File: datasets/aisi_316_L/data/M1/train_99.csv
Time(s),Strain(%),Stress(MPa),Temp(C),Log_SR(s-1)
0.0,0.0,0.0,381.1360386544181,1.937159308965791
1.9415562298274312e-07,1.68e-05,2.8704624374999996,381.1360386544181,1.937159308965791
6.934129392240826e-07,5.9999999999999995e-05,10.2516515625,381.1360386544181,1.937159308965791
8.413410329252202e-07,7.28e-05,12.438670562499999,381.1360386544181,1.937159308965791
1.0262511500516422e-06,8.879999999999999e-05,15.172444312499998,381.1360386544181,1.937159308965791
1.0724786793332477e-06,9.279999999999999e-05,15.855887749999999,381.1360386544181,1.937159308965791
1.1741792437527799e-06,0.00010159999999999999,17.359463312499997,381.1360386544181,1.937159308965791
1.460789925298734e-06,0.00012639999999999998,21.596812625,381.1360386544181,1.937159308965791
1.5902270072872294e-06,0.00013759999999999998,23.51045425,381.1360386544181,1.937159308965791
1.7843826302699724e-06,0.00015439999999999999,26.380916687499997,381.1360386544181,1.937159308965791
1.8121191478389358e-06,0.0001568,26.790982749999998,381.1360386544181,1.937159308965791
1.9415562298274314e-06,0.000168,28.704624374999998,381.1360386544181,1.937159308965791
2.18193938209178e-06,0.00018879999999999998,32.25853025,381.1360386544181,1.937159308965791
2.551759616344624e-06,0.0002208,37.72607775,381.1360386544181,1.937159308965791
2.801388274465294e-06,0.00024239999999999998,41.4166723125,381.1360386544181,1.937159308965791
2.829124792034257e-06,0.0002448,41.826738375,381.1360386544181,1.937159308965791
2.866106815459542e-06,0.000248,42.373493125,381.1360386544181,1.937159308965791
3.0232804150169997e-06,0.00026159999999999996,44.69720081249999,381.1360386544181,1.937159308965791
3.27290907313767e-06,0.0002832,48.387795375,381.1360386544181,1.937159308965791
3.5132922254020183e-06,0.00030399999999999996,51.941701249999994,381.1360386544181,1.937159308965791
3.5595197546836245e-06,0.000308,52.625144687500004,381.1360386544181,1.937159308965791
3.6612203191031562e-06,0.0003168,54.12872025,381.1360386544181,1.937159308965791
3.827639424516936e-06,0.0003312,56.589116624999996,381.1360386544181,1.937159308965791
4.160477635344496e-06,0.00035999999999999997,61.50990937499999,381.1360386544181,1.937159308965791
4.345387752470918e-06,0.000376,64.24368312499999,381.1360386544181,1.937159308965791
4.6412439398731935e-06,0.0004016,68.617721125,381.1360386544181,1.937159308965791
4.6689804574421565e-06,0.000404,69.0277871875,381.1360386544181,1.937159308965791
4.770681021861689e-06,0.0004128,70.53136275,381.1360386544181,1.937159308965791
4.918609115562826e-06,0.0004256,72.71838174999999,381.1360386544181,1.937159308965791
5.112764738545569e-06,0.00044239999999999997,75.58884418749999,381.1360386544181,1.937159308965791
5.297674855671991e-06,0.0004584,78.3226179375,381.1360386544181,1.937159308965791
5.353147890809918e-06,0.0004632,79.1427500625,381.1360386544181,1.937159308965791
5.427111937660486e-06,0.0004696,80.2362595625,381.1360386544181,1.937159308965791
5.612022054786908e-06,0.0004856,82.9700333125,381.1360386544181,1.937159308965791
5.667495089924835e-06,0.0004904,83.7901654375,381.1360386544181,1.937159308965791
5.7691956543443675e-06,0.0004992,85.293741,381.1360386544181,1.937159308965791
5.991087794896074e-06,0.0005184,88.5742695,381.1360386544181,1.937159308965791
6.120524876884569e-06,0.0005296,90.487911125,381.1360386544181,1.937159308965791
6.175997912022495e-06,0.0005344,91.30804325,381.1360386544181,1.937159308965791
6.2222254413041015e-06,0.0005384,91.9914866875,381.1360386544181,1.937159308965791
6.444117581855808e-06,0.0005576,95.2720151875,381.1360386544181,1.937159308965791
6.638273204838551e-06,0.0005744,98.142477625,381.1360386544181,1.937159308965791
6.675255228263835e-06,0.0005775999999999999,98.68923237499999,381.1360386544181,1.937159308965791
6.9156383805281846e-06,0.0005984,102.24313825,381.1360386544181,1.937159308965791
6.989602427378752e-06,0.0006048,103.33664775,381.1360386544181,1.937159308965791
7.1375305210798895e-06,0.0006175999999999999,105.52366674999999,381.1360386544181,1.937159308965791
7.313195132349992e-06,0.0006328,108.1207518125,381.1360386544181,1.937159308965791
7.451877720194808e-06,0.0006448,110.171082125,381.1360386544181,1.937159308965791
7.590560308039624e-06,0.0006567999999999999,112.22141243749999,381.1360386544181,1.937159308965791
7.849434472016614e-06,0.0006791999999999999,116.04869568749999,381.1360386544181,1.937159308965791
7.904907507154542e-06,0.0006839999999999999,116.86882781249999,381.1360386544181,1.937159308965791
7.923398518867183e-06,0.0006856,117.1422051875,381.1360386544181,1.937159308965791
8.062081106712e-06,0.0006975999999999999,119.19253549999999,381.1360386544181,1.937159308965791
8.089817624280965e-06,0.0007,119.6026015625,381.1360386544181,1.937159308965791
8.237745717982101e-06,0.0007128,121.78962056249999,381.1360386544181,1.937159308965791
8.376428305826917e-06,0.0007247999999999999,123.83995087499999,381.1360386544181,1.937159308965791
8.847949104499294e-06,0.0007656,130.8110739375,381.1360386544181,1.937159308965791
9.032859221625716e-06,0.0007815999999999999,133.54484768749998,381.1360386544181,1.937159308965791
9.217769338752139e-06,0.0007976,136.2786214375,381.1360386544181,1.937159308965791
9.291733385602706e-06,0.0008039999999999999,137.37213093749997,381.1360386544181,1.937159308965791
9.476643502729129e-06,0.00082,140.1059046875,381.1360386544181,1.937159308965791
9.587589573004983e-06,0.0008296,141.7461689375,381.1360386544181,1.937159308965791
9.901936772119901e-06,0.0008568,146.3935843125,381.1360386544181,1.937159308965791
1.0225529477091138e-05,0.0008847999999999999,151.17768837499997,381.1360386544181,1.937159308965791
1.0373457570792275e-05,0.0008975999999999999,153.364707375,381.1360386544181,1.937159308965791
1.0706295781619836e-05,0.0009264,158.285500125,381.1360386544181,1.937159308965791
1.0844978369464652e-05,0.0009383999999999999,160.3358304375,381.1360386544181,1.937159308965791
1.0946678933884183e-05,0.0009471999999999999,161.839406,381.1360386544181,1.937159308965791
1.1066870510016358e-05,0.0009576,163.6163589375,381.1360386544181,1.937159308965791
1.1187062086148534e-05,0.000968,165.393311875,381.1360386544181,1.937159308965791
1.123328961543014e-05,0.000972,166.0767553125,381.1360386544181,1.937159308965791
1.1399708720843917e-05,0.0009864,168.1228037140449,381.1360386544181,1.937159308965791
1.1815756484378367e-05,0.0010224,168.31934978586602,381.1360386544181,1.937159308965791
1.1954439072223184e-05,0.0010344,168.38426287151276,381.1360386544181,1.937159308965791
1.2019157613217431e-05,0.00104,168.41445507524904,381.1360386544181,1.937159308965791
1.2102367165924321e-05,0.0010471999999999999,168.4531806216804,381.1360386544181,1.937159308965791
1.233350481233235e-05,0.0010672,168.56021051558034,381.1360386544181,1.937159308965791
1.2472187400177167e-05,0.0010792,168.62405301661497,381.1360386544181,1.937159308965791
1.2768043587579442e-05,0.0011048,168.7593323350303,381.1360386544181,1.937159308965791
1.293446269299322e-05,0.0011191999999999999,168.83488958605383,381.1360386544181,1.937159308965791
1.3211827868682855e-05,0.0011432,168.95998119300032,381.1360386544181,1.937159308965791
1.3285791915533423e-05,0.0011496,168.9931654462556,381.1360386544181,1.937159308965791
1.342447450337824e-05,0.0011616,169.05519237027016,381.1360386544181,1.937159308965791
1.3988450360613826e-05,0.0012104,169.3049025703612,381.1360386544181,1.937159308965791
1.4080905419177037e-05,0.0012184,169.34546110030686,381.1360386544181,1.937159308965791
1.434902508901035e-05,0.0012416,169.4624976095953,381.1360386544181,1.937159308965791
1.4478462170998843e-05,0.0012527999999999999,169.51869247204712,381.1360386544181,1.937159308965791
1.4570917229562054e-05,0.0012607999999999999,169.5587117691095,381.1360386544181,1.937159308965791
1.4663372288125268e-05,0.0012688,169.5986321552881,381.1360386544181,1.937159308965791
1.4709599817406872e-05,0.0012728,169.61855552787384,381.1360386544181,1.937159308965791
1.503319252237811e-05,0.0013008,169.75734171494548,381.1360386544181,1.937159308965791
1.5088665557516037e-05,0.0013055999999999999,169.78101616674047,381.1360386544181,1.937159308965791
1.5218102639504532e-05,0.0013168,169.83612493830378,381.1360386544181,1.937159308965791
1.538452174491831e-05,0.0013311999999999998,169.90671120568925,381.1360386544181,1.937159308965791
1.5624904897182662e-05,0.001352,170.00814567987194,381.1360386544181,1.937159308965791
1.5671132426464268e-05,0.001356,170.0275823416055,381.1360386544181,1.937159308965791
1.6262844801268818e-05,0.0014072,170.27442897390188,381.1360386544181,1.937159308965791
1.636454536568835e-05,0.001416,170.3165005118947,381.1360386544181,1.937159308965791
1.6438509412538916e-05,0.0014223999999999999,170.34703397376023,381.1360386544181,1.937159308965791
1.667889256480327e-05,0.0014432,170.44589973338088,381.1360386544181,1.937159308965791
1.7252113927895174e-05,0.0014927999999999999,170.67944044176713,381.1360386544181,1.937159308965791
1.7446269550877917e-05,0.0015095999999999998,170.75785421496136,381.1360386544181,1.937159308965791
1.752947910358481e-05,0.0015168,170.7913558518703,381.1360386544181,1.937159308965791
1.7658916185573303e-05,0.0015279999999999998,170.84334649741015,381.1360386544181,1.937159308965791
1.7908544843693974e-05,0.0015496,170.94319636961788,381.1360386544181,1.937159308965791
1.7964017878831898e-05,0.0015543999999999998,170.96531134398057,381.1360386544181,1.937159308965791
1.830610159551578e-05,0.001584,171.101103143437,381.1360386544181,1.937159308965791
1.8564975759492774e-05,0.0016064,171.20320765362834,381.1360386544181,1.937159308965791
1.86204487946307e-05,0.0016112,171.22501477801973,381.1360386544181,1.937159308965791
1.8953287005458258e-05,0.00164,171.35532938727516,381.1360386544181,1.937159308965791
1.9027251052308827e-05,0.0016464,171.38416663014968,381.1360386544181,1.937159308965791
1.9128951616728357e-05,0.0016552,171.42374655725808,381.1360386544181,1.937159308965791
1.938782578070535e-05,0.0016776,171.52412691966623,381.1360386544181,1.937159308965791
1.9535753874406486e-05,0.0016903999999999999,171.58125241791794,381.1360386544181,1.937159308965791
1.9609717921257055e-05,0.0016967999999999998,171.60975188657702,381.1360386544181,1.937159308965791
1.9803873544239802e-05,0.0017136,171.68436423956626,381.1360386544181,1.937159308965791
1.9840855567665085e-05,0.0017167999999999999,171.6985437139241,381.1360386544181,1.937159308965791
1.9933310626228295e-05,0.0017247999999999999,171.73394737892338,381.1360386544181,1.937159308965791
2.0136711755067358e-05,0.0017423999999999999,171.81161079461035,381.1360386544181,1.937159308965791
2.0441813448325954e-05,0.0017687999999999998,171.9275347125126,381.1360386544181,1.937159308965791
2.0598987047883414e-05,0.0017824,171.98698962706945,381.1360386544181,1.937159308965791
2.062672356545238e-05,0.0017848,171.99746327876645,381.1360386544181,1.937159308965791
2.08116336825788e-05,0.0018008,172.067147784446,381.1360386544181,1.937159308965791
2.083937020014776e-05,0.0018031999999999998,172.0775795969087,381.1360386544181,1.937159308965791
2.1125980881693718e-05,0.001828,172.18505981076078,381.1360386544181,1.937159308965791
2.1394100551527027e-05,0.0018512,172.28509212064898,381.1360386544181,1.937159308965791
2.1431082574952313e-05,0.0018544,172.29885121202318,381.1360386544181,1.937159308965791
2.158825617450977e-05,0.0018679999999999999,172.3572243477523,381.1360386544181,1.937159308965791
2.173618426821091e-05,0.0018808,172.41201254596174,381.1360386544181,1.937159308965791
2.2133741020032715e-05,0.0019152,172.55854000636194,381.1360386544181,1.937159308965791
2.2263178102021212e-05,0.0019264,172.6060246515755,381.1360386544181,1.937159308965791
2.2364878666440745e-05,0.0019352,172.64325852443,381.1360386544181,1.937159308965791
2.2549788783567167e-05,0.0019512,172.71078773933596,381.1360386544181,1.937159308965791
2.2817908453400476e-05,0.0019744,172.80832275876108,381.1360386544181,1.937159308965791
2.2938100029532654e-05,0.0019848,172.85190015576265,381.1360386544181,1.937159308965791
2.2993573064670578e-05,0.0019896,172.87198275666182,381.1360386544181,1.937159308965791
2.315074666422804e-05,0.0020032,172.92878110323448,381.1360386544181,1.937159308965791
2.3307920263785496e-05,0.0020168,172.98542925875793,381.1360386544181,1.937159308965791
2.3354147793067105e-05,0.0020208,173.0020621030923,381.1360386544181,1.937159308965791
2.3511321392624562e-05,0.0020344,173.05851797748045,381.1360386544181,1.937159308965791
2.3640758474613056e-05,0.0020456,173.1049006140178,381.1360386544181,1.937159308965791
2.3714722521463625e-05,0.002052,173.13136050910012,381.1360386544181,1.937159308965791
2.3797932074170513e-05,0.0020591999999999997,173.16108945001733,381.1360386544181,1.937159308965791
2.3871896121021083e-05,0.0020656,173.18748115914653,381.1360386544181,1.937159308965791
2.402906972057854e-05,0.0020792,173.24345788749903,381.1360386544181,1.937159308965791
2.4287943884555534e-05,0.0021016,173.33534456718883,381.1360386544181,1.937159308965791
2.4556063554388847e-05,0.0021248,173.43011114791025,381.1360386544181,1.937159308965791
2.502758435306122e-05,0.0021655999999999997,173.5957965144326,381.1360386544181,1.937159308965791
2.515702143504972e-05,0.0021768,173.6410652358684,381.1360386544181,1.937159308965791
2.527721301118189e-05,0.0021872,173.68301920842097,381.1360386544181,1.937159308965791
2.576722482156691e-05,0.0022296,173.8532632940974,381.1360386544181,1.937159308965791
2.5979871456262295e-05,0.002248,173.92674942768647,381.1360386544181,1.937159308965791
2.6137045055819753e-05,0.0022616,173.98091458560606,381.1360386544181,1.937159308965791
2.6312709667089855e-05,0.0022768,174.0413020124698,381.1360386544181,1.937159308965791
2.6562338325210523e-05,0.0022984,174.12684595658556,381.1360386544181,1.937159308965791
2.6821212489187517e-05,0.0023208,174.21522768267732,381.1360386544181,1.937159308965791
2.6959895077032333e-05,0.0023328,174.26243815594486,381.1360386544181,1.937159308965791
2.7033859123882902e-05,0.0023392,174.28757834384126,381.1360386544181,1.937159308965791
2.7338960817141494e-05,0.0023656,174.39099933233302,381.1360386544181,1.937159308965791
2.7653308016256416e-05,0.0023928,174.4970845798086,381.1360386544181,1.937159308965791
2.7958409709515008e-05,0.0024192,174.59960082558234,381.1360386544181,1.937159308965791
2.8235774885204643e-05,0.0024432,174.69241942446052,381.1360386544181,1.937159308965791
2.8411439496474746e-05,0.0024584,174.75102066016862,381.1360386544181,1.937159308965791
2.8494649049181637e-05,0.0024656,174.77872980483124,381.1360386544181,1.937159308965791
2.862408613117013e-05,0.0024768,174.82177027666236,381.1360386544181,1.937159308965791
2.8707295683877022e-05,0.002484,174.8493990743235,381.1360386544181,1.937159308965791
2.8781259730727588e-05,0.0024904,174.8739317965222,381.1360386544181,1.937159308965791
2.9493163681664316e-05,0.002552,175.1088153457288,381.1360386544181,1.937159308965791
2.952090019923328e-05,0.0025544,175.11792162663454,381.1360386544181,1.937159308965791
2.9715055822216023e-05,0.0025712,175.18157242318148,381.1360386544181,1.937159308965791
2.9770528857353944e-05,0.0025759999999999997,175.19972854723545,381.1360386544181,1.937159308965791
2.9955438974480366e-05,0.0025919999999999997,175.26015389502575,381.1360386544181,1.937159308965791
3.0140349091606794e-05,0.002608,175.3204339482453,381.1360386544181,1.937159308965791
3.030676819702057e-05,0.0026224,175.37456279249352,381.1360386544181,1.937159308965791
3.0371486738014817e-05,0.0026279999999999997,175.3955815778885,381.1360386544181,1.937159308965791
3.046394179657803e-05,0.002636,175.42557813846594,381.1360386544181,1.937159308965791
3.0537905843428597e-05,0.0026424,175.44954983175086,381.1360386544181,1.937159308965791
3.087998956011248e-05,0.002672,175.5601256984064,381.1360386544181,1.937159308965791
3.1212827770940035e-05,0.0027007999999999997,175.66725540836703,381.1360386544181,1.937159308965791
3.140698339392278e-05,0.0027175999999999997,175.72954199352472,381.1360386544181,1.937159308965791
3.1573402499336565e-05,0.002732,175.78281106647518,381.1360386544181,1.937159308965791
3.166585755789977e-05,0.00274,175.8123576773909,381.1360386544181,1.937159308965791
3.188774969845148e-05,0.0027592,175.8831326114155,381.1360386544181,1.937159308965791
3.2054168803865256e-05,0.0027735999999999998,175.93608783376604,381.1360386544181,1.937159308965791
3.235002499126753e-05,0.0027992,176.02996645919083,381.1360386544181,1.937159308965791
3.245172555568706e-05,0.0028079999999999997,176.06215982521994,381.1360386544181,1.937159308965791
3.274758174308934e-05,0.0028336,176.15559027872166,381.1360386544181,1.937159308965791
3.284928230750887e-05,0.0028423999999999997,176.18763089143852,381.1360386544181,1.937159308965791
3.2950982871928405e-05,0.0028512,176.2196328406201,381.1360386544181,1.937159308965791
3.315438400076747e-05,0.0028688,176.28352141024743,381.1360386544181,1.937159308965791
3.3256084565187e-05,0.0028775999999999997,176.31540835859494,381.1360386544181,1.937159308965791
3.348722221159503e-05,0.0028975999999999997,176.38773759862644,381.1360386544181,1.937159308965791
3.353344974087663e-05,0.0029016,176.40218005396136,381.1360386544181,1.937159308965791
3.377383289314098e-05,0.0029224,176.47715602161253,381.1360386544181,1.937159308965791
3.385704244584787e-05,0.0029295999999999997,176.5030607145643,381.1360386544181,1.937159308965791
3.393100649269844e-05,0.002936,176.52606627114537,381.1360386544181,1.937159308965791
3.410667110396854e-05,0.0029511999999999997,176.5806262255089,381.1360386544181,1.937159308965791
3.427309020938232e-05,0.0029655999999999997,176.63221359872654,381.1360386544181,1.937159308965791
3.443026380893978e-05,0.0029792,176.68084537851507,381.1360386544181,1.937159308965791
3.4476491338221384e-05,0.0029831999999999997,176.695132355783,381.1360386544181,1.937159308965791
3.4698383478773095e-05,0.0030023999999999997,176.763606121088,381.1360386544181,1.937159308965791
3.481857505490527e-05,0.0030128,176.8006247650119,381.1360386544181,1.937159308965791
3.4984994160319046e-05,0.0030272,176.85179917992656,381.1360386544181,1.937159308965791
3.508669472473858e-05,0.003036,176.88302570032462,381.1360386544181,1.937159308965791
3.515141326573283e-05,0.0030415999999999998,176.90287874468711,381.1360386544181,1.937159308965791
3.5216131806727076e-05,0.0030472,176.9227175388145,381.1360386544181,1.937159308965791
3.5262359336008684e-05,0.0030512,176.93687940157807,381.1360386544181,1.937159308965791
3.54010419238535e-05,0.0030632,176.9793216100221,381.1360386544181,1.937159308965791
3.561368855854888e-05,0.0030816,177.04427393905894,381.1360386544181,1.937159308965791
3.5743125640537375e-05,0.0030927999999999997,177.08373609167538,381.1360386544181,1.937159308965791
3.627011947434768e-05,0.0031384,177.2438313840347,381.1360386544181,1.937159308965791
3.64550295914741e-05,0.0031544,177.29978983461694,381.1360386544181,1.937159308965791
3.660295768517524e-05,0.0031672,177.34447693471077,381.1360386544181,1.937159308965791
3.700051443699705e-05,0.0032015999999999998,177.4642258797388,381.1360386544181,1.937159308965791
3.7055987472134976e-05,0.0032064,177.48089505297764,381.1360386544181,1.937159308965791
3.717617904826715e-05,0.0032167999999999997,177.51697824550612,381.1360386544181,1.937159308965791
3.7388825682962535e-05,0.0032351999999999997,177.58070648470755,381.1360386544181,1.937159308965791
3.751826276495103e-05,0.0032464,177.61942838378414,381.1360386544181,1.937159308965791
3.7592226811801594e-05,0.0032527999999999997,177.6415317911242,381.1360386544181,1.937159308965791
3.778638243478434e-05,0.0032695999999999997,177.69947268908467,381.1360386544181,1.937159308965791
3.7906574010916516e-05,0.00328,177.7352826833939,381.1360386544181,1.937159308965791
3.79897835636234e-05,0.0032871999999999997,177.76004828178205,381.1360386544181,1.937159308965791
3.831337626859465e-05,0.0033152,177.85615850800215,381.1360386544181,1.937159308965791
3.845205885643946e-05,0.0033271999999999998,177.89725163509496,381.1360386544181,1.937159308965791
3.869244200870381e-05,0.003348,177.9683430606143,381.1360386544181,1.937159308965791
3.8858861114117586e-05,0.0033623999999999998,178.01745932973404,381.1360386544181,1.937159308965791
3.9016034713675043e-05,0.0033759999999999997,178.06377164553007,381.1360386544181,1.937159308965791
3.927490887765204e-05,0.0033983999999999998,178.13989245503146,381.1360386544181,1.937159308965791
3.9321136406933646e-05,0.0034024,178.15346484034643,381.1360386544181,1.937159308965791
3.945981899477846e-05,0.0034143999999999997,178.19414470779876,381.1360386544181,1.937159308965791
3.950604652406007e-05,0.0034184,178.2076922678659,381.1360386544181,1.937159308965791
3.9607747088479604e-05,0.0034272,178.2374751567722,381.1360386544181,1.937159308965791
3.987586675831291e-05,0.0034503999999999997,178.315851069594,381.1360386544181,1.937159308965791
3.9986812828588765e-05,0.00346,178.3482223324962,381.1360386544181,1.937159308965791
4.0097758898864614e-05,0.0034695999999999998,178.3805585859636,381.1360386544181,1.937159308965791
4.019021395742783e-05,0.0034776,178.40747881764943,381.1360386544181,1.937159308965791
4.068947127366917e-05,0.0035207999999999997,178.55243285028965,381.1360386544181,1.937159308965791
4.118872858991051e-05,0.003564,178.6966948741622,381.1360386544181,1.937159308965791
4.137363870703693e-05,0.00358,178.7499519837692,381.1360386544181,1.937159308965791
4.154005781245071e-05,0.0035943999999999998,178.7978040668787,381.1360386544181,1.937159308965791
4.163251287101392e-05,0.0036024,178.82435624991825,381.1360386544181,1.937159308965791
4.1706476917864484e-05,0.0036087999999999997,178.84558144257556,381.1360386544181,1.937159308965791
4.180817748228402e-05,0.0036176,178.87474212803127,381.1360386544181,1.937159308965791
4.217799771653686e-05,0.0036496,178.98054857777103,381.1360386544181,1.937159308965791
4.2261207269243754e-05,0.0036568,179.0043050947736,381.1360386544181,1.937159308965791
4.261253649178396e-05,0.0036872,179.10440993857242,381.1360386544181,1.937159308965791
4.272348256205981e-05,0.0036967999999999997,179.13595505378888,381.1360386544181,1.937159308965791
4.323198538415747e-05,0.0037408,179.28013000984154,381.1360386544181,1.937159308965791
4.349085954813446e-05,0.0037632,179.35327401594887,381.1360386544181,1.937159308965791
4.3675769665260884e-05,0.0037792,179.40541581450404,381.1360386544181,1.937159308965791
4.380520674724938e-05,0.0037903999999999998,179.44186385983502,381.1360386544181,1.937159308965791
4.392539832338155e-05,0.0038008,179.4756708821888,381.1360386544181,1.937159308965791
4.407332641708269e-05,0.0038136,179.51723004012325,381.1360386544181,1.937159308965791
4.436918260448496e-05,0.0038391999999999996,179.60018551228586,381.1360386544181,1.937159308965791
4.4803721379732057e-05,0.0038767999999999997,179.72163631462803,381.1360386544181,1.937159308965791
4.5034859026140087e-05,0.0038967999999999997,179.78605059782905,381.1360386544181,1.937159308965791
4.5293733190117074e-05,0.003919199999999999,179.85804171992456,381.1360386544181,1.937159308965791
4.559883488337567e-05,0.0039456,179.94268271286765,381.1360386544181,1.937159308965791
4.588544556492163e-05,0.0039704,180.02199297522802,381.1360386544181,1.937159308965791
4.60056371410538e-05,0.0039808,180.05519459250965,381.1360386544181,1.937159308965791
4.711527539303462e-05,0.004076815363072615,180.36013875898308,381.1360386544181,1.937159308965791
5.221981553375202e-05,0.004518503700740148,181.72834649388304,381.1360386544181,1.937159308965791
5.5992736507325744e-05,0.00484496899379876,182.70630156942397,381.1360386544181,1.937159308965791
5.8877911369470355e-05,0.005094618923784757,183.43689727779338,381.1360386544181,1.937159308965791
6.797730901161875e-05,0.005881976395279056,185.65451361851595,381.1360386544181,1.937159308965791
7.086248387376335e-05,0.006131626325265053,186.33304571977072,381.1360386544181,1.937159308965791
7.907413540448264e-05,0.006842168433686738,188.20763478982428,381.1360386544181,1.937159308965791
8.218124679448453e-05,0.007111022204440888,188.89692578173174,381.1360386544181,1.937159308965791
8.861740610234558e-05,0.007667933586717343,190.29321490608814,381.1360386544181,1.937159308965791
9.35000097152057e-05,0.008090418083616723,191.32622450737688,381.1360386544181,1.937159308965791
0.00010193359777378226,0.008820164032806561,193.06225580833544,381.1360386544181,1.937159308965791
0.00011103299541593066,0.00960752150430086,194.87361509176438,381.1360386544181,1.937159308965791
0.00011391817027807528,0.009857171434286858,195.43573107401022,381.1360386544181,1.937159308965791
0.00011924464694664995,0.010318063612722545,196.45910686941428,381.1360386544181,1.937159308965791
0.00012301756792022366,0.010644528905781155,197.173237342209,381.1360386544181,1.937159308965791
0.00012501499667093917,0.01081736347269454,197.5478454756286,381.1360386544181,1.937159308965791
0.0001325608386180866,0.011470294058811763,198.94244704754246,381.1360386544181,1.937159308965791
0.00013544601348023123,0.011719943988797759,199.46744975433506,381.1360386544181,1.937159308965791
0.00014010668056523405,0.012123224644928985,200.30640973695495,381.1360386544181,1.937159308965791
0.00014432347459452234,0.012488097619523904,201.05613521501493,381.1360386544181,1.937159308965791
0.00015719579321024445,0.013601920384076815,203.29360521403788,381.1360386544181,1.937159308965791
0.00016341001599024825,0.014139627925585117,204.34807581655136,381.1360386544181,1.937159308965791
0.00016762681001953654,0.014504500900180036,205.0547166835423,381.1360386544181,1.937159308965791
0.0001700681118259666,0.014715743148629726,205.46065562227696,381.1360386544181,1.937159308965791
0.00017117779446525297,0.014811762352470495,205.64442140826347,381.1360386544181,1.937159308965791
0.00017739201724525675,0.015349469893978797,206.66505071727192,381.1360386544181,1.937159308965791
0.00018049912863525865,0.015618323664732947,207.17012896354345,381.1360386544181,1.937159308965791
0.00018138687474668775,0.01569513902780556,207.31381275305313,381.1360386544181,1.937159308965791
0.00018626947835954788,0.016117623524704944,208.09922511972135,381.1360386544181,1.937159308965791
0.00019248370113955163,0.016655331066213242,209.08732349622102,381.1360386544181,1.937159308965791
0.00019337144725098076,0.016732146429285857,209.22745805969814,381.1360386544181,1.937159308965791
0.00019625662211312538,0.016981796359271856,209.6811723461089,381.1360386544181,1.937159308965791
0.0002029147179488437,0.01755791158231646,210.71839159533758,381.1360386544181,1.937159308965791
0.00020646570239456013,0.01786517303460692,211.26614353152652,381.1360386544181,1.937159308965791
0.00021046055989599118,0.01821084216843369,211.87799152762736,381.1360386544181,1.937159308965791
0.0002137896078138503,0.01849889977995599,212.3844124373556,381.1360386544181,1.937159308965791
0.00021489929045313672,0.01859491898379676,212.5525347431263,381.1360386544181,1.937159308965791
0.0002264399899017152,0.01959351870374075,214.28139311160845,381.1360386544181,1.937159308965791
0.00022954710129171704,0.019862372474494898,214.74093902304017,381.1360386544181,1.937159308965791
0.00023465164143243446,0.020304060812162433,215.49067539349963,381.1360386544181,1.937159308965791
0.00023909037198958002,0.020688137627525506,216.1374644178826,381.1360386544181,1.937159308965791
0.00024375103907458282,0.02109141828365673,216.81157281103006,381.1360386544181,1.937159308965791
0.0002481897696317284,0.021475495099019803,217.44892241635583,381.1360386544181,1.937159308965791
0.00025107494449387303,0.021725145029005802,217.86081707951817,381.1360386544181,1.937159308965791
0.0002561794846345904,0.022166833366673334,218.58506002187715,381.1360386544181,1.937159308965791
0.00026106208824745053,0.022589317863572714,219.27256569291393,381.1360386544181,1.937159308965791
0.00026572275533245335,0.022992598519703943,219.9241579775009,381.1360386544181,1.937159308965791
0.0002712711685288853,0.023472694538907782,220.6940798997726,381.1360386544181,1.937159308965791
0.0002810363757546055,0.024317663532706542,222.034388815218,381.1360386544181,1.937159308965791
0.0002843654236724647,0.024605721144228845,222.48714444520928,381.1360386544181,1.937159308965791
0.0002908015829803258,0.025162632526505302,223.35665289665386,381.1360386544181,1.937159308965791
0.0002983474249274732,0.025815563112622526,224.36657549052728,381.1360386544181,1.937159308965791
0.0003052274572910488,0.026410882176435287,225.27873792642913,381.1360386544181,1.937159308965791
0.00030811263215319343,0.026660532106421286,225.65886713020586,381.1360386544181,1.937159308965791
0.0003123294261824817,0.027025405081016203,226.2119528895028,381.1360386544181,1.937159308965791
0.0003154365375724836,0.027294258851770354,226.61762804485676,381.1360386544181,1.937159308965791
0.00031743396632319913,0.02746709341868374,226.87759649770575,381.1360386544181,1.937159308965791
0.0003196533316017719,0.027659131826365275,227.1657032453464,381.1360386544181,1.937159308965791
0.00032076301424105826,0.02775515103020604,227.30946399397237,381.1360386544181,1.937159308965791
0.00032231656993605924,0.02788957791558312,227.5104036109359,381.1360386544181,1.937159308965791
0.00032320431604748837,0.027966393278655733,227.6250566555299,381.1360386544181,1.937159308965791
0.0003247578717424893,0.028100820164032807,227.8254043917984,381.1360386544181,1.937159308965791
0.00033230371368963673,0.02875375075015003,228.79325486103443,381.1360386544181,1.937159308965791
0.0003334133963289231,0.028849769953990797,228.93485956017338,381.1360386544181,1.937159308965791
0.0003438444131382152,0.02975235047009402,230.25707931364255,381.1360386544181,1.937159308965791
0.0003487270167510753,0.0301748349669934,230.87060675285687,381.1360386544181,1.937159308965791
0.00036004577967179644,0.031154230846169233,232.2801323944176,381.1360386544181,1.937159308965791
0.00036315289106179834,0.031423084616923384,232.66402419052844,381.1360386544181,1.937159308965791
0.0003647064467567993,0.03155751150230046,232.85548956826324,381.1360386544181,1.937159308965791
0.00036936711384180214,0.031960792158431686,233.42798626101148,381.1360386544181,1.937159308965791
0.00037158647912037486,0.03215283056611322,233.69961292606052,381.1360386544181,1.937159308965791
0.0003778007019003787,0.03269053810762153,234.4568220372528,381.1360386544181,1.937159308965791
0.0003817955594018097,0.03303620724144829,234.94103547081644,381.1360386544181,1.937159308965791
0.0003897852744046717,0.03372754550910182,235.90357482029063,381.1360386544181,1.937159308965791
0.0003915607666275299,0.03388117623524705,236.11642391143482,381.1360386544181,1.937159308965791
0.00039666530676824734,0.034322864572914585,236.72627838468927,381.1360386544181,1.937159308965791
0.00039932854510253457,0.03455331066213242,237.0432478591861,381.1360386544181,1.937159308965791
0.00040931568885611207,0.035417483496699334,238.22461155173394,381.1360386544181,1.937159308965791
0.00041042537149539864,0.035513502700540114,238.35517653282636,381.1360386544181,1.937159308965791
0.00041486410205254407,0.03589757951590318,238.87606556640802,381.1360386544181,1.937159308965791
0.00041974670566540423,0.036320064012802564,239.44653949951427,381.1360386544181,1.937159308965791
0.00042840223025183803,0.03706901380276055,240.45151415416507,381.1360386544181,1.937159308965791
0.0004392771201168447,0.038010002000400084,241.70301940097565,381.1360386544181,1.937159308965791
0.0004428281045625612,0.03831726345269054,242.10904947981743,381.1360386544181,1.937159308965791
0.0004488203908147077,0.03883576715343069,242.7913576056983,381.1360386544181,1.937159308965791
0.00045259331178828133,0.039162232446489295,243.21913687158596,381.1360386544181,1.937159308965791
0.0004545907405389969,0.03933506701340268,243.445045091592,381.1360386544181,1.937159308965791
0.0004636901381811452,0.040122424484896974,244.46932296571975,381.1360386544181,1.937159308965791
0.00046613143998757524,0.040333666733346665,244.74279167847385,381.1360386544181,1.937159308965791
0.0004710140436004354,0.04075615123024605,245.28805910236392,381.1360386544181,1.937159308965791
0.00047589664721329556,0.04117863572714543,245.83112652230392,381.1360386544181,1.937159308965791
0.0004812231238818702,0.04163952790558112,246.4210913863575,381.1360386544181,1.937159308965791
0.000489878648468304,0.042388477695539106,247.3743813392698,381.1360386544181,1.937159308965791
0.0004925418868025914,0.04261892378475696,247.66637678563293,381.1360386544181,1.937159308965791
0.0004972025538875943,0.04302220444088818,248.17589147567057,381.1360386544181,1.937159308965791
0.0004998657922218815,0.04325265053010602,248.4662063893683,381.1360386544181,1.937159308965791
0.000507411634169029,0.04390558111622324,249.28550744112675,381.1360386544181,1.937159308965791
0.0005140697300047473,0.04448169633926785,250.00448211071466,381.1360386544181,1.937159308965791
0.0005262762390368977,0.04553790758151631,251.31323995188305,381.1360386544181,1.937159308965791
0.0005284956043154704,0.04572994598919784,251.5499184967656,381.1360386544181,1.937159308965791
0.0005329343348726158,0.04611402280456091,252.0221159110381,381.1360386544181,1.937159308965791
0.0005373730654297615,0.04649809961992399,252.49278197649764,381.1360386544181,1.937159308965791
0.000540924049875478,0.046805361072214446,252.86822406578628,381.1360386544181,1.937159308965791
0.0005420337325147644,0.04690138027605521,252.985352433997,381.1360386544181,1.937159308965791
0.0005478040822390535,0.047400680136027204,253.592918990791,381.1360386544181,1.937159308965791
0.0005493576379340546,0.04753510702140429,253.75606749980403,381.1360386544181,1.937159308965791
0.0005522428127961991,0.047784756951390284,254.0585810018767,381.1360386544181,1.937159308965791
0.0005540183050190574,0.04793838767753551,254.24443681440485,381.1360386544181,1.937159308965791
0.0005633396391890631,0.04874494898979796,255.21639494873824,381.1360386544181,1.937159308965791
0.0005708854811362104,0.04939787957591518,255.99863218316037,381.1360386544181,1.937159308965791
0.0005755461482212133,0.04980116023204641,256.479764693953,381.1360386544181,1.937159308965791
0.0005779874500276434,0.0500124024804961,256.73117993802083,381.1360386544181,1.937159308965791
0.0005790971326669297,0.050108421684336865,256.845322651173,381.1360386544181,1.937159308965791
0.0005835358632240754,0.050492498499699945,257.30104306081324,381.1360386544181,1.937159308965791
0.000587308784197649,0.05081896379275855,257.68734345770986,381.1360386544181,1.937159308965791
0.0005897500860040791,0.05103020604120824,257.9367869078336,381.1360386544181,1.937159308965791
0.0005924133243383665,0.05126065213042609,258.2084481973031,381.1360386544181,1.937159308965791
0.0005970739914233693,0.051663932786557315,258.682712144945,381.1360386544181,1.937159308965791
0.0005988494836462275,0.051817563512702544,258.86300407742124,381.1360386544181,1.937159308965791
0.0006110559926783778,0.05287377475495099,260.09691600876744,381.1360386544181,1.937159308965791
0.0006137192310126651,0.05310422084416884,260.3648513373951,381.1360386544181,1.937159308965791
0.0006179360250419533,0.05346909381876375,260.78815675763246,381.1360386544181,1.937159308965791
0.0006241502478219571,0.054006801360272055,261.4099276241252,381.1360386544181,1.937159308965791
0.0006330277089362483,0.0547749549909982,262.29399986689145,381.1360386544181,1.937159308965791
0.0006407954874112531,0.05544708941788358,263.06360415080735,381.1360386544181,1.937159308965791
0.0006416832335226821,0.05552390478095619,263.1513266482279,381.1360386544181,1.937159308965791
0.0006547774886662615,0.056656931386277254,264.4397850605181,381.1360386544181,1.937159308965791
0.0006587723461676925,0.057002600520104016,264.8308683456559,381.1360386544181,1.937159308965791
0.0006632110767248381,0.057386677335467096,265.2643221680637,381.1360386544181,1.937159308965791
0.0006649865689476964,0.057540308061612325,265.437386728824,381.1360386544181,1.937159308965791
0.0006669839976984118,0.05771314262852571,265.6318690975687,381.1360386544181,1.937159308965791
0.0006716446647834147,0.05811642328465694,266.0847800952002,381.1360386544181,1.937159308965791
0.0006767492049241321,0.058558111622324466,266.57942142496,381.1360386544181,1.937159308965791
0.0006811879354812775,0.05894218843768753,267.0083627486204,381.1360386544181,1.937159308965791
0.0006867363486777095,0.05942228445689138,267.54300957565476,381.1360386544181,1.937159308965791
0.0006909531427069978,0.0597871574314863,267.94821522016025,381.1360386544181,1.937159308965791
0.0006931725079855705,0.05997919583916783,268.1610939115978,381.1360386544181,1.937159308965791
0.0006936163810412851,0.060017603520704135,268.2036377337586,381.1360386544181,1.937159308965791
0.0006978331750705734,0.060382476495299056,268.6072758698958,381.1360386544181,1.937159308965791
0.0007004964134048608,0.06061292258451691,268.8617151790025,381.1360386544181,1.937159308965791
0.0007058228900734355,0.061073814762952594,269.36946480420823,381.1360386544181,1.937159308965791
0.0007084861284077227,0.06130426085217043,269.62277906899936,381.1360386544181,1.937159308965791
0.0007109274302141528,0.06151550310062012,269.854657767295,381.1360386544181,1.937159308965791
0.0007198048913284439,0.06228365673134627,270.69524787208684,381.1360386544181,1.937159308965791
0.0007273507332755914,0.06293658731746349,271.4065753480602,381.1360386544181,1.937159308965791
0.0007309017177213078,0.06324384876975395,271.7403212941701,381.1360386544181,1.937159308965791
0.0007404449884191708,0.06406961392278455,272.6341448394397,381.1360386544181,1.937159308965791
0.0007475469573106036,0.06468413682736547,273.2964028017963,381.1360386544181,1.937159308965791
0.0007486566399498901,0.06478015603120624,273.3996585404374,381.1360386544181,1.937159308965791
0.0007522076243956065,0.0650874174834967,273.7296765133274,381.1360386544181,1.937159308965791
0.0007550927992577511,0.06533706741348269,273.99736895470795,381.1360386544181,1.937159308965791
0.0007588657202313248,0.06566353270654131,274.3468271719855,381.1360386544181,1.937159308965791
0.0007646360699556141,0.0661628325665133,274.8799848842153,381.1360386544181,1.937159308965791
0.0007655238160670432,0.06623964792958592,274.96186966494,381.1360386544181,1.937159308965791
0.0007668554352341869,0.06635487097419485,275.08462743202995,381.1360386544181,1.937159308965791
0.0007761767694041925,0.0671614322864573,275.94161598079654,381.1360386544181,1.937159308965791
0.0007772864520434789,0.06725745149029806,276.04337037816566,381.1360386544181,1.937159308965791
0.0007797277538499091,0.06746869373874775,276.26703084142594,381.1360386544181,1.937159308965791
0.0007803935634334809,0.06752630526105222,276.3279817297924,381.1360386544181,1.937159308965791
0.0007826129287120536,0.06771834366873375,276.5310050458032,381.1360386544181,1.937159308965791
0.0007957071838556331,0.06885137027405482,277.7243037520892,381.1360386544181,1.937159308965791
0.0008012555970520651,0.06933146629325866,278.22762591613815,381.1360386544181,1.937159308965791
0.0008025872162192086,0.06944668933786757,278.3482207537953,381.1360386544181,1.937159308965791
0.0008039188353863523,0.0695619123824765,278.4687375831442,381.1360386544181,1.937159308965791
0.0008112427408056425,0.07019563912782557,279.13019373413505,381.1360386544181,1.937159308965791
0.0008125743599727861,0.07031086217243449,279.25020785449044,381.1360386544181,1.937159308965791
0.0008207860115035055,0.07102140428085618,279.9886071486971,381.1360386544181,1.937159308965791
0.0008243369959492219,0.07132866573314664,280.307022018982,381.1360386544181,1.937159308965791
0.0008305512187292256,0.07186637327465493,280.8629638444018,381.1360386544181,1.937159308965791
0.0008336583301192276,0.07213522704540909,281.1403262475106,381.1360386544181,1.937159308965791
0.0008438674104006622,0.07301860372074415,282.0488344286459,381.1360386544181,1.937159308965791
0.000846752585262807,0.07326825365073016,282.30480855465424,381.1360386544181,1.937159308965791
0.0008525229349870962,0.07376755351070215,282.8157386218454,381.1360386544181,1.937159308965791
0.000862732015268531,0.07465093018603722,283.7164000805802,381.1360386544181,1.937159308965791
0.0008645075074913892,0.07480456091218245,283.87261160482024,381.1360386544181,1.937159308965791
0.0008685023649928202,0.07515023004600921,284.22363078857353,381.1360386544181,1.937159308965791
0.0008762701434678249,0.07582236447289459,284.90437072388823,381.1360386544181,1.937159308965791
0.0008815966201363996,0.07628325665133028,285.36980420617937,381.1360386544181,1.937159308965791
0.0008840379219428296,0.07649449889977997,285.5827612377211,381.1360386544181,1.937159308965791
0.0008882547159721179,0.07685937187437487,285.95005668634343,381.1360386544181,1.937159308965791
0.0008913618273621198,0.07712822564512903,286.2202604466691,381.1360386544181,1.937159308965791
0.0009015709076435546,0.0780116023204641,287.10549771218285,381.1360386544181,1.937159308965791
0.0009048999555614138,0.0782996599319864,287.3933156519864,381.1360386544181,1.937159308965791
0.0009055657651449856,0.07835727145429086,287.45082965333864,381.1360386544181,1.937159308965791
0.000908229003479273,0.07858771754350871,287.680720932529,381.1360386544181,1.937159308965791
0.0009135554801478476,0.0790486097219444,288.1397162873213,381.1360386544181,1.937159308965791
0.0009226548777899959,0.07983596719343869,288.9214261910836,381.1360386544181,1.937159308965791
0.0009235426239014252,0.07991278255651131,288.99752924085647,381.1360386544181,1.937159308965791
0.0009246523065407115,0.08000880176035208,289.09261794503703,381.1360386544181,1.937159308965791
0.0009266497352914269,0.08018163632726545,289.26366553467864,381.1360386544181,1.937159308965791
0.000929091037097857,0.08039287857571514,289.4725285507004,381.1360386544181,1.937159308965791
0.000930644592792858,0.08052730546109223,289.605329945864,381.1360386544181,1.937159308965791
0.0009419633557135792,0.08150670134026806,290.5702867572641,381.1360386544181,1.937159308965791
0.0009446265940478665,0.0817371474294859,290.79667696371814,381.1360386544181,1.937159308965791
0.0009477337054378685,0.08200600120024006,291.0604844958365,381.1360386544181,1.937159308965791
0.0009499530707164412,0.08219803960792159,291.24871197639465,381.1360386544181,1.937159308965791
0.000951506626411442,0.08233246649329866,291.38036918117416,381.1360386544181,1.937159308965791
0.0009550576108571585,0.08263972794558912,291.6809855322477,381.1360386544181,1.937159308965791
0.0009626034528043061,0.08329265853170635,292.31835175702946,381.1360386544181,1.937159308965791
0.0009657105641943079,0.08356151230246049,292.5802299615092,381.1360386544181,1.937159308965791
0.0009688176755843098,0.08383036607321465,292.8417797666689,381.1360386544181,1.937159308965791
0.0009730344696135981,0.08419523904780957,293.19621756211524,381.1360386544181,1.937159308965791
0.0009743660887807418,0.08431046209241849,293.3080207657966,381.1360386544181,1.937159308965791
0.0009759196444757426,0.08444488897779556,293.4383825490175,381.1360386544181,1.937159308965791
0.0009768073905871719,0.08452170434086818,293.5128386589199,381.1360386544181,1.937159308965791
0.0009821338672557464,0.08498259651930387,293.95902238239137,381.1360386544181,1.937159308965791
0.000983243549895033,0.08507861572314464,294.051858428289,381.1360386544181,1.937159308965791
0.0009845751690621765,0.08519383876775355,294.1632077631024,381.1360386544181,1.937159308965791
0.0009872384073964639,0.0854242848569714,294.38573038984447,381.1360386544181,1.937159308965791
0.000989901645730751,0.08565473094618924,294.6080190256873,381.1360386544181,1.937159308965791
0.000996115868510755,0.08619243848769755,295.12578744704837,381.1360386544181,1.937159308965791
0.0009983352337893277,0.08638447689537908,295.310399251803,381.1360386544181,1.937159308965791
0.0010058810757364752,0.0870374074814963,295.93688561938615,381.1360386544181,1.937159308965791
0.0010136488542114798,0.08770954190838168,296.57988647817234,381.1360386544181,1.937159308965791
0.0010231921249093429,0.08853530706141229,297.36723421114567,381.1360386544181,1.937159308965791
0.0010271869824107739,0.08888097619523905,297.69597066900417,381.1360386544181,1.937159308965791
0.0010331792686629204,0.0893994798959792,298.1881419995917,381.1360386544181,1.937159308965791
0.0010358425069972078,0.08962992598519705,298.40652733887845,381.1360386544181,1.937159308965791
0.0010418347932493544,0.0901484296859372,298.89709529451756,381.1360386544181,1.937159308965791
0.0010456077142229278,0.0904748949789958,299.2054069394541,381.1360386544181,1.937159308965791
0.0010487148256129299,0.09074374874974996,299.4589849987437,381.1360386544181,1.937159308965791
0.0010555948579765054,0.09133906781356271,300.019438892868,381.1360386544181,1.937159308965791
0.0010595897154779365,0.09168473694738949,300.3442099824535,381.1360386544181,1.937159308965791
0.0010611432711729375,0.09181916383276656,300.47038084355387,381.1360386544181,1.937159308965791
0.0010684671765922276,0.09245289057811563,301.06421870134955,381.1360386544181,1.937159308965791
0.001083336923958665,0.09373954790958192,302.26502830952336,381.1360386544181,1.937159308965791
0.0010884414640993827,0.09418123624724946,302.67576220844853,381.1360386544181,1.937159308965791
0.0010922143850729561,0.09450770154030806,302.97886546369864,381.1360386544181,1.937159308965791
0.0010939898772958144,0.09466133226645329,303.12136096984284,381.1360386544181,1.937159308965791
0.0010962092425743873,0.09485337067413484,303.2993535829521,381.1360386544181,1.937159308965791
0.0011019795922986766,0.09535267053410683,303.7614778896233,381.1360386544181,1.937159308965791
0.0011073060689672511,0.09581356271254252,304.1872172287817,381.1360386544181,1.937159308965791
0.0011135202917472548,0.09635127025405081,304.68290497828565,381.1360386544181,1.937159308965791
0.0011192906414715443,0.09685057011402282,305.1422213147919,381.1360386544181,1.937159308965791
0.0011246171181401188,0.0973114622924585,305.56538662210335,381.1360386544181,1.937159308965791
0.001129499721752979,0.09773394678935787,305.9526020052681,381.1360386544181,1.937159308965791
0.0011403746116179856,0.0986749349869974,306.81269778346507,381.1360386544181,1.937159308965791
0.0011432597864801301,0.0989245849169834,307.0403487995157,381.1360386544181,1.937159308965791
0.0011443694691194166,0.09902060412082417,307.12784720845735,381.1360386544181,1.937159308965791
0.0011483643266208476,0.09936627325465093,307.44256786619627,381.1360386544181,1.937159308965791
0.001151027564955135,0.09959671934386878,307.6521444578529,381.1360386544181,1.937159308965791