File: datasets/aisi_316_L/data/M1/train_78.csv
Time(s),Strain(%),Stress(MPa),Temp(C),Log_SR(s-1)
0.0,0.0,0.0,54.54388873852338,3.0064968250892443
3.310110198300918e-08,3.36e-05,6.554527349999999,54.54388873852338,3.0064968250892443
5.2016017401871575e-08,5.2799999999999996e-05,10.299971549999999,54.54388873852338,3.0064968250892443
6.46259610144465e-08,6.56e-05,12.796934349999999,54.54388873852338,3.0064968250892443
8.038839053016515e-08,8.159999999999999e-05,15.918137849999999,54.54388873852338,3.0064968250892443
8.432899790909483e-08,8.56e-05,16.698438725,54.54388873852338,3.0064968250892443
9.063396971538229e-08,9.2e-05,17.946920125,54.54388873852338,3.0064968250892443
1.0245579185217128e-07,0.000104,20.28782275,54.54388873852338,3.0064968250892443
1.0560827775531502e-07,0.00010719999999999999,20.912063449999998,54.54388873852338,3.0064968250892443
1.363450153109664e-07,0.0001384,26.998410275,54.54388873852338,3.0064968250892443
1.4107374416568198e-07,0.00014319999999999998,27.934771324999996,54.54388873852338,3.0064968250892443
1.52895566302471e-07,0.0001552,30.27567395,54.54388873852338,3.0064968250892443
1.8836103271283798e-07,0.00019119999999999999,37.298381825,54.54388873852338,3.0064968250892443
2.104284340348441e-07,0.0002136,41.668066724999996,54.54388873852338,3.0064968250892443
2.340720783084221e-07,0.0002376,46.349871975,54.54388873852338,3.0064968250892443
2.529869937272845e-07,0.0002568,50.095316175,54.54388873852338,3.0064968250892443
2.7978312390400616e-07,0.00028399999999999996,55.40136212499999,54.54388873852338,3.0064968250892443
3.1524859031437314e-07,0.00031999999999999997,62.42406999999999,54.54388873852338,3.0064968250892443
3.254941694995903e-07,0.0003304,64.452852275,54.54388873852338,3.0064968250892443
3.5701902853102764e-07,0.00036239999999999997,70.695259275,54.54388873852338,3.0064968250892443
3.7435770099831816e-07,0.00037999999999999997,74.12858312499999,54.54388873852338,3.0064968250892443
3.9327261641718055e-07,0.0003992,77.874027325,54.54388873852338,3.0064968250892443
4.208568680696882e-07,0.0004272,83.33613344999999,54.54388873852338,3.0064968250892443
4.381955405369787e-07,0.00044479999999999997,86.7694573,54.54388873852338,3.0064968250892443
4.736610069473457e-07,0.0004808,93.792165175,54.54388873852338,3.0064968250892443
4.878471935114925e-07,0.0004952,96.601248325,54.54388873852338,3.0064968250892443
4.996690156482814e-07,0.0005072,98.94215095,54.54388873852338,3.0064968250892443
5.028215015514252e-07,0.0005103999999999999,99.56639164999999,54.54388873852338,3.0064968250892443
5.162195666397861e-07,0.0005239999999999999,102.21941462499998,54.54388873852338,3.0064968250892443
5.201601740187157e-07,0.0005279999999999999,102.9997155,54.54388873852338,3.0064968250892443
5.556256404290827e-07,0.0005639999999999999,110.02242337499999,54.54388873852338,3.0064968250892443
5.595662478080123e-07,0.0005679999999999999,110.80272424999998,54.54388873852338,3.0064968250892443
5.658712196142999e-07,0.0005744,112.05120565,54.54388873852338,3.0064968250892443
5.86362377984734e-07,0.0005951999999999999,116.1087702,54.54388873852338,3.0064968250892443
5.966079571699512e-07,0.0006056,118.13755247499999,54.54388873852338,3.0064968250892443
5.99760443073095e-07,0.0006087999999999999,118.761793175,54.54388873852338,3.0064968250892443
6.320734235803183e-07,0.0006416,125.16026035,54.54388873852338,3.0064968250892443
6.34437788007676e-07,0.0006439999999999999,125.62844087499998,54.54388873852338,3.0064968250892443
6.423190027655354e-07,0.000652,127.189042625,54.54388873852338,3.0064968250892443
6.59657675232826e-07,0.0006696,130.622366475,54.54388873852338,3.0064968250892443
6.856656839337617e-07,0.000696,135.77235225,54.54388873852338,3.0064968250892443
7.030043564010522e-07,0.0007136,139.2056761,54.54388873852338,3.0064968250892443
7.195549073925568e-07,0.0007304,142.482939775,54.54388873852338,3.0064968250892443
7.39257944287205e-07,0.0007503999999999999,146.38444414999998,54.54388873852338,3.0064968250892443
7.526560093755659e-07,0.0007639999999999999,149.03746712499998,54.54388873852338,3.0064968250892443
7.99155176446936e-07,0.0008112,158.24501745,54.54388873852338,3.0064968250892443
8.10976998583725e-07,0.0008232,160.585920075,54.54388873852338,3.0064968250892443
8.251631851478719e-07,0.0008376,163.39500322499998,54.54388873852338,3.0064968250892443
8.46442464994092e-07,0.0008592,167.60862795,54.54388873852338,3.0064968250892443
8.503830723730216e-07,0.0008632,168.388928825,54.54388873852338,3.0064968250892443
8.7008610926767e-07,0.0008832,172.2904332,54.54388873852338,3.0064968250892443
8.890010246865324e-07,0.0009023999999999999,176.03587739999998,54.54388873852338,3.0064968250892443
8.953059964928198e-07,0.0009088,177.2843588,54.54388873852338,3.0064968250892443
9.126446689601104e-07,0.0009264,180.71768265,54.54388873852338,3.0064968250892443
9.157971548632541e-07,0.0009295999999999999,181.34192334999997,54.54388873852338,3.0064968250892443
9.28407098475829e-07,0.0009423999999999999,183.83888614999998,54.54388873852338,3.0064968250892443
9.386526776610462e-07,0.0009528,185.867668425,54.54388873852338,3.0064968250892443
9.51262621273621e-07,0.0009655999999999999,188.36463122499998,54.54388873852338,3.0064968250892443
1.0040667601512788e-06,0.0010192,198.82066295,54.54388873852338,3.0064968250892443
1.010371731957566e-06,0.0010256,200.06914435,54.54388873852338,3.0064968250892443
1.0371678621342879e-06,0.0010528,205.3751903,54.54388873852338,3.0064968250892443
1.0568708990289361e-06,0.0010728,209.27669467500002,54.54388873852338,3.0064968250892443
1.066328356738367e-06,0.0010823999999999999,211.14941677499996,54.54388873852338,3.0064968250892443
1.0749976929720124e-06,0.0010911999999999999,212.86607869999997,54.54388873852338,3.0064968250892443
1.1262255888980982e-06,0.0011432,223.00999007500002,54.54388873852338,3.0064968250892443
1.140411775462245e-06,0.0011576,225.81907322499998,54.54388873852338,3.0064968250892443
1.1522335975990342e-06,0.0011696,228.15997585,54.54388873852338,3.0064968250892443
1.164055419735823e-06,0.0011815999999999999,230.50087847499998,54.54388873852338,3.0064968250892443
1.188487185485187e-06,0.0012064,235.3387439,54.54388873852338,3.0064968250892443
1.1940040358156885e-06,0.001212,236.431165125,54.54388873852338,3.0064968250892443
1.19952088614619e-06,0.0012175999999999999,237.52358635,54.54388873852338,3.0064968250892443
1.2089783438556211e-06,0.0012272,239.39630845,54.54388873852338,3.0064968250892443
1.2160714371376945e-06,0.0012343999999999999,240.80085002499996,54.54388873852338,3.0064968250892443
1.2176476800892664e-06,0.001236,241.11297037499997,54.54388873852338,3.0064968250892443
1.232621988129199e-06,0.0012511999999999998,244.07811369999996,54.54388873852338,3.0064968250892443
1.2491725391207037e-06,0.001268,247.35537737500002,54.54388873852338,3.0064968250892443
1.2570537538785632e-06,0.001276,248.915979125,54.54388873852338,3.0064968250892443
1.2641468471606365e-06,0.0012832,250.3205207,54.54388873852338,3.0064968250892443
1.2783330337247832e-06,0.0012975999999999999,253.12960384999997,54.54388873852338,3.0064968250892443
1.3137985001351501e-06,0.0013335999999999999,260.152311725,54.54388873852338,3.0064968250892443
1.316950986038294e-06,0.0013368,260.776552425,54.54388873852338,3.0064968250892443
1.3271965652235111e-06,0.0013472,262.8053347,54.54388873852338,3.0064968250892443
1.339806508836086e-06,0.0013599999999999999,265.30229749999995,54.54388873852338,3.0064968250892443
1.3492639665455173e-06,0.0013696,267.1750196,54.54388873852338,3.0064968250892443
1.3768482181980248e-06,0.0013976,272.637125725,54.54388873852338,3.0064968250892443
1.3949750121411013e-06,0.001416,276.22650975,54.54388873852338,3.0064968250892443
1.4036443483747466e-06,0.0014248,277.943171675,54.54388873852338,3.0064968250892443
1.408373077229462e-06,0.0014295999999999998,278.879532725,54.54388873852338,3.0064968250892443
1.4209830208420372e-06,0.0014424,281.376495525,54.54388873852338,3.0064968250892443
1.4280761141241105e-06,0.0014495999999999999,282.7810371,54.54388873852338,3.0064968250892443
1.4706346738165508e-06,0.0014927999999999999,291.20828654999997,54.54388873852338,3.0064968250892443
1.4871852248080554e-06,0.0015095999999999998,294.48555022499994,54.54388873852338,3.0064968250892443
1.5139813549847772e-06,0.0015367999999999998,297.95160974427904,54.54388873852338,3.0064968250892443
1.5431418495888566e-06,0.0015664,298.18941866942225,54.54388873852338,3.0064968250892443
1.5644211294350769e-06,0.001588,298.3618502188853,54.54388873852338,3.0064968250892443
1.5857004092812971e-06,0.0016095999999999999,298.53336944425905,54.54388873852338,3.0064968250892443
1.6038272032243736e-06,0.0016279999999999999,298.6787715591576,54.54388873852338,3.0064968250892443
1.6156490253611627e-06,0.00164,298.7732538585733,54.54388873852338,3.0064968250892443
1.6400807911105264e-06,0.0016648,298.96766714745456,54.54388873852338,3.0064968250892443
1.6645125568598904e-06,0.0016895999999999999,299.1609541771209,54.54388873852338,3.0064968250892443
1.6991899017944715e-06,0.0017247999999999999,299.43340799406843,54.54388873852338,3.0064968250892443
1.705494873600759e-06,0.0017312,299.48271118523695,54.54388873852338,3.0064968250892443
1.7196810601649058e-06,0.0017456,299.59338420407613,54.54388873852338,3.0064968250892443
1.7299266393501229e-06,0.001756,299.6730933975924,54.54388873852338,3.0064968250892443
1.750417797720557e-06,0.0017767999999999998,299.83196158579966,54.54388873852338,3.0064968250892443
1.7614514983815602e-06,0.0017879999999999999,299.9172054977332,54.54388873852338,3.0064968250892443
1.7669683487120618e-06,0.0017936,299.95974934284857,54.54388873852338,3.0064968250892443
1.7945526003645693e-06,0.0018215999999999998,300.1716964312246,54.54388873852338,3.0064968250892443
1.800857572170857e-06,0.001828,300.21996263230494,54.54388873852338,3.0064968250892443
1.8197724875897193e-06,0.0018472,300.3643673546963,54.54388873852338,3.0064968250892443
1.8300180667749362e-06,0.0018575999999999998,300.4423421182856,54.54388873852338,3.0064968250892443
1.8378992815327956e-06,0.0018655999999999998,300.50220690825273,54.54388873852338,3.0064968250892443
1.8520854680969425e-06,0.00188,300.60971184430286,54.54388873852338,3.0064968250892443
1.856026075475872e-06,0.0018839999999999998,300.63951727237156,54.54388873852338,3.0064968250892443
1.8725766264673769e-06,0.0019008,300.76443152327215,54.54388873852338,3.0064968250892443
1.8820340841768079e-06,0.0019103999999999998,300.8356177676532,54.54388873852338,3.0064968250892443
1.8899152989346673e-06,0.0019184,300.8948331298878,54.54388873852338,3.0064968250892443
1.913558943208245e-06,0.0019424,301.07190406750254,54.54388873852338,3.0064968250892443
1.927745129772392e-06,0.0019568,301.1777371036419,54.54388873852338,3.0064968250892443
1.931685737151322e-06,0.0019608,301.20708120907756,54.54388873852338,3.0064968250892443
1.9813373901258355e-06,0.0020112,301.57483903949066,54.54388873852338,3.0064968250892443
1.9931592122626244e-06,0.0020231999999999997,301.66186853748,54.54388873852338,3.0064968250892443
2.009709763254129e-06,0.0020399999999999997,301.7833723855211,54.54388873852338,3.0064968250892443
2.018379099487774e-06,0.0020488,301.84686148148717,54.54388873852338,3.0064968250892443
2.0294128001487774e-06,0.0020599999999999998,301.92751218148203,54.54388873852338,3.0064968250892443
2.045963351140282e-06,0.0020767999999999997,302.04816832552655,54.54388873852338,3.0064968250892443
2.0767000886959336e-06,0.002108,302.2712389161265,54.54388873852338,3.0064968250892443
2.081428817550649e-06,0.0021127999999999997,302.3054428457377,54.54388873852338,3.0064968250892443
2.1098011906789426e-06,0.0021416,302.51003360724286,54.54388873852338,3.0064968250892443
2.1208348913399454e-06,0.0021528,302.58930655260184,54.54388873852338,3.0064968250892443
2.1484191429924535e-06,0.0021808,302.78678845685727,54.54388873852338,3.0064968250892443
2.164181572508172e-06,0.0021968,302.89919125302634,54.54388873852338,3.0064968250892443
2.1917658241606796e-06,0.0022248,303.0951308888234,54.54388873852338,3.0064968250892443
2.1957064315396093e-06,0.0022288,303.1230435555022,54.54388873852338,3.0064968250892443
2.2027995248216824e-06,0.0022359999999999997,303.17323717250054,54.54388873852338,3.0064968250892443
2.2524511777961964e-06,0.0022864,303.52284422792513,54.54388873852338,3.0064968250892443
2.2626967569814135e-06,0.0022968,303.5946098383851,54.54388873852338,3.0064968250892443
2.291857251585493e-06,0.0023263999999999997,303.79817542051063,54.54388873852338,3.0064968250892443
2.312348409955927e-06,0.0023472,303.9406176260055,54.54388873852338,3.0064968250892443
2.3194415032380007e-06,0.0023544,303.9898097360822,54.54388873852338,3.0064968250892443
2.3470257548905084e-06,0.0023824,304.1805572609973,54.54388873852338,3.0064968250892443
2.3643644273577986e-06,0.0024,304.30000831243007,54.54388873852338,3.0064968250892443
2.3683050347367286e-06,0.002404,304.32710857674925,54.54388873852338,3.0064968250892443
2.410863594429169e-06,0.0024472,304.6186795967552,54.54388873852338,3.0064968250892443
2.4384478460816764e-06,0.0024752,304.80658920488946,54.54388873852338,3.0064968250892443
2.459727125927897e-06,0.0024968,304.9509821693023,54.54388873852338,3.0064968250892443
2.4723370695404715e-06,0.0025096,305.036318495267,54.54388873852338,3.0064968250892443
2.4770657983951872e-06,0.0025144,305.06827583318375,54.54388873852338,3.0064968250892443
2.4999213211929797e-06,0.0025376,305.2224021452572,54.54388873852338,3.0064968250892443
2.515683750708698e-06,0.0025536,305.3283761108894,54.54388873852338,3.0064968250892443
2.5204124795634134e-06,0.0025583999999999997,305.36011776246016,54.54388873852338,3.0064968250892443
2.5416917594096336e-06,0.00258,305.5026687524398,54.54388873852338,3.0064968250892443
2.566123525158998e-06,0.0026048,305.66576567743283,54.54388873852338,3.0064968250892443
2.576369104344215e-06,0.0026152,305.73398080200906,54.54388873852338,3.0064968250892443
2.597648384190435e-06,0.0026368,305.8753212465019,54.54388873852338,3.0064968250892443
2.6134108137061536e-06,0.0026528,305.9797269237688,54.54388873852338,3.0064968250892443
2.620503906988227e-06,0.00266,306.0266293267725,54.54388873852338,3.0064968250892443
2.6370544579797317e-06,0.0026768,306.1358761423154,54.54388873852338,3.0064968250892443
2.663062466680667e-06,0.0027032,306.3070109936482,54.54388873852338,3.0064968250892443
2.679613017672172e-06,0.0027199999999999998,306.41557569545466,54.54388873852338,3.0064968250892443
2.693799204236319e-06,0.0027343999999999997,306.5084231751668,54.54388873852338,3.0064968250892443
2.7300527921224714e-06,0.0027711999999999997,306.7448378517198,54.54388873852338,3.0064968250892443
2.7426627357350468e-06,0.002784,306.8267816278089,54.54388873852338,3.0064968250892443
2.7678826229601966e-06,0.0028095999999999998,306.99022970516364,54.54388873852338,3.0064968250892443
2.7907381457579886e-06,0.0028328,307.13785351739966,54.54388873852338,3.0064968250892443
2.808864939701065e-06,0.0028512,307.25459946777084,54.54388873852338,3.0064968250892443
2.8325085839746434e-06,0.0028752,307.40643616664266,54.54388873852338,3.0064968250892443
2.8372373128293587e-06,0.0028799999999999997,307.4367441038217,54.54388873852338,3.0064968250892443
2.848271013490362e-06,0.0028912,307.50738611570046,54.54388873852338,3.0064968250892443
2.8656096859576525e-06,0.0029088,307.6181797451093,54.54388873852338,3.0064968250892443
2.8695502933365817e-06,0.0029127999999999997,307.64332361764554,54.54388873852338,3.0064968250892443
2.880583993997585e-06,0.002924,307.71365492138455,54.54388873852338,3.0064968250892443
2.888465208755444e-06,0.0029319999999999997,307.7638272573092,54.54388873852338,3.0064968250892443
2.9010751523680194e-06,0.0029448,307.84399208773027,54.54388873852338,3.0064968250892443
2.920778189262668e-06,0.0029648,307.9689781164949,54.54388873852338,3.0064968250892443
2.9389049832057438e-06,0.0029831999999999997,308.083675154307,54.54388873852338,3.0064968250892443
2.9444218335362456e-06,0.0029888,308.1185281423731,54.54388873852338,3.0064968250892443
2.950726805342533e-06,0.0029952,308.15832895859035,54.54388873852338,3.0064968250892443
2.9554555341972487e-06,0.003,308.1881578083489,54.54388873852338,3.0064968250892443
2.9704298422371815e-06,0.0030152,308.28249327197494,54.54388873852338,3.0064968250892443
2.9759466925676825e-06,0.0030207999999999997,308.31720166753814,54.54388873852338,3.0064968250892443
2.993285365034973e-06,0.0030383999999999997,308.42612218962,54.54388873852338,3.0064968250892443
3.0027428227444045e-06,0.003048,308.48542966222357,54.54388873852338,3.0064968250892443
3.01141215897805e-06,0.0030567999999999997,308.5397308800316,54.54388873852338,3.0064968250892443
3.016929009308551e-06,0.0030624,308.57425446006107,54.54388873852338,3.0064968250892443
3.0366320462031997e-06,0.0030824,308.6973524795672,54.54388873852338,3.0064968250892443
3.056335083097848e-06,0.0031024,308.820139391248,54.54388873852338,3.0064968250892443
3.0760381199924966e-06,0.0031224,308.94261797941704,54.54388873852338,3.0064968250892443
3.0965292783629308e-06,0.0031432,309.0696715883005,54.54388873852338,3.0064968250892443
3.1051986145965757e-06,0.003152,309.12332628064047,54.54388873852338,3.0064968250892443
3.1485452957648022e-06,0.003196,309.3907283977036,54.54388873852338,3.0064968250892443
3.165883968232093e-06,0.0032136,309.49728677041134,54.54388873852338,3.0064968250892443
3.178493911844668e-06,0.0032264,309.57464086623196,54.54388873852338,3.0064968250892443
3.1863751266025266e-06,0.0032343999999999997,309.62292640359016,54.54388873852338,3.0064968250892443
3.206866284972961e-06,0.0032551999999999998,309.7482513199547,54.54388873852338,3.0064968250892443
3.2234168359644657e-06,0.0032719999999999997,309.84924744713,54.54388873852338,3.0064968250892443
3.2407555084317563e-06,0.0032895999999999997,309.9548362399211,54.54388873852338,3.0064968250892443
3.2557298164716887e-06,0.0033047999999999997,310.04584938290753,54.54388873852338,3.0064968250892443
3.2722803674631932e-06,0.0033215999999999996,310.1462531317816,54.54388873852338,3.0064968250892443
3.2825259466484107e-06,0.003332,310.20830859251004,54.54388873852338,3.0064968250892443
3.291195282882056e-06,0.0033407999999999997,310.26075808085324,54.54388873852338,3.0064968250892443
3.2982883761641296e-06,0.003348,310.30363123323514,54.54388873852338,3.0064968250892443
3.304593347970417e-06,0.0033544,310.3417105242397,54.54388873852338,3.0064968250892443
3.3085339553493462e-06,0.0033583999999999997,310.36549569298063,54.54388873852338,3.0064968250892443
3.3203557774861355e-06,0.0033704,310.436784997319,54.54388873852338,3.0064968250892443
3.339270692904998e-06,0.0033896,310.5506423315959,54.54388873852338,3.0064968250892443
3.3550331224207168e-06,0.0034056,310.64533143469004,54.54388873852338,3.0064968250892443
3.3668549445575056e-06,0.0034176,310.71623444684093,54.54388873852338,3.0064968250892443
3.370795551936435e-06,0.0034216,310.73984719927785,54.54388873852338,3.0064968250892443
3.380253009645866e-06,0.0034311999999999997,310.79647392434543,54.54388873852338,3.0064968250892443
3.382617374073224e-06,0.0034335999999999998,310.81062094695193,54.54388873852338,3.0064968250892443
3.4007441680163008e-06,0.0034519999999999998,310.9189536258817,54.54388873852338,3.0064968250892443
3.418870961959377e-06,0.0034704,311.0270613360309,54.54388873852338,3.0064968250892443
3.422023447862521e-06,0.0034736,311.04583983508513,54.54388873852338,3.0064968250892443
3.442514606232955e-06,0.0034944,311.1677360406501,54.54388873852338,3.0064968250892443
3.4614295216518175e-06,0.0035136,311.28000469173656,54.54388873852338,3.0064968250892443
3.485073165925395e-06,0.0035375999999999997,311.4200046128823,54.54388873852338,3.0064968250892443
3.4976831095379705e-06,0.0035504,311.49451975410176,54.54388873852338,3.0064968250892443
3.502411838392686e-06,0.0035551999999999997,311.5224359114931,54.54388873852338,3.0064968250892443
3.5213267538115482e-06,0.0035743999999999997,311.6339538613318,54.54388873852338,3.0064968250892443
3.539453547754625e-06,0.0035927999999999997,311.74060621523796,54.54388873852338,3.0064968250892443
3.547334762512484e-06,0.0036008,311.7869103381222,54.54388873852338,3.0064968250892443
3.5489110054640563e-06,0.0036024,311.7961663462586,54.54388873852338,3.0064968250892443
3.5536397343187716e-06,0.0036071999999999996,311.8239247556209,54.54388873852338,3.0064968250892443
3.559944706125059e-06,0.0036136,311.8609135698574,54.54388873852338,3.0064968250892443
3.561520949076631e-06,0.0036152,311.8701567802965,54.54388873852338,3.0064968250892443
3.5772833785923497e-06,0.0036312,311.96250130564425,54.54388873852338,3.0064968250892443
3.601715144341714e-06,0.003656,312.10532233020245,54.54388873852338,3.0064968250892443
3.608020116148001e-06,0.0036623999999999997,312.1421179723025,54.54388873852338,3.0064968250892443
3.6143250879542884e-06,0.0036688,312.1788885459531,54.54388873852338,3.0064968250892443
3.6300875174700073e-06,0.0036848,312.27070570375906,54.54388873852338,3.0064968250892443
3.6482143114130836e-06,0.0037032,312.3761034339745,54.54388873852338,3.0064968250892443
3.665552983880374e-06,0.0037208,312.47672770807316,54.54388873852338,3.0064968250892443
3.6718579556866617e-06,0.0037272,312.51327230786205,54.54388873852338,3.0064968250892443
3.6789510489687348e-06,0.0037343999999999997,312.5543557425646,54.54388873852338,3.0064968250892443
3.680527291920307e-06,0.0037359999999999997,312.56348119820075,54.54388873852338,3.0064968250892443
3.715204636854888e-06,0.0037711999999999997,312.76385723811586,54.54388873852338,3.0064968250892443
3.7293908234190345e-06,0.0037855999999999996,312.8456188642191,54.54388873852338,3.0064968250892443
3.739636402604252e-06,0.003796,312.9045935115486,54.54388873852338,3.0064968250892443
3.7530344676926126e-06,0.0038096,312.9816192115787,54.54388873852338,3.0064968250892443
3.7609156824504722e-06,0.0038176,313.02687835241335,54.54388873852338,3.0064968250892443
3.7884999341029795e-06,0.0038456,313.1849948808066,54.54388873852338,3.0064968250892443
3.830270372319634e-06,0.003888,313.4235764268713,54.54388873852338,3.0064968250892443
3.835787222650135e-06,0.0038935999999999997,313.45501116544614,54.54388873852338,3.0064968250892443
3.864159595778429e-06,0.0039223999999999995,313.61639785880305,54.54388873852338,3.0064968250892443
3.880710146769934e-06,0.0039391999999999995,313.7103266797495,54.54388873852338,3.0064968250892443
3.9161756131803005e-06,0.0039752,313.91107825967,54.54388873852338,3.0064968250892443
3.935090528599163e-06,0.0039943999999999995,314.01785579438877,54.54388873852338,3.0064968250892443
4.337900061262242e-06,0.0044032806561312265,316.2463227349553,54.54388873852338,3.0064968250892443
4.508168353690489e-06,0.004576115223044609,317.1638467625738,54.54388873852338,3.0064968250892443
4.981135832657842e-06,0.00505621124224845,319.6441751418276,54.54388873852338,3.0064968250892443
5.227078921720866e-06,0.0053058611722344474,320.89751463407623,54.54388873852338,3.0064968250892443
5.397347214149114e-06,0.00547869573914783,321.7517675357612,54.54388873852338,3.0064968250892443
5.56761550657736e-06,0.005651530306061212,322.5955727250318,54.54388873852338,3.0064968250892443
6.740574854416396e-06,0.006842168433686738,328.1567468502533,54.54388873852338,3.0064968250892443
7.3081358291772194e-06,0.007418283656731346,330.7106247134489,54.54388873852338,3.0064968250892443
7.572997617398938e-06,0.007687137427485497,331.8758380189003,54.54388873852338,3.0064968250892443
7.610835015716326e-06,0.007725545109021804,332.0409902717935,54.54388873852338,3.0064968250892443
8.27298948627062e-06,0.008397679535907181,334.88124183871196,54.54388873852338,3.0064968250892443
8.443257778698867e-06,0.008570514102820564,335.59708102056936,54.54388873852338,3.0064968250892443
8.935143956824915e-06,0.009069813962792559,337.634094815775,54.54388873852338,3.0064968250892443
9.067574850935775e-06,0.009204240848169634,338.1749877613374,54.54388873852338,3.0064968250892443
9.124330948411856e-06,0.009261852370474095,338.40585491650825,54.54388873852338,3.0064968250892443
9.408111435792269e-06,0.0095499099819964,339.5518948101939,54.54388873852338,3.0064968250892443
9.786485418966153e-06,0.009933986797359472,341.05919047266195,54.54388873852338,3.0064968250892443
9.862160215600928e-06,0.010010802160432087,341.3579032939566,54.54388873852338,3.0064968250892443
1.0013509808870482e-05,0.010164432886577316,341.95266059376695,54.54388873852338,3.0064968250892443
1.0467558588679141e-05,0.010625325065013003,343.71624408556676,54.54388873852338,3.0064968250892443
1.097836346596388e-05,0.01114382876575315,345.66498722503394,54.54388873852338,3.0064968250892443
1.120538785586821e-05,0.011374274854970993,346.5197089100199,54.54388873852338,3.0064968250892443
1.2226997610437694e-05,0.01241128225645129,350.28529838674774,54.54388873852338,3.0064968250892443
1.2662127691087659e-05,0.012852970594118824,351.85164937469375,54.54388873852338,3.0064968250892443
1.3059420373420235e-05,0.01325625125025005,353.26355542359516,54.54388873852338,3.0064968250892443
1.3248607365007178e-05,0.013448289657931586,353.92999473639554,54.54388873852338,3.0064968250892443
1.3286444763324566e-05,0.013486697339467894,354.0628360951394,54.54388873852338,3.0064968250892443
1.3475631754911507e-05,0.01367873574714943,354.72484258651843,54.54388873852338,3.0064968250892443
1.3797249640609307e-05,0.014005201040208042,355.8419946480437,54.54388873852338,3.0064968250892443
1.4156704924624496e-05,0.014370074014802961,357.07862594118177,54.54388873852338,3.0064968250892443
1.5026965085924426e-05,0.015253450690138028,360.0229200103216,54.54388873852338,3.0064968250892443
1.5481013865733085e-05,0.015714342868573716,361.532623660799,54.54388873852338,3.0064968250892443
1.5556688662367862e-05,0.01579115823164633,361.7825524618897,54.54388873852338,3.0064968250892443
1.604857484049391e-05,0.016290458091618325,363.39568367017245,54.54388873852338,3.0064968250892443
1.724045288749164e-05,0.017500300060012002,367.22645697488474,54.54388873852338,3.0064968250892443
1.7448558578237273e-05,0.01771154230846169,367.8845878405751,54.54388873852338,3.0064968250892443
1.778909516309377e-05,0.01805721144228846,368.95496407623426,54.54388873852338,3.0064968250892443
1.7864769959728547e-05,0.018134026805361074,369.1917367615129,54.54388873852338,3.0064968250892443
1.7997200853839404e-05,0.018268453690738148,369.6051498934458,54.54388873852338,3.0064968250892443
1.862151792607631e-05,0.01890218043608722,371.5383380786447,54.54388873852338,3.0064968250892443
1.9510696786534935e-05,0.01980476095219044,374.2485816215978,54.54388873852338,3.0064968250892443
2.0305282151200088e-05,0.02061132226445289,376.62999915449274,54.54388873852338,3.0064968250892443
2.0513387841945722e-05,0.02082256451290258,377.2476624095834,54.54388873852338,3.0064968250892443
2.0929599223436992e-05,0.02124504900980196,378.47570588265484,54.54388873852338,3.0064968250892443
2.1080948816706547e-05,0.02139867973594719,378.9199009720904,54.54388873852338,3.0064968250892443
2.1534997596515206e-05,0.021859571914382876,380.2450831137721,54.54388873852338,3.0064968250892443
2.159175369399129e-05,0.02191718343668734,380.4099612633115,54.54388873852338,3.0064968250892443
2.1799859384736922e-05,0.022128425685137027,381.01307377731933,54.54388873852338,3.0064968250892443
2.18755341813717e-05,0.02220524104820964,381.2318301727936,54.54388873852338,3.0064968250892443
2.2083639872117337e-05,0.022416483296659333,381.8318937441739,54.54388873852338,3.0064968250892443
2.2386339058656445e-05,0.02272374474894979,382.7007915743295,54.54388873852338,3.0064968250892443
2.2859306537623795e-05,0.02320384076815363,384.04932700344915,54.54388873852338,3.0064968250892443
2.3294436618273763e-05,0.023645529105821166,385.28039951396335,54.54388873852338,3.0064968250892443
2.3786322796399808e-05,0.024144828965793157,386.6612978116747,54.54388873852338,3.0064968250892443
2.3956591088828056e-05,0.024317663532706542,387.1367003992847,54.54388873852338,3.0064968250892443
2.4448477266954104e-05,0.024816963392678536,388.5027390439151,54.54388873852338,3.0064968250892443
2.4789013851810598e-05,0.025162632526505302,389.44218540219384,54.54388873852338,3.0064968250892443
2.5148469135825785e-05,0.02552750550110022,390.42837916898554,54.54388873852338,3.0064968250892443
2.5924135801332247e-05,0.02631486297259452,392.5379426407034,54.54388873852338,3.0064968250892443
2.6510615475251763e-05,0.02691018203640728,394.11667358785024,54.54388873852338,3.0064968250892443
2.70403390516952e-05,0.027447889577915583,395.5309544637177,54.54388873852338,3.0064968250892443
2.7532225229821247e-05,0.027947189437887578,396.83457005878074,54.54388873852338,3.0064968250892443
2.758898132729733e-05,0.02800480096019204,396.9844004831357,54.54388873852338,3.0064968250892443
2.7948436611312518e-05,0.028369673934786958,397.9305501481611,54.54388873852338,3.0064968250892443
2.8553834984390728e-05,0.028984196839367874,399.51340754884365,54.54388873852338,3.0064968250892443
2.9083558560834164e-05,0.029521904380876176,400.887701604859,54.54388873852338,3.0064968250892443
2.9840306527181932e-05,0.03029005801160232,402.8341634611009,54.54388873852338,3.0064968250892443
2.989706262465801e-05,0.03034766953390678,402.9793673762222,54.54388873852338,3.0064968250892443
3.0180843112038425e-05,0.030635727145429087,403.7037806183882,54.54388873852338,3.0064968250892443
3.0370030103625368e-05,0.030827765553110623,404.18524751797855,54.54388873852338,3.0064968250892443
3.067272929016447e-05,0.03113502700540108,404.95316868446554,54.54388873852338,3.0064968250892443
3.112677806997313e-05,0.031595919183836765,406.0995318339479,54.54388873852338,3.0064968250892443
3.161866424809918e-05,0.03209521904380876,407.3340904633104,54.54388873852338,3.0064968250892443
3.1788932540527425e-05,0.032268053610722144,407.7596895626269,54.54388873852338,3.0064968250892443
3.203487562959045e-05,0.03251770354070814,408.3728776214658,54.54388873852338,3.0064968250892443
3.2091631727066534e-05,0.0325753150630126,408.5141215013394,54.54388873852338,3.0064968250892443
3.254568050687519e-05,0.03303620724144829,409.6405865140891,54.54388873852338,3.0064968250892443
3.2924054490049075e-05,0.03342028405681136,410.5746330005421,54.54388873852338,3.0064968250892443
3.356729026144468e-05,0.03407321464292859,412.15296080082965,54.54388873852338,3.0064968250892443
3.3851070748825084e-05,0.03436127225445089,412.8455272876326,54.54388873852338,3.0064968250892443
3.4078095138729415e-05,0.03459171834366873,413.3979515527373,54.54388873852338,3.0064968250892443
3.47780870076011e-05,0.03530226045209042,415.0922934320411,54.54388873852338,3.0064968250892443
3.536456668152061e-05,0.03589757951590318,416.5016613922108,54.54388873852338,3.0064968250892443
3.5610509770583635e-05,0.036147229445889176,417.089970465978,54.54388873852338,3.0064968250892443
3.6253745541979233e-05,0.036800160032006396,418.62118143087554,54.54388873852338,3.0064968250892443
3.687806261421615e-05,0.03743388677735547,420.0972561781524,54.54388873852338,3.0064968250892443
3.7237517898231336e-05,0.03779875975195039,420.9426962440376,54.54388873852338,3.0064968250892443
3.7805078872992164e-05,0.038374874974995005,422.27115002267993,54.54388873852338,3.0064968250892443
3.859966423765732e-05,0.039181436287257454,424.1179915093782,54.54388873852338,3.0064968250892443
3.897803822083119e-05,0.03956551310262052,424.9922231992192,54.54388873852338,3.0064968250892443
3.9167225212418145e-05,0.03975755151030207,425.428097441051,54.54388873852338,3.0064968250892443
3.9299656106528995e-05,0.03989197839567914,425.7327209883912,54.54388873852338,3.0064968250892443
4.003748537371806e-05,0.040640928185637124,427.4226371485431,54.54388873852338,3.0064968250892443
4.052937155184412e-05,0.04114022804560913,428.5425051061653,54.54388873852338,3.0064968250892443
4.0661802445954976e-05,0.0412746549309862,428.8431007733591,54.54388873852338,3.0064968250892443
4.1021257729970164e-05,0.04163952790558112,429.6570848198562,54.54388873852338,3.0064968250892443
4.1096932526604934e-05,0.04171634326865373,429.828094889036,54.54388873852338,3.0064968250892443
4.168341220052446e-05,0.0423116623324665,431.14928421302363,54.54388873852338,3.0064968250892443
4.200503008622225e-05,0.0426381276255251,431.87072879167374,54.54388873852338,3.0064968250892443
4.2459078866030915e-05,0.04309901980396079,432.88558199744733,54.54388873852338,3.0064968250892443
4.259150976014178e-05,0.04323344668933787,433.18078243109534,54.54388873852338,3.0064968250892443
4.3026639840791736e-05,0.0436751350270054,434.14821607178106,54.54388873852338,3.0064968250892443
4.308339593826782e-05,0.043732746549309864,434.2741211693165,54.54388873852338,3.0064968250892443
4.3802306506298205e-05,0.044462492498499706,435.86336103900953,54.54388873852338,3.0064968250892443
4.389690000209167e-05,0.04455851170234047,436.0717116379535,54.54388873852338,3.0064968250892443
4.406716829451991e-05,0.04473134626925385,436.44630199985016,54.54388873852338,3.0064968250892443
4.4748241464232905e-05,0.045422684536907385,437.9390530113812,54.54388873852338,3.0064968250892443
4.5296883739835036e-05,0.04597959591918384,439.13511306625503,54.54388873852338,3.0064968250892443
4.5637420324691526e-05,0.0463252650530106,439.87465404906646,54.54388873852338,3.0064968250892443
4.60347130070241e-05,0.046728545709141825,440.7347372835391,54.54388873852338,3.0064968250892443
4.6242818697769736e-05,0.04693978795759152,441.184101482397,54.54388873852338,3.0064968250892443
4.699956666411751e-05,0.04770794158831766,442.81154667514613,54.54388873852338,3.0064968250892443
4.722659105402184e-05,0.04793838767753551,443.29778323265316,54.54388873852338,3.0064968250892443
4.76428024355131e-05,0.04836087217443488,444.1868559018336,54.54388873852338,3.0064968250892443
4.788874552457612e-05,0.04861052210442088,444.7107932609827,54.54388873852338,3.0064968250892443
4.8872517880828223e-05,0.049609121824364874,446.7961329798547,54.54388873852338,3.0064968250892443
4.9326566660636886e-05,0.05007001400280056,447.75306963753883,54.54388873852338,3.0064968250892443
4.953467235138252e-05,0.05028125625125025,448.19051690908816,54.54388873852338,3.0064968250892443
4.9629265847175994e-05,0.05037727545509102,448.38911957939933,54.54388873852338,3.0064968250892443
5.0234664220254204e-05,0.050991798359671936,449.6566986440693,54.54388873852338,3.0064968250892443
5.097249348744327e-05,0.05174074814962992,451.19353393798633,54.54388873852338,3.0064968250892443
5.1350867470617157e-05,0.052124824964993,451.97828764102485,54.54388873852338,3.0064968250892443
5.176707885210844e-05,0.052547309461892386,452.8389166344688,54.54388873852338,3.0064968250892443
5.210761543696493e-05,0.05289297859571915,453.5410621608757,54.54388873852338,3.0064968250892443
5.2467070720980115e-05,0.05325785157031407,454.28027706487626,54.54388873852338,3.0064968250892443
5.352651787386699e-05,0.05433326665333067,456.44761142941593,54.54388873852338,3.0064968250892443
5.3923810556199564e-05,0.0547365473094619,457.2560403136099,54.54388873852338,3.0064968250892443
5.5134607302355984e-05,0.05596559311862373,459.7056152948846,54.54388873852338,3.0064968250892443
5.526703819646684e-05,0.0561000200040008,459.97225857647516,54.54388873852338,3.0064968250892443
5.560757478132333e-05,0.05644568913782756,460.6567710427611,54.54388873852338,3.0064968250892443
5.579676177291028e-05,0.05663772754550911,461.03634928269236,54.54388873852338,3.0064968250892443
5.587243656954505e-05,0.05671454290858172,461.18803999691477,54.54388873852338,3.0064968250892443
5.661026583673412e-05,0.0574634926985397,462.66284929938075,54.54388873852338,3.0064968250892443
5.700755851906671e-05,0.05786677335467094,463.45387148438454,54.54388873852338,3.0064968250892443
5.7385932502240586e-05,0.05825085017003401,464.20522950150314,54.54388873852338,3.0064968250892443
5.7442688599716666e-05,0.05830846169233847,464.31776634201987,54.54388873852338,3.0064968250892443
5.787781868036663e-05,0.058750150030006,465.1791127653154,54.54388873852338,3.0064968250892443
5.857781054923831e-05,0.05946069213842768,466.5594765745584,54.54388873852338,3.0064968250892443
5.941023331222086e-05,0.06030566113222645,468.1926444226575,54.54388873852338,3.0064968250892443
5.956158290549041e-05,0.06045929185837168,468.48862271964896,54.54388873852338,3.0064968250892443
5.9883200791188203e-05,0.06078575715143028,469.11660445792825,54.54388873852338,3.0064968250892443
6.016698127856863e-05,0.061073814762952594,469.66961446413114,54.54388873852338,3.0064968250892443
6.045076176594903e-05,0.06136187237447489,470.22160816441334,54.54388873852338,3.0064968250892443
6.092372924491639e-05,0.06184196839367874,471.1393571692609,54.54388873852338,3.0064968250892443
6.101832274070986e-05,0.061937987597519506,471.3225730757227,54.54388873852338,3.0064968250892443
6.12075097322968e-05,0.06213002600520104,471.6886729120295,54.54388873852338,3.0064968250892443
6.192642030032718e-05,0.06285977195439088,473.07584591306374,54.54388873852338,3.0064968250892443
6.209668859275542e-05,0.06303260652130425,473.4034652871658,54.54388873852338,3.0064968250892443
6.273992436415103e-05,0.06368553710742149,474.6379894653263,54.54388873852338,3.0064968250892443
6.343991623302271e-05,0.06439607921584317,475.9758469536745,54.54388873852338,3.0064968250892443
6.355342842797488e-05,0.0645113022604521,476.192253163585,54.54388873852338,3.0064968250892443
6.370477802124443e-05,0.06466493298659733,476.48056043337675,54.54388873852338,3.0064968250892443
6.431017639432264e-05,0.06527945589117824,477.63112817289795,54.54388873852338,3.0064968250892443
6.465071297917913e-05,0.065625125025005,478.27646606068924,54.54388873852338,3.0064968250892443
6.485881866992477e-05,0.0658363672734547,478.6701866467435,54.54388873852338,3.0064968250892443
6.514259915730517e-05,0.066124424884977,479.20628528439516,54.54388873852338,3.0064968250892443
6.548313574216168e-05,0.06647009401880376,479.8484028828347,54.54388873852338,3.0064968250892443
6.557772923795515e-05,0.06656611322264454,480.02653759457127,54.54388873852338,3.0064968250892443
6.610745281439858e-05,0.06710382076415283,481.022246254223,54.54388873852338,3.0064968250892443
6.618312761103337e-05,0.06718063612722545,481.1642359199679,54.54388873852338,3.0064968250892443
6.623988370850945e-05,0.06723824764952992,481.2706866207711,54.54388873852338,3.0064968250892443
6.661825769168332e-05,0.06762232446489298,481.97945109131604,54.54388873852338,3.0064968250892443
6.709122517065068e-05,0.06810242048409683,482.8632027670362,54.54388873852338,3.0064968250892443
6.739392435718979e-05,0.06840968193638729,483.42752895551274,54.54388873852338,3.0064968250892443
6.750743655214195e-05,0.0685249049809962,483.63889631466344,54.54388873852338,3.0064968250892443
6.758311134877672e-05,0.06860172034406882,483.7797308872978,54.54388873852338,3.0064968250892443
6.792364793363321e-05,0.06894738947789558,484.41272692439736,54.54388873852338,3.0064968250892443
6.820742842101362e-05,0.06923544708941788,484.93927872619196,54.54388873852338,3.0064968250892443
6.845337151007667e-05,0.06948509701940389,485.39493289476144,54.54388873852338,3.0064968250892443
6.885066419240924e-05,0.06988837767553512,486.12964322726236,54.54388873852338,3.0064968250892443
6.964524955707439e-05,0.07069493898779756,487.5941223329739,54.54388873852338,3.0064968250892443
6.99101113452961e-05,0.07096379275855172,488.0808320812506,54.54388873852338,3.0064968250892443
7.051550971837432e-05,0.07157831566313264,489.1906191038237,54.54388873852338,3.0064968250892443
7.064794061248517e-05,0.0717127425485097,489.4328889722517,54.54388873852338,3.0064968250892443
7.089388370154819e-05,0.0719623924784957,489.8823493529709,54.54388873852338,3.0064968250892443
7.149928207462641e-05,0.07257691538307662,490.9861304011877,54.54388873852338,3.0064968250892443
7.212359914686332e-05,0.0732106421284257,492.1205937663715,54.54388873852338,3.0064968250892443
7.229386743929156e-05,0.07338347669533907,492.4293273574674,54.54388873852338,3.0064968250892443
7.257764792667198e-05,0.07367153430686138,492.9432539031017,54.54388873852338,3.0064968250892443
7.293710321068717e-05,0.0740364072814563,493.5931038898928,54.54388873852338,3.0064968250892443
7.312629020227411e-05,0.07422844568913783,493.9346284474926,54.54388873852338,3.0064968250892443
7.329655849470235e-05,0.07440128025605121,494.24170603673764,54.54388873852338,3.0064968250892443
7.350466418544798e-05,0.0746125225045009,494.6166455435996,54.54388873852338,3.0064968250892443
7.392087556693926e-05,0.07503500700140028,495.36528487924926,54.54388873852338,3.0064968250892443
7.44505991433827e-05,0.07557271454290859,496.31572526636626,54.54388873852338,3.0064968250892443
7.477221702908049e-05,0.0758991798359672,496.8914917436313,54.54388873852338,3.0064968250892443
7.50749162156196e-05,0.07620644128825765,497.43250793639595,54.54388873852338,3.0064968250892443
7.577490808449128e-05,0.07691698339667934,498.6803600122089,54.54388873852338,3.0064968250892443
7.609652597018909e-05,0.07724344868973795,499.25218934977886,54.54388873852338,3.0064968250892443
7.63424690592521e-05,0.07749309861972395,499.68883485770834,54.54388873852338,3.0064968250892443
7.645598125420427e-05,0.07760832166433287,499.89017848757004,54.54388873852338,3.0064968250892443
7.677759913990207e-05,0.07793478695739148,500.46001997667923,54.54388873852338,3.0064968250892443
7.706137962728249e-05,0.07822284456891379,500.96204863939226,54.54388873852338,3.0064968250892443
7.73640788138216e-05,0.07853010602120425,501.49675182917815,54.54388873852338,3.0064968250892443
7.781812759363025e-05,0.07899099819963994,502.29727930067577,54.54388873852338,3.0064968250892443
7.804515198353458e-05,0.07922144428885777,502.6968597726664,54.54388873852338,3.0064968250892443
7.855595686081932e-05,0.07973994798959792,503.59426213623726,54.54388873852338,3.0064968250892443
7.936946092464317e-05,0.08056571314262853,505.0187744756478,54.54388873852338,3.0064968250892443
7.952081051791273e-05,0.08071934386877376,505.28317060019754,54.54388873852338,3.0064968250892443
7.978567230613444e-05,0.08098819763952791,505.74539206667197,54.54388873852338,3.0064968250892443
7.986134710276922e-05,0.08106501300260052,505.8773453784346,54.54388873852338,3.0064968250892443
8.016404628930832e-05,0.08137227445489098,506.4046717159742,54.54388873852338,3.0064968250892443
8.033431458173658e-05,0.08154510902180437,506.70095150808726,54.54388873852338,3.0064968250892443
8.05613389716409e-05,0.0817755551110222,507.0956105476172,54.54388873852338,3.0064968250892443
8.101538775144956e-05,0.08223644728945789,507.8836298027074,54.54388873852338,3.0064968250892443
8.122349344219519e-05,0.08244768953790758,508.24422948043787,54.54388873852338,3.0064968250892443
8.135592433630606e-05,0.08258211642328467,508.4735144089206,54.54388873852338,3.0064968250892443
8.167754222200385e-05,0.08290858171634327,509.0297440760431,54.54388873852338,3.0064968250892443
8.171537962032123e-05,0.08294698939787958,509.0951266549728,54.54388873852338,3.0064968250892443
8.215050970097121e-05,0.08338867773554712,509.84617965770167,54.54388873852338,3.0064968250892443
8.279374547236681e-05,0.08404160832166434,510.9535962348485,54.54388873852338,3.0064968250892443
8.396670482020585e-05,0.08523224644928987,512.9644030568237,54.54388873852338,3.0064968250892443
8.419372921011017e-05,0.0854626925385077,513.3523229398246,54.54388873852338,3.0064968250892443
8.472345278655361e-05,0.08600040008001601,514.2558863517603,54.54388873852338,3.0064968250892443
8.527209506215574e-05,0.08655731146229247,515.1894002224235,54.54388873852338,3.0064968250892443
8.546128205374268e-05,0.086749349869974,515.5107580422601,54.54388873852338,3.0064968250892443
8.57072251428057e-05,0.08699899979996,515.9281087352084,54.54388873852338,3.0064968250892443
8.582073733775787e-05,0.08711422284456892,516.1205745743497,54.54388873852338,3.0064968250892443
8.616127392261436e-05,0.08745989197839568,516.6973772840907,54.54388873852338,3.0064968250892443
8.655856660494693e-05,0.0878631726345269,517.3691912772746,54.54388873852338,3.0064968250892443
8.66909974990578e-05,0.08799759951990399,517.5928618946126,54.54388873852338,3.0064968250892443
8.693694058812083e-05,0.08824724944988999,518.0078969651212,54.54388873852338,3.0064968250892443
8.82612495292294e-05,0.08959151830366073,520.234879157258,54.54388873852338,3.0064968250892443
8.863962351240329e-05,0.08997559511902381,520.8687612698275,54.54388873852338,3.0064968250892443
8.89612413981011e-05,0.09030206041208243,521.406731795818,54.54388873852338,3.0064968250892443
8.924502188548151e-05,0.09059011802360473,521.8807820839565,54.54388873852338,3.0064968250892443
8.988825765687711e-05,0.09124304860972195,522.9531250000506,54.54388873852338,3.0064968250892443
9.043689993247923e-05,0.0917999599919984,523.8654076352407,54.54388873852338,3.0064968250892443
9.05693308265901e-05,0.09193438687737548,524.0852901010308,54.54388873852338,3.0064968250892443
9.068284302154225e-05,0.0920496099219844,524.273661004444,54.54388873852338,3.0064968250892443
9.094770480976397e-05,0.09231846369273855,524.7128358559378,54.54388873852338,3.0064968250892443
9.143959098789002e-05,0.09281776355271054,525.5271252115441,54.54388873852338,3.0064968250892443
9.155310318284219e-05,0.09293298659731947,525.7147953242047,54.54388873852338,3.0064968250892443
9.183688367022259e-05,0.09322104420884177,526.1835740278092,54.54388873852338,3.0064968250892443
9.259363163657036e-05,0.09398919783956791,527.4308968827419,54.54388873852338,3.0064968250892443
9.265038773404644e-05,0.09404680936187237,527.5242855191756,54.54388873852338,3.0064968250892443
9.302876171722034e-05,0.09443088617723545,528.1463072350912,54.54388873852338,3.0064968250892443
9.329362350544205e-05,0.09469973994798961,528.5811354968938,54.54388873852338,3.0064968250892443
9.346389179787029e-05,0.09487257451490298,528.8604137377426,54.54388873852338,3.0064968250892443
9.37855096835681e-05,0.0951990398079616,529.3873985250665,54.54388873852338,3.0064968250892443
9.446658285328107e-05,0.09589037807561512,530.5010453924415,54.54388873852338,3.0064968250892443
9.554494870532665e-05,0.09698499699939989,532.2579369175294,54.54388873852338,3.0064968250892443
9.577197309523097e-05,0.09721544308861772,532.626821490844,54.54388873852338,3.0064968250892443
9.582872919270706e-05,0.09727305461092219,532.7189893293587,54.54388873852338,3.0064968250892443
9.598007878597662e-05,0.09742668533706741,532.9646662107444,54.54388873852338,3.0064968250892443
9.637737146830919e-05,0.09782996599319864,533.6088502492613,54.54388873852338,3.0064968250892443
9.660439585821352e-05,0.09806041208241649,533.9764904237978,54.54388873852338,3.0064968250892443
9.703952593886348e-05,0.09850210042008402,534.6801936420362,54.54388873852338,3.0064968250892443
9.722871293045042e-05,0.09869413882776555,534.9857676047541,54.54388873852338,3.0064968250892443
9.741789992203737e-05,0.0988861772354471,535.2911097675735,54.54388873852338,3.0064968250892443
9.751249341783084e-05,0.09898219643928786,535.4436941195985,54.54388873852338,3.0064968250892443
9.779627390521125e-05,0.09927025405081016,535.9011011925592,54.54388873852338,3.0064968250892443
9.800437959595689e-05,0.09948149629925986,536.2362041249784,54.54388873852338,3.0064968250892443