File: datasets/aisi_316_L/data/M1/train_25.csv
Time(s),Strain(%),Stress(MPa),Temp(C),Log_SR(s-1)
0.0,0.0,0.0,229.36749380641155,4.156853308030779
2.341455829131765e-09,3.36e-05,6.1669965,229.36749380641155,4.156853308030779
3.177690053821681e-09,4.56e-05,8.36949525,229.36749380641155,4.156853308030779
5.017405348139497e-09,7.2e-05,13.214992500000001,229.36749380641155,4.156853308030779
7.693354867147229e-09,0.0001104,20.2629885,229.36749380641155,4.156853308030779
8.529589091837144e-09,0.0001224,22.46548725,229.36749380641155,4.156853308030779
1.0425053334467621e-08,0.0001496,27.45781775,229.36749380641155,4.156853308030779
1.087104492096891e-08,0.000156,28.63248375,229.36749380641155,4.156853308030779
1.1205538610844877e-08,0.0001608,29.51348325,229.36749380641155,4.156853308030779
1.1372785455782858e-08,0.00016319999999999998,29.953982999999997,229.36749380641155,4.156853308030779
1.3602743388289303e-08,0.0001952,35.827313000000004,229.36749380641155,4.156853308030779
1.4606224457917202e-08,0.0002096,38.4703115,229.36749380641155,4.156853308030779
1.5330960785981794e-08,0.00021999999999999998,40.37914375,229.36749380641155,4.156853308030779
1.6836182390423645e-08,0.0002416,44.3436415,229.36749380641155,4.156853308030779
1.756091871848824e-08,0.000252,46.25247375,229.36749380641155,4.156853308030779
1.850865083980348e-08,0.0002656,48.748639000000004,229.36749380641155,4.156853308030779
1.9679378754369358e-08,0.0002824,51.832137249999995,229.36749380641155,4.156853308030779
1.979087665099468e-08,0.00028399999999999996,52.125803749999996,229.36749380641155,4.156853308030779
2.1519094048687175e-08,0.00030879999999999997,56.677634499999996,229.36749380641155,4.156853308030779
2.3693303032880955e-08,0.00033999999999999997,62.40413124999999,229.36749380641155,4.156853308030779
2.397204777444426e-08,0.00034399999999999996,63.13829749999999,229.36749380641155,4.156853308030779
2.4139294619382245e-08,0.00034639999999999996,63.578797249999994,229.36749380641155,4.156853308030779
2.5142775689010146e-08,0.0003608,66.22179575,229.36749380641155,4.156853308030779
2.5477269378886113e-08,0.0003656,67.10279525,229.36749380641155,4.156853308030779
2.6257754655263368e-08,0.0003768,69.15846075,229.36749380641155,4.156853308030779
2.7316984673203927e-08,0.000392,71.9482925,229.36749380641155,4.156853308030779
2.9658440502335693e-08,0.0004256,78.115289,229.36749380641155,4.156853308030779
3.138665790002819e-08,0.0004504,82.66711975,229.36749380641155,4.156853308030779
3.1776900538216813e-08,0.00045599999999999997,83.6949525,229.36749380641155,4.156853308030779
3.417410531566124e-08,0.0004904,90.00878225,229.36749380641155,4.156853308030779
3.495459059203849e-08,0.0005015999999999999,92.06444774999999,229.36749380641155,4.156853308030779
3.573507586841575e-08,0.0005128,94.12011325,229.36749380641155,4.156853308030779
3.5958071661666394e-08,0.000516,94.70744624999999,229.36749380641155,4.156853308030779
3.6627059041418326e-08,0.0005256,96.46944524999999,229.36749380641155,4.156853308030779
3.7797786955984205e-08,0.0005424,99.5529435,229.36749380641155,4.156853308030779
3.8912765922237436e-08,0.0005584,102.4896085,229.36749380641155,4.156853308030779
3.9303008560426056e-08,0.0005639999999999999,103.51744124999999,229.36749380641155,4.156853308030779
4.15329664929325e-08,0.000596,109.39077124999999,229.36749380641155,4.156853308030779
4.314968599399967e-08,0.0006192,113.6489355,229.36749380641155,4.156853308030779
4.4376162856878215e-08,0.0006368,116.879267,229.36749380641155,4.156853308030779
4.487790339169216e-08,0.0006439999999999999,118.20076624999999,229.36749380641155,4.156853308030779
4.6829116582635305e-08,0.000672,123.33993,229.36749380641155,4.156853308030779
4.788834660057586e-08,0.0006872,126.12976175,229.36749380641155,4.156853308030779
4.799984449720118e-08,0.0006887999999999999,126.42342824999999,229.36749380641155,4.156853308030779
4.833433818707715e-08,0.0006935999999999999,127.30442774999999,229.36749380641155,4.156853308030779
4.8557333980327795e-08,0.0006967999999999999,127.89176074999999,229.36749380641155,4.156853308030779
4.922632136007973e-08,0.0007063999999999999,129.65375974999998,229.36749380641155,4.156853308030779
4.9560815049955694e-08,0.0007111999999999999,130.53475924999998,229.36749380641155,4.156853308030779
5.034130032633295e-08,0.0007224,132.59042475,229.36749380641155,4.156853308030779
5.078729191283424e-08,0.0007287999999999999,133.76509074999998,229.36749380641155,4.156853308030779
5.173502403414948e-08,0.0007423999999999999,136.261256,229.36749380641155,4.156853308030779
5.307299879365334e-08,0.0007616,139.785254,229.36749380641155,4.156853308030779
5.3909233018343254e-08,0.0007735999999999999,141.98775275,229.36749380641155,4.156853308030779
5.563745041603576e-08,0.0007984,146.5395835,229.36749380641155,4.156853308030779
5.6752429382288977e-08,0.0008144,149.4762485,229.36749380641155,4.156853308030779
5.6975425175539616e-08,0.0008175999999999999,150.0635815,229.36749380641155,4.156853308030779
5.725416991710292e-08,0.0008215999999999999,150.79774774999998,229.36749380641155,4.156853308030779
5.7978906245167515e-08,0.000832,152.70658,229.36749380641155,4.156853308030779
5.853639572829413e-08,0.0008399999999999999,154.17491249999998,229.36749380641155,4.156853308030779
6.059910681586258e-08,0.0008696,159.60774275,229.36749380641155,4.156853308030779
6.182558367874113e-08,0.0008872,162.83807425,229.36749380641155,4.156853308030779
6.232732421355508e-08,0.0008944,164.1595735,229.36749380641155,4.156853308030779
6.277331580005637e-08,0.0009008,165.3342395,229.36749380641155,4.156853308030779
6.377679686968427e-08,0.0009151999999999999,167.97723799999997,229.36749380641155,4.156853308030779
6.41670395078729e-08,0.0009207999999999999,169.00507075,229.36749380641155,4.156853308030779
6.461303109437419e-08,0.0009272,170.17973675,229.36749380641155,4.156853308030779
6.528201847412612e-08,0.0009368,171.94173575,229.36749380641155,4.156853308030779
6.600675480219072e-08,0.0009471999999999999,173.85056799999998,229.36749380641155,4.156853308030779
6.806946588975917e-08,0.0009767999999999999,179.28339824999998,229.36749380641155,4.156853308030779
6.862695537288577e-08,0.0009847999999999999,180.75173074999998,229.36749380641155,4.156853308030779
7.046667066720359e-08,0.0010111999999999999,185.59722799999997,229.36749380641155,4.156853308030779
7.130290489189352e-08,0.0010232,187.79972675,229.36749380641155,4.156853308030779
7.236213490983407e-08,0.0010383999999999999,190.58955849999998,229.36749380641155,4.156853308030779
7.314262018621133e-08,0.0010496,192.64522399999998,229.36749380641155,4.156853308030779
7.370010966933793e-08,0.0010576,194.1135565,229.36749380641155,4.156853308030779
7.43133481007772e-08,0.0010664,195.72872224999998,229.36749380641155,4.156853308030779
7.470359073896585e-08,0.001072,196.75655500000002,229.36749380641155,4.156853308030779
7.60415654984697e-08,0.0010911999999999999,200.28055299999997,229.36749380641155,4.156853308030779
7.698929761978495e-08,0.0011048,202.77671825,229.36749380641155,4.156853308030779
7.87732639657901e-08,0.0011304,207.47538225,229.36749380641155,4.156853308030779
7.972099608710535e-08,0.001144,209.9715475,229.36749380641155,4.156853308030779
8.044573241516993e-08,0.0011543999999999999,211.88037974999997,229.36749380641155,4.156853308030779
8.094747294998388e-08,0.0011616,213.20187900000002,229.36749380641155,4.156853308030779
8.122621769154718e-08,0.0011656,213.93604524999998,229.36749380641155,4.156853308030779
8.16164603297358e-08,0.0011711999999999998,214.96387799999997,229.36749380641155,4.156853308030779
8.245269455442573e-08,0.0011832,217.16637674999998,229.36749380641155,4.156853308030779
8.340042667574097e-08,0.0011968,219.662542,229.36749380641155,4.156853308030779
8.484989933187016e-08,0.0012175999999999999,221.29281387813802,229.36749380641155,4.156853308030779
8.624362303968668e-08,0.0012376,221.42476024449607,229.36749380641155,4.156853308030779
8.73586020059399e-08,0.0012536,221.52971955421822,229.36749380641155,4.156853308030779
8.864082781713111e-08,0.001272,221.64977902939611,229.36749380641155,4.156853308030779
8.93655641451957e-08,0.0012824,221.71733909043903,229.36749380641155,4.156853308030779
9.064778995638691e-08,0.0013008,221.8363472936095,229.36749380641155,4.156853308030779
9.10937815428882e-08,0.0013072,221.87758732318332,229.36749380641155,4.156853308030779
9.204151366420344e-08,0.0013208,221.96496183961847,229.36749380641155,4.156853308030779
9.371398211358327e-08,0.0013448,222.1183010057827,229.36749380641155,4.156853308030779
9.527495266633777e-08,0.0013671999999999998,222.2604574116782,229.36749380641155,4.156853308030779
9.66686763741543e-08,0.0013871999999999999,222.38661699543667,229.36749380641155,4.156853308030779
9.728191480559357e-08,0.0013959999999999999,222.44190226850273,229.36749380641155,4.156853308030779
9.79509021853455e-08,0.0014056,222.5020586936908,229.36749380641155,4.156853308030779
9.962337063472534e-08,0.0014295999999999998,222.65175294659036,229.36749380641155,4.156853308030779
1.002366090661646e-07,0.0014383999999999998,222.70639485902197,229.36749380641155,4.156853308030779
1.0107284329085452e-07,0.0014504,222.78069691386258,229.36749380641155,4.156853308030779
1.0174183067060646e-07,0.00146,222.83996608186396,229.36749380641155,4.156853308030779
1.0213207330879508e-07,0.0014655999999999998,222.87446957442282,229.36749380641155,4.156853308030779
1.0302405648179766e-07,0.0014784,222.95314220717313,229.36749380641155,4.156853308030779
1.0408328649973823e-07,0.0014935999999999999,223.04622176190273,229.36749380641155,4.156853308030779
1.0737247445018523e-07,0.0015408,223.33293107922356,229.36749380641155,4.156853308030779
1.0843170446812578e-07,0.0015559999999999999,223.424529316941,229.36749380641155,4.156853308030779
1.0898919395125239e-07,0.0015639999999999999,223.47259871347745,229.36749380641155,4.156853308030779
1.1038291765906893e-07,0.001584,223.592354567988,229.36749380641155,4.156853308030779
1.1261287559157538e-07,0.001616,223.78274456519316,229.36749380641155,4.156853308030779
1.1378360350614125e-07,0.0016328,223.88211040030794,229.36749380641155,4.156853308030779
1.1551182090383375e-07,0.0016576,224.02806763781683,229.36749380641155,4.156853308030779
1.1690554461165027e-07,0.0016776,224.14515569216337,229.36749380641155,4.156853308030779
1.1868951095765543e-07,0.0017032,224.29423704834542,229.36749380641155,4.156853308030779
1.1974874097559598e-07,0.0017184,224.3823406528141,229.36749380641155,4.156853308030779
1.2337242261591895e-07,0.0017703999999999999,224.68147556955157,229.36749380641155,4.156853308030779
1.2554663160011275e-07,0.0018016,224.85931204352806,229.36749380641155,4.156853308030779
1.2615987003155202e-07,0.0018104,224.90925336186382,229.36749380641155,4.156853308030779
1.2627136792817734e-07,0.001812,224.918323420799,229.36749380641155,4.156853308030779
1.2822258111912048e-07,0.0018399999999999998,225.076547309783,229.36749380641155,4.156853308030779
1.3039679010331426e-07,0.0018712,225.25175190150745,229.36749380641155,4.156853308030779
1.3229225434594475e-07,0.0018984,225.40356684034035,229.36749380641155,4.156853308030779
1.3468945912338916e-07,0.0019328,225.59435865621464,229.36749380641155,4.156853308030779
1.360831828312057e-07,0.0019528,225.7046753142416,229.36749380641155,4.156853308030779
1.3652917441770698e-07,0.0019592,225.73988346747836,229.36749380641155,4.156853308030779
1.3786714917721084e-07,0.0019784,225.84523977852217,229.36749380641155,4.156853308030779
1.4076609448946924e-07,0.00202,226.07215344950063,229.36749380641155,4.156853308030779
1.4171382661078445e-07,0.0020336,226.1459404946653,229.36749380641155,4.156853308030779
1.42940303473663e-07,0.0020512,226.24114456181277,229.36749380641155,4.156853308030779
1.437765376983529e-07,0.0020632,226.30587383896042,229.36749380641155,4.156853308030779
1.4433402718147953e-07,0.0020712,226.34894513883154,229.36749380641155,4.156853308030779
1.457834998376087e-07,0.002092,226.46062796463266,229.36749380641155,4.156853308030779
1.4678698090723662e-07,0.0021064,226.53769328412426,229.36749380641155,4.156853308030779
1.4740021933867586e-07,0.0021152,226.58468761796448,229.36749380641155,4.156853308030779
1.4806920671842784e-07,0.0021248,226.6358672862626,229.36749380641155,4.156853308030779
1.483479514599911e-07,0.0021287999999999997,226.6571655230117,229.36749380641155,4.156853308030779
1.4884969199480507e-07,0.002136,226.69546305996394,229.36749380641155,4.156853308030779
1.4935143252961903e-07,0.0021432,226.73371028368038,229.36749380641155,4.156853308030779
1.515256415138128e-07,0.0021744,226.89887254553085,229.36749380641155,4.156853308030779
1.5174863730706344e-07,0.0021776,226.9157598389918,229.36749380641155,4.156853308030779
1.5264062048006603e-07,0.0021904,226.98321245503206,229.36749380641155,4.156853308030779
1.538113483946319e-07,0.0022072,227.07151118129192,229.36749380641155,4.156853308030779
1.5403434418788254e-07,0.0022104,227.08830022747674,229.36749380641155,4.156853308030779
1.5498207630919777e-07,0.002224,227.15954818134614,229.36749380641155,4.156853308030779
1.563758000170143e-07,0.002244,227.26401668267033,229.36749380641155,4.156853308030779
1.5648729791363963e-07,0.0022456,227.27235844325563,229.36749380641155,4.156853308030779
1.5776952372483085e-07,0.002264,227.3681226828329,229.36749380641155,4.156853308030779
1.594419921742107e-07,0.002288,227.4925776316062,229.36749380641155,4.156853308030779
1.5999948165733727e-07,0.002296,227.53394933721918,229.36749380641155,4.156853308030779
1.6050122219215125e-07,0.0023032,227.57113582947966,229.36749380641155,4.156853308030779
1.6117020957190317e-07,0.0023128,227.62064737206128,229.36749380641155,4.156853308030779
1.6217369064153105e-07,0.0023271999999999998,227.69476466936337,229.36749380641155,4.156853308030779
1.6440364857403753e-07,0.0023592,227.85883240202344,229.36749380641155,4.156853308030779
1.6496113805716412e-07,0.0023672,227.899713441632,229.36749380641155,4.156853308030779
1.6574162333354136e-07,0.0023783999999999997,227.9568564916913,229.36749380641155,4.156853308030779
1.6646635966160598e-07,0.0023888,228.00982399806568,229.36749380641155,4.156853308030779
1.6707959809304523e-07,0.0023975999999999997,228.05457244999087,229.36749380641155,4.156853308030779
1.6819457705929845e-07,0.0024135999999999997,228.1357695097367,229.36749380641155,4.156853308030779
1.693095560255517e-07,0.0024296,228.21675691598526,229.36749380641155,4.156853308030779
1.696997986637403e-07,0.0024351999999999998,228.2450533331469,229.36749380641155,4.156853308030779
1.7009004130192894e-07,0.0024408,228.2733243841225,229.36749380641155,4.156853308030779
1.7075902868168086e-07,0.0024503999999999997,228.32173026041585,229.36749380641155,4.156853308030779
1.7181825869962144e-07,0.0024656,228.39822191388004,229.36749380641155,4.156853308030779
1.72877488717562e-07,0.0024808,228.4745298792844,229.36749380641155,4.156853308030779
1.7533044244331908e-07,0.002516,228.65054641144513,229.36749380641155,4.156853308030779
1.780063919623268e-07,0.0025544,228.84147269773752,229.36749380641155,4.156853308030779
1.7839663460051544e-07,0.0025599999999999998,228.869222306287,229.36749380641155,4.156853308030779
1.7895412408364204e-07,0.002568,228.90882357254307,229.36749380641155,4.156853308030779
1.7923286882520536e-07,0.002572,228.92860616095783,229.36749380641155,4.156853308030779
1.804593456880839e-07,0.0025896,229.0155073954462,229.36749380641155,4.156853308030779
1.8123983096446117e-07,0.0026008,229.07068827251982,229.36749380641155,4.156853308030779
1.8224331203408905e-07,0.0026152,229.141499129533,229.36749380641155,4.156853308030779
1.8307954625877896e-07,0.0026271999999999997,229.20039209294143,229.36749380641155,4.156853308030779
1.840830273284069e-07,0.0026416,229.2709253491405,229.36749380641155,4.156853308030779
1.8441752101828282e-07,0.0026463999999999997,229.29440309095187,229.36749380641155,4.156853308030779
1.8608998946766267e-07,0.0026704,229.41154360665155,229.36749380641155,4.156853308030779
1.8675897684741462e-07,0.00268,229.45828476145604,229.36749380641155,4.156853308030779
1.8726071738222855e-07,0.0026872,229.4932977877568,229.36749380641155,4.156853308030779
1.8843144529679442e-07,0.002704,229.5748528749863,229.36749380641155,4.156853308030779
1.8943492636642232e-07,0.0027183999999999997,229.6446000754542,229.36749380641155,4.156853308030779
1.9027116059111226e-07,0.0027304,229.70261274021334,229.36749380641155,4.156853308030779
1.9110739481580217e-07,0.0027424,229.760526054047,229.36749380641155,4.156853308030779
1.9127464166074014e-07,0.0027448,229.77209684794528,229.36749380641155,4.156853308030779
1.920551269371174e-07,0.0027559999999999998,229.82604180089012,229.36749380641155,4.156853308030779
1.9283561221349467e-07,0.0027672,229.87990132361003,229.36749380641155,4.156853308030779
1.935045995932466e-07,0.0027768,229.9259989974735,229.36749380641155,4.156853308030779
1.9456382961118714e-07,0.0027919999999999998,229.99886007085072,229.36749380641155,4.156853308030779
1.969052854403189e-07,0.0028255999999999997,230.1593746857429,229.36749380641155,4.156853308030779
1.9723977913019487e-07,0.0028304,230.18224443041882,229.36749380641155,4.156853308030779
1.9802026440657214e-07,0.0028415999999999997,230.23554842618188,229.36749380641155,4.156853308030779
1.9952548601101397e-07,0.0028631999999999998,230.33811816868896,229.36749380641155,4.156853308030779
2.0030597128739126e-07,0.0028744,230.39118364715827,229.36749380641155,4.156853308030779
2.0097495866714318e-07,0.002884,230.4366041926168,229.36749380641155,4.156853308030779
2.0348366134121291e-07,0.00292,230.6064086317472,229.36749380641155,4.156853308030779
2.043756445142155e-07,0.0029327999999999997,230.6665865330037,229.36749380641155,4.156853308030779
2.06271108756846e-07,0.00296,230.7941255288044,229.36749380641155,4.156853308030779
2.0705159403322323e-07,0.0029712,230.84650863862112,229.36749380641155,4.156853308030779
2.0744183667141186e-07,0.0029768,230.87267131108206,229.36749380641155,4.156853308030779
2.086683135342904e-07,0.0029944,230.9547721688457,229.36749380641155,4.156853308030779
2.105080288286082e-07,0.0030207999999999997,231.07757146325685,229.36749380641155,4.156853308030779
2.116787567431741e-07,0.0030375999999999997,231.15549859690074,229.36749380641155,4.156853308030779
2.1290523360605264e-07,0.0030551999999999997,231.23695647861948,229.36749380641155,4.156853308030779
2.15971425763249e-07,0.0030992,231.4398045898703,229.36749380641155,4.156853308030779
2.1647316629806296e-07,0.0031064,231.4728906909639,229.36749380641155,4.156853308030779
2.1764389421262885e-07,0.0031232,231.54997550353357,229.36749380641155,4.156853308030779
2.1792263895419214e-07,0.0031271999999999997,231.56830517486495,229.36749380641155,4.156853308030779
2.1803413685081746e-07,0.0031287999999999997,231.57563448287948,229.36749380641155,4.156853308030779
2.1859162633394409e-07,0.0031368,231.61225911980296,229.36749380641155,4.156853308030779
2.19427860558634e-07,0.0031487999999999998,231.66712784589484,229.36749380641155,4.156853308030779
2.2020834583501126e-07,0.00316,231.7182651262073,229.36749380641155,4.156853308030779
2.2065433742151252e-07,0.0031663999999999998,231.74745469223978,229.36749380641155,4.156853308030779
2.2149057164620245e-07,0.0031784,231.8021231859348,229.36749380641155,4.156853308030779
2.2489125749327478e-07,0.0032272,232.0236174520972,229.36749380641155,4.156853308030779
2.257274917179647e-07,0.0032392,232.07788268823984,229.36749380641155,4.156853308030779
2.281246964954091e-07,0.0032735999999999998,232.23301020294562,229.36749380641155,4.156853308030779
2.2879368387516105e-07,0.0032832,232.27618796995927,229.36749380641155,4.156853308030779
2.3035465442791556e-07,0.0033055999999999997,232.3767450657357,229.36749380641155,4.156853308030779
2.3197137392898273e-07,0.0033288,232.48061372768575,229.36749380641155,4.156853308030779
2.326961102570473e-07,0.0033391999999999996,232.5270838559209,229.36749380641155,4.156853308030779
2.333093486884866e-07,0.003348,232.56636066295596,229.36749380641155,4.156853308030779
2.3364384237836258e-07,0.0033528,232.58776740513673,229.36749380641155,4.156853308030779
2.3581805136255633e-07,0.003384,232.72662103172598,229.36749380641155,4.156853308030779
2.3592954925918168e-07,0.0033856,232.73372824140733,229.36749380641155,4.156853308030779
2.36208294000745e-07,0.0033896,232.7514905370757,229.36749380641155,4.156853308030779
2.378807624501248e-07,0.0034135999999999997,232.85789314772222,229.36749380641155,4.156853308030779
2.390514903646907e-07,0.0034303999999999997,232.9322014492223,229.36749380641155,4.156853308030779
2.3927448615794133e-07,0.0034335999999999998,232.94633930562946,229.36749380641155,4.156853308030779
2.403337161758819e-07,0.0034487999999999997,233.01342407502153,229.36749380641155,4.156853308030779
2.4122569934888447e-07,0.0034616,233.06982712359948,229.36749380641155,4.156853308030779
2.4222918041851237e-07,0.003476,233.13318341796534,229.36749380641155,4.156853308030779
2.425079251600757e-07,0.00348,233.15076421205598,229.36749380641155,4.156853308030779
2.4334415938476557e-07,0.003492,233.20345936889024,229.36749380641155,4.156853308030779
2.4406889571283016e-07,0.0035023999999999997,233.24907140518965,229.36749380641155,4.156853308030779
2.4574136416221004e-07,0.0035264,233.35412883056316,229.36749380641155,4.156853308030779
2.464661004902746e-07,0.0035367999999999997,233.3995670761599,229.36749380641155,4.156853308030779
2.4797132209471644e-07,0.0035583999999999998,233.49377265473672,229.36749380641155,4.156853308030779
2.483058157845924e-07,0.0035632,233.5146769108167,229.36749380641155,4.156853308030779
2.488075563194064e-07,0.0035704,233.5460127146073,229.36749380641155,4.156853308030779
2.5053577371709887e-07,0.0035952,233.65375901541273,229.36749380641155,4.156853308030779
2.5265423375298e-07,0.0036255999999999997,233.78544050253151,229.36749380641155,4.156853308030779
2.5310022533948126e-07,0.003632,233.81310797204594,229.36749380641155,4.156853308030779
2.535462169259826e-07,0.0036384,233.84075643431294,229.36749380641155,4.156853308030779
2.550514385304244e-07,0.0036599999999999996,233.93393028050878,229.36749380641155,4.156853308030779
2.566124090831789e-07,0.0036823999999999997,234.03032877792668,229.36749380641155,4.156853308030779
2.572256475146182e-07,0.0036912,234.06813701353838,229.36749380641155,4.156853308030779
2.579503838426828e-07,0.0037015999999999998,234.11277418229005,229.36749380641155,4.156853308030779
2.591768607055613e-07,0.0037191999999999998,234.18820274316258,229.36749380641155,4.156853308030779
2.619085591728817e-07,0.0037584,234.35570420149674,229.36749380641155,4.156853308030779
2.6335803182901095e-07,0.0037792,234.4443057774205,229.36749380641155,4.156853308030779
2.6419426605370083e-07,0.0037911999999999998,234.4953355600992,229.36749380641155,4.156853308030779
2.6480750448514013e-07,0.0038,234.5327173741201,229.36749380641155,4.156853308030779
2.6558798976151734e-07,0.0038112,234.58024543570053,229.36749380641155,4.156853308030779
2.663684750378946e-07,0.0038223999999999997,234.62771905668257,229.36749380641155,4.156853308030779
2.6770644979739845e-07,0.0038415999999999997,234.70897638673827,229.36749380641155,4.156853308030779
2.6826393928052507e-07,0.0038496,234.74278684407636,229.36749380641155,4.156853308030779
2.69267420350153e-07,0.003864,234.80357669397787,229.36749380641155,4.156853308030779
2.716646251275974e-07,0.0038983999999999998,234.94844036373027,229.36749380641155,4.156853308030779
2.7205486776578605e-07,0.003904,234.97197555659417,229.36749380641155,4.156853308030779
2.737273362151659e-07,0.003928,235.07269190747138,229.36749380641155,4.156853308030779
2.741175788533545e-07,0.0039336,235.09615782261443,229.36749380641155,4.156853308030779
2.7489806412973175e-07,0.0039448,235.1430506034676,229.36749380641155,4.156853308030779
2.766262815274243e-07,0.0039696,235.24670023543493,229.36749380641155,4.156853308030779
2.7779700944199017e-07,0.0039864,235.31677105729727,229.36749380641155,4.156853308030779
2.8811243841920365e-07,0.0041344268853770755,235.9292741113587,229.36749380641155,4.156853308030779
3.255832258427966e-07,0.004672134426885377,238.0856121387271,229.36749380641155,4.156853308030779
3.4298037714660765e-07,0.004921784356871375,239.05361866784568,229.36749380641155,4.156853308030779
3.938335886500552e-07,0.005651530306061212,241.7789247791665,229.36749380641155,4.156853308030779
4.19260194401779e-07,0.006016403280656131,243.08976922722508,229.36749380641155,4.156853308030779
4.4334855774551734e-07,0.006362072414482897,244.30329702650093,229.36749380641155,4.156853308030779
4.91525284432994e-07,0.007053410682136428,246.65578359941355,229.36749380641155,4.156853308030779
5.008929812888922e-07,0.007187837567513502,247.10257479568722,229.36749380641155,4.156853308030779
5.182901325927032e-07,0.0074374874974994995,247.92377763801989,229.36749380641155,4.156853308030779
5.289960718565869e-07,0.007591118223644729,248.42379215241567,229.36749380641155,4.156853308030779
5.584374048322671e-07,0.008013602720544109,249.77888302804934,229.36749380641155,4.156853308030779
5.785110409520491e-07,0.008301660332066413,250.6868679019791,229.36749380641155,4.156853308030779
6.025994042957874e-07,0.008647329465893179,251.7603864497995,229.36749380641155,4.156853308030779
6.373937069034095e-07,0.009146629325865173,253.28193130008833,229.36749380641155,4.156853308030779
6.588055854311769e-07,0.009453890778155631,254.20217471763397,229.36749380641155,4.156853308030779
6.802174639589443e-07,0.00976115223044609,255.11082486048113,229.36749380641155,4.156853308030779
7.310706754623918e-07,0.010490898179635926,257.2252799752645,229.36749380641155,4.156853308030779
7.431148571342611e-07,0.01066373274654931,257.71757315047427,229.36749380641155,4.156853308030779
7.511443115821739e-07,0.010778955791158232,258.04404090629106,229.36749380641155,4.156853308030779
7.765709173338976e-07,0.01114382876575315,259.0689891962924,229.36749380641155,4.156853308030779
7.805856445578541e-07,0.011201440288057612,259.22961893360815,229.36749380641155,4.156853308030779
8.167181895734615e-07,0.011719943988797759,260.66107074046846,229.36749380641155,4.156853308030779
8.32777098469287e-07,0.011950390078015603,261.2893201184447,229.36749380641155,4.156853308030779
8.541889769970544e-07,0.01225765153030606,262.1196847662074,229.36749380641155,4.156853308030779
8.943362492366183e-07,0.01283376675335067,263.6550578605382,229.36749380641155,4.156853308030779
9.184246125803567e-07,0.013179435887177435,264.56338158107235,229.36749380641155,4.156853308030779
9.277923094362549e-07,0.013313862772554511,264.9141034198974,229.36749380641155,4.156853308030779
9.492041879640224e-07,0.013621124224844969,265.71060815448993,229.36749380641155,4.156853308030779
1.0080868539153828e-06,0.01446609321864373,267.865654497118,229.36749380641155,4.156853308030779
1.032175217259121e-06,0.014811762352470495,268.7330446250772,229.36749380641155,4.156853308030779
1.0803519439465978e-06,0.015503100620124026,270.4444939208523,229.36749380641155,4.156853308030779
1.0990873376583942e-06,0.015771954390878175,271.1019859562993,229.36749380641155,4.156853308030779
1.1164844889622052e-06,0.016021604320864174,271.70861097725253,229.36749380641155,4.156853308030779
1.1472640643458708e-06,0.016463292658531706,272.77291602273624,229.36749380641155,4.156853308030779
1.2021320030732747e-06,0.017250650130026003,274.6429364575225,229.36749380641155,4.156853308030779
1.211499699929173e-06,0.01738507701540308,274.95885197845183,229.36749380641155,4.156853308030779
1.2342498208649257e-06,0.01771154230846169,275.72213511663995,229.36749380641155,4.156853308030779
1.2422792753128387e-06,0.017826765353070616,275.99021655573176,229.36749380641155,4.156853308030779
1.2837647899603881e-06,0.018422084416883377,277.3646836323669,229.36749380641155,4.156853308030779
1.2904560020003156e-06,0.018518103620724147,277.5847392362879,229.36749380641155,4.156853308030779
1.30383842608017e-06,0.01871014202840568,278.02351997448955,229.36749380641155,4.156853308030779
1.3185590925680101e-06,0.01892138427685537,278.5041551145227,229.36749380641155,4.156853308030779
1.3653975768475015e-06,0.01959351870374075,280.01970966702646,229.36749380641155,4.156853308030779
1.4001918794551233e-06,0.02009281856371274,281.13245652043184,229.36749380641155,4.156853308030779
1.4216037579828907e-06,0.0204000800160032,281.8118655232078,229.36749380641155,4.156853308030779
1.4349861820627453e-06,0.020592118423684736,282.2344701058095,229.36749380641155,4.156853308030779
1.4416773941026727e-06,0.020688137627525506,282.44519580353614,229.36749380641155,4.156853308030779
1.483162908750222e-06,0.021283456691338267,283.7432827107673,229.36749380641155,4.156853308030779
1.488515878382164e-06,0.02136027205441088,283.9097402286939,229.36749380641155,4.156853308030779
1.5326778778456843e-06,0.021993998799759953,285.2742187441195,229.36749380641155,4.156853308030779
1.5714869076772625e-06,0.022550910182036407,286.46069675793956,229.36749380641155,4.156853308030779
1.5862075741651027e-06,0.0227621524304861,286.9077437927449,229.36749380641155,4.156853308030779
1.6116341799168265e-06,0.023127025405081016,287.6761235000928,229.36749380641155,4.156853308030779
1.6343843008525795e-06,0.02345349069813963,288.3596226619675,229.36749380641155,4.156853308030779
1.670516845868187e-06,0.023971994398879776,289.43760258579664,229.36749380641155,4.156853308030779
1.7334142390435035e-06,0.024874574914982996,291.2926404717622,229.36749380641155,4.156853308030779
1.7588408447952275e-06,0.025239447889577916,292.03507537422087,229.36749380641155,4.156853308030779
1.7735615112830675e-06,0.025450690138027605,292.462992851749,229.36749380641155,4.156853308030779
1.8056793290747185e-06,0.025911582316463292,293.39185221764393,229.36749380641155,4.156853308030779
1.8190617531545733e-06,0.02610362072414483,293.77697262438136,229.36749380641155,4.156853308030779
1.8257529651945007e-06,0.0261996399279856,293.9691183516614,229.36749380641155,4.156853308030779
1.856532540578166e-06,0.02664132826565313,294.8494752907602,229.36749380641155,4.156853308030779
1.9020327824496719e-06,0.027294258851770354,296.1405163979833,229.36749380641155,4.156853308030779
1.9087239944895995e-06,0.027390278055611124,296.3293545615213,229.36749380641155,4.156853308030779
1.9207681761614683e-06,0.027563112622524505,296.6686139367267,229.36749380641155,4.156853308030779
1.9783125997048435e-06,0.028388877775555113,298.2782057523884,229.36749380641155,4.156853308030779
2.0211363567603783e-06,0.029003400680136026,299.4642159910447,229.36749380641155,4.156853308030779
2.049239447328073e-06,0.029406681336267254,300.2372128514359,229.36749380641155,4.156853308030779
2.1000926588315207e-06,0.030136427285457092,301.6255406413747,229.36749380641155,4.156853308030779
2.1228427797672735e-06,0.030462892578515702,302.24238337161546,229.36749380641155,4.156853308030779
2.1375634462551135e-06,0.030674134826965394,302.64014353222797,229.36749380641155,4.156853308030779
2.1750342336787067e-06,0.031211842368473696,303.6478332520312,229.36749380641155,4.156853308030779
2.1924313849825174e-06,0.031461492298459695,304.11338557158206,229.36749380641155,4.156853308030779
2.2606817477897762e-06,0.03244088817763553,305.92603810641464,229.36749380641155,4.156853308030779
2.288784838357471e-06,0.03284416883376676,306.66620597467636,229.36749380641155,4.156853308030779
2.294137807989412e-06,0.032920984196839365,306.8067875747965,229.36749380641155,4.156853308030779
2.3195644137411362e-06,0.033285857171434285,307.47281097326635,229.36749380641155,4.156853308030779
2.4212708367480314e-06,0.03474534906981396,310.10891339857676,229.36749380641155,4.156853308030779
2.431976776011915e-06,0.03489897979595919,310.3838620193507,229.36749380641155,4.156853308030779
2.4734622906594646e-06,0.035494298859771956,311.4448589996458,229.36749380641155,4.156853308030779
2.512271320491043e-06,0.03605121024204841,312.4311386235665,229.36749380641155,4.156853308030779
2.5243155021629126e-06,0.0362240448089618,312.73601487079566,229.36749380641155,4.156853308030779
2.5350214414267962e-06,0.036377675535107026,313.0065400417387,229.36749380641155,4.156853308030779
2.5698157440344182e-06,0.03687697539507902,313.8826855820066,229.36749380641155,4.156853308030779
2.5791834408903158e-06,0.03701140228045609,314.1177789034246,229.36749380641155,4.156853308030779
2.585874652930243e-06,0.037107421484296854,314.28549886758725,229.36749380641155,4.156853308030779
2.6166542283139094e-06,0.037549109821964397,315.0548411072364,229.36749380641155,4.156853308030779
2.6501102885135454e-06,0.03802920584116823,315.8870905126054,229.36749380641155,4.156853308030779
2.6675074398173574e-06,0.03827885577115424,316.31824024496694,229.36749380641155,4.156853308030779
2.69293404556908e-06,0.038643728745749145,316.9464147242707,229.36749380641155,4.156853308030779
2.767875620416266e-06,0.03971914382876575,318.7845573019196,229.36749380641155,4.156853308030779
2.7986551957999326e-06,0.04016083216643329,319.5338733909612,229.36749380641155,4.156853308030779
2.8147141046957574e-06,0.04039127825565113,319.92354465486113,229.36749380641155,4.156853308030779
2.8280965287756117e-06,0.04058331666333266,320.24760881872834,229.36749380641155,4.156853308030779
2.8441554376714378e-06,0.04081376275255051,320.635697460905,229.36749380641155,4.156853308030779
2.8535231345273358e-06,0.04094818963792758,320.8616878501916,229.36749380641155,4.156853308030779
2.8655673161992054e-06,0.04112102420484097,321.1518222272138,229.36749380641155,4.156853308030779
2.884302709911002e-06,0.041389877975595124,321.6021988545394,229.36749380641155,4.156853308030779
2.917758770110638e-06,0.041869973994798956,322.40361526090345,229.36749380641155,4.156853308030779
2.932479436598478e-06,0.04208121624324865,322.75510226502735,229.36749380641155,4.156853308030779
2.9552295575342314e-06,0.042407681536307265,323.29695897895596,229.36749380641155,4.156853308030779
2.9900238601418534e-06,0.042906981396279256,324.12254488450554,229.36749380641155,4.156853308030779
3.02347992034149e-06,0.0433870774154831,324.9128512621513,229.36749380641155,4.156853308030779
3.1037744648206177e-06,0.044539307861572314,326.79579917551246,229.36749380641155,4.156853308030779
3.122509858532414e-06,0.04480816163232647,327.2324086178914,229.36749380641155,4.156853308030779
3.157304161140036e-06,0.04530746149229846,328.04055369260556,229.36749380641155,4.156853308030779
3.1720248276278766e-06,0.04551870374074815,328.381414782967,229.36749380641155,4.156853308030779
3.1934367061556437e-06,0.04582596519303861,328.8761135059433,229.36749380641155,4.156853308030779
3.224216281539309e-06,0.04626765353070614,329.58498258307526,229.36749380641155,4.156853308030779
3.2616870689629025e-06,0.046805361072214446,330.44440144197534,229.36749380641155,4.156853308030779
3.2871136747146265e-06,0.04717023404680937,331.02538671306587,229.36749380641155,4.156853308030779
3.29781961397851e-06,0.047323864772954596,331.26948744158636,229.36749380641155,4.156853308030779
3.316555007690306e-06,0.04759271854370874,331.6959213646911,229.36749380641155,4.156853308030779
3.340643371034045e-06,0.04793838767753551,332.2428156146306,229.36749380641155,4.156853308030779
3.348672825481957e-06,0.048053610722144424,332.4247716464744,229.36749380641155,4.156853308030779
3.3928348249454777e-06,0.0486873374674935,333.42250480154735,229.36749380641155,4.156853308030779
3.4276291275530997e-06,0.04918663732746549,334.20503474366075,229.36749380641155,4.156853308030779
3.4945412479523725e-06,0.05014682936587317,335.70124698217927,229.36749380641155,4.156853308030779
3.53067379296798e-06,0.05066533306661332,336.5045540207468,229.36749380641155,4.156853308030779
3.548070944271791e-06,0.050914982996599314,336.8901874496699,229.36749380641155,4.156853308030779
3.5855417316953845e-06,0.05145269053810762,337.7182867581431,229.36749380641155,4.156853308030779
3.6123065798550933e-06,0.05183676735347069,338.3077212040862,229.36749380641155,4.156853308030779
3.6323802159748757e-06,0.052124824964993,338.7486799222783,229.36749380641155,4.156853308030779
3.6631597913585413e-06,0.05256651330266053,339.4229752562156,229.36749380641155,4.156853308030779
3.7033070635981053e-06,0.05314262852570514,340.2991794748709,229.36749380641155,4.156853308030779
3.74613082065364e-06,0.05375715143028606,341.2297239429079,229.36749380641155,4.156853308030779
3.83445481958068e-06,0.055024604920984196,343.1359711028659,229.36749380641155,4.156853308030779
3.855866698108448e-06,0.055331866373274655,343.5955033107557,229.36749380641155,4.156853308030779
3.865234394964346e-06,0.055466293258651725,343.7962355907634,229.36749380641155,4.156853308030779
3.906719909611896e-06,0.056061612322464496,344.6829219793632,229.36749380641155,4.156853308030779
3.950881909075416e-06,0.05669533906781356,345.62278831772477,229.36749380641155,4.156853308030779
4.003073362986849e-06,0.05744428885777156,346.7282734167375,229.36749380641155,4.156853308030779
4.012441059842747e-06,0.05757871574314863,346.9260973673039,229.36749380641155,4.156853308030779
4.023146999106631e-06,0.05773234646929386,347.1519614583945,229.36749380641155,4.156853308030779
4.075338453018063e-06,0.058481296259251844,348.2497097632226,229.36749380641155,4.156853308030779
4.090059119505904e-06,0.058692538507701536,348.5583380121509,229.36749380641155,4.156853308030779
4.09675033154583e-06,0.0587885577115423,348.69848034007583,229.36749380641155,4.156853308030779
4.151618270273235e-06,0.05957591518303661,349.84429947957017,229.36749380641155,4.156853308030779
4.17972136084093e-06,0.05997919583916783,350.42889431844884,229.36749380641155,4.156853308030779
4.205147966592654e-06,0.06034406881376275,350.9564938826216,229.36749380641155,4.156853308030779
4.241280511608262e-06,0.0608625725145029,351.7041054160262,229.36749380641155,4.156853308030779
4.277413056623869e-06,0.06138107621524305,352.4492370895153,229.36749380641155,4.156853308030779
4.288118995887752e-06,0.06153470694138828,352.6695448911201,229.36749380641155,4.156853308030779
4.357707601102996e-06,0.06253330666133226,354.09635233153034,229.36749380641155,4.156853308030779
4.369751782774866e-06,0.06270614122824565,354.3423949559943,229.36749380641155,4.156853308030779
4.416590267054357e-06,0.06337827565513103,355.29672373533555,229.36749380641155,4.156853308030779
4.446031600030036e-06,0.0638007601520304,355.89456772967964,229.36749380641155,4.156853308030779
4.466105236149819e-06,0.06408881776355271,356.3013036807623,229.36749380641155,4.156853308030779
4.470119963373776e-06,0.06414642928585718,356.3825652462468,229.36749380641155,4.156853308030779
4.491531841901543e-06,0.06445369073814763,356.81548049541794,229.36749380641155,4.156853308030779
4.516958447653267e-06,0.06481856371274256,357.32852335866806,229.36749380641155,4.156853308030779
4.535693841365062e-06,0.0650874174834967,357.70583451726964,229.36749380641155,4.156853308030779
4.55710571989283e-06,0.06539467893578715,358.1363037856566,229.36749380641155,4.156853308030779
4.590561780092467e-06,0.065874774954991,358.80733621944,229.36749380641155,4.156853308030779
4.630709052332032e-06,0.06645089017803561,359.6100627522589,229.36749380641155,4.156853308030779
4.640076749187929e-06,0.06658531706341268,359.7969745220404,229.36749380641155,4.156853308030779
4.674871051795552e-06,0.06708461692338469,360.48993354231646,229.36749380641155,4.156853308030779
4.692268203099363e-06,0.06733426685337068,360.8356585457773,229.36749380641155,4.156853308030779
4.694944687915333e-06,0.06737267453490699,360.8888026047668,229.36749380641155,4.156853308030779
4.716356566443101e-06,0.06767993598719745,361.3135305486865,229.36749380641155,4.156853308030779
4.733753717746912e-06,0.06792958591718344,361.6580685469766,229.36749380641155,4.156853308030779
4.749812626642737e-06,0.06816003200640128,361.9756655704863,229.36749380641155,4.156853308030779
4.788621656474316e-06,0.06871694338867775,362.7414677614095,229.36749380641155,4.156853308030779
4.844827837609705e-06,0.0695235047009402,363.8462832074615,229.36749380641155,4.156853308030779
4.87560741299337e-06,0.06996519303860772,364.44918257011943,229.36749380641155,4.156853308030779
4.9184311700489056e-06,0.07057971594318864,365.2855356205589,229.36749380641155,4.156853308030779
4.9585784422884696e-06,0.07115583116623325,366.06704103291054,229.36749380641155,4.156853308030779
4.97329910877631e-06,0.07136707341468294,366.3529742200808,229.36749380641155,4.156853308030779
5.0094316537919176e-06,0.0718855771154231,367.0534144007752,229.36749380641155,4.156853308030779
5.050917168439467e-06,0.07248089617923585,367.8551982405306,229.36749380641155,4.156853308030779
5.151285349038377e-06,0.07392118423684738,369.78444796721067,229.36749380641155,4.156853308030779
5.175373712382114e-06,0.07426685337067414,370.24527972912426,229.36749380641155,4.156853308030779
5.194109106093911e-06,0.07453570714142829,370.60312634878306,229.36749380641155,4.156853308030779
5.199462075725853e-06,0.0746125225045009,370.7052757334081,229.36749380641155,4.156853308030779
5.23559462074146e-06,0.07513102620524105,371.39371444065046,229.36749380641155,4.156853308030779
5.248977044821315e-06,0.07532306461292258,371.6482211974238,229.36749380641155,4.156853308030779
5.266374196125126e-06,0.07557271454290859,371.97870197734096,229.36749380641155,4.156853308030779
5.352021710236196e-06,0.07680176035207043,373.5995174478222,229.36749380641155,4.156853308030779
5.402874921739643e-06,0.07753150630126025,374.55709082453444,229.36749380641155,4.156853308030779
5.449713406019135e-06,0.07820364072814563,375.43596114739717,229.36749380641155,4.156853308030779
5.472463526954888e-06,0.07853010602120425,375.8617776842624,229.36749380641155,4.156853308030779
5.492537163074669e-06,0.07881816363272655,376.2369251653438,229.36749380641155,4.156853308030779
5.499228375114597e-06,0.07891418283656731,376.3618554512606,229.36749380641155,4.156853308030779
5.520640253642364e-06,0.07922144428885777,376.7612345668987,229.36749380641155,4.156853308030779
5.540713889762147e-06,0.07950950190038009,377.1351041858183,229.36749380641155,4.156853308030779
5.587552374041637e-06,0.08018163632726545,378.0054183148416,229.36749380641155,4.156853308030779
5.612978979793361e-06,0.08054650930186037,378.47668285384754,229.36749380641155,4.156853308030779
5.678552857784649e-06,0.0814874974994999,379.68822299953337,229.36749380641155,4.156853308030779
5.7106706755763e-06,0.08194838967793559,380.2796387291461,229.36749380641155,4.156853308030779
5.732082554104067e-06,0.08225565113022605,380.67319536122005,229.36749380641155,4.156853308030779
5.744126735775937e-06,0.08242848569713944,380.8943190019185,229.36749380641155,4.156853308030779
5.777582795975573e-06,0.08290858171634327,381.5076045951271,229.36749380641155,4.156853308030779
5.8070241289512535e-06,0.08333106621324265,382.0461511464983,229.36749380641155,4.156853308030779
5.831112492294991e-06,0.08367673534706942,382.48598854130466,229.36749380641155,4.156853308030779
5.8364654619269335e-06,0.08375355071014204,382.58363388650514,229.36749380641155,4.156853308030779
5.860553825270672e-06,0.0840992198439688,383.02260643693216,229.36749380641155,4.156853308030779
5.9060540671421775e-06,0.08475215043008602,383.84986167725384,229.36749380641155,4.156853308030779
5.938171884933829e-06,0.08521304260852171,384.4323107342014,229.36749380641155,4.156853308030779
5.943524854565771e-06,0.08528985797159433,384.52926600448563,229.36749380641155,4.156853308030779
5.991701581253247e-06,0.08598119623924785,385.4003363008006,229.36749380641155,4.156853308030779
6.010436974965044e-06,0.08625005001000201,385.7383476527525,229.36749380641155,4.156853308030779
6.042554792756695e-06,0.0867109421884377,386.31684123838903,229.36749380641155,4.156853308030779
6.074672610548346e-06,0.08717183436687338,386.89413686774157,229.36749380641155,4.156853308030779
6.088055034628201e-06,0.08736387277455492,387.1343252446849,229.36749380641155,4.156853308030779
6.0960844890761134e-06,0.08747909581916384,387.27833943714535,229.36749380641155,4.156853308030779
6.133555276499706e-06,0.08801680336067214,387.94942994082777,229.36749380641155,4.156853308030779
6.160320124659416e-06,0.08840088017603522,388.4278017404041,229.36749380641155,4.156853308030779
6.181732003187183e-06,0.08870814162832567,388.8099158258088,229.36749380641155,4.156853308030779
6.216526305794805e-06,0.08920744148829766,389.42975213715687,229.36749380641155,4.156853308030779
6.236599941914587e-06,0.08949549909981996,389.7867345424502,229.36749380641155,4.156853308030779
6.280761941378107e-06,0.09012922584516904,390.57052226449036,229.36749380641155,4.156853308030779
6.316894486393715e-06,0.09064772954590919,391.2102056979886,229.36749380641155,4.156853308030779
6.327600425657599e-06,0.09080136027205442,391.39946727672174,229.36749380641155,4.156853308030779
6.3650712130811906e-06,0.09133906781356271,392.06090157108406,229.36749380641155,4.156853308030779
6.409233212544712e-06,0.09197279455891179,392.8385027308804,229.36749380641155,4.156853308030779
6.431983333480465e-06,0.0922992598519704,393.23826947327854,229.36749380641155,4.156853308030779
6.4855130297998826e-06,0.09306741348269654,394.17672810311313,229.36749380641155,4.156853308030779
6.516292605183549e-06,0.09350910182036408,394.71497390070795,229.36749380641155,4.156853308030779
6.5256603020394466e-06,0.09364352870574115,394.87859091311975,229.36749380641155,4.156853308030779
6.541719210935272e-06,0.093873974794959,395.1588642676118,229.36749380641155,4.156853308030779
6.5551016350151266e-06,0.09406601320264053,395.3922204804777,229.36749380641155,4.156853308030779
6.600601876886632e-06,0.09471894378875775,396.1842455333305,229.36749380641155,4.156853308030779
6.682234663773745e-06,0.09589037807561512,397.59991516850613,229.36749380641155,4.156853308030779
6.694278845445615e-06,0.09606321264252851,397.8082120751702,229.36749380641155,4.156853308030779
6.730411390461223e-06,0.09658171634326866,398.43222761441996,229.36749380641155,4.156853308030779
6.7558379962129466e-06,0.09694658931786358,398.8705667033485,229.36749380641155,4.156853308030779
6.770558662700787e-06,0.09715783156631327,399.1240478880014,229.36749380641155,4.156853308030779
6.778588117148699e-06,0.09727305461092219,399.2622197555111,229.36749380641155,4.156853308030779
6.799999995676466e-06,0.09758031606321264,399.63036636347977,229.36749380641155,4.156853308030779
6.8133824197563205e-06,0.09777235447089418,399.86022842821615,229.36749380641155,4.156853308030779
6.858882661627827e-06,0.09842528505701141,400.6404457558103,229.36749380641155,4.156853308030779
6.86691211607574e-06,0.09854050810162032,400.7779213676549,229.36749380641155,4.156853308030779
6.8749415705236525e-06,0.09865573114622925,400.9153343013863,229.36749380641155,4.156853308030779
6.9150888427632165e-06,0.09923184636927386,401.6014623489927,229.36749380641155,4.156853308030779
6.941853690922925e-06,0.09961592318463693,402.0580181578034,229.36749380641155,4.156853308030779
6.947206660554868e-06,0.09969273854770955,402.1492468822582,229.36749380641155,4.156853308030779