File: datasets/aisi_316_L/data/M1/train_67.csv
Time(s),Strain(%),Stress(MPa),Temp(C),Log_SR(s-1)
0.0,0.0,0.0,209.94769104670178,1.1191128964664685
2.4324116895461365e-07,3.2e-06,0.5923889,209.94769104670178,1.1191128964664685
1.520257305966335e-06,1.9999999999999998e-05,3.702430625,209.94769104670178,1.1191128964664685
2.0067396438755624e-06,2.6399999999999998e-05,4.887208425,209.94769104670178,1.1191128964664685
2.4932219817847897e-06,3.28e-05,6.071986225,209.94769104670178,1.1191128964664685
4.804013086853619e-06,6.319999999999999e-05,11.699680775,209.94769104670178,1.1191128964664685
5.108064548046886e-06,6.72e-05,12.4401669,209.94769104670178,1.1191128964664685
6.932373315206489e-06,9.12e-05,16.88308365,209.94769104670178,1.1191128964664685
8.756682082366091e-06,0.0001152,21.326000399999998,209.94769104670178,1.1191128964664685
9.12154383579801e-06,0.00011999999999999999,22.21458375,209.94769104670178,1.1191128964664685
1.2405299616685294e-05,0.00016319999999999998,30.2118339,209.94769104670178,1.1191128964664685
1.3621505461458363e-05,0.0001792,33.173778399999996,209.94769104670178,1.1191128964664685
1.3864746630412977e-05,0.0001824,33.7661673,209.94769104670178,1.1191128964664685
1.5141762767424699e-05,0.0001992,36.876209025,209.94769104670178,1.1191128964664685
1.7817415625925446e-05,0.00023439999999999998,43.39248692499999,209.94769104670178,1.1191128964664685
2.2925480173972335e-05,0.0003016,55.832653825,209.94769104670178,1.1191128964664685
2.3776824265313482e-05,0.00031279999999999996,57.90601497499999,209.94769104670178,1.1191128964664685
2.4810599233370587e-05,0.00032639999999999996,60.4236678,209.94769104670178,1.1191128964664685
2.5601133032473086e-05,0.0003368,62.348931725,209.94769104670178,1.1191128964664685
2.6513287416052884e-05,0.00034879999999999997,64.5703901,209.94769104670178,1.1191128964664685
2.7364631507394034e-05,0.00035999999999999997,66.64375125,209.94769104670178,1.1191128964664685
2.785111384530326e-05,0.00036639999999999996,67.82852904999999,209.94769104670178,1.1191128964664685
2.9310560859030943e-05,0.0003856,71.38286245,209.94769104670178,1.1191128964664685
3.0587576996042664e-05,0.00040239999999999997,74.49290417499999,209.94769104670178,1.1191128964664685
3.1499731379622465e-05,0.0004144,76.71436255,209.94769104670178,1.1191128964664685
3.2594316639918224e-05,0.00042879999999999996,79.38011259999999,209.94769104670178,1.1191128964664685
3.460105628379379e-05,0.0004552,84.267321025,209.94769104670178,1.1191128964664685
3.5209159206180324e-05,0.0004632,85.748293275,209.94769104670178,1.1191128964664685
3.563483125185089e-05,0.00046879999999999996,86.78497384999999,209.94769104670178,1.1191128964664685
3.6668606219908e-05,0.00048239999999999996,89.302626675,209.94769104670178,1.1191128964664685
4.0864516384375086e-05,0.0005376,99.5213352,209.94769104670178,1.1191128964664685
4.3418548658398536e-05,0.0005712,105.74141865,209.94769104670178,1.1191128964664685
4.433070304197834e-05,0.0005832,107.962877025,209.94769104670178,1.1191128964664685
4.4695564795410254e-05,0.000588,108.851460375,209.94769104670178,1.1191128964664685
4.6459063270331205e-05,0.0006112,113.1462799,209.94769104670178,1.1191128964664685
4.7371217653911005e-05,0.0006232,115.367738275,209.94769104670178,1.1191128964664685
4.797932057629754e-05,0.0006312,116.84871052499999,209.94769104670178,1.1191128964664685
4.852661320644542e-05,0.0006384,118.18158555000001,209.94769104670178,1.1191128964664685
5.07765940192756e-05,0.000668,123.661182875,209.94769104670178,1.1191128964664685
5.296576453986712e-05,0.0006967999999999999,128.99268297499998,209.94769104670178,1.1191128964664685
5.357386746225366e-05,0.0007048,130.473655225,209.94769104670178,1.1191128964664685
5.545898652165191e-05,0.0007296,135.0646692,209.94769104670178,1.1191128964664685
5.5945468859561134e-05,0.000736,136.249447,209.94769104670178,1.1191128964664685
5.667519236642498e-05,0.0007456,138.0266137,209.94769104670178,1.1191128964664685
5.8073829087914e-05,0.0007639999999999999,141.432849875,209.94769104670178,1.1191128964664685
5.910760405597111e-05,0.0007775999999999999,143.9505027,209.94769104670178,1.1191128964664685
5.995894814731226e-05,0.0007888,146.02386385,209.94769104670178,1.1191128964664685
6.318189363596089e-05,0.0008311999999999999,153.873016775,209.94769104670178,1.1191128964664685
6.40940480195407e-05,0.0008432,156.09447515,209.94769104670178,1.1191128964664685
6.482377152640453e-05,0.0008527999999999999,157.87164184999997,209.94769104670178,1.1191128964664685
6.676970087804145e-05,0.0008784,162.61075305,209.94769104670178,1.1191128964664685
6.938454344430354e-05,0.0009128,168.978933725,209.94769104670178,1.1191128964664685
7.053993899683795e-05,0.000928,171.792781,209.94769104670178,1.1191128964664685
7.236424776399755e-05,0.0009519999999999999,176.23569774999999,209.94769104670178,1.1191128964664685
7.382369477772523e-05,0.0009712,179.79003115,209.94769104670178,1.1191128964664685
7.424936682339581e-05,0.0009767999999999999,180.82671172499997,209.94769104670178,1.1191128964664685
7.637772705174867e-05,0.0010048,186.01011459999998,209.94769104670178,1.1191128964664685
7.76547431887604e-05,0.0010216,189.12015632499998,209.94769104670178,1.1191128964664685
7.978310341711327e-05,0.0010496,194.3035592,209.94769104670178,1.1191128964664685
8.063444750845442e-05,0.0010608,196.37692035,209.94769104670178,1.1191128964664685
8.318847978247786e-05,0.0010944,202.59700379999998,209.94769104670178,1.1191128964664685
8.373577241262573e-05,0.0011015999999999999,203.92987882499997,209.94769104670178,1.1191128964664685
8.556008117978535e-05,0.0011256,208.372795575,209.94769104670178,1.1191128964664685
8.701952819351302e-05,0.0011447999999999999,211.92712897499996,209.94769104670178,1.1191128964664685
8.750601053142226e-05,0.0011512,212.90036055373804,209.94769104670178,1.1191128964664685
8.969518105201377e-05,0.0011799999999999998,213.08726644946245,209.94769104670178,1.1191128964664685
9.024247368216166e-05,0.0011872,213.13371388819638,209.94769104670178,1.1191128964664685
9.103300748126416e-05,0.0011976,213.20061115316543,209.94769104670178,1.1191128964664685
9.370866033976492e-05,0.0012328,213.42537016411524,209.94769104670178,1.1191128964664685
9.693160582841353e-05,0.0012752,213.69280616992984,209.94769104670178,1.1191128964664685
9.71140367051295e-05,0.0012776,213.70783950267912,209.94769104670178,1.1191128964664685
9.839105284214123e-05,0.0012944,213.8127661562895,209.94769104670178,1.1191128964664685
9.9303207225721e-05,0.0013063999999999999,213.88738884807188,209.94769104670178,1.1191128964664685
0.00010100589540840332,0.0013288,214.0259731693308,209.94769104670178,1.1191128964664685
0.00010276939388332425,0.001352,214.16854979901498,209.94769104670178,1.1191128964664685
0.00010447208206600656,0.0013744,214.3053073377369,209.94769104670178,1.1191128964664685
0.0001050801849883931,0.0013824,214.35393829388408,209.94769104670178,1.1191128964664685
0.00010647882170988212,0.0014008,214.46537486958778,209.94769104670178,1.1191128964664685
0.00010708692463226866,0.0014088,214.51364733664388,209.94769104670178,1.1191128964664685
0.00010751259667793922,0.0014144,214.54737447406478,209.94769104670178,1.1191128964664685
0.00010927609515286018,0.0014376,214.68654998061277,209.94769104670178,1.1191128964664685
0.00011018824953643997,0.0014495999999999999,214.75819342998898,209.94769104670178,1.1191128964664685
0.0001105531112898719,0.0014544,214.78678600099792,209.94769104670178,1.1191128964664685
0.00011183012742688363,0.0014712,214.886571466725,209.94769104670178,1.1191128964664685
0.00011292471268717938,0.0014856,214.97174867561756,209.94769104670178,1.1191128964664685
0.00011450578028538438,0.0015064,215.09421614786314,209.94769104670178,1.1191128964664685
0.00011529631408448687,0.0015168,215.15520244470983,209.94769104670178,1.1191128964664685
0.00011584360671463474,0.001524,215.1973282285378,209.94769104670178,1.1191128964664685
0.00011699900226716915,0.0015392,215.2860063957843,209.94769104670178,1.1191128964664685
0.00011742467431283974,0.0015448,215.31859112338634,209.94769104670178,1.1191128964664685
0.00011906655220328337,0.0015664,215.44384589868696,209.94769104670178,1.1191128964664685
0.00012083005067820432,0.0015895999999999998,215.5776308361285,209.94769104670178,1.1191128964664685
0.00012101248155492027,0.0015919999999999999,215.59142705358403,209.94769104670178,1.1191128964664685
0.0001213773433083522,0.0015968,215.6189951785659,209.94769104670178,1.1191128964664685
0.00012222868739969334,0.0016079999999999998,215.68319542289785,209.94769104670178,1.1191128964664685
0.00012277598002984123,0.0016152,215.72437493582635,209.94769104670178,1.1191128964664685
0.00012368813441342104,0.0016271999999999999,215.79284872409144,209.94769104670178,1.1191128964664685
0.00012484352996595545,0.0016424,215.87930013287792,209.94769104670178,1.1191128964664685
0.00012636378727192178,0.0016623999999999999,215.9925780759136,209.94769104670178,1.1191128964664685
0.0001270935107787856,0.0016719999999999999,216.04676259196304,209.94769104670178,1.1191128964664685
0.00012903944013042251,0.0016975999999999998,216.1906647199902,209.94769104670178,1.1191128964664685
0.00012982997392952503,0.0017079999999999999,216.24888291401996,209.94769104670178,1.1191128964664685
0.00013135023123549136,0.001728,216.36045386557367,209.94769104670178,1.1191128964664685
0.0001340258840939921,0.0017632,216.55560318932388,209.94769104670178,1.1191128964664685
0.00013542452081548114,0.0017816,216.65700802024432,209.94769104670178,1.1191128964664685
0.00013730963987487938,0.0018063999999999999,216.79304019728949,209.94769104670178,1.1191128964664685
0.0001374312604593567,0.001808,216.8017913731127,209.94769104670178,1.1191128964664685
0.00013907313834980034,0.0018296,216.91963818827045,209.94769104670178,1.1191128964664685
0.00014047177507128935,0.0018479999999999998,217.01959886700445,209.94769104670178,1.1191128964664685
0.00014144473974710782,0.0018608,217.08890791728805,209.94769104670178,1.1191128964664685
0.00014491092640471107,0.0019064,217.33432446941833,209.94769104670178,1.1191128964664685
0.0001469784763408253,0.0019336,217.4796233397492,209.94769104670178,1.1191128964664685
0.00014819468218559836,0.0019496,217.56472091493737,209.94769104670178,1.1191128964664685
0.00014898521598470085,0.00196,217.61988831948696,209.94769104670178,1.1191128964664685
0.0001497149394915647,0.0019695999999999997,217.67071083476367,209.94769104670178,1.1191128964664685
0.00015117438650529236,0.0019887999999999998,217.77206696477552,209.94769104670178,1.1191128964664685
0.00015202573059663353,0.002,217.8310151436427,209.94769104670178,1.1191128964664685
0.00015251221293454274,0.0020063999999999998,217.86464201301087,209.94769104670178,1.1191128964664685
0.00015336355702588392,0.0020176,217.92338854854455,209.94769104670178,1.1191128964664685
0.00015366760848707715,0.0020215999999999997,217.9443386139311,209.94769104670178,1.1191128964664685
0.00015409328053274772,0.0020272,217.9736415662253,209.94769104670178,1.1191128964664685
0.00015640407163781654,0.0020575999999999997,218.13216726944415,209.94769104670178,1.1191128964664685
0.00015664731280677117,0.0020608,218.1488008758075,209.94769104670178,1.1191128964664685
0.00015725541572915772,0.0020688,218.19034088245496,209.94769104670178,1.1191128964664685
0.00015968782741870386,0.0021008,218.3558782399832,209.94769104670178,1.1191128964664685
0.00016053917151004498,0.0021119999999999997,218.41358360787854,209.94769104670178,1.1191128964664685
0.00016072160238676095,0.0021144,218.42593350283664,209.94769104670178,1.1191128964664685
0.00016120808472467018,0.0021208,218.4588398576134,209.94769104670178,1.1191128964664685
0.00016187699793929536,0.0021295999999999997,218.50402293006843,209.94769104670178,1.1191128964664685
0.00016394454787540958,0.0021568,218.64322153252044,209.94769104670178,1.1191128964664685
0.00016424859933660287,0.0021608,218.66363402461218,209.94769104670178,1.1191128964664685
0.00016582966693480782,0.0021815999999999997,218.769542360854,209.94769104670178,1.1191128964664685
0.000168079647747638,0.0022112,218.9195816082983,209.94769104670178,1.1191128964664685
0.00016832288891659264,0.0022144,218.93575501097456,209.94769104670178,1.1191128964664685
0.00016899180213121782,0.0022232,218.98018493691188,209.94769104670178,1.1191128964664685
0.00017063368002166146,0.0022448,219.08895041584313,209.94769104670178,1.1191128964664685
0.0001714850241130026,0.0022559999999999998,219.14518659674707,209.94769104670178,1.1191128964664685
0.0001720323167431505,0.0022632,219.18128093877874,209.94769104670178,1.1191128964664685
0.00017324852258792357,0.0022792,219.2613306400621,209.94769104670178,1.1191128964664685
0.0001748904004783672,0.0023008,219.3690509588368,209.94769104670178,1.1191128964664685
0.00017610660632314028,0.0023168,219.44858968576958,209.94769104670178,1.1191128964664685
0.0001767147092455268,0.0023247999999999997,219.48827869325746,209.94769104670178,1.1191128964664685
0.00017878225918164102,0.002352,219.62282467827677,209.94769104670178,1.1191128964664685
0.00018072818853327792,0.0023775999999999997,219.7489029179653,209.94769104670178,1.1191128964664685
0.00018267411788491482,0.0024032,219.87445282871442,209.94769104670178,1.1191128964664685
0.0001840119443141652,0.0024208,219.9604659852683,209.94769104670178,1.1191128964664685
0.00018632273541923402,0.0024511999999999997,220.10846192979363,209.94769104670178,1.1191128964664685
0.0001876605618484844,0.0024687999999999997,220.19381660661531,209.94769104670178,1.1191128964664685
0.00018845109564758693,0.0024792,220.24414191856684,209.94769104670178,1.1191128964664685
0.00019015378383026923,0.0025016,220.35225610986487,209.94769104670178,1.1191128964664685
0.0001903970249992238,0.0025047999999999997,220.36767011764806,209.94769104670178,1.1191128964664685
0.00019282943668876996,0.0025368,220.52139013723163,209.94769104670178,1.1191128964664685
0.0001936807807801111,0.002548,220.57501324052978,209.94769104670178,1.1191128964664685
0.00019453212487145224,0.0025591999999999998,220.62854449690298,209.94769104670178,1.1191128964664685
0.00019599157188517993,0.0025784,220.72010028530661,209.94769104670178,1.1191128964664685
0.00019769426006786223,0.0026008,220.82657999263742,209.94769104670178,1.1191128964664685
0.00019878884532815799,0.0026152,220.894842411974,209.94769104670178,1.1191128964664685
0.00019939694825054453,0.0026232,220.93270263294983,209.94769104670178,1.1191128964664685
0.0002003091026341243,0.0026352,220.98940864180054,209.94769104670178,1.1191128964664685
0.00020079558497203357,0.0026416,221.01961066431053,209.94769104670178,1.1191128964664685
0.00020219422169352258,0.00266,221.1062829250309,209.94769104670178,1.1191128964664685
0.00020237665257023853,0.0026623999999999997,221.1175707395131,209.94769104670178,1.1191128964664685
0.00020401853046068217,0.0026839999999999998,221.21898311816386,209.94769104670178,1.1191128964664685
0.0002054171671821712,0.0027023999999999998,221.305120639159,209.94769104670178,1.1191128964664685
0.00020651175244246696,0.0027167999999999997,221.372373163708,209.94769104670178,1.1191128964664685
0.0002088225435475358,0.0027472,221.51389588514584,209.94769104670178,1.1191128964664685
0.0002091874053009677,0.0027519999999999997,221.536185624956,209.94769104670178,1.1191128964664685
0.00021034280085350214,0.0027672,221.606669981039,209.94769104670178,1.1191128964664685
0.00021192386845170712,0.0027879999999999997,221.7028780604222,209.94769104670178,1.1191128964664685
0.00021228873020513904,0.0027928,221.7250401236657,209.94769104670178,1.1191128964664685
0.00021253197137409367,0.002796,221.73980658022165,209.94769104670178,1.1191128964664685
0.00021362655663438942,0.0028104,221.8061742397108,209.94769104670178,1.1191128964664685
0.00021496438306363978,0.002828,221.88711043752878,209.94769104670178,1.1191128964664685
0.0002167886918307994,0.002852,221.99716210665954,209.94769104670178,1.1191128964664685
0.00021745760504542457,0.0028607999999999997,222.0374238142063,209.94769104670178,1.1191128964664685
0.00021776165650661786,0.0028648,222.0557086203923,209.94769104670178,1.1191128964664685
0.00021964677556601613,0.0028896,222.16885298650402,209.94769104670178,1.1191128964664685
0.00022092379170302783,0.0029064,222.24528408243526,209.94769104670178,1.1191128964664685
0.00022165351520989166,0.0029159999999999998,222.28888163271964,209.94769104670178,1.1191128964664685
0.00022238323871675553,0.0029256,222.3324232417023,209.94769104670178,1.1191128964664685
0.0002242075474839151,0.0029495999999999997,222.44103418945514,209.94769104670178,1.1191128964664685
0.00022603185625107473,0.0029736,222.54930102256645,209.94769104670178,1.1191128964664685
0.00022706563121913182,0.0029871999999999998,222.6105009462294,209.94769104670178,1.1191128964664685
0.00022846426794062084,0.0030055999999999998,222.69312816213113,209.94769104670178,1.1191128964664685
0.0002295588532009166,0.0030199999999999997,222.75765540996306,209.94769104670178,1.1191128964664685
0.0002299845252465872,0.0030256,222.78271691991034,209.94769104670178,1.1191128964664685
0.0002302277664155418,0.0030288,222.79702966045647,209.94769104670178,1.1191128964664685
0.00023120073109136026,0.0030415999999999998,222.85422174630693,209.94769104670178,1.1191128964664685
0.00023266017810508793,0.0030608,222.93983419082292,209.94769104670178,1.1191128964664685
0.0002348493486256795,0.0030896,223.06786119394144,209.94769104670178,1.1191128964664685
0.0002360047441782139,0.0031048,223.13524331236533,209.94769104670178,1.1191128964664685
0.00023795067352985077,0.0031303999999999998,223.24843890504093,209.94769104670178,1.1191128964664685
0.00023971417200477173,0.0031536,223.35071095318327,209.94769104670178,1.1191128964664685
0.00024257225573998844,0.0031912,223.51584125323186,209.94769104670178,1.1191128964664685
0.0002437884615847615,0.0032072,223.58587912320456,209.94769104670178,1.1191128964664685
0.000244578995383864,0.0032175999999999997,223.63133067710947,209.94769104670178,1.1191128964664685
0.000246160062982069,0.0032384,223.7220622649441,209.94769104670178,1.1191128964664685
0.00024725464824236476,0.0032527999999999997,223.78474334647746,209.94769104670178,1.1191128964664685
0.0002476803202880353,0.0032584,223.809090085173,209.94769104670178,1.1191128964664685
0.0002499303011008655,0.0032879999999999997,223.93750990783417,209.94769104670178,1.1191128964664685
0.00025236271279041166,0.00332,224.0758360062653,209.94769104670178,1.1191128964664685
0.0002529708157127982,0.003328,224.1103361649052,209.94769104670178,1.1191128964664685
0.00025534241711010566,0.0033591999999999997,224.24457887430205,209.94769104670178,1.1191128964664685
0.0002569842950005493,0.0033807999999999998,224.337231415855,209.94769104670178,1.1191128964664685
0.00025807888026084503,0.0033951999999999997,224.3988715516494,209.94769104670178,1.1191128964664685
0.00025965994785905007,0.0034159999999999998,224.48772760641643,209.94769104670178,1.1191128964664685
0.00026154506691844834,0.0034408,224.5933960616617,209.94769104670178,1.1191128964664685
0.0002627004624709827,0.003456,224.6580137986778,209.94769104670178,1.1191128964664685
0.00026294370363993735,0.0034592,224.67160339882707,209.94769104670178,1.1191128964664685
0.0002646463918226196,0.0034815999999999996,224.76659369737797,209.94769104670178,1.1191128964664685
0.0002649504432838129,0.0034855999999999997,224.78353113927804,209.94769104670178,1.1191128964664685
0.0002676869064345523,0.0035215999999999997,224.93562851426105,209.94769104670178,1.1191128964664685
0.0002696936460784279,0.003548,225.04678147315968,209.94769104670178,1.1191128964664685
0.0002709706622154396,0.0035648,225.11734726352367,209.94769104670178,1.1191128964664685
0.0002722476783524513,0.0035816,225.18778347453687,209.94769104670178,1.1191128964664685
0.0002731598327360311,0.0035935999999999997,225.2380161874812,209.94769104670178,1.1191128964664685
0.00027449765916528145,0.0036111999999999997,225.31157265963947,209.94769104670178,1.1191128964664685
0.000275105762087668,0.0036192,225.34496118751593,209.94769104670178,1.1191128964664685
0.0002756530547178159,0.0036263999999999997,225.37498626102126,209.94769104670178,1.1191128964664685
0.0002758962958867705,0.0036295999999999998,225.38832327454443,209.94769104670178,1.1191128964664685
0.00027699088114706624,0.0036439999999999997,225.44828317689135,209.94769104670178,1.1191128964664685
0.0002774773634849755,0.0036504,225.47490235318224,209.94769104670178,1.1191128964664685
0.00027845032816079397,0.0036631999999999997,225.52808616520394,209.94769104670178,1.1191128964664685
0.0002790584310831805,0.0036712,225.56128924624338,209.94769104670178,1.1191128964664685
0.00028051787809690816,0.0036904,225.6408617226028,209.94769104670178,1.1191128964664685
0.000281065170727056,0.0036975999999999997,225.6706597551592,209.94769104670178,1.1191128964664685
0.0002819773251106359,0.0037096,225.72027290538298,209.94769104670178,1.1191128964664685
0.0002839840647545114,0.0037359999999999997,225.82920204648983,209.94769104670178,1.1191128964664685
0.0002850178397225685,0.0037495999999999996,225.88519987676762,209.94769104670178,1.1191128964664685
0.00028520027059928446,0.0037519999999999997,225.89507361856437,209.94769104670178,1.1191128964664685
0.00028550432206047774,0.003756,225.911524382939,209.94769104670178,1.1191128964664685
0.00028745025141211467,0.0037816,226.01664794213647,209.94769104670178,1.1191128964664685
0.00028854483667241045,0.003796,226.07565797037537,209.94769104670178,1.1191128964664685
0.0002909164380697179,0.0038272,226.2032143667285,209.94769104670178,1.1191128964664685
0.00029292317771359346,0.0038536,226.31083025996554,209.94769104670178,1.1191128964664685
0.00029413938355836656,0.0038696,226.3759120896089,209.94769104670178,1.1191128964664685
0.00029572045115657154,0.0038904,226.46036178512188,209.94769104670178,1.1191128964664685
0.0002986393451840269,0.0039288,226.61580773381,209.94769104670178,1.1191128964664685
0.0003002204127822319,0.0039496,226.69976017330768,209.94769104670178,1.1191128964664685
0.00030259201417953934,0.0039808,226.82536625198185,209.94769104670178,1.1191128964664685
0.00031280989496238696,0.004115223044608922,227.36219913676877,209.94769104670178,1.1191128964664685
0.00034638389107734664,0.004556911382276456,229.0798275531751,209.94769104670178,1.1191128964664685
0.0003653604975771065,0.004806561312262453,230.02188954394234,209.94769104670178,1.1191128964664685
0.00041353188330726606,0.005440288057611523,232.33130800342238,209.94769104670178,1.1191128964664685
0.00043688770669158574,0.00574754950990198,233.41300899106452,209.94769104670178,1.1191128964664685
0.00046462274696046547,0.006112422484496899,234.66865367541263,209.94769104670178,1.1191128964664685
0.0004850590924217453,0.00638127625525105,235.5752320311952,209.94769104670178,1.1191128964664685
0.000523012305421265,0.006880576115223045,237.2202930097262,209.94769104670178,1.1191128964664685
0.0005463681288055847,0.007187837567513502,238.20951039615196,209.94769104670178,1.1191128964664685
0.0006018382093433441,0.00791758351670334,240.4950149134637,209.94769104670178,1.1191128964664685
0.0006295732496122239,0.00828245649129826,241.6068256776927,209.94769104670178,1.1191128964664685
0.0006675264626117435,0.008781756351270254,243.09777180052737,209.94769104670178,1.1191128964664685
0.0006806641132654234,0.008954590918183637,243.6061159653857,209.94769104670178,1.1191128964664685
0.0006996407197651833,0.009204240848169634,244.3336865377346,209.94769104670178,1.1191128964664685
0.0007594900171875026,0.009991598319663933,246.5794694880905,209.94769104670178,1.1191128964664685
0.000831017226301982,0.010932586517303462,249.1747911983413,209.94769104670178,1.1191128964664685
0.0008572925276093418,0.011278255651130227,250.10609266836397,209.94769104670178,1.1191128964664685
0.0008645912224169416,0.011374274854970993,250.36280328254227,209.94769104670178,1.1191128964664685
0.000936118431531421,0.012315263052610522,252.83537897293013,209.94769104670178,1.1191128964664685
0.0009492560821851007,0.012488097619523904,253.2813985764947,209.94769104670178,1.1191128964664685
0.0009799106003770205,0.012891378275655131,254.3128519689086,209.94769104670178,1.1191128964664685
0.0010091053796074203,0.013275455091018204,255.28354996469108,209.94769104670178,1.1191128964664685
0.00102808198610718,0.013525105021004201,255.90863526554915,209.94769104670178,1.1191128964664685
0.0010762533718373397,0.014158831766353271,257.4755100198798,209.94769104670178,1.1191128964664685
0.0010835520666449396,0.01425485097019404,257.7105075813513,209.94769104670178,1.1191128964664685
0.0010937702393755795,0.014389277855571115,258.0384696762305,209.94769104670178,1.1191128964664685
0.001131723452375099,0.01488857771554311,259.24629209603444,209.94769104670178,1.1191128964664685
0.0011667571874515788,0.015349469893978797,260.3472558873883,209.94769104670178,1.1191128964664685
0.0011886532718743785,0.0156375275055011,261.02881461812314,209.94769104670178,1.1191128964664685
0.0012236870069508583,0.01609841968393679,262.10921091161583,209.94769104670178,1.1191128964664685
0.001229525962796938,0.016175235047009403,262.28809762063946,209.94769104670178,1.1191128964664685
0.0012485025692966977,0.0164248849769954,262.8672046073819,209.94769104670178,1.1191128964664685
0.0012660194368349378,0.016655331066213242,263.39872525205055,209.94769104670178,1.1191128964664685
0.0012879155212577374,0.016943388677735545,264.05910982256853,209.94769104670178,1.1191128964664685
0.0013463050797185368,0.01771154230846169,265.79907095594865,209.94769104670178,1.1191128964664685
0.0013638219472567766,0.017941988397679534,266.31528704002716,209.94769104670178,1.1191128964664685
0.0013871777706410964,0.018249249849969992,266.99957060176257,209.94769104670178,1.1191128964664685
0.0014119933329869363,0.018575715143028606,267.721716802078,209.94769104670178,1.1191128964664685
0.001433889417409736,0.01886377275455091,268.354804041231,209.94769104670178,1.1191128964664685
0.0014630841966401357,0.01924784956991398,269.193086193048,209.94769104670178,1.1191128964664685
0.0014733023693707758,0.01938227645529106,269.48494040491556,209.94769104670178,1.1191128964664685
0.0014878997589859756,0.019574314862972595,269.900509288932,209.94769104670178,1.1191128964664685
0.0015141750602933354,0.01991998399679936,270.64454834061877,209.94769104670178,1.1191128964664685
0.001521473755100935,0.020016003200640127,270.8503300376289,209.94769104670178,1.1191128964664685
0.0015433698395237352,0.020304060812162433,271.4653774951454,209.94769104670178,1.1191128964664685
0.001557967229138935,0.02049609921984397,271.87351958140334,209.94769104670178,1.1191128964664685
0.0015711048797926147,0.02066893378675735,272.23957407066786,209.94769104670178,1.1191128964664685
0.0015754840966771748,0.020726545309061813,272.36132669562454,209.94769104670178,1.1191128964664685
0.0015813230525232548,0.020803360672134428,272.52345841734785,209.94769104670178,1.1191128964664685
0.0015900814862923748,0.02091858371674335,272.76621891429346,209.94769104670178,1.1191128964664685
0.0016075983538306146,0.021149029805961193,273.25018105702674,209.94769104670178,1.1191128964664685
0.0016280346992918943,0.021417883576715344,273.81221183290484,209.94769104670178,1.1191128964664685
0.001641172349945574,0.021590718143628725,274.17206489768796,209.94769104670178,1.1191128964664685
0.0016703671291759738,0.021974794958991798,274.96774038577115,209.94769104670178,1.1191128964664685
0.0016893437356757337,0.022224444888977797,275.4820225593883,209.94769104670178,1.1191128964664685
0.0017010216473678937,0.022378075615123026,275.79738424239935,209.94769104670178,1.1191128964664685
0.0017214579928291735,0.022646929385877177,276.34724294537267,209.94769104670178,1.1191128964664685
0.0017725488564823727,0.023319063812762553,277.71086739864023,209.94769104670178,1.1191128964664685
0.001868891627942692,0.024586517303460693,280.2412690586052,209.94769104670178,1.1191128964664685
0.0018893279734039717,0.024855371074214844,280.7714214994685,209.94769104670178,1.1191128964664685
0.0019010058850961317,0.025009001800360073,281.0733615735284,209.94769104670178,1.1191128964664685
0.0019214422305574115,0.025277855571114224,281.60002182566865,209.94769104670178,1.1191128964664685
0.0019360396201726113,0.02546989397879576,281.9748710818194,209.94769104670178,1.1191128964664685
0.001982751266941251,0.026084416883376677,283.1670483811443,209.94769104670178,1.1191128964664685
0.001994429178633411,0.026238047609521906,283.4633749341617,209.94769104670178,1.1191128964664685
0.0020134057851331705,0.0264876975395079,283.9434664238596,209.94769104670178,1.1191128964664685
0.0020250836968253305,0.02664132826565313,284.23803033071493,209.94769104670178,1.1191128964664685
0.00205719795397877,0.02706381276255251,285.0446848327285,209.94769104670178,1.1191128964664685
0.00209807064490133,0.027601520304060812,286.0642683060456,209.94769104670178,1.1191128964664685
0.0021112082955550096,0.027774354870974197,286.390342549452,209.94769104670178,1.1191128964664685
0.0021243459462086892,0.027947189437887578,286.7156263978551,209.94769104670178,1.1191128964664685
0.002171057592977329,0.028561712342468494,287.8658907995531,209.94769104670178,1.1191128964664685
0.0022031718501307686,0.028984196839367874,288.6511043701186,209.94769104670178,1.1191128964664685
0.0022206887176690086,0.029214642928585718,289.07752078310193,209.94769104670178,1.1191128964664685
0.0022411250631302884,0.02948349669933987,289.57335216014354,209.94769104670178,1.1191128964664685
0.002249883496899408,0.02959871974394879,289.7853111760252,209.94769104670178,1.1191128964664685
0.002293675665745008,0.0301748349669934,290.84031733740676,209.94769104670178,1.1191128964664685
0.0023126522722447676,0.030424484896979395,291.2950438063229,209.94769104670178,1.1191128964664685
0.0023389275735521274,0.03077015403080616,291.9222699888801,209.94769104670178,1.1191128964664685
0.002357904180051887,0.03101980396079216,292.37355888778995,209.94769104670178,1.1191128964664685
0.002365202874859487,0.031115823164632926,292.54675409481496,209.94769104670178,1.1191128964664685
0.002403156087859007,0.031615123024604924,293.44403113641954,209.94769104670178,1.1191128964664685
0.0024279716502048467,0.031941588317663534,294.0277256924105,209.94769104670178,1.1191128964664685
0.0024498677346276466,0.03222964592918584,294.54082087298804,209.94769104670178,1.1191128964664685
0.0024907404255502057,0.032767353470694136,295.49383857052715,209.94769104670178,1.1191128964664685
0.0025549689398570857,0.0336123224644929,296.9792062637994,209.94769104670178,1.1191128964664685
0.002592922152856605,0.034111622324464894,297.8500788969718,209.94769104670178,1.1191128964664685
0.002608979281433325,0.034322864572914585,298.2170268266701,209.94769104670178,1.1191128964664685
0.0026162779762409247,0.03441888377675535,298.3835300693662,209.94769104670178,1.1191128964664685
0.0026337948437791647,0.034649329865973195,298.7824004745648,209.94769104670178,1.1191128964664685
0.0026732077957402037,0.03516783356671334,299.6760954352727,209.94769104670178,1.1191128964664685
0.002730137615239484,0.03591678335667134,300.95796875094567,209.94769104670178,1.1191128964664685
0.0027447350048546834,0.03610882176435287,301.28496970561446,209.94769104670178,1.1191128964664685
0.002747654482777723,0.036147229445889176,301.35028843052197,209.94769104670178,1.1191128964664685
0.002788527173700283,0.036684936987397485,302.2619271234175,209.94769104670178,1.1191128964664685
0.0028016648243539624,0.03685777155431086,302.5538451489088,209.94769104670178,1.1191128964664685
0.0028469167321610827,0.03745309061812363,303.5552794295485,209.94769104670178,1.1191128964664685
0.0028702725555454028,0.03776035207041409,304.06971861725964,209.94769104670178,1.1191128964664685
0.002908225768544922,0.03825965193038608,304.9022139417416,209.94769104670178,1.1191128964664685
0.0029374205477753212,0.038643728745749145,305.5397149775146,209.94769104670178,1.1191128964664685
0.0029782932386978813,0.039181436287257454,306.42808055810127,209.94769104670178,1.1191128964664685
0.002984132194543961,0.03925825165033006,306.5546007038049,209.94769104670178,1.1191128964664685
0.0030031088010437205,0.03950790158031606,306.965126003866,209.94769104670178,1.1191128964664685
0.0030396022750817206,0.0399879975995199,307.75176529612025,209.94769104670178,1.1191128964664685
0.00306587757638908,0.040333666733346665,308.31586661877805,209.94769104670178,1.1191128964664685
0.00307755548808124,0.040487297459491894,308.56597278370066,209.94769104670178,1.1191128964664685
0.0031009113114655595,0.04079455891178235,309.0650774988344,209.94769104670178,1.1191128964664685
0.003169519042657,0.04169713942788558,310.52278771946436,209.94769104670178,1.1191128964664685
0.0032089319946180393,0.04221564312862573,311.354629889965,209.94769104670178,1.1191128964664685
0.003235207295925399,0.042561312262452494,311.90697873229186,209.94769104670178,1.1191128964664685
0.0032629423361942786,0.042926185237047415,312.48811895961103,209.94769104670178,1.1191128964664685
0.0032950565933477175,0.043348669733946785,313.15861683762165,209.94769104670178,1.1191128964664685
0.003349066934923957,0.04405921184236847,314.2805531998562,209.94769104670178,1.1191128964664685
0.0033592851076545975,0.04419363872774555,314.4920153094007,209.94769104670178,1.1191128964664685
0.003365124063500677,0.04427045409081816,314.6127381702443,209.94769104670178,1.1191128964664685
0.0033826409310389175,0.04450090018003601,314.97441754188446,209.94769104670178,1.1191128964664685
0.003392859103769557,0.04463532706541308,315.1850598530299,209.94769104670178,1.1191128964664685
0.003454168140153396,0.04544188837767553,316.4437569883907,209.94769104670178,1.1191128964664685
0.0034673057908070765,0.04561472294458892,316.7123407863772,209.94769104670178,1.1191128964664685
0.0034965005700374765,0.045998799759952,317.30777678396447,209.94769104670178,1.1191128964664685
0.0035110979596526763,0.04619083816763353,317.6047674404698,209.94769104670178,1.1191128964664685
0.003543212216806116,0.046613322664532914,318.25645709701166,209.94769104670178,1.1191128964664685
0.0035534303895367555,0.046747749549909984,318.4633292746679,209.94769104670178,1.1191128964664685
0.003566568040190436,0.04692058411682337,318.728967207529,209.94769104670178,1.1191128964664685
0.0036337160324203545,0.04780396079215843,320.0807580417,209.94769104670178,1.1191128964664685
0.003687726373996594,0.04851450290058011,321.1610117726772,209.94769104670178,1.1191128964664685
0.003699404285688754,0.04866813362672534,321.3937668372725,209.94769104670178,1.1191128964664685
0.003708162719457874,0.048783356671334266,321.5681451354122,209.94769104670178,1.1191128964664685
0.003722760109073074,0.0489753950790158,321.8584191020121,209.94769104670178,1.1191128964664685
0.0037373574986882744,0.049167433486697346,322.1482495088472,209.94769104670178,1.1191128964664685
0.003747575671418914,0.049301860372074416,322.35086816504406,209.94769104670178,1.1191128964664685
0.0037548743662265136,0.04939787957591518,322.4954638846467,209.94769104670178,1.1191128964664685
0.003778230189610833,0.04970514102820564,322.95743530696416,209.94769104670178,1.1191128964664685
0.0038161834026103525,0.05020444088817763,323.7057705199631,209.94769104670178,1.1191128964664685
0.0039037677403015525,0.05135667133426686,325.42170710985215,209.94769104670178,1.1191128964664685
0.003921284607839792,0.051587117423484694,325.7630854981446,209.94769104670178,1.1191128964664685
0.0039606975598008316,0.052105621124224843,326.52901981789336,209.94769104670178,1.1191128964664685
0.003997191033838832,0.05258571714342869,327.2355720610804,209.94769104670178,1.1191128964664685
0.004054120853338111,0.053334666933386676,328.3327907196963,209.94769104670178,1.1191128964664685
0.004113970150760431,0.05412202440488098,329.4798174824205,209.94769104670178,1.1191128964664685
0.00415630258064451,0.054678935787157434,330.28720289910456,209.94769104670178,1.1191128964664685
0.004169440231298189,0.05485177035407081,330.5371178566907,209.94769104670178,1.1191128964664685
0.00417673892610579,0.05494778955791159,330.6758267923483,209.94769104670178,1.1191128964664685
0.004198635010528589,0.05523584716943389,331.09138751800083,209.94769104670178,1.1191128964664685
0.004264323263796989,0.0561000200040008,332.33302790090954,209.94769104670178,1.1191128964664685
0.004300816737834989,0.056580116023204646,333.01960432806936,209.94769104670178,1.1191128964664685
0.004341689428757548,0.05711782356471294,333.7858782324535,209.94769104670178,1.1191128964664685
0.004351907601488189,0.057252250450090025,333.9770064880731,209.94769104670178,1.1191128964664685
0.0043840218586416275,0.057674734946989395,334.5765590512027,209.94769104670178,1.1191128964664685
0.004400078987218347,0.05788597719543909,334.8756928410784,209.94769104670178,1.1191128964664685
0.004421975071641147,0.058174034806961386,335.2829173621143,209.94769104670178,1.1191128964664685
0.004489123063871067,0.05905741148229646,336.5268632549848,209.94769104670178,1.1191128964664685
0.004529995754793626,0.059595119023804766,337.28049545153414,209.94769104670178,1.1191128964664685
0.004548972361293386,0.05984476895379076,337.6294942255877,209.94769104670178,1.1191128964664685
0.004557730795062507,0.059959991998399687,337.79037903316447,209.94769104670178,1.1191128964664685
0.004567948967793146,0.06009441888377676,337.9779256614363,209.94769104670178,1.1191128964664685
0.004636556698984585,0.06099699939987997,339.2329566925008,209.94769104670178,1.1191128964664685
0.004658452783407385,0.061285057011402286,339.6319711662221,209.94769104670178,1.1191128964664685
0.004709543647060585,0.061957191438287665,340.56017124535754,209.94769104670178,1.1191128964664685
0.004747496860060104,0.062456491298259656,341.2471511634268,209.94769104670178,1.1191128964664685
0.0047635539886368245,0.06266773354670935,341.53715135830214,209.94769104670178,1.1191128964664685
0.004817564330213063,0.06337827565513103,342.509820775159,209.94769104670178,1.1191128964664685
0.004832161719828264,0.06357031406281256,342.77197318546007,209.94769104670178,1.1191128964664685
0.004858437021135623,0.06391598319663933,343.243070538829,209.94769104670178,1.1191128964664685
0.004865735715943223,0.06401200240048009,343.37375444171784,209.94769104670178,1.1191128964664685
0.004915366840634903,0.06466493298659733,344.26038621287654,209.94769104670178,1.1191128964664685
0.004924125274404022,0.06478015603120624,344.41648752177286,209.94769104670178,1.1191128964664685
0.004947481097788342,0.0650874174834967,344.83222919331934,209.94769104670178,1.1191128964664685
0.004962078487403543,0.06527945589117824,345.09167908663267,209.94769104670178,1.1191128964664685
0.004992733005595462,0.06568273654730947,345.63555695924646,209.94769104670178,1.1191128964664685
0.005046743347171701,0.06639327865573115,346.59065984009226,209.94769104670178,1.1191128964664685
0.005064260214709942,0.066623724744949,346.8995657450426,209.94769104670178,1.1191128964664685
0.005089075777055781,0.0669501900380076,347.336470075455,209.94769104670178,1.1191128964664685
0.005102213427709461,0.06712302460492099,347.5674359539682,209.94769104670178,1.1191128964664685
0.005109512122517061,0.06721904380876176,347.6956501079896,209.94769104670178,1.1191128964664685
0.005141626379670501,0.06764152830566114,348.2589459630412,209.94769104670178,1.1191128964664685
0.00518395880955458,0.0681984396879376,348.99938028822174,209.94769104670178,1.1191128964664685
0.005192717243323699,0.0683136627325465,349.1522787676993,209.94769104670178,1.1191128964664685
0.0052073146329389,0.06850570114022805,349.40688625151586,209.94769104670178,1.1191128964664685
0.005254026279707539,0.06912022404480897,350.21976599499027,209.94769104670178,1.1191128964664685
0.005261324974515139,0.06921624324864974,350.3465234048889,209.94769104670178,1.1191128964664685
0.0052992781875146585,0.06971554310862173,351.0045597200839,209.94769104670178,1.1191128964664685
0.005364966440783058,0.07057971594318864,352.1391416779691,209.94769104670178,1.1191128964664685
0.005392701481051938,0.07094458891778356,352.61655924875674,209.94769104670178,1.1191128964664685
0.005401459914821058,0.07105981196239249,352.76712361881283,209.94769104670178,1.1191128964664685
0.005483205296666177,0.07213522704540909,354.16782955700467,209.94769104670178,1.1191128964664685
0.005525537726550257,0.07269213842768554,354.8899929516453,209.94769104670178,1.1191128964664685
0.005621880498010576,0.07395959191838368,356.5255417283572,209.94769104670178,1.1191128964664685
0.0056320986707412155,0.07409401880376075,356.6983654287653,209.94769104670178,1.1191128964664685
0.005675890839586815,0.07467013402680536,357.4376576685585,209.94769104670178,1.1191128964664685
0.005713844052586335,0.07516943388677735,358.0765800220448,209.94769104670178,1.1191128964664685
0.005732820659086095,0.07541908381676336,358.39542036978526,209.94769104670178,1.1191128964664685
0.005743038831816735,0.07555351070214043,358.566933132907,209.94769104670178,1.1191128964664685
0.005763475177278015,0.07582236447289459,358.9096020389112,209.94769104670178,1.1191128964664685
0.005778072566893214,0.07601440288057612,359.1540754833454,209.94769104670178,1.1191128964664685
0.005808727085085134,0.07641768353670735,359.66668706531806,209.94769104670178,1.1191128964664685
0.005870036121468973,0.0772242448489698,360.68875604688316,209.94769104670178,1.1191128964664685
0.005900690639660893,0.07762752550510102,361.1982287164411,209.94769104670178,1.1191128964664685
0.005950321764352573,0.07828045609121825,362.0209061561605,209.94769104670178,1.1191128964664685
0.005994113933198172,0.07885657131426285,362.74457819535456,209.94769104670178,1.1191128964664685
0.006007251583851852,0.07902940588117624,362.9612773449673,209.94769104670178,1.1191128964664685
0.0060335268851592115,0.079375075015003,363.3941219613932,209.94769104670178,1.1191128964664685
0.006052503491658971,0.079624724944989,363.7062748961611,209.94769104670178,1.1191128964664685
0.0060802385319278516,0.07998959791958392,364.1618126954783,209.94769104670178,1.1191128964664685
0.006105054094273692,0.08031606321264254,364.5687126746555,209.94769104670178,1.1191128964664685
0.00612257096181193,0.08054650930186037,364.8555479177801,209.94769104670178,1.1191128964664685
0.006144467046234731,0.08083456691338269,365.2136422984228,209.94769104670178,1.1191128964664685
0.006258326685233289,0.08233246649329866,367.06777112281645,209.94769104670178,1.1191128964664685
0.006300659115117369,0.08288937787557511,367.7537658392512,209.94769104670178,1.1191128964664685
0.006316716243694088,0.0831006201240248,368.013500218959,209.94769104670178,1.1191128964664685
0.006324014938501689,0.08319663932786557,368.131476165435,209.94769104670178,1.1191128964664685
0.006350290239809049,0.08354230846169235,368.5557505971578,209.94769104670178,1.1191128964664685
0.006383864235924008,0.08398399679935988,369.09688403834826,209.94769104670178,1.1191128964664685
0.006401381103462249,0.08421444288857773,369.3787738587961,209.94769104670178,1.1191128964664685
0.006413059015154409,0.08436807361472295,369.5665332942027,209.94769104670178,1.1191128964664685
0.006464149878807607,0.08504020804160832,370.3864180133722,209.94769104670178,1.1191128964664685
0.006506482308691688,0.08559711942388479,371.0638382696199,209.94769104670178,1.1191128964664685
0.006522539437268406,0.08580836167233447,371.32034085589385,209.94769104670178,1.1191128964664685
0.006540056304806647,0.08603880776155232,371.5998811552727,209.94769104670178,1.1191128964664685
0.006550274477537287,0.08617323464692939,371.76281148292077,209.94769104670178,1.1191128964664685
0.006561952389229447,0.08632686537307462,371.9488962442978,209.94769104670178,1.1191128964664685
0.006586767951575287,0.08665333066613323,372.3438980761905,209.94769104670178,1.1191128964664685
0.006608664035998086,0.08694138827765553,372.69194737833476,209.94769104670178,1.1191128964664685
0.0066291003814593664,0.08721024204840969,373.01638785111663,209.94769104670178,1.1191128964664685
0.006643697771074566,0.08740228045609122,373.24789227022677,209.94769104670178,1.1191128964664685
0.006659754899651285,0.08761352270454091,373.50231812811955,209.94769104670178,1.1191128964664685
0.006672892550304966,0.0877863572714543,373.71030683866604,209.94769104670178,1.1191128964664685
0.006702087329535365,0.08817043408681736,374.1719330583844,209.94769104670178,1.1191128964664685
0.006723983413958166,0.08845849169833968,374.51763824027086,209.94769104670178,1.1191128964664685
0.006734201586688805,0.08859291858371675,374.67881704808235,209.94769104670178,1.1191128964664685
0.006744419759419445,0.08872734546909382,374.83990050354885,209.94769104670178,1.1191128964664685
0.006766315843842245,0.08901540308061613,375.1847591847989,209.94769104670178,1.1191128964664685
0.006820326185418484,0.08972594518903781,376.0335549836882,209.94769104670178,1.1191128964664685
0.006832004097110644,0.08987957591518304,376.2167332642632,209.94769104670178,1.1191128964664685
0.006890393655571443,0.09064772954590919,377.1307993789559,209.94769104670178,1.1191128964664685
0.006929806607532484,0.09116623324664934,377.7460868918211,209.94769104670178,1.1191128964664685
0.006940024780263123,0.09130066013202641,377.9053829061472,209.94769104670178,1.1191128964664685
0.006956081908839843,0.0915119023804761,378.15552053123145,209.94769104670178,1.1191128964664685
0.0070071727724930425,0.09218403680736148,378.9499189694071,209.94769104670178,1.1191128964664685
0.007014471467300642,0.09228005601120225,379.063219784957,209.94769104670178,1.1191128964664685
0.007027609117954323,0.09245289057811563,379.2670454570779,209.94769104670178,1.1191128964664685
0.007048045463415602,0.09272174434886978,379.5838124875006,209.94769104670178,1.1191128964664685
0.0070757805036844815,0.0930866173234647,380.0131382421025,209.94769104670178,1.1191128964664685
0.007094757110184241,0.09333626725345069,380.30650936570856,209.94769104670178,1.1191128964664685
0.007137089540068321,0.09389317863572715,380.95985209816257,209.94769104670178,1.1191128964664685
0.007182341447875441,0.09448849769953992,381.65658392258786,209.94769104670178,1.1191128964664685
0.007196938837490641,0.09468053610722145,381.88097064832886,209.94769104670178,1.1191128964664685
0.0072246738777595205,0.09504540908181637,382.3068170305348,209.94769104670178,1.1191128964664685
0.0072451102232208,0.09531426285257052,382.62019071448697,209.94769104670178,1.1191128964664685
0.007265546568682079,0.09558311662332467,382.93321985244904,209.94769104670178,1.1191128964664685
0.00729766082583552,0.09600560112022405,383.42442989521913,209.94769104670178,1.1191128964664685
0.007323936127142879,0.09635127025405081,383.82570227325397,209.94769104670178,1.1191128964664685
0.007369188034949999,0.09694658931786358,384.5154688671364,209.94769104670178,1.1191128964664685
0.007399842553141919,0.09734986997399481,384.98179182476974,209.94769104670178,1.1191128964664685
0.007458232111602718,0.09811802360472095,385.8679470797341,209.94769104670178,1.1191128964664685
0.007481587934987038,0.09842528505701141,386.22165109893194,209.94769104670178,1.1191128964664685
0.007491806107717678,0.09855971194238848,386.37626116596493,209.94769104670178,1.1191128964664685
0.007509322975255918,0.09879015803160633,386.6411157956831,209.94769104670178,1.1191128964664685
0.007560413838909117,0.0994622924584917,387.41223566579083,209.94769104670178,1.1191128964664685
0.007595447573985596,0.09992318463692738,387.9398293847519,209.94769104670178,1.1191128964664685
0.007599826790870156,0.09998079615923185,388.00571180335425,209.94769104670178,1.1191128964664685