File: datasets/aisi_316_L/data/M1/train_60.csv
Time(s),Strain(%),Stress(MPa),Temp(C),Log_SR(s-1)
0.0,0.0,0.0,118.74367088460689,-2.1813245693773933
0.0027934595843415963,1.84e-05,3.5310451,118.74367088460689,-2.1813245693773933
0.00534400963961001,3.52e-05,6.7550428,118.74367088460689,-2.1813245693773933
0.006072738226829556,3.9999999999999996e-05,7.676184999999999,118.74367088460689,-2.1813245693773933
0.0070443763431222856,4.6399999999999996e-05,8.904374599999999,118.74367088460689,-2.1813245693773933
0.012145476453659113,7.999999999999999e-05,15.352369999999999,118.74367088460689,-2.1813245693773933
0.013117114569951842,8.64e-05,16.5805596,118.74367088460689,-2.1813245693773933
0.013481478863561614,8.879999999999999e-05,17.041130699999997,118.74367088460689,-2.1813245693773933
0.01396729792170798,9.2e-05,17.6552255,118.74367088460689,-2.1813245693773933
0.016639302741512985,0.0001096,21.0327469,118.74367088460689,-2.1813245693773933
0.019311307561317992,0.0001272,24.410268300000002,118.74367088460689,-2.1813245693773933
0.022226221910196176,0.00014639999999999998,28.094837099999996,118.74367088460689,-2.1813245693773933
0.024655317200928,0.0001624,31.165311099999997,118.74367088460689,-2.1813245693773933
0.025869864846293913,0.0001704,32.7005481,118.74367088460689,-2.1813245693773933
0.028420414901562326,0.0001872,35.9245458,118.74367088460689,-2.1813245693773933
0.029513507782391642,0.00019439999999999998,37.3062591,118.74367088460689,-2.1813245693773933
0.03340006024756256,0.00021999999999999998,42.2190175,118.74367088460689,-2.1813245693773933
0.03631497459644075,0.0002392,45.9035863,118.74367088460689,-2.1813245693773933
0.037893886535416435,0.0002496,47.8993944,118.74367088460689,-2.1813245693773933
0.040322981826148255,0.0002656,50.9698684,118.74367088460689,-2.1813245693773933
0.04238771282327031,0.0002792,53.579771300000004,118.74367088460689,-2.1813245693773933
0.0438451699977094,0.00028879999999999997,55.422055699999994,118.74367088460689,-2.1813245693773933
0.04578844623029486,0.0003016,57.8784349,118.74367088460689,-2.1813245693773933
0.0478531772274169,0.00031519999999999996,60.4883378,118.74367088460689,-2.1813245693773933
0.051739729692587826,0.0003408,65.4010962,118.74367088460689,-2.1813245693773933
0.05866265127117351,0.00038639999999999996,74.15194709999999,118.74367088460689,-2.1813245693773933
0.05914847032931988,0.0003896,74.76604189999999,118.74367088460689,-2.1813245693773933
0.05975574415200283,0.00039359999999999997,75.53366039999999,118.74367088460689,-2.1813245693773933
0.06218483944273466,0.0004096,78.60413439999999,118.74367088460689,-2.1813245693773933
0.06352084185263716,0.0004184,80.2928951,118.74367088460689,-2.1813245693773933
0.06740739431780808,0.000444,85.2056535,118.74367088460689,-2.1813245693773933
0.06910776102132035,0.0004552,87.3549853,118.74367088460689,-2.1813245693773933
0.07226558489927172,0.00047599999999999997,91.34660149999999,118.74367088460689,-2.1813245693773933
0.07323722301556444,0.00048239999999999996,92.5747911,118.74367088460689,-2.1813245693773933
0.07396595160278399,0.00048719999999999997,93.49593329999999,118.74367088460689,-2.1813245693773933
0.07615213736444264,0.0005015999999999999,96.25935989999999,118.74367088460689,-2.1813245693773933
0.07858123265517447,0.0005176,99.3298339,118.74367088460689,-2.1813245693773933
0.08186051129766242,0.0005392,103.4749738,118.74367088460689,-2.1813245693773933
0.08271069464941856,0.0005448,104.5496397,118.74367088460689,-2.1813245693773933
0.08513978994015038,0.0005608,107.62011369999999,118.74367088460689,-2.1813245693773933
0.08914779716985789,0.0005872,112.6863958,118.74367088460689,-2.1813245693773933
0.09206271151873609,0.0006064,116.3709646,118.74367088460689,-2.1813245693773933
0.09352016869317517,0.000616,118.213249,118.74367088460689,-2.1813245693773933
0.09485617110307767,0.0006248,119.90200970000001,118.74367088460689,-2.1813245693773933
0.09679944733566313,0.0006376,122.3583889,118.74367088460689,-2.1813245693773933
0.09813544974556564,0.0006464,124.0471496,118.74367088460689,-2.1813245693773933
0.09874272356824859,0.0006504,124.8147681,118.74367088460689,-2.1813245693773933
0.10250782126888291,0.0006751999999999999,129.5740028,118.74367088460689,-2.1813245693773933
0.10748746661488315,0.000708,135.8684745,118.74367088460689,-2.1813245693773933
0.1095521976120052,0.0007216,138.4783774,118.74367088460689,-2.1813245693773933
0.11052383572829792,0.0007279999999999999,139.70656699999998,118.74367088460689,-2.1813245693773933
0.11198129290273702,0.0007375999999999999,141.5488514,118.74367088460689,-2.1813245693773933
0.11258856672541998,0.0007415999999999999,142.3164699,118.74367088460689,-2.1813245693773933
0.1178111216004934,0.000776,148.917989,118.74367088460689,-2.1813245693773933
0.12024021689122522,0.000792,151.988463,118.74367088460689,-2.1813245693773933
0.12497695270815228,0.0008232,157.97588729999998,118.74367088460689,-2.1813245693773933
0.12643440988259136,0.0008328,159.8181717,118.74367088460689,-2.1813245693773933
0.12825623135064024,0.0008447999999999999,162.1210272,118.74367088460689,-2.1813245693773933
0.12947077899600615,0.0008527999999999999,163.65626419999998,118.74367088460689,-2.1813245693773933
0.13141405522859162,0.0008656,166.1126434,118.74367088460689,-2.1813245693773933
0.13930861492347002,0.0009176,176.0916839,118.74367088460689,-2.1813245693773933
0.139915888746153,0.0009216,176.8593024,118.74367088460689,-2.1813245693773933
0.14319516738864094,0.0009431999999999999,181.0044423,118.74367088460689,-2.1813245693773933
0.14501698885668982,0.0009551999999999999,183.3072978,118.74367088460689,-2.1813245693773933
0.14623153650205573,0.0009632,184.8425348,118.74367088460689,-2.1813245693773933
0.14975372467361686,0.0009864,189.29472209999997,118.74367088460689,-2.1813245693773933
0.15388318666786097,0.0010136,194.5145279,118.74367088460689,-2.1813245693773933
0.1561908271940562,0.0010287999999999999,197.43147819999996,118.74367088460689,-2.1813245693773933
0.15752682960395867,0.0010375999999999999,199.12023889999998,118.74367088460689,-2.1813245693773933
0.15837701295571485,0.0010432,200.1949048,118.74367088460689,-2.1813245693773933
0.16092756301098324,0.00106,203.4189025,118.74367088460689,-2.1813245693773933
0.16323520353717846,0.0010752,206.33585279999997,118.74367088460689,-2.1813245693773933
0.16481411547615415,0.0010856,208.33166089999997,118.74367088460689,-2.1813245693773933
0.16675739170873963,0.0010984,210.78804010000002,118.74367088460689,-2.1813245693773933
0.16870066794132507,0.0011112,213.24441929999998,118.74367088460689,-2.1813245693773933
0.17088685370298373,0.0011256,216.0078459,118.74367088460689,-2.1813245693773933
0.17416613234547168,0.0011472,220.15298579999998,118.74367088460689,-2.1813245693773933
0.1753806799908376,0.0011551999999999999,221.68822279999998,118.74367088460689,-2.1813245693773933
0.17635231810713034,0.0011616,222.9164124,118.74367088460689,-2.1813245693773933
0.17720250145888647,0.0011672,223.9910783,118.74367088460689,-2.1813245693773933
0.17987450627869148,0.0011848,227.3685997,118.74367088460689,-2.1813245693773933
0.1821821468048867,0.0012,229.12693108158163,118.74367088460689,-2.1813245693773933
0.18485415162469168,0.0012175999999999999,229.24794398140085,118.74367088460689,-2.1813245693773933
0.18934797791254557,0.0012472,229.44993839930697,118.74367088460689,-2.1813245693773933
0.191291254145131,0.0012599999999999998,229.5367073100307,118.74367088460689,-2.1813245693773933
0.19481344231669218,0.0012832,229.6931047732371,118.74367088460689,-2.1813245693773933
0.2011290900725949,0.0013248,229.9708075428089,118.74367088460689,-2.1813245693773933
0.2070803735348879,0.001364,230.2293926137362,118.74367088460689,-2.1813245693773933
0.2080520116511806,0.0013704,230.27133381316338,118.74367088460689,-2.1813245693773933
0.2090236497674733,0.0013767999999999999,230.31319869150877,118.74367088460689,-2.1813245693773933
0.21436765940708333,0.0014119999999999998,230.54211302966607,118.74367088460689,-2.1813245693773933
0.21667529993327858,0.0014272,230.6402731614668,118.74367088460689,-2.1813245693773933
0.2203189428693763,0.0014512,230.7944367736701,118.74367088460689,-2.1813245693773933
0.22250512863103494,0.0014655999999999998,230.88645772301484,118.74367088460689,-2.1813245693773933
0.22371967627640088,0.0014736,230.93742809093015,118.74367088460689,-2.1813245693773933
0.2262702263316693,0.0014904,231.0441159252912,118.74367088460689,-2.1813245693773933
0.2277276835061084,0.0015,231.1048698126434,118.74367088460689,-2.1813245693773933
0.22833495732879133,0.001504,231.13013915525542,118.74367088460689,-2.1813245693773933
0.23003532403230362,0.0015152,231.20075425603798,118.74367088460689,-2.1813245693773933
0.23367896696840132,0.0015392,231.35139047772327,118.74367088460689,-2.1813245693773933
0.23574369796552339,0.0015528,231.43634433904367,118.74367088460689,-2.1813245693773933
0.2381727932562552,0.0015688,231.53591943650676,118.74367088460689,-2.1813245693773933
0.24120916236967,0.0015888,231.65983308675192,118.74367088460689,-2.1813245693773933
0.24157352666327975,0.0015911999999999999,231.67466173427798,118.74367088460689,-2.1813245693773933
0.2436382576604018,0.0016048,231.75852655700143,118.74367088460689,-2.1813245693773933
0.2440026219540116,0.0016072,231.7732974128324,118.74367088460689,-2.1813245693773933
0.24473135054123113,0.001612,231.8028133430926,118.74367088460689,-2.1813245693773933
0.24606735295113363,0.0016208,231.8568370115231,118.74367088460689,-2.1813245693773933
0.2478891744191825,0.0016328,231.93032165857443,118.74367088460689,-2.1813245693773933
0.24971099588723136,0.0016447999999999999,232.0035959801444,118.74367088460689,-2.1813245693773933
0.25189718164889,0.0016592,232.09125053272896,118.74367088460689,-2.1813245693773933
0.25384045788147547,0.0016719999999999999,232.16891692427237,118.74367088460689,-2.1813245693773933
0.25882010322747573,0.0017048,232.36688598320663,118.74367088460689,-2.1813245693773933
0.26331392951532956,0.0017343999999999999,232.54426942369872,118.74367088460689,-2.1813245693773933
0.26732193674503707,0.0017607999999999999,232.70148259490034,118.74367088460689,-2.1813245693773933
0.27120848921020796,0.0017863999999999998,232.85305615471825,118.74367088460689,-2.1813245693773933
0.27327322020733,0.0018,232.93323493116276,118.74367088460689,-2.1813245693773933
0.2777670464951839,0.0018296,233.10692950716427,118.74367088460689,-2.1813245693773933
0.2784957750824035,0.0018344,233.1349925996996,118.74367088460689,-2.1813245693773933
0.279831777492306,0.0018432,233.1863673353684,118.74367088460689,-2.1813245693773933
0.28165359896035486,0.0018552,233.25626989855058,118.74367088460689,-2.1813245693773933
0.2840826942510867,0.0018712,233.34919962681468,118.74367088460689,-2.1813245693773933
0.28687615383542825,0.0018896,233.4556865611678,118.74367088460689,-2.1813245693773933
0.29513507782391646,0.001944,233.76817719569712,118.74367088460689,-2.1813245693773933
0.30157218034435573,0.0019863999999999997,234.0093769966948,118.74367088460689,-2.1813245693773933
0.3031510922833315,0.0019968,234.0682315323452,118.74367088460689,-2.1813245693773933
0.3066732804548926,0.00202,234.19909332566823,118.74367088460689,-2.1813245693773933
0.30995255909738056,0.0020415999999999998,234.32040422635274,118.74367088460689,-2.1813245693773933
0.31444638538523445,0.0020712,234.48583524276088,118.74367088460689,-2.1813245693773933
0.3184543926149419,0.0020976,234.63260549546538,118.74367088460689,-2.1813245693773933
0.32039766884752735,0.0021103999999999997,234.70350735940548,118.74367088460689,-2.1813245693773933
0.3222194903155763,0.0021224,234.7698256913869,118.74367088460689,-2.1813245693773933
0.32562022372260085,0.0021448,234.89322996078465,118.74367088460689,-2.1813245693773933
0.3278064094842595,0.0021592,234.97229593087627,118.74367088460689,-2.1813245693773933
0.32902095712962537,0.0021671999999999998,235.0161326027697,118.74367088460689,-2.1813245693773933
0.33217878100757675,0.002188,235.12981361305984,118.74367088460689,-2.1813245693773933
0.3330289643593329,0.0021936,235.16034792810058,118.74367088460689,-2.1813245693773933
0.33460787629830857,0.002204,235.21697397983024,118.74367088460689,-2.1813245693773933
0.33642969776635745,0.002216,235.28218240400233,118.74367088460689,-2.1813245693773933
0.3387373382925527,0.0022312,235.36458238346773,118.74367088460689,-2.1813245693773933
0.3418951621705041,0.002252,235.47698635860837,118.74367088460689,-2.1813245693773933
0.3476035361037238,0.0022895999999999997,235.67915599302384,118.74367088460689,-2.1813245693773933
0.35088281474621175,0.0023112,235.79471038658284,118.74367088460689,-2.1813245693773933
0.3545264576823095,0.0023352,235.922611307534,118.74367088460689,-2.1813245693773933
0.35646973391489495,0.002348,235.99061546475153,118.74367088460689,-2.1813245693773933
0.3584130101474804,0.0023607999999999997,236.0584751934602,118.74367088460689,-2.1813245693773933
0.363878474551627,0.0023967999999999997,236.24856564902274,118.74367088460689,-2.1813245693773933
0.36533593172606615,0.0024064,236.29906796365046,118.74367088460689,-2.1813245693773933
0.3681293913104077,0.0024248,236.39564498143847,118.74367088460689,-2.1813245693773933
0.3704370318366029,0.00244,236.47521060664315,118.74367088460689,-2.1813245693773933
0.37165157948196886,0.002448,236.51700959589144,118.74367088460689,-2.1813245693773933
0.3738377652436275,0.0024624,236.59211377519622,118.74367088460689,-2.1813245693773933
0.37614540576982275,0.0024776,236.67120481847525,118.74367088460689,-2.1813245693773933
0.3767526795925057,0.0024816,236.6919867705372,118.74367088460689,-2.1813245693773933
0.377238498650652,0.0024847999999999997,236.7086029275897,118.74367088460689,-2.1813245693773933
0.3801534129995302,0.0025039999999999997,236.80812517813635,118.74367088460689,-2.1813245693773933
0.3833112368774816,0.0025248,236.91560569824702,118.74367088460689,-2.1813245693773933
0.38537596787460365,0.0025383999999999997,236.98569476287798,118.74367088460689,-2.1813245693773933
0.38646906075543297,0.0025456,237.02274144072015,118.74367088460689,-2.1813245693773933
0.38756215363626234,0.0025528,237.059747275585,118.74367088460689,-2.1813245693773933
0.3905985227496771,0.0025728,237.16232829503068,118.74367088460689,-2.1813245693773933
0.39436362045031137,0.0025976,237.28909786665878,118.74367088460689,-2.1813245693773933
0.39776435385733594,0.00262,237.4031942798121,118.74367088460689,-2.1813245693773933
0.3995861753253848,0.002632,237.46416083632002,118.74367088460689,-2.1813245693773933
0.40043635867714095,0.0026376,237.49257478832826,118.74367088460689,-2.1813245693773933
0.402501089674263,0.0026512,237.56148232685013,118.74367088460689,-2.1813245693773933
0.4052945492586046,0.0026696,237.65449114858097,118.74367088460689,-2.1813245693773933
0.40869528266562916,0.002692,237.76738251717717,118.74367088460689,-2.1813245693773933
0.41270328989533667,0.0027183999999999997,237.89996381319403,118.74367088460689,-2.1813245693773933
0.4136749280116294,0.0027248,237.93202899519625,118.74367088460689,-2.1813245693773933
0.4161040233023612,0.0027408,238.01206371234542,118.74367088460689,-2.1813245693773933
0.41768293524133693,0.0027512,238.06398858364958,118.74367088460689,-2.1813245693773933
0.41950475670938575,0.0027632,238.1238068694326,118.74367088460689,-2.1813245693773933
0.4229054901164103,0.0027856,238.2351972979995,118.74367088460689,-2.1813245693773933
0.42569894970075195,0.002804,238.32643547902367,118.74367088460689,-2.1813245693773933
0.4275207711688008,0.002816,238.38581287080635,118.74367088460689,-2.1813245693773933
0.43116441410489853,0.00284,238.50427243671726,118.74367088460689,-2.1813245693773933
0.4327433260438742,0.0028504,238.5554835992765,118.74367088460689,-2.1813245693773933
0.4355367856282158,0.0028688,238.645909808134,118.74367088460689,-2.1813245693773933
0.43699424280265486,0.0028783999999999997,238.69299889147206,118.74367088460689,-2.1813245693773933
0.4379658809189476,0.0028848,238.72435759056302,118.74367088460689,-2.1813245693773933
0.44015206668060625,0.0028991999999999998,238.79481563081555,118.74367088460689,-2.1813245693773933
0.440516430974216,0.0029016,238.80654535568365,118.74367088460689,-2.1813245693773933
0.44221679767772826,0.0029127999999999997,238.8612341199166,118.74367088460689,-2.1813245693773933
0.4440386191457772,0.0029248,238.91973829725202,118.74367088460689,-2.1813245693773933
0.4456175310847528,0.0029352,238.97036623618467,118.74367088460689,-2.1813245693773933
0.44731789778826514,0.0029464,239.02481045623168,118.74367088460689,-2.1813245693773933
0.45108299548889946,0.0029712,239.14507910695767,118.74367088460689,-2.1813245693773933
0.4522975431342654,0.0029792,239.18379184689329,118.74367088460689,-2.1813245693773933
0.4547266384249972,0.0029952,239.2610959139899,118.74367088460689,-2.1813245693773933
0.45630555036397286,0.0030055999999999998,239.31125720929217,118.74367088460689,-2.1813245693773933
0.4597062837709974,0.003028,239.41906758840486,118.74367088460689,-2.1813245693773933
0.4688153911112418,0.003088,239.70632389084804,118.74367088460689,-2.1813245693773933
0.4736735816927054,0.00312,239.8586367987641,118.74367088460689,-2.1813245693773933
0.4742808555153884,0.003124,239.8776329812764,118.74367088460689,-2.1813245693773933
0.4768314055706568,0.0031408,239.95731358327183,118.74367088460689,-2.1813245693773933
0.47913904609685204,0.003156,240.02926244222152,118.74367088460689,-2.1813245693773933
0.4810823223294375,0.0031688,240.08974619567957,118.74367088460689,-2.1813245693773933
0.4831470533265595,0.0031823999999999997,240.153905875138,118.74367088460689,-2.1813245693773933
0.48472596526553524,0.0031928,240.20289703385026,118.74367088460689,-2.1813245693773933
0.49055579396329163,0.0032312,240.38325084489244,118.74367088460689,-2.1813245693773933
0.4911630677859745,0.0032351999999999997,240.40198950184308,118.74367088460689,-2.1813245693773933
0.49322779878309664,0.0032488,240.46563345736095,118.74367088460689,-2.1813245693773933
0.4937136178412429,0.0032519999999999997,240.48059339519511,118.74367088460689,-2.1813245693773933
0.49492816548660884,0.00326,240.51796814450472,118.74367088460689,-2.1813245693773933
0.4966285321901211,0.0032711999999999997,240.57023275638107,118.74367088460689,-2.1813245693773933
0.49796453460002366,0.00328,240.61124886582152,118.74367088460689,-2.1813245693773933
0.4994219917744627,0.0032895999999999997,240.65594479703415,118.74367088460689,-2.1813245693773933
0.5008794489489018,0.0032992,240.70058988721516,118.74367088460689,-2.1813245693773933
0.5078023705274876,0.0033447999999999998,240.9119660417421,118.74367088460689,-2.1813245693773933
0.5088954634083168,0.003352,240.94523821267026,118.74367088460689,-2.1813245693773933
0.5112031039345121,0.0033672,241.01538806999508,118.74367088460689,-2.1813245693773933
0.513024925402561,0.0033791999999999997,241.07068233773418,118.74367088460689,-2.1813245693773933
0.5164256588095855,0.0034016,241.17369384381303,118.74367088460689,-2.1813245693773933
0.518368935042171,0.0034143999999999997,241.23243877860787,118.74367088460689,-2.1813245693773933
0.5222554875073419,0.00344,241.3496716180922,118.74367088460689,-2.1813245693773933
0.5258991304434396,0.0034639999999999996,241.45926876930602,118.74367088460689,-2.1813245693773933
0.5278424066760251,0.0034768,241.51759947642162,118.74367088460689,-2.1813245693773933
0.5313645948475861,0.0034999999999999996,241.62311086219987,118.74367088460689,-2.1813245693773933
0.5333078710801716,0.0035128,241.68120727113296,118.74367088460689,-2.1813245693773933
0.5339151449028546,0.0035168,241.69934546000005,118.74367088460689,-2.1813245693773933
0.5346438734900741,0.0035215999999999997,241.72110066961568,118.74367088460689,-2.1813245693773933
0.5380446068970988,0.003544,241.82247246520413,118.74367088460689,-2.1813245693773933
0.5402307926587573,0.0035583999999999998,241.8875081187043,118.74367088460689,-2.1813245693773933
0.5432671617721722,0.0035784,241.9776653951109,118.74367088460689,-2.1813245693773933
0.5461820761210503,0.0035976,242.06403167569195,118.74367088460689,-2.1813245693773933
0.5472751690018797,0.0036048,242.0963726625649,118.74367088460689,-2.1813245693773933
0.5493398999990017,0.0036184,242.1573925416618,118.74367088460689,-2.1813245693773933
0.5516475405251969,0.0036336,242.2254854799759,118.74367088460689,-2.1813245693773933
0.5550482739322214,0.003656,242.32563083293437,118.74367088460689,-2.1813245693773933
0.5561413668130508,0.0036631999999999997,242.35776955320682,118.74367088460689,-2.1813245693773933
0.5599064645136851,0.003688,242.4682815101177,118.74367088460689,-2.1813245693773933
0.563793016978856,0.0037135999999999996,242.5820547960571,118.74367088460689,-2.1813245693773933
0.5648861098596853,0.0037208,242.61399836801934,118.74367088460689,-2.1813245693773933
0.5681653885021734,0.0037424,242.70968475437556,118.74367088460689,-2.1813245693773933
0.5709588480865149,0.0037608,242.79102561628812,118.74367088460689,-2.1813245693773933
0.5742381267290029,0.0037824,242.88631493786997,118.74367088460689,-2.1813245693773933
0.5749668553162224,0.0037871999999999997,242.90746149476237,118.74367088460689,-2.1813245693773933
0.5778817696651006,0.0038063999999999997,242.99194340496672,118.74367088460689,-2.1813245693773933
0.5809181387785154,0.0038263999999999998,243.0797688594149,118.74367088460689,-2.1813245693773933
0.5816468673657349,0.0038312,243.10082030693403,118.74367088460689,-2.1813245693773933
0.5840759626564668,0.0038472,243.17091762825308,118.74367088460689,-2.1813245693773933
0.5849261460082229,0.0038528,243.19542481837064,118.74367088460689,-2.1813245693773933
0.5872337865344182,0.003868,243.26187440703933,118.74367088460689,-2.1813245693773933
0.5902701556478329,0.003888,243.34915312723032,118.74367088460689,-2.1813245693773933
0.5905130651769062,0.0038896,243.35612785166688,118.74367088460689,-2.1813245693773933
0.5951283462292966,0.00392,243.48843576036774,118.74367088460689,-2.1813245693773933
0.5976788962845649,0.0039368,243.56138159434087,118.74367088460689,-2.1813245693773933
0.5987719891653942,0.003944,243.59260691915827,118.74367088460689,-2.1813245693773933
0.6012010844561261,0.00396,243.66191704622972,118.74367088460689,-2.1813245693773933
0.6024156321014921,0.003968,243.69653114764003,118.74367088460689,-2.1813245693773933
0.6043589083340775,0.0039808,243.7518571529525,118.74367088460689,-2.1813245693773933
0.6364287971666344,0.0041920384076815365,244.65511246293914,118.74367088460689,-2.1813245693773933
0.6976542435823594,0.004595319063812763,246.3316844979792,118.74367088460689,-2.1813245693773933
0.7355557104111416,0.00484496899379876,247.34082469480256,118.74367088460689,-2.1813245693773933
0.8026121517236025,0.005286657331466294,249.07787556934602,118.74367088460689,-2.1813245693773933
0.8405136185523846,0.005536307261452291,250.03461605610116,118.74367088460689,-2.1813245693773933
0.872584090484431,0.00574754950990198,250.8310925067609,118.74367088460689,-2.1813245693773933
0.8900770751746382,0.005862772554510902,251.26071875029984,118.74367088460689,-2.1813245693773933
1.0096124705577205,0.006650130026005201,254.11301575253694,118.74367088460689,-2.1813245693773933
1.0271054552479277,0.006765353070614123,254.51909671787956,118.74367088460689,-2.1813245693773933
1.059175927179974,0.006976595319063813,255.25664094342525,118.74367088460689,-2.1813245693773933
1.0737534144218135,0.007072614522904581,255.5890038495609,118.74367088460689,-2.1813245693773933
1.0883309016636527,0.007168633726745349,255.91961157456106,118.74367088460689,-2.1813245693773933
1.1058238863538599,0.00728385677135427,256.3140698263646,118.74367088460689,-2.1813245693773933
1.1757958251146885,0.007744748949789958,257.86815501029287,118.74367088460689,-2.1813245693773933
1.231190276633678,0.008109621924384877,259.07302787464016,118.74367088460689,-2.1813245693773933
1.2603452511173565,0.008301660332066413,259.6986682148347,118.74367088460689,-2.1813245693773933
1.2807537332559316,0.008436087217443489,260.1332621757788,118.74367088460689,-2.1813245693773933
1.3069932102912423,0.008608921784356871,260.6880776605139,118.74367088460689,-2.1813245693773933
1.4790075597449461,0.009741948389677936,264.22316910190426,118.74367088460689,-2.1813245693773933
1.4965005444351533,0.009857171434286858,264.5734410003894,118.74367088460689,-2.1813245693773933
1.5693879806443496,0.010337267453490697,266.01604370873787,118.74367088460689,-2.1813245693773933
1.604373950024764,0.01056771354270854,266.6991897446339,118.74367088460689,-2.1813245693773933
1.662683898992121,0.010951790358071613,267.8249939538425,118.74367088460689,-2.1813245693773933
1.709331858166007,0.011259051810362072,268.71458844230165,118.74367088460689,-2.1813245693773933
1.7676418071333642,0.011643128625725144,269.8133767239772,118.74367088460689,-2.1813245693773933
1.8026277765137786,0.011873574714942988,270.4658656622826,118.74367088460689,-2.1813245693773933
1.8638532229295037,0.012276855371074214,271.5959594551555,118.74367088460689,-2.1813245693773933
1.9046701872066538,0.012545709141828365,272.34132171199883,118.74367088460689,-2.1813245693773933
1.9134166795517573,0.012603320664132826,272.5002287490577,118.74367088460689,-2.1813245693773933
1.9921351106576897,0.013121824364872975,273.9178659582136,118.74367088460689,-2.1813245693773933
2.0329520749348395,0.013390678135627125,274.6443251785731,118.74367088460689,-2.1813245693773933
2.0416985672799433,0.013448289657931586,274.7992523961344,118.74367088460689,-2.1813245693773933
2.1029240136956684,0.013851570314062813,275.87658609731693,118.74367088460689,-2.1813245693773933
2.126247993282611,0.014005201040208042,276.28377236933903,118.74367088460689,-2.1813245693773933
2.167064957559761,0.014274054810962193,276.99218129179354,118.74367088460689,-2.1813245693773933
2.213712916733647,0.014581316263252651,277.7954502502235,118.74367088460689,-2.1813245693773933
2.2632763733559007,0.014907781556311263,278.6417236735403,118.74367088460689,-2.1813245693773933
2.362403286600408,0.015560712142428487,280.3128912732206,118.74367088460689,-2.1813245693773933
2.3973892559808223,0.01579115823164633,280.89615580769873,118.74367088460689,-2.1813245693773933
2.540248630950847,0.016732146429285857,283.2441551317759,118.74367088460689,-2.1813245693773933
2.586896590124733,0.017039407881576315,283.9996182604087,118.74367088460689,-2.1813245693773933
2.607305072263308,0.01717383476695339,284.32846068706203,118.74367088460689,-2.1813245693773933
2.6218825595051474,0.01726985397079416,284.5627338250052,118.74367088460689,-2.1813245693773933
2.7472489497849653,0.018095619123824763,286.55693427363656,118.74367088460689,-2.1813245693773933
2.779319421717012,0.018306861372274455,287.06133752385944,118.74367088460689,-2.1813245693773933
2.7851504166137477,0.018345269053810762,287.15280280905614,118.74367088460689,-2.1813245693773933
2.8551223553745766,0.01880616123224645,288.24462463630726,118.74367088460689,-2.1813245693773933
2.8726153400647836,0.01892138427685537,288.5159433394009,118.74367088460689,-2.1813245693773933
2.9309252890321407,0.019305461092218444,289.4157210048606,118.74367088460689,-2.1813245693773933
3.0183902124831765,0.019881576315263053,290.7524062043109,118.74367088460689,-2.1813245693773933
3.0446296895184872,0.020054410882176434,291.15045477616803,118.74367088460689,-2.1813245693773933
3.0883621512440054,0.02034246849369874,291.8109087485402,118.74367088460689,-2.1813245693773933
3.178742572143409,0.0209377875575115,293.1643994522526,118.74367088460689,-2.1813245693773933
3.1991510542819843,0.02107221444288858,293.4679393889018,118.74367088460689,-2.1813245693773933
3.2341370236623983,0.021302660532106422,293.986542443097,118.74367088460689,-2.1813245693773933
3.260376500697709,0.021475495099019803,294.37406010334564,118.74367088460689,-2.1813245693773933
3.280784982836284,0.02160992198439688,294.6746224381009,118.74367088460689,-2.1813245693773933
3.333263936906906,0.021955591118223646,295.4441677940664,118.74367088460689,-2.1813245693773933
3.3682499062873203,0.02218603720744149,295.9545745454395,118.74367088460689,-2.1813245693773933
3.3828273935291593,0.022282056411282256,296.16663330618906,118.74367088460689,-2.1813245693773933
3.5052782863606096,0.02308861772354471,297.9340717733512,118.74367088460689,-2.1813245693773933
3.5315177633959203,0.023261452290458094,298.30965687124376,118.74367088460689,-2.1813245693773933
3.595658707260013,0.02368393678735747,299.2232010665132,118.74367088460689,-2.1813245693773933
3.6277291791920594,0.023895179035807162,299.6775882014215,118.74367088460689,-2.1813245693773933
3.6423066664338988,0.02399119823964793,299.8836096516941,118.74367088460689,-2.1813245693773933
3.6772926358143128,0.024221644328865772,300.37675350695037,118.74367088460689,-2.1813245693773933
3.7647575592653486,0.02479775955191038,301.6016745519929,118.74367088460689,-2.1813245693773933
3.828898503129442,0.02522024404880976,302.49290733625094,118.74367088460689,-2.1813245693773933
3.881377457200063,0.025565913182636527,303.217774766595,118.74367088460689,-2.1813245693773933
4.018405837273353,0.02646849369873975,305.0926884520491,118.74367088460689,-2.1813245693773933
4.105870760724389,0.02704460892178436,306.2764147680677,118.74367088460689,-2.1813245693773933
4.132110237759699,0.02721744348869774,306.6296095952135,118.74367088460689,-2.1813245693773933
4.19916667907216,0.027659131826365275,307.52826750055436,118.74367088460689,-2.1813245693773933
4.234152648452575,0.02788957791558312,307.9949097124822,118.74367088460689,-2.1813245693773933
4.362434536180761,0.028734546909381875,309.6932150712011,118.74367088460689,-2.1813245693773933
4.409082495354646,0.029041808361672333,310.30593709140777,118.74367088460689,-2.1813245693773933
4.429490977493221,0.02917623524704941,310.5732074114427,118.74367088460689,-2.1813245693773933
4.58109684480835,0.0301748349669934,312.54382460554075,118.74367088460689,-2.1813245693773933
4.6394067937757075,0.030558911782356472,313.2949609689825,118.74367088460689,-2.1813245693773933
4.645237788672443,0.03059731946389278,313.3698715359097,118.74367088460689,-2.1813245693773933
4.686054752949593,0.03086617323464693,313.89322248462724,118.74367088460689,-2.1813245693773933
4.709378732536536,0.03101980396079216,314.19148192687743,118.74367088460689,-2.1813245693773933
4.732702712123479,0.03117343468693739,314.48916582238354,118.74367088460689,-2.1813245693773933
4.814336640677779,0.03171114222844569,315.52658347979485,118.74367088460689,-2.1813245693773933
4.875562087093504,0.032114422884576915,316.30015040325264,118.74367088460689,-2.1813245693773933
4.9163790513706545,0.03238327665533107,316.81375797907185,118.74367088460689,-2.1813245693773933
4.980519995234747,0.032805761152230446,317.6175083706881,118.74367088460689,-2.1813245693773933
5.015505964615161,0.03303620724144829,318.05421580339976,118.74367088460689,-2.1813245693773933
5.050491933995576,0.033266653330666134,318.489736790195,118.74367088460689,-2.1813245693773933
5.082562405927622,0.033477895579115825,318.88793184898725,118.74367088460689,-2.1813245693773933
5.143787852343348,0.03388117623524705,319.64541185817194,118.74367088460689,-2.1813245693773933
5.239999268139487,0.03451490298059612,320.82867160147134,118.74367088460689,-2.1813245693773933
5.260407750278062,0.034649329865973195,321.07857336990423,118.74367088460689,-2.1813245693773933
5.286647227313372,0.034822164432886576,321.3993207470967,118.74367088460689,-2.1813245693773933
5.365365658419305,0.035340668133626726,322.35785819392237,118.74367088460689,-2.1813245693773933
5.4703235665605465,0.03603200640128025,323.62741946321114,118.74367088460689,-2.1813245693773933
5.540295505321375,0.03649289857971594,324.4685197516711,118.74367088460689,-2.1813245693773933
5.557788490011583,0.03660812162432486,324.6781462396061,118.74367088460689,-2.1813245693773933
5.6219294338756765,0.03703060612122425,325.4445850281952,118.74367088460689,-2.1813245693773933
5.651084408359354,0.03722264452890578,325.79183816703346,118.74367088460689,-2.1813245693773933
5.726887342016918,0.03772194438887777,326.69144206998084,118.74367088460689,-2.1813245693773933
5.791028285881012,0.038144428885777154,327.44902400959364,118.74367088460689,-2.1813245693773933
5.805605773122851,0.03824044808961792,327.62074450708616,118.74367088460689,-2.1813245693773933
5.986366614921659,0.03943108621724345,329.736296615893,118.74367088460689,-2.1813245693773933
6.033014574095545,0.03973834766953391,330.2781828076401,118.74367088460689,-2.1813245693773933
6.056338553682488,0.03989197839567914,330.54851294905376,118.74367088460689,-2.1813245693773933
6.073831538372695,0.04000720144028806,330.7509941825813,118.74367088460689,-2.1813245693773933
6.140887979685155,0.04044888977795559,331.52507443325436,118.74367088460689,-2.1813245693773933
6.210859918445984,0.04090978195639128,332.3293038431969,118.74367088460689,-2.1813245693773933
6.301240339345387,0.041505101020204035,333.36288953927715,118.74367088460689,-2.1813245693773933
6.356634790864376,0.041869973994798956,333.9935203292856,118.74367088460689,-2.1813245693773933
6.388705262796424,0.04208121624324865,334.3576427407614,118.74367088460689,-2.1813245693773933
6.455761704108886,0.04252290458091619,335.1166941050034,118.74367088460689,-2.1813245693773933
6.496578668386034,0.04279175835167033,335.57722009163757,118.74367088460689,-2.1813245693773933
6.54322662755992,0.04309901980396079,336.1021560056307,118.74367088460689,-2.1813245693773933
6.601536576527278,0.04348309661932387,336.7562779544811,118.74367088460689,-2.1813245693773933
6.624860556114221,0.0436367273454691,337.01729533952346,118.74367088460689,-2.1813245693773933
6.671508515288107,0.043943988797759556,337.538257410038,118.74367088460689,-2.1813245693773933
6.712325479565255,0.0442128425685137,337.99293497224954,118.74367088460689,-2.1813245693773933
6.758973438739141,0.044520104020804155,338.51124819939866,118.74367088460689,-2.1813245693773933
6.811452392809764,0.04486577315463093,339.0926858752535,118.74367088460689,-2.1813245693773933
6.861015849432016,0.045192238447689534,339.64021934278963,118.74367088460689,-2.1813245693773933
6.910579306054271,0.04551870374074815,340.18621238263313,118.74367088460689,-2.1813245693773933
6.936818783089582,0.04569153830766154,340.4746491332344,118.74367088460689,-2.1813245693773933
7.038861193782456,0.046363672734546904,341.5923258915872,118.74367088460689,-2.1813245693773933
7.070931665714503,0.046574914982996596,341.94228828038285,118.74367088460689,-2.1813245693773933
7.100086640198183,0.04676695339067814,342.25989909840274,118.74367088460689,-2.1813245693773933
7.199213553442689,0.04741988397679536,343.33599151387745,118.74367088460689,-2.1813245693773933
7.213791040684528,0.04751590318063613,343.49375166477046,118.74367088460689,-2.1813245693773933
7.254608004961679,0.047784756951390284,343.93482001450377,118.74367088460689,-2.1813245693773933
7.26626999475515,0.04786157231446289,344.0606616424946,118.74367088460689,-2.1813245693773933
7.368312405448025,0.04853370674134827,345.1584361844359,118.74367088460689,-2.1813245693773933
7.543242252350096,0.04968593718743748,347.0266399507899,118.74367088460689,-2.1813245693773933
7.589890211523982,0.04999319863972794,347.5219642613183,118.74367088460689,-2.1813245693773933
7.671524140078283,0.05053090618123625,348.38593437897225,118.74367088460689,-2.1813245693773933
7.721087596700537,0.050857371474294866,348.9087385679272,118.74367088460689,-2.1813245693773933
7.74441157628748,0.051011002200440095,349.15431103434634,118.74367088460689,-2.1813245693773933
7.788144038012997,0.051299059811962394,349.6139833680505,118.74367088460689,-2.1813245693773933
7.826045504841779,0.05154870974194839,350.0115523854779,118.74367088460689,-2.1813245693773933
7.834791997186883,0.05160632126425285,350.1031923593625,118.74367088460689,-2.1813245693773933
7.963073884915068,0.052451290258051605,351.44269450113745,118.74367088460689,-2.1813245693773933
8.050538808366104,0.05302740548109622,352.35116980032683,118.74367088460689,-2.1813245693773933
8.076778285401415,0.053200240048009606,352.6229607041173,118.74367088460689,-2.1813245693773933
8.15258121905898,0.0536995399079816,353.40620672791715,118.74367088460689,-2.1813245693773933
8.240046142510016,0.05427565513102621,354.3064315095213,118.74367088460689,-2.1813245693773933
8.277947609338797,0.054525305061012205,354.69537073601686,118.74367088460689,-2.1813245693773933
8.339173055754523,0.05492858571714343,355.3221932819362,118.74367088460689,-2.1813245693773933
8.435384471550663,0.055562312462492505,356.3035860320864,118.74367088460689,-2.1813245693773933
8.531595887346802,0.05619603920784157,357.2806229129051,118.74367088460689,-2.1813245693773933
8.604483323555998,0.05667613522704541,358.01794421618325,118.74367088460689,-2.1813245693773933
8.67153976486846,0.05711782356471294,358.694131326588,118.74367088460689,-2.1813245693773933
8.73859620618092,0.057559511902380484,359.36828220984336,118.74367088460689,-2.1813245693773933
8.855216104115634,0.058327665533106615,360.5359327009926,118.74367088460689,-2.1813245693773933
8.904779560737888,0.05865413082616523,361.0303663811503,118.74367088460689,-2.1813245693773933
9.053469930604649,0.05963352670534107,362.5072675666709,118.74367088460689,-2.1813245693773933
9.10594888467527,0.05997919583916783,363.02626427995574,118.74367088460689,-2.1813245693773933
9.170089828539362,0.060401680336067215,363.6590121477631,118.74367088460689,-2.1813245693773933
9.199244803023042,0.06059371874374875,363.9460539816896,118.74367088460689,-2.1813245693773933
9.31003370606102,0.06132346469293859,365.03359246700165,118.74367088460689,-2.1813245693773933
9.400414126960424,0.06191878375675135,365.9170614596426,118.74367088460689,-2.1813245693773933
9.496625542756563,0.06255251050210042,366.85389605110674,118.74367088460689,-2.1813245693773933
9.546188999378819,0.06287897579515904,367.3350627656609,118.74367088460689,-2.1813245693773933
9.566597481517393,0.06301340268053611,367.53290693462424,118.74367088460689,-2.1813245693773933
9.587005963655967,0.06314782956591318,367.7305865676358,118.74367088460689,-2.1813245693773933
9.65114690752006,0.06357031406281256,368.3507996681475,118.74367088460689,-2.1813245693773933
9.686132876900473,0.0638007601520304,368.6884200908013,118.74367088460689,-2.1813245693773933
9.729865338625993,0.06408881776355271,369.1097775623565,118.74367088460689,-2.1813245693773933
9.808583769731925,0.06460732146429286,369.86636443214064,118.74367088460689,-2.1813245693773933
9.828992251870499,0.06474174834966993,370.06212956467743,118.74367088460689,-2.1813245693773933
9.931034662563375,0.06541388277655531,371.03858738202473,118.74367088460689,-2.1813245693773933
9.957274139598686,0.0655867173434687,371.2890430980064,118.74367088460689,-2.1813245693773933
10.012668591117674,0.06595159031806361,371.81693922604154,118.74367088460689,-2.1813245693773933
10.06223204773993,0.06627805561112222,372.2883026350913,118.74367088460689,-2.1813245693773933
10.094302519671976,0.06648929785957192,372.59282004651885,118.74367088460689,-2.1813245693773933
10.18468294057138,0.06708461692338469,373.4489821078289,118.74367088460689,-2.1813245693773933
10.22549990484853,0.06735347069413883,373.8346641665561,118.74367088460689,-2.1813245693773933
10.242992889538737,0.06746869373874775,373.9997726260044,118.74367088460689,-2.1813245693773933
10.310049330851196,0.06791038207641528,374.6316722579084,118.74367088460689,-2.1813245693773933
10.336288807886508,0.06808321664332867,374.87850076823497,118.74367088460689,-2.1813245693773933
10.435415721131015,0.06873614722944589,375.8087669020166,118.74367088460689,-2.1813245693773933
10.452908705821223,0.06885137027405482,375.9725731284101,118.74367088460689,-2.1813245693773933
10.575359598652673,0.06965793158631726,377.11623801002867,118.74367088460689,-2.1813245693773933
10.595768080791249,0.06979235847169435,377.3063455986433,118.74367088460689,-2.1813245693773933
10.671571014448812,0.07029165833166634,378.0112127130655,118.74367088460689,-2.1813245693773933
11.03017720059806,0.07265373074614924,381.31966151973353,118.74367088460689,-2.1813245693773933
11.047670185288265,0.07276895379075815,381.47996748547365,118.74367088460689,-2.1813245693773933
11.079740657220311,0.07298019603920784,381.7736048834991,118.74367088460689,-2.1813245693773933
11.143881601084406,0.07340268053610723,382.35988714009954,118.74367088460689,-2.1813245693773933
11.184698565361556,0.07367153430686138,382.732290737834,118.74367088460689,-2.1813245693773933
11.202191550051761,0.07378675735147029,382.891729986181,118.74367088460689,-2.1813245693773933
11.31589595053811,0.07453570714142829,383.9257283579203,118.74367088460689,-2.1813245693773933
11.397529879092408,0.07507341468293659,384.6655888562988,118.74367088460689,-2.1813245693773933
11.429600351024455,0.07528465693138628,384.9556825463993,118.74367088460689,-2.1813245693773933
11.467501817853238,0.07553430686137227,385.2981115873678,118.74367088460689,-2.1813245693773933
11.607445695374894,0.07645609121824365,386.5586594269077,118.74367088460689,-2.1813245693773933
11.639516167306942,0.07666733346669334,386.8466985458981,118.74367088460689,-2.1813245693773933
11.747389572896552,0.07737787557511502,387.81329392302814,118.74367088460689,-2.1813245693773933
11.796953029518807,0.07770434086817364,388.25624408696183,118.74367088460689,-2.1813245693773933
11.814446014209015,0.07781956391278257,388.41240607672825,118.74367088460689,-2.1813245693773933
11.843600988692693,0.0780116023204641,388.67247581802684,118.74367088460689,-2.1813245693773933
11.966051881524143,0.07881816363272655,389.7620534191246,118.74367088460689,-2.1813245693773933
11.986460363662717,0.07895259051810362,389.9432260888903,118.74367088460689,-2.1813245693773933
12.041854815181706,0.07931746349269854,390.4343750706428,118.74367088460689,-2.1813245693773933
12.158474713116421,0.08008561712342468,391.46550201786795,118.74367088460689,-2.1813245693773933
12.193460682496836,0.08031606321264254,391.77408701101115,118.74367088460689,-2.1813245693773933
12.353813042157068,0.08137227445489098,393.18403997125097,118.74367088460689,-2.1813245693773933
12.496672417127094,0.08231326265253051,394.4341789831153,118.74367088460689,-2.1813245693773933
12.54040487885261,0.08260132026405281,394.81575871306524,118.74367088460689,-2.1813245693773933
12.613292315061807,0.08308141628325666,395.4505736812077,118.74367088460689,-2.1813245693773933
12.657024776787326,0.08336947389477896,395.8307759815744,118.74367088460689,-2.1813245693773933
12.738658705341626,0.08390718143628727,396.5391189822498,118.74367088460689,-2.1813245693773933
12.919419547140432,0.08509781956391278,398.1013230396201,118.74367088460689,-2.1813245693773933
12.939828029279008,0.08523224644928987,398.2771637392082,118.74367088460689,-2.1813245693773933
12.974813998659421,0.0854626925385077,398.5783535095684,118.74367088460689,-2.1813245693773933
13.018546460384941,0.08575075015003002,398.9543956845876,118.74367088460689,-2.1813245693773933
13.076856409352297,0.08613482696539308,399.4550197959328,118.74367088460689,-2.1813245693773933
13.094349394042505,0.08625005001000201,399.605037165251,118.74367088460689,-2.1813245693773933
13.132250860871286,0.086499699939988,399.92980692855554,118.74367088460689,-2.1813245693773933
13.190560809838644,0.08688377675535107,400.4287398182762,118.74367088460689,-2.1813245693773933
13.237208769012529,0.08719103820764153,400.82726708321877,118.74367088460689,-2.1813245693773933
13.283856728186414,0.08749829965993199,401.2252470026706,118.74367088460689,-2.1813245693773933
13.30426521032499,0.08763272654530907,401.3991917858676,118.74367088460689,-2.1813245693773933
13.353828666947242,0.08795919183836767,401.82119644327315,118.74367088460689,-2.1813245693773933
13.508350031710739,0.08897699539907981,403.13295413693527,118.74367088460689,-2.1813245693773933
13.601645950058511,0.08959151830366073,403.9221258127146,118.74367088460689,-2.1813245693773933
13.64537841178403,0.08987957591518304,404.29132305822895,118.74367088460689,-2.1813245693773933
13.796984279099158,0.09087817563512703,405.5676492734384,118.74367088460689,-2.1813245693773933
13.829054751031205,0.09108941788357672,405.8369391387573,118.74367088460689,-2.1813245693773933
13.846547735721412,0.09120464092818564,405.98372186054894,118.74367088460689,-2.1813245693773933
13.866956217859986,0.09133906781356271,406.15487699550977,118.74367088460689,-2.1813245693773933
13.99815360303654,0.09220324064812963,407.25282360238697,118.74367088460689,-2.1813245693773933
14.047717059658796,0.09252970594118824,407.66655806321796,118.74367088460689,-2.1813245693773933
14.152674967800037,0.09322104420884177,408.5408270459281,118.74367088460689,-2.1813245693773933
14.2197314091125,0.09366273254650931,409.0980642205748,118.74367088460689,-2.1813245693773933
14.243055388699442,0.09381636327265454,409.29164549868796,118.74367088460689,-2.1813245693773933
14.45005570753356,0.09517983596719344,411.0042956004642,118.74367088460689,-2.1813245693773933
14.525858641191123,0.09567913582716543,411.6290663111874,118.74367088460689,-2.1813245693773933
14.627901051883999,0.09635127025405081,412.4680995696373,118.74367088460689,-2.1813245693773933
14.668718016161149,0.09662012402480497,412.803073353071,118.74367088460689,-2.1813245693773933
14.724112467680138,0.09698499699939989,413.2570997713329,118.74367088460689,-2.1813245693773933
14.756182939612186,0.09719623924784958,413.5196526901747,118.74367088460689,-2.1813245693773933
14.8728028375469,0.09796439287857572,414.472520347472,118.74367088460689,-2.1813245693773933
14.901957812030577,0.09815643128625726,414.7102814150355,118.74367088460689,-2.1813245693773933
14.93985927885936,0.09840608121624325,415.01909976336617,118.74367088460689,-2.1813245693773933
15.015662212516924,0.09890538107621524,415.6358213465541,118.74367088460689,-2.1813245693773933
15.065225669139178,0.09923184636927386,416.038405992387,118.74367088460689,-2.1813245693773933
15.088549648726122,0.09938547709541909,416.22767882551466,118.74367088460689,-2.1813245693773933
15.100211638519593,0.0994622924584917,416.3222724499347,118.74367088460689,-2.1813245693773933
15.1177046232098,0.09957751550310062,416.4641094824944,118.74367088460689,-2.1813245693773933