File: datasets/aisi_316_L/data/M1/train_92.csv
Time(s),Strain(%),Stress(MPa),Temp(C),Log_SR(s-1)
0.0,0.0,0.0,301.9744064168077,0.5992970678395242
3.824252155151583e-06,1.52e-05,2.698097375,301.9744064168077,0.5992970678395242
6.03829287655513e-06,2.4e-05,4.26015375,301.9744064168077,0.5992970678395242
1.107020360701774e-05,4.4e-05,7.810281874999999,301.9744064168077,0.5992970678395242
1.7712325771228382e-05,7.04e-05,12.496451,301.9744064168077,0.5992970678395242
2.6568488656842573e-05,0.00010559999999999999,18.744676499999997,301.9744064168077,0.5992970678395242
3.3814440108708726e-05,0.0001344,23.856861,301.9744064168077,0.5992970678395242
3.7034862976204804e-05,0.0001472,26.128943,301.9744064168077,0.5992970678395242
3.9852732985263865e-05,0.0001584,28.11701475,301.9744064168077,0.5992970678395242
4.6897408007911516e-05,0.0001864,33.087194125,301.9744064168077,0.5992970678395242
5.11242130215001e-05,0.00020319999999999998,36.069301749999994,301.9744064168077,0.5992970678395242
5.4545912318214674e-05,0.00021679999999999998,38.483388874999996,301.9744064168077,0.5992970678395242
6.48110102083584e-05,0.0002576,45.725650249999994,301.9744064168077,0.5992970678395242
7.346589666475409e-05,0.000292,51.831870625,301.9744064168077,0.5992970678395242
7.809525453677969e-05,0.0003104,55.0979885,301.9744064168077,0.5992970678395242
7.970546597052773e-05,0.0003168,56.2340295,301.9744064168077,0.5992970678395242
8.131567740427576e-05,0.0003232,57.3700705,301.9744064168077,0.5992970678395242
8.453610027177182e-05,0.000336,59.642152499999995,301.9744064168077,0.5992970678395242
8.574375884708285e-05,0.0003408,60.49418325,301.9744064168077,0.5992970678395242
9.137949886520097e-05,0.0003632,64.47032675,301.9744064168077,0.5992970678395242
9.72165153125376e-05,0.00038639999999999996,68.58847537499999,301.9744064168077,0.5992970678395242
9.943055603394114e-05,0.00039519999999999996,70.15053175,301.9744064168077,0.5992970678395242
0.00010969565392408487,0.00043599999999999997,77.392793125,301.9744064168077,0.5992970678395242
0.0001111045889286144,0.0004416,78.386829,301.9744064168077,0.5992970678395242
0.00011231224750392541,0.00044639999999999995,79.23885974999999,301.9744064168077,0.5992970678395242
0.00011392245893767347,0.0004528,80.37490075,301.9744064168077,0.5992970678395242
0.00011694160537595102,0.00046479999999999997,82.504977625,301.9744064168077,0.5992970678395242
0.00011955819895579159,0.0004752,84.35104425,301.9744064168077,0.5992970678395242
0.00012277862182328764,0.000488,86.62312625,301.9744064168077,0.5992970678395242
0.0001282130854121873,0.0005096,90.45726462500001,301.9744064168077,0.5992970678395242
0.00013103095542124632,0.0005208,92.445336375,301.9744064168077,0.5992970678395242
0.00013787435401467547,0.000548,97.273510625,301.9744064168077,0.5992970678395242
0.00014471775260810463,0.0005752,102.101684875,301.9744064168077,0.5992970678395242
0.00014652924047107115,0.0005824,103.37973099999999,301.9744064168077,0.5992970678395242
0.0001479381754756007,0.000588,104.373766875,301.9744064168077,0.5992970678395242
0.00014914583405091172,0.0005928,105.225797625,301.9744064168077,0.5992970678395242
0.00015075604548465973,0.0005991999999999999,106.36183862499999,301.9744064168077,0.5992970678395242
0.00015860582622418141,0.0006303999999999999,111.9000385,301.9744064168077,0.5992970678395242
0.00016102114337480347,0.0006399999999999999,113.60409999999999,301.9744064168077,0.5992970678395242
0.00016283263123777002,0.0006472,114.882146125,301.9744064168077,0.5992970678395242
0.00016766326553901411,0.0006663999999999999,118.290269125,301.9744064168077,0.5992970678395242
0.00017068241197729168,0.0006784,120.420346,301.9744064168077,0.5992970678395242
0.00017812963985837634,0.000708,125.67453562499999,301.9744064168077,0.5992970678395242
0.00018698580274399053,0.0007432,131.922761125,301.9744064168077,0.5992970678395242
0.00020630833994896697,0.00082,145.555253125,301.9744064168077,0.5992970678395242
0.00020711344566584096,0.0008232,146.123273625,301.9744064168077,0.5992970678395242
0.0002089249335288075,0.0008303999999999999,147.40131974999997,301.9744064168077,0.5992970678395242
0.0002131517385423961,0.0008472,150.383427375,301.9744064168077,0.5992970678395242
0.00021516450283458116,0.0008552,151.803478625,301.9744064168077,0.5992970678395242
0.0002218066249987918,0.0008816,156.48964775,301.9744064168077,0.5992970678395242
0.00022844874716300244,0.000908,161.17581687499998,301.9744064168077,0.5992970678395242
0.00023488959289799457,0.0009335999999999999,165.71998087499998,301.9744064168077,0.5992970678395242
0.00023750618647783514,0.000944,167.5660475,301.9744064168077,0.5992970678395242
0.00024273937363751623,0.0009647999999999999,171.25818074999998,301.9744064168077,0.5992970678395242
0.0002477712843679788,0.0009847999999999999,174.80830887499997,301.9744064168077,0.5992970678395242
0.00025119298366469344,0.0009984,177.222396,301.9744064168077,0.5992970678395242
0.00025320574795687845,0.0010064,178.64244725,301.9744064168077,0.5992970678395242
0.00025441340653218947,0.0010111999999999999,179.494478,301.9744064168077,0.5992970678395242
0.0002594453172626521,0.0010312,183.04060422417606,301.9744064168077,0.5992970678395242
0.00026648999228529973,0.0010592,183.20423338332392,301.9744064168077,0.5992970678395242
0.00027111935015732534,0.0010776,183.31084337586643,301.9744064168077,0.5992970678395242
0.0002717231794449809,0.00108,183.32469649974567,301.9744064168077,0.5992970678395242
0.0002733333908787289,0.0010864,183.36157959292177,301.9744064168077,0.5992970678395242
0.0002763525373170065,0.0010984,183.43050779705024,301.9744064168077,0.5992970678395242
0.0002817870009059061,0.00112,183.55384299035228,301.9744064168077,0.5992970678395242
0.0002844035944857466,0.0011304,183.61289544822816,301.9744064168077,0.5992970678395242
0.00028722146449480573,0.0011416,183.67625393851435,301.9744064168077,0.5992970678395242
0.00029386358665901634,0.001168,183.82464741347093,301.9744064168077,0.5992970678395242
0.0002999018795355715,0.001192,183.9584192564253,301.9744064168077,0.5992970678395242
0.000302115920256975,0.0012008,184.00720521003595,301.9744064168077,0.5992970678395242
0.00030553761955368964,0.0012144,184.08232831594052,301.9744064168077,0.5992970678395242
0.0003109720831425892,0.001236,184.20097059156265,301.9744064168077,0.5992970678395242
0.0003145950588685223,0.0012504,184.2796165140623,301.9744064168077,0.5992970678395242
0.0003188218638821109,0.0012672,184.37092503249045,301.9744064168077,0.5992970678395242
0.00032143845746195147,0.0012776,184.42721281768124,301.9744064168077,0.5992970678395242
0.000324457603900229,0.0012896,184.49193868973813,301.9744064168077,0.5992970678395242
0.0003304958967767841,0.0013135999999999998,184.62069002144227,301.9744064168077,0.5992970678395242
0.0003337163196442802,0.0013264,184.6889821190238,301.9744064168077,0.5992970678395242
0.0003349239782195912,0.0013311999999999998,184.71452533097792,301.9744064168077,0.5992970678395242
0.00033794312465786877,0.0013432,184.7782267117203,301.9744064168077,0.5992970678395242
0.0003429750353883314,0.0013632,184.88390465590473,301.9744064168077,0.5992970678395242
0.0003457929053973905,0.0013744,184.94282014319793,301.9744064168077,0.5992970678395242
0.00034659801111426445,0.0013775999999999999,184.9596187101828,301.9744064168077,0.5992970678395242
0.0003474031168311385,0.0013808,184.9764020658285,301.9744064168077,0.5992970678395242
0.00035283758042003815,0.0014024,185.0892955519263,301.9744064168077,0.5992970678395242
0.0003552528975706601,0.0014119999999999998,185.13925254734812,301.9744064168077,0.5992970678395242
0.00035585672685831566,0.0014144,185.15172107716273,301.9744064168077,0.5992970678395242
0.0003578694911505007,0.0014223999999999999,185.19322337956882,301.9744064168077,0.5992970678395242
0.0003622975725933078,0.0014399999999999999,185.28420934693284,301.9744064168077,0.5992970678395242
0.0003663231011776779,0.0014559999999999998,185.3665482040475,301.9744064168077,0.5992970678395242
0.0003775945812139141,0.0015007999999999998,185.5952405101974,301.9744064168077,0.5992970678395242
0.0003820226626567212,0.0015183999999999998,185.68435355001364,301.9744064168077,0.5992970678395242
0.00038745712624562085,0.00154,185.79317087079806,301.9744064168077,0.5992970678395242
0.0003886647848209319,0.0015448,185.8172714727119,301.9744064168077,0.5992970678395242
0.00039168393125920943,0.0015568,185.87739555599595,301.9744064168077,0.5992970678395242
0.00039530690698514253,0.0015712,185.94930639983107,301.9744064168077,0.5992970678395242
0.00039892988271107564,0.0015856,186.0209606645293,301.9744064168077,0.5992970678395242
0.0004005400941448236,0.0015919999999999999,186.05272549386513,301.9744064168077,0.5992970678395242
0.0004041630698707567,0.0016064,186.12401483421746,301.9744064168077,0.5992970678395242
0.0004093962570304378,0.0016271999999999999,186.2265498953434,301.9744064168077,0.5992970678395242
0.0004160383791946485,0.0016535999999999999,186.35595739746435,301.9744064168077,0.5992970678395242
0.0004180511434868335,0.0016615999999999998,186.39501238566723,301.9744064168077,0.5992970678395242
0.0004206677370666741,0.0016719999999999999,186.4456744115815,301.9744064168077,0.5992970678395242
0.00042368688350495165,0.001684,186.5039781332905,301.9744064168077,0.5992970678395242
0.0004299264528107253,0.0017088,186.62396152868743,301.9744064168077,0.5992970678395242
0.00043375070496587685,0.0017239999999999998,186.697164133196,301.9744064168077,0.5992970678395242
0.00044280814428070955,0.0017599999999999998,186.86954192181128,301.9744064168077,0.5992970678395242
0.0004488464371572647,0.001784,186.98369709169552,301.9744064168077,0.5992970678395242
0.00045307324217085327,0.0018008,187.0632496063224,301.9744064168077,0.5992970678395242
0.0004548847300338198,0.001808,187.09725487783209,301.9744064168077,0.5992970678395242
0.00045669621789678637,0.0018151999999999999,187.13120737666935,301.9744064168077,0.5992970678395242
0.0004593128114766269,0.0018256,187.18015729711595,301.9744064168077,0.5992970678395242
0.000464948551494745,0.0018479999999999998,187.2852200415001,301.9744064168077,0.5992970678395242
0.00046655876292849306,0.0018544,187.31514659343236,301.9744064168077,0.5992970678395242
0.00047078556794208164,0.0018712,187.3935127673232,301.9744064168077,0.5992970678395242
0.00047179195008817415,0.0018751999999999998,187.41213087815214,301.9744064168077,0.5992970678395242
0.00047521364938488874,0.0018888,187.47531692170534,301.9744064168077,0.5992970678395242
0.0004770251372478553,0.001896,187.50869651073967,301.9744064168077,0.5992970678395242
0.00048346598298284744,0.0019215999999999999,187.6269812064137,301.9744064168077,0.5992970678395242
0.0004858813001334695,0.0019311999999999999,187.67117932133868,301.9744064168077,0.5992970678395242
0.00048789406442565454,0.0019391999999999999,187.70794566686718,301.9744064168077,0.5992970678395242
0.0004901081051470581,0.0019479999999999999,187.74832039205543,301.9744064168077,0.5992970678395242
0.0004933285280145542,0.0019608,187.80692051628318,301.9744064168077,0.5992970678395242
0.0004969515037404872,0.0019752,187.87266761967047,301.9744064168077,0.5992970678395242
0.0005013795851832943,0.0019928,187.9527718741125,301.9744064168077,0.5992970678395242
0.0005056063901968829,0.0020096,188.0289780333055,301.9744064168077,0.5992970678395242
0.0005068140487721939,0.0020144,188.0507055341629,301.9744064168077,0.5992970678395242
0.000507619154489068,0.0020176,188.06517931827588,301.9744064168077,0.5992970678395242
0.0005106383009273455,0.0020296,188.11937645745823,301.9744064168077,0.5992970678395242
0.0005168778702331192,0.0020544,188.2309894579322,301.9744064168077,0.5992970678395242
0.0005207021223882708,0.0020696,188.2991377438044,301.9744064168077,0.5992970678395242
0.0005275455209816999,0.0020968,188.42060211120094,301.9744064168077,0.5992970678395242
0.000529558285273885,0.0021048,188.45620977544152,301.9744064168077,0.5992970678395242
0.0005317723259952884,0.0021135999999999998,188.49531729838702,301.9744064168077,0.5992970678395242
0.0005364016838673141,0.0021319999999999998,188.57688296925195,301.9744064168077,0.5992970678395242
0.0005382131717302807,0.0021392,188.608725181693,301.9744064168077,0.5992970678395242
0.0005408297653101211,0.0021495999999999998,188.65464579733978,301.9744064168077,0.5992970678395242
0.0005438489117483988,0.0021616,188.70752359457273,301.9744064168077,0.5992970678395242
0.0005496859281957353,0.0021847999999999998,188.80943050020872,301.9744064168077,0.5992970678395242
0.000555522944643072,0.002208,188.91091623792593,301.9744064168077,0.5992970678395242
0.0005603535789443161,0.0022272,188.99459030990175,301.9744064168077,0.5992970678395242
0.0005675995303961822,0.0022559999999999998,189.1195758681659,301.9744064168077,0.5992970678395242
0.0005708199532636784,0.0022688,189.1749251020588,301.9744064168077,0.5992970678395242
0.0005734365468435189,0.0022792,189.21980673589547,301.9744064168077,0.5992970678395242
0.00057464420541883,0.002284,189.24049439093767,301.9744064168077,0.5992970678395242
0.0005843054740213182,0.0023224,189.4053895858252,301.9744064168077,0.5992970678395242
0.0005887335554641252,0.00234,189.4806108454808,301.9744064168077,0.5992970678395242
0.0005905450433270917,0.0023472,189.51131954475755,301.9744064168077,0.5992970678395242
0.0005923565311900583,0.0023544,189.54199152853067,301.9744064168077,0.5992970678395242
0.0005969858890620839,0.0023728,189.6202097538523,301.9744064168077,0.5992970678395242
0.0005991999297834874,0.0023815999999999998,189.65753481848895,301.9744064168077,0.5992970678395242
0.000600608864788017,0.0023872,189.68125913013202,301.9744064168077,0.5992970678395242
0.0006072509869522276,0.0024135999999999997,189.79281126745298,301.9744064168077,0.5992970678395242
0.0006086599219567571,0.0024192,189.81641255142932,301.9744064168077,0.5992970678395242
0.0006134905562580012,0.0024384,189.8971699742255,301.9744064168077,0.5992970678395242
0.0006144969384040938,0.0024424,189.91396318019403,301.9744064168077,0.5992970678395242
0.0006165097026962788,0.0024503999999999997,189.94751744848125,301.9744064168077,0.5992970678395242
0.000620132678422212,0.0024648,190.00780766656916,301.9744064168077,0.5992970678395242
0.0006251645891526744,0.0024847999999999997,190.0913166866902,301.9744064168077,0.5992970678395242
0.0006271773534448596,0.0024928,190.12464684545677,301.9744064168077,0.5992970678395242
0.0006285862884493891,0.0024984,190.147953139891,301.9744064168077,0.5992970678395242
0.0006362347927596923,0.0025288,190.27411930609188,301.9744064168077,0.5992970678395242
0.0006410654270609363,0.002548,190.35349851386277,301.9744064168077,0.5992970678395242
0.0006442858499284324,0.0025608,190.40628842563007,301.9744064168077,0.5992970678395242
0.0006454935085037435,0.0025656,190.42605809891884,301.9744064168077,0.5992970678395242
0.0006483113785128024,0.0025767999999999998,190.47213132436428,301.9744064168077,0.5992970678395242
0.0006527394599556096,0.0025943999999999997,190.544374627279,301.9744064168077,0.5992970678395242
0.0006545509478185762,0.0026016,190.57387358679506,301.9744064168077,0.5992970678395242
0.0006593815821198202,0.0026208,190.65238223488623,301.9744064168077,0.5992970678395242
0.0006642122164210644,0.00264,190.73066689030176,301.9744064168077,0.5992970678395242
0.0006694454035807455,0.0026608,190.8152251191189,301.9744064168077,0.5992970678395242
0.0006722632735898045,0.002672,190.8606496783401,301.9744064168077,0.5992970678395242
0.0006738734850235525,0.0026784,190.88657322891635,301.9744064168077,0.5992970678395242
0.0006821258186215113,0.0027112,191.0190541504021,301.9744064168077,0.5992970678395242
0.0006845411357721332,0.0027207999999999998,191.0577106157176,301.9744064168077,0.5992970678395242
0.0006861513472058813,0.0027272,191.08345204463987,301.9744064168077,0.5992970678395242
0.000691183257936344,0.0027472,191.1637425821776,301.9744064168077,0.5992970678395242
0.0006940011279454029,0.0027584,191.20860570092444,301.9744064168077,0.5992970678395242
0.0006992343151050841,0.0027792,191.29173489368398,301.9744064168077,0.5992970678395242
0.0007068828194153873,0.0028095999999999998,191.41279626654284,301.9744064168077,0.5992970678395242
0.0007080904779906983,0.0028144,191.43186442208574,301.9744064168077,0.5992970678395242
0.00071594025873022,0.0028455999999999998,191.55549971719387,301.9744064168077,0.5992970678395242
0.00071996578731459,0.0028615999999999997,191.6186972867843,301.9744064168077,0.5992970678395242
0.0007229849337528676,0.0028736,191.66600506674905,301.9744064168077,0.5992970678395242
0.0007272117387664563,0.0028904,191.73210672546537,301.9744064168077,0.5992970678395242
0.0007294257794878597,0.0028991999999999998,191.76667159453868,301.9744064168077,0.5992970678395242
0.0007312372673508263,0.0029064,191.7949215179983,301.9744064168077,0.5992970678395242
0.0007350615195059779,0.0029216,191.8544707719184,301.9744064168077,0.5992970678395242
0.0007360679016520705,0.0029256,191.8701215308209,301.9744064168077,0.5992970678395242
0.0007445215116792476,0.0029592,192.00126005210205,301.9744064168077,0.5992970678395242
0.0007451253409669032,0.0029616,192.01060480855767,301.9744064168077,0.5992970678395242
0.0007477419345467436,0.002972,192.0510646734061,301.9744064168077,0.5992970678395242
0.0007529751217064248,0.0029928,192.13181913167324,301.9744064168077,0.5992970678395242
0.0007543840567109543,0.0029984,192.15352328076528,301.9744064168077,0.5992970678395242
0.0007555917152862652,0.0030031999999999997,192.17211425743426,301.9744064168077,0.5992970678395242
0.0007598185202998539,0.0030199999999999997,192.2370916137868,301.9744064168077,0.5992970678395242
0.0007606236260167279,0.0030231999999999998,192.24945225394953,301.9744064168077,0.5992970678395242
0.0007678695774685941,0.003052,192.36046934286168,301.9744064168077,0.5992970678395242
0.0007696810653315606,0.0030591999999999998,192.38815968415958,301.9744064168077,0.5992970678395242
0.0007741091467743677,0.0030767999999999998,192.45574040120204,301.9744064168077,0.5992970678395242
0.0007815563746554524,0.0031064,192.56905986663745,301.9744064168077,0.5992970678395242
0.000786990838244352,0.0031279999999999997,192.6514868479446,301.9744064168077,0.5992970678395242
0.000789808708253411,0.0031392,192.69413935401673,301.9744064168077,0.5992970678395242
0.0007906138139702851,0.0031424,192.70631487831528,301.9744064168077,0.5992970678395242
0.0007976584889929328,0.0031704,192.8126452429205,301.9744064168077,0.5992970678395242
0.0008006776354312102,0.0031823999999999997,192.8581032148686,301.9744064168077,0.5992970678395242
0.0008036967818694879,0.0031944,192.90349438579926,301.9744064168077,0.5992970678395242
0.0008123516683258836,0.0032288,193.03324863711757,301.9744064168077,0.5992970678395242
0.0008163771969102537,0.0032448,193.09341564689478,301.9744064168077,0.5992970678395242
0.0008238244247913383,0.0032744,193.2044204658245,301.9744064168077,0.5992970678395242
0.0008260384655127418,0.0032832,193.2373463400461,301.9744064168077,0.5992970678395242
0.0008274474005172713,0.0032887999999999997,193.25828125017054,301.9744064168077,0.5992970678395242
0.0008302652705263305,0.0033,193.30010941020402,301.9744064168077,0.5992970678395242
0.000836504839832104,0.0033247999999999997,193.39253238467248,301.9744064168077,0.5992970678395242
0.0008407316448456926,0.0033415999999999997,193.4549887905576,301.9744064168077,0.5992970678395242
0.0008439520677131887,0.0033544,193.50249246250695,301.9744064168077,0.5992970678395242
0.0008463673848638107,0.003364,193.53807383698017,301.9744064168077,0.5992970678395242
0.0008620669463428541,0.0034264,193.76839497904822,301.9744064168077,0.5992970678395242
0.0008646835399226946,0.0034368,193.80662223511038,301.9744064168077,0.5992970678395242
0.0008675014099317537,0.0034479999999999997,193.8477396308559,301.9744064168077,0.5992970678395242
0.0008711243856576868,0.0034624,193.90052839701642,301.9744064168077,0.5992970678395242
0.0008741435320959644,0.0034744,193.94445366072995,301.9744064168077,0.5992970678395242
0.0008749486378128384,0.0034776,193.9561570667089,301.9744064168077,0.5992970678395242
0.000877967784251116,0.0034896,194.00000748352147,301.9744064168077,0.5992970678395242
0.0008793767192556455,0.0034952,194.02045088198224,301.9744064168077,0.5992970678395242
0.000881993312835486,0.0035055999999999998,194.05838333476456,301.9744064168077,0.5992970678395242
0.0008848111828445452,0.0035168,194.09918462007644,301.9744064168077,0.5992970678395242
0.0008896418171457891,0.0035359999999999996,194.16901197632424,301.9744064168077,0.5992970678395242
0.0008968877685976553,0.0035648,194.2734763934631,301.9744064168077,0.5992970678395242
0.000901517126469681,0.0035832,194.34004526616633,301.9744064168077,0.5992970678395242
0.0009065490372001436,0.0036032,194.41225170898196,301.9744064168077,0.5992970678395242
0.0009113796715013877,0.0036224,194.48142298227654,301.9744064168077,0.5992970678395242
0.0009119835007890432,0.0036247999999999996,194.49005932645085,301.9744064168077,0.5992970678395242
0.0009172166879487242,0.0036455999999999997,194.56481445775788,301.9744064168077,0.5992970678395242
0.0009206383872454389,0.0036592,194.61360289276269,301.9744064168077,0.5992970678395242
0.0009220473222499684,0.0036647999999999997,194.63367168748317,301.9744064168077,0.5992970678395242
0.0009264754036927755,0.0036823999999999997,194.6966673225406,301.9744064168077,0.5992970678395242
0.0009337213551446417,0.0037112,194.7994983922933,301.9744064168077,0.5992970678395242
0.0009371430544413562,0.0037248,194.84794928380552,301.9744064168077,0.5992970678395242
0.0009387532658751042,0.0037311999999999996,194.87072582606052,301.9744064168077,0.5992970678395242
0.0009409673065965079,0.00374,194.90201870909826,301.9744064168077,0.5992970678395242
0.0009421749651718188,0.0037448,194.91907545057643,301.9744064168077,0.5992970678395242
0.0009451941116100964,0.0037568,194.96168004309055,301.9744064168077,0.5992970678395242
0.0009502260223405591,0.0037768,195.0325699435354,301.9744064168077,0.5992970678395242
0.0009520375102035256,0.003784,195.0580544484544,301.9744064168077,0.5992970678395242
0.0009550566566418031,0.003796,195.1004866383343,301.9744064168077,0.5992970678395242
0.0009566668680755511,0.0038023999999999996,195.12309574767042,301.9744064168077,0.5992970678395242
0.0009651204781027284,0.003836,195.24155096484915,301.9744064168077,0.5992970678395242
0.0009703536652624094,0.0038567999999999996,195.314677632152,301.9744064168077,0.5992970678395242
0.0009755868524220906,0.0038775999999999997,195.3876506530253,301.9744064168077,0.5992970678395242
0.0009784047224311496,0.0038888,195.42688057926654,301.9744064168077,0.5992970678395242
0.0009838391860200492,0.0039104,195.50241408140138,301.9744064168077,0.5992970678395242
0.0009878647146044194,0.0039264,195.55825995899778,301.9744064168077,0.5992970678395242
0.0009900787553258229,0.0039352,195.588937358719,301.9744064168077,0.5992970678395242
0.000991688966759571,0.0039416,195.6112313928834,301.9744064168077,0.5992970678395242
0.0009981298124945631,0.0039672,195.70026671551125,301.9744064168077,0.5992970678395242
0.0010007464060744035,0.0039775999999999995,195.736373277729,301.9744064168077,0.5992970678395242
0.0010025578939373701,0.0039848,195.7613485633526,301.9744064168077,0.5992970678395242
0.0010035642760834627,0.0039888,195.77521611714477,301.9744064168077,0.5992970678395242
0.0010112137467138901,0.004019203840768154,195.88044613406544,301.9744064168077,0.5992970678395242
0.0010498665516848371,0.004172834566913383,196.40749890957693,301.9744064168077,0.5992970678395242
0.0010788561554130474,0.004288057611522305,196.79783563390345,301.9744064168077,0.5992970678395242
0.0011078457591412578,0.0044032806561312265,197.18410257501156,301.9744064168077,0.5992970678395242
0.0013349309883455716,0.0053058611722344474,200.0841872071449,301.9744064168077,0.5992970678395242
0.0013687521926951502,0.005440288057611523,200.49903496787852,301.9744064168077,0.5992970678395242
0.0014750474063652543,0.005862772554510902,201.77754533703794,301.9744064168077,0.5992970678395242
0.0016151638243849375,0.006419683936787358,203.40920912256334,301.9744064168077,0.5992970678395242
0.001803596248618304,0.007168633726745349,205.51891789516543,301.9744064168077,0.5992970678395242
0.0019098914622884084,0.007591118223644729,206.67100998520138,301.9744064168077,0.5992970678395242
0.0019485442672593555,0.007744748949789958,207.08371605939934,301.9744064168077,0.5992970678395242
0.002016186675958513,0.008013602720544109,207.79834967139828,301.9744064168077,0.5992970678395242
0.0020983238865217753,0.00834006801360272,208.65366804479743,301.9744064168077,0.5992970678395242
0.002161134694599564,0.008589717943588718,209.29895219969575,301.9744064168077,0.5992970678395242
0.0022770931095124052,0.009050610122024405,210.47134630210354,301.9744064168077,0.5992970678395242
0.002325409115726089,0.009242648529705941,210.95294354620586,301.9744064168077,0.5992970678395242
0.0023737251219397727,0.009434686937387478,211.430653749901,301.9744064168077,0.5992970678395242
0.00244136753063893,0.009703540708141629,212.09312540102653,301.9744064168077,0.5992970678395242
0.002499346738095351,0.009933986797359472,212.65528027870522,301.9744064168077,0.5992970678395242
0.002653957957979139,0.010548509701940389,214.13003288047153,301.9744064168077,0.5992970678395242
0.0029245275927757683,0.011623924784956993,216.6326037359796,301.9744064168077,0.5992970678395242
0.0030501492089313456,0.012123224644928985,217.7636370733018,301.9744064168077,0.5992970678395242
0.003064644010795451,0.012180836167233446,217.89296130716838,301.9744064168077,0.5992970678395242
0.0031371180201159765,0.01246889377875575,218.5360384316814,301.9744064168077,0.5992970678395242
0.003219255230679239,0.012795359071814363,219.2578953823377,301.9744064168077,0.5992970678395242
0.003296560840621133,0.013102620524104821,219.93075582850003,301.9744064168077,0.5992970678395242
0.0034704984629903945,0.013793958791758352,221.42258731491359,301.9744064168077,0.5992970678395242
0.003528477670446815,0.014024404880976196,221.91334579230704,301.9744064168077,0.5992970678395242
0.00366376248784513,0.014562112422484497,223.0463779001997,301.9744064168077,0.5992970678395242
0.003818373707728918,0.015176635327065414,224.3214774126254,301.9744064168077,0.5992970678395242
0.003881184515806707,0.015426285257051411,224.83371522041548,301.9744064168077,0.5992970678395242
0.003972984927612706,0.01579115823164633,225.5765926937991,301.9744064168077,0.5992970678395242
0.004103438144389652,0.016309661932386477,226.62084609902806,301.9744064168077,0.5992970678395242
0.004175912153710178,0.016597719543908783,227.19538978552416,301.9744064168077,0.5992970678395242
0.0042242281599238615,0.016789757951590316,227.57625988454583,301.9744064168077,0.5992970678395242
0.004340186574836702,0.017250650130026003,228.4834820819143,301.9744064168077,0.5992970678395242
0.004417492184778596,0.01755791158231646,229.083050374155,301.9744064168077,0.5992970678395242
0.004504460995963228,0.01790358071614323,229.7526946926964,301.9744064168077,0.5992970678395242
0.004605924609011963,0.018306861372274455,230.52760628410874,301.9744064168077,0.5992970678395242
0.004620419410876069,0.018364472894578918,230.63776202145962,301.9744064168077,0.5992970678395242
0.004630082612118805,0.01840288057611522,230.71112431528155,301.9744064168077,0.5992970678395242
0.004866831042565856,0.01934386877375475,232.49026639253316,301.9744064168077,0.5992970678395242
0.004919978649400907,0.01955511102220444,232.8849882064087,301.9744064168077,0.5992970678395242
0.004934473451265013,0.019612722544508902,232.99235055486764,301.9744064168077,0.5992970678395242
0.005108411073634275,0.020304060812162433,234.2712511830981,301.9744064168077,0.5992970678395242
0.005229201089168484,0.020784156831366273,235.14940138602302,301.9744064168077,0.5992970678395242
0.005432128315265956,0.021590718143628725,236.60708881442375,301.9744064168077,0.5992970678395242
0.005562581532042902,0.022109221844368875,237.5329693379567,301.9744064168077,0.5992970678395242
0.005620560739499323,0.02233966793358672,237.9417494239736,301.9744064168077,0.5992970678395242
0.005726855953169427,0.0227621524304861,238.68693360031457,301.9744064168077,0.5992970678395242
0.005780003560004479,0.022973394678935787,239.05750141592415,301.9744064168077,0.5992970678395242
0.005842814368082269,0.023223044608921786,239.49373627856846,301.9744064168077,0.5992970678395242
0.006007088789208793,0.023875975195039006,240.62609757632777,301.9744064168077,0.5992970678395242
0.006147205207228476,0.024432886577315464,241.58242354014416,301.9744064168077,0.5992970678395242
0.00625350042089858,0.024855371074214844,242.30225164648772,301.9744064168077,0.5992970678395242
0.006292153225869528,0.025009001800360073,242.56282218253554,301.9744064168077,0.5992970678395242
0.00652407005569521,0.025930786157231447,244.1133336893968,301.9744064168077,0.5992970678395242
0.006606207266258472,0.026257251450290058,244.65729870283988,301.9744064168077,0.5992970678395242
0.006620702068122578,0.02631486297259452,244.75301808052626,301.9744064168077,0.5992970678395242
0.006755986885520892,0.026852570514102822,245.64249239460662,301.9744064168077,0.5992970678395242
0.006944419309754258,0.027601520304060812,246.86991274249417,301.9744064168077,0.5992970678395242
0.006983072114725206,0.02775515103020604,247.120078111898,301.9744064168077,0.5992970678395242
0.007079704127152573,0.028139227845569114,247.74314039751363,301.9744064168077,0.5992970678395242
0.00732611575884236,0.029118623724744948,249.31712027850912,301.9744064168077,0.5992970678395242
0.007408252969405623,0.02944508901780356,249.83717395863664,301.9744064168077,0.5992970678395242
0.0075435377868039374,0.029982796559311863,250.68885743810145,301.9744064168077,0.5992970678395242
0.007582190591774884,0.030136427285457092,250.9310987549835,301.9744064168077,0.5992970678395242
0.007736801811658673,0.03075095019003801,251.89528632545108,301.9744064168077,0.5992970678395242
0.007838265424707409,0.031154230846169233,252.52395325991625,301.9744064168077,0.5992970678395242
0.00795422383962025,0.031615123024604924,253.23855646295223,301.9744064168077,0.5992970678395242
0.008017034647698039,0.03186477295459092,253.6239363335712,301.9744064168077,0.5992970678395242
0.008128161461989511,0.03230646129225845,254.30288998740076,301.9744064168077,0.5992970678395242
0.008210298672552773,0.032632926585317065,254.80240081502953,301.9744064168077,0.5992970678395242
0.008248951477523721,0.032786557311462294,255.03679002597025,301.9744064168077,0.5992970678395242
0.008340751889329721,0.033151430286057215,255.5917543583487,301.9744064168077,0.5992970678395242
0.008534015914184456,0.03391958391678336,256.7523734911696,301.9744064168077,0.5992970678395242
0.008678963932825506,0.034495699139827966,257.61612238693317,301.9744064168077,0.5992970678395242
0.008756269542767401,0.034802960592118425,258.0744871843122,301.9744064168077,0.5992970678395242
0.008852901555194768,0.0351870374074815,258.6452298411522,301.9744064168077,0.5992970678395242
0.008935038765758033,0.035513502700540114,259.12845337899887,301.9744064168077,0.5992970678395242
0.008978523171350346,0.03568633726745349,259.3835760844522,301.9744064168077,0.5992970678395242
0.00905582878129224,0.03599359871974395,259.83594090575673,301.9744064168077,0.5992970678395242
0.00917178719620508,0.036454490898179634,260.51167450205867,301.9744064168077,0.5992970678395242
0.009384377623545291,0.0372994598919784,261.74192840656696,301.9744064168077,0.5992970678395242
0.009456851632865816,0.0375875175035007,262.158842493748,301.9744064168077,0.5992970678395242
0.009548652044671814,0.03795239047809562,262.6851491810898,301.9744064168077,0.5992970678395242
0.009674273660827392,0.03845169033806761,263.4021716334235,301.9744064168077,0.5992970678395242
0.009698431663934233,0.03854770954190838,263.5396432977355,301.9744064168077,0.5992970678395242
0.009746747670147916,0.03873974794958991,263.81418663726794,301.9744064168077,0.5992970678395242
0.009886864088167602,0.03929665933186638,264.6073766737835,301.9744064168077,0.5992970678395242
0.010152602122342862,0.040352870574114824,266.0997632130371,301.9744064168077,0.5992970678395242
0.010268560537255703,0.04081376275255051,266.7462035637006,301.9744064168077,0.5992970678395242
0.01033620294595486,0.041082616523304666,267.12197902175234,301.9744064168077,0.5992970678395242
0.01049081416583865,0.04169713942788558,267.97731140209,301.9744064168077,0.5992970678395242
0.010539130172052331,0.041889177835567115,268.2435927033118,301.9744064168077,0.5992970678395242
0.010650256986343804,0.042330866173234644,268.85423948448766,301.9744064168077,0.5992970678395242
0.010737225797528437,0.04267653530706142,269.33040529915706,301.9744064168077,0.5992970678395242
0.010761383800635278,0.042772554510902186,269.4624063351647,301.9744064168077,0.5992970678395242
0.010843521011198539,0.04309901980396079,269.91034793902264,301.9744064168077,0.5992970678395242
0.010978805828596856,0.0436367273454691,270.6452601423813,301.9744064168077,0.5992970678395242
0.011060943039160116,0.0439631926385277,271.08973398483903,301.9744064168077,0.5992970678395242
0.011152743450966115,0.04432806561312262,271.5849783622677,301.9744064168077,0.5992970678395242
0.011215554259043903,0.04457771554310862,271.9229141207015,301.9744064168077,0.5992970678395242
0.011283196667743063,0.04484656931386277,272.28602055333175,301.9744064168077,0.5992970678395242
0.011389491881413168,0.045269053810762155,272.8549058327941,301.9744064168077,0.5992970678395242
0.011486123893840534,0.04565313062612522,273.37027999031443,301.9744064168077,0.5992970678395242
0.01161657711061748,0.04617163432686537,274.0633607955822,301.9744064168077,0.5992970678395242
0.011766356729879902,0.04676695339067814,274.85538786510205,301.9744064168077,0.5992970678395242
0.01180500953485085,0.04692058411682337,275.0591424401433,301.9744064168077,0.5992970678395242
0.01182916753795769,0.04701660332066414,275.18635693202697,301.9744064168077,0.5992970678395242
0.01197411555659874,0.04759271854370874,275.9475269355599,301.9744064168077,0.5992970678395242
0.012244685191395368,0.04866813362672534,277.3588314434801,301.9744064168077,0.5992970678395242
0.012293001197609055,0.04886017203440689,277.60956495043223,301.9744064168077,0.5992970678395242
0.012457275618735579,0.04951310262052411,278.4591986963616,301.9744064168077,0.5992970678395242
0.012592560436133892,0.0500508101620324,279.15562088712505,301.9744064168077,0.5992970678395242
0.01266503444545442,0.050338867773554716,279.52750363921643,301.9744064168077,0.5992970678395242
0.01275200325663905,0.05068453690738148,279.972669213607,301.9744064168077,0.5992970678395242
0.012940435680872414,0.051433486697339464,280.9331528478379,301.9744064168077,0.5992970678395242
0.013032236092678414,0.051798359671934385,281.3991035150923,301.9744064168077,0.5992970678395242
0.013085383699513467,0.05200960192038408,281.6682793550396,301.9744064168077,0.5992970678395242
0.013182015711940836,0.05239367873574716,282.15660012621527,301.9744064168077,0.5992970678395242
0.01322550011753315,0.05256651330266053,282.3758888011241,301.9744064168077,0.5992970678395242
0.013278647724368202,0.05277775555111022,282.6435268004177,301.9744064168077,0.5992970678395242
0.013384942938038307,0.053200240048009606,283.17755275970956,301.9744064168077,0.5992970678395242
0.013394606139281043,0.05323864772954591,283.22601841184877,301.9744064168077,0.5992970678395242
0.01343325894425199,0.05339227845569114,283.41974481519446,301.9744064168077,0.5992970678395242
0.013500901352951148,0.05366113222644529,283.75824372385324,301.9744064168077,0.5992970678395242
0.013679670575941778,0.054371674334866976,284.6496791773118,301.9744064168077,0.5992970678395242
0.013718323380912726,0.054525305061012205,284.8418232881407,301.9744064168077,0.5992970678395242
0.013790797390233249,0.054813362672534505,285.20152536549824,301.9744064168077,0.5992970678395242
0.013858439798932408,0.05508221644328866,285.5365827329174,301.9744064168077,0.5992970678395242
0.013940577009495672,0.055408681736347276,285.9425818744699,301.9744064168077,0.5992970678395242
0.01397439821384525,0.055543108621724346,286.10948670373693,301.9744064168077,0.5992970678395242
0.014186988641185456,0.0563880776155231,287.15501831732365,301.9744064168077,0.5992970678395242
0.014288452254234195,0.05679135827165434,287.65186643187866,301.9744064168077,0.5992970678395242
0.01436092626355472,0.05707941588317664,288.00591587164246,301.9744064168077,0.5992970678395242
0.014370589464797455,0.05711782356471294,288.05306975901374,301.9744064168077,0.5992970678395242
0.014433400272875244,0.05736747349469894,288.35926916074465,301.9744064168077,0.5992970678395242
0.014515537483438508,0.057693938787757554,288.75890077937424,301.9744064168077,0.5992970678395242
0.01456385348965219,0.05788597719543909,288.9935662388079,301.9744064168077,0.5992970678395242
0.014607337895244507,0.058058811762352475,289.20450568580617,301.9744064168077,0.5992970678395242
0.014699138307050507,0.058423684736947396,289.64901975633325,301.9744064168077,0.5992970678395242
0.014877907530041137,0.05913422684536908,290.5115575214674,301.9744064168077,0.5992970678395242
0.014906897133769343,0.05924944988997799,290.65104674734533,301.9744064168077,0.5992970678395242
0.01492139193563345,0.05930706141228245,290.72075168475664,301.9744064168077,0.5992970678395242
0.014969707941847136,0.059499099819964,290.9529109895835,301.9744064168077,0.5992970678395242
0.015066339954274503,0.059883176635327065,291.41635475689026,301.9744064168077,0.5992970678395242
0.015162971966701872,0.060267253450690145,291.87864071920995,301.9744064168077,0.5992970678395242
0.015216119573536921,0.06047849569913982,292.1324082018504,301.9744064168077,0.5992970678395242
0.015370730793420708,0.06109301860372074,292.8686826969447,301.9744064168077,0.5992970678395242
0.015443204802741237,0.06138107621524305,293.21281656111904,301.9744064168077,0.5992970678395242
0.015515678812061761,0.06166913382676535,293.55632114894973,301.9744064168077,0.5992970678395242
0.01566545843132418,0.06226445289057812,294.2642540065069,301.9744064168077,0.5992970678395242
0.01575725884313018,0.06262932586517303,294.6968437412722,301.9744064168077,0.5992970678395242
0.016008502075441338,0.06362792558511703,295.8757764503693,301.9744064168077,0.5992970678395242
0.016047154880412282,0.06378155631126226,296.0565082402176,301.9744064168077,0.5992970678395242
0.01614378689283965,0.06416563312662532,296.5075965211951,301.9744064168077,0.5992970678395242
0.016221092502781545,0.06447289457891578,296.8677094226174,301.9744064168077,0.5992970678395242
0.016361208920801226,0.06502980596119223,297.518712692174,301.9744064168077,0.5992970678395242
0.016395030125150808,0.06516423284656932,297.6755252146453,301.9744064168077,0.5992970678395242
0.016486830536956806,0.06552910582116424,298.1005245474106,301.9744064168077,0.5992970678395242
0.016573799348141436,0.065874774954991,298.5023049687405,301.9744064168077,0.5992970678395242
0.016622115354355118,0.06606681336267253,298.7251610066105,301.9744064168077,0.5992970678395242
0.01676706337299617,0.06664292858571715,299.39221822522563,301.9744064168077,0.5992970678395242
0.016863695385423542,0.06702700540108023,299.83567403746514,301.9744064168077,0.5992970678395242
0.017003811803443222,0.06758391678335668,300.47692870703264,301.9744064168077,0.5992970678395242
0.017134265020220172,0.06810242048409683,301.07210885709316,301.9744064168077,0.5992970678395242
0.017211570630162064,0.06840968193638729,301.4239743019526,301.9744064168077,0.5992970678395242
0.017259886636375746,0.06860172034406882,301.64357724071135,301.9744064168077,0.5992970678395242
0.0173130342432108,0.06881296259251851,301.8848637503627,301.9744064168077,0.5992970678395242
0.017448319060609112,0.0693506701340268,302.4977477077487,301.9744064168077,0.5992970678395242
0.01769956229292027,0.0703492698539708,303.6310662932623,301.9744064168077,0.5992970678395242
0.017738215097891218,0.07050290058011603,303.8048645594462,301.9744064168077,0.5992970678395242
0.017883163116532267,0.07107901580316063,304.45529679318844,301.9744064168077,0.5992970678395242
0.01794114232398869,0.07130946189237848,304.71489360020894,301.9744064168077,0.5992970678395242
0.018134406348843425,0.07207761552310463,305.57786300819544,301.9744064168077,0.5992970678395242
0.01823103836127079,0.07246169233846769,306.00800211807734,301.9744064168077,0.5992970678395242
0.018603071609116156,0.07394038807761552,307.65580208322257,301.9744064168077,0.5992970678395242
0.018627229612223,0.0740364072814563,307.76235557785037,301.9744064168077,0.5992970678395242
0.01879633563397089,0.07470854170834167,308.5067267832256,301.9744064168077,0.5992970678395242
0.018883304445155524,0.07505421084216844,308.88852897288706,301.9744064168077,0.5992970678395242
0.018970273256340153,0.0753998799759952,309.26964598927214,301.9744064168077,0.5992970678395242
0.01909589487249573,0.0758991798359672,309.8189475510283,301.9744064168077,0.5992970678395242
0.01912971607684531,0.07603360672134428,309.966595416364,301.9744064168077,0.5992970678395242
0.019269832494864993,0.07659051810362073,310.5771980391934,301.9744064168077,0.5992970678395242
0.019501749324690676,0.07751230246049211,311.584059458631,301.9744064168077,0.5992970678395242
0.0196660237458172,0.07816523304660933,312.29442956219543,301.9744064168077,0.5992970678395242
0.01975299255700183,0.07851090218043609,312.66957077010636,301.9744064168077,0.5992970678395242
0.019825466566322354,0.07879895979195839,312.98169663446737,301.9744064168077,0.5992970678395242
0.020023562191798457,0.0795863172634527,313.8325784434241,301.9744064168077,0.5992970678395242
0.020207163015410458,0.08031606321264254,314.618273787162,301.9744064168077,0.5992970678395242
0.020535711857663508,0.08162192438487698,316.0173412107683,301.9744064168077,0.5992970678395242
0.020627512269469506,0.0819867973594719,316.40669326278123,301.9744064168077,0.5992970678395242
0.020728975882518243,0.08239007801560312,316.8362443649822,301.9744064168077,0.5992970678395242
0.02088358710240203,0.08300460092018404,317.4892250120385,301.9744064168077,0.5992970678395242
0.02094639791047982,0.08325425085017003,317.7539595265548,301.9744064168077,0.5992970678395242
0.020985050715450766,0.08340788157631526,317.9167191977687,301.9744064168077,0.5992970678395242
0.02112033553284908,0.08394558911782357,318.48545960179547,301.9744064168077,0.5992970678395242
0.021144493535955922,0.08404160832166434,318.5868707016814,301.9744064168077,0.5992970678395242
0.021289441554596975,0.08461772354470895,319.19439108525773,301.9744064168077,0.5992970678395242
0.021415063170752553,0.08511702340468094,319.7196050684003,301.9744064168077,0.5992970678395242
0.021535853186286764,0.08559711942388479,320.223486554123,301.9744064168077,0.5992970678395242
0.02157450599125771,0.08575075015003002,320.3844956865601,301.9744064168077,0.5992970678395242
0.021646980000578235,0.08603880776155232,320.6860849107474,301.9744064168077,0.5992970678395242
0.02168080120492781,0.08617323464692939,320.8266917611163,301.9744064168077,0.5992970678395242
0.021733948811762865,0.08638447689537908,321.0474726749456,301.9744064168077,0.5992970678395242
0.02190305483351076,0.08705661132226446,321.7485606940923,301.9744064168077,0.5992970678395242
0.022072160855258652,0.08772874574914984,322.4475408472105,301.9744064168077,0.5992970678395242
0.02227508808135612,0.08853530706141229,323.2835661788637,301.9744064168077,0.5992970678395242
0.022357225291919386,0.0888617723544709,323.621112299149,301.9744064168077,0.5992970678395242
0.022429699301239912,0.0891498299659932,323.9185456809639,301.9744064168077,0.5992970678395242
0.022482846908074963,0.0893610722144429,324.13642533525706,301.9744064168077,0.5992970678395242
0.022545657716152752,0.08961072214442889,324.3936606705969,301.9744064168077,0.5992970678395242
0.02268094253355107,0.0901484296859372,324.94675865567683,301.9744064168077,0.5992970678395242
0.02290802776275538,0.09105101020204041,325.8722893954155,301.9744064168077,0.5992970678395242
0.023023986177668224,0.0915119023804761,326.34352031957235,301.9744064168077,0.5992970678395242
0.02313028139133833,0.09193438687737548,326.77466952855684,301.9744064168077,0.5992970678395242
0.02321241860190159,0.09226085217043409,327.10730124457655,301.9744064168077,0.5992970678395242
0.023275229409979375,0.09251050210042008,327.36135703717395,301.9744064168077,0.5992970678395242
0.023304219013707588,0.09262572514502901,327.4785233610036,301.9744064168077,0.5992970678395242
0.02351197784042643,0.09345149029805962,328.316558190848,301.9744064168077,0.5992970678395242
0.02359411505098969,0.09377795559111823,328.64707709891553,301.9744064168077,0.5992970678395242
0.023632767855960638,0.09393158631726346,328.80246010699426,301.9744064168077,0.5992970678395242
0.023758389472116215,0.09443088617723545,329.30677175885705,301.9744064168077,0.5992970678395242
0.023884011088271793,0.09493018603720745,329.81004452996905,301.9744064168077,0.5992970678395242
0.024028959106912846,0.09550630126025206,330.3894628712651,301.9744064168077,0.5992970678395242
0.024130422719961582,0.09590958191638328,330.79424492348886,301.9744064168077,0.5992970678395242
0.02424638113487442,0.09637047409481897,331.2560410666894,301.9744064168077,0.5992970678395242
0.024265707537359894,0.09644728945789158,331.3329232732582,301.9744064168077,0.5992970678395242
0.024391329153515474,0.09694658931786358,331.83207678986827,301.9744064168077,0.5992970678395242
0.024434813559107788,0.09711942388477696,332.00462697504696,301.9744064168077,0.5992970678395242
0.024516950769671052,0.09744588917783557,332.3302287075418,301.9744064168077,0.5992970678395242
0.02454594037339926,0.0975611122224445,332.4450453578081,301.9744064168077,0.5992970678395242
0.024599087980234313,0.09777235447089418,332.6554052901297,301.9744064168077,0.5992970678395242
0.024657067187690736,0.09800280056011203,332.884686800255,301.9744064168077,0.5992970678395242
0.024676393590176204,0.09807961592318463,332.9610672324696,301.9744064168077,0.5992970678395242
0.02471987799576852,0.09825245049009802,333.1328379560438,301.9744064168077,0.5992970678395242
0.02485516281316684,0.09879015803160633,333.6664837043672,301.9744064168077,0.5992970678395242
0.02499044763056515,0.09932786557311463,334.19899785565224,301.9744064168077,0.5992970678395242
0.025067753240507046,0.09963512702540508,334.5027868704045,301.9744064168077,0.5992970678395242
0.025135395649206204,0.09990398079615924,334.7683026673408,301.9744064168077,0.5992970678395242
0.02514989045107031,0.0999615923184637,334.82516263764325,301.9744064168077,0.5992970678395242