File: datasets/aisi_316_L/data/M1/train_15.csv
Time(s),Strain(%),Stress(MPa),Temp(C),Log_SR(s-1)
0.0,0.0,0.0,309.52132946291255,2.363740081427218
7.270582391365497e-08,1.68e-05,2.97148215,309.52132946291255,2.363740081427218
9.347891646041355e-08,2.16e-05,3.82047705,309.52132946291255,2.363740081427218
1.1771419109829853e-07,2.7199999999999997e-05,4.8109711,309.52132946291255,2.363740081427218
2.042687433764592e-07,4.7199999999999995e-05,8.34844985,309.52132946291255,2.363740081427218
2.735123851989877e-07,6.319999999999999e-05,11.178432849999998,309.52132946291255,2.363740081427218
3.4968039120376916e-07,8.08e-05,14.29141415,309.52132946291255,2.363740081427218
4.431593076641827e-07,0.0001024,18.1118912,309.52132946291255,2.363740081427218
4.812433106665733e-07,0.00011119999999999999,19.66838185,309.52132946291255,2.363740081427218
5.92033137582619e-07,0.0001368,24.19635465,309.52132946291255,2.363740081427218
6.47428051040642e-07,0.0001496,26.46034105,309.52132946291255,2.363740081427218
6.855120540430327e-07,0.0001584,28.0168317,309.52132946291255,2.363740081427218
7.651422421389404e-07,0.0001768,31.271312149999996,309.52132946291255,2.363740081427218
8.690077048727334e-07,0.0002008,35.51628665,309.52132946291255,2.363740081427218
9.97108442244411e-07,0.0002304,40.7517552,309.52132946291255,2.363740081427218
1.045578991520181e-06,0.0002416,42.732743299999996,309.52132946291255,2.363740081427218
1.100973904978204e-06,0.0002544,44.9967297,309.52132946291255,2.363740081427218
1.2186880960765026e-06,0.0002816,49.8077008,309.52132946291255,2.363740081427218
1.3571753797215595e-06,0.0003136,55.467666799999996,309.52132946291255,2.363740081427218
1.3814106543594447e-06,0.0003192,56.45816085,309.52132946291255,2.363740081427218
1.450654296181973e-06,0.00033519999999999996,59.28814384999999,309.52132946291255,2.363740081427218
1.4852761170932374e-06,0.0003432,60.70313535,309.52132946291255,2.363740081427218
1.547595394733513e-06,0.00035759999999999996,63.25012004999999,309.52132946291255,2.363740081427218
1.6099146723737888e-06,0.000372,65.79710475,309.52132946291255,2.363740081427218
1.7726372306567308e-06,0.0004096,72.4475648,309.52132946291255,2.363740081427218
1.7934103232034894e-06,0.0004144,73.2965597,309.52132946291255,2.363740081427218
1.92843542475742e-06,0.0004456,78.81502655,309.52132946291255,2.363740081427218
2.115393257678247e-06,0.0004888,86.45598064999999,309.52132946291255,2.363740081427218
2.1604016248628907e-06,0.0004992,88.2954696,309.52132946291255,2.363740081427218
2.2365696308676722e-06,0.0005168,91.40845089999999,309.52132946291255,2.363740081427218
2.253880541323304e-06,0.0005208,92.11594665,309.52132946291255,2.363740081427218
2.2781158159611894e-06,0.0005264,93.10644070000001,309.52132946291255,2.363740081427218
2.3369729115103385e-06,0.00054,95.51192625,309.52132946291255,2.363740081427218
2.406216553332867e-06,0.000556,98.34190924999999,309.52132946291255,2.363740081427218
2.4996954697932806e-06,0.0005775999999999999,102.1623863,309.52132946291255,2.363740081427218
2.6035609325270736e-06,0.0006016,106.40736079999999,309.52132946291255,2.363740081427218
2.6277962071649584e-06,0.0006072,107.39785485,309.52132946291255,2.363740081427218
2.707426395260866e-06,0.0006255999999999999,110.65233529999999,309.52132946291255,2.363740081427218
2.738586034081004e-06,0.0006328,111.92582765,309.52132946291255,2.363740081427218
2.783594401265648e-06,0.0006432,113.7653166,309.52132946291255,2.363740081427218
2.856300225179303e-06,0.00066,116.73679875,309.52132946291255,2.363740081427218
2.915157320728452e-06,0.0006736,119.1422843,309.52132946291255,2.363740081427218
2.9497791416397163e-06,0.0006816,120.5572758,309.52132946291255,2.363740081427218
3.0259471476444974e-06,0.0006992,123.6702571,309.52132946291255,2.363740081427218
3.0605689685557617e-06,0.0007072,125.08524859999999,309.52132946291255,2.363740081427218
3.109039517831532e-06,0.0007184,127.0662367,309.52132946291255,2.363740081427218
3.136736974560543e-06,0.0007247999999999999,128.1982299,309.52132946291255,2.363740081427218
3.1678966133806813e-06,0.000732,129.47172225,309.52132946291255,2.363740081427218
3.42063590603291e-06,0.0007903999999999999,139.8011602,309.52132946291255,2.363740081427218
3.507190458311071e-06,0.0008104,143.33863895,309.52132946291255,2.363740081427218
3.687223927049645e-06,0.000852,150.69659475,309.52132946291255,2.363740081427218
3.7218457479609095e-06,0.00086,152.11158625,309.52132946291255,2.363740081427218
3.766854115145553e-06,0.0008703999999999999,153.9510752,309.52132946291255,2.363740081427218
3.877643942061599e-06,0.000896,158.479048,309.52132946291255,2.363740081427218
3.908803580881736e-06,0.0009031999999999999,159.75254035,309.52132946291255,2.363740081427218
3.946887583884127e-06,0.0009119999999999999,161.30903099999998,309.52132946291255,2.363740081427218
4.019593407797782e-06,0.0009287999999999999,164.28051315,309.52132946291255,2.363740081427218
4.078450503346931e-06,0.0009423999999999999,166.6859987,309.52132946291255,2.363740081427218
4.126921052622701e-06,0.0009536,168.6669868,309.52132946291255,2.363740081427218
4.14769414516946e-06,0.0009584,169.5159817,309.52132946291255,2.363740081427218
4.227324333265367e-06,0.0009767999999999999,172.77046215,309.52132946291255,2.363740081427218
4.286181428814518e-06,0.0009904,175.1759477,309.52132946291255,2.363740081427218
4.338114160181413e-06,0.0010023999999999999,177.29843494999997,309.52132946291255,2.363740081427218
4.518147628919988e-06,0.001044,184.65639075,309.52132946291255,2.363740081427218
4.566618178195757e-06,0.0010551999999999998,186.63737884999998,309.52132946291255,2.363740081427218
4.5839290886513894e-06,0.0010592,187.3448746,309.52132946291255,2.363740081427218
4.691256733476309e-06,0.001084,188.63406056967614,309.52132946291255,2.363740081427218
4.712029826023068e-06,0.0010888,188.66248771998738,309.52132946291255,2.363740081427218
4.805508742483481e-06,0.0011103999999999999,188.7898098494422,309.52132946291255,2.363740081427218
4.950920390310792e-06,0.001144,188.9859631021941,309.52132946291255,2.363740081427218
4.9855422112220555e-06,0.001152,189.03233352216284,309.52132946291255,2.363740081427218
5.065172399317964e-06,0.0011704,189.1385114994655,309.52132946291255,2.363740081427218
5.33868478451695e-06,0.0012335999999999998,189.4983514381678,309.52132946291255,2.363740081427218
5.369844423337089e-06,0.0012408,189.53888447706422,309.52132946291255,2.363740081427218
5.44601242934187e-06,0.0012584,189.63758099245055,309.52132946291255,2.363740081427218
5.581037530895801e-06,0.0012896,189.81122999896613,309.52132946291255,2.363740081427218
5.60181062344256e-06,0.0012944,189.83779910210262,309.52132946291255,2.363740081427218
5.733373542905364e-06,0.0013248,190.00518647455704,309.52132946291255,2.363740081427218
5.764533181725501e-06,0.0013319999999999999,190.04461063274357,309.52132946291255,2.363740081427218
5.9341801041906965e-06,0.0013712,190.25781270906728,309.52132946291255,2.363740081427218
6.12460011920265e-06,0.0014152,190.4943094238482,309.52132946291255,2.363740081427218
6.193843761025179e-06,0.0014311999999999999,190.5795949651095,309.52132946291255,2.363740081427218
6.290784859576719e-06,0.0014536,190.6983726505224,309.52132946291255,2.363740081427218
6.411961232766144e-06,0.0014816,190.84584564546572,309.52132946291255,2.363740081427218
6.484667056679799e-06,0.0014984,190.93380778541595,309.52132946291255,2.363740081427218
6.640465250780488e-06,0.0015344,191.12101326626606,309.52132946291255,2.363740081427218
6.650851797053867e-06,0.0015367999999999998,191.1334323829508,309.52132946291255,2.363740081427218
6.733944167240901e-06,0.0015559999999999999,191.23251446526194,309.52132946291255,2.363740081427218
6.761641623969913e-06,0.0015624,191.2654357162127,309.52132946291255,2.363740081427218
6.8274230837013145e-06,0.0015776,191.34341361801808,309.52132946291255,2.363740081427218
6.84127181206582e-06,0.0015807999999999998,191.35979262009727,309.52132946291255,2.363740081427218
6.875893632977085e-06,0.0015888,191.40068365468258,309.52132946291255,2.363740081427218
6.90012890761497e-06,0.0015944,191.42925961392498,309.52132946291255,2.363740081427218
6.910515453888349e-06,0.0015968,191.44149446804093,309.52132946291255,2.363740081427218
7.021305280804395e-06,0.0016224,191.571556442668,309.52132946291255,2.363740081427218
7.042078373351153e-06,0.0016271999999999999,191.59585370038232,309.52132946291255,2.363740081427218
7.090548922626923e-06,0.0016384,191.65243885666158,309.52132946291255,2.363740081427218
7.305204212276762e-06,0.0016879999999999998,191.90123861710893,309.52132946291255,2.363740081427218
7.357136943643658e-06,0.0017,191.9610017577447,309.52132946291255,2.363740081427218
7.384834400372669e-06,0.0017063999999999998,191.99280815008814,309.52132946291255,2.363740081427218
7.502548591470968e-06,0.0017335999999999999,192.1274695624728,309.52132946291255,2.363740081427218
7.544094776564485e-06,0.0017431999999999999,192.1748000574418,309.52132946291255,2.363740081427218
7.596027507931382e-06,0.0017552,192.23382046676917,309.52132946291255,2.363740081427218
7.634111510933772e-06,0.001764,192.27700213117964,309.52132946291255,2.363740081427218
7.699892970665174e-06,0.0017791999999999999,192.3513912818719,309.52132946291255,2.363740081427218
7.786447522943335e-06,0.0017992,192.44889521994673,309.52132946291255,2.363740081427218
7.928396988679518e-06,0.0018319999999999999,192.60789154253663,309.52132946291255,2.363740081427218
8.066884272324576e-06,0.001864,192.76194344105937,309.52132946291255,2.363740081427218
8.125741367873725e-06,0.0018775999999999999,192.82710277827445,309.52132946291255,2.363740081427218
8.191522827605126e-06,0.0018927999999999998,192.89971048662724,309.52132946291255,2.363740081427218
8.44079993816623e-06,0.0019504,193.17281610474305,309.52132946291255,2.363740081427218
8.503119215806506e-06,0.0019648,193.24059876072468,309.52132946291255,2.363740081427218
8.558514129264529e-06,0.0019776,193.3006875309997,309.52132946291255,2.363740081427218
8.638144317360436e-06,0.001996,193.3868000805332,309.52132946291255,2.363740081427218
8.707387959182964e-06,0.002012,193.46142921425962,309.52132946291255,2.363740081427218
8.755858508458734e-06,0.0020231999999999997,193.5135319527506,309.52132946291255,2.363740081427218
8.835488696554641e-06,0.0020415999999999998,193.59888576959483,309.52132946291255,2.363740081427218
8.908194520468298e-06,0.0020583999999999997,193.67655586470232,309.52132946291255,2.363740081427218
8.984362526473079e-06,0.0020759999999999997,193.75765983363956,309.52132946291255,2.363740081427218
9.14708508475602e-06,0.0021135999999999998,193.93003444785373,309.52132946291255,2.363740081427218
9.181706905667285e-06,0.0021216,193.9665551313738,309.52132946291255,2.363740081427218
9.25441272958094e-06,0.0021384,194.04307421297028,309.52132946291255,2.363740081427218
9.306345460947836e-06,0.0021504,194.09758722689247,309.52132946291255,2.363740081427218
9.396362195317124e-06,0.0021712,194.19179624196553,309.52132946291255,2.363740081427218
9.441370562501767e-06,0.0021815999999999997,194.23876870851223,309.52132946291255,2.363740081427218
9.55562257150894e-06,0.002208,194.35761598046915,309.52132946291255,2.363740081427218
9.583320028237952e-06,0.0022144,194.38634382411013,309.52132946291255,2.363740081427218
9.645639305878227e-06,0.0022288,194.4508633427253,309.52132946291255,2.363740081427218
9.756429132794271e-06,0.0022543999999999997,194.56516472461044,309.52132946291255,2.363740081427218
9.808361864161169e-06,0.0022664,194.61856913913937,309.52132946291255,2.363740081427218
9.89491641643933e-06,0.0022864,194.70733208560205,309.52132946291255,2.363740081427218
9.974546604535238e-06,0.0023048,194.78872691761538,309.52132946291255,2.363740081427218
1.0102647341906915e-05,0.0023344,194.9191366794171,309.52132946291255,2.363740081427218
1.0161504437456064e-05,0.002348,194.97883830006887,309.52132946291255,2.363740081427218
1.0189201894185076e-05,0.0023544,195.00688650135132,309.52132946291255,2.363740081427218
1.0244596807643099e-05,0.0023672,195.06289385769506,309.52132946291255,2.363740081427218
1.0390008455470408e-05,0.0024008,195.20935408044227,309.52132946291255,2.363740081427218
1.0448865551019557e-05,0.0024143999999999997,195.26840806866278,309.52132946291255,2.363740081427218
1.055273101375335e-05,0.0024384,195.37230548998164,309.52132946291255,2.363740081427218
1.0566579742117856e-05,0.0024416,195.386128284915,309.52132946291255,2.363740081427218
1.060120156302912e-05,0.0024495999999999997,195.4206543971639,309.52132946291255,2.363740081427218
1.0625436837667006e-05,0.0024552,195.44479651528417,309.52132946291255,2.363740081427218
1.066005865857827e-05,0.0024632,195.4792480355805,309.52132946291255,2.363740081427218
1.0736226664583052e-05,0.0024808,195.55488814795623,309.52132946291255,2.363740081427218
1.0798545942223328e-05,0.0024952,195.61661996725834,309.52132946291255,2.363740081427218
1.0840092127316844e-05,0.0025047999999999997,195.65769734166972,309.52132946291255,2.363740081427218
1.0857403037772476e-05,0.0025088,195.67479478767865,309.52132946291255,2.363740081427218
1.0878176130319236e-05,0.0025136,195.69529769588806,309.52132946291255,2.363740081427218
1.0985503775144153e-05,0.0025383999999999997,195.80098711807614,309.52132946291255,2.363740081427218
1.107552050951344e-05,0.0025591999999999998,195.88931970402987,309.52132946291255,2.363740081427218
1.1158612879700475e-05,0.0025784,195.97060928125234,309.52132946291255,2.363740081427218
1.1234780885705256e-05,0.002596,196.0449175807762,309.52132946291255,2.363740081427218
1.130748670961891e-05,0.0026127999999999998,196.11566516165644,309.52132946291255,2.363740081427218
1.1414814354443831e-05,0.0026376,196.21977868029637,309.52132946291255,2.363740081427218
1.1428663082808338e-05,0.0026408,196.23318481864678,309.52132946291255,2.363740081427218
1.1452898357446221e-05,0.0026463999999999997,196.25663032590427,309.52132946291255,2.363740081427218
1.1546377273906635e-05,0.002668,196.3468823283525,309.52132946291255,2.363740081427218
1.1653704918731555e-05,0.0026928,196.45015432535791,309.52132946291255,2.363740081427218
1.1740259471009716e-05,0.0027128,196.53316826215203,309.52132946291255,2.363740081427218
1.1767956927738725e-05,0.0027191999999999997,196.559682266434,309.52132946291255,2.363740081427218
1.193760385020392e-05,0.0027584,196.72155267182154,309.52132946291255,2.363740081427218
1.2055318041302221e-05,0.0027856,196.8333440712168,309.52132946291255,2.363740081427218
1.2093402044304611e-05,0.0027944,196.8694206239915,309.52132946291255,2.363740081427218
1.221111623540291e-05,0.0028216,196.98065085939646,309.52132946291255,2.363740081427218
1.2318443880227828e-05,0.0028464,197.08170273862203,309.52132946291255,2.363740081427218
1.244308243550838e-05,0.0028752,197.1986233991778,309.52132946291255,2.363740081427218
1.2477704256419643e-05,0.0028832,197.2310201868706,309.52132946291255,2.363740081427218
1.256079662660668e-05,0.0029024,197.30862977588743,309.52132946291255,2.363740081427218
1.263696463261146e-05,0.00292,197.3795961852291,309.52132946291255,2.363740081427218
1.2713132638616241e-05,0.0029376,197.45039596961416,309.52132946291255,2.363740081427218
1.2886241743172563e-05,0.0029776,197.61069219920736,309.52132946291255,2.363740081427218
1.2931250110357206e-05,0.0029879999999999998,197.65223138200122,309.52132946291255,2.363740081427218
1.2990107205906354e-05,0.0030015999999999997,197.70646687114336,309.52132946291255,2.363740081427218
1.3035115573090999e-05,0.003012,197.74787642845052,309.52132946291255,2.363740081427218
1.311128357909578e-05,0.0030296,197.8178273328211,309.52132946291255,2.363740081427218
1.3142443217915918e-05,0.0030367999999999997,197.84639791206837,309.52132946291255,2.363740081427218
1.3201300313465068e-05,0.0030504,197.90029258640882,309.52132946291255,2.363740081427218
1.3222073406011826e-05,0.0030551999999999997,197.91929185166592,309.52132946291255,2.363740081427218
1.3260157409014217e-05,0.003064,197.9540936303717,309.52132946291255,2.363740081427218
1.3284392683652102e-05,0.0030696,197.97621992212618,309.52132946291255,2.363740081427218
1.3294779229925482e-05,0.003072,197.98569779878054,309.52132946291255,2.363740081427218
1.3377871600112515e-05,0.0030911999999999997,198.06141712978064,309.52132946291255,2.363740081427218
1.3471350516572929e-05,0.0031127999999999998,198.1463824756333,309.52132946291255,2.363740081427218
1.3495585791210814e-05,0.0031184,198.16837295516333,309.52132946291255,2.363740081427218
1.3595989071853481e-05,0.0031416,198.25931278440828,309.52132946291255,2.363740081427218
1.3623686528582491e-05,0.0031479999999999998,198.28435349418857,309.52132946291255,2.363740081427218
1.3713703262951779e-05,0.0031688,198.36559902520392,309.52132946291255,2.363740081427218
1.375178726595417e-05,0.0031776,198.39990949352648,309.52132946291255,2.363740081427218
1.3928358552601617e-05,0.0032183999999999997,198.55850360671917,309.52132946291255,2.363740081427218
1.3956056009330628e-05,0.0032248,198.583309792072,309.52132946291255,2.363740081427218
1.4101467657157939e-05,0.0032584,198.71322860935567,309.52132946291255,2.363740081427218
1.412916511388695e-05,0.0032648,198.73791570170079,309.52132946291255,2.363740081427218
1.4208795301982858e-05,0.0032832,198.8087861780408,309.52132946291255,2.363740081427218
1.422610621243849e-05,0.0032871999999999997,198.82417228689124,309.52132946291255,2.363740081427218
1.430227421844327e-05,0.0033047999999999997,198.8917846072498,309.52132946291255,2.363740081427218
1.4402677499085938e-05,0.003328,198.98069576668473,309.52132946291255,2.363740081427218
1.443037495581495e-05,0.0033344,199.00518040180407,309.52132946291255,2.363740081427218
1.446845895881734e-05,0.0033431999999999997,199.03881686966753,309.52132946291255,2.363740081427218
1.452731605436649e-05,0.0033568,199.0907326633112,309.52132946291255,2.363740081427218
1.4561937875277754e-05,0.0033648,199.12123304709465,309.52132946291255,2.363740081427218
1.4593097514097892e-05,0.003372,199.1486592204382,309.52132946291255,2.363740081427218
1.466234115592042e-05,0.003388,199.2095246360071,309.52132946291255,2.363740081427218
1.4686576430558304e-05,0.0033935999999999997,199.23080103411579,309.52132946291255,2.363740081427218
1.4707349523105063e-05,0.0033983999999999998,199.24902705079518,309.52132946291255,2.363740081427218
1.4800828439565477e-05,0.00342,199.33092020146935,309.52132946291255,2.363740081427218
1.4838912442567867e-05,0.0034287999999999996,199.36422621764834,309.52132946291255,2.363740081427218
1.4973937544121799e-05,0.00346,199.48204350106016,309.52132946291255,2.363740081427218
1.5005097182941935e-05,0.0034671999999999997,199.50917317823402,309.52132946291255,2.363740081427218
1.5129735738222488e-05,0.003496,199.6174728899286,309.52132946291255,2.363740081427218
1.5268223021867545e-05,0.003528,199.7373986382624,309.52132946291255,2.363740081427218
1.5299382660687683e-05,0.0035351999999999996,199.7643233803107,309.52132946291255,2.363740081427218
1.5385937212965844e-05,0.0035551999999999997,199.83900235063177,309.52132946291255,2.363740081427218
1.5417096851785982e-05,0.0035624,199.86584664804857,309.52132946291255,2.363740081427218
1.551750013242865e-05,0.0035856,199.95220135737816,309.52132946291255,2.363740081427218
1.5600592502615682e-05,0.0036048,200.02350265262126,309.52132946291255,2.363740081427218
1.5617903413071314e-05,0.0036087999999999997,200.03833842979532,309.52132946291255,2.363740081427218
1.566291178025596e-05,0.0036192,200.07688146795147,309.52132946291255,2.363740081427218
1.568022269071159e-05,0.0036232,200.09169420883777,309.52132946291255,2.363740081427218
1.5714844511622853e-05,0.0036312,200.12130057123628,309.52132946291255,2.363740081427218
1.5773701607172e-05,0.0036447999999999997,200.17157307285098,309.52132946291255,2.363740081427218
1.581524779226552e-05,0.0036544,200.207015507613,309.52132946291255,2.363740081427218
1.5856793977359037e-05,0.0036639999999999997,200.24242164949356,309.52132946291255,2.363740081427218
1.5898340162452553e-05,0.0036736,200.2777916306012,309.52132946291255,2.363740081427218
1.6126844180466898e-05,0.0037264,200.47168597878712,309.52132946291255,2.363740081427218
1.6140692908831405e-05,0.0037296,200.48340259718088,309.52132946291255,2.363740081427218
1.6216860914836188e-05,0.0037472,200.5477740539967,309.52132946291255,2.363740081427218
1.6355348198481243e-05,0.0037792,200.66451178366387,309.52132946291255,2.363740081427218
1.6379583473119128e-05,0.0037847999999999996,200.68490118883824,309.52132946291255,2.363740081427218
1.646613802539729e-05,0.0038047999999999997,200.75762464367568,309.52132946291255,2.363740081427218
1.6545768213493197e-05,0.0038231999999999997,200.82439865784337,309.52132946291255,2.363740081427218
1.657000348813108e-05,0.0038288,200.84469629167643,309.52132946291255,2.363740081427218
1.6708490771776137e-05,0.0038607999999999997,200.96046143031668,309.52132946291255,2.363740081427218
1.674657477477853e-05,0.0038696,200.99223116270542,309.52132946291255,2.363740081427218
1.677427223150754e-05,0.0038759999999999997,201.01531872742294,309.52132946291255,2.363740081427218
1.680543187032768e-05,0.0038832,201.04127447378917,309.52132946291255,2.363740081427218
1.690237296887922e-05,0.0039056,201.1219059160334,309.52132946291255,2.363740081427218
1.702701152415977e-05,0.0039344,201.22531039564373,309.52132946291255,2.363740081427218
1.7061633345071034e-05,0.0039423999999999996,201.25398141928318,309.52132946291255,2.363740081427218
1.7158574443622574e-05,0.0039648,201.33413982511925,309.52132946291255,2.363740081427218
1.7186271900351587e-05,0.0039712,201.3570097613141,309.52132946291255,2.363740081427218
1.7193196264533837e-05,0.003972799999999999,201.36272499882028,309.52132946291255,2.363740081427218
1.7227818085445103e-05,0.0039808,201.3912877322266,309.52132946291255,2.363740081427218
1.9970398199165942e-05,0.0046145229045809165,203.58753110748233,309.52132946291255,2.363740081427218
2.0967706102991118e-05,0.00484496899379876,204.35654429816447,309.52132946291255,2.363740081427218
2.2629885942699746e-05,0.005229045809161833,205.60725178501943,309.52132946291255,2.363740081427218
2.3045430902626904e-05,0.005325065013002601,205.91426460126337,309.52132946291255,2.363740081427218
2.5704918646160704e-05,0.005939587917583517,207.83034897125142,309.52132946291255,2.363740081427218
2.786575243778192e-05,0.006438887777555511,209.33077547771907,309.52132946291255,2.363740081427218
2.8115079413738214e-05,0.006496499299859972,209.50093088409432,309.52132946291255,2.363740081427218
2.8779951349621663e-05,0.006650130026005201,209.95182588418325,309.52132946291255,2.363740081427218
3.0608349173301156e-05,0.007072614522904581,211.17130846375832,309.52132946291255,2.363740081427218
3.119011211719917e-05,0.007207041408281656,211.553322477187,309.52132946291255,2.363740081427218
3.409892683668927e-05,0.007879175835167033,213.42321801113786,309.52132946291255,2.363740081427218
3.443136280463099e-05,0.007955991198239648,213.63288293390318,309.52132946291255,2.363740081427218
3.542867070845617e-05,0.008186437287457491,214.2571911932064,309.52132946291255,2.363740081427218
3.783883147603368e-05,0.008743348669733947,215.73829022881105,309.52132946291255,2.363740081427218
3.9417902323756877e-05,0.009108221644328866,216.68875032204704,309.52132946291255,2.363740081427218
4.257604401920327e-05,0.009837967593518704,218.54623827979015,309.52132946291255,2.363740081427218
4.415511486692646e-05,0.010202840568113623,219.45476429146345,309.52132946291255,2.363740081427218
4.515242277075164e-05,0.010433286657331467,220.02204607733933,309.52132946291255,2.363740081427218
4.7313256562372854e-05,0.010932586517303462,221.23465685974253,309.52132946291255,2.363740081427218
4.82274554742126e-05,0.01114382876575315,221.7411596454654,309.52132946291255,2.363740081427218
4.972341732995036e-05,0.011489497899579915,222.56197879975076,309.52132946291255,2.363740081427218
5.055450724980467e-05,0.011681536307261452,223.0138260866988,309.52132946291255,2.363740081427218
5.196736011355701e-05,0.012008001600320064,223.77537359386562,309.52132946291255,2.363740081427218
5.404508491319279e-05,0.012488097619523904,224.88078763322147,309.52132946291255,2.363740081427218
5.48761748330471e-05,0.01268013602720544,225.31829705890465,309.52132946291255,2.363740081427218
5.520861080098883e-05,0.012756951390278055,225.4925763428105,309.52132946291255,2.363740081427218
5.562415576091599e-05,0.012852970594118824,225.7098509798503,309.52132946291255,2.363740081427218
5.720322660863918e-05,0.013217843568713743,226.52978459634863,309.52132946291255,2.363740081427218
5.8117425520478926e-05,0.013429085817163433,227.00044802179676,309.52132946291255,2.363740081427218
5.9031624432318675e-05,0.013640328065613123,227.4682327283373,309.52132946291255,2.363740081427218
6.002893233614385e-05,0.013870774154830966,227.975332692431,309.52132946291255,2.363740081427218
6.1026240239969026e-05,0.01410122024404881,228.47915740687202,309.52132946291255,2.363740081427218
6.210665713577963e-05,0.014350870174034807,229.02135744016346,309.52132946291255,2.363740081427218
6.385194596747369e-05,0.014754150830166034,229.88951197437953,309.52132946291255,2.363740081427218
6.459992689534258e-05,0.014926985397079416,230.2587395537576,309.52132946291255,2.363740081427218
6.501547185526973e-05,0.015023004600920185,230.4631454403061,309.52132946291255,2.363740081427218
6.568034379115319e-05,0.015176635327065414,230.7891382424074,309.52132946291255,2.363740081427218
6.67607606869638e-05,0.015426285257051411,231.3161449454597,309.52132946291255,2.363740081427218
6.900470347057044e-05,0.01594478895779156,232.40018597238125,309.52132946291255,2.363740081427218
7.083310129424993e-05,0.01636727345469094,233.27334804164562,309.52132946291255,2.363740081427218
7.174730020608967e-05,0.016578515703140628,233.70662942412937,309.52132946291255,2.363740081427218
7.216284516601683e-05,0.016674534906981398,233.902863193415,309.52132946291255,2.363740081427218
7.440678794962347e-05,0.017193038607721544,234.95500642745785,309.52132946291255,2.363740081427218
7.548720484543409e-05,0.017442688537707543,235.4571739332014,309.52132946291255,2.363740081427218
7.806358359698245e-05,0.018038007601520304,236.6434711371482,309.52132946291255,2.363740081427218
7.889467351683676e-05,0.01823004600920184,237.0228772639989,309.52132946291255,2.363740081427218
8.063996234853082e-05,0.018633326665333065,237.8145936103377,309.52132946291255,2.363740081427218
8.238525118022489e-05,0.019036607321464293,238.59965477422438,309.52132946291255,2.363740081427218
8.570961085964214e-05,0.01980476095219044,240.07729319260835,309.52132946291255,2.363740081427218
8.679002775545274e-05,0.020054410882176434,240.55269033048944,309.52132946291255,2.363740081427218
8.72055727153799e-05,0.020150430086017204,240.73492011810285,309.52132946291255,2.363740081427218
8.920018852303026e-05,0.02061132226445289,241.6049523564229,309.52132946291255,2.363740081427218
9.044682340281172e-05,0.020899379875975194,242.14487111237116,309.52132946291255,2.363740081427218
9.227522122649121e-05,0.021321864372874574,242.9315313625361,309.52132946291255,2.363740081427218
9.551647191392304e-05,0.022070814162832568,244.31128508771383,309.52132946291255,2.363740081427218
9.593201687385019e-05,0.022166833366673334,244.48684647203825,309.52132946291255,2.363740081427218
9.72617607456171e-05,0.022474094818963793,245.0466602515622,309.52132946291255,2.363740081427218
0.00010008746647312176,0.023127025405081016,246.2264488896056,309.52132946291255,2.363740081427218
0.00010058612042503435,0.023242248449689938,246.43329119731365,309.52132946291255,2.363740081427218
0.00010490778800827679,0.024240848169633927,248.2094761017763,309.52132946291255,2.363740081427218
0.0001065699678479854,0.024624924984997,248.88499616843924,309.52132946291255,2.363740081427218
0.00010823214768769403,0.025009001800360073,249.55641941578497,309.52132946291255,2.363740081427218
0.00011064230845527154,0.025565913182636527,250.52288354556703,309.52132946291255,2.363740081427218
0.00011296936023086362,0.02610362072414483,251.4482601293012,309.52132946291255,2.363740081427218
0.00011313557821483447,0.026142028405681136,251.51407259515352,309.52132946291255,2.363740081427218
0.00011463154007057224,0.0264876975395079,252.10469750868833,309.52132946291255,2.363740081427218
0.0001168754828541789,0.02700620124024805,252.98502951011346,309.52132946291255,2.363740081427218
0.00011737413680609148,0.027121424284856973,253.1797607927499,309.52132946291255,2.363740081427218
0.00011870388067785839,0.02742868573714743,253.69747326575225,309.52132946291255,2.363740081427218
0.00012078160547749416,0.02790878175635127,254.5018937845768,309.52132946291255,2.363740081427218
0.0001221944583412465,0.028235247049409884,255.04581944933884,309.52132946291255,2.363740081427218
0.0001226931122931591,0.028350470094018806,255.2372068959755,309.52132946291255,2.363740081427218
0.0001237735291889697,0.0286001200240048,255.65084210002556,309.52132946291255,2.363740081427218
0.00012443840112485316,0.02875375075015003,255.90468703327292,309.52132946291255,2.363740081427218
0.00012585125398860547,0.02908021604320864,256.44235790075516,309.52132946291255,2.363740081427218
0.00012792897878824127,0.029560312062412483,257.2287935017377,309.52132946291255,2.363740081427218
0.00012950804963596444,0.0299251850370074,257.82315743354354,309.52132946291255,2.363740081427218
0.00013058846653177508,0.0301748349669934,258.22819996226065,309.52132946291255,2.363740081427218
0.00013266619133141085,0.03065493098619724,259.0034733080362,309.52132946291255,2.363740081427218
0.00013349728125126517,0.030846969393878775,259.31225500566075,309.52132946291255,2.363740081427218
0.00013382971721920687,0.03092378475695139,259.43555765734493,309.52132946291255,2.363740081427218
0.00013482702512303206,0.031154230846169233,259.80475088981336,309.52132946291255,2.363740081427218
0.00013615676899479898,0.031461492298459695,260.2953560345161,309.52132946291255,2.363740081427218
0.00013748651286656587,0.03176875375075015,260.78409605877505,309.52132946291255,2.363740081427218
0.00013840071177840564,0.031979995999199845,261.11903593913115,309.52132946291255,2.363740081427218
0.0001413095264978957,0.03265213042608522,262.1790584581087,309.52132946291255,2.363740081427218
0.00014180818044980828,0.032767353470694136,262.3599187779871,309.52132946291255,2.363740081427218
0.0001423068344017209,0.03288257651530306,262.5405312362989,309.52132946291255,2.363740081427218
0.0001443845592013567,0.03336267253450691,263.290441709447,309.52132946291255,2.363740081427218
0.0001462960660170216,0.033804360872174435,263.9766505747401,309.52132946291255,2.363740081427218
0.00014912177174452625,0.034457291458291656,264.98467545902605,309.52132946291255,2.363740081427218
0.00015128260553614746,0.034956591318263654,265.7504995131897,309.52132946291255,2.363740081427218
0.0001526954583998998,0.035283056611322264,266.2489251342671,309.52132946291255,2.363740081427218
0.00015543805513541906,0.03591678335667134,267.2113524229726,309.52132946291255,2.363740081427218
0.00015610292707130251,0.03607041408281657,267.4436679882182,309.52132946291255,2.363740081427218
0.00015676779900718595,0.0362240448089618,267.6755979767576,309.52132946291255,2.363740081427218
0.00015959350473469062,0.03687697539507902,268.6570511951617,309.52132946291255,2.363740081427218
0.0001601752676785886,0.03701140228045609,268.8582712094825,309.52132946291255,2.363740081427218
0.00016250231945418072,0.037549109821964397,269.66031726052773,309.52132946291255,2.363740081427218
0.00016291786441410786,0.03764512902580516,269.80306715102944,309.52132946291255,2.363740081427218
0.00016341651836602046,0.03776035207041409,269.9741797162012,309.52132946291255,2.363740081427218
0.00016433071727786023,0.03797159431886378,270.2873581377842,309.52132946291255,2.363740081427218
0.00016524491618969992,0.03818283656731346,270.59985780909574,309.52132946291255,2.363740081427218
0.00016615911510153966,0.03839407881576315,270.9116839441645,309.52132946291255,2.363740081427218
0.00016723953199735027,0.038643728745749145,271.2793444111611,309.52132946291255,2.363740081427218
0.00016940036578897154,0.03914302860572115,272.0118980855998,309.52132946291255,2.363740081427218
0.00017388825135618478,0.040180036007201436,273.52181261515335,309.52132946291255,2.363740081427218
0.0001786254638993544,0.0412746549309862,275.09921451643913,309.52132946291255,2.363740081427218
0.0001804538617230339,0.04169713942788558,275.7036619068056,309.52132946291255,2.363740081427218
0.0001828640224906114,0.042254050810162036,276.49679659962794,309.52132946291255,2.363740081427218
0.0001852741832581889,0.04281096219243849,277.28586471940247,309.52132946291255,2.363740081427218
0.0001873519080578247,0.043291058211642336,277.9628881855392,309.52132946291255,2.363740081427218
0.0001879336710017227,0.043425485097019406,278.15192921236496,309.52132946291255,2.363740081427218
0.0001885154339456207,0.043559911982396476,278.3407421520343,309.52132946291255,2.363740081427218
0.0001908424857212128,0.044097619523904785,279.09373248802916,309.52132946291255,2.363740081427218
0.0001933357554807757,0.044673734746949384,279.89654511478705,309.52132946291255,2.363740081427218
0.00019416684540063007,0.04486577315463093,280.1632507199526,309.52132946291255,2.363740081427218
0.00019616146120828042,0.04532666533306662,280.8015342127494,309.52132946291255,2.363740081427218
0.00019707566012012017,0.04553790758151631,281.09323439743326,309.52132946291255,2.363740081427218
0.00019898716693578507,0.04597959591918384,281.70145317310244,309.52132946291255,2.363740081427218
0.00020015069282358113,0.04624844968993799,282.07055780375003,309.52132946291255,2.363740081427218
0.0002023946356071878,0.04676695339067814,282.7800478060659,309.52132946291255,2.363740081427218
0.00020405681544689638,0.04715103020604121,283.3036197089437,309.52132946291255,2.363740081427218
0.00020555277730263414,0.04749669933986797,283.77341401322855,309.52132946291255,2.363740081427218
0.0002082953740381534,0.048130426085217046,284.6312548776636,309.52132946291255,2.363740081427218
0.00021087175278970173,0.0487257451490298,285.4331013578176,309.52132946291255,2.363740081427218
0.00021411300347713358,0.049474694938987804,286.4364695908135,309.52132946291255,2.363740081427218
0.00021535963835691505,0.0497627525505101,286.8208009380361,309.52132946291255,2.363740081427218
0.00021602451029279849,0.04991638327665533,287.02542283851886,309.52132946291255,2.363740081427218
0.00021826845307640515,0.05043488697739548,287.71421562080315,309.52132946291255,2.363740081427218
0.0002213434857798661,0.051145429085817165,288.6536481895804,309.52132946291255,2.363740081427218
0.00022175903073979325,0.05124144828965793,288.78020702197296,309.52132946291255,2.363740081427218
0.000222091466707735,0.05131826365273055,288.8813875079734,309.52132946291255,2.363740081427218
0.00022500028142722505,0.05199039807961592,289.7642113942182,309.52132946291255,2.363740081427218
0.0002260806983230357,0.05224004800960193,290.0909822997398,309.52132946291255,2.363740081427218
0.00022649624328296286,0.052336067213442694,290.2165011803169,309.52132946291255,2.363740081427218
0.00022865707707458405,0.052835367073414685,290.8677572567876,309.52132946291255,2.363740081427218
0.00022973749397039466,0.05308501700340068,291.1924848874869,309.52132946291255,2.363740081427218
0.00023198143675400132,0.05360352070414083,291.8650223180676,309.52132946291255,2.363740081427218
0.00023272941768187017,0.053776355271054205,292.08863703240576,309.52132946291255,2.363740081427218
0.0002349733604654768,0.054294858971794355,292.7578054754274,309.52132946291255,2.363740081427218
0.00023547201441738943,0.05441008201640328,292.906170581114,309.52132946291255,2.363740081427218
0.00024178829780828224,0.05586957391478296,294.7749797458284,309.52132946291255,2.363740081427218
0.00024203762478423847,0.05592718543708741,294.8483553293754,309.52132946291255,2.363740081427218
0.00024328425966402,0.056215243048609725,295.2147920026152,309.52132946291255,2.363740081427218
0.00024527887547167034,0.05667613522704541,295.7995711667473,309.52132946291255,2.363740081427218
0.0002467748373274081,0.057021804360872175,296.23693921507413,309.52132946291255,2.363740081427218
0.00024743970926329156,0.057175435087017404,296.4309929780048,309.52132946291255,2.363740081427218
0.00024984987003086903,0.05773234646929386,297.1327396065046,309.52132946291255,2.363740081427218
0.00025093028692667964,0.05798199639927985,297.44645817622813,309.52132946291255,2.363740081427218
0.0002541715376141115,0.058730946189237854,298.3844682496171,309.52132946291255,2.363740081427218
0.00025566749946984927,0.059076615323064616,298.81582143028487,309.52132946291255,2.363740081427218
0.0002590749681412519,0.059863972794558906,299.79469035421334,309.52132946291255,2.363740081427218
0.00025949051310117914,0.059959991998399687,299.91372015012246,309.52132946291255,2.363740081427218
0.0002609033659649314,0.06028645729145829,300.31786656034114,309.52132946291255,2.363740081427218
0.00026131891092485857,0.060382476495299056,300.43657059774785,309.52132946291255,2.363740081427218
0.0002623993278206692,0.06063212642528505,300.7448570797692,309.52132946291255,2.363740081427218
0.00026339663572449437,0.0608625725145029,301.028990111707,309.52132946291255,2.363740081427218
0.0002664716684279553,0.061573114622924585,301.90243722427056,309.52132946291255,2.363740081427218
0.0002668041043958971,0.06164992998599721,301.99662788614233,309.52132946291255,2.363740081427218
0.0002697960281073726,0.06234126825365073,302.84229410636414,309.52132946291255,2.363740081427218
0.00027303727879480436,0.06309021804360872,303.75431574203895,309.52132946291255,2.363740081427218
0.00027519811258642563,0.06358951790358072,304.3599854677386,309.52132946291255,2.363740081427218
0.0002763616384742216,0.06385837167433486,304.6853469772112,309.52132946291255,2.363740081427218
0.0002766109654501779,0.06391598319663933,304.75499774652866,309.52132946291255,2.363740081427218
0.0002817637229532747,0.06510662132426485,306.1890106662872,309.52132946291255,2.363740081427218
0.0002825117038811436,0.06527945589117824,306.39632059373344,309.52132946291255,2.363740081427218
0.00028317657581702704,0.06543308661732347,306.5804164468036,309.52132946291255,2.363740081427218
0.00028400766573688133,0.065625125025005,306.8102993792355,309.52132946291255,2.363740081427218
0.0002847556466647502,0.06579795959191838,307.01696980214905,309.52132946291255,2.363740081427218
0.00028591917255254624,0.06606681336267253,307.3380367998583,309.52132946291255,2.363740081427218
0.00028824622432813835,0.06660452090418084,307.97864619680485,309.52132946291255,2.363740081427218
0.00028907731424799264,0.06679655931186237,308.20694605044673,309.52132946291255,2.363740081427218
0.0002894928592079198,0.06689257851570314,308.3209999749568,309.52132946291255,2.363740081427218
0.0002898252951758616,0.06696939387877576,308.4121971499267,309.52132946291255,2.363740081427218
0.00029007462215181783,0.06702700540108023,308.48056826119694,309.52132946291255,2.363740081427218
0.00029364830880719144,0.06785277055411083,309.458049334768,309.52132946291255,2.363740081427218
0.00029531048864690003,0.0682368473694739,309.9111098943433,309.52132946291255,2.363740081427218
0.00029730510445455036,0.06869773954790959,310.45347189263754,309.52132946291255,2.363740081427218
0.00029921661127021526,0.06913942788557711,310.9719054002198,309.52132946291255,2.363740081427218
0.00030586533062904975,0.0706757351470294,312.7651777614763,309.52132946291255,2.363740081427218
0.00030628087558897695,0.07077175435087017,312.87674985294035,309.52132946291255,2.363740081427218
0.00030719507450081666,0.07098299659931986,313.1220008581051,309.52132946291255,2.363740081427218
0.00030860792736456906,0.07130946189237848,313.5004660042464,309.52132946291255,2.363740081427218
0.0003100207802283214,0.0716359271854371,313.8782560093401,309.52132946291255,2.363740081427218
0.0003113505241000883,0.07194318863772756,314.2332101625505,309.52132946291255,2.363740081427218
0.0003130127039397969,0.07232726545309062,314.6760725378546,309.52132946291255,2.363740081427218
0.0003158384096673015,0.07298019603920784,315.4268394411323,309.52132946291255,2.363740081427218
0.00031999385926657307,0.07394038807761552,316.5261670751965,309.52132946291255,2.363740081427218
0.0003215729301142963,0.07430526105221044,316.9424499763637,309.52132946291255,2.363740081427218
0.0003244817448337864,0.07497739547909582,317.70720596794257,309.52132946291255,2.363740081427218
0.0003265594696334222,0.07545749149829967,318.25182418635166,309.52132946291255,2.363740081427218
0.0003271412325773202,0.07559191838367674,318.40407490283275,309.52132946291255,2.363740081427218
0.0003281385404811454,0.07582236447289459,318.66483069525634,309.52132946291255,2.363740081427218
0.0003300500472968103,0.07626405281056212,319.1637503307269,309.52132946291255,2.363740081427218
0.0003317953361285044,0.07666733346669334,319.61830233864623,309.52132946291255,2.363740081427218
0.00033204466310446064,0.0767249449889978,319.6831621367838,309.52132946291255,2.363740081427218
0.0003338730609281402,0.07714742948589719,320.1582216481969,309.52132946291255,2.363740081427218
0.0003383609464953534,0.07818443688737747,321.3199954716563,309.52132946291255,2.363740081427218
0.0003389427094392515,0.07831886377275456,321.4701545521796,309.52132946291255,2.363740081427218
0.000340771107262931,0.07874134826965394,321.94143003993287,309.52132946291255,2.363740081427218
0.00034251639609462505,0.07914462892578517,322.39036482705524,309.52132946291255,2.363740081427218
0.00034417857593433364,0.07952870574114823,322.81709306486033,309.52132946291255,2.363740081427218
0.0003471704996458092,0.08022004400880177,323.58318399375275,309.52132946291255,2.363740081427218
0.0003480846985576489,0.08043128625725146,323.8167531880615,309.52132946291255,2.363740081427218
0.00035215703916493504,0.08137227445489098,324.8543049084635,309.52132946291255,2.363740081427218
0.00035481652690846883,0.0819867973594719,325.52936488522374,309.52132946291255,2.363740081427218
0.00036096659231539074,0.08340788157631526,327.0829280494784,309.52132946291255,2.363740081427218
0.0003617976822352451,0.08359991998399681,327.2920744586683,309.52132946291255,2.363740081427218
0.000362545663163114,0.08377275455091018,327.48014608117103,309.52132946291255,2.363740081427218
0.0003639585160268663,0.0840992198439688,327.834980115673,309.52132946291255,2.363740081427218
0.000367947747642167,0.08502100420084018,328.833976317891,309.52132946291255,2.363740081427218
0.00036927749151393393,0.08532826565313063,329.1660351983298,309.52132946291255,2.363740081427218
0.0003698592544578319,0.0854626925385077,329.3111642842321,309.52132946291255,2.363740081427218
0.00037152143429754057,0.08584676935387078,329.72532906283544,309.52132946291255,2.363740081427218
0.00037434714002504524,0.086499699939988,330.42775452292364,309.52132946291255,2.363740081427218
0.0003768404097846082,0.08707581516303262,331.0458262578989,309.52132946291255,2.363740081427218
0.0003774221727285062,0.08721024204840969,331.18981327293983,309.52132946291255,2.363740081427218
0.00037858569861630225,0.08747909581916384,331.4775278923725,309.52132946291255,2.363740081427218
0.0003807465324079234,0.08797839567913583,332.01094177605063,309.52132946291255,2.363740081427218
0.00038207627627969033,0.08828565713142629,332.33860970457494,309.52132946291255,2.363740081427218
0.00038340602015145725,0.08859291858371675,332.66583318320266,309.52132946291255,2.363740081427218
0.00038714592479080164,0.08945709141828366,333.58378472156807,309.52132946291255,2.363740081427218
0.0003883925596705831,0.08974514902980596,333.8889991903187,309.52132946291255,2.363740081427218
0.000389140540598452,0.08991798359671935,334.0719444854732,309.52132946291255,2.363740081427218
0.0003896391945503646,0.09003320664132827,334.19383183157976,309.52132946291255,2.363740081427218
0.0003909689384221315,0.09034046809361873,334.5185677020069,309.52132946291255,2.363740081427218
0.00039171691935000033,0.0905133026605321,334.70104233150664,309.52132946291255,2.363740081427218
0.00039304666322176725,0.09082056411282256,335.02510649867395,309.52132946291255,2.363740081427218
0.0003949581700374322,0.0912622524504901,335.4902006393866,309.52132946291255,2.363740081427218
0.0003963710229011845,0.09158871774354871,335.83340184781974,309.52132946291255,2.363740081427218
0.0003966203498771408,0.09164632926585317,335.89391720810835,309.52132946291255,2.363740081427218
0.0003984487477008203,0.09206881376275255,336.33724407602983,309.52132946291255,2.363740081427218
0.0003995291645966309,0.09231846369273855,336.59883703468694,309.52132946291255,2.363740081427218
0.0004016068893962667,0.0927985597119424,337.1011262917939,309.52132946291255,2.363740081427218
0.00040310285125200445,0.09314422884576916,337.4621472337629,309.52132946291255,2.363740081427218
0.0004037677231878879,0.09329785957191439,337.6224332246792,309.52132946291255,2.363740081427218
0.00040443259512377137,0.09345149029805962,337.78261631275427,309.52132946291255,2.363740081427218
0.0004051805760516403,0.093624324864973,337.96269957843884,309.52132946291255,2.363740081427218
0.00040734140984326146,0.094123624724945,338.48221326466773,309.52132946291255,2.363740081427218
0.00041133064145856216,0.09504540908181637,339.43850047642286,309.52132946291255,2.363740081427218
0.00041307593029025623,0.0954486897379476,339.8557380124757,309.52132946291255,2.363740081427218
0.0004177300338414404,0.0965241048209642,340.96502387291633,309.52132946291255,2.363740081427218
0.000418810450737251,0.0967737547509502,341.22184607592726,309.52132946291255,2.363740081427218
0.00042030641259298876,0.09711942388477696,341.5770198906084,309.52132946291255,2.363740081427218
0.0004211375025128431,0.0973114622924585,341.7741256368123,309.52132946291255,2.363740081427218
0.00042346455428843516,0.0978491698339668,342.3252163109737,309.52132946291255,2.363740081427218
0.00042429564420828946,0.09804120824164833,342.52174801684555,309.52132946291255,2.363740081427218
0.0004265395869918961,0.09855971194238848,343.0516351461943,309.52132946291255,2.363740081427218
0.0004267889139678524,0.09861732346469294,343.1104443074066,309.52132946291255,2.363740081427218
0.000427869330863663,0.09886697339467894,343.3651293325723,309.52132946291255,2.363740081427218
0.0004288666387674882,0.09909741948389679,343.6000006770972,309.52132946291255,2.363740081427218
0.00042936529271940077,0.0992126425285057,343.71735646344854,309.52132946291255,2.363740081427218
0.00043011327364726965,0.09938547709541909,343.89329052728687,309.52132946291255,2.363740081427218
0.0004305288186071968,0.09948149629925986,343.9909801137757,309.52132946291255,2.363740081427218
0.0004313599085270511,0.09967353470694139,344.18624903786264,309.52132946291255,2.363740081427218
0.00043177545348697824,0.09976955391078215,344.2838284738862,309.52132946291255,2.363740081427218
0.000432689652398818,0.09998079615923185,344.49837440460414,309.52132946291255,2.363740081427218
0.0004327727613908035,0.1,344.51786980965716,309.52132946291255,2.363740081427218