File: datasets/aisi_316_L/data/M1/train_16.csv
Time(s),Strain(%),Stress(MPa),Temp(C),Log_SR(s-1)
0.0,0.0,0.0,308.93418973066116,0.33843841893701576
6.972767254017622e-06,1.52e-05,2.689231975,308.93418973066116,0.33843841893701576
8.073730504651983e-06,1.76e-05,3.11384755,308.93418973066116,0.33843841893701576
1.578047325909251e-05,3.4399999999999996e-05,6.0861565749999995,308.93418973066116,0.33843841893701576
3.1193958767973574e-05,6.8e-05,12.030774625,308.93418973066116,0.33843841893701576
3.229492201860793e-05,7.04e-05,12.4553902,308.93418973066116,0.33843841893701576
3.6331787270933925e-05,7.92e-05,14.012313975,308.93418973066116,0.33843841893701576
4.110262802368282e-05,8.96e-05,15.852314799999998,308.93418973066116,0.33843841893701576
6.642478278827314e-05,0.0001448,25.618473025,308.93418973066116,0.33843841893701576
7.339755004229076e-05,0.00015999999999999999,28.307705,308.93418973066116,0.33843841893701576
8.110429279673128e-05,0.0001768,31.280014024999996,308.93418973066116,0.33843841893701576
8.440718254863438e-05,0.000184,32.55386075,308.93418973066116,0.33843841893701576
9.358187630392071e-05,0.000204,36.092323875,308.93418973066116,0.33843841893701576
0.00010349054555962997,0.00022559999999999998,39.913864049999994,308.93418973066116,0.33843841893701576
0.00011450017806597358,0.0002496,44.1600198,308.93418973066116,0.33843841893701576
0.00012000499431914538,0.00026159999999999996,46.28309767499999,308.93418973066116,0.33843841893701576
0.00012661077382295155,0.000276,48.830791125,308.93418973066116,0.33843841893701576
0.00014165727158162115,0.00030879999999999997,54.63387064999999,308.93418973066116,0.33843841893701576
0.00015817172034113657,0.0003448,61.003104275,308.93418973066116,0.33843841893701576
0.0001596396713419824,0.000348,61.569258375,308.93418973066116,0.33843841893701576
0.00016074063459261677,0.0003504,61.99387395,308.93418973066116,0.33843841893701576
0.00016220858559346256,0.0003536,62.56002804999999,308.93418973066116,0.33843841893701576
0.00016404352434451984,0.00035759999999999996,63.26772067499999,308.93418973066116,0.33843841893701576
0.0001820259241048811,0.0003968,70.2031084,308.93418973066116,0.33843841893701576
0.00019413651986185905,0.0004232,74.873879725,308.93418973066116,0.33843841893701576
0.0001952374831124934,0.0004256,75.2984953,308.93418973066116,0.33843841893701576
0.0001978063973639736,0.00043119999999999996,76.289264975,308.93418973066116,0.33843841893701576
0.00020771506661968286,0.0004528,80.11080515,308.93418973066116,0.33843841893701576
0.00021175193187200885,0.0004616,81.667728925,308.93418973066116,0.33843841893701576
0.0002168897603749692,0.0004728,83.649268275,308.93418973066116,0.33843841893701576
0.00022055963787708373,0.0004808,85.064653525,308.93418973066116,0.33843841893701576
0.00022533047862983264,0.0004912,86.90465435,308.93418973066116,0.33843841893701576
0.00023303722138427315,0.000508,89.876963375,308.93418973066116,0.33843841893701576
0.00023707408663659914,0.0005168,91.43388715,308.93418973066116,0.33843841893701576
0.00024551480489146257,0.0005352,94.689273225,308.93418973066116,0.33843841893701576
0.00025432251089653745,0.0005543999999999999,98.08619782499999,308.93418973066116,0.33843841893701576
0.0002561574496475948,0.0005584,98.79389045,308.93418973066116,0.33843841893701576
0.0002634972046518238,0.0005744,101.62466094999999,308.93418973066116,0.33843841893701576
0.0002653321434028811,0.0005784,102.332353575,308.93418973066116,0.33843841893701576
0.0002748738249083789,0.0005991999999999999,106.012355225,308.93418973066116,0.33843841893701576
0.000289553334916837,0.0006312,111.673896225,308.93418973066116,0.33843841893701576
0.00029212224916831724,0.0006368,112.66466589999999,308.93418973066116,0.33843841893701576
0.00029395718791937447,0.0006408,113.372358525,308.93418973066116,0.33843841893701576
0.000297627065421489,0.0006487999999999999,114.787743775,308.93418973066116,0.33843841893701576
0.00031120561217931283,0.0006784,120.0246692,308.93418973066116,0.33843841893701576
0.00032184825693544494,0.0007015999999999999,124.12928642499999,308.93418973066116,0.33843841893701576
0.00032845403643925114,0.000716,126.67697987499999,308.93418973066116,0.33843841893701576
0.00034129860769665203,0.000744,131.63082825,308.93418973066116,0.33843841893701576
0.00034753739945024673,0.0007576,134.036983175,308.93418973066116,0.33843841893701576
0.00036515281146039653,0.0007959999999999999,140.830832375,308.93418973066116,0.33843841893701576
0.00036698775021145377,0.0007999999999999999,141.538525,308.93418973066116,0.33843841893701576
0.0003757954562165287,0.0008192,144.9354496,308.93418973066116,0.33843841893701576
0.0003783643704680089,0.0008248,145.926219275,308.93418973066116,0.33843841893701576
0.0003842361744713921,0.0008376,148.190835675,308.93418973066116,0.33843841893701576
0.0003868050887228723,0.0008432,149.18160535,308.93418973066116,0.33843841893701576
0.0003904749662249868,0.0008512,150.5969906,308.93418973066116,0.33843841893701576
0.000393043880476467,0.0008568,151.587760275,308.93418973066116,0.33843841893701576
0.0003948788192275243,0.0008608,152.2954529,308.93418973066116,0.33843841893701576
0.0003974477334790044,0.0008663999999999999,153.28622257499998,308.93418973066116,0.33843841893701576
0.000401117610981119,0.0008744,154.701607825,308.93418973066116,0.33843841893701576
0.00040992531698619386,0.0008935999999999999,158.09853242499997,308.93418973066116,0.33843841893701576
0.00041763205974063445,0.0009104,161.07084145,308.93418973066116,0.33843841893701576
0.00041983398624190313,0.0009151999999999999,161.9200726,308.93418973066116,0.33843841893701576
0.0004264397657457093,0.0009295999999999999,164.46776605,308.93418973066116,0.33843841893701576
0.0004290086799971895,0.0009352,165.458535725,308.93418973066116,0.33843841893701576
0.0004323115697490925,0.0009423999999999999,166.73238245,308.93418973066116,0.33843841893701576
0.0004462571042571278,0.0009728,172.1108464,308.93418973066116,0.33843841893701576
0.0004554317980124142,0.0009928,175.649309525,308.93418973066116,0.33843841893701576
0.00046350552851706617,0.0010104,178.763157075,308.93418973066116,0.33843841893701576
0.00048442383027911894,0.0010559999999999999,180.28412329109773,308.93418973066116,0.33843841893701576
0.0004935985240344053,0.001076,180.39826848709484,308.93418973066116,0.33843841893701576
0.000500571291288423,0.0010911999999999999,180.48446627264482,308.93418973066116,0.33843841893701576
0.0005060761075415947,0.0011032,180.5521868195962,308.93418973066116,0.33843841893701576
0.0005101129727939208,0.001112,180.6016661075576,308.93418973066116,0.33843841893701576
0.0005156177890470926,0.001124,180.66889246371613,308.93418973066116,0.33843841893701576
0.0005332332010572423,0.0011623999999999998,180.8821596939017,308.93418973066116,0.33843841893701576
0.0005387380173104141,0.0011744,180.94823985242456,308.93418973066116,0.33843841893701576
0.0005420409070623172,0.0011815999999999999,180.9877615598512,308.93418973066116,0.33843841893701576
0.000551582588567815,0.0012024,181.10141120435247,308.93418973066116,0.33843841893701576
0.0005581883680716212,0.0012167999999999999,181.17964296206412,308.93418973066116,0.33843841893701576
0.0005669960740766961,0.001236,181.28339260170995,308.93418973066116,0.33843841893701576
0.0005743358290809252,0.0012519999999999999,181.36937135753968,308.93418973066116,0.33843841893701576
0.000595988106343401,0.0012992,181.62054627680703,308.93418973066116,0.33843841893701576
0.0005967220818438239,0.0013008,181.6289977338683,308.93418973066116,0.33843841893701576
0.0006066307510995331,0.0013223999999999998,181.7426984923361,308.93418973066116,0.33843841893701576
0.0006114015918522819,0.0013327999999999999,181.79718477955822,308.93418973066116,0.33843841893701576
0.0006205762856075684,0.0013528,181.9015022989769,308.93418973066116,0.33843841893701576
0.0006253471263603172,0.0013632,181.95550960364326,308.93418973066116,0.33843841893701576
0.0006323198936143349,0.0013784,182.03415519745948,308.93418973066116,0.33843841893701576
0.0006499353056244846,0.0014168,182.2313469748848,308.93418973066116,0.33843841893701576
0.0006653487911333657,0.0014504,182.40218606449798,308.93418973066116,0.33843841893701576
0.0006822302276430926,0.0014872,182.58753412123784,308.93418973066116,0.33843841893701576
0.0006873680561460529,0.0014984,182.64358822843974,308.93418973066116,0.33843841893701576
0.000698744676402608,0.0015232,182.76712979459782,308.93418973066116,0.33843841893701576
0.0007038825049055684,0.0015344,182.82266537122067,308.93418973066116,0.33843841893701576
0.0007060844314068371,0.0015392,182.84641791159925,308.93418973066116,0.33843841893701576
0.000710121296659163,0.001548,182.88988934192946,308.93418973066116,0.33843841893701576
0.000710855272159586,0.0015496,182.89778287276303,308.93418973066116,0.33843841893701576
0.0007214979169157181,0.0015727999999999998,183.01188423220572,308.93418973066116,0.33843841893701576
0.000726268757668467,0.0015831999999999999,183.0628198449549,308.93418973066116,0.33843841893701576
0.0007449851329292512,0.001624,183.2613966661276,308.93418973066116,0.33843841893701576
0.000754526814434749,0.0016447999999999999,183.361882459332,308.93418973066116,0.33843841893701576
0.0007637015081900353,0.0016648,183.4580370842354,308.93418973066116,0.33843841893701576
0.0007681053611925728,0.0016744,183.5040311928536,308.93418973066116,0.33843841893701576
0.0007754451161968018,0.0016903999999999999,183.58046015422852,308.93418973066116,0.33843841893701576
0.0007787480059487049,0.0016975999999999998,183.61476108812164,308.93418973066116,0.33843841893701576
0.0007816839079503966,0.001704,183.64520320476507,308.93418973066116,0.33843841893701576
0.0007893906507048371,0.0017208,183.72490235477088,308.93418973066116,0.33843841893701576
0.0007919595649563173,0.0017264,183.75140122757017,308.93418973066116,0.33843841893701576
0.0008040701607132953,0.0017527999999999999,183.87587573597014,308.93418973066116,0.33843841893701576
0.0008121438912179472,0.0017703999999999999,183.95845277353186,308.93418973066116,0.33843841893701576
0.0008246214747251367,0.0017976,184.08544486977914,308.93418973066116,0.33843841893701576
0.0008400349602340177,0.0018311999999999998,184.24128749529459,308.93418973066116,0.33843841893701576
0.0008415029112348635,0.0018344,184.25607124590374,308.93418973066116,0.33843841893701576
0.0008477417029884582,0.0018479999999999998,184.318790309545,308.93418973066116,0.33843841893701576
0.00085324651924163,0.0018599999999999999,184.37398132206368,308.93418973066116,0.33843841893701576
0.0008576503722441675,0.0018696,184.41803421266522,308.93418973066116,0.33843841893701576
0.0008602192864956476,0.0018751999999999998,184.44369099249099,308.93418973066116,0.33843841893701576
0.0008635221762475508,0.0018824,184.47663441563373,308.93418973066116,0.33843841893701576
0.0008664580782492424,0.0018888,184.5058762258457,308.93418973066116,0.33843841893701576
0.0008679260292500882,0.001892,184.52048263827402,308.93418973066116,0.33843841893701576
0.00087343084550326,0.0019039999999999999,184.5751710884758,308.93418973066116,0.33843841893701576
0.0008914132452636212,0.0019432,184.75289050570723,308.93418973066116,0.33843841893701576
0.0008932481840146785,0.0019471999999999998,184.77094616995473,308.93418973066116,0.33843841893701576
0.0008947161350155243,0.0019504,184.78538028851756,308.93418973066116,0.33843841893701576
0.0009020558900197534,0.0019664,184.85741280552617,308.93418973066116,0.33843841893701576
0.0009108635960248284,0.0019856,184.94355079828912,308.93418973066116,0.33843841893701576
0.0009141664857767313,0.0019928,184.9757687204883,308.93418973066116,0.33843841893701576
0.0009310479222864582,0.0020296,185.13973443681928,308.93418973066116,0.33843841893701576
0.0009376537017902643,0.002044,185.2035788075754,308.93418973066116,0.33843841893701576
0.0009497642975472425,0.0020704,185.32017307565695,308.93418973066116,0.33843841893701576
0.0009626088688046432,0.0020984,185.44320184663584,308.93418973066116,0.33843841893701576
0.0009644438075557005,0.0021024,185.4607249790348,308.93418973066116,0.33843841893701576
0.000968113685057815,0.0021103999999999997,185.49573228559532,308.93418973066116,0.33843841893701576
0.0009765544033126784,0.0021287999999999997,185.576053272538,308.93418973066116,0.33843841893701576
0.0009824262073160619,0.0021416,185.63176912538376,308.93418973066116,0.33843841893701576
0.000988298011319445,0.0021544,185.68735525671144,308.93418973066116,0.33843841893701576
0.001001142582576846,0.0021823999999999997,185.80850285275326,308.93418973066116,0.33843841893701576
0.001004445472328749,0.0021896,185.83955692367965,308.93418973066116,0.33843841893701576
0.0010092163130814979,0.0021999999999999997,185.88434258872533,308.93418973066116,0.33843841893701576
0.0010139871538342468,0.0022104,185.92904576098994,308.93418973066116,0.33843841893701576
0.0010260977495912247,0.0022367999999999997,186.04215620556346,308.93418973066116,0.33843841893701576
0.0010341714800958766,0.0022543999999999997,186.11727405289113,308.93418973066116,0.33843841893701576
0.0010473830391034891,0.0022832,186.23970269831705,308.93418973066116,0.33843841893701576
0.001052153879856238,0.0022936,186.28376483819724,308.93418973066116,0.33843841893701576
0.0010576586961094099,0.0023056,186.33450906218383,308.93418973066116,0.33843841893701576
0.001063530500112793,0.0023184,186.38852283530863,308.93418973066116,0.33843841893701576
0.0010712372428672335,0.0023352,186.45923974287447,308.93418973066116,0.33843841893701576
0.0010800449488723085,0.0023544,186.53981656245688,308.93418973066116,0.33843841893701576
0.001088485667127172,0.0023728,186.6167958813174,308.93418973066116,0.33843841893701576
0.0010961924098816125,0.0023896,186.68687826718204,308.93418973066116,0.33843841893701576
0.0011042661403862645,0.0024072,186.76009212056917,308.93418973066116,0.33843841893701576
0.0011134408341415508,0.0024272,186.8430367474896,308.93418973066116,0.33843841893701576
0.001134726123653815,0.0024736,187.03444848853087,308.93418973066116,0.33843841893701576
0.0011416988909078328,0.0024887999999999998,187.09684716298946,308.93418973066116,0.33843841893701576
0.0011446347929095243,0.0024952,187.12307580485037,308.93418973066116,0.33843841893701576
0.0011552774376656567,0.0025184,187.21793548299226,308.93418973066116,0.33843841893701576
0.001158947315167771,0.0025264,187.25056661508833,308.93418973066116,0.33843841893701576
0.001167021045672423,0.002544,187.32221359219432,308.93418973066116,0.33843841893701576
0.001168488996673269,0.0025472,187.33521951972335,308.93418973066116,0.33843841893701576
0.0011787646536791897,0.0025696,187.42608325277612,308.93418973066116,0.33843841893701576
0.001187205371934053,0.002588,187.50049044791172,308.93418973066116,0.33843841893701576
0.0011901412739357446,0.0025943999999999997,187.52632281290784,308.93418973066116,0.33843841893701576
0.0012007839186918769,0.0026176,187.61975752272352,308.93418973066116,0.33843841893701576
0.0012055547594446256,0.0026279999999999997,187.6615371512744,308.93418973066116,0.33843841893701576
0.0012117935511982204,0.0026416,187.71607488454407,308.93418973066116,0.33843841893701576
0.0012231701714547755,0.0026663999999999998,187.8152449679201,308.93418973066116,0.33843841893701576
0.0012250051102058327,0.0026704,187.83120639246158,308.93418973066116,0.33843841893701576
0.0012264730612066787,0.0026736,187.84396881956832,308.93418973066116,0.33843841893701576
0.0012290419754581589,0.0026792,187.86628874148184,308.93418973066116,0.33843841893701576
0.0012411525712151367,0.0027056,187.9712671373715,308.93418973066116,0.33843841893701576
0.0012451894364674627,0.0027144,188.00617106113074,308.93418973066116,0.33843841893701576
0.0012536301547223262,0.0027328,188.07900970862295,308.93418973066116,0.33843841893701576
0.0012646397872286697,0.0027568,188.17372984527586,308.93418973066116,0.33843841893701576
0.00126977761573163,0.002768,188.2178224670131,308.93418973066116,0.33843841893701576
0.001274548456484379,0.0027784,188.25870335416107,308.93418973066116,0.33843841893701576
0.0012796862849873392,0.0027895999999999997,188.30266224041506,308.93418973066116,0.33843841893701576
0.0012976686847477005,0.0028288,188.45597921442368,308.93418973066116,0.33843841893701576
0.0013009715744996036,0.002836,188.48404917292626,308.93418973066116,0.33843841893701576
0.0013050084397519296,0.0028447999999999998,188.51831918512016,308.93418973066116,0.33843841893701576
0.0013171190355089077,0.0028712,188.6208820150733,308.93418973066116,0.33843841893701576
0.0013314315577671544,0.0029024,188.74161966751214,308.93418973066116,0.33843841893701576
0.0013406062515224407,0.0029224,188.81874944149766,308.93418973066116,0.33843841893701576
0.0013417072147730751,0.0029248,188.82799116020766,308.93418973066116,0.33843841893701576
0.001353817810530053,0.0029511999999999997,188.92945563681832,308.93418973066116,0.33843841893701576
0.0013563867247815332,0.0029568,188.95093282735243,308.93418973066116,0.33843841893701576
0.0013582216635325906,0.0029608,188.96626396632945,308.93418973066116,0.33843841893701576
0.0013600566022836478,0.0029648,188.98158702968976,308.93418973066116,0.33843841893701576
0.0013681303327883,0.0029824,189.0489129528225,308.93418973066116,0.33843841893701576
0.0013743691245418944,0.002996,189.10083145692894,308.93418973066116,0.33843841893701576
0.001382809842796758,0.0030144,189.17092807604612,308.93418973066116,0.33843841893701576
0.0013857457447984493,0.0030207999999999997,189.1952703679264,308.93418973066116,0.33843841893701576
0.001391617548801833,0.0030336,189.24389469560984,308.93418973066116,0.33843841893701576
0.0013971223650550047,0.0030456,189.28940738384787,308.93418973066116,0.33843841893701576
0.0014007922425571192,0.0030536,189.31971032838214,308.93418973066116,0.33843841893701576
0.0014059300710600794,0.0030648,189.36208248645875,308.93418973066116,0.33843841893701576
0.0014073980220609254,0.003068,189.37417771987185,308.93418973066116,0.33843841893701576
0.00141363681381452,0.0030816,189.425527669185,308.93418973066116,0.33843841893701576
0.0014173066913166347,0.0030896,189.4556922363567,308.93418973066116,0.33843841893701576
0.0014327201768255156,0.0031232,189.5820522159314,308.93418973066116,0.33843841893701576
0.0014374910175782645,0.0031336,189.62105604628348,308.93418973066116,0.33843841893701576
0.0014496016133352426,0.00316,189.7198397149961,308.93418973066116,0.33843841893701576
0.0014595102825909517,0.0031815999999999997,189.8004235356273,308.93418973066116,0.33843841893701576
0.0014642811233437007,0.003192,189.8391470324004,308.93418973066116,0.33843841893701576
0.001476024731350467,0.0032175999999999997,189.9342573708242,308.93418973066116,0.33843841893701576
0.0014782266578517358,0.0032224,189.9520576563394,308.93418973066116,0.33843841893701576
0.0014874013516070223,0.0032424,190.02611448020141,308.93418973066116,0.33843841893701576
0.0014936401433606169,0.0032559999999999998,190.0763713882544,308.93418973066116,0.33843841893701576
0.0014965760453623086,0.0032624,190.09999336384843,308.93418973066116,0.33843841893701576
0.001512356518621401,0.0032968,190.22665318741412,308.93418973066116,0.33843841893701576
0.001516393383873727,0.0033055999999999997,190.25897161517162,308.93418973066116,0.33843841893701576
0.0015215312123766874,0.0033168,190.30005567215207,308.93418973066116,0.33843841893701576
0.0015336418081336653,0.0033431999999999997,190.3966831828728,308.93418973066116,0.33843841893701576
0.0015354767468847227,0.0033472,190.41129771412082,308.93418973066116,0.33843841893701576
0.0015395136121370487,0.003356,190.44342572869195,308.93418973066116,0.33843841893701576
0.0015453854161404318,0.0033688,190.49009879715538,308.93418973066116,0.33843841893701576
0.0015545601098957184,0.0033888,190.56288724679797,308.93418973066116,0.33843841893701576
0.0015736434729067138,0.0034303999999999997,190.71375275202485,308.93418973066116,0.33843841893701576
0.0015802492524105202,0.0034448,190.76580896620217,308.93418973066116,0.33843841893701576
0.001587589007414749,0.0034608,190.82354977162484,308.93418973066116,0.33843841893701576
0.0015912588849168637,0.0034687999999999997,190.8523811265127,308.93418973066116,0.33843841893701576
0.001604470443924476,0.0034976,190.95595997463857,308.93418973066116,0.33843841893701576
0.0016081403214265905,0.0035055999999999998,190.98467277750956,308.93418973066116,0.33843841893701576
0.0016099752601776477,0.0035096,190.9990195951906,308.93418973066116,0.33843841893701576
0.0016154800764308194,0.0035215999999999997,191.04202183450502,308.93418973066116,0.33843841893701576
0.001631994525190335,0.0035575999999999997,191.17068697009188,308.93418973066116,0.33843841893701576
0.001639334280194564,0.0035735999999999997,191.22770838075084,308.93418973066116,0.33843841893701576
0.0016477749984494274,0.0035919999999999997,191.29316005803335,308.93418973066116,0.33843841893701576
0.0016650234227093658,0.0036295999999999998,191.42650393211522,308.93418973066116,0.33843841893701576
0.001671629202213172,0.0036439999999999997,191.47742899476097,308.93418973066116,0.33843841893701576
0.0016767670307161323,0.0036552,191.5169831359809,308.93418973066116,0.33843841893701576
0.0016866756999718417,0.0036768,191.59313289463776,308.93418973066116,0.33843841893701576
0.0016885106387228988,0.0036807999999999997,191.60721553513687,308.93418973066116,0.33843841893701576
0.001691813528474802,0.003688,191.63254925660465,308.93418973066116,0.33843841893701576
0.001699153283479031,0.003704,191.6887774591137,308.93418973066116,0.33843841893701576
0.0017013552099802997,0.0037088,191.7056274380002,308.93418973066116,0.33843841893701576
0.0017156677322385464,0.00374,191.8149457249694,308.93418973066116,0.33843841893701576
0.0017296132667465817,0.0037703999999999997,191.92111939449933,308.93418973066116,0.33843841893701576
0.0017321821809980619,0.003776,191.94064123300566,308.93418973066116,0.33843841893701576
0.0017413568747533482,0.003796,192.0102701004002,308.93418973066116,0.33843841893701576
0.0017497975930082117,0.0038144,192.07420240077275,308.93418973066116,0.33843841893701576
0.001751632531759269,0.0038184,192.0880847985842,308.93418973066116,0.33843841893701576
0.0017578713235128637,0.003832,192.13524258533252,308.93418973066116,0.33843841893701576
0.001762275176515401,0.0038415999999999997,192.16849114380227,308.93418973066116,0.33843841893701576
0.001768513968268996,0.0038552,192.21553785286594,308.93418973066116,0.33843841893701576
0.001771082882520476,0.0038607999999999997,192.23489120861478,308.93418973066116,0.33843841893701576
0.001776954686523859,0.0038735999999999996,192.2790863868209,308.93418973066116,0.33843841893701576
0.0017989739515365465,0.0039216,192.44431349064,308.93418973066116,0.33843841893701576
0.00180998358404289,0.0039456,192.5266311342352,308.93418973066116,0.33843841893701576
0.0018176903267973306,0.0039624,192.58413733267787,308.93418973066116,0.33843841893701576
0.0018213602042994451,0.0039704,192.611487808574,308.93418973066116,0.33843841893701576
0.0019142239621451607,0.004172834566913383,193.2965804707636,308.93418973066116,0.33843841893701576
0.0019846997053343976,0.004326465293058612,193.80788857172953,308.93418973066116,0.33843841893701576
0.0021520795954088354,0.004691338267653531,194.994662154365,308.93418973066116,0.33843841893701576
0.0022666026780913456,0.004940988197639528,195.7859852568274,308.93418973066116,0.33843841893701576
0.002469220439760402,0.005382676535307062,197.14882184441998,308.93418973066116,0.33843841893701576
0.0026189813940375303,0.005709141828365673,198.1282467557977,308.93418973066116,0.33843841893701576
0.0029713601099837154,0.0064772954590918185,200.3503461256315,308.93418973066116,0.33843841893701576
0.0030770737247675707,0.006707741548309662,200.99659648833517,308.93418973066116,0.33843841893701576
0.0035704039270922296,0.007783156631326265,203.90474573757413,308.93418973066116,0.33843841893701576
0.0036144512665855027,0.007879175835167033,204.1565231476634,308.93418973066116,0.33843841893701576
0.003984448918328997,0.008685737147429486,206.22617796517943,308.93418973066116,0.33843841893701576
0.004204685615795362,0.009165833166633327,207.4225159284896,308.93418973066116,0.33843841893701576
0.0043192086984778725,0.009415483096619324,208.03493668874108,308.93418973066116,0.33843841893701576
0.004477779120653656,0.00976115223044609,208.8725494976828,308.93418973066116,0.33843841893701576
0.004609921139133475,0.010049209841968394,209.5617582892471,308.93418973066116,0.33843841893701576
0.004777301029207912,0.010414082816563312,210.42379333104077,308.93418973066116,0.33843841893701576
0.004971109322978314,0.010836567313462692,211.40735664096633,308.93418973066116,0.33843841893701576
0.005032775598268898,0.010970994198839769,211.71715709749282,308.93418973066116,0.33843841893701576
0.005226583892039299,0.011393478695739149,212.68131485353115,308.93418973066116,0.33843841893701576
0.00543801112160701,0.011854370874174834,213.71735521091907,308.93418973066116,0.33843841893701576
0.005464439525302973,0.011911982396479295,213.84574644854115,308.93418973066116,0.33843841893701576
0.005816818241249158,0.01268013602720544,215.53512573640305,308.93418973066116,0.33843841893701576
0.006142768553499379,0.013390678135627125,217.06258585675542,308.93418973066116,0.33843841893701576
0.00635419578306709,0.013851570314062813,218.03649180328762,308.93418973066116,0.33843841893701576
0.006539194608938838,0.01425485097019404,218.8783375116426,308.93418973066116,0.33843841893701576
0.006777050242202512,0.014773354670934187,219.9471849089886,308.93418973066116,0.33843841893701576
0.006803478645898476,0.014830966193238648,220.06503562001603,308.93418973066116,0.33843841893701576
0.006918001728580986,0.015080616123224646,220.57367270113124,308.93418973066116,0.33843841893701576
0.0069532396001756045,0.01515743148629726,220.72951436530195,308.93418973066116,0.33843841893701576
0.007103000554452734,0.015483896779355872,221.38843439668244,308.93418973066116,0.33843841893701576
0.00719109523343928,0.01567593518703741,221.77350351667988,308.93418973066116,0.33843841893701576
0.007287999380324481,0.0158871774354871,222.19496084020182,308.93418973066116,0.33843841893701576
0.00753466448148681,0.0164248849769954,223.25801641065888,308.93418973066116,0.33843841893701576
0.007807757986345102,0.01702020404080816,224.41926126427734,308.93418973066116,0.33843841893701576
0.008116089362798014,0.01769233846769354,225.71146902762152,308.93418973066116,0.33843841893701576
0.008618229033021327,0.018786957391478294,227.7756671412404,308.93418973066116,0.33843841893701576
0.008635847968818638,0.018825365073014605,227.84723047626773,308.93418973066116,0.33843841893701576
0.00894417934527155,0.01949749949989998,229.09051578944684,308.93418973066116,0.33843841893701576
0.00905870242795406,0.019747149429885976,229.5480355530368,308.93418973066116,0.33843841893701576
0.009243701253825806,0.020150430086017204,230.28236922647054,308.93418973066116,0.33843841893701576
0.009446319015494862,0.020592118423684736,231.0800937567742,308.93418973066116,0.33843841893701576
0.009472747419190826,0.0206497299459892,231.1836505891923,308.93418973066116,0.33843841893701576
0.009719412520353157,0.0211874374874975,232.14480800384734,308.93418973066116,0.33843841893701576
0.009895601878326249,0.021571514302860573,232.82553332556864,308.93418973066116,0.33843841893701576
0.010195123786880506,0.022224444888977797,233.9720164227678,308.93418973066116,0.33843841893701576
0.010256790062171088,0.02235887177435487,234.2064179650388,308.93418973066116,0.33843841893701576
0.01043297942014418,0.022742948589717944,234.8731271640502,308.93418973066116,0.33843841893701576
0.010785358136090365,0.02351110222044409,236.19351555325383,308.93418973066116,0.33843841893701576
0.011357973549502916,0.024759351870374074,238.3038104863761,308.93418973066116,0.33843841893701576
0.011446068228489462,0.02495139027805561,238.62475080769553,308.93418973066116,0.33843841893701576
0.011675114393854482,0.025450690138027605,239.45471927377383,308.93418973066116,0.33843841893701576
0.011789637476536993,0.025700340068013604,239.8673203634792,308.93418973066116,0.33843841893701576
0.011957017366611429,0.02606521304260852,240.4675520375805,308.93418973066116,0.33843841893701576
0.012371062357848198,0.026967793558711744,241.9384260717425,308.93418973066116,0.33843841893701576
0.012705822137997074,0.027697539507901582,243.11365427167516,308.93418973066116,0.33843841893701576
0.0128555830922742,0.028024004800960192,243.63549808108894,308.93418973066116,0.33843841893701576
0.01313748606503115,0.02863852770554111,244.61140513002601,308.93418973066116,0.33843841893701576
0.01357795945996388,0.02959871974394879,246.120066041468,308.93418973066116,0.33843841893701576
0.013912719240112757,0.03032846569313863,247.25391549639747,308.93418973066116,0.33843841893701576
0.014062480194389885,0.03065493098619724,247.75771392865897,308.93418973066116,0.33843841893701576
0.014177003277072395,0.030904580916183238,248.14156095107276,308.93418973066116,0.33843841893701576
0.014423668378234724,0.031442288457691536,248.96422502118278,308.93418973066116,0.33843841893701576
0.014476525185626652,0.03155751150230046,249.1397942489657,308.93418973066116,0.33843841893701576
0.014538191460917232,0.03169193838767753,249.34430934834035,308.93418973066116,0.33843841893701576
0.014723190286788982,0.03209521904380876,249.95583431112027,308.93418973066116,0.33843841893701576
0.014802475497876872,0.032268053610722144,250.21699825600564,308.93418973066116,0.33843841893701576
0.015031521663241891,0.032767353470694136,250.96842475790035,308.93418973066116,0.33843841893701576
0.015101997406431129,0.032920984196839365,251.1987327820711,308.93418973066116,0.33843841893701576
0.015286996232302879,0.033324264852970596,251.80130581989724,308.93418973066116,0.33843841893701576
0.015489613993971935,0.03376595319063813,252.45801296456256,308.93418973066116,0.33843841893701576
0.015947706324701973,0.034764552910582114,253.93051611757048,308.93418973066116,0.33843841893701576
0.01615032408637103,0.03520624124824965,254.57654381808499,308.93418973066116,0.33843841893701576
0.01644984599492529,0.035859171834366876,255.52578111112,308.93418973066116,0.33843841893701576
0.016643654288695693,0.03628165633126626,256.13640344127754,308.93418973066116,0.33843841893701576
0.016749367903479546,0.0365121024204841,256.46830112118244,308.93418973066116,0.33843841893701576
0.016907938325655326,0.03685777155431086,256.96461993519495,308.93418973066116,0.33843841893701576
0.017013651940439186,0.03708821764352871,257.29449099666886,308.93418973066116,0.33843841893701576
0.017277935977398826,0.03766433286657332,258.1156906045741,308.93418973066116,0.33843841893701576
0.01731317384899344,0.03774114822964593,258.22481257235137,308.93418973066116,0.33843841893701576
0.017348411720588063,0.03781796359271855,258.3338479561021,308.93418973066116,0.33843841893701576
0.017392459060081335,0.03791398279655932,258.4700207991587,308.93418973066116,0.33843841893701576
0.017859360858710028,0.03893178635727146,259.90527974371594,308.93418973066116,0.33843841893701576
0.01823816797835218,0.03975755151030207,261.0590115703773,308.93418973066116,0.33843841893701576
0.018335072125237373,0.039968793758751744,261.3526463744596,308.93418973066116,0.33843841893701576
0.01839673840052796,0.04010322064412883,261.5391898011395,308.93418973066116,0.33843841893701576
0.018440785740021233,0.040199239847969595,261.672285831233,308.93418973066116,0.33843841893701576
0.018546499354805086,0.04042968593718743,261.99121145940796,308.93418973066116,0.33843841893701576
0.018846021263359346,0.041082616523304666,262.89100670875706,308.93418973066116,0.33843841893701576
0.01898697274973782,0.041389877975595124,263.31250834042606,308.93418973066116,0.33843841893701576
0.01910149583242033,0.04163952790558112,263.65408056486814,308.93418973066116,0.33843841893701576
0.01926006625459611,0.04198519703940788,264.1257111220022,308.93418973066116,0.33843841893701576
0.019286494658292075,0.042042808561712344,264.2041687520281,308.93418973066116,0.33843841893701576
0.019550778695251715,0.04261892378475696,264.98645262417386,308.93418973066116,0.33843841893701576
0.019797443796414044,0.04315663132626525,265.71287144458773,308.93418973066116,0.33843841893701576
0.019956014218589824,0.043502300460092014,266.17799166903916,308.93418973066116,0.33843841893701576
0.02030839293453601,0.04427045409081816,267.2064625418938,308.93418973066116,0.33843841893701576
0.02061672431098892,0.04494258851770354,268.10067869040876,308.93418973066116,0.33843841893701576
0.02078410420106336,0.04530746149229846,268.58392553855197,308.93418973066116,0.33843841893701576
0.021048388238023002,0.04588357671534307,269.3438681067419,308.93418973066116,0.33843841893701576
0.021436004825563803,0.046728545709141825,270.4517533563084,308.93418973066116,0.33843841893701576
0.021735526734118063,0.04738147629525906,271.3025036513634,308.93418973066116,0.33843841893701576
0.021885287688395188,0.04770794158831766,271.72616332183287,308.93418973066116,0.33843841893701576
0.021964572899483083,0.04788077615523105,271.94999592394373,308.93418973066116,0.33843841893701576
0.022149571725354828,0.048284056811362275,272.4710501573867,308.93418973066116,0.33843841893701576
0.02236980842282119,0.04876415283056611,273.08914500999884,308.93418973066116,0.33843841893701576
0.022431474698111777,0.04889857971594319,273.26178569411263,308.93418973066116,0.33843841893701576
0.022730996606666033,0.04955151030206041,274.0977074932787,308.93418973066116,0.33843841893701576
0.023021709047321638,0.05018523704740949,274.90494492053415,308.93418973066116,0.33843841893701576
0.023056946918916254,0.050262052410482094,275.00252100831835,308.93418973066116,0.33843841893701576
0.023241945744788,0.05066533306661332,275.51384444126785,308.93418973066116,0.33843841893701576
0.02340932563486244,0.05103020604120824,275.9751042958256,308.93418973066116,0.33843841893701576
0.02356789605703822,0.051375875175035,276.41090226745854,308.93418973066116,0.33843841893701576
0.02367360967182208,0.05160632126425285,276.7007991183395,308.93418973066116,0.33843841893701576
0.023840989561896515,0.05197119423884777,277.15877208254597,308.93418973066116,0.33843841893701576
0.02393789370878172,0.052182436487297465,277.4233411819587,308.93418973066116,0.33843841893701576
0.024008369451970955,0.052336067213442694,277.61549279029805,308.93418973066116,0.33843841893701576
0.024219796681538668,0.05279695939187838,278.19063205044046,308.93418973066116,0.33843841893701576
0.024290272424727904,0.05295059011802361,278.38190957463013,308.93418973066116,0.33843841893701576
0.024457652314802337,0.05331546309261852,278.83532833212246,308.93418973066116,0.33843841893701576
0.0245809848653835,0.05358431686337267,279.1686523600734,308.93418973066116,0.33843841893701576
0.024730745819660633,0.05391078215643129,279.5725273852501,308.93418973066116,0.33843841893701576
0.02481003103074852,0.05408361672334466,279.7859573651517,308.93418973066116,0.33843841893701576
0.02486288783814045,0.05419883976795359,279.92809625847985,308.93418973066116,0.33843841893701576
0.024898125709735073,0.05427565513102621,280.0227900544879,308.93418973066116,0.33843841893701576
0.024933363581329686,0.05435247049409882,280.1174315977079,308.93418973066116,0.33843841893701576
0.025602883141627442,0.0558119623924785,281.90582733628753,308.93418973066116,0.33843841893701576
0.025646930481120715,0.05590798159631927,282.02284147773963,308.93418973066116,0.33843841893701576
0.025858357710688427,0.056368873774754955,282.5834219988107,308.93418973066116,0.33843841893701576
0.026078594408154788,0.05684896979395879,283.1654624990997,308.93418973066116,0.33843841893701576
0.026131451215546716,0.05696419283856771,283.3048665880934,308.93418973066116,0.33843841893701576
0.02622835536243192,0.057175435087017404,283.5601554674367,308.93418973066116,0.33843841893701576
0.02632525950931712,0.057386677335467096,283.8150767631725,308.93418973066116,0.33843841893701576
0.026404544720405015,0.057559511902380484,284.0233766368553,308.93418973066116,0.33843841893701576
0.02650144886729021,0.05777075415083016,284.2776344023712,308.93418973066116,0.33843841893701576
0.02658954354627676,0.05796279255851171,284.5084633595027,308.93418973066116,0.33843841893701576
0.026633590885770032,0.058058811762352475,284.62376597718605,308.93418973066116,0.33843841893701576
0.02670406662895927,0.058212442488497704,284.80809559809836,308.93418973066116,0.33843841893701576
0.027118111620196034,0.05911502300460092,285.8872251731248,308.93418973066116,0.33843841893701576
0.02732072938186509,0.05955671134226845,286.4129666375189,308.93418973066116,0.33843841893701576
0.027761202776797826,0.06051690338067614,287.55066530457003,308.93418973066116,0.33843841893701576
0.0278052501162911,0.06061292258451691,287.6640465952331,308.93418973066116,0.33843841893701576
0.02784929745578437,0.06070894178835767,287.7773578589888,308.93418973066116,0.33843841893701576
0.027955011070568223,0.06093938787757551,288.0490201019702,308.93418973066116,0.33843841893701576
0.028078343621149388,0.061208241648329664,288.3654535275259,308.93418973066116,0.33843841893701576
0.028298580318615756,0.06168833766753351,288.92916825500566,308.93418973066116,0.33843841893701576
0.02832500872231172,0.06174594918983797,288.9966988521921,308.93418973066116,0.33843841893701576
0.028510007548183468,0.0621492298459692,289.4687268785011,308.93418973066116,0.33843841893701576
0.028562864355575396,0.06226445289057812,289.6033724273675,308.93418973066116,0.33843841893701576
0.028642149566663284,0.0624372874574915,289.80515869059076,308.93418973066116,0.33843841893701576
0.028677387438257904,0.06251410282056412,289.89477153732844,308.93418973066116,0.33843841893701576
0.028695006374055212,0.06255251050210042,289.9395618558773,308.93418973066116,0.33843841893701576
0.028739053713548485,0.06264852970594119,290.05149075331263,308.93418973066116,0.33843841893701576
0.029126670301089286,0.06349349869973994,291.03359684524065,308.93418973066116,0.33843841893701576
0.029338097530656998,0.06395439087817563,291.567142166436,308.93418973066116,0.33843841893701576
0.029672857310805874,0.06468413682736547,292.40886564137116,308.93418973066116,0.33843841893701576
0.029998807623056095,0.06539467893578715,293.22488718499943,308.93418973066116,0.33843841893701576
0.030095711769941295,0.06560592118423685,293.46682040169276,308.93418973066116,0.33843841893701576
0.03013094964153592,0.06568273654730947,293.5547207684944,308.93418973066116,0.33843841893701576
0.030263091660015735,0.06597079415883177,293.8839906910918,308.93418973066116,0.33843841893701576
0.030562613568569996,0.066623724744949,294.6282669899182,308.93418973066116,0.33843841893701576
0.030633089311759235,0.06677735547109423,294.8029767582267,308.93418973066116,0.33843841893701576
0.030950230156110797,0.06746869373874775,295.587238888898,308.93418973066116,0.33843841893701576
0.031108800578286577,0.06781436287257452,295.9781942080065,308.93418973066116,0.33843841893701576
0.03120570472517178,0.06802560512102421,296.2167287739258,308.93418973066116,0.33843841893701576
0.03131141833995564,0.06825605121024206,296.4766190705404,308.93418973066116,0.33843841893701576
0.03155808344111796,0.06879375875175035,297.08170260973907,308.93418973066116,0.33843841893701576
0.0317254633311924,0.06915863172634527,297.49124491389,308.93418973066116,0.33843841893701576
0.0321923651298211,0.07017643528705741,298.62922245015403,308.93418973066116,0.33843841893701576
0.03231569768040227,0.07044528905781157,298.92874327942,308.93418973066116,0.33843841893701576
0.03246545863467939,0.07077175435087017,299.2918484641349,308.93418973066116,0.33843841893701576
0.032685695332145756,0.07125185037007402,299.82464224110083,308.93418973066116,0.33843841893701576
0.03272974267163903,0.07134786957391479,299.93103278609726,308.93418973066116,0.33843841893701576
0.032949979369105396,0.07182796559311863,300.462150212086,308.93418973066116,0.33843841893701576
0.033029264580193285,0.072000800160032,300.65301333081635,308.93418973066116,0.33843841893701576
0.033196644470267725,0.07236567313462693,301.05536079634027,308.93418973066116,0.33843841893701576
0.03330235808505158,0.07259611922384478,301.3090673900418,308.93418973066116,0.33843841893701576
0.03346973797512602,0.0729609921984397,301.71012808703307,308.93418973066116,0.33843841893701576
0.03357545158990988,0.07319143828765753,301.96302660309,308.93418973066116,0.33843841893701576
0.033610689461504493,0.07326825365073016,302.04725707435597,308.93418973066116,0.33843841893701576
0.033725212544187005,0.07351790358071615,302.32076856106227,308.93418973066116,0.33843841893701576
0.03386616403056548,0.07382516503300661,302.6569013354008,308.93418973066116,0.33843841893701576
0.03400711551694395,0.07413242648529707,302.9924889444531,308.93418973066116,0.33843841893701576
0.034359494232890135,0.07490058011602321,303.82909338802455,308.93418973066116,0.33843841893701576
0.03466782560934305,0.07557271454290859,304.55838117938583,308.93418973066116,0.33843841893701576
0.03472949188463363,0.07570714142828566,304.70393470682393,308.93418973066116,0.33843841893701576
0.03483520549941748,0.0759375875175035,304.95322075673084,308.93418973066116,0.33843841893701576
0.03497615698579596,0.07624484896979396,305.2851436966889,308.93418973066116,0.33843841893701576
0.03506425166478251,0.0764368873774755,305.49233064357446,308.93418973066116,0.33843841893701576
0.03514353687587039,0.07660972194438888,305.6786253889735,308.93418973066116,0.33843841893701576
0.035258059958552905,0.07685937187437487,305.94742868379194,308.93418973066116,0.33843841893701576
0.03544305878442466,0.07726265253050611,306.38093119966595,308.93418973066116,0.33843841893701576
0.03550472505971524,0.07739707941588318,306.52523581940585,308.93418973066116,0.33843841893701576
0.03576019962877622,0.07795399079815964,307.12203090563435,308.93418973066116,0.33843841893701576
0.03581305643616815,0.07806921384276856,307.2452978924283,308.93418973066116,0.33843841893701576
0.036033293133634514,0.0785493098619724,307.7581484736583,308.93418973066116,0.33843841893701576
0.0361918635558103,0.07889497899579917,308.1266442314294,308.93418973066116,0.33843841893701576
0.03626233929899954,0.0790486097219444,308.2902179539713,308.93418973066116,0.33843841893701576
0.03645614759276993,0.07947109421884377,308.7394076494112,308.93418973066116,0.33843841893701576
0.03653543280385783,0.07964392878575716,308.92289853089966,308.93418973066116,0.33843841893701576
0.0365794801433511,0.07973994798959792,309.0247708051683,308.93418973066116,0.33843841893701576
0.03661471801494572,0.07981676335267054,309.1062341831004,308.93418973066116,0.33843841893701576
0.03672043162972957,0.08004720944188838,309.3504410584468,308.93418973066116,0.33843841893701576
0.036975906198790556,0.08060412082416483,309.93947846599906,308.93418973066116,0.33843841893701576
0.0371609050246623,0.08100740148029606,310.36503241758953,308.93418973066116,0.33843841893701576
0.037310665978939436,0.08133386677335468,310.7089236388308,308.93418973066116,0.33843841893701576
0.037478045869013876,0.0816987397479496,311.09263622718635,308.93418973066116,0.33843841893701576
0.03773352043807486,0.08225565113022605,311.6770167789327,308.93418973066116,0.33843841893701576
0.03780399618126409,0.08240928185637128,311.8379533994722,308.93418973066116,0.33843841893701576
0.03803304234662911,0.08290858171634327,312.3601911762005,308.93418973066116,0.33843841893701576
0.03813875596141297,0.08313902780556112,312.60081016127,308.93418973066116,0.33843841893701576
0.03836780212677799,0.08363832766553311,313.12126078224514,308.93418973066116,0.33843841893701576
0.03851756308105511,0.08396479295859172,313.4609004010949,308.93418973066116,0.33843841893701576
0.03878184711801475,0.08454090818163633,314.0590107452987,308.93418973066116,0.33843841893701576
0.03892279860439323,0.08484816963392679,314.37735286090384,308.93418973066116,0.33843841893701576
0.03928398678823807,0.08563552710542109,315.1910591532922,308.93418973066116,0.33843841893701576
0.03934565306352865,0.08576995399079816,315.32969250488264,308.93418973066116,0.33843841893701576
0.039715650715272145,0.08657651530306061,316.15972006171796,308.93418973066116,0.33843841893701576
0.039742079118968106,0.08663412682536507,316.2188920918709,308.93418973066116,0.33843841893701576
0.03984779273375197,0.08686457291458292,316.4554269117748,308.93418973066116,0.33843841893701576
0.040076838899116986,0.08736387277455492,316.9670810956194,308.93418973066116,0.33843841893701576
0.04046445548665779,0.08820884176835367,317.8303669800231,308.93418973066116,0.33843841893701576
0.04062302590883358,0.08855451090218044,318.18259911824947,308.93418973066116,0.33843841893701576
0.04071993005571878,0.08876575315063014,318.3975881335797,308.93418973066116,0.33843841893701576
0.04135421174442191,0.0901484296859372,319.79989375109415,308.93418973066116,0.33843841893701576
0.04154802003819231,0.09057091418283657,320.22669961641554,308.93418973066116,0.33843841893701576
0.041653733652976165,0.09080136027205442,320.45917552433866,308.93418973066116,0.33843841893701576
0.041750637799861365,0.09101260252050411,320.6720763820875,308.93418973066116,0.33843841893701576
0.042261586937983334,0.09212642528505702,321.79147350424086,308.93418973066116,0.33843841893701576
0.042358491084868534,0.09233766753350671,322.0031762119131,308.93418973066116,0.33843841893701576
0.04275491714030799,0.09320184036807362,322.8672731428737,308.93418973066116,0.33843841893701576
0.0428694402229905,0.09345149029805962,323.11631868719314,308.93418973066116,0.33843841893701576
0.043010391709368975,0.09375875175035008,323.42248036998564,308.93418973066116,0.33843841893701576
0.043283485214227264,0.09435407081416283,324.0145573890423,308.93418973066116,0.33843841893701576
0.043468484040099016,0.09475735147029406,324.4148143008262,308.93418973066116,0.33843841893701576
0.04363586393017345,0.09512222444488898,324.7763794152326,308.93418973066116,0.33843841893701576
0.04369753020546404,0.09525665133026606,324.9094512171869,308.93418973066116,0.33843841893701576
0.043988242646119634,0.09589037807561512,325.53580588642865,308.93418973066116,0.33843841893701576
0.04402348051771426,0.09596719343868775,325.61161780782635,308.93418973066116,0.33843841893701576
0.04423490774728197,0.09642808561712343,326.06599334360806,308.93418973066116,0.33843841893701576
0.044534429655836226,0.09708101620324065,326.70824482206876,308.93418973066116,0.33843841893701576
0.04484276103228914,0.09775315063012603,327.3676288282751,308.93418973066116,0.33843841893701576
0.044904427307579715,0.0978875775155031,327.49929318960585,308.93418973066116,0.33843841893701576
0.04501014092236358,0.09811802360472095,327.72483958257635,308.93418973066116,0.33843841893701576
0.04512466400504608,0.09836767353470695,327.9689484984976,308.93418973066116,0.33843841893701576
0.04518633028033667,0.09850210042008402,328.1002916780528,308.93418973066116,0.33843841893701576
0.045309662830917835,0.09877095419083817,328.3627685080509,308.93418973066116,0.33843841893701576
0.045512280592586885,0.0992126425285057,328.7933763486859,308.93418973066116,0.33843841893701576
0.04559156580367478,0.09938547709541909,328.9616714719213,308.93418973066116,0.33843841893701576
0.04578537409744518,0.09980796159231847,329.3725797493314,308.93418973066116,0.33843841893701576
0.045873468776431725,0.1,329.55913193525356,308.93418973066116,0.33843841893701576