File: datasets/aisi_316_L/data/M1/train_41.csv
Time(s),Strain(%),Stress(MPa),Temp(C),Log_SR(s-1)
0.0,0.0,0.0,80.48843349445346,2.985325235038715
1.5722382324756372e-08,1.52e-05,2.949777075,80.48843349445346,2.985325235038715
2.399732039041762e-08,2.3199999999999998e-05,4.502291325,80.48843349445346,2.985325235038715
4.1374690328306243e-08,3.9999999999999996e-05,7.76257125,80.48843349445346,2.985325235038715
4.9649628393967496e-08,4.8e-05,9.3150855,80.48843349445346,2.985325235038715
5.4614591233364236e-08,5.2799999999999996e-05,10.246594049999999,80.48843349445346,2.985325235038715
7.2819454977819e-08,7.04e-05,13.6621254,80.48843349445346,2.985325235038715
8.771434349600925e-08,8.48e-05,16.45665105,80.48843349445346,2.985325235038715
9.68167753682366e-08,9.36e-05,18.164416725,80.48843349445346,2.985325235038715
1.166766267258236e-07,0.00011279999999999999,21.890450925,80.48843349445346,2.985325235038715
1.4481141614907186e-07,0.00014,27.168999375,80.48843349445346,2.985325235038715
1.6467126750665884e-07,0.0001592,30.895033575,80.48843349445346,2.985325235038715
1.770836746051507e-07,0.0001712,33.223804949999995,80.48843349445346,2.985325235038715
1.961160321561716e-07,0.0001896,36.794587725,80.48843349445346,2.985325235038715
2.3831821629104395e-07,0.0002304,44.712410399999996,80.48843349445346,2.985325235038715
2.490756357764036e-07,0.0002408,46.730678925,80.48843349445346,2.985325235038715
2.631430304880277e-07,0.0002544,49.36995315,80.48843349445346,2.985325235038715
2.7472794377995347e-07,0.0002656,51.5434731,80.48843349445346,2.985325235038715
3.061727084294662e-07,0.000296,57.44302725,80.48843349445346,2.985325235038715
3.103101774622968e-07,0.0003,58.219284374999994,80.48843349445346,2.985325235038715
3.293425350133177e-07,0.0003184,61.79006715,80.48843349445346,2.985325235038715
3.3513499165928053e-07,0.00032399999999999996,62.87682712499999,80.48843349445346,2.985325235038715
3.50857373984037e-07,0.0003392,65.8266042,80.48843349445346,2.985325235038715
3.566498306299998e-07,0.0003448,66.913364175,80.48843349445346,2.985325235038715
3.7402720056788845e-07,0.0003616,70.1736441,80.48843349445346,2.985325235038715
3.8064715102041746e-07,0.000368,71.4156555,80.48843349445346,2.985325235038715
3.947145457320416e-07,0.0003816,74.05492972500001,80.48843349445346,2.985325235038715
3.996795085714383e-07,0.00038639999999999996,74.986438275,80.48843349445346,2.985325235038715
4.1871186612245917e-07,0.0004048,78.55722105,80.48843349445346,2.985325235038715
4.327792608340833e-07,0.0004184,81.19649527499999,80.48843349445346,2.985325235038715
4.3608923606034783e-07,0.0004216,81.817500975,80.48843349445346,2.985325235038715
4.567765812245009e-07,0.0004416,85.6987866,80.48843349445346,2.985325235038715
4.973237777462411e-07,0.0004808,93.306106425,80.48843349445346,2.985325235038715
5.080811972316007e-07,0.0004912,95.32437495,80.48843349445346,2.985325235038715
5.287685423957537e-07,0.0005112,99.205660575,80.48843349445346,2.985325235038715
5.386984680745472e-07,0.0005208,101.06867767499999,80.48843349445346,2.985325235038715
5.610408008518326e-07,0.0005424,105.26046614999998,80.48843349445346,2.985325235038715
5.693157389174938e-07,0.0005503999999999999,106.81298039999999,80.48843349445346,2.985325235038715
5.809006522094196e-07,0.0005616,108.98650035,80.48843349445346,2.985325235038715
6.123454168589324e-07,0.000592,114.8860545,80.48843349445346,2.985325235038715
6.206203549245936e-07,0.0006,116.43856874999999,80.48843349445346,2.985325235038715
6.239303301508582e-07,0.0006032,117.05957445,80.48843349445346,2.985325235038715
6.396527124756145e-07,0.0006184,120.00935152499999,80.48843349445346,2.985325235038715
6.471001567347096e-07,0.0006255999999999999,121.40661434999998,80.48843349445346,2.985325235038715
6.504101319609742e-07,0.0006288,122.02762005,80.48843349445346,2.985325235038715
6.603400576397677e-07,0.0006384,123.89063715,80.48843349445346,2.985325235038715
7.050247231943384e-07,0.0006816,132.2742141,80.48843349445346,2.985325235038715
7.174371302928302e-07,0.0006935999999999999,134.602985475,80.48843349445346,2.985325235038715
7.439169321029462e-07,0.0007191999999999999,139.57103107499998,80.48843349445346,2.985325235038715
7.521918701686075e-07,0.0007272,141.123545325,80.48843349445346,2.985325235038715
7.637767834605332e-07,0.0007384,143.297065275,80.48843349445346,2.985325235038715
7.81981647204988e-07,0.0007559999999999999,146.712596625,80.48843349445346,2.985325235038715
8.026689923691411e-07,0.000776,150.59388225,80.48843349445346,2.985325235038715
8.059789675954056e-07,0.0007792,151.21488795,80.48843349445346,2.985325235038715
8.250113251464265e-07,0.0007976,154.785670725,80.48843349445346,2.985325235038715
8.407337074711828e-07,0.0008127999999999999,157.73544779999997,80.48843349445346,2.985325235038715
8.597660650222036e-07,0.0008311999999999999,161.30623057499997,80.48843349445346,2.985325235038715
8.804534101863568e-07,0.0008512,165.1875162,80.48843349445346,2.985325235038715
8.920383234782825e-07,0.0008623999999999999,167.36103615,80.48843349445346,2.985325235038715
8.961757925111132e-07,0.0008663999999999999,168.137293275,80.48843349445346,2.985325235038715
9.201731129015308e-07,0.0008895999999999999,172.63958459999998,80.48843349445346,2.985325235038715
9.292755447737582e-07,0.0008983999999999999,174.347350275,80.48843349445346,2.985325235038715
9.549278527773081e-07,0.0009232,179.16014445,80.48843349445346,2.985325235038715
9.665127660692338e-07,0.0009343999999999999,181.33366439999998,80.48843349445346,2.985325235038715
9.706502351020644e-07,0.0009383999999999999,182.10992152499998,80.48843349445346,2.985325235038715
9.805801607808579e-07,0.000948,183.97293862499998,80.48843349445346,2.985325235038715
9.896825926530853e-07,0.0009568,185.6807043,80.48843349445346,2.985325235038715
1.007059962590974e-06,0.0009735999999999999,188.940984225,80.48843349445346,2.985325235038715
1.0385047272404866e-06,0.001004,194.840538375,80.48843349445346,2.985325235038715
1.0525721219521109e-06,0.0010176,197.4798126,80.48843349445346,2.985325235038715
1.05919207240464e-06,0.001024,198.721824,80.48843349445346,2.985325235038715
1.0666395166637349e-06,0.0010312,200.11908682499998,80.48843349445346,2.985325235038715
1.0898093432475865e-06,0.0010536,204.466126725,80.48843349445346,2.985325235038715
1.1154616512511362e-06,0.0010784,209.2789209,80.48843349445346,2.985325235038715
1.133666514995591e-06,0.001096,212.69445224999998,80.48843349445346,2.985325235038715
1.1419414530612523e-06,0.001104,214.24696649999998,80.48843349445346,2.985325235038715
1.1576638353860085e-06,0.0011191999999999999,217.19674357499997,80.48843349445346,2.985325235038715
1.1618013044188393e-06,0.0011232,217.9730007,80.48843349445346,2.985325235038715
1.179178674356728e-06,0.00114,221.233280625,80.48843349445346,2.985325235038715
1.1833161433895587e-06,0.001144,222.00953775000002,80.48843349445346,2.985325235038715
1.1866261186158231e-06,0.0011472,222.63054344999998,80.48843349445346,2.985325235038715
1.192418575261786e-06,0.0011528,223.717303425,80.48843349445346,2.985325235038715
1.1949010566814842e-06,0.0011551999999999999,224.18305769999998,80.48843349445346,2.985325235038715
1.20648596997341e-06,0.0011664,226.35657765,80.48843349445346,2.985325235038715
1.2172433894587697e-06,0.0011768,228.374846175,80.48843349445346,2.985325235038715
1.232965771783526e-06,0.001192,231.32462324999997,80.48843349445346,2.985325235038715
1.2668930178527372e-06,0.0012247999999999998,237.68993167499997,80.48843349445346,2.985325235038715
1.2776504373380968e-06,0.0012351999999999999,239.70820019999996,80.48843349445346,2.985325235038715
1.2958553010825515e-06,0.0012527999999999999,243.12373154999997,80.48843349445346,2.985325235038715
1.3107501896007419e-06,0.0012672,245.9182572,80.48843349445346,2.985325235038715
1.3471599170896514e-06,0.0013024,252.7493199,80.48843349445346,2.985325235038715
1.3984645330967509e-06,0.001352,262.37490825,80.48843349445346,2.985325235038715
1.403429495936148e-06,0.0013568,263.3064168,80.48843349445346,2.985325235038715
1.405911977355846e-06,0.0013591999999999999,263.77217107499996,80.48843349445346,2.985325235038715
1.4191518782609042e-06,0.001372,266.256193875,80.48843349445346,2.985325235038715
1.4555616057498137e-06,0.0014072,273.08725657499997,80.48843349445346,2.985325235038715
1.47128398807457e-06,0.0014223999999999999,276.03703364999996,80.48843349445346,2.985325235038715
1.4745939633008346e-06,0.0014256,276.65803934999997,80.48843349445346,2.985325235038715
1.4927988270452892e-06,0.0014432,279.62713837680565,80.48843349445346,2.985325235038715
1.5085212093700456e-06,0.0014583999999999999,279.745089847438,80.48843349445346,2.985325235038715
1.517623641242273e-06,0.0014671999999999999,279.81315840297583,80.48843349445346,2.985325235038715
1.5308635421473311e-06,0.00148,279.91188366599397,80.48843349445346,2.985325235038715
1.5515508873114842e-06,0.0015,280.0654778450714,80.48843349445346,2.985325235038715
1.557343343957447e-06,0.0015056,280.10834082286027,80.48843349445346,2.985325235038715
1.5664457758296744e-06,0.0015144,280.1755715230793,80.48843349445346,2.985325235038715
1.5755482077019017e-06,0.0015232,280.2426500336148,80.48843349445346,2.985325235038715
1.5937530714463565e-06,0.0015408,280.37635535205845,80.48843349445346,2.985325235038715
1.5970630466726212e-06,0.001544,280.40060128070496,80.48843349445346,2.985325235038715
1.6003730218988854e-06,0.0015471999999999999,280.42482761950737,80.48843349445346,2.985325235038715
1.6152679104170757e-06,0.0015616,280.5336052227361,80.48843349445346,2.985325235038715
1.6334727741615305e-06,0.0015792,280.6660258152649,80.48843349445346,2.985325235038715
1.669055007843874e-06,0.0016136,280.923197627902,80.48843349445346,2.985325235038715
1.6748474644898367e-06,0.0016192,280.96485959149925,80.48843349445346,2.985325235038715
1.683949896362064e-06,0.0016279999999999999,281.0302150359382,80.48843349445346,2.985325235038715
1.6880873653948948e-06,0.001632,281.05987649588513,80.48843349445346,2.985325235038715
1.735254512369164e-06,0.0016776,281.3960373828402,80.48843349445346,2.985325235038715
1.756769351339883e-06,0.0016983999999999999,281.5481885228201,80.48843349445346,2.985325235038715
1.7658717832121103e-06,0.0017071999999999999,281.6123411952453,80.48843349445346,2.985325235038715
1.7791116841171684e-06,0.00172,281.70542443035254,80.48843349445346,2.985325235038715
1.8262788310914376e-06,0.0017656,282.0348601240903,80.48843349445346,2.985325235038715
1.8477936700621568e-06,0.0017863999999999998,282.1840253410734,80.48843349445346,2.985325235038715
1.8676535214197438e-06,0.0018055999999999999,282.3211162067537,80.48843349445346,2.985325235038715
1.875928459485405e-06,0.0018135999999999998,282.3780694693897,80.48843349445346,2.985325235038715
1.8941333232298596e-06,0.0018311999999999998,282.50302289757013,80.48843349445346,2.985325235038715
1.9131656807808807e-06,0.0018495999999999999,282.63315626696306,80.48843349445346,2.985325235038715
1.926405581685939e-06,0.0018624,282.7233862063943,80.48843349445346,2.985325235038715
1.9388179887844304e-06,0.0018743999999999998,282.80775737111964,80.48843349445346,2.985325235038715
1.9520578896894886e-06,0.0018872,282.89752142181976,80.48843349445346,2.985325235038715
1.9669527782076785e-06,0.0019015999999999998,282.9982226437459,80.48843349445346,2.985325235038715
1.986812629565266e-06,0.0019207999999999999,283.1320295298342,80.48843349445346,2.985325235038715
2.00088002427689e-06,0.0019344,283.22649398791225,80.48843349445346,2.985325235038715
2.0323247889264026e-06,0.0019648,283.4367182593845,80.48843349445346,2.985325235038715
2.054667121703688e-06,0.0019863999999999997,283.58531796382476,80.48843349445346,2.985325235038715
2.0803194297072377e-06,0.0020112,283.755157496723,80.48843349445346,2.985325235038715
2.100179281064825e-06,0.0020304,283.8860858341077,80.48843349445346,2.985325235038715
2.136589008553734e-06,0.0020656,284.1248738454384,80.48843349445346,2.985325235038715
2.1854111431411357e-06,0.0021127999999999997,284.4425908342309,80.48843349445346,2.985325235038715
2.1936860812067972e-06,0.0021208,284.4961656434625,80.48843349445346,2.985325235038715
2.2094084635315533e-06,0.002136,284.59774114124286,80.48843349445346,2.985325235038715
2.245818191020463e-06,0.0021712,284.8318924320403,80.48843349445346,2.985325235038715
2.251610647666426e-06,0.0021768,284.86900683769824,80.48843349445346,2.985325235038715
2.268160523797748e-06,0.0021928,284.97484336696124,80.48843349445346,2.985325235038715
2.300432782253827e-06,0.002224,285.1803623170698,80.48843349445346,2.985325235038715
2.318637645998282e-06,0.0022416,285.29579996911957,80.48843349445346,2.985325235038715
2.335187522129604e-06,0.0022576,285.40043691359335,80.48843349445346,2.985325235038715
2.3724247434250797e-06,0.0022936,285.63481833503164,80.48843349445346,2.985325235038715
2.38731963194327e-06,0.0023079999999999997,285.72816864324926,80.48843349445346,2.985325235038715
2.3972495576220637e-06,0.0023176,285.7902760205477,80.48843349445346,2.985325235038715
2.4088344709139892e-06,0.0023288,285.8626079609341,80.48843349445346,2.985325235038715
2.412144446140254e-06,0.002332,285.8832492944714,80.48843349445346,2.985325235038715
2.418764396592783e-06,0.0023384,285.9244988519981,80.48843349445346,2.985325235038715
2.4344867789175394e-06,0.0023536,286.0222904888239,80.48843349445346,2.985325235038715
2.446899186016031e-06,0.0023656,286.09932053661163,80.48843349445346,2.985325235038715
2.4576566055013912e-06,0.002376,286.16595672517735,80.48843349445346,2.985325235038715
2.5023412710559614e-06,0.0024192,286.44154430796476,80.48843349445346,2.985325235038715
2.520546134800416e-06,0.0024368,286.55326968676064,80.48843349445346,2.985325235038715
2.537923504738305e-06,0.0024536,286.6596234281587,80.48843349445346,2.985325235038715
2.5486809242236647e-06,0.002464,286.7253191522454,80.48843349445346,2.985325235038715
2.5569558622893257e-06,0.002472,286.7757807640309,80.48843349445346,2.985325235038715
2.5652308003549872e-06,0.00248,286.8261787264462,80.48843349445346,2.985325235038715
2.5685407755812516e-06,0.0024832,286.8463201535512,80.48843349445346,2.985325235038715
2.5859181455191403e-06,0.0025,286.95189703284234,80.48843349445346,2.985325235038715
2.592538095971669e-06,0.0025063999999999998,286.992043969446,80.48843349445346,2.985325235038715
2.604950503070161e-06,0.0025184,287.0672118807156,80.48843349445346,2.985325235038715
2.629775317267145e-06,0.0025423999999999998,287.2171299508736,80.48843349445346,2.985325235038715
2.632257798686843e-06,0.0025448,287.23209133766477,80.48843349445346,2.985325235038715
2.65211765004443e-06,0.002564,287.3515849660158,80.48843349445346,2.985325235038715
2.680252439467678e-06,0.0025911999999999997,287.52027195297245,80.48843349445346,2.985325235038715
2.704249759858096e-06,0.0026144,287.66360703248426,80.48843349445346,2.985325235038715
2.7290745740550797e-06,0.0026384,287.81136365671966,80.48843349445346,2.985325235038715
2.7530718944454977e-06,0.0026616,287.9536976010395,80.48843349445346,2.985325235038715
2.7745867334162165e-06,0.0026823999999999997,288.0808964997123,80.48843349445346,2.985325235038715
2.783689165288444e-06,0.0026912,288.1345955535452,80.48843349445346,2.985325235038715
2.8200988927773536e-06,0.0027264,288.34871048379165,80.48843349445346,2.985325235038715
2.856508620266263e-06,0.0027616,288.56174997422943,80.48843349445346,2.985325235038715
2.862301076912226e-06,0.0027672,288.5955447337995,80.48843349445346,2.985325235038715
2.869748521171321e-06,0.0027743999999999998,288.6389559728308,80.48843349445346,2.985325235038715
2.8887808787223417e-06,0.0027928,288.7496966634074,80.48843349445346,2.985325235038715
2.9119507053061936e-06,0.0028152,288.88412810609043,80.48843349445346,2.985325235038715
2.915260680532458e-06,0.0028184,288.90329848888337,80.48843349445346,2.985325235038715
2.9334655442769128e-06,0.002836,289.0085842495311,80.48843349445346,2.985325235038715
2.9591178522804625e-06,0.0028607999999999997,289.1565099662075,80.48843349445346,2.985325235038715
2.988080135510277e-06,0.0028888,289.3229231089746,80.48843349445346,2.985325235038715
3.0104224682875624e-06,0.0029104,289.450869511301,80.48843349445346,2.985325235038715
3.0402122453239426e-06,0.0029392,289.6208901211738,80.48843349445346,2.985325235038715
3.0650370595209267e-06,0.0029632,289.7620782097258,80.48843349445346,2.985325235038715
3.0724845037800217e-06,0.0029703999999999998,289.8043475789912,80.48843349445346,2.985325235038715
3.076621972812852e-06,0.0029744,289.82781329547834,80.48843349445346,2.985325235038715
3.0931718489441747e-06,0.0029904,289.92155335097095,80.48843349445346,2.985325235038715
3.1113767126886295e-06,0.003008,290.02444177796616,80.48843349445346,2.985325235038715
3.1254441074002533e-06,0.0030215999999999997,290.10378574839257,80.48843349445346,2.985325235038715
3.1370290206921797e-06,0.0030328,290.16902331613903,80.48843349445346,2.985325235038715
3.147786440177539e-06,0.0030432,290.2295169763784,80.48843349445346,2.985325235038715
3.162681328695729e-06,0.0030575999999999997,290.3131444930152,80.48843349445346,2.985325235038715
3.1941260933452423e-06,0.003088,290.4891887280475,80.48843349445346,2.985325235038715
3.205711006637168e-06,0.0030992,290.5538765856332,80.48843349445346,2.985325235038715
3.231363314640718e-06,0.003124,290.6967904212049,80.48843349445346,2.985325235038715
3.2437757217392096e-06,0.003136,290.7657833747541,80.48843349445346,2.985325235038715
3.255360635031135e-06,0.0031471999999999997,290.8300839620446,80.48843349445346,2.985325235038715
3.287632893487214e-06,0.0031784,291.0087381546367,80.48843349445346,2.985325235038715
3.3017002881988383e-06,0.003192,291.0863988741887,80.48843349445346,2.985325235038715
3.313285201490764e-06,0.0032032,291.1502579117578,80.48843349445346,2.985325235038715
3.318250164330161e-06,0.003208,291.1775994068817,80.48843349445346,2.985325235038715
3.3414199909140123e-06,0.0032304,291.30498268704304,80.48843349445346,2.985325235038715
3.3521774103993717e-06,0.0032408,291.36400778233207,80.48843349445346,2.985325235038715
3.3712097679503925e-06,0.0032592,291.4682561504418,80.48843349445346,2.985325235038715
3.3952070883408105e-06,0.0032824,291.5993731677916,80.48843349445346,2.985325235038715
3.4101019768590004e-06,0.0032968,291.68057437996714,80.48843349445346,2.985325235038715
3.4340992972494183e-06,0.00332,291.8111082100673,80.48843349445346,2.985325235038715
3.4638890742857986e-06,0.0033488,291.9726563479105,80.48843349445346,2.985325235038715
3.5019537893878404e-06,0.0033856,292.17829263466217,80.48843349445346,2.985325235038715
3.5044362708075387e-06,0.003388,292.19167333856234,80.48843349445346,2.985325235038715
3.525123615971692e-06,0.003408,292.30303580936624,80.48843349445346,2.985325235038715
3.5309160726176545e-06,0.0034135999999999997,292.3341715895792,80.48843349445346,2.985325235038715
3.5838756762378866e-06,0.0034647999999999997,292.61792387963555,80.48843349445346,2.985325235038715
3.5954605895298125e-06,0.003476,292.6797761641562,80.48843349445346,2.985325235038715
3.6029080337889075e-06,0.0034831999999999997,292.71949730755387,80.48843349445346,2.985325235038715
3.612010465661135e-06,0.003492,292.7680019125669,80.48843349445346,2.985325235038715
3.6194579099202305e-06,0.0034992,292.8076520504341,80.48843349445346,2.985325235038715
3.6343527984384204e-06,0.0035136,292.8868570010845,80.48843349445346,2.985325235038715
3.6566951312157057e-06,0.0035351999999999996,293.0054274688451,80.48843349445346,2.985325235038715
3.671590019733896e-06,0.0035496,293.0843175184541,80.48843349445346,2.985325235038715
3.6757274887667266e-06,0.0035535999999999996,293.1062092575681,80.48843349445346,2.985325235038715
3.6889673896717847e-06,0.0035664,293.1761983296904,80.48843349445346,2.985325235038715
3.722894635740996e-06,0.0035992,293.3550996328022,80.48843349445346,2.985325235038715
3.741926993292017e-06,0.0036176,293.4551804847825,80.48843349445346,2.985325235038715
3.770889276521831e-06,0.0036455999999999997,293.6070973640005,80.48843349445346,2.985325235038715
3.802334041171344e-06,0.003676,293.77152138233265,80.48843349445346,2.985325235038715
3.811436473043571e-06,0.0036848,293.8190187245026,80.48843349445346,2.985325235038715
3.818883917302666e-06,0.003692,293.85784729010874,80.48843349445346,2.985325235038715
3.848673694339047e-06,0.0037208,294.01286714524,80.48843349445346,2.985325235038715
3.860258607630972e-06,0.0037319999999999996,294.07302617954366,80.48843349445346,2.985325235038715
3.873498508536031e-06,0.0037448,294.14169321115116,80.48843349445346,2.985325235038715
3.897495828926448e-06,0.0037679999999999996,294.26591934898374,80.48843349445346,2.985325235038715
3.90990823602494e-06,0.00378,294.33005717637224,80.48843349445346,2.985325235038715
3.917355680284035e-06,0.0037871999999999997,294.3685017577336,80.48843349445346,2.985325235038715
3.92480312454313e-06,0.0037944,294.40691784510165,80.48843349445346,2.985325235038715
3.964522827258304e-06,0.0038328,294.6113254989197,80.48843349445346,2.985325235038715
3.992657616681553e-06,0.0038599999999999997,294.75563130307654,80.48843349445346,2.985325235038715
3.997622579520949e-06,0.0038648,294.7810558114764,80.48843349445346,2.985325235038715
4.024102381331066e-06,0.0038904,294.9164457711605,80.48843349445346,2.985325235038715
4.037342282236123e-06,0.0039032,294.9840104238548,80.48843349445346,2.985325235038715
4.047272207914917e-06,0.0039128,295.03462722022743,80.48843349445346,2.985325235038715
4.052237170754314e-06,0.0039176,295.0599174543312,80.48843349445346,2.985325235038715
4.064649577852805e-06,0.0039296,295.1230902262388,80.48843349445346,2.985325235038715
4.089474392049789e-06,0.0039536,295.2492105130881,80.48843349445346,2.985325235038715
4.094439354889186e-06,0.0039584,295.2743987018997,80.48843349445346,2.985325235038715
4.120919156699301e-06,0.003984,295.4085350644893,80.48843349445346,2.985325235038715
4.47515404291162e-06,0.004326465293058612,297.17179643736125,80.48843349445346,2.985325235038715
4.9916134700943185e-06,0.0048257651530306065,299.64790784374435,80.48843349445346,2.985325235038715
5.229979359563257e-06,0.00505621124224845,300.7567990392007,80.48843349445346,2.985325235038715
5.5676643696442515e-06,0.005382676535307062,302.29455562812205,80.48843349445346,2.985325235038715
5.865621731480423e-06,0.005670734146829366,303.62142994598264,80.48843349445346,2.985325235038715
6.044396148582126e-06,0.0058435687137427484,304.40493914794,80.48843349445346,2.985325235038715
6.243034389806241e-06,0.006035607121424285,305.2649798945676,80.48843349445346,2.985325235038715
6.441672631030356e-06,0.006227645529105821,306.1144123346378,80.48843349445346,2.985325235038715
6.680038520499294e-06,0.006458091618323665,307.1203625849908,80.48843349445346,2.985325235038715
6.858812937600997e-06,0.006630926185237048,307.8656624317923,80.48843349445346,2.985325235038715
6.977995882335467e-06,0.006746149229845969,308.3583240584468,80.48843349445346,2.985325235038715
7.117042651192346e-06,0.006880576115223045,308.92896720532394,80.48843349445346,2.985325235038715
7.196497947681993e-06,0.006957391478295659,309.2530966111547,80.48843349445346,2.985325235038715
8.269144450292212e-06,0.007994398879775955,313.5005431798186,80.48843349445346,2.985325235038715
8.388327395026681e-06,0.008109621924384877,313.9588162175157,80.48843349445346,2.985325235038715
8.765740053352499e-06,0.008474494898979796,315.3935390684729,80.48843349445346,2.985325235038715
9.023969766943848e-06,0.008724144828965793,316.3613362550734,80.48843349445346,2.985325235038715
9.361654777024844e-06,0.009050610122024405,317.61077273028997,80.48843349445346,2.985325235038715
9.83838655596272e-06,0.009511502300460092,319.34516043454965,80.48843349445346,2.985325235038715
1.025552686253336e-05,0.009914782956591319,320.8360299469782,80.48843349445346,2.985325235038715
1.0454165103757475e-05,0.010106821364272855,321.5376378659891,80.48843349445346,2.985325235038715
1.0891169234450526e-05,0.010529305861172233,323.0631285734979,80.48843349445346,2.985325235038715
1.1367901013388402e-05,0.01099019803960792,324.7003223963006,80.48843349445346,2.985325235038715
1.1765177495836632e-05,0.011374274854970993,326.0442909980484,80.48843349445346,2.985325235038715
1.1963815737060747e-05,0.01156631326265253,326.7096291222535,80.48843349445346,2.985325235038715
1.2122726330040038e-05,0.011719943988797759,327.23880281879525,80.48843349445346,2.985325235038715
1.2718641053712383e-05,0.012296059211842368,329.1995607805668,80.48843349445346,2.985325235038715
1.2917279294936498e-05,0.012488097619523904,329.84514048866964,80.48843349445346,2.985325235038715
1.3175509008527847e-05,0.012737747549509902,330.6786350987681,80.48843349445346,2.985325235038715
1.3672104611588135e-05,0.013217843568713743,332.2638159152925,80.48843349445346,2.985325235038715
1.4208427862893244e-05,0.013736347269453891,333.9507940850964,80.48843349445346,2.985325235038715
1.508243612427935e-05,0.014581316263252651,336.6476681369318,80.48843349445346,2.985325235038715
1.589685291329822e-05,0.01536867373474695,339.10628982997326,80.48843349445346,2.985325235038715
1.6055763506277513e-05,0.01552230446089218,339.5802393011368,80.48843349445346,2.985325235038715
1.631399321986886e-05,0.015771954390878175,340.34652383695567,80.48843349445346,2.985325235038715
1.6929771767663618e-05,0.01636727345469094,342.15497493967354,80.48843349445346,2.985325235038715
1.752568649133596e-05,0.016943388677735545,343.8808166184107,80.48843349445346,2.985325235038715
1.8121601215008308e-05,0.017519503900780158,345.5839179216812,80.48843349445346,2.985325235038715
1.8320239456232418e-05,0.01771154230846169,346.1467458485482,80.48843349445346,2.985325235038715
1.9293566838230582e-05,0.01865253050610122,348.8709240403174,80.48843349445346,2.985325235038715
1.9591524200066756e-05,0.018940588117623523,349.6940697855774,80.48843349445346,2.985325235038715
2.0306621868473567e-05,0.019631926385277054,351.64994948669323,80.48843349445346,2.985325235038715
2.046553246145286e-05,0.019785557111422283,352.0809197920082,80.48843349445346,2.985325235038715
2.1041583361002795e-05,0.02034246849369874,353.63236467202023,80.48843349445346,2.985325235038715
2.2432051049571598e-05,0.021686737347469495,357.310508154091,80.48843349445346,2.985325235038715
2.2551233994306067e-05,0.021801960392078417,357.621579610057,80.48843349445346,2.985325235038715
2.3067693421488765e-05,0.02230126025205041,358.9622141108746,80.48843349445346,2.985325235038715
2.3127284893855998e-05,0.02235887177435487,359.1161457706652,80.48843349445346,2.985325235038715
2.3226604014468058e-05,0.02245489097819564,359.372355234471,80.48843349445346,2.985325235038715
2.3604016672793876e-05,0.022819763952790558,360.34207907916755,80.48843349445346,2.985325235038715
2.390197403463005e-05,0.023107821564312864,361.10338555890075,80.48843349445346,2.985325235038715
2.408074845173175e-05,0.023280656131226245,361.55839304317817,80.48843349445346,2.985325235038715
2.4716390823648918e-05,0.023895179035807162,363.16563561439074,80.48843349445346,2.985325235038715
2.477598229601615e-05,0.02395279055811162,363.3154832775537,80.48843349445346,2.985325235038715
2.4974620537240267e-05,0.024144828965793157,363.813963419116,80.48843349445346,2.985325235038715
2.5252714074954025e-05,0.02441368273654731,364.50924572707436,80.48843349445346,2.985325235038715
2.648427117054354e-05,0.025604320864172834,367.5531436446194,80.48843349445346,2.985325235038715
2.688154765299177e-05,0.025988397679535907,368.5232025850579,80.48843349445346,2.985325235038715
2.715964119070553e-05,0.026257251450290058,369.198919759738,80.48843349445346,2.985325235038715
2.7735692090255464e-05,0.026814162832566515,370.5900958157061,80.48843349445346,2.985325235038715
2.8311742989805396e-05,0.02737107421484297,371.9700478626192,80.48843349445346,2.985325235038715
2.878847476874327e-05,0.027831966393278656,373.10381493662595,80.48843349445346,2.985325235038715
2.890765771347774e-05,0.027947189437887578,373.38610968280545,80.48843349445346,2.985325235038715
2.9523436261272498e-05,0.028542508501700342,374.8374640920139,80.48843349445346,2.985325235038715
2.9900848919598315e-05,0.02890738147629526,375.7211701424743,80.48843349445346,2.985325235038715
3.049676364327066e-05,0.02948349669933987,377.1076895573554,80.48843349445346,2.985325235038715
3.083444865335165e-05,0.02980996199239848,377.88869291020404,80.48843349445346,2.985325235038715
3.1092678366943e-05,0.030059611922384478,378.48368208269056,80.48843349445346,2.985325235038715
3.196668662832911e-05,0.030904580916183238,380.48334349047593,80.48843349445346,2.985325235038715
3.2284507814287695e-05,0.031211842368473696,381.2051916676527,80.48843349445346,2.985325235038715
3.254273752787904e-05,0.031461492298459695,381.7896547916112,80.48843349445346,2.985325235038715
3.268178429673592e-05,0.031595919183836765,382.1036164087874,80.48843349445346,2.985325235038715
3.2741375769103154e-05,0.03165353070614123,382.23801186535337,80.48843349445346,2.985325235038715
3.327769902040827e-05,0.03217203440688138,383.44330828427724,80.48843349445346,2.985325235038715
3.341674578926514e-05,0.03230646129225845,383.75455289059005,80.48843349445346,2.985325235038715
3.3595520206366854e-05,0.032479295859171836,384.1539833702429,80.48843349445346,2.985325235038715
3.45489837642426e-05,0.03340108021604321,386.27044054753117,80.48843349445346,2.985325235038715
3.4846941126078766e-05,0.03368913782756551,386.92714555274364,80.48843349445346,2.985325235038715
3.508530701554772e-05,0.03391958391678336,387.45093418947437,80.48843349445346,2.985325235038715
3.613808969403552e-05,0.0349373874774955,389.74792992661145,80.48843349445346,2.985325235038715
3.6654549121218214e-05,0.03543668733746749,390.8652042138129,80.48843349445346,2.985325235038715
3.6773732065952686e-05,0.03555191038207642,391.1221628591421,80.48843349445346,2.985325235038715
3.727032766901297e-05,0.03603200640128025,392.1893465473526,80.48843349445346,2.985325235038715
3.7866242392685316e-05,0.03660812162432486,393.46267452592014,80.48843349445346,2.985325235038715
3.794569768917497e-05,0.036684936987397485,393.6318591761445,80.48843349445346,2.985325235038715
3.85217485887249e-05,0.03724184836967394,394.8543425112572,80.48843349445346,2.985325235038715
3.862106770933695e-05,0.037337867573514705,395.06439286628205,80.48843349445346,2.985325235038715
3.877997830231625e-05,0.037491498299659934,395.4000357782843,80.48843349445346,2.985325235038715
3.893888889529554e-05,0.03764512902580516,395.7351427186054,80.48843349445346,2.985325235038715
3.931630155362136e-05,0.038010002000400084,396.5288913247577,80.48843349445346,2.985325235038715
3.981289715668164e-05,0.038490098019603916,397.56878468731963,80.48843349445346,2.985325235038715
4.0746496890434986e-05,0.039392678535707146,399.51019085596806,80.48843349445346,2.985325235038715
4.168009662418832e-05,0.04029525905181036,401.43432442433505,80.48843349445346,2.985325235038715
4.195819016190209e-05,0.040564112822564516,402.004211832241,80.48843349445346,2.985325235038715
4.2156828403126194e-05,0.04075615123024605,402.41037274633817,80.48843349445346,2.985325235038715
4.243492194083996e-05,0.0410250050010002,402.977746349984,80.48843349445346,2.985325235038715
4.267328783030889e-05,0.04125545109021804,403.4629133772478,80.48843349445346,2.985325235038715
4.281233459916578e-05,0.041389877975595124,403.74543938644473,80.48843349445346,2.985325235038715
4.303083666451231e-05,0.041601120224044816,404.1886868787326,80.48843349445346,2.985325235038715
4.40637555188777e-05,0.0425997199439888,406.2722702869801,80.48843349445346,2.985325235038715
4.44014405289587e-05,0.042926185237047415,406.9492986005585,80.48843349445346,2.985325235038715
4.477885318728452e-05,0.043291058211642336,407.70360540417744,80.48843349445346,2.985325235038715
4.499735525263103e-05,0.043502300460092014,408.13917606404186,80.48843349445346,2.985325235038715
4.505694672499827e-05,0.043559911982396476,408.257824801817,80.48843349445346,2.985325235038715
4.5632997624548204e-05,0.04411682336467293,409.40162484821514,80.48843349445346,2.985325235038715
4.6367959117077424e-05,0.04482736547309461,410.85281327352106,80.48843349445346,2.985325235038715
4.674537177540324e-05,0.045192238447689534,411.59453023537844,80.48843349445346,2.985325235038715
4.75200609161773e-05,0.045941188237647534,413.10972474261996,80.48843349445346,2.985325235038715
4.779815445389105e-05,0.046210042008401675,413.6512869619039,80.48843349445346,2.985325235038715
4.8215294760461704e-05,0.046613322664532914,414.4613319121656,80.48843349445346,2.985325235038715
4.889066478062369e-05,0.047266253250650134,415.76706230148847,80.48843349445346,2.985325235038715
4.944685185605121e-05,0.04780396079215843,416.8370958047225,80.48843349445346,2.985325235038715
4.9645490097275334e-05,0.047995999199839975,417.21811171675796,80.48843349445346,2.985325235038715
4.976467304200979e-05,0.04811122224444889,417.4464358888856,80.48843349445346,2.985325235038715
5.042017923804937e-05,0.04874494898979796,418.69842746580173,80.48843349445346,2.985325235038715
5.109554925821136e-05,0.04939787957591518,419.981736479016,80.48843349445346,2.985325235038715
5.1572281037149234e-05,0.04985877175435087,420.8836216984893,80.48843349445346,2.985325235038715
5.252574459502499e-05,0.050780556111222244,422.6776965097855,80.48843349445346,2.985325235038715
5.2664791363881864e-05,0.050914982996599314,422.9382673417901,80.48843349445346,2.985325235038715
5.290315725335081e-05,0.051145429085817165,423.3843368378249,80.48843349445346,2.985325235038715
5.3717574042369683e-05,0.05193278655731147,424.90252811395294,80.48843349445346,2.985325235038715
5.423403346955238e-05,0.05243208641728346,425.86063394495875,80.48843349445346,2.985325235038715
5.488953966559195e-05,0.05306581316263252,427.07158252399984,80.48843349445346,2.985325235038715
5.502858643444884e-05,0.053200240048009606,427.32772385456497,80.48843349445346,2.985325235038715
5.530667997216259e-05,0.05346909381876375,427.83925052329613,80.48843349445346,2.985325235038715
5.580327557522288e-05,0.05394918983796759,428.75020300699146,80.48843349445346,2.985325235038715
5.6458781771262466e-05,0.05458291658331667,429.9478339285192,80.48843349445346,2.985325235038715
5.7134151791424454e-05,0.05523584716943389,431.17609838008246,80.48843349445346,2.985325235038715
5.7253334736158926e-05,0.05535107021404281,431.392261829942,80.48843349445346,2.985325235038715
5.794856858044333e-05,0.05602320464092819,432.64973520926213,80.48843349445346,2.985325235038715
5.854448330411566e-05,0.05659931986397279,433.7228936952748,80.48843349445346,2.985325235038715
5.8842440665951845e-05,0.056887377475495104,434.2578747611652,80.48843349445346,2.985325235038715
5.921985332427766e-05,0.057252250450090025,434.93400322398196,80.48843349445346,2.985325235038715
5.933903626901212e-05,0.05736747349469894,435.14716806451315,80.48843349445346,2.985325235038715
5.9478083037869016e-05,0.05750190038007602,435.3956494546147,80.48843349445346,2.985325235038715
5.955753833435865e-05,0.05757871574314863,435.53753710353266,80.48843349445346,2.985325235038715
5.9716448927337946e-05,0.05773234646929386,435.8210911246924,80.48843349445346,2.985325235038715
6.031236365101029e-05,0.05830846169233847,436.8818079669229,80.48843349445346,2.985325235038715
6.0511001892234406e-05,0.05850050010002,437.23447091639486,80.48843349445346,2.985325235038715
6.063018483696888e-05,0.05861572314462893,437.44585197506285,80.48843349445346,2.985325235038715
6.086855072643781e-05,0.058846169233846765,437.8681285622334,80.48843349445346,2.985325235038715
6.108705279178434e-05,0.05905741148229646,438.2546492257608,80.48843349445346,2.985325235038715
6.150419309835497e-05,0.05946069213842768,438.9910583344998,80.48843349445346,2.985325235038715
6.176242281194633e-05,0.05971034206841368,439.44595461051296,80.48843349445346,2.985325235038715
6.206038017378251e-05,0.05999839967993599,439.9699142465357,80.48843349445346,2.985325235038715
6.22391545908842e-05,0.060171234246849364,440.2838191327683,80.48843349445346,2.985325235038715
6.239806518386348e-05,0.060324864972994593,440.5625506114543,80.48843349445346,2.985325235038715
6.281520549043414e-05,0.06072814562912583,441.2929067460839,80.48843349445346,2.985325235038715
6.331180109349441e-05,0.061208241648329664,442.1599166410265,80.48843349445346,2.985325235038715
6.36097584553306e-05,0.06149629925985198,442.6788496072174,80.48843349445346,2.985325235038715
6.386798816892195e-05,0.06174594918983797,443.1278251637711,80.48843349445346,2.985325235038715
6.422553700312535e-05,0.062091618323664735,443.74831661596954,80.48843349445346,2.985325235038715
6.452349436496152e-05,0.062379675935187034,444.26436439391114,80.48843349445346,2.985325235038715
6.456322201320635e-05,0.06241808361672335,444.33310047774603,80.48843349445346,2.985325235038715
6.509954526451145e-05,0.06293658731746349,445.2594290618994,80.48843349445346,2.985325235038715
6.51988643851235e-05,0.06303260652130425,445.43064428018744,80.48843349445346,2.985325235038715
6.539750262634763e-05,0.0632246449289858,445.77276986677623,80.48843349445346,2.985325235038715
6.629137471185615e-05,0.06408881776355271,447.30734715410966,80.48843349445346,2.985325235038715
6.696674473201813e-05,0.06474174834966993,448.46145921943724,80.48843349445346,2.985325235038715
6.722497444560948e-05,0.06499139827965593,448.90153661286655,80.48843349445346,2.985325235038715
6.839694006883177e-05,0.066124424884977,450.89058287282097,80.48843349445346,2.985325235038715
6.923122068197305e-05,0.06693098619723946,452.29842343733816,80.48843349445346,2.985325235038715
6.972781628503333e-05,0.06741108221644329,453.1332826636828,80.48843349445346,2.985325235038715
7.002577364686952e-05,0.0676991398279656,453.63308521607877,80.48843349445346,2.985325235038715
7.024427571221602e-05,0.06791038207641528,453.9990801226692,80.48843349445346,2.985325235038715
7.03634586569505e-05,0.06802560512102421,454.1985265577395,80.48843349445346,2.985325235038715
7.060182454641945e-05,0.06825605121024206,454.59702461109924,80.48843349445346,2.985325235038715
7.151556045605037e-05,0.06913942788557711,456.11976418394494,80.48843349445346,2.985325235038715
7.163474340078483e-05,0.06925465093018604,456.31782149669357,80.48843349445346,2.985325235038715
7.183338164200894e-05,0.06944668933786757,456.64763167321803,80.48843349445346,2.985325235038715
7.201215605911065e-05,0.06961952390478096,456.9441568462322,80.48843349445346,2.985325235038715
7.24292963656813e-05,0.07002280456091219,457.6349346803097,80.48843349445346,2.985325235038715
7.288616432049675e-05,0.07046449289857971,458.38972305840235,80.48843349445346,2.985325235038715
7.342248757180186e-05,0.07098299659931986,459.2734286024765,80.48843349445346,2.985325235038715
7.34820790441691e-05,0.07104060812162433,459.3714624589214,80.48843349445346,2.985325235038715
7.43362234814328e-05,0.07186637327465493,460.77322469293335,80.48843349445346,2.985325235038715
7.445540642616728e-05,0.07198159631926386,460.96831884501654,80.48843349445346,2.985325235038715
7.499172967747239e-05,0.07250010002000401,461.84473968983207,80.48843349445346,2.985325235038715
7.552805292877748e-05,0.07301860372074415,462.71871941281876,80.48843349445346,2.985325235038715
7.592532941122572e-05,0.07340268053610723,463.36455215112505,80.48843349445346,2.985325235038715
7.596505705947053e-05,0.07344108821764353,463.42906285462186,80.48843349445346,2.985325235038715
7.677947384848941e-05,0.07422844568913783,464.74864658669475,80.48843349445346,2.985325235038715
7.717675033093764e-05,0.0746125225045009,465.3903641422365,80.48843349445346,2.985325235038715
7.731579709979452e-05,0.07474694938987798,465.6146607601143,80.48843349445346,2.985325235038715
7.759389063750827e-05,0.07501580316063212,466.0627825976101,80.48843349445346,2.985325235038715
7.785212035109964e-05,0.07526545309061813,466.4783352084829,80.48843349445346,2.985325235038715
7.809048624056857e-05,0.07549589917983597,466.8614453614141,80.48843349445346,2.985325235038715
7.830898830591509e-05,0.07570714142828566,467.21222921143567,80.48843349445346,2.985325235038715
7.860694566775126e-05,0.07599519903980796,467.6899562739837,80.48843349445346,2.985325235038715
7.880558390897539e-05,0.07618723744748951,468.0080486996025,80.48843349445346,2.985325235038715
7.920286039142361e-05,0.07657131426285257,468.6432970111559,80.48843349445346,2.985325235038715
8.003714100456488e-05,0.07737787557511502,469.97328773416416,80.48843349445346,2.985325235038715
8.055360043174759e-05,0.07787717543508701,470.79390632045704,80.48843349445346,2.985325235038715
8.087142161770617e-05,0.07818443688737747,471.2978825964853,80.48843349445346,2.985325235038715
8.122897045190959e-05,0.07853010602120425,471.86393351850296,80.48843349445346,2.985325235038715
8.168583840672504e-05,0.07897179435887178,472.58580870958934,80.48843349445346,2.985325235038715
8.202352341680604e-05,0.0792982596519304,473.1183570171788,80.48843349445346,2.985325235038715
8.285780402994733e-05,0.08010482096419284,474.4304119284856,80.48843349445346,2.985325235038715
8.416881642202649e-05,0.08137227445489098,476.48185053337943,80.48843349445346,2.985325235038715
8.476473114569882e-05,0.08194838967793559,477.41019923144853,80.48843349445346,2.985325235038715
8.494350556280053e-05,0.08212122424484898,477.6882070470341,80.48843349445346,2.985325235038715
8.502296085929018e-05,0.08219803960792159,477.8116928203227,80.48843349445346,2.985325235038715
8.538050969349357e-05,0.08254370874174835,478.3668227969167,80.48843349445346,2.985325235038715
8.567846705532976e-05,0.08283176635327066,478.8287388763885,80.48843349445346,2.985325235038715
8.587710529655387e-05,0.0830238047609522,479.13633493112184,80.48843349445346,2.985325235038715
8.607574353777798e-05,0.08321584316863373,479.44365363122324,80.48843349445346,2.985325235038715
8.641342854785898e-05,0.08354230846169235,479.96546140719363,80.48843349445346,2.985325235038715
8.657233914083828e-05,0.08369593918783758,480.2107427788232,80.48843349445346,2.985325235038715
8.746621122634679e-05,0.08456011202240449,481.58719269007685,80.48843349445346,2.985325235038715
8.76648494675709e-05,0.08475215043008602,481.8923241610212,80.48843349445346,2.985325235038715
8.812171742238636e-05,0.08519383876775355,482.59310509203556,80.48843349445346,2.985325235038715
8.86977683219363e-05,0.08575075015003002,483.4746821059111,80.48843349445346,2.985325235038715
8.969095952805688e-05,0.0867109421884377,484.98941662623287,80.48843349445346,2.985325235038715
9.002864453813787e-05,0.0870374074814963,485.5029343348086,80.48843349445346,2.985325235038715
9.058483161356539e-05,0.08757511502300461,486.34709368654524,80.48843349445346,2.985325235038715
9.062455926181021e-05,0.08761352270454091,486.4073133211391,80.48843349445346,2.985325235038715
9.116088251311532e-05,0.08813202640528106,487.21927334621006,80.48843349445346,2.985325235038715
9.149856752319632e-05,0.08845849169833968,487.7295517757423,80.48843349445346,2.985325235038715
9.18163887091549e-05,0.08876575315063014,488.2091433133791,80.48843349445346,2.985325235038715
9.205475459862383e-05,0.08899619923984797,488.5684122005307,80.48843349445346,2.985325235038715
9.261094167405137e-05,0.08953390678135628,489.40529829160755,80.48843349445346,2.985325235038715
9.28493075635203e-05,0.08976435287057412,489.7633634592799,80.48843349445346,2.985325235038715
9.308767345298924e-05,0.08999479895979197,490.12107030344913,80.48843349445346,2.985325235038715
9.344522228719265e-05,0.09034046809361873,490.6569614995278,80.48843349445346,2.985325235038715
9.39020902420081e-05,0.09078215643128626,491.34054905607724,80.48843349445346,2.985325235038715
9.408086465910981e-05,0.09095499099819965,491.6076866022816,80.48843349445346,2.985325235038715
9.453773261392527e-05,0.09139667933586718,492.2894735749269,80.48843349445346,2.985325235038715
9.481582615163904e-05,0.09166553310662133,492.70384524706503,80.48843349445346,2.985325235038715
9.505419204110797e-05,0.09189597919583917,493.05864385450866,80.48843349445346,2.985325235038715
9.51137835134752e-05,0.09195359071814363,493.1472892681143,80.48843349445346,2.985325235038715
9.533228557882173e-05,0.09216483296659332,493.4721373025499,80.48843349445346,2.985325235038715
9.61268385437182e-05,0.09293298659731947,494.65096299377643,80.48843349445346,2.985325235038715
9.628574913669748e-05,0.0930866173234647,494.8862714572794,80.48843349445346,2.985325235038715
9.648438737792159e-05,0.09327865573114623,495.18019415753696,80.48843349445346,2.985325235038715
9.672275326739053e-05,0.09350910182036408,495.53259006798925,80.48843349445346,2.985325235038715
9.783512741824558e-05,0.09458451690338068,497.17264675318535,80.48843349445346,2.985325235038715
9.845090596604033e-05,0.09517983596719344,498.0774076160277,80.48843349445346,2.985325235038715
9.87289995037541e-05,0.0954486897379476,498.4852856058084,80.48843349445346,2.985325235038715
9.882831862436616e-05,0.09554470894178836,498.6308476977101,80.48843349445346,2.985325235038715
9.92653227550592e-05,0.09596719343868775,499.2706443371359,80.48843349445346,2.985325235038715
9.970232688575226e-05,0.09638967793558713,499.9093434287545,80.48843349445346,2.985325235038715
9.994069277522119e-05,0.09662012402480497,500.2572645408485,80.48843349445346,2.985325235038715
0.00010009960336820049,0.0967737547509502,500.4890321723974,80.48843349445346,2.985325235038715
0.00010139075193615724,0.09802200440088019,502.3668540608786,80.48843349445346,2.985325235038715
0.00010164898164974859,0.09827165433086618,502.74129679156596,80.48843349445346,2.985325235038715
0.00010210584960456404,0.09871334266853371,503.40286486425487,80.48843349445346,2.985325235038715
0.00010214557725280886,0.09875175035007001,503.46033790830563,80.48843349445346,2.985325235038715
0.00010224489637342092,0.09884776955391078,503.60398239167336,80.48843349445346,2.985325235038715
0.0001025428537352571,0.0991358271654331,504.03458968723567,80.48843349445346,2.985325235038715
0.00010266203667999158,0.09925105021004202,504.2066959402891,80.48843349445346,2.985325235038715
0.00010284081109709327,0.09942388477695539,504.4647092865784,80.48843349445346,2.985325235038715
0.00010333740670015357,0.09990398079615924,505.18049684143176,80.48843349445346,2.985325235038715
0.00010343672582076562,0.1,505.3234932348484,80.48843349445346,2.985325235038715