File: datasets/aisi_316_L/data/M1/train_18.csv
Time(s),Strain(%),Stress(MPa),Temp(C),Log_SR(s-1)
0.0,0.0,0.0,293.2641606925346,-1.8769044912381299
0.001626890197425826,2.16e-05,3.8498932125,293.2641606925346,-1.8769044912381299
0.0028319940473708824,3.76e-05,6.7016659625,293.2641606925346,-1.8769044912381299
0.004940925784774731,6.56e-05,11.692268275,293.2641606925346,-1.8769044912381299
0.005061436169769237,6.72e-05,11.977445549999999,293.2641606925346,-1.8769044912381299
0.006567815982200557,8.719999999999999e-05,15.542161487499998,293.2641606925346,-1.8769044912381299
0.006808836752189569,9.04e-05,16.1125160375,293.2641606925346,-1.8769044912381299
0.007290878292167591,9.68e-05,17.2532251375,293.2641606925346,-1.8769044912381299
0.008375471757118141,0.00011119999999999999,19.8198206125,293.2641606925346,-1.8769044912381299
0.012774100809417599,0.0001696,30.22879115,293.2641606925346,-1.8769044912381299
0.014883032546821445,0.00019759999999999998,35.219393462499994,293.2641606925346,-1.8769044912381299
0.015847115626777493,0.0002104,37.5008116625,293.2641606925346,-1.8769044912381299
0.016148391589263754,0.00021439999999999998,38.213754849999994,293.2641606925346,-1.8769044912381299
0.016811198706733536,0.00022319999999999998,39.782229862499996,293.2641606925346,-1.8769044912381299
0.017172729861717053,0.00022799999999999999,40.637761687499996,293.2641606925346,-1.8769044912381299
0.0181368129416731,0.0002408,42.9191798875,293.2641606925346,-1.8769044912381299
0.018438088904159364,0.0002448,43.632123074999996,293.2641606925346,-1.8769044912381299
0.0191611512141264,0.0002544,45.343186725,293.2641606925346,-1.8769044912381299
0.020245744679076947,0.0002688,47.909782199999995,293.2641606925346,-1.8769044912381299
0.020788041411552223,0.000276,49.193079937499995,293.2641606925346,-1.8769044912381299
0.0213303381440275,0.0002832,50.476377675,293.2641606925346,-1.8769044912381299
0.021571358914016507,0.00028639999999999997,51.04673222499999,293.2641606925346,-1.8769044912381299
0.02217391083898904,0.0002944,52.4726186,293.2641606925346,-1.8769044912381299
0.02289697314895607,0.00030399999999999996,54.18368225,293.2641606925346,-1.8769044912381299
0.023921311421409366,0.00031759999999999997,56.60768908749999,293.2641606925346,-1.8769044912381299
0.024584118538879148,0.00032639999999999996,58.176164099999994,293.2641606925346,-1.8769044912381299
0.025126415271354424,0.0003336,59.459461837499994,293.2641606925346,-1.8769044912381299
0.026994326238769264,0.0003584,63.8797096,293.2641606925346,-1.8769044912381299
0.028741726821189598,0.0003816,68.0147800875,293.2641606925346,-1.8769044912381299
0.02928402355366487,0.00038879999999999996,69.298077825,293.2641606925346,-1.8769044912381299
0.03253780394851652,0.000432,76.99786424999999,293.2641606925346,-1.8769044912381299
0.03651464665333521,0.00048479999999999997,86.40871432499999,293.2641606925346,-1.8769044912381299
0.03711719857830773,0.0004927999999999999,87.8346007,293.2641606925346,-1.8769044912381299
0.03802102646576653,0.0005048,89.9734302625,293.2641606925346,-1.8769044912381299
0.038985109545722575,0.0005176,92.25484846250001,293.2641606925346,-1.8769044912381299
0.04139531724561269,0.0005496,97.9583939625,293.2641606925346,-1.8769044912381299
0.04404654571549181,0.0005848,104.2322940125,293.2641606925346,-1.8769044912381299
0.045070883987945114,0.0005984,106.65630085000001,293.2641606925346,-1.8769044912381299
0.04639649822288467,0.000616,109.793250875,293.2641606925346,-1.8769044912381299
0.048927216307769285,0.0006496,115.78197365,293.2641606925346,-1.8769044912381299
0.05013232015771434,0.0006655999999999999,118.63374639999998,293.2641606925346,-1.8769044912381299
0.05145793439265391,0.0006832,121.770696425,293.2641606925346,-1.8769044912381299
0.05224125189511819,0.0006935999999999999,123.6243487125,293.2641606925346,-1.8769044912381299
0.05471171478750556,0.0007264,129.47048285,293.2641606925346,-1.8769044912381299
0.05615783940743963,0.0007456,132.89261015,293.2641606925346,-1.8769044912381299
0.057001412102401165,0.0007568,134.888851075,293.2641606925346,-1.8769044912381299
0.05754370883487644,0.0007639999999999999,136.17214881249998,293.2641606925346,-1.8769044912381299
0.05766421921987095,0.0007656,136.45732608749998,293.2641606925346,-1.8769044912381299
0.058387281529837985,0.0007752,138.1683897375,293.2641606925346,-1.8769044912381299
0.05911034383980502,0.0007848,139.8794533875,293.2641606925346,-1.8769044912381299
0.061821827502181396,0.0008208,146.295942075,293.2641606925346,-1.8769044912381299
0.062183358657164914,0.0008256,147.1514739,293.2641606925346,-1.8769044912381299
0.0629666761596292,0.0008359999999999999,149.0051261875,293.2641606925346,-1.8769044912381299
0.06543713905201656,0.0008688,154.851260325,293.2641606925346,-1.8769044912381299
0.06622045655448085,0.0008792,156.7049126125,293.2641606925346,-1.8769044912381299
0.06736530521192866,0.0008944,159.41409672499998,293.2641606925346,-1.8769044912381299
0.06754607078942042,0.0008968,159.84186263750001,293.2641606925346,-1.8769044912381299
0.06851015386937646,0.0009096,162.1232808375,293.2641606925346,-1.8769044912381299
0.06911270579434899,0.0009176,163.54916721249998,293.2641606925346,-1.8769044912381299
0.069353726564338,0.0009207999999999999,164.1195217625,293.2641606925346,-1.8769044912381299
0.07086010637676932,0.0009408,167.6842377,293.2641606925346,-1.8769044912381299
0.07230623099670339,0.0009599999999999999,171.10636499999998,293.2641606925346,-1.8769044912381299
0.07339082446165393,0.0009743999999999999,173.672960475,293.2641606925346,-1.8769044912381299
0.07441516273410723,0.000988,174.687142046505,293.2641606925346,-1.8769044912381299
0.0749574594665825,0.0009952,174.72818761256548,293.2641606925346,-1.8769044912381299
0.0757407769690468,0.0010056,174.78727178282156,293.2641606925346,-1.8769044912381299
0.07640358408651657,0.0010144,174.83708017913386,293.2641606925346,-1.8769044912381299
0.07682537043399734,0.0010199999999999999,174.86868871104534,293.2641606925346,-1.8769044912381299
0.07754843274396438,0.0010295999999999999,174.92271775916046,293.2641606925346,-1.8769044912381299
0.0780304742839424,0.001036,174.95862801499007,293.2641606925346,-1.8769044912381299
0.07851251582392042,0.0010424,174.9944518569286,293.2641606925346,-1.8769044912381299
0.07977787486636273,0.0010592,175.08808367193947,293.2641606925346,-1.8769044912381299
0.08038042679133525,0.0010672,175.13246652154828,293.2641606925346,-1.8769044912381299
0.08164578583377756,0.001084,175.22525036171916,293.2641606925346,-1.8769044912381299
0.08471880065113747,0.0011248,175.44827802567664,293.2641606925346,-1.8769044912381299
0.08526109738361275,0.001132,175.4873060685542,293.2641606925346,-1.8769044912381299
0.0877315602760001,0.0011648,175.66388951251292,293.2641606925346,-1.8769044912381299
0.0886353881634589,0.0011768,175.72800729532077,293.2641606925346,-1.8769044912381299
0.08996100239839847,0.0011944,175.82158737552803,293.2641606925346,-1.8769044912381299
0.09032253355338198,0.0011991999999999999,175.847015683144,293.2641606925346,-1.8769044912381299
0.09044304393837647,0.0012008,175.85548296061967,293.2641606925346,-1.8769044912381299
0.0939981002957144,0.001248,176.10332270985788,293.2641606925346,-1.8769044912381299
0.09466090741318418,0.0012568,176.14912295909147,293.2641606925346,-1.8769044912381299
0.09484167299067595,0.0012592,176.16159220831332,293.2641606925346,-1.8769044912381299
0.09598652164812374,0.0012744,176.24034996489954,293.2641606925346,-1.8769044912381299
0.0961672872256155,0.0012768,176.25275183263014,293.2641606925346,-1.8769044912381299
0.09689034953558254,0.0012864,176.30226865725282,293.2641606925346,-1.8769044912381299
0.09737239107556056,0.0012928,176.33519983278933,293.2641606925346,-1.8769044912381299
0.09791468780803583,0.0013,176.37217150195204,293.2641606925346,-1.8769044912381299
0.10008387473793694,0.0013288,176.51926650877016,293.2641606925346,-1.8769044912381299
0.10237357205283254,0.0013591999999999999,176.67319087202512,293.2641606925346,-1.8769044912381299
0.10430173821274462,0.0013847999999999998,176.80177274722618,293.2641606925346,-1.8769044912381299
0.10466326936772814,0.0013896,176.825778293397,293.2641606925346,-1.8769044912381299
0.10653118033514299,0.0014144,176.94929551181806,293.2641606925346,-1.8769044912381299
0.10791704976257979,0.0014328,177.04039220822227,293.2641606925346,-1.8769044912381299
0.10978496072999464,0.0014575999999999999,177.16245608125374,293.2641606925346,-1.8769044912381299
0.11068878861745343,0.0014696,177.22122824054685,293.2641606925346,-1.8769044912381299
0.11165287169740948,0.0014824,177.28371262643347,293.2641606925346,-1.8769044912381299
0.11201440285239299,0.0014872,177.30708997830354,293.2641606925346,-1.8769044912381299
0.11243618919987375,0.0014927999999999999,177.33432639680672,293.2641606925346,-1.8769044912381299
0.11321950670233805,0.0015032,177.38480283277875,293.2641606925346,-1.8769044912381299
0.11448486574478035,0.0015199999999999999,177.46605493137216,293.2641606925346,-1.8769044912381299
0.11677456305967597,0.0015504,177.61219778156894,293.2641606925346,-1.8769044912381299
0.11852196364209629,0.0015735999999999999,177.72297718582968,293.2641606925346,-1.8769044912381299
0.11984757787703586,0.0015911999999999999,177.8065923433457,293.2641606925346,-1.8769044912381299
0.12123344730447266,0.0016095999999999999,177.89362344198688,293.2641606925346,-1.8769044912381299
0.1217154888444507,0.001616,177.92380406534426,293.2641606925346,-1.8769044912381299
0.122739827116904,0.0016296,177.98778354822934,293.2641606925346,-1.8769044912381299
0.12382442058185454,0.0016439999999999998,178.05529997331013,293.2641606925346,-1.8769044912381299
0.12484875885430784,0.0016576,178.11885402056316,293.2641606925346,-1.8769044912381299
0.12629488347424192,0.0016768,178.2082322616922,293.2641606925346,-1.8769044912381299
0.12731922174669522,0.0016903999999999999,178.27130052159498,293.2641606925346,-1.8769044912381299
0.12828330482665126,0.0017032,178.33047835352545,293.2641606925346,-1.8769044912381299
0.12912687752161278,0.0017143999999999998,178.38211682044644,293.2641606925346,-1.8769044912381299
0.13099478848902762,0.0017392,178.49599323545263,293.2641606925346,-1.8769044912381299
0.1335857617664095,0.0017736,178.6529079049301,293.2641606925346,-1.8769044912381299
0.13412805849888476,0.0017808,178.68559979098183,293.2641606925346,-1.8769044912381299
0.13533316234882983,0.0017967999999999999,178.758064432602,293.2641606925346,-1.8769044912381299
0.13720107331624465,0.0018215999999999998,178.86988925989746,293.2641606925346,-1.8769044912381299
0.13732158370123917,0.0018231999999999999,178.87708330940913,293.2641606925346,-1.8769044912381299
0.13852668755118422,0.0018391999999999998,178.94888889946643,293.2641606925346,-1.8769044912381299
0.14009332255611281,0.0018599999999999999,179.04187300225303,293.2641606925346,-1.8769044912381299
0.14208174390852216,0.0018863999999999999,179.15930934966906,293.2641606925346,-1.8769044912381299
0.1434073581434617,0.0019039999999999999,179.2372443466749,293.2641606925346,-1.8769044912381299
0.14491373795589302,0.001924,179.3254666090357,293.2641606925346,-1.8769044912381299
0.14557654507336282,0.0019328,179.364171021247,293.2641606925346,-1.8769044912381299
0.14617909699833534,0.0019408,179.39929725356959,293.2641606925346,-1.8769044912381299
0.14756496642577216,0.0019592,179.4798739904649,293.2641606925346,-1.8769044912381299
0.14810726315824743,0.0019664,179.5113236137045,293.2641606925346,-1.8769044912381299
0.14925211181569525,0.0019816,179.5775701627352,293.2641606925346,-1.8769044912381299
0.15220461624806064,0.0020208,179.7475083636544,293.2641606925346,-1.8769044912381299
0.15292767855802766,0.0020304,179.78892930768865,293.2641606925346,-1.8769044912381299
0.154916099910437,0.0020568,179.90244493229793,293.2641606925346,-1.8769044912381299
0.1564224797228683,0.0020767999999999997,179.98806370446906,293.2641606925346,-1.8769044912381299
0.1568442660703491,0.0020824,180.01197925873808,293.2641606925346,-1.8769044912381299
0.15702503164784085,0.0020848,180.02222110226703,293.2641606925346,-1.8769044912381299
0.15931472896273643,0.0021152,180.15155566295815,293.2641606925346,-1.8769044912381299
0.16106212954515678,0.0021384,180.24977120908798,293.2641606925346,-1.8769044912381299
0.16311080609006337,0.0021655999999999997,180.36439280867674,293.2641606925346,-1.8769044912381299
0.16570177936744523,0.0021999999999999997,180.50855451639137,293.2641606925346,-1.8769044912381299
0.1665453520624068,0.0022112,180.5553008247746,293.2641606925346,-1.8769044912381299
0.1671479039873793,0.0022191999999999997,180.58863452651087,293.2641606925346,-1.8769044912381299
0.16967862207226395,0.0022528,180.7281273833073,293.2641606925346,-1.8769044912381299
0.17088372592220902,0.0022688,180.79426715865998,293.2641606925346,-1.8769044912381299
0.17124525707719251,0.0022735999999999998,180.8140735867275,293.2641606925346,-1.8769044912381299
0.1717875538096678,0.0022808,180.84375267900126,293.2641606925346,-1.8769044912381299
0.17449903747204418,0.0023168,180.99160356144563,293.2641606925346,-1.8769044912381299
0.17564388612949197,0.002332,181.05376016100863,293.2641606925346,-1.8769044912381299
0.17672847959444252,0.0023464,181.1124997729591,293.2641606925346,-1.8769044912381299
0.17745154190440957,0.002356,181.15158142744843,293.2641606925346,-1.8769044912381299
0.17805409382938206,0.0023639999999999998,181.18410205341314,293.2641606925346,-1.8769044912381299
0.18004251518179143,0.0023904,181.2911168876611,293.2641606925346,-1.8769044912381299
0.1826334884591733,0.0024248,181.42987137353336,293.2641606925346,-1.8769044912381299
0.18287450922916232,0.002428,181.44273961312265,293.2641606925346,-1.8769044912381299
0.18341680596163756,0.0024351999999999998,181.4716689932282,293.2641606925346,-1.8769044912381299
0.18462190981158264,0.0024511999999999997,181.53583734195254,293.2641606925346,-1.8769044912381299
0.1850436961590634,0.0024568,181.55825764498246,293.2641606925346,-1.8769044912381299
0.18667058635648923,0.0024784,181.6445499010671,293.2641606925346,-1.8769044912381299
0.18769492462894252,0.002492,181.69873161705732,293.2641606925346,-1.8769044912381299
0.18992436675134086,0.0025215999999999997,181.81625949077696,293.2641606925346,-1.8769044912381299
0.19046666348381616,0.0025288,181.8447658464538,293.2641606925346,-1.8769044912381299
0.19076793944630244,0.0025328,181.86058903276074,293.2641606925346,-1.8769044912381299
0.19118972579378318,0.0025383999999999997,181.88272513045837,293.2641606925346,-1.8769044912381299
0.19173202252625846,0.0025456,181.91115786235682,293.2641606925346,-1.8769044912381299
0.1933589127236843,0.0025672,181.9962684705333,293.2641606925346,-1.8769044912381299
0.19390120945615955,0.0025743999999999997,182.02457655075307,293.2641606925346,-1.8769044912381299
0.19498580292111015,0.0025888,182.08110025088536,293.2641606925346,-1.8769044912381299
0.1955280996535854,0.002596,182.10931610914156,293.2641606925346,-1.8769044912381299
0.19643192754104422,0.002608,182.15627481164262,293.2641606925346,-1.8769044912381299
0.19775754177598376,0.0026256,182.224995433734,293.2641606925346,-1.8769044912381299
0.1997459631283931,0.002652,182.32774047269666,293.2641606925346,-1.8769044912381299
0.20034851505336562,0.00266,182.35879647900543,293.2641606925346,-1.8769044912381299
0.20125234294082442,0.002672,182.40531227595395,293.2641606925346,-1.8769044912381299
0.2016741292883052,0.0026776,182.42699175965308,293.2641606925346,-1.8769044912381299
0.20354204025572,0.0027023999999999998,182.52278913341283,293.2641606925346,-1.8769044912381299
0.20516893045314585,0.002724,182.60594654169165,293.2641606925346,-1.8769044912381299
0.20553046160812938,0.0027288,182.62439099605396,293.2641606925346,-1.8769044912381299
0.2057714823781184,0.002732,182.63668026991203,293.2641606925346,-1.8769044912381299
0.20643428949558815,0.0027408,182.67044686068857,293.2641606925346,-1.8769044912381299
0.20794066930801947,0.0027608,182.74703225909644,293.2641606925346,-1.8769044912381299
0.2097483250829371,0.0027848,182.83864971372765,293.2641606925346,-1.8769044912381299
0.21029062181541233,0.0027919999999999998,182.8660748352604,293.2641606925346,-1.8769044912381299
0.21149572566535738,0.0028079999999999997,182.92692099154533,293.2641606925346,-1.8769044912381299
0.21438797490522551,0.0028464,183.07240272407313,293.2641606925346,-1.8769044912381299
0.2152918027926843,0.0028583999999999997,183.11770852691032,293.2641606925346,-1.8769044912381299
0.21583409952515958,0.0028656,183.14485640441305,293.2641606925346,-1.8769044912381299
0.21631614106513763,0.002872,183.16896552640486,293.2641606925346,-1.8769044912381299
0.21794303126256345,0.0028936,183.25017956723806,293.2641606925346,-1.8769044912381299
0.21848532799503873,0.0029008,183.2771983281964,293.2641606925346,-1.8769044912381299
0.21932890069000024,0.0029119999999999997,183.3191755842162,293.2641606925346,-1.8769044912381299
0.2200519629999673,0.0029216,183.35510599836914,293.2641606925346,-1.8769044912381299
0.2215583428123986,0.0029416,183.4298134791911,293.2641606925346,-1.8769044912381299
0.22210063954487388,0.0029487999999999997,183.4566596447482,293.2641606925346,-1.8769044912381299
0.2231249778173272,0.0029624,183.5072994220764,293.2641606925346,-1.8769044912381299
0.22384804012729423,0.002972,183.54299057307247,293.2641606925346,-1.8769044912381299
0.22511339916973652,0.0029888,183.60534208586324,293.2641606925346,-1.8769044912381299
0.22607748224969257,0.0030015999999999997,183.65275629970768,293.2641606925346,-1.8769044912381299
0.22686079975215687,0.003012,183.69122231175558,293.2641606925346,-1.8769044912381299
0.23035560091699753,0.0030583999999999997,183.8622127001137,293.2641606925346,-1.8769044912381299
0.23222351188441237,0.0030832,183.95318909038153,293.2641606925346,-1.8769044912381299
0.23409142285182719,0.0031079999999999997,184.04388053117097,293.2641606925346,-1.8769044912381299
0.23535678189426953,0.0031248,184.10515637467702,293.2641606925346,-1.8769044912381299
0.23601958901173928,0.0031336,184.13720196174472,293.2641606925346,-1.8769044912381299
0.2371644376691871,0.0031487999999999998,184.19247088653864,293.2641606925346,-1.8769044912381299
0.23788749997915415,0.0031584,184.2273239715094,293.2641606925346,-1.8769044912381299
0.23963490056157444,0.0031815999999999997,184.31138213086376,293.2641606925346,-1.8769044912381299
0.23975541094656896,0.0031831999999999997,184.3171704185005,293.2641606925346,-1.8769044912381299
0.2405989836415305,0.0031944,184.35765670851958,293.2641606925346,-1.8769044912381299
0.24288868095642613,0.0032248,184.4672699664528,293.2641606925346,-1.8769044912381299
0.2433104673039069,0.0032304,184.48741785077584,293.2641606925346,-1.8769044912381299
0.245720675003797,0.0032624,184.6022883788879,293.2641606925346,-1.8769044912381299
0.24596169577378602,0.0032656,184.613751210351,293.2641606925346,-1.8769044912381299
0.24638348212126676,0.0032711999999999997,184.63380062994932,293.2641606925346,-1.8769044912381299
0.24734756520122284,0.003284,184.67957767722348,293.2641606925346,-1.8769044912381299
0.24831164828117888,0.0032968,184.7252851915766,293.2641606925346,-1.8769044912381299
0.2503000696335882,0.0033231999999999997,184.81933894055248,293.2641606925346,-1.8769044912381299
0.25060134559607444,0.0033271999999999998,184.8335640478982,293.2641606925346,-1.8769044912381299
0.25102313194355524,0.0033328,184.85346799833331,293.2641606925346,-1.8769044912381299
0.25150517348353324,0.0033391999999999996,184.87619940604526,293.2641606925346,-1.8769044912381299
0.2528910429109701,0.0033575999999999996,184.9414577482726,293.2641606925346,-1.8769044912381299
0.25445767791589863,0.0033783999999999997,185.01506033448754,293.2641606925346,-1.8769044912381299
0.2560845681133245,0.0034,185.09130697627245,293.2641606925346,-1.8769044912381299
0.2567473752307943,0.0034088,185.12231623528697,293.2641606925346,-1.8769044912381299
0.25837426542822006,0.0034303999999999997,185.1982978030152,293.2641606925346,-1.8769044912381299
0.26084472832060746,0.0034632,185.31332139799062,293.2641606925346,-1.8769044912381299
0.26174855620806625,0.0034752,185.35529694839732,293.2641606925346,-1.8769044912381299
0.2629536600580113,0.0034912,185.4111765224402,293.2641606925346,-1.8769044912381299
0.2645202950629399,0.003512,185.48367088088813,293.2641606925346,-1.8769044912381299
0.2660869300678685,0.0035328,185.55599798429856,293.2641606925346,-1.8769044912381299
0.26693050276283,0.003544,185.59487455040352,293.2641606925346,-1.8769044912381299
0.267894585842786,0.0035567999999999997,185.6392462877834,293.2641606925346,-1.8769044912381299
0.2686779033452503,0.0035672,185.67525248648877,293.2641606925346,-1.8769044912381299
0.2697022416177036,0.0035808,185.72227580280708,293.2641606925346,-1.8769044912381299
0.27000351758018987,0.0035848,185.73609292762524,293.2641606925346,-1.8769044912381299
0.2707265798901569,0.0035943999999999998,185.7692295179866,293.2641606925346,-1.8769044912381299
0.2709676006601459,0.0035976,185.78026737560276,293.2641606925346,-1.8769044912381299
0.27157015258511846,0.0036056,185.80784528096743,293.2641606925346,-1.8769044912381299
0.27361882913002505,0.0036328,185.90143217378628,293.2641606925346,-1.8769044912381299
0.2750649537499591,0.003652,185.96732904588237,293.2641606925346,-1.8769044912381299
0.2763905679848987,0.0036696,186.02761591515497,293.2641606925346,-1.8769044912381299
0.2772341406798602,0.0036807999999999997,186.0659215805088,293.2641606925346,-1.8769044912381299
0.28277761838960747,0.0037543999999999998,186.31652310003037,293.2641606925346,-1.8769044912381299
0.284103232624547,0.0037719999999999997,186.37616479993667,293.2641606925346,-1.8769044912381299
0.2856698676294756,0.0037928,186.44651070183627,293.2641606925346,-1.8769044912381299
0.28741726821189595,0.003816,186.52479618207377,293.2641606925346,-1.8769044912381299
0.2903095174517641,0.0038544,186.65396549786723,293.2641606925346,-1.8769044912381299
0.29163513168670363,0.003872,186.7130002772018,293.2641606925346,-1.8769044912381299
0.29229793880417343,0.0038808,186.74247841552756,293.2641606925346,-1.8769044912381299
0.2933222770766267,0.0038943999999999997,186.7879843139045,293.2641606925346,-1.8769044912381299
0.2941658497715883,0.0039056,186.82541324155937,293.2641606925346,-1.8769044912381299
0.2963350367014894,0.0039344,186.92146734638817,293.2641606925346,-1.8769044912381299
0.29814269247640696,0.0039584,187.00130314103592,293.2641606925346,-1.8769044912381299
0.29952856190384375,0.0039768,187.06238280485084,293.2641606925346,-1.8769044912381299
0.30037213459880535,0.003988,187.09950777175766,293.2641606925346,-1.8769044912381299
0.3142936876106956,0.004172834566913383,187.70642996509804,293.2641606925346,-1.8769044912381299
0.3519004490812755,0.004672134426885377,189.29563978337768,293.2641606925346,-1.8769044912381299
0.38372155494099697,0.005094618923784757,190.58920354368206,293.2641606925346,-1.8769044912381299
0.4140962468980038,0.005497899579915984,191.78545029848235,293.2641606925346,-1.8769044912381299
0.4386852832441521,0.005824364872974595,192.7289501615303,293.2641606925346,-1.8769044912381299
0.45314942227129823,0.006016403280656131,193.27431413137566,293.2641606925346,-1.8769044912381299
0.47339921690930276,0.006285257051410282,194.0265520097229,293.2641606925346,-1.8769044912381299
0.48641694203373426,0.006458091618323665,194.50351360302759,293.2641606925346,-1.8769044912381299
0.5167916339907411,0.006861372274454891,195.59746926313844,293.2641606925346,-1.8769044912381299
0.5196844617961703,0.0068997799559911985,195.70032989838003,293.2641606925346,-1.8769044912381299
0.5500591537531772,0.007303060612122424,196.76721801874095,293.2641606925346,-1.8769044912381299
0.5529519815586064,0.007341468293658731,196.8676127981533,293.2641606925346,-1.8769044912381299
0.5847730874183278,0.007763952790558111,197.95876630002587,293.2641606925346,-1.8769044912381299
0.6773435771920628,0.008992998599719944,201.00841411391306,293.2641606925346,-1.8769044912381299
0.684575646705636,0.009089017803560712,201.2395881781241,293.2641606925346,-1.8769044912381299
0.7554499279386518,0.01003000600120024,203.45683405731853,293.2641606925346,-1.8769044912381299
0.7612355835495104,0.010106821364272855,203.6341706364251,293.2641606925346,-1.8769044912381299
0.7713604808685126,0.01024124824964993,203.9432499729178,293.2641606925346,-1.8769044912381299
0.7930566894092317,0.010529305861172233,204.60028470350235,293.2641606925346,-1.8769044912381299
0.7988423450200901,0.010606121224244848,204.7743052311441,293.2641606925346,-1.8769044912381299
0.8451275899069577,0.011220644128825764,206.14920014421116,293.2641606925346,-1.8769044912381299
0.866823798447677,0.01150870174034807,206.78354135761066,293.2641606925346,-1.8769044912381299
0.8971984904046837,0.011911982396479295,207.66131263842232,293.2641606925346,-1.8769044912381299
0.9304660101671197,0.012353670734146829,208.6094870619478,293.2641606925346,-1.8769044912381299
0.9376980796806927,0.012449689937987597,208.81385170389626,293.2641606925346,-1.8769044912381299
0.9651799438322703,0.012814562912582516,209.5848945982976,293.2641606925346,-1.8769044912381299
1.0013402914001357,0.013294658931786357,210.58650290563375,293.2641606925346,-1.8769044912381299
1.0302685694544278,0.01367873574714943,211.37766839960108,293.2641606925346,-1.8769044912381299
1.0461791223842887,0.01388997799559912,211.809114775077,293.2641606925346,-1.8769044912381299
1.0678753309250077,0.014178035607121425,212.39334915501317,293.2641606925346,-1.8769044912381299
1.0968036089793,0.014562112422484497,213.16517721946897,293.2641606925346,-1.8769044912381299
1.1141605758118753,0.014792558511702341,213.62446386986122,293.2641606925346,-1.8769044912381299
1.1184998175200191,0.014850170034006802,213.7388484773839,293.2641606925346,-1.8769044912381299
1.1401960260607382,0.015138227645529106,214.30819592772528,293.2641606925346,-1.8769044912381299
1.1879276848503204,0.015771954390878175,215.54609460499387,293.2641606925346,-1.8769044912381299
1.2197487907100422,0.01619443888777756,216.36059873135986,293.2641606925346,-1.8769044912381299
1.2284272741263296,0.016309661932386477,216.58129253253418,293.2641606925346,-1.8769044912381299
1.2906230719430578,0.017135427085417085,218.14550965074415,293.2641606925346,-1.8769044912381299
1.2993015553593452,0.017250650130026003,218.36141168589234,293.2641606925346,-1.8769044912381299
1.3137656943864917,0.017442688537707543,218.72000277844052,293.2641606925346,-1.8769044912381299
1.3586045253706445,0.018038007601520304,219.82197356747622,293.2641606925346,-1.8769044912381299
1.3745150783005051,0.018249249849969992,220.2095739262985,293.2641606925346,-1.8769044912381299
1.3875328034249368,0.018422084416883377,220.52540163960094,293.2641606925346,-1.8769044912381299
1.442496531728092,0.019151830366073215,221.84635339954457,293.2641606925346,-1.8769044912381299
1.4960138461285324,0.019862372474494898,223.11380722191393,293.2641606925346,-1.8769044912381299
1.5379598493072564,0.020419283856771355,224.0948951146142,293.2641606925346,-1.8769044912381299
1.56110247175069,0.020726545309061813,224.63171596295044,293.2641606925346,-1.8769044912381299
1.572673782972407,0.020880176035207042,224.89896185097518,293.2641606925346,-1.8769044912381299
1.6059413027348428,0.021321864372874574,225.6630550983283,293.2641606925346,-1.8769044912381299
1.6146197861511304,0.021437087417483496,225.86136539223372,293.2641606925346,-1.8769044912381299
1.6580122032325688,0.022013202640528105,226.8467488807088,293.2641606925346,-1.8769044912381299
1.717315173243868,0.022800560112022406,228.17732520906728,293.2641606925346,-1.8769044912381299
1.7317793122710141,0.022992598519703943,228.49912275539234,293.2641606925346,-1.8769044912381299
1.7491362791035896,0.023223044608921786,228.88389947142065,293.2641606925346,-1.8769044912381299
1.7679396598388792,0.023472694538907782,229.29906436002148,293.2641606925346,-1.8769044912381299
1.8012071796013152,0.023914382876575314,230.02939268900306,293.2641606925346,-1.8769044912381299
1.8605101496126144,0.024701740348069615,231.31836650611973,293.2641606925346,-1.8769044912381299
1.8720814608343312,0.024855371074214844,231.5679945092427,293.2641606925346,-1.8769044912381299
1.9096882223049112,0.02535467093418684,232.37516109050532,293.2641606925346,-1.8769044912381299
1.921259533526628,0.025508301660332067,232.62226973565262,293.2641606925346,-1.8769044912381299
1.9299380169429157,0.02562352470494099,232.80722049254186,293.2641606925346,-1.8769044912381299
1.9371700864564887,0.025719543908781756,232.96109848212856,293.2641606925346,-1.8769044912381299
1.9501878115809204,0.02589237847569514,233.23751545595235,293.2641606925346,-1.8769044912381299
2.0210620928139362,0.026833366673334667,234.73001424888704,293.2641606925346,-1.8769044912381299
2.0254013345220803,0.02689097819563913,234.82072292578718,293.2641606925346,-1.8769044912381299
2.065900923798089,0.02742868573714743,235.6637138323535,293.2641606925346,-1.8769044912381299
2.1150789964903858,0.028081616323264655,236.67872990239047,293.2641606925346,-1.8769044912381299
2.136775205031105,0.028369673934786958,237.1236005405324,293.2641606925346,-1.8769044912381299
2.1685963108908264,0.028792158431686338,237.7729039770379,293.2641606925346,-1.8769044912381299
2.21054231406955,0.02934906981396279,238.62315474283398,293.2641606925346,-1.8769044912381299
2.226452866999411,0.029560312062412483,238.9440146994888,293.2641606925346,-1.8769044912381299
2.278523767497137,0.030251650330066014,239.9879045512847,293.2641606925346,-1.8769044912381299
2.3074520455514294,0.030635727145429087,240.56382194434485,293.2641606925346,-1.8769044912381299
2.3653086016600136,0.03140388077615523,241.70727766671519,293.2641606925346,-1.8769044912381299
2.439075710698459,0.03238327665533107,243.14948511010834,293.2641606925346,-1.8769044912381299
2.4781288860717536,0.03290178035607122,243.90611437433398,293.2641606925346,-1.8769044912381299
2.5779314453590616,0.03422684536907382,245.81889264320475,293.2641606925346,-1.8769044912381299
2.602520481705209,0.03455331066213242,246.28569543712553,293.2641606925346,-1.8769044912381299
2.6328951736622166,0.034956591318263654,246.85996617111655,293.2641606925346,-1.8769044912381299
2.6676091073273667,0.035417483496699334,247.51312115463065,293.2641606925346,-1.8769044912381299
2.696537385381659,0.035801560312062414,248.05488861300034,293.2641606925346,-1.8769044912381299
2.732697732949525,0.03628165633126626,248.7289208995303,293.2641606925346,-1.8769044912381299
2.760179597101102,0.03664652930586117,249.2388615646917,293.2641606925346,-1.8769044912381299
2.7876614612526796,0.03701140228045609,249.74682590315746,293.2641606925346,-1.8769044912381299
2.816589739306972,0.03739547909581917,250.2794198224505,293.2641606925346,-1.8769044912381299
2.852750086874837,0.037875575115023,250.9421716866238,293.2641606925346,-1.8769044912381299
2.888910434442703,0.038355671134226846,251.6016552254999,293.2641606925346,-1.8769044912381299
2.9323028515241414,0.03893178635727146,252.38880103806062,293.2641606925346,-1.8769044912381299
2.9872665798272955,0.039661532306461286,253.37936119910358,293.2641606925346,-1.8769044912381299
3.0118556161734444,0.0399879975995199,253.8202026249906,293.2641606925346,-1.8769044912381299
3.0176412717843033,0.040064812962592525,253.92372576399563,293.2641606925346,-1.8769044912381299
3.058140861060312,0.04060252050410082,254.64623257218136,293.2641606925346,-1.8769044912381299
3.1073189337526084,0.04125545109021804,255.51856477335306,293.2641606925346,-1.8769044912381299
3.169514731569337,0.04208121624324865,256.61413567909557,293.2641606925346,-1.8769044912381299
3.1883181123046267,0.042330866173234644,256.94369998493954,293.2641606925346,-1.8769044912381299
3.2215856320670633,0.042772554510902186,257.52492437299753,293.2641606925346,-1.8769044912381299
3.2403890128023534,0.04302220444088818,257.8524069967321,293.2641606925346,-1.8769044912381299
3.266424463051216,0.043367873574714944,258.30462359416117,293.2641606925346,-1.8769044912381299
3.2996919828136515,0.04380956191238247,258.8804154541708,293.2641606925346,-1.8769044912381299
3.3098168801326544,0.043943988797759556,259.05520649654204,293.2641606925346,-1.8769044912381299
3.3199417774516564,0.044078415683136626,259.2297891319565,293.2641606925346,-1.8769044912381299
3.38069116136567,0.044884976995399076,260.2729573976925,293.2641606925346,-1.8769044912381299
3.4125122672253916,0.04530746149229846,260.8164597949452,293.2641606925346,-1.8769044912381299
3.4298692340579673,0.04553790758151631,261.1120824284137,293.2641606925346,-1.8769044912381299
3.489172204069266,0.0463252650530106,262.1177532506616,293.2641606925346,-1.8769044912381299
3.5267789655398456,0.04682456491298259,262.7520430715611,293.2641606925346,-1.8769044912381299
3.570171382621284,0.047400680136027204,263.480647416202,293.2641606925346,-1.8769044912381299
3.581742693843001,0.04755431086217243,263.6743575857932,293.2641606925346,-1.8769044912381299
3.5904211772592887,0.04766953390678136,263.8194800861489,293.2641606925346,-1.8769044912381299
3.6338135943407273,0.04824564912982597,264.5430506196857,293.2641606925346,-1.8769044912381299
3.665634700200448,0.04866813362672534,265.0715291350236,293.2641606925346,-1.8769044912381299
3.677206011422165,0.04882176435287057,265.263259150213,293.2641606925346,-1.8769044912381299
3.691670150449312,0.049013802760552116,265.5025911031139,293.2641606925346,-1.8769044912381299
3.7394018092388936,0.04964752950590118,266.2898045623593,293.2641606925346,-1.8769044912381299
3.7437410509470372,0.04970514102820564,266.36117453294213,293.2641606925346,-1.8769044912381299
3.7582051899741833,0.04989717943588717,266.59884177705015,293.2641606925346,-1.8769044912381299
3.775562156806759,0.050127625525105024,266.88357209862727,293.2641606925346,-1.8769044912381299
3.787133468028476,0.05028125625125025,267.07310875738364,293.2641606925346,-1.8769044912381299
3.797258365347478,0.05041568313662732,267.2387681393655,293.2641606925346,-1.8769044912381299
3.811722504374624,0.050607721544308856,267.47512588217137,293.2641606925346,-1.8769044912381299
3.8232938155963407,0.050761352270454085,267.66396032577495,293.2641606925346,-1.8769044912381299
3.9129714775646467,0.051951990398079614,269.119944847672,293.2641606925346,-1.8769044912381299
3.931774858299937,0.05220164032806561,269.42357495201435,293.2641606925346,-1.8769044912381299
3.947685411229797,0.0524128825765153,269.68005066503855,293.2641606925346,-1.8769044912381299
3.9520246529379413,0.052470494098819764,269.74992858054503,293.2641606925346,-1.8769044912381299
3.992524242213951,0.05300820164032807,270.4006859135211,293.2641606925346,-1.8769044912381299
4.03302383148996,0.05354590918183637,271.0488738161809,293.2641606925346,-1.8769044912381299
4.066291351252396,0.053987597519503897,271.5794169338612,293.2641606925346,-1.8769044912381299
4.089433973695829,0.054294858971794355,271.94749243512683,293.2641606925346,-1.8769044912381299
4.138612046388126,0.05494778955791159,272.72696642003064,293.2641606925346,-1.8769044912381299
4.15886184102613,0.05521664332866573,273.046875373149,293.2641606925346,-1.8769044912381299
4.203700672010284,0.0558119623924785,273.75309126927584,293.2641606925346,-1.8769044912381299
4.264450055924297,0.05661852370474095,274.7052312194709,293.2641606925346,-1.8769044912381299
4.280360608854158,0.05682976595319064,274.9537252109293,293.2641606925346,-1.8769044912381299
4.294824747881304,0.057021804360872175,275.17931641606856,293.2641606925346,-1.8769044912381299
4.30928888690845,0.05721384276855371,275.4046115134998,293.2641606925346,-1.8769044912381299
4.344002820573601,0.057674734946989395,275.94411986633366,293.2641606925346,-1.8769044912381299
4.361359787406177,0.057905181036207246,276.2132433206119,293.2641606925346,-1.8769044912381299
4.419216343514761,0.05867333466693339,277.1073199524469,293.2641606925346,-1.8769044912381299
4.429341240833763,0.05880776155231046,277.2633128580813,293.2641606925346,-1.8769044912381299
4.45682310498534,0.05917263452690538,277.68602274640205,293.2641606925346,-1.8769044912381299
4.576875458910654,0.060766553310662136,279.5208047201332,293.2641606925346,-1.8769044912381299
4.592786011840515,0.06097779555911183,279.7625522467211,293.2641606925346,-1.8769044912381299
4.615928634283948,0.061285057011402286,280.1136027810861,293.2641606925346,-1.8769044912381299
4.618821462089377,0.06132346469293859,280.1574357831637,293.2641606925346,-1.8769044912381299
4.627499945505665,0.061438687737547515,280.2888705940381,293.2641606925346,-1.8769044912381299
4.652088981851812,0.06176515303060612,280.66074818857385,293.2641606925346,-1.8769044912381299
4.686802915516964,0.062226045209041805,281.18444945254925,293.2641606925346,-1.8769044912381299
4.704159882349539,0.062456491298259656,281.4457326350671,293.2641606925346,-1.8769044912381299
4.7200704352794,0.06266773354670935,281.68491211842024,293.2641606925346,-1.8769044912381299
4.733088160403831,0.06284056811362272,281.88037063557465,293.2641606925346,-1.8769044912381299
4.735980988209261,0.06287897579515904,281.9237773766754,293.2641606925346,-1.8769044912381299
4.75478436894455,0.06312862572514504,282.2056695696258,293.2641606925346,-1.8769044912381299
4.767802094068982,0.06330146029205841,282.400571071707,293.2641606925346,-1.8769044912381299
4.790944716512415,0.06360872174434887,282.746550967041,293.2641606925346,-1.8769044912381299
4.808301683344991,0.06383916783356672,283.0056083142293,293.2641606925346,-1.8769044912381299
4.909550656535013,0.06518343668733746,284.5095704702239,293.2641606925346,-1.8769044912381299
4.934139692881162,0.06550990198039608,284.8729869289949,293.2641606925346,-1.8769044912381299
4.973192868254457,0.06602840568113623,285.4487294018443,293.2641606925346,-1.8769044912381299
5.003567560211463,0.06643168633726745,285.89531093510436,293.2641606925346,-1.8769044912381299
5.041174321682044,0.06693098619723946,286.4467592288899,293.2641606925346,-1.8769044912381299
5.058531288514619,0.0671614322864573,286.7007324850955,293.2641606925346,-1.8769044912381299
5.07444184144448,0.06737267453490699,286.9332429039056,293.2641606925346,-1.8769044912381299
5.096138049985198,0.06766073214642929,287.2498448882708,293.2641606925346,-1.8769044912381299
5.100477291693342,0.06771834366873375,287.31310215632294,293.2641606925346,-1.8769044912381299
5.125066328039491,0.06804480896179237,287.6711643549813,293.2641606925346,-1.8769044912381299
5.162673089510071,0.06854410882176436,288.2174956943167,293.2641606925346,-1.8769044912381299
5.198833437077936,0.0690242048409682,288.74135248464717,293.2641606925346,-1.8769044912381299
5.213297576105083,0.06921624324864974,288.9504970800925,293.2641606925346,-1.8769044912381299
5.253797165381091,0.06975395079015803,289.53490143328224,293.2641606925346,-1.8769044912381299
5.275493373921811,0.07004200840168034,289.8472523586865,293.2641606925346,-1.8769044912381299
5.330457102224965,0.07077175435087017,290.636307460985,293.2641606925346,-1.8769044912381299
5.355046138571114,0.07109821964392879,290.9882778359593,293.2641606925346,-1.8769044912381299
5.36951027759826,0.07129025805161032,291.195024806005,293.2641606925346,-1.8769044912381299
5.394099313944409,0.07161672334466894,291.54599687408006,293.2641606925346,-1.8769044912381299
5.414349108582414,0.0718855771154231,291.83456442207284,293.2641606925346,-1.8769044912381299
5.438938144928561,0.0722120424084817,292.1844026308919,293.2641606925346,-1.8769044912381299
5.459187939566566,0.07248089617923585,292.47204177129646,293.2641606925346,-1.8769044912381299
5.5228301512860085,0.0733258651730346,293.3733534074037,293.2641606925346,-1.8769044912381299
5.534401462507725,0.07347949589917983,293.53679212852103,293.2641606925346,-1.8769044912381299
5.583579535200022,0.07413242648529707,294.2299251621006,293.2641606925346,-1.8769044912381299
5.606722157643457,0.07443968793758753,294.555281202709,293.2641606925346,-1.8769044912381299
5.670364369362899,0.07528465693138628,295.44732084378256,293.2641606925346,-1.8769044912381299
5.690614164000904,0.07555351070214043,295.7303316679408,293.2641606925346,-1.8769044912381299
5.70218547522262,0.07570714142828566,295.89187579439385,293.2641606925346,-1.8769044912381299
5.736899408887771,0.07616803360672135,296.37574281985616,293.2641606925346,-1.8769044912381299
5.745577892304059,0.07628325665133028,296.49653099347535,293.2641606925346,-1.8769044912381299
5.754256375720346,0.07639847969593919,296.6172480340448,293.2641606925346,-1.8769044912381299
5.788970309385497,0.07685937187437487,297.09940783935457,293.2641606925346,-1.8769044912381299
5.797648792801785,0.0769745949189838,297.21977144015773,293.2641606925346,-1.8769044912381299
5.81211293182893,0.07716663332666533,297.4202214100706,293.2641606925346,-1.8769044912381299
5.878647971353803,0.0780500100020004,298.33979701825405,293.2641606925346,-1.8769044912381299
5.913361905018953,0.07851090218043609,298.8179637428012,293.2641606925346,-1.8769044912381299
5.952415080392249,0.07902940588117624,299.3545946749649,293.2641606925346,-1.8769044912381299
5.985682600154684,0.07947109421884377,299.81064257976067,293.2641606925346,-1.8769044912381299
6.026182189430694,0.08000880176035208,300.36449930279457,293.2641606925346,-1.8769044912381299
6.068128192609417,0.08056571314262853,300.93660840979817,293.2641606925346,-1.8769044912381299
6.081145917733849,0.08073854770954192,301.11384563801585,293.2641606925346,-1.8769044912381299
6.0985028845664235,0.08096899379875976,301.3499319408883,293.2641606925346,-1.8769044912381299
6.139002473842433,0.08150670134026806,301.8997832407758,293.2641606925346,-1.8769044912381299
6.152020198966865,0.08167953590718144,302.0762204784403,293.2641606925346,-1.8769044912381299
6.157805854577723,0.08175635127025406,302.1545902853519,293.2641606925346,-1.8769044912381299
6.186734132632015,0.08214042808561713,302.5460093907015,293.2641606925346,-1.8769044912381299
6.196859029951018,0.08227485497099421,302.68283736164335,293.2641606925346,-1.8769044912381299
6.214215996783593,0.08250530106021205,302.9171969251318,293.2641606925346,-1.8769044912381299
6.243144274837884,0.08288937787557511,303.3072296810601,293.2641606925346,-1.8769044912381299
6.2619476555731755,0.08313902780556112,303.5603730633214,293.2641606925346,-1.8769044912381299
6.286536691919323,0.08346549309861973,303.8909598563589,293.2641606925346,-1.8769044912381299
6.31691138387633,0.08386877375475095,304.29863636764327,293.2641606925346,-1.8769044912381299
6.348732489736052,0.08429125825165033,304.7249069047788,293.2641606925346,-1.8769044912381299
6.383446423401202,0.08475215043008602,305.1889801077892,293.2641606925346,-1.8769044912381299
6.451427876828788,0.08565473094618924,306.0949489276224,293.2641606925346,-1.8769044912381299
6.471677671466793,0.08592358471694339,306.3640912951594,293.2641606925346,-1.8769044912381299
6.5555696778242405,0.0870374074814963,307.47562876612466,293.2641606925346,-1.8769044912381299
6.604747750516538,0.08769033806761353,308.12464058674874,293.2641606925346,-1.8769044912381299
6.623551131251828,0.08793998799759953,308.3722937594131,293.2641606925346,-1.8769044912381299
6.684300515165841,0.08874654930986198,309.170536598611,293.2641606925346,-1.8769044912381299
6.695871826387558,0.0889001800360072,309.3222615386404,293.2641606925346,-1.8769044912381299
6.717568034928277,0.0891882376475295,309.6064704694582,293.2641606925346,-1.8769044912381299
6.742157071274426,0.08951470294058812,309.928141508716,293.2641606925346,-1.8769044912381299
6.784103074453149,0.09007161432286458,310.47582050050596,293.2641606925346,-1.8769044912381299
6.814477766410156,0.0904748949789958,310.8715915435256,293.2641606925346,-1.8769044912381299
6.846298872269878,0.09089737947589518,311.28547161507083,293.2641606925346,-1.8769044912381299
6.937422948140898,0.09210722144428886,312.46654356029507,293.2641606925346,-1.8769044912381299
6.943208603751756,0.09218403680736148,312.5413273421481,293.2641606925346,-1.8769044912381299
6.948994259362615,0.09226085217043409,312.6160868246942,293.2641606925346,-1.8769044912381299
6.954779914973473,0.09233766753350671,312.6908220360501,293.2641606925346,-1.8769044912381299
6.96924405400062,0.09252970594118824,312.87755406199716,293.2641606925346,-1.8769044912381299
6.990940262541338,0.09281776355271054,313.15736895666544,293.2641606925346,-1.8769044912381299
7.0415647491363496,0.09348989797959592,313.8089566134376,293.2641606925346,-1.8769044912381299
7.069046613287927,0.09385477095419084,314.1619104442352,293.2641606925346,-1.8769044912381299
7.1109926164666515,0.0944116823364673,314.69959946263367,293.2641606925346,-1.8769044912381299
7.129795997201941,0.09466133226645329,314.9402307913603,293.2641606925346,-1.8769044912381299
7.137028066715514,0.09475735147029406,315.03271538426793,293.2641606925346,-1.8769044912381299
7.1717420003806645,0.09521824364872974,315.4761336691305,293.2641606925346,-1.8769044912381299
7.189098967213241,0.0954486897379476,315.69752885697073,293.2641606925346,-1.8769044912381299
7.232491384294679,0.09602480496099221,316.2501067466261,293.2641606925346,-1.8769044912381299
7.2700981457652585,0.0965241048209642,316.7279625550601,293.2641606925346,-1.8769044912381299
7.299026423819551,0.09690818163632726,317.0948882507309,293.2641606925346,-1.8769044912381299
7.307704907235839,0.09702340468093619,317.20485530769054,293.2641606925346,-1.8769044912381299
7.32072263236027,0.09719623924784958,317.36971044410507,293.2641606925346,-1.8769044912381299
7.353990152122706,0.0976379275855171,317.79048833635517,293.2641606925346,-1.8769044912381299
7.410400294328575,0.09838687737547509,318.50228860963057,293.2641606925346,-1.8769044912381299
7.43065008896658,0.09865573114622925,318.7572908073395,293.2641606925346,-1.8769044912381299
7.443667814091012,0.09882856571314264,318.92107768747553,293.2641606925346,-1.8769044912381299
7.492845886783308,0.09948149629925986,319.53882257836085,293.2641606925346,-1.8769044912381299
7.530452648253888,0.09998079615923185,320.01014939693226,293.2641606925346,-1.8769044912381299