File: datasets/aisi_316_L/data/M1/train_75.csv
Time(s),Strain(%),Stress(MPa),Temp(C),Log_SR(s-1)
0.0,0.0,0.0,305.7737394354058,-1.6771664230645378
0.0009510348217185187,1.9999999999999998e-05,3.5437609374999997,305.7737394354058,-1.6771664230645378
0.001787945464830815,3.76e-05,6.6622705625,305.7737394354058,-1.6771664230645378
0.0027389802865493335,5.76e-05,10.2060315,305.7737394354058,-1.6771664230645378
0.003956304858349038,8.319999999999999e-05,14.742045499999998,305.7737394354058,-1.6771664230645378
0.005363836394492445,0.00011279999999999999,19.986811687499998,305.7737394354058,-1.6771664230645378
0.006200747037604742,0.0001304,23.1053213125,305.7737394354058,-1.6771664230645378
0.006505078180554668,0.0001368,24.239324812499998,305.7737394354058,-1.6771664230645378
0.007037657680717038,0.000148,26.223830937499997,305.7737394354058,-1.6771664230645378
0.007684361359485631,0.0001616,28.633588375,305.7737394354058,-1.6771664230645378
0.008293023645385483,0.00017439999999999998,30.901595374999996,305.7737394354058,-1.6771664230645378
0.009015810109891557,0.0001896,33.5948536875,305.7737394354058,-1.6771664230645378
0.009586431002922668,0.0002016,35.72111025,305.7737394354058,-1.6771664230645378
0.010080969110216298,0.000212,37.5638659375,305.7737394354058,-1.6771664230645378
0.010841796967591112,0.00022799999999999999,40.3988746875,305.7737394354058,-1.6771664230645378
0.011450459253490966,0.0002408,42.6668816875,305.7737394354058,-1.6771664230645378
0.011754790396440892,0.0002472,43.8008851875,305.7737394354058,-1.6771664230645378
0.012135204325128298,0.00025519999999999997,45.21838956249999,305.7737394354058,-1.6771664230645378
0.012439535468078224,0.00026159999999999996,46.35239306249999,305.7737394354058,-1.6771664230645378
0.014341605111515263,0.0003016,53.4399149375,305.7737394354058,-1.6771664230645378
0.015520888290446223,0.00032639999999999996,57.83417849999999,305.7737394354058,-1.6771664230645378
0.016243674754952298,0.0003416,60.5274368125,305.7737394354058,-1.6771664230645378
0.01677625425511467,0.0003528,62.5119429375,305.7737394354058,-1.6771664230645378
0.01833595136273304,0.0003856,68.323710875,305.7737394354058,-1.6771664230645378
0.019020696434370373,0.00039999999999999996,70.87521874999999,305.7737394354058,-1.6771664230645378
0.020580393541988744,0.0004328,76.6869866875,305.7737394354058,-1.6771664230645378
0.02080864189920119,0.00043759999999999996,77.53748931249999,305.7737394354058,-1.6771664230645378
0.021227097220757336,0.00044639999999999995,79.09674412499999,305.7737394354058,-1.6771664230645378
0.021341221399363557,0.00044879999999999996,79.5219954375,305.7737394354058,-1.6771664230645378
0.02290091850698193,0.0004816,85.333763375,305.7737394354058,-1.6771664230645378
0.023699787757225484,0.0004984,88.3105225625,305.7737394354058,-1.6771664230645378
0.02396607750730667,0.000504,89.302775625,305.7737394354058,-1.6771664230645378
0.02434649143599408,0.000512,90.72028,305.7737394354058,-1.6771664230645378
0.024917112329025187,0.0005239999999999999,92.84653656249999,305.7737394354058,-1.6771664230645378
0.025868147150743707,0.000544,96.3902975,305.7737394354058,-1.6771664230645378
0.02602031272221867,0.0005472,96.95729924999999,305.7737394354058,-1.6771664230645378
0.02697134754393719,0.0005672,100.5010601875,305.7737394354058,-1.6771664230645378
0.028683210223030525,0.0006032,106.879829875,305.7737394354058,-1.6771664230645378
0.02898754136598045,0.0006096,108.01383337499999,305.7737394354058,-1.6771664230645378
0.02967228643761778,0.000624,110.56534125,305.7737394354058,-1.6771664230645378
0.030395072902123853,0.0006391999999999999,113.25859956249998,305.7737394354058,-1.6771664230645378
0.03069940404507378,0.0006456,114.3926030625,305.7737394354058,-1.6771664230645378
0.03199281140261097,0.0006728,119.2121179375,305.7737394354058,-1.6771664230645378
0.03343838433162311,0.0007032,124.5986345625,305.7737394354058,-1.6771664230645378
0.03381879826031052,0.0007111999999999999,126.01613893749999,305.7737394354058,-1.6771664230645378
0.03594911626096001,0.0007559999999999999,133.9541634375,305.7737394354058,-1.6771664230645378
0.03651973715399112,0.000768,136.08042,305.7737394354058,-1.6771664230645378
0.03709035804702223,0.00078,138.2066765625,305.7737394354058,-1.6771664230645378
0.03769902033292208,0.0007928,140.4746835625,305.7737394354058,-1.6771664230645378
0.0378131445115283,0.0007951999999999999,140.89993487499999,305.7737394354058,-1.6771664230645378
0.03910655186906548,0.0008223999999999999,145.71944975,305.7737394354058,-1.6771664230645378
0.039829338333571565,0.0008376,148.4127080625,305.7737394354058,-1.6771664230645378
0.04112274569110875,0.0008648,153.23222293749998,305.7737394354058,-1.6771664230645378
0.04222594608430223,0.000888,157.342985625,305.7737394354058,-1.6771664230645378
0.04241615304864593,0.000892,158.0517378125,305.7737394354058,-1.6771664230645378
0.04313893951315201,0.0009071999999999999,160.744996125,305.7737394354058,-1.6771664230645378
0.044166057120608004,0.0009287999999999999,164.57225793749998,305.7737394354058,-1.6771664230645378
0.04496492637085157,0.0009456,167.549017125,305.7737394354058,-1.6771664230645378
0.045725754228226376,0.0009616,170.384025875,305.7737394354058,-1.6771664230645378
0.04717132715723853,0.000992,172.410280130524,305.7737394354058,-1.6771664230645378
0.04800823780035082,0.0010096,172.5089376582706,305.7737394354058,-1.6771664230645378
0.04823648615756326,0.0010144,172.53572755444748,305.7737394354058,-1.6771664230645378
0.04903535540780682,0.0010312,172.62910532919184,305.7737394354058,-1.6771664230645378
0.049529893515100454,0.0010416,172.6866133752312,305.7737394354058,-1.6771664230645378
0.05010051440813157,0.0010536,172.75269128012565,305.7737394354058,-1.6771664230645378
0.05158412873001245,0.0010848,172.9231345783128,305.7737394354058,-1.6771664230645378
0.05211670823017482,0.001096,172.98385161272444,305.7737394354058,-1.6771664230645378
0.0528394946946809,0.0011112,173.06586766501198,305.7737394354058,-1.6771664230645378
0.053372074194843265,0.0011224,173.1260208425566,305.7737394354058,-1.6771664230645378
0.05375248812353067,0.0011304,173.16884416153783,305.7737394354058,-1.6771664230645378
0.05462744015951171,0.0011488,173.2668917464974,305.7737394354058,-1.6771664230645378
0.054779605730986676,0.001152,173.2838807914732,305.7737394354058,-1.6771664230645378
0.05599693030278638,0.0011776,173.41913682430325,305.7737394354058,-1.6771664230645378
0.05656755119581749,0.0011895999999999999,173.48214288013386,305.7737394354058,-1.6771664230645378
0.056986006517373636,0.0011983999999999999,173.52818989594078,305.7737394354058,-1.6771664230645378
0.05725229626745482,0.001204,173.55742389551983,305.7737394354058,-1.6771664230645378
0.05827941387491082,0.0012255999999999999,173.66969033763735,305.7737394354058,-1.6771664230645378
0.058850034767941935,0.0012376,173.7317270785788,305.7737394354058,-1.6771664230645378
0.05938261426810431,0.0012488,173.78941671482912,305.7737394354058,-1.6771664230645378
0.06185530480457246,0.0013008,174.05466173505846,305.7737394354058,-1.6771664230645378
0.06204551176891615,0.0013047999999999998,174.0748922870967,305.7737394354058,-1.6771664230645378
0.062273760126128605,0.0013096,174.09913705029686,305.7737394354058,-1.6771664230645378
0.06280633962629098,0.0013208,174.1555737883487,305.7737394354058,-1.6771664230645378
0.06356716748366578,0.0013368,174.23587500505622,305.7737394354058,-1.6771664230645378
0.06390954001948446,0.001344,174.2718881731676,305.7737394354058,-1.6771664230645378
0.06467036787685927,0.0013599999999999999,174.35164914173427,305.7737394354058,-1.6771664230645378
0.06596377523439645,0.0013871999999999999,174.4864079659312,305.7737394354058,-1.6771664230645378
0.06680068587750874,0.0014047999999999999,174.57305603445107,305.7737394354058,-1.6771664230645378
0.06744738955627734,0.0014184,174.6397217044049,305.7737394354058,-1.6771664230645378
0.06767563791348978,0.0014232,174.6631911846479,305.7737394354058,-1.6771664230645378
0.0684364657708646,0.0014391999999999999,174.74120078504876,305.7737394354058,-1.6771664230645378
0.06953966616405809,0.0014624,174.85371658765885,305.7737394354058,-1.6771664230645378
0.07140369441462638,0.0015015999999999999,175.0422603215764,305.7737394354058,-1.6771664230645378
0.07265906037929482,0.0015279999999999998,175.16815817147153,305.7737394354058,-1.6771664230645378
0.07296339152224475,0.0015344,175.19855075848344,305.7737394354058,-1.6771664230645378
0.07345792962953838,0.0015448,175.2478334793926,305.7737394354058,-1.6771664230645378
0.0743328816655194,0.0015631999999999998,175.33471017120027,305.7737394354058,-1.6771664230645378
0.07528391648723794,0.0015831999999999999,175.42869025279055,305.7737394354058,-1.6771664230645378
0.07608278573748149,0.0015999999999999999,175.5072762401687,305.7737394354058,-1.6771664230645378
0.07642515827330017,0.0016072,175.54085736258907,305.7737394354058,-1.6771664230645378
0.07657732384477513,0.0016104,175.55576346796283,305.7737394354058,-1.6771664230645378
0.0778707312023123,0.0016376,175.68200233219187,305.7737394354058,-1.6771664230645378
0.07836526930960594,0.001648,175.73005369108674,305.7737394354058,-1.6771664230645378
0.07912609716698076,0.001664,175.8037485753409,305.7737394354058,-1.6771664230645378
0.0814085807391052,0.001712,176.02319266578357,305.7737394354058,-1.6771664230645378
0.08270198809664239,0.0017392,176.14647892128352,305.7737394354058,-1.6771664230645378
0.08350085734688593,0.001756,176.22225074959726,305.7737394354058,-1.6771664230645378
0.08395735406131083,0.0017656,176.26542199580467,305.7737394354058,-1.6771664230645378
0.08429972659712949,0.0017728,176.29774037916673,305.7737394354058,-1.6771664230645378
0.08475622331155439,0.0017824,176.34075204027005,305.7737394354058,-1.6771664230645378
0.0850605544545043,0.0017888,176.36937629863448,305.7737394354058,-1.6771664230645378
0.08544096838319172,0.0017967999999999999,176.40510051702802,305.7737394354058,-1.6771664230645378
0.08612571345482906,0.0018112,176.4692481804047,305.7737394354058,-1.6771664230645378
0.08692458270507261,0.001828,176.5438362690516,305.7737394354058,-1.6771664230645378
0.08730499663376001,0.001836,176.57926040071294,305.7737394354058,-1.6771664230645378
0.08840819702695349,0.0018591999999999999,176.6816515463042,305.7737394354058,-1.6771664230645378
0.08882665234850964,0.0018679999999999999,176.72035906297677,305.7737394354058,-1.6771664230645378
0.08920706627719704,0.0018759999999999998,176.75548604667426,305.7737394354058,-1.6771664230645378
0.09004397692030934,0.0018935999999999998,176.83256042652013,305.7737394354058,-1.6771664230645378
0.09095697034915912,0.0019127999999999999,176.91632362879105,305.7737394354058,-1.6771664230645378
0.09160367402792773,0.0019264,176.97545761885686,305.7737394354058,-1.6771664230645378
0.09274491581398994,0.0019504,177.079416067849,305.7737394354058,-1.6771664230645378
0.09422853013587083,0.0019816,177.21381922383034,305.7737394354058,-1.6771664230645378
0.09529368913619556,0.0020039999999999997,177.30980533160596,305.7737394354058,-1.6771664230645378
0.0959784342078329,0.0020184,177.37128979906345,305.7737394354058,-1.6771664230645378
0.0963588481365203,0.0020264,177.40537390926048,305.7737394354058,-1.6771664230645378
0.09658709649373276,0.0020312,177.42579918661414,305.7737394354058,-1.6771664230645378
0.09837504195856357,0.0020688,177.58515103727757,305.7737394354058,-1.6771664230645378
0.09879349728011971,0.0020775999999999998,177.62228255945593,305.7737394354058,-1.6771664230645378
0.09921195260167587,0.0020864,177.65935279426384,305.7737394354058,-1.6771664230645378
0.09985865628044446,0.0021,177.71652344185543,305.7737394354058,-1.6771664230645378
0.10012494603052564,0.0021056,177.74002230550238,305.7737394354058,-1.6771664230645378
0.10080969110216298,0.00212,177.80033630787125,305.7737394354058,-1.6771664230645378
0.10103793945937543,0.0021248,177.82040544209056,305.7737394354058,-1.6771664230645378
0.10134227060232534,0.0021311999999999998,177.84713680498984,305.7737394354058,-1.6771664230645378
0.10179876731675024,0.0021408,177.88717522367074,305.7737394354058,-1.6771664230645378
0.10221722263830638,0.0021495999999999998,177.92381563767177,305.7737394354058,-1.6771664230645378
0.10248351238838757,0.0021552,177.94710180973823,305.7737394354058,-1.6771664230645378
0.10301609188854993,0.0021663999999999997,177.99360348251597,305.7737394354058,-1.6771664230645378
0.10320629885289365,0.0021704,178.01018848846314,305.7737394354058,-1.6771664230645378
0.10332042303149987,0.0021728,178.02013377021225,305.7737394354058,-1.6771664230645378
0.10370083696018728,0.0021808,178.05325381120198,305.7737394354058,-1.6771664230645378
0.10430949924608714,0.0021936,178.1061474888349,305.7737394354058,-1.6771664230645378
0.10510836849633068,0.0022104,178.17538812865902,305.7737394354058,-1.6771664230645378
0.10552682381788682,0.0022191999999999997,178.21157510850696,305.7737394354058,-1.6771664230645378
0.1064398172467366,0.0022383999999999998,178.29033483519356,305.7737394354058,-1.6771664230645378
0.1080375557472237,0.0022719999999999997,178.42753330029785,305.7737394354058,-1.6771664230645378
0.10978745981918579,0.0023087999999999997,178.57689350590098,305.7737394354058,-1.6771664230645378
0.1112710741410667,0.00234,178.7027991200424,305.7737394354058,-1.6771664230645378
0.11172757085549156,0.0023496,178.74140736905815,305.7737394354058,-1.6771664230645378
0.11206994339131024,0.0023568,178.77032319574934,305.7737394354058,-1.6771664230645378
0.11233623314139142,0.0023623999999999997,178.7927894714156,305.7737394354058,-1.6771664230645378
0.1126786056772101,0.0023696,178.82164418786311,305.7737394354058,-1.6771664230645378
0.11518933760654698,0.0024224,179.03221045660555,305.7737394354058,-1.6771664230645378
0.11606428964252802,0.0024408,179.1051680373584,305.7737394354058,-1.6771664230645378
0.11625449660687173,0.0024448,179.12099996165537,305.7737394354058,-1.6771664230645378
0.11644470357121542,0.0024487999999999997,179.13682178699247,305.7737394354058,-1.6771664230645378
0.11739573839293393,0.0024687999999999997,179.21578022844884,305.7737394354058,-1.6771664230645378
0.11811852485744002,0.002484,179.27562191426716,305.7737394354058,-1.6771664230645378
0.1185750215718649,0.0024936,179.3133430927145,305.7737394354058,-1.6771664230645378
0.11903151828628979,0.0025031999999999997,179.35100767726604,305.7737394354058,-1.6771664230645378
0.11956409778645218,0.0025144,179.39487856621338,305.7737394354058,-1.6771664230645378
0.12116183628693927,0.002548,179.52603622573457,305.7737394354058,-1.6771664230645378
0.12215091250152654,0.0025688,179.60689111033463,305.7737394354058,-1.6771664230645378
0.12264545060882016,0.0025792,179.6472227743083,305.7737394354058,-1.6771664230645378
0.12348236125193246,0.0025968,179.7153321701224,305.7737394354058,-1.6771664230645378
0.12386277518061987,0.0026048,179.74623144864887,305.7737394354058,-1.6771664230645378
0.12458556164512595,0.00262,179.80483830398398,305.7737394354058,-1.6771664230645378
0.12546051368110697,0.0026384,179.87560632688766,305.7737394354058,-1.6771664230645378
0.12568876203831944,0.0026432,179.89403586252996,305.7737394354058,-1.6771664230645378
0.12625938293135053,0.0026552,179.9400526894378,305.7737394354058,-1.6771664230645378
0.12690608661011912,0.0026688,179.99210715557857,305.7737394354058,-1.6771664230645378
0.12770495586036268,0.0026856,180.05626712111294,305.7737394354058,-1.6771664230645378
0.1289222804321624,0.0027112,180.15373451469932,305.7737394354058,-1.6771664230645378
0.13029177057543706,0.00274,180.2629573203742,305.7737394354058,-1.6771664230645378
0.13105259843281186,0.0027559999999999998,180.32344316694267,305.7737394354058,-1.6771664230645378
0.13177538489731794,0.0027711999999999997,180.38077799775067,305.7737394354058,-1.6771664230645378
0.13204167464739913,0.0027768,180.40187042312297,305.7737394354058,-1.6771664230645378
0.1331448750405926,0.0028,180.48907718433009,305.7737394354058,-1.6771664230645378
0.13382962011222996,0.0028144,180.54306380135404,305.7737394354058,-1.6771664230645378
0.13417199264804863,0.0028216,180.57001670428258,305.7737394354058,-1.6771664230645378
0.13538931721984832,0.0028472,180.66563277519202,305.7737394354058,-1.6771664230645378
0.13599797950574816,0.0028599999999999997,180.71331503522242,305.7737394354058,-1.6771664230645378
0.1378239663634477,0.0028983999999999998,180.85586493835018,305.7737394354058,-1.6771664230645378
0.1379761319349227,0.0029016,180.86771074782902,305.7737394354058,-1.6771664230645378
0.13991624297122848,0.0029424,181.01830096703958,305.7737394354058,-1.6771664230645378
0.14113356754302817,0.0029679999999999997,181.11237327331924,305.7737394354058,-1.6771664230645378
0.14128573311450313,0.0029712,181.12411002077442,305.7737394354058,-1.6771664230645378
0.1416281056503218,0.0029784,181.15049969292468,305.7737394354058,-1.6771664230645378
0.142769347436384,0.0030023999999999997,181.2382861304336,305.7737394354058,-1.6771664230645378
0.14356821668662756,0.0030191999999999997,181.29957387165908,305.7737394354058,-1.6771664230645378
0.14391058922244623,0.0030264,181.32579931587358,305.7737394354058,-1.6771664230645378
0.14467141707982106,0.0030424,181.3839911203045,305.7737394354058,-1.6771664230645378
0.14626915558030817,0.0030759999999999997,181.5058068479008,305.7737394354058,-1.6771664230645378
0.14634523836604565,0.0030775999999999998,181.51159461762336,305.7737394354058,-1.6771664230645378
0.14737235597350165,0.0030992,181.5896150084074,305.7737394354058,-1.6771664230645378
0.1488179289025138,0.0031295999999999997,181.69906317179834,305.7737394354058,-1.6771664230645378
0.14965483954562608,0.0031471999999999997,181.76223838461027,305.7737394354058,-1.6771664230645378
0.15018741904578847,0.0031584,181.8023690641958,305.7737394354058,-1.6771664230645378
0.15091020551029455,0.0031736,181.8567434709021,305.7737394354058,-1.6771664230645378
0.1514427850104569,0.0031848,181.89674385442396,305.7737394354058,-1.6771664230645378
0.15159495058193187,0.003188,181.90816245406853,305.7737394354058,-1.6771664230645378
0.15193732311775054,0.0031952,181.93383797245318,305.7737394354058,-1.6771664230645378
0.1535731030111064,0.0032296,182.0561998096584,305.7737394354058,-1.6771664230645378
0.15421980668987498,0.0032432,182.10443508909864,305.7737394354058,-1.6771664230645378
0.15452413783282493,0.0032496,182.12710674246338,305.7737394354058,-1.6771664230645378
0.15482846897577485,0.0032559999999999998,182.1497609885278,305.7737394354058,-1.6771664230645378
0.15513280011872477,0.0032624,182.17239787483354,305.7737394354058,-1.6771664230645378
0.1558175451903621,0.0032768,182.2232676421438,305.7737394354058,-1.6771664230645378
0.15646424886913068,0.0032903999999999997,182.27123131726563,305.7737394354058,-1.6771664230645378
0.15752940786945543,0.0033128,182.35006211190793,305.7737394354058,-1.6771664230645378
0.15779569761953663,0.0033184,182.36973729562385,305.7737394354058,-1.6771664230645378
0.15867064965551766,0.0033368,182.4342933472436,305.7737394354058,-1.6771664230645378
0.1590891049770738,0.0033456,182.4651188911395,305.7737394354058,-1.6771664230645378
0.15981189144157987,0.0033607999999999997,182.51828863564603,305.7737394354058,-1.6771664230645378
0.16053467790608594,0.0033759999999999997,182.57136467814294,305.7737394354058,-1.6771664230645378
0.16080096765616714,0.0033816,182.590895506213,305.7737394354058,-1.6771664230645378
0.16175200247788565,0.0034016,182.66054572817038,305.7737394354058,-1.6771664230645378
0.16239870615665425,0.0034151999999999997,182.70781667702025,305.7737394354058,-1.6771664230645378
0.1638442790856664,0.0034456,182.81321649685262,305.7737394354058,-1.6771664230645378
0.16612676265779083,0.0034936,182.97890184995416,305.7737394354058,-1.6771664230645378
0.16681150772942818,0.003508,183.0284340232025,305.7737394354058,-1.6771664230645378
0.16745821140819675,0.0035215999999999997,183.07514164840865,305.7737394354058,-1.6771664230645378
0.1679527495154904,0.003532,183.11081179321567,305.7737394354058,-1.6771664230645378
0.1685233704085215,0.003544,183.15191879275017,305.7737394354058,-1.6771664230645378
0.16894182573007765,0.0035528,183.1820294338442,305.7737394354058,-1.6771664230645378
0.1691700740872901,0.0035575999999999997,183.19844115967103,305.7737394354058,-1.6771664230645378
0.17031131587335233,0.0035816,183.28037060824377,305.7737394354058,-1.6771664230645378
0.17080585398064593,0.0035919999999999997,183.31580684554316,305.7737394354058,-1.6771664230645378
0.17156668183802076,0.0036079999999999997,183.3702461005685,305.7737394354058,-1.6771664230645378
0.17236555108826432,0.0036247999999999996,183.4273060846469,305.7737394354058,-1.6771664230645378
0.172707923624083,0.003632,183.45172878019847,305.7737394354058,-1.6771664230645378
0.17434370351743883,0.0036663999999999998,183.56815537533245,305.7737394354058,-1.6771664230645378
0.1746860760532575,0.0036736,183.59246972967023,305.7737394354058,-1.6771664230645378
0.17529473833915735,0.0036864,183.63564940886306,305.7737394354058,-1.6771664230645378
0.17590340062505722,0.0036991999999999997,183.6787706550063,305.7737394354058,-1.6771664230645378
0.17670226987530077,0.0037159999999999997,183.73527908416767,305.7737394354058,-1.6771664230645378
0.1772728907683319,0.003728,183.77558126399725,305.7737394354058,-1.6771664230645378
0.1784141325543941,0.0037519999999999997,183.85603416212203,305.7737394354058,-1.6771664230645378
0.17917496041176892,0.0037679999999999996,183.909557953973,305.7737394354058,-1.6771664230645378
0.18069661612651855,0.0038,184.01634036250877,305.7737394354058,-1.6771664230645378
0.18134331980528715,0.0038136,184.06161662637206,305.7737394354058,-1.6771664230645378
0.18229435462700566,0.0038336,184.12808514192514,305.7737394354058,-1.6771664230645378
0.18297909969864298,0.003848,184.17585876096717,305.7737394354058,-1.6771664230645378
0.18362580337741158,0.0038615999999999998,184.22091430947643,305.7737394354058,-1.6771664230645378
0.18499529352068625,0.0038904,184.31612228532538,305.7737394354058,-1.6771664230645378
0.18556591441371736,0.0039024,184.35571110311142,305.7737394354058,-1.6771664230645378
0.18655499062830463,0.0039232,184.42421943627474,305.7737394354058,-1.6771664230645378
0.1868212803783858,0.0039288,184.44263976618296,305.7737394354058,-1.6771664230645378
0.18723973569994193,0.0039375999999999994,184.47156532392088,305.7737394354058,-1.6771664230645378
0.1888374742004291,0.0039712,184.58177723292084,305.7737394354058,-1.6771664230645378
0.18929397091485395,0.0039808,184.61319947542668,305.7737394354058,-1.6771664230645378
0.18956026066493514,0.0039864,184.63151546916933,305.7737394354058,-1.6771664230645378
0.20573095743276779,0.004326465293058612,185.72566554799678,305.7737394354058,-1.6771664230645378
0.2239944787140196,0.004710542108421685,186.92183050726146,305.7737394354058,-1.6771664230645378
0.23221306329058292,0.004883376675335067,187.44762563529414,305.7737394354058,-1.6771664230645378
0.23769211967495846,0.004998599719943989,187.79412884783736,305.7737394354058,-1.6771664230645378
0.2468238803155844,0.005190638127625526,188.36479017729832,305.7737394354058,-1.6771664230645378
0.27330598617339946,0.00574754950990198,189.9748828848213,305.7737394354058,-1.6771664230645378
0.27878504255777503,0.005862772554510902,190.30027394573355,305.7737394354058,-1.6771664230645378
0.3107462047999657,0.006534906981396279,192.15090781237328,305.7737394354058,-1.6771664230645378
0.33357560640153044,0.00701500300060012,193.42756371676128,305.7737394354058,-1.6771664230645378
0.34909959949059444,0.007341468293658731,194.2762757833474,305.7737394354058,-1.6771664230645378
0.37101582502809666,0.007802360472094419,195.44980916047857,305.7737394354058,-1.6771664230645378
0.3974979308859118,0.008359271854370874,196.8323409951519,305.7737394354058,-1.6771664230645378
0.4230668606796643,0.008896979395879176,198.13348927771085,305.7737394354058,-1.6771664230645378
0.4285459170640399,0.009012202440488098,198.40827432763155,305.7737394354058,-1.6771664230645378
0.44863579047341684,0.009434686937387478,199.40430567695176,305.7737394354058,-1.6771664230645378
0.45685437504998017,0.00960752150430086,199.8067406877804,305.7737394354058,-1.6771664230645378
0.46233343143435573,0.009722744548909782,200.07346319027022,305.7737394354058,-1.6771664230645378
0.4824233048437327,0.010145229045809162,201.04107308263636,305.7737394354058,-1.6771664230645378
0.526255755918737,0.011067013402680535,203.09926744445661,305.7737394354058,-1.6771664230645378
0.5399533968796759,0.011355071014202842,203.72859082813653,305.7737394354058,-1.6771664230645378
0.5627827984812406,0.01183516703340668,204.76379869808102,305.7737394354058,-1.6771664230645378
0.5764804394421795,0.012123224644928985,205.377063742394,305.7737394354058,-1.6771664230645378
0.6212260665812465,0.013064212842568514,207.34191141304586,305.7737394354058,-1.6771664230645378
0.6449686442468738,0.013563512702540508,208.3620205207173,305.7737394354058,-1.6771664230645378
0.6541004048874997,0.013755551110222045,208.7504570267114,305.7737394354058,-1.6771664230645378
0.6614058134000005,0.013909181836367274,209.05968561370034,305.7737394354058,-1.6771664230645378
0.6723639261687515,0.014139627925585117,209.52104252542344,305.7737394354058,-1.6771664230645378
0.6769298064890644,0.014235647129425886,209.71240800114512,305.7737394354058,-1.6771664230645378
0.6997592080906293,0.014715743148629726,210.66178671817832,305.7737394354058,-1.6771664230645378
0.7107173208593803,0.01494618923784757,211.1131909223502,305.7737394354058,-1.6771664230645378
0.7171095533078184,0.015080616123224646,211.37525653204648,305.7737394354058,-1.6771664230645378
0.7362862506531329,0.015483896779355872,212.15604084007666,305.7737394354058,-1.6771664230645378
0.7609420043828228,0.01600240048009602,213.14834943333528,305.7737394354058,-1.6771664230645378
0.7655078847031358,0.01609841968393679,213.330725914567,305.7737394354058,-1.6771664230645378
0.7728132932156365,0.016252050410082017,213.62164834456004,305.7737394354058,-1.6771664230645378
0.8111666879062653,0.01705861172234447,215.1317444710741,305.7737394354058,-1.6771664230645378
0.8303433852515797,0.017461892378475695,215.87632956339465,305.7737394354058,-1.6771664230645378
0.8641308996218954,0.018172434486897378,217.17210086230006,305.7737394354058,-1.6771664230645378
0.8696099560062711,0.018287657531506303,217.38034965036508,305.7737394354058,-1.6771664230645378
0.8787417166468969,0.018479695939187836,217.72629740245048,305.7737394354058,-1.6771664230645378
0.889699829415648,0.01871014202840568,218.13958944925378,305.7737394354058,-1.6771664230645378
0.9116160549531501,0.019171034206841367,218.9602653296846,305.7737394354058,-1.6771664230645378
0.914355583145338,0.01922864572914583,219.06230600971466,305.7737394354058,-1.6771664230645378
0.9380981608109654,0.019727945589117824,219.94171923138333,305.7737394354058,-1.6771664230645378
0.9609275624125301,0.020208041608321663,220.779158498925,305.7737394354058,-1.6771664230645378
0.9864964922062825,0.020745749149829965,221.70793209652427,305.7737394354058,-1.6771664230645378
1.0020204852953467,0.02107221444288858,222.2672510759556,305.7737394354058,-1.6771664230645378
1.0175444783844108,0.02139867973594719,222.82320059520148,305.7737394354058,-1.6771664230645378
1.0513319927547267,0.022109221844368875,224.02190025977777,305.7737394354058,-1.6771664230645378
1.0595505773312899,0.022282056411282256,224.31119250185677,305.7737394354058,-1.6771664230645378
1.079640450740667,0.022704540908181636,225.01469149773385,305.7737394354058,-1.6771664230645378
1.1070357326625446,0.023280656131226245,225.96583520860028,305.7737394354058,-1.6771664230645378
1.1627394725703626,0.024452090418083616,227.87197538112065,305.7737394354058,-1.6771664230645378
1.1782634656594266,0.02477855571114223,228.39680526385712,305.7737394354058,-1.6771664230645378
1.1837425220438023,0.02489377875575115,228.581394573558,305.7737394354058,-1.6771664230645378
1.2367067337594324,0.026007601520304062,230.34890516091764,305.7737394354058,-1.6771664230645378
1.2704942481297483,0.026718143628725745,231.4610459115296,305.7737394354058,-1.6771664230645378
1.3042817625000642,0.02742868573714743,232.5617099221089,305.7737394354058,-1.6771664230645378
1.3152398752688153,0.027659131826365275,232.9162864871511,305.7737394354058,-1.6771664230645378
1.328937516229754,0.027947189437887578,233.357891154498,305.7737394354058,-1.6771664230645378
1.3545064460235066,0.02848489697939588,234.17749913599837,305.7737394354058,-1.6771664230645378
1.3618118545360074,0.02863852770554111,234.41056168150038,305.7737394354058,-1.6771664230645378
1.4220814747641384,0.02990598119623925,236.3150683220814,305.7737394354058,-1.6771664230645378
1.4522162848782036,0.030539707941588317,237.25549629796626,305.7737394354058,-1.6771664230645378
1.4704798061594555,0.03092378475695139,237.8217493722783,305.7737394354058,-1.6771664230645378
1.4860037992485198,0.03125025005001,238.3009112298743,305.7737394354058,-1.6771664230645378
1.503354144465709,0.031615123024604924,238.8341407762978,305.7737394354058,-1.6771664230645378
1.534402130643837,0.032268053610722144,239.7823890193155,305.7737394354058,-1.6771664230645378
1.5554051801172766,0.03270974194838968,240.41961148164353,305.7737394354058,-1.6771664230645378
1.5617974125657148,0.03284416883376676,240.61288151237832,305.7737394354058,-1.6771664230645378
1.5764082295907162,0.033151430286057215,241.05348685563715,305.7737394354058,-1.6771664230645378
1.5901058705516549,0.033439487897579515,241.46511011669253,305.7737394354058,-1.6771664230645378
1.614761624281345,0.033957991598319665,242.20256393387356,305.7737394354058,-1.6771664230645378
1.6375910258829096,0.034438087617523504,242.88148539683485,305.7737394354058,-1.6771664230645378
1.667725835996975,0.03507181436287257,243.7720363335246,305.7737394354058,-1.6771664230645378
1.6805103008938513,0.035340668133626726,244.14794731136286,305.7737394354058,-1.6771664230645378
1.688728885470415,0.035513502700540114,244.38901555071143,305.7737394354058,-1.6771664230645378
1.7142978152641672,0.03605121024204841,245.1360960999315,305.7737394354058,-1.6771664230645378
1.7279954562251059,0.03633926785357071,245.5345296341895,305.7737394354058,-1.6771664230645378
1.7489985056985458,0.03678095619123825,246.14307702470714,305.7737394354058,-1.6771664230645378
1.7581302663391716,0.036972994598919784,246.40677316322376,305.7737394354058,-1.6771664230645378
1.7626961466594844,0.03706901380276055,246.53842088351453,305.7737394354058,-1.6771664230645378
1.770914731236048,0.03724184836967394,246.77505213008197,305.7737394354058,-1.6771664230645378
1.7937441328376125,0.03772194438887777,247.4301244972058,305.7737394354058,-1.6771664230645378
1.8047022456063637,0.03795239047809562,247.74340359398445,305.7737394354058,-1.6771664230645378
1.8375765839126168,0.038643728745749145,248.67881966140578,305.7737394354058,-1.6771664230645378
1.8521874009376182,0.0389509901980396,249.09246279617366,305.7737394354058,-1.6771664230645378
1.856753281257931,0.03904700940188037,249.2214650445151,305.7737394354058,-1.6771664230645378
1.8695377461548075,0.039315863172634524,249.58201481952264,305.7737394354058,-1.6771664230645378
1.884148563179809,0.03962312462492498,249.99289636754725,305.7737394354058,-1.6771664230645378
1.8914539716923098,0.03977675535107021,250.1978710210394,305.7737394354058,-1.6771664230645378
1.9060647887173112,0.04008401680336067,250.60689640736044,305.7737394354058,-1.6771664230645378
1.9234151339345005,0.04044888977795559,251.09102926361322,305.7737394354058,-1.6771664230645378
1.928894190318876,0.040564112822564516,251.24355908175306,305.7737394354058,-1.6771664230645378
1.9389391270235647,0.04077535507101421,251.5227589436978,305.7737394354058,-1.6771664230645378
1.958115824368879,0.04117863572714543,252.05421537901535,305.7737394354058,-1.6771664230645378
1.9754661695860682,0.04154350870174035,252.53331037571172,305.7737394354058,-1.6771664230645378
1.9855111062907569,0.041754750950190045,252.80993108629164,305.7737394354058,-1.6771664230645378
1.9982955711876327,0.042023604720944185,253.161205722081,305.7737394354058,-1.6771664230645378
2.0037746275720085,0.04213882776555311,253.31148356825997,305.7737394354058,-1.6771664230645378
2.013819564276697,0.0423500700140028,253.58657738952346,305.7737394354058,-1.6771664230645378
2.027517205237636,0.0426381276255251,253.96084445781307,305.7737394354058,-1.6771664230645378
2.0329962616220114,0.04275335067013403,254.11027501686104,305.7737394354058,-1.6771664230645378
2.0622178956720143,0.043367873574714944,254.9046009967351,305.7737394354058,-1.6771664230645378
2.068610128120452,0.043502300460092014,255.07777325929038,305.7737394354058,-1.6771664230645378
2.0768287126970155,0.0436751350270054,255.3001169630747,305.7737394354058,-1.6771664230645378
2.105137170682956,0.04427045409081816,256.06335459328733,305.7737394354058,-1.6771664230645378
2.12066116377202,0.044596919383876776,256.4802044950517,305.7737394354058,-1.6771664230645378
2.143490565373585,0.04507701540308062,257.0910636288194,305.7737394354058,-1.6771664230645378
2.1480564456938978,0.04517303460692139,257.2129304013768,305.7737394354058,-1.6771664230645378
2.1553618542063986,0.04532666533306662,257.40770731627225,305.7737394354058,-1.6771664230645378
2.1626672627188994,0.04548029605921185,257.6022269308113,305.7737394354058,-1.6771664230645378
2.1772780797439006,0.045787557511502305,257.9904990784279,305.7737394354058,-1.6771664230645378
2.1891493685767145,0.0460372074414883,258.30522250962696,305.7737394354058,-1.6771664230645378
2.2220237068829674,0.046728545709141825,259.1733095122837,305.7737394354058,-1.6771664230645378
2.234808171779844,0.04699739947989598,259.5095444142683,305.7737394354058,-1.6771664230645378
2.2777274467907853,0.047899979995999195,260.63288649712234,305.7737394354058,-1.6771664230645378
2.2905119116876618,0.04816883376675335,260.9658993248452,305.7737394354058,-1.6771664230645378
2.314254489353289,0.04866813362672534,261.5824348383246,305.7737394354058,-1.6771664230645378
2.348042003723605,0.04937867573514702,262.4555760764599,305.7737394354058,-1.6771664230645378
2.361739644684544,0.04966673334666934,262.80815468652224,305.7737394354058,-1.6771664230645378
2.365392348940794,0.049743548709741944,262.90204084561884,305.7737394354058,-1.6771664230645378
2.389134926606422,0.05024284856971395,263.51092845236997,305.7737394354058,-1.6771664230645378
2.392787630862672,0.05031966393278656,263.6043935999671,305.7737394354058,-1.6771664230645378
2.410137976079861,0.05068453690738148,264.04759538368654,305.7737394354058,-1.6771664230645378
2.436620081937676,0.05124144828965793,264.72166975955747,305.7737394354058,-1.6771664230645378
2.447578194706428,0.05147189437887578,264.9997606315761,305.7737394354058,-1.6771664230645378
2.4585363074751783,0.05170234046809362,265.2773663568047,305.7737394354058,-1.6771664230645378
2.4786261808845556,0.052124824964993,265.785060096724,305.7737394354058,-1.6771664230645378
2.484105237268931,0.05224004800960193,265.9232431768921,305.7737394354058,-1.6771664230645378
2.495063350037682,0.052470494098819764,266.1992532574857,305.7737394354058,-1.6771664230645378
2.5142400473829962,0.05287377475495099,266.68113600798836,305.7737394354058,-1.6771664230645378
2.5407221532408113,0.05343068613722744,267.34424323457347,305.7737394354058,-1.6771664230645378
2.548940737817375,0.05360352070414083,267.5494863350192,305.7737394354058,-1.6771664230645378
2.559898850586126,0.05383396679335867,267.8227427803804,305.7737394354058,-1.6771664230645378
2.5672042590986264,0.053987597519503897,268.004660347151,305.7737394354058,-1.6771664230645378
2.586380956443941,0.05439087817563512,268.4812359654045,305.7737394354058,-1.6771664230645378
2.5964258931486293,0.05460212042408481,268.7303207188759,305.7737394354058,-1.6771664230645378
2.615602590493944,0.05500540108021604,269.204805026138,305.7737394354058,-1.6771664230645378
2.635692463903321,0.05542788557711542,269.70043096002627,305.7737394354058,-1.6771664230645378
2.6466505766720725,0.05565833166633327,269.97015130863963,305.7737394354058,-1.6771664230645378
2.658521865504886,0.05590798159631927,270.261857343359,305.7737394354058,-1.6771664230645378
2.6795249149783253,0.056349669933986796,270.77671122216276,305.7737394354058,-1.6771664230645378
2.6913962038111388,0.05659931986397279,271.0670193493186,305.7737394354058,-1.6771664230645378
2.6987016123236396,0.05675295059011802,271.2454223023662,305.7737394354058,-1.6771664230645378
2.715138781476767,0.057098619723944796,271.6461417444032,305.7737394354058,-1.6771664230645378
2.718791485733017,0.057175435087017404,271.73506189657337,305.7737394354058,-1.6771664230645378
2.7352286548861433,0.057521104220844166,272.1346274180214,305.7737394354058,-1.6771664230645378
2.7507526479752076,0.05784756951390278,272.51113586277705,305.7737394354058,-1.6771664230645378
2.768102993192397,0.058212442488497704,272.9309601287829,305.7737394354058,-1.6771664230645378
2.7763215777689596,0.05838527705541108,273.1294659470446,305.7737394354058,-1.6771664230645378
2.7863665144736482,0.05859651930386077,273.37177321922576,305.7737394354058,-1.6771664230645378
2.8110222682033386,0.05911502300460092,273.9650875836112,305.7737394354058,-1.6771664230645378
2.8210672049080268,0.05932626525305061,274.20622597483236,305.7737394354058,-1.6771664230645378
2.830198965548653,0.059518303660732144,274.42515226961945,305.7737394354058,-1.6771664230645378
2.8502888389580296,0.05994078815763153,274.90582274524974,305.7737394354058,-1.6771664230645378
2.8594205995986557,0.06013282656531306,275.1238723527091,305.7737394354058,-1.6771664230645378
2.8639864799189683,0.06022884576915383,275.23279530222476,305.7737394354058,-1.6771664230645378
2.89960034641741,0.06097779555911183,276.0800823539369,305.7737394354058,-1.6771664230645378
2.907818930993973,0.0611506301260252,276.2750326140692,305.7737394354058,-1.6771664230645378
2.926995628339287,0.061553910782156426,276.7290827791425,305.7737394354058,-1.6771664230645378
2.964435846965854,0.06234126825365073,277.6122317952066,305.7737394354058,-1.6771664230645378
2.985438896439293,0.06278295659131826,278.1057520095956,305.7737394354058,-1.6771664230645378
2.9954838331439815,0.06299419883976795,278.34130459373523,305.7737394354058,-1.6771664230645378
3.003702417720545,0.06316703340668134,278.53380038581486,305.7737394354058,-1.6771664230645378
3.0557534533721125,0.06426165233046609,279.74820471991967,305.7737394354058,-1.6771664230645378
3.0676247422049268,0.0645113022604521,280.0240411663304,305.7737394354058,-1.6771664230645378
3.090454143806491,0.06499139827965593,280.55332858788506,305.7737394354058,-1.6771664230645378
3.112370369343993,0.06545229045809162,281.0600117831267,305.7737394354058,-1.6771664230645378
3.165334581059624,0.06656611322264454,282.2787855772544,305.7737394354058,-1.6771664230645378
3.189990334789314,0.06708461692338469,282.84343033540887,305.7737394354058,-1.6771664230645378
3.198208919365877,0.06725745149029806,283.03126668922766,305.7737394354058,-1.6771664230645378
3.221038320967442,0.06773754750950191,283.5520491827623,305.7737394354058,-1.6771664230645378
3.238388666184631,0.06810242048409683,283.94688168707614,305.7737394354058,-1.6771664230645378
3.2895265257721364,0.06917783556711343,285.1058272858455,305.7737394354058,-1.6771664230645378
3.30139781460495,0.06942748549709943,285.37386079007257,305.7737394354058,-1.6771664230645378
3.3150954555658885,0.06971554310862173,285.68266358887445,305.7737394354058,-1.6771664230645378
3.336098505039328,0.07015723144628926,286.15519648741986,305.7737394354058,-1.6771664230645378
3.347969793872142,0.07040688137627527,286.42176706024406,305.7737394354058,-1.6771664230645378
3.357101554512768,0.0705989197839568,286.62657058055464,305.7737394354058,-1.6771664230645378
3.3954549492033963,0.07140548109621925,287.48438357281094,305.7737394354058,-1.6771664230645378
3.4018471816518345,0.07153990798159632,287.626984215459,305.7737394354058,-1.6771664230645378
3.414631646548711,0.07180876175235047,287.91187238215844,305.7737394354058,-1.6771664230645378
3.4484191609190264,0.07251930386077216,288.66279577472153,305.7737394354058,-1.6771664230645378
3.470335386456529,0.07298019603920784,289.14834740555096,305.7737394354058,-1.6771664230645378
3.489512083801843,0.07338347669533907,289.5722249141381,305.7737394354058,-1.6771664230645378
3.491338435929969,0.07342188437687538,289.6125467612169,305.7737394354058,-1.6771664230645378
3.50960195721122,0.07380596119223845,290.01531382263363,305.7737394354058,-1.6771664230645378
3.5780901620159145,0.07524624924984998,291.5184651686445,305.7737394354058,-1.6771664230645378
3.603659091809667,0.07578395679135827,292.07675974370983,305.7737394354058,-1.6771664230645378
3.617356732770606,0.07607201440288058,292.37521053621117,305.7737394354058,-1.6771664230645378
3.6356202540518576,0.07645609121824365,292.7724602194639,305.7737394354058,-1.6771664230645378
3.684931761511238,0.07749309861972395,293.8411659008711,305.7737394354058,-1.6771664230645378
3.7013689306643642,0.07783876775355071,294.1961597659633,305.7737394354058,-1.6771664230645378
3.7159797476893655,0.07814602920584117,294.5111940476252,305.7737394354058,-1.6771664230645378
3.729677388650305,0.07843408681736348,294.80610023240376,305.7737394354058,-1.6771664230645378
3.7388091492909306,0.07862612522504502,295.00246972394655,305.7737394354058,-1.6771664230645378
3.757985846636245,0.07902940588117624,295.41423784984914,305.7737394354058,-1.6771664230645378
3.778075720045622,0.07945189037807562,295.8447360111271,305.7737394354058,-1.6771664230645378
3.803644649839374,0.07998959791958392,296.39135375096475,305.7737394354058,-1.6771664230645378
3.8310399317612522,0.08056571314262853,296.9754277899976,305.7737394354058,-1.6771664230645378
3.834692636017502,0.08064252850570114,297.05318107438404,305.7737394354058,-1.6771664230645378
3.8684801503878186,0.08135307061412284,297.771034854262,305.7737394354058,-1.6771664230645378
3.894049080181571,0.08189077815563113,298.31265132392633,305.7737394354058,-1.6771664230645378
3.9022676647581345,0.08206361272254452,298.4864475452066,305.7737394354058,-1.6771664230645378
3.9068335450784475,0.08215963192638528,298.5829393166746,305.7737394354058,-1.6771664230645378
3.9369683551925125,0.08279335867173435,299.218685571487,305.7737394354058,-1.6771664230645378
4.004543383933145,0.08421444288857773,300.6374392210934,305.7737394354058,-1.6771664230645378
4.026459609470646,0.08467533506701341,301.0955663272935,305.7737394354058,-1.6771664230645378
4.029199137662834,0.08473294658931786,301.15276375757713,305.7737394354058,-1.6771664230645378
4.051115363200336,0.08519383876775355,301.60979846209983,305.7737394354058,-1.6771664230645378
4.089468757890965,0.08600040008001601,302.40729565233755,305.7737394354058,-1.6771664230645378
4.097687342467529,0.08617323464692939,302.5778077994935,305.7737394354058,-1.6771664230645378
4.111384983428468,0.0864612922584517,302.8616986188382,305.7737394354058,-1.6771664230645378
4.143346145670659,0.08713342668533708,303.52267990069475,305.7737394354058,-1.6771664230645378
4.163436019080035,0.08755591118223645,303.9371362352355,305.7737394354058,-1.6771664230645378
4.168915075464411,0.08767113422684537,304.05003432413514,305.7737394354058,-1.6771664230645378
4.171654603656599,0.08772874574914984,304.10646166726264,305.7737394354058,-1.6771664230645378
4.176220483976912,0.0878247649529906,304.200475134672,305.7737394354058,-1.6771664230645378
4.1908313010019125,0.08813202640528106,304.50104920743985,305.7737394354058,-1.6771664230645378
4.210007998347227,0.08853530706141229,304.89493319601195,305.7737394354058,-1.6771664230645378
4.237403280269105,0.0891114222844569,305.4564129746969,305.7737394354058,-1.6771664230645378
4.252927273358169,0.0894378875775155,305.7739564042007,305.7737394354058,-1.6771664230645378
4.283062083472235,0.09007161432286458,306.38907675210646,305.7737394354058,-1.6771664230645378
4.293107020176923,0.09028285657131427,306.59374148356034,305.7737394354058,-1.6771664230645378
4.326894534547239,0.09099339867973595,307.2807927344078,305.7737394354058,-1.6771664230645378
4.342418527636303,0.09131986397279457,307.5957630977838,305.7737394354058,-1.6771664230645378
4.362508401045679,0.09174234846969394,308.0027206956036,305.7737394354058,-1.6771664230645378
4.378032394134744,0.09206881376275255,308.3166875330892,305.7737394354058,-1.6771664230645378
4.3899036829675575,0.09231846369273855,308.5564869484549,305.7737394354058,-1.6771664230645378
4.426430725530061,0.0930866173234647,309.2927499812168,305.7737394354058,-1.6771664230645378
4.442867894683188,0.09343228645729146,309.62329490620107,305.7737394354058,-1.6771664230645378
4.458391887772252,0.09375875175035008,309.9350385712913,305.7737394354058,-1.6771664230645378
4.495832106398819,0.09454610922184438,310.68515436994176,305.7737394354058,-1.6771664230645378
4.520487860128508,0.09506461292258452,311.1778030193678,305.7737394354058,-1.6771664230645378
4.556101726626949,0.09581356271254252,311.8875605850928,305.7737394354058,-1.6771664230645378
4.577104776100389,0.09625525105021004,312.305121304684,305.7737394354058,-1.6771664230645378
4.587149712805077,0.09646649329865974,312.50456004354396,305.7737394354058,-1.6771664230645378
4.595368297381641,0.09663932786557312,312.6676105361235,305.7737394354058,-1.6771664230645378
4.614544994726955,0.09704260852170435,313.04762005515715,305.7737394354058,-1.6771664230645378
4.626416283559768,0.09729225845169034,313.2825554222847,305.7737394354058,-1.6771664230645378
4.65837744580196,0.09796439287857572,313.913908060921,305.7737394354058,-1.6771664230645378
4.662030150058209,0.09804120824164833,313.98595492066585,305.7737394354058,-1.6771664230645378
4.66933555857071,0.09819483896779356,314.12998262912464,305.7737394354058,-1.6771664230645378
4.677554143147273,0.09836767353470695,314.2919087961485,305.7737394354058,-1.6771664230645378
4.680293671339461,0.09842528505701141,314.34585952281157,305.7737394354058,-1.6771664230645378
4.696730840492588,0.09877095419083817,314.66930562926734,305.7737394354058,-1.6771664230645378
4.728692002734778,0.09944308861772355,315.2969676328958,305.7737394354058,-1.6771664230645378