File: datasets/aisi_316_L/data/M1/train_19.csv
Time(s),Strain(%),Stress(MPa),Temp(C),Log_SR(s-1)
0.0,0.0,0.0,75.98025592970095,-1.4151880873209697
0.00016648229776087474,6.4e-06,1.2433367,75.98025592970095,-1.4151880873209697
0.0008116012015842644,3.12e-05,6.0612664125,75.98025592970095,-1.4151880873209697
0.0009572732121250298,3.68e-05,7.149186025,75.98025592970095,-1.4151880873209697
0.0010613246482255765,4.0799999999999996e-05,7.926271462499999,75.98025592970095,-1.4151880873209697
0.001331858382086998,5.12e-05,9.9466936,75.98025592970095,-1.4151880873209697
0.0014983406798478726,5.76e-05,11.1900303,75.98025592970095,-1.4151880873209697
0.0018521155625897314,7.12e-05,13.8321207875,75.98025592970095,-1.4151880873209697
0.002413993317532684,9.279999999999999e-05,18.02838215,75.98025592970095,-1.4151880873209697
0.0028301990619348702,0.00010879999999999999,21.136723899999996,75.98025592970095,-1.4151880873209697
0.002913440210815308,0.000112,21.75839225,75.98025592970095,-1.4151880873209697
0.0032672150935571668,0.0001256,24.4004827375,75.98025592970095,-1.4151880873209697
0.0034961282529783694,0.0001344,26.110070699999998,75.98025592970095,-1.4151880873209697
0.0036001796890789165,0.0001384,26.8871561375,75.98025592970095,-1.4151880873209697
0.0042036780184620875,0.0001616,31.394251675,75.98025592970095,-1.4151880873209697
0.004390970603443071,0.00016879999999999998,32.7930054625,75.98025592970095,-1.4151880873209697
0.004827986635065368,0.00018559999999999998,36.0567643,75.98025592970095,-1.4151880873209697
0.005223382092247445,0.0002008,39.0096889625,75.98025592970095,-1.4151880873209697
0.00538986439000832,0.0002072,40.2530256625,75.98025592970095,-1.4151880873209697
0.006347137602133349,0.000244,47.4022116875,75.98025592970095,-1.4151880873209697
0.00665929191043499,0.000256,49.733467999999995,75.98025592970095,-1.4151880873209697
0.007075497654837177,0.000272,52.84180975,75.98025592970095,-1.4151880873209697
0.007637375409780128,0.0002936,57.0380711125,75.98025592970095,-1.4151880873209697
0.007824667994761112,0.0003008,58.4368249,75.98025592970095,-1.4151880873209697
0.008011960579742097,0.000308,59.8355786875,75.98025592970095,-1.4151880873209697
0.008095201728622534,0.0003112,60.4572470375,75.98025592970095,-1.4151880873209697
0.008386545749704065,0.0003224,62.633086262499994,75.98025592970095,-1.4151880873209697
0.009239767525728547,0.00035519999999999996,69.00518684999999,75.98025592970095,-1.4151880873209697
0.00948949097236986,0.0003648,70.8701919,75.98025592970095,-1.4151880873209697
0.01011379958897314,0.00038879999999999996,75.532704525,75.98025592970095,-1.4151880873209697
0.01040514361005467,0.00039999999999999996,77.70854374999999,75.98025592970095,-1.4151880873209697
0.010717297918356312,0.000412,80.03980006249999,75.98025592970095,-1.4151880873209697
0.011195934524418827,0.0004304,83.614393075,75.98025592970095,-1.4151880873209697
0.012236448885424293,0.0004704,91.38524745,75.98025592970095,-1.4151880873209697
0.012465362044845496,0.0004792,93.0948354125,75.98025592970095,-1.4151880873209697
0.013235342671989543,0.0005088,98.84526765,75.98025592970095,-1.4151880873209697
0.014483959905196103,0.0005568,108.17029289999999,75.98025592970095,-1.4151880873209697
0.015045837660139054,0.0005784,112.36655426249999,75.98025592970095,-1.4151880873209697
0.015628525702302117,0.0006008,116.7182327125,75.98025592970095,-1.4151880873209697
0.016190403457245067,0.0006224,120.914494075,75.98025592970095,-1.4151880873209697
0.017043625233269553,0.0006552,127.2865946625,75.98025592970095,-1.4151880873209697
0.017563882413772283,0.0006751999999999999,131.17202185,75.98025592970095,-1.4151880873209697
0.017855226434853818,0.0006864,133.347861075,75.98025592970095,-1.4151880873209697
0.01845872476423699,0.0007096,137.8549566125,75.98025592970095,-1.4151880873209697
0.01868763792365819,0.0007184,139.564544575,75.98025592970095,-1.4151880873209697
0.019166274529720705,0.0007368,143.13913758750002,75.98025592970095,-1.4151880873209697
0.01997787573130497,0.000768,149.200404,75.98025592970095,-1.4151880873209697
0.020414891762927267,0.0007848,152.4641628375,75.98025592970095,-1.4151880873209697
0.021954853017215354,0.0008439999999999999,163.96502731249998,75.98025592970095,-1.4151880873209697
0.022100525027756123,0.0008495999999999999,165.052946925,75.98025592970095,-1.4151880873209697
0.022329438187177326,0.0008583999999999999,166.76253488749998,75.98025592970095,-1.4151880873209697
0.022828885080459948,0.0008776,170.4925449875,75.98025592970095,-1.4151880873209697
0.023016177665440934,0.0008847999999999999,171.891298775,75.98025592970095,-1.4151880873209697
0.02401507145200618,0.0009232,179.351318975,75.98025592970095,-1.4151880873209697
0.024535328632508915,0.0009431999999999999,183.2367461625,75.98025592970095,-1.4151880873209697
0.024785052079150226,0.0009528,185.1017512125,75.98025592970095,-1.4151880873209697
0.025118016674671978,0.0009655999999999999,187.58842461249998,75.98025592970095,-1.4151880873209697
0.025450981270193726,0.0009784,190.07509801249998,75.98025592970095,-1.4151880873209697
0.02572151500405515,0.0009888,192.09552015,75.98025592970095,-1.4151880873209697
0.025783945865715478,0.0009912,192.5617714125,75.98025592970095,-1.4151880873209697
0.02603366931235679,0.0010008,194.42677646250002,75.98025592970095,-1.4151880873209697
0.026429064769538865,0.001016,197.379701125,75.98025592970095,-1.4151880873209697
0.026699598503400288,0.0010264,199.4001232625,75.98025592970095,-1.4151880873209697
0.027136614535022585,0.0010432,202.6638821,75.98025592970095,-1.4151880873209697
0.027698492289965532,0.0010647999999999999,206.86014346249996,75.98025592970095,-1.4151880873209697
0.028031456885487284,0.0010776,209.3468168625,75.98025592970095,-1.4151880873209697
0.02838523176822914,0.0010911999999999999,211.98890734999998,75.98025592970095,-1.4151880873209697
0.028634955214870455,0.0011007999999999999,213.85391239999998,75.98025592970095,-1.4151880873209697
0.028697386076530784,0.0011032,214.3201636625,75.98025592970095,-1.4151880873209697
0.02915521239537319,0.0011208,217.73933958749998,75.98025592970095,-1.4151880873209697
0.029280074118693846,0.0011256,218.6718421125,75.98025592970095,-1.4151880873209697
0.02948817699089494,0.0011336,220.2260129875,75.98025592970095,-1.4151880873209697
0.029696279863096035,0.0011416,221.7801838625,75.98025592970095,-1.4151880873209697
0.030299778192479202,0.0011648,226.2872794,75.98025592970095,-1.4151880873209697
0.03102813824518303,0.0011928,231.7268774625,75.98025592970095,-1.4151880873209697
0.031194620542943904,0.0011991999999999999,232.97021416249999,75.98025592970095,-1.4151880873209697
0.03136110284070478,0.0012056,234.2135508625,75.98025592970095,-1.4151880873209697
0.03256809949947112,0.0012519999999999999,243.22774193749999,75.98025592970095,-1.4151880873209697
0.033171597828854295,0.0012752,247.734837475,75.98025592970095,-1.4151880873209697
0.03348375213715593,0.0012871999999999998,250.06609378749997,75.98025592970095,-1.4151880873209697
0.03396238874321845,0.0013055999999999999,253.64068679999997,75.98025592970095,-1.4151880873209697
0.034149681328199434,0.0013128,254.6343750920037,75.98025592970095,-1.4151880873209697
0.035065333965884245,0.001348,254.89261691289096,75.98025592970095,-1.4151880873209697
0.035627211720827195,0.0013696,255.0497818584977,75.98025592970095,-1.4151880873209697
0.036189089475770146,0.0013912,255.2059830487054,75.98025592970095,-1.4151880873209697
0.03650124378407178,0.0014031999999999998,255.29235271488625,75.98025592970095,-1.4151880873209697
0.03700069067735441,0.0014223999999999999,255.4299474096853,75.98025592970095,-1.4151880873209697
0.03756256843229736,0.001444,255.5838785348831,75.98025592970095,-1.4151880873209697
0.03812444618724031,0.0014655999999999998,255.73691423195524,75.98025592970095,-1.4151880873209697
0.03847822106998217,0.0014792,255.83281891100438,75.98025592970095,-1.4151880873209697
0.0385406519316425,0.0014816,255.8497075068972,75.98025592970095,-1.4151880873209697
0.03893604738882458,0.0014968,255.95642191148679,75.98025592970095,-1.4151880873209697
0.039331442846006655,0.0015119999999999999,256.0627145062896,75.98025592970095,-1.4151880873209697
0.0398725103137295,0.0015328,256.2074946689396,75.98025592970095,-1.4151880873209697
0.040309526345351794,0.0015496,256.32387391881963,75.98025592970095,-1.4151880873209697
0.04058006007921322,0.00156,256.3956716676021,75.98025592970095,-1.4151880873209697
0.0409754555363953,0.0015752,256.5002719548784,75.98025592970095,-1.4151880873209697
0.041017076110835514,0.0015768,256.5112595636161,75.98025592970095,-1.4151880873209697
0.04205759047184098,0.0016167999999999998,256.78455259592994,75.98025592970095,-1.4151880873209697
0.04239055506736273,0.0016296,256.87144775904596,75.98025592970095,-1.4151880873209697
0.04332701799226765,0.0016656,257.1144247252726,75.98025592970095,-1.4151880873209697
0.04357674143890897,0.0016752,257.17887157390174,75.98025592970095,-1.4151880873209697
0.04399294718331115,0.0016912,257.2859638265008,75.98025592970095,-1.4151880873209697
0.04497103068265629,0.0017288,257.53608716762335,75.98025592970095,-1.4151880873209697
0.045241564416517714,0.0017392,257.60489449072486,75.98025592970095,-1.4151880873209697
0.04557452901203946,0.0017519999999999999,257.68936053730096,75.98025592970095,-1.4151880873209697
0.04592830389478132,0.0017656,257.7788424364918,75.98025592970095,-1.4151880873209697
0.046157217054202525,0.0017744,257.83659928089776,75.98025592970095,-1.4151880873209697
0.04665666394748515,0.0017936,257.9622278721627,75.98025592970095,-1.4151880873209697
0.0472185417024281,0.0018151999999999999,258.1029347978125,75.98025592970095,-1.4151880873209697
0.04753069601072974,0.0018272,258.18082311272383,75.98025592970095,-1.4151880873209697
0.048321486925093894,0.0018575999999999998,258.377252580576,75.98025592970095,-1.4151880873209697
0.04846715893563466,0.0018632,258.4132997994291,75.98025592970095,-1.4151880873209697
0.048612830946175425,0.0018687999999999999,258.4493047892439,75.98025592970095,-1.4151880873209697
0.049091467552237936,0.0018872,258.56731174360385,75.98025592970095,-1.4151880873209697
0.04981982760494177,0.0019152,258.74603021093134,75.98025592970095,-1.4151880873209697
0.04992387904104231,0.0019191999999999998,258.77147798829145,75.98025592970095,-1.4151880873209697
0.05013198191324341,0.0019272,258.82231157311014,75.98025592970095,-1.4151880873209697
0.05083953167872712,0.0019544,258.99453349908305,75.98025592970095,-1.4151880873209697
0.05208814891193369,0.0020024,259.29619134686334,75.98025592970095,-1.4151880873209697
0.052545975230776094,0.00202,259.406090914521,75.98025592970095,-1.4151880873209697
0.05285812953907773,0.002032,259.4808084132062,75.98025592970095,-1.4151880873209697
0.05344081758124079,0.0020544,259.6198222629835,75.98025592970095,-1.4151880873209697
0.05360729987900166,0.0020608,259.65943176791603,75.98025592970095,-1.4151880873209697
0.05402350562340385,0.0020767999999999997,259.7582462202323,75.98025592970095,-1.4151880873209697
0.05425241878282506,0.0020856,259.81246760129676,75.98025592970095,-1.4151880873209697
0.05446052165502614,0.0020935999999999997,259.8616823888765,75.98025592970095,-1.4151880873209697
0.05514726113328976,0.00212,260.02357330953356,75.98025592970095,-1.4151880873209697
0.05537617429271095,0.0021287999999999997,260.0773619791424,75.98025592970095,-1.4151880873209697
0.05558427716491205,0.0021368,260.1261855668914,75.98025592970095,-1.4151880873209697
0.055709138888232715,0.0021416,260.1554455021672,75.98025592970095,-1.4151880873209697
0.05641668865371643,0.0021688,260.3207712239327,75.98025592970095,-1.4151880873209697
0.05679127382367839,0.0021831999999999997,260.4079691329133,75.98025592970095,-1.4151880873209697
0.0570201869830996,0.002192,260.46114633222487,75.98025592970095,-1.4151880873209697
0.057457203014721896,0.0022088,260.5624358099557,75.98025592970095,-1.4151880873209697
0.0577069264613632,0.0022183999999999997,260.620180608023,75.98025592970095,-1.4151880873209697
0.05783178818468386,0.0022232,260.6490164551597,75.98025592970095,-1.4151880873209697
0.05806070134410507,0.002232,260.70181919161683,75.98025592970095,-1.4151880873209697
0.058289614503526266,0.0022408,260.7545407989077,75.98025592970095,-1.4151880873209697
0.05866419967348823,0.0022551999999999997,260.8406386776089,75.98025592970095,-1.4151880873209697
0.05889311283290944,0.002264,260.8931485093402,75.98025592970095,-1.4151880873209697
0.059559042023952936,0.0022895999999999997,261.04545366949696,75.98025592970095,-1.4151880873209697
0.059621472885613265,0.0022919999999999998,261.0596981419885,75.98025592970095,-1.4151880873209697
0.06012091977889589,0.0023112,261.1734452560376,75.98025592970095,-1.4151880873209697
0.06049550494885785,0.0023255999999999997,261.25851390262517,75.98025592970095,-1.4151880873209697
0.06095333126770026,0.0023431999999999997,261.36220822663785,75.98025592970095,-1.4151880873209697
0.06114062385268125,0.0023504,261.4045410304769,75.98025592970095,-1.4151880873209697
0.06136953701210246,0.0023592,261.4562125050013,75.98025592970095,-1.4151880873209697
0.062410051373107914,0.0023991999999999998,261.69014190645186,75.98025592970095,-1.4151880873209697
0.06293030855361065,0.0024192,261.8065358478756,75.98025592970095,-1.4151880873209697
0.0632840834363525,0.0024327999999999997,261.8854694500354,75.98025592970095,-1.4151880873209697
0.06363785831909437,0.0024464,261.96423114724143,75.98025592970095,-1.4151880873209697
0.06378353032963513,0.0024519999999999998,261.9966127795364,75.98025592970095,-1.4151880873209697
0.06388758176573568,0.002456,262.01972486081,75.98025592970095,-1.4151880873209697
0.06463675210565961,0.0024847999999999997,262.1857006333412,75.98025592970095,-1.4151880873209697
0.06511538871172212,0.0025031999999999997,262.2913480442261,75.98025592970095,-1.4151880873209697
0.06565645617944497,0.0025239999999999998,262.410411536753,75.98025592970095,-1.4151880873209697
0.06655129852990968,0.0025583999999999997,262.60648788339904,75.98025592970095,-1.4151880873209697
0.06732127915705373,0.002588,262.77438314668905,75.98025592970095,-1.4151880873209697
0.06769586432701569,0.0026024,262.85579099683304,75.98025592970095,-1.4151880873209697
0.06825774208195864,0.002624,262.97757414719854,75.98025592970095,-1.4151880873209697
0.06909015357076302,0.002656,263.157277427399,75.98025592970095,-1.4151880873209697
0.06967284161292608,0.0026784,263.2825676409514,75.98025592970095,-1.4151880873209697
0.07052606338895057,0.0027112,263.4652935214688,75.98025592970095,-1.4151880873209697
0.07090064855891252,0.0027256,263.5452420864318,75.98025592970095,-1.4151880873209697
0.07146252631385548,0.0027472,263.664856755181,75.98025592970095,-1.4151880873209697
0.07250304067486095,0.0027871999999999997,263.8854013118957,75.98025592970095,-1.4151880873209697
0.07281519498316259,0.0027992,263.9513235207007,75.98025592970095,-1.4151880873209697
0.073273021302005,0.0028168,264.0478104086936,75.98025592970095,-1.4151880873209697
0.0741678636524697,0.0028512,264.23572221379055,75.98025592970095,-1.4151880873209697
0.0743967768118909,0.0028599999999999997,264.2836503903157,75.98025592970095,-1.4151880873209697
0.07491703399239363,0.0028799999999999997,264.3923646840339,75.98025592970095,-1.4151880873209697
0.07531242944957571,0.0028951999999999997,264.4747907425846,75.98025592970095,-1.4151880873209697
0.07543729117289637,0.0029,264.50078493873997,75.98025592970095,-1.4151880873209697
0.07568701461953768,0.0029096,264.552723046678,75.98025592970095,-1.4151880873209697
0.075936738066179,0.0029192,264.604594364803,75.98025592970095,-1.4151880873209697
0.07645699524668173,0.0029392,264.7124464259997,75.98025592970095,-1.4151880873209697
0.07687320099108391,0.0029552,264.7985221413859,75.98025592970095,-1.4151880873209697
0.07726859644826599,0.0029703999999999998,264.8801258791415,75.98025592970095,-1.4151880873209697
0.07787209477764916,0.0029936,265.0043656711943,75.98025592970095,-1.4151880873209697
0.07814262851151058,0.0030039999999999997,265.0599374179392,75.98025592970095,-1.4151880873209697
0.07897504000031497,0.003036,265.2304586604045,75.98025592970095,-1.4151880873209697
0.07905828114919539,0.0030391999999999997,265.24747214130224,75.98025592970095,-1.4151880873209697
0.07943286631915737,0.0030536,265.32394651453325,75.98025592970095,-1.4151880873209697
0.08036932924406229,0.0030896,265.5145196799781,75.98025592970095,-1.4151880873209697
0.08053581154182315,0.003096,265.548308491485,75.98025592970095,-1.4151880873209697
0.08091039671178513,0.0031103999999999997,265.6242338778783,75.98025592970095,-1.4151880873209697
0.08103525843510578,0.0031152,265.64951185999,75.98025592970095,-1.4151880873209697
0.08120174073286666,0.0031216,265.6831922197047,75.98025592970095,-1.4151880873209697
0.08134741274340741,0.0031271999999999997,265.7126404492399,75.98025592970095,-1.4151880873209697
0.08159713619004873,0.0031368,265.76307532528574,75.98025592970095,-1.4151880873209697
0.0819509110727906,0.0031504,265.83442180821436,75.98025592970095,-1.4151880873209697
0.08209658308333136,0.003156,265.8637648466425,75.98025592970095,-1.4151880873209697
0.08259602997661399,0.0031752,265.9642157510942,75.98025592970095,-1.4151880873209697
0.08305385629545639,0.0031928,266.0560878399656,75.98025592970095,-1.4151880873209697
0.08338682089097814,0.0032056,266.1227798951041,75.98025592970095,-1.4151880873209697
0.08382383692260043,0.0032224,266.2101558179942,75.98025592970095,-1.4151880873209697
0.0839486986459211,0.0032272,266.2350877130008,75.98025592970095,-1.4151880873209697
0.08407356036924175,0.003232,266.260005149965,75.98025592970095,-1.4151880873209697
0.08426085295422273,0.0032392,266.29735426182384,75.98025592970095,-1.4151880873209697
0.08457300726252437,0.0032511999999999997,266.35953091257574,75.98025592970095,-1.4151880873209697
0.08476029984750535,0.0032584,266.39679394384956,75.98025592970095,-1.4151880873209697
0.08515569530468743,0.0032735999999999998,266.4753550530275,75.98025592970095,-1.4151880873209697
0.0857383833468505,0.003296,266.5908705118464,75.98025592970095,-1.4151880873209697
0.08607134794237224,0.0033087999999999998,266.656741876372,75.98025592970095,-1.4151880873209697
0.08625864052735323,0.003316,266.6937508445137,75.98025592970095,-1.4151880873209697
0.0866540359845353,0.0033312,266.7717781297372,75.98025592970095,-1.4151880873209697
0.0868829491439565,0.0033399999999999997,266.8168883565195,75.98025592970095,-1.4151880873209697
0.08702862115449726,0.0033456,266.84557073204235,75.98025592970095,-1.4151880873209697
0.08738239603723913,0.0033591999999999997,266.9151500891622,75.98025592970095,-1.4151880873209697
0.08748644747333967,0.0033632,266.93559368672794,75.98025592970095,-1.4151880873209697
0.08786103264330164,0.0033775999999999997,267.00911225207886,75.98025592970095,-1.4151880873209697
0.08858939269600548,0.0034056,267.1517160236936,75.98025592970095,-1.4151880873209697
0.08948423504647017,0.00344,267.3262905031529,75.98025592970095,-1.4151880873209697
0.09019178481195389,0.0034671999999999997,267.46384460167496,75.98025592970095,-1.4151880873209697
0.09062880084357618,0.0034839999999999997,267.5485942705026,75.98025592970095,-1.4151880873209697
0.09102419630075827,0.0034992,267.6251353073812,75.98025592970095,-1.4151880873209697
0.09179417692790232,0.0035288,267.773817801684,75.98025592970095,-1.4151880873209697
0.09243929583172569,0.0035535999999999996,267.8980155152469,75.98025592970095,-1.4151880873209697
0.0926682089911469,0.0035624,267.9420043573609,75.98025592970095,-1.4151880873209697
0.09327170732053008,0.0035856,268.05777228015273,75.98025592970095,-1.4151880873209697
0.09358386162883171,0.0035976,268.11753758876716,75.98025592970095,-1.4151880873209697
0.09402087766045401,0.0036144,268.20107857141517,75.98025592970095,-1.4151880873209697
0.09437465254319587,0.0036279999999999997,268.268596122794,75.98025592970095,-1.4151880873209697
0.09454113484095675,0.0036344,268.3003349265956,75.98025592970095,-1.4151880873209697
0.0949157200109187,0.0036488,268.3716676471967,75.98025592970095,-1.4151880873209697
0.09514463317033992,0.0036576,268.4152058201641,75.98025592970095,-1.4151880873209697
0.09522787431922035,0.0036607999999999996,268.43102775184167,75.98025592970095,-1.4151880873209697
0.09539435661698123,0.0036672,268.46265544297694,75.98025592970095,-1.4151880873209697
0.09547759776586166,0.0036704,268.4784612155125,75.98025592970095,-1.4151880873209697
0.09620595781856549,0.0036983999999999997,268.6165332335875,75.98025592970095,-1.4151880873209697
0.09651811212686713,0.0037104,268.67558209038214,75.98025592970095,-1.4151880873209697
0.09753781620065248,0.0037495999999999996,268.86795806031046,75.98025592970095,-1.4151880873209697
0.09778753964729381,0.0037592,268.9149507823925,75.98025592970095,-1.4151880873209697
0.09795402194505468,0.0037656,268.9462532649448,75.98025592970095,-1.4151880873209697
0.09847427912555741,0.0037855999999999996,269.0439400588314,75.98025592970095,-1.4151880873209697
0.0989112951571797,0.0038023999999999996,269.1258415168393,75.98025592970095,-1.4151880873209697
0.09920263917826123,0.0038136,269.18036409923224,75.98025592970095,-1.4151880873209697
0.09943155233768243,0.0038223999999999997,269.2231594736416,75.98025592970095,-1.4151880873209697
0.09974370664598409,0.0038344,269.28145493032576,75.98025592970095,-1.4151880873209697
0.1002223432520466,0.0038528,269.3707032960385,75.98025592970095,-1.4151880873209697
0.10055530784756835,0.0038656,269.43269110021305,75.98025592970095,-1.4151880873209697
0.1006593592836689,0.0038696,269.45204586568184,75.98025592970095,-1.4151880873209697
0.10070097985810911,0.0038712,269.45978558691803,75.98025592970095,-1.4151880873209697
0.10084665186864987,0.0038767999999999997,269.4868647921355,75.98025592970095,-1.4151880873209697
0.10115880617695151,0.0038888,269.5448403448872,75.98025592970095,-1.4151880873209697
0.10172068393189446,0.0039104,269.6490208225844,75.98025592970095,-1.4151880873209697
0.10238661312293795,0.003935999999999999,269.7722038077802,75.98025592970095,-1.4151880873209697
0.1029276805906608,0.0039568,269.8720600672973,75.98025592970095,-1.4151880873209697
0.10311497317564179,0.003964,269.90657797117694,75.98025592970095,-1.4151880873209697
0.10332307604784288,0.003972,269.9449025326821,75.98025592970095,-1.4151880873209697
0.10369766121780487,0.0039864,270.013810967817,75.98025592970095,-1.4151880873209697
0.10405143610054672,0.004,270.0788020732919,75.98025592970095,-1.4151880873209697
0.1085473573243351,0.004172834566913383,270.89736979477306,75.98025592970095,-1.4151880873209697
0.118038746574555,0.004537707541508302,272.58324251706733,75.98025592970095,-1.4151880873209697
0.12303421460098654,0.004729745949189838,273.4492511083012,75.98025592970095,-1.4151880873209697
0.12703058902213177,0.004883376675335067,274.13222290918213,75.98025592970095,-1.4151880873209697
0.15050928874635994,0.0057859571914382875,277.9872350857128,75.98025592970095,-1.4151880873209697
0.16699433323358398,0.006419683936787358,280.5545615582935,75.98025592970095,-1.4151880873209697
0.17049116085208604,0.006554110822164433,281.0862118110975,75.98025592970095,-1.4151880873209697
0.17698526928644703,0.00680376075215043,282.06241323743166,75.98025592970095,-1.4151880873209697
0.1794830032996628,0.0068997799559911985,282.43414275844486,75.98025592970095,-1.4151880873209697
0.1929707669710279,0.007418283656731346,284.4076570905759,75.98025592970095,-1.4151880873209697
0.21195354547146775,0.008148029605921184,287.09632622949323,75.98025592970095,-1.4151880873209697
0.22344312193226026,0.008589717943588718,288.6780594757365,75.98025592970095,-1.4151880873209697
0.23343405798512332,0.00897379475895179,290.0278620002408,75.98025592970095,-1.4151880873209697
0.2379299792089117,0.009146629325865173,290.62790217775625,75.98025592970095,-1.4151880873209697
0.2564132109067084,0.009857171434286858,293.0496489765556,75.98025592970095,-1.4151880873209697
0.2674032405648577,0.010279655931186238,294.4573270913369,75.98025592970095,-1.4151880873209697
0.27189916178864604,0.010452490498099619,295.02666995728805,75.98025592970095,-1.4151880873209697
0.28238964464415234,0.010855771154230847,296.3410456967858,75.98025592970095,-1.4151880873209697
0.28738511267058386,0.011047809561912383,296.96023298452843,75.98025592970095,-1.4151880873209697
0.31735792082917297,0.0122000400080016,300.59083252605416,75.98025592970095,-1.4151880873209697
0.3253506696714634,0.012507301460292058,301.53607627859657,75.98025592970095,-1.4151880873209697
0.33684024613225594,0.012948989797959592,302.8791487882063,75.98025592970095,-1.4151880873209697
0.35332529061948,0.013582716543308662,304.77536485073017,75.98025592970095,-1.4151880873209697
0.3563225714353389,0.013697939587917584,305.1163916311338,75.98025592970095,-1.4151880873209697
0.37130897551463354,0.014274054810962193,306.8050261956985,75.98025592970095,-1.4151880873209697
0.37980127115956713,0.014600520104020805,307.75011531854847,75.98025592970095,-1.4151880873209697
0.4142700005419446,0.015925585117023404,311.50434761209993,75.98025592970095,-1.4151880873209697
0.4307550450291686,0.016559311862372472,313.2565852454429,75.98025592970095,-1.4151880873209697
0.43275323223974127,0.016636127225445087,313.4671858092867,75.98025592970095,-1.4151880873209697
0.43525096625295706,0.016732146429285857,313.7299039623022,75.98025592970095,-1.4151880873209697
0.43774870026617285,0.016828165633126627,313.9920347908666,75.98025592970095,-1.4151880873209697
0.4467405427137495,0.01717383476695339,314.9309140151573,75.98025592970095,-1.4151880873209697
0.45523283835868317,0.017500300060012002,315.81088856880876,75.98025592970095,-1.4151880873209697
0.46472422760890303,0.01786517303460692,316.7868478415495,75.98025592970095,-1.4151880873209697
0.474215616859123,0.01823004600920184,317.75506359772896,75.98025592970095,-1.4151880873209697
0.487203833727845,0.018729345869173835,319.0678308730796,75.98025592970095,-1.4151880873209697
0.49619567617542176,0.0190750150030006,319.96868475787056,75.98025592970095,-1.4151880873209697
0.5106825334520732,0.019631926385277054,321.4067824156458,75.98025592970095,-1.4151880873209697
0.5406553416106623,0.020784156831366273,324.33259777731877,75.98025592970095,-1.4151880873209697
0.552644464874098,0.02124504900980196,325.48512425041037,75.98025592970095,-1.4151880873209697
0.5591385733084591,0.02149469893978796,326.10533621358957,75.98025592970095,-1.4151880873209697
0.5661322285454632,0.02176355271054211,326.77012328819325,75.98025592970095,-1.4151880873209697
0.5836163666379734,0.022435687137427485,328.4182297340135,75.98025592970095,-1.4151880873209697
0.5906100218749776,0.022704540908181636,329.07206670898114,75.98025592970095,-1.4151880873209697
0.5956054899014092,0.022896579315863173,329.5372457696605,75.98025592970095,-1.4151880873209697
0.6065955195595585,0.023319063812762553,330.55531699006906,75.98025592970095,-1.4151880873209697
0.6115909875859901,0.02351110222044409,331.01569603625234,75.98025592970095,-1.4151880873209697
0.6190841896256373,0.023799159831966392,331.7035243305046,75.98025592970095,-1.4151880873209697
0.6360687809155045,0.024452090418083616,333.2506930307643,75.98025592970095,-1.4151880873209697
0.6415637957445792,0.024663332666533307,333.74778682926285,75.98025592970095,-1.4151880873209697
0.6520542786000854,0.025066613322664532,334.69219725129693,75.98025592970095,-1.4151880873209697
0.6575492934291601,0.025277855571114224,335.1845224889102,75.98025592970095,-1.4151880873209697
0.6790298059428157,0.02610362072414483,337.0938654159193,75.98025592970095,-1.4151880873209697
0.6820270867586746,0.02621884376875375,337.3584003039528,75.98025592970095,-1.4151880873209697
0.686523007982463,0.026391678335667135,337.75435411313487,75.98025592970095,-1.4151880873209697
0.6915184760088945,0.02658371674334867,338.1931186181795,75.98025592970095,-1.4151880873209697
0.7050062396802597,0.027102220444088818,339.37165155728025,75.98025592970095,-1.4151880873209697
0.7075039736934754,0.027198239647929588,339.5889300147279,75.98025592970095,-1.4151880873209697
0.725987205391272,0.02790878175635127,341.18759496446205,75.98025592970095,-1.4151880873209697
0.7414731562732099,0.028504100820164035,342.51483184449216,75.98025592970095,-1.4151880873209697
0.7589572943657201,0.02917623524704941,344.0003995461976,75.98025592970095,-1.4151880873209697
0.7824359940899484,0.03007881576315263,345.9744760389311,75.98025592970095,-1.4151880873209697
0.7909282897348819,0.030405281056211243,346.6827966961334,75.98025592970095,-1.4151880873209697
0.7954242109586703,0.030578115623124624,347.05658887290843,75.98025592970095,-1.4151880873209697
0.8004196789851018,0.03077015403080616,347.4709484599279,75.98025592970095,-1.4151880873209697
0.8129083490511807,0.03125025005001,348.50245926203417,75.98025592970095,-1.4151880873209697
0.8194024574855416,0.031499899979996,349.0364013121645,75.98025592970095,-1.4151880873209697
0.8283942999331183,0.03184556911382276,349.7729891054981,75.98025592970095,-1.4151880873209697
0.8388847827886247,0.03224884976995399,350.62841201196807,75.98025592970095,-1.4151880873209697
0.8418820636044835,0.03236407281456291,350.8720509656867,75.98025592970095,-1.4151880873209697
0.8453788912229856,0.03249849969993999,351.1558692651347,75.98025592970095,-1.4151880873209697
0.8478766252362014,0.03259451890378076,351.3583163745091,75.98025592970095,-1.4151880873209697
0.8538711868679192,0.0328249649929986,351.8432428206942,75.98025592970095,-1.4151880873209697
0.8578675612890644,0.03297859571914383,352.1657897027215,75.98025592970095,-1.4151880873209697
0.8648612165260686,0.03324744948989798,352.7288402086998,75.98025592970095,-1.4151880873209697
0.8753516993815748,0.033650730146029206,353.5700979130116,75.98025592970095,-1.4151880873209697
0.8783489801974338,0.03376595319063813,353.809733877102,75.98025592970095,-1.4151880873209697
0.8908376502635124,0.034246049209841964,354.8048035859336,75.98025592970095,-1.4151880873209697
0.895833118289944,0.034438087617523504,355.20130633642907,75.98025592970095,-1.4151880873209697
0.9018276799216618,0.03466853370674135,355.67597321208405,75.98025592970095,-1.4151880873209697
0.9073226947507366,0.03487977595519104,356.1100046546775,75.98025592970095,-1.4151880873209697
0.918312724408886,0.03530226045209042,356.9750042160038,75.98025592970095,-1.4151880873209697
0.9298023008696784,0.03574394878975795,357.8750162336339,75.98025592970095,-1.4151880873209697
0.9517823601859773,0.03658891778355672,359.5847836188494,75.98025592970095,-1.4151880873209697
0.9612737494361969,0.036953790758151625,360.31832399860133,75.98025592970095,-1.4151880873209697
0.9707651386864169,0.037318663732746546,361.049045061833,75.98025592970095,-1.4151880873209697
0.9942438384106453,0.038221244248849776,362.84474825537967,75.98025592970095,-1.4151880873209697
1.0077316020820102,0.03873974794958991,363.8688424390832,75.98025592970095,-1.4151880873209697
1.0292121145956656,0.03956551310262052,365.48883963596955,75.98025592970095,-1.4151880873209697
1.0312103018062386,0.03964232846569314,365.6388635008623,75.98025592970095,-1.4151880873209697
1.0566871887410394,0.04062172434486898,367.54183685227537,75.98025592970095,-1.4151880873209697
1.0601840163595413,0.04075615123024605,367.8016257470713,75.98025592970095,-1.4151880873209697
1.062182203570114,0.04083296659331867,367.9499265029298,75.98025592970095,-1.4151880873209697
1.069175858807118,0.04110182036407281,368.46812448915284,75.98025592970095,-1.4151880873209697
1.0716735928203336,0.04119783956791358,368.6528746107445,75.98025592970095,-1.4151880873209697
1.0741713268335498,0.04129385877175436,368.8374568766323,75.98025592970095,-1.4151880873209697
1.0851613564916989,0.04171634326865373,369.6476383999438,75.98025592970095,-1.4151880873209697
1.1121368838344292,0.04275335067013403,371.62281633787535,75.98025592970095,-1.4151880873209697
1.1216282730846492,0.04311822364472895,372.3133310635576,75.98025592970095,-1.4151880873209697
1.133617396348085,0.043579115823164635,373.1823115241643,75.98025592970095,-1.4151880873209697
1.1386128643745164,0.04377115423084617,373.5433280166084,75.98025592970095,-1.4151880873209697
1.158095189677599,0.044520104020804155,374.94542945942743,75.98025592970095,-1.4151880873209697
1.1750797809674667,0.04517303460692139,376.16028548210073,75.98025592970095,-1.4151880873209697
1.1850707170203294,0.045557111422284455,376.87170779466135,75.98025592970095,-1.4151880873209697
1.1945621062705494,0.045921984396879376,377.5453954811521,75.98025592970095,-1.4151880873209697
1.2010562147049104,0.04617163432686537,378.00513732329296,75.98025592970095,-1.4151880873209697
1.2240353676264955,0.04705501100220044,379.62418875022286,75.98025592970095,-1.4151880873209697
1.2365240376925746,0.04753510702140429,380.4991344102164,75.98025592970095,-1.4151880873209697
1.2560063629956573,0.048284056811362275,381.85719919665036,75.98025592970095,-1.4151880873209697
1.2610018310220887,0.04847609521904381,382.2040944954024,75.98025592970095,-1.4151880873209697
1.2729909542855244,0.048936987397479495,383.0344638049544,75.98025592970095,-1.4151880873209697
1.2809837031278148,0.04924424884976995,383.58634953457926,75.98025592970095,-1.4151880873209697
1.2949710136018233,0.04978195639127826,384.54892889630213,75.98025592970095,-1.4151880873209697
1.3184497133260513,0.05068453690738148,386.15562096896076,75.98025592970095,-1.4151880873209697
1.3269420089709851,0.051011002200440095,386.7340119264492,75.98025592970095,-1.4151880873209697
1.3384315854317774,0.05145269053810762,387.5142482678583,75.98025592970095,-1.4151880873209697
1.3419284130502795,0.051587117423484694,387.7511924512805,75.98025592970095,-1.4151880873209697
1.3484225214846404,0.05183676735347069,388.19059377587155,75.98025592970095,-1.4151880873209697
1.3524188959057857,0.05199039807961592,388.46058440748067,75.98025592970095,-1.4151880873209697
1.3649075659718646,0.052470494098819764,389.302306630545,75.98025592970095,-1.4151880873209697
1.3748985020247277,0.052854570914182844,389.9735237913939,75.98025592970095,-1.4151880873209697
1.3783953296432299,0.052988997799559914,390.2080000465223,75.98025592970095,-1.4151880873209697
1.3813926104590888,0.05310422084416884,390.4087951110767,75.98025592970095,-1.4151880873209697
1.405870403788603,0.05404520904180836,392.0423095218426,75.98025592970095,-1.4151880873209697
1.4198577142626114,0.05458291658331667,392.9707657039518,75.98025592970095,-1.4151880873209697
1.4238540886837567,0.0547365473094619,393.2353828329215,75.98025592970095,-1.4151880873209697
1.4283500099075448,0.05490938187637527,393.53273111803435,75.98025592970095,-1.4151880873209697
1.4333454779339767,0.05510142028405682,393.8626903251465,75.98025592970095,-1.4151880873209697
1.4378413991577648,0.05527425485097019,394.15927035268913,75.98025592970095,-1.4151880873209697
1.454326443644989,0.05590798159631927,395.24364989955626,75.98025592970095,-1.4151880873209697
1.4573237244608481,0.05602320464092819,395.4402937056362,75.98025592970095,-1.4151880873209697
1.4688133009216404,0.05646489297859572,396.1926382722512,75.98025592970095,-1.4151880873209697
1.4877960794220804,0.05719463892778556,397.4306331236532,75.98025592970095,-1.4151880873209697
1.4982865622775865,0.05759791958391679,398.1121448504344,75.98025592970095,-1.4151880873209697
1.533254838462607,0.05894218843768753,400.3705287016146,75.98025592970095,-1.4151880873209697
1.542246680910184,0.05928785757151431,400.9479979828621,75.98025592970095,-1.4151880873209697
1.5527371637656902,0.05969113822764553,401.62005518547915,75.98025592970095,-1.4151880873209697
1.5607299126079806,0.05999839967993599,402.1309108790807,75.98025592970095,-1.4151880873209697
1.568722661450271,0.06030566113222645,402.6407472776729,75.98025592970095,-1.4151880873209697
1.587705439950711,0.06103540708141629,403.847565556258,75.98025592970095,-1.4151880873209697
1.59869546960886,0.06145789157831566,404.54367776372754,75.98025592970095,-1.4151880873209697
1.605189578043221,0.061707541508301655,404.9541395942259,75.98025592970095,-1.4151880873209697
1.6136818736881546,0.06203400680136027,405.4899214999495,75.98025592970095,-1.4151880873209697
1.6226737161357314,0.062379675935187034,406.05602278689446,75.98025592970095,-1.4151880873209697
1.6386592138203122,0.06299419883976795,407.0594135141479,75.98025592970095,-1.4151880873209697
1.6481506030705322,0.06335907181436287,407.65337065609754,75.98025592970095,-1.4151880873209697
1.6686320219789017,0.06414642928585718,408.9305414665714,75.98025592970095,-1.4151880873209697
1.6881143472819844,0.06489537907581516,410.1397493447829,75.98025592970095,-1.4151880873209697
1.7016021109533497,0.06541388277655531,410.97370687672077,75.98025592970095,-1.4151880873209697
1.7070971257824243,0.065625125025005,411.3127277714258,75.98025592970095,-1.4151880873209697
1.7120925938088558,0.06581716343268654,411.62055944340835,75.98025592970095,-1.4151880873209697
1.71908624904586,0.06608601720344069,412.05093594917486,75.98025592970095,-1.4151880873209697
1.723582170269648,0.06625885177035407,412.32724602060705,75.98025592970095,-1.4151880873209697
1.7330735595198685,0.066623724744949,412.90964589429444,75.98025592970095,-1.4151880873209697
1.7470608699938766,0.0671614322864573,413.76565716416036,75.98025592970095,-1.4151880873209697
1.7630463676784576,0.06777595519103821,414.7406896982292,75.98025592970095,-1.4151880873209697
1.7665431952969595,0.06791038207641528,414.95351776642815,75.98025592970095,-1.4151880873209697
1.771039116520748,0.06808321664332867,415.2269125865397,75.98025592970095,-1.4151880873209697
1.7730373037313205,0.06816003200640128,415.3483344988645,75.98025592970095,-1.4151880873209697
1.7780327717577522,0.06835207041408282,415.6516560289623,75.98025592970095,-1.4151880873209697
1.7855259737973994,0.06864012802560512,416.1060159002168,75.98025592970095,-1.4151880873209697
1.7880237078106151,0.06873614722944589,416.2573038568376,75.98025592970095,-1.4151880873209697
1.7930191758370466,0.06892818563712742,416.55963273177935,75.98025592970095,-1.4151880873209697
1.7995132842714079,0.06917783556711343,416.95216961720865,75.98025592970095,-1.4151880873209697
1.8055078459031255,0.06940828165633127,417.31402127938907,75.98025592970095,-1.4151880873209697
1.8149992351533455,0.06977315463092619,417.8859963086793,75.98025592970095,-1.4151880873209697
1.8159983287586317,0.0698115623124625,417.94613626942055,75.98025592970095,-1.4151880873209697
1.8279874520220674,0.07027245449089818,418.6668122186664,75.98025592970095,-1.4151880873209697
1.8354806540617148,0.0705605121024205,419.11629871235704,75.98025592970095,-1.4151880873209697
1.845971136917221,0.07096379275855172,419.744379374946,75.98025592970095,-1.4151880873209697
1.8479693241277935,0.07104060812162433,419.86385579753545,75.98025592970095,-1.4151880873209697
1.8659530090229473,0.07173194638927786,420.9368858540317,75.98025592970095,-1.4151880873209697
1.8834371471154576,0.07240408081616324,421.9762494826486,75.98025592970095,-1.4151880873209697
1.8889321619445318,0.07261532306461292,422.3021285722408,75.98025592970095,-1.4151880873209697
1.8934280831683203,0.07278815763152631,422.5684820077194,75.98025592970095,-1.4151880873209697
1.8969249107868225,0.07292258451690338,422.77547529994746,75.98025592970095,-1.4151880873209697
1.9129104084714033,0.0735371074214843,423.71984167392986,75.98025592970095,-1.4151880873209697
1.9169067828925486,0.07369073814762953,423.95545174892504,75.98025592970095,-1.4151880873209697
1.940385482616777,0.07459331866373275,425.33581180563834,75.98025592970095,-1.4151880873209697
1.9633646355383616,0.07547669533906781,426.68050891822173,75.98025592970095,-1.4151880873209697
1.9748542119991543,0.07591838367673535,427.35055472706483,75.98025592970095,-1.4151880873209697
1.9833465076440877,0.07624484896979396,427.8448292434279,75.98025592970095,-1.4151880873209697
1.9918388032890215,0.07657131426285257,428.3382790553061,75.98025592970095,-1.4151880873209697
2.003328379749814,0.0770130026005201,429.0045836255241,75.98025592970095,-1.4151880873209697
2.0308034538951873,0.07806921384276856,430.5919063760122,75.98025592970095,-1.4151880873209697
2.0377971091321916,0.0783380676135227,430.99461213955107,75.98025592970095,-1.4151880873209697
2.044790764369196,0.07860692138427686,431.3967792537453,75.98025592970095,-1.4151880873209697
2.0472884983824113,0.07870294058811762,431.5402803138712,75.98025592970095,-1.4151880873209697
2.0502857791982705,0.07881816363272655,431.7123914893932,75.98025592970095,-1.4151880873209697
2.052783513211486,0.07891418283656731,431.8557425240608,75.98025592970095,-1.4151880873209697
2.065272183277565,0.07939427885577116,432.57147985646225,75.98025592970095,-1.4151880873209697
2.0802585873568598,0.07997039407881577,433.4281404243715,75.98025592970095,-1.4151880873209697
2.082256774567432,0.08004720944188838,433.54217970897537,75.98025592970095,-1.4151880873209697
2.0922477106202955,0.08043128625725146,434.11173719183887,75.98025592970095,-1.4151880873209697
2.094745444633511,0.08052730546109223,434.2539607060686,75.98025592970095,-1.4151880873209697
2.103737287081088,0.08087297459491899,434.7654186463744,75.98025592970095,-1.4151880873209697
2.1102313955154486,0.08112262452490498,435.1342748585497,75.98025592970095,-1.4151880873209697
2.114227769936594,0.08127625525105021,435.361043266856,75.98025592970095,-1.4151880873209697
2.1157264103445237,0.08133386677335468,435.44603831341504,75.98025592970095,-1.4151880873209697
2.1232196123841707,0.08162192438487698,435.87066185770857,75.98025592970095,-1.4151880873209697
2.126716440002673,0.08175635127025406,436.0686194657198,75.98025592970095,-1.4151880873209697
2.1357082824502496,0.08210202040408082,436.57707130555457,75.98025592970095,-1.4151880873209697
2.1456992185031125,0.08248609721944389,437.1410396319634,75.98025592970095,-1.4151880873209697
2.15319242054276,0.0827741548309662,437.56334403458925,75.98025592970095,-1.4151880873209697
2.166180637411482,0.08327345469093819,438.29398309973453,75.98025592970095,-1.4151880873209697
2.174173386253772,0.08358071614322865,438.7427580118557,75.98025592970095,-1.4151880873209697
2.178669307477561,0.08375355071014204,438.9949111381359,75.98025592970095,-1.4151880873209697
2.18016794788549,0.08381116223244649,439.0789170730079,75.98025592970095,-1.4151880873209697
2.185163415911922,0.08400320064012803,439.3587743488246,75.98025592970095,-1.4151880873209697
2.198651179583287,0.08452170434086818,440.1131454643574,75.98025592970095,-1.4151880873209697
2.2021480072017887,0.08465613122624525,440.3084282784092,75.98025592970095,-1.4151880873209697
2.203147100807075,0.08469453890778156,440.3642011505642,75.98025592970095,-1.4151880873209697
2.215136224070511,0.08515543108621725,441.032708069655,75.98025592970095,-1.4151880873209697
2.2271253473339465,0.08561632326465293,441.6998053697214,75.98025592970095,-1.4151880873209697
2.228623987741876,0.0856739347869574,441.78309394465043,75.98025592970095,-1.4151880873209697
2.234618549373594,0.08590438087617525,442.1160300476091,75.98025592970095,-1.4151880873209697
2.251103593860818,0.08653810762152431,443.0298131251802,75.98025592970095,-1.4151880873209697
2.277080027598262,0.0875367073414683,444.4644352639654,75.98025592970095,-1.4151880873209697
2.289069150861698,0.08799759951990399,445.1244144508622,75.98025592970095,-1.4151880873209697
2.294564165690772,0.08820884176835367,445.4264542399311,75.98025592970095,-1.4151880873209697
2.3020573677304195,0.08849689937987598,445.83787245623273,75.98025592970095,-1.4151880873209697
2.3050546485462786,0.08861212242448491,446.0022934660212,75.98025592970095,-1.4151880873209697
2.3170437718097143,0.0890730146029206,446.65914540631695,75.98025592970095,-1.4151880873209697
2.3210401462308594,0.08922664532906582,446.8778013193671,75.98025592970095,-1.4151880873209697
2.333528816296938,0.08970674134826966,447.5601566100345,75.98025592970095,-1.4151880873209697
2.340522471533942,0.08997559511902381,447.94165344031603,75.98025592970095,-1.4151880873209697
2.346017486363017,0.0901868373674735,448.241089154239,75.98025592970095,-1.4151880873209697
2.368497092481959,0.09105101020204041,449.4632158971742,75.98025592970095,-1.4151880873209697
2.3764898413242492,0.09135827165433087,449.8966586050807,75.98025592970095,-1.4151880873209697
2.381984856153324,0.09156951390278056,450.19432072775635,75.98025592970095,-1.4151880873209697
2.40196672825905,0.09233766753350671,451.27447825991794,75.98025592970095,-1.4151880873209697
2.4169531323383446,0.09291378275655131,452.082298099038,75.98025592970095,-1.4151880873209697
2.421449053562133,0.0930866173234647,452.3242628157381,75.98025592970095,-1.4151880873209697
2.434936817233498,0.09360512102420485,453.04910788504225,75.98025592970095,-1.4151880873209697
2.4389331916546433,0.09375875175035008,453.2635758550448,75.98025592970095,-1.4151880873209697
2.4519214085233654,0.09425805161032207,453.95965213798826,75.98025592970095,-1.4151880873209697
2.4719032806290913,0.09502620524104821,455.0277373342983,75.98025592970095,-1.4151880873209697
2.4813946698793115,0.09539107821564313,455.5338977447747,75.98025592970095,-1.4151880873209697
2.4973801675638923,0.09600560112022405,456.3846750145986,75.98025592970095,-1.4151880873209697
2.4998779015771078,0.09610162032406482,456.5174168706449,75.98025592970095,-1.4151880873209697
2.524355694906623,0.09704260852170435,457.81556139375874,75.98025592970095,-1.4151880873209697
2.526353882117195,0.09711942388477696,457.9213151563099,75.98025592970095,-1.4151880873209697
2.532348443748913,0.09734986997399481,458.23838088903204,75.98025592970095,-1.4151880873209697
2.538842552183274,0.0975995199039808,458.5815386253872,75.98025592970095,-1.4151880873209697
2.553828956262569,0.09817563512702542,459.372137243078,75.98025592970095,-1.4151880873209697
2.5768081091841535,0.09905901180236047,460.5808833242514,75.98025592970095,-1.4151880873209697
2.587798138842303,0.09948149629925986,461.1574925797261,75.98025592970095,-1.4151880873209697
2.5922940600660915,0.09965433086617324,461.39310283134836,75.98025592970095,-1.4151880873209697