File: datasets/aisi_316_L/data/M1/train_22.csv
Time(s),Strain(%),Stress(MPa),Temp(C),Log_SR(s-1)
0.0,0.0,0.0,40.473400567694,-0.4926065747260573
0.00013679154388795115,4.4e-05,8.59805925,40.473400567694,-0.4926065747260573
0.00020394375634203625,6.56e-05,12.818924699999998,40.473400567694,-0.4926065747260573
0.00026114749287699766,8.4e-05,16.41447675,40.473400567694,-0.4926065747260573
0.0003855034418660442,0.000124,24.230894250000002,40.473400567694,-0.4926065747260573
0.0004128617506436344,0.0001328,25.950506100000002,40.473400567694,-0.4926065747260573
0.0005023980339157479,0.0001616,31.578326699999998,40.473400567694,-0.4926065747260573
0.0005720373653496139,0.000184,35.9555205,40.473400567694,-0.4926065747260573
0.0006441638157632609,0.0002072,40.48904265,40.473400567694,-0.4926065747260573
0.0007212645041364698,0.000232,45.3352215,40.473400567694,-0.4926065747260573
0.00074862281291406,0.0002408,47.05483335,40.473400567694,-0.4926065747260573
0.0007884167165905548,0.0002536,49.556086949999994,40.473400567694,-0.4926065747260573
0.0008083136684288023,0.00026,50.80671374999999,40.473400567694,-0.4926065747260573
0.0008580560480244209,0.000276,53.933280749999994,40.473400567694,-0.4926065747260573
0.0009276953794582869,0.0002984,58.310474549999995,40.473400567694,-0.4926065747260573
0.0009550536882358771,0.0003072,60.030086399999995,40.473400567694,-0.4926065747260573
0.0009998218298719339,0.0003216,62.843996700000005,40.473400567694,-0.4926065747260573
0.0010570255664068952,0.00033999999999999997,66.43954875,40.473400567694,-0.4926065747260573
0.0010719482802855809,0.0003448,67.37751885,40.473400567694,-0.4926065747260573
0.001141587611719447,0.0003672,71.75471265,40.473400567694,-0.4926065747260573
0.001171433039476818,0.0003768,73.63065285,40.473400567694,-0.4926065747260573
0.0012012784672341891,0.00038639999999999996,75.50659304999999,40.473400567694,-0.4926065747260573
0.0013206601782636738,0.00042479999999999997,83.01035385,40.473400567694,-0.4926065747260573
0.0014101964615357873,0.00045359999999999997,88.63817445,40.473400567694,-0.4926065747260573
0.0015146554586865865,0.00048719999999999997,95.20396514999999,40.473400567694,-0.4926065747260573
0.0015370395295046149,0.0004944,96.6109203,40.473400567694,-0.4926065747260573
0.0016216015748171664,0.0005216,101.9260842,40.473400567694,-0.4926065747260573
0.0016564212405340993,0.0005327999999999999,104.11468109999998,40.473400567694,-0.4926065747260573
0.0016862666682914706,0.0005424,105.99062129999999,40.473400567694,-0.4926065747260573
0.0017036765011499372,0.000548,107.08491975,40.473400567694,-0.4926065747260573
0.0017932127844220505,0.0005767999999999999,112.71274034999999,40.473400567694,-0.4926065747260573
0.0018628521158559166,0.0005991999999999999,117.08993414999999,40.473400567694,-0.4926065747260573
0.00195238839912803,0.000628,122.71775475,40.473400567694,-0.4926065747260573
0.0020046178977034296,0.0006448,126.00065009999999,40.473400567694,-0.4926065747260573
0.0020891799430159813,0.000672,131.315814,40.473400567694,-0.4926065747260573
0.0021239996087329144,0.0006832,133.5044109,40.473400567694,-0.4926065747260573
0.002203587416085904,0.0007088,138.5069181,40.473400567694,-0.4926065747260573
0.0022135358920050275,0.000712,139.1322315,40.473400567694,-0.4926065747260573
0.002243381319762399,0.0007216,141.0081717,40.473400567694,-0.4926065747260573
0.0022533297956815225,0.0007247999999999999,141.6334851,40.473400567694,-0.4926065747260573
0.002317994889155827,0.0007456,145.6980222,40.473400567694,-0.4926065747260573
0.002375198625690788,0.0007639999999999999,149.29357424999998,40.473400567694,-0.4926065747260573
0.002397582696508817,0.0007712,150.7005294,40.473400567694,-0.4926065747260573
0.002469709146922464,0.0007944,155.23405155,40.473400567694,-0.4926065747260573
0.0025492969542754533,0.00082,160.23655875,40.473400567694,-0.4926065747260573
0.0025816295010126053,0.0008303999999999999,162.26882729999997,40.473400567694,-0.4926065747260573
0.002713446806940995,0.0008728,170.55422984999998,40.473400567694,-0.4926065747260573
0.002745779353678147,0.0008832,172.5864984,40.473400567694,-0.4926065747260573
0.0027805990193950796,0.0008944,174.7750953,40.473400567694,-0.4926065747260573
0.002882570897566098,0.0009272,181.18455765,40.473400567694,-0.4926065747260573
0.0029049549683841263,0.0009343999999999999,182.59151279999998,40.473400567694,-0.4926065747260573
0.0029671329428786497,0.0009544,186.49972155,40.473400567694,-0.4926065747260573
0.002987029894716897,0.0009607999999999999,187.75034835,40.473400567694,-0.4926065747260573
0.0030317980363529537,0.0009752,190.56425865,40.473400567694,-0.4926065747260573
0.0030442336312518584,0.0009792,191.34590039999998,40.473400567694,-0.4926065747260573
0.0030815404159485727,0.0009912,193.69082565,40.473400567694,-0.4926065747260573
0.003091488891867696,0.0009943999999999999,194.31613904999998,40.473400567694,-0.4926065747260573
0.003098950248807039,0.0009968,194.7851241,40.473400567694,-0.4926065747260573
0.00312879567656441,0.0010064,196.6610643,40.473400567694,-0.4926065747260573
0.003161128223301562,0.0010168,198.69333285,40.473400567694,-0.4926065747260573
0.003203409245957838,0.0010304,201.35091479999997,40.473400567694,-0.4926065747260573
0.003245690268614114,0.001044,204.00849675,40.473400567694,-0.4926065747260573
0.0032854841722906084,0.0010567999999999999,206.50975035,40.473400567694,-0.4926065747260573
0.003345175027805351,0.001076,210.26163075,40.473400567694,-0.4926065747260573
0.0034595825008752737,0.0011128,217.45273484999998,40.473400567694,-0.4926065747260573
0.0035018635235315497,0.0011264,220.11031680000002,40.473400567694,-0.4926065747260573
0.003549118784147387,0.0011416,223.08055545,40.473400567694,-0.4926065747260573
0.0035640414980260726,0.0011464,224.01852555,40.473400567694,-0.4926065747260573
0.0035889126878238817,0.0011543999999999999,225.58180904999998,40.473400567694,-0.4926065747260573
0.0036908845659949004,0.0011872,231.99127140000002,40.473400567694,-0.4926065747260573
0.003765498135388328,0.0012112,236.6811219,40.473400567694,-0.4926065747260573
0.0038028049200850423,0.0012232,239.02604715,40.473400567694,-0.4926065747260573
0.003887366965397594,0.0012504,244.34121105,40.473400567694,-0.4926065747260573
0.0040863364837800675,0.0013143999999999999,256.84747904999995,40.473400567694,-0.4926065747260573
0.004136078863375687,0.0013304,259.97404605,40.473400567694,-0.4926065747260573
0.004180847005011743,0.0013448,262.78795635,40.473400567694,-0.4926065747260573
0.00430520295400079,0.0013847999999999998,270.60437384999994,40.473400567694,-0.4926065747260573
0.004317638548899694,0.0013888,271.3860156,40.473400567694,-0.4926065747260573
0.004347483976657066,0.0013984,273.2619558,40.473400567694,-0.4926065747260573
0.004367380928495313,0.0014047999999999999,274.5125826,40.473400567694,-0.4926065747260573
0.004409661951151589,0.0014184,277.17016455,40.473400567694,-0.4926065747260573
0.004419610427070712,0.0014215999999999999,277.79547794999996,40.473400567694,-0.4926065747260573
0.004432046021969617,0.0014256,278.57711969999997,40.473400567694,-0.4926065747260573
0.004454430092787646,0.0014328,279.98407484999996,40.473400567694,-0.4926065747260573
0.0045091467103428266,0.0014504,283.42329854999997,40.473400567694,-0.4926065747260573
0.004536505019120417,0.0014592,285.1429104,40.473400567694,-0.4926065747260573
0.004616092826473406,0.0014847999999999999,286.4926892702033,40.473400567694,-0.4926065747260573
0.004633502659331873,0.0014904,286.536728437819,40.473400567694,-0.4926065747260573
0.004683245038927491,0.0015064,286.66220043619603,40.473400567694,-0.4926065747260573
0.004787704036078291,0.00154,286.9240123405893,40.473400567694,-0.4926065747260573
0.004827497939754785,0.0015528,287.0231630134277,40.473400567694,-0.4926065747260573
0.004959315245683175,0.0015952,287.3493462767488,40.473400567694,-0.4926065747260573
0.005031441696096821,0.0016183999999999999,287.5263920083986,40.473400567694,-0.4926065747260573
0.005163259002025211,0.0016607999999999998,287.84742167979005,40.473400567694,-0.4926065747260573
0.0052428468093782005,0.0016864,288.03970368934984,40.473400567694,-0.4926065747260573
0.005257769523256886,0.0016912,288.0756294814751,40.473400567694,-0.4926065747260573
0.005354767163468343,0.0017224,288.30818528748813,40.473400567694,-0.4926065747260573
0.0054517648036797985,0.0017536,288.5391038717372,40.473400567694,-0.4926065747260573
0.005484097350416951,0.001764,288.6157199302378,40.473400567694,-0.4926065747260573
0.005528865492053008,0.0017783999999999999,288.7215135110599,40.473400567694,-0.4926065747260573
0.005563685157769941,0.0017896,288.80356660467413,40.473400567694,-0.4926065747260573
0.005613427537365559,0.0018055999999999999,288.9204387479762,40.473400567694,-0.4926065747260573
0.005715399415536578,0.0018384,289.1587714844678,40.473400567694,-0.4926065747260573
0.00575021908125351,0.0018495999999999999,289.2397728180378,40.473400567694,-0.4926065747260573
0.005794987222889568,0.001864,289.34363686114233,40.473400567694,-0.4926065747260573
0.005837268245545843,0.0018775999999999999,289.4414437169393,40.473400567694,-0.4926065747260573
0.005874575030242557,0.0018896,289.5275146676844,40.473400567694,-0.4926065747260573
0.005996443860251822,0.0019287999999999998,289.80720579444164,40.473400567694,-0.4926065747260573
0.006048673358827222,0.0019456,289.92639379159027,40.473400567694,-0.4926065747260573
0.006056134715766564,0.0019479999999999999,289.9433878253591,40.473400567694,-0.4926065747260573
0.0060984157384228405,0.0019616,290.03953355869317,40.473400567694,-0.4926065747260573
0.006143183880058897,0.001976,290.14105199847336,40.473400567694,-0.4926065747260573
0.006173029307816269,0.0019856,290.2085707122952,40.473400567694,-0.4926065747260573
0.006200387616593858,0.0019944,290.27035111091254,40.473400567694,-0.4926065747260573
0.006217797449452326,0.002,290.3096105634048,40.473400567694,-0.4926065747260573
0.006252617115169258,0.0020112,290.3880010906287,40.473400567694,-0.4926065747260573
0.006289923899865972,0.0020231999999999997,290.4718022526804,40.473400567694,-0.4926065747260573
0.00630982085170422,0.0020296,290.5164169339625,40.473400567694,-0.4926065747260573
0.006324743565582906,0.0020344,290.54984194733163,40.473400567694,-0.4926065747260573
0.006369511707218962,0.0020488,290.64993293293605,40.473400567694,-0.4926065747260573
0.00644163815763261,0.002072,290.8106154659968,40.473400567694,-0.4926065747260573
0.006521225964985599,0.0020976,290.9871082163866,40.473400567694,-0.4926065747260573
0.006558532749682313,0.0021096,291.06954982818104,40.473400567694,-0.4926065747260573
0.006620710724176835,0.0021295999999999997,291.20654724735016,40.473400567694,-0.4926065747260573
0.006667965984792674,0.0021448,291.3103299584524,40.473400567694,-0.4926065747260573
0.006707759888469169,0.0021576,291.3975036326646,40.473400567694,-0.4926065747260573
0.00676496362500413,0.002176,291.5224632624405,40.473400567694,-0.4926065747260573
0.006777399219903035,0.00218,291.5495737916284,40.473400567694,-0.4926065747260573
0.006789834814801938,0.0021839999999999997,291.57666492754777,40.473400567694,-0.4926065747260573
0.006822167361539092,0.0021944,291.64701147398455,40.473400567694,-0.4926065747260573
0.006876883979094272,0.002212,291.7657639861714,40.473400567694,-0.4926065747260573
0.0069316005966494525,0.0022296,291.8841485670236,40.473400567694,-0.4926065747260573
0.006946523310528138,0.0022344,291.916371946849,40.473400567694,-0.4926065747260573
0.00697885585726529,0.0022448,291.9860968008934,40.473400567694,-0.4926065747260573
0.007016162641962004,0.0022567999999999998,292.06639220225406,40.473400567694,-0.4926065747260573
0.00703108535584069,0.0022616,292.0984637189484,40.473400567694,-0.4926065747260573
0.007070879259517184,0.0022743999999999998,292.18385824538495,40.473400567694,-0.4926065747260573
0.007215132160344479,0.0023208,292.49185454487184,40.473400567694,-0.4926065747260573
0.007232541993202944,0.0023263999999999997,292.52886340358816,40.473400567694,-0.4926065747260573
0.007297207086677249,0.0023472,292.6660217535896,40.473400567694,-0.4926065747260573
0.007351923704232429,0.0023648,292.781708976421,40.473400567694,-0.4926065747260573
0.007404153202807829,0.0023815999999999998,292.8918248485465,40.473400567694,-0.4926065747260573
0.007429024392605638,0.0023896,292.94415446661975,40.473400567694,-0.4926065747260573
0.007451408463423666,0.0023967999999999997,292.9911927343231,40.473400567694,-0.4926065747260573
0.007518560675877751,0.0024184,293.1319779959202,40.473400567694,-0.4926065747260573
0.007603122721190304,0.0024456,293.30856749738973,40.473400567694,-0.4926065747260573
0.007682710528543293,0.0024712,293.474070957399,40.473400567694,-0.4926065747260573
0.007695146123442197,0.0024752,293.49987034849994,40.473400567694,-0.4926065747260573
0.007720017313240008,0.0024832,293.5514204021268,40.473400567694,-0.4926065747260573
0.007819502072431244,0.0025152,293.75697620134076,40.473400567694,-0.4926065747260573
0.007849347500188616,0.0025248,293.81844372349576,40.473400567694,-0.4926065747260573
0.00789162852284489,0.0025383999999999997,293.9053669121613,40.473400567694,-0.4926065747260573
0.007963754973258538,0.0025616,294.0532296244923,40.473400567694,-0.4926065747260573
0.008060752613469994,0.0025927999999999997,294.25125862970384,40.473400567694,-0.4926065747260573
0.008068213970409337,0.0025951999999999998,294.26645302787864,40.473400567694,-0.4926065747260573
0.008115469231025175,0.0026103999999999997,294.3625572688876,40.473400567694,-0.4926065747260573
0.008187595681438821,0.0026336,294.50882298667585,40.473400567694,-0.4926065747260573
0.008222415347155754,0.0026447999999999997,294.57925409834894,40.473400567694,-0.4926065747260573
0.008436307579416916,0.0027136,295.00937787143386,40.473400567694,-0.4926065747260573
0.008491024196972096,0.0027312,295.118723736477,40.473400567694,-0.4926065747260573
0.008503459791870999,0.0027351999999999997,295.143536703798,40.473400567694,-0.4926065747260573
0.00853330521962837,0.0027448,295.20303015676876,40.473400567694,-0.4926065747260573
0.008699942191273694,0.0027984,295.533722458505,40.473400567694,-0.4926065747260573
0.008772068641687341,0.0028216,295.6760908999655,40.473400567694,-0.4926065747260573
0.008829272378222303,0.00284,295.788679442316,40.473400567694,-0.4926065747260573
0.008844195092100987,0.0028447999999999998,295.81800353486074,40.473400567694,-0.4926065747260573
0.008871553400878578,0.0028536,295.8717143029149,40.473400567694,-0.4926065747260573
0.008883988995777484,0.0028576,295.89610693003345,40.473400567694,-0.4926065747260573
0.008913834423534854,0.0028672,295.95459496886826,40.473400567694,-0.4926065747260573
0.009050625967422805,0.0029112,296.221693947411,40.473400567694,-0.4926065747260573
0.009060574443341927,0.0029143999999999997,296.2410576931946,40.473400567694,-0.4926065747260573
0.009105342584977985,0.0029288,296.32809214085887,40.473400567694,-0.4926065747260573
0.0091426493696747,0.0029408,296.4004934356407,40.473400567694,-0.4926065747260573
0.009207314463149003,0.0029616,296.52571666332295,40.473400567694,-0.4926065747260573
0.00925456972376484,0.0029768,296.6170091424161,40.473400567694,-0.4926065747260573
0.009274466675603088,0.0029831999999999997,296.6553936716142,40.473400567694,-0.4926065747260573
0.00930928634132002,0.0029944,296.72248940883134,40.473400567694,-0.4926065747260573
0.00935902872091564,0.0030104,296.81817092931857,40.473400567694,-0.4926065747260573
0.009393848386632573,0.0030215999999999997,296.885030021957,40.473400567694,-0.4926065747260573
0.009403796862551696,0.0030248,296.90411485866684,40.473400567694,-0.4926065747260573
0.009421206695410163,0.0030304,296.93749438647893,40.473400567694,-0.4926065747260573
0.009458513480106876,0.0030424,297.008941047596,40.473400567694,-0.4926065747260573
0.009503281621742934,0.0030567999999999997,297.0945321322394,40.473400567694,-0.4926065747260573
0.009565459596237457,0.0030767999999999998,297.213148228641,40.473400567694,-0.4926065747260573
0.00959779214297461,0.0030872,297.2747097388855,40.473400567694,-0.4926065747260573
0.00965002164155001,0.003104,297.3739846771742,40.473400567694,-0.4926065747260573
0.009684841307266942,0.0031152,297.4400515766916,40.473400567694,-0.4926065747260573
0.00970473825910519,0.0031216,297.47776249835124,40.473400567694,-0.4926065747260573
0.009719660972983874,0.0031263999999999997,297.5060259047092,40.473400567694,-0.4926065747260573
0.009771890471559274,0.0031432,297.604814831754,40.473400567694,-0.4926065747260573
0.009791787423397522,0.0031496,297.6423945156324,40.473400567694,-0.4926065747260573
0.009856452516871827,0.0031704,297.76432332689507,40.473400567694,-0.4926065747260573
0.0098987335395281,0.0031839999999999998,297.8438773695831,40.473400567694,-0.4926065747260573
0.00991863049136635,0.0031904,297.88126870033835,40.473400567694,-0.4926065747260573
0.009938527443204595,0.0031967999999999996,297.9186307895132,40.473400567694,-0.4926065747260573
0.010042986440355397,0.0032304,298.114305221774,40.473400567694,-0.4926065747260573
0.01013252272362751,0.0032592,298.28139524080933,40.473400567694,-0.4926065747260573
0.010154906794445539,0.0032664,298.3230776496667,40.473400567694,-0.4926065747260573
0.010202162055061376,0.0032816,298.41095635660986,40.473400567694,-0.4926065747260573
0.010271801386495241,0.0033039999999999996,298.54017302117717,40.473400567694,-0.4926065747260573
0.010314082409151517,0.0033176,298.618459320987,40.473400567694,-0.4926065747260573
0.010361337669767354,0.0033328,298.70580781141774,40.473400567694,-0.4926065747260573
0.01037626038364604,0.0033376,298.73335924907326,40.473400567694,-0.4926065747260573
0.01043097700120122,0.0033552,298.8342492483643,40.473400567694,-0.4926065747260573
0.01045584819099903,0.0033632,298.8800400871105,40.473400567694,-0.4926065747260573
0.010470770904877715,0.003368,298.90749420060126,40.473400567694,-0.4926065747260573
0.01053543599835202,0.0033888,299.02628612888674,40.473400567694,-0.4926065747260573
0.010547871593250924,0.0033927999999999996,299.0490980940067,40.473400567694,-0.4926065747260573
0.010567768545089172,0.0033992,299.08557543348184,40.473400567694,-0.4926065747260573
0.010634920757543256,0.0034208,299.2084891863194,40.473400567694,-0.4926065747260573
0.010659791947341065,0.0034287999999999996,299.2539359381387,40.473400567694,-0.4926065747260573
0.010716995683876027,0.0034471999999999997,299.3583068206587,40.473400567694,-0.4926065747260573
0.010791609253269456,0.0034712,299.49411681892167,40.473400567694,-0.4926065747260573
0.010831403156945951,0.0034839999999999997,299.5663990567839,40.473400567694,-0.4926065747260573
0.010943323511036092,0.0035199999999999997,299.76913968322185,40.473400567694,-0.4926065747260573
0.011007988604510396,0.0035407999999999998,299.8859101162616,40.473400567694,-0.4926065747260573
0.011075140816964481,0.0035624,300.0068889176785,40.473400567694,-0.4926065747260573
0.011122396077580319,0.0035776,300.091850717411,40.473400567694,-0.4926065747260573
0.011172138457175938,0.0035935999999999997,300.1811322430037,40.473400567694,-0.4926065747260573
0.011276597454326737,0.0036271999999999997,300.368120396913,40.473400567694,-0.4926065747260573
0.011328826952902136,0.0036439999999999997,300.4613610606022,40.473400567694,-0.4926065747260573
0.011341262547801042,0.0036479999999999998,300.48353649040155,40.473400567694,-0.4926065747260573
0.011395979165356222,0.0036655999999999998,300.5809959425535,40.473400567694,-0.4926065747260573
0.011405927641275345,0.0036688,300.59869621842904,40.473400567694,-0.4926065747260573
0.011435773069032717,0.0036783999999999996,300.65176095517984,40.473400567694,-0.4926065747260573
0.011537744947203735,0.0037112,300.83265934203314,40.473400567694,-0.4926065747260573
0.011614845635576944,0.0037359999999999997,300.96902250916344,40.473400567694,-0.4926065747260573
0.011679510729051247,0.0037568,301.08311962405895,40.473400567694,-0.4926065747260573
0.011774021250282922,0.0037871999999999997,301.2494347718021,40.473400567694,-0.4926065747260573
0.01179143108314139,0.0037928,301.2800148997707,40.473400567694,-0.4926065747260573
0.01190086431825175,0.003828,301.47183120477786,40.473400567694,-0.4926065747260573
0.011918274151110218,0.0038336,301.5022838969989,40.473400567694,-0.4926065747260573
0.01192573550804956,0.003836,301.51532973938276,40.473400567694,-0.4926065747260573
0.011992887720503644,0.0038575999999999997,301.6325994235484,40.473400567694,-0.4926065747260573
0.012025220267240797,0.003868,301.688971247307,40.473400567694,-0.4926065747260573
0.012079936884795977,0.0038856,301.78423524165015,40.473400567694,-0.4926065747260573
0.012189370119906338,0.0039207999999999995,301.97425986887157,40.473400567694,-0.4926065747260573
0.012204292833785024,0.0039256,302.0001206726523,40.473400567694,-0.4926065747260573
0.012298803355016699,0.0039559999999999994,302.1636203106568,40.473400567694,-0.4926065747260573
0.012343571496652756,0.0039704,302.2408964163352,40.473400567694,-0.4926065747260573
0.012373416924410128,0.00398,302.29235310422104,40.473400567694,-0.4926065747260573
0.012398288114207939,0.003988,302.33519671151316,40.473400567694,-0.4926065747260573
0.013390839636087965,0.004307261452290458,304.01858052935677,40.473400567694,-0.4926065747260573
0.014286381577197322,0.004595319063812763,305.4960941288425,40.473400567694,-0.4926065747260573
0.014584895557567108,0.004691338267653531,305.9805111131707,40.473400567694,-0.4926065747260573
0.01518192351830668,0.004883376675335067,306.9378970435098,40.473400567694,-0.4926065747260573
0.018584982894522234,0.005977995599119824,312.13773921294006,40.473400567694,-0.4926065747260573
0.020435769572814906,0.006573314662932587,314.8087253915499,40.473400567694,-0.4926065747260573
0.021032797533554477,0.006765353070614123,315.6499744926284,40.473400567694,-0.4926065747260573
0.023301503784364845,0.00749509901980396,318.76516633758155,40.473400567694,-0.4926065747260573
0.023719423356882544,0.007629525905181036,319.32587139982024,40.473400567694,-0.4926065747260573
0.025629912831249175,0.008244048809761952,321.84155492805667,40.473400567694,-0.4926065747260573
0.027838916285985588,0.008954590918183637,324.6608230243962,40.473400567694,-0.4926065747260573
0.02861505263494703,0.009204240848169634,325.6304770903093,40.473400567694,-0.4926065747260573
0.028913566615316817,0.009300260052010402,326.00068289222696,40.473400567694,-0.4926065747260573
0.029391188983908474,0.009453890778155631,326.5899266208353,40.473400567694,-0.4926065747260573
0.03010762253679596,0.009684336867373475,327.4668377921134,40.473400567694,-0.4926065747260573
0.030525542109313658,0.00981876375275055,327.97461103592093,40.473400567694,-0.4926065747260573
0.03195840921508863,0.010279655931186238,329.6953265374063,40.473400567694,-0.4926065747260573
0.03237632878760632,0.010414082816563312,330.19149920541946,40.473400567694,-0.4926065747260573
0.03327187072871569,0.010702140428085618,331.2463925748244,40.473400567694,-0.4926065747260573
0.034107709873751085,0.010970994198839769,332.2210117158746,40.473400567694,-0.4926065747260573
0.034585332242342746,0.011124624924984998,332.77375415700595,40.473400567694,-0.4926065747260573
0.03685403849315311,0.011854370874174834,335.3596701504797,40.473400567694,-0.4926065747260573
0.03816750000678017,0.012276855371074214,336.82839040304674,40.473400567694,-0.4926065747260573
0.038824230763593696,0.012488097619523904,337.5553482832063,40.473400567694,-0.4926065747260573
0.04037650346151658,0.012987397479495899,339.254808225654,40.473400567694,-0.4926065747260573
0.04151085658692177,0.013352270454090818,340.4806472768498,40.473400567694,-0.4926065747260573
0.04288402089662278,0.013793958791758352,341.9472140846862,40.473400567694,-0.4926065747260573
0.04407807681810193,0.014178035607121425,343.2076639952068,40.473400567694,-0.4926065747260573
0.04533183553565502,0.014581316263252651,344.51688661635677,40.473400567694,-0.4926065747260573
0.048436380931500794,0.01557991598319664,347.6994097439705,40.473400567694,-0.4926065747260573
0.049391625668684117,0.0158871774354871,348.6625066220254,40.473400567694,-0.4926065747260573
0.05082449277445907,0.016348069613922784,350.09364131243285,40.473400567694,-0.4926065747260573
0.052675279452751744,0.016943388677735545,351.91911164605557,40.473400567694,-0.4926065747260573
0.0535708213938611,0.01723144628925785,352.79340842282386,40.473400567694,-0.4926065747260573
0.05428725494674859,0.017461892378475695,353.48874862026497,40.473400567694,-0.4926065747260573
0.05512309409178399,0.017730746149229846,354.29547163889544,40.473400567694,-0.4926065747260573
0.0560783388289673,0.018038007601520304,355.21162194135917,40.473400567694,-0.4926065747260573
0.056735069585780826,0.018249249849969992,355.8379476443265,40.473400567694,-0.4926065747260573
0.05757090873081624,0.018518103620724147,356.631015131729,40.473400567694,-0.4926065747260573
0.059302289816960986,0.0190750150030006,358.25965359750836,40.473400567694,-0.4926065747260573
0.06055604853451408,0.019478295659131825,359.4274573609236,40.473400567694,-0.4926065747260573
0.06091426531095784,0.01959351870374075,359.7593786682808,40.473400567694,-0.4926065747260573
0.0627650519892505,0.02018883776755351,361.46232719463126,40.473400567694,-0.4926065747260573
0.0649740554439869,0.020899379875975194,363.4694504745392,40.473400567694,-0.4926065747260573
0.06706365330657542,0.021571514302860573,365.34372223357457,40.473400567694,-0.4926065747260573
0.06980998192597744,0.02245489097819564,367.772768623508,40.473400567694,-0.4926065747260573
0.07046671268279096,0.02266613322664533,368.3480708986886,40.473400567694,-0.4926065747260573
0.07082492945923471,0.02278135627125425,368.66099065180356,40.473400567694,-0.4926065747260573
0.07136225462390033,0.022954190838167635,369.12921543113686,40.473400567694,-0.4926065747260573
0.07249660774930551,0.023319063812762553,370.1131985753293,40.473400567694,-0.4926065747260573
0.07458620561189401,0.02399119823964793,371.91022189677983,40.473400567694,-0.4926065747260573
0.07476531400011588,0.02404880976195239,372.0633329168746,40.473400567694,-0.4926065747260573
0.07560115314515128,0.024317663532706542,372.77596810073635,40.473400567694,-0.4926065747260573
0.0762578839019648,0.02452890578115623,373.3337423616906,40.473400567694,-0.4926065747260573
0.07769075100773977,0.024989797959591917,374.54424283382804,40.473400567694,-0.4926065747260573
0.07900421252136683,0.025412282456491297,375.64624100526595,40.473400567694,-0.4926065747260573
0.07942213209388455,0.025546709341868375,375.9953753130905,40.473400567694,-0.4926065747260573
0.0796012404821064,0.025604320864172834,376.1447848882549,40.473400567694,-0.4926065747260573
0.0804370796271418,0.025873174634926985,376.84030333489903,40.473400567694,-0.4926065747260573
0.08097440479180743,0.02604600920184037,377.2859343575282,40.473400567694,-0.4926065747260573
0.08186994673291678,0.026334066813362672,378.0260984183454,40.473400567694,-0.4926065747260573
0.08342221943083966,0.026833366673334667,379.30161269374497,40.473400567694,-0.4926065747260573
0.0837804362072834,0.02694858971794359,379.59464364470676,40.473400567694,-0.4926065747260573
0.08527300610913234,0.02742868573714743,380.81038335059327,40.473400567694,-0.4926065747260573
0.08682527880705522,0.027927985597119426,382.06598127608805,40.473400567694,-0.4926065747260573
0.0892133906500135,0.028696139227845568,383.98070872587175,40.473400567694,-0.4926065747260573
0.08975071581467912,0.028868973794758952,384.4087553227745,40.473400567694,-0.4926065747260573
0.09136269130867596,0.0293874774954991,385.6869383284608,40.473400567694,-0.4926065747260573
0.09190001647334158,0.029560312062412483,386.1110408442951,40.473400567694,-0.4926065747260573
0.0945269395005957,0.030405281056211243,388.1706697221314,40.473400567694,-0.4926065747260573
0.09643742897496231,0.03101980396079216,389.654585981615,40.473400567694,-0.4926065747260573
0.09685534854748001,0.031154230846169233,389.97765925330197,40.473400567694,-0.4926065747260573
0.09739267371214563,0.03132706541308262,390.3922414364183,40.473400567694,-0.4926065747260573
0.0984076212454029,0.03165353070614123,391.1729153600243,40.473400567694,-0.4926065747260573
0.09894494641006853,0.031826365273054616,391.58494173404404,40.473400567694,-0.4926065747260573
0.10294503374702364,0.033113022604520904,394.625283115634,40.473400567694,-0.4926065747260573
0.10330325052346737,0.03322824564912982,394.8952845274707,40.473400567694,-0.4926065747260573
0.10419879246457674,0.03351630326065213,395.56869546139126,40.473400567694,-0.4926065747260573
0.1050943344056861,0.033804360872174435,396.2398529514354,40.473400567694,-0.4926065747260573
0.10688541828790482,0.03438047609521905,397.57551365283916,40.473400567694,-0.4926065747260573
0.10784066302508814,0.034687737547509506,398.2842955038151,40.473400567694,-0.4926065747260573
0.10849739378190165,0.03489897979595919,398.7701632914445,40.473400567694,-0.4926065747260573
0.10933323292693704,0.03516783356671334,399.3868848456073,40.473400567694,-0.4926065747260573
0.11112431680915576,0.03574394878975795,400.7022732367893,40.473400567694,-0.4926065747260573
0.11207956154633908,0.03605121024204841,401.4004315678119,40.473400567694,-0.4926065747260573
0.11285569789530052,0.036300860172034405,401.96597801741706,40.473400567694,-0.4926065747260573
0.11315421187567029,0.03639687937587517,402.183091730898,40.473400567694,-0.4926065747260573
0.1138706454285578,0.03662732546509302,402.70325527003456,40.473400567694,-0.4926065747260573
0.11428856500107548,0.03676175235047009,403.00609458163217,40.473400567694,-0.4926065747260573
0.11578113490292444,0.03724184836967394,404.0841557042805,40.473400567694,-0.4926065747260573
0.1159602432911463,0.0372994598919784,404.2131578043876,40.473400567694,-0.4926065747260573
0.11661697404795984,0.03751070214042809,404.6855021299056,40.473400567694,-0.4926065747260573
0.1170945964165515,0.03766433286657332,405.0283739305357,40.473400567694,-0.4926065747260573
0.11799013835766084,0.03795239047809562,405.6697920169405,40.473400567694,-0.4926065747260573
0.11840805793017853,0.03808681736347269,405.96847043434417,40.473400567694,-0.4926065747260573
0.12067676418098891,0.03881656331266253,407.5827499953041,40.473400567694,-0.4926065747260573
0.12234844247105968,0.03935427085417083,408.7646555490898,40.473400567694,-0.4926065747260573
0.12276636204357741,0.03948869773954791,409.0591458074935,40.473400567694,-0.4926065747260573
0.1231842816160951,0.03962312462492498,409.35324534952804,40.473400567694,-0.4926065747260573
0.12396041796505654,0.03987277455491098,409.89839988885717,40.473400567694,-0.4926065747260573
0.1252738794786836,0.04029525905181036,410.8179462433061,40.473400567694,-0.4926065747260573
0.12593061023549712,0.04050650130026005,411.27630883790596,40.473400567694,-0.4926065747260573
0.1270649633609023,0.040871374274854974,412.0658363180088,40.473400567694,-0.4926065747260573
0.12807991089415957,0.04119783956791358,412.7699285813383,40.473400567694,-0.4926065747260573
0.1283187220784554,0.0412746549309862,412.93528071410395,40.473400567694,-0.4926065747260573
0.12855753326275124,0.041351470294058806,413.10051287436005,40.473400567694,-0.4926065747260573
0.12879634444704707,0.04142828565713143,413.26562537177483,40.473400567694,-0.4926065747260573
0.12993069757245226,0.04179315863172635,414.048285022581,40.473400567694,-0.4926065747260573
0.13249791780363243,0.04261892378475696,415.8097935410367,40.473400567694,-0.4926065747260573
0.13482632685051674,0.043367873574714944,417.39596280018816,40.473400567694,-0.4926065747260573
0.13685622191703128,0.044020804160832164,418.77008048344265,40.473400567694,-0.4926065747260573
0.13828908902280623,0.04448169633926785,419.7352641887578,40.473400567694,-0.4926065747260573
0.13870700859532398,0.044616123224644935,420.0160403979447,40.473400567694,-0.4926065747260573
0.1390652253717677,0.04473134626925385,420.2564432258128,40.473400567694,-0.4926065747260573
0.14049809247754266,0.045192238447689534,421.2156492565892,40.473400567694,-0.4926065747260573
0.14151304001079995,0.04551870374074815,421.8927799368493,40.473400567694,-0.4926065747260573
0.1422294735636874,0.04574914982996599,422.36961466337914,40.473400567694,-0.4926065747260573
0.1440802602419801,0.04634446889377876,423.59712215131424,40.473400567694,-0.4926065747260573
0.1454534245516811,0.04678615723144629,424.50388344052726,40.473400567694,-0.4926065747260573
0.14718480563782585,0.04734306861372274,425.6424466808998,40.473400567694,-0.4926065747260573
0.15052816221796744,0.048418483696739345,427.8263768772521,40.473400567694,-0.4926065747260573
0.1522595433041122,0.0489753950790158,428.9499006578229,40.473400567694,-0.4926065747260573
0.1528565712648518,0.049167433486697346,429.3361659124849,40.473400567694,-0.4926065747260573
0.1545282495549226,0.04970514102820564,430.41459091899685,40.473400567694,-0.4926065747260573
0.15542379149603192,0.04999319863972794,430.9904465687478,40.473400567694,-0.4926065747260573
0.15667755021358507,0.05039647929585918,431.7944752306775,40.473400567694,-0.4926065747260573
0.15721487537825066,0.05056931386277255,432.13829037224576,40.473400567694,-0.4926065747260573
0.1578119033389902,0.050761352270454085,432.5197701556497,40.473400567694,-0.4926065747260573
0.15822982291150794,0.05089577915583117,432.78647117981603,40.473400567694,-0.4926065747260573
0.16037912357017037,0.051587117423484694,434.1537609992613,40.473400567694,-0.4926065747260573
0.16073734034661413,0.05170234046809362,434.38094607407635,40.473400567694,-0.4926065747260573
0.16187169347201932,0.05206721344268854,435.0990662724826,40.473400567694,-0.4926065747260573
0.16324485778172032,0.05250890178035607,435.9657491083231,40.473400567694,-0.4926065747260573
0.1667673227500838,0.053641928385677135,438.1760769527677,40.473400567694,-0.4926065747260573
0.17076741008703894,0.05492858571714343,440.6641493405436,40.473400567694,-0.4926065747260573
0.17184206041637015,0.05527425485097019,441.3286999184301,40.473400567694,-0.4926065747260573
0.17309581913392325,0.05567753550710142,442.1019638744594,40.473400567694,-0.4926065747260573
0.17458838903577217,0.05615763152630526,443.01967394174824,40.473400567694,-0.4926065747260573
0.17572274216117736,0.056522504500900184,443.7150886589558,40.473400567694,-0.4926065747260573
0.17697650087873046,0.05692578515703141,444.4816712026958,40.473400567694,-0.4926065747260573
0.17852877357665334,0.0574250850170034,445.4278452636127,40.473400567694,-0.4926065747260573
0.17906609874131899,0.05759791958391679,445.7546188153006,40.473400567694,-0.4926065747260573
0.18199153574894286,0.05853890778155631,447.52705541378276,40.473400567694,-0.4926065747260573
0.18288707769005222,0.05882696539307862,448.0674120837753,40.473400567694,-0.4926065747260573
0.18366321403901367,0.059076615323064616,448.5348870262104,40.473400567694,-0.4926065747260573
0.18449905318404908,0.05934546909381877,449.0374607992153,40.473400567694,-0.4926065747260573
0.1848572699604928,0.05946069213842768,449.2525776483453,40.473400567694,-0.4926065747260573
0.1855737035133803,0.05969113822764553,449.6823242482097,40.473400567694,-0.4926065747260573
0.18629013706626776,0.05992158431686337,450.1114242849675,40.473400567694,-0.4926065747260573
0.18772300417204274,0.060382476495299056,450.9676984524802,40.473400567694,-0.4926065747260573
0.18933497966603957,0.060900980196039206,451.9279659004715,40.473400567694,-0.4926065747260573
0.19082754956788853,0.06138107621524305,452.8142633181385,40.473400567694,-0.4926065747260573
0.19261863345010724,0.061957191438287665,453.87425946874686,40.473400567694,-0.4926065747260573
0.19357387818729058,0.06226445289057812,454.43801864316936,40.473400567694,-0.4926065747260573
0.19387239216766033,0.06236047209441889,454.61397074104696,40.473400567694,-0.4926065747260573
0.1945888257205478,0.06259091818363673,455.03582524466884,40.473400567694,-0.4926065747260573
0.195723178845953,0.06295579115823165,455.7025248355543,40.473400567694,-0.4926065747260573
0.1982306962810592,0.0637623524704941,457.17095765980207,40.473400567694,-0.4926065747260573
0.1987680214457248,0.06393518703740748,457.4846773167392,40.473400567694,-0.4926065747260573
0.2003202941436477,0.06443448689737948,458.3891259926001,40.473400567694,-0.4926065747260573
0.20133524167690497,0.06476095219043809,458.97901880889395,40.473400567694,-0.4926065747260573
0.20211137802586643,0.06501060212042409,459.4293311264971,40.473400567694,-0.4926065747260573
0.20396216470415907,0.06560592118423685,460.5004399052824,40.473400567694,-0.4926065747260573
0.20485770664526845,0.06589397879575916,461.0173569694712,40.473400567694,-0.4926065747260573
0.20527562621778614,0.06602840568113623,461.2582832662326,40.473400567694,-0.4926065747260573
0.20611146536282154,0.06629725945189038,461.7395627411866,40.473400567694,-0.4926065747260573
0.2067681961196351,0.06650850170034008,462.1171771208628,40.473400567694,-0.4926065747260573
0.208260766021484,0.06698859771954391,462.97365635787156,40.473400567694,-0.4926065747260573
0.2088577939822236,0.06718063612722545,463.3155773542583,40.473400567694,-0.4926065747260573
0.2089771995743715,0.06721904380876176,463.38391578847757,40.473400567694,-0.4926065747260573
0.20951452473903712,0.06739187837567515,463.69125048584374,40.473400567694,-0.4926065747260573
0.21029066108799857,0.06764152830566114,464.1346362504108,40.473400567694,-0.4926065747260573
0.21070858066051626,0.06777595519103821,464.37311806471837,40.473400567694,-0.4926065747260573
0.21112650023303392,0.06791038207641528,464.61141547824957,40.473400567694,-0.4926065747260573
0.21154441980555166,0.06804480896179237,464.84952899818234,40.473400567694,-0.4926065747260573
0.21393253164850995,0.06881296259251851,466.20667469194007,40.473400567694,-0.4926065747260573
0.21488777638569326,0.06912022404480897,466.74787706685134,40.473400567694,-0.4926065747260573
0.21691767145220778,0.06977315463092619,467.8948266268251,40.473400567694,-0.4926065747260573
0.21781321339331713,0.07006121224244849,468.3995022560184,40.473400567694,-0.4926065747260573
0.2198431084598317,0.07071414282856572,469.54044726115256,40.473400567694,-0.4926065747260573
0.22073865040094104,0.07100220044008802,470.0424984294398,40.473400567694,-0.4926065747260573
0.22199240911849413,0.07140548109621925,470.744037581844,40.473400567694,-0.4926065747260573
0.22270884267138166,0.0716359271854371,471.1442233053887,40.473400567694,-0.4926065747260573
0.22312676224389932,0.07177035407081417,471.37743311970013,40.473400567694,-0.4926065747260573
0.2234252762242691,0.07186637327465493,471.54390727227326,40.473400567694,-0.4926065747260573
0.2246790349418222,0.07226965393078616,472.24215357525225,40.473400567694,-0.4926065747260573
0.2259327936593753,0.07267293458691738,472.93888193730805,40.473400567694,-0.4926065747260573
0.22641041602796697,0.07282656531306261,473.20390543541663,40.473400567694,-0.4926065747260573
0.22694774119263258,0.072999399879976,473.50179638294446,40.473400567694,-0.4926065747260573
0.22861941948270337,0.0735371074214843,474.4268140345229,40.473400567694,-0.4926065747260573
0.22885823066699923,0.07361392278455692,474.5587437569914,40.473400567694,-0.4926065747260573
0.23035080056884813,0.07409401880376075,475.38209142505605,40.473400567694,-0.4926065747260573
0.23130604530603144,0.07440128025605121,475.9079422167459,40.473400567694,-0.4926065747260573
0.23184337047069706,0.0745741148229646,476.2033610821955,40.473400567694,-0.4926065747260573
0.23267920961573246,0.07484296859371875,476.66237134925194,40.473400567694,-0.4926065747260573
0.23423148231365534,0.07534226845369074,477.5131165207676,40.473400567694,-0.4926065747260573
0.238888300407424,0.07684016803360673,480.0522560869225,40.473400567694,-0.4926065747260573
0.2390077059995719,0.07687857571514303,480.1171071160415,40.473400567694,-0.4926065747260573
0.2404405731053469,0.07733946789357872,480.8943364886265,40.473400567694,-0.4926065747260573
0.24193314300719584,0.07781956391278257,481.7020319958062,40.473400567694,-0.4926065747260573
0.24258987376400934,0.07803080616123224,482.05680211754907,40.473400567694,-0.4926065747260573
0.2427689821522312,0.0780884176835367,482.1534925732434,40.473400567694,-0.4926065747260573
0.24647055550881655,0.07927905581116224,484.14557559025894,40.473400567694,-0.4926065747260573
0.24873926175962693,0.08000880176035208,485.3607637100009,40.473400567694,-0.4926065747260573
0.2501721288654019,0.08046969393878776,486.1260242721718,40.473400567694,-0.4926065747260573
0.25220202393191643,0.08112262452490498,487.20722372314094,40.473400567694,-0.4926065747260573
0.2523811323201383,0.08118023604720945,487.30246043405106,40.473400567694,-0.4926065747260573
0.25357518824161746,0.08156431286257251,487.93669956719447,40.473400567694,-0.4926065747260573
0.2547692441630966,0.08194838967793559,488.56977500646906,40.473400567694,-0.4926065747260573
0.25536627212383617,0.08214042808561713,488.88587871115885,40.473400567694,-0.4926065747260573
0.25638121965709343,0.08246689337867574,489.42259434328633,40.473400567694,-0.4926065747260573
0.257037950413907,0.08267813562712543,489.76943942351795,40.473400567694,-0.4926065747260573
0.2581126007432382,0.0830238047609522,490.3362595344026,40.473400567694,-0.4926065747260573
0.2594857650529392,0.08346549309861973,491.05919209099847,40.473400567694,-0.4926065747260573
0.26115744334301,0.08400320064012803,491.9372732439371,40.473400567694,-0.4926065747260573
0.26193357969197145,0.08425285057011403,492.3442083944388,40.473400567694,-0.4926065747260573
0.2628888244291548,0.08456011202240449,492.8444066703312,40.473400567694,-0.4926065747260573
0.26336644679774646,0.08471374274854972,493.09423995679555,40.473400567694,-0.4926065747260573
0.2637843663702641,0.08484816963392679,493.31269916832264,40.473400567694,-0.4926065747260573
0.26444109712707764,0.08505941188237648,493.65571969282905,40.473400567694,-0.4926065747260573
0.2649784222917433,0.08523224644928987,493.93612580130645,40.473400567694,-0.4926065747260573
0.26665010058181404,0.08576995399079816,494.8070855674092,40.473400567694,-0.4926065747260573
0.2672471285425536,0.0859619923984797,495.11762621879825,40.473400567694,-0.4926065747260573
0.26766504811507136,0.08609641928385678,495.33484371119056,40.473400567694,-0.4926065747260573
0.2690979152208463,0.08655731146229247,496.0785872924862,40.473400567694,-0.4926065747260573
0.2696949431815859,0.086749349869974,496.3880244299955,40.473400567694,-0.4926065747260573
0.27005315995802964,0.08686457291458292,496.573558482067,40.473400567694,-0.4926065747260573
0.27029197114232545,0.08694138827765553,496.697194530239,40.473400567694,-0.4926065747260573
0.2710681074912869,0.08719103820764153,497.09871778701796,40.473400567694,-0.4926065747260573
0.2717845410441744,0.08742148429685938,497.46895686032684,40.473400567694,-0.4926065747260573
0.2726203801892098,0.08769033806761353,497.9004217215843,40.473400567694,-0.4926065747260573
0.27548611440075976,0.08861212242448491,499.37582886195435,40.473400567694,-0.4926065747260573
0.2775160094672743,0.08926505301060213,500.41728958212656,40.473400567694,-0.4926065747260573
0.27888917377697525,0.08970674134826966,501.12012302858153,40.473400567694,-0.4926065747260573
0.2796056073298628,0.0899371874374875,501.48628290666227,40.473400567694,-0.4926065747260573
0.28085936604741585,0.09034046809361873,502.1261834604536,40.473400567694,-0.4926065747260573
0.2816952051924513,0.09060932186437289,502.5521650270031,40.473400567694,-0.4926065747260573
0.2823519359492648,0.09082056411282256,502.88651911085503,40.473400567694,-0.4926065747260573
0.2840236142393356,0.09135827165433087,503.73623652734034,40.473400567694,-0.4926065747260573
0.28671024006266366,0.09222244448889778,505.09777891541313,40.473400567694,-0.4926065747260573
0.2874863764116251,0.09247209441888378,505.490185855199,40.473400567694,-0.4926065747260573
0.28897894631347404,0.09295219043808763,506.24365527240127,40.473400567694,-0.4926065747260573
0.2914864637485802,0.09375875175035008,507.5060760932853,40.473400567694,-0.4926065747260573
0.29178497772895,0.09385477095419084,507.6560816466244,40.473400567694,-0.4926065747260573
0.29285962805828125,0.0942004400880176,508.19560677781266,40.473400567694,-0.4926065747260573
0.2956656594737572,0.09510302060412083,509.6007391863313,40.473400567694,-0.4926065747260573
0.29674030980308846,0.0954486897379476,510.13749648527033,40.473400567694,-0.4926065747260573
0.29799406852064153,0.09585197039407882,510.7627561060233,40.473400567694,-0.4926065747260573
0.2997851524028603,0.09642808561712343,511.6542073388624,40.473400567694,-0.4926065747260573
0.30121801950863525,0.09688897779555912,512.3658736823621,40.473400567694,-0.4926065747260573
0.3021135614497446,0.09717703540708142,512.809994758296,40.473400567694,-0.4926065747260573
0.3030091033908539,0.09746509301860372,513.2536026994543,40.473400567694,-0.4926065747260573
0.3048001872730727,0.09804120824164833,514.1392875898949,40.473400567694,-0.4926065747260573
0.30521810684559036,0.09817563512702542,514.3456550618083,40.473400567694,-0.4926065747260573
0.30724800191210494,0.09882856571314264,515.3464480286851,40.473400567694,-0.4926065747260573
0.30748681309640075,0.09890538107621524,515.4640186063735,40.473400567694,-0.4926065747260573
0.3086808690178799,0.09928945789157832,516.0513381687116,40.473400567694,-0.4926065747260573
0.30945700536684134,0.09953910782156432,516.4326208039405,40.473400567694,-0.4926065747260573
0.30993462773543295,0.09969273854770955,516.6670709083826,40.473400567694,-0.4926065747260573