File: datasets/aisi_316_L/data/M1/train_80.csv
Time(s),Strain(%),Stress(MPa),Temp(C),Log_SR(s-1)
0.0,0.0,0.0,262.99547759797883,4.066448729646479
1.2357020365928652e-09,1.44e-05,2.602980225,262.99547759797883,4.066448729646479
2.6087042994738263e-09,3.04e-05,5.495180475,262.99547759797883,4.066448729646479
3.9817065623547874e-09,4.6399999999999996e-05,8.387380725,262.99547759797883,4.066448729646479
4.7368578069393164e-09,5.52e-05,9.9780908625,262.99547759797883,4.066448729646479
6.178510182964326e-09,7.2e-05,13.014901125,262.99547759797883,4.066448729646479
6.659060974972662e-09,7.76e-05,14.0271712125,262.99547759797883,4.066448729646479
7.963413124709575e-09,9.279999999999999e-05,16.77476145,262.99547759797883,4.066448729646479
1.0228866858463161e-08,0.0001192,21.5468918625,262.99547759797883,4.066448729646479
1.2768921044792938e-08,0.00014879999999999998,26.897462324999996,262.99547759797883,4.066448729646479
1.3180821723657227e-08,0.0001536,27.7651224,262.99547759797883,4.066448729646479
1.3798672741953661e-08,0.0001608,29.0666125125,262.99547759797883,4.066448729646479
1.4828424439114382e-08,0.0001728,31.2357627,262.99547759797883,4.066448729646479
1.6681977494003676e-08,0.00019439999999999998,35.140233037499996,262.99547759797883,4.066448729646479
1.7093878172867968e-08,0.0001992,36.0078931125,262.99547759797883,4.066448729646479
1.7299828512300112e-08,0.0002016,36.44172315,262.99547759797883,4.066448729646479
1.8123629870028686e-08,0.00021119999999999998,38.177043299999994,262.99547759797883,4.066448729646479
1.8878781114613215e-08,0.00021999999999999998,39.7677534375,262.99547759797883,4.066448729646479
2.086963439579061e-08,0.0002432,43.9614438,262.99547759797883,4.066448729646479
2.258588722439181e-08,0.0002632,47.5766941125,262.99547759797883,4.066448729646479
2.2860487676968002e-08,0.00026639999999999997,48.1551341625,262.99547759797883,4.066448729646479
2.334103846897634e-08,0.000272,49.16740425,262.99547759797883,4.066448729646479
2.4714040731857303e-08,0.000288,52.0596045,262.99547759797883,4.066448729646479
2.581244254216207e-08,0.0003008,54.373364699999996,262.99547759797883,4.066448729646479
2.6636243899890648e-08,0.0003104,56.10868485,262.99547759797883,4.066448729646479
2.746004525761922e-08,0.00031999999999999997,57.844004999999996,262.99547759797883,4.066448729646479
2.8901697633644234e-08,0.0003368,60.8808152625,262.99547759797883,4.066448729646479
3.089255091482162e-08,0.00035999999999999997,65.074505625,262.99547759797883,4.066448729646479
3.3844505780015695e-08,0.0003944,71.29273616249999,262.99547759797883,4.066448729646479
3.549210849547285e-08,0.00041359999999999997,74.76337646249999,262.99547759797883,4.066448729646479
3.858136358695501e-08,0.0004496,81.270827025,262.99547759797883,4.066448729646479
4.1876569017869315e-08,0.000488,88.212107625,262.99547759797883,4.066448729646479
4.331822139389433e-08,0.0005048,91.2489178875,262.99547759797883,4.066448729646479
4.613287603280029e-08,0.0005376,97.17792839999998,262.99547759797883,4.066448729646479
5.052648327401937e-08,0.0005888,106.4329692,262.99547759797883,4.066448729646479
5.3272487799781296e-08,0.0006208,112.2173697,262.99547759797883,4.066448729646479
5.4027639044365825e-08,0.0006296,113.8080798375,262.99547759797883,4.066448729646479
5.505739074152654e-08,0.0006416,115.977230025,262.99547759797883,4.066448729646479
5.9588298209033715e-08,0.0006944,125.52149084999999,262.99547759797883,4.066448729646479
6.109860069820277e-08,0.000712,128.70291112499999,262.99547759797883,4.066448729646479
6.350135465824445e-08,0.00074,133.7642615625,262.99547759797883,4.066448729646479
6.535490771313375e-08,0.0007616,137.66873189999998,262.99547759797883,4.066448729646479
6.652195963658257e-08,0.0007752,140.12710211249998,262.99547759797883,4.066448729646479
6.823821246518376e-08,0.0007951999999999999,143.74235242499998,262.99547759797883,4.066448729646479
6.89933637097683e-08,0.0008039999999999999,145.33306256249998,262.99547759797883,4.066448729646479
6.961121472806473e-08,0.0008112,146.634552675,262.99547759797883,4.066448729646479
7.235721925382666e-08,0.0008432,152.418953175,262.99547759797883,4.066448729646479
7.386752174299571e-08,0.0008608,155.60037345,262.99547759797883,4.066448729646479
7.455402287443619e-08,0.0008688,157.046473575,262.99547759797883,4.066448729646479
7.778057819220644e-08,0.0009063999999999999,163.84314416249998,262.99547759797883,4.066448729646479
7.894763011565526e-08,0.0009199999999999999,166.30151437499998,262.99547759797883,4.066448729646479
8.107578362312076e-08,0.0009448,170.7844247625,262.99547759797883,4.066448729646479
8.29979867911541e-08,0.0009672,174.8335051125,262.99547759797883,4.066448729646479
8.492018995918745e-08,0.0009896,178.8825854625,262.99547759797883,4.066448729646479
8.553804097748388e-08,0.0009968,180.18407557499998,262.99547759797883,4.066448729646479
8.8558645955822e-08,0.001032,186.546916125,262.99547759797883,4.066448729646479
9.01375985581351e-08,0.0010504,189.8729464125,262.99547759797883,4.066448729646479
9.116735025529583e-08,0.0010624,192.0420966,262.99547759797883,4.066448729646479
9.240305229188869e-08,0.0010768,194.645076825,262.99547759797883,4.066448729646479
9.308955342332916e-08,0.0010848,196.09117694999998,262.99547759797883,4.066448729646479
9.473715613878632e-08,0.001104,199.56181725,262.99547759797883,4.066448729646479
9.590420806223513e-08,0.0011175999999999998,202.02018746249996,262.99547759797883,4.066448729646479
9.693395975939586e-08,0.0011296,204.18933765,262.99547759797883,4.066448729646479
9.961131417201374e-08,0.0011608,209.79626347994363,262.99547759797883,4.066448729646479
9.995456473773396e-08,0.0011648,209.8218602911273,262.99547759797883,4.066448729646479
1.021513683583435e-07,0.0011903999999999999,209.98487551962677,262.99547759797883,4.066448729646479
1.0311246994236018e-07,0.0012016,210.0557641261391,262.99547759797883,4.066448729646479
1.0352437062122449e-07,0.0012064,210.08606602050224,262.99547759797883,4.066448729646479
1.0874177922017213e-07,0.0012672,210.46590821918298,262.99547759797883,4.066448729646479
1.1059533227506142e-07,0.0012887999999999999,210.59913214796603,262.99547759797883,4.066448729646479
1.1546949030828884e-07,0.0013456,210.94537046212125,262.99547759797883,4.066448729646479
1.1595004110029716e-07,0.0013511999999999999,210.97919497902697,262.99547759797883,4.066448729646479
1.1794089438147457e-07,0.0013744,211.1187466418353,262.99547759797883,4.066448729646479
1.186960456260591e-07,0.0013832,211.1714393222341,262.99547759797883,4.066448729646479
1.2151070026496507e-07,0.001416,211.3666980313554,262.99547759797883,4.066448729646479
1.2295235264099007e-07,0.0014328,211.46602493481703,262.99547759797883,4.066448729646479
1.2432535490387104e-07,0.0014487999999999999,211.56020055002097,262.99547759797883,4.066448729646479
1.2542375671417582e-07,0.0014616,211.6352493232502,262.99547759797883,4.066448729646479
1.2576700727989604e-07,0.0014655999999999998,211.65864944110484,262.99547759797883,4.066448729646479
1.2645350841133653e-07,0.0014736,211.70537508859783,262.99547759797883,4.066448729646479
1.272773097690651e-07,0.0014831999999999998,211.76131548005293,262.99547759797883,4.066448729646479
1.2810111112679368e-07,0.0014927999999999999,211.81711483965233,262.99547759797883,4.066448729646479
1.2961141361596273e-07,0.0015103999999999999,211.91905153979647,262.99547759797883,4.066448729646479
1.3125901633141988e-07,0.0015295999999999999,212.02972831869303,262.99547759797883,4.066448729646479
1.3228876802858062e-07,0.0015416,212.09862623715043,262.99547759797883,4.066448729646479
1.329752691600211e-07,0.0015496,212.1444420181022,262.99547759797883,4.066448729646479
1.344169215360461e-07,0.0015664,212.24035598029357,262.99547759797883,4.066448729646479
1.3606452425150326e-07,0.0015856,212.3494820409766,262.99547759797883,4.066448729646479
1.3647642493036753e-07,0.0015903999999999998,212.3766828830648,262.99547759797883,4.066448729646479
1.3709427594866397e-07,0.0015976,212.41742419120212,262.99547759797883,4.066448729646479
1.375748267406723e-07,0.0016032,212.44906238863868,262.99547759797883,4.066448729646479
1.388791788904092e-07,0.0016183999999999999,212.5347209834516,262.99547759797883,4.066448729646479
1.3977163036128184e-07,0.0016288,212.59314879658598,262.99547759797883,4.066448729646479
1.3990893058756994e-07,0.0016304,212.6021247607978,262.99547759797883,4.066448729646479
1.4203708409503543e-07,0.0016552,212.74081586382223,262.99547759797883,4.066448729646479
1.425862850001878e-07,0.0016615999999999998,212.77647526236643,262.99547759797883,4.066448729646479
1.434100863579164e-07,0.0016711999999999999,212.82986408761207,262.99547759797883,4.066448729646479
1.4450848816822118e-07,0.001684,212.90086350326865,262.99547759797883,4.066448729646479
1.4649934144939856e-07,0.0017071999999999999,213.0290158043651,262.99547759797883,4.066448729646479
1.4704854235455096e-07,0.0017136,213.06424840730747,262.99547759797883,4.066448729646479
1.480096439385676e-07,0.0017247999999999999,213.12578222471473,262.99547759797883,4.066448729646479
1.481469441648557e-07,0.0017264,213.13456003228805,262.99547759797883,4.066448729646479
1.4938264620144857e-07,0.0017407999999999998,213.21341804259512,262.99547759797883,4.066448729646479
1.5096159880376168e-07,0.0017591999999999998,213.31381181761722,262.99547759797883,4.066448729646479
1.5137349948262598e-07,0.001764,213.33993404340893,262.99547759797883,4.066448729646479
1.5219730084035454e-07,0.0017736,213.39209547880193,262.99547759797883,4.066448729646479
1.5315840242437124e-07,0.0017848,213.45281152288126,262.99547759797883,4.066448729646479
1.5480600513982837e-07,0.0018039999999999998,213.5565515976443,262.99547759797883,4.066448729646479
1.554238561581248e-07,0.0018112,213.59534299809206,262.99547759797883,4.066448729646479
1.5700280876043792e-07,0.0018296,213.69420433501273,262.99547759797883,4.066448729646479
1.6091586520964864e-07,0.0018751999999999998,213.93755186514224,262.99547759797883,4.066448729646479
1.6180831668052128e-07,0.0018855999999999999,213.992727680703,262.99547759797883,4.066448729646479
1.6263211803824984e-07,0.0018951999999999999,214.0435539526831,262.99547759797883,4.066448729646479
1.65721373129732e-07,0.0019311999999999999,214.23326479199562,262.99547759797883,4.066448729646479
1.673003257320451e-07,0.0019496,214.3296951608166,262.99547759797883,4.066448729646479
1.6949712935265464e-07,0.0019752,214.46327078505803,262.99547759797883,4.066448729646479
1.69977680144663e-07,0.0019808,214.49240025419874,262.99547759797883,4.066448729646479
1.7121338218125586e-07,0.0019952,214.56715750727298,262.99547759797883,4.066448729646479
1.7258638444413683e-07,0.0020112,214.64997476452962,262.99547759797883,4.066448729646479
1.7299828512300112e-07,0.002016,214.67476978439547,262.99547759797883,4.066448729646479
1.7492048829103446e-07,0.0020384,214.79017681303577,262.99547759797883,4.066448729646479
1.7704864179849993e-07,0.0020632,214.91737348296263,262.99547759797883,4.066448729646479
1.7780379304308448e-07,0.002072,214.9623642732806,262.99547759797883,4.066448729646479
1.795200458716857e-07,0.002092,215.06433984163877,262.99547759797883,4.066448729646479
1.8034384722941426e-07,0.0021016,215.1131530014923,262.99547759797883,4.066448729646479
1.808243980214226e-07,0.0021072,215.1415871860922,262.99547759797883,4.066448729646479
1.8157954926600712e-07,0.002116,215.18621000624972,262.99547759797883,4.066448729646479
1.8302120164203212e-07,0.0021328,215.27119856363532,262.99547759797883,4.066448729646479
1.8528665537578572e-07,0.0021592,215.40422640321611,262.99547759797883,4.066448729646479
1.8597315650722618e-07,0.0021671999999999998,215.44441243604132,262.99547759797883,4.066448729646479
1.862477569598024e-07,0.0021704,215.46047064516435,262.99547759797883,4.066448729646479
1.8665965763866669e-07,0.0021752,215.4845406566878,262.99547759797883,4.066448729646479
1.8741480888325118e-07,0.0021839999999999997,215.5286152787379,262.99547759797883,4.066448729646479
1.8851321069355599e-07,0.0021968,215.59260038316603,262.99547759797883,4.066448729646479
1.8878781114613215e-07,0.0021999999999999997,215.60857392033165,262.99547759797883,4.066448729646479
1.8947431227757263e-07,0.002208,215.6484681710338,262.99547759797883,4.066448729646479
1.9146516555875004e-07,0.0022312,215.76384394669788,262.99547759797883,4.066448729646479
1.929754680479191e-07,0.0022488,215.8510585606408,262.99547759797883,4.066448729646479
1.9400521974507982e-07,0.0022608,215.91037049801835,262.99547759797883,4.066448729646479
1.9476037098966435e-07,0.0022696,215.95378791484595,262.99547759797883,4.066448729646479
1.9606472313940127e-07,0.0022848,216.02862731245511,262.99547759797883,4.066448729646479
1.9846747709944292e-07,0.0023128,216.16598302926204,262.99547759797883,4.066448729646479
1.9949722879660363e-07,0.0023247999999999997,216.22465106413492,262.99547759797883,4.066448729646479
2.0018372992804414e-07,0.0023328,216.26369748797742,262.99547759797883,4.066448729646479
2.0361623558524656e-07,0.0023728,216.45815171521042,262.99547759797883,4.066448729646479
2.049892378481275e-07,0.0023888,216.5355749309788,262.99547759797883,4.066448729646479
2.0595033943214417e-07,0.0024,216.5896508911209,262.99547759797883,4.066448729646479
2.084217435053299e-07,0.0024288,216.72825337180427,262.99547759797883,4.066448729646479
2.1075584735222755e-07,0.002456,216.8585683358463,262.99547759797883,4.066448729646479
2.118542491625323e-07,0.0024687999999999997,216.91969815292057,262.99547759797883,4.066448729646479
2.139824026699978e-07,0.0024936,217.0377865658966,262.99547759797883,4.066448729646479
2.1563000538545497e-07,0.0025128,217.12889556124367,262.99547759797883,4.066448729646479
2.1652245685632757e-07,0.0025231999999999997,217.17813289075642,262.99547759797883,4.066448729646479
2.1926846138208953e-07,0.0025552,217.32913828380995,262.99547759797883,4.066448729646479
2.2016091285296213e-07,0.0025656,217.37805599947578,262.99547759797883,4.066448729646479
2.2373071873645263e-07,0.0026072,217.57295843455773,262.99547759797883,4.066448729646479
2.2407396930217285e-07,0.0026111999999999997,217.5916349072252,262.99547759797883,4.066448729646479
2.251037209993336e-07,0.0026232,217.64759749301984,262.99547759797883,4.066448729646479
2.2530967133876574e-07,0.0026256,217.65877801951265,262.99547759797883,4.066448729646479
2.2620212280963834e-07,0.002636,217.70718098320435,262.99547759797883,4.066448729646479
2.3100763072972172e-07,0.002692,217.96654321365946,262.99547759797883,4.066448729646479
2.3299848401089913e-07,0.0027152,218.07337583209835,262.99547759797883,4.066448729646479
2.3492068717893245e-07,0.0027375999999999998,218.1761872771749,262.99547759797883,4.066448729646479
2.360877391023813e-07,0.0027512,218.23844846122017,262.99547759797883,4.066448729646479
2.3677424023382175e-07,0.0027592,218.2750166176036,262.99547759797883,4.066448729646479
2.3842184294927893e-07,0.0027784,218.36261189619626,262.99547759797883,4.066448729646479
2.395202447595837e-07,0.0027911999999999998,218.4208776312043,262.99547759797883,4.066448729646479
2.4171704838019324e-07,0.0028168,218.5370974183811,262.99547759797883,4.066448729646479
2.4212894905905753e-07,0.0028216,218.55884269248665,262.99547759797883,4.066448729646479
2.4295275041678607e-07,0.0028312,218.6022900081354,262.99547759797883,4.066448729646479
2.448749535848194e-07,0.0028536,218.70344425435806,262.99547759797883,4.066448729646479
2.4748365788429326e-07,0.002884,218.84023108764822,262.99547759797883,4.066448729646479
2.4803285878944563e-07,0.0028904,218.86895653227992,262.99547759797883,4.066448729646479
2.4947451116547067e-07,0.0029072,218.9442430498713,262.99547759797883,4.066448729646479
2.5180861501236825e-07,0.0029343999999999998,219.06577676150587,262.99547759797883,4.066448729646479
2.526324163700969e-07,0.002944,219.10856601304422,262.99547759797883,4.066448729646479
2.532502673883933e-07,0.0029511999999999997,219.1406222498575,262.99547759797883,4.066448729646479
2.559276218010112e-07,0.0029824,219.27918164216194,262.99547759797883,4.066448729646479
2.5709467372445997e-07,0.002996,219.33940228514118,262.99547759797883,4.066448729646479
2.575752245164683e-07,0.0030015999999999997,219.3641680218679,262.99547759797883,4.066448729646479
2.590855270056374e-07,0.0030191999999999997,219.4418861406187,262.99547759797883,4.066448729646479
2.6093908006052665e-07,0.0030407999999999998,219.53702640216918,262.99547759797883,4.066448729646479
2.6203748187083145e-07,0.0030536,219.59328144827077,262.99547759797883,4.066448729646479
2.6286128322856e-07,0.0030632,219.63541240049832,262.99547759797883,4.066448729646479
2.640283351520088e-07,0.0030767999999999998,219.69500987423206,262.99547759797883,4.066448729646479
2.6416563537829694e-07,0.0030784,219.70201458091412,262.99547759797883,4.066448729646479
2.6492078662288147e-07,0.0030872,219.7405151174612,262.99547759797883,4.066448729646479
2.664310891120505e-07,0.0031048,219.81738802897254,262.99547759797883,4.066448729646479
2.668429897909148e-07,0.0031095999999999997,219.83832384947013,262.99547759797883,4.066448729646479
2.6746084080921125e-07,0.0031168,219.86970396418363,262.99547759797883,4.066448729646479
2.698635947692529e-07,0.0031447999999999997,219.99146994059586,262.99547759797883,4.066448729646479
2.7020684533497313e-07,0.0031487999999999998,220.00883050172862,262.99547759797883,4.066448729646479
2.7164849771099816e-07,0.0031655999999999998,220.08165113631682,262.99547759797883,4.066448729646479
2.7363935099217557e-07,0.0031888,220.1819656676277,262.99547759797883,4.066448729646479
2.7411990178418393e-07,0.0031944,220.20613682665376,262.99547759797883,4.066448729646479
2.751496534813446e-07,0.0032064,220.257876590046,262.99547759797883,4.066448729646479
2.792686602699875e-07,0.0032543999999999997,220.4640848996259,262.99547759797883,4.066448729646479
2.808476128723006e-07,0.0032727999999999998,220.5428164948015,262.99547759797883,4.066448729646479
2.831130666060542e-07,0.0032992,220.6554783577801,262.99547759797883,4.066448729646479
2.8462336909522324e-07,0.0033168,220.73039100024275,262.99547759797883,4.066448729646479
2.8544717045295183e-07,0.0033263999999999998,220.7711870931375,262.99547759797883,4.066448729646479
2.8579042101867206e-07,0.0033304,220.7881719101278,262.99547759797883,4.066448729646479
2.8668287248954466e-07,0.0033407999999999997,220.83229524250248,262.99547759797883,4.066448729646479
2.877126241867054e-07,0.0033528,220.8831402694794,262.99547759797883,4.066448729646479
2.8874237588386614e-07,0.0033648,220.93391437384386,262.99547759797883,4.066448729646479
2.901840282598911e-07,0.0033816,221.00487963833808,262.99547759797883,4.066448729646479
2.915570305227721e-07,0.0033975999999999998,221.07233788076664,262.99547759797883,4.066448729646479
2.9375383414338164e-07,0.0034232,221.18001394177205,262.99547759797883,4.066448729646479
2.960879379902793e-07,0.0034503999999999997,221.29407622838514,262.99547759797883,4.066448729646479
2.973236400268721e-07,0.0034647999999999997,221.3543201488353,262.99547759797883,4.066448729646479
2.9917719308176143e-07,0.0034863999999999997,221.4445032631773,262.99547759797883,4.066448729646479
3.01373996702371e-07,0.003512,221.55110527188288,262.99547759797883,4.066448729646479
3.043946016807091e-07,0.0035472,221.69718952826221,262.99547759797883,4.066448729646479
3.0590490416987813e-07,0.0035648,221.77001956703756,262.99547759797883,4.066448729646479
3.0659140530131864e-07,0.0035727999999999997,221.80307775850898,262.99547759797883,4.066448729646479
3.076898071116234e-07,0.0035856,221.85591088171068,262.99547759797883,4.066448729646479
3.080330576773436e-07,0.0035895999999999996,221.87240614128024,262.99547759797883,4.066448729646479
3.0871955880878413e-07,0.0035976,221.90537517020718,262.99547759797883,4.066448729646479
3.110536626556817e-07,0.0036247999999999996,222.01725661749984,262.99547759797883,4.066448729646479
3.129758658237151e-07,0.0036471999999999997,222.10914863699057,262.99547759797883,4.066448729646479
3.133877665025794e-07,0.003652,222.12881111800587,262.99547759797883,4.066448729646479
3.145548184260282e-07,0.0036655999999999998,222.1844668217885,262.99547759797883,4.066448729646479
3.1517266944432466e-07,0.0036728,222.2138990004132,262.99547759797883,4.066448729646479
3.167516220466378e-07,0.0036912,222.2890125193888,262.99547759797883,4.066448729646479
3.181246243095187e-07,0.0037072,222.3542100032921,262.99547759797883,4.066448729646479
3.189484256672473e-07,0.0037167999999999997,222.39327581997188,262.99547759797883,4.066448729646479
3.19978177364408e-07,0.0037288,222.44205279679124,262.99547759797883,4.066448729646479
3.2107657917471277e-07,0.0037416,222.49401414316077,262.99547759797883,4.066448729646479
3.216944301930092e-07,0.0037487999999999996,222.52321193401798,262.99547759797883,4.066448729646479
3.2279283200331396e-07,0.0037616,222.57506517447803,262.99547759797883,4.066448729646479
3.252642360764997e-07,0.0037903999999999998,222.69148402327872,262.99547759797883,4.066448729646479
3.2649993811309256e-07,0.0038047999999999997,222.74956404288548,262.99547759797883,4.066448729646479
3.267745385656688e-07,0.0038079999999999998,222.7624590645488,262.99547759797883,4.066448729646479
3.2746103969710923e-07,0.003816,222.79467814333162,262.99547759797883,4.066448729646479
3.280788907154057e-07,0.0038231999999999997,222.8236527982772,262.99547759797883,4.066448729646479
3.3192329705147236e-07,0.003868,223.00346371667345,262.99547759797883,4.066448729646479
3.326097981829128e-07,0.0038759999999999997,223.03548715496163,262.99547759797883,4.066448729646479
3.3446335123780214e-07,0.0038975999999999998,223.12182194057004,262.99547759797883,4.066448729646479
3.358363535006831e-07,0.0039136,223.18565337977176,262.99547759797883,4.066448729646479
3.381018072344367e-07,0.00394,223.29075319720155,262.99547759797883,4.066448729646479
3.392002090447415e-07,0.0039528,223.34161179231788,262.99547759797883,4.066448729646479
3.424267643625117e-07,0.0039904,223.49063877031597,262.99547759797883,4.066448729646479
3.430446153808081e-07,0.0039976,223.51911326994653,262.99547759797883,4.066448729646479
3.597298887394157e-07,0.0041920384076815365,224.28067541704732,262.99547759797883,4.066448729646479
3.7620921175859106e-07,0.004384076815363073,225.01942772798378,262.99547759797883,4.066448729646479
3.860968055700963e-07,0.004499299859971995,225.4566224526477,262.99547759797883,4.066448729646479
4.075199254950243e-07,0.004748949789957992,226.3891705518312,262.99547759797883,4.066448729646479
4.3718270692953996e-07,0.005094618923784757,227.6494124655661,262.99547759797883,4.066448729646479
4.750851498736433e-07,0.005536307261452291,229.21218364157124,262.99547759797883,4.066448729646479
5.344107127426746e-07,0.006227645529105821,231.56389988593472,262.99547759797883,4.066448729646479
6.266949216500567e-07,0.007303060612122424,235.02874633810927,262.99547759797883,4.066448729646479
6.448221769711496e-07,0.007514302860572114,235.68528832848253,262.99547759797883,4.066448729646479
6.711890938018301e-07,0.007821564312862572,236.62755101869018,262.99547759797883,4.066448729646479
6.942601460286757e-07,0.008090418083616723,237.44024917953126,262.99547759797883,4.066448729646479
7.024998075382634e-07,0.008186437287457491,237.72793693912314,262.99547759797883,4.066448729646479
7.156832659536036e-07,0.00834006801360272,238.18551509991855,262.99547759797883,4.066448729646479
7.453460473881193e-07,0.008685737147429486,239.20321376658967,262.99547759797883,4.066448729646479
7.618253704072947e-07,0.008877775555111022,239.76177239418666,262.99547759797883,4.066448729646479
8.524616470127593e-07,0.009933986797359472,242.75349648311106,262.99547759797883,4.066448729646479
8.771806315415222e-07,0.010222044408881775,243.54753912620066,262.99547759797883,4.066448729646479
9.348582621086361e-07,0.010894178835767154,245.36711424461555,262.99547759797883,4.066448729646479
9.826482988642447e-07,0.011451090218043608,246.8418102649027,262.99547759797883,4.066448729646479
9.95831757279585e-07,0.011604720944188837,247.24366573263848,262.99547759797883,4.066448729646479
1.0156069449025954e-06,0.01183516703340668,247.84258032196593,262.99547759797883,4.066448729646479
1.0469176586390285e-06,0.0122000400080016,248.78164279848838,262.99547759797883,4.066448729646479
1.091411830790802e-06,0.012718543708741748,250.09747090399557,262.99547759797883,4.066448729646479
1.1490894613579158e-06,0.013390678135627125,251.77244052008297,262.99547759797883,4.066448729646479
1.1573291228675035e-06,0.013486697339467894,252.0090173137005,262.99547759797883,4.066448729646479
1.1771043104905141e-06,0.013717143428685737,252.574137454142,262.99547759797883,4.066448729646479
1.1853439720001018e-06,0.013813162632526505,252.80850997286834,262.99547759797883,4.066448729646479
1.2248943472461226e-06,0.014274054810962193,253.9247714056061,262.99547759797883,4.066448729646479
1.2463174671710507e-06,0.01452370474094819,254.5235398696626,262.99547759797883,4.066448729646479
1.2562050609825558e-06,0.014638927785557112,254.79853939934222,262.99547759797883,4.066448729646479
1.2825719778132364e-06,0.01494618923784757,255.52777547044732,262.99547759797883,4.066448729646479
1.3188264884554222e-06,0.01536867373474695,256.52099928910593,262.99547759797883,4.066448729646479
1.3402496083803503e-06,0.015618323664732947,257.1028993558736,262.99547759797883,4.066448729646479
1.3929834420417114e-06,0.016232846569313862,258.52002446858177,262.99547759797883,4.066448729646479
1.4028710358532165e-06,0.016348069613922784,258.7833897774681,262.99547759797883,4.066448729646479
1.4391255464954023e-06,0.016770554110822164,259.74293044993254,262.99547759797883,4.066448729646479
1.5000990416663511e-06,0.017481096219243847,261.33570877897705,262.99547759797883,4.066448729646479
1.5380014846104545e-06,0.017922784556911382,262.3130959077193,262.99547759797883,4.066448729646479
1.5676642660449703e-06,0.018268453690738148,263.0714695899396,262.99547759797883,4.066448729646479
1.5824956567622282e-06,0.018441288257651532,263.4485562517451,262.99547759797883,4.066448729646479
1.6171022351024964e-06,0.018844568913782757,264.3231053270562,262.99547759797883,4.066448729646479
1.6220460320082493e-06,0.01890218043608722,264.44744245455155,262.99547759797883,4.066448729646479
1.671484001065775e-06,0.019478295659131825,265.6827911705718,262.99547759797883,4.066448729646479
1.6929071209907032e-06,0.019727945589117824,266.2136742986018,262.99547759797883,4.066448729646479
1.711034376311796e-06,0.019939187837567512,266.6608397998093,262.99547759797883,4.066448729646479
1.725865767029054e-06,0.020112022404480897,267.0253298270106,262.99547759797883,4.066448729646479
1.7555285484635697e-06,0.020457691538307662,267.75066561506856,262.99547759797883,4.066448729646479
1.7769516683884975e-06,0.020707341468293658,268.27154983891563,262.99547759797883,4.066448729646479
1.8016706529172605e-06,0.020995399079815964,268.8695364356296,262.99547759797883,4.066448729646479
1.8478127573709516e-06,0.021533106621324266,269.9772859470931,262.99547759797883,4.066448729646479
1.9021945233342302e-06,0.022166833366673334,271.2690915850701,262.99547759797883,4.066448729646479
1.9681118154109317e-06,0.02293498699739948,272.8157634945283,262.99547759797883,4.066448729646479
1.991182867637777e-06,0.02320384076815363,273.352308210401,262.99547759797883,4.066448729646479
2.014253919864623e-06,0.023472694538907782,273.8864338057795,262.99547759797883,4.066448729646479
2.0900588057528294e-06,0.02435607121424285,275.62485477469824,262.99547759797883,4.066448729646479
2.10983399337584e-06,0.024586517303460693,276.07428960090846,262.99547759797883,4.066448729646479
2.1213695194892625e-06,0.024720944188837767,276.3357012347445,262.99547759797883,4.066448729646479
2.146088504018026e-06,0.025009001800360073,276.8940095183615,262.99547759797883,4.066448729646479
2.159271962433366e-06,0.025162632526505302,277.19074819062644,262.99547759797883,4.066448729646479
2.2449644421330783e-06,0.02616123224644929,279.1026085291602,262.99547759797883,4.066448729646479
2.269683426661841e-06,0.026449289857971594,279.6487895789659,262.99547759797883,4.066448729646479
2.2746272235675938e-06,0.026506901380276057,279.7577468664622,262.99547759797883,4.066448729646479
2.2894586142848515e-06,0.026679735947189438,280.0840659306432,262.99547759797883,4.066448729646479
2.3108817342097798e-06,0.026929385877175437,280.5539639603378,262.99547759797883,4.066448729646479
2.409757672324832e-06,0.028081616323264655,282.7010806675974,262.99547759797883,4.066448729646479
2.4278849276459246e-06,0.028292858571714343,283.0909630115933,262.99547759797883,4.066448729646479
2.4476601152689352e-06,0.028523304660932187,283.51499669903336,262.99547759797883,4.066448729646479
2.5201691365533068e-06,0.029368273654730947,285.05848572214404,262.99547759797883,4.066448729646479
2.5251129334590592e-06,0.029425885177035406,285.1630885613784,262.99547759797883,4.066448729646479
2.5613674441012452e-06,0.029848369673934786,285.92775037959353,262.99547759797883,4.066448729646479
2.5926781578376784e-06,0.030213242648529707,286.5847494202844,262.99547759797883,4.066448729646479
2.6421161268952045e-06,0.030789357871574316,287.6158508983601,262.99547759797883,4.066448729646479
2.653651653008627e-06,0.03092378475695139,287.85535527214137,262.99547759797883,4.066448729646479
2.668483043725885e-06,0.031096619323864774,288.16269367818126,262.99547759797883,4.066448729646479
2.68496236674506e-06,0.03128865773154631,288.5034005245981,262.99547759797883,4.066448729646479
2.7228648096891637e-06,0.03173034606921384,289.28394629824305,262.99547759797883,4.066448729646479
2.7591193203313493e-06,0.03215283056611322,290.0265996948282,262.99547759797883,4.066448729646479
2.8069093570869582e-06,0.03270974194838968,290.999762890087,262.99547759797883,4.066448729646479
2.821740747804216e-06,0.03288257651530306,291.3004623374607,262.99547759797883,4.066448729646479
2.834924206219556e-06,0.03303620724144829,291.5672336519498,262.99547759797883,4.066448729646479
2.8662349199559897e-06,0.03340108021604321,292.1988838802651,262.99547759797883,4.066448729646479
2.87941837837133e-06,0.03355471094218844,292.46403613691695,262.99547759797883,4.066448729646479
2.9041373629000924e-06,0.03384276855371074,292.95992397982036,262.99547759797883,4.066448729646479
2.907433227503928e-06,0.03388117623524705,293.02591776565004,262.99547759797883,4.066448729646479
2.9272084151269383e-06,0.034111622324464894,293.42126951994356,262.99547759797883,4.066448729646479
2.9618149934672067e-06,0.03451490298059612,294.11063776904336,262.99547759797883,4.066448729646479
2.9947736395055574e-06,0.03489897979595919,294.76426424603477,262.99547759797883,4.066448729646479
3.0178446917324024e-06,0.03516783356671334,295.22013454901077,262.99547759797883,4.066448729646479
3.0376198793554135e-06,0.03539827965593119,295.6097997820921,262.99547759797883,4.066448729646479
3.049155405468836e-06,0.03553270654130826,295.83664762437206,262.99547759797883,4.066448729646479
3.0920016453186916e-06,0.03603200640128025,296.67631095050245,262.99547759797883,4.066448729646479
3.1183685621493723e-06,0.03633926785357071,297.1907718532087,262.99547759797883,4.066448729646479
3.1546230727915583e-06,0.03676175235047009,297.89539411754515,262.99547759797883,4.066448729646479
3.184285854226074e-06,0.037107421484296854,298.46955712899387,262.99547759797883,4.066448729646479
3.217244500264425e-06,0.037491498299659934,299.10507513042467,262.99547759797883,4.066448729646479
3.2287800263778475e-06,0.037625925185037004,299.32690591245677,262.99547759797883,4.066448729646479
3.2485552140008585e-06,0.037856371274254855,299.7064694905736,262.99547759797883,4.066448729646479
3.2765700631334556e-06,0.03818283656731346,300.2426456480875,262.99547759797883,4.066448729646479
3.311176641473724e-06,0.03858611722344468,300.9025188566973,262.99547759797883,4.066448729646479
3.3573187459274157e-06,0.03912382476495299,301.7781809564285,262.99547759797883,4.066448729646479
3.365558407437003e-06,0.03921984396879376,301.93405401285565,262.99547759797883,4.066448729646479
3.4100525795887766e-06,0.03973834766953391,302.77321070424637,262.99547759797883,4.066448729646479
3.4149963764945295e-06,0.03979595919183837,302.8661859919978,262.99547759797883,4.066448729646479
3.4298277672117864e-06,0.039968793758751744,303.1447974065128,262.99547759797883,4.066448729646479
3.4364194964194573e-06,0.040045609121824366,303.26847383999484,262.99547759797883,4.066448729646479
3.5056326530999936e-06,0.040852170434086815,304.561539050941,262.99547759797883,4.066448729646479
3.5435350960440977e-06,0.04129385877175436,305.26542568270696,262.99547759797883,4.066448729646479
3.556718554459438e-06,0.04144748949789959,305.50956674048086,262.99547759797883,4.066448729646479
3.5666061482709423e-06,0.0415627125425085,305.69244099274187,262.99547759797883,4.066448729646479
3.6226358465361397e-06,0.04221564312862573,306.72501787326036,262.99547759797883,4.066448729646479
3.6770176124994175e-06,0.042849369873974794,307.72128488302695,262.99547759797883,4.066448729646479
3.6984407324243453e-06,0.04309901980396079,308.1121739055731,262.99547759797883,4.066448729646479
3.7346952430665317e-06,0.04352150430086017,308.77167270693474,262.99547759797883,4.066448729646479
3.7511745660857066e-06,0.043713542708541706,309.0706190267705,262.99547759797883,4.066448729646479
3.7923728736336455e-06,0.04419363872774555,309.8157527025187,262.99547759797883,4.066448729646479
3.818739790464326e-06,0.04450090018003601,310.2909819722198,262.99547759797883,4.066448729646479
3.831923248879667e-06,0.04465453090618124,310.5281165967664,262.99547759797883,4.066448729646479
3.868177759521853e-06,0.04507701540308062,311.1786018457104,262.99547759797883,4.066448729646479
3.881361217937193e-06,0.04523064612922585,311.41455186594794,262.99547759797883,4.066448729646479
3.89619260865445e-06,0.045403480696139226,311.6796223545998,262.99547759797883,4.066448729646479
3.9588140361273165e-06,0.04613322664532907,312.7944980295354,262.99547759797883,4.066448729646479
3.998364411373338e-06,0.046594118823764755,313.4950876028015,262.99547759797883,4.066448729646479
4.0230833959021e-06,0.046882176435287054,313.931583897024,262.99547759797883,4.066448729646479
4.0560420419404515e-06,0.047266253250650134,314.51195537112926,262.99547759797883,4.066448729646479
4.065929635751957e-06,0.04738147629525906,314.6857077828673,262.99547759797883,4.066448729646479
4.107127943299895e-06,0.04786157231446289,315.40790952939585,262.99547759797883,4.066448729646479
4.179636964584267e-06,0.04870654130826166,316.67215972681583,262.99547759797883,4.066448729646479
4.21753940752837e-06,0.04914822964592919,317.32961189909645,262.99547759797883,4.066448729646479
4.273569105793566e-06,0.04980116023204641,318.297292465998,262.99547759797883,4.066448729646479
4.33124673636068e-06,0.050473294658931786,319.2882797860175,262.99547759797883,4.066448729646479
4.374092976210535e-06,0.05097259451890378,320.0211133853136,262.99547759797883,4.066448729646479
4.385628502323959e-06,0.05110702140428086,320.21793572878977,262.99547759797883,4.066448729646479
4.42517887756998e-06,0.05156791358271655,320.8912276651059,262.99547759797883,4.066448729646479
4.433418539079567e-06,0.051663932786557315,321.03120096724894,262.99547759797883,4.066448729646479
4.5224068833831145e-06,0.052700940188037615,322.5365040430526,262.99547759797883,4.066448729646479
4.555365529421465e-06,0.05308501700340068,323.09108645999095,262.99547759797883,4.066448729646479
4.56525312323297e-06,0.053200240048009606,323.25715574923277,262.99547759797883,4.066448729646479
4.5817324462521455e-06,0.05339227845569114,323.53362651549986,262.99547759797883,4.066448729646479
4.598211769271321e-06,0.05358431686337267,323.8097097386571,262.99547759797883,4.066448729646479
4.608099363082826e-06,0.0536995399079816,323.9751744551044,262.99547759797883,4.066448729646479
4.624578686102001e-06,0.05389157831566313,324.2506416152273,262.99547759797883,4.066448729646479
4.771244660972662e-06,0.05560072014402881,326.68566135485514,262.99547759797883,4.066448729646479
4.781132254784168e-06,0.055715943188637734,326.84876187019137,262.99547759797883,4.066448729646479
4.819034697728271e-06,0.05615763152630526,327.47276566054796,262.99547759797883,4.066448729646479
4.8569371406723736e-06,0.05659931986397279,328.0948582848742,262.99547759797883,4.066448729646479
4.888247854408807e-06,0.05696419283856771,328.6073341039621,262.99547759797883,4.066448729646479
4.908023042031819e-06,0.05719463892778556,328.93034353725926,262.99547759797883,4.066448729646479
4.917910635843323e-06,0.057309861972394474,329.0916578876232,262.99547759797883,4.066448729646479
4.967348604900849e-06,0.05788597719543909,329.896340093932,262.99547759797883,4.066448729646479
4.992067589429612e-06,0.058174034806961386,330.2975094888991,262.99547759797883,4.066448729646479
5.0134907093545405e-06,0.058423684736947396,330.6445633825939,262.99547759797883,4.066448729646479
5.061280746110149e-06,0.05898059611922385,331.4166831268016,262.99547759797883,4.066448729646479
5.079408001431242e-06,0.05919183836767354,331.7088116817321,262.99547759797883,4.066448729646479
5.082703866035077e-06,0.059230246049209845,331.7618822523753,262.99547759797883,4.066448729646479
5.090943527544664e-06,0.05932626525305061,331.8944999948735,262.99547759797883,4.066448729646479
5.153564955017531e-06,0.06005601120224045,332.8996734936665,262.99547759797883,4.066448729646479
5.181579804150129e-06,0.060382476495299056,333.3478130256215,262.99547759797883,4.066448729646479
5.259032622340254e-06,0.061285057011402286,334.58189609419287,262.99547759797883,4.066448729646479
5.2886954037747686e-06,0.06163072614522905,335.05264394071037,262.99547759797883,4.066448729646479
5.306822659095862e-06,0.06184196839367874,335.339816309131,262.99547759797883,4.066448729646479
5.324949914416955e-06,0.06205321064212843,335.6266063668138,262.99547759797883,4.066448729646479
5.367796154266811e-06,0.06255251050210042,336.30296443603305,262.99547759797883,4.066448729646479
5.404050664908997e-06,0.0629749949989998,336.8736244805349,262.99547759797883,4.066448729646479
5.445248972456935e-06,0.06345509101820364,337.5202925487943,262.99547759797883,4.066448729646479
5.493039009212543e-06,0.06401200240048009,338.2680418324461,262.99547759797883,4.066448729646479
5.50127867072213e-06,0.06410802160432086,338.39670727051725,262.99547759797883,4.066448729646479
5.5276455875528115e-06,0.06441528305661132,338.80793252996705,262.99547759797883,4.066448729646479
5.558956301289244e-06,0.06478015603120624,339.29527024632876,262.99547759797883,4.066448729646479
5.590267015025678e-06,0.06514502900580116,339.7815386119695,262.99547759797883,4.066448729646479
5.606746338044853e-06,0.06533706741348269,340.0370426304702,262.99547759797883,4.066448729646479
5.651240510196627e-06,0.06585557111422284,340.72544474577165,262.99547759797883,4.066448729646479
5.6973826146503186e-06,0.06639327865573115,341.43711423763773,262.99547759797883,4.066448729646479
5.712214005367577e-06,0.06656611322264454,341.6653873020443,262.99547759797883,4.066448729646479
5.738580922198257e-06,0.066873374674935,342.0706361592152,262.99547759797883,4.066448729646479
5.75670817751935e-06,0.06708461692338469,342.34882360629365,262.99547759797883,4.066448729646479
5.7929626881615356e-06,0.06750710142028406,342.90417571692245,262.99547759797883,4.066448729646479
5.822625469596052e-06,0.06785277055411083,343.35754719766163,262.99547759797883,4.066448729646479
5.834160995709474e-06,0.0679871974394879,343.53361495683464,262.99547759797883,4.066448729646479
5.852288251030567e-06,0.0681984396879376,343.81001880233083,262.99547759797883,4.066448729646479
5.906670016993845e-06,0.06883216643328666,344.63723386618625,262.99547759797883,4.066448729646479
5.956107986051371e-06,0.06940828165633127,345.38667365289984,262.99547759797883,4.066448729646479
6.012137684316568e-06,0.07006121224244849,346.2331121167569,262.99547759797883,4.066448729646479
6.040152533449166e-06,0.0703876775355071,346.65517727596426,262.99547759797883,4.066448729646479
6.061575653374094e-06,0.0706373274654931,346.97741805443457,262.99547759797883,4.066448729646479
6.096182231714362e-06,0.07104060812162433,347.49702417476345,262.99547759797883,4.066448729646479
6.135732606960383e-06,0.07150150030006001,348.08945319371304,262.99547759797883,4.066448729646479
6.175282982206404e-06,0.0719623924784957,348.68039476076467,262.99547759797883,4.066448729646479
6.209889560546672e-06,0.07236567313462693,349.19625885858176,262.99547759797883,4.066448729646479
6.249439935792693e-06,0.07282656531306261,349.7844469423808,262.99547759797883,4.066448729646479
6.265919258811868e-06,0.07301860372074415,350.0290966383018,262.99547759797883,4.066448729646479
6.376330723040343e-06,0.07430526105221044,351.6618244722945,262.99547759797883,4.066448729646479
6.40599350447486e-06,0.07465093018603722,352.0985840017721,262.99547759797883,4.066448729646479
6.4752066611553964e-06,0.07545749149829967,353.11463372405507,262.99547759797883,4.066448729646479
6.4867421872688185e-06,0.07559191838367674,353.2835627038712,262.99547759797883,4.066448729646479
6.508165307193746e-06,0.07584156831366273,353.5969774459097,262.99547759797883,4.066448729646479
6.514757036401417e-06,0.07591838367673535,353.69333177061986,262.99547759797883,4.066448729646479
6.560899140855108e-06,0.07645609121824365,354.3667506139212,262.99547759797883,4.066448729646479
6.63340816213948e-06,0.07730106021204242,355.42126035527394,262.99547759797883,4.066448729646479
6.6432957559509854e-06,0.07741628325665134,355.56470804997866,262.99547759797883,4.066448729646479
6.668014740479748e-06,0.07770434086817364,355.9229634815033,262.99547759797883,4.066448729646479
6.677902334291253e-06,0.07781956391278257,356.0661205820712,262.99547759797883,4.066448729646479
6.7009733865180976e-06,0.0780884176835367,356.39983272303476,262.99547759797883,4.066448729646479
6.7388758294622024e-06,0.07853010602120425,356.94710297277345,262.99547759797883,4.066448729646479
6.79325759542548e-06,0.07916383276655331,357.73022462956084,262.99547759797883,4.066448729646479
6.826216241463832e-06,0.07954790958191639,358.2036540068846,262.99547759797883,4.066448729646479
6.859174887502182e-06,0.07993198639727946,358.67619274395855,262.99547759797883,4.066448729646479
6.910260788861626e-06,0.08052730546109223,359.40688153502464,262.99547759797883,4.066448729646479
6.921796314975048e-06,0.0806617323464693,359.57158386092414,262.99547759797883,4.066448729646479
6.946515299503811e-06,0.0809497899579916,359.9241573792873,262.99547759797883,4.066448729646479
6.959698757919151e-06,0.08110342068413683,360.11199650310243,262.99547759797883,4.066448729646479
7.033855711505441e-06,0.08196759351870375,361.16601731352927,262.99547759797883,4.066448729646479
7.061870560638039e-06,0.08229405881176236,361.5630739638537,262.99547759797883,4.066448729646479
7.136027514224328e-06,0.08315823164632927,362.61115221663283,262.99547759797883,4.066448729646479
7.167338227960761e-06,0.08352310462092419,363.05239780915474,262.99547759797883,4.066448729646479
7.218424129320205e-06,0.08411842368473695,363.77071435678795,262.99547759797883,4.066448729646479
7.246438978452803e-06,0.08444488897779556,364.16378805714083,262.99547759797883,4.066448729646479
7.2761017598873185e-06,0.08479055811162232,364.5793383186587,262.99547759797883,4.066448729646479
7.285989353698824e-06,0.08490578115623125,364.71770818288127,262.99547759797883,4.066448729646479
7.320595932039092e-06,0.08530906181236247,365.2014270520794,262.99547759797883,4.066448729646479
7.351906645775526e-06,0.0856739347869574,365.6383095536444,262.99547759797883,4.066448729646479
7.379921494908124e-06,0.08600040008001601,366.02858971753085,262.99547759797883,4.066448729646479
7.431007396267567e-06,0.08659571914382877,366.73879283017806,262.99547759797883,4.066448729646479
7.463966042305919e-06,0.08697979595919185,367.1959780674423,262.99547759797883,4.066448729646479
7.485389162230847e-06,0.08722944588917785,367.49272632637286,262.99547759797883,4.066448729646479
7.529883334382619e-06,0.08774794958991798,368.10799338006257,262.99547759797883,4.066448729646479
7.548010589703712e-06,0.08795919183836767,368.3582510413921,262.99547759797883,4.066448729646479
7.571081641930558e-06,0.08822804560912183,368.6764220496107,262.99547759797883,4.066448729646479
7.60898408487466e-06,0.08866973394678936,369.19831191441926,262.99547759797883,4.066448729646479
7.628759272497672e-06,0.0889001800360072,369.47019974115403,262.99547759797883,4.066448729646479
7.636998934007259e-06,0.08899619923984797,369.58340519608464,262.99547759797883,4.066448729646479
7.660069986234105e-06,0.08926505301060213,369.9001273369219,262.99547759797883,4.066448729646479
7.665013783139859e-06,0.08932266453290659,369.9679479405779,262.99547759797883,4.066448729646479
7.674901376951362e-06,0.0894378875775155,370.10353799020265,262.99547759797883,4.066448729646479
7.707860022989714e-06,0.08982196439287858,370.5550136109544,262.99547759797883,4.066448729646479
7.745762465933816e-06,0.09026365273054611,371.0732808561276,262.99547759797883,4.066448729646479
7.82980701333161e-06,0.09124304860972195,372.2189670789929,262.99547759797883,4.066448729646479
7.89078050850256e-06,0.09195359071814363,373.04715139078803,262.99547759797883,4.066448729646479
7.92373915454091e-06,0.09233766753350671,373.49377927153535,262.99547759797883,4.066448729646479
7.953401935975427e-06,0.09268333666733347,373.8951252816974,262.99547759797883,4.066448729646479
7.992952311221448e-06,0.09314422884576916,374.42934638579726,262.99547759797883,4.066448729646479
8.016023363448294e-06,0.09341308261652331,374.74049927732995,262.99547759797883,4.066448729646479
8.027558889561715e-06,0.09354750950190038,374.8959447372502,262.99547759797883,4.066448729646479
8.057221670996232e-06,0.09389317863572715,375.29526214239746,262.99547759797883,4.066448729646479
8.068757197109655e-06,0.09402760552110423,375.45039735775384,262.99547759797883,4.066448729646479
8.08523652012883e-06,0.09421964392878576,375.6718691308267,262.99547759797883,4.066448729646479
8.147857947601697e-06,0.0949493898779756,376.5118611770227,262.99547759797883,4.066448729646479
8.156097609111284e-06,0.09504540908181637,376.6221987069911,262.99547759797883,4.066448729646479
8.223662833489902e-06,0.09583276655331066,377.52533248999924,262.99547759797883,4.066448729646479
8.268157005641675e-06,0.09635127025405081,378.11849925465003,262.99547759797883,4.066448729646479
8.31924290700112e-06,0.09694658931786358,378.7980095317631,262.99547759797883,4.066448729646479
8.350553620737554e-06,0.0973114622924585,379.21367929044465,262.99547759797883,4.066448729646479
8.371976740662482e-06,0.0975611122224445,379.4977347532888,262.99547759797883,4.066448729646479
8.39339986058741e-06,0.0978107621524305,379.7815068771469,262.99547759797883,4.066448729646479
8.408231251304667e-06,0.09798359671934387,379.9777990501663,262.99547759797883,4.066448729646479
8.512050986325472e-06,0.09919343868773756,381.3480829911862,262.99547759797883,4.066448729646479
8.535122038552316e-06,0.0994622924584917,381.6517035603566,262.99547759797883,4.066448729646479
8.576320346100255e-06,0.09994238847769554,382.1930882391847,262.99547759797883,4.066448729646479
8.581264143006008e-06,0.1,382.25798617259255,262.99547759797883,4.066448729646479