File: datasets/aisi_316_L/data/M1/train_55.csv
Time(s),Strain(%),Stress(MPa),Temp(C),Log_SR(s-1)
0.0,0.0,0.0,305.2155660077844,-2.573099639063357
0.005388428582591361,1.44e-05,2.55218175,305.2155660077844,-2.573099639063357
0.006286500013023254,1.68e-05,2.9775453749999996,305.2155660077844,-2.573099639063357
0.015267214317342188,4.0799999999999996e-05,7.231181625,305.2155660077844,-2.573099639063357
0.021553714330365445,5.76e-05,10.208727,305.2155660077844,-2.573099639063357
0.029337000060775185,7.84e-05,13.89521175,305.2155660077844,-2.573099639063357
0.036222214360753034,9.68e-05,17.156332875,305.2155660077844,-2.573099639063357
0.038617071508571424,0.0001032,18.290635875,305.2155660077844,-2.573099639063357
0.04310742866073089,0.0001152,20.417454,305.2155660077844,-2.573099639063357
0.05178878582157253,0.0001384,24.529302375,305.2155660077844,-2.573099639063357
0.053584928682436306,0.00014319999999999998,25.380029625,305.2155660077844,-2.573099639063357
0.062266285843277945,0.00016639999999999998,29.491877999999996,305.2155660077844,-2.573099639063357
0.07274378586498337,0.00019439999999999998,34.454453625,305.2155660077844,-2.573099639063357
0.07693478587366553,0.00020559999999999998,36.439483875,305.2155660077844,-2.573099639063357
0.081425143025825,0.00021759999999999998,38.56630199999999,305.2155660077844,-2.573099639063357
0.09160328590405313,0.0002448,43.38708975,305.2155660077844,-2.573099639063357
0.09459685733882611,0.00025279999999999996,44.804968499999994,305.2155660077844,-2.573099639063357
0.10028464306489478,0.000268,47.498938125,305.2155660077844,-2.573099639063357
0.10118271449532668,0.0002704,47.924301750000005,305.2155660077844,-2.573099639063357
0.10297885735619045,0.00027519999999999997,48.775028999999996,305.2155660077844,-2.573099639063357
0.10537371450400884,0.0002816,49.909332,305.2155660077844,-2.573099639063357
0.11764735738657806,0.0003144,55.722634875,305.2155660077844,-2.573099639063357
0.12483192883003319,0.0003336,59.125543875,305.2155660077844,-2.573099639063357
0.1269274288343743,0.0003392,60.118059,305.2155660077844,-2.573099639063357
0.13201650027348835,0.0003528,62.528452875,305.2155660077844,-2.573099639063357
0.13560878599521592,0.00036239999999999997,64.229907375,305.2155660077844,-2.573099639063357
0.13860235742998891,0.0003704,65.647786125,305.2155660077844,-2.573099639063357
0.14518821458648945,0.000388,68.767119375,305.2155660077844,-2.573099639063357
0.14848114316473973,0.0003968,70.326786,305.2155660077844,-2.573099639063357
0.1544682860342857,0.0004128,73.1625435,305.2155660077844,-2.573099639063357
0.15506700032124027,0.0004144,73.44611925,305.2155660077844,-2.573099639063357
0.16045542890383163,0.00042879999999999996,75.998301,305.2155660077844,-2.573099639063357
0.16225157176469543,0.00043359999999999997,76.84902824999999,305.2155660077844,-2.573099639063357
0.16704128606033217,0.00044639999999999995,79.11763425,305.2155660077844,-2.573099639063357
0.17272907178640085,0.0004616,81.811603875,305.2155660077844,-2.573099639063357
0.17841685751246952,0.0004768,84.5055735,305.2155660077844,-2.573099639063357
0.1912892146819933,0.0005112,90.602452125,305.2155660077844,-2.573099639063357
0.19428278611676628,0.0005191999999999999,92.02033087499998,305.2155660077844,-2.573099639063357
0.19877314326892578,0.0005312,94.147149,305.2155660077844,-2.573099639063357
0.20386221470803984,0.0005448,96.557542875,305.2155660077844,-2.573099639063357
0.21643521473408633,0.0005784,102.51263362499999,305.2155660077844,-2.573099639063357
0.22721207189926906,0.0006072,107.616997125,305.2155660077844,-2.573099639063357
0.23050500047751935,0.000616,109.17666375,305.2155660077844,-2.573099639063357
0.23649214334706528,0.000632,112.01242124999999,305.2155660077844,-2.573099639063357
0.23918635763836096,0.0006391999999999999,113.28851212499998,305.2155660077844,-2.573099639063357
0.24217992907313396,0.0006472,114.706390875,305.2155660077844,-2.573099639063357
0.24966385766006638,0.0006672,118.25108775,305.2155660077844,-2.573099639063357
0.250262571947021,0.0006688,118.5346635,305.2155660077844,-2.573099639063357
0.25295678623831663,0.000676,119.81075437499999,305.2155660077844,-2.573099639063357
0.2544535719557032,0.0006799999999999999,120.51969374999999,305.2155660077844,-2.573099639063357
0.2634342862600221,0.000704,124.77333,305.2155660077844,-2.573099639063357
0.2691220719860907,0.0007191999999999999,127.46729962499998,305.2155660077844,-2.573099639063357
0.2751092148556367,0.0007352,130.303057125,305.2155660077844,-2.573099639063357
0.2781027862904097,0.0007432,131.72093587499998,305.2155660077844,-2.573099639063357
0.2840899291599556,0.0007591999999999999,134.55669337499998,305.2155660077844,-2.573099639063357
0.2891790005990697,0.0007727999999999999,136.96708725,305.2155660077844,-2.573099639063357
0.2930706434642746,0.0007832,138.81032962499998,305.2155660077844,-2.573099639063357
0.2942680720381837,0.0007863999999999999,139.37748112499997,305.2155660077844,-2.573099639063357
0.2990577863338205,0.0007991999999999999,141.64608712499998,305.2155660077844,-2.573099639063357
0.3092359292120486,0.0008263999999999999,146.46687487499997,305.2155660077844,-2.573099639063357
0.31193014350334436,0.0008336,147.74296575,305.2155660077844,-2.573099639063357
0.3164205006555038,0.0008456,149.869783875,305.2155660077844,-2.573099639063357
0.32270700066852703,0.0008623999999999999,152.84732925,305.2155660077844,-2.573099639063357
0.3274967149641638,0.0008751999999999999,155.11593524999998,305.2155660077844,-2.573099639063357
0.3295922149685049,0.0008807999999999999,156.108450375,305.2155660077844,-2.573099639063357
0.3328851435467552,0.0008895999999999999,157.668117,305.2155660077844,-2.573099639063357
0.34186585785107415,0.0009136,161.92175325,305.2155660077844,-2.573099639063357
0.3481523578640974,0.0009304,164.899298625,305.2155660077844,-2.573099639063357
0.35473821502059794,0.000948,168.01863187499998,305.2155660077844,-2.573099639063357
0.3616234293205758,0.0009664,168.7045855962618,305.2155660077844,-2.573099639063357
0.36491635789882604,0.0009752,168.75347123473284,305.2155660077844,-2.573099639063357
0.3703047864814174,0.0009896,168.8330964399535,305.2155660077844,-2.573099639063357
0.3765912864944407,0.0010064,168.92542362047536,305.2155660077844,-2.573099639063357
0.38407521508137316,0.0010264,169.03455684840551,305.2155660077844,-2.573099639063357
0.3918585008117828,0.0010471999999999999,169.14717921794986,305.2155660077844,-2.573099639063357
0.4170045008638759,0.0011144,169.50521377881154,305.2155660077844,-2.573099639063357
0.4176032151508305,0.001116,169.5136341424855,305.2155660077844,-2.573099639063357
0.4217942151595126,0.0011271999999999999,169.5724454186574,305.2155660077844,-2.573099639063357
0.43406785804208187,0.00116,169.74338137242822,305.2155660077844,-2.573099639063357
0.43586400090294564,0.0011648,169.7682373668622,305.2155660077844,-2.573099639063357
0.4424498580594462,0.0011824,169.85903623975264,305.2155660077844,-2.573099639063357
0.4487363580724694,0.0011991999999999999,169.94521743539002,305.2155660077844,-2.573099639063357
0.4607106438115614,0.0012312,170.10808049043143,305.2155660077844,-2.573099639063357
0.46220742952894783,0.0012351999999999999,170.1283216526813,305.2155660077844,-2.573099639063357
0.4660990723941527,0.0012456,170.1808293975415,305.2155660077844,-2.573099639063357
0.4708887866897895,0.0012584,170.24522018400756,305.2155660077844,-2.573099639063357
0.4726849295506533,0.0012632,170.26930081065618,305.2155660077844,-2.573099639063357
0.4789714295636765,0.0012799999999999999,170.35330340795934,305.2155660077844,-2.573099639063357
0.4831624295723587,0.0012912,170.4090663787877,305.2155660077844,-2.573099639063357
0.4879521438679955,0.001304,170.47256501833354,305.2155660077844,-2.573099639063357
0.4921431438766776,0.0013151999999999999,170.52792718559658,305.2155660077844,-2.573099639063357
0.4936399295940641,0.0013192,170.5476547892092,305.2155660077844,-2.573099639063357
0.4972322153157917,0.0013288,170.5949060996436,305.2155660077844,-2.573099639063357
0.5023212867549057,0.0013423999999999999,170.66161818988718,305.2155660077844,-2.573099639063357
0.5113020010592247,0.0013664,170.7787059333497,305.2155660077844,-2.573099639063357
0.5154930010679069,0.0013775999999999999,170.83307213552007,305.2155660077844,-2.573099639063357
0.517588501072248,0.0013832,170.86019057412278,305.2155660077844,-2.573099639063357
0.5184865725026798,0.0013855999999999999,170.87179965063982,305.2155660077844,-2.573099639063357
0.522677572511362,0.0013968,170.92587198879306,305.2155660077844,-2.573099639063357
0.5298621439548171,0.001416,171.018175670776,305.2155660077844,-2.573099639063357
0.5394415725460907,0.0014416,171.14049150317416,305.2155660077844,-2.573099639063357
0.5433332154112955,0.001452,171.1899399840464,305.2155660077844,-2.573099639063357
0.5541100725764783,0.0014808,171.32615852942385,305.2155660077844,-2.573099639063357
0.5588997868721151,0.0014935999999999999,171.38636803518213,305.2155660077844,-2.573099639063357
0.5654856440286156,0.0015111999999999999,171.46882855394733,305.2155660077844,-2.573099639063357
0.5690779297503432,0.0015207999999999999,171.5136491224438,305.2155660077844,-2.573099639063357
0.5765618583372756,0.0015408,171.6066724554467,305.2155660077844,-2.573099639063357
0.5894342155067994,0.0015752,171.76557847206635,305.2155660077844,-2.573099639063357
0.6023065726763233,0.0016095999999999999,171.9231367036261,305.2155660077844,-2.573099639063357
0.6103892155502103,0.0016312,172.02139771856247,305.2155660077844,-2.573099639063357
0.6178731441371428,0.0016512,172.11192862881745,305.2155660077844,-2.573099639063357
0.6280512870153709,0.0016784,172.23436733713905,305.2155660077844,-2.573099639063357
0.6325416441675303,0.0016903999999999999,172.2881381406139,305.2155660077844,-2.573099639063357
0.6370320013196898,0.0017024,172.34176027995719,305.2155660077844,-2.573099639063357
0.6466114299109633,0.001728,172.45566397528657,305.2155660077844,-2.573099639063357
0.6552927870718049,0.0017511999999999998,172.5583219960611,305.2155660077844,-2.573099639063357
0.6588850727935325,0.0017607999999999999,172.60064586779652,305.2155660077844,-2.573099639063357
0.6615792870848282,0.0017679999999999998,172.6323297385834,305.2155660077844,-2.573099639063357
0.6690632156717606,0.0017879999999999999,172.72007754625204,305.2155660077844,-2.573099639063357
0.6843304299891029,0.0018288,172.8979049652161,305.2155660077844,-2.573099639063357
0.6882220728543077,0.0018391999999999998,172.94298521755573,305.2155660077844,-2.573099639063357
0.691515001432558,0.0018479999999999998,172.9810524501525,305.2155660077844,-2.573099639063357
0.6924130728629899,0.0018503999999999999,172.9914221447512,305.2155660077844,-2.573099639063357
0.7019925014542634,0.0018759999999999998,173.10170780426142,305.2155660077844,-2.573099639063357
0.7127693586194461,0.0019048,173.22507998491122,305.2155660077844,-2.573099639063357
0.7355205015237208,0.0019656,173.48316845449935,305.2155660077844,-2.573099639063357
0.742705072967176,0.0019848,173.5640207321026,305.2155660077844,-2.573099639063357
0.7462973586889035,0.0019944,173.6043324432183,305.2155660077844,-2.573099639063357
0.7480935015497673,0.0019992,173.62445991541466,305.2155660077844,-2.573099639063357
0.7582716444279953,0.0020264,173.73816159368008,305.2155660077844,-2.573099639063357
0.7600677872888592,0.0020312,173.75816465254613,305.2155660077844,-2.573099639063357
0.7651568587279732,0.0020448,173.8147401183062,305.2155660077844,-2.573099639063357
0.7690485015931782,0.0020552,173.85790474693914,305.2155660077844,-2.573099639063357
0.7774305016105424,0.0020775999999999998,173.95058644467696,305.2155660077844,-2.573099639063357
0.787009930201816,0.0021032,174.05603251383903,305.2155660077844,-2.573099639063357
0.7915002873539755,0.0021152,174.1052879375075,305.2155660077844,-2.573099639063357
0.8004810016582944,0.0021392,174.20347305559602,305.2155660077844,-2.573099639063357
0.8013790730887264,0.0021416,174.21326787988224,305.2155660077844,-2.573099639063357
0.8109585016799997,0.0021671999999999998,174.31748102441492,305.2155660077844,-2.573099639063357
0.8133533588278182,0.0021736,174.34345915931195,305.2155660077844,-2.573099639063357
0.8178437159799776,0.0021855999999999998,174.39208789905015,305.2155660077844,-2.573099639063357
0.820238573127796,0.002192,174.41798064495677,305.2155660077844,-2.573099639063357
0.8244295731364781,0.0022031999999999998,174.46322211709239,305.2155660077844,-2.573099639063357
0.8319135017234106,0.0022232,174.54378799828854,305.2155660077844,-2.573099639063357
0.8346077160147064,0.0022304,174.57272245611085,305.2155660077844,-2.573099639063357
0.8384993588799112,0.0022408,174.61445244557595,305.2155660077844,-2.573099639063357
0.8417922874581616,0.0022496,174.64970347325857,305.2155660077844,-2.573099639063357
0.8486775017581394,0.002268,174.72323685900756,305.2155660077844,-2.573099639063357
0.8522697874798669,0.0022776,174.76150972236042,305.2155660077844,-2.573099639063357
0.8642440732189588,0.0023095999999999998,174.88863397581517,305.2155660077844,-2.573099639063357
0.8660402160798226,0.0023144,174.90764320246643,305.2155660077844,-2.573099639063357
0.8813074303971649,0.0023552,175.06860551560965,305.2155660077844,-2.573099639063357
0.8863965018362788,0.0023688,175.12201747351514,305.2155660077844,-2.573099639063357
0.8923836447058249,0.0023848,175.18470219793417,305.2155660077844,-2.573099639063357
0.9103450733144627,0.0024327999999999997,175.37177957233138,305.2155660077844,-2.573099639063357
0.919625144762259,0.0024576,175.46787185314977,305.2155660077844,-2.573099639063357
0.9220200019100774,0.002464,175.4926083786885,305.2155660077844,-2.573099639063357
0.9378859305143741,0.0025063999999999998,175.65585951405478,305.2155660077844,-2.573099639063357
0.9420769305230563,0.0025176,175.6988021780482,305.2155660077844,-2.573099639063357
0.9474653591056477,0.002532,175.75390485669445,305.2155660077844,-2.573099639063357
0.9507582876838978,0.0025407999999999997,175.78751855460604,305.2155660077844,-2.573099639063357
0.9582422162708303,0.0025608,175.8637449217531,305.2155660077844,-2.573099639063357
0.9663248591447174,0.0025824,175.9458090826888,305.2155660077844,-2.573099639063357
0.9714139305838314,0.002596,175.99734179705413,305.2155660077844,-2.573099639063357
0.9738087877316499,0.0026024,176.02155604437706,305.2155660077844,-2.573099639063357
0.9836875734664006,0.0026287999999999997,176.12119531296415,305.2155660077844,-2.573099639063357
0.9893753591924694,0.002644,176.17838634435103,305.2155660077844,-2.573099639063357
0.9932670020576743,0.0026544,176.21744318971508,305.2155660077844,-2.573099639063357
0.99596121634897,0.0026616,176.24444759083906,305.2155660077844,-2.573099639063357
1.0001522163576522,0.0026728,176.2863978783176,305.2155660077844,-2.573099639063357
1.0058400020837206,0.002688,176.34322092016592,305.2155660077844,-2.573099639063357
1.0076361449445845,0.0026928,176.36113898560143,305.2155660077844,-2.573099639063357
1.0139226449576078,0.0027096,176.42375435615074,305.2155660077844,-2.573099639063357
1.0273937164140863,0.0027456,176.55742257670093,305.2155660077844,-2.573099639063357
1.0327821449966774,0.00276,176.610698264608,305.2155660077844,-2.573099639063357
1.0348776450010186,0.0027656,176.6313872982449,305.2155660077844,-2.573099639063357
1.0396673592966554,0.0027784,176.67861526442232,305.2155660077844,-2.573099639063357
1.0414635021575191,0.0027832,176.69630386539734,305.2155660077844,-2.573099639063357
1.0459538593096787,0.0027952,176.74047339604738,305.2155660077844,-2.573099639063357
1.0588262164792024,0.0028296,176.86668470423683,305.2155660077844,-2.573099639063357
1.0702017879313397,0.0028599999999999997,176.977723041118,305.2155660077844,-2.573099639063357
1.0752908593704538,0.0028736,177.02724896292327,305.2155660077844,-2.573099639063357
1.0788831450921814,0.0028832,177.06215341444874,305.2155660077844,-2.573099639063357
1.0839722165312955,0.0028967999999999997,177.11152389901352,305.2155660077844,-2.573099639063357
1.0920548594051824,0.0029184,177.18975045275587,305.2155660077844,-2.573099639063357
1.1004368594225469,0.0029408,177.27063615626858,305.2155660077844,-2.573099639063357
1.1058252880051382,0.0029552,177.32250725318718,305.2155660077844,-2.573099639063357
1.1139079308790252,0.0029768,177.40012945310156,305.2155660077844,-2.573099639063357
1.122589288039867,0.003,177.48325717811107,305.2155660077844,-2.573099639063357
1.1240860737572533,0.0030039999999999997,177.49756416777208,305.2155660077844,-2.573099639063357
1.1264809309050718,0.0030104,177.52043990711323,305.2155660077844,-2.573099639063357
1.1273790023355037,0.0030128,177.52901341848616,305.2155660077844,-2.573099639063357
1.1309712880572311,0.0030223999999999997,177.56328086183422,305.2155660077844,-2.573099639063357
1.1474359309484825,0.0030664,177.71980001166227,305.2155660077844,-2.573099639063357
1.1486333595223919,0.0030696,177.73114893920547,305.2155660077844,-2.573099639063357
1.1510282166702102,0.0030759999999999997,177.75383296145904,305.2155660077844,-2.573099639063357
1.1528243595310739,0.0030808,177.77083390066792,305.2155660077844,-2.573099639063357
1.1546205023919378,0.0030856,177.78782451265465,305.2155660077844,-2.573099639063357
1.1653973595571205,0.0031144,177.8895525572665,305.2155660077844,-2.573099639063357
1.1749767881483941,0.00314,177.97966989208268,305.2155660077844,-2.573099639063357
1.18096393101794,0.003156,178.03584774240792,305.2155660077844,-2.573099639063357
1.1968298596222366,0.0031983999999999997,178.18418445514715,305.2155660077844,-2.573099639063357
1.206109931070033,0.0032232,178.27059197100792,305.2155660077844,-2.573099639063357
1.2103009310787152,0.0032343999999999997,178.3095296909525,305.2155660077844,-2.573099639063357
1.2114983596526243,0.0032375999999999998,178.32064509082022,305.2155660077844,-2.573099639063357
1.2180842168091248,0.0032551999999999998,178.3817033738096,305.2155660077844,-2.573099639063357
1.2204790739569433,0.0032616,178.40387444721333,305.2155660077844,-2.573099639063357
1.2327527168395125,0.0032944,178.51723599280518,305.2155660077844,-2.573099639063357
1.2357462882742856,0.0033024,178.544818273388,305.2155660077844,-2.573099639063357
1.2441282882916498,0.0033247999999999997,178.62191037011897,305.2155660077844,-2.573099639063357
1.2507141454481503,0.0033423999999999997,178.6823407193389,305.2155660077844,-2.573099639063357
1.259395502608992,0.0033656,178.76180963448505,305.2155660077844,-2.573099639063357
1.261491002613333,0.0033712,178.7809597434772,305.2155660077844,-2.573099639063357
1.2626884311872424,0.0033744,178.79189709272833,305.2155660077844,-2.573099639063357
1.2698730026306972,0.0033935999999999997,178.85743644261905,305.2155660077844,-2.573099639063357
1.2728665740654703,0.0034016,178.88470180583457,305.2155660077844,-2.573099639063357
1.2761595026437205,0.0034103999999999996,178.91466483723906,305.2155660077844,-2.573099639063357
1.2791530740784935,0.0034184,178.94187780132916,305.2155660077844,-2.573099639063357
1.2806498597958802,0.0034224,178.95547496851367,305.2155660077844,-2.573099639063357
1.2884331455262898,0.0034432,179.02608057735702,305.2155660077844,-2.573099639063357
1.2914267169610627,0.0034511999999999998,179.0531922639234,305.2155660077844,-2.573099639063357
1.3004074312653817,0.0034752,179.13438064514253,305.2155660077844,-2.573099639063357
1.3087894312827462,0.0034976,179.20995940006242,305.2155660077844,-2.573099639063357
1.314776574152292,0.0035136,179.26382869475216,305.2155660077844,-2.573099639063357
1.3345341456217938,0.0035664,179.4409224534022,305.2155660077844,-2.573099639063357
1.340820645634817,0.0035832,179.49705564540852,305.2155660077844,-2.573099639063357
1.3477058599347949,0.0036016,179.55841721710905,305.2155660077844,-2.573099639063357
1.3498013599391359,0.0036071999999999996,179.57706819515747,305.2155660077844,-2.573099639063357
1.350998788513045,0.0036103999999999997,179.5877208268388,305.2155660077844,-2.573099639063357
1.3551897885217274,0.0036216,179.62497607452826,305.2155660077844,-2.573099639063357
1.3584827170999776,0.0036303999999999998,179.65421654195958,305.2155660077844,-2.573099639063357
1.361775645678228,0.0036392,179.68342937993356,305.2155660077844,-2.573099639063357
1.368960217121683,0.0036584,179.7470710254273,305.2155660077844,-2.573099639063357
1.3836287171520705,0.0036975999999999997,179.8766030135854,305.2155660077844,-2.573099639063357
1.386023574299889,0.003704,179.89770013178867,305.2155660077844,-2.573099639063357
1.392010717169435,0.0037199999999999998,179.9503808249179,305.2155660077844,-2.573099639063357
1.3941062171737761,0.0037256,179.96879818109144,305.2155660077844,-2.573099639063357
1.405182431482436,0.0037551999999999998,180.06596829445357,305.2155660077844,-2.573099639063357
1.4078766457737317,0.0037624,180.08955904510185,305.2155660077844,-2.573099639063357
1.4150612172171868,0.0037816,180.15238179592168,305.2155660077844,-2.573099639063357
1.4213477172302103,0.0037984,180.20724972965394,305.2155660077844,-2.573099639063357
1.4228445029475965,0.0038023999999999996,180.22029956386703,305.2155660077844,-2.573099639063357
1.4309271458214836,0.0038239999999999997,180.29067636955241,305.2155660077844,-2.573099639063357
1.4345194315432113,0.0038336,180.32190516779377,305.2155660077844,-2.573099639063357
1.44020721726928,0.0038488,180.37128846296957,305.2155660077844,-2.573099639063357
1.4482898601431669,0.0038704,180.44133408319257,305.2155660077844,-2.573099639063357
1.4515827887214172,0.0038791999999999997,180.46982746004454,305.2155660077844,-2.573099639063357
1.4560731458735767,0.0038912,180.50864147280072,305.2155660077844,-2.573099639063357
1.460264145882259,0.0039024,180.54482578826907,305.2155660077844,-2.573099639063357
1.4617609315996454,0.0039064,180.55773893975652,305.2155660077844,-2.573099639063357
1.464455145890941,0.0039136,180.58096962482017,305.2155660077844,-2.573099639063357
1.469544217330055,0.0039272,180.62480438156805,305.2155660077844,-2.573099639063357
1.477327503060465,0.003948,180.6917314356208,305.2155660077844,-2.573099639063357
1.4842127173604427,0.0039664,180.75082159179152,305.2155660077844,-2.573099639063357
1.4881043602256476,0.0039768,180.78417308505868,305.2155660077844,-2.573099639063357
1.4890024316560793,0.0039792,180.79186475082966,305.2155660077844,-2.573099639063357
1.597389838419068,0.004268853770754151,181.70730634667729,305.2155660077844,-2.573099639063357
1.9207602274523563,0.005133026605321065,184.30423192017597,305.2155660077844,-2.573099639063357
1.985434305259014,0.0053058611722344474,184.80248080471029,305.2155660077844,-2.573099639063357
2.06448040035604,0.0055171034206841375,185.4029362946459,305.2155660077844,-2.573099639063357
2.0860384262915925,0.0055747149429885975,185.5651320403027,305.2155660077844,-2.573099639063357
2.272874651066381,0.006074014802960592,186.9444521293413,305.2155660077844,-2.573099639063357
2.3950367980345124,0.006400480096019204,187.82245323286725,305.2155660077844,-2.573099639063357
2.502826927712275,0.0066885377075415085,188.58275277956687,305.2155660077844,-2.573099639063357
2.7974532821648266,0.007475895179035807,190.59835936264605,305.2155660077844,-2.573099639063357
2.9842895069396156,0.007975195039007801,191.83370502771183,305.2155660077844,-2.573099639063357
3.2573578354566144,0.00870494098819764,193.586249831154,305.2155660077844,-2.573099639063357
3.278915861392167,0.0087625525105021,193.7221187028254,305.2155660077844,-2.573099639063357
3.4441940602314034,0.009204240848169634,194.75244847459237,305.2155660077844,-2.573099639063357
3.537612172618798,0.009453890778155631,195.326274201617,305.2155660077844,-2.573099639063357
3.7172623887484026,0.009933986797359472,196.41343926414166,305.2155660077844,-2.573099639063357
3.8537965530069016,0.01029885977195439,197.22603091435718,305.2155660077844,-2.573099639063357
3.961586682684665,0.010586917383476696,197.85964553702263,305.2155660077844,-2.573099639063357
4.105306855588349,0.010970994198839769,198.69410272807139,305.2155660077844,-2.573099639063357
4.349631149524611,0.011623924784956993,200.08698914395356,305.2155660077844,-2.573099639063357
4.414305227331268,0.011796759351870374,200.45054322885244,305.2155660077844,-2.573099639063357
4.673001538557899,0.012488097619523904,201.88445246670253,305.2155660077844,-2.573099639063357
4.759233642300109,0.012718543708741748,202.35549692663207,305.2155660077844,-2.573099639063357
4.960441884365267,0.01325625125025005,203.44184184354575,305.2155660077844,-2.573099639063357
5.046673988107477,0.013486697339467894,203.902141609747,305.2155660077844,-2.573099639063357
5.10416205726895,0.013640328065613123,204.20730512927452,305.2155660077844,-2.573099639063357
5.290998282043739,0.014139627925585117,205.18995530641124,305.2155660077844,-2.573099639063357
5.456276480882975,0.014581316263252651,206.04799590294783,305.2155660077844,-2.573099639063357
5.5856246364962905,0.014926985397079416,206.7124544062924,305.2155660077844,-2.573099639063357
5.628740688367396,0.015042208441688338,206.9326034352353,305.2155660077844,-2.573099639063357
5.873064982303657,0.01569513902780556,208.16791057718987,305.2155660077844,-2.573099639063357
5.901809016884394,0.015771954390878175,208.31191119557982,305.2155660077844,-2.573099639063357
5.959297086045868,0.015925585117023404,208.59909448192832,305.2155660077844,-2.573099639063357
6.009599146562158,0.01606001200240048,208.84949470421773,305.2155660077844,-2.573099639063357
6.11738927623992,0.016348069613922784,209.3833306090472,305.2155660077844,-2.573099639063357
6.174877345401393,0.016501700340068013,209.66654247995547,305.2155660077844,-2.573099639063357
6.3185975183050775,0.016885777155431086,210.37011002671326,305.2155660077844,-2.573099639063357
6.404829622047288,0.01711622324464893,210.7892552520749,305.2155660077844,-2.573099639063357
6.526991769015419,0.017442688537707543,211.3792962891561,305.2155660077844,-2.573099639063357
7.09468645198497,0.01895979195839168,214.0666350880673,305.2155660077844,-2.573099639063357
7.188104564372365,0.019209441888377678,214.50069033034103,305.2155660077844,-2.573099639063357
7.224034607598285,0.019305461092218444,214.66704815411293,305.2155660077844,-2.573099639063357
7.303080702695311,0.019516703340668136,215.03190371000804,305.2155660077844,-2.573099639063357
7.489916927470099,0.020016003200640127,215.88822111450114,305.2155660077844,-2.573099639063357
7.525846970696021,0.020112022404480897,216.0519381256938,305.2155660077844,-2.573099639063357
7.74861323869673,0.020707341468293658,217.06026287555008,305.2155660077844,-2.573099639063357
8.05761161043965,0.021533106621324266,218.44038509969062,305.2155660077844,-2.573099639063357
8.100727662310756,0.021648329665933188,218.6313061806548,305.2155660077844,-2.573099639063357
8.201331783343335,0.02191718343668734,219.07525411796516,305.2155660077844,-2.573099639063357
8.36660998218257,0.02235887177435487,219.800013889711,305.2155660077844,-2.573099639063357
8.41691204269886,0.022493298659731948,220.01948181547613,305.2155660077844,-2.573099639063357
8.546260198312176,0.022838967793558713,220.58149189588917,305.2155660077844,-2.573099639063357
8.718724405796596,0.0232998599719944,221.3257051798052,305.2155660077844,-2.573099639063357
8.905560630571383,0.023799159831966392,222.1254866656629,305.2155660077844,-2.573099639063357
9.142698915862463,0.024432886577315464,223.1312319689331,305.2155660077844,-2.573099639063357
9.322349131992066,0.024912982596519303,223.88640092303075,305.2155660077844,-2.573099639063357
9.43013926166983,0.02520104020804161,224.33677839528804,305.2155660077844,-2.573099639063357
9.77506767663867,0.026122824564912984,225.76467764713314,305.2155660077844,-2.573099639063357
9.882857806316434,0.026410882176435287,226.20684820201612,305.2155660077844,-2.573099639063357
9.897229823606802,0.026449289857971594,226.26566184631793,305.2155660077844,-2.573099639063357
10.019391970574933,0.026775755151030207,226.76424013260035,305.2155660077844,-2.573099639063357
10.191856178059354,0.027236647329465895,227.46409800667368,305.2155660077844,-2.573099639063357
10.263716264511196,0.02742868573714743,227.7543405174198,305.2155660077844,-2.573099639063357
10.385878411479327,0.02775515103020604,228.2459405172911,305.2155660077844,-2.573099639063357
10.61583068812522,0.028369673934786958,229.16523033598546,305.2155660077844,-2.573099639063357
10.658946739996326,0.02848489697939588,229.33672915288273,305.2155660077844,-2.573099639063357
10.795480904254823,0.028849769953990797,229.87803243815378,305.2155660077844,-2.573099639063357
11.01106116361035,0.029425885177035406,230.72731716316218,305.2155660077844,-2.573099639063357
11.154781336514034,0.02980996199239848,231.2899069803183,305.2155660077844,-2.573099639063357
11.384733613159927,0.030424484896979395,232.1842060080964,305.2155660077844,-2.573099639063357
11.794336105935429,0.03151910382076416,233.75991765865086,305.2155660077844,-2.573099639063357
11.995544348000584,0.03205681136227245,234.52612257388665,305.2155660077844,-2.573099639063357
12.33328675432424,0.032959391878375675,235.80107861849112,305.2155660077844,-2.573099639063357
12.491378944518292,0.03338187637527505,236.39318101579053,305.2155660077844,-2.573099639063357
12.613541091486425,0.03370834166833367,236.848715206054,305.2155660077844,-2.573099639063357
12.872237402713052,0.03439967993598719,237.80773470609665,305.2155660077844,-2.573099639063357
13.008771566971554,0.034764552910582114,238.31085183154588,305.2155660077844,-2.573099639063357
13.231537834972265,0.035359871974394885,239.1273283656721,305.2155660077844,-2.573099639063357
13.260281869553,0.03543668733746749,239.232288291669,305.2155660077844,-2.573099639063357
13.49742015484408,0.03607041408281657,240.09484778908563,305.2155660077844,-2.573099639063357
13.53335019807,0.036166433286657335,240.22502122417976,305.2155660077844,-2.573099639063357
13.763302474715895,0.03678095619123825,241.05496214087302,305.2155660077844,-2.573099639063357
13.928580673555128,0.03722264452890578,241.64814533639307,305.2155660077844,-2.573099639063357
14.021998785942523,0.037472294458891775,241.98220839192442,305.2155660077844,-2.573099639063357
14.26632307987879,0.03812522504500901,242.8518335970268,305.2155660077844,-2.573099639063357
14.302253123104709,0.038221244248849776,242.9792280711507,305.2155660077844,-2.573099639063357
14.37411320955655,0.03841328265653131,243.23364319017273,305.2155660077844,-2.573099639063357
14.395671235492102,0.03847089417883577,243.3098709358452,305.2155660077844,-2.573099639063357
14.532205399750604,0.03883576715343069,243.79161691064502,305.2155660077844,-2.573099639063357
14.726227633170572,0.03935427085417083,244.47317778544544,305.2155660077844,-2.573099639063357
14.862761797429071,0.03971914382876575,244.95069690084907,305.2155660077844,-2.573099639063357
15.092714074074966,0.040333666733346665,245.75109056155276,305.2155660077844,-2.573099639063357
15.293922316140126,0.040871374274854974,246.44754162063987,305.2155660077844,-2.573099639063357
15.437642489043807,0.04125545109021804,246.94282061306964,305.2155660077844,-2.573099639063357
15.509502575495652,0.04144748949789959,247.1897855270251,305.2155660077844,-2.573099639063357
15.581362661947493,0.04163952790558112,247.43630458020863,305.2155660077844,-2.573099639063357
15.66040875704452,0.04185077015403081,247.70696397683164,305.2155660077844,-2.573099639063357
15.818500947238569,0.04227325465093018,248.24668964329376,305.2155660077844,-2.573099639063357
15.854430990464493,0.04236927385477096,248.36906069912058,305.2155660077844,-2.573099639063357
15.962221120142255,0.04265733146629326,248.7355265736556,305.2155660077844,-2.573099639063357
15.99096515472299,0.04273414682936587,248.83308764774682,305.2155660077844,-2.573099639063357
16.01970918930373,0.04281096219243849,248.9305803523559,305.2155660077844,-2.573099639063357
16.098755284400756,0.04302220444088818,249.19833414891897,305.2155660077844,-2.573099639063357
16.206545414078516,0.04331026205241048,249.56262812958585,305.2155660077844,-2.573099639063357
16.37182361291775,0.04375195039007801,250.11938230231766,305.2155660077844,-2.573099639063357
16.551473829047357,0.044232046409281855,250.72206948673696,305.2155660077844,-2.573099639063357
16.68082198466067,0.04457771554310862,251.1544256374766,305.2155660077844,-2.573099639063357
16.889216235371013,0.04513462692538507,251.848259306746,305.2155660077844,-2.573099639063357
17.054494434210252,0.045576315263052614,252.39616991549872,305.2155660077844,-2.573099639063357
17.183842589823566,0.045921984396879376,252.82352630679847,305.2155660077844,-2.573099639063357
17.29881872814651,0.046229245849169834,253.20234656233592,305.2155660077844,-2.573099639063357
17.47128293563093,0.04669013802760552,253.76874097328223,305.2155660077844,-2.573099639063357
17.52158499614722,0.04682456491298259,253.93352806083314,305.2155660077844,-2.573099639063357
17.69404920363164,0.04728545709141828,254.49711693233104,305.2155660077844,-2.573099639063357
17.715607229567194,0.04734306861372274,254.56741459378682,305.2155660077844,-2.573099639063357
17.751537272793115,0.04743908781756351,254.68450326941277,305.2155660077844,-2.573099639063357
17.873699419761248,0.047765553110622125,255.0819152300666,305.2155660077844,-2.573099639063357
17.952745514858275,0.04797679535907182,255.33849978109916,305.2155660077844,-2.573099639063357
18.089279679116775,0.04834166833366674,255.7806559190611,305.2155660077844,-2.573099639063357
18.2114418260849,0.04866813362672534,256.17516725989555,305.2155660077844,-2.573099639063357
18.369534016278955,0.049090618123624724,256.68418266773875,305.2155660077844,-2.573099639063357
18.506068180537454,0.049455491098219645,257.1224135288987,305.2155660077844,-2.573099639063357
18.592300284279663,0.04968593718743748,257.39854134539263,305.2155660077844,-2.573099639063357
18.64978835344114,0.04983956791358271,257.5823491236805,305.2155660077844,-2.573099639063357
18.99471676840998,0.050761352270454085,258.68059096974343,305.2155660077844,-2.573099639063357
19.037832820281086,0.05087657531506301,258.8173222108243,305.2155660077844,-2.573099639063357
19.246227070991424,0.051433486697339464,259.4764949257088,305.2155660077844,-2.573099639063357
19.32527316608845,0.051644728945789156,259.7257970502279,305.2155660077844,-2.573099639063357
19.38994724389511,0.051817563512702544,259.9294758459733,305.2155660077844,-2.573099639063357
19.66301557241211,0.052547309461892386,260.78654829843475,305.2155660077844,-2.573099639063357
19.74924767615432,0.05277775555111022,261.05623670317,305.2155660077844,-2.573099639063357
19.857037805832082,0.05306581316263252,261.39270226692196,305.2155660077844,-2.573099639063357
19.936083900929106,0.053277055411082214,261.63899114063315,305.2155660077844,-2.573099639063357
20.015129996026133,0.053488297659531905,261.88489946096234,305.2155660077844,-2.573099639063357
20.35287240234979,0.05439087817563512,262.93136070887374,305.2155660077844,-2.573099639063357
20.52533660983421,0.05485177035407081,263.4631103328593,305.2155660077844,-2.573099639063357
20.59001068764087,0.055024604920984196,263.66206683528856,305.2155660077844,-2.573099639063357
20.683428800028263,0.05527425485097019,263.94901871358263,305.2155660077844,-2.573099639063357
20.992427171771183,0.0561000200040008,264.89458661968604,305.2155660077844,-2.573099639063357
21.121775327384498,0.05644568913782756,265.2887922340724,305.2155660077844,-2.573099639063357
21.294239534868918,0.05690658131626325,265.8129382882178,305.2155660077844,-2.573099639063357
21.402029664546685,0.05719463892778556,266.13968897862424,305.2155660077844,-2.573099639063357
21.481075759643712,0.057405881176235254,266.3788983921841,305.2155660077844,-2.573099639063357
22.027212416677706,0.058865373074614924,268.0223380900911,305.2155660077844,-2.573099639063357
22.055956451258442,0.05894218843768753,268.1083920164317,305.2155660077844,-2.573099639063357
22.228420658742863,0.05940308061612322,268.6238000728203,305.2155660077844,-2.573099639063357
22.32183877113026,0.05965273054610923,268.9023281679031,305.2155660077844,-2.573099639063357
22.63802315151836,0.06049769953990798,269.84168361050575,305.2155660077844,-2.573099639063357
22.724255255260573,0.06072814562912583,270.096981643824,305.2155660077844,-2.573099639063357
22.882347445454624,0.0611506301260252,270.5640488948955,305.2155660077844,-2.573099639063357
22.918277488680545,0.06124664932986597,270.6700248300744,305.2155660077844,-2.573099639063357
23.090741696164965,0.061707541508301655,271.17781011279436,305.2155660077844,-2.573099639063357
23.428484102488625,0.06261012202440489,272.1679586186084,305.2155660077844,-2.573099639063357
23.54346024081157,0.06291738347669534,272.5037582884205,305.2155660077844,-2.573099639063357
23.593762301327857,0.06305181036207241,272.65046946689733,305.2155660077844,-2.573099639063357
23.86683062984486,0.06378155631126226,273.4447831428561,305.2155660077844,-2.573099639063357
24.154270975652228,0.0645497099419884,274.27708324446496,305.2155660077844,-2.573099639063357
24.23331707074925,0.06476095219043809,274.5052874356957,305.2155660077844,-2.573099639063357
24.31236316584628,0.06497219443888778,274.7332015050429,305.2155660077844,-2.573099639063357
24.578245485718092,0.06568273654730947,275.4977095116882,305.2155660077844,-2.573099639063357
24.721965658621777,0.06606681336267253,275.909613864962,305.2155660077844,-2.573099639063357
24.81538377100917,0.06631646329265853,276.1768509894716,305.2155660077844,-2.573099639063357
25.11719613410691,0.06712302460492099,277.03756334727706,305.2155660077844,-2.573099639063357
25.29684635023651,0.06760312062412482,277.5479772434142,305.2155660077844,-2.573099639063357
25.512426609592037,0.06817923584716944,278.1586116558064,305.2155660077844,-2.573099639063357
25.555542661463143,0.06829445889177836,278.2804966961923,305.2155660077844,-2.573099639063357
25.74237888623793,0.06879375875175035,278.8077411685067,305.2155660077844,-2.573099639063357
25.92921511101272,0.06929305861172234,279.3334953223381,305.2155660077844,-2.573099639063357
26.137609361723058,0.0698499699939988,279.91817349052576,305.2155660077844,-2.573099639063357
26.245399491400825,0.07013802760552111,280.2198796871744,305.2155660077844,-2.573099639063357
26.504095802627454,0.07082936587317464,280.9420096759105,305.2155660077844,-2.573099639063357
26.597513915014847,0.07107901580316063,281.2021026092681,305.2155660077844,-2.573099639063357
26.662187992821508,0.07125185037007402,281.38195828138674,305.2155660077844,-2.573099639063357
26.99993039914516,0.07215443088617723,282.31845452967036,305.2155660077844,-2.573099639063357
27.086162502887376,0.07238487697539508,282.55682641677805,305.2155660077844,-2.573099639063357
27.474206969727323,0.07342188437687538,283.62585833782913,305.2155660077844,-2.573099639063357
27.553253064824343,0.07363312662532506,283.8429003717865,305.2155660077844,-2.573099639063357
27.66822920314729,0.07394038807761552,284.15816488326766,305.2155660077844,-2.573099639063357
27.91973950572874,0.0746125225045009,284.8460301975014,305.2155660077844,-2.573099639063357
28.077831695922793,0.07503500700140028,285.2771659967731,305.2155660077844,-2.573099639063357
28.243109894762025,0.07547669533906781,285.7268878451189,305.2155660077844,-2.573099639063357
28.695828439408633,0.0766865373074615,286.95350901095327,305.2155660077844,-2.573099639063357
28.77487453450566,0.07689777955591119,287.1669047273733,305.2155660077844,-2.573099639063357
28.832362603667132,0.07705141028205642,287.32195804191343,305.2155660077844,-2.573099639063357
29.076686897603395,0.07770434086817364,287.9795940461407,305.2155660077844,-2.573099639063357
29.105430932184127,0.07778115623124625,288.05682104583724,305.2155660077844,-2.573099639063357
29.328197200184842,0.07837647529505902,288.6543250614327,305.2155660077844,-2.573099639063357
29.40724329528187,0.07858771754350871,288.8659168176061,305.2155660077844,-2.573099639063357
29.522219433604814,0.07889497899579917,289.1732911092473,305.2155660077844,-2.573099639063357
29.7090556583796,0.07939427885577116,289.67178046943155,305.2155660077844,-2.573099639063357
29.852775831283285,0.07977835567113423,290.0544023164328,305.2155660077844,-2.573099639063357
29.99649600418697,0.0801624324864973,290.43630643237844,305.2155660077844,-2.573099639063357
30.09710012521955,0.08043128625725146,290.7032148230503,305.2155660077844,-2.573099639063357
30.17614622031657,0.08064252850570114,290.91268453804173,305.2155660077844,-2.573099639063357
30.327052401865444,0.08104580916183238,291.3119879901489,305.2155660077844,-2.573099639063357
30.76539892922168,0.08221724344868975,292.46749819884167,305.2155660077844,-2.573099639063357
30.844445024318706,0.08242848569713944,292.6751837502903,305.2155660077844,-2.573099639063357
30.923491119415726,0.08263972794558912,292.8826618304975,305.2155660077844,-2.573099639063357
31.06002528367423,0.08300460092018404,293.24054654177297,305.2155660077844,-2.573099639063357
31.189373439287543,0.0833502700540108,293.5790296796782,305.2155660077844,-2.573099639063357
31.361837646771964,0.08381116223244649,294.0294901488477,305.2155660077844,-2.573099639063357
31.57741790612749,0.0843872774554911,294.591209476133,305.2155660077844,-2.573099639063357
31.64927799257933,0.08457931586317263,294.77811663564324,305.2155660077844,-2.573099639063357
31.699580053095623,0.08471374274854972,294.90885318351536,305.2155660077844,-2.573099639063357
31.77862614819265,0.08492498499699941,295.1141329811219,305.2155660077844,-2.573099639063357
31.82174220006375,0.08504020804160832,295.2260198419175,305.2155660077844,-2.573099639063357
31.92234632109633,0.08530906181236247,295.4868595124928,305.2155660077844,-2.573099639063357
32.015764433483724,0.08555871174234847,295.7287808589185,305.2155660077844,-2.573099639063357
32.137926580451854,0.08588517703540709,296.04472455727444,305.2155660077844,-2.573099639063357
32.18104263232296,0.08600040008001601,296.156122226752,305.2155660077844,-2.573099639063357
32.252902718774806,0.08619243848769755,296.3416557462119,305.2155660077844,-2.573099639063357
32.38225087438812,0.08653810762152431,296.67521032961906,305.2155660077844,-2.573099639063357
32.53315705593698,0.08694138827765553,297.06370131441145,305.2155660077844,-2.573099639063357
32.57627310780809,0.08705661132226446,297.1745695728316,305.2155660077844,-2.573099639063357
32.633761176969564,0.08721024204840969,297.32230493699774,305.2155660077844,-2.573099639063357
32.77029534122806,0.08757511502300461,297.6727702345913,305.2155660077844,-2.573099639063357
32.80622538445399,0.08767113422684537,297.76490323787823,305.2155660077844,-2.573099639063357
33.00024761787396,0.08818963792758552,298.2617430880971,305.2155660077844,-2.573099639063357
33.237385903165034,0.08882336467293458,298.86744737076884,305.2155660077844,-2.573099639063357
33.596686335424245,0.08978355671134228,299.7819796203614,305.2155660077844,-2.573099639063357
33.654174404585724,0.0899371874374875,299.9279500653384,305.2155660077844,-2.573099639063357
33.718848482392374,0.09011002200440088,300.09205062762067,305.2155660077844,-2.573099639063357
33.90568470716717,0.09060932186437289,300.5654307906579,305.2155660077844,-2.573099639063357
34.17156702703898,0.09131986397279457,301.23733693629936,305.2155660077844,-2.573099639063357
34.23624110484564,0.09149269853970794,301.4004648973025,305.2155660077844,-2.573099639063357
34.49493741607227,0.09218403680736148,302.05177850964316,305.2155660077844,-2.573099639063357
34.653029606266315,0.09260652130426085,302.44886580323913,305.2155660077844,-2.573099639063357
34.76081973594408,0.09289457891578316,302.7192021497028,305.2155660077844,-2.573099639063357
34.89735390020258,0.09325945189037808,303.0611593209274,305.2155660077844,-2.573099639063357
34.97639999529961,0.09347069413882778,303.25889603934525,305.2155660077844,-2.573099639063357
35.04826008175145,0.09366273254650931,303.43850550647056,305.2155660077844,-2.573099639063357
35.29258437568771,0.09431566313262653,304.0481062833228,305.2155660077844,-2.573099639063357
35.493792617752874,0.09485337067413484,304.5488955913558,305.2155660077844,-2.573099639063357
35.54409467826916,0.09498779755951191,304.67391977342936,305.2155660077844,-2.573099639063357
35.572838712849894,0.09506461292258452,304.7453311814426,305.2155660077844,-2.573099639063357
35.91058111917356,0.09596719343868775,305.5827365392482,305.2155660077844,-2.573099639063357
36.13334738717426,0.0965625125025005,306.13338720028094,305.2155660077844,-2.573099639063357
36.28425356872313,0.09696579315863173,306.50565659208917,305.2155660077844,-2.573099639063357
36.427973741626815,0.09734986997399481,306.8596378929129,305.2155660077844,-2.573099639063357
36.708228078789,0.0980988197639528,307.5483387491859,305.2155660077844,-2.573099639063357
36.938180355434895,0.09871334266853371,308.1118963666543,305.2155660077844,-2.573099639063357
37.182504649371154,0.09936627325465093,308.709179216277,305.2155660077844,-2.573099639063357
37.26155074446818,0.09957751550310062,308.9020898185311,305.2155660077844,-2.573099639063357
37.275922761758544,0.09961592318463693,308.93714731938536,305.2155660077844,-2.573099639063357
37.405270917371865,0.0999615923184637,309.2524279653194,305.2155660077844,-2.573099639063357
37.419642934662235,0.1,309.28743288180465,305.2155660077844,-2.573099639063357