File: datasets/aisi_316_L/data/M1/train_2.csv
Time(s),Strain(%),Stress(MPa),Temp(C),Log_SR(s-1)
0.0,0.0,0.0,357.7985767449866,-2.999085001461241
0.004789897708225998,4.8e-06,0.8295452249999999,357.7985767449866,-2.999085001461241
0.03113433510346899,3.12e-05,5.3920439625,357.7985767449866,-2.999085001461241
0.044705711943442646,4.48e-05,7.7424221,357.7985767449866,-2.999085001461241
0.048697293366964316,4.88e-05,8.4337097875,357.7985767449866,-2.999085001461241
0.06386530277634664,6.4e-05,11.060602999999999,357.7985767449866,-2.999085001461241
0.06865520048457263,6.879999999999999e-05,11.890148224999999,357.7985767449866,-2.999085001461241
0.0918063727409983,9.2e-05,15.8996168125,357.7985767449866,-2.999085001461241
0.0965962704492243,9.68e-05,16.7291620375,357.7985767449866,-2.999085001461241
0.11336091242801528,0.0001136,19.632570325,357.7985767449866,-2.999085001461241
0.14689019638559728,0.0001472,25.4393869,357.7985767449866,-2.999085001461241
0.16125988951027528,0.0001616,27.928022575,357.7985767449866,-2.999085001461241
0.1772262152043619,0.00017759999999999998,30.693173324999997,357.7985767449866,-2.999085001461241
0.20357065259960494,0.000204,35.2556720625,357.7985767449866,-2.999085001461241
0.21634371315487425,0.00021679999999999998,37.467792662499996,357.7985767449866,-2.999085001461241
0.22991508999484792,0.0002304,39.8181708,357.7985767449866,-2.999085001461241
0.25546121110538655,0.000256,44.242411999999995,357.7985767449866,-2.999085001461241
0.27541911822299486,0.000276,47.6988504375,357.7985767449866,-2.999085001461241
0.2849989136394469,0.0002856,49.3579408875,357.7985767449866,-2.999085001461241
0.3193265138817332,0.00031999999999999997,55.303014999999995,357.7985767449866,-2.999085001461241
0.3265113604440722,0.0003272,56.5473328375,357.7985767449866,-2.999085001461241
0.3504608489852022,0.00035119999999999997,60.69505896249999,357.7985767449866,-2.999085001461241
0.36163727697106285,0.00036239999999999997,62.63066448749999,357.7985767449866,-2.999085001461241
0.3696204398181062,0.0003704,64.0132398625,357.7985767449866,-2.999085001461241
0.37999855151926254,0.0003808,65.81058785,357.7985767449866,-2.999085001461241
0.3887800306510102,0.0003896,67.3314207625,357.7985767449866,-2.999085001461241
0.39995645863687085,0.0004008,69.2670262875,357.7985767449866,-2.999085001461241
0.4231076308932965,0.000424,73.276494875,357.7985767449866,-2.999085001461241
0.4374773240179745,0.0004384,75.76513055,357.7985767449866,-2.999085001461241
0.4510487008579482,0.000452,78.1155086875,357.7985767449866,-2.999085001461241
0.4734015568296695,0.0004744,81.9867197375,357.7985767449866,-2.999085001461241
0.4837796685308258,0.00048479999999999997,83.784067725,357.7985767449866,-2.999085001461241
0.5061325245025471,0.0005072,87.655278775,357.7985767449866,-2.999085001461241
0.5149140036342947,0.000516,89.1761116875,357.7985767449866,-2.999085001461241
0.5460483387377638,0.0005472,94.56815565,357.7985767449866,-2.999085001461241
0.5524348690153985,0.0005536,95.67421595,357.7985767449866,-2.999085001461241
0.5787793064106415,0.00058,100.2367146875,357.7985767449866,-2.999085001461241
0.6186951206458581,0.00062,107.1495915625,357.7985767449866,-2.999085001461241
0.6386530277634664,0.0006399999999999999,110.60602999999999,357.7985767449866,-2.999085001461241
0.6889469536998394,0.0006904,119.3162548625,357.7985767449866,-2.999085001461241
0.7057115956786304,0.0007072,122.21966314999999,357.7985767449866,-2.999085001461241
0.7296610842197604,0.0007312,126.367389275,357.7985767449866,-2.999085001461241
0.7352492982126908,0.0007368,127.33519203750001,357.7985767449866,-2.999085001461241
0.7448290936291426,0.0007463999999999999,128.9942824875,357.7985767449866,-2.999085001461241
0.7615937356079338,0.0007632,131.897690775,357.7985767449866,-2.999085001461241
0.7671819496008639,0.0007687999999999999,132.8654935375,357.7985767449866,-2.999085001461241
0.7783583775867247,0.00078,134.8010990625,357.7985767449866,-2.999085001461241
0.7839465915796551,0.0007856,135.768901825,357.7985767449866,-2.999085001461241
0.8134842941137154,0.0008152,140.8844307125,357.7985767449866,-2.999085001461241
0.8382320989395496,0.0008399999999999999,145.17041437499998,357.7985767449866,-2.999085001461241
0.8494085269254104,0.0008512,147.1060199,357.7985767449866,-2.999085001461241
0.862979903765384,0.0008648,149.4563980375,357.7985767449866,-2.999085001461241
0.8685681177583142,0.0008703999999999999,150.4242008,357.7985767449866,-2.999085001461241
0.889324341160627,0.0008912,154.018896775,357.7985767449866,-2.999085001461241
0.8933159225841486,0.0008952,154.44993472068376,357.7985767449866,-2.999085001461241
0.8973075040076703,0.0008992,154.4709632578004,357.7985767449866,-2.999085001461241
0.9212569925488003,0.0009232,154.5963767867691,357.7985767449866,-2.999085001461241
0.9236519414029133,0.0009256,154.6088477965788,357.7985767449866,-2.999085001461241
0.9316351042499565,0.0009335999999999999,154.65032704866397,357.7985767449866,-2.999085001461241
0.9460047973746346,0.000948,154.72464205656016,357.7985767449866,-2.999085001461241
0.9675593370616516,0.0009695999999999999,154.83529436748603,357.7985767449866,-2.999085001461241
0.973147551054582,0.0009752,154.86382454738526,357.7985767449866,-2.999085001461241
0.9883155604639643,0.0009904,154.94094333886238,357.7985767449866,-2.999085001461241
1.004281886158051,0.0010064,155.02162399234655,357.7985767449866,-2.999085001461241
1.0074751512968683,0.0010096,155.03769992425515,357.7985767449866,-2.999085001461241
1.0202482118521377,0.0010224,155.10180592273676,357.7985767449866,-2.999085001461241
1.0266347421297721,0.0010287999999999999,155.13374148888002,357.7985767449866,-2.999085001461241
1.047390965532085,0.0010496,155.23700105348672,357.7985767449866,-2.999085001461241
1.068945505219102,0.0010712,155.34339093359392,357.7985767449866,-2.999085001461241
1.0745337192120323,0.0010768,155.37083650722965,357.7985767449866,-2.999085001461241
1.1072646868849099,0.0011095999999999999,155.53048525286627,357.7985767449866,-2.999085001461241
1.1200377474401793,0.0011224,155.59228659583482,357.7985767449866,-2.999085001461241
1.1304158591413356,0.0011328,155.6422980388724,357.7985767449866,-2.999085001461241
1.1376007057036746,0.00114,155.67681649798715,357.7985767449866,-2.999085001461241
1.1447855522660135,0.0011472,155.71125003664127,357.7985767449866,-2.999085001461241
1.1687350408071435,0.0011711999999999998,155.82542460276122,357.7985767449866,-2.999085001461241
1.1791131525082998,0.0011815999999999999,155.8746164734226,357.7985767449866,-2.999085001461241
1.191087896778865,0.0011936,155.93116698815385,357.7985767449866,-2.999085001461241
1.200667692195317,0.0012032,155.97624791628405,357.7985767449866,-2.999085001461241
1.2070542224729515,0.0012096,156.00622396047297,357.7985767449866,-2.999085001461241
1.2142390690352904,0.0012167999999999999,156.03987317211067,357.7985767449866,-2.999085001461241
1.2302053947293772,0.0012328,156.11437242642242,357.7985767449866,-2.999085001461241
1.2357936087223076,0.0012384,156.14035795384396,357.7985767449866,-2.999085001461241
1.239785190145829,0.0012423999999999998,156.15889099525944,357.7985767449866,-2.999085001461241
1.2541548832705072,0.0012568,156.22541812502038,357.7985767449866,-2.999085001461241
1.2573481484093243,0.0012599999999999998,156.24016148377095,357.7985767449866,-2.999085001461241
1.2669279438257763,0.0012695999999999999,156.28430419078038,357.7985767449866,-2.999085001461241
1.2709195252492982,0.0012736,156.3026585435368,357.7985767449866,-2.999085001461241
1.3092387069151061,0.001312,156.47773120912066,357.7985767449866,-2.999085001461241
1.327599981463306,0.0013304,156.56091097117172,357.7985767449866,-2.999085001461241
1.334784828025645,0.0013376,156.59333729361975,357.7985767449866,-2.999085001461241
1.351549470004436,0.0013544,156.66873513719457,357.7985767449866,-2.999085001461241
1.3715073771220443,0.0013744,156.75802055283302,357.7985767449866,-2.999085001461241
1.383482121392609,0.0013863999999999999,156.8113486079269,357.7985767449866,-2.999085001461241
1.3874737028161308,0.0013904,156.82908458281346,357.7985767449866,-2.999085001461241
1.390666967954948,0.0013935999999999998,156.84325903935604,357.7985767449866,-2.999085001461241
1.4082299262184435,0.0014112,156.92099283226767,357.7985767449866,-2.999085001461241
1.4281878333360518,0.0014311999999999999,157.0088692003327,357.7985767449866,-2.999085001461241
1.4457507915995471,0.0014487999999999999,157.08580499601135,357.7985767449866,-2.999085001461241
1.4553305870159992,0.0014583999999999999,157.12761631158975,357.7985767449866,-2.999085001461241
1.4665070150018598,0.0014696,157.17626075798827,357.7985767449866,-2.999085001461241
1.5096160943758936,0.0015128,157.36255038345305,357.7985767449866,-2.999085001461241
1.5335655829170236,0.0015367999999999998,157.46514777890778,357.7985767449866,-2.999085001461241
1.541548745764067,0.0015448,157.49920779858968,357.7985767449866,-2.999085001461241
1.551128541180519,0.0015543999999999998,157.5399891535287,357.7985767449866,-2.999085001461241
1.5551201226040408,0.0015584,157.55695238029625,357.7985767449866,-2.999085001461241
1.572683080867536,0.001576,157.63138975852905,357.7985767449866,-2.999085001461241
1.5750780297216491,0.0015784,157.64151513344842,357.7985767449866,-2.999085001461241
1.5806662437145793,0.001584,157.66511768659385,357.7985767449866,-2.999085001461241
1.6038174159710052,0.0016072,157.7625550169445,357.7985767449866,-2.999085001461241
1.627766904512135,0.0016312,157.86277674625052,357.7985767449866,-2.999085001461241
1.6565062907614911,0.00166,157.98228687441198,357.7985767449866,-2.999085001461241
1.6628928210391256,0.0016664,158.00873454711996,357.7985767449866,-2.999085001461241
1.6796574630179166,0.0016832,158.07797189210137,357.7985767449866,-2.999085001461241
1.6916322072884817,0.0016952,158.12726223178427,357.7985767449866,-2.999085001461241
1.706800216697864,0.0017104,158.18950175223156,357.7985767449866,-2.999085001461241
1.757094142634237,0.0017607999999999999,158.39434853020273,357.7985767449866,-2.999085001461241
1.7682705706200976,0.001772,158.43955799581084,357.7985767449866,-2.999085001461241
1.771463835758915,0.0017752,158.45245449940094,357.7985767449866,-2.999085001461241
1.7818419474600713,0.0017855999999999998,158.49430565979037,357.7985767449866,-2.999085001461241
1.8257493431188097,0.0018296,158.67032657217948,357.7985767449866,-2.999085001461241
1.857681994506983,0.0018616,158.79730646582547,357.7985767449866,-2.999085001461241
1.8608752596458003,0.0018648,158.80995745546767,357.7985767449866,-2.999085001461241
1.8776399016245913,0.0018816,158.87623675973458,357.7985767449866,-2.999085001461241
1.8824297993328172,0.0018863999999999999,158.8951312612671,357.7985767449866,-2.999085001461241
1.9039843390198343,0.001908,158.97992554887577,357.7985767449866,-2.999085001461241
1.9071776041586515,0.0019111999999999998,158.99245575328652,357.7985767449866,-2.999085001461241
1.9119675018668776,0.001916,159.01123572933997,357.7985767449866,-2.999085001461241
1.9167573995751035,0.0019207999999999999,159.02999736562822,357.7985767449866,-2.999085001461241
1.9367153066927119,0.0019408,159.1079748451691,357.7985767449866,-2.999085001461241
1.949488367247981,0.0019535999999999998,159.15771601135833,357.7985767449866,-2.999085001461241
1.9614631115185464,0.0019656,159.20423304414047,357.7985767449866,-2.999085001461241
2.002177242038467,0.0020063999999999998,159.36156903752686,357.7985767449866,-2.999085001461241
2.019740200301962,0.0020239999999999998,159.4290536913111,357.7985767449866,-2.999085001461241
2.042891372558388,0.0020472,159.51766209140195,357.7985767449866,-2.999085001461241
2.0724290750924483,0.0020767999999999997,159.63014766910715,357.7985767449866,-2.999085001461241
2.0772189728006745,0.0020816,159.6483294924627,357.7985767449866,-2.999085001461241
2.080412237939492,0.0020848,159.66044162495209,357.7985767449866,-2.999085001461241
2.0860004519324225,0.0020904,159.6816204246795,357.7985767449866,-2.999085001461241
2.0963785636335786,0.0021008,159.72089386956506,357.7985767449866,-2.999085001461241
2.1027650939112132,0.0021072,159.74502445820974,357.7985767449866,-2.999085001461241
2.1219246847441173,0.0021264,159.8172453075633,357.7985767449866,-2.999085001461241
2.1299078475911606,0.0021344,159.84726221623401,357.7985767449866,-2.999085001461241
2.1426809081464295,0.0021471999999999997,159.89519816541002,357.7985767449866,-2.999085001461241
2.165033764118151,0.0021696,159.9788187712309,357.7985767449866,-2.999085001461241
2.1889832526592814,0.0021936,160.06803951073582,357.7985767449866,-2.999085001461241
2.1977647317910285,0.0022023999999999998,160.10065829116922,357.7985767449866,-2.999085001461241
2.2073445272074808,0.002212,160.1361844987328,357.7985767449866,-2.999085001461241
2.2145293737698197,0.0022191999999999997,160.16278970677973,357.7985767449866,-2.999085001461241
2.217722638908637,0.0022224,160.17460343572125,357.7985767449866,-2.999085001461241
2.2249074854709763,0.0022296,160.20116009704205,357.7985767449866,-2.999085001461241
2.237680546026245,0.0022424,160.248289504307,357.7985767449866,-2.999085001461241
2.2496552902968103,0.0022543999999999997,160.2923781256867,357.7985767449866,-2.999085001461241
2.2616300345673754,0.0022664,160.33637531613633,357.7985767449866,-2.999085001461241
2.270411513699123,0.0022752,160.36858220261234,357.7985767449866,-2.999085001461241
2.2991508999484793,0.002304,160.47364851213501,357.7985767449866,-2.999085001461241
2.3023441650872964,0.0023071999999999997,160.48529084306503,357.7985767449866,-2.999085001461241
2.315117225642566,0.00232,160.53179732960461,357.7985767449866,-2.999085001461241
2.33427681647547,0.0023392,160.601369868767,357.7985767449866,-2.999085001461241
2.3430582956072175,0.002348,160.63318281840668,357.7985767449866,-2.999085001461241
2.381377477273025,0.0023864,160.77146233823245,357.7985767449866,-2.999085001461241
2.392553905258886,0.0023975999999999997,160.8116300477546,357.7985767449866,-2.999085001461241
2.399738751821225,0.0024048,160.8374135092733,357.7985767449866,-2.999085001461241
2.418898342654129,0.002424,160.9060226437586,357.7985767449866,-2.999085001461241
2.422889924077651,0.002428,160.92028950034737,357.7985767449866,-2.999085001461241
2.4396545660564417,0.0024448,160.98011047519915,357.7985767449866,-2.999085001461241
2.462805738312867,0.0024679999999999997,161.06245749829048,357.7985767449866,-2.999085001461241
2.471587217444615,0.0024768,161.0936135329406,357.7985767449866,-2.999085001461241
2.479570380291658,0.0024847999999999997,161.1218997580709,357.7985767449866,-2.999085001461241
2.4851585942845884,0.0024904,161.1416789867356,357.7985767449866,-2.999085001461241
2.5107047153951276,0.002516,161.23187833823118,357.7985767449866,-2.999085001461241
2.5354525202209617,0.0025407999999999997,161.31891825320673,357.7985767449866,-2.999085001461241
2.5753683344561784,0.0025808,161.45861026287244,357.7985767449866,-2.999085001461241
2.586544762442039,0.0025919999999999997,161.4975723824823,357.7985767449866,-2.999085001461241
2.598519506712604,0.002604,161.53924472139485,357.7985767449866,-2.999085001461241
2.605704353274943,0.0026111999999999997,161.5642121766569,357.7985767449866,-2.999085001461241
2.615284148691395,0.0026208,161.59746039171702,357.7985767449866,-2.999085001461241
2.619275730114917,0.0026248,161.61129979242892,357.7985767449866,-2.999085001461241
2.6336454232395945,0.0026392,161.66105367524696,357.7985767449866,-2.999085001461241
2.639233637232525,0.0026447999999999997,161.68037380159555,357.7985767449866,-2.999085001461241
2.65120838150309,0.0026568,161.72172043184148,357.7985767449866,-2.999085001461241
2.6631831257736547,0.0026688,161.76299429308497,357.7985767449866,-2.999085001461241
2.6935191445924196,0.0026991999999999997,161.8672321204915,357.7985767449866,-2.999085001461241
2.7374265402511577,0.0027432,162.01729537095937,357.7985767449866,-2.999085001461241
2.7406198053899753,0.0027464,162.02817230525378,357.7985767449866,-2.999085001461241
2.756586131084062,0.0027624,162.08248301374243,357.7985767449866,-2.999085001461241
2.778140670771079,0.002784,162.15560826476548,357.7985767449866,-2.999085001461241
2.7933086801804614,0.0027992,162.20693419427585,357.7985767449866,-2.999085001461241
2.8132665872980698,0.0028192,162.27430301480655,357.7985767449866,-2.999085001461241
2.8539807178179903,0.0028599999999999997,162.41116019303806,357.7985767449866,-2.999085001461241
2.8771318900744163,0.0028832,162.4886413282485,357.7985767449866,-2.999085001461241
2.898686429761433,0.0029048,162.56056064627163,357.7985767449866,-2.999085001461241
2.905072960039068,0.0029112,162.58182998036068,357.7985767449866,-2.999085001461241
2.9066695926084765,0.0029127999999999997,162.58714446357192,357.7985767449866,-2.999085001461241
2.9162493880249287,0.0029224,162.61900748715422,357.7985767449866,-2.999085001461241
2.933812346288424,0.00294,162.6773172108591,357.7985767449866,-2.999085001461241
2.9401988765660585,0.0029464,162.69848697388454,357.7985767449866,-2.999085001461241
2.9425938254201713,0.0029487999999999997,162.70642101054585,357.7985767449866,-2.999085001461241
2.987299537363614,0.0029936,162.8540638867152,357.7985767449866,-2.999085001461241
2.9952827002106575,0.0030015999999999997,162.88033775449168,357.7985767449866,-2.999085001461241
3.0064591281965183,0.0030128,162.9170753345207,357.7985767449866,-2.999085001461241
3.0128456584741525,0.0030191999999999997,162.93804432318942,357.7985767449866,-2.999085001461241
3.0176355561823787,0.0030239999999999998,162.95375969033265,357.7985767449866,-2.999085001461241
3.030408616737648,0.0030367999999999997,162.99561984702467,357.7985767449866,-2.999085001461241
3.0439799935776217,0.0030504,163.04002093768528,357.7985767449866,-2.999085001461241
3.047971575001143,0.0030543999999999997,163.05306538049453,357.7985767449866,-2.999085001461241
3.073517696111682,0.00308,163.1363926056437,357.7985767449866,-2.999085001461241
3.0918789706598817,0.0030984,163.19611729632464,357.7985767449866,-2.999085001461241
3.0998621335069254,0.0031064,163.22204139117719,357.7985767449866,-2.999085001461241
3.162130803713863,0.0031688,163.4233633296146,357.7985767449866,-2.999085001461241
3.1980550365255582,0.0032048,163.53880724974238,357.7985767449866,-2.999085001461241
3.250743911316044,0.0032576,163.70721432467167,357.7985767449866,-2.999085001461241
3.2619203393019047,0.0032687999999999997,163.7427998012583,357.7985767449866,-2.999085001461241
3.2691051858642437,0.003276,163.7656510712983,357.7985767449866,-2.999085001461241
3.280281613850104,0.0032871999999999997,163.8011585981806,357.7985767449866,-2.999085001461241
3.3146092140923904,0.0033215999999999996,163.90992357579717,357.7985767449866,-2.999085001461241
3.3257856420782512,0.0033328,163.94524051423437,357.7985767449866,-2.999085001461241
3.3696930377369894,0.0033767999999999997,164.08353984065437,357.7985767449866,-2.999085001461241
3.400827372840459,0.003408,164.1811810974584,357.7985767449866,-2.999085001461241
3.425575177666293,0.0034327999999999997,164.2585449154933,357.7985767449866,-2.999085001461241
3.432760024228632,0.00344,164.2809645114133,357.7985767449866,-2.999085001461241
3.4407431870756753,0.0034479999999999997,164.30585372087265,357.7985767449866,-2.999085001461241
3.4503229824921275,0.0034576,164.33569106355932,357.7985767449866,-2.999085001461241
3.480659001310892,0.0034879999999999998,164.42996353925432,357.7985767449866,-2.999085001461241
3.4966253270049785,0.0035039999999999997,164.4794518946079,357.7985767449866,-2.999085001461241
3.5133899689837693,0.0035207999999999997,164.5313199118809,357.7985767449866,-2.999085001461241
3.530952927247265,0.0035383999999999997,164.58555441413313,357.7985767449866,-2.999085001461241
3.538137773809604,0.0035456,164.60771092081424,357.7985767449866,-2.999085001461241
3.565280527489551,0.0035727999999999997,164.69125539541295,357.7985767449866,-2.999085001461241
3.6028013928706546,0.0036103999999999997,164.80633604453033,357.7985767449866,-2.999085001461241
3.6067929742941764,0.0036144,164.81855109643155,357.7985767449866,-2.999085001461241
3.6251542488423762,0.0036328,164.8746725700965,357.7985767449866,-2.999085001461241
3.6339357279741242,0.0036416,164.90147407725004,357.7985767449866,-2.999085001461241
3.648305421098802,0.003656,164.94527666921798,357.7985767449866,-2.999085001461241
3.6666666956470015,0.0036744,165.00114885531434,357.7985767449866,-2.999085001461241
3.683431337625793,0.0036912,165.05206736708766,357.7985767449866,-2.999085001461241
3.7001959796045836,0.003708,165.102895576643,357.7985767449866,-2.999085001461241
3.706582509882218,0.0037143999999999996,165.12223506994513,357.7985767449866,-2.999085001461241
3.7249437844304176,0.0037327999999999997,165.17776385513557,357.7985767449866,-2.999085001461241
3.732128630992757,0.00374,165.19946343920384,357.7985767449866,-2.999085001461241
3.7385151612703917,0.0037464,165.2187382848315,357.7985767449866,-2.999085001461241
3.7472966404021393,0.0037551999999999998,165.24522024272207,357.7985767449866,-2.999085001461241
3.7648595986656344,0.0037727999999999998,165.2981116619939,357.7985767449866,-2.999085001461241
3.7840191894985384,0.003792,165.35570176594442,357.7985767449866,-2.999085001461241
3.8287249014419813,0.0038368,165.4896382284886,357.7985767449866,-2.999085001461241
3.848682808559589,0.0038567999999999996,165.54923422723053,357.7985767449866,-2.999085001461241
3.85985923654545,0.003868,165.5825553377175,357.7985767449866,-2.999085001461241
3.874228929670128,0.0038824,165.62534152704154,357.7985767449866,-2.999085001461241
3.8909935716489192,0.0038992,165.6751806027111,357.7985767449866,-2.999085001461241
3.9101531624818233,0.0039184,165.73203711406512,357.7985767449866,-2.999085001461241
3.9197329578982756,0.003928,165.76042461785593,357.7985767449866,-2.999085001461241
3.940489181300588,0.0039488,165.8218382192774,357.7985767449866,-2.999085001461241
3.9804049955358045,0.0039888,165.93958785782817,357.7985767449866,-2.999085001461241
4.010744847039273,0.004019203840768154,166.02878109681123,357.7985767449866,-2.999085001461241
5.045569716990079,0.00505621124224845,168.92950274232038,357.7985767449866,-2.999085001461241
5.275530799201369,0.005286657331466294,169.54136859873222,357.7985767449866,-2.999085001461241
5.697126116588734,0.005709141828365673,170.63675581952975,357.7985767449866,-2.999085001461241
6.310355669152175,0.006323664732946589,172.1751753865339,357.7985767449866,-2.999085001461241
6.42533621025782,0.006438887777555511,172.45701646392163,357.7985767449866,-2.999085001461241
6.770277833574755,0.006784556911382277,173.29096723089256,357.7985767449866,-2.999085001461241
6.8852583746804,0.0068997799559911985,173.5652460368999,357.7985767449866,-2.999085001461241
7.076892609856475,0.007091818363672734,174.0184405228786,357.7985767449866,-2.999085001461241
7.249363421514943,0.007264652930586117,174.42223936931993,357.7985767449866,-2.999085001461241
7.843429550560775,0.00785997199439888,175.7852869083254,357.7985767449866,-2.999085001461241
7.996736938701636,0.008013602720544109,176.1304274662424,357.7985767449866,-2.999085001461241
8.245861444430533,0.008263252650530106,176.68582707561717,357.7985767449866,-2.999085001461241
8.456659103124217,0.008474494898979796,177.15068750958906,357.7985767449866,-2.999085001461241
8.801600726441151,0.008820164032806561,177.90173601243708,357.7985767449866,-2.999085001461241
9.28068631438134,0.009300260052010402,178.92608368134938,357.7985767449866,-2.999085001461241
9.568137667145452,0.009588317663532707,179.5307950844863,357.7985767449866,-2.999085001461241
10.028059831568033,0.010049209841968394,180.48379856905578,357.7985767449866,-2.999085001461241
10.871250466342763,0.010894178835767154,182.1878149125242,357.7985767449866,-2.999085001461241
10.967067583930799,0.01099019803960792,182.37813468525715,357.7985767449866,-2.999085001461241
11.19702866614209,0.011220644128825764,182.83227556090245,357.7985767449866,-2.999085001461241
11.484480018906204,0.01150870174034807,183.3948683211303,357.7985767449866,-2.999085001461241
11.963565606846391,0.01198879775955191,184.320468503267,357.7985767449866,-2.999085001461241
12.59595858292744,0.01262252450490098,185.52041758028622,357.7985767449866,-2.999085001461241
13.075044170867628,0.013102620524104821,186.4138868200995,357.7985767449866,-2.999085001461241
13.36249552363174,0.013390678135627125,186.94384100641136,357.7985767449866,-2.999085001461241
13.554129758807814,0.013582716543308662,187.29467574161143,357.7985767449866,-2.999085001461241
13.937398229159966,0.013966793358671735,187.99059474107008,357.7985767449866,-2.999085001461241
14.493137511170584,0.01452370474094819,188.98656291170914,357.7985767449866,-2.999085001461241
14.933896252075558,0.014965393078615724,189.7659157886578,357.7985767449866,-2.999085001461241
15.106367063734025,0.015138227645529106,190.06843153118106,357.7985767449866,-2.999085001461241
15.52796238112139,0.015560712142428487,190.80229873366676,357.7985767449866,-2.999085001461241
15.738760039815071,0.015771954390878175,191.16631516071016,357.7985767449866,-2.999085001461241
16.198682204237652,0.016232846569313862,191.95399723415363,357.7985767449866,-2.999085001461241
16.371153015896116,0.016405681136227243,192.24712312123185,357.7985767449866,-2.999085001461241
16.716094639213058,0.016751350270054012,192.82978654038362,357.7985767449866,-2.999085001461241
17.367651038811708,0.017404280856171232,193.91773529226103,357.7985767449866,-2.999085001461241
17.501795003434964,0.01753870774154831,194.1397356557611,357.7985767449866,-2.999085001461241
17.789246356199076,0.017826765353070616,194.6132284249308,357.7985767449866,-2.999085001461241
18.05753428544558,0.018095619123824763,195.05246986372012,357.7985767449866,-2.999085001461241
18.709090685044238,0.01874854970994199,196.10873490485756,357.7985767449866,-2.999085001461241
18.862398073185098,0.01890218043608722,196.355171100756,357.7985767449866,-2.999085001461241
18.939051767255528,0.018978995799159834,196.47809617745014,357.7985767449866,-2.999085001461241
19.111522578913995,0.019151830366073215,196.75397036977472,357.7985767449866,-2.999085001461241
19.724752131477434,0.01976635327065413,197.72708890748066,357.7985767449866,-2.999085001461241
20.069693754794372,0.020112022404480897,198.2692811840277,357.7985767449866,-2.999085001461241
20.242164566452836,0.020284856971394278,198.53901354998675,357.7985767449866,-2.999085001461241
20.510452495699344,0.02055371074214843,198.95682248511986,357.7985767449866,-2.999085001461241
20.62543303680499,0.02066893378675735,199.13523037583457,357.7985767449866,-2.999085001461241
21.219499165850824,0.021264252850570115,200.05089728083578,357.7985767449866,-2.999085001461241
21.602767636202973,0.021648329665933188,200.63634835594374,357.7985767449866,-2.999085001461241
22.63759250615378,0.022685337067413484,202.1971747175847,357.7985767449866,-2.999085001461241
22.982534129470714,0.02303100620124025,202.71123298987587,357.7985767449866,-2.999085001461241
23.48078314092851,0.023530306061212244,203.44848083304515,357.7985767449866,-2.999085001461241
23.902378458315873,0.02395279055811162,204.06755266956867,357.7985767449866,-2.999085001461241
23.979032152386303,0.024029605921184236,204.17965215529358,357.7985767449866,-2.999085001461241
24.362300622738452,0.02441368273654731,204.7380668445905,357.7985767449866,-2.999085001461241
24.688078822537783,0.024740148029605922,205.21003072264568,357.7985767449866,-2.999085001461241
24.918039904749072,0.024970594118823766,205.54172041533147,357.7985767449866,-2.999085001461241
25.72290369248859,0.02577715543108622,206.69334821194482,357.7985767449866,-2.999085001461241
26.221152703946384,0.026276455291058213,207.39922126991752,357.7985767449866,-2.999085001461241
26.585257750780926,0.02664132826565313,207.9117477490164,357.7985767449866,-2.999085001461241
27.31346784445001,0.02737107421484297,208.92866070262713,357.7985767449866,-2.999085001461241
27.63924604424934,0.027697539507901582,209.38016632974362,357.7985767449866,-2.999085001461241
27.7925534323902,0.02785117023404681,209.59192096198424,357.7985767449866,-2.999085001461241
28.17582190274235,0.028235247049409884,210.11932422956446,357.7985767449866,-2.999085001461241
28.252475596812783,0.0283120624124825,210.22446832468833,357.7985767449866,-2.999085001461241
28.827378302341003,0.028888177635527104,211.0095332168117,357.7985767449866,-2.999085001461241
29.402281007869227,0.029464292858571713,211.7885152769675,357.7985767449866,-2.999085001461241
29.593915243045306,0.02965633126625325,212.0468529140921,357.7985767449866,-2.999085001461241
29.804712901738988,0.02986757351470294,212.3302719465671,357.7985767449866,-2.999085001461241
30.24547164264396,0.030309261852370473,212.920361584458,357.7985767449866,-2.999085001461241
31.740218677017346,0.03180716143228646,214.89702350502685,357.7985767449866,-2.999085001461241
32.10432372385189,0.03217203440688138,215.37297778558434,357.7985767449866,-2.999085001461241
32.391775076616,0.03246009201840368,215.7472457266485,357.7985767449866,-2.999085001461241
32.736716699932934,0.032805761152230446,216.19466175787858,357.7985767449866,-2.999085001461241
33.04333147621466,0.033113022604520904,216.5908236850742,357.7985767449866,-2.999085001461241
33.77154156988374,0.03384276855371074,217.5260061689132,357.7985767449866,-2.999085001461241
33.86735868747178,0.033938787757551506,217.64846837165422,357.7985767449866,-2.999085001461241
34.05899292264785,0.034130826165233046,217.89298816112105,357.7985767449866,-2.999085001461241
34.250627157823935,0.034322864572914585,218.13697197347992,357.7985767449866,-2.999085001461241
34.53807851058804,0.034610922184436885,218.50195182823774,357.7985767449866,-2.999085001461241
35.400432568880376,0.0354750950190038,219.58984869025622,357.7985767449866,-2.999085001461241
35.64955707460928,0.03572474494898979,219.9021994026884,357.7985767449866,-2.999085001461241
35.745374192197325,0.03582076415283057,220.02210747755518,357.7985767449866,-2.999085001461241
35.78370103923253,0.035859171834366876,220.0700356007006,357.7985767449866,-2.999085001461241
36.30111347420794,0.036377675535107026,220.7151182235451,357.7985767449866,-2.999085001461241
36.39693059179598,0.03647369473894779,220.83418342270437,357.7985767449866,-2.999085001461241
36.51191113290162,0.03658891778355672,220.97690042138112,357.7985767449866,-2.999085001461241
36.93350645028898,0.03701140228045609,221.49870318218177,357.7985767449866,-2.999085001461241
37.56589942637003,0.03764512902580516,222.27707267359824,357.7985767449866,-2.999085001461241
37.930004473204576,0.038010002000400084,222.7229065093356,357.7985767449866,-2.999085001461241
38.006658167275,0.03808681736347269,222.81655323077499,357.7985767449866,-2.999085001461241
38.17912897893348,0.03825965193038608,223.02698945462595,357.7985767449866,-2.999085001461241
38.86901222556734,0.0389509901980396,223.86505316546635,357.7985767449866,-2.999085001461241
39.13730015481384,0.03921984396879376,224.1893976608537,357.7985767449866,-2.999085001461241
40.07630790717662,0.04016083216643329,225.3178372327582,357.7985767449866,-2.999085001461241
40.8045180008457,0.04089057811562312,226.18586903311316,357.7985767449866,-2.999085001461241
41.62854521210282,0.04171634326865373,227.16086192425084,357.7985767449866,-2.999085001461241
41.85850629431412,0.04194678935787158,227.43160584831918,357.7985767449866,-2.999085001461241
42.37591872928952,0.04246529305861173,228.03866768013287,357.7985767449866,-2.999085001461241
42.81667747019449,0.042906981396279256,228.55351777493345,357.7985767449866,-2.999085001461241
43.3340899051699,0.043425485097019406,229.15527698293067,357.7985767449866,-2.999085001461241
43.48739729331076,0.043579115823164635,229.3330370177913,357.7985767449866,-2.999085001461241
43.73652179903965,0.04382876575315063,229.62137670526502,357.7985767449866,-2.999085001461241
44.00480972828616,0.044097619523904785,229.9311809686028,357.7985767449866,-2.999085001461241
44.809673516025676,0.044904180836167235,230.85620383196127,357.7985767449866,-2.999085001461241
45.595373880247585,0.04569153830766154,231.75297225927469,357.7985767449866,-2.999085001461241
45.69119099783562,0.045787557511502305,231.86192044532885,357.7985767449866,-2.999085001461241
46.1702765857758,0.04626765353070614,232.40533052704973,357.7985767449866,-2.999085001461241
46.38107424446949,0.04647889577915583,232.64373381742047,357.7985767449866,-2.999085001461241
46.611035326680785,0.04670934186837368,232.90332870813359,357.7985767449866,-2.999085001461241
47.49255280849072,0.04759271854370874,233.89384927392604,357.7985767449866,-2.999085001461241
47.62669677311398,0.04772714542908582,234.04394974996163,357.7985767449866,-2.999085001461241
48.14410920808938,0.04824564912982597,234.62137080709073,357.7985767449866,-2.999085001461241
48.316580019747846,0.048418483696739345,234.8133060062769,357.7985767449866,-2.999085001461241
48.7190119136176,0.04882176435287057,235.26011868689122,357.7985767449866,-2.999085001461241
49.083116960452145,0.04918663732746549,235.66313900187137,357.7985767449866,-2.999085001461241
49.236424348593005,0.04934026805361072,235.83248275349382,357.7985767449866,-2.999085001461241
50.06045155985013,0.05016603320664133,236.73920634037626,357.7985767449866,-2.999085001461241
50.86531534758964,0.05097259451890378,237.61924067549683,357.7985767449866,-2.999085001461241
50.96113246517768,0.051068613722744544,237.72364369059753,357.7985767449866,-2.999085001461241
51.11443985331854,0.05122224444888977,237.89052941869122,357.7985767449866,-2.999085001461241
51.51687174718831,0.05162552510502101,238.32767830742836,357.7985767449866,-2.999085001461241
51.86181337050524,0.05197119423884777,238.70131841110722,357.7985767449866,-2.999085001461241
52.072611029198924,0.052182436487297465,238.92917694997334,357.7985767449866,-2.999085001461241
52.18759157030456,0.052297659531906376,239.05331179073676,357.7985767449866,-2.999085001461241
52.475042923068685,0.05258571714342869,239.36318315218924,357.7985767449866,-2.999085001461241
52.72416742879758,0.052835367073414685,239.63120323603346,357.7985767449866,-2.999085001461241
53.14576274618495,0.05325785157031407,240.0836532565081,357.7985767449866,-2.999085001461241
53.241579863772984,0.053353870774154835,240.1862873344258,357.7985767449866,-2.999085001461241
53.68233860467795,0.053795559111822364,240.65747936723005,357.7985767449866,-2.999085001461241
54.084770498547705,0.05419883976795359,241.08638213085234,357.7985767449866,-2.999085001461241
54.27640473372378,0.05439087817563512,241.29018392863495,357.7985767449866,-2.999085001461241
54.62134635704072,0.0547365473094619,241.65632138244658,357.7985767449866,-2.999085001461241
55.23457590960417,0.05535107021404281,242.30501358780074,357.7985767449866,-2.999085001461241
55.598680956438706,0.055715943188637734,242.68884571315715,357.7985767449866,-2.999085001461241
55.828642038649996,0.05594638927785557,242.9307609845359,357.7985767449866,-2.999085001461241
56.82514006156559,0.05694498899779957,243.97460160833012,357.7985767449866,-2.999085001461241
56.920957179153625,0.057041008201640334,244.07459318789492,357.7985767449866,-2.999085001461241
57.18924510840012,0.057309861972394474,244.3542209846149,357.7985767449866,-2.999085001461241
57.380879343576204,0.05750190038007602,244.55364199082004,357.7985767449866,-2.999085001461241
57.66833069634031,0.05778995799159832,244.85228717612233,357.7985767449866,-2.999085001461241
58.01327231965725,0.05813562712542508,245.20989615228163,357.7985767449866,-2.999085001461241
58.10908943724528,0.05823164632926585,245.30908468802951,357.7985767449866,-2.999085001461241
58.68399214277351,0.05880776155231046,245.9028819123988,357.7985767449866,-2.999085001461241
58.79897268387916,0.05892298459691939,246.02136864166968,357.7985767449866,-2.999085001461241
59.27805827181934,0.05940308061612322,246.5140938396709,357.7985767449866,-2.999085001461241
60.06375863604125,0.06019043808761752,247.3188143291559,357.7985767449866,-2.999085001461241
60.562007647499044,0.060689737947589514,247.82699836472966,357.7985767449866,-2.999085001461241
60.964439541368804,0.06109301860372074,248.23626538160215,357.7985767449866,-2.999085001461241
61.462688552826606,0.061592318463692744,248.74152005967312,357.7985767449866,-2.999085001461241
61.750139905590714,0.06188037607521504,249.0322865099164,357.7985767449866,-2.999085001461241
62.305879187601334,0.0624372874574915,249.59294249283684,357.7985767449866,-2.999085001461241
62.84245504609435,0.0629749949989998,250.132417845468,357.7985767449866,-2.999085001461241
63.01492585775281,0.06314782956591318,250.3054387298797,357.7985767449866,-2.999085001461241
63.16823324589367,0.06330146029205841,250.45908008675056,357.7985767449866,-2.999085001461241
64.12640442177404,0.06426165233046609,251.4160646194012,357.7985767449866,-2.999085001461241
64.64381685674945,0.06478015603120624,251.93051679577118,357.7985767449866,-2.999085001461241
64.91210478599595,0.06504900980196039,252.19663740125094,357.7985767449866,-2.999085001461241
65.0270853271016,0.06516423284656932,252.3105577363987,357.7985767449866,-2.999085001461241
65.87027596187633,0.06600920184036807,253.14358629475757,357.7985767449866,-2.999085001461241
66.02358335001719,0.0661628325665133,253.29459816589917,357.7985767449866,-2.999085001461241
66.19605416167566,0.06633566713342669,253.46432315305537,357.7985767449866,-2.999085001461241
66.94342767886236,0.06708461692338469,254.19781417212693,357.7985767449866,-2.999085001461241
67.34585957273212,0.06748789757951591,254.5914477582789,357.7985767449866,-2.999085001461241
67.76745489011947,0.06791038207641528,255.0028431463559,357.7985767449866,-2.999085001461241
68.53399183082378,0.06867853570714143,255.7482865641906,357.7985767449866,-2.999085001461241
68.5914821013766,0.06873614722944589,255.8040633931408,357.7985767449866,-2.999085001461241
69.14722138338722,0.06929305861172234,256.3423027288989,357.7985767449866,-2.999085001461241
69.3580190420809,0.06950430086017204,256.5460208159554,357.7985767449866,-2.999085001461241
69.68379724188023,0.06983076615323065,256.86038354602596,357.7985767449866,-2.999085001461241
70.33535364147889,0.07048369673934787,257.4873947464265,357.7985767449866,-2.999085001461241
70.71862211183104,0.07086777355471095,257.85516672779363,357.7985767449866,-2.999085001461241
70.79527580590147,0.07094458891778356,257.9286277538328,357.7985767449866,-2.999085001461241
71.3701785114297,0.07152070414082817,258.4786000835933,357.7985767449866,-2.999085001461241
71.58097617012338,0.07173194638927786,258.67982335884545,357.7985767449866,-2.999085001461241
72.02173491102835,0.0721736347269454,259.09981767200316,357.7985767449866,-2.999085001461241
72.44333022841572,0.07259611922384478,259.50061437638135,357.7985767449866,-2.999085001461241
72.84576212228548,0.072999399879976,259.8823453105842,357.7985767449866,-2.999085001461241
72.99906951042634,0.07315303060612123,260.0275501720916,357.7985767449866,-2.999085001461241
73.1907037456024,0.07334506901380276,260.208889112553,357.7985767449866,-2.999085001461241
74.45548969776449,0.0746125225045009,261.401115608257,357.7985767449866,-2.999085001461241
74.74294105052861,0.07490058011602321,261.6709715461324,357.7985767449866,-2.999085001461241
74.9537387092223,0.0751118223644729,261.8686087272769,357.7985767449866,-2.999085001461241
75.16453636791597,0.07532306461292258,262.0660292536423,357.7985767449866,-2.999085001461241
75.83525619103224,0.07599519903980796,262.69275375764283,357.7985767449866,-2.999085001461241
76.33350520249004,0.07649449889977997,263.1569220337597,357.7985767449866,-2.999085001461241
76.52513943766611,0.0766865373074615,263.3351334795087,357.7985767449866,-2.999085001461241
76.96589817857108,0.07712822564512903,263.7443606063774,357.7985767449866,-2.999085001461241
77.2533495313352,0.07741628325665134,264.01075555322416,357.7985767449866,-2.999085001461241
77.34916664892324,0.07751230246049211,264.09946792599317,357.7985767449866,-2.999085001461241
77.5024740370641,0.07766593318663734,264.24131862904653,357.7985767449866,-2.999085001461241
77.96239620148668,0.07812682536507302,264.66621559882617,357.7985767449866,-2.999085001461241
78.36482809535644,0.07853010602120425,265.03719917875037,357.7985767449866,-2.999085001461241
78.46064521294447,0.07862612522504502,265.1254190004726,357.7985767449866,-2.999085001461241
78.97805764791988,0.07914462892578517,265.60108196182074,357.7985767449866,-2.999085001461241
79.24634557716638,0.0794134826965393,265.8472434621091,357.7985767449866,-2.999085001461241
79.68710431807135,0.07985517103420685,266.25094722756836,357.7985767449866,-2.999085001461241
79.802084859177,0.07997039407881577,266.3561179159976,357.7985767449866,-2.999085001461241
80.01288251787068,0.08018163632726545,266.5487774836126,357.7985767449866,-2.999085001461241
80.18535332952915,0.08035447089417884,266.7062608443085,357.7985767449866,-2.999085001461241
80.41531441174044,0.08058491698339669,266.91603331572304,357.7985767449866,-2.999085001461241
80.74109261153977,0.0809113822764553,267.2128109444858,357.7985767449866,-2.999085001461241
80.79858288209259,0.08096899379875976,267.26513495241835,357.7985767449866,-2.999085001461241
81.14352450540952,0.08131466293258652,267.5787746308455,357.7985767449866,-2.999085001461241
81.46930270520885,0.08164112822564513,267.8745127729201,357.7985767449866,-2.999085001461241
81.69926378742014,0.08187157431486297,268.0829914887572,357.7985767449866,-2.999085001461241
82.3508201870188,0.0825245049009802,268.6724420035088,357.7985767449866,-2.999085001461241
82.94488631606463,0.08311982396479296,269.20829889534394,357.7985767449866,-2.999085001461241
83.17484739827592,0.0833502700540108,269.41532526975203,357.7985767449866,-2.999085001461241
84.22883569174434,0.08440648129625926,270.3613544339888,357.7985767449866,-2.999085001461241
84.9187189383782,0.08509781956391278,270.97807460748135,357.7985767449866,-2.999085001461241
85.22533371465993,0.08540508101620324,271.2515449295626,357.7985767449866,-2.999085001461241
85.57027533797687,0.08575075015003002,271.55874080840874,357.7985767449866,-2.999085001461241
86.14517804350508,0.08632686537307462,272.0696628860397,357.7985767449866,-2.999085001461241
86.27932200812835,0.0864612922584517,272.1886864901605,357.7985767449866,-2.999085001461241
86.68175390199809,0.08686457291458292,272.5453250301344,357.7985767449866,-2.999085001461241
87.06502237235024,0.08724864972994599,272.88438091411695,357.7985767449866,-2.999085001461241
87.33331030159675,0.08751750350070014,273.12137376970793,357.7985767449866,-2.999085001461241
87.48661768973761,0.08767113422684537,273.25667077542727,357.7985767449866,-2.999085001461241
87.73574219546651,0.08792078415683137,273.476331367754,357.7985767449866,-2.999085001461241
88.50227913617081,0.08868893778755751,274.1506893770441,357.7985767449866,-2.999085001461241
88.90471103004056,0.08909221844368874,274.50381525612687,357.7985767449866,-2.999085001461241
89.17299895928707,0.0893610722144429,274.7388862421586,357.7985767449866,-2.999085001461241
89.2496526533575,0.0894378875775155,274.80599869878074,357.7985767449866,-2.999085001461241
90.16949698220266,0.09035967193438688,275.6096026669289,357.7985767449866,-2.999085001461241
90.5336020290372,0.0907245449089818,275.9268118924077,357.7985767449866,-2.999085001461241
91.62591716954084,0.09181916383276656,276.8754677012247,357.7985767449866,-2.999085001461241
92.08583933396342,0.09228005601120225,277.2735810234874,357.7985767449866,-2.999085001461241
92.5649249219036,0.09276015203040608,277.68745867266796,357.7985767449866,-2.999085001461241
92.7948860041149,0.09299059811962393,277.8858231327979,357.7985767449866,-2.999085001461241
93.21648132150226,0.09341308261652331,278.24899409503206,357.7985767449866,-2.999085001461241
93.96385483868895,0.0941620324064813,278.8912267429787,357.7985767449866,-2.999085001461241
94.1171622268298,0.09431566313262653,279.02272019003067,357.7985767449866,-2.999085001461241
94.78788204994608,0.09498779755951191,279.597024646242,357.7985767449866,-2.999085001461241
94.94118943808694,0.09514142828565714,279.72807144984426,357.7985767449866,-2.999085001461241
95.49692872009756,0.09569833966793359,280.20242587008744,357.7985767449866,-2.999085001461241
95.70772637879124,0.09590958191638328,280.3820716280038,357.7985767449866,-2.999085001461241
96.110158272661,0.09631286257251451,280.72460378784655,357.7985767449866,-2.999085001461241
96.43593647246033,0.09663932786557312,281.0014822209378,357.7985767449866,-2.999085001461241
96.68506097818923,0.09688897779555912,281.2129667233402,357.7985767449866,-2.999085001461241
97.1258197190942,0.09733066613322665,281.5866117379469,357.7985767449866,-2.999085001461241
97.79653954221045,0.09800280056011203,282.1539356583506,357.7985767449866,-2.999085001461241
98.79303756512604,0.09900140028005601,282.9940229110561,357.7985767449866,-2.999085001461241
98.96550837678451,0.0991742348469694,283.13908650114354,357.7985767449866,-2.999085001461241
99.4637573882423,0.09967353470694139,283.5576062885031,357.7985767449866,-2.999085001461241
99.63622819990077,0.09984636927385478,283.70228791861365,357.7985767449866,-2.999085001461241