File: datasets/aisi_316_L/data/M1/train_51.csv
Time(s),Strain(%),Stress(MPa),Temp(C),Log_SR(s-1)
0.0,0.0,0.0,387.89224210010065,2.4306842635191277
3.561122960646385e-08,9.6e-06,1.6348108499999998,387.89224210010065,2.4306842635191277
6.528725427851706e-08,1.76e-05,2.9971532250000004,387.89224210010065,2.4306842635191277
9.793088141777559e-08,2.6399999999999998e-05,4.4957298375,387.89224210010065,2.4306842635191277
1.3057450855703412e-07,3.52e-05,5.994306450000001,387.89224210010065,2.4306842635191277
1.6321813569629265e-07,4.4e-05,7.4928830625,387.89224210010065,2.4306842635191277
2.017969677699618e-07,5.4399999999999994e-05,9.263928149999998,387.89224210010065,2.4306842635191277
3.0566305412214804e-07,8.24e-05,14.032126462499999,387.89224210010065,2.4306842635191277
4.599783824168248e-07,0.000124,21.1163068125,387.89224210010065,2.4306842635191277
4.80751599687262e-07,0.0001296,22.069946475000002,387.89224210010065,2.4306842635191277
5.252656366953418e-07,0.0001416,24.1134600375,387.89224210010065,2.4306842635191277
5.964880959082696e-07,0.0001608,27.3830817375,387.89224210010065,2.4306842635191277
8.309286908174899e-07,0.000224,38.1455865,387.89224210010065,2.4306842635191277
8.427991006863111e-07,0.0002272,38.69052345,387.89224210010065,2.4306842635191277
9.051187524976229e-07,0.000244,41.5514424375,387.89224210010065,2.4306842635191277
9.466651870384973e-07,0.00025519999999999997,43.4587217625,387.89224210010065,2.4306842635191277
9.644708018417291e-07,0.00026,44.276127187499995,387.89224210010065,2.4306842635191277
1.0178876462514251e-06,0.0002744,46.7283434625,387.89224210010065,2.4306842635191277
1.0505312733906836e-06,0.0002832,48.226920075,387.89224210010065,2.4306842635191277
1.0920777079315582e-06,0.0002944,50.1341994,387.89224210010065,2.4306842635191277
1.2048466016853602e-06,0.0003248,55.311100425,387.89224210010065,2.4306842635191277
1.2345226263574133e-06,0.00033279999999999996,56.67344279999999,387.89224210010065,2.4306842635191277
1.3650971349144477e-06,0.000368,62.66774925,387.89224210010065,2.4306842635191277
1.4748984262010444e-06,0.00039759999999999996,67.70841603749999,387.89224210010065,2.4306842635191277
1.5223800656763296e-06,0.0004104,69.8881638375,387.89224210010065,2.4306842635191277
1.5490884878811775e-06,0.00041759999999999996,71.114271975,387.89224210010065,2.4306842635191277
1.5906349224220519e-06,0.00042879999999999996,73.0215513,387.89224210010065,2.4306842635191277
1.6292137544957213e-06,0.0004392,74.7925963875,387.89224210010065,2.4306842635191277
1.8191403123968618e-06,0.0004904,83.5115875875,387.89224210010065,2.4306842635191277
1.8666219518721468e-06,0.0005032,85.69133538749999,387.89224210010065,2.4306842635191277
1.9052007839458162e-06,0.0005136,87.462380475,387.89224210010065,2.4306842635191277
1.9289416036834583e-06,0.00052,88.55225437499999,387.89224210010065,2.4306842635191277
2.0120344727652075e-06,0.0005424,92.366813025,387.89224210010065,2.4306842635191277
2.083256931978135e-06,0.0005616,95.636434725,387.89224210010065,2.4306842635191277
2.1129329566501882e-06,0.0005696,96.9987771,387.89224210010065,2.4306842635191277
2.127770968986215e-06,0.0005736,97.6799482875,387.89224210010065,2.4306842635191277
2.2524102726088386e-06,0.0006072,103.4017862625,387.89224210010065,2.4306842635191277
2.3117623219529447e-06,0.0006232,106.12647101249999,387.89224210010065,2.4306842635191277
2.3800171786986674e-06,0.0006416,109.259858475,387.89224210010065,2.4306842635191277
2.3978227935018993e-06,0.0006464,110.0772639,387.89224210010065,2.4306842635191277
2.406725600903515e-06,0.0006487999999999999,110.4859666125,387.89224210010065,2.4306842635191277
2.6589718106159673e-06,0.0007168,122.0658768,387.89224210010065,2.4306842635191277
2.7361294747633058e-06,0.0007375999999999999,125.60796697499998,387.89224210010065,2.4306842635191277
2.8073519339762334e-06,0.0007568,128.877588675,387.89224210010065,2.4306842635191277
2.851865970984313e-06,0.0007687999999999999,130.92110223749998,387.89224210010065,2.4306842635191277
2.881541995656367e-06,0.0007768,132.2834446125,387.89224210010065,2.4306842635191277
2.91121802032842e-06,0.0007848,133.6457869875,387.89224210010065,2.4306842635191277
2.931991237598857e-06,0.0007903999999999999,134.59942665,387.89224210010065,2.4306842635191277
2.997278491877374e-06,0.000808,137.596579875,387.89224210010065,2.4306842635191277
3.05069533628707e-06,0.0008223999999999999,140.04879615,387.89224210010065,2.4306842635191277
3.09520937329515e-06,0.0008344,142.0923097125,387.89224210010065,2.4306842635191277
3.142691012770435e-06,0.0008472,144.2720575125,387.89224210010065,2.4306842635191277
3.1693994349752826e-06,0.0008544,145.49816565,387.89224210010065,2.4306842635191277
3.302941545999522e-06,0.0008904,151.6287063375,387.89224210010065,2.4306842635191277
3.3237147632699595e-06,0.000896,152.582346,387.89224210010065,2.4306842635191277
3.478030091564636e-06,0.0009375999999999999,159.66652635,387.89224210010065,2.4306842635191277
3.6501510346625444e-06,0.0009839999999999998,167.56811212499997,387.89224210010065,2.4306842635191277
3.676859456867393e-06,0.0009912,168.34026074703212,387.89224210010065,2.4306842635191277
3.700600276605035e-06,0.0009976,168.37537777007202,387.89224210010065,2.4306842635191277
3.807433965424427e-06,0.0010264,168.5323295265907,387.89224210010065,2.4306842635191277
3.851948002432506e-06,0.0010383999999999999,168.59721806624805,387.89224210010065,2.4306842635191277
3.866786014768533e-06,0.0010424,168.6187825045146,387.89224210010065,2.4306842635191277
3.97065210112072e-06,0.0010704,168.76884010497793,387.89224210010065,2.4306842635191277
3.9765873060551305e-06,0.001072,168.777368290352,387.89224210010065,2.4306842635191277
4.068582982538495e-06,0.0010968,168.9089268320018,387.89224210010065,2.4306842635191277
4.098259007210548e-06,0.0011048,168.95111691388396,387.89224210010065,2.4306842635191277
4.1516758516202434e-06,0.0011191999999999999,169.02676003106592,387.89224210010065,2.4306842635191277
4.172449068890681e-06,0.0011248,169.05607417422738,387.89224210010065,2.4306842635191277
4.193222286161118e-06,0.0011304,169.08533145368935,387.89224210010065,2.4306842635191277
4.208060298497145e-06,0.0011344,169.10619491281622,387.89224210010065,2.4306842635191277
4.234768720701993e-06,0.0011416,169.143676981678,387.89224210010065,2.4306842635191277
4.261477142906841e-06,0.0011488,169.18106696824682,387.89224210010065,2.4306842635191277
4.350505216923e-06,0.0011727999999999999,169.30504541662535,387.89224210010065,2.4306842635191277
4.4039220613326965e-06,0.0011872,169.37895761461448,387.89224210010065,2.4306842635191277
4.4335980860047496e-06,0.0011952,169.41986884582985,387.89224210010065,2.4306842635191277
4.478112123012829e-06,0.0012071999999999999,169.48103601703843,387.89224210010065,2.4306842635191277
4.507788147684883e-06,0.0012152,169.5216824441142,387.89224210010065,2.4306842635191277
4.564172594561783e-06,0.0012304,169.5986242957047,387.89224210010065,2.4306842635191277
4.614621836504273e-06,0.0012439999999999999,169.66715334006878,387.89224210010065,2.4306842635191277
4.641330258709122e-06,0.0012511999999999998,169.7033151015813,387.89224210010065,2.4306842635191277
4.697714705586023e-06,0.0012664,169.7793911662993,387.89224210010065,2.4306842635191277
4.774872369733361e-06,0.0012871999999999998,169.8829206778021,387.89224210010065,2.4306842635191277
4.923252493093627e-06,0.0013272,170.08020016452784,387.89224210010065,2.4306842635191277
5.027118579445814e-06,0.0013552,170.21691825116005,387.89224210010065,2.4306842635191277
5.0449241942490455e-06,0.0013599999999999999,170.2402445853785,387.89224210010065,2.4306842635191277
5.080535423855509e-06,0.0013696,170.28680115255065,387.89224210010065,2.4306842635191277
5.175498702806079e-06,0.0013951999999999999,170.41033396356488,387.89224210010065,2.4306842635191277
5.267494379289445e-06,0.00142,170.52916611570774,387.89224210010065,2.4306842635191277
5.291235199027087e-06,0.0014264,170.55970074170978,387.89224210010065,2.4306842635191277
5.317943621231935e-06,0.0014336,170.59398840096782,387.89224210010065,2.4306842635191277
5.3535548508383985e-06,0.0014432,170.63960099212258,387.89224210010065,2.4306842635191277
5.398068887846479e-06,0.0014552,170.6964506714199,387.89224210010065,2.4306842635191277
5.406971695248095e-06,0.0014575999999999999,170.7077986355473,387.89224210010065,2.4306842635191277
5.445550527321764e-06,0.001468,170.75688918028433,387.89224210010065,2.4306842635191277
5.5612870235427716e-06,0.0014992,170.90335339191324,387.89224210010065,2.4306842635191277
5.682958724698189e-06,0.001532,171.05605253256041,387.89224210010065,2.4306842635191277
5.694829134567011e-06,0.0015352,171.07088141592857,387.89224210010065,2.4306842635191277
5.739343171575091e-06,0.0015471999999999999,171.12638269321377,387.89224210010065,2.4306842635191277
5.751213581443912e-06,0.0015504,171.1411546485177,387.89224210010065,2.4306842635191277
5.852112065328893e-06,0.0015776,171.26623977914113,387.89224210010065,2.4306842635191277
5.866950077664919e-06,0.0015815999999999998,171.28456346437304,387.89224210010065,2.4306842635191277
5.887723294935357e-06,0.0015872,171.3101862894482,387.89224210010065,2.4306842635191277
5.973783766484311e-06,0.0016104,171.41596456517217,387.89224210010065,2.4306842635191277
5.988621778820338e-06,0.0016144,171.43414196713886,387.89224210010065,2.4306842635191277
6.086552660238113e-06,0.0016408,171.55367530843625,387.89224210010065,2.4306842635191277
6.125131492311783e-06,0.0016512,171.60055796840774,387.89224210010065,2.4306842635191277
6.199321553991915e-06,0.0016711999999999999,171.69039450802566,387.89224210010065,2.4306842635191277
6.252738398401611e-06,0.0016856,171.75481738683516,387.89224210010065,2.4306842635191277
6.300220037876896e-06,0.0016983999999999999,171.81190219401822,387.89224210010065,2.4306842635191277
6.353636882286592e-06,0.0017128,171.87592242483115,387.89224210010065,2.4306842635191277
6.377377702024234e-06,0.0017192,171.9043084456645,387.89224210010065,2.4306842635191277
6.51388741551568e-06,0.001756,172.06673534019507,387.89224210010065,2.4306842635191277
6.561369054990964e-06,0.0017687999999999998,172.1229197580799,387.89224210010065,2.4306842635191277
6.6147858994006605e-06,0.0017832,172.18593803573404,387.89224210010065,2.4306842635191277
6.65336473147433e-06,0.0017936,172.23132787036477,387.89224210010065,2.4306842635191277
6.721619588220052e-06,0.001812,172.31138231479798,387.89224210010065,2.4306842635191277
6.786906842498569e-06,0.0018296,172.38765999142743,387.89224210010065,2.4306842635191277
6.819550469637827e-06,0.0018384,172.4256914784087,387.89224210010065,2.4306842635191277
6.867032109113113e-06,0.0018512,172.4808835081708,387.89224210010065,2.4306842635191277
6.902643338719577e-06,0.0018608,172.52217991196775,387.89224210010065,2.4306842635191277
6.9530925806620665e-06,0.0018743999999999998,172.58054120003027,387.89224210010065,2.4306842635191277
7.021347437407789e-06,0.0018927999999999998,172.65923840724568,387.89224210010065,2.4306842635191277
7.095537499087922e-06,0.0019127999999999999,172.74444121390303,387.89224210010065,2.4306842635191277
7.160824753366439e-06,0.0019303999999999999,172.8191326950921,387.89224210010065,2.4306842635191277
7.2112739953089295e-06,0.001944,172.8766670833312,387.89224210010065,2.4306842635191277
7.2261120076449565e-06,0.0019479999999999999,172.8935590600453,387.89224210010065,2.4306842635191277
7.276561249587447e-06,0.0019616,172.95089086591693,387.89224210010065,2.4306842635191277
7.288431659456269e-06,0.0019648,172.96435814868616,387.89224210010065,2.4306842635191277
7.368556926070811e-06,0.0019863999999999997,173.05503959834954,387.89224210010065,2.4306842635191277
7.419006168013303e-06,0.002,173.1119380790129,387.89224210010065,2.4306842635191277
7.4457145902181494e-06,0.0020071999999999998,173.14199970529302,387.89224210010065,2.4306842635191277
7.478358217357409e-06,0.002016,173.17868464187856,387.89224210010065,2.4306842635191277
7.499131434627845e-06,0.0020215999999999997,173.2019970890144,387.89224210010065,2.4306842635191277
7.647511557988112e-06,0.0020616,173.367788240572,387.89224210010065,2.4306842635191277
7.68015518512737e-06,0.0020704,173.40409338541284,387.89224210010065,2.4306842635191277
7.721701619668244e-06,0.0020816,173.45021301274306,387.89224210010065,2.4306842635191277
7.742474836938683e-06,0.0020872,173.47323652784237,387.89224210010065,2.4306842635191277
7.81369729615161e-06,0.0021064,173.55199204096266,387.89224210010065,2.4306842635191277
7.94723940717585e-06,0.0021424,173.6989081138378,387.89224210010065,2.4306842635191277
8.065943505864062e-06,0.0021744,173.82869380918623,387.89224210010065,2.4306842635191277
8.101554735470525e-06,0.0021839999999999997,173.86748398120534,387.89224210010065,2.4306842635191277
8.154971579880222e-06,0.0021984,173.9255447892298,387.89224210010065,2.4306842635191277
8.241032051429176e-06,0.0022216,174.01877619367548,387.89224210010065,2.4306842635191277
8.285546088437256e-06,0.0022336,174.06685029410883,387.89224210010065,2.4306842635191277
8.324124920510925e-06,0.002244,174.108433094353,387.89224210010065,2.4306842635191277
8.356768547650184e-06,0.0022528,174.14355986902413,387.89224210010065,2.4306842635191277
8.413152994527085e-06,0.002268,174.20410760554248,387.89224210010065,2.4306842635191277
8.442829019199138e-06,0.002276,174.23591125869058,387.89224210010065,2.4306842635191277
8.46656983893678e-06,0.0022824,174.26132280239906,387.89224210010065,2.4306842635191277
8.478440248805602e-06,0.0022856,174.274018152035,387.89224210010065,2.4306842635191277
8.49921346607604e-06,0.0022911999999999997,174.29621834640267,387.89224210010065,2.4306842635191277
8.54372750308412e-06,0.0023032,174.34371905912985,387.89224210010065,2.4306842635191277
8.579338732690582e-06,0.0023128,174.3816501721358,387.89224210010065,2.4306842635191277
8.60011194996102e-06,0.0023184,174.40374829840113,387.89224210010065,2.4306842635191277
8.641658384501895e-06,0.0023296,174.4478821986984,387.89224210010065,2.4306842635191277
8.671334409173948e-06,0.0023376,174.4793557643663,387.89224210010065,2.4306842635191277
8.778168097993339e-06,0.0023664,174.59231442965105,387.89224210010065,2.4306842635191277
8.822682135001417e-06,0.0023783999999999997,174.6392221532407,387.89224210010065,2.4306842635191277
8.852358159673471e-06,0.0023864,174.67044270108167,387.89224210010065,2.4306842635191277
8.944353836156838e-06,0.0024112,174.76696801017115,387.89224210010065,2.4306842635191277
9.057122729910639e-06,0.0024416,174.8847627604528,387.89224210010065,2.4306842635191277
9.16989162366444e-06,0.002472,175.00198688811423,387.89224210010065,2.4306842635191277
9.211438058205316e-06,0.0024832,175.04503282904773,387.89224210010065,2.4306842635191277
9.232211275475753e-06,0.0024887999999999998,175.0665274002433,387.89224210010065,2.4306842635191277
9.333109759360734e-06,0.002516,175.17066248745923,387.89224210010065,2.4306842635191277
9.39246180870484e-06,0.002532,175.23171333218957,387.89224210010065,2.4306842635191277
9.469619472852179e-06,0.0025528,175.31085496856193,387.89224210010065,2.4306842635191277
9.549744739466722e-06,0.0025743999999999997,175.3927747891201,387.89224210010065,2.4306842635191277
9.597226378942008e-06,0.0025872,175.4411933817471,387.89224210010065,2.4306842635191277
9.727800887499042e-06,0.0026224,175.5738651729985,387.89224210010065,2.4306842635191277
9.772314924507122e-06,0.0026344,175.61893521149318,387.89224210010065,2.4306842635191277
9.822764166449611e-06,0.0026479999999999997,175.66991790933466,387.89224210010065,2.4306842635191277
9.858375396056076e-06,0.0026576,175.70584423069675,387.89224210010065,2.4306842635191277
9.893986625662539e-06,0.0026671999999999998,175.7417199749239,387.89224210010065,2.4306842635191277
9.956306277473851e-06,0.0026839999999999998,175.8043815854265,387.89224210010065,2.4306842635191277
9.983014699678699e-06,0.0026912,175.83118971460266,387.89224210010065,2.4306842635191277
1.0006755519416342e-05,0.0026976,175.8549956893957,387.89224210010065,2.4306842635191277
1.0158103245243813e-05,0.0027383999999999998,176.00624424448173,387.89224210010065,2.4306842635191277
1.0196682077317483e-05,0.0027488,176.04465691647505,387.89224210010065,2.4306842635191277
1.0279774946399231e-05,0.0027711999999999997,176.12719992040152,387.89224210010065,2.4306842635191277
1.0353965008079365e-05,0.0027911999999999998,176.200679402085,387.89224210010065,2.4306842635191277
1.039551144262024e-05,0.0028024,176.24173821387006,387.89224210010065,2.4306842635191277
1.0437057877161114e-05,0.0028136,176.28273307840885,387.89224210010065,2.4306842635191277
1.0567632385718148e-05,0.0028488,176.41116169746982,387.89224210010065,2.4306842635191277
1.0647757652332691e-05,0.0028704,176.4896638193456,387.89224210010065,2.4306842635191277
1.0713044906611208e-05,0.002888,176.55345830886122,387.89224210010065,2.4306842635191277
1.0796137775692959e-05,0.0029104,176.63443243364486,387.89224210010065,2.4306842635191277
1.0885165849709117e-05,0.0029343999999999998,176.72092117630228,387.89224210010065,2.4306842635191277
1.0935615091651606e-05,0.0029479999999999997,176.76980899814683,387.89224210010065,2.4306842635191277
1.0941550296586017e-05,0.0029495999999999997,176.77555471815631,387.89224210010065,2.4306842635191277
1.095935591138925e-05,0.0029544,176.79278458943372,387.89224210010065,2.4306842635191277
1.1030578370602177e-05,0.0029736,176.86159518074706,387.89224210010065,2.4306842635191277
1.1078060010077461e-05,0.0029863999999999997,176.90737266848274,387.89224210010065,2.4306842635191277
1.1152250071757595e-05,0.0030064,176.97874710005414,387.89224210010065,2.4306842635191277
1.1202699313700086e-05,0.0030199999999999997,177.02717597182826,387.89224210010065,2.4306842635191277
1.1276889375380218e-05,0.0030399999999999997,177.09824067481472,387.89224210010065,2.4306842635191277
1.1359982244461968e-05,0.0030624,177.17761702593984,387.89224210010065,2.4306842635191277
1.13777878592652e-05,0.0030672,177.19459674790284,387.89224210010065,2.4306842635191277
1.1404496281470048e-05,0.0030743999999999997,177.2200469127791,387.89224210010065,2.4306842635191277
1.156177921223193e-05,0.0031168,177.36945130235011,387.89224210010065,2.4306842635191277
1.1695321323256169e-05,0.0031528,177.49568290757162,387.89224210010065,2.4306842635191277
1.1713126938059401e-05,0.0031576,177.51247121521567,387.89224210010065,2.4306842635191277
1.1754673372600275e-05,0.0031688,177.5516052745094,387.89224210010065,2.4306842635191277
1.1876345073755694e-05,0.0032015999999999998,177.6659030335354,387.89224210010065,2.4306842635191277
1.1971308352706264e-05,0.0032272,177.7547940282825,387.89224210010065,2.4306842635191277
1.1989113967509497e-05,0.003232,177.77143043001806,387.89224210010065,2.4306842635191277
1.2081109643992861e-05,0.0032568,177.8572321488822,387.89224210010065,2.4306842635191277
1.225916579202518e-05,0.0033047999999999997,178.02257955242686,387.89224210010065,2.4306842635191277
1.2368967083311778e-05,0.0033344,178.12407701697427,387.89224210010065,2.4306842635191277
1.2466897964729552e-05,0.0033607999999999997,178.21430569537097,387.89224210010065,2.4306842635191277
1.2511412001737634e-05,0.0033728,178.25522731024336,387.89224210010065,2.4306842635191277
1.2541088026409686e-05,0.0033807999999999998,178.28247684596107,387.89224210010065,2.4306842635191277
1.2650889317696283e-05,0.0034103999999999996,178.38308221514134,387.89224210010065,2.4306842635191277
1.2769593416384497e-05,0.0034424,178.49146246235702,387.89224210010065,2.4306842635191277
1.2876427105203887e-05,0.0034712,178.58866919757878,387.89224210010065,2.4306842635191277
1.2888297515072709e-05,0.0034744,178.5994504948899,387.89224210010065,2.4306842635191277
1.2932811552080787e-05,0.0034863999999999997,178.6398459157859,387.89224210010065,2.4306842635191277
1.302777483103136e-05,0.003512,178.72584202826044,387.89224210010065,2.4306842635191277
1.3069321265572233e-05,0.0035231999999999998,178.76338841531992,387.89224210010065,2.4306842635191277
1.3140543724785161e-05,0.0035424,178.82764553221128,387.89224210010065,2.4306842635191277
1.3208798581530882e-05,0.0035608,178.88909793311691,387.89224210010065,2.4306842635191277
1.3250345016071756e-05,0.0035719999999999997,178.92644311223512,387.89224210010065,2.4306842635191277
1.3300794258014249e-05,0.0035856,178.9717294915821,387.89224210010065,2.4306842635191277
1.330672946294866e-05,0.0035872,178.97705289315803,387.89224210010065,2.4306842635191277
1.3455109586308924e-05,0.0036271999999999997,179.10983848639577,387.89224210010065,2.4306842635191277
1.3464012393710541e-05,0.0036295999999999998,179.1177874129013,387.89224210010065,2.4306842635191277
1.3499623623317006e-05,0.0036392,179.14956264170848,387.89224210010065,2.4306842635191277
1.3558975672661112e-05,0.0036552,179.20244880759012,387.89224210010065,2.4306842635191277
1.363019813187404e-05,0.0036744,179.26579317983266,387.89224210010065,2.4306842635191277
1.3668776963947707e-05,0.0036848,179.30005081082243,387.89224210010065,2.4306842635191277
1.3704388193554172e-05,0.0036944,179.3316397851849,387.89224210010065,2.4306842635191277
1.376374024289828e-05,0.0037104,179.3842170284779,387.89224210010065,2.4306842635191277
1.3873541534184875e-05,0.00374,179.48125241406655,387.89224210010065,2.4306842635191277
1.3971472415602652e-05,0.0037664,179.56754508143425,387.89224210010065,2.4306842635191277
1.4208880612979076e-05,0.0038304,179.77576613247203,387.89224210010065,2.4306842635191277
1.428900587959362e-05,0.003852,179.8457339149411,387.89224210010065,2.4306842635191277
1.4321649506732878e-05,0.0038607999999999997,179.8741954199696,387.89224210010065,2.4306842635191277
1.4458159220224324e-05,0.0038975999999999998,179.99294317340903,387.89224210010065,2.4306842635191277
1.447893243749476e-05,0.0039032,180.0109750790839,387.89224210010065,2.4306842635191277
1.4514543667101225e-05,0.0039128,180.04186346132988,387.89224210010065,2.4306842635191277
1.457983092137974e-05,0.0039304,180.0984155081333,387.89224210010065,2.4306842635191277
1.4636215368256642e-05,0.0039456,180.14717648008272,387.89224210010065,2.4306842635191277
1.4722275839805596e-05,0.0039688,180.2214601153965,387.89224210010065,2.4306842635191277
1.480240110642014e-05,0.0039904,180.29046865119727,387.89224210010065,2.4306842635191277
1.5051722455689321e-05,0.004057611522304461,180.50427262090065,387.89224210010065,2.4306842635191277
1.5977799640894424e-05,0.004307261452290458,181.28661185321988,387.89224210010065,2.4306842635191277
1.6903876826099524e-05,0.004556911382276456,182.05145349199165,387.89224210010065,2.4306842635191277
1.7758717304750386e-05,0.004787357471494299,182.74307482594932,387.89224210010065,2.4306842635191277
1.9967055207931783e-05,0.005382676535307062,184.4721605131316,387.89224210010065,2.4306842635191277
2.082189568658264e-05,0.005613122624524905,185.12123714457493,387.89224210010065,2.4306842635191277
2.1534262752125027e-05,0.005805161032206441,185.65423163448145,387.89224210010065,2.4306842635191277
2.3600127242197946e-05,0.006362072414482897,187.16233597358507,387.89224210010065,2.4306842635191277
2.687701574369292e-05,0.007245449089817963,189.45281104566942,387.89224210010065,2.4306842635191277
2.88716435272116e-05,0.007783156631326265,190.79367877113026,387.89224210010065,2.4306842635191277
3.0153904245187893e-05,0.00812882576515303,191.63661456302606,387.89224210010065,2.4306842635191277
3.0367614364850608e-05,0.008186437287457491,191.77573341800954,387.89224210010065,2.4306842635191277
3.20060586155981e-05,0.008628125625125025,192.8299102874416,387.89224210010065,2.4306842635191277
3.314584592046591e-05,0.008935387077415483,193.5508675100524,387.89224210010065,2.4306842635191277
3.35020294532371e-05,0.009031406281256251,193.7741751303728,387.89224210010065,2.4306842635191277
3.400068639911678e-05,0.009165833166633327,194.0852564799688,387.89224210010065,2.4306842635191277
3.8559835618588045e-05,0.01039487897579516,196.85137655300454,387.89224210010065,2.4306842635191277
4.0411989988998246e-05,0.010894178835767154,197.93827724577253,387.89224210010065,2.4306842635191277
4.2762801305288116e-05,0.011527905581116223,199.29021781944726,387.89224210010065,2.4306842635191277
4.447248226258984e-05,0.01198879775955191,200.25530255241185,387.89224210010065,2.4306842635191277
4.646711004610852e-05,0.012526505301060212,201.36313050622186,387.89224210010065,2.4306842635191277
4.782060747063905e-05,0.012891378275655131,202.104326850371,387.89224210010065,2.4306842635191277
4.967276184104926e-05,0.013390678135627125,203.10547029878748,387.89224210010065,2.4306842635191277
5.1168732678688264e-05,0.013793958791758352,203.90349749716847,387.89224210010065,2.4306842635191277
5.337707058186966e-05,0.014389277855571115,205.06510312656235,387.89224210010065,2.4306842635191277
5.4303147767074765e-05,0.014638927785557112,205.54663198738604,387.89224210010065,2.4306842635191277
5.53004616588341e-05,0.014907781556311263,206.06163369580682,387.89224210010065,2.4306842635191277
5.651148567025616e-05,0.015234246849369875,206.68214857715168,387.89224210010065,2.4306842635191277
5.6796432496473113e-05,0.01531106221244249,206.8273957932338,387.89224210010065,2.4306842635191277
5.8719823573437554e-05,0.015829565913182637,207.8004855742929,387.89224210010065,2.4306842635191277
5.9218480519317236e-05,0.015963992798559715,208.05072885093966,387.89224210010065,2.4306842635191277
5.964590075864265e-05,0.016079215843168633,208.2645696953032,387.89224210010065,2.4306842635191277
6.0073320997968094e-05,0.01619443888777756,208.47781374152902,387.89224210010065,2.4306842635191277
6.235289560770371e-05,0.01680896179235847,209.60527502203587,387.89224210010065,2.4306842635191277
6.349268291257154e-05,0.01711622324464893,210.16296838442847,387.89224210010065,2.4306842635191277
6.392010315189696e-05,0.01723144628925785,210.37109503557838,387.89224210010065,2.4306842635191277
6.477494363054783e-05,0.017461892378475695,210.78572715529933,387.89224210010065,2.4306842635191277
6.548731069609021e-05,0.01765393078615723,211.12962622628257,387.89224210010065,2.4306842635191277
6.584349422886141e-05,0.017749949989998,211.3010284277826,387.89224210010065,2.4306842635191277
6.726822835994618e-05,0.018134026805361074,211.9830517277951,387.89224210010065,2.4306842635191277
6.76956485992716e-05,0.018249249849969992,212.1865571009542,387.89224210010065,2.4306842635191277
6.919161943691061e-05,0.01865253050610122,212.89491292427007,387.89224210010065,2.4306842635191277
6.969027638279029e-05,0.018786957391478294,213.12970088668982,387.89224210010065,2.4306842635191277
6.990398650245301e-05,0.018844568913782757,213.23012362826663,387.89224210010065,2.4306842635191277
7.075882698110387e-05,0.0190750150030006,213.63062300769147,387.89224210010065,2.4306842635191277
7.218356111218864e-05,0.019459091818363673,214.29395381832555,387.89224210010065,2.4306842635191277
7.275345476462255e-05,0.019612722544508902,214.55785403074827,387.89224210010065,2.4306842635191277
7.325211171050221e-05,0.019747149429885976,214.78810608074838,387.89224210010065,2.4306842635191277
7.360829524327341e-05,0.019843168633726746,214.95219772644228,387.89224210010065,2.4306842635191277
7.48905559612497e-05,0.02018883776755351,215.54038077408603,387.89224210010065,2.4306842635191277
7.65290002119972e-05,0.020630526105221043,216.2862634868877,387.89224210010065,2.4306842635191277
7.759755081031077e-05,0.02091858371674335,216.76935567508747,387.89224210010065,2.4306842635191277
7.909352164794978e-05,0.021321864372874574,217.4413485865195,387.89224210010065,2.4306842635191277
8.108814943146845e-05,0.021859571914382876,218.32967831296645,387.89224210010065,2.4306842635191277
8.450751134607191e-05,0.02278135627125425,219.83295166153,387.89224210010065,2.4306842635191277
8.507740499850581e-05,0.02293498699739948,220.08117264549875,387.89224210010065,2.4306842635191277
8.571853535749397e-05,0.023107821564312864,220.35964744467208,387.89224210010065,2.4306842635191277
8.621719230337363e-05,0.023242248449689938,220.57567773938612,387.89224210010065,2.4306842635191277
8.792687326067536e-05,0.023703140628125625,221.3126815241115,387.89224210010065,2.4306842635191277
9.056263140318218e-05,0.02441368273654731,222.43803877501912,387.89224210010065,2.4306842635191277
9.127499846872456e-05,0.024605721144228845,222.73998737073748,387.89224210010065,2.4306842635191277
9.248602248014663e-05,0.024932186437287458,223.25119918344356,387.89224210010065,2.4306842635191277
9.319838954568901e-05,0.025124224844968995,223.55069256704397,387.89224210010065,2.4306842635191277
9.725888181928061e-05,0.02621884376875375,225.24105847529768,387.89224210010065,2.4306842635191277
9.832743241759419e-05,0.026506901380276057,225.6812883477991,387.89224210010065,2.4306842635191277
9.975216654867896e-05,0.02689097819563913,226.2653700526934,387.89224210010065,2.4306842635191277
0.0001001795867880044,0.02700620124024805,226.43995894788495,387.89224210010065,2.4306842635191277
0.00010238792469118578,0.027601520304060812,227.33741505523872,387.89224210010065,2.4306842635191277
0.0001035277119960536,0.02790878175635127,227.79766254285306,387.89224210010065,2.4306842635191277
0.00010915541181383845,0.029425885177035406,230.0417912876911,387.89224210010065,2.4306842635191277
0.00010958283205316387,0.029541108221644328,230.2103649950397,387.89224210010065,2.4306842635191277
0.00011022396241215203,0.029713942788557712,230.46274554849904,387.89224210010065,2.4306842635191277
0.00011086509277114017,0.029886777355471093,230.71455422678844,387.89224210010065,2.4306842635191277
0.00011243230031533342,0.030309261852370473,231.32770752429388,387.89224210010065,2.4306842635191277
0.00011449816480540634,0.03086617323464693,232.13088613751552,387.89224210010065,2.4306842635191277
0.0001147831116316233,0.030942988597719545,232.24122420688022,387.89224210010065,2.4306842635191277
0.00011556671540371992,0.031154230846169233,232.54410444710913,387.89224210010065,2.4306842635191277
0.00011642155588237076,0.031384676935387074,232.8736072451043,387.89224210010065,2.4306842635191277
0.00011706268624135893,0.03155751150230046,233.1201154789178,387.89224210010065,2.4306842635191277
0.00011855865707899794,0.031960792158431686,233.69326277886856,387.89224210010065,2.4306842635191277
0.00011905731402487762,0.03209521904380876,233.88368419783063,387.89224210010065,2.4306842635191277
0.00012076699498217933,0.03255611122224445,234.53420916028716,387.89224210010065,2.4306842635191277
0.00012126565192805902,0.03269053810762153,234.7232677635521,387.89224210010065,2.4306842635191277
0.00012240543923292682,0.032997799559911986,235.15426685748628,387.89224210010065,2.4306842635191277
0.00012311780629846922,0.03318983796759352,235.42284662223278,387.89224210010065,2.4306842635191277
0.00012383017336401158,0.03338187637527505,235.69082099893717,387.89224210010065,2.4306842635191277
0.0001255398543213133,0.03384276855371074,236.33151831751897,387.89224210010065,2.4306842635191277
0.00012632345809340993,0.03405401080216043,236.62403310707833,387.89224210010065,2.4306842635191277
0.0001270358251589523,0.034246049209841964,236.88934213528577,387.89224210010065,2.4306842635191277
0.00012796190234415743,0.034495699139827966,237.23337805481543,387.89224210010065,2.4306842635191277
0.00012924416306213374,0.034841368273654735,237.70813670803648,387.89224210010065,2.4306842635191277
0.00013088260731288122,0.035283056611322264,238.31210800918865,387.89224210010065,2.4306842635191277
0.0001317374477915321,0.035513502700540114,238.62605249871478,387.89224210010065,2.4306842635191277
0.00013394578569471348,0.03610882176435287,239.43342037598612,387.89224210010065,2.4306842635191277
0.00013430196922748465,0.03620484096819364,239.56315326075534,387.89224210010065,2.4306842635191277
0.00013943101209938982,0.0375875175035007,241.41667538307252,387.89224210010065,2.4306842635191277
0.00014057079940425765,0.03789477895579116,241.82493552664653,387.89224210010065,2.4306842635191277
0.00014128316646980002,0.03808681736347269,242.07944263186135,387.89224210010065,2.4306842635191277
0.00014185306012223393,0.03824044808961792,242.28268816217283,387.89224210010065,2.4306842635191277
0.00014299284742710176,0.03854770954190838,242.6882263873949,387.89224210010065,2.4306842635191277
0.00014334903095987293,0.038643728745749145,242.81469828797424,387.89224210010065,2.4306842635191277
0.00014384768790575263,0.03877815563112623,242.99155324726118,387.89224210010065,2.4306842635191277
0.000144560054971295,0.03897019403880776,243.24378898632125,387.89224210010065,2.4306842635191277
0.00014719581311380182,0.039680736147229445,244.17287594027917,387.89224210010065,2.4306842635191277
0.0001474807599400188,0.03975755151030207,244.27292760498514,387.89224210010065,2.4306842635191277
0.00014812189029900693,0.03993038607721544,244.4977686147332,387.89224210010065,2.4306842635191277
0.00014926167760387474,0.0402376475295059,244.89655104966806,387.89224210010065,2.4306842635191277
0.00015125630538739344,0.04077535507101421,245.59157433925714,387.89224210010065,2.4306842635191277
0.00015203990915949007,0.0409865973194639,245.8636401066064,387.89224210010065,2.4306842635191277
0.0001530372230512494,0.04125545109021804,246.20911601591368,387.89224210010065,2.4306842635191277
0.00015332216987746635,0.04133226645329066,246.30766200125953,387.89224210010065,2.4306842635191277
0.0001545331938888884,0.041658731746349265,246.72568808846538,387.89224210010065,2.4306842635191277
0.00015645658496585282,0.042177235447089415,247.3869954529922,387.89224210010065,2.4306842635191277
0.00015695524191173253,0.0423116623324665,247.55792699870366,387.89224210010065,2.4306842635191277
0.00015795255580349185,0.04258051610322064,247.89915603265814,387.89224210010065,2.4306842635191277
0.00015959100005423935,0.04302220444088818,248.4579280787415,387.89224210010065,2.4306842635191277
0.0001605883139459987,0.043291058211642336,248.796954948881,387.89224210010065,2.4306842635191277
0.0001609444974787699,0.0433870774154831,248.917836845508,387.89224210010065,2.4306842635191277
0.00016258294172951738,0.04382876575315063,249.47255526208232,387.89224210010065,2.4306842635191277
0.0001642926226868191,0.04428965793158632,250.04907241921302,387.89224210010065,2.4306842635191277
0.00016628725047033774,0.04482736547309461,250.7187268390683,387.89224210010065,2.4306842635191277
0.00016714209094898864,0.045057811562312464,251.00476178479212,387.89224210010065,2.4306842635191277
0.00016792569472108527,0.045269053810762155,251.26645968344698,387.89224210010065,2.4306842635191277
0.0001702052693308209,0.04588357671534307,252.0250681986053,387.89224210010065,2.4306842635191277
0.00017120258322258025,0.046152430486097226,252.3557123022396,387.89224210010065,2.4306842635191277
0.00017198618699467683,0.046363672734546904,252.61497740962702,387.89224210010065,2.4306842635191277
0.00017284102747332772,0.046594118823764755,252.89728721856534,387.89224210010065,2.4306842635191277
0.0001746219451371837,0.0470742148429686,253.4836896894864,387.89224210010065,2.4306842635191277
0.00017668780962725662,0.047631126225245055,254.16100244168211,387.89224210010065,2.4306842635191277
0.00017889614753043798,0.04822644528905781,254.88162000783157,387.89224210010065,2.4306842635191277
0.00018053459178118546,0.04866813362672534,255.41403195971085,387.89224210010065,2.4306842635191277
0.00018089077531395666,0.04876415283056611,255.52952394731355,387.89224210010065,2.4306842635191277
0.0001813181955532821,0.04887937587517503,255.66799732801815,387.89224210010065,2.4306842635191277
0.0001830278765105838,0.04934026805361072,256.22062253303295,387.89224210010065,2.4306842635191277
0.0001843101372285601,0.04968593718743748,256.63377121513537,387.89224210010065,2.4306842635191277
0.00018587734477275335,0.050108421684336865,257.1372115283901,387.89224210010065,2.4306842635191277
0.00018630476501207881,0.05022364472894579,257.27422577872215,387.89224210010065,2.4306842635191277
0.00018822815608904325,0.05074214842968594,257.8892791155236,387.89224210010065,2.4306842635191277
0.0001890829965676941,0.05097259451890378,258.16184887194214,387.89224210010065,2.4306842635191277
0.00019000907375289918,0.05122224444888977,258.4565910120236,387.89224210010065,2.4306842635191277
0.0001907214408184416,0.05141428285657132,258.6829346641256,387.89224210010065,2.4306842635191277
0.00019235988506918907,0.05185597119423885,259.2022775058835,387.89224210010065,2.4306842635191277
0.00019378461920027389,0.05224004800960193,259.65247924078733,387.89224210010065,2.4306842635191277
0.00019435451285270777,0.05239367873574716,259.8321982653947,387.89224210010065,2.4306842635191277
0.0001969902709952146,0.05310422084416884,260.66073994202003,387.89224210010065,2.4306842635191277
0.00019820129500663661,0.05343068613722744,261.03997054681366,387.89224210010065,2.4306842635191277
0.0001984862418328536,0.053507501500300064,261.1290698184633,387.89224210010065,2.4306842635191277
0.0001988424253656248,0.05360352070414083,261.24037378814427,387.89224210010065,2.4306842635191277
0.00020261797081299942,0.05462132426485297,262.4154546763313,387.89224210010065,2.4306842635191277
0.00020496878212928932,0.05525505101020205,263.1427963988573,387.89224210010065,2.4306842635191277
0.00020781825039145886,0.05602320464092819,264.0200754977212,387.89224210010065,2.4306842635191277
0.00020874432757666397,0.05627285457091419,264.3041794837159,387.89224210010065,2.4306842635191277
0.00020988411488153178,0.056580116023204646,264.65317202659423,387.89224210010065,2.4306842635191277
0.0002119499793716047,0.0571370274054811,265.28384288465435,387.89224210010065,2.4306842635191277
0.00021330347679613523,0.05750190038007602,265.69574157900894,387.89224210010065,2.4306842635191277
0.00021487068434032845,0.05792438487697539,266.1714056056426,387.89224210010065,2.4306842635191277
0.00021558305140587087,0.05811642328465694,266.3871690462812,387.89224210010065,2.4306842635191277
0.00021579676152553353,0.058174034806961386,266.4518438343927,387.89224210010065,2.4306842635191277
0.0002167228387107387,0.058423684736947396,266.7318130961288,387.89224210010065,2.4306842635191277
0.00021700778553695562,0.05850050010002,266.8178635674373,387.89224210010065,2.4306842635191277
0.00022014220062534213,0.05934546909381877,267.7615286596017,387.89224210010065,2.4306842635191277
0.00022042714745155906,0.05942228445689138,267.84705571465486,387.89224210010065,2.4306842635191277
0.00022220806511541504,0.059902380476095224,268.3806262002369,387.89224210010065,2.4306842635191277
0.00022263548535474045,0.060017603520704135,268.5084346359393,387.89224210010065,2.4306842635191277
0.0002242026928989337,0.06044008801760352,268.9762490902997,387.89224210010065,2.4306842635191277
0.00022591237385623543,0.060900980196039206,269.48514001071976,387.89224210010065,2.4306842635191277
0.0002289755522380677,0.061726745349069814,270.3931624776249,387.89224210010065,2.4306842635191277
0.00023146883696746604,0.06239887977595519,271.1287581605989,387.89224210010065,2.4306842635191277
0.00023552932924105762,0.06349349869973994,272.3201482498173,387.89224210010065,2.4306842635191277
0.00023617045960004578,0.06366633326665333,272.50752773661236,387.89224210010065,2.4306842635191277
0.00023681158995903396,0.06383916783356672,272.69470894374234,387.89224210010065,2.4306842635191277
0.0002406583721129628,0.064876175235047,273.81367374273003,387.89224210010065,2.4306842635191277
0.00024129950247195095,0.06504900980196039,273.99948760760265,387.89224210010065,2.4306842635191277
0.00024279547330958998,0.06545229045809162,274.4323061162007,387.89224210010065,2.4306842635191277
0.00024386402390790357,0.06574034806961393,274.7408256725304,387.89224210010065,2.4306842635191277
0.0002465710187569646,0.06647009401880376,275.52005822795485,387.89224210010065,2.4306842635191277
0.0002474258592356155,0.06670054010802161,275.7654375730551,387.89224210010065,2.4306842635191277
0.0002504178009108935,0.06750710142028406,276.62167365315037,387.89224210010065,2.4306842635191277
0.0002524836654009664,0.06806401280256051,277.2105571822994,387.89224210010065,2.4306842635191277
0.000255048186836919,0.06875535107021405,277.9389772357389,387.89224210010065,2.4306842635191277
0.0002590374424039564,0.06983076615323065,279.0664229449171,387.89224210010065,2.4306842635191277
0.00026010599300226993,0.07011882376475295,279.36726492011775,387.89224210010065,2.4306842635191277
0.00026174443725301744,0.0705605121024205,279.82762148849986,387.89224210010065,2.4306842635191277
0.00026288422455788527,0.07086777355471095,280.147206911324,387.89224210010065,2.4306842635191277
0.0002643801953955243,0.07127105421084218,280.56584389058065,387.89224210010065,2.4306842635191277
0.000265804929526609,0.07165513102620524,280.9636877122001,387.89224210010065,2.4306842635191277
0.0002670159535380311,0.07198159631926386,281.30120150114783,387.89224210010065,2.4306842635191277
0.00026787079401668196,0.0722120424084817,281.5390871860902,387.89224210010065,2.4306842635191277
0.00026872563449533283,0.07244248849769955,281.7766769858072,387.89224210010065,2.4306842635191277
0.00026958047497398365,0.07267293458691738,282.0139722078123,387.89224210010065,2.4306842635191277
0.0002700791319198634,0.07280736147229447,282.15225889944713,387.89224210010065,2.4306842635191277
0.0002711476825181769,0.07309541908381677,282.4482526639432,387.89224210010065,2.4306842635191277
0.00027556435832453975,0.0742860572114423,283.66689836379686,387.89224210010065,2.4306842635191277
0.00027656167221629905,0.07455491098219644,283.9410193817544,387.89224210010065,2.4306842635191277
0.00027763022281461264,0.07484296859371875,284.23429301382123,387.89224210010065,2.4306842635191277
0.0002786987734129262,0.07513102620524105,284.5271267586638,387.89224210010065,2.4306842635191277
0.0002804084543702279,0.07559191838367674,284.994751624046,387.89224210010065,2.4306842635191277
0.00028190442520786694,0.07599519903980796,285.40301198903796,387.89224210010065,2.4306842635191277
0.0002843977099372653,0.07666733346669334,286.0815732879659,387.89224210010065,2.4306842635191277
0.000284896366883145,0.07680176035207043,286.21700670930176,387.89224210010065,2.4306842635191277
0.0002854662605355789,0.07695539107821565,286.3716746102203,387.89224210010065,2.4306842635191277
0.0002862498643076755,0.07716663332666533,286.5841464927772,387.89224210010065,2.4306842635191277
0.0002889568591567366,0.07789637927585517,287.3164012516665,387.89224210010065,2.4306842635191277
0.0002915213805926892,0.07858771754350871,288.0076523391954,387.89224210010065,2.4306842635191277
0.00029372971849587055,0.07918303660732147,288.60099812045155,387.89224210010065,2.4306842635191277
0.00029707784370391975,0.08008561712342468,289.49727922247644,387.89224210010065,2.4306842635191277
0.0002979326841825706,0.08031606321264254,289.725484557208,387.89224210010065,2.4306842635191277
0.00029836010442189605,0.08043128625725146,289.8394914534291,387.89224210010065,2.4306842635191277
0.0003007821524447402,0.08108421684336868,290.4843314344511,387.89224210010065,2.4306842635191277
0.00030206441316271644,0.08142988597719544,290.82489729699205,387.89224210010065,2.4306842635191277
0.00030391656753312666,0.08192918583716743,291.3158320607303,387.89224210010065,2.4306842635191277
0.00030512759154454873,0.08225565113022605,291.636197110374,387.89224210010065,2.4306842635191277
0.0003067660357952962,0.08269733946789358,292.06884399787475,387.89224210010065,2.4306842635191277
0.0003082620066329352,0.0831006201240248,292.46308300099065,387.89224210010065,2.4306842635191277
0.0003099004508836827,0.08354230846169235,292.8940134349886,387.89224210010065,2.4306842635191277
0.0003114676584278759,0.08396479295859172,293.30537708723404,387.89224210010065,2.4306842635191277
0.0003123224989065268,0.08419523904780957,293.5294169907252,387.89224210010065,2.4306842635191277
0.00031388970645072006,0.08461772354470895,293.93953667065364,387.89224210010065,2.4306842635191277
0.0003180926721374202,0.08575075015003002,295.0354794718635,387.89224210010065,2.4306842635191277
0.0003182351455505286,0.08578915783156632,295.0725307779807,387.89224210010065,2.4306842635191277
0.00032065719357337273,0.08644208841768354,295.70141654327904,387.89224210010065,2.4306842635191277
0.0003227942947699999,0.08701820364072815,296.254778885465,387.89224210010065,2.4306842635191277
0.00032372037195520497,0.08726785357071415,296.4941253094059,387.89224210010065,2.4306842635191277
0.00032535881620595247,0.08770954190838168,296.91693123793567,387.89224210010065,2.4306842635191277
0.00032621365668460334,0.08793998799759953,297.13719595149564,387.89224210010065,2.4306842635191277
0.00032713973386980846,0.08818963792758552,297.37556218388534,387.89224210010065,2.4306842635191277
0.0003279233376419051,0.08840088017603522,297.57705121324057,387.89224210010065,2.4306842635191277
0.00032827952117467623,0.08849689937987598,297.6685750523462,387.89224210010065,2.4306842635191277
0.0003293480717729898,0.08878495699139828,297.9429144818556,387.89224210010065,2.4306842635191277
0.0003311289894368458,0.08926505301060213,298.3993767195268,387.89224210010065,2.4306842635191277
0.0003319838299154966,0.08949549909981996,298.61813842228673,387.89224210010065,2.4306842635191277
0.00033347980075313564,0.08989877975595119,299.00044351679196,387.89224210010065,2.4306842635191277
0.0003339072209924611,0.09001400280056011,299.1095506187399,387.89224210010065,2.4306842635191277
0.00033461958805800347,0.09020604120824165,299.2912748250835,387.89224210010065,2.4306842635191277
0.00033490453488422043,0.09028285657131427,299.36392225391285,387.89224210010065,2.4306842635191277
0.0003376827664398357,0.09103180636127226,300.07097591754166,387.89224210010065,2.4306842635191277
0.0003378964765594984,0.09108941788357672,300.12527051051717,387.89224210010065,2.4306842635191277
0.0003401760511692341,0.09170394078815763,300.7035819761639,387.89224210010065,2.4306842635191277
0.0003427405726051867,0.09239527905581117,301.35237883154946,387.89224210010065,2.4306842635191277
0.0003433104662576206,0.0925489097819564,301.4962984791528,387.89224210010065,2.4306842635191277
0.0003445214902690426,0.092875375075015,301.80181873282777,387.89224210010065,2.4306842635191277
0.0003457325142804647,0.09320184036807362,302.10692043927656,387.89224210010065,2.4306842635191277
0.0003466585914656698,0.09345149029805962,302.3399523650926,387.89224210010065,2.4306842635191277
0.0003481545623033088,0.09385477095419084,302.7158763393783,387.89224210010065,2.4306842635191277
0.0003502204267933817,0.0944116823364673,303.2339754373002,387.89224210010065,2.4306842635191277
0.00035435215577352754,0.0955255051010202,304.2666117281249,387.89224210010065,2.4306842635191277
0.0003559193633177208,0.09594798959791959,304.6570716246304,387.89224210010065,2.4306842635191277
0.0003568454405029259,0.09619763952790558,304.887482758785,387.89224210010065,2.4306842635191277
0.0003575578075684683,0.09638967793558713,305.06456344007137,387.89224210010065,2.4306842635191277
0.00036047851253719206,0.09717703540708142,305.789160360947,387.89224210010065,2.4306842635191277
0.00036119087960273446,0.09736907381476295,305.96554354808234,387.89224210010065,2.4306842635191277
0.0003638978744517955,0.0980988197639528,306.634565959891,387.89224210010065,2.4306842635191277
0.0003656787921156515,0.09857891578315664,307.07365404921865,387.89224210010065,2.4306842635191277
0.00036653363259430235,0.09880936187237448,307.2841200321655,387.89224210010065,2.4306842635191277
0.00036667610600741083,0.09884776955391078,307.31917907610045,387.89224210010065,2.4306842635191277
0.0003683857869647125,0.09930866173234647,307.7394740618199,387.89224210010065,2.4306842635191277
0.0003702379413351228,0.09980796159231847,308.19393609205395,387.89224210010065,2.4306842635191277