File: datasets/aisi_316_L/data/M1/train_10.csv
Time(s),Strain(%),Stress(MPa),Temp(C),Log_SR(s-1)
0.0,0.0,0.0,93.76598808777156,0.35355611522635844
1.772163861722294e-06,4e-06,0.7735593749999999,93.76598808777156,0.35355611522635844
1.0632983170333765e-05,2.4e-05,4.64135625,93.76598808777156,0.35355611522635844
1.594947475550065e-05,3.6e-05,6.962034375,93.76598808777156,0.35355611522635844
2.126596634066753e-05,4.8e-05,9.2827125,93.76598808777156,0.35355611522635844
2.9417920104590083e-05,6.64e-05,12.841085625,93.76598808777156,0.35355611522635844
4.182306713664614e-05,9.439999999999999e-05,18.256001249999997,93.76598808777156,0.35355611522635844
6.308903347731367e-05,0.0001424,27.53871375,93.76598808777156,0.35355611522635844
6.62789284284138e-05,0.0001496,28.931120625000002,93.76598808777156,0.35355611522635844
6.769665951779164e-05,0.0001528,29.549968125,93.76598808777156,0.35355611522635844
7.549418050936973e-05,0.0001704,32.953629375,93.76598808777156,0.35355611522635844
8.081067209453661e-05,0.0001824,35.2743075,93.76598808777156,0.35355611522635844
8.612716367970348e-05,0.00019439999999999998,37.594985625,93.76598808777156,0.35355611522635844
9.179808803721484e-05,0.0002072,40.070375625,93.76598808777156,0.35355611522635844
0.0001006589073458263,0.0002272,43.9381725,93.76598808777156,0.35355611522635844
0.0001066842644756821,0.0002408,46.568274375,93.76598808777156,0.35355611522635844
0.00011660838210132696,0.0002632,50.900206875,93.76598808777156,0.35355611522635844
0.0001197982770524271,0.0002704,52.29261375,93.76598808777156,0.35355611522635844
0.0001229881720035272,0.00027759999999999997,53.68502062499999,93.76598808777156,0.35355611522635844
0.0001307856929951053,0.00029519999999999997,57.08868187499999,93.76598808777156,0.35355611522635844
0.00013751991566965003,0.0003104,60.0282075,93.76598808777156,0.35355611522635844
0.00015169722656342837,0.0003424,66.21668249999999,93.76598808777156,0.35355611522635844
0.00015524155428687296,0.0003504,67.76380125,93.76598808777156,0.35355611522635844
0.00015878588201031756,0.0003584,69.31092,93.76598808777156,0.35355611522635844
0.00016481123914017335,0.000372,71.941021875,93.76598808777156,0.35355611522635844
0.00018430504161911858,0.000416,80.450175,93.76598808777156,0.35355611522635844
0.00019174812983835222,0.0004328,83.699124375,93.76598808777156,0.35355611522635844
0.0001970646214235191,0.00044479999999999997,86.0198025,93.76598808777156,0.35355611522635844
0.00019954565082993031,0.0004504,87.102785625,93.76598808777156,0.35355611522635844
0.00020805203736619731,0.0004696,90.815870625,93.76598808777156,0.35355611522635844
0.00021124193231729745,0.0004768,92.2082775,93.76598808777156,0.35355611522635844
0.0002162039911301199,0.000488,94.37424375,93.76598808777156,0.35355611522635844
0.00022364707934935353,0.0005048,97.623193125,93.76598808777156,0.35355611522635844
0.00022506481043873134,0.000508,98.242040625,93.76598808777156,0.35355611522635844
0.00023888768856016526,0.0005392,104.27580375,93.76598808777156,0.35355611522635844
0.0002527105666815991,0.0005704,110.309566875,93.76598808777156,0.35355611522635844
0.0002548371633156659,0.0005752,111.237838125,93.76598808777156,0.35355611522635844
0.0002619258187625551,0.0005912,114.33207562499999,93.76598808777156,0.35355611522635844
0.0002668878775753775,0.0006024,116.498041875,93.76598808777156,0.35355611522635844
0.0002693689069817887,0.0006079999999999999,117.58102499999998,93.76598808777156,0.35355611522635844
0.0002771664279733668,0.0006255999999999999,120.98468624999998,93.76598808777156,0.35355611522635844
0.00028248291955853367,0.0006376,123.305364375,93.76598808777156,0.35355611522635844
0.0002916981716394896,0.0006584,127.327873125,93.76598808777156,0.35355611522635844
0.00029949569263106767,0.000676,130.731534375,93.76598808777156,0.35355611522635844
0.0003165084657036017,0.0007144,138.157704375,93.76598808777156,0.35355611522635844
0.00032147052451642413,0.0007256,140.323670625,93.76598808777156,0.35355611522635844
0.00033245794045910234,0.0007503999999999999,145.11973874999998,93.76598808777156,0.35355611522635844
0.0003342301043208247,0.0007544,145.893298125,93.76598808777156,0.35355611522635844
0.0003406098942230249,0.0007687999999999999,148.67811187499998,93.76598808777156,0.35355611522635844
0.0003427364908570917,0.0007735999999999999,149.60638312499998,93.76598808777156,0.35355611522635844
0.0003491162807592919,0.000788,152.391196875,93.76598808777156,0.35355611522635844
0.0003679012176935482,0.0008303999999999999,160.59092625,93.76598808777156,0.35355611522635844
0.00037109111264464837,0.0008376,161.983333125,93.76598808777156,0.35355611522635844
0.00037924306640857094,0.000856,165.54170625,93.76598808777156,0.35355611522635844
0.00039483810839172713,0.0008912,172.34902875,93.76598808777156,0.35355611522635844
0.00039731913779813833,0.0008968,173.432011875,93.76598808777156,0.35355611522635844
0.00040653438987909424,0.0009176,177.454520625,93.76598808777156,0.35355611522635844
0.00041326861255363894,0.0009327999999999999,180.39404624999997,93.76598808777156,0.35355611522635844
0.00041929396968349474,0.0009463999999999999,183.02414812499998,93.76598808777156,0.35355611522635844
0.0004214205663175615,0.0009511999999999999,183.95241937499998,93.76598808777156,0.35355611522635844
0.00043559787721133994,0.0009832,190.14089437500002,93.76598808777156,0.35355611522635844
0.0004380789066177511,0.0009888,191.2238775,93.76598808777156,0.35355611522635844
0.00044764859147105153,0.0010104,195.401098125,93.76598808777156,0.35355611522635844
0.00045296508305621837,0.0010224,197.72177624999998,93.76598808777156,0.35355611522635844
0.00045934487295841864,0.0010368,200.50659000000002,93.76598808777156,0.35355611522635844
0.0004600537385031075,0.0010383999999999999,200.81601374999997,93.76598808777156,0.35355611522635844
0.00046962342335640794,0.00106,204.993234375,93.76598808777156,0.35355611522635844
0.00047281331830750805,0.0010672,206.38564125,93.76598808777156,0.35355611522635844
0.0004834463014778418,0.0010911999999999999,211.02699749999996,93.76598808777156,0.35355611522635844
0.00048734506197363085,0.0010999999999999998,212.72882812499998,93.76598808777156,0.35355611522635844
0.0004944337174205201,0.001116,215.823065625,93.76598808777156,0.35355611522635844
0.0005004590745503758,0.0011296,218.45316749999998,93.76598808777156,0.35355611522635844
0.0005057755661355427,0.0011416,220.773845625,93.76598808777156,0.35355611522635844
0.0005125097888100874,0.0011568,223.71337125,93.76598808777156,0.35355611522635844
0.0005178262803952543,0.0011688,226.034049375,93.76598808777156,0.35355611522635844
0.0005369656501018551,0.001212,234.388490625,93.76598808777156,0.35355611522635844
0.0005394466795082663,0.0012175999999999999,235.47147374999997,93.76598808777156,0.35355611522635844
0.0005504340954509445,0.0012423999999999998,240.26754187499998,93.76598808777156,0.35355611522635844
0.0005522062593126668,0.0012464,241.04110125,93.76598808777156,0.35355611522635844
0.0005607126458489339,0.0012656,244.75418625,93.76598808777156,0.35355611522635844
0.0005830419105066348,0.001316,254.501034375,93.76598808777156,0.35355611522635844
0.0005862318054577349,0.0013231999999999999,255.83856144098831,93.76598808777156,0.35355611522635844
0.0005876495365471127,0.0013264,255.86218035434322,93.76598808777156,0.35355611522635844
0.0005972192214004132,0.001348,256.0210307238148,93.76598808777156,0.35355611522635844
0.0005993458180344798,0.0013528,256.05619563427354,93.76598808777156,0.35355611522635844
0.0006099788012048136,0.0013767999999999999,256.23129551967793,93.76598808777156,0.35355611522635844
0.0006170674566517028,0.0013928,256.3473678871998,93.76598808777156,0.35355611522635844
0.0006284093053667255,0.0014184,256.53200782255976,93.76598808777156,0.35355611522635844
0.0006340802297242368,0.0014311999999999999,256.6238400756601,93.76598808777156,0.35355611522635844
0.0006397511540817482,0.001444,256.71535257238656,93.76598808777156,0.35355611522635844
0.0006418777507158149,0.0014487999999999999,256.74958812688095,93.76598808777156,0.35355611522635844
0.0006440043473498817,0.0014536,256.7837794739548,93.76598808777156,0.35355611522635844
0.0006503841372520819,0.001468,256.88609029051435,93.76598808777156,0.35355611522635844
0.0006539284649755265,0.0014759999999999999,256.94276048888133,93.76598808777156,0.35355611522635844
0.0006574727926989711,0.0014839999999999999,256.9993110224046,93.76598808777156,0.35355611522635844
0.00065818165824366,0.0014856,257.0106068483569,93.76598808777156,0.35355611522635844
0.0006617259859671046,0.0014935999999999999,257.0670149654404,93.76598808777156,0.35355611522635844
0.0006666880447799271,0.0015048,257.1457887731306,93.76598808777156,0.35355611522635844
0.0006992958598356173,0.0015784,257.65787101665904,93.76598808777156,0.35355611522635844
0.0007028401875590619,0.0015864,257.71296515469146,93.76598808777156,0.35355611522635844
0.0007113465740953289,0.0016056,257.8447508658352,93.76598808777156,0.35355611522635844
0.0007177263639975291,0.00162,257.9431871871817,93.76598808777156,0.35355611522635844
0.0007205618261762847,0.0016263999999999999,257.98682706592666,93.76598808777156,0.35355611522635844
0.0007297770782572407,0.0016472,258.12819637346485,93.76598808777156,0.35355611522635844
0.0007365113009317854,0.0016623999999999999,258.231064816788,93.76598808777156,0.35355611522635844
0.0007425366580616412,0.001676,258.32279447914067,93.76598808777156,0.35355611522635844
0.0007471442841021193,0.0016864,258.39274495253744,93.76598808777156,0.35355611522635844
0.000748562015191497,0.0016895999999999999,258.4142343017324,93.76598808777156,0.35355611522635844
0.0007570684017277641,0.0017088,258.5428386427636,93.76598808777156,0.35355611522635844
0.0007733723092556091,0.0017456,258.7877659165519,93.76598808777156,0.35355611522635844
0.0007769166369790537,0.0017536,258.8407435523973,93.76598808777156,0.35355611522635844
0.0007783343680684316,0.0017568,258.8619082045416,93.76598808777156,0.35355611522635844
0.0007815242630195317,0.001764,258.9094737774664,93.76598808777156,0.35355611522635844
0.0008010180654984769,0.001808,259.19852403812376,93.76598808777156,0.35355611522635844
0.0008130687797581885,0.0018352,259.3758379929234,93.76598808777156,0.35355611522635844
0.0008190941368880443,0.0018487999999999998,259.46411040439625,93.76598808777156,0.35355611522635844
0.0008279549561966558,0.0018687999999999999,259.5934641159439,93.76598808777156,0.35355611522635844
0.0008314992839201004,0.0018767999999999999,259.6450542933992,93.76598808777156,0.35355611522635844
0.0008353980444158894,0.0018855999999999999,259.70170453292684,93.76598808777156,0.35355611522635844
0.0008478031914479454,0.0019136,259.88127314335685,93.76598808777156,0.35355611522635844
0.0008531196830331124,0.0019256,259.95791710454915,93.76598808777156,0.35355611522635844
0.0008563095779842126,0.0019328,260.0038140735792,93.76598808777156,0.35355611522635844
0.0008761578132355022,0.0019776,260.2879113713721,93.76598808777156,0.35355611522635844
0.0008768666787801911,0.0019792,260.29801101362926,93.76598808777156,0.35355611522635844
0.0008821831703653579,0.0019912,260.37365709621577,93.76598808777156,0.35355611522635844
0.0008984870778932031,0.002028,260.6045373853719,93.76598808777156,0.35355611522635844
0.0009034491367060255,0.0020391999999999997,260.6744802256279,93.76598808777156,0.35355611522635844
0.000909120061063537,0.002052,260.7542317103275,93.76598808777156,0.35355611522635844
0.000919398611461526,0.0020751999999999997,260.8982885139517,93.76598808777156,0.35355611522635844
0.0009349936534446822,0.0021103999999999997,261.1156637803665,93.76598808777156,0.35355611522635844
0.0009449177710703271,0.0021328,261.25325757443323,93.76598808777156,0.35355611522635844
0.0009505886954278386,0.0021456,261.3316295475423,93.76598808777156,0.35355611522635844
0.0009530697248342498,0.0021512,261.36585992511755,93.76598808777156,0.35355611522635844
0.000955550754240661,0.0021568,261.4000555679825,93.76598808777156,0.35355611522635844
0.0009729179600855395,0.002196,261.6384629242094,93.76598808777156,0.35355611522635844
0.0009839053760282177,0.0022207999999999998,261.7884352414722,93.76598808777156,0.35355611522635844
0.0009945383591985514,0.0022448,261.9329490830531,93.76598808777156,0.35355611522635844
0.0010069435062306075,0.0022727999999999997,262.10078917426864,93.76598808777156,0.35355611522635844
0.001014386594449841,0.0022895999999999997,262.2011061900257,93.76598808777156,0.35355611522635844
0.001016513191083908,0.0022944,262.229715414362,93.76598808777156,0.35355611522635844
0.0010200575188073525,0.0023024,262.2773456377934,93.76598808777156,0.35355611522635844
0.0010271461742542417,0.0023184,262.37241289331274,93.76598808777156,0.35355611522635844
0.0010352981280181642,0.0023368,262.48142448531286,93.76598808777156,0.35355611522635844
0.0010363614263351976,0.0023392,262.4956186681909,93.76598808777156,0.35355611522635844
0.0010434500817820868,0.0023552,262.59010182666066,93.76598808777156,0.35355611522635844
0.001049829871684287,0.0023696,262.6749228522553,93.76598808777156,0.35355611522635844
0.0010555007960417982,0.0023824,262.75015070160646,93.76598808777156,0.35355611522635844
0.0010611717203993097,0.0023952,262.82522108520493,93.76598808777156,0.35355611522635844
0.0010640071825780654,0.0024016,262.86269759307896,93.76598808777156,0.35355611522635844
0.0010771211951548102,0.0024311999999999997,263.03552230534166,93.76598808777156,0.35355611522635844
0.0010810199556505994,0.00244,263.08674412181136,93.76598808777156,0.35355611522635844
0.0010902352077315554,0.0024608,263.20752831985004,93.76598808777156,0.35355611522635844
0.0011065391152594005,0.0024976,263.4202525557741,93.76598808777156,0.35355611522635844
0.0011115011740722228,0.0025088,263.4847516263426,93.76598808777156,0.35355611522635844
0.0011157543673403565,0.0025184,263.5399472154194,93.76598808777156,0.35355611522635844
0.0011207164261531788,0.0025296,263.6042384656227,93.76598808777156,0.35355611522635844
0.0011309949765511682,0.0025528,263.7370611197631,93.76598808777156,0.35355611522635844
0.0011387924975427462,0.0025704,263.8375093339822,93.76598808777156,0.35355611522635844
0.0011483621823960464,0.0025919999999999997,263.9604208269889,93.76598808777156,0.35355611522635844
0.0011572230017046579,0.0026119999999999997,264.073872063399,93.76598808777156,0.35355611522635844
0.0011621850605174806,0.0026232,264.13725676122914,93.76598808777156,0.35355611522635844
0.0011636027916068583,0.0026264,264.1553472778791,93.76598808777156,0.35355611522635844
0.001171045879826092,0.0026432,264.25018182993585,93.76598808777156,0.35355611522635844
0.001184159892402837,0.0026728,264.41670128797125,93.76598808777156,0.35355611522635844
0.0011891219512156592,0.0026839999999999998,264.47952090378266,93.76598808777156,0.35355611522635844
0.0011905396823050371,0.0026872,264.4974505770811,93.76598808777156,0.35355611522635844
0.0011944384428008263,0.002696,264.5467142940392,93.76598808777156,0.35355611522635844
0.0011976283377519263,0.0027032,264.5869743426211,93.76598808777156,0.35355611522635844
0.0012040081276541265,0.0027175999999999997,264.6673691963552,93.76598808777156,0.35355611522635844
0.0012107423503286713,0.0027328,264.7520504008639,93.76598808777156,0.35355611522635844
0.001214286678052116,0.0027408,264.7965456639496,93.76598808777156,0.35355611522635844
0.0012196031696372826,0.0027527999999999997,264.86319370518635,93.76598808777156,0.35355611522635844
0.0012302361528076166,0.0027768,264.9961508351494,93.76598808777156,0.35355611522635844
0.0012369703754821612,0.0027919999999999998,265.08012526202964,93.76598808777156,0.35355611522635844
0.001239096972116228,0.0027968,265.1066064354233,93.76598808777156,0.35355611522635844
0.0012557553124164177,0.0028344,265.31343257376335,93.76598808777156,0.35355611522635844
0.00126071737122924,0.0028455999999999998,265.37483316097916,93.76598808777156,0.35355611522635844
0.0012663882955867513,0.0028583999999999997,265.4448899706439,93.76598808777156,0.35355611522635844
0.001276312413212396,0.0028807999999999998,265.56719569560636,93.76598808777156,0.35355611522635844
0.0012816289047975632,0.0028928,265.63256402800204,93.76598808777156,0.35355611522635844
0.0012919074551955524,0.0029159999999999998,265.7586437103197,93.76598808777156,0.35355611522635844
0.001305375900544642,0.0029464,265.92326098766364,93.76598808777156,0.35355611522635844
0.0013082113627233974,0.0029527999999999998,265.9578327010269,93.76598808777156,0.35355611522635844
0.001315654450942631,0.0029695999999999998,266.048444693574,93.76598808777156,0.35355611522635844
0.0013206165097554537,0.0029808,266.1087416455754,93.76598808777156,0.35355611522635844
0.0013287684635193762,0.0029992,266.2076094598453,93.76598808777156,0.35355611522635844
0.001334084955104543,0.0030112,266.27196105047756,93.76598808777156,0.35355611522635844
0.0013376292828279875,0.0030191999999999997,266.3148065558221,93.76598808777156,0.35355611522635844
0.001343300207185499,0.003032,266.38326738544913,93.76598808777156,0.35355611522635844
0.0013514521609494215,0.0030504,266.48148268401235,93.76598808777156,0.35355611522635844
0.0013581863836239663,0.0030656,266.56244291054554,93.76598808777156,0.35355611522635844
0.001360312980258033,0.0030704,266.5879767530236,93.76598808777156,0.35355611522635844
0.0013681105012496111,0.003088,266.6814679478288,93.76598808777156,0.35355611522635844
0.001373426992834778,0.0031,266.74509282764075,93.76598808777156,0.35355611522635844
0.001381224513826356,0.0031176,266.838235844142,93.76598808777156,0.35355611522635844
0.0013893764675902787,0.003136,266.9353936334394,93.76598808777156,0.35355611522635844
0.0013939840936307564,0.0031463999999999997,266.9902105583662,93.76598808777156,0.35355611522635844
0.0013975284213542012,0.0031544,267.03232935259035,93.76598808777156,0.35355611522635844
0.0014024904801670235,0.0031655999999999998,267.0912257439134,93.76598808777156,0.35355611522635844
0.0014237564465076913,0.0032136,267.34272391672994,93.76598808777156,0.35355611522635844
0.001429781803637547,0.0032272,267.4137148288679,93.76598808777156,0.35355611522635844
0.0014304906691822359,0.0032288,267.422059023236,93.76598808777156,0.35355611522635844
0.0014336805641333359,0.0032359999999999997,267.4595879598529,93.76598808777156,0.35355611522635844
0.0014418325178972584,0.0032543999999999997,267.5553475917853,93.76598808777156,0.35355611522635844
0.0014489211733441476,0.0032703999999999997,267.6384453311789,93.76598808777156,0.35355611522635844
0.0014556553960186924,0.0032856,267.71724144714125,93.76598808777156,0.35355611522635844
0.0014613263203762036,0.0032984,267.78348586494485,93.76598808777156,0.35355611522635844
0.0014641617825549593,0.0033047999999999997,267.81657047155426,93.76598808777156,0.35355611522635844
0.0014744403329529487,0.003328,267.93629327379836,93.76598808777156,0.35355611522635844
0.0014822378539445268,0.0033456,268.0269004662842,93.76598808777156,0.35355611522635844
0.0014942885682042385,0.0033728,268.16656497664997,93.76598808777156,0.35355611522635844
0.001497124030382994,0.0033791999999999997,268.19936329375344,93.76598808777156,0.35355611522635844
0.0015038582530575387,0.0033943999999999997,268.27716235606545,93.76598808777156,0.35355611522635844
0.0015098836101873946,0.003408,268.34665694986023,93.76598808777156,0.35355611522635844
0.0015268963832599286,0.0034463999999999996,268.54229556174863,93.76598808777156,0.35355611522635844
0.001540364828609018,0.0034768,268.6965738665144,93.76598808777156,0.35355611522635844
0.0015478079168282518,0.0034936,268.7816072003731,93.76598808777156,0.35355611522635844
0.0015595041983156187,0.0035199999999999997,268.9149095165949,93.76598808777156,0.35355611522635844
0.0015637573915837524,0.0035296,268.96328634145306,93.76598808777156,0.35355611522635844
0.0015669472865348524,0.0035367999999999997,268.9995352915799,93.76598808777156,0.35355611522635844
0.0015733270764370527,0.0035512,269.0719469689742,93.76598808777156,0.35355611522635844
0.0015832511940626975,0.0035735999999999997,269.1843601563852,93.76598808777156,0.35355611522635844
0.0015903398495095867,0.0035895999999999996,269.26448710765374,93.76598808777156,0.35355611522635844
0.0015924664461436533,0.0035943999999999998,269.28849801594475,93.76598808777156,0.35355611522635844
0.0015995551015905425,0.0036103999999999997,269.36844421561784,93.76598808777156,0.35355611522635844
0.001609833651988532,0.0036336,269.4841212098776,93.76598808777156,0.35355611522635844
0.0016243653956546547,0.0036663999999999998,269.6471742575497,93.76598808777156,0.35355611522635844
0.0016342895132802997,0.0036888,269.75820077890876,93.76598808777156,0.35355611522635844
0.0016357072443696774,0.003692,269.77404021972336,93.76598808777156,0.35355611522635844
0.0016420870342718776,0.0037064,269.8452515495313,93.76598808777156,0.35355611522635844
0.0016505934208081447,0.0037256,269.94003237080034,93.76598808777156,0.35355611522635844
0.0016534288829869004,0.0037319999999999996,269.9715836200722,93.76598808777156,0.35355611522635844
0.0016615808367508229,0.0037503999999999997,270.06217613188335,93.76598808777156,0.35355611522635844
0.0016658340300189564,0.00376,270.1093729695966,93.76598808777156,0.35355611522635844
0.001685682265270246,0.0038047999999999997,270.3290064708131,93.76598808777156,0.35355611522635844
0.0016867455635872794,0.0038071999999999997,270.34074400639633,93.76598808777156,0.35355611522635844
0.0016924164879447907,0.0038199999999999996,270.40329552790575,93.76598808777156,0.35355611522635844
0.001705530500521536,0.0038496,270.5476336787808,93.76598808777156,0.35355611522635844
0.0017097836937896693,0.0038591999999999997,270.5943530135903,93.76598808777156,0.35355611522635844
0.0017228977063664143,0.0038888,270.7381197901384,93.76598808777156,0.35355611522635844
0.0017409737777559818,0.0039296,270.9355872122129,93.76598808777156,0.35355611522635844
0.0017469991348858377,0.0039432,271.0012317856265,93.76598808777156,0.35355611522635844
0.0017523156264710044,0.0039552,271.0590801759092,93.76598808777156,0.35355611522635844
0.0017654296390477496,0.0039848,271.2014809862699,93.76598808777156,0.35355611522635844
0.0020018822418775345,0.004518503700740148,273.70220640939243,93.76598808777156,0.35355611522635844
0.0021805520931093884,0.004921784356871375,275.5159880413907,93.76598808777156,0.35355611522635844
0.002512367531111402,0.005670734146829366,278.73742562659316,93.76598808777156,0.35355611522635844
0.0027080535586510514,0.006112422484496899,280.55934540688514,93.76598808777156,0.35355611522635844
0.002801642528343927,0.006323664732946589,281.41247624053955,93.76598808777156,0.35355611522635844
0.0028271667928056205,0.00638127625525105,281.6432099370419,93.76598808777156,0.35355611522635844
0.0030739013492686565,0.006938187637527506,283.8332653581806,93.76598808777156,0.35355611522635844
0.0034227329635784657,0.007725545109021804,286.815899801795,93.76598808777156,0.35355611522635844
0.0034567653161940567,0.007802360472094419,287.1003886351764,93.76598808777156,0.35355611522635844
0.0035248300214252393,0.007955991198239648,287.66611029354425,93.76598808777156,0.35355611522635844
0.0038396292831194574,0.008666533306661332,290.22905915901015,93.76598808777156,0.35355611522635844
0.003924710164658436,0.008858571714342869,290.9075052788552,93.76598808777156,0.35355611522635844
0.0042735417789682454,0.009645929185837168,293.6311788884473,93.76598808777156,0.35355611522635844
0.004333098396045529,0.009780356071214243,294.0873903673323,93.76598808777156,0.35355611522635844
0.004494752070969588,0.010145229045809162,295.31351532948446,93.76598808777156,0.35355611522635844
0.0046393895695858505,0.010471694338867774,296.39606978884694,93.76598808777156,0.35355611522635844
0.004826567508971601,0.010894178835767154,297.77767915894583,93.76598808777156,0.35355611522635844
0.004886124126048885,0.011028605721144228,298.21287875418295,93.76598808777156,0.35355611522635844
0.00491164839051058,0.01108621724344869,298.39875901169137,93.76598808777156,0.35355611522635844
0.005209431475897002,0.011758351670334066,300.5402436405719,93.76598808777156,0.35355611522635844
0.00525197191666649,0.011854370874174834,300.84222628563964,93.76598808777156,0.35355611522635844
0.005583787354668504,0.012603320664132826,303.1658065558963,93.76598808777156,0.35355611522635844
0.00567737632436138,0.012814562912582516,303.8113557323072,93.76598808777156,0.35355611522635844
0.005847538087439336,0.013198639727945589,304.97454732726436,93.76598808777156,0.35355611522635844
0.0064090719055965905,0.01446609321864373,308.7226659541633,93.76598808777156,0.35355611522635844
0.006596249844982342,0.01488857771554311,309.94327052401826,93.76598808777156,0.35355611522635844
0.0067579035199064,0.015253450690138028,310.9865973701197,93.76598808777156,0.35355611522635844
0.006911049106676561,0.015599119823964794,311.9660695373064,93.76598808777156,0.35355611522635844
0.00698762190006164,0.015771954390878175,312.45262856495606,93.76598808777156,0.35355611522635844
0.00718330792760129,0.01621364272854571,313.6867030550394,93.76598808777156,0.35355611522635844
0.007251372632832472,0.01636727345469094,314.11286382843144,93.76598808777156,0.35355611522635844
0.007302421161755858,0.016482496499299858,314.43146136982386,93.76598808777156,0.35355611522635844
0.007336453514371449,0.016559311862372472,314.6433773049188,93.76598808777156,0.35355611522635844
0.007523631453757202,0.016981796359271856,315.802133353862,93.76598808777156,0.35355611522635844
0.007634236599757873,0.01723144628925785,316.48156846408284,93.76598808777156,0.35355611522635844
0.007880971156220908,0.017788357671534305,317.98354750210314,93.76598808777156,0.35355611522635844
0.008536093944071038,0.019267053410682137,321.88511750427114,93.76598808777156,0.35355611522635844
0.00861266673745612,0.01943988797759552,322.33339190123115,93.76598808777156,0.35355611522635844
0.008884925558380847,0.020054410882176434,323.91481965549804,93.76598808777156,0.35355611522635844
0.008952990263612029,0.020208041608321663,324.30720950739953,93.76598808777156,0.35355611522635844
0.009012546880689315,0.02034246849369874,324.64959724503046,93.76598808777156,0.35355611522635844
0.009327346142383532,0.021053010602120423,326.44490929753016,93.76598808777156,0.35355611522635844
0.009514524081769284,0.021475495099019803,327.5011906230309,93.76598808777156,0.35355611522635844
0.009744242461924525,0.021993998799759953,328.7865236176565,93.76598808777156,0.35355611522635844
0.009905896136848584,0.02235887177435487,329.6839422397432,93.76598808777156,0.35355611522635844
0.01003351745915705,0.022646929385877177,330.388402419486,93.76598808777156,0.35355611522635844
0.010212187310388903,0.023050210042008402,331.36880383955736,93.76598808777156,0.35355611522635844
0.010314284368235676,0.023280656131226245,331.92602942576605,93.76598808777156,0.35355611522635844
0.010433397602390246,0.023549509901980396,332.5734143825506,93.76598808777156,0.35355611522635844
0.010595051277314303,0.023914382876575314,333.4474165472275,93.76598808777156,0.35355611522635844
0.010909850539008522,0.024624924984997,335.1346373973239,93.76598808777156,0.35355611522635844
0.011216141712548843,0.02531626325265053,336.7581264234722,93.76598808777156,0.35355611522635844
0.011335254946703413,0.025585117023404682,337.38480218710475,93.76598808777156,0.35355611522635844
0.01153944906239696,0.02604600920184037,338.4531610120149,93.76598808777156,0.35355611522635844
0.011633038032089834,0.026257251450290058,338.94035890766065,93.76598808777156,0.35355611522635844
0.011735135089936607,0.0264876975395079,339.4701074248614,93.76598808777156,0.35355611522635844
0.011786183618859995,0.026602920584116823,339.7343074149041,93.76598808777156,0.35355611522635844
0.011981869646399645,0.02704460892178436,340.74296648652097,93.76598808777156,0.35355611522635844
0.01199888582270744,0.027083016603320666,340.83037121166245,93.76598808777156,0.35355611522635844
0.012024410087169132,0.027140628125625125,340.9613877137252,93.76598808777156,0.35355611522635844
0.012245620379170475,0.02763992798559712,342.09235643521794,93.76598808777156,0.35355611522635844
0.012330701260709453,0.027831966393278656,342.52521926860777,93.76598808777156,0.35355611522635844
0.012568927729018593,0.028369673934786958,343.7310818340358,93.76598808777156,0.35355611522635844
0.012662516698711468,0.02858091618323665,344.2023707354281,93.76598808777156,0.35355611522635844
0.012951791695943992,0.02923384676935387,345.65056594388847,93.76598808777156,0.35355611522635844
0.01307941301825246,0.029521904380876176,346.28545939810925,93.76598808777156,0.35355611522635844
0.013266590957638212,0.029944388877775556,347.21228350085784,93.76598808777156,0.35355611522635844
0.013436752720716167,0.03032846569313863,348.05043475466533,93.76598808777156,0.35355611522635844
0.013487801249639553,0.03044368873774755,348.30107158016665,93.76598808777156,0.35355611522635844
0.01365796301271751,0.030827765553110623,349.1338685581799,93.76598808777156,0.35355611522635844
0.013845140952103261,0.03125025005001,350.0452853859725,93.76598808777156,0.35355611522635844
0.013938729921796138,0.031461492298459695,350.4991908061708,93.76598808777156,0.35355611522635844
0.014185464478259172,0.03201840368073615,351.69018925021544,93.76598808777156,0.35355611522635844
0.014313085800567638,0.03230646129225845,352.30305108647246,93.76598808777156,0.35355611522635844
0.014364134329491025,0.032421684336867373,352.547598648109,93.76598808777156,0.35355611522635844
0.014593852709646266,0.03294018803760752,353.64389503066224,93.76598808777156,0.35355611522635844
0.014687441679339143,0.033151430286057215,354.0886023648874,93.76598808777156,0.35355611522635844
0.014883127706878791,0.033593118623724744,355.01488961900276,93.76598808777156,0.35355611522635844
0.015019257117341155,0.0339003800760152,355.6564638842967,93.76598808777156,0.35355611522635844
0.01535107255534317,0.034649329865973195,357.21087321780874,93.76598808777156,0.35355611522635844
0.015487201965805535,0.034956591318263654,357.8447823838904,93.76598808777156,0.35355611522635844
0.015572282847344514,0.035148629725945194,358.23987230377645,93.76598808777156,0.35355611522635844
0.015606315199960101,0.0352254450890178,358.39767244309763,93.76598808777156,0.35355611522635844
0.01586155784457704,0.035801560312062414,359.5769253790212,93.76598808777156,0.35355611522635844
0.01593813063796212,0.0359743948789758,359.929255060378,93.76598808777156,0.35355611522635844
0.016065751960270585,0.0362624524904981,360.5150076993987,93.76598808777156,0.35355611522635844
0.01615934092996346,0.03647369473894779,360.94340694600066,93.76598808777156,0.35355611522635844
0.01620188137073295,0.03656971394278856,361.13781388680906,93.76598808777156,0.35355611522635844
0.016244421811502437,0.036665733146629326,361.33202185598356,93.76598808777156,0.35355611522635844
0.016346518869349215,0.036896179235847176,361.79731350014384,93.76598808777156,0.35355611522635844
0.016669826219197326,0.037625925185037004,363.2633151628448,93.76598808777156,0.35355611522635844
0.016908052687506468,0.03816363272654531,364.3364409900686,93.76598808777156,0.35355611522635844
0.01707821445058442,0.03854770954190838,365.0993522748908,93.76598808777156,0.35355611522635844
0.017222851949200684,0.038874174834966996,365.74549886691324,93.76598808777156,0.35355611522635844
0.01726539238997017,0.03897019403880776,365.9351387818653,93.76598808777156,0.35355611522635844
0.017418537976740332,0.039315863172634524,366.61633878701434,93.76598808777156,0.35355611522635844
0.017937531354128098,0.040487297459491894,368.90767464314416,93.76598808777156,0.35355611522635844
0.017997087971205385,0.04062172434486898,369.1689506142176,93.76598808777156,0.35355611522635844
0.018175757822437237,0.0410250050010002,369.9507627718654,93.76598808777156,0.35355611522635844
0.01819277399874503,0.04106341268253651,370.02506440608954,93.76598808777156,0.35355611522635844
0.018448016643361966,0.04163952790558112,371.1363566526855,93.76598808777156,0.35355611522635844
0.01921374457721277,0.043367873574714944,374.43479901772866,93.76598808777156,0.35355611522635844
0.01938390634029072,0.04375195039007801,375.16077696598165,93.76598808777156,0.35355611522635844
0.019537051927060886,0.044097619523904785,375.8120347838882,93.76598808777156,0.35355611522635844
0.01978378648352392,0.04465453090618124,376.8571112655241,93.76598808777156,0.35355611522635844
0.01992842398214018,0.04498099619923984,377.4673790851932,93.76598808777156,0.35355611522635844
0.020004996775525263,0.04515383076615323,377.78976259923223,93.76598808777156,0.35355611522635844
0.020107093833372038,0.04538427685537108,378.21885966605174,93.76598808777156,0.35355611522635844
0.020251731331988296,0.045710742148429684,378.82529544461823,93.76598808777156,0.35355611522635844
0.02054100632922082,0.046363672734546904,380.0331231559956,93.76598808777156,0.35355611522635844
0.020694151915990985,0.04670934186837368,380.6698747904766,93.76598808777156,0.35355611522635844
0.021111048235531973,0.0476503300660132,382.39401100578624,93.76598808777156,0.35355611522635844
0.02120463720522485,0.04786157231446289,382.77923093803236,93.76598808777156,0.35355611522635844
0.021570484995842455,0.0486873374674935,384.27877125455063,93.76598808777156,0.35355611522635844
0.021655565877381433,0.04887937587517503,384.6260760621974,93.76598808777156,0.35355611522635844
0.021766171023382103,0.04912902580516103,385.07677778052926,93.76598808777156,0.35355611522635844
0.022004397491691245,0.04966673334666934,386.04449741387174,93.76598808777156,0.35355611522635844
0.022063954108768526,0.04980116023204641,386.2857878281505,93.76598808777156,0.35355611522635844
0.022268148224462072,0.050262052410482094,387.1111476775331,93.76598808777156,0.35355611522635844
0.022446818075693927,0.05066533306661332,387.83091926449066,93.76598808777156,0.35355611522635844
0.022685044544003066,0.05120304060812163,388.78714860631345,93.76598808777156,0.35355611522635844
0.022812665866311532,0.05149109821964393,389.29780298244873,93.76598808777156,0.35355611522635844
0.022914762924158307,0.05172154430886178,389.70552475938797,93.76598808777156,0.35355611522635844
0.023229562185852527,0.05243208641728346,390.958229801649,93.76598808777156,0.35355611522635844
0.02341674012523828,0.052854570914182844,391.6999430006692,93.76598808777156,0.35355611522635844
0.023603918064624026,0.053277055411082214,392.4393475523387,93.76598808777156,0.35355611522635844
0.023935733502626042,0.054026005201040214,393.7445145764282,93.76598808777156,0.35355611522635844
0.02395274967893384,0.05406441288257652,393.81125535835946,93.76598808777156,0.35355611522635844
0.02407186291308841,0.05433326665333067,394.2779241723916,93.76598808777156,0.35355611522635844
0.02413141953016569,0.05446769353870774,394.51092079862985,93.76598808777156,0.35355611522635844
0.024156943794627385,0.054525305061012205,394.6107078311913,93.76598808777156,0.35355611522635844
0.024463234968167703,0.05521664332866573,395.80496268389254,93.76598808777156,0.35355611522635844
0.024590856290476172,0.05550470094018804,396.3008461118803,93.76598808777156,0.35355611522635844
0.024769526141708027,0.05590798159631927,396.9934000438652,93.76598808777156,0.35355611522635844
0.024999244521863268,0.05642648529705942,397.8809704546154,93.76598808777156,0.35355611522635844
0.025203438637556815,0.056887377475495104,398.6672551095541,93.76598808777156,0.35355611522635844
0.02533956804801918,0.05719463892778556,399.1900650786957,93.76598808777156,0.35355611522635844
0.025484205546635438,0.057521104220844166,399.74435190495615,93.76598808777156,0.35355611522635844
0.025594810692636107,0.05777075415083016,400.1673908626726,93.76598808777156,0.35355611522635844
0.025645859221559496,0.05788597719543909,400.36239908770546,93.76598808777156,0.35355611522635844
0.02586706951356084,0.05838527705541108,401.2056914147702,93.76598808777156,0.35355611522635844
0.02637755480279471,0.0595375075015003,403.1410889350978,93.76598808777156,0.35355611522635844
0.02643711141987199,0.05967193438687737,403.3659297916804,93.76598808777156,0.35355611522635844
0.02653920847771877,0.059902380476095224,403.7509122194706,93.76598808777156,0.35355611522635844
0.026641305535565537,0.06013282656531306,404.13531747387077,93.76598808777156,0.35355611522635844
0.026734894505258414,0.06034406881376275,404.4871845506967,93.76598808777156,0.35355611522635844
0.026888040092028574,0.060689737947589514,405.0619326073491,93.76598808777156,0.35355611522635844
0.02714328273664551,0.06126585317063413,406.01701702138365,93.76598808777156,0.35355611522635844
0.027415541557570238,0.06188037607521504,407.0319211423333,93.76598808777156,0.35355611522635844
0.027458081998339726,0.06197639527905581,407.1901441443026,93.76598808777156,0.35355611522635844
0.027730340819264454,0.06259091818363673,408.20051691040715,93.76598808777156,0.35355611522635844
0.02787497831788072,0.06291738347669534,408.73570350524005,93.76598808777156,0.35355611522635844
0.02808768052172816,0.06339747949589918,409.52077938501867,93.76598808777156,0.35355611522635844
0.028172761403267143,0.06358951790358072,409.83416010723766,93.76598808777156,0.35355611522635844
0.02841949595973018,0.06414642928585718,410.74088370515085,93.76598808777156,0.35355611522635844
0.028487560664961362,0.0643000600120024,410.9904734095343,93.76598808777156,0.35355611522635844
0.02858114963465424,0.0645113022604521,411.33327983981764,93.76598808777156,0.35355611522635844
0.02874280330957829,0.064876175235047,411.92437068579346,93.76598808777156,0.35355611522635844
0.028972521689733532,0.06539467893578715,412.76211646934973,93.76598808777156,0.35355611522635844
0.02903207830681082,0.06552910582116424,412.978886452033,93.76598808777156,0.35355611522635844
0.02924478051065826,0.06600920184036807,413.7516532432122,93.76598808777156,0.35355611522635844
0.029372401832966733,0.06629725945189038,414.2142612344697,93.76598808777156,0.35355611522635844
0.02940643418558232,0.06637407481496299,414.3374908896694,93.76598808777156,0.35355611522635844
0.029942443739277885,0.06758391678335668,416.2710804026834,93.76598808777156,0.35355611522635844
0.030044540797124656,0.06781436287257452,416.6378476360202,93.76598808777156,0.35355611522635844
0.03018067020758702,0.06812162432486497,417.12611539257426,93.76598808777156,0.35355611522635844
0.030248734912818202,0.0682752550510102,417.3699271270353,93.76598808777156,0.35355611522635844
0.03029978344174159,0.06839047809561913,417.55264554109306,93.76598808777156,0.35355611522635844
0.03035083197066498,0.06850570114022805,417.73524393664803,93.76598808777156,0.35355611522635844
0.030393372411434468,0.06860172034406882,417.8873177878777,93.76598808777156,0.35355611522635844
0.03072518784943648,0.0693506701340268,419.0706581018636,93.76598808777156,0.35355611522635844
0.03083579299543715,0.0696003200640128,419.46399594646516,93.76598808777156,0.35355611522635844
0.030929381965130027,0.0698115623124625,419.79639069460023,93.76598808777156,0.35355611522635844
0.031091035640054086,0.07017643528705741,420.3696046453031,93.76598808777156,0.35355611522635844
0.031142084168977475,0.07029165833166634,420.550377940647,93.76598808777156,0.35355611522635844
0.031184624609746962,0.0703876775355071,420.70093408996775,93.76598808777156,0.35355611522635844
0.03129522975574763,0.0706373274654931,421.09200569481044,93.76598808777156,0.35355611522635844
0.03146539151882559,0.07102140428085618,421.6926034082992,93.76598808777156,0.35355611522635844
0.03160152092928795,0.07132866573314664,422.1721700484627,93.76598808777156,0.35355611522635844
0.031686601810826935,0.07152070414082817,422.47149010542637,93.76598808777156,0.35355611522635844
0.031856763573904885,0.07190478095619124,423.06919155064526,93.76598808777156,0.35355611522635844
0.03210349813036792,0.07246169233846769,423.93365175053896,93.76598808777156,0.35355611522635844
0.03229067606975367,0.07288417683536708,424.58772179360335,93.76598808777156,0.35355611522635844
0.03238426503944655,0.07309541908381677,424.9142022001956,93.76598808777156,0.35355611522635844
0.032639507684063485,0.07367153430686138,425.8027384020039,93.76598808777156,0.35355611522635844
0.032733096653756365,0.07388277655531107,426.1278555079263,93.76598808777156,0.35355611522635844
0.032903258416834315,0.07426685337067414,426.71805024615423,93.76598808777156,0.35355611522635844
0.03304789591545058,0.07459331866373275,427.21878044606007,93.76598808777156,0.35355611522635844
0.03314148488514346,0.07480456091218245,427.5423269646656,93.76598808777156,0.35355611522635844
0.03325209003114413,0.07505421084216844,427.924241081774,93.76598808777156,0.35355611522635844
0.03354987311653055,0.07572634526905382,428.9500168552083,93.76598808777156,0.35355611522635844
0.03387318046637866,0.07645609121824365,430.0597041855868,93.76598808777156,0.35355611522635844
0.03414543928730339,0.07707061412282457,430.99097752656525,93.76598808777156,0.35355611522635844
0.03416245546361119,0.07710902180436088,431.0490857715069,93.76598808777156,0.35355611522635844
0.03441769810822812,0.07768513702740548,431.91935937921886,93.76598808777156,0.35355611522635844
0.03481757825146132,0.07858771754350871,433.2777443904616,93.76598808777156,0.35355611522635844
0.03493669148561589,0.07885657131426285,433.6811918184555,93.76598808777156,0.35355611522635844
0.035200442218386724,0.07945189037807562,434.57263554924316,93.76598808777156,0.35355611522635844
0.03536209589331078,0.07981676335267054,435.11771684915146,93.76598808777156,0.35355611522635844
0.035523749568234834,0.08018163632726545,435.6618272184357,93.76598808777156,0.35355611522635844
0.03580451647731346,0.08081536307261453,436.6045715059402,93.76598808777156,0.35355611522635844
0.035889597358852436,0.08100740148029606,436.8896818022757,93.76598808777156,0.35355611522635844
0.036085283386392095,0.0814490898179636,437.5444370165109,93.76598808777156,0.35355611522635844
0.036161856179777165,0.08162192438487698,437.80026845272755,93.76598808777156,0.35355611522635844
0.036204396620546656,0.08171794358871774,437.94230573580035,93.76598808777156,0.35355611522635844
0.03635754220731682,0.08206361272254452,438.4531019019808,93.76598808777156,0.35355611522635844
0.03668935764531883,0.0828125625125025,439.55695715993426,93.76598808777156,0.35355611522635844
0.03672338999793442,0.08288937787557511,439.6699525002966,93.76598808777156,0.35355611522635844
0.036970124554397465,0.08344628925785158,440.48795086309906,93.76598808777156,0.35355611522635844
0.036987140730705255,0.08348469693938788,440.5442859385455,93.76598808777156,0.35355611522635844
0.03701266499516695,0.08354230846169235,440.6287696033929,93.76598808777156,0.35355611522635844
0.037089237788552026,0.08371514302860572,440.8820843732396,93.76598808777156,0.35355611522635844
0.037242383375322194,0.0840608121624325,441.388102852895,93.76598808777156,0.35355611522635844
0.03775286866455606,0.08521304260852171,443.069000658533,93.76598808777156,0.35355611522635844
0.03788899807501842,0.08552030406081217,443.5157400502518,93.76598808777156,0.35355611522635844
0.03820379733671264,0.08623084616923385,444.54643423821165,93.76598808777156,0.35355611522635844
0.038229321601174336,0.08628845769153831,444.62985859249665,93.76598808777156,0.35355611522635844
0.03828037013009772,0.08640368073614724,444.79664216154094,93.76598808777156,0.35355611522635844
0.03842500762871398,0.08673014602920584,445.2687252093112,93.76598808777156,0.35355611522635844
0.03851008851025296,0.08692218443688739,445.5460973921644,93.76598808777156,0.35355611522635844
0.038603677479945836,0.08713342668533708,445.8509309033409,93.76598808777156,0.35355611522635844
0.0387398068904082,0.08744068813762754,446.29381109852443,93.76598808777156,0.35355611522635844
0.03906311424025632,0.08817043408681736,447.34322613744195,93.76598808777156,0.35355611522635844
0.039233276003334275,0.08855451090218044,447.8941889843993,93.76598808777156,0.35355611522635844
0.039394929678258334,0.08891938387677537,448.41674110689974,93.76598808777156,0.35355611522635844
0.03942896203087392,0.08899619923984797,448.52664544619375,93.76598808777156,0.35355611522635844
0.039548075265028494,0.08926505301060213,448.9110196290467,93.76598808777156,0.35355611522635844
0.04010960908318575,0.09053250650130026,450.71702277698944,93.76598808777156,0.35355611522635844
0.04013513334764744,0.09059011802360473,450.7988787172038,93.76598808777156,0.35355611522635844
0.04019468996472472,0.0907245449089818,450.9897969987669,93.76598808777156,0.35355611522635844
0.04040739216857217,0.09120464092818564,451.6707492372833,93.76598808777156,0.35355611522635844
0.0406626348131891,0.09178075615123026,452.4860494046652,93.76598808777156,0.35355611522635844
0.04073920760657418,0.09195359071814363,452.7302499358571,93.76598808777156,0.35355611522635844
0.041028482603806704,0.09260652130426085,453.65117426236213,93.76598808777156,0.35355611522635844
0.04107953113273009,0.09272174434886978,453.8134271049474,93.76598808777156,0.35355611522635844
0.04110505539719179,0.09277935587117424,453.894524036849,93.76598808777156,0.35355611522635844
0.04125820098396194,0.093125025005001,454.38069384379077,93.76598808777156,0.35355611522635844
0.0414538870115016,0.09356671334266854,455.0008878481076,93.76598808777156,0.35355611522635844
0.04156449215750227,0.09381636327265454,455.350927204052,93.76598808777156,0.35355611522635844
0.04167509730350294,0.09406601320264053,455.7006034739057,93.76598808777156,0.35355611522635844
0.041692113479810736,0.09410442088417684,455.75436768196187,93.76598808777156,0.35355611522635844
0.041853767154734794,0.09446929385877176,456.26470155287785,93.76598808777156,0.35355611522635844
0.04199840465335106,0.09479575915183037,456.7206648303734,93.76598808777156,0.35355611522635844
0.04228767965058358,0.0954486897379476,457.6307583006248,93.76598808777156,0.35355611522635844
0.042432317149199844,0.09577515503100621,458.0848943048417,93.76598808777156,0.35355611522635844
0.04267905170566288,0.09633206641328267,458.8582060118466,93.76598808777156,0.35355611522635844
0.04281518111612524,0.09663932786557312,459.28411434184505,93.76598808777156,0.35355611522635844
0.042959818614741505,0.09696579315863173,459.7360636872603,93.76598808777156,0.35355611522635844
0.04321506125935844,0.09754190838167634,460.53217637029604,93.76598808777156,0.35355611522635844
0.04341074728689809,0.09798359671934387,461.1412881527412,93.76598808777156,0.35355611522635844
0.04355538478551435,0.09831006201240249,461.5908131853744,93.76598808777156,0.35355611522635844
0.043623449490745536,0.09846369273854771,461.80215289683287,93.76598808777156,0.35355611522635844
0.04370002228413061,0.0986365273054611,462.03975641321824,93.76598808777156,0.35355611522635844
0.043895708311670265,0.09907821564312863,462.64622889126656,93.76598808777156,0.35355611522635844
0.04409139433920991,0.09951990398079616,463.2516478616547,93.76598808777156,0.35355611522635844
0.0441339347799794,0.09961592318463693,463.3831219121821,93.76598808777156,0.35355611522635844
0.04422752374967227,0.09982716543308662,463.6721909781892,93.76598808777156,0.35355611522635844