File: datasets/aisi_316_L/data/M1/train_47.csv
Time(s),Strain(%),Stress(MPa),Temp(C),Log_SR(s-1)
0.0,0.0,0.0,293.8059227415904,-0.651086813010564
2.149453480699229e-05,4.8e-06,0.855314175,293.8059227415904,-0.651086813010564
8.95605616958012e-05,1.9999999999999998e-05,3.5638090625,293.8059227415904,-0.651086813010564
0.0002149453480699229,4.8e-05,8.55314175,293.8059227415904,-0.651086813010564
0.00025793441768390745,5.76e-05,10.2637701,293.8059227415904,-0.651086813010564
0.000300923487297892,6.72e-05,11.974398449999999,293.8059227415904,-0.651086813010564
0.000444220386011174,9.92e-05,17.67649295,293.8059227415904,-0.651086813010564
0.0005051215679643188,0.00011279999999999999,20.0998831125,293.8059227415904,-0.651086813010564
0.0005588579049817995,0.0001248,22.23816855,293.8059227415904,-0.651086813010564
0.0007021548036950814,0.0001568,27.94026305,293.8059227415904,-0.651086813010564
0.0008311220125370351,0.00018559999999999998,33.0721481,293.8059227415904,-0.651086813010564
0.0009063528843615081,0.0002024,36.0657477125,293.8059227415904,-0.651086813010564
0.0010102431359286376,0.00022559999999999998,40.199766225,293.8059227415904,-0.651086813010564
0.0010926388526887748,0.000244,43.4784705625,293.8059227415904,-0.651086813010564
0.0012144412165950643,0.0002712,48.3252508875,293.8059227415904,-0.651086813010564
0.001261012708676881,0.0002816,50.1784316,293.8059227415904,-0.651086813010564
0.001339826002969186,0.0002992,53.314583575,293.8059227415904,-0.651086813010564
0.0013756502276475065,0.0003072,54.7401072,293.8059227415904,-0.651086813010564
0.0014867053241503,0.000332,59.1592304375,293.8059227415904,-0.651086813010564
0.0015476065061034447,0.0003456,61.5826206,293.8059227415904,-0.651086813010564
0.0017338924744307112,0.0003872,68.99534345,293.8059227415904,-0.651086813010564
0.0018377827259978407,0.0004104,73.1293619625,293.8059227415904,-0.651086813010564
0.0019452554000328021,0.0004344,77.4059328375,293.8059227415904,-0.651086813010564
0.0019918268921146186,0.00044479999999999997,79.25911355,293.8059227415904,-0.651086813010564
0.002088552298746084,0.00046639999999999995,83.10802733749999,293.8059227415904,-0.651086813010564
0.0021315413683600684,0.00047599999999999997,84.8186556875,293.8059227415904,-0.651086813010564
0.002217519507588038,0.0004952,88.2399123875,293.8059227415904,-0.651086813010564
0.002249761309798526,0.0005024,89.52288365,293.8059227415904,-0.651086813010564
0.0022605085772020223,0.0005048,89.9505407375,293.8059227415904,-0.651086813010564
0.0024754539252719453,0.0005528,98.5036824875,293.8059227415904,-0.651086813010564
0.0025076957274824336,0.00056,99.78665374999999,293.8059227415904,-0.651086813010564
0.0025399375296929223,0.0005672,101.0696250125,293.8059227415904,-0.651086813010564
0.00265815747113138,0.0005936,105.773852975,293.8059227415904,-0.651086813010564
0.0027978719473768297,0.0006248,111.3333951125,293.8059227415904,-0.651086813010564
0.002923256733750951,0.0006527999999999999,116.32272779999998,293.8059227415904,-0.651086813010564
0.0029483336910257757,0.0006584,117.3205943375,293.8059227415904,-0.651086813010564
0.003145366926756538,0.0007023999999999999,125.16097427499999,293.8059227415904,-0.651086813010564
0.0032349274884523396,0.0007224,128.72478333749999,293.8059227415904,-0.651086813010564
0.0032635868681949957,0.0007287999999999999,129.8652022375,293.8059227415904,-0.651086813010564
0.003292246247937652,0.0007352,131.0056211375,293.8059227415904,-0.651086813010564
0.003360312274826461,0.0007503999999999999,133.71411602499998,293.8059227415904,-0.651086813010564
0.0034606201039257584,0.0007727999999999999,137.705582175,293.8059227415904,-0.651086813010564
0.003593169735235544,0.0008024,142.9800195875,293.8059227415904,-0.651086813010564
0.0036074994251068726,0.0008056,143.5502290375,293.8059227415904,-0.651086813010564
0.0036433236497851926,0.0008135999999999999,144.97575266249999,293.8059227415904,-0.651086813010564
0.0037006424092705056,0.0008263999999999999,147.2565904625,293.8059227415904,-0.651086813010564
0.0037364666339488265,0.0008344,148.6821140875,293.8059227415904,-0.651086813010564
0.0037615435912236503,0.0008399999999999999,149.67998062499998,293.8059227415904,-0.651086813010564
0.0037722908586271466,0.0008424,150.1076377125,293.8059227415904,-0.651086813010564
0.003869016265258612,0.000864,153.9565515,293.8059227415904,-0.651086813010564
0.003933499869679589,0.0008784,156.522494025,293.8059227415904,-0.651086813010564
0.003954994404486581,0.0008832,157.3778082,293.8059227415904,-0.651086813010564
0.004044554966182382,0.0009031999999999999,160.9416172625,293.8059227415904,-0.651086813010564
0.004094708880732031,0.0009144,162.9373503375,293.8059227415904,-0.651086813010564
0.004216511244638321,0.0009416,167.7841306625,293.8059227415904,-0.651086813010564
0.004284577271527129,0.0009568,170.49262554999999,293.8059227415904,-0.651086813010564
0.004306071806334122,0.0009616,171.347939725,293.8059227415904,-0.651086813010564
0.004413544480369083,0.0009855999999999999,175.62451059999998,293.8059227415904,-0.651086813010564
0.0044386214376439075,0.0009912,176.6223771375,293.8059227415904,-0.651086813010564
0.004528181999339708,0.0010111999999999999,179.83537313833767,293.8059227415904,-0.651086813010564
0.00465356678571383,0.0010391999999999999,179.99745745465347,293.8059227415904,-0.651086813010564
0.004746709769877464,0.00106,180.11676252310767,293.8059227415904,-0.651086813010564
0.004778951572087952,0.0010672,180.15784724912567,293.8059227415904,-0.651086813010564
0.004875676978719418,0.0010888,180.28045766636782,293.8059227415904,-0.651086813010564
0.0049222484708012345,0.0010992,180.33915366116724,293.8059227415904,-0.651086813010564
0.00493299573820473,0.0011015999999999999,180.3526680857443,293.8059227415904,-0.651086813010564
0.005011809032497035,0.0011191999999999999,180.45142537097027,293.8059227415904,-0.651086813010564
0.005069127791982348,0.001132,180.52286882494855,293.8059227415904,-0.651086813010564
0.0051228641289998295,0.001144,180.58956145617142,293.8059227415904,-0.651086813010564
0.0052375016479704545,0.0011696,180.73093398865848,293.8059227415904,-0.651086813010564
0.005269743450180943,0.0011768,180.77047691102067,293.8059227415904,-0.651086813010564
0.005398710659022897,0.0012056,180.92771407154774,293.8059227415904,-0.651086813010564
0.005524095445397018,0.0012335999999999998,181.0791850418063,293.8059227415904,-0.651086813010564
0.005638732964367644,0.0012592,181.2165034306941,293.8059227415904,-0.651086813010564
0.0056530626542389715,0.0012624,181.2335913435596,293.8059227415904,-0.651086813010564
0.005728293526063444,0.0012791999999999999,181.32302724385477,293.8059227415904,-0.651086813010564
0.005753370483338269,0.0012848,181.35273725958265,293.8059227415904,-0.651086813010564
0.005774865018145261,0.0012896,181.3781628132562,293.8059227415904,-0.651086813010564
0.005785612285548758,0.001292,181.39086174765973,293.8059227415904,-0.651086813010564
0.00582501893269491,0.0013008,181.43734600563943,293.8059227415904,-0.651086813010564
0.005835766200098407,0.0013032,181.4500022248551,293.8059227415904,-0.651086813010564
0.005860843157373231,0.0013088,181.47949810539683,293.8059227415904,-0.651086813010564
0.005993392788683017,0.0013384,181.63459477731,293.8059227415904,-0.651086813010564
0.006075788505443154,0.0013568,181.73033222787683,293.8059227415904,-0.651086813010564
0.0060972830402501454,0.0013616,181.75522377233762,293.8059227415904,-0.651086813010564
0.006211920559220771,0.0013871999999999999,181.8874051393426,293.8059227415904,-0.651086813010564
0.0062656568962382525,0.0013992,181.9490373463082,293.8059227415904,-0.651086813010564
0.006358799880401886,0.00142,182.05538038619866,293.8059227415904,-0.651086813010564
0.006373129570273213,0.0014232,182.07168677651657,293.8059227415904,-0.651086813010564
0.006441195597162022,0.0014383999999999998,182.14894770253437,293.8059227415904,-0.651086813010564
0.006527173736389991,0.0014575999999999999,182.24608683301653,293.8059227415904,-0.651086813010564
0.006573745228471808,0.001468,182.29849545025797,293.8059227415904,-0.651086813010564
0.006591657340810969,0.001472,182.3186140291674,293.8059227415904,-0.651086813010564
0.0066382288328927855,0.0014824,182.3708228033271,293.8059227415904,-0.651086813010564
0.006760031196799074,0.0015095999999999998,182.50669788647397,293.8059227415904,-0.651086813010564
0.006842426913559211,0.0015279999999999998,182.59807239007287,293.8059227415904,-0.651086813010564
0.0068961632505766925,0.00154,182.6574333552122,293.8059227415904,-0.651086813010564
0.0069821413898046615,0.0015592,182.75203704711234,293.8059227415904,-0.651086813010564
0.007043042571757806,0.0015727999999999998,182.8187733064332,293.8059227415904,-0.651086813010564
0.007157680090728431,0.0015983999999999998,182.9437871193428,293.8059227415904,-0.651086813010564
0.00717200978059976,0.0016016,182.95935875457207,293.8059227415904,-0.651086813010564
0.007218581272681577,0.001612,183.00988297679083,293.8059227415904,-0.651086813010564
0.007261570342295562,0.0016216,183.0564080022052,293.8059227415904,-0.651086813010564
0.007290229722038218,0.0016279999999999999,183.08736502296966,293.8059227415904,-0.651086813010564
0.00732963636918437,0.0016367999999999999,183.12985354124768,293.8059227415904,-0.651086813010564
0.007566076252061286,0.0016895999999999999,183.38293857351673,293.8059227415904,-0.651086813010564
0.007652054391289255,0.0017088,183.4742022844162,293.8059227415904,-0.651086813010564
0.007798933712470368,0.0017415999999999998,183.6291913292256,293.8059227415904,-0.651086813010564
0.007945813033651482,0.0017744,183.783046074788,293.8059227415904,-0.651086813010564
0.00799596694820113,0.0017855999999999998,183.8353272820343,293.8059227415904,-0.651086813010564
0.008157175959253573,0.0018215999999999998,184.00251436410676,293.8059227415904,-0.651086813010564
0.008225241986142382,0.0018368,184.07271699654692,293.8059227415904,-0.651086813010564
0.008329132237709511,0.0018599999999999999,184.1794331353662,293.8059227415904,-0.651086813010564
0.008357791617452167,0.0018663999999999998,184.2087805529468,293.8059227415904,-0.651086813010564
0.008436604911744474,0.0018839999999999998,184.28928427634833,293.8059227415904,-0.651086813010564
0.00848317640382629,0.0018943999999999999,184.33671680071973,293.8059227415904,-0.651086813010564
0.008608561190200412,0.0019223999999999999,184.46391766768278,293.8059227415904,-0.651086813010564
0.008716033864235372,0.0019463999999999998,184.57237294733784,293.8059227415904,-0.651086813010564
0.008762605356317189,0.0019568,184.61920812796984,293.8059227415904,-0.651086813010564
0.008891572565159144,0.0019856,184.74840161188436,293.8059227415904,-0.651086813010564
0.009031287041404594,0.0020168,184.8875392680121,293.8059227415904,-0.651086813010564
0.00911368275816473,0.0020352,184.96920131226952,293.8059227415904,-0.651086813010564
0.009228320277135355,0.0020608,185.08234069736147,293.8059227415904,-0.651086813010564
0.009260562079345844,0.002068,185.1140622189843,293.8059227415904,-0.651086813010564
0.009403858978059126,0.0021,185.25452885439447,293.8059227415904,-0.651086813010564
0.009543573454304576,0.0021311999999999998,185.3906823002358,293.8059227415904,-0.651086813010564
0.009604474636257722,0.0021448,185.44978771908677,293.8059227415904,-0.651086813010564
0.009643881283403873,0.0021536,185.4879545296661,293.8059227415904,-0.651086813010564
0.009679705508082195,0.0021616,185.52259888267199,293.8059227415904,-0.651086813010564
0.009701200042889185,0.0021663999999999997,185.5433614929888,293.8059227415904,-0.651086813010564
0.009747771534971004,0.0021768,185.5882857007201,293.8059227415904,-0.651086813010564
0.009790760604584987,0.0021864,185.62967996057202,293.8059227415904,-0.651086813010564
0.009840914519134637,0.0021976,185.67788378119658,293.8059227415904,-0.651086813010564
0.009880321166280789,0.0022064,185.71569102983747,293.8059227415904,-0.651086813010564
0.009948387193169596,0.0022216,185.78085623654596,293.8059227415904,-0.651086813010564
0.009973464150444422,0.0022272,185.8048206090032,293.8059227415904,-0.651086813010564
0.010020035642526237,0.0022375999999999997,185.84926361893568,293.8059227415904,-0.651086813010564
0.010030782909929734,0.00224,185.8595082490817,293.8059227415904,-0.651086813010564
0.010066607134608056,0.002248,185.8936261415846,293.8059227415904,-0.651086813010564
0.01009526651435071,0.0022543999999999997,185.9208863743237,293.8059227415904,-0.651086813010564
0.01014542042890036,0.0022656,185.96851926845724,293.8059227415904,-0.651086813010564
0.01023139856812833,0.0022848,186.04996255463348,293.8059227415904,-0.651086813010564
0.010288717327613642,0.0022976,186.1041098417993,293.8059227415904,-0.651086813010564
0.010414102113987763,0.0023255999999999997,186.22214856971263,293.8059227415904,-0.651086813010564
0.01044276149373042,0.002332,186.2490508746046,293.8059227415904,-0.651086813010564
0.01047858571840874,0.00234,186.2826382982687,293.8059227415904,-0.651086813010564
0.01054665174529755,0.0023552,186.34633128245278,293.8059227415904,-0.651086813010564
0.010697113488946496,0.0023888,186.48656017883204,293.8059227415904,-0.651086813010564
0.010732937713624815,0.0023967999999999997,186.51983437693983,293.8059227415904,-0.651086813010564
0.010779509205706634,0.0024072,186.56302615166734,293.8059227415904,-0.651086813010564
0.010865487344934602,0.0024264,186.64257409714347,293.8059227415904,-0.651086813010564
0.010933553371823411,0.0024416,186.70537558660837,293.8059227415904,-0.651086813010564
0.010976542441437394,0.0024511999999999997,186.7449611352877,293.8059227415904,-0.651086813010564
0.011026696355987044,0.0024624,186.7910679373145,293.8059227415904,-0.651086813010564
0.011155663564828997,0.0024912,186.90925429409134,293.8059227415904,-0.651086813010564
0.011238059281589134,0.0025096,186.9844833567096,293.8059227415904,-0.651086813010564
0.011395685870173745,0.0025448,187.12780313079486,293.8059227415904,-0.651086813010564
0.011413597982512905,0.0025488,187.14404040126,293.8059227415904,-0.651086813010564
0.011467334319530386,0.0025608,187.19269268892285,293.8059227415904,-0.651086813010564
0.011531817923951361,0.0025751999999999997,187.25095822416273,293.8059227415904,-0.651086813010564
0.011589136683436677,0.002588,187.30264322369945,293.8059227415904,-0.651086813010564
0.011628543330582828,0.0025968,187.33811884396735,293.8059227415904,-0.651086813010564
0.011675114822664645,0.0026072,187.37998418655167,293.8059227415904,-0.651086813010564
0.011725268737214294,0.0026184,187.42499716960336,293.8059227415904,-0.651086813010564
0.011782587496699606,0.0026311999999999998,187.47634873362495,293.8059227415904,-0.651086813010564
0.011854235946056247,0.0026471999999999997,187.54040138957964,293.8059227415904,-0.651086813010564
0.011972455887494704,0.0026736,187.64575916301123,293.8059227415904,-0.651086813010564
0.012029774646980016,0.0026864,187.69669560684585,293.8059227415904,-0.651086813010564
0.012112170363740155,0.0027048,187.7697512305458,293.8059227415904,-0.651086813010564
0.012158741855821971,0.0027152,187.81095779978233,293.8059227415904,-0.651086813010564
0.012190983658032459,0.0027224,187.83944937302437,293.8059227415904,-0.651086813010564
0.012212478192839452,0.0027272,187.85842743057205,293.8059227415904,-0.651086813010564
0.012309203599470919,0.0027488,187.94366799483535,293.8059227415904,-0.651086813010564
0.012380852048827558,0.0027648,188.0066408318034,293.8059227415904,-0.651086813010564
0.012409511428570214,0.0027711999999999997,188.03179015200266,293.8059227415904,-0.651086813010564
0.012613709509236641,0.0028168,188.21032794269814,293.8059227415904,-0.651086813010564
0.012710434915868107,0.0028384,188.29450472322765,293.8059227415904,-0.651086813010564
0.012753423985482092,0.002848,188.3318363961498,293.8059227415904,-0.651086813010564
0.012792830632628245,0.0028568,188.36601400664475,293.8059227415904,-0.651086813010564
0.012850149392113557,0.0028696,188.41565369036783,293.8059227415904,-0.651086813010564
0.012950457221212854,0.002892,188.5023158478068,293.8059227415904,-0.651086813010564
0.012971951756019845,0.0028967999999999997,188.5208522066104,293.8059227415904,-0.651086813010564
0.013043600205376486,0.0029127999999999997,188.58255373836423,293.8059227415904,-0.651086813010564
0.013136743189540119,0.0029335999999999997,188.66256847908173,293.8059227415904,-0.651086813010564
0.01317256741421844,0.0029416,188.69328442681245,293.8059227415904,-0.651086813010564
0.013183314681621938,0.002944,188.702492856029,293.8059227415904,-0.651086813010564
0.013269292820849907,0.0029632,188.77605518756795,293.8059227415904,-0.651086813010564
0.013337358847738715,0.0029784,188.83416028184104,293.8059227415904,-0.651086813010564
0.013459161211645004,0.0030055999999999998,188.93784999959456,293.8059227415904,-0.651086813010564
0.01350215028125899,0.0030152,188.97435891153717,293.8059227415904,-0.651086813010564
0.013548721773340806,0.0030256,189.01385911320588,293.8059227415904,-0.651086813010564
0.013566633885679967,0.0030296,189.02903739432307,293.8059227415904,-0.651086813010564
0.013620370222697447,0.0030415999999999998,189.07452541339876,293.8059227415904,-0.651086813010564
0.013652612024907935,0.0030488,189.1017846304915,293.8059227415904,-0.651086813010564
0.013699183516989752,0.0030591999999999998,189.14111477368942,293.8059227415904,-0.651086813010564
0.013731425319200241,0.0030664,189.16831279307604,293.8059227415904,-0.651086813010564
0.013813821035960377,0.0030848,189.2377059314102,293.8059227415904,-0.651086813010564
0.013846062838170865,0.0030919999999999997,189.26481580328334,293.8059227415904,-0.651086813010564
0.01385681010557436,0.0030943999999999998,189.27384695471332,293.8059227415904,-0.651086813010564
0.013914128865059676,0.0031072,189.3219670379125,293.8059227415904,-0.651086813010564
0.013953535512205828,0.003116,189.35500475884973,293.8059227415904,-0.651086813010564
0.01397503004701282,0.0031208,189.37300999606452,293.8059227415904,-0.651086813010564
0.014057425763772956,0.0031392,189.44193024980743,293.8059227415904,-0.651086813010564
0.014129074213129597,0.0031552,189.50173294261666,293.8059227415904,-0.651086813010564
0.014172063282743582,0.0031647999999999997,189.53755779080493,293.8059227415904,-0.651086813010564
0.014200722662486238,0.0031712,189.56141748065025,293.8059227415904,-0.651086813010564
0.014333272293796023,0.0032007999999999997,189.67152518403745,293.8059227415904,-0.651086813010564
0.014422832855491825,0.0032208,189.74569756230002,293.8059227415904,-0.651086813010564
0.014530305529526787,0.0032448,189.83446772852568,293.8059227415904,-0.651086813010564
0.014541052796930284,0.0032472,189.84333063820273,293.8059227415904,-0.651086813010564
0.014655690315900909,0.0032727999999999998,189.937709927695,293.8059227415904,-0.651086813010564
0.014677184850707901,0.0032776,189.95537394591122,293.8059227415904,-0.651086813010564
0.01472733876525755,0.0032887999999999997,189.99655080080313,293.8059227415904,-0.651086813010564
0.014809734482017686,0.0033071999999999997,190.06407996455928,293.8059227415904,-0.651086813010564
0.01493870169085964,0.003336,190.16948437007525,293.8059227415904,-0.651086813010564
0.014960196225666631,0.0033407999999999997,190.18701721090162,293.8059227415904,-0.651086813010564
0.01498885560540929,0.0033472,190.21037905720743,293.8059227415904,-0.651086813010564
0.015081998589572923,0.003368,190.28618502835647,293.8059227415904,-0.651086813010564
0.015096328279444252,0.0033712,190.29783126011355,293.8059227415904,-0.651086813010564
0.015128570081654738,0.0033783999999999997,190.32401952968107,293.8059227415904,-0.651086813010564
0.01530410878257851,0.0034176,190.46622007236917,293.8059227415904,-0.651086813010564
0.015336350584788999,0.0034248,190.49226924515875,293.8059227415904,-0.651086813010564
0.015379339654402982,0.0034343999999999998,190.526968276705,293.8059227415904,-0.651086813010564
0.01549755959584144,0.0034608,190.62219611358125,293.8059227415904,-0.651086813010564
0.015529801398051928,0.0034679999999999997,190.64811811944233,293.8059227415904,-0.651086813010564
0.015594285002472905,0.0034823999999999996,190.69989925073403,293.8059227415904,-0.651086813010564
0.015662351029361716,0.0034976,190.7544665996745,293.8059227415904,-0.651086813010564
0.015751911591057516,0.0035175999999999996,190.8261250460477,293.8059227415904,-0.651086813010564
0.01582356004041416,0.0035336,190.88333746331432,293.8059227415904,-0.651086813010564
0.01584863699768898,0.0035391999999999997,190.90333792910272,293.8059227415904,-0.651086813010564
0.015923867869513452,0.0035559999999999997,190.9632654051559,293.8059227415904,-0.651086813010564
0.015974021784063104,0.0035672,191.00315572434363,293.8059227415904,-0.651086813010564
0.016042087810951913,0.0035824,191.05721454668125,293.8059227415904,-0.651086813010564
0.016171055019793865,0.0036111999999999997,191.15939710248637,293.8059227415904,-0.651086813010564
0.01621404408940785,0.0036208,191.1933872629644,293.8059227415904,-0.651086813010564
0.01630002222863582,0.00364,191.2612623272302,293.8059227415904,-0.651086813010564
0.016489890619430916,0.0036823999999999997,191.41066040946959,293.8059227415904,-0.651086813010564
0.01668692385516168,0.0037264,191.56498853680299,293.8059227415904,-0.651086813010564
0.01679797895166447,0.0037511999999999997,191.65166028140936,293.8059227415904,-0.651086813010564
0.016855297711149787,0.003764,191.69630663222048,293.8059227415904,-0.651086813010564
0.016923363738038596,0.0037792,191.74924734083535,293.8059227415904,-0.651086813010564
0.01696993523012041,0.0037895999999999997,191.78542209326,293.8059227415904,-0.651086813010564
0.01698784734245957,0.0037936,191.7993251475583,293.8059227415904,-0.651086813010564
0.017027253989605723,0.0038023999999999996,191.8298917583876,293.8059227415904,-0.651086813010564
0.017113232128833693,0.0038215999999999997,191.89648694604412,293.8059227415904,-0.651086813010564
0.01717055088831901,0.0038344,191.94081126019765,293.8059227415904,-0.651086813010564
0.017181298155722502,0.0038368,191.94911564092777,293.8059227415904,-0.651086813010564
0.017242199337675648,0.0038504,191.99613558806166,293.8059227415904,-0.651086813010564
0.017274441139886135,0.0038575999999999997,192.021002276958,293.8059227415904,-0.651086813010564
0.01729951809716096,0.0038632,192.04033052299508,293.8059227415904,-0.651086813010564
0.01745714468574557,0.0038983999999999998,192.16157310478528,293.8059227415904,-0.651086813010564
0.017485804065488227,0.0039048,192.18357126334814,293.8059227415904,-0.651086813010564
0.01752879313510221,0.0039144,192.21654215425568,293.8059227415904,-0.651086813010564
0.017550287669909202,0.003919199999999999,192.23301577278212,293.8059227415904,-0.651086813010564
0.017672090033815493,0.0039464,192.32621807599173,293.8059227415904,-0.651086813010564
0.017851211157207097,0.0039864,192.4628264580275,293.8059227415904,-0.651086813010564
0.01785837600214276,0.003988,192.46827964581632,293.8059227415904,-0.651086813010564
0.018944056398707783,0.004230446089217844,193.28500126191074,293.8059227415904,-0.651086813010564
0.019374033090185924,0.004326465293058612,193.60338589180182,293.8059227415904,-0.651086813010564
0.020319981811437834,0.004537707541508302,194.29428854726893,293.8059227415904,-0.651086813010564
0.02255586060712417,0.0050370074014802965,195.8792615404049,293.8059227415904,-0.651086813010564
0.023243823313489197,0.005190638127625526,196.35445135448654,293.8059227415904,-0.651086813010564
0.024361762711332367,0.005440288057611523,197.11509818031624,293.8059227415904,-0.651086813010564
0.02496373007940176,0.0055747149429885975,197.51903242624013,293.8059227415904,-0.651086813010564
0.0259956741389493,0.005805161032206441,198.20276220426342,293.8059227415904,-0.651086813010564
0.02651164616872307,0.005920384076815363,198.54065111996718,293.8059227415904,-0.651086813010564
0.029865464362252573,0.006669333866773355,200.67752159658448,293.8059227415904,-0.651086813010564
0.03003745503884383,0.006707741548309662,200.78450841007825,293.8059227415904,-0.651086813010564
0.0305534270686176,0.006822964592918584,201.10404449341982,293.8059227415904,-0.651086813010564
0.030725417745208858,0.006861372274454891,201.21008793928175,293.8059227415904,-0.651086813010564
0.03192935248134765,0.007130226045209041,201.9460154860083,293.8059227415904,-0.651086813010564
0.03433722195362524,0.007667933586717343,203.38617185357182,293.8059227415904,-0.651086813010564
0.03597113338124218,0.008032806561312262,204.34104732862676,293.8059227415904,-0.651086813010564
0.038636988868406656,0.008628125625125025,205.8634512022228,293.8059227415904,-0.651086813010564
0.04147483503216239,0.009261852370474095,207.4397050770554,293.8059227415904,-0.651086813010564
0.04500064390228315,0.010049209841968394,209.34063240269862,293.8059227415904,-0.651086813010564
0.04594659262353506,0.010260452090418083,209.84063662456077,293.8059227415904,-0.651086813010564
0.04706453202137823,0.010510102020404082,210.42640383968862,293.8059227415904,-0.651086813010564
0.04766649938944762,0.010644528905781155,210.73956817009253,293.8059227415904,-0.651086813010564
0.04912842014047331,0.010970994198839769,211.4937568719799,293.8059227415904,-0.651086813010564
0.05024635953831647,0.011220644128825764,212.06459800268158,293.8059227415904,-0.651086813010564
0.052654229010594064,0.011758351670334066,213.27754327207842,293.8059227415904,-0.651086813010564
0.053170201040367834,0.011873574714942988,213.53462328694266,293.8059227415904,-0.651086813010564
0.053858163746732864,0.012027205441088217,213.87588824026147,293.8059227415904,-0.651086813010564
0.054890107806280404,0.01225765153030606,214.3846151454619,293.8059227415904,-0.651086813010564
0.055578070512645426,0.01241128225645129,214.72169566363675,293.8059227415904,-0.651086813010564
0.05712598660196674,0.012756951390278055,215.4742331384168,293.8059227415904,-0.651086813010564
0.05867390269128805,0.013102620524104821,216.21885878379024,293.8059227415904,-0.651086813010564
0.059619851412539955,0.013313862772554511,216.6701373799365,293.8059227415904,-0.651086813010564
0.060307814118904984,0.01346749349869974,216.99658790320845,293.8059227415904,-0.651086813010564
0.06073779081038313,0.013563512702540508,217.19988212207033,293.8059227415904,-0.651086813010564
0.061855730208226295,0.013813162632526505,217.72583753872254,293.8059227415904,-0.651086813010564
0.06323165562095635,0.014120424084816964,218.36810527783166,293.8059227415904,-0.651086813010564
0.06512355306346017,0.014542908581716344,219.2423934264291,293.8059227415904,-0.651086813010564
0.06563952509323394,0.014658131626325266,219.47910925965044,293.8059227415904,-0.651086813010564
0.067015450505964,0.014965393078615724,220.10683027859272,293.8059227415904,-0.651086813010564
0.06821938524210279,0.015234246849369875,220.65197429464374,293.8059227415904,-0.651086813010564
0.06864936193358093,0.015330266053210643,220.84575760328298,293.8059227415904,-0.651086813010564
0.0715732034356323,0.015983196639327867,222.15115170099196,293.8059227415904,-0.651086813010564
0.0721751708037017,0.016117623524704944,222.41730890763708,293.8059227415904,-0.651086813010564
0.0764749377184831,0.017077815563112622,224.29387149390644,293.8059227415904,-0.651086813010564
0.07716290042484812,0.01723144628925785,224.59025984432796,293.8059227415904,-0.651086813010564
0.07879681185246508,0.017596319263852772,225.2900820375084,293.8059227415904,-0.651086813010564
0.07914079320564758,0.017673134626925387,225.43668929263725,293.8059227415904,-0.651086813010564
0.07991475125030824,0.017845969193838768,225.76565001801123,293.8059227415904,-0.651086813010564
0.08240861606088144,0.01840288057611522,226.81728083121982,293.8059227415904,-0.651086813010564
0.08326856944383774,0.01859491898379676,227.17702457500863,293.8059227415904,-0.651086813010564
0.08533245756293283,0.01905581116223245,228.03454858095176,293.8059227415904,-0.651086813010564
0.08610641560759347,0.01922864572914583,228.3540297977099,293.8059227415904,-0.651086813010564
0.08791231771180166,0.019631926385277054,229.0951620762407,293.8059227415904,-0.651086813010564
0.08980421515430548,0.020054410882176434,229.8652457611068,293.8059227415904,-0.651086813010564
0.09161011725851369,0.020457691538307662,230.59444450207647,293.8059227415904,-0.651086813010564
0.09418997740738254,0.02103380676135227,231.62650595176353,293.8059227415904,-0.651086813010564
0.09496393545204318,0.021206641328265653,231.93396681122212,293.8059227415904,-0.651086813010564
0.09977967439659836,0.022282056411282256,233.82555250859687,293.8059227415904,-0.651086813010564
0.1010696044710328,0.022570114022804563,234.32613783913578,293.8059227415904,-0.651086813010564
0.1038214552964929,0.02318463692738548,235.38580074647743,293.8059227415904,-0.651086813010564
0.10476740401774481,0.023395879175835167,235.74752248425528,293.8059227415904,-0.651086813010564
0.10648731078365738,0.02377995599119824,236.40195179972065,293.8059227415904,-0.651086813010564
0.11001311965377812,0.024567313462692537,237.73078354717117,293.8059227415904,-0.651086813010564
0.11095906837503004,0.02477855571114223,238.08446019285336,293.8059227415904,-0.651086813010564
0.11551682130469834,0.02579635927185437,239.77232571743434,293.8059227415904,-0.651086813010564
0.11672075604083713,0.02606521304260852,240.21381490030635,293.8059227415904,-0.651086813010564
0.11783869543868031,0.02631486297259452,240.62218153120185,293.8059227415904,-0.651086813010564
0.1202465649109579,0.026852570514102822,241.49664367899678,293.8059227415904,-0.651086813010564
0.12643822926824314,0.028235247049409884,243.71446391857052,293.8059227415904,-0.651086813010564
0.1324579029489371,0.029579515903180635,245.83041165798065,293.8059227415904,-0.651086813010564
0.13383382836166716,0.029886777355471093,246.30875109006513,293.8059227415904,-0.651086813010564
0.1363276931722404,0.03044368873774755,247.17088122977114,293.8059227415904,-0.651086813010564
0.13684366520201416,0.030558911782356472,247.34848260572358,293.8059227415904,-0.651086813010564
0.13761762324667481,0.030731746349269853,247.61439577265148,293.8059227415904,-0.651086813010564
0.13856357196792674,0.030942988597719545,247.9386100184857,293.8059227415904,-0.651086813010564
0.13976750670406551,0.031211842368473696,248.35000060965473,293.8059227415904,-0.651086813010564
0.14191739016145621,0.03169193838767753,249.0812056126656,293.8059227415904,-0.651086813010564
0.14234736685293436,0.031787957591518305,249.2269268215876,293.8059227415904,-0.651086813010564
0.14535720369328134,0.03246009201840368,250.24221131004364,293.8059227415904,-0.651086813010564
0.14707711045919394,0.03284416883376676,250.81869224983814,293.8059227415904,-0.651086813010564
0.14793706384215022,0.03303620724144829,251.10594636443247,293.8059227415904,-0.651086813010564
0.14862502654851523,0.03318983796759352,251.33528105292476,293.8059227415904,-0.651086813010564
0.14965697060806277,0.03342028405681136,251.67850834840252,293.8059227415904,-0.651086813010564
0.1506889146676103,0.033650730146029206,252.0208138667786,293.8059227415904,-0.651086813010564
0.15189284940374911,0.03391958391678336,252.4190169635938,293.8059227415904,-0.651086813010564
0.15240882143352288,0.03403480696139228,252.58929840619382,293.8059227415904,-0.651086813010564
0.15292479346329663,0.0341500300060012,252.759355169888,293.8059227415904,-0.651086813010564
0.1557626396270524,0.03478375675135027,253.69069787027377,293.8059227415904,-0.651086813010564
0.15748254639296494,0.03516783356671334,254.25192791127165,293.8059227415904,-0.651086813010564
0.1579985184227387,0.035283056611322264,254.4198301234368,293.8059227415904,-0.651086813010564
0.15989041586524255,0.03570554110822165,255.033650511756,293.8059227415904,-0.651086813010564
0.16083636458649447,0.03591678335667134,255.3394980138335,293.8059227415904,-0.651086813010564
0.16272826202899823,0.03633926785357071,255.94909648201156,293.8059227415904,-0.651086813010564
0.16350222007365892,0.0365121024204841,256.19768027451664,293.8059227415904,-0.651086813010564
0.1660820802225278,0.03708821764352871,257.0229983689579,293.8059227415904,-0.651086813010564
0.1683179590182141,0.0375875175035007,257.7342378993096,293.8059227415904,-0.651086813010564
0.16926390773946604,0.03779875975195039,258.0340366296186,293.8059227415904,-0.651086813010564
0.17141379119685676,0.03827885577115424,258.7129778478568,293.8059227415904,-0.651086813010564
0.1716717772117436,0.03833646729345869,258.79422702481514,293.8059227415904,-0.651086813010564
0.17313369796276928,0.038662932586517304,259.25374272660076,293.8059227415904,-0.651086813010564
0.17726147420095945,0.03958471694338868,260.54310116734933,293.8059227415904,-0.651086813010564
0.1788953856285764,0.0399495899179836,261.0502307713643,293.8059227415904,-0.651086813010564
0.18035730637960204,0.0402760552110422,261.5024491494468,293.8059227415904,-0.651086813010564
0.18328114788165345,0.04092898579715944,262.4026198637375,293.8059227415904,-0.651086813010564
0.18723693344325232,0.041812362472494494,263.6116337386722,293.8059227415904,-0.651086813010564
0.1889568402091649,0.04219643928785757,264.13418023429944,293.8059227415904,-0.651086813010564
0.19084873765166874,0.04261892378475696,264.70684357365724,293.8059227415904,-0.651086813010564
0.19540649058133702,0.0436367273454691,266.0774254277559,293.8059227415904,-0.651086813010564
0.19609445328770206,0.04379035807161433,266.2832176514306,293.8059227415904,-0.651086813010564
0.1980723460685015,0.044232046409281855,266.87330765442033,293.8059227415904,-0.651086813010564
0.19850232275997962,0.04432806561312262,267.0012834862469,293.8059227415904,-0.651086813010564
0.1998782481727097,0.04463532706541308,267.4100815417596,293.8059227415904,-0.651086813010564
0.2010821829088485,0.044904180836167235,267.76688039274734,293.8059227415904,-0.651086813010564
0.20245810832157854,0.04521144228845769,268.1736319231497,293.8059227415904,-0.651086813010564
0.20306007568964793,0.04534586917383476,268.35124655724707,293.8059227415904,-0.651086813010564
0.2035760477194217,0.04546109221844369,268.5033242936161,293.8059227415904,-0.651086813010564
0.20598391719169934,0.045998799759952,269.2110422467371,293.8059227415904,-0.651086813010564
0.20632789854488182,0.046075615123024605,269.3118808016237,293.8059227415904,-0.651086813010564
0.20649988922147305,0.04611402280456091,269.36227549090233,293.8059227415904,-0.651086813010564
0.20735984260442938,0.046306061212242455,269.6140038131956,293.8059227415904,-0.651086813010564
0.20821979598738566,0.04649809961992399,269.86532532020095,293.8059227415904,-0.651086813010564
0.21062766545966322,0.04703580716143228,270.56688105808826,293.8059227415904,-0.651086813010564
0.21251956290216706,0.04745829165833167,271.11591150467734,293.8059227415904,-0.651086813010564
0.21277754891705394,0.04751590318063613,271.19063133364557,293.8059227415904,-0.651086813010564
0.21355150696171463,0.04768873774754952,271.4145791149383,293.8059227415904,-0.651086813010564
0.21484143703614902,0.04797679535907182,271.7871232779695,293.8059227415904,-0.651086813010564
0.21853923658286104,0.048802560512102425,272.8502789012941,293.8059227415904,-0.651086813010564
0.21922719928922607,0.048956191238247654,273.0472988371282,293.8059227415904,-0.651086813010564
0.22111909673172986,0.04937867573514702,273.58786425484465,293.8059227415904,-0.651086813010564
0.22232303146786866,0.04964752950590118,273.9309214744732,293.8059227415904,-0.651086813010564
0.2261928216911719,0.05051170234046809,275.0287303625591,293.8059227415904,-0.651086813010564
0.2269667797358326,0.05068453690738148,275.2474104859741,293.8059227415904,-0.651086813010564
0.2299766165761796,0.05135667133426686,276.0950829150401,293.8059227415904,-0.651086813010564
0.23315844409311784,0.05206721344268854,276.9865026362535,293.8059227415904,-0.651086813010564
0.23367441612289164,0.052182436487297465,277.13060894508067,293.8059227415904,-0.651086813010564
0.23685624363982988,0.05289297859571915,278.0165378586567,293.8059227415904,-0.651086813010564
0.23797418303767304,0.05314262852570514,278.3267067145583,293.8059227415904,-0.651086813010564
0.23917811777381184,0.0534114822964593,278.66009988249556,293.8059227415904,-0.651086813010564
0.2421879546141588,0.05408361672334466,279.4907321371748,293.8059227415904,-0.651086813010564
0.24304790799711512,0.05427565513102621,279.72731492481705,293.8059227415904,-0.651086813010564
0.24519779145450576,0.05475575115023004,280.3173481015542,293.8059227415904,-0.651086813010564
0.2457997588225752,0.054890178035607126,280.48219539123846,293.8059227415904,-0.651086813010564
0.24648772152894025,0.055043808761752355,280.67039962292097,293.8059227415904,-0.651086813010564
0.247691656265079,0.055312662532506496,280.9992648205867,293.8059227415904,-0.651086813010564
0.25052950242883476,0.05594638927785557,281.7719902715456,293.8059227415904,-0.651086813010564
0.2537973252840686,0.05667613522704541,282.6575792141797,293.8059227415904,-0.651086813010564
0.2557752180648681,0.05711782356471294,283.19143349386195,293.8059227415904,-0.651086813010564
0.2574951248307807,0.05750190038007602,283.6543472413312,293.8059227415904,-0.651086813010564
0.2584410735520326,0.05771314262852571,283.9084357512483,293.8059227415904,-0.651086813010564
0.2600749849796495,0.05807801560312062,284.34646325151897,293.8059227415904,-0.651086813010564
0.2606769523477189,0.058212442488497704,284.50757109806824,293.8059227415904,-0.651086813010564
0.2614509103923795,0.05838527705541108,284.7144967182903,293.8059227415904,-0.651086813010564
0.263428803173179,0.05882696539307862,285.2422242171358,293.8059227415904,-0.651086813010564
0.26506271460079595,0.05919183836767354,285.67700846039713,293.8059227415904,-0.651086813010564
0.2691044955006905,0.06009441888377676,286.7480606554855,293.8059227415904,-0.651086813010564
0.270824402266603,0.06047849569913982,287.2019226106765,293.8059227415904,-0.651086813010564
0.2717703509878549,0.060689737947589514,287.4510674944871,293.8059227415904,-0.651086813010564
0.2735762530920631,0.06109301860372074,287.9257705803758,293.8059227415904,-0.651086813010564
0.27693007128559266,0.06184196839367874,288.8041323206353,293.8059227415904,-0.651086813010564
0.2784779873749139,0.0621876375275055,289.2081298506822,293.8059227415904,-0.651086813010564
0.2800259034642352,0.06253330666133226,289.61125253418487,293.8059227415904,-0.651086813010564
0.28303574030458223,0.06320544108821764,290.3926230084968,293.8059227415904,-0.651086813010564
0.28337972165776476,0.06328225645129026,290.4817156767193,293.8059227415904,-0.651086813010564
0.2857015957917467,0.0638007601520304,291.08199181278854,293.8059227415904,-0.651086813010564
0.2875074978959549,0.06420404080816164,291.54755886200417,293.8059227415904,-0.651086813010564
0.2879374745874331,0.0643000600120024,291.6582398923058,293.8059227415904,-0.651086813010564
0.28931340000016315,0.06460732146429286,292.0119868070366,293.8059227415904,-0.651086813010564
0.29129129278096255,0.06504900980196039,292.51935066743283,293.8059227415904,-0.651086813010564
0.29283920887028386,0.06539467893578715,292.9154814343216,293.8059227415904,-0.651086813010564
0.29361316691494455,0.06556751350270054,293.11324052401045,293.8059227415904,-0.651086813010564
0.2956770550340396,0.06602840568113623,293.63960669569536,293.8059227415904,-0.651086813010564
0.299976821948821,0.06698859771954391,294.7316228138634,293.8059227415904,-0.651086813010564
0.30066478465518603,0.06714222844568914,294.905777304177,293.8059227415904,-0.651086813010564
0.30530853292314997,0.06817923584716944,296.0772814978432,293.8059227415904,-0.651086813010564
0.305996495629515,0.06833286657331467,296.25024484380344,293.8059227415904,-0.651086813010564
0.3072004303656538,0.06860172034406882,296.55256621454726,293.8059227415904,-0.651086813010564
0.3077164023954276,0.06871694338867775,296.68199102517553,293.8059227415904,-0.651086813010564
0.3095223044996358,0.06912022404480897,297.1343128571073,293.8059227415904,-0.651086813010564
0.3121881599868002,0.06971554310862173,297.800149474232,293.8059227415904,-0.651086813010564
0.31494001081226036,0.07033006601320264,298.48514292942826,293.8059227415904,-0.651086813010564
0.3206157031397718,0.07159751950390078,299.8906136388304,293.8059227415904,-0.651086813010564
0.3232815586269363,0.07219283856771355,300.5474066909356,293.8059227415904,-0.651086813010564
0.3245714887013707,0.07248089617923585,300.86445119294893,293.8059227415904,-0.651086813010564
0.32629139546728325,0.07286497299459892,301.2864138430353,293.8059227415904,-0.651086813010564
0.33007519035229094,0.07370994198839768,302.2116902927287,293.8059227415904,-0.651086813010564
0.3311071344118384,0.07394038807761552,302.46331930272845,293.8059227415904,-0.651086813010564
0.3331710225309335,0.07440128025605121,302.96566163826185,293.8059227415904,-0.651086813010564
0.33506291997343735,0.07482376475295059,303.425077004437,293.8059227415904,-0.651086813010564
0.33678282673934995,0.07520784156831367,303.8418501892782,293.8059227415904,-0.651086813010564
0.33893271019674065,0.0756879375875175,304.36165121479104,293.8059227415904,-0.651086813010564
0.33979266357969695,0.07587997599519905,304.5692113852654,293.8059227415904,-0.651086813010564
0.3427165050817483,0.07653290658131627,305.2733886109116,293.8059227415904,-0.651086813010564
0.3488221741007379,0.07789637927585517,306.7363660570184,293.8059227415904,-0.651086813010564
0.3495961321453986,0.07806921384276856,306.9210980506302,293.8059227415904,-0.651086813010564
0.3512300435730155,0.07843408681736348,307.310564849215,293.8059227415904,-0.651086813010564
0.35501383845802315,0.07927905581116224,308.20978518391007,293.8059227415904,-0.651086813010564
0.3561317778558663,0.07952870574114823,308.4747475960154,293.8059227415904,-0.651086813010564
0.35905561935791763,0.08018163632726545,309.1661971156704,293.8059227415904,-0.651086813010564
0.3603455494323521,0.08046969393878776,309.47054990756976,293.8059227415904,-0.651086813010564
0.3612055028153084,0.0806617323464693,309.6732157459678,293.8059227415904,-0.651086813010564
0.36146348883019525,0.08071934386877376,309.7339787917224,293.8059227415904,-0.651086813010564
0.36473131168542916,0.0814490898179636,310.5021858931122,293.8059227415904,-0.651086813010564
0.3678271438640717,0.08214042808561713,311.2274887017372,293.8059227415904,-0.651086813010564
0.3709229760427144,0.08283176635327066,311.95041460911466,293.8059227415904,-0.651086813010564
0.3711809620576012,0.08288937787557511,312.010552010998,293.8059227415904,-0.651086813010564
0.3725568874703313,0.08319663932786557,312.33100993235723,293.8059227415904,-0.651086813010564
0.37307285950010505,0.0833118623724745,312.45106261252255,293.8059227415904,-0.651086813010564
0.37539473363408704,0.08383036607321465,312.99050034402467,293.8059227415904,-0.651086813010564
0.37702864506170397,0.08419523904780957,313.3693249196231,293.8059227415904,-0.651086813010564
0.38055445393182474,0.08498259651930387,314.1846138533036,293.8059227415904,-0.651086813010564
0.38141440731478105,0.0851746349269854,314.383017285938,293.8059227415904,-0.651086813010564
0.3834782954338761,0.08563552710542109,314.85847508377304,293.8059227415904,-0.651086813010564
0.38562817889126677,0.08611562312462492,315.35268361951006,293.8059227415904,-0.651086813010564
0.3868321136274056,0.08638447689537908,315.6289710172558,293.8059227415904,-0.651086813010564
0.3890679924230919,0.08688377675535107,316.1411880977511,293.8059227415904,-0.651086813010564
0.39087389452730015,0.08728705741148231,316.55406432596396,293.8059227415904,-0.651086813010564
0.3929377826463952,0.08774794958991798,317.0250130107332,293.8059227415904,-0.651086813010564
0.3968075728696985,0.08861212242448491,317.9054497233264,293.8059227415904,-0.651086813010564
0.39887146098879356,0.0890730146029206,318.3736464446001,293.8059227415904,-0.651086813010564
0.40308523256527934,0.09001400280056011,319.3266246202779,293.8059227415904,-0.651086813010564
0.40678303211199135,0.09083976795359072,320.1597153732931,293.8059227415904,-0.651086813010564
0.40781497617153895,0.09107021404280857,320.3916780191943,293.8059227415904,-0.651086813010564
0.41048083165870336,0.09166553310662133,320.98985780384635,293.8059227415904,-0.651086813010564
0.4127167104543897,0.09216483296659332,321.4903896345209,293.8059227415904,-0.651086813010564
0.41607052864791916,0.09291378275655131,322.23920906828,293.8059227415904,-0.651086813010564
0.4183064074436056,0.09341308261652331,322.73711463902896,293.8059227415904,-0.651086813010564
0.42037029556270067,0.093873974794959,323.1957993269013,293.8059227415904,-0.651086813010564
0.4249280484923689,0.09489177835567114,324.2056281264781,293.8059227415904,-0.651086813010564
0.4254440205221427,0.09500700140028007,324.3196815717801,293.8059227415904,-0.651086813010564
0.4266479552582815,0.09527585517103421,324.5855966951132,293.8059227415904,-0.651086813010564
0.42793788533271593,0.09556391278255652,324.8701812179742,293.8059227415904,-0.651086813010564
0.4283678620241941,0.09565993198639729,324.96496835551017,293.8059227415904,-0.651086813010564
0.43103371751135855,0.09625525105021004,325.55182256332404,293.8059227415904,-0.651086813010564
0.432323647585793,0.09654330866173236,325.83527595789036,293.8059227415904,-0.651086813010564
0.43387156367511426,0.09688897779555912,326.1749850149503,293.8059227415904,-0.651086813010564
0.43533348442613995,0.09721544308861772,326.49538759738596,293.8059227415904,-0.651086813010564
0.4370533911920525,0.0975995199039808,326.8717950721153,293.8059227415904,-0.651086813010564
0.43842931660478257,0.09790678135627126,327.17250528307983,293.8059227415904,-0.651086813010564
0.44057920006217327,0.09838687737547509,327.6416292165374,293.8059227415904,-0.651086813010564
0.4414391534451296,0.09857891578315664,327.8290287104208,293.8059227415904,-0.651086813010564
0.44255709284297273,0.09882856571314264,328.07243533840915,293.8059227415904,-0.651086813010564
0.44401901359399837,0.09915503100620124,328.3903747954446,293.8059227415904,-0.651086813010564
0.44677086441945846,0.09976955391078215,328.9877437454455,293.8059227415904,-0.651086813010564
0.4473728317875279,0.09990398079615924,329.1182267211534,293.8059227415904,-0.651086813010564