File: datasets/aisi_316_L/data/M1/train_45.csv
Time(s),Strain(%),Stress(MPa),Temp(C),Log_SR(s-1)
0.0,0.0,0.0,69.77282776925438,0.5831482094072413
3.342425686837518e-06,1.28e-05,2.4900644,69.77282776925438,0.5831482094072413
7.938261006239106e-06,3.04e-05,5.91390295,69.77282776925438,0.5831482094072413
1.545871880162352e-05,5.9199999999999996e-05,11.516547849999998,69.77282776925438,0.5831482094072413
1.7965538066751658e-05,6.879999999999999e-05,13.384096149999998,69.77282776925438,0.5831482094072413
2.6530503889272798e-05,0.00010159999999999999,19.764886174999997,69.77282776925438,0.5831482094072413
3.112633920867439e-05,0.0001192,23.188724725,69.77282776925438,0.5831482094072413
3.6139977738930666e-05,0.0001384,26.923821325000002,69.77282776925438,0.5831482094072413
3.6975584160640044e-05,0.0001416,27.546337425,69.77282776925438,0.5831482094072413
3.822899379320411e-05,0.00014639999999999998,28.480111574999995,69.77282776925438,0.5831482094072413
4.031800984747756e-05,0.00015439999999999999,30.036401825,69.77282776925438,0.5831482094072413
4.345153392888773e-05,0.00016639999999999998,32.3708372,69.77282776925438,0.5831482094072413
4.6167254799443216e-05,0.0001768,34.394014524999996,69.77282776925438,0.5831482094072413
4.9091877275426045e-05,0.000188,36.572820875,69.77282776925438,0.5831482094072413
5.6194531859955773e-05,0.0002152,41.864207725,69.77282776925438,0.5831482094072413
5.870135112508391e-05,0.0002248,43.731756024999996,69.77282776925438,0.5831482094072413
6.831082497474176e-05,0.00026159999999999996,50.89069117499999,69.77282776925438,0.5831482094072413
6.977313621273319e-05,0.0002672,51.980094349999995,69.77282776925438,0.5831482094072413
7.123544745072459e-05,0.00027279999999999996,53.069497524999996,69.77282776925438,0.5831482094072413
7.520457795384416e-05,0.000288,56.026449,69.77282776925438,0.5831482094072413
7.771139721897229e-05,0.00029759999999999997,57.893997299999995,69.77282776925438,0.5831482094072413
8.752977267405749e-05,0.00033519999999999996,65.208561475,69.77282776925438,0.5831482094072413
8.961878872833095e-05,0.0003432,66.764851725,69.77282776925438,0.5831482094072413
9.463242725858722e-05,0.00036239999999999997,70.49994832499999,69.77282776925438,0.5831482094072413
9.943716418341616e-05,0.0003808,74.0794159,69.77282776925438,0.5831482094072413
0.00010507750752995446,0.00040239999999999997,78.281399575,69.77282776925438,0.5831482094072413
0.00010821103161136465,0.0004144,80.61583494999999,69.77282776925438,0.5831482094072413
0.0001117623589036295,0.000428,83.261528375,69.77282776925438,0.5831482094072413
0.0001155225878013217,0.00044239999999999997,86.062850825,69.77282776925438,0.5831482094072413
0.00011928281669901392,0.0004568,88.864173275,69.77282776925438,0.5831482094072413
0.00012116293114786003,0.000464,90.2648345,69.77282776925438,0.5831482094072413
0.0001224163407804241,0.00046879999999999996,91.19860865,69.77282776925438,0.5831482094072413
0.0001238786520184155,0.0004744,92.288011825,69.77282776925438,0.5831482094072413
0.00012972789697038114,0.0004967999999999999,96.64562452499999,69.77282776925438,0.5831482094072413
0.00013912846921461166,0.0005327999999999999,103.64893064999998,69.77282776925438,0.5831482094072413
0.0001443510093502953,0.0005528,107.539656275,69.77282776925438,0.5831482094072413
0.0001470667302208508,0.0005632,109.5628336,69.77282776925438,0.5831482094072413
0.00014790233664256018,0.0005664,110.1853497,69.77282776925438,0.5831482094072413
0.00015542279443794458,0.0005951999999999999,115.78799459999999,69.77282776925438,0.5831482094072413
0.00015792961370307272,0.0006048,117.65554289999999,69.77282776925438,0.5831482094072413
0.0001596008265464915,0.0006112,118.9005751,69.77282776925438,0.5831482094072413
0.00016085423617905555,0.000616,119.83434925,69.77282776925438,0.5831482094072413
0.0001667034811310212,0.0006384,124.19196195,69.77282776925438,0.5831482094072413
0.0001727616276884142,0.0006615999999999999,128.70520367499998,69.77282776925438,0.5831482094072413
0.0001742239389264056,0.0006672,129.79460684999998,69.77282776925438,0.5831482094072413
0.00017631295498067906,0.0006751999999999999,131.3508971,69.77282776925438,0.5831482094072413
0.00017777526621867048,0.0006808,132.440300275,69.77282776925438,0.5831482094072413
0.0001844601175923455,0.0007063999999999999,137.420429075,69.77282776925438,0.5831482094072413
0.00019198057538772994,0.0007352,143.023073975,69.77282776925438,0.5831482094072413
0.00019678531231255886,0.0007536,146.60254155,69.77282776925438,0.5831482094072413
0.00020221675405366984,0.0007744,150.6488962,69.77282776925438,0.5831482094072413
0.00020576808134593468,0.000788,153.294589625,69.77282776925438,0.5831482094072413
0.00020723039258392612,0.0007936,154.3839928,69.77282776925438,0.5831482094072413
0.00021161732629790034,0.0008104,157.652202325,69.77282776925438,0.5831482094072413
0.00021851107927700272,0.0008368,162.78796015,69.77282776925438,0.5831482094072413
0.0002249870290452504,0.0008615999999999999,167.612459925,69.77282776925438,0.5831482094072413
0.00022853835633751527,0.0008751999999999999,170.25815335,69.77282776925438,0.5831482094072413
0.0002318807820243528,0.000888,172.74821775,69.77282776925438,0.5831482094072413
0.00023731222376546378,0.0009088,176.7945724,69.77282776925438,0.5831482094072413
0.0002394012398197372,0.0009168,178.35086264999998,69.77282776925438,0.5831482094072413
0.0002412813542685833,0.0009239999999999999,179.75152387499998,69.77282776925438,0.5831482094072413
0.00024378817353371145,0.0009335999999999999,181.61907217499999,69.77282776925438,0.5831482094072413
0.00024462377995542085,0.0009368,182.241588275,69.77282776925438,0.5831482094072413
0.00025172643453995054,0.0009639999999999999,187.53297512499998,69.77282776925438,0.5831482094072413
0.00025339764738336934,0.0009704,188.778007325,69.77282776925438,0.5831482094072413
0.0002567400730702069,0.0009832,191.268071725,69.77282776925438,0.5831482094072413
0.000259873597151617,0.0009952,193.60250709999997,69.77282776925438,0.5831482094072413
0.0002642605308655912,0.0010119999999999999,196.87071662499997,69.77282776925438,0.5831482094072413
0.0002717809886609757,0.0010408,202.47336152499997,69.77282776925438,0.5831482094072413
0.0002784658400346507,0.0010664,207.453490325,69.77282776925438,0.5831482094072413
0.0002803459544834968,0.0010735999999999999,208.85415154999998,69.77282776925438,0.5831482094072413
0.00028118156090520616,0.0010768,209.47666765,69.77282776925438,0.5831482094072413
0.0002828527737486249,0.0010831999999999999,210.72169984999996,69.77282776925438,0.5831482094072413
0.00028389728177576166,0.0010872,211.499844975,69.77282776925438,0.5831482094072413
0.00028494178980289836,0.0010911999999999999,212.27799009999998,69.77282776925438,0.5831482094072413
0.0002859862978300351,0.0010952,213.056135225,69.77282776925438,0.5831482094072413
0.0002884931170951633,0.0011048,214.923683525,69.77282776925438,0.5831482094072413
0.0002914177395711461,0.001116,217.102489875,69.77282776925438,0.5831482094072413
0.0002941334604417016,0.0011264,219.1256672,69.77282776925438,0.5831482094072413
0.0002945512636525562,0.0011279999999999999,219.43692524999997,69.77282776925438,0.5831482094072413
0.0002976847877339664,0.00114,221.771360625,69.77282776925438,0.5831482094072413
0.0002997738037882399,0.001148,223.327650875,69.77282776925438,0.5831482094072413
0.00030123611502623124,0.0011535999999999999,224.41705404999996,69.77282776925438,0.5831482094072413
0.0003037429342913594,0.0011631999999999999,226.28460234999997,69.77282776925438,0.5831482094072413
0.00030959217924332507,0.0011856,230.64221505,69.77282776925438,0.5831482094072413
0.00032254407877982047,0.0012351999999999999,240.2912146,69.77282776925438,0.5831482094072413
0.0003250508980449486,0.0012448,242.15876289999997,69.77282776925438,0.5831482094072413
0.0003290200285480681,0.0012599999999999998,245.11571437499998,69.77282776925438,0.5831482094072413
0.0003369582895543073,0.0012904,251.02961732499998,69.77282776925438,0.5831482094072413
0.0003425986329008456,0.001312,255.231601,69.77282776925438,0.5831482094072413
0.00034406094413883697,0.0013176,256.321004175,69.77282776925438,0.5831482094072413
0.0003459410585876831,0.0013248,257.7216654,69.77282776925438,0.5831482094072413
0.00035325261477764017,0.0013528,263.168681275,69.77282776925438,0.5831482094072413
0.00036390659665443473,0.0013935999999999998,271.0790475660836,69.77282776925438,0.5831482094072413
0.00036620451431413557,0.0014024,271.1463051164497,69.77282776925438,0.5831482094072413
0.00037330716889866526,0.0014295999999999998,271.3531589798031,69.77282776925438,0.5831482094072413
0.0003879302812785794,0.0014856,271.7742629438454,69.77282776925438,0.5831482094072413
0.00039001929733285286,0.0014935999999999999,271.83391135537363,69.77282776925438,0.5831482094072413
0.00039753975512823726,0.0015224,272.0476215915029,69.77282776925438,0.5831482094072413
0.0004017177872367842,0.0015383999999999999,272.1656680339102,69.77282776925438,0.5831482094072413
0.00040547801613447643,0.0015528,272.27150106937825,69.77282776925438,0.5831482094072413
0.0004069403273724678,0.0015584,272.3125549052022,69.77282776925438,0.5831482094072413
0.0004096560482430233,0.0015688,272.38864542426694,69.77282776925438,0.5831482094072413
0.00041425188356242486,0.0015864,272.51696735346997,69.77282776925438,0.5831482094072413
0.00041466968677327957,0.001588,272.5286053823021,69.77282776925438,0.5831482094072413
0.00041759430924926235,0.0015991999999999998,272.60994391871174,69.77282776925438,0.5831482094072413
0.0004276215863097749,0.0016376,272.88714762943994,69.77282776925438,0.5831482094072413
0.0004330530280508859,0.0016584,273.0362406688326,69.77282776925438,0.5831482094072413
0.00043388863447259523,0.0016615999999999998,273.059113169133,69.77282776925438,0.5831482094072413
0.00043827556818656953,0.0016784,273.17891311788406,69.77282776925438,0.5831482094072413
0.00044496041956024456,0.001704,273.360570042022,69.77282776925438,0.5831482094072413
0.0004468405340090907,0.0017112,273.41146887857946,69.77282776925438,0.5831482094072413
0.0004516452709339196,0.0017296,273.54116567455867,69.77282776925438,0.5831482094072413
0.0004543609918044751,0.00174,273.6142345127658,69.77282776925438,0.5831482094072413
0.00045916572872930405,0.0017584,273.7430942665581,69.77282776925438,0.5831482094072413
0.0004683573993681072,0.0017936,273.9881526383465,69.77282776925438,0.5831482094072413
0.00047107312023866263,0.0018039999999999998,274.0601963577353,69.77282776925438,0.5831482094072413
0.0004733710378983634,0.0018127999999999998,274.12103000168895,69.77282776925438,0.5831482094072413
0.0004748333491363549,0.0018184,274.15968236330536,69.77282776925438,0.5831482094072413
0.00048026479087746583,0.0018391999999999998,274.3028436398873,69.77282776925438,0.5831482094072413
0.00048172710211545725,0.0018448,274.3412789991733,69.77282776925438,0.5831482094072413
0.0004890386583054143,0.0018728,274.532777465405,69.77282776925438,0.5831482094072413
0.0004930077888085338,0.001888,274.6362660425408,69.77282776925438,0.5831482094072413
0.0004963502144953714,0.0019008,274.72316253403505,69.77282776925438,0.5831482094072413
0.0005061685899504566,0.0019383999999999998,274.9771107704395,69.77282776925438,0.5831482094072413
0.0005109733268752855,0.0019568,275.10068262694324,69.77282776925438,0.5831482094072413
0.0005138979493512683,0.0019679999999999997,275.1756784343323,69.77282776925438,0.5831482094072413
0.00051849378467067,0.0019856,275.2931935578275,69.77282776925438,0.5831482094072413
0.0005205828007249434,0.0019936,275.3464751600482,69.77282776925438,0.5831482094072413
0.0005220451119629349,0.0019992,275.3837226778904,69.77282776925438,0.5831482094072413
0.0005283121601257551,0.0020231999999999997,275.5428962155399,69.77282776925438,0.5831482094072413
0.000530610077785456,0.002032,275.6010751212429,69.77282776925438,0.5831482094072413
0.0005337436018668661,0.002044,275.6802518833648,69.77282776925438,0.5831482094072413
0.0005368771259482764,0.002056,275.75924756627904,69.77282776925438,0.5831482094072413
0.0005395928468188318,0.0020664,275.82756515325775,69.77282776925438,0.5831482094072413
0.0005446064853490881,0.0020856,275.95333866385545,69.77282776925438,0.5831482094072413
0.0005471133046142161,0.0020951999999999998,276.01605602207957,69.77282776925438,0.5831482094072413
0.0005504557303010537,0.002108,276.09950510951205,69.77282776925438,0.5831482094072413
0.0005531714511716092,0.0021184,276.16716207632186,69.77282776925438,0.5831482094072413
0.0005598563025452843,0.002144,276.3331527629279,69.77282776925438,0.5831482094072413
0.000562154220204985,0.0021528,276.39003330312084,69.77282776925438,0.5831482094072413
0.0005644521378646858,0.0021616,276.4468232361325,69.77282776925438,0.5831482094072413
0.0005703013828166515,0.0021839999999999997,276.59097406334627,69.77282776925438,0.5831482094072413
0.0005723903988709249,0.002192,276.6423166146539,69.77282776925438,0.5831482094072413
0.0005784485454283179,0.0022152,276.7907983641219,69.77282776925438,0.5831482094072413
0.0005807464630880187,0.002224,276.8469602223134,69.77282776925438,0.5831482094072413
0.0005840888887748562,0.0022367999999999997,276.9284957336699,69.77282776925438,0.5831482094072413
0.0005903559369376766,0.0022608,277.0808860308035,69.77282776925438,0.5831482094072413
0.0005928627562028048,0.0022704,277.1416653356583,69.77282776925438,0.5831482094072413
0.0005955784770733602,0.0022808,277.2073965892417,69.77282776925438,0.5831482094072413
0.0005993387059710524,0.0022952,277.2982164463674,69.77282776925438,0.5831482094072413
0.0006053968525284454,0.0023184,277.4440712983913,69.77282776925438,0.5831482094072413
0.000609365983031565,0.0023336,277.5393228373785,69.77282776925438,0.5831482094072413
0.0006116639006912657,0.0023423999999999997,277.59435787085647,69.77282776925438,0.5831482094072413
0.0006124995071129751,0.0023455999999999998,277.61435061054004,69.77282776925438,0.5831482094072413
0.000614797424772676,0.0023544,277.6692758709872,69.77282776925438,0.5831482094072413
0.0006204377681192143,0.002376,277.8037540691258,69.77282776925438,0.5831482094072413
0.0006214822761463509,0.0023799999999999997,277.82860502962296,69.77282776925438,0.5831482094072413
0.0006256603082548978,0.0023959999999999997,277.92784641512776,69.77282776925438,0.5831482094072413
0.0006338074708665644,0.0024272,278.120626852022,69.77282776925438,0.5831482094072413
0.0006400745190293846,0.0024511999999999997,278.268262584301,69.77282776925438,0.5831482094072413
0.0006429991415053675,0.0024624,278.3369662302538,69.77282776925438,0.5831482094072413
0.0006446703543487862,0.0024687999999999997,278.37617073746503,69.77282776925438,0.5831482094072413
0.0006490572880627605,0.0024855999999999997,278.47889444758397,69.77282776925438,0.5831482094072413
0.000651146304117034,0.0024936,278.5277152974688,69.77282776925438,0.5831482094072413
0.0006519819105387433,0.0024968,278.5472265291066,69.77282776925438,0.5831482094072413
0.000663889302048102,0.0025423999999999998,278.8242104211572,69.77282776925438,0.5831482094072413
0.0006668139245240848,0.0025536,278.8919443424095,69.77282776925438,0.5831482094072413
0.0006682762357620762,0.0025591999999999998,278.9257678482107,69.77282776925438,0.5831482094072413
0.0006703652518163497,0.0025672,278.97403711381475,69.77282776925438,0.5831482094072413
0.0006739165791086146,0.0025808,279.05596045042915,69.77282776925438,0.5831482094072413
0.0006768412015845973,0.0025919999999999997,279.1233003816426,69.77282776925438,0.5831482094072413
0.0006885396914885287,0.0026368,279.3915329959849,69.77282776925438,0.5831482094072413
0.0006952245428622037,0.0026623999999999997,279.54401069855896,69.77282776925438,0.5831482094072413
0.0006962690508893404,0.0026663999999999998,279.5677835906605,69.77282776925438,0.5831482094072413
0.0006989847717598959,0.0026768,279.6295281094,69.77282776925438,0.5831482094072413
0.0007029539022630155,0.002692,279.71960207102,69.77282776925438,0.5831482094072413
0.000706296327949853,0.0027048,279.7953000882178,69.77282776925438,0.5831482094072413
0.0007140256873506647,0.0027343999999999997,279.96981867680273,69.77282776925438,0.5831482094072413
0.0007175770146429296,0.002748,280.04975571434926,69.77282776925438,0.5831482094072413
0.0007211283419351945,0.0027616,280.12953861099317,69.77282776925438,0.5831482094072413
0.0007248885708328866,0.002776,280.21384778225456,69.77282776925438,0.5831482094072413
0.0007301111109685702,0.002796,280.3306614469835,69.77282776925438,0.5831482094072413
0.0007322001270228438,0.002804,280.37729561320737,69.77282776925438,0.5831482094072413
0.000735960355920536,0.0028184,280.46110656077116,69.77282776925438,0.5831482094072413
0.0007376315687639546,0.0028247999999999997,280.49830224754015,69.77282776925438,0.5831482094072413
0.0007443164201376297,0.0028504,280.64675750648286,69.77282776925438,0.5831482094072413
0.0007476588458244672,0.0028631999999999998,280.7207900740405,69.77282776925438,0.5831482094072413
0.0007528813859601508,0.0028832,280.83620808029735,69.77282776925438,0.5831482094072413
0.0007545525988035697,0.0028896,280.8730758412212,69.77282776925438,0.5831482094072413
0.0007576861228849798,0.0029016,280.9421171721106,69.77282776925438,0.5831482094072413
0.0007626997614152361,0.0029208,281.0523521299469,69.77282776925438,0.5831482094072413
0.0007645798758640823,0.002928,281.0936173338181,69.77282776925438,0.5831482094072413
0.0007721003336594667,0.0029568,281.2582839425704,69.77282776925438,0.5831482094072413
0.0007766961689788682,0.0029744,281.35860564453264,69.77282776925438,0.5831482094072413
0.0007777406770060049,0.0029784,281.381373712814,69.77282776925438,0.5831482094072413
0.0007837988235633979,0.0030015999999999997,281.5131941032312,69.77282776925438,0.5831482094072413
0.0007865145444339534,0.003012,281.5721569531998,69.77282776925438,0.5831482094072413
0.0007886035604882268,0.0030199999999999997,281.61745897826586,69.77282776925438,0.5831482094072413
0.0007925726909913465,0.0030352,281.7034040944608,69.77282776925438,0.5831482094072413
0.0007931993958076284,0.0030375999999999997,281.7169590165628,69.77282776925438,0.5831482094072413
0.0007959151166781839,0.003048,281.77564881344404,69.77282776925438,0.5831482094072413
0.0008021821648410044,0.003072,281.910789546494,69.77282776925438,0.5831482094072413
0.0008057334921332691,0.0030856,281.9871865113378,69.77282776925438,0.5831482094072413
0.0008126272451123715,0.0031119999999999997,282.1351126554521,69.77282776925438,0.5831482094072413
0.0008155518675883544,0.0031232,282.197721253297,69.77282776925438,0.5831482094072413
0.0008172230804317731,0.0031295999999999997,282.23345828070535,69.77282776925438,0.5831482094072413
0.0008226545221728841,0.0031504,282.34940727450385,69.77282776925438,0.5831482094072413
0.0008257880462542942,0.0031623999999999997,282.41616511442993,69.77282776925438,0.5831482094072413
0.0008287126687302771,0.0031736,282.47838335264544,69.77282776925438,0.5831482094072413
0.0008393666506070717,0.0032144,282.7043149275731,69.77282776925438,0.5831482094072413
0.0008441713875319006,0.0032327999999999996,282.80583943165766,69.77282776925438,0.5831482094072413
0.0008464693051916014,0.0032416,282.85431494410363,69.77282776925438,0.5831482094072413
0.0008491850260621568,0.0032519999999999997,282.9115380678724,69.77282776925438,0.5831482094072413
0.0008506473373001483,0.0032576,282.942320955555,69.77282776925438,0.5831482094072413
0.0008581677950955327,0.0032863999999999997,283.1003081344795,69.77282776925438,0.5831482094072413
0.0008610924175715155,0.0032976,283.1616016576429,69.77282776925438,0.5831482094072413
0.0008667327609180539,0.0033192,283.27958180277847,69.77282776925438,0.5831482094072413
0.0008671505641289085,0.0033208,283.2883091431455,69.77282776925438,0.5831482094072413
0.0008717463994483102,0.0033384,283.384201903186,69.77282776925438,0.5831482094072413
0.0008786401524274125,0.0033648,283.527672189883,69.77282776925438,0.5831482094072413
0.000883235987746814,0.0033824,283.6230752306248,69.77282776925438,0.5831482094072413
0.0008882496262770704,0.0034016,283.7269307412919,69.77282776925438,0.5831482094072413
0.0008907564455421984,0.0034111999999999996,283.7787727464918,69.77282776925438,0.5831482094072413
0.0008920098551747625,0.0034159999999999998,283.80467240946064,69.77282776925438,0.5831482094072413
0.000892845461596472,0.0034192,283.8219309667439,69.77282776925438,0.5831482094072413
0.0008991125097592924,0.0034432,283.9511699552163,69.77282776925438,0.5831482094072413
0.0009074685739763861,0.0034752,284.12294342450497,69.77282776925438,0.5831482094072413
0.0009093486884252321,0.0034823999999999996,284.16150731402837,69.77282776925438,0.5831482094072413
0.0009120644092957877,0.0034928,284.2171558581959,69.77282776925438,0.5831482094072413
0.0009183314574586081,0.0035168,284.34532952817005,69.77282776925438,0.5831482094072413
0.0009271053248865566,0.0035504,284.5242010348747,69.77282776925438,0.5831482094072413
0.0009296121441516846,0.00356,284.5751857634446,69.77282776925438,0.5831482094072413
0.0009450708629533082,0.0036192,284.88841492962587,69.77282776925438,0.5831482094072413
0.0009467420757967268,0.0036255999999999997,284.92215742430875,69.77282776925438,0.5831482094072413
0.0009515468127215558,0.0036439999999999997,285.01903794256305,69.77282776925438,0.5831482094072413
0.0009561426480409574,0.0036615999999999997,285.1115278997396,69.77282776925438,0.5831482094072413
0.0009624096962037778,0.0036856,285.23737163894856,69.77282776925438,0.5831482094072413
0.000967423334734034,0.0037048,285.3378166740508,69.77282776925438,0.5831482094072413
0.0009751526941348458,0.0037343999999999997,285.49227260185904,69.77282776925438,0.5831482094072413
0.0009805841358759568,0.0037551999999999998,285.60052368590937,69.77282776925438,0.5831482094072413
0.0009853888728007857,0.0037736,285.69608948391647,69.77282776925438,0.5831482094072413
0.0009878956920659138,0.0037832,285.7458777479725,69.77282776925438,0.5831482094072413
0.0009929093305961702,0.0038023999999999996,285.8453067050611,69.77282776925438,0.5831482094072413
0.0009972962643101445,0.0038192,285.93214653271406,69.77282776925438,0.5831482094072413
0.0010002208867861272,0.0038304,285.98995700046976,69.77282776925438,0.5831482094072413
0.0010087858526086483,0.0038632,286.15888105294033,69.77282776925438,0.5831482094072413
0.0010137994911389046,0.0038824,286.25750388604064,69.77282776925438,0.5831482094072413
0.0010171419168257421,0.0038951999999999997,286.3231467877127,69.77282776925438,0.5831482094072413
0.001020066539301725,0.0039064,286.3805153476442,69.77282776925438,0.5831482094072413
0.001023826768199417,0.0039207999999999995,286.4541807553203,69.77282776925438,0.5831482094072413
0.0010315561276002289,0.0039504,286.6052735576808,69.77282776925438,0.5831482094072413
0.0010371964709467673,0.003972,286.71525195433253,69.77282776925438,0.5831482094072413
0.0010426279126878781,0.0039927999999999995,286.820936839824,69.77282776925438,0.5831482094072413
0.0011046837246393001,0.004230446089217844,288.0135622282822,69.77282776925438,0.5831482094072413
0.0011297569319320402,0.004326465293058612,288.48798647649073,69.77282776925438,0.5831482094072413
0.0014607232681962071,0.005593918783756751,294.4082044779704,69.77282776925438,0.5831482094072413
0.0014958257584060432,0.005728345669133827,295.00368171249386,69.77282776925438,0.5831482094072413
0.001520898965698783,0.005824364872974595,295.4256905765874,69.77282776925438,0.5831482094072413
0.001530928248615879,0.005862772554510902,295.59373334075747,69.77282776925438,0.5831482094072413
0.0017064406996650586,0.006534906981396279,298.4683260165561,69.77282776925438,0.5831482094072413
0.0017616017557090865,0.006746149229845969,299.34762681840607,69.77282776925438,0.5831482094072413
0.0019070263580069778,0.007303060612122424,301.61577291476135,69.77282776925438,0.5831482094072413
0.001957172772592458,0.00749509901980396,302.3821123569149,69.77282776925438,0.5831482094072413
0.0020624802432219654,0.007898379675935187,303.96693426584415,69.77282776925438,0.5831482094072413
0.0020825388090561577,0.007975195039007801,304.265193114841,69.77282776925438,0.5831482094072413
0.002308197674690817,0.008839367873574715,307.5468597003603,69.77282776925438,0.5831482094072413
0.0023934465794861327,0.009165833166633327,308.7537066271223,69.77282776925438,0.5831482094072413
0.0025689590305353126,0.009837967593518704,311.1868345585685,69.77282776925438,0.5831482094072413
0.002654207935330628,0.010164432886577316,312.3451662135063,69.77282776925438,0.5831482094072413
0.00269933970845756,0.010337267453490697,312.9525215063491,69.77282776925438,0.5831482094072413
0.0027394568401259436,0.010490898179635926,313.48907595394337,69.77282776925438,0.5831482094072413
0.0027896032547114233,0.010682936587317463,314.15547902717253,69.77282776925438,0.5831482094072413
0.0029651157057606035,0.011355071014202842,316.4519603808516,69.77282776925438,0.5831482094072413
0.0030403353276388227,0.011643128625725144,317.4198646242688,69.77282776925438,0.5831482094072413
0.0030954963836828508,0.011854370874174834,318.1237354900552,69.77282776925438,0.5831482094072413
0.0031807452884781667,0.012180836167233446,319.2019894675393,69.77282776925438,0.5831482094072413
0.0032008038543123586,0.01225765153030606,319.45405122933147,69.77282776925438,0.5831482094072413
0.0032359063445221944,0.012392078415683136,319.89368195600235,69.77282776925438,0.5831482094072413
0.00339637487119573,0.013006601320264053,321.88019849069264,69.77282776925438,0.5831482094072413
0.003436492002864114,0.013160232046409282,322.3710656303574,69.77282776925438,0.5831482094072413
0.0035117116247423336,0.013448289657931586,323.2854595777341,69.77282776925438,0.5831482094072413
0.003757429056211185,0.014389277855571115,326.22060963571346,69.77282776925438,0.5831482094072413
0.0038928243755919807,0.014907781556311263,327.805905255802,69.77282776925438,0.5831482094072413
0.0039229122243432685,0.015023004600920185,328.15525573203985,69.77282776925438,0.5831482094072413
0.003963029356011652,0.015176635327065414,328.61943516140576,69.77282776925438,0.5831482094072413
0.004048278260806969,0.015503100620124026,329.5997753573547,69.77282776925438,0.5831482094072413
0.004319068899568559,0.01654010802160432,332.6616923207941,69.77282776925438,0.5831482094072413
0.004379244597071136,0.016770554110822164,333.3318410935951,69.77282776925438,0.5831482094072413
0.004509625274993383,0.01726985397079416,334.77163195007034,69.77282776925438,0.5831482094072413
0.0045547570481203154,0.017442688537707543,335.266226529944,69.77282776925438,0.5831482094072413
0.004705196291876754,0.01801880376075215,336.90124233593406,69.77282776925438,0.5831482094072413
0.004945899081887057,0.018940588117623523,339.47547945208515,69.77282776925438,0.5831482094072413
0.005051206552516565,0.01934386877375475,340.58629117311153,69.77282776925438,0.5831482094072413
0.005211675079190101,0.019958391678335668,342.2617444137089,69.77282776925438,0.5831482094072413
0.005316982549819609,0.020361672334466892,343.3503373786977,69.77282776925438,0.5831482094072413
0.0055125535667029804,0.021110622124424886,345.3499567564986,69.77282776925438,0.5831482094072413
0.005622875678791037,0.021533106621324266,346.4657368048874,69.77282776925438,0.5831482094072413
0.0056529635275423245,0.021648329665933188,346.7685544956622,69.77282776925438,0.5831482094072413
0.005723168507961996,0.02191718343668734,347.4726951202681,69.77282776925438,0.5831482094072413
0.0058284759785915035,0.022320464092818564,348.52262245469905,69.77282776925438,0.5831482094072413
0.005938798090679559,0.022742948589717944,349.6146417585882,69.77282776925438,0.5831482094072413
0.006024046995474875,0.023069413882776557,350.45306487088186,69.77282776925438,0.5831482094072413
0.006044105561309067,0.02314622924584917,350.64966688625134,69.77282776925438,0.5831482094072413
0.006089237334435999,0.023319063812762553,351.09109342851,69.77282776925438,0.5831482094072413
0.0061494130319385745,0.023549509901980396,351.67768239956433,69.77282776925438,0.5831482094072413
0.006400145104865974,0.024509701940388078,354.0980891443832,69.77282776925438,0.5831482094072413
0.006530525782788222,0.025009001800360073,355.34206771542506,69.77282776925438,0.5831482094072413
0.006565628272998057,0.025143428685737147,355.6753252860178,69.77282776925438,0.5831482094072413
0.0066007307632078936,0.025277855571114224,356.00788870227115,69.77282776925438,0.5831482094072413
0.006791287138632717,0.026007601520304062,357.801339092598,69.77282776925438,0.5831482094072413
0.006876536043428033,0.026334066813362672,358.59730684853577,69.77282776925438,0.5831482094072413
0.006906623892179321,0.026449289857971594,358.8773166164002,69.77282776925438,0.5831482094072413
0.0070721070603114045,0.027083016603320666,360.40894989046234,69.77282776925438,0.5831482094072413
0.007092165626145596,0.02715983196639328,360.593647840673,69.77282776925438,0.5831482094072413
0.007202487738233653,0.02758231646329266,361.6058682213061,69.77282776925438,0.5831482094072413
0.007287736643028967,0.02790878175635127,362.38390255242933,69.77282776925438,0.5831482094072413
0.007367970906365736,0.02821604320864173,363.1129340377669,69.77282776925438,0.5831482094072413
0.007488322301370887,0.028676935387077416,364.20070262013246,69.77282776925438,0.5831482094072413
0.007568556564707655,0.028984196839367874,364.92209614245775,69.77282776925438,0.5831482094072413
0.007668849393878615,0.029368273654730947,365.81965753801416,69.77282776925438,0.5831482094072413
0.007734039732839738,0.029617923584716942,366.4006185336081,69.77282776925438,0.5831482094072413
0.007944654674098753,0.030424484896979395,368.26465020348854,69.77282776925438,0.5831482094072413
0.008004830371601329,0.03065493098619724,368.7936778633437,69.77282776925438,0.5831482094072413
0.008065006069103906,0.030885377075415082,369.32115677650825,69.77282776925438,0.5831482094072413
0.008140225690982125,0.03117343468693739,369.9783519008499,69.77282776925438,0.5831482094072413
0.008170313539733413,0.03128865773154631,370.2405662862272,69.77282776925438,0.5831482094072413
0.00828063565182147,0.03171114222844569,371.1988138971104,69.77282776925438,0.5831482094072413
0.008340811349324045,0.031941588317663534,371.71939535035955,69.77282776925438,0.5831482094072413
0.008395972405368072,0.03215283056611322,372.19530970459675,69.77282776925438,0.5831482094072413
0.0084511334614121,0.03236407281456291,372.6700061846163,69.77282776925438,0.5831482094072413
0.008616616629544185,0.032997799559911986,374.0868978830742,69.77282776925438,0.5831482094072413
0.00868180696850531,0.03324744948989798,374.64214861309625,69.77282776925438,0.5831482094072413
0.008731953383090787,0.033439487897579515,375.0681588155982,69.77282776925438,0.5831482094072413
0.008857319419554489,0.03391958391678336,376.12903109503884,69.77282776925438,0.5831482094072413
0.009007758663310926,0.034495699139827966,377.3943788340117,69.77282776925438,0.5831482094072413
0.00912811005831608,0.034956591318263654,378.40073284626897,69.77282776925438,0.5831482094072413
0.00917825647290156,0.035148629725945194,378.8185182174265,69.77282776925438,0.5831482094072413
0.009238432170404133,0.03537907581516303,379.31868740799354,69.77282776925438,0.5831482094072413
0.009273534660613971,0.035513502700540114,379.6098660094798,69.77282776925438,0.5831482094072413
0.009328695716657997,0.03572474494898979,380.06656541617684,69.77282776925438,0.5831482094072413
0.00954933994083411,0.03656971394278856,381.88292846664126,69.77282776925438,0.5831482094072413
0.009795057372302962,0.03751070214042809,383.8865406161306,69.77282776925438,0.5831482094072413
0.009845203786888442,0.037702740548109626,384.29302194293945,69.77282776925438,0.5831482094072413
0.00990036484293247,0.03791398279655932,384.7392199275151,69.77282776925438,0.5831482094072413
0.010025730879396167,0.03839407881576315,385.7497161016652,69.77282776925438,0.5831482094072413
0.010141067632942773,0.03883576715343069,386.67502870979473,69.77282776925438,0.5831482094072413
0.010266433669406471,0.039315863172634524,387.6761604465622,69.77282776925438,0.5831482094072413
0.010396814347328717,0.039815163032606515,388.712292800768,69.77282776925438,0.5831482094072413
0.010416872913162912,0.03989197839567914,388.87124688180063,69.77282776925438,0.5831482094072413
0.010542238949626612,0.04037207441488298,389.86201897524916,69.77282776925438,0.5831482094072413
0.010587370722753542,0.04054490898179636,390.2175706985233,69.77282776925438,0.5831482094072413
0.010757868532344173,0.04119783956791358,391.5554649708998,69.77282776925438,0.5831482094072413
0.010913322417559162,0.04179315863172635,392.7681198085952,69.77282776925438,0.5831482094072413
0.011068776302774148,0.042388477695539106,393.97405636560796,69.77282776925438,0.5831482094072413
0.011204171622154944,0.042906981396279256,395.01901641026564,69.77282776925438,0.5831482094072413
0.011484991543833633,0.04398239647929586,397.1707703462568,69.77282776925438,0.5831482094072413
0.011540152599877661,0.04419363872774555,397.5910145821461,69.77282776925438,0.5831482094072413
0.011650474711965718,0.044616123224644935,398.4291601825009,69.77282776925438,0.5831482094072413
0.011825987163014895,0.0452882576515303,399.75622238685634,69.77282776925438,0.5831482094072413
0.011901206784893117,0.045576315263052614,400.32260946892404,69.77282776925438,0.5831482094072413
0.01196138248239569,0.04580676135227045,400.7747145825916,69.77282776925438,0.5831482094072413
0.012212114555323093,0.04676695339067814,402.6490167285931,69.77282776925438,0.5831482094072413
0.01228231953574276,0.04703580716143228,403.17112412121975,69.77282776925438,0.5831482094072413
0.012357539157620983,0.047323864772954596,403.7292350105938,69.77282776925438,0.5831482094072413
0.012543080891587259,0.04803440688137628,405.1002737120174,69.77282776925438,0.5831482094072413
0.012638359079299671,0.0483992798559712,405.8012454662141,69.77282776925438,0.5831482094072413
0.012658417645133861,0.04847609521904381,405.94855551295166,69.77282776925438,0.5831482094072413
0.012813871530348847,0.049071414282856565,407.08713778883697,69.77282776925438,0.5831482094072413
0.012934222925353999,0.04953230646129225,407.9649250763944,69.77282776925438,0.5831482094072413
0.012979354698480931,0.04970514102820564,408.29327334182864,69.77282776925438,0.5831482094072413
0.013074632886193344,0.05007001400280056,408.9849943430852,69.77282776925438,0.5831482094072413
0.0131849549982814,0.050492498499699945,409.783483208568,69.77282776925438,0.5831482094072413
0.013280233185993813,0.050857371474294866,410.4709926066979,69.77282776925438,0.5831482094072413
0.013420643146833154,0.05139507901580316,411.48066838981435,69.77282776925438,0.5831482094072413
0.013581111673506691,0.05200960192038408,412.6295526053295,69.77282776925438,0.5831482094072413
0.013716506992887487,0.05252810562112423,413.5948115761875,69.77282776925438,0.5831482094072413
0.013796741256224255,0.052835367073414685,414.16506350482473,69.77282776925438,0.5831482094072413
0.013887004802478118,0.05318103620724145,414.8050532314192,69.77282776925438,0.5831482094072413
0.01400735619748327,0.053641928385677135,415.6558549215074,69.77282776925438,0.5831482094072413
0.014092605102278586,0.05396839367873575,416.2567820708533,69.77282776925438,0.5831482094072413
0.014142751516864066,0.054160432086417284,416.6096063964383,69.77282776925438,0.5831482094072413
0.014323278609371791,0.05485177035407081,417.87575406774323,69.77282776925438,0.5831482094072413
0.014403512872708558,0.05515903180636127,418.43648702885633,69.77282776925438,0.5831482094072413
0.014448644645835493,0.055331866373274655,418.75136396071537,69.77282776925438,0.5831482094072413
0.014493776418962425,0.05550470094018804,419.065857541152,69.77282776925438,0.5831482094072413
0.014639201021260317,0.056061612322464496,420.0766375637983,69.77282776925438,0.5831482094072413
0.014714420643138534,0.056349669933986796,420.59791776608586,69.77282776925438,0.5831482094072413
0.014975181998983032,0.05734826965393079,422.3970307376242,69.77282776925438,0.5831482094072413
0.015050401620861251,0.05763632726545309,422.9137297260076,69.77282776925438,0.5831482094072413
0.01508048946961254,0.057751550310062016,423.12012720741706,69.77282776925438,0.5831482094072413
0.015145679808573663,0.05800120024004801,423.56677161060105,69.77282776925438,0.5831482094072413
0.01522591407191043,0.05830846169233847,424.11545987727186,69.77282776925438,0.5831482094072413
0.01527606048649591,0.05850050010002,424.4578174812495,69.77282776925438,0.5831482094072413
0.015431514371710897,0.05909581916383276,425.5163512602529,69.77282776925438,0.5831482094072413
0.015516763276506213,0.05942228445689138,426.0950716243418,69.77282776925438,0.5831482094072413
0.015612041464218625,0.0597871574314863,426.74041133399066,69.77282776925438,0.5831482094072413
0.015762480707975066,0.06036327265453091,427.7562502689877,69.77282776925438,0.5831482094072413
0.01587280282006312,0.06078575715143028,428.4987972852699,69.77282776925438,0.5831482094072413
0.01592796387610715,0.06099699939987997,428.8693158024382,69.77282776925438,0.5831482094072413
0.016013212780902463,0.06132346469293859,429.4409525244617,69.77282776925438,0.5831482094072413
0.01606837383694649,0.06153470694138828,429.8102027749626,69.77282776925438,0.5831482094072413
0.01614860810028326,0.06184196839367874,430.34641277313597,69.77282776925438,0.5831482094072413
0.016238871646537124,0.0621876375275055,430.94840861865197,69.77282776925438,0.5831482094072413
0.016294032702581153,0.06239887977595519,431.3156525824688,69.77282776925438,0.5831482094072413
0.016449486587796137,0.06299419883976795,432.3480132837912,69.77282776925438,0.5831482094072413
0.016660101529055154,0.0638007601520304,433.74064627448035,69.77282776925438,0.5831482094072413
0.01675036507530902,0.06414642928585718,434.3353852151909,69.77282776925438,0.5831482094072413
0.01684564326302143,0.0645113022604521,434.96181081234477,69.77282776925438,0.5831482094072413
0.016965994658026583,0.06497219443888778,435.75111369983165,69.77282776925438,0.5831482094072413
0.017076316770114636,0.06539467893578715,436.47272519296166,69.77282776925438,0.5831482094072413
0.01717159495782705,0.06575955191038207,437.0944731714068,69.77282776925438,0.5831482094072413
0.01723678529678817,0.06600920184036807,437.5191046816144,69.77282776925438,0.5831482094072413
0.01734710740887623,0.06643168633726745,438.2362877752562,69.77282776925438,0.5831482094072413
0.017382209899086065,0.06656611322264454,438.464109071486,69.77282776925438,0.5831482094072413
0.017402268464920257,0.06664292858571715,438.5942121088962,69.77282776925438,0.5831482094072413
0.01764297125493056,0.06756471294258852,440.15091430914674,69.77282776925438,0.5831482094072413
0.017718190876808784,0.06785277055411083,440.63568222057546,69.77282776925438,0.5831482094072413
0.01782349834743829,0.06825605121024206,441.3130110612735,69.77282776925438,0.5831482094072413
0.018049157213072948,0.06912022404480897,442.75919676904977,69.77282776925438,0.5831482094072413
0.018179537890995197,0.06961952390478096,443.59155653774604,69.77282776925438,0.5831482094072413
0.018440299246839688,0.07061812362472494,445.2493243707525,69.77282776925438,0.5831482094072413
0.018560650641844843,0.07107901580316063,446.0113619884917,69.77282776925438,0.5831482094072413
0.01874117773435257,0.07177035407081417,447.1508150710715,69.77282776925438,0.5831482094072413
0.018801353431855145,0.072000800160032,447.52968046393863,69.77282776925438,0.5831482094072413
0.018821411997689337,0.07207761552310463,447.65586379795644,69.77282776925438,0.5831482094072413
0.018971851241445778,0.07265373074614924,448.60057276548525,69.77282776925438,0.5831482094072413
0.019062114787699643,0.072999399879976,449.1659958962968,69.77282776925438,0.5831482094072413
0.019362993275212518,0.07415163032606521,451.0432434310978,69.77282776925438,0.5831482094072413
0.019553549650637343,0.07488137627525505,452.2262848586869,69.77282776925438,0.5831482094072413
0.019648827838349755,0.07524624924984998,452.81611881199876,69.77282776925438,0.5831482094072413
0.019678915687101044,0.0753614722944589,453.0021502857181,69.77282776925438,0.5831482094072413
0.01973909138460362,0.07559191838367674,453.3738807835819,69.77282776925438,0.5831482094072413
0.019819325647940388,0.0758991798359672,453.8688346780203,69.77282776925438,0.5831482094072413
0.019919618477111347,0.07628325665133028,454.4864295109618,69.77282776925438,0.5831482094072413
0.019964750250238278,0.07645609121824365,454.7639514187359,69.77282776925438,0.5831482094072413
0.02006002843795069,0.07682096419283857,455.3490288034963,69.77282776925438,0.5831482094072413
0.02026562873775116,0.07760832166433287,456.6078843108888,69.77282776925438,0.5831482094072413
0.020280672662126804,0.07766593318663734,456.699799661738,69.77282776925438,0.5831482094072413
0.020491287603385817,0.07847249449889979,457.9838353391167,69.77282776925438,0.5831482094072413
0.020551463300888393,0.07870294058811762,458.34975596049657,69.77282776925438,0.5831482094072413
0.02056149258380549,0.07874134826965394,458.4107020827636,69.77282776925438,0.5831482094072413
0.020636712205683708,0.07902940588117624,458.86742902405126,69.77282776925438,0.5831482094072413
0.020737005034854667,0.0794134826965393,459.47538961616544,69.77282776925438,0.5831482094072413
0.020872400354235463,0.07993198639727946,460.29432052946913,69.77282776925438,0.5831482094072413
0.0209075028444453,0.08006641328265654,460.5062974334042,69.77282776925438,0.5831482094072413
0.020947619976113684,0.08022004400880177,460.7483868676153,69.77282776925438,0.5831482094072413
0.02103788352236755,0.08056571314262853,461.29242796543014,69.77282776925438,0.5831482094072413
0.021123132427162867,0.08089217843568715,461.8054092726716,69.77282776925438,0.5831482094072413
0.021243483822168018,0.08135307061412284,462.5282457470969,69.77282776925438,0.5831482094072413
0.02130867416112914,0.08160272054410883,462.9191152611548,69.77282776925438,0.5831482094072413
0.02136383521717317,0.08181396279255852,463.24948688196673,69.77282776925438,0.5831482094072413
0.021398937707383003,0.08194838967793559,463.4595501684878,69.77282776925438,0.5831482094072413
0.021524303743846705,0.08242848569713944,464.2086816330821,69.77282776925438,0.5831482094072413
0.02167975762906169,0.0830238047609522,465.13524556877087,69.77282776925438,0.5831482094072413
0.0217850650996912,0.08342708541708342,465.76144621804343,69.77282776925438,0.5831482094072413
0.021820167589901032,0.08356151230246049,465.96991728188965,69.77282776925438,0.5831482094072413
0.02195556290928183,0.08408001600320064,466.7727977395583,69.77282776925438,0.5831482094072413
0.022271485321170355,0.08528985797159433,468.63871345999235,69.77282776925438,0.5831482094072413
0.022336675660131478,0.08553950790158033,469.02245571740576,69.77282776925438,0.5831482094072413
0.02243195384784389,0.08590438087617525,469.58252502212946,69.77282776925438,0.5831482094072413
0.02262251022326871,0.08663412682536507,470.69988810928845,69.77282776925438,0.5831482094072413
0.0227679348255666,0.08719103820764153,471.55014477072996,69.77282776925438,0.5831482094072413
0.022787993391400797,0.08726785357071415,471.66725511627726,69.77282776925438,0.5831482094072413
0.022833125164527728,0.08744068813762754,471.9306065032026,69.77282776925438,0.5831482094072413
0.0230286961814111,0.08818963792758552,473.0694579785099,69.77282776925438,0.5831482094072413
0.02308887187891367,0.08842008401680336,473.41911414543307,69.77282776925438,0.5831482094072413
0.0231440329349577,0.08863132626525305,473.73932021137375,69.77282776925438,0.5831482094072413
0.023209223273918826,0.08888097619523905,474.1173620857324,69.77282776925438,0.5831482094072413
0.023284442895797047,0.08916903380676136,474.55305004406864,69.77282776925438,0.5831482094072413
0.023339603951841075,0.08938027605521105,474.87220576056706,69.77282776925438,0.5831482094072413
0.023419838215177843,0.08968753750750151,475.3359076198617,69.77282776925438,0.5831482094072413
0.02346998462976332,0.08987957591518304,475.62540668690804,69.77282776925438,0.5831482094072413
0.02350007247851461,0.08999479895979197,475.7989903370526,69.77282776925438,0.5831482094072413
0.023555233534558635,0.09020604120824165,476.11700208118833,69.77282776925438,0.5831482094072413
0.023670570288105243,0.09064772954590919,476.7809987409013,69.77282776925438,0.5831482094072413
0.02372071670269072,0.09083976795359072,477.06929924534336,69.77282776925438,0.5831482094072413
0.023765848475817655,0.09101260252050411,477.32856653285967,69.77282776925438,0.5831482094072413
0.023790921683110394,0.09110862172434488,477.47252094241924,69.77282776925438,0.5831482094072413
0.023821009531861684,0.0912238447689538,477.64518815554567,69.77282776925438,0.5831482094072413
0.023861126663530068,0.09137747549509903,477.875278855212,69.77282776925438,0.5831482094072413
0.024081770887706175,0.09222244448889778,479.13809118490826,69.77282776925438,0.5831482094072413
0.024262297980213902,0.09291378275655131,480.16794830147404,69.77282776925438,0.5831482094072413
0.02437262009230196,0.09333626725345069,480.7958343939128,69.77282776925438,0.5831482094072413
0.024528073977516947,0.09393158631726346,481.67870489408483,69.77282776925438,0.5831482094072413
0.024598278957936617,0.0942004400880176,482.0767050350756,69.77282776925438,0.5831482094072413
0.02467349857981484,0.09448849769953992,482.5026424739306,69.77282776925438,0.5831482094072413
0.02484901103086402,0.0951606321264253,483.49453194478065,69.77282776925438,0.5831482094072413
0.024959333142952074,0.09558311662332467,484.11660705775694,69.77282776925438,0.5831482094072413
0.025059625972123033,0.09596719343868775,484.6811999603747,69.77282776925438,0.5831482094072413
0.025345460535260267,0.0970618123624725,486.2854752338854,69.77282776925438,0.5831482094072413
0.025450768005889773,0.09746509301860372,486.8747433798892,69.77282776925438,0.5831482094072413
0.02553100226922654,0.09777235447089418,487.32307156103934,69.77282776925438,0.5831482094072413
0.02561123653256331,0.09807961592318463,487.7708505967369,69.77282776925438,0.5831482094072413
0.02570651472027572,0.09844448889777956,488.3018782528963,69.77282776925438,0.5831482094072413
0.025751646493402655,0.09861732346469294,488.5531497060751,69.77282776925438,0.5831482094072413
0.025922144302993284,0.09927025405081016,489.50085147851024,69.77282776925438,0.5831482094072413
0.02594220286882748,0.09934706941388279,489.61218575585804,69.77282776925438,0.5831482094072413
0.025952232151744574,0.09938547709541909,489.66784030440414,69.77282776925438,0.5831482094072413
0.026067568905291178,0.09982716543308662,490.3072658982009,69.77282776925438,0.5831482094072413
0.026107686036959562,0.09998079615923185,490.529416041909,69.77282776925438,0.5831482094072413