File: datasets/aisi_316_L/data/M1/train_7.csv
Time(s),Strain(%),Stress(MPa),Temp(C),Log_SR(s-1)
0.0,0.0,0.0,373.89177648519166,-0.23551418365561805
2.063932214500095e-05,1.2e-05,2.057637,373.89177648519166,-0.23551418365561805
4.4030553909335354e-05,2.56e-05,4.3896256,373.89177648519166,-0.23551418365561805
8.118133377033706e-05,4.7199999999999995e-05,8.0933722,373.89177648519166,-0.23551418365561805
0.00010457256553467148,6.08e-05,10.4253608,373.89177648519166,-0.23551418365561805
0.00013759548096667297,7.999999999999999e-05,13.717579999999998,373.89177648519166,-0.23551418365561805
0.000152730983873007,8.879999999999999e-05,15.226513799999998,373.89177648519166,-0.23551418365561805
0.0001554828934923405,9.04e-05,15.5008654,373.89177648519166,-0.23551418365561805
0.00018025008006634162,0.0001048,17.9700298,373.89177648519166,-0.23551418365561805
0.0002352882724530108,0.0001368,23.457061799999998,373.89177648519166,-0.23551418365561805
0.00027794287155267946,0.0001616,27.7095116,373.89177648519166,-0.23551418365561805
0.0004237940813773528,0.00024639999999999997,42.2501464,373.89177648519166,-0.23551418365561805
0.00047745631895435524,0.00027759999999999997,47.600002599999996,373.89177648519166,-0.23551418365561805
0.0004925918218606892,0.00028639999999999997,49.1089364,373.89177648519166,-0.23551418365561805
0.0004967196862896894,0.00028879999999999997,49.520463799999995,373.89177648519166,-0.23551418365561805
0.0005104792343863568,0.0002968,50.8922218,373.89177648519166,-0.23551418365561805
0.0005214868728636907,0.0003032,51.9896282,373.89177648519166,-0.23551418365561805
0.0005490059690570252,0.0003192,54.7331442,373.89177648519166,-0.23551418365561805
0.0005834048392986935,0.0003392,58.1625392,373.89177648519166,-0.23551418365561805
0.0006356911220660292,0.0003696,63.375219599999994,373.89177648519166,-0.23551418365561805
0.000682473585594698,0.0003968,68.0391968,373.89177648519166,-0.23551418365561805
0.0007031129077396989,0.00040879999999999996,70.0968338,373.89177648519166,-0.23551418365561805
0.0007347598683620337,0.0004272,73.2518772,373.89177648519166,-0.23551418365561805
0.0007430155972200341,0.000432,74.074932,373.89177648519166,-0.23551418365561805
0.0007664068289843685,0.0004456,76.40692059999999,373.89177648519166,-0.23551418365561805
0.0007966778347970366,0.0004632,79.4247882,373.89177648519166,-0.23551418365561805
0.0008627236656610396,0.0005015999999999999,86.00922659999999,373.89177648519166,-0.23551418365561805
0.000901250400331708,0.0005239999999999999,89.85014899999999,373.89177648519166,-0.23551418365561805
0.0009287694965250427,0.00054,92.593665,373.89177648519166,-0.23551418365561805
0.0009384011801927097,0.0005455999999999999,93.55389559999999,373.89177648519166,-0.23551418365561805
0.000978303869673045,0.0005688,97.5319938,373.89177648519166,-0.23551418365561805
0.0010581092486337154,0.0006152,105.4881902,373.89177648519166,-0.23551418365561805
0.001099387892923717,0.0006391999999999999,109.60346419999999,373.89177648519166,-0.23551418365561805
0.001121403169878385,0.000652,111.798277,373.89177648519166,-0.23551418365561805
0.0011324108083557187,0.0006584,112.8956834,373.89177648519166,-0.23551418365561805
0.0011475463112620527,0.0006672,114.40461719999999,373.89177648519166,-0.23551418365561805
0.001170937543026387,0.0006808,116.73660579999999,373.89177648519166,-0.23551418365561805
0.0011778173170747207,0.0006848,117.42248479999999,373.89177648519166,-0.23551418365561805
0.0012245997806033895,0.000712,122.086462,373.89177648519166,-0.23551418365561805
0.0012493669671773907,0.0007264,124.5556264,373.89177648519166,-0.23551418365561805
0.001263126515274058,0.0007344,125.9273844,373.89177648519166,-0.23551418365561805
0.00130440515956406,0.0007584,130.0426584,373.89177648519166,-0.23551418365561805
0.0013181647076607273,0.0007664,131.4144164,373.89177648519166,-0.23551418365561805
0.001351187623092729,0.0007856,134.7066356,373.89177648519166,-0.23551418365561805
0.0013842105385247303,0.0008047999999999999,137.99885479999998,373.89177648519166,-0.23551418365561805
0.001415857499147065,0.0008232,141.1538982,373.89177648519166,-0.23551418365561805
0.001472271646343401,0.000856,146.778106,373.89177648519166,-0.23551418365561805
0.0014791514203917346,0.00086,147.463985,373.89177648519166,-0.23551418365561805
0.001487407149249735,0.0008648,148.2870398,373.89177648519166,-0.23551418365561805
0.0014956628781077354,0.0008696,149.1100946,373.89177648519166,-0.23551418365561805
0.001506670516585069,0.0008759999999999999,150.20750099999998,373.89177648519166,-0.23551418365561805
0.0015520770253040714,0.0009023999999999999,154.7343024,373.89177648519166,-0.23551418365561805
0.0015754682570684056,0.0009159999999999999,157.06629099999998,373.89177648519166,-0.23551418365561805
0.0016029873532617403,0.000932,159.809807,373.89177648519166,-0.23551418365561805
0.0016373862235034085,0.0009519999999999999,161.55760685784546,373.89177648519166,-0.23551418365561805
0.0016827927322224105,0.0009784,161.69843725627763,373.89177648519166,-0.23551418365561805
0.0017089358736060783,0.0009935999999999999,161.77884906230565,373.89177648519166,-0.23551418365561805
0.0017213194668930793,0.0010008,161.81677128782115,373.89177648519166,-0.23551418365561805
0.0017405828342284132,0.0010119999999999999,161.8755506117545,373.89177648519166,-0.23551418365561805
0.001747462608276747,0.001016,161.8964816723745,373.89177648519166,-0.23551418365561805
0.0017681019304217481,0.001028,161.95908287018747,373.89177648519166,-0.23551418365561805
0.0017749817044700816,0.001032,161.97988651908548,373.89177648519166,-0.23551418365561805
0.0017942450718054159,0.0010432,162.03797009876507,373.89177648519166,-0.23551418365561805
0.0018520351738114183,0.0010768,162.21077885371642,373.89177648519166,-0.23551418365561805
0.0018740504507660863,0.0010896,162.276055954797,373.89177648519166,-0.23551418365561805
0.0018768023603854193,0.0010911999999999999,162.2841945119758,373.89177648519166,-0.23551418365561805
0.0018960657277207536,0.0011024,162.3410346648419,373.89177648519166,-0.23551418365561805
0.0019043214565787542,0.0011072,162.36532573715894,373.89177648519166,-0.23551418365561805
0.0019731191970620908,0.0011472,162.56617852188796,373.89177648519166,-0.23551418365561805
0.002008894022113426,0.001168,162.6695413953408,373.89177648519166,-0.23551418365561805
0.002022653570210093,0.001176,162.70910488302573,373.89177648519166,-0.23551418365561805
0.0020653081693097616,0.0012008,162.83108987898115,373.89177648519166,-0.23551418365561805
0.002077691762596762,0.0012079999999999999,162.86632032567317,373.89177648519166,-0.23551418365561805
0.002105210858790097,0.001224,162.94431832818253,373.89177648519166,-0.23551418365561805
0.002185016237750767,0.0012703999999999999,163.16829478689786,373.89177648519166,-0.23551418365561805
0.0022042796050861014,0.0012816,163.22187727909565,373.89177648519166,-0.23551418365561805
0.002222167017611769,0.001292,163.27146915809072,373.89177648519166,-0.23551418365561805
0.0022648216167114373,0.0013168,163.38910262931302,373.89177648519166,-0.23551418365561805
0.002306100261001439,0.0013407999999999998,163.50212153144312,373.89177648519166,-0.23551418365561805
0.002352882724530108,0.0013679999999999999,163.62926013761316,373.89177648519166,-0.23551418365561805
0.002357010588959108,0.0013704,163.64043070103205,373.89177648519166,-0.23551418365561805
0.00239416136882011,0.001392,163.74062476262813,373.89177648519166,-0.23551418365561805
0.0024079209169167773,0.0014,163.7775795655013,373.89177648519166,-0.23551418365561805
0.002456079335255113,0.001428,163.90627777423575,373.89177648519166,-0.23551418365561805
0.0024670869737324465,0.0014344,163.93555587737504,373.89177648519166,-0.23551418365561805
0.0025028617987837816,0.0014552,164.03035978669928,373.89177648519166,-0.23551418365561805
0.0025193732564997824,0.0014647999999999998,164.0739370484715,373.89177648519166,-0.23551418365561805
0.0025441404430737837,0.0014792,164.13909467843482,373.89177648519166,-0.23551418365561805
0.0025757874036961186,0.0014976,164.2219927729886,373.89177648519166,-0.23551418365561805
0.0025895469517927855,0.0015056,164.25791142239058,373.89177648519166,-0.23551418365561805
0.0026156900931764535,0.0015207999999999999,164.325952455945,373.89177648519166,-0.23551418365561805
0.0026198179576054537,0.0015232,164.33667148493822,373.89177648519166,-0.23551418365561805
0.0026473370537987884,0.0015392,164.40796409237245,373.89177648519166,-0.23551418365561805
0.002678984014421123,0.0015576,164.48959425632816,373.89177648519166,-0.23551418365561805
0.0027078790654241243,0.0015743999999999999,164.56379829091455,373.89177648519166,-0.23551418365561805
0.0027133828846627912,0.0015776,164.5778973129597,373.89177648519166,-0.23551418365561805
0.0027271424327594586,0.0015856,164.6130961598255,373.89177648519166,-0.23551418365561805
0.002793188263623462,0.001624,164.78109588763994,373.89177648519166,-0.23551418365561805
0.0028055718569104625,0.0016312,164.81242261206538,373.89177648519166,-0.23551418365561805
0.002868865778155132,0.001668,164.9717024928927,373.89177648519166,-0.23551418365561805
0.002884001281061466,0.0016768,165.00958739555531,373.89177648519166,-0.23551418365561805
0.0029018886935871335,0.0016872,165.05426063762198,373.89177648519166,-0.23551418365561805
0.0029321596993998017,0.0017048,165.12961762666384,373.89177648519166,-0.23551418365561805
0.0029569268859738025,0.0017192,165.19104792345428,373.89177648519166,-0.23551418365561805
0.002965182614831803,0.0017239999999999998,165.21148005276746,373.89177648519166,-0.23551418365561805
0.0029775662081188035,0.0017312,165.24208669694391,373.89177648519166,-0.23551418365561805
0.0029885738465961374,0.0017376,165.26925095128985,373.89177648519166,-0.23551418365561805
0.003005085304312138,0.0017472,165.3099242839217,373.89177648519166,-0.23551418365561805
0.0030229727168378058,0.0017576,165.35388883201074,373.89177648519166,-0.23551418365561805
0.0030422360841731396,0.0017687999999999998,165.40112195890077,373.89177648519166,-0.23551418365561805
0.0030986502313694758,0.0018016,165.5387811352738,373.89177648519166,-0.23551418365561805
0.0031302971919918107,0.00182,165.61557654120537,373.89177648519166,-0.23551418365561805
0.003144056740088478,0.001828,165.6488713392083,373.89177648519166,-0.23551418365561805
0.0031922151584268133,0.001856,165.76495824563696,373.89177648519166,-0.23551418365561805
0.0031963430228558135,0.0018583999999999999,165.7748766604771,373.89177648519166,-0.23551418365561805
0.003204598751713814,0.0018632,165.79469851637867,373.89177648519166,-0.23551418365561805
0.003214230435381481,0.0018687999999999999,165.81779886158557,373.89177648519166,-0.23551418365561805
0.003280276266245484,0.0019072,165.97548023731207,373.89177648519166,-0.23551418365561805
0.0033174270461064858,0.0019287999999999998,166.0636317834735,373.89177648519166,-0.23551418365561805
0.0033476980519191535,0.0019463999999999998,166.13517465410956,373.89177648519166,-0.23551418365561805
0.003391728605828489,0.001972,166.23878826597266,373.89177648519166,-0.23551418365561805
0.003401360289496156,0.0019776,166.26138366335522,373.89177648519166,-0.23551418365561805
0.0034137438827831572,0.0019848,166.2903982558549,373.89177648519166,-0.23551418365561805
0.003427503430879824,0.0019928,166.32258859159094,373.89177648519166,-0.23551418365561805
0.0034412629789764915,0.0020008,166.3547285682398,373.89177648519166,-0.23551418365561805
0.0034577744366924923,0.0020104,166.39323045980817,373.89177648519166,-0.23551418365561805
0.00347566184921816,0.0020208,166.43486001763952,373.89177648519166,-0.23551418365561805
0.0034907973521244935,0.0020296,166.47001980687435,373.89177648519166,-0.23551418365561805
0.003523820267556495,0.0020488,166.54652636450106,373.89177648519166,-0.23551418365561805
0.0035417076800821623,0.0020591999999999997,166.587850646206,373.89177648519166,-0.23551418365561805
0.0035664748666561644,0.0020736,166.64493475814558,373.89177648519166,-0.23551418365561805
0.0036173851946138327,0.0021032,166.76179108707896,373.89177648519166,-0.23551418365561805
0.0036338966523298336,0.0021127999999999997,166.7995524615642,373.89177648519166,-0.23551418365561805
0.0036490321552361676,0.0021216,166.83410831316817,373.89177648519166,-0.23551418365561805
0.0036985665283841697,0.0021504,166.94681136551378,373.89177648519166,-0.23551418365561805
0.0037302134890065046,0.0021688,167.0185080107028,373.89177648519166,-0.23551418365561805
0.0037412211274838385,0.0021752,167.04339031648925,373.89177648519166,-0.23551418365561805
0.003764612359248173,0.0021888,167.096170613814,373.89177648519166,-0.23551418365561805
0.0037769959525351736,0.002196,167.1240613370911,373.89177648519166,-0.23551418365561805
0.003800387184299508,0.0022096,167.17664670294673,373.89177648519166,-0.23551418365561805
0.0038168986420155085,0.0022191999999999997,167.2136898130933,373.89177648519166,-0.23551418365561805
0.0038389139189701767,0.002232,167.26298355809723,373.89177648519166,-0.23551418365561805
0.0038705608795925116,0.0022504,167.33365060431294,373.89177648519166,-0.23551418365561805
0.003933854800837181,0.0022872,167.4743122746332,373.89177648519166,-0.23551418365561805
0.003965501761459516,0.0023056,167.54431191469337,373.89177648519166,-0.23551418365561805
0.004085209829900521,0.0023752,167.80714538835008,373.89177648519166,-0.23551418365561805
0.004126488474190523,0.0023991999999999998,167.89707888782732,373.89177648519166,-0.23551418365561805
0.004141623977096857,0.002408,167.92996650749987,373.89177648519166,-0.23551418365561805
0.004158135434812858,0.0024176,167.96579049839556,373.89177648519166,-0.23551418365561805
0.004182902621386858,0.0024319999999999997,168.01942263785503,373.89177648519166,-0.23551418365561805
0.004198038124293193,0.0024408,168.05213687094104,373.89177648519166,-0.23551418365561805
0.00427921945806353,0.0024879999999999998,168.2268252934812,373.89177648519166,-0.23551418365561805
0.004319122147543865,0.0025112,168.31221494136446,373.89177648519166,-0.23551418365561805
0.004379664159169201,0.0025464,168.4411864588656,373.89177648519166,-0.23551418365561805
0.004397551571694868,0.0025567999999999997,168.47915837253095,373.89177648519166,-0.23551418365561805
0.004416814939030203,0.002568,168.51998389985673,373.89177648519166,-0.23551418365561805
0.0044264466226978695,0.0025735999999999997,168.54037061871895,373.89177648519166,-0.23551418365561805
0.00443057448712687,0.0025759999999999997,168.5491024870644,373.89177648519166,-0.23551418365561805
0.004453965718891205,0.0025896,168.59852327565463,373.89177648519166,-0.23551418365561805
0.004463597402558871,0.0025951999999999998,168.61884357875988,373.89177648519166,-0.23551418365561805
0.004531019188232541,0.0026344,168.76060992943337,373.89177648519166,-0.23551418365561805
0.0045667940132838765,0.0026552,168.83549868768898,373.89177648519166,-0.23551418365561805
0.004580553561380544,0.0026631999999999997,168.86424109098962,373.89177648519166,-0.23551418365561805
0.004619080296051212,0.0026856,168.94454123398884,373.89177648519166,-0.23551418365561805
0.0046397196181962135,0.0026976,168.98745170012907,373.89177648519166,-0.23551418365561805
0.004652103211483214,0.0027048,169.0131622479927,373.89177648519166,-0.23551418365561805
0.004694757810582883,0.0027296,169.10151721431083,373.89177648519166,-0.23551418365561805
0.004707141403869883,0.0027367999999999997,169.12710994388772,373.89177648519166,-0.23551418365561805
0.004752547912588885,0.0027632,169.22072613649752,373.89177648519166,-0.23551418365561805
0.004758051731827552,0.0027664,169.23204980206134,373.89177648519166,-0.23551418365561805
0.004786946782830553,0.0027832,169.29141544529676,373.89177648519166,-0.23551418365561805
0.004835105201168889,0.0028112,169.39004855723516,373.89177648519166,-0.23551418365561805
0.004844736884836556,0.0028168,169.4097291222933,373.89177648519166,-0.23551418365561805
0.004892895303174891,0.0028447999999999998,169.50790398489656,373.89177648519166,-0.23551418365561805
0.004919038444558559,0.0028599999999999997,169.56104106591806,373.89177648519166,-0.23551418365561805
0.00494793349556156,0.0028767999999999997,169.61964354976047,373.89177648519166,-0.23551418365561805
0.004956189224419561,0.0028816,169.6363625823176,373.89177648519166,-0.23551418365561805
0.0049892121398515624,0.0029008,169.70313038479082,373.89177648519166,-0.23551418365561805
0.00500297168794823,0.0029088,169.73089940927173,373.89177648519166,-0.23551418365561805
0.0050511301062865655,0.0029368,169.82785730402668,373.89177648519166,-0.23551418365561805
0.005063513699573566,0.002944,169.85273097857961,373.89177648519166,-0.23551418365561805
0.005104792343863567,0.0029679999999999997,169.93547241473394,373.89177648519166,-0.23551418365561805
0.005179093903585571,0.0030112,170.08375241769514,373.89177648519166,-0.23551418365561805
0.0051914774968725725,0.0030184,170.10838486876474,373.89177648519166,-0.23551418365561805
0.005216244683446573,0.0030328,170.15758113224348,373.89177648519166,-0.23551418365561805
0.005245139734449574,0.0030496,170.21486178153006,373.89177648519166,-0.23551418365561805
0.0052905462431685766,0.0030759999999999997,170.3046262121912,373.89177648519166,-0.23551418365561805
0.005305681746074911,0.0030848,170.33448085444536,373.89177648519166,-0.23551418365561805
0.00536071993846158,0.0031168,170.44276432143295,373.89177648519166,-0.23551418365561805
0.005384111170225914,0.0031303999999999998,170.48865340416708,373.89177648519166,-0.23551418365561805
0.0054212619500869155,0.003152,170.56137657882695,373.89177648519166,-0.23551418365561805
0.005433645543373917,0.0031592,170.5855744122081,373.89177648519166,-0.23551418365561805
0.0054419012722319166,0.0031639999999999997,170.60169435343417,373.89177648519166,-0.23551418365561805
0.005466668458805918,0.0031784,170.64999704944475,373.89177648519166,-0.23551418365561805
0.005502443283857253,0.0031991999999999997,170.71961720776702,373.89177648519166,-0.23551418365561805
0.005521706651192587,0.0032104,170.75703185656664,373.89177648519166,-0.23551418365561805
0.005542345973337588,0.0032224,170.79706253547877,373.89177648519166,-0.23551418365561805
0.00565517426773026,0.0032879999999999997,171.0148778559136,373.89177648519166,-0.23551418365561805
0.0056661819062075935,0.0032944,171.03603698256177,373.89177648519166,-0.23551418365561805
0.005674437635065594,0.0032992,171.05189580868594,373.89177648519166,-0.23551418365561805
0.0057074605504975956,0.0033184,171.11524133535414,373.89177648519166,-0.23551418365561805
0.005741859420739264,0.0033384,171.18107444864117,373.89177648519166,-0.23551418365561805
0.005783138065029265,0.0033623999999999998,171.2598714955464,373.89177648519166,-0.23551418365561805
0.005792769748696933,0.003368,171.27822587495308,373.89177648519166,-0.23551418365561805
0.005813409070841933,0.0033799999999999998,171.31751665794536,373.89177648519166,-0.23551418365561805
0.005898718269041271,0.0034295999999999997,171.47934475445905,373.89177648519166,-0.23551418365561805
0.005909725907518605,0.003436,171.5001591108507,373.89177648519166,-0.23551418365561805
0.005923485455615272,0.003444,171.52615580599763,373.89177648519166,-0.23551418365561805
0.005930365229663606,0.0034479999999999997,171.53914532118378,373.89177648519166,-0.23551418365561805
0.005948252642189273,0.0034584,171.57289058646978,373.89177648519166,-0.23551418365561805
0.006014298473053277,0.0034968,171.6971471274893,373.89177648519166,-0.23551418365561805
0.006081720258726946,0.0035359999999999996,171.8234446566412,373.89177648519166,-0.23551418365561805
0.006085848123155946,0.0035383999999999997,171.83115937169444,373.89177648519166,-0.23551418365561805
0.006109239354920281,0.003552,171.8748376044079,373.89177648519166,-0.23551418365561805
0.006121622948207281,0.0035591999999999998,171.89793496744915,373.89177648519166,-0.23551418365561805
0.006183540914642284,0.0035952,172.013149571493,373.89177648519166,-0.23551418365561805
0.006202804281977618,0.0036063999999999996,172.04890223500763,373.89177648519166,-0.23551418365561805
0.006215187875264619,0.0036136,172.07186322560185,373.89177648519166,-0.23551418365561805
0.006222067649312953,0.0036176,172.08461162173697,373.89177648519166,-0.23551418365561805
0.006246834835886954,0.003632,172.13046039939033,373.89177648519166,-0.23551418365561805
0.006288113480176956,0.003656,172.20671780003318,373.89177648519166,-0.23551418365561805
0.006292241344605956,0.0036584,172.21433278661777,373.89177648519166,-0.23551418365561805
0.006347279536992625,0.0036904,172.3156804890598,373.89177648519166,-0.23551418365561805
0.006377550542805293,0.003708,172.37127561738322,373.89177648519166,-0.23551418365561805
0.006413325367856628,0.0037288,172.43684644336128,373.89177648519166,-0.23551418365561805
0.0064683635602432975,0.0037608,172.53744677759587,373.89177648519166,-0.23551418365561805
0.006513770068962299,0.0037871999999999997,172.6201909776101,373.89177648519166,-0.23551418365561805
0.0065522968036329675,0.0038096,172.69022192176215,373.89177648519166,-0.23551418365561805
0.006623846453735638,0.0038512,172.81985480228985,373.89177648519166,-0.23551418365561805
0.0066403579114516385,0.0038607999999999997,172.84969239270032,373.89177648519166,-0.23551418365561805
0.006647237685499972,0.0038648,172.8621161806139,373.89177648519166,-0.23551418365561805
0.006659621278786973,0.003872,172.8844663690101,373.89177648519166,-0.23551418365561805
0.006706403742315642,0.0038992,172.96875453872835,373.89177648519166,-0.23551418365561805
0.006742178567366977,0.00392,173.03305556425036,373.89177648519166,-0.23551418365561805
0.006754562160653977,0.0039272,173.05528259141855,373.89177648519166,-0.23551418365561805
0.006788961030895645,0.0039472,173.1169411016046,373.89177648519166,-0.23551418365561805
0.0068178560818986465,0.003964,173.16864014759037,373.89177648519166,-0.23551418365561805
0.006831615629995314,0.003972,173.19322870059997,373.89177648519166,-0.23551418365561805
0.006857758771378982,0.0039872,173.23989380592232,373.89177648519166,-0.23551418365561805
0.007705512081740369,0.004480096019203841,174.7174893727823,373.89177648519166,-0.23551418365561805
0.008035807295103057,0.004672134426885377,175.27582772138436,373.89177648519166,-0.23551418365561805
0.008531250115147089,0.004960192038407682,176.09683476959356,373.89177648519166,-0.23551418365561805
0.010380903309978139,0.006035607121424285,179.00997835544462,373.89177648519166,-0.23551418365561805
0.011074523258039783,0.006438887777555511,180.04914943030016,373.89177648519166,-0.23551418365561805
0.011140582300712321,0.0064772954590918185,180.1467750253785,373.89177648519166,-0.23551418365561805
0.01173511368476516,0.006822964592918584,181.0154738872799,373.89177648519166,-0.23551418365561805
0.012957205974207103,0.007533506701340268,182.74897852550487,373.89177648519166,-0.23551418365561805
0.013155383102224716,0.0076487297459491895,183.02396305178485,373.89177648519166,-0.23551418365561805
0.013981121135631436,0.00812882576515303,184.15276188482156,373.89177648519166,-0.23551418365561805
0.014080209699640241,0.008186437287457491,184.28644782700897,373.89177648519166,-0.23551418365561805
0.0144435344343392,0.008397679535907181,184.77352157689594,373.89177648519166,-0.23551418365561805
0.01493897725438323,0.008685737147429486,185.43008087912656,373.89177648519166,-0.23551418365561805
0.015335331510418456,0.00891618323664733,185.94923372640466,373.89177648519166,-0.23551418365561805
0.01741619135460339,0.010126025205041009,188.5933777596283,373.89177648519166,-0.23551418365561805
0.018109811302665032,0.010529305861172233,189.44696398963922,373.89177648519166,-0.23551418365561805
0.019199785506761904,0.011163032606521305,190.762987484327,373.89177648519166,-0.23551418365561805
0.01979431689081474,0.01150870174034807,191.46852200130274,373.89177648519166,-0.23551418365561805
0.020091582582841157,0.011681536307261452,191.81818634394196,373.89177648519166,-0.23551418365561805
0.020653084445557728,0.012008001600320064,192.4732069953643,373.89177648519166,-0.23551418365561805
0.021247615829610565,0.012353670734146829,193.15923260123117,373.89177648519166,-0.23551418365561805
0.02164397008564579,0.012584116823364673,193.61242821326866,373.89177648519166,-0.23551418365561805
0.0228000033324152,0.01325625125025005,194.9161165970302,373.89177648519166,-0.23551418365561805
0.02349362328047684,0.013659531906381276,195.68595762839942,373.89177648519166,-0.23551418365561805
0.024088154664529682,0.014005201040208042,196.33879197011908,373.89177648519166,-0.23551418365561805
0.02471571556991879,0.014370074014802961,197.02111361247418,373.89177648519166,-0.23551418365561805
0.025376305996644165,0.014754150830166034,197.73208693023489,373.89177648519166,-0.23551418365561805
0.025904778338024462,0.015061412282456492,198.2956818403408,373.89177648519166,-0.23551418365561805
0.026069925944705807,0.01515743148629726,198.47088330405433,373.89177648519166,-0.23551418365561805
0.02689566397811253,0.0156375275055011,199.34048059730873,373.89177648519166,-0.23551418365561805
0.02735807727682029,0.015906381276255252,199.8229052874512,373.89177648519166,-0.23551418365561805
0.02838199243824462,0.016501700340068013,200.87995601193833,373.89177648519166,-0.23551418365561805
0.029141671428978798,0.016943388677735545,201.6546331681258,373.89177648519166,-0.23551418365561805
0.029538025685014024,0.01717383476695339,202.05568360125838,373.89177648519166,-0.23551418365561805
0.030000438983721792,0.017442688537707543,202.52093270655993,373.89177648519166,-0.23551418365561805
0.030330734197084475,0.017634726945389076,202.85154279803538,373.89177648519166,-0.23551418365561805
0.030859206538464776,0.017941988397679534,203.37761325941906,373.89177648519166,-0.23551418365561805
0.03109041318781866,0.01807641528305661,203.6066629636302,373.89177648519166,-0.23551418365561805
0.03241159404126941,0.018844568913782757,204.90299451764224,373.89177648519166,-0.23551418365561805
0.033105213989331056,0.01924784956991398,205.57530881676564,373.89177648519166,-0.23551418365561805
0.03412912915075539,0.019843168633726746,206.55781764250528,373.89177648519166,-0.23551418365561805
0.03515304431217972,0.020438487697539507,207.52889560549215,373.89177648519166,-0.23551418365561805
0.036011811866922705,0.0209377875575115,208.3348708593515,373.89177648519166,-0.23551418365561805
0.036540284208303006,0.02124504900980196,208.82713114436243,373.89177648519166,-0.23551418365561805
0.03693663846433823,0.021475495099019803,209.1945062584653,373.89177648519166,-0.23551418365561805
0.03720087463502838,0.021629125825165033,209.43856922192572,373.89177648519166,-0.23551418365561805
0.03832387836046152,0.022282056411282256,210.46838367133702,373.89177648519166,-0.23551418365561805
0.03938082304322212,0.022896579315863173,211.4269209622907,373.89177648519166,-0.23551418365561805
0.040702003896672875,0.023664732946589318,212.61109770707188,373.89177648519166,-0.23551418365561805
0.04083412198201795,0.023741548309661933,212.7286848359329,373.89177648519166,-0.23551418365561805
0.04142865336607079,0.024087217443488698,213.25600146295042,373.89177648519166,-0.23551418365561805
0.04159380097275213,0.024183236647329465,213.40195348234298,373.89177648519166,-0.23551418365561805
0.04208924379279616,0.02447129425885177,213.8384595047925,373.89177648519166,-0.23551418365561805
0.04238650948482258,0.024644128825765152,214.09940133672376,373.89177648519166,-0.23551418365561805
0.0432122475182293,0.025124224844968995,214.82052138813225,373.89177648519166,-0.23551418365561805
0.043509513210255715,0.025297059411882376,215.07880641888923,373.89177648519166,-0.23551418365561805
0.04509493023439662,0.02621884376875375,216.44487460116866,373.89177648519166,-0.23551418365561805
0.04549128449043184,0.026449289857971594,216.7834489045661,373.89177648519166,-0.23551418365561805
0.04644914060918364,0.02700620124024805,217.59695523959672,373.89177648519166,-0.23551418365561805
0.047010642471900205,0.02733266653330666,218.07079652539858,373.89177648519166,-0.23551418365561805
0.04747305577060797,0.027601520304060812,218.45936361190306,373.89177648519166,-0.23551418365561805
0.047671232898625585,0.027716743348669734,218.62544018645582,373.89177648519166,-0.23551418365561805
0.04833182332535096,0.028100820164032807,219.1770943505611,373.89177648519166,-0.23551418365561805
0.04902544327341261,0.028504100820164035,219.7531757348472,373.89177648519166,-0.23551418365561805
0.04971906322147425,0.02890738147629526,220.326087054323,373.89177648519166,-0.23551418365561805
0.05031359460552709,0.029253050610122025,220.81467731560082,373.89177648519166,-0.23551418365561805
0.05064388981888977,0.02944508901780356,221.0851432775885,373.89177648519166,-0.23551418365561805
0.050742978382898575,0.02950270054010802,221.1661488035566,373.89177648519166,-0.23551418365561805
0.051436598330960225,0.02990598119623925,221.73147007150945,373.89177648519166,-0.23551418365561805
0.052196277321694406,0.03034766953390678,222.34723098881793,373.89177648519166,-0.23551418365561805
0.05322019248311874,0.030942988597719545,223.17166768328315,373.89177648519166,-0.23551418365561805
0.05371563530316277,0.031231046209241848,223.56836591044393,373.89177648519166,-0.23551418365561805
0.05381472386717157,0.03128865773154631,223.6475340393249,373.89177648519166,-0.23551418365561805
0.054111989559198,0.031461492298459695,223.8846980226284,373.89177648519166,-0.23551418365561805
0.05530105232730367,0.03215283056611322,224.8283164413807,373.89177648519166,-0.23551418365561805
0.05556528849799382,0.03230646129225845,225.036930965596,373.89177648519166,-0.23551418365561805
0.055730436104675166,0.03240248049609922,225.16711859027075,373.89177648519166,-0.23551418365561805
0.056655262702090696,0.03294018803760752,225.89340781180474,373.89177648519166,-0.23551418365561805
0.05774523690618756,0.03357391478295659,226.74348200690298,373.89177648519166,-0.23551418365561805
0.059330653930328464,0.034495699139827966,227.9688663863987,373.89177648519166,-0.23551418365561805
0.059826096750372496,0.03478375675135027,228.34917125341525,373.89177648519166,-0.23551418365561805
0.06184089755188489,0.03595519103820764,229.88325628632722,373.89177648519166,-0.23551418365561805
0.06200604515856623,0.03605121024204841,230.00813000103443,373.89177648519166,-0.23551418365561805
0.062435428935937724,0.036300860172034405,230.3321961232215,373.89177648519166,-0.23551418365561805
0.06322813744800818,0.03676175235047009,230.9281976396718,373.89177648519166,-0.23551418365561805
0.06372358026805222,0.037049809961992405,231.29921909968846,373.89177648519166,-0.23551418365561805
0.0643511411734413,0.03741468293658731,231.76756856575682,373.89177648519166,-0.23551418365561805
0.06507779064283922,0.037837167433486696,232.30764832915062,373.89177648519166,-0.23551418365561805
0.06613473532559982,0.03845169033806761,233.0890392830201,373.89177648519166,-0.23551418365561805
0.06633291245361744,0.03856691338267654,233.23500629799145,373.89177648519166,-0.23551418365561805
0.06692744383767027,0.0389125825165033,233.6718902860622,373.89177648519166,-0.23551418365561805
0.06745591617905057,0.03921984396879376,234.05896256225964,373.89177648519166,-0.23551418365561805
0.06894224463918266,0.04008401680336067,235.1413134380744,373.89177648519166,-0.23551418365561805
0.06940465793789044,0.040352870574114824,235.47618372367097,373.89177648519166,-0.23551418365561805
0.07032948453530595,0.04089057811562312,236.14332526206582,373.89177648519166,-0.23551418365561805
0.0709240159193588,0.041236247249449895,236.57039591107667,373.89177648519166,-0.23551418365561805
0.07201399012345566,0.041869973994798956,237.34975002309153,373.89177648519166,-0.23551418365561805
0.0727076100715173,0.04227325465093018,237.84330826374747,373.89177648519166,-0.23551418365561805
0.07333517097690641,0.0426381276255251,238.28828090422329,373.89177648519166,-0.23551418365561805
0.0737645547542779,0.0428877775555111,238.5918805638074,373.89177648519166,-0.23551418365561805
0.07432605661699448,0.043214242848569714,238.9878575724634,373.89177648519166,-0.23551418365561805
0.07498664704371985,0.04359831966393278,239.4522223253997,373.89177648519166,-0.23551418365561805
0.07508573560772866,0.04365593118623724,239.52173919202806,373.89177648519166,-0.23551418365561805
0.07541603082109136,0.04384796959391879,239.7532041152443,373.89177648519166,-0.23551418365561805
0.07561420794910896,0.0439631926385277,239.89189330585452,373.89177648519166,-0.23551418365561805
0.07604359172648045,0.0442128425685137,240.19190116665354,373.89177648519166,-0.23551418365561805
0.07637388693984315,0.04440488097619524,240.4222271017026,373.89177648519166,-0.23551418365561805
0.0768363002385509,0.044673734746949384,240.7440318385532,373.89177648519166,-0.23551418365561805
0.07819051061333793,0.04546109221844369,241.6821432395868,373.89177648519166,-0.23551418365561805
0.0785538353480369,0.04567233446689338,241.93275086497317,373.89177648519166,-0.23551418365561805
0.07904927816808091,0.04596039207841568,242.27376124427443,373.89177648519166,-0.23551418365561805
0.07937957338144362,0.046152430486097226,242.50063853317033,373.89177648519166,-0.23551418365561805
0.07984198668015136,0.04642128425685137,242.81764918536564,373.89177648519166,-0.23551418365561805
0.08010622285084151,0.046574914982996596,242.99847663408818,373.89177648519166,-0.23551418365561805
0.0802383409361866,0.04665173034606922,243.08880311370262,373.89177648519166,-0.23551418365561805
0.08126225609761092,0.047247049409881975,243.78687730153047,373.89177648519166,-0.23551418365561805
0.08162558083230988,0.04745829165833167,244.0337553778378,373.89177648519166,-0.23551418365561805
0.08304585024976945,0.048284056811362275,244.9947400782243,373.89177648519166,-0.23551418365561805
0.08344220450580465,0.04851450290058011,245.2617751398182,373.89177648519166,-0.23551418365561805
0.08370644067649481,0.04866813362672534,245.4395237401241,373.89177648519166,-0.23551418365561805
0.08406976541119376,0.04887937587517503,245.68357117387532,373.89177648519166,-0.23551418365561805
0.08525882817929946,0.04957071414282857,246.47941131100362,373.89177648519166,-0.23551418365561805
0.08598547764869735,0.04999319863972794,246.96362750880937,373.89177648519166,-0.23551418365561805
0.08631577286206006,0.05018523704740949,247.18319795120064,373.89177648519166,-0.23551418365561805
0.08717454041680303,0.05068453690738148,247.75255301737866,373.89177648519166,-0.23551418365561805
0.08776907180085587,0.05103020604120824,248.14544116140723,373.89177648519166,-0.23551418365561805
0.08800027845020977,0.051164632926585324,248.29795052213103,373.89177648519166,-0.23551418365561805
0.08852875079159006,0.05147189437887578,248.64595774888656,373.89177648519166,-0.23551418365561805
0.08892510504762528,0.05170234046809362,248.90643172539703,373.89177648519166,-0.23551418365561805
0.08925540026098797,0.05189437887577515,249.12314767859436,373.89177648519166,-0.23551418365561805
0.08968478403835946,0.05214402880576115,249.4044114042012,373.89177648519166,-0.23551418365561805
0.0901802268584035,0.05243208641728346,249.7282947138334,373.89177648519166,-0.23551418365561805
0.09041143350775738,0.05256651330266053,249.87920270051063,373.89177648519166,-0.23551418365561805
0.09057658111443871,0.0526625325065013,249.98690198770888,373.89177648519166,-0.23551418365561805
0.0911380829771553,0.052988997799559914,250.35250808145574,373.89177648519166,-0.23551418365561805
0.09146837819051798,0.05318103620724145,250.56716013808892,373.89177648519166,-0.23551418365561805
0.09156746675452679,0.05323864772954591,250.6314967799446,373.89177648519166,-0.23551418365561805
0.091963821010562,0.05346909381876375,250.88857228967663,373.89177648519166,-0.23551418365561805
0.09232714574526096,0.05368033606721344,251.12384550027983,373.89177648519166,-0.23551418365561805
0.09424285798276456,0.05479415883176636,252.35845621310912,373.89177648519166,-0.23551418365561805
0.09487041888815365,0.05515903180636127,252.7607642100857,373.89177648519166,-0.23551418365561805
0.09520071410151636,0.05535107021404281,252.97208831342422,373.89177648519166,-0.23551418365561805
0.09681916064699352,0.05629205841168233,254.0034715699447,373.89177648519166,-0.23551418365561805
0.09774398724440905,0.05682976595319064,254.58981425337387,373.89177648519166,-0.23551418365561805
0.09794216437242667,0.05694498899779957,254.71517716628176,373.89177648519166,-0.23551418365561805
0.09909819761919605,0.05761712342468493,255.44449878715275,373.89177648519166,-0.23551418365561805
0.0998909061312665,0.05807801560312062,255.94268838949122,373.89177648519166,-0.23551418365561805
0.10068361464333696,0.05853890778155631,256.43933848936047,373.89177648519166,-0.23551418365561805
0.10197176597545145,0.05928785757151431,257.2431546592598,373.89177648519166,-0.23551418365561805
0.10309476970088459,0.05994078815763153,257.9406918116797,373.89177648519166,-0.23551418365561805
0.10345809443558354,0.06015203040608122,258.1657303251644,373.89177648519166,-0.23551418365561805
0.10461412768235295,0.0608241648329666,258.8797200712338,373.89177648519166,-0.23551418365561805
0.10497745241705192,0.06103540708141629,259.103480470788,373.89177648519166,-0.23551418365561805
0.1052086590664058,0.06116983396679336,259.24571621242245,373.89177648519166,-0.23551418365561805
0.10577016092912236,0.06149629925985198,259.5906392995698,373.89177648519166,-0.23551418365561805
0.10596833805713995,0.06161152230446089,259.71220626368626,373.89177648519166,-0.23551418365561805
0.10692619417589175,0.06216843368673734,260.2985345608107,373.89177648519166,-0.23551418365561805
0.10722345986791817,0.06234126825365073,260.4800815404966,373.89177648519166,-0.23551418365561805
0.10821434550800625,0.06291738347669534,261.0838254429607,373.89177648519166,-0.23551418365561805
0.10890796545606789,0.06332066413282657,261.5051639759262,373.89177648519166,-0.23551418365561805
0.10956855588279325,0.06370474094818963,261.9054668547778,373.89177648519166,-0.23551418365561805
0.10979976253214715,0.06383916783356672,262.04535035162615,373.89177648519166,-0.23551418365561805
0.11009702822417355,0.06401200240048009,262.2250318803002,373.89177648519166,-0.23551418365561805
0.1105924710442176,0.0643000600120024,262.5240812049564,373.89177648519166,-0.23551418365561805
0.11118700242827044,0.06464572914582917,262.8822515963689,373.89177648519166,-0.23551418365561805
0.11141820907762431,0.06478015603120624,263.0213382712899,373.89177648519166,-0.23551418365561805
0.11181456333365955,0.06501060212042409,263.2595109758359,373.89177648519166,-0.23551418365561805
0.11224394711103104,0.06526025205041008,263.51716014911267,373.89177648519166,-0.23551418365561805
0.11277241945241134,0.06556751350270054,263.83373974274343,373.89177648519166,-0.23551418365561805
0.1130036261017652,0.06570194038807761,263.9720613208393,373.89177648519166,-0.23551418365561805
0.11330089179379164,0.065874774954991,264.14974127761514,373.89177648519166,-0.23551418365561805
0.11369724604982685,0.06610522104420884,264.3863653317745,373.89177648519166,-0.23551418365561805
0.113961482220517,0.06625885177035407,264.5439360014946,373.89177648519166,-0.23551418365561805
0.11432480695521596,0.06647009401880376,264.76036321680033,373.89177648519166,-0.23551418365561805
0.11501842690327763,0.066873374674935,265.1727990213025,373.89177648519166,-0.23551418365561805
0.11554689924465793,0.06718063612722545,265.486385082771,373.89177648519166,-0.23551418365561805
0.11657081440608225,0.06777595519103821,266.09237088169704,373.89177648519166,-0.23551418365561805
0.11690110961944493,0.06796799359871974,266.2874068812522,373.89177648519166,-0.23551418365561805
0.11742958196082523,0.0682752550510102,266.59901805661343,373.89177648519166,-0.23551418365561805
0.11825531999423196,0.06875535107021405,267.08481784711637,373.89177648519166,-0.23551418365561805
0.11858561520759464,0.06894738947789558,267.2787671206649,373.89177648519166,-0.23551418365561805
0.11871773329293973,0.0690242048409682,267.3562878260369,373.89177648519166,-0.23551418365561805
0.11934529419832882,0.06938907781556311,267.72405268810945,373.89177648519166,-0.23551418365561805
0.12000588462505421,0.06977315463092619,268.1103597453735,373.89177648519166,-0.23551418365561805
0.12030315031708064,0.06994598919783958,268.28392726248666,373.89177648519166,-0.23551418365561805
0.12136009499984124,0.0705605121024205,268.89970617707826,373.89177648519166,-0.23551418365561805
0.12208674446923913,0.07098299659931986,269.32184144331075,373.89177648519166,-0.23551418365561805
0.12248309872527437,0.07121344268853771,269.55168399594913,373.89177648519166,-0.23551418365561805
0.12281339393863705,0.07140548109621925,269.7429979594948,373.89177648519166,-0.23551418365561805
0.12400245670674273,0.07209681936387279,270.4300729545046,373.89177648519166,-0.23551418365561805
0.12446487000545048,0.07236567313462693,270.6965742777127,373.89177648519166,-0.23551418365561805
0.12512546043217587,0.07274974994999,271.07662159030025,373.89177648519166,-0.23551418365561805
0.12542272612420227,0.07292258451690338,271.2473875062847,373.89177648519166,-0.23551418365561805
0.12621543463627272,0.07338347669533907,271.7019933514331,373.89177648519166,-0.23551418365561805
0.12644664128562663,0.07351790358071615,271.83437679373037,373.89177648519166,-0.23551418365561805
0.12704117266967946,0.07386357271454291,272.17435860050927,373.89177648519166,-0.23551418365561805
0.12723934979769708,0.07397879575915184,272.2875479039511,373.89177648519166,-0.23551418365561805
0.12789994022442244,0.0743628725745149,272.6643500045594,373.89177648519166,-0.23551418365561805
0.12918809155653693,0.0751118223644729,273.39693815070723,373.89177648519166,-0.23551418365561805
0.12978262294058976,0.07545749149829967,273.73409437110263,373.89177648519166,-0.23551418365561805
0.13077350858067782,0.07603360672134428,274.2946859070655,373.89177648519166,-0.23551418365561805
0.13166530565675708,0.07655211042208442,274.7978034854524,373.89177648519166,-0.23551418365561805
0.1319625713487835,0.0767249449889978,274.96521377977285,373.89177648519166,-0.23551418365561805
0.1329204274675353,0.07728185637127426,275.5036492205839,373.89177648519166,-0.23551418365561805
0.13334981124490677,0.07753150630126025,275.7445253975732,373.89177648519166,-0.23551418365561805
0.13377919502227828,0.07778115623124625,275.985099273331,373.89177648519166,-0.23551418365561805
0.13437372640633113,0.07812682536507302,276.3177050060714,373.89177648519166,-0.23551418365561805
0.13615732055848961,0.07916383276655331,277.31209560877835,373.89177648519166,-0.23551418365561805
0.13645458625051604,0.0793366673334667,277.4773322263472,373.89177648519166,-0.23551418365561805
0.1371151766772414,0.07972074414882976,277.8440229199458,373.89177648519166,-0.23551418365561805
0.13784182614663934,0.08014322864572915,278.2465878229056,373.89177648519166,-0.23551418365561805
0.13886574130806367,0.08073854770954192,278.8124364246814,373.89177648519166,-0.23551418365561805
0.13932815460677142,0.08100740148029606,279.0674473585194,373.89177648519166,-0.23551418365561805
0.13955936125612534,0.08114182836567314,279.19482903147104,373.89177648519166,-0.23551418365561805
0.139889656469488,0.08133386677335468,279.3766601732919,373.89177648519166,-0.23551418365561805
0.14160719157897397,0.08233246649329866,280.3194965829834,373.89177648519166,-0.23551418365561805
0.1420035458350092,0.08256291258251651,280.5364396131646,373.89177648519166,-0.23551418365561805
0.14279625434707965,0.0830238047609522,280.96961850963214,373.89177648519166,-0.23551418365561805
0.14365502190182264,0.08352310462092419,281.4378386855742,373.89177648519166,-0.23551418365561805
0.14388622855117653,0.08365753150630126,281.563711291755,373.89177648519166,-0.23551418365561805
0.14415046472186666,0.08381116223244649,281.7074691493034,373.89177648519166,-0.23551418365561805
0.14484408466992832,0.08421444288857773,282.08434540523245,373.89177648519166,-0.23551418365561805
0.1450752913192822,0.0843488697739548,282.20981432562064,373.89177648519166,-0.23551418365561805
0.1457028522246713,0.08471374274854972,282.54998033698837,373.89177648519166,-0.23551418365561805
0.14619829504471535,0.08500180036007202,282.8181289960609,373.89177648519166,-0.23551418365561805
0.14682585595010444,0.08536667333466694,283.15727575318874,373.89177648519166,-0.23551418365561805
0.1470900921207946,0.08552030406081217,283.2999052039038,373.89177648519166,-0.23551418365561805
0.14778371206885624,0.08592358471694339,283.67383288552713,373.89177648519166,-0.23551418365561805
0.1487745977089443,0.086499699939988,284.20683014356297,373.89177648519166,-0.23551418365561805
0.14936912909299713,0.08684536907381477,284.52596399077305,373.89177648519166,-0.23551418365561805
0.14966639478502355,0.08701820364072815,284.6853451139052,373.89177648519166,-0.23551418365561805
0.15095454611713804,0.08776715343068614,285.37457491619574,373.89177648519166,-0.23551418365561805
0.15181331367188103,0.08826645329065813,285.83278756459146,373.89177648519166,-0.23551418365561805
0.15211057936390746,0.08843928785757152,285.9911639686869,373.89177648519166,-0.23551418365561805
0.15253996314127893,0.08868893778755751,286.21971694838845,373.89177648519166,-0.23551418365561805
0.15303540596132295,0.08897699539907981,286.48312037951285,373.89177648519166,-0.23551418365561805
0.15356387830270327,0.08928425685137027,286.7637177365789,373.89177648519166,-0.23551418365561805
0.1555456495828794,0.0904364872974595,287.81262055081874,373.89177648519166,-0.23551418365561805
0.15630532857361357,0.09087817563512703,288.2133164667356,373.89177648519166,-0.23551418365561805
0.1566356237869763,0.09107021404280857,288.3872951052603,373.89177648519166,-0.23551418365561805
0.15719712564969285,0.09139667933586718,288.6827307858812,373.89177648519166,-0.23551418365561805
0.15762650942706433,0.09164632926585317,288.9083745766217,373.89177648519166,-0.23551418365561805
0.15785771607641821,0.09178075615123026,289.0297757818163,373.89177648519166,-0.23551418365561805
0.15855133602447988,0.09218403680736148,289.3935640024474,373.89177648519166,-0.23551418365561805
0.1595422216645679,0.09276015203040608,289.91218662265936,373.89177648519166,-0.23551418365561805
0.16036795969797463,0.09324024804960993,290.3434132264761,373.89177648519166,-0.23551418365561805
0.16165611103008912,0.09398919783956791,291.0144016141162,373.89177648519166,-0.23551418365561805
0.1628451737981948,0.09468053610722145,291.63192703982554,373.89177648519166,-0.23551418365561805
0.16307638044754869,0.09481496299259852,291.7517969493935,373.89177648519166,-0.23551418365561805
0.16347273470358392,0.09504540908181637,291.9571341347347,373.89177648519166,-0.23551418365561805
0.16396817752362794,0.09533346669333867,292.2135327774611,373.89177648519166,-0.23551418365561805
0.16492603364237973,0.09589037807561512,292.7083816913116,373.89177648519166,-0.23551418365561805
0.16555359454776883,0.09625525105021004,293.03198543128246,373.89177648519166,-0.23551418365561805
0.16575177167578645,0.09637047409481897,293.13407664834045,373.89177648519166,-0.23551418365561805
0.16614812593182166,0.0966009201840368,293.338116381082,373.89177648519166,-0.23551418365561805
0.16773354295596257,0.09752270454090818,294.1523841374634,373.89177648519166,-0.23551418365561805
0.16872442859605064,0.0980988197639528,294.65977751499133,373.89177648519166,-0.23551418365561805
0.17060711131221798,0.09919343868773756,295.6206346840993,373.89177648519166,-0.23551418365561805
0.171102554132262,0.09948149629925986,295.87280341285947,373.89177648519166,-0.23551418365561805
0.17136679030295215,0.09963512702540508,296.0071769553392,373.89177648519166,-0.23551418365561805
0.17153193790963348,0.09973114622924585,296.09111938638955,373.89177648519166,-0.23551418365561805
0.1719282921656687,0.0999615923184637,296.2924527273946,373.89177648519166,-0.23551418365561805