File: datasets/aisi_316_L/data/M1/train_57.csv
Time(s),Strain(%),Stress(MPa),Temp(C),Log_SR(s-1)
0.0,0.0,0.0,245.1028030911054,-1.8261714007535188
0.002305312702701155,3.4399999999999996e-05,6.269276375,245.1028030911054,-1.8261714007535188
0.0026805961659315757,3.9999999999999996e-05,7.28985625,245.1028030911054,-1.8261714007535188
0.004181730018853258,6.24e-05,11.37217575,245.1028030911054,-1.8261714007535188
0.005897311565049467,8.8e-05,16.03768375,245.1028030911054,-1.8261714007535188
0.008417071961025148,0.0001256,22.890148625,245.1028030911054,-1.8261714007535188
0.009757370043990935,0.0001456,26.535076749999998,245.1028030911054,-1.8261714007535188
0.010079041583902725,0.0001504,27.4098595,245.1028030911054,-1.8261714007535188
0.010293489277177251,0.0001536,27.993047999999998,245.1028030911054,-1.8261714007535188
0.010829608510363567,0.0001616,29.451019249999998,245.1028030911054,-1.8261714007535188
0.010990444280319462,0.000164,29.888410625,245.1028030911054,-1.8261714007535188
0.012437966209922512,0.00018559999999999998,33.824932999999994,245.1028030911054,-1.8261714007535188
0.01442160737271188,0.0002152,39.219426625,245.1028030911054,-1.8261714007535188
0.014743278912623668,0.00021999999999999998,40.094209375,245.1028030911054,-1.8261714007535188
0.01629802468886398,0.0002432,44.322326000000004,245.1028030911054,-1.8261714007535188
0.017799158541785664,0.0002656,48.4046455,245.1028030911054,-1.8261714007535188
0.018817785084839663,0.0002808,51.174790875,245.1028030911054,-1.8261714007535188
0.019032232778114187,0.00028399999999999996,51.75797937499999,245.1028030911054,-1.8261714007535188
0.019997247397849558,0.0002984,54.382327624999995,245.1028030911054,-1.8261714007535188
0.02106948586422219,0.0003144,57.298270125,245.1028030911054,-1.8261714007535188
0.021766440867364397,0.0003248,59.19363275,245.1028030911054,-1.8261714007535188
0.023964529723428288,0.00035759999999999996,65.171314875,245.1028030911054,-1.8261714007535188
0.025412051653031342,0.0003792,69.10783725,245.1028030911054,-1.8261714007535188
0.027074021275908917,0.000404,73.627548125,245.1028030911054,-1.8261714007535188
0.028360707435556073,0.0004232,77.126679125,245.1028030911054,-1.8261714007535188
0.029540169748565968,0.0004408,80.334215875,245.1028030911054,-1.8261714007535188
0.03184548245126712,0.0004752,86.60349225,245.1028030911054,-1.8261714007535188
0.03227437783781618,0.0004816,87.76986925,245.1028030911054,-1.8261714007535188
0.03313216861091428,0.0004944,90.10262325,245.1028030911054,-1.8261714007535188
0.033882735537375114,0.0005055999999999999,92.14378299999998,245.1028030911054,-1.8261714007535188
0.034740526310473224,0.0005184,94.47653700000001,245.1028030911054,-1.8261714007535188
0.036295272086713536,0.0005415999999999999,98.70465362499999,245.1028030911054,-1.8261714007535188
0.037313898629767535,0.0005568,101.47479899999999,245.1028030911054,-1.8261714007535188
0.039887270949061845,0.0005951999999999999,108.47306099999999,245.1028030911054,-1.8261714007535188
0.0403161663356109,0.0006016,109.639438,245.1028030911054,-1.8261714007535188
0.041656464418576684,0.0006215999999999999,113.28436612499999,245.1028030911054,-1.8261714007535188
0.04299676250154248,0.0006416,116.92929425,245.1028030911054,-1.8261714007535188
0.0443906725078269,0.0006624,120.72001949999999,245.1028030911054,-1.8261714007535188
0.045248463280925,0.0006751999999999999,123.05277349999999,245.1028030911054,-1.8261714007535188
0.04771461175358205,0.000712,129.75944124999998,245.1028030911054,-1.8261714007535188
0.048197119063449735,0.0007191999999999999,131.071615375,245.1028030911054,-1.8261714007535188
0.04862601444999879,0.0007256,132.237992375,245.1028030911054,-1.8261714007535188
0.04985908868632731,0.000744,135.59132625,245.1028030911054,-1.8261714007535188
0.050556043689469525,0.0007544,137.486688875,245.1028030911054,-1.8261714007535188
0.05189634177243531,0.0007744,141.131617,245.1028030911054,-1.8261714007535188
0.05302219216212657,0.0007911999999999999,144.19335662499998,245.1028030911054,-1.8261714007535188
0.053611923318631516,0.0007999999999999999,145.797125,245.1028030911054,-1.8261714007535188
0.05479138563164141,0.0008175999999999999,149.00466175,245.1028030911054,-1.8261714007535188
0.055166669094871834,0.0008232,150.02524162499998,245.1028030911054,-1.8261714007535188
0.05548834063478362,0.000828,150.900024375,245.1028030911054,-1.8261714007535188
0.05629251948456309,0.0008399999999999999,153.08698124999998,245.1028030911054,-1.8261714007535188
0.05709669833434257,0.000852,155.273938125,245.1028030911054,-1.8261714007535188
0.05741836987425436,0.0008568,156.148720875,245.1028030911054,-1.8261714007535188
0.05891950372717604,0.0008792,160.231040375,245.1028030911054,-1.8261714007535188
0.059241175267087824,0.0008839999999999999,161.10582312499997,245.1028030911054,-1.8261714007535188
0.059830906423592775,0.0008927999999999999,162.7095915,245.1028030911054,-1.8261714007535188
0.0620826072029753,0.0009264,168.83307075,245.1028030911054,-1.8261714007535188
0.06256511451284298,0.0009335999999999999,170.14524487499997,245.1028030911054,-1.8261714007535188
0.06331568143930383,0.0009448,172.186404625,245.1028030911054,-1.8261714007535188
0.06428069605903919,0.0009592,174.810752875,245.1028030911054,-1.8261714007535188
0.06556738221868634,0.0009784,178.309883875,245.1028030911054,-1.8261714007535188
0.0658354418352795,0.0009824,179.0388695,245.1028030911054,-1.8261714007535188
0.06653239683842173,0.0009928,180.93423212500002,245.1028030911054,-1.8261714007535188
0.06712212799492667,0.0010016,182.5380005,245.1028030911054,-1.8261714007535188
0.06749741145815709,0.0010072,183.558580375,245.1028030911054,-1.8261714007535188
0.0681943664612993,0.0010176,185.453943,245.1028030911054,-1.8261714007535188
0.0700707837774514,0.0010456,187.9924883508898,245.1028030911054,-1.8261714007535188
0.07033884339404455,0.0010496,188.01646343927453,245.1028030911054,-1.8261714007535188
0.07221526071019665,0.0010776,188.18330244984173,245.1028030911054,-1.8261714007535188
0.07259054417342707,0.0010831999999999999,188.2164664287025,245.1028030911054,-1.8261714007535188
0.07377000648643696,0.0011007999999999999,188.32026340699645,245.1028030911054,-1.8261714007535188
0.07419890187298603,0.0011072,188.35784703393477,245.1028030911054,-1.8261714007535188
0.07575364764922633,0.0011304,188.4933831599735,245.1028030911054,-1.8261714007535188
0.0760217072658195,0.0011344,188.5166413809051,245.1028030911054,-1.8261714007535188
0.07666505034564308,0.001144,188.57233100192772,245.1028030911054,-1.8261714007535188
0.07720116957882939,0.001152,188.61859993132074,245.1028030911054,-1.8261714007535188
0.0775764530420598,0.0011576,188.65091364993876,245.1028030911054,-1.8261714007535188
0.07816618419856475,0.0011664,188.7015694487567,245.1028030911054,-1.8261714007535188
0.07870230343175107,0.0011744,188.74749098271235,245.1028030911054,-1.8261714007535188
0.08084678036449634,0.0012064,188.92997009221807,245.1028030911054,-1.8261714007535188
0.08132928767436402,0.0012136,188.97076658912272,245.1028030911054,-1.8261714007535188
0.08207985460082486,0.0012247999999999998,189.03404068408798,245.1028030911054,-1.8261714007535188
0.08240152614073665,0.0012296,189.06108903087076,245.1028030911054,-1.8261714007535188
0.0836882123003838,0.0012488,189.16887314567197,245.1028030911054,-1.8261714007535188
0.08400988384029559,0.0012536,189.1957179522022,245.1028030911054,-1.8261714007535188
0.08583268923312906,0.0012808,189.3470880645659,245.1028030911054,-1.8261714007535188
0.08663686808290853,0.0012928,189.4134698779878,245.1028030911054,-1.8261714007535188
0.08813800193583021,0.0013151999999999999,189.5367431648837,245.1028030911054,-1.8261714007535188
0.09156916502822264,0.0013664,189.81547631955553,245.1028030911054,-1.8261714007535188
0.09328474657441885,0.001392,189.95331307503147,245.1028030911054,-1.8261714007535188
0.09478588042734053,0.0014144,190.07311125141868,245.1028030911054,-1.8261714007535188
0.09526838773720821,0.0014215999999999999,190.1114603661419,245.1028030911054,-1.8261714007535188
0.0957508950470759,0.0014288,190.1497338065671,245.1028030911054,-1.8261714007535188
0.09596534274035042,0.001432,190.16672007274957,245.1028030911054,-1.8261714007535188
0.098645938906282,0.001472,190.377814505435,245.1028030911054,-1.8261714007535188
0.09950372967938009,0.0014847999999999999,190.4448906615005,245.1028030911054,-1.8261714007535188
0.09971817737265462,0.001488,190.46162441725082,245.1028030911054,-1.8261714007535188
0.10014707275920368,0.0014944,190.49504988390413,245.1028030911054,-1.8261714007535188
0.10111208737893905,0.0015088,190.570053733891,245.1028030911054,-1.8261714007535188
0.10196987815203715,0.0015216,190.63648976934732,245.1028030911054,-1.8261714007535188
0.10282766892513526,0.0015344,190.70270819839382,245.1028030911054,-1.8261714007535188
0.10502575778119914,0.0015672,190.87141702181037,245.1028030911054,-1.8261714007535188
0.10668772740407673,0.0015919999999999999,190.9980646449792,245.1028030911054,-1.8261714007535188
0.10722384663726303,0.0015999999999999999,191.038754274074,245.1028030911054,-1.8261714007535188
0.10856414472022882,0.00162,191.14013274612068,245.1028030911054,-1.8261714007535188
0.11001166664983188,0.0016416,191.24907479066889,245.1028030911054,-1.8261714007535188
0.11220975550589576,0.0016744,191.4134423253435,245.1028030911054,-1.8261714007535188
0.11371088935881744,0.0016967999999999998,191.52497235314448,245.1028030911054,-1.8261714007535188
0.11462229205523419,0.0017104,191.5924069057985,245.1028030911054,-1.8261714007535188
0.11494396359514597,0.0017151999999999998,191.6161573667452,245.1028030911054,-1.8261714007535188
0.11569453052160682,0.0017264,191.67147453076944,245.1028030911054,-1.8261714007535188
0.11660593321802357,0.00174,191.73845757024932,245.1028030911054,-1.8261714007535188
0.11757094783775893,0.0017544,191.80915861961617,245.1028030911054,-1.8261714007535188
0.11778539553103345,0.0017576,191.82483918706617,245.1028030911054,-1.8261714007535188
0.11848235053417565,0.0017679999999999998,191.87572430881607,245.1028030911054,-1.8261714007535188
0.11987626054046008,0.0017888,191.97714568870418,245.1028030911054,-1.8261714007535188
0.12153823016333765,0.0018135999999999998,192.09747202905766,245.1028030911054,-1.8261714007535188
0.12250324478307302,0.001828,192.1670444560554,245.1028030911054,-1.8261714007535188
0.12303936401625934,0.001836,192.20560343850215,245.1028030911054,-1.8261714007535188
0.12373631901940155,0.0018464,192.25563229760397,245.1028030911054,-1.8261714007535188
0.12405799055931334,0.0018512,192.27868546232196,245.1028030911054,-1.8261714007535188
0.12539828864227912,0.0018712,192.37449046003428,245.1028030911054,-1.8261714007535188
0.12641691518533313,0.0018863999999999999,192.4470354021423,245.1028030911054,-1.8261714007535188
0.12727470595843124,0.0018992,192.50794923091146,245.1028030911054,-1.8261714007535188
0.12786443711493617,0.001908,192.54973464245117,245.1028030911054,-1.8261714007535188
0.13070586905082365,0.0019504,192.7500202720358,245.1028030911054,-1.8261714007535188
0.13220700290374532,0.0019728,192.85514564375427,245.1028030911054,-1.8261714007535188
0.13333285329343658,0.0019896,192.93368444461152,245.1028030911054,-1.8261714007535188
0.13445870368312784,0.0020063999999999998,193.01196502917506,245.1028030911054,-1.8261714007535188
0.13531649445622596,0.0020192,193.0714359203713,245.1028030911054,-1.8261714007535188
0.13713929984905943,0.0020464,193.1973255829817,245.1028030911054,-1.8261714007535188
0.13735374754233395,0.0020496,193.21209310559004,245.1028030911054,-1.8261714007535188
0.14105297025131952,0.0021048,193.46543428424238,245.1028030911054,-1.8261714007535188
0.14196437294773626,0.0021184,193.52745218961363,245.1028030911054,-1.8261714007535188
0.1423396564109667,0.002124,193.5529438185259,245.1028030911054,-1.8261714007535188
0.1430366114141089,0.0021344,193.60021598195942,245.1028030911054,-1.8261714007535188
0.14582443142667773,0.002176,193.78841318015103,245.1028030911054,-1.8261714007535188
0.14732556527959942,0.0021984,193.88916870203232,245.1028030911054,-1.8261714007535188
0.14802252028274163,0.0022088,193.93581187685257,245.1028030911054,-1.8261714007535188
0.14861225143924656,0.0022175999999999997,193.97521231875706,245.1028030911054,-1.8261714007535188
0.14973810182893785,0.0022344,194.05026243195525,245.1028030911054,-1.8261714007535188
0.1508639522186291,0.0022512,194.12509279326872,245.1028030911054,-1.8261714007535188
0.15311565299801164,0.0022848,194.2741033249774,245.1028030911054,-1.8261714007535188
0.15397344377110972,0.0022976,194.3306441353983,245.1028030911054,-1.8261714007535188
0.15456317492761465,0.0023063999999999997,194.36944470172423,245.1028030911054,-1.8261714007535188
0.15504568223748236,0.0023136,194.401147693141,245.1028030911054,-1.8261714007535188
0.1554745776240314,0.00232,194.4292958420605,245.1028030911054,-1.8261714007535188
0.1566540399370413,0.0023376,194.50654753340177,245.1028030911054,-1.8261714007535188
0.15826239763660024,0.0023615999999999997,194.6115261764271,245.1028030911054,-1.8261714007535188
0.15847684532987477,0.0023648,194.62549182577325,245.1028030911054,-1.8261714007535188
0.15890574071642383,0.0023712,194.65340103342444,245.1028030911054,-1.8261714007535188
0.1603532626460269,0.0023928,194.7473784703155,245.1028030911054,-1.8261714007535188
0.16105021764916908,0.0024032,194.79250881678365,245.1028030911054,-1.8261714007535188
0.16169356072899269,0.0024128,194.8341000391325,245.1028030911054,-1.8261714007535188
0.16222967996217896,0.0024208,194.86871011411867,245.1028030911054,-1.8261714007535188
0.16324830650523298,0.002436,194.9343466131654,245.1028030911054,-1.8261714007535188
0.16399887343169384,0.0024472,194.98260818821268,245.1028030911054,-1.8261714007535188
0.1663577980577136,0.0024824,195.13372964464784,245.1028030911054,-1.8261714007535188
0.16748364844740488,0.0024992,195.20556097292072,245.1028030911054,-1.8261714007535188
0.16785893191063528,0.0025047999999999997,195.22946286882188,245.1028030911054,-1.8261714007535188
0.16994979692006193,0.002536,195.36225102089074,245.1028030911054,-1.8261714007535188
0.17257678116267486,0.0025751999999999997,195.5281877310759,245.1028030911054,-1.8261714007535188
0.17322012424249844,0.0025848,195.56867476924268,245.1028030911054,-1.8261714007535188
0.17380985539900337,0.0025935999999999997,195.60573640006476,245.1028030911054,-1.8261714007535188
0.17525737732860644,0.0026152,195.6964985451787,245.1028030911054,-1.8261714007535188
0.17659767541157223,0.0026352,195.78027723306295,245.1028030911054,-1.8261714007535188
0.1771874065680772,0.002644,195.8170612571273,245.1028030911054,-1.8261714007535188
0.17793797349453802,0.0026552,195.8638083059364,245.1028030911054,-1.8261714007535188
0.17901021196091063,0.0026712,195.9304566226484,245.1028030911054,-1.8261714007535188
0.18018967427392055,0.0026888,196.00359020457387,245.1028030911054,-1.8261714007535188
0.18142274851024906,0.0027072,196.07984870205405,245.1028030911054,-1.8261714007535188
0.18270943466989623,0.0027264,196.15920758598253,245.1028030911054,-1.8261714007535188
0.1839961208295434,0.0027456,196.2383488092999,245.1028030911054,-1.8261714007535188
0.18699838853538672,0.0027903999999999997,196.4221770089166,245.1028030911054,-1.8261714007535188
0.1878025673851662,0.0028024,196.47122079909965,245.1028030911054,-1.8261714007535188
0.1879634031551221,0.0028048,196.48101972136502,245.1028030911054,-1.8261714007535188
0.18962537277799968,0.0028296,196.58208450939787,245.1028030911054,-1.8261714007535188
0.19026871585782326,0.0028392,196.62111354542003,245.1028030911054,-1.8261714007535188
0.19064399932105366,0.0028447999999999998,196.64385671554118,245.1028030911054,-1.8261714007535188
0.19080483509100957,0.0028472,196.65359844272186,245.1028030911054,-1.8261714007535188
0.19123373047755862,0.0028536,196.67956073778157,245.1028030911054,-1.8261714007535188
0.19241319279056854,0.0028712,196.7508402199816,245.1028030911054,-1.8261714007535188
0.19520101280313734,0.0029127999999999997,196.91864500911532,245.1028030911054,-1.8261714007535188
0.19691659434933356,0.0029384,197.02144503180378,245.1028030911054,-1.8261714007535188
0.19847134012557388,0.0029616,197.11430623979612,245.1028030911054,-1.8261714007535188
0.20174166744801042,0.0030104,197.3087140651857,245.1028030911054,-1.8261714007535188
0.2042614278439861,0.003048,197.45766655946886,245.1028030911054,-1.8261714007535188
0.20474393515385375,0.0030551999999999997,197.48610744459137,245.1028030911054,-1.8261714007535188
0.20629868093009407,0.0030784,197.5775729929723,245.1028030911054,-1.8261714007535188
0.20710285977987355,0.0030903999999999997,197.62477724791313,245.1028030911054,-1.8261714007535188
0.20914011286598155,0.0031208,197.74404254520596,245.1028030911054,-1.8261714007535188
0.21015873940903557,0.003136,197.80350522190142,245.1028030911054,-1.8261714007535188
0.2136435144247466,0.003188,198.0060855138351,245.1028030911054,-1.8261714007535188
0.21455491712116334,0.0032015999999999998,198.05885494056068,245.1028030911054,-1.8261714007535188
0.21525187212430555,0.003212,198.09914906606463,245.1028030911054,-1.8261714007535188
0.21584160328081048,0.0032208,198.13320436903328,245.1028030911054,-1.8261714007535188
0.21696745367050174,0.0032375999999999998,198.19811843951092,245.1028030911054,-1.8261714007535188
0.21728912521041355,0.0032424,198.21664117088724,245.1028030911054,-1.8261714007535188
0.218093304060193,0.0032543999999999997,198.26290127413648,245.1028030911054,-1.8261714007535188
0.21905831867992837,0.0032687999999999997,198.31832567849162,245.1028030911054,-1.8261714007535188
0.2192727663732029,0.0032719999999999997,198.33062927188868,245.1028030911054,-1.8261714007535188
0.2224894817723208,0.00332,198.51462368336755,245.1028030911054,-1.8261714007535188
0.2228647652355512,0.0033255999999999997,198.53602190787223,245.1028030911054,-1.8261714007535188
0.2232936606221003,0.003332,198.56045982173524,245.1028030911054,-1.8261714007535188
0.22409783947187975,0.0033439999999999998,198.6062316254381,245.1028030911054,-1.8261714007535188
0.22495563024497786,0.0033568,198.65498433288857,245.1028030911054,-1.8261714007535188
0.22559897332480144,0.0033664,198.69150129853233,245.1028030911054,-1.8261714007535188
0.2272073310243604,0.0033904,198.78261647982507,245.1028030911054,-1.8261714007535188
0.229298196033787,0.0034216,198.90069103814488,245.1028030911054,-1.8261714007535188
0.22978070334365466,0.0034287999999999996,198.92787929402107,245.1028030911054,-1.8261714007535188
0.2301559868068851,0.0034343999999999998,198.94901032465407,245.1028030911054,-1.8261714007535188
0.23230046373963037,0.0034663999999999997,199.06950228272981,245.1028030911054,-1.8261714007535188
0.23364076182259616,0.0034863999999999997,199.14458950607064,245.1028030911054,-1.8261714007535188
0.23449855259569427,0.0034992,199.19255718174554,245.1028030911054,-1.8261714007535188
0.23583885067866003,0.0035191999999999997,199.26736990620813,245.1028030911054,-1.8261714007535188
0.23669664145175817,0.003532,199.31516304327502,245.1028030911054,-1.8261714007535188
0.23787610376476806,0.0035496,199.3807684585782,245.1028030911054,-1.8261714007535188
0.2383586110746357,0.0035567999999999997,199.40757045811893,245.1028030911054,-1.8261714007535188
0.2393236256943711,0.0035711999999999996,199.4611110631501,245.1028030911054,-1.8261714007535188
0.24103920724056732,0.0035968,199.55608693063166,245.1028030911054,-1.8261714007535188
0.24178977416702813,0.0036079999999999997,199.59755593292832,245.1028030911054,-1.8261714007535188
0.24318368417331257,0.0036287999999999997,199.67443684351196,245.1028030911054,-1.8261714007535188
0.24398786302309206,0.0036408,199.71871303672435,245.1028030911054,-1.8261714007535188
0.2440950868697293,0.0036423999999999996,199.72461222604892,245.1028030911054,-1.8261714007535188
0.24538177302937644,0.0036615999999999997,199.79532385199292,245.1028030911054,-1.8261714007535188
0.24640039957243048,0.0036768,199.8512013870562,245.1028030911054,-1.8261714007535188
0.24790153342535212,0.0036991999999999997,199.93338330034814,245.1028030911054,-1.8261714007535188
0.24822320496526393,0.003704,199.95096843417247,245.1028030911054,-1.8261714007535188
0.24892015996840614,0.0037143999999999996,199.9890390973404,245.1028030911054,-1.8261714007535188
0.25004601035809737,0.0037311999999999996,200.05045016106047,245.1028030911054,-1.8261714007535188
0.250689353437921,0.0037408,200.08549377949885,245.1028030911054,-1.8261714007535188
0.2533163376805339,0.00378,200.22822605166283,245.1028030911054,-1.8261714007535188
0.25551442653659784,0.0038128,200.3472120429898,245.1028030911054,-1.8261714007535188
0.25610415769310274,0.0038215999999999997,200.37906711058082,245.1028030911054,-1.8261714007535188
0.257230008082794,0.0038383999999999996,200.43980200378527,245.1028030911054,-1.8261714007535188
0.25744445577606856,0.0038415999999999997,200.45135879137564,245.1028030911054,-1.8261714007535188
0.2590528134756275,0.0038656,200.53791534554173,245.1028030911054,-1.8261714007535188
0.2602322757886374,0.0038832,200.60125700775205,245.1028030911054,-1.8261714007535188
0.2607147830985051,0.0038904,200.627137223827,245.1028030911054,-1.8261714007535188
0.26119729040837275,0.0038975999999999998,200.65299876689244,245.1028030911054,-1.8261714007535188
0.26291287195456897,0.0039232,200.7448004085128,245.1028030911054,-1.8261714007535188
0.2633953792644366,0.0039304,200.77057748901476,245.1028030911054,-1.8261714007535188
0.26532540850390735,0.0039591999999999995,200.87350218390597,245.1028030911054,-1.8261714007535188
0.26773794505324583,0.0039952,201.0017483615917,245.1028030911054,-1.8261714007535188
0.27964210852836907,0.004172834566913383,201.6280711497936,245.1028030911054,-1.8261714007535188
0.2989462617537215,0.004460892178435687,202.62206509095546,245.1028030911054,-1.8261714007535188
0.3156765278823603,0.004710542108421685,203.46343702509103,245.1028030911054,-1.8261714007535188
0.3529978907847083,0.00526745349069814,205.28003823405382,245.1028030911054,-1.8261714007535188
0.3710151004617039,0.005536307261452291,206.13004860564112,245.1028030911054,-1.8261714007535188
0.40704951981569504,0.006074014802960592,207.78322468421842,245.1028030911054,-1.8261714007535188
0.41605812465419284,0.0062084416883376676,208.1874724395932,245.1028030911054,-1.8261714007535188
0.4392231085246157,0.006554110822164433,209.21159462422904,245.1028030911054,-1.8261714007535188
0.4662489230401091,0.006957391478295659,210.38014102083295,245.1028030911054,-1.8261714007535188
0.4829791891687478,0.007207041408281656,211.0902973738504,245.1028030911054,-1.8261714007535188
0.5460394230382324,0.008148029605921184,213.6849041232793,245.1028030911054,-1.8261714007535188
0.5975171649725055,0.00891618323664733,215.7172238795299,245.1028030911054,-1.8261714007535188
0.6116735440044306,0.00912742548509702,216.26398554198772,245.1028030911054,-1.8261714007535188
0.6399863020682809,0.0095499099819964,217.34292247928997,245.1028030911054,-1.8261714007535188
0.7107681972279063,0.010606121224244848,219.96182119318865,245.1028030911054,-1.8261714007535188
0.7313592940016156,0.010913382676535306,220.70430933402744,245.1028030911054,-1.8261714007535188
0.7570981649687522,0.011297459491898379,221.62105209273682,245.1028030911054,-1.8261714007535188
0.7648198262588931,0.0114126825365073,221.8936940161906,245.1028030911054,-1.8261714007535188
0.7969934149678138,0.011892778555711142,223.01833596349502,245.1028030911054,-1.8261714007535188
0.8291670036767346,0.012372874574914983,224.12540477137298,245.1028030911054,-1.8261714007535188
0.8587667052889416,0.012814562912582516,225.1291980133286,245.1028030911054,-1.8261714007535188
0.9282616569002103,0.013851570314062813,227.43432488819442,245.1028030911054,-1.8261714007535188
0.9372702617387081,0.013985997199439888,227.72812967867088,245.1028030911054,-1.8261714007535188
0.9501396972222764,0.014178035607121425,228.14594749435432,245.1028030911054,-1.8261714007535188
0.9578613585124174,0.014293258651730346,228.39557888684476,245.1028030911054,-1.8261714007535188
0.9913218907696949,0.014792558511702341,229.46837041489624,245.1028030911054,-1.8261714007535188
1.020921592381902,0.015234246849369875,230.4056602021084,245.1028030911054,-1.8261714007535188
1.056956011735893,0.015771954390878175,231.53252292506335,245.1028030911054,-1.8261714007535188
1.094277374638241,0.01632886577315463,232.68394522743392,245.1028030911054,-1.8261714007535188
1.1238770762504482,0.016770554110822164,233.58628685436852,245.1028030911054,-1.8261714007535188
1.147042060120871,0.01711622324464893,234.28601751047464,245.1028030911054,-1.8261714007535188
1.170207043991294,0.017461892378475695,234.98025814391568,245.1028030911054,-1.8261714007535188
1.215250068183783,0.018134026805361074,236.3150147278841,245.1028030911054,-1.8261714007535188
1.2229717294739237,0.018249249849969992,236.54187897416847,245.1028030911054,-1.8261714007535188
1.2808841891499811,0.019113422684536908,238.22590513209934,245.1028030911054,-1.8261714007535188
1.334935818180968,0.01991998399679936,239.7710597598336,245.1028030911054,-1.8261714007535188
1.35037914076125,0.020150430086017204,240.20802548010238,245.1028030911054,-1.8261714007535188
1.3683963504382455,0.020419283856771355,240.71536315978312,245.1028030911054,-1.8261714007535188
1.379978842373457,0.020592118423684736,241.04013362170673,245.1028030911054,-1.8261714007535188
1.425021866565946,0.021264252850570115,242.29315149960195,245.1028030911054,-1.8261714007535188
1.4571954552748665,0.021744348869773954,243.17872464935724,245.1028030911054,-1.8261714007535188
1.4597693423715803,0.02178275655131026,243.2492393761066,245.1028030911054,-1.8261714007535188
1.4906559875321441,0.02224364872974595,244.09166875028333,245.1028030911054,-1.8261714007535188
1.4958037617255715,0.022320464092818564,244.23140914726255,245.1028030911054,-1.8261714007535188
1.5318381810795625,0.022858171634326865,245.20439336135786,245.1028030911054,-1.8261714007535188
1.5434206730147741,0.02303100620124025,245.51523713756526,245.1028030911054,-1.8261714007535188
1.5498553907565582,0.023127025405081016,245.6875349855065,245.1028030911054,-1.8261714007535188
1.558863995595056,0.023261452290458094,245.92828401250145,245.1028030911054,-1.8261714007535188
1.5691595439819108,0.023415083016603323,246.20276234811953,245.1028030911054,-1.8261714007535188
1.5794550923687654,0.02356871374274855,246.47653922319407,245.1028030911054,-1.8261714007535188
1.6206372859161837,0.024183236647329465,247.5647576123501,245.1028030911054,-1.8261714007535188
1.6669672536570295,0.024874574914982996,248.77619291509802,245.1028030911054,-1.8261714007535188
1.6759758584955273,0.025009001800360073,249.01021723122335,245.1028030911054,-1.8261714007535188
1.6811236326889547,0.025085817163432687,249.14372514367255,245.1028030911054,-1.8261714007535188
1.6991408423659502,0.02535467093418684,249.60975243369677,245.1028030911054,-1.8261714007535188
1.708149447204448,0.025489097819563912,249.84204307654747,245.1028030911054,-1.8261714007535188
1.7248797133330869,0.02573874774954991,250.27217633752332,245.1028030911054,-1.8261714007535188
1.7454708101067962,0.02604600920184037,250.79934395489832,245.1028030911054,-1.8261714007535188
1.760914132687078,0.026276455291058213,251.19312946398622,245.1028030911054,-1.8261714007535188
1.7866530036542145,0.026660532106421286,251.8464586844678,245.1028030911054,-1.8261714007535188
1.8188265923631353,0.027140628125625125,252.65798108329184,245.1028030911054,-1.8261714007535188
1.8561479552654834,0.027697539507901582,253.59236599837195,245.1028030911054,-1.8261714007535188
1.8767390520391927,0.02800480096019204,254.10475128676336,245.1028030911054,-1.8261714007535188
1.9179212455866108,0.028619323864772953,255.12299123637854,245.1028030911054,-1.8261714007535188
1.9307906810701791,0.02881136227245449,255.4394378080431,245.1028030911054,-1.8261714007535188
1.9500948342955318,0.029099419883976796,255.9125696422424,245.1028030911054,-1.8261714007535188
1.9629642697790999,0.029291458291658332,256.22697648529044,245.1028030911054,-1.8261714007535188
1.9784075923593818,0.029521904380876176,256.6032055321336,245.1028030911054,-1.8261714007535188
2.0144420117133732,0.030059611922384478,257.4766470673667,245.1028030911054,-1.8261714007535188
2.0337461649387256,0.03034766953390678,257.9420546404624,245.1028030911054,-1.8261714007535188
2.0427547697772233,0.030482096419283858,258.1586549400805,245.1028030911054,-1.8261714007535188
2.110962777840135,0.031499899979996,259.7867096714607,245.1028030911054,-1.8261714007535188
2.1341277617105576,0.03184556911382276,260.33494967879204,245.1028030911054,-1.8261714007535188
2.1650144068711215,0.03230646129225845,261.062339679728,245.1028030911054,-1.8261714007535188
2.2036227133218267,0.03288257651530306,261.96591082768373,245.1028030911054,-1.8261714007535188
2.2190660359021086,0.033113022604520904,262.32560798205685,245.1028030911054,-1.8261714007535188
2.237083245579104,0.03338187637527505,262.7440230793127,245.1028030911054,-1.8261714007535188
2.261535172997884,0.03374674934986997,263.30977606349796,245.1028030911054,-1.8261714007535188
2.2641090600945972,0.03378515703140628,263.36918990217777,245.1028030911054,-1.8261714007535188
2.2834132133199505,0.03407321464292859,263.8139570948884,245.1028030911054,-1.8261714007535188
2.294995705255161,0.034246049209841964,264.08011357182806,245.1028030911054,-1.8261714007535188
2.3078651407387296,0.034438087617523504,264.3752293378045,245.1028030911054,-1.8261714007535188
2.319447632673941,0.034610922184436885,264.64028523180014,245.1028030911054,-1.8261714007535188
2.3541951084795754,0.035129425885177035,265.4323728931218,245.1028030911054,-1.8261714007535188
2.3657776004147872,0.03530226045209042,265.6953871618988,245.1028030911054,-1.8261714007535188
2.400525076220422,0.03582076415283057,266.4814331998894,245.1028030911054,-1.8261714007535188
2.4146814552523463,0.03603200640128025,266.8004005057528,245.1028030911054,-1.8261714007535188
2.4288378342842716,0.03624324864972994,267.11863934494625,245.1028030911054,-1.8261714007535188
2.440420326219483,0.03641608321664333,267.3784788639279,245.1028030911054,-1.8261714007535188
2.4996197294438973,0.0372994598919784,268.6991100474227,245.1028030911054,-1.8261714007535188
2.529219431056104,0.03774114822964593,269.35484712237394,245.1028030911054,-1.8261714007535188
2.5601060762166683,0.03820204040808162,270.0359114947157,245.1028030911054,-1.8261714007535188
2.563966906861739,0.03825965193038608,270.1208186463179,245.1028030911054,-1.8261714007535188
2.5704016246035226,0.038355671134226846,270.2622198432181,245.1028030911054,-1.8261714007535188
2.5794102294420203,0.038490098019603916,270.459949809869,245.1028030911054,-1.8261714007535188
2.597427439119016,0.03875895179035807,270.8546036219175,245.1028030911054,-1.8261714007535188
2.621879366537796,0.03912382476495299,271.388501782017,245.1028030911054,-1.8261714007535188
2.6450443504082184,0.03946949389877975,271.8925115896174,245.1028030911054,-1.8261714007535188
2.6707832213753555,0.03985357071414283,272.4505077810786,245.1028030911054,-1.8261714007535188
2.6810787697622103,0.04000720144028806,272.6731185570015,245.1028030911054,-1.8261714007535188
2.7016698665359193,0.04031446289257852,273.11734245887135,245.1028030911054,-1.8261714007535188
2.7158262455678446,0.04052570514102821,273.4219807287773,245.1028030911054,-1.8261714007535188
2.7467128907284084,0.0409865973194639,274.08450467752976,245.1028030911054,-1.8261714007535188
2.7930428584692537,0.04167793558711742,275.0728685655325,245.1028030911054,-1.8261714007535188
2.8470944875002404,0.04248449689937987,276.2179144325523,245.1028030911054,-1.8261714007535188
2.8612508665321656,0.042695739147829564,276.51640244717703,245.1028030911054,-1.8261714007535188
2.8831289068542323,0.04302220444088818,276.9765717335825,245.1028030911054,-1.8261714007535188
2.9307458181434347,0.043732746549309864,277.97343526775364,245.1028030911054,-1.8261714007535188
2.94490219717536,0.043943988797759556,278.2685793817579,245.1028030911054,-1.8261714007535188
2.9732149552392095,0.044366473294658926,278.85721285587294,245.1028030911054,-1.8261714007535188
2.997666882657989,0.04473134626925385,279.3638210587845,245.1028030911054,-1.8261714007535188
3.023405753625126,0.045115423084616926,279.89535483786034,245.1028030911054,-1.8261714007535188
3.090326818139681,0.04611402280456091,281.2691484697498,245.1028030911054,-1.8261714007535188
3.1006223665265353,0.04626765353070614,281.47946709609613,245.1028030911054,-1.8261714007535188
3.1302220681387434,0.04670934186837368,282.08262134521954,245.1028030911054,-1.8261714007535188
3.1585348262025925,0.04713182636527305,282.65747350325995,245.1028030911054,-1.8261714007535188
3.180412866524659,0.04745829165833167,283.10030209889646,245.1028030911054,-1.8261714007535188
3.1958561891049415,0.04768873774754952,283.41217199329986,245.1028030911054,-1.8261714007535188
3.2898030681349892,0.049090618123624724,285.296870769051,245.1028030911054,-1.8261714007535188
3.311681108457056,0.04941708341668334,285.732745907161,245.1028030911054,-1.8261714007535188
3.332272205230765,0.0497243448689738,286.1419565881342,245.1028030911054,-1.8261714007535188
3.355437189101188,0.05007001400280056,286.60114165610645,245.1028030911054,-1.8261714007535188
3.3605849632946145,0.05014682936587317,286.70301469279127,245.1028030911054,-1.8261714007535188
3.381176060068324,0.05045409081816363,287.10989971659717,245.1028030911054,-1.8261714007535188
3.3927585520035355,0.050626925385077015,287.3383478419263,245.1028030911054,-1.8261714007535188
3.4030541003903902,0.050780556111222244,287.5411576230666,245.1028030911054,-1.8261714007535188
3.445523237486166,0.05141428285657132,288.3752310231965,245.1028030911054,-1.8261714007535188
3.4738359955500155,0.05183676735347069,288.9290535408967,245.1028030911054,-1.8261714007535188
3.4918532052270113,0.052105621124224843,289.2805696774709,245.1028030911054,-1.8261714007535188
3.5047226407105794,0.052297659531906376,289.5312196919759,245.1028030911054,-1.8261714007535188
3.526600681032646,0.05262412482496499,289.9565024825259,245.1028030911054,-1.8261714007535188
3.61025201167584,0.053872374474894985,291.57318255901555,245.1028030911054,-1.8261714007535188
3.6411386568364037,0.05433326665333067,292.1664091499639,245.1028030911054,-1.8261714007535188
3.6501472616749013,0.05446769353870774,292.33906347184853,245.1028030911054,-1.8261714007535188
3.661729753610113,0.05464052810562113,292.5608036080258,245.1028030911054,-1.8261714007535188
3.7080597213509585,0.055331866373274655,293.4450423394168,245.1028030911054,-1.8261714007535188
3.7209291568345266,0.05552390478095619,293.6898981959156,245.1028030911054,-1.8261714007535188
3.7376594229631652,0.05577355471094218,294.0077176079954,245.1028030911054,-1.8261714007535188
3.762111350381945,0.056138427685537104,294.47122670964495,245.1028030911054,-1.8261714007535188
3.768546068123729,0.05623444688937787,294.59300732657084,245.1028030911054,-1.8261714007535188
3.82517158425143,0.05707941588317664,295.6612024455522,245.1028030911054,-1.8261714007535188
3.9307009552166896,0.05865413082616523,297.6356159963116,245.1028030911054,-1.8261714007535188
3.988613414892747,0.059518303660732144,298.7103461130596,245.1028030911054,-1.8261714007535188
4.0503867052138744,0.06044008801760352,299.8500387042538,245.1028030911054,-1.8261714007535188
4.063256140697443,0.06063212642528505,300.0866191617978,245.1028030911054,-1.8261714007535188
4.068403914890871,0.06070894178835767,300.181169498071,245.1028030911054,-1.8261714007535188
4.113446939083359,0.06138107621524305,301.0065041703659,245.1028030911054,-1.8261714007535188
4.144333584243923,0.06184196839367874,301.57041190838027,245.1028030911054,-1.8261714007535188
4.146907471340636,0.06188037607521504,301.61733010841994,245.1028030911054,-1.8261714007535188
4.1559160761791345,0.062014802960592114,301.78145444567235,245.1028030911054,-1.8261714007535188
4.17393328585613,0.06228365673134627,302.1092874669218,245.1028030911054,-1.8261714007535188
4.189376608436413,0.06251410282056412,302.389848175935,245.1028030911054,-1.8261714007535188
4.229271858435474,0.06310942188437688,303.11276946296294,245.1028030911054,-1.8261714007535188
4.233132689080544,0.06316703340668134,303.18258814588796,245.1028030911054,-1.8261714007535188
4.267880164886179,0.06368553710742149,303.8098426979871,245.1028030911054,-1.8261714007535188
4.298766810046743,0.06414642928585718,304.36573220555647,245.1028030911054,-1.8261714007535188
4.319357906820452,0.06445369073814763,304.7354600756779,245.1028030911054,-1.8261714007535188
4.337375116497447,0.06472254450890177,305.0584084485472,245.1028030911054,-1.8261714007535188
4.350244551981016,0.06491458291658332,305.2887656207342,245.1028030911054,-1.8261714007535188
4.375983422948152,0.06529865973194639,305.74868419049517,245.1028030911054,-1.8261714007535188
4.392713689076791,0.06554830966193238,306.04706561479287,245.1028030911054,-1.8261714007535188
4.440330600365994,0.06625885177035407,306.893888857704,245.1028030911054,-1.8261714007535188
4.463495584236417,0.06660452090418084,307.30457574113467,245.1028030911054,-1.8261714007535188
4.482799737461769,0.06689257851570314,307.64618021224834,245.1028030911054,-1.8261714007535188
4.507251664880549,0.06725745149029806,308.07805674639127,245.1028030911054,-1.8261714007535188
4.531703592299329,0.06762232446489298,308.5090204951073,245.1028030911054,-1.8261714007535188
4.534277479396042,0.06766073214642929,308.5543322818968,245.1028030911054,-1.8261714007535188
4.53942525358947,0.06773754750950191,308.6449257728153,245.1028030911054,-1.8261714007535188
4.570311898750034,0.0681984396879376,309.1876477109637,245.1028030911054,-1.8261714007535188
4.5754596729434605,0.0682752550510102,309.2779621173289,245.1028030911054,-1.8261714007535188
4.603772431007311,0.06869773954790959,309.7739848053109,245.1028030911054,-1.8261714007535188
4.635946019716232,0.06917783556711343,310.3362051293769,245.1028030911054,-1.8261714007535188
4.665545721328439,0.06961952390478096,310.8521053123982,245.1028030911054,-1.8261714007535188
4.674554326166937,0.06975395079015803,311.00886483959624,245.1028030911054,-1.8261714007535188
4.691284592295575,0.07000360072014403,311.2996774502513,245.1028030911054,-1.8261714007535188
4.702867084230787,0.07017643528705741,311.5007723620561,245.1028030911054,-1.8261714007535188
4.719597350359425,0.07042608521704341,311.79090212473784,245.1028030911054,-1.8261714007535188
4.733753729391351,0.0706373274654931,312.0360833892808,245.1028030911054,-1.8261714007535188
4.747910108423276,0.0708485697139428,312.28097886453475,245.1028030911054,-1.8261714007535188
4.773648979390412,0.07123264652930586,312.72551503180813,245.1028030911054,-1.8261714007535188
4.798100906809192,0.07159751950390078,313.1469593451421,245.1028030911054,-1.8261714007535188
4.809683398744403,0.07177035407081417,313.34629843246313,245.1028030911054,-1.8261714007535188
4.847004761646751,0.07232726545309062,313.98734347750104,245.1028030911054,-1.8261714007535188
4.85215253584018,0.07240408081616324,314.0756121724893,245.1028030911054,-1.8261714007535188
4.854726422936893,0.07244248849769955,314.119732823642,245.1028030911054,-1.8261714007535188
4.870169745517174,0.07267293458691738,314.3842654050249,245.1028030911054,-1.8261714007535188
4.8843261245491,0.07288417683536708,314.62646635869476,245.1028030911054,-1.8261714007535188
4.895908616484311,0.07305701140228046,314.82442720884,245.1028030911054,-1.8261714007535188
4.913925826161306,0.0733258651730346,315.13200365741477,245.1028030911054,-1.8261714007535188
4.920360543903091,0.07342188437687538,315.241745759268,245.1028030911054,-1.8261714007535188
4.948673301966941,0.07384436887377475,315.72394759481625,245.1028030911054,-1.8261714007535188
4.974412172934078,0.07422844568913783,316.1613800462214,245.1028030911054,-1.8261714007535188
5.000151043901214,0.0746125225045009,316.5979306622371,245.1028030911054,-1.8261714007535188
5.040046293900276,0.07520784156831367,317.2728561060066,245.1028030911054,-1.8261714007535188
5.061924334222342,0.07553430686137227,317.64209181078263,245.1028030911054,-1.8261714007535188
5.079941543899337,0.07580316063212643,317.9457011715441,245.1028030911054,-1.8261714007535188
5.114689019704972,0.07632166433286658,318.53005016788177,245.1028030911054,-1.8261714007535188
5.123697624543469,0.07645609121824365,318.681295068046,245.1028030911054,-1.8261714007535188
5.146862608413893,0.07680176035207043,319.0697350783113,245.1028030911054,-1.8261714007535188
5.18032314067117,0.07730106021204242,319.6296135247125,245.1028030911054,-1.8261714007535188
5.195766463251451,0.07753150630126025,319.88754310363424,245.1028030911054,-1.8261714007535188
5.2137836729284475,0.07780036007201441,320.18808336016684,245.1028030911054,-1.8261714007535188
5.311591382603566,0.07925985197039408,321.81257428252854,245.1028030911054,-1.8261714007535188
5.332182479377275,0.07956711342268454,322.1530810868075,245.1028030911054,-1.8261714007535188
5.355347463247699,0.07991278255651131,322.5355388577512,245.1028030911054,-1.8261714007535188
5.364356068086196,0.08004720944188838,322.6840981255055,245.1028030911054,-1.8261714007535188
5.42355547131061,0.08093058611722345,323.65793541642194,245.1028030911054,-1.8261714007535188
5.473746269696527,0.08167953590718144,324.4803371233085,245.1028030911054,-1.8261714007535188
5.486615705180094,0.08187157431486297,324.69073497864485,245.1028030911054,-1.8261714007535188
5.508493745502161,0.08219803960792159,325.0479701528608,245.1028030911054,-1.8261714007535188
5.527797898727513,0.08248609721944389,325.36271839103307,245.1028030911054,-1.8261714007535188
5.570267035823289,0.08311982396479296,326.0536595226172,245.1028030911054,-1.8261714007535188
5.579275640661786,0.08325425085017003,326.199958327685,245.1028030911054,-1.8261714007535188
5.588284245500285,0.08338867773554712,326.34616503509284,245.1028030911054,-1.8261714007535188
5.620457834209205,0.08386877375475095,326.86758314954193,245.1028030911054,-1.8261714007535188
5.6423358745312715,0.08419523904780957,327.22148272637264,245.1028030911054,-1.8261714007535188
5.660353084208267,0.08446409281856372,327.51252776947734,245.1028030911054,-1.8261714007535188
5.670648632595122,0.08461772354470895,327.6786770039932,245.1028030911054,-1.8261714007535188
5.68737889872376,0.08486737347469495,327.9484188120536,245.1028030911054,-1.8261714007535188
5.701535277755686,0.08507861572314464,328.1764202601467,245.1028030911054,-1.8261714007535188
5.713117769690896,0.08525145029005801,328.36280272688026,245.1028030911054,-1.8261714007535188
5.7311349793678925,0.08552030406081217,328.65243836303137,245.1028030911054,-1.8261714007535188
5.750439132593244,0.08580836167233447,328.96236847656564,245.1028030911054,-1.8261714007535188
5.76845634227024,0.08607721544308862,329.25127069020164,245.1028030911054,-1.8261714007535188
5.785186608398878,0.08632686537307462,329.5192220785296,245.1028030911054,-1.8261714007535188
5.8765596003322145,0.08769033806761353,330.9773509984784,245.1028030911054,-1.8261714007535188
5.9087331890411345,0.08817043408681736,331.4886683358687,245.1028030911054,-1.8261714007535188
5.922889568073059,0.08838167633526706,331.7133038528013,245.1028030911054,-1.8261714007535188
5.944767608395126,0.08870814162832567,332.0600564097021,245.1028030911054,-1.8261714007535188
6.00010618097447,0.08953390678135628,332.9349222342351,245.1028030911054,-1.8261714007535188
6.006540898716254,0.08962992598519705,333.0364461825604,245.1028030911054,-1.8261714007535188
6.033566713231747,0.09003320664132827,333.46238440401703,245.1028030911054,-1.8261714007535188
6.0451492051669575,0.09020604120824165,333.64470150678153,245.1028030911054,-1.8261714007535188
6.068314189037381,0.09055171034206842,334.008927523131,245.1028030911054,-1.8261714007535188
6.112070269681514,0.09120464092818564,334.6954339371843,245.1028030911054,-1.8261714007535188
6.144243858390435,0.09168473694738949,335.1989958667134,245.1028030911054,-1.8261714007535188
6.171269672905928,0.09208801760352071,335.6211936639401,245.1028030911054,-1.8261714007535188
6.191860769679637,0.09239527905581117,335.94238436243324,245.1028030911054,-1.8261714007535188
6.206017148711561,0.09260652130426085,336.16296136566655,245.1028030911054,-1.8261714007535188
6.2471993422589795,0.09322104420884177,336.80352690633407,245.1028030911054,-1.8261714007535188
6.274225156774474,0.093624324864973,337.22300325949726,245.1028030911054,-1.8261714007535188
6.315407350321893,0.09423884776955392,337.8608528365266,245.1028030911054,-1.8261714007535188
6.329563729353817,0.0944500900180036,338.07973871361685,245.1028030911054,-1.8261714007535188
6.347580939030813,0.09471894378875775,338.35804480709794,245.1028030911054,-1.8261714007535188
6.378467584191377,0.09517983596719344,338.8344252711072,245.1028030911054,-1.8261714007535188
6.387476189029875,0.09531426285257052,338.97319999832973,245.1028030911054,-1.8261714007535188
6.395197850320015,0.09542948589717944,339.09208902197213,245.1028030911054,-1.8261714007535188
6.435093100319078,0.09602480496099221,339.70545940325513,245.1028030911054,-1.8261714007535188
6.442814761609218,0.09614002800560112,339.82400476237893,245.1028030911054,-1.8261714007535188
6.508448882575416,0.09711942388477696,340.82941293705034,245.1028030911054,-1.8261714007535188
6.529039979349125,0.09742668533706741,341.14401922920706,245.1028030911054,-1.8261714007535188
6.544483301929407,0.09765713142628527,341.3797200711347,245.1028030911054,-1.8261714007535188
6.556065793864619,0.09782996599319864,341.556353378083,245.1028030911054,-1.8261714007535188
6.580517721283399,0.09819483896779356,341.92884675324717,245.1028030911054,-1.8261714007535188
6.625560745475887,0.09886697339467894,342.61360875785505,245.1028030911054,-1.8261714007535188
6.695055697087157,0.09990398079615924,343.6665479864474,245.1028030911054,-1.8261714007535188
6.701490414828941,0.1,343.7638262408679,245.1028030911054,-1.8261714007535188