File: datasets/aisi_316_L/data/M1/train_91.csv
Time(s),Strain(%),Stress(MPa),Temp(C),Log_SR(s-1)
0.0,0.0,0.0,54.405603553088795,4.59591406965657
6.085512685352609e-10,2.4e-05,4.6819035,54.405603553088795,4.59591406965657
9.128269028028914e-10,3.6e-05,7.02285525,54.405603553088795,4.59591406965657
1.0142521142254348e-09,3.9999999999999996e-05,7.8031725,54.405603553088795,4.59591406965657
1.135962367932487e-09,4.48e-05,8.7395532,54.405603553088795,4.59591406965657
1.9067939747438174e-09,7.52e-05,14.6699643,54.405603553088795,4.59591406965657
2.616770454701622e-09,0.0001032,20.13218505,54.405603553088795,4.59591406965657
3.225321723236883e-09,0.0001272,24.81408855,54.405603553088795,4.59591406965657
3.42817214608197e-09,0.0001352,26.37472305,54.405603553088795,4.59591406965657
3.7121627380650913e-09,0.00014639999999999998,28.559611349999997,54.405603553088795,4.59591406965657
4.3004289643158435e-09,0.0001696,33.085451400000004,54.405603553088795,4.59591406965657
4.706129810006018e-09,0.00018559999999999998,36.206720399999995,54.405603553088795,4.59591406965657
4.848125105997578e-09,0.00019119999999999999,37.29916455,54.405603553088795,4.59591406965657
5.781237051084978e-09,0.00022799999999999999,44.47808325,54.405603553088795,4.59591406965657
5.943517389361048e-09,0.00023439999999999998,45.726590849999994,54.405603553088795,4.59591406965657
6.024657558499083e-09,0.0002376,46.35084465,54.405603553088795,4.59591406965657
6.207222939059661e-09,0.0002448,47.7554157,54.405603553088795,4.59591406965657
6.430358404189257e-09,0.0002536,49.47211365,54.405603553088795,4.59591406965657
6.633208827034343e-09,0.00026159999999999996,51.03274814999999,54.405603553088795,4.59591406965657
7.3634703492766576e-09,0.0002904,56.65103235,54.405603553088795,4.59591406965657
7.647460941259779e-09,0.0003016,58.835920650000006,54.405603553088795,4.59591406965657
7.890881448673883e-09,0.0003112,60.70868204999999,54.405603553088795,4.59591406965657
9.18912415488244e-09,0.00036239999999999997,70.69674284999999,54.405603553088795,4.59591406965657
9.675965169710648e-09,0.0003816,74.44226565,54.405603553088795,4.59591406965657
1.012223609996984e-08,0.0003992,77.87566155,54.405603553088795,4.59591406965657
1.0284516438245909e-08,0.0004056,79.12416915,54.405603553088795,4.59591406965657
1.0852497622212154e-08,0.000428,83.49394575,54.405603553088795,4.59591406965657
1.103506300277273e-08,0.00043519999999999995,84.8985168,54.405603553088795,4.59591406965657
1.133933863704036e-08,0.0004472,87.23946855,54.405603553088795,4.59591406965657
1.1704469398161519e-08,0.0004616,90.04861065,54.405603553088795,4.59591406965657
1.2515871089541866e-08,0.0004936,96.29114865,54.405603553088795,4.59591406965657
1.2779576639240479e-08,0.000504,98.3199735,54.405603553088795,4.59591406965657
1.2982427062085565e-08,0.000512,99.880608,54.405603553088795,4.59591406965657
1.3022997146654584e-08,0.0005136,100.1927349,54.405603553088795,4.59591406965657
1.3753258668896896e-08,0.0005424,105.8110191,54.405603553088795,4.59591406965657
1.4138674472302562e-08,0.0005576,108.77622465,54.405603553088795,4.59591406965657
1.4422665064285683e-08,0.0005688,110.96111294999999,54.405603553088795,4.59591406965657
1.478779582540684e-08,0.0005832,113.77025504999999,54.405603553088795,4.59591406965657
1.5335491967088574e-08,0.0006048,117.98396819999999,54.405603553088795,4.59591406965657
1.5578912474502677e-08,0.0006144,119.8567296,54.405603553088795,4.59591406965657
1.570062272820973e-08,0.0006192,120.7931103,54.405603553088795,4.59591406965657
1.643088425045204e-08,0.0006479999999999999,126.41139449999999,54.405603553088795,4.59591406965657
1.691772526528025e-08,0.0006672,130.1569173,54.405603553088795,4.59591406965657
1.7526276533815515e-08,0.0006912,134.8388208,54.405603553088795,4.59591406965657
1.8195682929204302e-08,0.0007176,139.98891465,54.405603553088795,4.59591406965657
1.880423419773956e-08,0.0007415999999999999,144.67081814999997,54.405603553088795,4.59591406965657
1.900708462058465e-08,0.0007496,146.23145265,54.405603553088795,4.59591406965657
1.9189650001145228e-08,0.0007568,147.63602369999998,54.405603553088795,4.59591406965657
1.9615635889119908e-08,0.0007735999999999999,150.91335615,54.405603553088795,4.59591406965657
2.0345897411362222e-08,0.0008024,156.53164035,54.405603553088795,4.59591406965657
2.054874783420731e-08,0.0008104,158.09227485,54.405603553088795,4.59591406965657
2.131957944101864e-08,0.0008408,164.02268594999998,54.405603553088795,4.59591406965657
2.1704995244424307e-08,0.000856,166.9878915,54.405603553088795,4.59591406965657
2.2009270878691934e-08,0.000868,169.32884325,54.405603553088795,4.59591406965657
2.2354116597528583e-08,0.0008816,171.9819219,54.405603553088795,4.59591406965657
2.2475826851235637e-08,0.0008864,172.9183026,54.405603553088795,4.59591406965657
2.2617822147227198e-08,0.000892,174.01074675,54.405603553088795,4.59591406965657
2.3429223838607543e-08,0.0009239999999999999,180.25328474999998,54.405603553088795,4.59591406965657
2.413920031856535e-08,0.0009519999999999999,185.71550549999998,54.405603553088795,4.59591406965657
2.428119561455691e-08,0.0009576,186.80794964999998,54.405603553088795,4.59591406965657
2.4808606713954136e-08,0.0009784,190.86559935,54.405603553088795,4.59591406965657
2.501145713679922e-08,0.0009864,192.42623385,54.405603553088795,4.59591406965657
2.5153452432790785e-08,0.000992,193.51867800000002,54.405603553088795,4.59591406965657
2.5559153278480958e-08,0.001008,196.639947,54.405603553088795,4.59591406965657
2.56605784899035e-08,0.0010119999999999999,197.42026424999997,54.405603553088795,4.59591406965657
2.653283530813737e-08,0.0010463999999999998,204.13099259999996,54.405603553088795,4.59591406965657
2.6735685730982463e-08,0.0010544,205.6916271,54.405603553088795,4.59591406965657
2.695882119611206e-08,0.0010632,207.40832505,54.405603553088795,4.59591406965657
2.740509212637125e-08,0.0010808,210.84172095,54.405603553088795,4.59591406965657
2.768908271835437e-08,0.0010919999999999999,213.02660924999998,54.405603553088795,4.59591406965657
2.7729652802923388e-08,0.0010936,213.33873615,54.405603553088795,4.59591406965657
2.7952788268052984e-08,0.0011024,215.05543409999999,54.405603553088795,4.59591406965657
2.813535364861356e-08,0.0011095999999999999,216.46000514999997,54.405603553088795,4.59591406965657
2.8581624578872752e-08,0.0011271999999999999,219.89340104999997,54.405603553088795,4.59591406965657
2.9474166439391135e-08,0.0011623999999999998,226.76019284999998,54.405603553088795,4.59591406965657
2.9636446777667207e-08,0.0011688,228.00870045,54.405603553088795,4.59591406965657
3.016385787706443e-08,0.0011895999999999999,232.06635014999998,54.405603553088795,4.59591406965657
3.081297923016871e-08,0.0012152,237.06038055000002,54.405603553088795,4.59591406965657
3.099554461072929e-08,0.0012224,238.4649516,54.405603553088795,4.59591406965657
3.138096041413495e-08,0.0012376,241.43015714999999,54.405603553088795,4.59591406965657
3.162438092154906e-08,0.0012472,243.30291855,54.405603553088795,4.59591406965657
3.225321723236883e-08,0.001272,248.1408855,54.405603553088795,4.59591406965657
3.259806295120548e-08,0.0012856,250.79396415,54.405603553088795,4.59591406965657
3.269948816262802e-08,0.0012896,251.5742814,54.405603553088795,4.59591406965657
3.2922623627757616e-08,0.0012984,253.29097935,54.405603553088795,4.59591406965657
3.40585859956901e-08,0.0013432,262.03053255,54.405603553088795,4.59591406965657
3.422086633396617e-08,0.0013495999999999998,263.27904014999996,54.405603553088795,4.59591406965657
3.4383146672242244e-08,0.001356,264.52754775,54.405603553088795,4.59591406965657
3.478884751793241e-08,0.001372,267.64881675,54.405603553088795,4.59591406965657
3.501198298306201e-08,0.0013808,269.3655147,54.405603553088795,4.59591406965657
3.564081929388178e-08,0.0014056,274.20348164999996,54.405603553088795,4.59591406965657
3.590452484358039e-08,0.001416,276.2323065,54.405603553088795,4.59591406965657
3.606680518185646e-08,0.0014223999999999999,277.4808141,54.405603553088795,4.59591406965657
3.655364619668467e-08,0.0014416,281.2263369,54.405603553088795,4.59591406965657
3.693906200009033e-08,0.0014567999999999998,284.19154245,54.405603553088795,4.59591406965657
3.7344762845780515e-08,0.0014728,287.31281145,54.405603553088795,4.59591406965657
3.773017864918618e-08,0.001488,290.278017,54.405603553088795,4.59591406965657
3.807502436802282e-08,0.0015015999999999999,292.93109565,54.405603553088795,4.59591406965657
3.860243546742005e-08,0.0015224,296.98874535,54.405603553088795,4.59591406965657
3.902842135539473e-08,0.0015392,300.2660778,54.405603553088795,4.59591406965657
3.937326707423138e-08,0.0015528,302.91915645,54.405603553088795,4.59591406965657
3.96572576662145e-08,0.0015639999999999999,305.10404474999996,54.405603553088795,4.59591406965657
4.05903696113019e-08,0.0016007999999999999,308.79112297518304,54.405603553088795,4.59591406965657
4.0894645245569535e-08,0.0016128,308.8895166305364,54.405603553088795,4.59591406965657
4.2091462740355545e-08,0.00166,309.27379300069316,54.405603553088795,4.59591406965657
4.239573837462317e-08,0.0016719999999999999,309.37080800761044,54.405603553088795,4.59591406965657
4.26797289666063e-08,0.0016832,309.46111063572437,54.405603553088795,4.59591406965657
4.36128409116937e-08,0.00172,309.756182909866,54.405603553088795,4.59591406965657
4.377512124996977e-08,0.0017264,309.8072474710986,54.405603553088795,4.59591406965657
4.4241677222513464e-08,0.0017448,309.9536484491951,54.405603553088795,4.59591406965657
4.4870513533333235e-08,0.0017695999999999999,310.1500223566292,54.405603553088795,4.59591406965657
4.5397924632730465e-08,0.0017904,310.3138968214617,54.405603553088795,4.59591406965657
4.5844195562989656e-08,0.001808,310.4519807189759,54.405603553088795,4.59591406965657
4.629046649324885e-08,0.0018256,310.5895413704663,54.405603553088795,4.59591406965657
4.6696167338939017e-08,0.0018415999999999999,310.7141483441073,54.405603553088795,4.59591406965657
4.6939587846353123e-08,0.0018512,310.7887098811895,54.405603553088795,4.59591406965657
4.730471860747428e-08,0.0018655999999999998,310.9002700614098,54.405603553088795,4.59591406965657
4.7811844664586995e-08,0.0018855999999999999,311.0546592328697,54.405603553088795,4.59591406965657
4.829868567941521e-08,0.0019048,311.20227310744247,54.405603553088795,4.59591406965657
4.840011089083775e-08,0.0019088,311.23295283095985,54.405603553088795,4.59591406965657
4.9191227539933585e-08,0.0019399999999999999,311.47140012572885,54.405603553088795,4.59591406965657
4.9292652751356134e-08,0.001944,311.50186176338315,54.405603553088795,4.59591406965657
4.94549330896322e-08,0.0019504,311.55054958838775,54.405603553088795,4.59591406965657
4.9982344189029426e-08,0.0019711999999999998,311.70835644363723,54.405603553088795,4.59591406965657
5.01446245273055e-08,0.0019776,311.7567815724227,54.405603553088795,4.59591406965657
5.0834315964978786e-08,0.0020047999999999997,311.9619102323091,54.405603553088795,4.59591406965657
5.099659630325486e-08,0.0020112,312.0100177158763,54.405603553088795,4.59591406965657
5.192970824834226e-08,0.002048,312.2854858576824,54.405603553088795,4.59591406965657
5.257882960144654e-08,0.0020736,312.47597837113653,54.405603553088795,4.59591406965657
5.280196506657614e-08,0.0020824,312.5412480534809,54.405603553088795,4.59591406965657
5.3471371461964926e-08,0.0021088,312.7364147111055,54.405603553088795,4.59591406965657
5.436391332248331e-08,0.002144,312.99516105905843,54.405603553088795,4.59591406965657
5.5297025267570714e-08,0.0021808,313.26390335297936,54.405603553088795,4.59591406965657
5.537816543670874e-08,0.0021839999999999997,313.2871883407728,54.405603553088795,4.59591406965657
5.590557653610597e-08,0.0022048,313.43821773111017,54.405603553088795,4.59591406965657
5.649384276235672e-08,0.002228,313.6060195628757,54.405603553088795,4.59591406965657
5.671697822748631e-08,0.0022367999999999997,313.66949009685084,54.405603553088795,4.59591406965657
5.704153890403846e-08,0.0022496,313.7616373053668,54.405603553088795,4.59591406965657
5.773123034171175e-08,0.0022768,313.9567739303839,54.405603553088795,4.59591406965657
5.7974650849125855e-08,0.0022864,314.0254283359728,54.405603553088795,4.59591406965657
5.8055791018263887e-08,0.0022895999999999997,314.04828814313504,54.405603553088795,4.59591406965657
5.858320211766111e-08,0.0023103999999999998,314.1965743287968,54.405603553088795,4.59591406965657
5.886719270964424e-08,0.0023216,314.2762050462185,54.405603553088795,4.59591406965657
5.9009188005635796e-08,0.0023271999999999998,314.31596421156155,54.405603553088795,4.59591406965657
5.9293178597618925e-08,0.0023384,314.3953707810413,54.405603553088795,4.59591406965657
6.026686062727535e-08,0.0023768,314.6665028522937,54.405603553088795,4.59591406965657
6.08956969380951e-08,0.0024016,314.8407014574729,54.405603553088795,4.59591406965657
6.117968753007823e-08,0.0024128,314.9191416949339,54.405603553088795,4.59591406965657
6.170709862947546e-08,0.0024335999999999997,315.0644407062168,54.405603553088795,4.59591406965657
6.241707510943326e-08,0.0024616,315.25927300496073,54.405603553088795,4.59591406965657
6.278220587055442e-08,0.002476,315.35913580391264,54.405603553088795,4.59591406965657
6.308648150482204e-08,0.0024879999999999998,315.44218189494865,54.405603553088795,4.59591406965657
6.365446268878828e-08,0.0025104,315.5967845060414,54.405603553088795,4.59591406965657
6.379645798477985e-08,0.002516,315.63535098039864,54.405603553088795,4.59591406965657
6.458757463387569e-08,0.0025472,315.84961162784043,54.405603553088795,4.59591406965657
6.568296691723917e-08,0.0025904,316.1445981135397,54.405603553088795,4.59591406965657
6.629151818577442e-08,0.0026144,316.30765029338664,54.405603553088795,4.59591406965657
6.67175040737491e-08,0.0026311999999999998,316.421439659684,54.405603553088795,4.59591406965657
6.69609245811632e-08,0.0026408,316.486334933272,54.405603553088795,4.59591406965657
6.708263483487026e-08,0.0026455999999999997,316.5187480633856,54.405603553088795,4.59591406965657
6.750862072284493e-08,0.0026623999999999997,316.6320138458205,54.405603553088795,4.59591406965657
6.807660190681119e-08,0.0026847999999999998,316.78260224309275,54.405603553088795,4.59591406965657
6.83403074565098e-08,0.0026952,316.85235164847495,54.405603553088795,4.59591406965657
6.862429804849292e-08,0.0027064,316.9273491090709,54.405603553088795,4.59591406965657
6.925313435931269e-08,0.0027312,317.0929855072327,54.405603553088795,4.59591406965657
6.945598478215777e-08,0.0027392,317.14629134086437,54.405603553088795,4.59591406965657
6.955740999358032e-08,0.0027432,317.1729214865928,54.405603553088795,4.59591406965657
6.969940528957188e-08,0.0027488,317.21017826277574,54.405603553088795,4.59591406965657
7.059194715009026e-08,0.002784,317.44368952100115,54.405603553088795,4.59591406965657
7.11193582494875e-08,0.0028048,317.58113224312336,54.405603553088795,4.59591406965657
7.126135354547904e-08,0.0028104,317.6180680624966,54.405603553088795,4.59591406965657
7.20727552368594e-08,0.0028423999999999997,317.82858184518767,54.405603553088795,4.59591406965657
7.264073642082564e-08,0.0028648,317.97539187541076,54.405603553088795,4.59591406965657
7.272187658996368e-08,0.002868,317.9963281330133,54.405603553088795,4.59591406965657
7.290444197052426e-08,0.0028752,318.0434014316719,54.405603553088795,4.59591406965657
7.308700735108483e-08,0.0028824,318.09042877962713,54.405603553088795,4.59591406965657
7.320871760479188e-08,0.0028872,318.1217548955511,54.405603553088795,4.59591406965657
7.367527357733559e-08,0.0029056,318.2416506491062,54.405603553088795,4.59591406965657
7.375641374647362e-08,0.0029088,318.26247182189087,54.405603553088795,4.59591406965657
7.395926416931871e-08,0.0029167999999999998,318.3144857094052,54.405603553088795,4.59591406965657
7.420268467673282e-08,0.0029264,318.37682899075594,54.405603553088795,4.59591406965657
7.452724535328495e-08,0.0029392,318.45982943460297,54.405603553088795,4.59591406965657
7.48923761144061e-08,0.0029536,318.5530366157751,54.405603553088795,4.59591406965657
7.517636670638923e-08,0.0029648,318.6254086186718,54.405603553088795,4.59591406965657
7.521693679095824e-08,0.0029663999999999997,318.6357387655106,54.405603553088795,4.59591406965657
7.541978721380334e-08,0.0029744,318.68735694053504,54.405603553088795,4.59591406965657
7.546035729837236e-08,0.002976,318.6976740750723,54.405603553088795,4.59591406965657
7.588634318634703e-08,0.0029928,318.8058737019729,54.405603553088795,4.59591406965657
7.610947865147662e-08,0.0030015999999999997,318.8624551473353,54.405603553088795,4.59591406965657
7.641375428574427e-08,0.0030136,318.9395075144858,54.405603553088795,4.59591406965657
7.659631966630483e-08,0.0030207999999999997,318.98568150044184,54.405603553088795,4.59591406965657
7.698173546971051e-08,0.003036,319.08301920161574,54.405603553088795,4.59591406965657
7.714401580798658e-08,0.0030424,319.12394661621124,54.405603553088795,4.59591406965657
7.724544101940911e-08,0.0030464,319.1495092002389,54.405603553088795,4.59591406965657
7.793513245708241e-08,0.0030735999999999997,319.32298892947694,54.405603553088795,4.59591406965657
7.809741279535848e-08,0.00308,319.36372055245613,54.405603553088795,4.59591406965657
7.872624910617826e-08,0.0031048,319.52124480058836,54.405603553088795,4.59591406965657
7.919280507872195e-08,0.0031232,319.63780071641344,54.405603553088795,4.59591406965657
7.9314515332429e-08,0.0031279999999999997,319.6681625257053,54.405603553088795,4.59591406965657
7.961879096669664e-08,0.00314,319.74398766133015,54.405603553088795,4.59591406965657
7.97810713049727e-08,0.0031463999999999997,319.78438151997284,54.405603553088795,4.59591406965657
7.982164138954172e-08,0.0031479999999999998,319.79447497621163,54.405603553088795,4.59591406965657
8.010563198152485e-08,0.0031592,319.8650732338059,54.405603553088795,4.59591406965657
8.077503837691363e-08,0.0031856,320.03109832290886,54.405603553088795,4.59591406965657
8.109959905346576e-08,0.0031983999999999997,320.1114021079841,54.405603553088795,4.59591406965657
8.14038746877334e-08,0.0032104,320.18657315069635,54.405603553088795,4.59591406965657
8.18501456179926e-08,0.003228,320.2966260959884,54.405603553088795,4.59591406965657
8.243841184424333e-08,0.0032511999999999997,320.4413389999494,54.405603553088795,4.59591406965657
8.270211739394196e-08,0.0032616,320.5060795121792,54.405603553088795,4.59591406965657
8.308753319734762e-08,0.0032768,320.6005556283817,54.405603553088795,4.59591406965657
8.369608446588289e-08,0.0033008,320.7493812023294,54.405603553088795,4.59591406965657
8.375693959273642e-08,0.0033032,320.7642405109494,54.405603553088795,4.59591406965657
8.462919641097028e-08,0.0033376,320.97676337024984,54.405603553088795,4.59591406965657
8.477119170696184e-08,0.0033431999999999997,321.0112791001797,54.405603553088795,4.59591406965657
8.548116818691965e-08,0.0033712,321.1835206850333,54.405603553088795,4.59591406965657
8.576515877890277e-08,0.0033824,321.25226099104657,54.405603553088795,4.59591406965657
8.641428013200705e-08,0.003408,321.4090492164466,54.405603553088795,4.59591406965657
8.665770063942115e-08,0.0034176,321.4677262968687,54.405603553088795,4.59591406965657
8.742853224623248e-08,0.0034479999999999997,321.65311439545826,54.405603553088795,4.59591406965657
8.848335444502693e-08,0.0034896,321.9057736687903,54.405603553088795,4.59591406965657
8.876734503701006e-08,0.0035007999999999997,321.97359627024434,54.405603553088795,4.59591406965657
8.90919057135622e-08,0.0035136,322.0510042807277,54.405603553088795,4.59591406965657
8.919333092498473e-08,0.0035175999999999996,322.0751717196182,54.405603553088795,4.59591406965657
8.927447109412277e-08,0.0035207999999999997,322.09449795475547,54.405603553088795,4.59591406965657
8.961931681295943e-08,0.0035344,322.1765581463816,54.405603553088795,4.59591406965657
9.032929329291722e-08,0.0035624,322.34511885660214,54.405603553088795,4.59591406965657
9.081613430774543e-08,0.0035816,322.4604048269683,54.405603553088795,4.59591406965657
9.150582574541873e-08,0.0036087999999999997,322.6233148806926,54.405603553088795,4.59591406965657
9.197238171796243e-08,0.0036271999999999997,322.7332472910146,54.405603553088795,4.59591406965657
9.207380692938498e-08,0.0036312,322.7571168373143,54.405603553088795,4.59591406965657
9.254036290192867e-08,0.0036496,322.8667849413196,54.405603553088795,4.59591406965657
9.292577870533434e-08,0.0036647999999999997,322.95721778195525,54.405603553088795,4.59591406965657
9.331119450874e-08,0.0036799999999999997,323.0475044606247,54.405603553088795,4.59591406965657
9.396031586184428e-08,0.0037056,323.1992381761602,54.405603553088795,4.59591406965657
9.406174107326683e-08,0.0037096,323.22290958982603,54.405603553088795,4.59591406965657
9.438630174981896e-08,0.0037224,323.2985913063762,54.405603553088795,4.59591406965657
9.495428293378521e-08,0.0037448,323.43079054289615,54.405603553088795,4.59591406965657
9.529912865262185e-08,0.0037584,323.51090391356826,54.405603553088795,4.59591406965657
9.53802688217599e-08,0.0037616,323.52973767820333,54.405603553088795,4.59591406965657
9.560340428688949e-08,0.0037703999999999997,323.5814983394027,54.405603553088795,4.59591406965657
9.584682479430359e-08,0.00378,323.6379108103977,54.405603553088795,4.59591406965657
9.615110042857123e-08,0.003792,323.7083478864877,54.405603553088795,4.59591406965657
9.661765640111492e-08,0.0038104,323.81618279759977,54.405603553088795,4.59591406965657
9.710449741594314e-08,0.0038296,323.9284898885022,54.405603553088795,4.59591406965657
9.728706279650372e-08,0.0038368,323.9705484066324,54.405603553088795,4.59591406965657
9.805789440331505e-08,0.0038672,324.14779053595447,54.405603553088795,4.59591406965657
9.811874953016857e-08,0.0038696,324.161760150473,54.405603553088795,4.59591406965657
9.830131491072914e-08,0.0038767999999999997,324.2036487338367,54.405603553088795,4.59591406965657
9.844331020672071e-08,0.0038824,324.2362077707075,54.405603553088795,4.59591406965657
9.856502046042776e-08,0.0038872,324.2641009414849,54.405603553088795,4.59591406965657
9.878815592555735e-08,0.0038959999999999997,324.3152035582493,54.405603553088795,4.59591406965657
9.917357172896302e-08,0.0039112,324.40336581100127,54.405603553088795,4.59591406965657
9.968069778607575e-08,0.0039312,324.51916546348343,54.405603553088795,4.59591406965657
9.990383325120534e-08,0.00394,324.5700444981503,54.405603553088795,4.59591406965657
1.0024867897004198e-07,0.0039536,324.64858864759486,54.405603553088795,4.59591406965657
1.0063409477344764e-07,0.0039688,324.73624869572853,54.405603553088795,4.59591406965657
1.0087751528086175e-07,0.0039784,324.79154548123995,54.405603553088795,4.59591406965657
1.0101951057685331e-07,0.003984,324.82377790774365,54.405603553088795,4.59591406965657
1.0288602663006961e-07,0.004057611522304461,325.24584101654796,54.405603553088795,4.59591406965657
1.0580765704512189e-07,0.004172834566913383,325.90054356678206,54.405603553088795,4.59591406965657
1.0872928746017414e-07,0.004288057611522305,326.54823243476494,54.405603553088795,4.59591406965657
1.1408560988776997e-07,0.004499299859971995,327.71829972391197,54.405603553088795,4.59591406965657
1.1944193231536578e-07,0.004710542108421685,328.86712819456926,54.405603553088795,4.59591406965657
1.4671048285585355e-07,0.0057859571914382875,334.42993960293774,54.405603553088795,4.59591406965657
1.5498843569850164e-07,0.006112422484496899,336.0366530404155,54.405603553088795,4.59591406965657
1.5791006611355392e-07,0.006227645529105821,336.59569065883295,54.405603553088795,4.59591406965657
1.62779450138641e-07,0.006419683936787358,337.5185376707643,54.405603553088795,4.59591406965657
1.7300515659132393e-07,0.006822964592918584,339.4221815702558,54.405603553088795,4.59591406965657
1.81283109433972e-07,0.007149429885977195,340.93127082674346,54.405603553088795,4.59591406965657
1.856655550565504e-07,0.007322264452890578,341.7193062776471,54.405603553088795,4.59591406965657
1.900480006791288e-07,0.00749509901980396,342.5001199176709,54.405603553088795,4.59591406965657
1.9150881588665491e-07,0.007552710542108421,342.75882648626293,54.405603553088795,4.59591406965657
1.949173847042159e-07,0.007687137427485497,343.35950051253735,54.405603553088795,4.59591406965657
2.0270839914435526e-07,0.007994398879775955,344.7172939318352,54.405603553088795,4.59591406965657
2.1634267441459915e-07,0.008532106421284257,347.0454344633819,54.405603553088795,4.59591406965657
2.231598120497211e-07,0.008800960192038408,348.18798725573777,54.405603553088795,4.59591406965657
2.314377648923692e-07,0.00912742548509702,349.5572319872616,54.405603553088795,4.59591406965657
2.392287793325086e-07,0.009434686937387478,350.8285852949832,54.405603553088795,4.59591406965657
2.421504097475608e-07,0.0095499099819964,351.301166412344,54.405603553088795,4.59591406965657
2.5237611620024376e-07,0.009953190638127626,352.93796730811766,54.405603553088795,4.59591406965657
2.776969131306967e-07,0.010951790358071613,356.88341006974497,54.405603553088795,4.59591406965657
2.8548792757083604e-07,0.011259051810362072,358.068816666544,54.405603553088795,4.59591406965657
2.9230506520595796e-07,0.011527905581116223,359.0957352970259,54.405603553088795,4.59591406965657
3.1373035491634126e-07,0.012372874574914983,362.26399838865035,54.405603553088795,4.59591406965657
3.2882544539411126e-07,0.012968193638727745,364.4456823693746,54.405603553088795,4.59591406965657
3.4538135107940745e-07,0.013621124224844969,366.7940548593397,54.405603553088795,4.59591406965657
3.5950256475216006e-07,0.014178035607121425,368.7625828931841,54.405603553088795,4.59591406965657
3.69728271204843e-07,0.014581316263252651,370.16928899565676,54.405603553088795,4.59591406965657
3.707021480098604e-07,0.014619723944788958,370.3024646763658,54.405603553088795,4.59591406965657
3.892058073051914e-07,0.015349469893978797,372.807442009972,54.405603553088795,4.59591406965657
3.994315137578743e-07,0.015752750550110023,374.17182864133116,54.405603553088795,4.59591406965657
4.169612962481879e-07,0.016444088817763554,376.4794982919863,54.405603553088795,4.59591406965657
4.193959882607314e-07,0.01654010802160432,376.7969891598709,54.405603553088795,4.59591406965657
4.2767394110337944e-07,0.01686657331466293,377.8711217059508,54.405603553088795,4.59591406965657
4.3546495554351884e-07,0.01717383476695339,378.8746865326843,54.405603553088795,4.59591406965657
4.36925770751045e-07,0.01723144628925785,379.062072808221,54.405603553088795,4.59591406965657
4.3984740116609724e-07,0.017346669333866773,379.4361139533189,54.405603553088795,4.59591406965657
4.456906619962018e-07,0.017577115423084617,380.18130195531785,54.405603553088795,4.59591406965657
4.578641220589196e-07,0.01805721144228846,381.7216490753458,54.405603553088795,4.59591406965657
4.6078575247397177e-07,0.018172434486897378,382.0889456343701,54.405603553088795,4.59591406965657
4.797763501718115e-07,0.01892138427685537,384.45461044685095,54.405603553088795,4.59591406965657
4.880543030144596e-07,0.01924784956991398,385.47433706698655,54.405603553088795,4.59591406965657
4.914628718320206e-07,0.01938227645529106,385.89226128053485,54.405603553088795,4.59591406965657
4.973061326621251e-07,0.019612722544508902,386.6060823252564,54.405603553088795,4.59591406965657
5.060710239072819e-07,0.019958391678335668,387.67071104576814,54.405603553088795,4.59591406965657
5.211661143850518e-07,0.02055371074214843,389.487532752666,54.405603553088795,4.59591406965657
5.289571288251913e-07,0.020860972194438887,390.417209903176,54.405603553088795,4.59591406965657
5.435652809004526e-07,0.021437087417483496,392.1460855962751,54.405603553088795,4.59591406965657
5.576864945732052e-07,0.021993998799759953,393.80018798175973,54.405603553088795,4.59591406965657
5.683991394283968e-07,0.022416483296659333,395.04414993986194,54.405603553088795,4.59591406965657
5.786248458810797e-07,0.022819763952790558,396.2230659316393,54.405603553088795,4.59591406965657
5.898244291387802e-07,0.023261452290458094,397.50497527983833,54.405603553088795,4.59591406965657
6.049195196165501e-07,0.023856771354270855,399.21784562612845,54.405603553088795,4.59591406965657
6.127105340566895e-07,0.024164032806561313,400.0953803682671,54.405603553088795,4.59591406965657
6.18553794886794e-07,0.024394478895779156,400.7506783705338,54.405603553088795,4.59591406965657
6.214754253018463e-07,0.024509701940388078,401.0774217074682,54.405603553088795,4.59591406965657
6.229362405093724e-07,0.024567313462692537,401.24056868795265,54.405603553088795,4.59591406965657
6.33648885364564e-07,0.024989797959591917,402.4324538309358,54.405603553088795,4.59591406965657
6.467962222322993e-07,0.025508301660332067,403.88453483817347,54.405603553088795,4.59591406965657
6.570219286849821e-07,0.025911582316463292,405.00598709642946,54.405603553088795,4.59591406965657
6.652998815276303e-07,0.026238047609521906,405.9088518237677,54.405603553088795,4.59591406965657
6.745517111752957e-07,0.026602920584116823,406.91276714073183,54.405603553088795,4.59591406965657
6.823427256154351e-07,0.02691018203640728,407.7540112428441,54.405603553088795,4.59591406965657
7.1448066018101e-07,0.02817763552710542,411.18526823792126,54.405603553088795,4.59591406965657
7.354190114888845e-07,0.029003400680136026,413.3884410243946,54.405603553088795,4.59591406965657
7.383406419039368e-07,0.029118623724744948,413.6939041043356,54.405603553088795,4.59591406965657
7.461316563440761e-07,0.029425885177035406,414.50617644634536,54.405603553088795,4.59591406965657
7.782695909096511e-07,0.030693338667733546,417.8224196544443,54.405603553088795,4.59591406965657
8.011556958275604e-07,0.031595919183836765,420.15150377093323,54.405603553088795,4.59591406965657
8.162507863053305e-07,0.03219123824764953,421.6735202410923,54.405603553088795,4.59591406965657
8.250156775504873e-07,0.0325369073814763,422.55223414266385,54.405603553088795,4.59591406965657
8.28911184770557e-07,0.03269053810762153,422.9416042147974,54.405603553088795,4.59591406965657
8.352413840031702e-07,0.03294018803760752,423.5728119551116,54.405603553088795,4.59591406965657
8.493625976759228e-07,0.03349709941988398,424.9742061833848,54.405603553088795,4.59591406965657
8.547189201035186e-07,0.03370834166833367,425.5033887767384,54.405603553088795,4.59591406965657
8.561797353110448e-07,0.03376595319063813,425.64748663717336,54.405603553088795,4.59591406965657
8.698140105812886e-07,0.034303660732146427,426.9878078937374,54.405603553088795,4.59591406965657
8.805266554364803e-07,0.03472614522904581,428.03517773313416,54.405603553088795,4.59591406965657
8.936739923042155e-07,0.03524464892978596,429.31381857711403,54.405603553088795,4.59591406965657
9.048735755619157e-07,0.03568633726745349,430.3972552348248,54.405603553088795,4.59591406965657
9.282466188823339e-07,0.03660812162432486,432.64163771467736,54.405603553088795,4.59591406965657
9.409070173475602e-07,0.037107421484296854,433.84813769312353,54.405603553088795,4.59591406965657
9.452894629701388e-07,0.03728025605121024,434.2642950138297,54.405603553088795,4.59591406965657
9.57949861435365e-07,0.03777955591118223,435.4623213841258,54.405603553088795,4.59591406965657
9.657408758755045e-07,0.03808681736347269,436.1964997747101,54.405603553088795,4.59591406965657
9.857053503783619e-07,0.038874174834966996,438.06736548230646,54.405603553088795,4.59591406965657
9.92035549610975e-07,0.03912382476495299,438.6574733575955,54.405603553088795,4.59591406965657
9.998265640511144e-07,0.03943108621724345,439.3817478451231,54.405603553088795,4.59591406965657
1.0168694081389193e-06,0.04010322064412883,440.958468652782,54.405603553088795,4.59591406965657
1.0202779769564801e-06,0.0402376475295059,441.27257239770375,54.405603553088795,4.59591406965657
1.027582052994111e-06,0.04052570514102821,441.94427707645093,54.405603553088795,4.59591406965657
1.044137958679407e-06,0.04117863572714543,443.459951874439,54.405603553088795,4.59591406965657
1.0480334658994767e-06,0.04133226645329066,443.8152156357503,54.405603553088795,4.59591406965657
1.0504681579120202e-06,0.04142828565713143,444.03699398504995,54.405603553088795,4.59591406965657
1.0670240635973163e-06,0.04208121624324865,445.53980553722874,54.405603553088795,4.59591406965657
1.072867324427421e-06,0.0423116623324665,446.06803483322886,54.405603553088795,4.59591406965657
1.0777367084525081e-06,0.04250370074014803,446.50736936846005,54.405603553088795,4.59591406965657
1.0869885381001736e-06,0.04286857371474295,447.3399780844801,54.405603553088795,4.59591406965657
1.0908840453202433e-06,0.04302220444088818,447.6897228073827,54.405603553088795,4.59591406965657
1.0918579221252606e-06,0.043060612122424485,447.7770828401525,54.405603553088795,4.59591406965657
1.0977011829553652e-06,0.043291058211642336,448.3006062945416,54.405603553088795,4.59591406965657
1.1020836285779434e-06,0.04346389277855571,448.69253593381904,54.405603553088795,4.59591406965657
1.1132832118356437e-06,0.04390558111622324,449.6913824409754,54.405603553088795,4.59591406965657
1.1201003494707656e-06,0.04417443488697739,450.29745752255127,54.405603553088795,4.59591406965657
1.127891363910905e-06,0.04448169633926785,450.98835600524643,54.405603553088795,4.59591406965657
1.1459080848037273e-06,0.045192238447689534,452.5789691487152,54.405603553088795,4.59591406965657
1.1483427768162709e-06,0.0452882576515303,452.7931663620525,54.405603553088795,4.59591406965657
1.172202758539198e-06,0.046229245849169834,454.88301008838323,54.405603553088795,4.59591406965657
1.1770721425642848e-06,0.04642128425685137,455.3074631706909,54.405603553088795,4.59591406965657
1.1868109106144593e-06,0.046805361072214446,456.1543204929113,54.405603553088795,4.59591406965657
1.1980104938721594e-06,0.047247049409881975,457.1248631672941,54.405603553088795,4.59591406965657
1.2131055843499296e-06,0.047842368473694746,458.427405616549,54.405603553088795,4.59591406965657
1.2369655660728563e-06,0.048783356671334266,460.4734442512393,54.405603553088795,4.59591406965657
1.246217395720522e-06,0.04914822964592919,461.26265767803113,54.405603553088795,4.59591406965657
1.2505998413431003e-06,0.049321064212842575,461.63569777607995,54.405603553088795,4.59591406965657
1.2671557470283964e-06,0.049973994798959795,463.04038309121466,54.405603553088795,4.59591406965657
1.2778683918835882e-06,0.05039647929585918,463.9454845253556,54.405603553088795,4.59591406965657
1.291015728751323e-06,0.050914982996599314,465.052256495313,54.405603553088795,4.59591406965657
1.298319804788954e-06,0.05120304060812163,465.66523019691243,54.405603553088795,4.59591406965657
1.3022153120090237e-06,0.05135667133426686,465.9915995220568,54.405603553088795,4.59591406965657
1.3080585728391279e-06,0.051587117423484694,466.48044048664855,54.405603553088795,4.59591406965657
1.3119540800591976e-06,0.05174074814962992,466.8058614095637,54.405603553088795,4.59591406965657
1.3221797865118806e-06,0.05214402880576115,467.6583034264465,54.405603553088795,4.59591406965657
1.3299708009520199e-06,0.052451290258051605,468.30605839304667,54.405603553088795,4.59591406965657
1.343605076222264e-06,0.052988997799559914,469.43607985418794,54.405603553088795,4.59591406965657
1.3499352754548772e-06,0.05323864772954591,469.9592116651926,54.405603553088795,4.59591406965657
1.3737952571778042e-06,0.05417963592718544,471.9224760906112,54.405603553088795,4.59591406965657
1.377203825995365e-06,0.054314062812562514,472.20185302449414,54.405603553088795,4.59591406965657
1.3966813620957133e-06,0.05508221644328866,473.7931496378407,54.405603553088795,4.59591406965657
1.4025246229258177e-06,0.055312662532506496,474.26884787571913,54.405603553088795,4.59591406965657
1.4122633909759922e-06,0.055696739347869575,475.0599642352063,54.405603553088795,4.59591406965657
1.4142111445860269e-06,0.05577355471094218,475.21793188256044,54.405603553088795,4.59591406965657
1.4229760358311839e-06,0.05611922384476896,475.9277388927536,54.405603553088795,4.59591406965657
1.4293062350637971e-06,0.056368873774754955,476.4393172816792,54.405603553088795,4.59591406965657
1.4356364342964102e-06,0.05661852370474095,476.9500128030276,54.405603553088795,4.59591406965657
1.4400188799189888e-06,0.05679135827165434,477.3030569026688,54.405603553088795,4.59591406965657
1.4478098943591282e-06,0.057098619723944796,477.92965796547946,54.405603553088795,4.59591406965657
1.451218463176689e-06,0.057233046609321866,478.20338226544686,54.405603553088795,4.59591406965657
1.46972212247202e-06,0.05796279255851171,479.6849620018813,54.405603553088795,4.59591406965657
1.4930951657924382e-06,0.05888457691538308,481.54607396302424,54.405603553088795,4.59591406965657
1.5179290243203821e-06,0.059863972794558906,483.5110986469817,54.405603553088795,4.59591406965657
1.5335110532006608e-06,0.06047849569913982,484.7376559195817,54.405603553088795,4.59591406965657
1.5364326836157132e-06,0.06059371874374875,484.9670932833018,54.405603553088795,4.59591406965657
1.5413020676408003e-06,0.06078575715143028,485.34911113245477,54.405603553088795,4.59591406965657
1.5505538972884657e-06,0.0611506301260252,486.073650793401,54.405603553088795,4.59591406965657
1.5695444949863057e-06,0.0618995799159832,487.5556028301521,54.405603553088795,4.59591406965657
1.5734400022063754e-06,0.06205321064212843,487.8587268100326,54.405603553088795,4.59591406965657
1.5763616326214274e-06,0.06216843368673734,488.08587775864993,54.405603553088795,4.59591406965657
1.6075256903819848e-06,0.06339747949589918,490.4986923727936,54.405603553088795,4.59591406965657
1.6235946576647724e-06,0.06403120624124825,491.7356673326254,54.405603553088795,4.59591406965657
1.630898733702403e-06,0.06431926385277055,492.29634938359806,54.405603553088795,4.59591406965657
1.6333334257149465e-06,0.06441528305661132,492.48302566501405,54.405603553088795,4.59591406965657
1.6435591321676297e-06,0.06481856371274256,493.265883925197,54.405603553088795,4.59591406965657
1.6503762698027514e-06,0.0650874174834967,493.7867343751222,54.405603553088795,4.59591406965657
1.6571934074378734e-06,0.06535627125425085,494.3067464304916,54.405603553088795,4.59591406965657
1.6635236066704866e-06,0.06560592118423685,494.788868250014,54.405603553088795,4.59591406965657
1.6820272659658177e-06,0.06633566713342669,496.1940617698165,54.405603553088795,4.59591406965657
1.6937137876260267e-06,0.06679655931186237,497.07844698453704,54.405603553088795,4.59591406965657
1.6995570484561315e-06,0.06702700540108023,497.51974691409134,54.405603553088795,4.59591406965657
1.7029656172736924e-06,0.0671614322864573,497.7768986137587,54.405603553088795,4.59591406965657
1.7131913237263752e-06,0.06756471294258852,498.5471520048658,54.405603553088795,4.59591406965657
1.7258517221916017e-06,0.06806401280256051,499.4983193488295,54.405603553088795,4.59591406965657
1.7326688598267236e-06,0.06833286657331467,500.00935908027617,54.405603553088795,4.59591406965657
1.7448423198894417e-06,0.06881296259251851,500.91998389594016,54.405603553088795,4.59591406965657
1.757502718354668e-06,0.0693122624524905,501.8644091652948,54.405603553088795,4.59591406965657
1.7682153632098596e-06,0.06973474694938989,502.6614676808353,54.405603553088795,4.59591406965657
1.7837973920901383e-06,0.0703492698539708,503.8174718282653,54.405603553088795,4.59591406965657
1.804735743398013e-06,0.07117503500700141,505.3646698343625,54.405603553088795,4.59591406965657
1.8139875730456782e-06,0.07153990798159632,506.0460837212273,54.405603553088795,4.59591406965657
1.8397953083786401e-06,0.07255771154230847,507.93974317439574,54.405603553088795,4.59591406965657
1.8553773372589186e-06,0.07317223444688938,509.07806968413854,54.405603553088795,4.59591406965657
1.8602467212840059e-06,0.07336427285457092,509.4330313049977,54.405603553088795,4.59591406965657
1.8704724277366889e-06,0.07376755351070215,510.1772733698088,54.405603553088795,4.59591406965657
1.8772895653718108e-06,0.0740364072814563,510.6725533855065,54.405603553088795,4.59591406965657
1.8821589493968978e-06,0.07422844568913783,511.02589547334946,54.405603553088795,4.59591406965657
1.903584239107281e-06,0.07507341468293659,512.5763845295994,54.405603553088795,4.59591406965657
1.9118621919499293e-06,0.0753998799759952,513.1736124953802,54.405603553088795,4.59591406965657
1.9225748368051207e-06,0.07582236447289459,513.9450008523222,54.405603553088795,4.59591406965657
1.9279311592327166e-06,0.07603360672134428,514.3300662885848,54.405603553088795,4.59591406965657
1.9420523729054694e-06,0.07659051810362073,515.3432441345846,54.405603553088795,4.59591406965657
1.984416013923727e-06,0.0782612522504501,518.365677394588,54.405603553088795,4.59591406965657
1.988311521143797e-06,0.07841488297659532,518.6423327748653,54.405603553088795,4.59591406965657
1.9936678435713928e-06,0.07862612522504502,519.0223890122392,54.405603553088795,4.59591406965657
2.0014588580115318e-06,0.07893338667733547,519.5744879796637,54.405603553088795,4.59591406965657
2.007789057244145e-06,0.07918303660732147,520.0224514853539,54.405603553088795,4.59591406965657
2.013145379671741e-06,0.07939427885577116,520.4010674725587,54.405603553088795,4.59591406965657
2.0170408868918107e-06,0.07954790958191639,520.6761778340926,54.405603553088795,4.59591406965657
2.040900868614737e-06,0.08048889777955591,522.3567295874003,54.405603553088795,4.59591406965657
2.0506396366649117e-06,0.08087297459491899,523.0404649858174,54.405603553088795,4.59591406965657
2.052100451872438e-06,0.08093058611722345,523.1429159660557,54.405603553088795,4.59591406965657
2.0559959590925076e-06,0.08108421684336868,523.4159796203514,54.405603553088795,4.59591406965657
2.0691432959602426e-06,0.08160272054410883,524.3360834187979,54.405603553088795,4.59591406965657
2.090568585670626e-06,0.08244768953790758,525.8306414064534,54.405603553088795,4.59591406965657
2.095437969695713e-06,0.08263972794558912,526.1694791732725,54.405603553088795,4.59591406965657
2.1080983681609394e-06,0.08313902780556112,527.049023334292,54.405603553088795,4.59591406965657
2.1183240746136224e-06,0.08354230846169235,527.7579214340684,54.405603553088795,4.59591406965657
2.1280628426637965e-06,0.08392638527705541,528.4318227318046,54.405603553088795,4.59591406965657
2.135853857103936e-06,0.08423364672934587,528.9700781824239,54.405603553088795,4.59591406965657
2.1446187483490928e-06,0.08457931586317263,529.5747011191083,54.405603553088795,4.59591406965657
2.1587399620218455e-06,0.0851362272454491,530.5467927334381,54.405603553088795,4.59591406965657
2.1631224076444237e-06,0.08530906181236247,530.8479716775256,54.405603553088795,4.59591406965657
2.171400360487072e-06,0.08563552710542109,531.4162167549798,54.405603553088795,4.59591406965657
2.1733481140971067e-06,0.0857123424684937,531.549798622305,54.405603553088795,4.59591406965657
2.1806521901347373e-06,0.08600040008001601,532.0503153450919,54.405603553088795,4.59591406965657
2.1864954509648416e-06,0.08623084616923385,532.4502581292159,54.405603553088795,4.59591406965657
2.1937995270024726e-06,0.08651890378075616,532.9496009139528,54.405603553088795,4.59591406965657
2.196234219015016e-06,0.08661492298459693,533.1159043689172,54.405603553088795,4.59591406965657
2.199642787832577e-06,0.086749349869974,533.3486084640772,54.405603553088795,4.59591406965657
2.2059729870651903e-06,0.08699899979996,533.7804004448514,54.405603553088795,4.59591406965657
2.218146447127908e-06,0.08747909581916384,534.6094138580667,54.405603553088795,4.59591406965657
2.220094200737943e-06,0.08755591118223645,534.7418911643948,54.405603553088795,4.59591406965657
2.226424399970556e-06,0.08780556111222244,535.1721297011937,54.405603553088795,4.59591406965657
2.2356762296182215e-06,0.08817043408681736,535.8000827009296,54.405603553088795,4.59591406965657
2.2546668273160613e-06,0.08891938387677537,537.0858726175056,54.405603553088795,4.59591406965657
2.271709671403866e-06,0.08959151830366073,538.2361949665751,54.405603553088795,4.59591406965657
2.293621899516758e-06,0.09045569113822766,539.7102473973289,54.405603553088795,4.59591406965657
2.297517406736828e-06,0.09060932186437289,539.971725155029,54.405603553088795,4.59591406965657
2.3048214827744585e-06,0.09089737947589518,540.4615303943337,54.405603553088795,4.59591406965657
2.307256174787002e-06,0.09099339867973595,540.6246642335852,54.405603553088795,4.59591406965657
2.3145602508246326e-06,0.09128145629125825,541.1136634098838,54.405603553088795,4.59591406965657
2.3252728956798244e-06,0.09170394078815763,541.8297749767576,54.405603553088795,4.59591406965657
2.332576971717455e-06,0.09199199839967995,542.3172953127813,54.405603553088795,4.59591406965657
2.3418288013651203e-06,0.09235687137427485,542.9339672353194,54.405603553088795,4.59591406965657
2.3486459390002424e-06,0.09262572514502901,543.3877492576441,54.405603553088795,4.59591406965657
2.3642279678805213e-06,0.09324024804960993,544.4230407796639,54.405603553088795,4.59591406965657
2.3686104135030995e-06,0.09341308261652331,544.7137366153432,54.405603553088795,4.59591406965657
2.3768883663457474e-06,0.09373954790958192,545.2622570775458,54.405603553088795,4.59591406965657
2.380783873565817e-06,0.09389317863572715,545.5201265138173,54.405603553088795,4.59591406965657
2.3992875328611485e-06,0.09462292458491699,546.7427662179124,54.405603553088795,4.59591406965657
2.4109740545213572e-06,0.09508381676335267,547.5130653397729,54.405603553088795,4.59591406965657
2.4294777138166886e-06,0.09581356271254252,548.7297341935918,54.405603553088795,4.59591406965657
2.4562593259546674e-06,0.09686977395479096,550.4843209793074,54.405603553088795,4.59591406965657
2.4733021700424725e-06,0.09754190838167634,551.5969925737317,54.405603553088795,4.59591406965657
2.484014814897664e-06,0.09796439287857572,552.2948558986998,54.405603553088795,4.59591406965657
2.4913188909352945e-06,0.09825245049009802,552.7699989693497,54.405603553088795,4.59591406965657
2.4976490901679078e-06,0.09850210042008402,553.181350347117,54.405603553088795,4.59591406965657
2.5069009198155734e-06,0.09886697339467894,553.7818255703531,54.405603553088795,4.59591406965657
2.522482948695852e-06,0.09948149629925986,554.7912023490119,54.405603553088795,4.59591406965657
2.524430702305887e-06,0.09955831166233248,554.917203242992,54.405603553088795,4.59591406965657
2.529300086330974e-06,0.09975035007001401,555.2320397144497,54.405603553088795,4.59591406965657
2.5312478399410087e-06,0.09982716543308662,555.3579081041131,54.405603553088795,4.59591406965657