File: datasets/aisi_316_L/data/M1/train_97.csv
Time(s),Strain(%),Stress(MPa),Temp(C),Log_SR(s-1)
0.0,0.0,0.0,116.71397186492558,1.5894358933782868
2.2648882503310897e-07,8.8e-06,1.689901125,116.71397186492558,1.5894358933782868
9.47135086502092e-07,3.68e-05,7.06685925,116.71397186492558,1.5894358933782868
1.1118542319807168e-06,4.32e-05,8.29587825,116.71397186492558,1.5894358933782868
1.5648318820469346e-06,6.08e-05,11.6756805,116.71397186492558,1.5894358933782868
3.953259491486993e-06,0.0001536,29.496456,116.71397186492558,1.5894358933782868
5.16806318939185e-06,0.0002008,38.560471125,116.71397186492558,1.5894358933782868
5.415141907609787e-06,0.0002104,40.403999625,116.71397186492558,1.5894358933782868
5.765170091751865e-06,0.000224,43.015665,116.71397186492558,1.5894358933782868
6.485816353220848e-06,0.000252,48.392623125,116.71397186492558,1.5894358933782868
6.979973789656721e-06,0.0002712,52.079680124999996,116.71397186492558,1.5894358933782868
7.927108876158815e-06,0.000308,59.146539375,116.71397186492558,1.5894358933782868
8.297726953485718e-06,0.0003224,61.911832125,116.71397186492558,1.5894358933782868
8.359496633040203e-06,0.0003248,62.372714249999994,116.71397186492558,1.5894358933782868
8.565395564888484e-06,0.00033279999999999996,63.908987999999994,116.71397186492558,1.5894358933782868
8.668345030812625e-06,0.0003368,64.677124875,116.71397186492558,1.5894358933782868
9.69783969005403e-06,0.0003768,72.358493625,116.71397186492558,1.5894358933782868
9.759609369608514e-06,0.0003792,72.81937575,116.71397186492558,1.5894358933782868
1.0068457767380934e-05,0.00039119999999999997,75.123786375,116.71397186492558,1.5894358933782868
1.0130227446935419e-05,0.00039359999999999997,75.58466849999999,116.71397186492558,1.5894358933782868
1.0377306165153355e-05,0.0004032,77.428197,116.71397186492558,1.5894358933782868
1.0603794990186464e-05,0.000412,79.118098125,116.71397186492558,1.5894358933782868
1.074792424248026e-05,0.00041759999999999996,80.19348975,116.71397186492558,1.5894358933782868
1.0995002960698199e-05,0.0004272,82.03701824999999,116.71397186492558,1.5894358933782868
1.1200901892546478e-05,0.00043519999999999995,83.573292,116.71397186492558,1.5894358933782868
1.1653879542612697e-05,0.0004528,86.95309425,116.71397186492558,1.5894358933782868
1.2003907726754773e-05,0.00046639999999999995,89.564759625,116.71397186492558,1.5894358933782868
1.2848093347332727e-05,0.0004992,95.863482,116.71397186492558,1.5894358933782868
1.2992222599626523e-05,0.0005048,96.938873625,116.71397186492558,1.5894358933782868
1.3342250783768601e-05,0.0005184,99.550539,116.71397186492558,1.5894358933782868
1.3815818327019644e-05,0.0005367999999999999,103.08396862499998,116.71397186492558,1.5894358933782868
1.4268795977085864e-05,0.0005543999999999999,106.46377087499998,116.71397186492558,1.5894358933782868
1.4598234268043115e-05,0.0005672,108.921808875,116.71397186492558,1.5894358933782868
1.4742363520336909e-05,0.0005727999999999999,109.99720049999999,116.71397186492558,1.5894358933782868
1.5092391704478986e-05,0.0005863999999999999,112.60886587499999,116.71397186492558,1.5894358933782868
1.527770074314244e-05,0.0005936,113.99151225,116.71397186492558,1.5894358933782868
1.5483599674990723e-05,0.0006016,115.52778599999999,116.71397186492558,1.5894358933782868
1.591598743187211e-05,0.0006184,118.75396087499999,116.71397186492558,1.5894358933782868
1.626601561601419e-05,0.000632,121.36562624999999,116.71397186492558,1.5894358933782868
1.6760173052450064e-05,0.0006512,125.05268325,116.71397186492558,1.5894358933782868
1.690430230474386e-05,0.0006567999999999999,126.12807487499998,116.71397186492558,1.5894358933782868
1.758376877984319e-05,0.0006832,131.19777825,116.71397186492558,1.5894358933782868
1.7913207070800437e-05,0.000696,133.65581625,116.71397186492558,1.5894358933782868
1.8201465575388027e-05,0.0007072,135.8065995,116.71397186492558,1.5894358933782868
1.8675033118639074e-05,0.0007256,139.340029125,116.71397186492558,1.5894358933782868
1.9313319807368745e-05,0.0007503999999999999,144.10247775,116.71397186492558,1.5894358933782868
1.9992786282468074e-05,0.0007768,149.172181125,116.71397186492558,1.5894358933782868
2.0425174039349462e-05,0.0007936,152.398356,116.71397186492558,1.5894358933782868
2.0939921368970164e-05,0.0008135999999999999,156.23904037499997,116.71397186492558,1.5894358933782868
2.139289901903638e-05,0.0008311999999999999,159.61884262499998,116.71397186492558,1.5894358933782868
2.18458766691026e-05,0.0008487999999999999,162.998644875,116.71397186492558,1.5894358933782868
2.2113545280505366e-05,0.0008592,164.99580075,116.71397186492558,1.5894358933782868
2.2628292610126068e-05,0.0008792,168.836485125,116.71397186492558,1.5894358933782868
2.3575427696628158e-05,0.0009159999999999999,175.903344375,116.71397186492558,1.5894358933782868
2.3678377162552298e-05,0.0009199999999999999,176.67148124999997,116.71397186492558,1.5894358933782868
2.388427609440058e-05,0.000928,178.207755,116.71397186492558,1.5894358933782868
2.4234304278542658e-05,0.0009416,180.819420375,116.71397186492558,1.5894358933782868
2.4687281928608876e-05,0.0009592,184.199222625,116.71397186492558,1.5894358933782868
2.5016720219566127e-05,0.000972,186.657260625,116.71397186492558,1.5894358933782868
2.538733829689303e-05,0.0009864,189.42255337499998,116.71397186492558,1.5894358933782868
2.60256249856227e-05,0.0010111999999999999,194.18500199999997,116.71397186492558,1.5894358933782868
2.6107984558362012e-05,0.0010144,194.7995115,116.71397186492558,1.5894358933782868
2.6808040926646168e-05,0.0010416,200.02284225,116.71397186492558,1.5894358933782868
2.7116889324418594e-05,0.0010536,202.327252875,116.71397186492558,1.5894358933782868
2.7261018576712385e-05,0.0010592,203.40264449999998,116.71397186492558,1.5894358933782868
2.7343378149451702e-05,0.0010624,204.017154,116.71397186492558,1.5894358933782868
2.7466917508560668e-05,0.0010672,204.93891824999997,116.71397186492558,1.5894358933782868
2.80022547313662e-05,0.001088,208.93323,116.71397186492558,1.5894358933782868
2.8681721206465525e-05,0.0011144,214.002933375,116.71397186492558,1.5894358933782868
2.8887620138313805e-05,0.0011224,215.539207125,116.71397186492558,1.5894358933782868
2.9114108963346913e-05,0.0011312,217.22910825,116.71397186492558,1.5894358933782868
2.9896524904370386e-05,0.0011616,223.0669485,116.71397186492558,1.5894358933782868
3.0081833943033836e-05,0.0011688,224.449594875,116.71397186492558,1.5894358933782868
3.0184783408957972e-05,0.0011727999999999999,225.21773174999998,116.71397186492558,1.5894358933782868
3.0287732874882116e-05,0.0011768,225.985868625,116.71397186492558,1.5894358933782868
3.04936318067304e-05,0.0011848,227.522142375,116.71397186492558,1.5894358933782868
3.088483977724213e-05,0.0012,230.4410625,116.71397186492558,1.5894358933782868
3.127604774775387e-05,0.0012152,233.35998262500001,116.71397186492558,1.5894358933782868
3.1605486038711116e-05,0.001228,235.81802062499997,116.71397186492558,1.5894358933782868
3.1976104116038016e-05,0.0012423999999999998,238.58331337499996,116.71397186492558,1.5894358933782868
3.240849187291941e-05,0.0012592,241.80948825000002,116.71397186492558,1.5894358933782868
3.331444717305185e-05,0.0012944,248.56909275,116.71397186492558,1.5894358933782868
3.343798653216081e-05,0.0012992,249.49085699999998,116.71397186492558,1.5894358933782868
3.38703742890422e-05,0.001316,251.85163191766043,116.71397186492558,1.5894358933782868
3.419981257999945e-05,0.0013288,251.94472062658107,116.71397186492558,1.5894358933782868
3.4549840764141526e-05,0.0013423999999999999,252.0432450158675,116.71397186492558,1.5894358933782868
3.465279023006567e-05,0.0013464,252.07214859253375,116.71397186492558,1.5894358933782868
3.508517798694706e-05,0.0013632,252.19317972388367,116.71397186492558,1.5894358933782868
3.588818382115535e-05,0.0013943999999999998,252.4164195862654,116.71397186492558,1.5894358933782868
3.65058806167002e-05,0.0014184,252.58681946053602,116.71397186492558,1.5894358933782868
3.6876498694027104e-05,0.0014328,252.68851971070694,116.71397186492558,1.5894358933782868
3.7308886450908495e-05,0.0014495999999999999,252.80666754954956,116.71397186492558,1.5894358933782868
3.76795045282354e-05,0.001464,252.90751271964817,116.71397186492558,1.5894358933782868
3.825602153741058e-05,0.0014864,253.06361744652114,116.71397186492558,1.5894358933782868
3.8832538546585775e-05,0.0015088,253.21880735063925,116.71397186492558,1.5894358933782868
3.930610608983681e-05,0.0015271999999999998,253.34561367070413,116.71397186492558,1.5894358933782868
3.959436459442441e-05,0.0015383999999999999,253.42250844574104,116.71397186492558,1.5894358933782868
3.986203320582717e-05,0.0015488,253.4937154721995,116.71397186492558,1.5894358933782868
4.023265128315408e-05,0.0015631999999999998,253.59200272970506,116.71397186492558,1.5894358933782868
4.039737042863271e-05,0.0015696,253.63557254519353,116.71397186492558,1.5894358933782868
4.099447733099272e-05,0.0015928,253.79293563292595,116.71397186492558,1.5894358933782868
4.1488634767428595e-05,0.001612,253.92249224958664,116.71397186492558,1.5894358933782868
4.198279220386447e-05,0.0016312,254.0514484335342,116.71397186492558,1.5894358933782868
4.222987092208241e-05,0.0016408,254.11570443698847,116.71397186492558,1.5894358933782868
4.280638793125759e-05,0.0016631999999999999,254.26506761006797,116.71397186492558,1.5894358933782868
4.301228686310587e-05,0.0016711999999999999,254.3182212041242,116.71397186492558,1.5894358933782868
4.3259365581323806e-05,0.0016807999999999999,254.38187470807603,116.71397186492558,1.5894358933782868
4.360939376546589e-05,0.0016944,254.47180832498003,116.71397186492558,1.5894358933782868
4.379470280412934e-05,0.0017016,254.51930624603943,116.71397186492558,1.5894358933782868
4.387706237686866e-05,0.0017048,254.5403912669535,116.71397186492558,1.5894358933782868
4.4185910774641074e-05,0.0017167999999999999,254.6193230022047,116.71397186492558,1.5894358933782868
4.4618298531522465e-05,0.0017335999999999999,254.72946690289515,116.71397186492558,1.5894358933782868
4.4741837890631434e-05,0.0017384,254.7608600277511,116.71397186492558,1.5894358933782868
4.521540543388248e-05,0.0017568,254.88088846245074,116.71397186492558,1.5894358933782868
4.560661340439421e-05,0.001772,254.97967302770596,116.71397186492558,1.5894358933782868
4.583310222942732e-05,0.0017808,255.03671304398526,116.71397186492558,1.5894358933782868
4.628607987949354e-05,0.0017984,255.15046435584412,116.71397186492558,1.5894358933782868
4.6512568704526645e-05,0.0018072,255.20717714253317,116.71397186492558,1.5894358933782868
4.665669795682044e-05,0.0018127999999999998,255.24321102874333,116.71397186492558,1.5894358933782868
4.6862596888668726e-05,0.0018208,255.29461279305895,116.71397186492558,1.5894358933782868
4.752147347058322e-05,0.0018464,255.4585096818104,116.71397186492558,1.5894358933782868
4.785091176154047e-05,0.0018591999999999999,255.5401256115839,116.71397186492558,1.5894358933782868
4.820093994568255e-05,0.0018728,255.6266027910287,116.71397186492558,1.5894358933782868
4.828329951842186e-05,0.0018759999999999998,255.64691472824597,116.71397186492558,1.5894358933782868
4.8674507488933596e-05,0.0018912,255.7432125064016,116.71397186492558,1.5894358933782868
4.906571545944533e-05,0.0019064,255.83920890616798,116.71397186492558,1.5894358933782868
4.953928300269638e-05,0.0019248,255.95501661541817,116.71397186492558,1.5894358933782868
4.972459204135983e-05,0.001932,256.0002150487283,116.71397186492558,1.5894358933782868
5.0651137234677086e-05,0.0019679999999999997,256.22522927248286,116.71397186492558,1.5894358933782868
5.0959985632449516e-05,0.00198,256.2998765282922,116.71397186492558,1.5894358933782868
5.122765424385228e-05,0.0019904,256.3644282114271,116.71397186492558,1.5894358933782868
5.1577682427994354e-05,0.0020039999999999997,256.44864381816933,116.71397186492558,1.5894358933782868
5.3018974950932317e-05,0.0020599999999999998,256.79309117747533,116.71397186492558,1.5894358933782868
5.345136270781371e-05,0.0020767999999999997,256.8957107233885,116.71397186492558,1.5894358933782868
5.4089649396543386e-05,0.0021016,257.04660698570825,116.71397186492558,1.5894358933782868
5.588097010362343e-05,0.0021712,257.46642500564906,116.71397186492558,1.5894358933782868
5.672515572420138e-05,0.002204,257.6624476250967,116.71397186492558,1.5894358933782868
5.728108284019174e-05,0.0022256,257.79091470407405,116.71397186492558,1.5894358933782868
5.8187038140324175e-05,0.0022608,257.9992314517271,116.71397186492558,1.5894358933782868
5.822821792669383e-05,0.0022624,258.00867022281113,116.71397186492558,1.5894358933782868
5.839293707217246e-05,0.0022688,258.04639930289386,116.71397186492558,1.5894358933782868
5.890768440179315e-05,0.0022887999999999997,258.1640360359855,116.71397186492558,1.5894358933782868
5.942243173141385e-05,0.0023087999999999997,258.2812725511844,116.71397186492558,1.5894358933782868
5.98136397019256e-05,0.002324,258.37010760084445,116.71397186492558,1.5894358933782868
6.024602745880699e-05,0.0023408,258.46803049346596,116.71397186492558,1.5894358933782868
6.0369566817915945e-05,0.0023455999999999998,258.49595807026196,116.71397186492558,1.5894358933782868
6.09872636134608e-05,0.0023696,258.63526301632174,116.71397186492558,1.5894358933782868
6.139906147715735e-05,0.0023856,258.7278274021808,116.71397186492558,1.5894358933782868
6.166673008856011e-05,0.0023959999999999997,258.78786444390477,116.71397186492558,1.5894358933782868
6.228442688410496e-05,0.00242,258.92602491774403,116.71397186492558,1.5894358933782868
6.327274175697671e-05,0.0024584,259.1459753355383,116.71397186492558,1.5894358933782868
6.382866887296708e-05,0.00248,259.2691085403974,116.71397186492558,1.5894358933782868
6.4075747591185e-05,0.0024896,259.3237000802527,116.71397186492558,1.5894358933782868
6.421987684347881e-05,0.0024952,259.35550723215715,116.71397186492558,1.5894358933782868
6.426105662984846e-05,0.0024968,259.3645898747786,116.71397186492558,1.5894358933782868
6.500229278450226e-05,0.0025256,259.52769127747035,116.71397186492558,1.5894358933782868
6.520819171635055e-05,0.0025336,259.5728682879402,116.71397186492558,1.5894358933782868
6.592883797781954e-05,0.0025616,259.7305515728397,116.71397186492558,1.5894358933782868
6.642299541425541e-05,0.0025808,259.8382889544764,116.71397186492558,1.5894358933782868
6.650535498699472e-05,0.002584,259.8562147504609,116.71397186492558,1.5894358933782868
6.73701305007575e-05,0.0026176,260.04391585475946,116.71397186492558,1.5894358933782868
6.819372622815062e-05,0.0026496,260.22180712056786,116.71397186492558,1.5894358933782868
6.833785548044442e-05,0.0026552,260.2528517499348,116.71397186492558,1.5894358933782868
6.844080494636857e-05,0.0026592,260.2750108533619,116.71397186492558,1.5894358933782868
6.936735013968583e-05,0.0026952,260.4738612136744,116.71397186492558,1.5894358933782868
6.947029960560996e-05,0.0026991999999999997,260.49589156941454,116.71397186492558,1.5894358933782868
6.979973789656721e-05,0.002712,260.56630329943147,116.71397186492558,1.5894358933782868
7.004681661478515e-05,0.0027216,260.61902707356313,116.71397186492558,1.5894358933782868
7.054097405122103e-05,0.0027408,260.72425753458646,116.71397186492558,1.5894358933782868
7.082923255580862e-05,0.0027519999999999997,260.78550920452506,116.71397186492558,1.5894358933782868
7.136456977861415e-05,0.0027727999999999997,260.89900499571587,116.71397186492558,1.5894358933782868
7.17763676423107e-05,0.0027887999999999997,260.9860836540687,116.71397186492558,1.5894358933782868
7.22911149719314e-05,0.0028087999999999998,261.0946584683596,116.71397186492558,1.5894358933782868
7.239406443785555e-05,0.0028128,261.1163372044656,116.71397186492558,1.5894358933782868
7.28676319811066e-05,0.0028312,261.215904940537,116.71397186492558,1.5894358933782868
7.309412080613971e-05,0.00284,261.2634350544663,116.71397186492558,1.5894358933782868
7.348532877665144e-05,0.0028552,261.34539745877703,116.71397186492558,1.5894358933782868
7.365004792213006e-05,0.0028615999999999997,261.3798570148225,116.71397186492558,1.5894358933782868
7.381476706760869e-05,0.002868,261.41428652696334,116.71397186492558,1.5894358933782868
7.400007610627215e-05,0.0028752,261.4529839322307,116.71397186492558,1.5894358933782868
7.463836279500182e-05,0.0029,261.5859866720922,116.71397186492558,1.5894358933782868
7.47001324745563e-05,0.0029024,261.59883431874226,116.71397186492558,1.5894358933782868
7.513252023143769e-05,0.0029192,261.68865211843047,116.71397186492558,1.5894358933782868
7.53590090564708e-05,0.002928,261.73561907135144,116.71397186492558,1.5894358933782868
7.562667766787357e-05,0.0029384,261.7910545542367,116.71397186492558,1.5894358933782868
7.595611595883081e-05,0.0029511999999999997,261.8591779075076,116.71397186492558,1.5894358933782868
7.647086328845151e-05,0.0029712,261.96539041217267,116.71397186492558,1.5894358933782868
7.657381275437566e-05,0.0029752,261.98659941386404,116.71397186492558,1.5894358933782868
7.698561061807221e-05,0.0029912,262.0713244507265,116.71397186492558,1.5894358933782868
7.706797019081153e-05,0.0029944,262.0882482285198,116.71397186492558,1.5894358933782868
7.712973987036602e-05,0.0029968,262.1009364334238,116.71397186492558,1.5894358933782868
7.731504890902946e-05,0.0030039999999999997,262.13897729178103,116.71397186492558,1.5894358933782868
7.766507709317155e-05,0.0030176,262.21073536860155,116.71397186492558,1.5894358933782868
7.780920634546533e-05,0.0030231999999999998,262.24024613897086,116.71397186492558,1.5894358933782868
7.85092627137495e-05,0.0030504,262.38328202241314,116.71397186492558,1.5894358933782868
7.861221217967362e-05,0.0030543999999999997,262.4042746823549,116.71397186492558,1.5894358933782868
7.900342015018537e-05,0.0030696,262.4839491981933,116.71397186492558,1.5894358933782868
7.91063696161095e-05,0.0030735999999999997,262.50489058395664,116.71397186492558,1.5894358933782868
7.937403822751228e-05,0.003084,262.5592885048229,116.71397186492558,1.5894358933782868
7.988878555713298e-05,0.003104,262.66369922972075,116.71397186492558,1.5894358933782868
8.03417632071992e-05,0.0031216,262.75536382653456,116.71397186492558,1.5894358933782868
8.08565105368199e-05,0.0031416,262.85928383439784,116.71397186492558,1.5894358933782868
8.149479722554956e-05,0.0031663999999999998,262.9877870083715,116.71397186492558,1.5894358933782868
8.155656690510405e-05,0.0031688,263.0002019317352,116.71397186492558,1.5894358933782868
8.266842113708477e-05,0.003212,263.2230472775718,116.71397186492558,1.5894358933782868
8.308021900078133e-05,0.003228,263.3052855656033,116.71397186492558,1.5894358933782868
8.353319665084754e-05,0.0032456,263.3955642863326,116.71397186492558,1.5894358933782868
8.396558440772894e-05,0.0032624,263.4815614891289,116.71397186492558,1.5894358933782868
8.456269131008896e-05,0.0032856,263.6000361352766,116.71397186492558,1.5894358933782868
8.507743863970965e-05,0.0033055999999999997,263.70190782981115,116.71397186492558,1.5894358933782868
8.530392746474276e-05,0.0033144,263.7466551931114,116.71397186492558,1.5894358933782868
8.571572532843932e-05,0.0033304,263.82789550614746,116.71397186492558,1.5894358933782868
8.614811308532072e-05,0.0033472,263.9130341833501,116.71397186492558,1.5894358933782868
8.639519180353866e-05,0.0033568,263.9616100296458,116.71397186492558,1.5894358933782868
8.68687593467897e-05,0.0033751999999999996,264.05456256471496,116.71397186492558,1.5894358933782868
8.775412475373732e-05,0.0034096,264.2278149912903,116.71397186492558,1.5894358933782868
8.78982540060311e-05,0.0034151999999999997,264.25595422752673,116.71397186492558,1.5894358933782868
8.820710240380353e-05,0.0034272,264.316192067733,116.71397186492558,1.5894358933782868
8.845418112202146e-05,0.0034368,264.3643231355619,116.71397186492558,1.5894358933782868
8.863949016068491e-05,0.003444,264.4003870346584,116.71397186492558,1.5894358933782868
8.907187791756631e-05,0.0034608,264.4844219773011,116.71397186492558,1.5894358933782868
8.933954652896907e-05,0.0034712,264.53636388736305,116.71397186492558,1.5894358933782868
9.057494012005875e-05,0.0035191999999999997,264.77531365976205,116.71397186492558,1.5894358933782868
9.071906937235254e-05,0.0035248,264.8031080935156,116.71397186492558,1.5894358933782868
9.17073842452243e-05,0.0035632,264.99323669511256,116.71397186492558,1.5894358933782868
9.209859221573603e-05,0.0035784,265.0682749692091,116.71397186492558,1.5894358933782868
9.279864858402019e-05,0.0036056,265.20224446556074,116.71397186492558,1.5894358933782868
9.331339591364088e-05,0.0036255999999999997,265.30050012496156,116.71397186492558,1.5894358933782868
9.360165441822848e-05,0.0036368,265.35543095681305,116.71397186492558,1.5894358933782868
9.399286238874022e-05,0.003652,265.42987453331864,116.71397186492558,1.5894358933782868
9.432230067969746e-05,0.0036647999999999997,265.49247018314287,116.71397186492558,1.5894358933782868
9.454878950473058e-05,0.0036736,265.5354552408937,116.71397186492558,1.5894358933782868
9.489881768887265e-05,0.0036872,265.60180778965093,116.71397186492558,1.5894358933782868
9.520766608664507e-05,0.0036991999999999997,265.6602749327393,116.71397186492558,1.5894358933782868
9.561946395034163e-05,0.0037151999999999997,265.7381161905673,116.71397186492558,1.5894358933782868
9.601067192085337e-05,0.0037304,265.81194437568365,116.71397186492558,1.5894358933782868
9.61136213867775e-05,0.0037343999999999997,265.83135333448456,116.71397186492558,1.5894358933782868
9.708134636646443e-05,0.0037719999999999997,266.0134029598446,116.71397186492558,1.5894358933782868
9.745196444379134e-05,0.0037863999999999997,266.0829364948477,116.71397186492558,1.5894358933782868
9.817261070526032e-05,0.0038144,266.2178460652109,116.71397186492558,1.5894358933782868
9.844027931666309e-05,0.0038247999999999997,266.2678568952952,116.71397186492558,1.5894358933782868
9.940800429635e-05,0.0038623999999999998,266.44822449163615,116.71397186492558,1.5894358933782868
9.988157183960105e-05,0.0038808,266.53623983406857,116.71397186492558,1.5894358933782868
0.00010008747077144934,0.0038888,266.5744565949747,116.71397186492558,1.5894358933782868
0.00010023160002374312,0.0038943999999999997,266.60119008613,116.71397186492558,1.5894358933782868
0.00010056103831470037,0.0039071999999999996,266.66223897509747,116.71397186492558,1.5894358933782868
0.00010066398778062453,0.0039112,266.6813007506056,116.71397186492558,1.5894358933782868
0.00010076693724654866,0.0039152,266.7003549247518,116.71397186492558,1.5894358933782868
0.00010117873511024523,0.0039312,266.7764958231759,116.71397186492558,1.5894358933782868
0.0001015287632943873,0.0039448,266.84112061004754,116.71397186492558,1.5894358933782868
0.00010177584201260522,0.003954399999999999,266.8866858018269,116.71397186492558,1.5894358933782868
0.00010262002763318318,0.0039872,267.0420424039338,116.71397186492558,1.5894358933782868
0.00010274356699229215,0.003992,267.06473563990636,116.71397186492558,1.5894358933782868
0.00012222546114418355,0.004748949789957992,270.52073449108593,116.71397186492558,1.5894358933782868
0.0001365588934872925,0.0053058611722344474,272.9273133762059,116.71397186492558,1.5894358933782868
0.0001439727378026937,0.005593918783756751,274.1332741369789,116.71397186492558,1.5894358933782868
0.0001558348887073356,0.0060548109621924385,276.01359290595514,116.71397186492558,1.5894358933782868
0.0001672027833242841,0.006496499299859972,277.76382295199573,116.71397186492558,1.5894358933782868
0.0001746166276396853,0.006784556911382277,278.8803170250965,116.71397186492558,1.5894358933782868
0.0001869730348320206,0.007264652930586117,280.70089392906124,116.71397186492558,1.5894358933782868
0.00019389262285972837,0.007533506701340268,281.69989833493617,116.71397186492558,1.5894358933782868
0.0001988351857366625,0.007725545109021804,282.40497751749245,116.71397186492558,1.5894358933782868
0.00020328349232590323,0.007898379675935187,283.03372546097245,116.71397186492558,1.5894358933782868
0.00020526051747667688,0.007975195039007801,283.31144419833174,116.71397186492558,1.5894358933782868
0.0002097088240659176,0.008148029605921184,283.9325251305721,116.71397186492558,1.5894358933782868
0.00021959394981978586,0.008532106421284257,285.2945981336521,116.71397186492558,1.5894358933782868
0.00022700779413518704,0.008820164032806561,286.30051139571987,116.71397186492558,1.5894358933782868
0.0002512263522321643,0.00976115223044609,289.50061764878916,116.71397186492558,1.5894358933782868
0.0002591344528352589,0.010068413682736548,290.5191730929836,116.71397186492558,1.5894358933782868
0.0002650655282875798,0.01029885977195439,291.2751523189295,116.71397186492558,1.5894358933782868
0.00026852532230143373,0.010433286657331467,291.7130935612554,116.71397186492558,1.5894358933782868
0.000280881729493769,0.010913382676535306,293.2595173885399,116.71397186492558,1.5894358933782868
0.00028631854865839663,0.011124624924984998,293.9315131023634,116.71397186492558,1.5894358933782868
0.00028928408638455706,0.01123984796959392,294.2959579649342,116.71397186492558,1.5894358933782868
0.0003135026444815343,0.012180836167233446,297.2195922288628,116.71397186492558,1.5894358933782868
0.00032487053909848276,0.01262252450490098,298.5613947233782,116.71397186492558,1.5894358933782868
0.00033129587083849713,0.012872174434886977,299.31170186348317,116.71397186492558,1.5894358933782868
0.00034562930318160614,0.013429085817163433,300.9653083080268,116.71397186492558,1.5894358933782868
0.00035403166007239414,0.013755551110222045,301.92222872730565,116.71397186492558,1.5894358933782868
0.0003644110421139558,0.014158831766353271,303.09216437400454,116.71397186492558,1.5894358933782868
0.0003663880672647295,0.014235647129425886,303.313528110618,116.71397186492558,1.5894358933782868
0.0003713306301416636,0.014427685537107422,303.8649090833001,116.71397186492558,1.5894358933782868
0.00039258365051248037,0.015253450690138028,306.2039555660662,116.71397186492558,1.5894358933782868
0.00039703195710172107,0.015426285257051411,306.68721355761244,116.71397186492558,1.5894358933782868
0.00040444580141712225,0.015714342868573716,307.4879772319519,116.71397186492558,1.5894358933782868
0.0004093883642940564,0.015906381276255252,308.01864151930465,116.71397186492558,1.5894358933782868
0.0004266873343633258,0.016578515703140628,309.8566033292982,116.71397186492558,1.5894358933782868
0.0004291586158017929,0.016674534906981398,310.1167770751572,116.71397186492558,1.5894358933782868
0.0004523886613233833,0.017577115423084617,312.53450121590765,116.71397186492558,1.5894358933782868
0.000471170400255733,0.018306861372274455,314.45403617544247,116.71397186492558,1.5894358933782868
0.0004953889583527102,0.01924784956991398,316.88573069519987,116.71397186492558,1.5894358933782868
0.0005097223906958192,0.01980476095219044,318.3030570782483,116.71397186492558,1.5894358933782868
0.0005235615667512348,0.02034246849369874,319.6568330919011,116.71397186492558,1.5894358933782868
0.000533446692505103,0.020726545309061813,320.61528490060437,116.71397186492558,1.5894358933782868
0.0005477801248482119,0.021283456691338267,321.99282662108203,116.71397186492558,1.5894358933782868
0.0005502514062866791,0.021379475895179037,322.22890588851055,116.71397186492558,1.5894358933782868
0.0005537112003005329,0.02151390278055611,322.5587233509663,116.71397186492558,1.5894358933782868
0.0005724929392328826,0.02224364872974595,324.3353298912462,116.71397186492558,1.5894358933782868
0.000575458476959043,0.02235887177435487,324.61375523613935,116.71397186492558,1.5894358933782868
0.0005769412458221234,0.022416483296659333,324.75275802550556,116.71397186492558,1.5894358933782868
0.0005818838086990574,0.02260852170434087,325.21509770146093,116.71397186492558,1.5894358933782868
0.0005907804218775389,0.022954190838167635,326.04346787148233,116.71397186492558,1.5894358933782868
0.00059819426619294,0.023242248449689938,326.73006643334725,116.71397186492558,1.5894358933782868
0.0006145047236868227,0.023875975195039006,328.2290082809839,116.71397186492558,1.5894358933782868
0.0006154932362622095,0.023914382876575314,328.3193513273157,116.71397186492558,1.5894358933782868
0.0006550337392776825,0.025450690138027605,331.8879828650916,116.71397186492558,1.5894358933782868
0.0006654131213192443,0.025853970794158833,332.81069871217767,116.71397186492558,1.5894358933782868
0.0006708499404838717,0.02606521304260852,333.2917849032345,116.71397186492558,1.5894358933782868
0.0006960570111562358,0.02704460892178436,335.5027034985437,116.71397186492558,1.5894358933782868
0.0007148387500885855,0.027774354870974197,337.12980614126707,116.71397186492558,1.5894358933782868
0.0007217583381162933,0.028043208641728348,337.72505109917364,116.71397186492558,1.5894358933782868
0.0007271951572809207,0.028254450890178036,338.19118364362294,116.71397186492558,1.5894358933782868
0.0007306549512947747,0.028388877775555113,338.48710592235506,116.71397186492558,1.5894358933782868
0.0007410343333363364,0.028792158431686338,339.37161109883357,116.71397186492558,1.5894358933782868
0.0007499309465148178,0.029137827565513103,340.12591957464184,116.71397186492558,1.5894358933782868
0.0007617930974194597,0.02959871974394879,341.1262576442876,116.71397186492558,1.5894358933782868
0.0007795863237764225,0.03029005801160232,342.61544872032044,116.71397186492558,1.5894358933782868
0.0007874944243795172,0.03059731946389278,343.27305017888875,116.71397186492558,1.5894358933782868
0.0008028163692980129,0.03119263852770554,344.5398697843177,116.71397186492558,1.5894358933782868
0.0008146785202026548,0.03165353070614123,345.5141682904082,116.71397186492558,1.5894358933782868
0.0008201153393672824,0.03186477295459092,345.95887120133017,116.71397186492558,1.5894358933782868
0.0008275291836826835,0.03215283056611322,346.5634357869352,116.71397186492558,1.5894358933782868
0.0008408741034504057,0.03267133426685337,347.6463555822138,116.71397186492558,1.5894358933782868
0.0008502649729165806,0.03303620724144829,348.4043958851879,116.71397186492558,1.5894358933782868
0.0008571845609442884,0.033305061012202444,348.9608641869871,116.71397186492558,1.5894358933782868
0.0008641041489719962,0.03357391478295659,349.5155833144077,116.71397186492558,1.5894358933782868
0.0008685524555612368,0.03374674934986997,349.87127385537065,116.71397186492558,1.5894358933782868
0.0008799203501781853,0.03418843768753751,350.77704806959844,116.71397186492558,1.5894358933782868
0.0008912882447951339,0.034630126025205044,351.6782698671936,116.71397186492558,1.5894358933782868
0.0008996906016859219,0.034956591318263654,352.3415117282912,116.71397186492558,1.5894358933782868
0.0009125412651659507,0.03545589117823565,353.3512280481922,116.71397186492558,1.5894358933782868
0.0009204493657690453,0.03576315263052611,353.9698362013812,116.71397186492558,1.5894358933782868
0.000923909159782899,0.03589757951590318,354.239825104682,116.71397186492558,1.5894358933782868
0.0009308287478106069,0.036166433286657335,354.77862290031726,116.71397186492558,1.5894358933782868
0.0009392311047013947,0.03649289857971594,355.4307818944928,116.71397186492558,1.5894358933782868
0.000943185155002942,0.03664652930586117,355.7368925679481,116.71397186492558,1.5894358933782868
0.0009486219741675696,0.03685777155431086,356.1569788085082,116.71397186492558,1.5894358933782868
0.0009723462759768535,0.03777955591118223,357.9792028491299,116.71397186492558,1.5894358933782868
0.0009891509897584294,0.03843248649729945,359.25946826412616,116.71397186492558,1.5894358933782868
0.0009911280149092032,0.038509301860372075,359.40952799502736,116.71397186492558,1.5894358933782868
0.0010059557035400058,0.03908541708341669,360.5312785533263,116.71397186492558,1.5894358933782868
0.0010128752915677132,0.03935427085417083,361.05255359658844,116.71397186492558,1.5894358933782868
0.001017323598156954,0.039527105421084216,361.3869257264509,116.71397186492558,1.5894358933782868
0.0010247374424723552,0.039815163032606515,361.9429482670549,116.71397186492558,1.5894358933782868
0.0010277029801985158,0.03993038607721544,362.16491773259844,116.71397186492558,1.5894358933782868
0.00103412831193853,0.040180036007201436,362.64499643095627,116.71397186492558,1.5894358933782868
0.0010415421562539314,0.04046809361872375,363.19749022408166,116.71397186492558,1.5894358933782868
0.001055381332309347,0.041005801160232044,364.22472557059535,116.71397186492558,1.5894358933782868
0.0010657607143509085,0.04140908181636327,364.9917080670408,116.71397186492558,1.5894358933782868
0.0010682319957893754,0.041505101020204035,365.1738929071946,116.71397186492558,1.5894358933782868
0.0010835539407078715,0.04210042008401681,366.2997920029843,116.71397186492558,1.5894358933782868
0.0010875079910094188,0.042254050810162036,366.58933654086144,116.71397186492558,1.5894358933782868
0.0011122208053940894,0.043214242848569714,368.38977555243315,116.71397186492558,1.5894358933782868
0.0011196346497094904,0.043502300460092014,368.9268560086971,116.71397186492558,1.5894358933782868
0.0011443474640941613,0.044462492498499706,370.7071906217494,116.71397186492558,1.5894358933782868
0.001164117715601898,0.04523064612922585,372.12068535186904,116.71397186492558,1.5894358933782868
0.001170543047341912,0.04548029605921185,372.57805126680813,116.71397186492558,1.5894358933782868
0.0011725200724926857,0.045557111422284455,372.71858212101586,116.71397186492558,1.5894358933782868
0.0011853707359727142,0.046056411282256446,373.62979048364974,116.71397186492558,1.5894358933782868
0.0011922903240004221,0.0463252650530106,374.11884504246996,116.71397186492558,1.5894358933782868
0.0011977271431650497,0.04653650730146029,374.5023260778007,116.71397186492558,1.5894358933782868
0.001209095037781998,0.04697819563912782,375.3019632443054,116.71397186492558,1.5894358933782868
0.001213543344371239,0.04715103020604121,375.6140659347732,116.71397186492558,1.5894358933782868
0.0012249112389881873,0.04759271854370874,376.4096414143874,116.71397186492558,1.5894358933782868
0.0012367733898928292,0.048053610722144424,377.2367431528775,116.71397186492558,1.5894358933782868
0.0012520953348113253,0.048648929785957196,378.3005182686932,116.71397186492558,1.5894358933782868
0.0012600034354144198,0.048956191238247654,378.8475763985599,116.71397186492558,1.5894358933782868
0.001274831124045222,0.04953230646129225,379.8697147130887,116.71397186492558,1.5894358933782868
0.0012812564557852367,0.04978195639127826,380.3112002572442,116.71397186492558,1.5894358933782868
0.0012881760438129442,0.0500508101620324,380.785681697634,116.71397186492558,1.5894358933782868
0.0012936128629775718,0.050262052410482094,381.15779157359066,116.71397186492558,1.5894358933782868
0.00130201521986836,0.05058851770354071,381.7316730325594,116.71397186492558,1.5894358933782868
0.0013104175767591477,0.050914982996599314,382.3041119475601,116.71397186492558,1.5894358933782868
0.0013183256773622424,0.05122224444888977,382.8415717315339,116.71397186492558,1.5894358933782868
0.001326233777965337,0.05152950590118023,383.37777561493874,116.71397186492558,1.5894358933782868
0.001332164853417658,0.05175995199039808,383.77911060295605,116.71397186492558,1.5894358933782868
0.0013400729540207527,0.05206721344268854,384.31314159035765,116.71397186492558,1.5894358933782868
0.001351440848637701,0.05250890178035607,385.07866289165065,116.71397186492558,1.5894358933782868
0.0013771421755977588,0.053507501500300064,386.8002093606629,116.71397186492558,1.5894358933782868
0.0013914756079408677,0.05406441288257652,387.7548587524888,116.71397186492558,1.5894358933782868
0.0013998779648316554,0.05439087817563512,388.31269779574285,116.71397186492558,1.5894358933782868
0.0014132228845993777,0.05490938187637527,389.19600099151444,116.71397186492558,1.5894358933782868
0.0014364529301209683,0.0558119623924785,390.7258820219147,116.71397186492558,1.5894358933782868
0.0014423840055732891,0.05604240848169634,391.1149398688612,116.71397186492558,1.5894358933782868
0.0014601772319302521,0.056733746749349875,392.2783870053135,116.71397186492558,1.5894358933782868
0.001467591076245653,0.057021804360872175,392.76152324831554,116.71397186492558,1.5894358933782868
0.0014799474834379885,0.05750190038007602,393.564640430281,116.71397186492558,1.5894358933782868
0.0014893383529041636,0.05786677335467094,394.1732617102748,116.71397186492558,1.5894358933782868
0.001496257940931871,0.05813562712542508,394.62076223236886,116.71397186492558,1.5894358933782868
0.0015016947600964986,0.058346869373874774,394.97180382282784,116.71397186492558,1.5894358933782868
0.0015041660415349657,0.05844288857771554,395.1312042921522,116.71397186492558,1.5894358933782868
0.001514051167288834,0.05882696539307862,395.76778745449485,116.71397186492558,1.5894358933782868
0.0015194879864534616,0.05903820764152831,396.1172172126193,116.71397186492558,1.5894358933782868
0.0015278903433442494,0.059364672934586915,396.65628745131994,116.71397186492558,1.5894358933782868
0.0015412352631119716,0.059883176635327065,397.5100875680055,116.71397186492558,1.5894358933782868
0.0015530974140166136,0.06034406881376275,398.26660355333075,116.71397186492558,1.5894358933782868
0.0015624882834827884,0.06070894178835767,398.86391508060814,116.71397186492558,1.5894358933782868
0.0015694078715104962,0.06097779555911183,399.303143853011,116.71397186492558,1.5894358933782868
0.0015738561780997368,0.0611506301260252,399.58510643105006,116.71397186492558,1.5894358933782868
0.0016025230427859551,0.06226445289057812,401.39479980745546,116.71397186492558,1.5894358933782868
0.0016138909374029033,0.06270614122824565,402.1089354205699,116.71397186492558,1.5894358933782868
0.0016213047817183045,0.06299419883976795,402.5736193672288,116.71397186492558,1.5894358933782868
0.0016257530883075453,0.06316703340668134,402.85203197237047,116.71397186492558,1.5894358933782868
0.0016277301134583187,0.06324384876975395,402.97567552817924,116.71397186492558,1.5894358933782868
0.0016366267266368004,0.06358951790358072,403.5313483351752,116.71397186492558,1.5894358933782868
0.0016608452847337776,0.06453050610122024,405.038076765242,116.71397186492558,1.5894358933782868
0.0016677648727614854,0.0647993598719744,405.46699359089274,116.71397186492558,1.5894358933782868
0.0016895121494199953,0.06564432886577315,406.8105216648488,116.71397186492558,1.5894358933782868
0.0016993972751738638,0.06602840568113623,407.418984934356,116.71397186492558,1.5894358933782868
0.0017087881446400386,0.06639327865573115,407.99574776893166,116.71397186492558,1.5894358933782868
0.0017191675266816002,0.06679655931186237,408.63178618855073,116.71397186492558,1.5894358933782868
0.0017226273206954544,0.06693098619723946,408.8434659608478,116.71397186492558,1.5894358933782868
0.0017265813709970018,0.06708461692338469,409.0851827779032,116.71397186492558,1.5894358933782868
0.0017325124464493225,0.06731506301260252,409.44735360975955,116.71397186492558,1.5894358933782868
0.0017438803410662709,0.06775675135027005,410.1401656556869,116.71397186492558,1.5894358933782868
0.0017557424919709128,0.06821764352870574,410.8612247033383,116.71397186492558,1.5894358933782868
0.001764144848861701,0.06854410882176436,411.3708257947563,116.71397186492558,1.5894358933782868
0.0017839151003694374,0.0693122624524905,412.5661677462663,116.71397186492558,1.5894358933782868
0.0017957772512740794,0.06977315463092619,413.2808932350569,116.71397186492558,1.5894358933782868
0.0018041796081648676,0.07009961992398481,413.7860435310408,116.71397186492558,1.5894358933782868
0.0018130762213433489,0.07044528905781157,414.3199095356878,116.71397186492558,1.5894358933782868
0.0018234556033849105,0.0708485697139428,414.94146366137534,116.71397186492558,1.5894358933782868
0.0018318579602756987,0.07117503500700141,415.44361652322203,116.71397186492558,1.5894358933782868
0.001838283292015713,0.0714246849369874,415.8270099042955,116.71397186492558,1.5894358933782868
0.0018476741614818879,0.07178955791158233,416.38641530372973,116.71397186492558,1.5894358933782868
0.0018521224680711284,0.0719623924784957,416.6510096900961,116.71397186492558,1.5894358933782868
0.0018570650309480624,0.07215443088617723,416.94471294858045,116.71397186492558,1.5894358933782868
0.0018600305686742229,0.07226965393078616,417.1207885751774,116.71397186492558,1.5894358933782868
0.0018664559004142372,0.07251930386077216,417.50191061764684,116.71397186492558,1.5894358933782868
0.0018753525135927185,0.07286497299459892,418.02877440048417,116.71397186492558,1.5894358933782868
0.001899571071689696,0.07380596119223845,419.4580992135227,116.71397186492558,1.5894358933782868
0.0019064906597174038,0.0740748149629926,419.86517007354274,116.71397186492558,1.5894358933782868
0.0019173642980466591,0.07449729945989199,420.5036906104729,116.71397186492558,1.5894358933782868
0.001927249423800527,0.07488137627525505,421.0829393798032,116.71397186492558,1.5894358933782868
0.0019297207052389942,0.07497739547909582,421.2275703818972,116.71397186492558,1.5894358933782868
0.0019425713687190227,0.07547669533906781,421.97849032838934,116.71397186492558,1.5894358933782868
0.001962341620226759,0.07624484896979396,423.12997984529926,116.71397186492558,1.5894358933782868
0.001968766951966774,0.07649449889977997,423.5032386098911,116.71397186492558,1.5894358933782868
0.0019756865399944814,0.07676335267053411,423.9046786720004,116.71397186492558,1.5894358933782868
0.0019796405902960286,0.07691698339667934,424.1338267976676,116.71397186492558,1.5894358933782868
0.0019875486908991235,0.0772242448489698,424.59158825309765,116.71397186492558,1.5894358933782868
0.0020008936106668458,0.07774274854970994,425.3624532632232,116.71397186492558,1.5894358933782868
0.0020078131986945537,0.0780116023204641,425.7613715087013,116.71397186492558,1.5894358933782868
0.002016215555585341,0.0783380676135227,426.2450521384726,116.71397186492558,1.5894358933782868
0.0020280777064899834,0.07879895979195839,426.9265592184764,116.71397186492558,1.5894358933782868
0.0020295604753530635,0.07885657131426285,427.0116381619223,116.71397186492558,1.5894358933782868
0.0020602043651900552,0.08004720944188838,428.76454551697435,116.71397186492558,1.5894358933782868
0.002062181390340829,0.080124024804961,428.87728588738366,116.71397186492558,1.5894358933782868
0.002070583747231617,0.0804504900980196,429.35596295618586,116.71397186492558,1.5894358933782868
0.0020775033352593247,0.08071934386877376,429.7495990374952,116.71397186492558,1.5894358933782868
0.0020819516418485655,0.08089217843568715,430.00238081869696,116.71397186492558,1.5894358933782868
0.0020972735867670613,0.0814874974994999,430.8714658911506,116.71397186492558,1.5894358933782868
0.0021081472250963165,0.08190998199639929,431.48673438424953,116.71397186492558,1.5894358933782868
0.0021111127628224767,0.0820252050410082,431.6543199230568,116.71397186492558,1.5894358933782868
0.002121986401151732,0.08244768953790758,432.26801631428316,116.71397186492558,1.5894358933782868
0.0021249519388778925,0.08256291258251651,432.43517504665135,116.71397186492558,1.5894358933782868
0.00213038875804252,0.0827741548309662,432.7413966175485,116.71397186492558,1.5894358933782868
0.002140273883796388,0.08315823164632927,433.29738340926576,116.71397186492558,1.5894358933782868
0.002155595828714884,0.08375355071014204,434.157187853689,116.71397186492558,1.5894358933782868
0.0021625154167425917,0.08402240448089618,434.5447050383369,116.71397186492558,1.5894358933782868
0.0021738833113595403,0.08446409281856372,435.18029222988827,116.71397186492558,1.5894358933782868
0.0021862397185518755,0.08494418883776755,435.8696794622701,116.71397186492558,1.5894358933782868
0.0021926650502918895,0.08519383876775355,436.2275601917289,116.71397186492558,1.5894358933782868
0.002196619100593437,0.08534746949389878,436.44759120528255,116.71397186492558,1.5894358933782868
0.0021985961257442108,0.0854242848569714,436.55754878305993,116.71397186492558,1.5894358933782868
0.002221826171265801,0.08632686537307462,437.8466751672886,116.71397186492558,1.5894358933782868
0.0022272629904304285,0.08653810762152431,438.1476252266844,116.71397186492558,1.5894358933782868
0.0022292400155812025,0.08661492298459693,438.25699056022836,116.71397186492558,1.5894358933782868
0.0022406079101981507,0.08705661132226446,438.8851087067011,116.71397186492558,1.5894358933782868
0.0022668034934459017,0.0880744148829766,440.32779866687673,116.71397186492558,1.5894358933782868
0.0022771828754874633,0.08847769553910782,440.8976302072816,116.71397186492558,1.5894358933782868
0.002279159900638237,0.08855451090218044,441.00605460772715,116.71397186492558,1.5894358933782868
0.002311286559338309,0.08980276055211042,442.7628422972973,116.71397186492558,1.5894358933782868
0.0023157348659275496,0.08997559511902381,443.00533706866685,116.71397186492558,1.5894358933782868
0.002319688916229097,0.09012922584516904,443.22073550903923,116.71397186492558,1.5894358933782868
0.0023251257353937246,0.09034046809361873,443.51667470509494,116.71397186492558,1.5894358933782868
0.002341436192887607,0.09097419483896779,444.40287726126036,116.71397186492558,1.5894358933782868
0.002349838549778395,0.09130066013202641,444.8584660528196,116.71397186492558,1.5894358933782868
0.0023602179318199567,0.09170394078815763,445.4203760031069,116.71397186492558,1.5894358933782868
0.002370103057573825,0.09208801760352071,445.95463303931996,116.71397186492558,1.5894358933782868
0.002384436489916934,0.09264492898579717,446.72776473065267,116.71397186492558,1.5894358933782868
0.0023948158719584956,0.09304820964192839,447.28648768782404,116.71397186492558,1.5894358933782868
0.0024017354599862035,0.09331706341268255,447.65844507806327,116.71397186492558,1.5894358933782868
0.002411126329452378,0.09368193638727745,448.16257659637233,116.71397186492558,1.5894358933782868
0.0024185401737677795,0.09396999399879977,448.5600344546465,116.71397186492558,1.5894358933782868
0.0024294138120970346,0.09439247849569915,449.14211420312125,116.71397186492558,1.5894358933782868
0.002434850631261662,0.09460372074414883,449.43277299049436,116.71397186492558,1.5894358933782868
0.002441275963001677,0.09485337067413484,449.77595270095964,116.71397186492558,1.5894358933782868
0.0024467127821663037,0.09506461292258452,450.0660604831736,116.71397186492558,1.5894358933782868
0.002468954315112508,0.09592878575715144,451.25025645249326,116.71397186492558,1.5894358933782868
0.002484770516318697,0.09654330866173236,452.0898215346763,116.71397186492558,1.5894358933782868
0.002493172873209485,0.09686977395479096,452.53499264586577,116.71397186492558,1.5894358933782868
0.002494655642072565,0.09692738547709542,452.613491477004,116.71397186492558,1.5894358933782868
0.0025045407678264335,0.0973114622924585,453.136352771042,116.71397186492558,1.5894358933782868
0.0025287593259234104,0.09825245049009802,454.4139730872607,116.71397186492558,1.5894358933782868
0.002537655939101892,0.09859811962392478,454.8821033773033,116.71397186492558,1.5894358933782868
0.002539138707964972,0.09865573114622925,454.9600628220995,116.71397186492558,1.5894358933782868
0.002543587014554213,0.09882856571314264,455.1938346962656,116.71397186492558,1.5894358933782868
0.002554460652883468,0.09925105021004202,455.76460683253777,116.71397186492558,1.5894358933782868
0.002565334291212723,0.09967353470694139,456.3344321995215,116.71397186492558,1.5894358933782868
0.0025707711103773504,0.09988477695539108,456.61899158847524,116.71397186492558,1.5894358933782868