File: datasets/aisi_316_L/data/M1/train_3.csv
Time(s),Strain(%),Stress(MPa),Temp(C),Log_SR(s-1)
0.0,0.0,0.0,162.1898112009249,-0.5813394189452818
7.932366174072978e-05,2.0799999999999997e-05,3.9282213749999997,162.1898112009249,-0.5813394189452818
0.00012813822281194812,3.36e-05,6.345588374999999,162.1898112009249,-0.5813394189452818
0.00018000369395011762,4.7199999999999995e-05,8.9140408125,162.1898112009249,-0.5813394189452818
0.0003111928268290169,8.159999999999999e-05,15.410714624999999,162.1898112009249,-0.5813394189452818
0.0003325491972976749,8.719999999999999e-05,16.4683126875,162.1898112009249,-0.5813394189452818
0.00040272012883755127,0.00010559999999999999,19.94327775,162.1898112009249,-0.5813394189452818
0.000543061991917304,0.0001424,26.893207874999998,162.1898112009249,-0.5813394189452818
0.0005888256429215712,0.00015439999999999999,29.159489437499996,162.1898112009249,-0.5813394189452818
0.0006650983945953498,0.00017439999999999998,32.936625375,162.1898112009249,-0.5813394189452818
0.0007108620455996171,0.0001864,35.2029069375,162.1898112009249,-0.5813394189452818
0.0007840838872064445,0.00020559999999999998,38.828957437499994,162.1898112009249,-0.5813394189452818
0.0008664584590141255,0.0002272,42.90826425,162.1898112009249,-0.5813394189452818
0.0009488330308218064,0.0002488,46.987571062499995,162.1898112009249,-0.5813394189452818
0.0010403603328303407,0.00027279999999999996,51.52013418749999,162.1898112009249,-0.5813394189452818
0.0010617167032989988,0.0002784,52.57773225,162.1898112009249,-0.5813394189452818
0.0010830730737676568,0.00028399999999999996,53.635330312499995,162.1898112009249,-0.5813394189452818
0.0011868040160439958,0.0003112,58.772235187499994,162.1898112009249,-0.5813394189452818
0.001253924037516921,0.00032879999999999997,62.09611481249999,162.1898112009249,-0.5813394189452818
0.0012813822281194814,0.000336,63.45588375,162.1898112009249,-0.5813394189452818
0.001296636778454237,0.00033999999999999997,64.21131093749999,162.1898112009249,-0.5813394189452818
0.0013149422388559439,0.0003448,65.11782356249999,162.1898112009249,-0.5813394189452818
0.0013271458791237487,0.000348,65.7221653125,162.1898112009249,-0.5813394189452818
0.0013973168106636248,0.00036639999999999996,69.19713037499999,162.1898112009249,-0.5813394189452818
0.0014247750012661852,0.0003736,70.5568993125,162.1898112009249,-0.5813394189452818
0.0014522331918687455,0.0003808,71.91666825,162.1898112009249,-0.5813394189452818
0.001546811403944231,0.0004056,76.6003168125,162.1898112009249,-0.5813394189452818
0.0016352877958858143,0.00042879999999999996,80.98179449999999,162.1898112009249,-0.5813394189452818
0.001732916918028251,0.0004544,85.8165285,162.1898112009249,-0.5813394189452818
0.0017603751086308114,0.0004616,87.1762974375,162.1898112009249,-0.5813394189452818
0.0017725787488986158,0.00046479999999999997,87.7806391875,162.1898112009249,-0.5813394189452818
0.001815291489835932,0.00047599999999999997,89.8958353125,162.1898112009249,-0.5813394189452818
0.0018763096911749546,0.0004919999999999999,92.91754406249999,162.1898112009249,-0.5813394189452818
0.0019251242522461732,0.0005048,95.3349110625,162.1898112009249,-0.5813394189452818
0.0019708879032504403,0.0005168,97.601192625,162.1898112009249,-0.5813394189452818
0.002025804284455561,0.0005312,100.3207305,162.1898112009249,-0.5813394189452818
0.00205021156499117,0.0005376,101.52941399999999,162.1898112009249,-0.5813394189452818
0.0021081788562632418,0.0005528,104.4000373125,162.1898112009249,-0.5813394189452818
0.002169197057602265,0.0005688,107.42174606249999,162.1898112009249,-0.5813394189452818
0.0022820807300794575,0.0005984,113.01190725000001,162.1898112009249,-0.5813394189452818
0.0023095389206820175,0.0006056,114.3716761875,162.1898112009249,-0.5813394189452818
0.0023492007515523825,0.000616,116.335786875,162.1898112009249,-0.5813394189452818
0.002404117132757503,0.0006303999999999999,119.05532474999998,162.1898112009249,-0.5813394189452818
0.0024407280535609166,0.0006399999999999999,120.86834999999999,162.1898112009249,-0.5813394189452818
0.0025627644562389628,0.000672,126.9117675,162.1898112009249,-0.5813394189452818
0.002675648128716155,0.0007015999999999999,132.5019286875,162.1898112009249,-0.5813394189452818
0.0027092081394526177,0.0007103999999999999,134.16386849999998,162.1898112009249,-0.5813394189452818
0.002761073610590787,0.0007239999999999999,136.7323209375,162.1898112009249,-0.5813394189452818
0.0028068372615950546,0.000736,138.9986025,162.1898112009249,-0.5813394189452818
0.0028983645636035888,0.0007599999999999999,143.531165625,162.1898112009249,-0.5813394189452818
0.002947179124674807,0.0007727999999999999,145.94853262499998,162.1898112009249,-0.5813394189452818
0.0029532809448087095,0.0007744,146.2507035,162.1898112009249,-0.5813394189452818
0.0029990445958129764,0.0007863999999999999,148.5169850625,162.1898112009249,-0.5813394189452818
0.003050910066951146,0.0007999999999999999,151.08543749999998,162.1898112009249,-0.5813394189452818
0.0030783682575537064,0.0008072,152.4452064375,162.1898112009249,-0.5813394189452818
0.003136335548825778,0.0008223999999999999,155.31582974999998,162.1898112009249,-0.5813394189452818
0.0031790482897630945,0.0008336,157.431025875,162.1898112009249,-0.5813394189452818
0.0032126083004995567,0.0008424,159.0929656875,162.1898112009249,-0.5813394189452818
0.003279728321972482,0.00086,162.4168453125,162.1898112009249,-0.5813394189452818
0.0033193901528428466,0.0008703999999999999,164.38095599999997,162.1898112009249,-0.5813394189452818
0.0033285428830437005,0.0008728,164.8342123125,162.1898112009249,-0.5813394189452818
0.0033804083541818697,0.0008864,167.40266474999999,162.1898112009249,-0.5813394189452818
0.0034109174548513812,0.0008944,168.913519125,162.1898112009249,-0.5813394189452818
0.003465833836056502,0.0009088,171.633057,162.1898112009249,-0.5813394189452818
0.0034780374763243066,0.0009119999999999999,172.23739874999998,162.1898112009249,-0.5813394189452818
0.0036092266092032058,0.0009463999999999999,178.7340725625,162.1898112009249,-0.5813394189452818
0.0037312630118812515,0.0009784,184.7774900625,162.1898112009249,-0.5813394189452818
0.003798383033354177,0.000996,188.10136968749998,162.1898112009249,-0.5813394189452818
0.0038136375836889326,0.001,188.85679687500001,162.1898112009249,-0.5813394189452818
0.003917368525965272,0.0010272,193.99370175,162.1898112009249,-0.5813394189452818
0.003941775806500881,0.0010336,195.20238525,162.1898112009249,-0.5813394189452818
0.003981437637371246,0.001044,197.1664959375,162.1898112009249,-0.5813394189452818
0.004021099468241611,0.0010544,199.130606625,162.1898112009249,-0.5813394189452818
0.0040577103890450245,0.001064,200.94363187500002,162.1898112009249,-0.5813394189452818
0.004082117669580634,0.0010704,202.152315375,162.1898112009249,-0.5813394189452818
0.004133983140718803,0.001084,204.7207678125,162.1898112009249,-0.5813394189452818
0.004188899521923924,0.0010984,207.4403056875,162.1898112009249,-0.5813394189452818
0.004204154072258679,0.0011024,208.19573287499998,162.1898112009249,-0.5813394189452818
0.0042346631729281905,0.0011103999999999999,209.70658724999998,162.1898112009249,-0.5813394189452818
0.004292630464200263,0.0011256,212.5772105625,162.1898112009249,-0.5813394189452818
0.004484837798418185,0.001176,220.8763771844924,162.1898112009249,-0.5813394189452818
0.00455195781989111,0.0011936,220.99403386010047,162.1898112009249,-0.5813394189452818
0.004597721470895377,0.0012056,221.07386665204845,162.1898112009249,-0.5813394189452818
0.004640434211832693,0.0012167999999999999,221.14809810884674,162.1898112009249,-0.5813394189452818
0.004683146952770009,0.001228,221.22206356697941,162.1898112009249,-0.5813394189452818
0.004731961513841228,0.0012408,221.30627412143187,162.1898112009249,-0.5813394189452818
0.0048173869957158595,0.0012632,221.45283186797406,162.1898112009249,-0.5813394189452818
0.004902812477590492,0.0012856,221.59837948858444,162.1898112009249,-0.5813394189452818
0.004963830678929515,0.0013016,221.7017371773194,162.1898112009249,-0.5813394189452818
0.004982136139331221,0.0013063999999999999,221.73264770493233,162.1898112009249,-0.5813394189452818
0.005040103430603293,0.0013216,221.83024010904546,162.1898112009249,-0.5813394189452818
0.005076714351406706,0.0013311999999999998,221.89165193284944,162.1898112009249,-0.5813394189452818
0.005131630732611828,0.0013456,221.9834468056173,162.1898112009249,-0.5813394189452818
0.005162139833281339,0.0013536,222.03427839192642,162.1898112009249,-0.5813394189452818
0.005247565315155971,0.0013759999999999998,222.17598726812713,162.1898112009249,-0.5813394189452818
0.005271972595691581,0.0013824,222.21630989961506,162.1898112009249,-0.5813394189452818
0.005314685336628896,0.0013935999999999998,222.2866997558301,162.1898112009249,-0.5813394189452818
0.005329939886963652,0.0013976,222.31178547786294,162.1898112009249,-0.5813394189452818
0.005384856268168772,0.0014119999999999998,222.40186315469217,162.1898112009249,-0.5813394189452818
0.005412314458771333,0.0014192,222.44676759034087,162.1898112009249,-0.5813394189452818
0.0054611290198425515,0.001432,222.52637893716067,162.1898112009249,-0.5813394189452818
0.005574012692319744,0.0014616,222.70942475496147,162.1898112009249,-0.5813394189452818
0.005610623613123158,0.0014712,222.76847973209348,162.1898112009249,-0.5813394189452818
0.005692998184930838,0.0014927999999999999,222.90080669473855,162.1898112009249,-0.5813394189452818
0.005720456375533399,0.0015,222.94474946466968,162.1898112009249,-0.5813394189452818
0.005747914566135959,0.0015072,222.9886100503069,162.1898112009249,-0.5813394189452818
0.005799780037274128,0.0015207999999999999,223.0712355153934,162.1898112009249,-0.5813394189452818
0.005921816439952174,0.0015528,223.26451990179703,162.1898112009249,-0.5813394189452818
0.0059889364614251,0.0015704,223.37016394161404,162.1898112009249,-0.5813394189452818
0.006056056482898025,0.001588,223.4753472221892,162.1898112009249,-0.5813394189452818
0.006107921954036194,0.0016016,223.55631412033205,162.1898112009249,-0.5813394189452818
0.006171991065442168,0.0016183999999999999,223.65596280411634,162.1898112009249,-0.5813394189452818
0.006184194705709974,0.0016216,223.6748976802915,162.1898112009249,-0.5813394189452818
0.006193347435910827,0.001624,223.68908927572454,162.1898112009249,-0.5813394189452818
0.006242161996982045,0.0016367999999999999,223.76464009144055,162.1898112009249,-0.5813394189452818
0.006306231108388019,0.0016535999999999999,223.8634517797516,162.1898112009249,-0.5813394189452818
0.006428267511066065,0.0016856,224.05058808056057,162.1898112009249,-0.5813394189452818
0.00647098025200338,0.0016967999999999998,224.11575778075533,162.1898112009249,-0.5813394189452818
0.006596067564748378,0.0017296,224.3056536870024,162.1898112009249,-0.5813394189452818
0.006678442136556059,0.0017511999999999998,224.4299406086589,162.1898112009249,-0.5813394189452818
0.0067059003271586195,0.0017584,224.47123653342643,162.1898112009249,-0.5813394189452818
0.006791325809033251,0.0017808,224.5992930270056,162.1898112009249,-0.5813394189452818
0.006971329502983369,0.001828,224.86708787690824,162.1898112009249,-0.5813394189452818
0.007007940423786782,0.0018376,224.92122310000974,162.1898112009249,-0.5813394189452818
0.007020144064054587,0.0018407999999999999,224.93924364921887,162.1898112009249,-0.5813394189452818
0.007035398614389343,0.0018448,224.96175216438803,162.1898112009249,-0.5813394189452818
0.007133027736531779,0.0018704,225.10535855867553,162.1898112009249,-0.5813394189452818
0.007194045937870802,0.0018863999999999999,225.19472339243939,162.1898112009249,-0.5813394189452818
0.007337438711017506,0.001924,225.40357515793528,162.1898112009249,-0.5813394189452818
0.007413711462691285,0.001944,225.5140176836548,162.1898112009249,-0.5813394189452818
0.007441169653293845,0.0019512,225.55366839930775,162.1898112009249,-0.5813394189452818
0.00750828967476677,0.0019687999999999997,225.65035290905973,162.1898112009249,-0.5813394189452818
0.007578460606306646,0.0019871999999999997,225.75107244782802,162.1898112009249,-0.5813394189452818
0.007627275167377865,0.002,225.82092380566513,162.1898112009249,-0.5813394189452818
0.0076608351781143275,0.0020088,225.8688455100748,162.1898112009249,-0.5813394189452818
0.007694395188850791,0.0020176,225.91668541067006,162.1898112009249,-0.5813394189452818
0.007788973400926275,0.0020423999999999998,226.0510710923392,162.1898112009249,-0.5813394189452818
0.00788050070293481,0.0020664,226.18051712261916,162.1898112009249,-0.5813394189452818
0.007898806163336517,0.0020712,226.20633582318018,162.1898112009249,-0.5813394189452818
0.008023893476081515,0.002104,226.38214321517444,162.1898112009249,-0.5813394189452818
0.00806965712708578,0.002116,226.44619551298584,162.1898112009249,-0.5813394189452818
0.008094064407621391,0.0021224,226.48029880574566,162.1898112009249,-0.5813394189452818
0.008295424472040167,0.0021752,226.76013682360534,162.1898112009249,-0.5813394189452818
0.008325933572709677,0.0021831999999999997,226.80230429533816,162.1898112009249,-0.5813394189452818
0.008435766335119919,0.002212,226.9536107687104,162.1898112009249,-0.5813394189452818
0.008527293637128452,0.0022359999999999997,227.0791134855056,162.1898112009249,-0.5813394189452818
0.008609668208936133,0.0022576,227.1916174545683,162.1898112009249,-0.5813394189452818
0.008637126399538694,0.0022648,227.22902538685995,162.1898112009249,-0.5813394189452818
0.008777468262618448,0.0023016,227.41950194408903,162.1898112009249,-0.5813394189452818
0.008826282823689666,0.0023144,227.48547576178964,162.1898112009249,-0.5813394189452818
0.0089178101256982,0.0023384,227.6087943892645,162.1898112009249,-0.5813394189452818
0.009033744708242343,0.0023688,227.7642916679885,162.1898112009249,-0.5813394189452818
0.0090489992585771,0.0023728,227.78469374156685,162.1898112009249,-0.5813394189452818
0.00910391563978222,0.0023872,227.85803040487423,162.1898112009249,-0.5813394189452818
0.009113068369983074,0.0023896,227.87023638913757,162.1898112009249,-0.5813394189452818
0.009149679290786486,0.0023991999999999998,227.9190125915995,162.1898112009249,-0.5813394189452818
0.009244257502861973,0.002424,228.04466677999235,162.1898112009249,-0.5813394189452818
0.009277817513598435,0.0024327999999999997,228.0891331033665,162.1898112009249,-0.5813394189452818
0.009286970243799288,0.0024351999999999998,228.10124938991808,162.1898112009249,-0.5813394189452818
0.009341886625004408,0.0024495999999999997,228.17384955244742,162.1898112009249,-0.5813394189452818
0.00947917757801721,0.0024855999999999997,228.35462553894027,162.1898112009249,-0.5813394189452818
0.009512737588753673,0.0024944,228.39865956121514,162.1898112009249,-0.5813394189452818
0.00955850123975794,0.0025063999999999998,228.45860844197432,162.1898112009249,-0.5813394189452818
0.0095859594303605,0.0025136,228.49452404264898,162.1898112009249,-0.5813394189452818
0.009616468531030011,0.0025215999999999997,228.53438324191177,162.1898112009249,-0.5813394189452818
0.009674435822302084,0.0025368,228.60998011169798,162.1898112009249,-0.5813394189452818
0.009729352203507206,0.0025512,228.68143541107665,162.1898112009249,-0.5813394189452818
0.009784268584712326,0.0025656,228.75273358669418,162.1898112009249,-0.5813394189452818
0.009930712267925981,0.002604,228.9421031550869,162.1898112009249,-0.5813394189452818
0.009949017728327687,0.0026088,228.9656975347238,162.1898112009249,-0.5813394189452818
0.01006190140080488,0.0026384,229.11082385894102,162.1898112009249,-0.5813394189452818
0.010190039623616828,0.002672,229.27479455239842,162.1898112009249,-0.5813394189452818
0.010391399688035603,0.0027248,229.5308473463094,162.1898112009249,-0.5813394189452818
0.010397501508169506,0.0027264,229.5385761640769,162.1898112009249,-0.5813394189452818
0.010446316069240723,0.0027392,229.6003431532507,162.1898112009249,-0.5813394189452818
0.01046157061957548,0.0027432,229.61962223916282,162.1898112009249,-0.5813394189452818
0.010482926990044139,0.0027488,229.646594550774,162.1898112009249,-0.5813394189452818
0.010604963392722183,0.0027808,229.8003129133905,162.1898112009249,-0.5813394189452818
0.010714796155132425,0.0028095999999999998,229.9380705906302,162.1898112009249,-0.5813394189452818
0.010800221637007057,0.002832,230.04483506109403,162.1898112009249,-0.5813394189452818
0.010913105309484248,0.0028615999999999997,230.1854129013346,162.1898112009249,-0.5813394189452818
0.010949716230287664,0.0028712,230.2308837752851,162.1898112009249,-0.5813394189452818
0.011029039892028393,0.002892,230.3292010911099,162.1898112009249,-0.5813394189452818
0.011080905363166563,0.0029056,230.39333641823617,162.1898112009249,-0.5813394189452818
0.01112666901417083,0.0029176,230.44982925119797,162.1898112009249,-0.5813394189452818
0.011242603596714973,0.0029479999999999997,230.59254036363862,162.1898112009249,-0.5813394189452818
0.011431760020865945,0.0029976,230.8241587842092,162.1898112009249,-0.5813394189452818
0.011462269121535456,0.0030055999999999998,230.86137616162824,162.1898112009249,-0.5813394189452818
0.01149888004233887,0.0030152,230.90598605664525,162.1898112009249,-0.5813394189452818
0.01152938914300838,0.0030231999999999998,230.94311867124281,162.1898112009249,-0.5813394189452818
0.01160566189468216,0.0030432,231.03578294410437,162.1898112009249,-0.5813394189452818
0.01166057827588728,0.0030575999999999997,231.10235421839488,162.1898112009249,-0.5813394189452818
0.011684985556422889,0.003064,231.13190219141458,162.1898112009249,-0.5813394189452818
0.011727698297360204,0.0030751999999999997,231.18355329023805,162.1898112009249,-0.5813394189452818
0.011746003757761912,0.00308,231.20566701104195,162.1898112009249,-0.5813394189452818
0.011779563768498376,0.0030888,231.2461739559804,162.1898112009249,-0.5813394189452818
0.01179481831883313,0.0030927999999999997,231.26457132263582,162.1898112009249,-0.5813394189452818
0.011813123779234838,0.0030976,231.2866359181246,162.1898112009249,-0.5813394189452818
0.011868040160439958,0.0031119999999999997,231.35274983630433,162.1898112009249,-0.5813394189452818
0.011941262002046786,0.0031311999999999998,231.44071643096024,162.1898112009249,-0.5813394189452818
0.01195346564231459,0.0031344,231.4553570538961,162.1898112009249,-0.5813394189452818
0.012048043854390076,0.0031592,231.5686248977385,162.1898112009249,-0.5813394189452818
0.012142622066465561,0.0031839999999999998,231.68154649420657,162.1898112009249,-0.5813394189452818
0.01219448753760373,0.0031975999999999997,231.7433255914092,162.1898112009249,-0.5813394189452818
0.012319574850348729,0.0032304,231.8919021461811,162.1898112009249,-0.5813394189452818
0.0125087312744997,0.00328,232.11546619619156,162.1898112009249,-0.5813394189452818
0.012655174957713355,0.0033184,232.28764373311995,162.1898112009249,-0.5813394189452818
0.012700938608717622,0.0033304,232.3412896294026,162.1898112009249,-0.5813394189452818
0.01272229497918628,0.003336,232.36629857763822,162.1898112009249,-0.5813394189452818
0.012746702259721888,0.0033423999999999997,232.39486019325554,162.1898112009249,-0.5813394189452818
0.012868738662399935,0.0033744,232.53734958518208,162.1898112009249,-0.5813394189452818
0.012920604133538105,0.003388,232.59774788867207,162.1898112009249,-0.5813394189452818
0.012999927795278834,0.0034088,232.68993919265822,162.1898112009249,-0.5813394189452818
0.013033487806015296,0.0034176,232.72887713237463,162.1898112009249,-0.5813394189452818
0.013137218748291636,0.0034448,232.84898428630046,162.1898112009249,-0.5813394189452818
0.013164676938894195,0.0034519999999999998,232.88071537473542,162.1898112009249,-0.5813394189452818
0.013207389679831512,0.0034632,232.93002358982247,162.1898112009249,-0.5813394189452818
0.01322874605030017,0.0034687999999999997,232.9546543731206,162.1898112009249,-0.5813394189452818
0.013308069712040899,0.0034896,233.04600468409643,162.1898112009249,-0.5813394189452818
0.013372138823446874,0.0035064,233.11963269915387,162.1898112009249,-0.5813394189452818
0.013402647924116386,0.0035144,233.15464529172718,162.1898112009249,-0.5813394189452818
0.013424004294585042,0.0035199999999999997,233.17913561428563,162.1898112009249,-0.5813394189452818
0.01349722613619187,0.0035391999999999997,233.26298731702295,162.1898112009249,-0.5813394189452818
0.013503327956325773,0.0035407999999999998,233.26996694092014,162.1898112009249,-0.5813394189452818
0.013558244337530893,0.0035551999999999997,233.33272830206013,162.1898112009249,-0.5813394189452818
0.013674178920075037,0.0035856,233.46489986404018,162.1898112009249,-0.5813394189452818
0.013698586200610645,0.0035919999999999997,233.49266968653333,162.1898112009249,-0.5813394189452818
0.013750451671748817,0.0036056,233.55161657007088,162.1898112009249,-0.5813394189452818
0.013802317142886985,0.0036192,233.6104768035909,162.1898112009249,-0.5813394189452818
0.013848080793891252,0.0036312,233.66234070621377,162.1898112009249,-0.5813394189452818
0.013893844444895519,0.0036431999999999997,233.7141378079873,162.1898112009249,-0.5813394189452818
0.013945709916033689,0.0036568,233.77276082100462,162.1898112009249,-0.5813394189452818
0.013967066286502346,0.0036623999999999997,233.79687498705064,162.1898112009249,-0.5813394189452818
0.014018931757640516,0.003676,233.8553781722069,162.1898112009249,-0.5813394189452818
0.014043339038176126,0.0036823999999999997,233.88287986886192,162.1898112009249,-0.5813394189452818
0.01424164819252795,0.0037343999999999997,234.10564428439824,162.1898112009249,-0.5813394189452818
0.014314870034134777,0.0037535999999999997,234.18758954062469,162.1898112009249,-0.5813394189452818
0.01435148095493819,0.0037632,234.22850085530538,162.1898112009249,-0.5813394189452818
0.014372837325406848,0.0037687999999999997,234.25234699226854,162.1898112009249,-0.5813394189452818
0.01440029551600941,0.003776,234.28298601603612,162.1898112009249,-0.5813394189452818
0.014433855526745872,0.0037847999999999996,234.32040278734377,162.1898112009249,-0.5813394189452818
0.014497924638151846,0.0038016,234.39174072390477,162.1898112009249,-0.5813394189452818
0.014519281008620504,0.0038071999999999997,234.41549270009608,162.1898112009249,-0.5813394189452818
0.014537586469022212,0.003812,234.43584069424006,162.1898112009249,-0.5813394189452818
0.014650470141499403,0.0038415999999999997,234.56109990125606,162.1898112009249,-0.5813394189452818
0.014763353813976596,0.0038712,234.68598326515834,162.1898112009249,-0.5813394189452818
0.014879288396520739,0.0039016,234.81385482656933,162.1898112009249,-0.5813394189452818
0.014909797497190251,0.0039096,234.84744058109177,162.1898112009249,-0.5813394189452818
0.014979968428730128,0.003928,234.9245862659775,162.1898112009249,-0.5813394189452818
0.015208786683751465,0.003988,235.17517483442091,162.1898112009249,-0.5813394189452818
0.015242346694487926,0.0039968,235.21180380808352,162.1898112009249,-0.5813394189452818
0.01620662469051564,0.004249649929985997,236.25119876731964,162.1898112009249,-0.5813394189452818
0.01818400989094007,0.004768153630726146,238.31001433557603,162.1898112009249,-0.5813394189452818
0.020307868069173715,0.005325065013002601,240.42622606484008,162.1898112009249,-0.5813394189452818
0.02323732762535805,0.006093218643728746,243.2084151780267,162.1898112009249,-0.5813394189452818
0.027118861537302294,0.007111022204440888,246.6921442320392,162.1898112009249,-0.5813394189452818
0.027558280470729946,0.0072262452490498095,247.07386430392734,162.1898112009249,-0.5813394189452818
0.02873006429320368,0.007533506701340268,248.080353830839,162.1898112009249,-0.5813394189452818
0.030414503538009674,0.007975195039007801,249.49956935192677,162.1898112009249,-0.5813394189452818
0.03561429425023688,0.00933866773354671,253.69852889536818,162.1898112009249,-0.5813394189452818
0.037518442961756694,0.009837967593518704,255.17536335826466,162.1898112009249,-0.5813394189452818
0.0401549565623226,0.010529305861172233,257.1728183540503,162.1898112009249,-0.5813394189452818
0.040814084962464074,0.010702140428085618,257.6641063772283,162.1898112009249,-0.5813394189452818
0.04132674038479633,0.010836567313462692,258.0440831156594,162.1898112009249,-0.5813394189452818
0.042278814740556246,0.01108621724344869,258.7449123583379,162.1898112009249,-0.5813394189452818
0.04301117962960233,0.011278255651130227,259.27983147189383,162.1898112009249,-0.5813394189452818
0.04389001749645763,0.01150870174034807,259.9170680394353,162.1898112009249,-0.5813394189452818
0.04498856483002675,0.011796759351870374,260.70665842967384,162.1898112009249,-0.5813394189452818
0.0471124230082604,0.012353670734146829,262.21219486991043,162.1898112009249,-0.5813394189452818
0.04762507843059265,0.012488097619523904,262.57160566239116,162.1898112009249,-0.5813394189452818
0.04821097034182952,0.012641728345669134,262.9805184188548,162.1898112009249,-0.5813394189452818
0.04894333523087561,0.01283376675335067,263.4889441313735,162.1898112009249,-0.5813394189452818
0.04923628118649404,0.012910582116423285,263.6914825888214,162.1898112009249,-0.5813394189452818
0.05077424745349082,0.013313862772554511,264.74719643929745,162.1898112009249,-0.5813394189452818
0.051799558298155336,0.013582716543308662,265.44408479802314,162.1898112009249,-0.5813394189452818
0.05201926776486916,0.013640328065613123,265.5927157373697,162.1898112009249,-0.5813394189452818
0.05472901785433967,0.014350870174034807,267.40614966238456,162.1898112009249,-0.5813394189452818
0.05553461923229037,0.014562112422484497,267.9384805349346,162.1898112009249,-0.5813394189452818
0.056779639543668714,0.01488857771554311,268.75528783499936,162.1898112009249,-0.5813394189452818
0.057731713899428626,0.015138227645529106,269.37520064047925,162.1898112009249,-0.5813394189452818
0.0609541194112314,0.015983196639327867,271.4443961212203,162.1898112009249,-0.5813394189452818
0.06139353834465905,0.01609841968393679,271.72321676508716,162.1898112009249,-0.5813394189452818
0.062711795144942,0.016444088817763554,272.5550459144402,162.1898112009249,-0.5813394189452818
0.06351739652289269,0.016655331066213242,273.06002970435384,162.1898112009249,-0.5813394189452818
0.0645427073675572,0.016924184836967393,273.69913825216497,162.1898112009249,-0.5813394189452818
0.06615391012345859,0.017346669333866773,274.6955091295204,162.1898112009249,-0.5813394189452818
0.06681303852360007,0.017519503900780158,275.10038221379466,162.1898112009249,-0.5813394189452818
0.06769187639045537,0.017749949989998,275.63779812152546,162.1898112009249,-0.5813394189452818
0.06959602510197518,0.018249249849969992,276.79295186338203,162.1898112009249,-0.5813394189452818
0.07084104541335354,0.018575715143028606,277.5415859454958,162.1898112009249,-0.5813394189452818
0.07274519412487335,0.0190750150030006,278.6767058130769,162.1898112009249,-0.5813394189452818
0.07362403199172865,0.019305461092218444,279.19669309813656,162.1898112009249,-0.5813394189452818
0.0749422887920116,0.01965113022604521,279.97215796662374,162.1898112009249,-0.5813394189452818
0.07728585643695908,0.020265653130626126,281.33775235242166,162.1898112009249,-0.5813394189452818
0.07757880239257751,0.02034246849369874,281.5073087587603,162.1898112009249,-0.5813394189452818
0.07838440377052819,0.02055371074214843,281.97230620556354,162.1898112009249,-0.5813394189452818
0.07897029568176506,0.020707341468293658,282.3093163062375,162.1898112009249,-0.5813394189452818
0.07940971461519271,0.02082256451290258,282.5614343251067,162.1898112009249,-0.5813394189452818
0.08043502545985723,0.02109141828365673,283.1476032218546,162.1898112009249,-0.5813394189452818
0.0818265187490448,0.02145629125825165,283.93847827614087,162.1898112009249,-0.5813394189452818
0.08263212012699549,0.02166753350670134,284.3939558445252,162.1898112009249,-0.5813394189452818
0.08702630946127199,0.022819763952790558,286.8485439905744,162.1898112009249,-0.5813394189452818
0.08922340412841025,0.023395879175835167,288.0576732905892,162.1898112009249,-0.5813394189452818
0.09039518795088398,0.023703140628125625,288.6977914190583,162.1898112009249,-0.5813394189452818
0.09193315421788076,0.02410642128425685,289.5330567039263,162.1898112009249,-0.5813394189452818
0.09339788399597292,0.024490498099619923,290.32349530565904,162.1898112009249,-0.5813394189452818
0.0949358502629697,0.02489377875575115,291.1482701795637,162.1898112009249,-0.5813394189452818
0.09530203270749274,0.024989797959591917,291.34387510866026,162.1898112009249,-0.5813394189452818
0.09618087057434804,0.02522024404880976,291.81213487882343,162.1898112009249,-0.5813394189452818
0.09771883684134483,0.02562352470494099,292.62759391563515,162.1898112009249,-0.5813394189452818
0.09911033013053239,0.025988397679535907,293.36108721580274,162.1898112009249,-0.5813394189452818
0.10086800586424298,0.026449289857971594,294.28188952316765,162.1898112009249,-0.5813394189452818
0.10167360724219368,0.026660532106421286,294.7018304662479,162.1898112009249,-0.5813394189452818
0.10225949915343055,0.026814162832566515,295.00642743060774,162.1898112009249,-0.5813394189452818
0.10562837764304255,0.027697539507901582,296.74482953766466,162.1898112009249,-0.5813394189452818
0.10672692497661167,0.027985597119423885,297.30700666592224,162.1898112009249,-0.5813394189452818
0.10782547231018079,0.02827365473094619,297.8669315249598,162.1898112009249,-0.5813394189452818
0.11075493186636512,0.029041808361672333,299.34929306478284,162.1898112009249,-0.5813394189452818
0.11126758728869739,0.02917623524704941,299.60712629256307,162.1898112009249,-0.5813394189452818
0.11551530364516467,0.03029005801160232,301.72592268879646,162.1898112009249,-0.5813394189452818
0.11617443204530614,0.030462892578515702,302.0519580112188,162.1898112009249,-0.5813394189452818
0.11719974288997066,0.030731746349269853,302.55769378992636,162.1898112009249,-0.5813394189452818
0.11844476320134902,0.031058211642328467,303.16948768479085,162.1898112009249,-0.5813394189452818
0.11947007404601354,0.03132706541308262,303.6714369760143,162.1898112009249,-0.5813394189452818
0.12034891191286884,0.03155751150230046,304.1003435078215,162.1898112009249,-0.5813394189452818
0.12196011466877023,0.031979995999199845,304.88351298101117,162.1898112009249,-0.5813394189452818
0.1227657160467209,0.03219123824764953,305.2735837983901,162.1898112009249,-0.5813394189452818
0.12335160795795777,0.03234486897379476,305.55664492696314,162.1898112009249,-0.5813394189452818
0.1254022296472868,0.03288257651530306,306.5432559343649,162.1898112009249,-0.5813394189452818
0.1286246351590896,0.03372754550910182,308.0810260070886,162.1898112009249,-0.5813394189452818
0.1303823108928002,0.03418843768753751,308.9134739316693,162.1898112009249,-0.5813394189452818
0.13301882449336608,0.03487977595519104,310.1539860981784,162.1898112009249,-0.5813394189452818
0.13360471640460295,0.03503340668133627,310.42834890748924,162.1898112009249,-0.5813394189452818
0.1349229732048859,0.03537907581516303,311.0439553948976,162.1898112009249,-0.5813394189452818
0.13712006787202416,0.03595519103820764,312.0647787989596,162.1898112009249,-0.5813394189452818
0.1403424733838269,0.036800160032006396,313.5505219792556,162.1898112009249,-0.5813394189452818
0.14129454773958686,0.037049809961992405,313.98693759067595,162.1898112009249,-0.5813394189452818
0.14393106134015274,0.03774114822964593,315.18952820127765,162.1898112009249,-0.5813394189452818
0.14473666271810345,0.03795239047809562,315.5552687888361,162.1898112009249,-0.5813394189452818
0.14729993982976475,0.038624524904981,316.71374201666066,162.1898112009249,-0.5813394189452818
0.1489843790745707,0.03906621324264853,317.4707460627047,162.1898112009249,-0.5813394189452818
0.15000968991923525,0.03933506701340268,317.92989710009516,162.1898112009249,-0.5813394189452818
0.15162089267513665,0.03975755151030207,318.64895503217537,162.1898112009249,-0.5813394189452818
0.15271944000870577,0.040045609121824366,319.137514053999,162.1898112009249,-0.5813394189452818
0.1537447508533703,0.04031446289257852,319.5922673486869,162.1898112009249,-0.5813394189452818
0.15477006169803478,0.04058331666333266,320.0458394121839,162.1898112009249,-0.5813394189452818
0.15586860903160393,0.040871374274854974,320.53051101373563,162.1898112009249,-0.5813394189452818
0.15791923072093295,0.04140908181636327,321.4316817925673,162.1898112009249,-0.5813394189452818
0.15879806858778828,0.04163952790558112,321.81649948259155,162.1898112009249,-0.5813394189452818
0.16048250783259424,0.04208121624324865,322.55175303258994,162.1898112009249,-0.5813394189452818
0.16326549441096938,0.04281096219243849,323.75995963517477,162.1898112009249,-0.5813394189452818
0.1634852038776832,0.04286857371474295,323.85500092124244,162.1898112009249,-0.5813394189452818
0.16480346067796614,0.043214242848569714,324.42420606786857,162.1898112009249,-0.5813394189452818
0.16612171747824908,0.043559911982396476,324.9916382689001,162.1898112009249,-0.5813394189452818
0.16656113641167675,0.0436751350270054,325.18039173358824,162.1898112009249,-0.5813394189452818
0.16795262970086433,0.04404000800160032,325.77683384424057,162.1898112009249,-0.5813394189452818
0.16875823107881502,0.044251250250050014,326.12126157271854,162.1898112009249,-0.5813394189452818
0.17146798116828552,0.0449617923584717,327.27511397682815,162.1898112009249,-0.5813394189452818
0.1722003460573316,0.04515383076615323,327.5857424386464,162.1898112009249,-0.5813394189452818
0.17322565690199612,0.045422684536907385,328.01975809600464,162.1898112009249,-0.5813394189452818
0.173811548813233,0.045576315263052614,328.26731721047554,162.1898112009249,-0.5813394189452818
0.17432420423556524,0.045710742148429684,328.4836645888959,162.1898112009249,-0.5813394189452818
0.17674100836941734,0.04634446889377876,329.50026442455317,162.1898112009249,-0.5813394189452818
0.18098872472588462,0.04745829165833167,331.2739741106313,162.1898112009249,-0.5813394189452818
0.18230698152616756,0.04780396079215843,331.8211248555702,162.1898112009249,-0.5813394189452818
0.1834055288597367,0.04809201840368074,332.275906115926,162.1898112009249,-0.5813394189452818
0.18523644108235188,0.048572114422884574,333.0315211487679,162.1898112009249,-0.5813394189452818
0.18743353574949015,0.04914822964592919,333.9344251477625,162.1898112009249,-0.5813394189452818
0.1892644479721054,0.04962832566513303,334.6836963253351,162.1898112009249,-0.5813394189452818
0.1924136169950035,0.05045409081816363,335.96586361958776,162.1898112009249,-0.5813394189452818
0.19336569135076345,0.05070374074814964,336.35188102293466,162.1898112009249,-0.5813394189452818
0.19475718463995098,0.051068613722744544,336.91472960692664,162.1898112009249,-0.5813394189452818
0.19768664419613532,0.05183676735347069,338.09457317032405,162.1898112009249,-0.5813394189452818
0.1990049009964183,0.052182436487297465,338.6232761604339,162.1898112009249,-0.5813394189452818
0.20003021184108277,0.052451290258051605,339.03354585416014,162.1898112009249,-0.5813394189452818
0.20061610375231964,0.052604920984196835,339.2676174400475,162.1898112009249,-0.5813394189452818
0.20156817810807962,0.052854570914182844,339.6474159549141,162.1898112009249,-0.5813394189452818
0.2025202524638395,0.05310422084416884,340.02651548334416,162.1898112009249,-0.5813394189452818
0.20347232681959943,0.053353870774154835,340.40492058876475,162.1898112009249,-0.5813394189452818
0.20398498224193165,0.053488297659531905,340.60839113670806,162.1898112009249,-0.5813394189452818
0.20757357019825748,0.05442928585717144,342.02714221220714,162.1898112009249,-0.5813394189452818
0.20969742837649114,0.05498619723944789,342.86230549451057,162.1898112009249,-0.5813394189452818
0.20999037433210954,0.0550630126025205,342.97724100029967,162.1898112009249,-0.5813394189452818
0.2113818676212971,0.05542788557711542,343.52233298421714,162.1898112009249,-0.5813394189452818
0.2121874689992478,0.05563912782556511,343.8372729265061,162.1898112009249,-0.5813394189452818
0.21270012442158004,0.05577355471094218,344.0374464777956,162.1898112009249,-0.5813394189452818
0.21387190824405378,0.05608081616323264,344.49428080250567,162.1898112009249,-0.5813394189452818
0.21467750962200446,0.05629205841168233,344.80778831023156,162.1898112009249,-0.5813394189452818
0.2158492934444782,0.05659931986397279,345.26298141420955,162.1898112009249,-0.5813394189452818
0.21789991513380727,0.0571370274054811,346.05725714645155,162.1898112009249,-0.5813394189452818
0.21877875300066255,0.05736747349469894,346.3967680374736,162.1898112009249,-0.5813394189452818
0.21929140842299483,0.05750190038007602,346.59457042886106,162.1898112009249,-0.5813394189452818
0.22046319224546856,0.05780916183236648,347.046014220572,162.1898112009249,-0.5813394189452818
0.2219279220235607,0.058193238647729545,347.6090051633364,162.1898112009249,-0.5813394189452818
0.22397854371288978,0.058730946189237854,348.3947639884847,162.1898112009249,-0.5813394189452818
0.22500385455755426,0.058999799959991994,348.78659092055216,162.1898112009249,-0.5813394189452818
0.22690800326907412,0.059499099819964,349.51242701931034,162.1898112009249,-0.5813394189452818
0.22742065869140635,0.05963352670534107,349.70743806607555,162.1898112009249,-0.5813394189452818
0.23042335473649533,0.060420884176835374,350.84622160380025,162.1898112009249,-0.5813394189452818
0.23254721291472896,0.06097779555911183,351.64821073183936,162.1898112009249,-0.5813394189452818
0.2338654697150119,0.06132346469293859,352.14456053964005,162.1898112009249,-0.5813394189452818
0.234964017048581,0.06161152230446089,352.55735240725954,162.1898112009249,-0.5813394189452818
0.23774700362695614,0.06234126825365073,353.5997372780592,162.1898112009249,-0.5813394189452818
0.24111588211656815,0.0632246449289858,354.85522621641184,162.1898112009249,-0.5813394189452818
0.24397210518384785,0.06397359471894379,355.91431273812583,162.1898112009249,-0.5813394189452818
0.2444847606061801,0.06410802160432086,356.1038922210889,162.1898112009249,-0.5813394189452818
0.24646214580660453,0.06462652530506101,356.83367970587864,162.1898112009249,-0.5813394189452818
0.24778040260688752,0.06497219443888778,357.31893648346295,162.1898112009249,-0.5813394189452818
0.24909865940717046,0.06531786357271455,357.80318743877683,162.1898112009249,-0.5813394189452818
0.2505633891852626,0.06570194038807761,358.3400733744202,162.1898112009249,-0.5813394189452818
0.25385903118597003,0.06656611322264454,359.5436115110336,162.1898112009249,-0.5813394189452818
0.25561670691968064,0.06702700540108023,360.1830061894693,162.1898112009249,-0.5813394189452818
0.2564955447865359,0.06725745149029806,360.50206035811726,162.1898112009249,-0.5813394189452818
0.2578138015868188,0.06760312062412482,360.97984338428336,162.1898112009249,-0.5813394189452818
0.2583996934980557,0.06775675135027005,361.1918854692858,162.1898112009249,-0.5813394189452818
0.25913205838710185,0.0679487897579516,361.45667458242434,162.1898112009249,-0.5813394189452818
0.2605235516762894,0.0683136627325465,361.95897121528907,162.1898112009249,-0.5813394189452818
0.2612559165653355,0.06850570114022805,362.2229175461887,162.1898112009249,-0.5813394189452818
0.2620615179432862,0.06871694338867775,362.51292544395324,162.1898112009249,-0.5813394189452818
0.26550363292180273,0.06961952390478096,363.74815400769586,162.1898112009249,-0.5813394189452818
0.26660218025537186,0.06990758151630326,364.14105912151535,162.1898112009249,-0.5813394189452818
0.2669683626998949,0.07000360072014403,364.2718871146849,162.1898112009249,-0.5813394189452818
0.26799367354455944,0.07027245449089818,364.6378337012873,162.1898112009249,-0.5813394189452818
0.2691654573670332,0.07057971594318864,365.0553904337977,162.1898112009249,-0.5813394189452818
0.27172873447869444,0.07125185037007402,365.96633216496673,162.1898112009249,-0.5813394189452818
0.2739990656347373,0.07184716943388678,366.7703712839321,162.1898112009249,-0.5813394189452818
0.27473143052378346,0.07203920784156832,367.0291839332823,162.1898112009249,-0.5813394189452818
0.27531732243502033,0.07219283856771355,367.2360403732065,162.1898112009249,-0.5813394189452818
0.27700176167982626,0.07263452690538108,367.82979848801176,162.1898112009249,-0.5813394189452818
0.2775144171021585,0.07276895379075815,368.01022776278336,162.1898112009249,-0.5813394189452818
0.2792720928358691,0.07322984596919384,368.62785795012684,162.1898112009249,-0.5813394189452818
0.28015093070272445,0.07346029205841169,368.9361044033924,162.1898112009249,-0.5813394189452818
0.28102976856957973,0.07369073814762953,369.24397396667166,162.1898112009249,-0.5813394189452818
0.2843986470591917,0.0745741148229646,370.4206784964759,162.1898112009249,-0.5813394189452818
0.2868154511930438,0.07520784156831367,371.2614897985902,162.1898112009249,-0.5813394189452818
0.2874745795931853,0.07538067613522705,371.4903218423523,162.1898112009249,-0.5813394189452818
0.28871959990456364,0.07570714142828566,371.92200263252266,162.1898112009249,-0.5813394189452818
0.2894519647936097,0.0758991798359672,372.17559338667394,162.1898112009249,-0.5813394189452818
0.2926011338165079,0.0767249449889978,373.26319455262126,162.1898112009249,-0.5813394189452818
0.2934067351944586,0.0769361872374475,373.5406836288276,162.1898112009249,-0.5813394189452818
0.29399262710569546,0.07708981796359272,373.74230726786254,162.1898112009249,-0.5813394189452818
0.295384120394883,0.07745469093818765,374.2205363984887,162.1898112009249,-0.5813394189452818
0.2956770663505014,0.07753150630126025,374.3211041696725,162.1898112009249,-0.5813394189452818
0.2972150326174982,0.07793478695739148,374.848448798207,162.1898112009249,-0.5813394189452818
0.2986797623955904,0.07831886377275456,375.3496932382372,162.1898112009249,-0.5813394189452818
0.30021772866258717,0.07872214442888578,375.87496923723955,162.1898112009249,-0.5813394189452818
0.3023415868408208,0.07927905581116224,376.5986283541914,162.1898112009249,-0.5813394189452818
0.30263453279643926,0.07935587117423486,376.6982875931778,162.1898112009249,-0.5813394189452818
0.3030007152409623,0.07945189037807562,376.82280875074036,162.1898112009249,-0.5813394189452818
0.3031471882187715,0.07949029805961193,376.8726007790087,162.1898112009249,-0.5813394189452818
0.30453868150795904,0.07985517103420685,377.3451580168264,162.1898112009249,-0.5813394189452818
0.30622312075276503,0.08029685937187438,377.9160758152843,162.1898112009249,-0.5813394189452818
0.3073216680863342,0.08058491698339669,378.2877537808709,162.1898112009249,-0.5813394189452818
0.3086399248866171,0.08093058611722345,378.733084079807,162.1898112009249,-0.5813394189452818
0.3108370195537554,0.08150670134026806,379.47365630023563,162.1898112009249,-0.5813394189452818
0.31252145879856136,0.08194838967793559,380.0400466294257,162.1898112009249,-0.5813394189452818
0.3131073507097982,0.08210202040408082,380.2367727236159,162.1898112009249,-0.5813394189452818
0.3138397155988443,0.08229405881176236,380.4824785692218,162.1898112009249,-0.5813394189452818
0.31515797239912724,0.08263972794558912,380.92418632481207,162.1898112009249,-0.5813394189452818
0.3158171007992687,0.0828125625125025,381.14476994989377,162.1898112009249,-0.5813394189452818
0.3184536143998346,0.08350390078015603,382.02531491420615,162.1898112009249,-0.5813394189452818
0.31867332386654845,0.08356151230246049,382.0985650793905,162.1898112009249,-0.5813394189452818
0.3208704185336867,0.0841376275255051,382.8299867023884,162.1898112009249,-0.5813394189452818
0.32394635106768027,0.08494418883776755,383.8507040445178,162.1898112009249,-0.5813394189452818
0.32702228360167385,0.08575075015003002,384.86764846554985,162.1898112009249,-0.5813394189452818
0.32951232422443055,0.08640368073614724,385.6881596108168,162.1898112009249,-0.5813394189452818
0.3343459324921347,0.08767113422684537,387.2740461079908,162.1898112009249,-0.5813394189452818
0.3355177163146084,0.08797839567913583,387.65715380632963,162.1898112009249,-0.5813394189452818
0.33603037173694067,0.0881128225645129,387.82459929981076,162.1898112009249,-0.5813394189452818
0.3370556825816052,0.08838167633526706,388.1591916998283,162.1898112009249,-0.5813394189452818
0.3381542299151743,0.08866973394678936,388.5172433698645,162.1898112009249,-0.5813394189452818
0.33903306778202963,0.0889001800360072,388.80335819092386,162.1898112009249,-0.5813394189452818
0.34013161511559875,0.0891882376475295,389.1605952878601,162.1898112009249,-0.5813394189452818
0.3413033989380725,0.08949549909981996,389.54115257418,162.1898112009249,-0.5813394189452818
0.3433540206274015,0.09003320664132827,390.20590398146487,162.1898112009249,-0.5813394189452818
0.3466496626281089,0.09089737947589518,391.27101980297067,162.1898112009249,-0.5813394189452818
0.34694260858372733,0.09097419483896779,391.36550522760194,162.1898112009249,-0.5813394189452818
0.34804115591729645,0.0912622524504901,391.7195488018115,162.1898112009249,-0.5813394189452818
0.34848057485072415,0.09137747549509903,391.8610441691422,162.1898112009249,-0.5813394189452818
0.35250858174047756,0.09243368673734748,393.1548587898005,162.1898112009249,-0.5813394189452818
0.3536071290740467,0.09272174434886978,393.5067150152121,162.1898112009249,-0.5813394189452818
0.3547789128965204,0.09302900580116023,393.88155876032283,162.1898112009249,-0.5813394189452818
0.35565775076337575,0.09325945189037808,394.162374786767,162.1898112009249,-0.5813394189452818
0.3580745548972278,0.09389317863572715,394.93322691879916,162.1898112009249,-0.5813394189452818
0.3596857576531292,0.09431566313262653,395.4460013635215,162.1898112009249,-0.5813394189452818
0.36093077796450757,0.09464212842568515,395.84162284764693,162.1898112009249,-0.5813394189452818
0.3620293252980767,0.09493018603720745,396.1902588530665,162.1898112009249,-0.5813394189452818
0.3625419807204089,0.09506461292258452,396.352814437883,162.1898112009249,-0.5813394189452818
0.3641531834763103,0.0954870974194839,396.86312077881246,162.1898112009249,-0.5813394189452818
0.3643728929430241,0.09554470894178836,396.932639719409,162.1898112009249,-0.5813394189452818
0.36459260240973795,0.09560232046409282,397.0021423137068,162.1898112009249,-0.5813394189452818
0.3651052578320702,0.0957367473494699,397.1642515416634,162.1898112009249,-0.5813394189452818
0.3684741363216822,0.09662012402480497,398.2273408671856,162.1898112009249,-0.5813394189452818
0.3724289067225311,0.09765713142628527,399.4704905303613,162.1898112009249,-0.5813394189452818
0.37352745405610016,0.09794518903780756,399.8148948470806,162.1898112009249,-0.5813394189452818
0.375797785212143,0.09854050810162032,400.525414491339,162.1898112009249,-0.5813394189452818
0.3772625149902352,0.0989245849169834,400.98292599334087,162.1898112009249,-0.5813394189452818
0.3786540082794228,0.09928945789157832,401.41692068081346,162.1898112009249,-0.5813394189452818
0.3796060826351827,0.09953910782156432,401.71350609784935,162.1898112009249,-0.5813394189452818
0.3807046299687518,0.09982716543308662,402.0553597977581,162.1898112009249,-0.5813394189452818
0.38085110294656105,0.09986557311462294,402.1009112066131,162.1898112009249,-0.5813394189452818