File: datasets/aisi_316_L/data/M1/train_66.csv
Time(s),Strain(%),Stress(MPa),Temp(C),Log_SR(s-1)
0.0,0.0,0.0,55.90819317611226,2.3103571617583105
4.698011454059503e-08,9.6e-06,1.8723257999999998,55.90819317611226,2.3103571617583105
1.2528030544158675e-07,2.56e-05,4.9928688,55.90819317611226,2.3103571617583105
1.370253340767355e-07,2.8e-05,5.46095025,55.90819317611226,2.3103571617583105
1.8400544861733055e-07,3.76e-05,7.33327605,55.90819317611226,2.3103571617583105
2.6230563951832226e-07,5.3599999999999995e-05,10.45381905,55.90819317611226,2.3103571617583105
3.640958876896115e-07,7.439999999999999e-05,14.510524949999999,55.90819317611226,2.3103571617583105
4.2673604041040483e-07,8.719999999999999e-05,17.00695935,55.90819317611226,2.3103571617583105
4.932912026762479e-07,0.0001008,19.6594209,55.90819317611226,2.3103571617583105
5.363563076717932e-07,0.0001096,21.37571955,55.90819317611226,2.3103571617583105
5.755064031222892e-07,0.0001176,22.93599105,55.90819317611226,2.3103571617583105
6.264015272079338e-07,0.000128,24.964344,55.90819317611226,2.3103571617583105
6.812116608386279e-07,0.0001392,27.1487241,55.90819317611226,2.3103571617583105
7.516818326495205e-07,0.0001536,29.957212799999997,55.90819317611226,2.3103571617583105
8.338970330955618e-07,0.0001704,33.23378295,55.90819317611226,2.3103571617583105
8.652171094559585e-07,0.0001768,34.48200015,55.90819317611226,2.3103571617583105
1.002242443532694e-06,0.0002048,39.9429504,55.90819317611226,2.3103571617583105
1.029647510348041e-06,0.0002104,41.03514045,55.90819317611226,2.3103571617583105
1.049222558073289e-06,0.00021439999999999998,41.8152762,55.90819317611226,2.3103571617583105
1.0922876630688345e-06,0.00022319999999999998,43.53157485,55.90819317611226,2.3103571617583105
1.162757834879727e-06,0.0002376,46.34006355,55.90819317611226,2.3103571617583105
1.2880381403213138e-06,0.0002632,51.33293235,55.90819317611226,2.3103571617583105
1.3311032453168592e-06,0.000272,53.049231,55.90819317611226,2.3103571617583105
1.436808503033198e-06,0.0002936,57.261964049999996,55.90819317611226,2.3103571617583105
1.5229387130242889e-06,0.0003112,60.694561349999994,55.90819317611226,2.3103571617583105
1.616898942105479e-06,0.0003304,64.43921295,55.90819317611226,2.3103571617583105
1.6717090757361733e-06,0.0003416,66.62359305,55.90819317611226,2.3103571617583105
1.7226041998218177e-06,0.000352,68.651946,55.90819317611226,2.3103571617583105
1.8087344098129087e-06,0.0003696,72.08454329999999,55.90819317611226,2.3103571617583105
1.8792045816238014e-06,0.000384,74.893032,55.90819317611226,2.3103571617583105
2.0358049634257848e-06,0.000416,81.134118,55.90819317611226,2.3103571617583105
2.153255249777272e-06,0.00043999999999999996,85.8149325,55.90819317611226,2.3103571617583105
2.1963203547728176e-06,0.00044879999999999996,87.53123115,55.90819317611226,2.3103571617583105
2.2472154788584623e-06,0.0004592,89.5595841,55.90819317611226,2.3103571617583105
2.333345688849553e-06,0.0004768,92.99218139999999,55.90819317611226,2.3103571617583105
2.4351359370208425e-06,0.0004976,97.04888729999999,55.90819317611226,2.3103571617583105
2.497776089741636e-06,0.0005103999999999999,99.54532169999999,55.90819317611226,2.3103571617583105
2.560416242462429e-06,0.0005231999999999999,102.04175609999999,55.90819317611226,2.3103571617583105
2.638716433363421e-06,0.0005392,105.1622991,55.90819317611226,2.3103571617583105
2.7170166242644125e-06,0.0005551999999999999,108.28284209999998,55.90819317611226,2.3103571617583105
2.775741767440157e-06,0.0005672,110.62324935000001,55.90819317611226,2.3103571617583105
2.8188068724357023e-06,0.000576,112.33954800000001,55.90819317611226,2.3103571617583105
2.8618719774312473e-06,0.0005848,114.05584665,55.90819317611226,2.3103571617583105
2.8931920537916437e-06,0.0005912,115.30406384999999,55.90819317611226,2.3103571617583105
3.104602569224322e-06,0.0006344,123.72952995,55.90819317611226,2.3103571617583105
3.1359226455847185e-06,0.0006408,124.97774715,55.90819317611226,2.3103571617583105
3.202477807850561e-06,0.0006544,127.6302087,55.90819317611226,2.3103571617583105
3.3277581132921477e-06,0.0006799999999999999,132.6230775,55.90819317611226,2.3103571617583105
3.3629931991975944e-06,0.0006872,134.02732185,55.90819317611226,2.3103571617583105
3.40605830419314e-06,0.000696,135.7436205,55.90819317611226,2.3103571617583105
3.4452083996436355e-06,0.000704,137.303892,55.90819317611226,2.3103571617583105
3.468698456913933e-06,0.0007088,138.2400549,55.90819317611226,2.3103571617583105
3.5156785714545284e-06,0.0007184,140.1123807,55.90819317611226,2.3103571617583105
3.613553810080768e-06,0.0007384,144.01305945,55.90819317611226,2.3103571617583105
3.6527039055312636e-06,0.0007463999999999999,145.57333094999998,55.90819317611226,2.3103571617583105
3.7505791441575035e-06,0.0007664,149.47400969999998,55.90819317611226,2.3103571617583105
3.840624363693644e-06,0.0007848,153.06263415,55.90819317611226,2.3103571617583105
3.942414611864933e-06,0.0008056,157.11934005,55.90819317611226,2.3103571617583105
4.020714802765925e-06,0.0008215999999999999,160.23988304999997,55.90819317611226,2.3103571617583105
4.075524936396619e-06,0.0008328,162.42426315,55.90819317611226,2.3103571617583105
4.091184974576817e-06,0.0008359999999999999,163.04837175,55.90819317611226,2.3103571617583105
4.196890232293156e-06,0.0008575999999999999,167.2611048,55.90819317611226,2.3103571617583105
4.243870346833751e-06,0.0008671999999999999,169.1334306,55.90819317611226,2.3103571617583105
4.416130766815932e-06,0.0009023999999999999,175.9986252,55.90819317611226,2.3103571617583105
4.474855909991677e-06,0.0009144,178.33903245,55.90819317611226,2.3103571617583105
4.53749606271247e-06,0.0009272,180.83546685,55.90819317611226,2.3103571617583105
4.654946349063957e-06,0.0009511999999999999,185.51628134999999,55.90819317611226,2.3103571617583105
4.768481625870396e-06,0.0009743999999999999,190.04106869999998,55.90819317611226,2.3103571617583105
4.807631721320892e-06,0.0009824,191.6013402,55.90819317611226,2.3103571617583105
4.854611835861487e-06,0.000992,193.473666,55.90819317611226,2.3103571617583105
4.948572064942676e-06,0.0010111999999999999,197.21831759999998,55.90819317611226,2.3103571617583105
5.046447303568916e-06,0.0010312,201.11899634999997,55.90819317611226,2.3103571617583105
5.11691747537981e-06,0.0010456,203.92748505,55.90819317611226,2.3103571617583105
5.136492523105057e-06,0.0010496,204.70762079999997,55.90819317611226,2.3103571617583105
5.4496932867090234e-06,0.0011136,217.1897928,55.90819317611226,2.3103571617583105
5.496673401249619e-06,0.0011232,219.0621186,55.90819317611226,2.3103571617583105
5.610208678056056e-06,0.0011464,223.58690595,55.90819317611226,2.3103571617583105
5.6806788498669496e-06,0.0011608,226.39539465000001,55.90819317611226,2.3103571617583105
5.723743954862495e-06,0.0011696,228.1116933,55.90819317611226,2.3103571617583105
5.86468429848428e-06,0.0011983999999999999,233.72867069999998,55.90819317611226,2.3103571617583105
5.9938796134709156e-06,0.0012247999999999998,238.87756664999998,55.90819317611226,2.3103571617583105
6.0486897471016105e-06,0.001236,241.06194674999998,55.90819317611226,2.3103571617583105
6.099584871187255e-06,0.0012464,243.09029969999997,55.90819317611226,2.3103571617583105
6.1465649857278496e-06,0.001256,244.9626255,55.90819317611226,2.3103571617583105
6.2444402243540895e-06,0.001276,248.86330425,55.90819317611226,2.3103571617583105
6.424530663426371e-06,0.0013128,256.04055315,55.90819317611226,2.3103571617583105
6.451935730241718e-06,0.0013184,257.1327432,55.90819317611226,2.3103571617583105
6.4950008352372635e-06,0.0013272,258.84904185,55.90819317611226,2.3103571617583105
6.5498109688679576e-06,0.0013384,261.03342195,55.90819317611226,2.3103571617583105
6.5693860165932045e-06,0.0013423999999999999,261.8135577,55.90819317611226,2.3103571617583105
6.643771197949148e-06,0.0013576,264.77807355,55.90819317611226,2.3103571617583105
6.686836302944693e-06,0.0013664,266.4943722,55.90819317611226,2.3103571617583105
6.741646436575386e-06,0.0013775999999999999,268.6787523,55.90819317611226,2.3103571617583105
6.847351694291726e-06,0.0013992,272.89148535,55.90819317611226,2.3103571617583105
6.9413119233729165e-06,0.0014184,276.63613695,55.90819317611226,2.3103571617583105
7.0587622097244034e-06,0.0014424,281.31695145,55.90819317611226,2.3103571617583105
7.0705072383595525e-06,0.0014448,281.7850329,55.90819317611226,2.3103571617583105
7.1683824769857916e-06,0.0014647999999999998,285.68571165,55.90819317611226,2.3103571617583105
7.2114475819813375e-06,0.0014736,287.40201030000003,55.90819317611226,2.3103571617583105
7.28191775379223e-06,0.001488,290.21049899999997,55.90819317611226,2.3103571617583105
7.321067849242726e-06,0.001496,291.77077049999997,55.90819317611226,2.3103571617583105
7.411113068778866e-06,0.0015144,292.27048990823124,55.90819317611226,2.3103571617583105
7.481583240589758e-06,0.0015287999999999999,292.3849111128065,55.90819317611226,2.3103571617583105
7.532478364675403e-06,0.0015392,292.46728740488913,55.90819317611226,2.3103571617583105
7.712568803747684e-06,0.001576,292.7570456603719,55.90819317611226,2.3103571617583105
7.84567912827937e-06,0.0016032,292.9695216461855,55.90819317611226,2.3103571617583105
7.908319281000164e-06,0.001616,293.0690234431399,55.90819317611226,2.3103571617583105
7.998364500536303e-06,0.0016343999999999998,293.2115204567814,55.90819317611226,2.3103571617583105
8.092324729617494e-06,0.0016535999999999999,293.35954754596975,55.90819317611226,2.3103571617583105
8.107984767797693e-06,0.0016568,293.384153412752,55.90819317611226,2.3103571617583105
8.198029987333832e-06,0.0016752,293.5252791131828,55.90819317611226,2.3103571617583105
8.241095092329379e-06,0.001684,293.5925601992586,55.90819317611226,2.3103571617583105
8.268500159144725e-06,0.0016895999999999999,293.6353040528681,55.90819317611226,2.3103571617583105
8.32331029277542e-06,0.0017008,293.7206263663191,55.90819317611226,2.3103571617583105
8.432930560036808e-06,0.0017231999999999998,293.890616443414,55.90819317611226,2.3103571617583105
8.522975779572947e-06,0.0017415999999999998,294.0296073798782,55.90819317611226,2.3103571617583105
8.60127597047394e-06,0.0017576,294.1500042015995,55.90819317611226,2.3103571617583105
8.718726256825427e-06,0.0017816,294.3298010575245,55.90819317611226,2.3103571617583105
8.757876352275923e-06,0.0017896,294.3895231058315,55.90819317611226,2.3103571617583105
8.836176543176916e-06,0.0018055999999999999,294.50865575691176,55.90819317611226,2.3103571617583105
8.922306753168006e-06,0.0018231999999999999,294.6392271524991,55.90819317611226,2.3103571617583105
8.949711819983353e-06,0.0018288,294.6806693863845,55.90819317611226,2.3103571617583105
8.988861915433849e-06,0.0018368,294.73978682837117,55.90819317611226,2.3103571617583105
9.129802259055634e-06,0.0018655999999999998,294.95178318565104,55.90819317611226,2.3103571617583105
9.270742602677419e-06,0.0018943999999999999,295.1625069754643,55.90819317611226,2.3103571617583105
9.305977688582865e-06,0.0019015999999999998,295.21499224793394,55.90819317611226,2.3103571617583105
9.376447860393758e-06,0.001916,295.3197308622203,55.90819317611226,2.3103571617583105
9.44691803220465e-06,0.0019303999999999999,295.42416292251835,55.90819317611226,2.3103571617583105
9.517388204015544e-06,0.0019448,295.52829160287587,55.90819317611226,2.3103571617583105
9.560453309011088e-06,0.0019535999999999998,295.59177778559564,55.90819317611226,2.3103571617583105
9.619178452186834e-06,0.0019656,295.678170407719,55.90819317611226,2.3103571617583105
9.799268891259114e-06,0.0020024,295.94183407171033,55.90819317611226,2.3103571617583105
9.893229120340303e-06,0.0020215999999999997,296.078647129929,55.90819317611226,2.3103571617583105
9.971529311241296e-06,0.0020376,296.1922713342076,55.90819317611226,2.3103571617583105
1.0167279788493774e-05,0.0020775999999999998,296.4748200042337,55.90819317611226,2.3103571617583105
1.020251487439922e-05,0.0020848,296.5254526433696,55.90819317611226,2.3103571617583105
1.0261240017574965e-05,0.0020968,296.6096890897312,55.90819317611226,2.3103571617583105
1.0343455218021006e-05,0.0021135999999999998,296.7273049353088,55.90819317611226,2.3103571617583105
1.0476565542552692e-05,0.0021408,296.916960504918,55.90819317611226,2.3103571617583105
1.0492225580732891e-05,0.002144,296.9392109714615,55.90819317611226,2.3103571617583105
1.0570525771633882e-05,0.00216,297.0502696190254,55.90819317611226,2.3103571617583105
1.0609675867084378e-05,0.002168,297.1056785958658,55.90819317611226,2.3103571617583105
1.0746701201161114e-05,0.002196,297.29898517498276,55.90819317611226,2.3103571617583105
1.0918961621143296e-05,0.0022312,297.5406407488422,55.90819317611226,2.3103571617583105
1.1099052060215576e-05,0.002268,297.7916962344137,55.90819317611226,2.3103571617583105
1.1130372136575973e-05,0.0022743999999999998,297.8351953867062,55.90819317611226,2.3103571617583105
1.1169522232026469e-05,0.0022824,297.88950225492897,55.90819317611226,2.3103571617583105
1.1236077394292312e-05,0.002296,297.981653866942,55.90819317611226,2.3103571617583105
1.134961267109875e-05,0.0023192,298.1383638664695,55.90819317611226,2.3103571617583105
1.1400507795184393e-05,0.0023296,298.2084145919345,55.90819317611226,2.3103571617583105
1.1482722995630435e-05,0.0023464,298.3213163670524,55.90819317611226,2.3103571617583105
1.1502298043355684e-05,0.0023504,298.3481512219628,55.90819317611226,2.3103571617583105
1.1611918310617072e-05,0.0023728,298.49809856263215,55.90819317611226,2.3103571617583105
1.1968184179216584e-05,0.0024456,298.981658445397,55.90819317611226,2.3103571617583105
1.2038654351027477e-05,0.00246,299.0766390514171,55.90819317611226,2.3103571617583105
1.2085634465568071e-05,0.0024695999999999997,299.1398390202718,55.90819317611226,2.3103571617583105
1.2128699570563618e-05,0.0024784,299.19768820659647,55.90819317611226,2.3103571617583105
1.218742471373936e-05,0.0024904,299.2764445278019,55.90819317611226,2.3103571617583105
1.2324450047816098e-05,0.0025184,299.45963595921654,55.90819317611226,2.3103571617583105
1.2367515152811641e-05,0.0025272,299.5170461288998,55.90819317611226,2.3103571617583105
1.2391005210081939e-05,0.002532,299.5483279040374,55.90819317611226,2.3103571617583105
1.2469305400982932e-05,0.002548,299.6524338565579,55.90819317611226,2.3103571617583105
1.2649395840055213e-05,0.0025848,299.8909147994881,55.90819317611226,2.3103571617583105
1.2735526050046303e-05,0.0026024,300.00450249541984,55.90819317611226,2.3103571617583105
1.2966511613204229e-05,0.0026496,300.3076545849988,55.90819317611226,2.3103571617583105
1.2997831689564626e-05,0.002656,300.34859720327495,55.90819317611226,2.3103571617583105
1.3029151765925021e-05,0.0026623999999999997,300.38950136338457,55.90819317611226,2.3103571617583105
1.3115281975916114e-05,0.00268,300.5017905497497,55.90819317611226,2.3103571617583105
1.313485702364136e-05,0.0026839999999999998,300.5272706675294,55.90819317611226,2.3103571617583105
1.3209242204997302e-05,0.0026991999999999997,300.6239603508457,55.90819317611226,2.3103571617583105
1.3291457405443344e-05,0.0027159999999999997,300.7305811766584,55.90819317611226,2.3103571617583105
1.3448057787245328e-05,0.002748,300.9329595928442,55.90819317611226,2.3103571617583105
1.350678293042107e-05,0.00276,301.0086142795178,55.90819317611226,2.3103571617583105
1.351852795905622e-05,0.0027624,301.0237298109795,55.90819317611226,2.3103571617583105
1.3659468302678004e-05,0.0027911999999999998,301.20471852257054,55.90819317611226,2.3103571617583105
1.3698618398128501e-05,0.0027992,301.2548637240771,55.90819317611226,2.3103571617583105
1.3765173560394344e-05,0.0028128,301.3399824841228,55.90819317611226,2.3103571617583105
1.3784748608119593e-05,0.0028168,301.3649868479385,55.90819317611226,2.3103571617583105
1.3933518970831477e-05,0.0028472,301.55456954026494,55.90819317611226,2.3103571617583105
1.3980499085372073e-05,0.0028568,301.61427353229067,55.90819317611226,2.3103571617583105
1.4000074133097318e-05,0.0028607999999999997,301.63912709647553,55.90819317611226,2.3103571617583105
1.4325019925336435e-05,0.0029272,302.0497367522661,55.90819317611226,2.3103571617583105
1.4391575087602278e-05,0.0029408,302.1333875363546,55.90819317611226,2.3103571617583105
1.4418980154417626e-05,0.0029464,302.1677881090288,55.90819317611226,2.3103571617583105
1.4473790288048319e-05,0.0029576,302.2365128522469,55.90819317611226,2.3103571617583105
1.4512940383498814e-05,0.0029655999999999997,302.2855398276887,55.90819317611226,2.3103571617583105
1.457558053621961e-05,0.0029784,302.36387583950517,55.90819317611226,2.3103571617583105
1.4622560650760203e-05,0.0029879999999999998,302.4225417141432,55.90819317611226,2.3103571617583105
1.4634305679395352e-05,0.0029904,302.437196691374,55.90819317611226,2.3103571617583105
1.484180118528298e-05,0.0030328,302.6953497043725,55.90819317611226,2.3103571617583105
1.4865291242553277e-05,0.0030375999999999997,302.72448561184854,55.90819317611226,2.3103571617583105
1.4974911509814667e-05,0.00306,302.86021647240426,55.90819317611226,2.3103571617583105
1.4990571547994864e-05,0.0030632,302.87957491582597,55.90819317611226,2.3103571617583105
1.5053211700715658e-05,0.0030759999999999997,302.95692995017123,55.90819317611226,2.3103571617583105
1.5194152044337443e-05,0.0031048,303.13052124727096,55.90819317611226,2.3103571617583105
1.5221557111152789e-05,0.0031103999999999997,303.1642020632524,55.90819317611226,2.3103571617583105
1.5354667435684475e-05,0.0031376,303.32745939250356,55.90819317611226,2.3103571617583105
1.538990252158992e-05,0.0031447999999999997,303.37058205903503,55.90819317611226,2.3103571617583105
1.550735280794141e-05,0.0031688,303.51404700262657,55.90819317611226,2.3103571617583105
1.5558247932027054e-05,0.0031791999999999996,303.57608347361787,55.90819317611226,2.3103571617583105
1.5726593342464186e-05,0.0032136,303.78071949376624,55.90819317611226,2.3103571617583105
1.5914513800626567e-05,0.0032519999999999997,304.0081439691331,55.90819317611226,2.3103571617583105
1.596540892471221e-05,0.0032624,304.0695575545381,55.90819317611226,2.3103571617583105
1.6114179287424095e-05,0.0032928,304.24863790940816,55.90819317611226,2.3103571617583105
1.6122009306514194e-05,0.0032944,304.25804528950357,55.90819317611226,2.3103571617583105
1.6223799554685485e-05,0.0033152,304.3801795317478,55.90819317611226,2.3103571617583105
1.6333419821946874e-05,0.0033376,304.5113749773005,55.90819317611226,2.3103571617583105
1.6407805003302815e-05,0.0033528,304.6002049473735,55.90819317611226,2.3103571617583105
1.6474360165568656e-05,0.0033664,304.679551352524,55.90819317611226,2.3103571617583105
1.6611385499645393e-05,0.0033943999999999997,304.8425190343155,55.90819317611226,2.3103571617583105
1.6689685690546385e-05,0.0034103999999999996,304.9354080252451,55.90819317611226,2.3103571617583105
1.674841083372213e-05,0.0034224,305.00496327407353,55.90819317611226,2.3103571617583105
1.683845605325827e-05,0.0034408,305.1114302080916,55.90819317611226,2.3103571617583105
1.6885436167798864e-05,0.0034503999999999997,305.16689001509855,55.90819317611226,2.3103571617583105
1.6979396396880053e-05,0.0034695999999999998,305.2776294216778,55.90819317611226,2.3103571617583105
1.7022461501875602e-05,0.0034784,305.32830508560033,55.90819317611226,2.3103571617583105
1.7081186645051344e-05,0.0034904,305.3973277595785,55.90819317611226,2.3103571617583105
1.7163401845497383e-05,0.0035072,305.49380422669685,55.90819317611226,2.3103571617583105
1.7245617045943426e-05,0.003524,305.59010062805913,55.90819317611226,2.3103571617583105
1.7284767141393923e-05,0.003532,305.6358931152169,55.90819317611226,2.3103571617583105
1.732000222729937e-05,0.0035391999999999997,305.6770717797562,55.90819317611226,2.3103571617583105
1.7343492284569666e-05,0.003544,305.70450607363796,55.90819317611226,2.3103571617583105
1.738655738956521e-05,0.0035528,305.75476467165805,55.90819317611226,2.3103571617583105
1.7621457962268188e-05,0.0036008,306.0280525868187,55.90819317611226,2.3103571617583105
1.7684098114988978e-05,0.0036136,306.1006889424262,55.90819317611226,2.3103571617583105
1.786418855406126e-05,0.0036504,306.3089616139991,55.90819317611226,2.3103571617583105
1.7899423639966707e-05,0.0036576,306.3496146647736,55.90819317611226,2.3103571617583105
1.7954233773597402e-05,0.0036688,306.4127907641492,55.90819317611226,2.3103571617583105
1.8005128897683046e-05,0.0036791999999999997,306.4713869689592,55.90819317611226,2.3103571617583105
1.804819400267859e-05,0.003688,306.52091793594576,55.90819317611226,2.3103571617583105
1.8095174117219187e-05,0.0036975999999999997,306.57489917912056,55.90819317611226,2.3103571617583105
1.8122579184034534e-05,0.0037032,306.6063629960843,55.90819317611226,2.3103571617583105
1.8193049355845427e-05,0.0037175999999999997,306.6871848660282,55.90819317611226,2.3103571617583105
1.8236114460840972e-05,0.0037264,306.7365159073294,55.90819317611226,2.3103571617583105
1.8294839604016714e-05,0.0037384,306.80371235219656,55.90819317611226,2.3103571617583105
1.8404459871278104e-05,0.0037608,306.92892107378157,55.90819317611226,2.3103571617583105
1.851799514808454e-05,0.003784,307.058295303922,55.90819317611226,2.3103571617583105
1.853757019580979e-05,0.0037879999999999997,307.0805699034267,55.90819317611226,2.3103571617583105
1.8690255568066725e-05,0.0038192,307.25399805951537,55.90819317611226,2.3103571617583105
1.8886006045319202e-05,0.0038591999999999997,307.4755356911159,55.90819317611226,2.3103571617583105
1.9030861398486038e-05,0.0038888,307.63889743958333,55.90819317611226,2.3103571617583105
1.9281422009369213e-05,0.00394,307.9203288387823,55.90819317611226,2.3103571617583105
1.9347977171635054e-05,0.0039536,307.99484384944117,55.90819317611226,2.3103571617583105
1.9398872295720698e-05,0.003964,308.0517584847875,55.90819317611226,2.3103571617583105
1.9473257477076638e-05,0.0039792,308.13483677032013,55.90819317611226,2.3103571617583105
1.950066254389199e-05,0.0039848,308.1654133495138,55.90819317611226,2.3103571617583105
1.9571132715702878e-05,0.0039992,308.24396198620065,55.90819317611226,2.3103571617583105
2.0608816998995773e-05,0.00421124224844969,309.3881243593808,55.90819317611226,2.3103571617583105
2.4837873118873303e-05,0.005075415083016604,313.83564851573004,55.90819317611226,2.3103571617583105
2.596562141750731e-05,0.0053058611722344474,314.97037953555537,55.90819317611226,2.3103571617583105
2.7093369716141318e-05,0.005536307261452291,316.0860445413757,55.90819317611226,2.3103571617583105
2.8127138989889155e-05,0.00574754950990198,317.09292548782395,55.90819317611226,2.3103571617583105
3.038263558715717e-05,0.0062084416883376676,319.2409604113236,55.90819317611226,2.3103571617583105
3.3108027308856025e-05,0.006765353070614123,321.755186584835,55.90819317611226,2.3103571617583105
3.395383853283153e-05,0.006938187637527506,322.5188712958178,55.90819317611226,2.3103571617583105
3.771299952827822e-05,0.00770634126825365,325.8270181718776,55.90819317611226,2.3103571617583105
3.9028705876684564e-05,0.007975195039007801,326.9541329596162,55.90819317611226,2.3103571617583105
3.9874517100660066e-05,0.008148029605921184,327.67088825438736,55.90819317611226,2.3103571617583105
4.194205564815575e-05,0.008570514102820564,329.3984376931307,55.90819317611226,2.3103571617583105
4.400959419565143e-05,0.008992998599719944,331.0930762619246,55.90819317611226,2.3103571617583105
4.701692299200878e-05,0.00960752150430086,333.5035820250397,55.90819317611226,2.3103571617583105
4.8520587390187464e-05,0.009914782956591319,334.68622243924267,55.90819317611226,2.3103571617583105
4.946037763904913e-05,0.010106821364272855,335.41811811843434,55.90819317611226,2.3103571617583105
5.284362253495115e-05,0.010798159631926384,338.00918219054154,55.90819317611226,2.3103571617583105
5.509911913221917e-05,0.011259051810362072,339.7006890927183,55.90819317611226,2.3103571617583105
5.697869962994251e-05,0.011643128625725144,341.0897433253743,55.90819317611226,2.3103571617583105
5.8952259152552026e-05,0.01204640928185637,342.5291507276131,55.90819317611226,2.3103571617583105
5.96101123267552e-05,0.012180836167233446,343.0047605410877,55.90819317611226,2.3103571617583105
6.054990257561687e-05,0.012372874574914983,343.68066739726817,55.90819317611226,2.3103571617583105
6.205356697379555e-05,0.01268013602720544,344.75366968946577,55.90819317611226,2.3103571617583105
6.741037139230709e-05,0.013774754950990198,348.4964546749234,55.90819317611226,2.3103571617583105
6.778628749185175e-05,0.013851570314062813,348.7546654800536,55.90819317611226,2.3103571617583105
6.928995189003043e-05,0.014158831766353271,349.7819725926188,55.90819317611226,2.3103571617583105
7.229728068638779e-05,0.014773354670934187,351.8108655197926,55.90819317611226,2.3103571617583105
7.530460948274514e-05,0.015387877575515104,353.8070986654034,55.90819317611226,2.3103571617583105
7.615042070672065e-05,0.015560712142428487,354.3629055611598,55.90819317611226,2.3103571617583105
7.690225290580999e-05,0.015714342868573716,354.8549380906761,55.90819317611226,2.3103571617583105
7.878183340353334e-05,0.01609841968393679,356.0768821092189,55.90819317611226,2.3103571617583105
7.953366560262267e-05,0.016252050410082017,356.5624696933021,55.90819317611226,2.3103571617583105
8.254099439898001e-05,0.01686657331466293,358.48718027654894,55.90819317611226,2.3103571617583105
8.554832319533737e-05,0.017481096219243847,360.3847281283093,55.90819317611226,2.3103571617583105
8.601821831976822e-05,0.017577115423084617,360.67885345810157,55.90819317611226,2.3103571617583105
8.620617636954055e-05,0.017615523104620924,360.7963280549964,55.90819317611226,2.3103571617583105
8.864963101658089e-05,0.01811482296459292,362.3145198091837,55.90819317611226,2.3103571617583105
9.193889688759674e-05,0.018786957391478294,364.3327130304778,55.90819317611226,2.3103571617583105
9.381847738532009e-05,0.019171034206841367,365.47331965497034,55.90819317611226,2.3103571617583105
9.457030958440943e-05,0.019324664932986596,365.92706270262426,55.90819317611226,2.3103571617583105
9.720172228122212e-05,0.019862372474494898,367.5042018278397,55.90819317611226,2.3103571617583105
9.78595754554253e-05,0.019996799359871975,367.8958738903031,55.90819317611226,2.3103571617583105
9.84234496047423e-05,0.020112022404480897,368.2307762023703,55.90819317611226,2.3103571617583105
0.000103310358898823,0.021110622124424886,371.10257181584404,55.90819317611226,2.3103571617583105
0.00010453208622234317,0.02136027205441088,371.8121809457889,55.90819317611226,2.3103571617583105
0.00010612972964540802,0.021686737347469495,372.735269887556,55.90819317611226,2.3103571617583105
0.00010650564574495269,0.02176355271054211,372.95167778374173,55.90819317611226,2.3103571617583105
0.00010866716331733453,0.02220524104820964,374.19029055891656,55.90819317611226,2.3103571617583105
0.00010951297454131004,0.022378075615123026,374.6723449105605,55.90819317611226,2.3103571617583105
0.00010988889064085472,0.02245489097819564,374.8861249853884,55.90819317611226,2.3103571617583105
0.00011129857601414722,0.022742948589717944,375.6852727581691,55.90819317611226,2.3103571617583105
0.00011383600968607375,0.023261452290458094,377.1138611774057,55.90819317611226,2.3103571617583105
0.0001150577370095939,0.02351110222044409,377.797266063381,55.90819317611226,2.3103571617583105
0.00011740721263174809,0.02399119823964793,379.1036037039198,55.90819317611226,2.3103571617583105
0.00011909883507969909,0.024336867373474694,380.03786181283226,55.90819317611226,2.3103571617583105
0.00011985066727878843,0.024490498099619923,380.4514249544692,55.90819317611226,2.3103571617583105
0.0001202265833783331,0.024567313462692537,380.6578270181632,55.90819317611226,2.3103571617583105
0.00012154228972673945,0.02483616723344669,381.37826050007914,55.90819317611226,2.3103571617583105
0.00012379778632400746,0.025297059411882376,382.6062529201536,55.90819317611226,2.3103571617583105
0.00012671113609547866,0.02589237847569514,384.1795719468558,55.90819317611226,2.3103571617583105
0.00012812082146877117,0.026180436087217443,384.93578519886864,55.90819317611226,2.3103571617583105
0.00012953050684206367,0.02646849369873975,385.68876035014637,55.90819317611226,2.3103571617583105
0.0001300004019664945,0.026564512902580516,385.9390409746825,55.90819317611226,2.3103571617583105
0.00013479333223568904,0.027543908781756353,388.47206827173227,55.90819317611226,2.3103571617583105
0.0001372367868827294,0.028043208641728348,389.7498795833063,55.90819317611226,2.3103571617583105
0.00013761270298227407,0.028120024004800962,389.9456756130662,55.90819317611226,2.3103571617583105
0.00014146584300260692,0.02890738147629526,391.9407030009008,55.90819317611226,2.3103571617583105
0.0001421236961768101,0.029041808361672333,392.2791883781434,55.90819317611226,2.3103571617583105
0.0001449430669233951,0.029617923584716942,393.72297344345714,55.90819317611226,2.3103571617583105
0.00014588285717225677,0.02980996199239848,394.2017957070485,55.90819317611226,2.3103571617583105
0.00014766845864509396,0.0301748349669934,395.1082567032752,55.90819317611226,2.3103571617583105
0.0001487022279188418,0.030386077215443088,395.63109604324245,55.90819317611226,2.3103571617583105
0.00015152159866542683,0.030962192438487697,397.0498658761322,55.90819317611226,2.3103571617583105
0.00015227343086451615,0.031115823164632926,397.42646092807587,55.90819317611226,2.3103571617583105
0.00015293128403871933,0.03125025005001,397.7553871377198,55.90819317611226,2.3103571617583105
0.00015518678063598736,0.03171114222844569,398.87896841213774,55.90819317611226,2.3103571617583105
0.0001570663611337107,0.03209521904380876,399.81042924966016,55.90819317611226,2.3103571617583105
0.00015894594163143406,0.032479295859171836,400.7375529189227,55.90819317611226,2.3103571617583105
0.00016016766895495422,0.03272894578915783,401.3378912738288,55.90819317611226,2.3103571617583105
0.00016157735432824672,0.03301700340068014,402.028374665175,55.90819317611226,2.3103571617583105
0.00016261112360199456,0.03322824564912982,402.5332368831702,55.90819317611226,2.3103571617583105
0.00016467866214949024,0.033650730146029206,403.5392217131253,55.90819317611226,2.3103571617583105
0.0001670281377716444,0.034130826165233046,404.67642632522484,55.90819317611226,2.3103571617583105
0.0001678739489956199,0.034303660732146427,405.08429057303135,55.90819317611226,2.3103571617583105
0.0001716331099910666,0.03507181436287257,406.88741047934315,55.90819317611226,2.3103571617583105
0.00017276085828970064,0.03530226045209042,407.42533438958145,55.90819317611226,2.3103571617583105
0.00017529829196162718,0.03582076415283057,408.6306811338167,55.90819317611226,2.3103571617583105
0.00017670797733491966,0.03610882176435287,409.2973774787376,55.90819317611226,2.3103571617583105
0.00017915143198196,0.03660812162432486,410.4480915989521,55.90819317611226,2.3103571617583105
0.0001811249915045695,0.03701140228045609,411.37305241394995,55.90819317611226,2.3103571617583105
0.00018272263492763438,0.037337867573514705,412.11895462775834,55.90819317611226,2.3103571617583105
0.00018488415250001618,0.03777955591118223,413.1240805195862,55.90819317611226,2.3103571617583105
0.0001868577120226257,0.03818283656731346,414.03780880140704,55.90819317611226,2.3103571617583105
0.00019174462131670643,0.039181436287257454,416.284323379365,55.90819317611226,2.3103571617583105
0.00019475195011306378,0.03979595919183837,417.65569890142933,55.90819317611226,2.3103571617583105
0.0001951278662126084,0.03987277455491098,417.8265382376725,55.90819317611226,2.3103571617583105
0.00019587969841169776,0.04002640528105621,418.16783232226754,55.90819317611226,2.3103571617583105
0.0001969134676854456,0.0402376475295059,418.6362786816289,55.90819317611226,2.3103571617583105
0.00019963885940714446,0.04079455891178235,419.86669900638725,55.90819317611226,2.3103571617583105
0.00020358597845236353,0.041601120224044816,421.6371359116894,55.90819317611226,2.3103571617583105
0.00020433781065145289,0.041754750950190045,421.97283884696304,55.90819317611226,2.3103571617583105
0.00020527760090031453,0.04194678935787158,422.3917908732736,55.90819317611226,2.3103571617583105
0.00020941267799530586,0.04279175835167033,424.2263643733107,55.90819317611226,2.3103571617583105
0.00021195011166723237,0.04331026205241048,425.34513258472896,55.90819317611226,2.3103571617583105
0.00021523937753824824,0.04398239647929586,426.78764378563176,55.90819317611226,2.3103571617583105
0.0002156152936377929,0.04405921184236847,426.9519529731486,55.90819317611226,2.3103571617583105
0.00021740089511063007,0.04442408481696339,427.7309010284902,55.90819317611226,2.3103571617583105
0.00022256974147936932,0.04548029605921185,429.9718073740983,55.90819317611226,2.3103571617583105
0.00022285167855402784,0.04553790758151631,430.0934515675919,55.90819317611226,2.3103571617583105
0.00022858439907208402,0.04670934186837368,432.55401440987674,55.90819317611226,2.3103571617583105
0.00023290743421684767,0.04759271854370874,434.3936345194973,55.90819317611226,2.3103571617583105
0.00023394120349059554,0.04780396079215843,434.8315648665856,55.90819317611226,2.3103571617583105
0.00023441109861502634,0.047899979995999195,435.03037455648655,55.90819317611226,2.3103571617583105
0.00023657261618740825,0.04834166833366674,435.94290467244946,55.90819317611226,2.3103571617583105
0.00023939198693399323,0.048917783556711336,437.1282894801703,55.90819317611226,2.3103571617583105
0.00024042575620774107,0.04912902580516103,437.56156479854707,55.90819317611226,2.3103571617583105
0.00024437287525296014,0.04993558711742349,439.2092482978325,55.90819317611226,2.3103571617583105
0.00024831999429817916,0.05074214842968594,440.84658464183394,55.90819317611226,2.3103571617583105
0.00024954172162169934,0.050991798359671936,441.35131801855266,55.90819317611226,2.3103571617583105
0.00025207915529362583,0.051510302060412086,442.3965414191457,55.90819317611226,2.3103571617583105
0.0002525490504180567,0.05160632126425285,442.5896501840749,55.90819317611226,2.3103571617583105
0.00025405271481623534,0.05191358271654331,443.20665869834653,55.90819317611226,2.3103571617583105
0.000254992505065097,0.052105621124224843,443.5915658612291,55.90819317611226,2.3103571617583105
0.0002564021904383896,0.05239367873574716,444.1678908798966,55.90819317611226,2.3103571617583105
0.00025790585483656824,0.052700940188037615,444.78127717065144,55.90819317611226,2.3103571617583105
0.00025940951923474694,0.05300820164032807,445.3932703120877,55.90819317611226,2.3103571617583105
0.0002617589948569011,0.053488297659531905,446.3467471793142,55.90819317611226,2.3103571617583105
0.0002626048060808766,0.05366113222644529,446.6891810371565,55.90819317611226,2.3103571617583105
0.0002662699880514371,0.05441008201640328,448.1681181716392,55.90819317611226,2.3103571617583105
0.00026767967342472955,0.05469813962792558,448.73482344082447,55.90819317611226,2.3103571617583105
0.00027190872954460714,0.055562312462492505,450.4279964959749,55.90819317611226,2.3103571617583105
0.0002759498276147123,0.0563880776155231,452.0363471367668,55.90819317611226,2.3103571617583105
0.0002781113451870942,0.05682976595319064,452.89285580936956,55.90819317611226,2.3103571617583105
0.0002796150095852729,0.0571370274054811,453.4871573469802,55.90819317611226,2.3103571617583105
0.00028093071593367924,0.057405881176235254,454.006149492723,55.90819317611226,2.3103571617583105
0.00028290427545628875,0.05780916183236648,454.78286383944607,55.90819317611226,2.3103571617583105
0.00028318621253094726,0.05786677335467094,454.89365028306776,55.90819317611226,2.3103571617583105
0.0002854417091282152,0.058327665533106615,455.77839852751714,55.90819317611226,2.3103571617583105
0.00028732128962593857,0.058711742348469695,456.51360788722144,55.90819317611226,2.3103571617583105
0.00028967076524809277,0.05919183836767354,457.4299871770989,55.90819317611226,2.3103571617583105
0.00029249013599467777,0.05976795359071814,458.52582486579,55.90819317611226,2.3103571617583105
0.00029408777941774265,0.06009441888377676,459.1449708032075,55.90819317611226,2.3103571617583105
0.00029624929699012444,0.060536107221444285,459.9805549271334,55.90819317611226,2.3103571617583105
0.00029747102431364463,0.06078575715143028,460.45178979037865,55.90819317611226,2.3103571617583105
0.0002980348984629616,0.060900980196039206,460.6690281693877,55.90819317611226,2.3103571617583105
0.0003019820175081806,0.061707541508301655,462.18523366635765,55.90819317611226,2.3103571617583105
0.00030245191263261154,0.061803560712142436,462.365218049251,55.90819317611226,2.3103571617583105
0.000303861598005904,0.062091618323664735,462.90451800726953,55.90819317611226,2.3103571617583105
0.00030611709460317204,0.06255251050210042,463.7653727968994,55.90819317611226,2.3103571617583105
0.0003073388219266922,0.06280216043208642,464.23063614216426,55.90819317611226,2.3103571617583105
0.0003089364653497571,0.06312862572514504,464.8379705309873,55.90819317611226,2.3103571617583105
0.0003103461507230496,0.06341668333666733,465.37283732534706,55.90819317611226,2.3103571617583105
0.0003110979829221389,0.06357031406281256,465.6577121490789,55.90819317611226,2.3103571617583105
0.00031419929074338247,0.06420404080816164,466.82999388188034,55.90819317611226,2.3103571617583105
0.0003161728502659919,0.06460732146429286,467.5736423472776,55.90819317611226,2.3103571617583105
0.00031645478734065044,0.06466493298659733,467.67972987310276,55.90819317611226,2.3103571617583105
0.0003170186614899674,0.06478015603120624,467.8917944059425,55.90819317611226,2.3103571617583105
0.0003190862000374631,0.06520264052810562,468.6681089770998,55.90819317611226,2.3103571617583105
0.0003227513820080236,0.06595159031806361,470.0394987991214,55.90819317611226,2.3103571617583105
0.0003249128995804055,0.06639327865573115,470.8454201010593,55.90819317611226,2.3103571617583105
0.00032594666885415335,0.06660452090418084,471.2301213362378,55.90819317611226,2.3103571617583105
0.0003272623752025597,0.066873374674935,471.7190535839757,55.90819317611226,2.3103571617583105
0.00032829614447630755,0.06708461692338469,472.10267703885097,55.90819317611226,2.3103571617583105
0.00032998776692425854,0.06743028605721145,472.72940986392746,55.90819317611226,2.3103571617583105
0.0003307395991233479,0.06758391678335668,473.00755545739844,55.90819317611226,2.3103571617583105
0.0003318673474219819,0.06781436287257452,473.42431194284694,55.90819317611226,2.3103571617583105
0.00033346499084504675,0.06814082816563313,474.0137727331979,55.90819317611226,2.3103571617583105
0.00033703619379072113,0.06887057411482297,475.3274229040333,55.90819317611226,2.3103571617583105
0.0003387278162386721,0.06921624324864974,475.9477825213994,55.90819317611226,2.3103571617583105
0.00034107729186082627,0.06969633926785357,476.80739239132635,55.90819317611226,2.3103571617583105
0.00034342676748298046,0.07017643528705741,477.66469601856613,55.90819317611226,2.3103571617583105
0.0003439906416322975,0.07029165833166634,477.87010816115327,55.90819317611226,2.3103571617583105
0.00034483645285627294,0.07046449289857971,478.17798032453265,55.90819317611226,2.3103571617583105
0.0003464340962793378,0.07079095819163833,478.75871429460864,55.90819317611226,2.3103571617583105
0.0003473738865281995,0.07098299659931986,479.09983461360247,55.90819317611226,2.3103571617583105
0.00034774980262774417,0.07105981196239249,479.2361819408977,55.90819317611226,2.3103571617583105
0.0003496293831254675,0.07144388877775555,479.9170582436769,55.90819317611226,2.3103571617583105
0.00035094508947387386,0.0717127425485097,480.39282252640874,55.90819317611226,2.3103571617583105
0.00035291864899648337,0.07211602320464093,481.10516672806904,55.90819317611226,2.3103571617583105
0.00035385843924534504,0.07230806161232246,481.4438320667146,55.90819317611226,2.3103571617583105
0.00035836943243988103,0.07322984596919384,483.0645679826442,55.90819317611226,2.3103571617583105
0.0003623165514851001,0.0740364072814563,484.47619622611813,55.90819317611226,2.3103571617583105
0.0003635382788086203,0.0742860572114423,484.9119116099562,55.90819317611226,2.3103571617583105
0.0003639141949081649,0.0743628725745149,485.0458629427823,55.90819317611226,2.3103571617583105
0.00036880110420224566,0.0753614722944589,486.78234851400214,55.90819317611226,2.3103571617583105
0.00037340607642166783,0.07630246049209842,488.4104580595607,55.90819317611226,2.3103571617583105
0.0003755675939940497,0.07674414882976596,489.17197058184496,55.90819317611226,2.3103571617583105
0.00037772911156643154,0.07718583716743349,489.93177573327523,55.90819317611226,2.3103571617583105
0.0003813003145121059,0.07791558311662333,491.1834013621035,55.90819317611226,2.3103571617583105
0.0003822401047609676,0.07810762152430487,491.5120156241357,55.90819317611226,2.3103571617583105
0.0003827099998853984,0.07820364072814563,491.6762045826566,55.90819317611226,2.3103571617583105
0.0003849654964826664,0.07866453290658132,492.4632197950586,55.90819317611226,2.3103571617583105
0.00038693905600527593,0.07906781356271254,493.15038409326536,55.90819317611226,2.3103571617583105
0.00038985240577674716,0.07966313262652532,494.16227653985817,55.90819317611226,2.3103571617583105
0.0003909801540753811,0.07989357871574315,494.55318456141214,55.90819317611226,2.3103571617583105
0.00039323565067264914,0.08035447089417884,495.33368387802057,55.90819317611226,2.3103571617583105
0.0003937995248219662,0.08046969393878776,495.52853566629864,55.90819317611226,2.3103571617583105
0.0003950212521454863,0.08071934386877376,495.95034164833896,55.90819317611226,2.3103571617583105
0.00039784062289207136,0.08129545909181837,496.9218030579668,55.90819317611226,2.3103571617583105
0.00039878041314093303,0.0814874974994999,497.245026391735,55.90819317611226,2.3103571617583105
0.00040169376291240415,0.08208281656331266,498.24513599556474,55.90819317611226,2.3103571617583105
0.00040338538536035525,0.08242848569713944,498.8245466460088,55.90819317611226,2.3103571617583105
0.0004057348609825094,0.08290858171634327,499.6277140673513,55.90819317611226,2.3103571617583105
0.00040705056733091575,0.08317743548709743,500.07669549359974,55.90819317611226,2.3103571617583105
0.0004081783156295497,0.08340788157631526,500.46108642634425,55.90819317611226,2.3103571617583105
0.0004102458541770454,0.08383036607321465,501.1647291131885,55.90819317611226,2.3103571617583105
0.0004105277912517039,0.08388797759551911,501.26057312265,55.90819317611226,2.3103571617583105
0.0004116555395503379,0.08411842368473695,501.64369273158394,55.90819317611226,2.3103571617583105
0.0004143809312720368,0.08467533506701341,502.56787912336677,55.90819317611226,2.3103571617583105
0.0004157906166453293,0.08496339267853571,503.04497619823997,55.90819317611226,2.3103571617583105
0.00041663642786930483,0.0851362272454491,503.3309316497091,55.90819317611226,2.3103571617583105
0.00041691836494396324,0.08519383876775355,503.42619981044646,55.90819317611226,2.3103571617583105
0.00041738826006839416,0.08528985797159433,503.58492426305764,55.90819317611226,2.3103571617583105
0.000418985903491459,0.08561632326465293,504.124066887549,55.90819317611226,2.3103571617583105
0.00042086548398918237,0.08600040008001601,504.7573269219926,55.90819317611226,2.3103571617583105
0.0004217112952131578,0.08617323464692939,505.04193399610614,55.90819317611226,2.3103571617583105
0.0004252824981588322,0.08690298059611923,506.2411622348727,55.90819317611226,2.3103571617583105
0.00042706809963166935,0.08726785357071415,506.8393031199549,55.90819317611226,2.3103571617583105
0.00042810186890541725,0.08747909581916384,507.1851494182566,55.90819317611226,2.3103571617583105
0.000429699512328482,0.08780556111222244,507.71899920013146,55.90819317611226,2.3103571617583105
0.0004309212396520022,0.08805521104220844,508.12671511595215,55.90819317611226,2.3103571617583105
0.00043251888307506707,0.08838167633526706,508.65920250752816,55.90819317611226,2.3103571617583105
0.0004351502957718798,0.08891938387677537,509.53457139507884,55.90819317611226,2.3103571617583105
0.00043655998114517226,0.08920744148829766,510.0026696888236,55.90819317611226,2.3103571617583105
0.0004391913938419849,0.08974514902980596,510.87487897049266,55.90819317611226,2.3103571617583105
0.00044060107921527745,0.09003320664132827,511.34129547145,55.90819317611226,2.3103571617583105
0.0004428565758125455,0.09049409881976396,512.0863531600527,55.90819317611226,2.3103571617583105
0.0004434204499618625,0.09060932186437289,512.2723861669516,55.90819317611226,2.3103571617583105
0.0004447361563102688,0.09087817563512703,512.7061047579977,55.90819317611226,2.3103571617583105
0.00044576992558401665,0.09108941788357672,513.0465326943623,55.90819317611226,2.3103571617583105
0.0004466157368079922,0.0912622524504901,513.3248356880953,55.90819317611226,2.3103571617583105
0.0004485892963306017,0.09166553310662133,513.973411197867,55.90819317611226,2.3103571617583105
0.0004495290865794633,0.09185757151430286,514.2818654672037,55.90819317611226,2.3103571617583105
0.00045300631050025153,0.09256811362272455,515.4209660987109,55.90819317611226,2.3103571617583105
0.0004542280378237717,0.09281776355271054,515.8203804503139,55.90819317611226,2.3103571617583105
0.00045620159734638117,0.09322104420884177,516.464704333721,55.90819317611226,2.3103571617583105
0.0004585510729685354,0.09370114022804561,517.2303409076248,55.90819317611226,2.3103571617583105
0.00046127646469023426,0.09425805161032207,518.1165652701633,55.90819317611226,2.3103571617583105
0.00046541154178522567,0.09510302060412083,519.4572918443149,55.90819317611226,2.3103571617583105
0.000466163373984315,0.09525665133026606,519.7005603666993,55.90819317611226,2.3103571617583105
0.00046729112228294895,0.0954870974194839,520.0651764446905,55.90819317611226,2.3103571617583105
0.00047114426230328185,0.0962744548909782,521.3083668601234,55.90819317611226,2.3103571617583105
0.0004738696540249807,0.09683136627325466,522.1853036007254,55.90819317611226,2.3103571617583105
0.0004744335281742977,0.09694658931786358,522.366492962139,55.90819317611226,2.3103571617583105
0.0004755612764729317,0.09717703540708142,522.7286199254141,55.90819317611226,2.3103571617583105
0.00047800473111997204,0.09767633526705341,523.5120814078674,55.90819317611226,2.3103571617583105
0.0004792264584434922,0.0979259851970394,523.9032263236144,55.90819317611226,2.3103571617583105
0.0004824217452896219,0.09857891578315664,524.9243864862058,55.90819317611226,2.3103571617583105
0.00048542907408597927,0.09919343868773756,525.8830714453292,55.90819317611226,2.3103571617583105
0.0004864628433597271,0.09940468093618725,526.2120840696442,55.90819317611226,2.3103571617583105
0.0004875905916583611,0.09963512702540508,526.5706961000164,55.90819317611226,2.3103571617583105
0.0004877785497081334,0.09967353470694139,526.630433308461,55.90819317611226,2.3103571617583105
0.0004885303819072228,0.09982716543308662,526.8692924236,55.90819317611226,2.3103571617583105
0.0004888123189818813,0.09988477695539108,526.958827625726,55.90819317611226,2.3103571617583105