File: datasets/aisi_316_L/data/M1/train_14.csv
Time(s),Strain(%),Stress(MPa),Temp(C),Log_SR(s-1)
0.0,0.0,0.0,54.420063907163126,-2.7808992544165907
0.004347421520209918,7.2e-06,1.404568125,54.420063907163126,-2.7808992544165907
0.013042264560629756,2.16e-05,4.213704375,54.420063907163126,-2.7808992544165907
0.018355779751997436,3.04e-05,5.93039875,54.420063907163126,-2.7808992544165907
0.024635388614522868,4.0799999999999996e-05,7.959219374999999,54.420063907163126,-2.7808992544165907
0.03284718481936383,5.4399999999999994e-05,10.612292499999999,54.420063907163126,-2.7808992544165907
0.039609840517468145,6.56e-05,12.79717625,54.420063907163126,-2.7808992544165907
0.04588944937999358,7.599999999999999e-05,14.825996874999998,54.420063907163126,-2.7808992544165907
0.05410124558483454,8.96e-05,17.47907,54.420063907163126,-2.7808992544165907
0.07294007217241086,0.0001208,23.565531874999998,54.420063907163126,-2.7808992544165907
0.07390616584356861,0.0001224,23.877658125,54.420063907163126,-2.7808992544165907
0.08260100888398844,0.0001368,26.686794374999998,54.420063907163126,-2.7808992544165907
0.09709241395135484,0.0001608,31.368688125000002,54.420063907163126,-2.7808992544165907
0.10723639749851131,0.00017759999999999998,34.646013749999995,54.420063907163126,-2.7808992544165907
0.12317694307261436,0.000204,39.796096874999996,54.420063907163126,-2.7808992544165907
0.1362192076332441,0.00022559999999999998,44.009801249999995,54.420063907163126,-2.7808992544165907
0.14249881649576954,0.000236,46.038621875,54.420063907163126,-2.7808992544165907
0.15892240890545148,0.0002632,51.344768125,54.420063907163126,-2.7808992544165907
0.16037154941218812,0.0002656,51.8129575,54.420063907163126,-2.7808992544165907
0.1623037367545036,0.0002688,52.43720999999999,54.420063907163126,-2.7808992544165907
0.17631209498629113,0.000292,56.963040625,54.420063907163126,-2.7808992544165907
0.18307475068439547,0.0003032,59.147924375,54.420063907163126,-2.7808992544165907
0.20722709246333945,0.0003432,66.951080625,54.420063907163126,-2.7808992544165907
0.2154388886681804,0.0003568,69.60415375,54.420063907163126,-2.7808992544165907
0.21640498233933816,0.0003584,69.91628,54.420063907163126,-2.7808992544165907
0.22123545069512696,0.00036639999999999996,71.47691124999999,54.420063907163126,-2.7808992544165907
0.22558287221533688,0.0003736,72.881479375,54.420063907163126,-2.7808992544165907
0.23137943424228344,0.0003832,74.754236875,54.420063907163126,-2.7808992544165907
0.2424895114605977,0.0004016,78.34368875,54.420063907163126,-2.7808992544165907
0.24780302665196535,0.0004104,80.060383125,54.420063907163126,-2.7808992544165907
0.26422661906164724,0.00043759999999999996,85.36652937499998,54.420063907163126,-2.7808992544165907
0.2671249000751205,0.00044239999999999997,86.30290812499999,54.420063907163126,-2.7808992544165907
0.2729214621020671,0.000452,88.175665625,54.420063907163126,-2.7808992544165907
0.2792010709645925,0.00046239999999999996,90.20448624999999,54.420063907163126,-2.7808992544165907
0.29031114818290676,0.0004808,93.793938125,54.420063907163126,-2.7808992544165907
0.31204825578395634,0.0005168,100.81677875,54.420063907163126,-2.7808992544165907
0.31881091148206064,0.0005279999999999999,103.00166249999998,54.420063907163126,-2.7808992544165907
0.3352345038917426,0.0005551999999999999,108.30780874999999,54.420063907163126,-2.7808992544165907
0.3473106747812146,0.0005752,112.20938687499999,54.420063907163126,-2.7808992544165907
0.35165809630142447,0.0005824,113.61395499999999,54.420063907163126,-2.7808992544165907
0.3671155950399486,0.0006079999999999999,118.60797499999998,54.420063907163126,-2.7808992544165907
0.3700138760534219,0.0006127999999999999,119.54435374999998,54.420063907163126,-2.7808992544165907
0.38112395327173615,0.0006312,123.133805625,54.420063907163126,-2.7808992544165907
0.38885270264099825,0.0006439999999999999,125.63081562499998,54.420063907163126,-2.7808992544165907
0.4028610608727858,0.0006672,130.15664625,54.420063907163126,-2.7808992544165907
0.4149372317622578,0.0006872,134.058224375,54.420063907163126,-2.7808992544165907
0.4216998874603621,0.0006984,136.243108125,54.420063907163126,-2.7808992544165907
0.4376404330344651,0.0007247999999999999,141.39319125,54.420063907163126,-2.7808992544165907
0.4526148849374104,0.0007496,146.231148125,54.420063907163126,-2.7808992544165907
0.4598605874710936,0.0007616,148.572095,54.420063907163126,-2.7808992544165907
0.4714537115249867,0.0007808,152.31761,54.420063907163126,-2.7808992544165907
0.47290285203172333,0.0007832,152.78579937499998,54.420063907163126,-2.7808992544165907
0.4758011330451966,0.000788,153.722178125,54.420063907163126,-2.7808992544165907
0.4854620697567742,0.0008039999999999999,156.84344062499997,54.420063907163126,-2.7808992544165907
0.48691121026351086,0.0008064,157.31163,54.420063907163126,-2.7808992544165907
0.5004365216597195,0.0008288,161.6813975,54.420063907163126,-2.7808992544165907
0.5134787862203493,0.0008504,165.895101875,54.420063907163126,-2.7808992544165907
0.522656676096348,0.0008656,168.86030125,54.420063907163126,-2.7808992544165907
0.5376311279992932,0.0008904,173.698258125,54.420063907163126,-2.7808992544165907
0.5453598773685553,0.0009031999999999999,176.19526812499998,54.420063907163126,-2.7808992544165907
0.5550208140801329,0.0009192,179.316530625,54.420063907163126,-2.7808992544165907
0.5661308912984471,0.0009375999999999999,182.9059825,54.420063907163126,-2.7808992544165907
0.5960797951043377,0.0009872,192.58189625,54.420063907163126,-2.7808992544165907
0.6226473710611761,0.0010312,201.165368125,54.420063907163126,-2.7808992544165907
0.6298930735948594,0.0010432,203.506315,54.420063907163126,-2.7808992544165907
0.6323083077727536,0.0010471999999999999,204.286630625,54.420063907163126,-2.7808992544165907
0.6332744014439114,0.0010488,204.598756875,54.420063907163126,-2.7808992544165907
0.6400370571420158,0.00106,206.783640625,54.420063907163126,-2.7808992544165907
0.6559776027161188,0.0010864,211.93372374999998,54.420063907163126,-2.7808992544165907
0.6598419774007498,0.0010927999999999999,213.18222874999998,54.420063907163126,-2.7808992544165907
0.6622572115786443,0.0010968,213.962544375,54.420063907163126,-2.7808992544165907
0.667570726770012,0.0011056,215.67923875,54.420063907163126,-2.7808992544165907
0.6728842419613796,0.0011144,217.395933125,54.420063907163126,-2.7808992544165907
0.683028225508536,0.0011312,220.67325875,54.420063907163126,-2.7808992544165907
0.6878586938643249,0.0011392,222.23388999999997,54.420063907163126,-2.7808992544165907
0.6941383027268503,0.0011496,224.26271062499998,54.420063907163126,-2.7808992544165907
0.6970365837403235,0.0011543999999999999,225.19908937499997,54.420063907163126,-2.7808992544165907
0.7042822862740068,0.0011664,227.54003624999999,54.420063907163126,-2.7808992544165907
0.719256738176952,0.0011912,232.377993125,54.420063907163126,-2.7808992544165907
0.7303668153952663,0.0012096,235.96744499999997,54.420063907163126,-2.7808992544165907
0.7405107989424228,0.0012263999999999999,239.24477062499997,54.420063907163126,-2.7808992544165907
0.7540361103386314,0.0012488,243.614538125,54.420063907163126,-2.7808992544165907
0.7564513445165257,0.0012527999999999999,244.39485374999998,54.420063907163126,-2.7808992544165907
0.7733579837617865,0.0012808,249.85706312499997,54.420063907163126,-2.7808992544165907
0.7777054052819965,0.0012879999999999999,251.26163124999997,54.420063907163126,-2.7808992544165907
0.7839850141445219,0.0012984,253.29045187499997,54.420063907163126,-2.7808992544165907
0.795578138198415,0.0013176,257.035966875,54.420063907163126,-2.7808992544165907
0.8047560280744137,0.0013327999999999999,259.4215370698177,54.420063907163126,-2.7808992544165907
0.8250439951687268,0.0013664,259.6711308476616,54.420063907163126,-2.7808992544165907
0.8429167280851453,0.0013959999999999999,259.8890345092622,54.420063907163126,-2.7808992544165907
0.8458150090986186,0.0014008,259.9241997402688,54.420063907163126,-2.7808992544165907
0.8704503977131414,0.0014416,260.22123027327353,54.420063907163126,-2.7808992544165907
0.8888061774651389,0.001472,260.4404200303851,54.420063907163126,-2.7808992544165907
0.8926705521497699,0.0014784,260.4863394806216,54.420063907163126,-2.7808992544165907
0.9066789103815573,0.0015015999999999999,260.6521515319733,54.420063907163126,-2.7808992544165907
0.9274499243114493,0.001536,260.8961834421189,54.420063907163126,-2.7808992544165907
0.9448396103922889,0.0015647999999999999,261.09885424139674,54.420063907163126,-2.7808992544165907
0.9535344534327088,0.0015792,261.1996437198035,54.420063907163126,-2.7808992544165907
0.9598140622952341,0.0015895999999999998,261.27221334006424,54.420063907163126,-2.7808992544165907
0.9714071863491273,0.0016087999999999999,261.405703401156,54.420063907163126,-2.7808992544165907
0.9776867952116527,0.0016192,261.4777510384828,54.420063907163126,-2.7808992544165907
0.9878307787588092,0.0016359999999999999,261.5937556101788,54.420063907163126,-2.7808992544165907
1.0023221838261758,0.00166,261.75867373386103,54.420063907163126,-2.7808992544165907
1.0230931977560676,0.0016944,261.9934438691197,54.420063907163126,-2.7808992544165907
1.0346863218099607,0.0017136,262.1236698710835,54.420063907163126,-2.7808992544165907
1.0385506964945916,0.00172,262.16695191877466,54.420063907163126,-2.7808992544165907
1.0506268673840637,0.00174,262.30180525655896,54.420063907163126,-2.7808992544165907
1.0588386635889047,0.0017536,262.3931604066063,54.420063907163126,-2.7808992544165907
1.0723639749851133,0.001776,262.54302765353435,54.420063907163126,-2.7808992544165907
1.0757453028341655,0.0017816,262.58037905665043,54.420063907163126,-2.7808992544165907
1.082024911696691,0.001792,262.64962469564637,54.420063907163126,-2.7808992544165907
1.0829910053678486,0.0017936,262.660263943961,54.420063907163126,-2.7808992544165907
1.0897536610659528,0.0018047999999999999,262.7346353160587,54.420063907163126,-2.7808992544165907
1.0955502230928993,0.0018143999999999999,262.7982390590007,54.420063907163126,-2.7808992544165907
1.1090755344891081,0.0018368,262.9461395699588,54.420063907163126,-2.7808992544165907
1.1110077218314236,0.0018399999999999998,262.9672106490546,54.420063907163126,-2.7808992544165907
1.1201856117074223,0.0018552,263.067103756608,54.420063907163126,-2.7808992544165907
1.129363501583421,0.0018704,263.1666781766056,54.420063907163126,-2.7808992544165907
1.1428888129796295,0.0018927999999999998,263.3128461190583,54.420063907163126,-2.7808992544165907
1.157380218046996,0.0019168,263.46870800022884,54.420063907163126,-2.7808992544165907
1.1607615458960483,0.0019223999999999999,263.50496603783927,54.420063907163126,-2.7808992544165907
1.1689733421008892,0.001936,263.5928502048717,54.420063907163126,-2.7808992544165907
1.18153255982594,0.0019568,263.72679699524986,54.420063907163126,-2.7808992544165907
1.1960239648933064,0.0019808,263.8806629191366,54.420063907163126,-2.7808992544165907
1.2013374800846741,0.0019896,263.9368980324643,54.420063907163126,-2.7808992544165907
1.2042357610981473,0.0019944,263.96753084179824,54.420063907163126,-2.7808992544165907
1.2119645104674095,0.0020071999999999998,264.0490780899485,54.420063907163126,-2.7808992544165907
1.2240406813568814,0.0020272,264.1760908166416,54.420063907163126,-2.7808992544165907
1.2370829459175112,0.0020488,264.31271689310694,54.420063907163126,-2.7808992544165907
1.2428795079444577,0.0020583999999999997,264.3732591543053,54.420063907163126,-2.7808992544165907
1.2554387256695085,0.0020792,264.50405756963113,54.420063907163126,-2.7808992544165907
1.262684428203192,0.0020912,264.5792860580105,54.420063907163126,-2.7808992544165907
1.2907011446667669,0.0021376,264.8685991521366,54.420063907163126,-2.7808992544165907
1.3071247370764487,0.0021647999999999997,265.03705781077997,54.420063907163126,-2.7808992544165907
1.3245144231572885,0.0021936,265.21452853013346,54.420063907163126,-2.7808992544165907
1.326929657335183,0.0021976,265.2391051776618,54.420063907163126,-2.7808992544165907
1.3312770788553927,0.0022048,265.28329922418186,54.420063907163126,-2.7808992544165907
1.3394888750602336,0.0022183999999999997,265.3666236033202,54.420063907163126,-2.7808992544165907
1.346251530758338,0.0022296,265.43509419485196,54.420063907163126,-2.7808992544165907
1.3515650459497057,0.0022383999999999998,265.4887984580078,54.420063907163126,-2.7808992544165907
1.3563955143054947,0.0022464,265.537549104857,54.420063907163126,-2.7808992544165907
1.3641242636747566,0.0022592,265.6154095408776,54.420063907163126,-2.7808992544165907
1.3713699662084398,0.0022711999999999997,265.6882475957333,54.420063907163126,-2.7808992544165907
1.3766834813998075,0.00228,265.74156681502586,54.420063907163126,-2.7808992544165907
1.3931070738094893,0.0023071999999999997,265.9058665119099,54.420063907163126,-2.7808992544165907
1.4129119940682235,0.00234,266.1029912996589,54.420063907163126,-2.7808992544165907
1.4153272282461178,0.0023439999999999997,266.12695696587133,54.420063907163126,-2.7808992544165907
1.4172594155884333,0.0023472,266.1461180169521,54.420063907163126,-2.7808992544165907
1.4375473826827463,0.0023807999999999998,266.3466977821954,54.420063907163126,-2.7808992544165907
1.438513476353904,0.0023824,266.3562215658303,54.420063907163126,-2.7808992544165907
1.451072694078955,0.0024032,266.4798046285341,54.420063907163126,-2.7808992544165907
1.454937068763586,0.0024096,266.5177461696993,54.420063907163126,-2.7808992544165907
1.4607336307905325,0.0024192,266.57458487346946,54.420063907163126,-2.7808992544165907
1.4679793333242157,0.0024311999999999997,266.64550970480997,54.420063907163126,-2.7808992544165907
1.4732928485155834,0.00244,266.6974345066043,54.420063907163126,-2.7808992544165907
1.4853690194050555,0.00246,266.81517456590035,54.420063907163126,-2.7808992544165907
1.5148348763753672,0.0025088,267.1009043991189,54.420063907163126,-2.7808992544165907
1.5259449535936813,0.0025272,267.208074832639,54.420063907163126,-2.7808992544165907
1.5312584687850492,0.002536,267.25922264702626,54.420063907163126,-2.7808992544165907
1.5360889371408377,0.002544,267.30566062578515,54.420063907163126,-2.7808992544165907
1.5385041713187322,0.002548,267.3288582555895,54.420063907163126,-2.7808992544165907
1.5418854991677844,0.0025536,267.3613110911183,54.420063907163126,-2.7808992544165907
1.5457498738524154,0.0025599999999999998,267.39836607883984,54.420063907163126,-2.7808992544165907
1.5558938573995718,0.0025767999999999998,267.495463934133,54.420063907163126,-2.7808992544165907
1.564105653604413,0.0025904,267.57388625598537,54.420063907163126,-2.7808992544165907
1.5703852624669383,0.0026008,267.6337479691976,54.420063907163126,-2.7808992544165907
1.5834275270275682,0.0026224,267.757778670278,54.420063907163126,-2.7808992544165907
1.59115627639683,0.0026352,267.8310903437149,54.420063907163126,-2.7808992544165907
1.607579868806512,0.0026623999999999997,267.9864181242726,54.420063907163126,-2.7808992544165907
1.6215882270382995,0.0026856,268.11841515136535,54.420063907163126,-2.7808992544165907
1.6278678359008252,0.002696,268.17744179731386,54.420063907163126,-2.7808992544165907
1.6380118194479816,0.0027128,268.2726052898383,54.420063907163126,-2.7808992544165907
1.6442914283105068,0.0027232,268.3314008551235,54.420063907163126,-2.7808992544165907
1.6539523650220844,0.0027392,268.42168486229065,54.420063907163126,-2.7808992544165907
1.6558845523644,0.0027424,268.43971695786723,54.420063907163126,-2.7808992544165907
1.6587828333778734,0.0027472,268.4667497226865,54.420063907163126,-2.7808992544165907
1.6655454890759775,0.0027584,268.5297546393599,54.420063907163126,-2.7808992544165907
1.6858334561702906,0.0027919999999999998,268.7181734756643,54.420063907163126,-2.7808992544165907
1.692596111868395,0.0028032,268.7807829650788,54.420063907163126,-2.7808992544165907
1.7022570485799726,0.0028192,268.8700561222367,54.420063907163126,-2.7808992544165907
1.7056383764290246,0.0028247999999999997,268.90125501674856,54.420063907163126,-2.7808992544165907
1.715782359976181,0.0028415999999999997,268.9947072919969,54.420063907163126,-2.7808992544165907
1.7259263435233374,0.0028583999999999997,269.0879443370229,54.420063907163126,-2.7808992544165907
1.752010872644597,0.0029016,269.32672065862914,54.420063907163126,-2.7808992544165907
1.7665022777119637,0.0029256,269.4587749773357,54.420063907163126,-2.7808992544165907
1.7805106359437508,0.0029487999999999997,269.58602647371777,54.420063907163126,-2.7808992544165907
1.8051460245582738,0.0029896,269.8088705032187,54.420063907163126,-2.7808992544165907
1.8133578207631147,0.0030031999999999997,269.8828878590917,54.420063907163126,-2.7808992544165907
1.8312305536795335,0.0030328,270.04353408483223,54.420063907163126,-2.7808992544165907
1.8399253967199534,0.0030472,270.1214651098173,54.420063907163126,-2.7808992544165907
1.853933754951741,0.0030704,270.246719224358,54.420063907163126,-2.7808992544165907
1.8645607853344761,0.003088,270.3414935235601,54.420063907163126,-2.7808992544165907
1.868425160019107,0.0030943999999999998,270.3759046444166,54.420063907163126,-2.7808992544165907
1.8829165650864736,0.0031184,270.50469988768845,54.420063907163126,-2.7808992544165907
1.8877470334422621,0.0031263999999999997,270.5475456520705,54.420063907163126,-2.7808992544165907
1.917212890412574,0.0031752,270.80798489401457,54.420063907163126,-2.7808992544165907
1.9196281245904683,0.0031791999999999996,270.8292629038153,54.420063907163126,-2.7808992544165907
1.925424686617415,0.0031888,270.8802875736145,54.420063907163126,-2.7808992544165907
1.9317042954799404,0.0031991999999999997,270.9354967414921,54.420063907163126,-2.7808992544165907
1.9355686701645713,0.0032056,270.9694368254126,54.420063907163126,-2.7808992544165907
1.9563396840944633,0.00324,271.1514140032286,54.420063907163126,-2.7808992544165907
1.961653199285831,0.0032488,271.19784507459923,54.420063907163126,-2.7808992544165907
1.9722802296685664,0.0032664,271.29056033083805,54.420063907163126,-2.7808992544165907
1.9766276511887761,0.0032735999999999998,271.3284331203513,54.420063907163126,-2.7808992544165907
1.980975072708986,0.0032808,271.3662734375717,54.420063907163126,-2.7808992544165907
1.9911190562561427,0.0032976,271.45444178516607,54.420063907163126,-2.7808992544165907
2.002229133474457,0.003316,271.5508063596786,54.420063907163126,-2.7808992544165907
2.0080256955014035,0.0033255999999999997,271.601000732004,54.420063907163126,-2.7808992544165907
2.0162374917062444,0.0033391999999999996,271.6720128010092,54.420063907163126,-2.7808992544165907
2.030245849938032,0.0033623999999999998,271.79289125900726,54.420063907163126,-2.7808992544165907
2.041838973991925,0.0033816,271.8926828093391,54.420063907163126,-2.7808992544165907
2.0437711613342406,0.0033848,271.909293227611,54.420063907163126,-2.7808992544165907
2.0481185828544506,0.003392,271.9466442928243,54.420063907163126,-2.7808992544165907
2.053432098045818,0.0034008,271.9922536306648,54.420063907163126,-2.7808992544165907
2.062609987921817,0.0034159999999999998,272.0709251322765,54.420063907163126,-2.7808992544165907
2.06550826893529,0.0034208,272.09574038527546,54.420063907163126,-2.7808992544165907
2.0838640486872877,0.0034511999999999998,272.2525894721469,54.420063907163126,-2.7808992544165907
2.089177563878655,0.00346,272.2978924717014,54.420063907163126,-2.7808992544165907
2.101736781603706,0.0034808,272.40479403162766,54.420063907163126,-2.7808992544165907
2.1205756081912823,0.003512,272.56468042842675,54.420063907163126,-2.7808992544165907
2.12588912338265,0.0035207999999999997,272.6096763116998,54.420063907163126,-2.7808992544165907
2.138448341107701,0.0035415999999999998,272.7158562199856,54.420063907163126,-2.7808992544165907
2.145694043641384,0.0035535999999999996,272.7770032292061,54.420063907163126,-2.7808992544165907
2.154871933517383,0.0035688,272.8543406275457,54.420063907163126,-2.7808992544165907
2.162117636051066,0.0035808,272.91530576370633,54.420063907163126,-2.7808992544165907
2.1659820107356973,0.0035872,272.9477879205159,54.420063907163126,-2.7808992544165907
2.170812479091486,0.0035952,272.98835885101045,54.420063907163126,-2.7808992544165907
2.2060748980887444,0.0036536,273.2834673249432,54.420063907163126,-2.7808992544165907
2.2089731791022174,0.0036584,273.3076406958118,54.420063907163126,-2.7808992544165907
2.2167019284714797,0.0036712,273.3720426216314,54.420063907163126,-2.7808992544165907
2.2234645841695837,0.0036823999999999997,273.42832250447265,54.420063907163126,-2.7808992544165907
2.234574661387898,0.0037007999999999997,273.5206376017967,54.420063907163126,-2.7808992544165907
2.2403712234148445,0.0037104,273.5687309311402,54.420063907163126,-2.7808992544165907
2.247616925948528,0.0037224,273.6287794038629,54.420063907163126,-2.7808992544165907
2.263074424687052,0.003748,273.756631070599,54.420063907163126,-2.7808992544165907
2.282396298110207,0.00378,273.915967731341,54.420063907163126,-2.7808992544165907
2.3133112955872557,0.0038312,274.1698165147504,54.420063907163126,-2.7808992544165907
2.334565356352726,0.0038664,274.34357057968975,54.420063907163126,-2.7808992544165907
2.3471245740777773,0.0038872,274.4459534654322,54.420063907163126,-2.7808992544165907
2.3582346512960912,0.0039056,274.53634497451225,54.420063907163126,-2.7808992544165907
2.3717599626923,0.003928,274.6461629589138,54.420063907163126,-2.7808992544165907
2.3765904310480885,0.003935999999999999,274.68532444219164,54.420063907163126,-2.7808992544165907
2.403158007004927,0.00398,274.90016026744786,54.420063907163126,-2.7808992544165907
2.4128189437165046,0.0039959999999999996,274.9780524738375,54.420063907163126,-2.7808992544165907
2.461615950464486,0.004076815363072615,275.36963939239814,54.420063907163126,-2.7808992544165907
2.484806836749529,0.004115223044608922,275.55467962018554,54.420063907163126,-2.7808992544165907
2.7283111427424833,0.004518503700740148,277.45858694569733,54.420063907163126,-2.7808992544165907
3.041388107590567,0.0050370074014802965,279.8116770603759,54.420063907163126,-2.7808992544165907
3.0645789938756103,0.005075415083016604,279.98212635167135,54.420063907163126,-2.7808992544165907
3.4704195038638668,0.00574754950990198,282.8880401223865,54.420063907163126,-2.7808992544165907
3.5863739352890827,0.005939587917583517,283.6935346325006,54.420063907163126,-2.7808992544165907
3.85306912756708,0.00638127625525105,285.5085754591871,54.420063907163126,-2.7808992544165907
4.131359762987599,0.006842168433686738,287.3510126992446,54.420063907163126,-2.7808992544165907
4.479223057263248,0.007418283656731346,289.5873201874899,54.420063907163126,-2.7808992544165907
4.699536476971158,0.007783156631326265,290.968656193513,54.420063907163126,-2.7808992544165907
4.885063567251504,0.008090418083616723,292.11240250435486,54.420063907163126,-2.7808992544165907
5.001017998676721,0.00828245649129826,292.8186466195209,54.420063907163126,-2.7808992544165907
5.035804328104286,0.00834006801360272,293.02927072388053,54.420063907163126,-2.7808992544165907
5.302499520382283,0.008781756351270254,294.6256188548727,54.420063907163126,-2.7808992544165907
5.592385598945324,0.009261852370474095,296.32566158387135,54.420063907163126,-2.7808992544165907
6.033012438361145,0.009991598319663933,298.84530926283566,54.420063907163126,-2.7808992544165907
6.20694408549897,0.010279655931186238,299.82001586826107,54.420063907163126,-2.7808992544165907
6.7403344700549646,0.011163032606521305,302.74473208932284,54.420063907163126,-2.7808992544165907
6.902670674050267,0.011431886377275456,303.6167543112297,54.420063907163126,-2.7808992544165907
7.00702966233296,0.011604720944188837,304.1731191350633,54.420063907163126,-2.7808992544165907
7.099793207473134,0.011758351670334066,304.66495836756667,54.420063907163126,-2.7808992544165907
7.1925567526133065,0.011911982396479295,305.1542976685355,54.420063907163126,-2.7808992544165907
7.552015490031477,0.012507301460292058,307.02768400345855,54.420063907163126,-2.7808992544165907
7.783924352881909,0.012891378275655131,308.21788632257955,54.420063907163126,-2.7808992544165907
8.224551192297731,0.013621124224844969,310.4418399047172,54.420063907163126,-2.7808992544165907
8.5840099297159,0.014216443288657732,312.22188748009535,54.420063907163126,-2.7808992544165907
8.873896008278942,0.014696539307861573,313.6363217428487,54.420063907163126,-2.7808992544165907
9.128995757414417,0.015119023804760953,314.8661825224342,54.420063907163126,-2.7808992544165907
9.372500063407372,0.01552230446089218,316.0276961277956,54.420063907163126,-2.7808992544165907
9.43047727911998,0.015618323664732947,316.3025050773654,54.420063907163126,-2.7808992544165907
9.755149687110585,0.016156031206241248,317.8294293841882,54.420063907163126,-2.7808992544165907
9.824722345965716,0.016271254250850173,318.15403406808315,54.420063907163126,-2.7808992544165907
9.92908133424841,0.016444088817763554,318.6392652437863,54.420063907163126,-2.7808992544165907
10.045035765673624,0.016636127225445087,319.17608419493314,54.420063907163126,-2.7808992544165907
10.381303616806752,0.017193038607721544,320.71935876038793,54.420063907163126,-2.7808992544165907
10.740762354224922,0.017788357671534305,322.3476599598429,54.420063907163126,-2.7808992544165907
10.821930456222574,0.017922784556911382,322.7123830889438,54.420063907163126,-2.7808992544165907
10.891503115077704,0.018038007601520304,323.0241545900892,54.420063907163126,-2.7808992544165907
11.239366409353353,0.018614122824564913,324.57151122499465,54.420063907163126,-2.7808992544165907
11.308939068208483,0.018729345869173835,324.8787288140565,54.420063907163126,-2.7808992544165907
11.482870715346305,0.019017403480696138,325.6435654545727,54.420063907163126,-2.7808992544165907
11.78435223705187,0.019516703340668136,326.9586644279595,54.420063907163126,-2.7808992544165907
12.00466565675978,0.019881576315263053,327.9114145300329,54.420063907163126,-2.7808992544165907
12.456887939318122,0.020630526105221043,329.84595635051176,54.420063907163126,-2.7808992544165907
12.688796802168554,0.021014602920584116,330.8273911632959,54.420063907163126,-2.7808992544165907
12.769964904166207,0.021149029805961193,331.1692373807182,54.420063907163126,-2.7808992544165907
12.804751233593771,0.021206641328265653,331.3154833766149,54.420063907163126,-2.7808992544165907
13.07144642587177,0.021648329665933188,332.43160032368814,54.420063907163126,-2.7808992544165907
13.164209971011942,0.021801960392078417,332.81772850606205,54.420063907163126,-2.7808992544165907
13.349737061292288,0.022109221844368875,333.5868160392728,54.420063907163126,-2.7808992544165907
13.628027696712808,0.022570114022804563,334.7326771207198,54.420063907163126,-2.7808992544165907
13.825150230135673,0.022896579315863173,335.5388138302145,54.420063907163126,-2.7808992544165907
14.01067732041602,0.02320384076815363,336.29344543467,54.420063907163126,-2.7808992544165907
14.416517830404276,0.023875975195039006,337.93074691975323,54.420063907163126,-2.7808992544165907
14.694808465824794,0.024336867373474694,339.0430919741937,54.420063907163126,-2.7808992544165907
14.903526442390184,0.02468253650730146,339.871967076797,54.420063907163126,-2.7808992544165907
15.054267203242967,0.024932186437287458,340.4677861362465,54.420063907163126,-2.7808992544165907
15.286176066093399,0.02531626325265053,341.37990747571376,54.420063907163126,-2.7808992544165907
15.657230246654091,0.025930786157231447,342.82815545625306,54.420063907163126,-2.7808992544165907
15.831161893791913,0.02621884376875375,343.5024080791437,54.420063907163126,-2.7808992544165907
15.981902654644696,0.02646849369873975,344.0844268122131,54.420063907163126,-2.7808992544165907
16.677629243195994,0.027620724144828968,346.7434005886554,54.420063907163126,-2.7808992544165907
17.187828741466944,0.028465693138627728,348.66589572122666,54.420063907163126,-2.7808992544165907
17.23421051403703,0.028542508501700342,348.8395568693147,54.420063907163126,-2.7808992544165907
17.280592286607117,0.028619323864772953,349.0130358393929,54.420063907163126,-2.7808992544165907
17.848769000590675,0.029560312062412483,351.1236255868284,54.420063907163126,-2.7808992544165907
18.161845965438758,0.03007881576315263,352.27540071988057,54.420063907163126,-2.7808992544165907
18.1850368517238,0.030117223444688937,352.36040811192015,54.420063907163126,-2.7808992544165907
18.556091032284495,0.030731746349269853,353.7148282088324,54.420063907163126,-2.7808992544165907
18.96193154227275,0.03140388077615523,355.1841872741449,54.420063907163126,-2.7808992544165907
19.228626734550748,0.03184556911382276,356.1430927183909,54.420063907163126,-2.7808992544165907
19.7388262328217,0.03269053810762153,357.9631895480029,54.420063907163126,-2.7808992544165907
20.37657560566039,0.03374674934986997,360.2127109938343,54.420063907163126,-2.7808992544165907
20.480934593943086,0.03391958391678336,360.5781842502277,54.420063907163126,-2.7808992544165907
20.921561433358907,0.034649329865973195,362.11335460118795,54.420063907163126,-2.7808992544165907
21.199852068779425,0.03511022204440888,363.076441969461,54.420063907163126,-2.7808992544165907
21.32740194334716,0.03532146429285857,363.51620797276416,54.420063907163126,-2.7808992544165907
21.559310806197598,0.03570554110822165,364.31316360565415,54.420063907163126,-2.7808992544165907
21.663669794480285,0.03587837567513502,364.6707021585612,54.420063907163126,-2.7808992544165907
21.7216470101929,0.0359743948789758,364.86904442449156,54.420063907163126,-2.7808992544165907
21.84919688476063,0.03618563712742548,365.3046721073035,54.420063907163126,-2.7808992544165907
22.069510304468544,0.0365505101020204,366.05479106651757,54.420063907163126,-2.7808992544165907
22.289823724176454,0.03691538307661532,366.80199524109173,54.420063907163126,-2.7808992544165907
22.556518916454458,0.037357071414282864,367.70266288101914,54.420063907163126,-2.7808992544165907
22.62609157530958,0.037472294458891775,367.93693543191864,54.420063907163126,-2.7808992544165907
22.718855120449756,0.037625925185037004,368.2488622818558,54.420063907163126,-2.7808992544165907
22.81161866558993,0.03777955591118223,368.56029280929613,54.420063907163126,-2.7808992544165907
23.194268289293145,0.03841328265653131,369.8397574931778,54.420063907163126,-2.7808992544165907
23.217459175578185,0.03845169033806761,369.91703517168537,54.420063907163126,-2.7808992544165907
23.58851335613888,0.03906621324264853,371.1494128550178,54.420063907163126,-2.7808992544165907
23.95956753669957,0.039680736147229445,372.37425290422544,54.420063907163126,-2.7808992544165907
24.284239944690178,0.040218443688737754,373.4399320606595,54.420063907163126,-2.7808992544165907
24.41178981925791,0.04042968593718743,373.8570696680313,54.420063907163126,-2.7808992544165907
25.14230273723678,0.04163952790558112,376.22995602382093,54.420063907163126,-2.7808992544165907
25.269852611804517,0.04185077015403081,376.6414969780138,54.420063907163126,-2.7808992544165907
25.30463894123208,0.041908381676335274,376.7535947177745,54.420063907163126,-2.7808992544165907
25.73367033750538,0.04261892378475696,378.13122863149687,54.420063907163126,-2.7808992544165907
25.76845666693295,0.04267653530706142,378.2425345699404,54.420063907163126,-2.7808992544165907
26.023556416068416,0.04309901980396079,379.0569950604457,54.420063907163126,-2.7808992544165907
26.20908350634876,0.04340628125625125,379.6473755332189,54.420063907163126,-2.7808992544165907
26.429396926056675,0.04377115423084617,380.34633961980836,54.420063907163126,-2.7808992544165907
26.475778698626765,0.04384796959391879,380.49319998927905,54.420063907163126,-2.7808992544165907
26.556946800624413,0.04398239647929586,380.7499644251906,54.420063907163126,-2.7808992544165907
26.67290123204963,0.04417443488697739,381.1162404781205,54.420063907163126,-2.7808992544165907
27.26426883231823,0.04515383076615323,382.97467553676387,54.420063907163126,-2.7808992544165907
27.403414150028496,0.04538427685537108,383.409661675108,54.420063907163126,-2.7808992544165907
27.58894124030884,0.04569153830766154,383.98830560474386,54.420063907163126,-2.7808992544165907
27.99478175029709,0.046363672734546904,385.24882472341034,54.420063907163126,-2.7808992544165907
28.133927068007356,0.046594118823764755,385.6793594574021,54.420063907163126,-2.7808992544165907
28.53976757799561,0.047266253250650134,386.9303676072919,54.420063907163126,-2.7808992544165907
28.725294668275957,0.04757351470294059,387.49994438535447,54.420063907163126,-2.7808992544165907
29.131135178264216,0.04824564912982597,388.740915624963,54.420063907163126,-2.7808992544165907
29.571762017680033,0.0489753950790158,390.08064619116163,54.420063907163126,-2.7808992544165907
30.464611139654195,0.05045409081816363,392.7717264289616,54.420063907163126,-2.7808992544165907
30.53418379850933,0.05056931386277255,392.980120274741,54.420063907163126,-2.7808992544165907
30.65013822993454,0.050761352270454085,393.3270323038402,54.420063907163126,-2.7808992544165907
30.719710888789674,0.05087657531506301,393.5349338440213,54.420063907163126,-2.7808992544165907
30.80087899078733,0.051011002200440095,393.7772536956362,54.420063907163126,-2.7808992544165907
31.090765069350365,0.05149109821964393,394.6406561115251,54.420063907163126,-2.7808992544165907
31.334269375343318,0.05189437887577515,395.3634905586777,54.420063907163126,-2.7808992544165907
31.566178238193757,0.05227845569113823,396.04987028868965,54.420063907163126,-2.7808992544165907
31.70532355590401,0.05250890178035607,396.46075420133576,54.420063907163126,-2.7808992544165907
31.890850646184358,0.052816163232646526,397.00750711731814,54.420063907163126,-2.7808992544165907
32.018400520752095,0.05302740548109622,397.3826803667014,54.420063907163126,-2.7808992544165907
32.087973179607225,0.05314262852570514,397.58707462978407,54.420063907163126,-2.7808992544165907
32.250309383602534,0.0534114822964593,398.06332362473825,54.420063907163126,-2.7808992544165907
32.389454701312786,0.053641928385677135,398.47079339829793,54.420063907163126,-2.7808992544165907
32.48221824645296,0.053795559111822364,398.7420607056878,54.420063907163126,-2.7808992544165907
32.94603597215382,0.05456371274254851,400.09389158029273,54.420063907163126,-2.7808992544165907
33.247517493859384,0.0550630126025205,400.9686032449508,54.420063907163126,-2.7808992544165907
33.444640027282254,0.05538947789557912,401.538858088202,54.420063907163126,-2.7808992544165907
33.49102179985234,0.055466293258651725,401.6728450188853,54.420063907163126,-2.7808992544165907
33.6301671175626,0.055696739347869575,402.07437227629674,54.420063907163126,-2.7808992544165907
33.943244082410686,0.056215243048609725,402.9754472028787,54.420063907163126,-2.7808992544165907
34.03600762755086,0.056368873774754955,403.24180913071757,54.420063907163126,-2.7808992544165907
34.221534717831204,0.05667613522704541,403.7736851352753,54.420063907163126,-2.7808992544165907
34.44184813753912,0.057041008201640334,404.4038294988306,54.420063907163126,-2.7808992544165907
34.70854332981711,0.05748269653930786,405.16453645293166,54.420063907163126,-2.7808992544165907
35.230338271230586,0.058346869373874774,406.64631495284954,54.420063907163126,-2.7808992544165907
35.41586536151093,0.05865413082616523,407.1711036680108,54.420063907163126,-2.7808992544165907
35.6129878949338,0.05898059611922385,407.72751828185073,54.420063907163126,-2.7808992544165907
35.79851498521415,0.05928785757151431,408.25010640771364,54.420063907163126,-2.7808992544165907
35.89127853035432,0.05944148829765954,408.5110043006862,54.420063907163126,-2.7808992544165907
35.949255746066925,0.0595375075015003,408.67393194621866,54.420063907163126,-2.7808992544165907
36.03042384806457,0.05967193438687737,408.90185859384593,54.420063907163126,-2.7808992544165907
36.285523597200054,0.06009441888377676,409.6168992819654,54.420063907163126,-2.7808992544165907
36.44785980119536,0.06036327265453091,410.07090458993287,54.420063907163126,-2.7808992544165907
36.62179144833318,0.06065133026605321,410.55646460414914,54.420063907163126,-2.7808992544165907
36.84210486804109,0.06101620324064813,411.1702181124582,54.420063907163126,-2.7808992544165907
37.03922740146396,0.06134266853370675,411.71815373789946,54.420063907163126,-2.7808992544165907
37.12039550346161,0.06147709541908382,411.94344359241853,54.420063907163126,-2.7808992544165907
37.88569475086803,0.06274454890978196,414.0582433510637,54.420063907163126,-2.7808992544165907
37.95526740972317,0.06285977195439088,414.2496679146542,54.420063907163126,-2.7808992544165907
38.17558082943108,0.0632246449289858,414.85494487968487,54.420063907163126,-2.7808992544165907
38.30313070399882,0.0634358871774355,415.2047457232177,54.420063907163126,-2.7808992544165907
38.419085135424034,0.06362792558511703,415.52235247309085,54.420063907163126,-2.7808992544165907
38.65099399827446,0.06401200240048009,416.15644664947416,54.420063907163126,-2.7808992544165907
38.87130741798237,0.06437687537507501,416.7574631550637,54.420063907163126,-2.7808992544165907
39.022048178835156,0.06462652530506101,417.1679197288116,54.420063907163126,-2.7808992544165907
39.161193496545415,0.06485697139427886,417.5462542019833,54.420063907163126,-2.7808992544165907
39.18438438283046,0.06489537907581516,417.6092589423469,54.420063907163126,-2.7808992544165907
39.497461347678545,0.06541388277655531,418.4584045993049,54.420063907163126,-2.7808992544165907
39.567034006533675,0.06552910582116424,418.6467466835027,54.420063907163126,-2.7808992544165907
39.76415653995654,0.06585557111422284,419.1796824800176,54.420063907163126,-2.7808992544165907
39.7989428693841,0.0659131826365273,419.27362291775364,54.420063907163126,-2.7808992544165907
40.12361527737471,0.06645089017803561,420.14886159213216,54.420063907163126,-2.7808992544165907
40.274356038227495,0.06670054010802161,420.5542830981319,54.420063907163126,-2.7808992544165907
40.40190591279523,0.0669117823564713,420.8968700449062,54.420063907163126,-2.7808992544165907
40.55264667364801,0.0671614322864573,421.3012021881856,54.420063907163126,-2.7808992544165907
40.69179199135827,0.06739187837567515,421.6739119074721,54.420063907163126,-2.7808992544165907
40.95848718363627,0.06783356671334267,422.3868858197984,54.420063907163126,-2.7808992544165907
41.65421377218756,0.06898579715943189,424.23834717053535,54.420063907163126,-2.7808992544165907
41.73538187418522,0.06912022404480897,424.4535625614436,54.420063907163126,-2.7808992544165907
41.85133630561043,0.0693122624524905,424.7607301697266,54.420063907163126,-2.7808992544165907
42.22239048617112,0.06992678535707142,425.74144355660974,54.420063907163126,-2.7808992544165907
42.62823099615938,0.0705989197839568,426.81025811024404,54.420063907163126,-2.7808992544165907
42.91811707472242,0.07107901580316063,427.5712688078722,54.420063907163126,-2.7808992544165907
43.428316572993374,0.0719239847969594,428.90579654953734,54.420063907163126,-2.7808992544165907
43.567461890703626,0.07215443088617723,429.2686956855998,54.420063907163126,-2.7808992544165907
43.75298898098398,0.07246169233846769,429.7518588414181,54.420063907163126,-2.7808992544165907
44.008088730119454,0.07288417683536708,430.41490556030607,54.420063907163126,-2.7808992544165907
44.14723404782972,0.07311462292458493,430.7759355598223,54.420063907163126,-2.7808992544165907
44.27478392239745,0.0733258651730346,431.10649006431845,54.420063907163126,-2.7808992544165907
44.41392924010771,0.07355631126225246,431.4666716969474,54.420063907163126,-2.7808992544165907
44.750197091240835,0.07411322264452891,432.3352985910741,54.420063907163126,-2.7808992544165907
44.90093785209362,0.0743628725745149,432.7238563467233,54.420063907163126,-2.7808992544165907
44.982105954091274,0.07449729945989199,432.93286901949494,54.420063907163126,-2.7808992544165907
45.4807100092197,0.07532306461292258,434.2135919494864,54.420063907163126,-2.7808992544165907
45.53868722493231,0.07541908381676336,434.3621570001208,54.420063907163126,-2.7808992544165907
45.78219153092527,0.07582236447289459,434.98532639960996,54.420063907163126,-2.7808992544165907
45.99090950749065,0.07616803360672135,435.5184434553654,54.420063907163126,-2.7808992544165907
46.09526849577335,0.07634086817363474,435.78464808406227,54.420063907163126,-2.7808992544165907
46.32717735862378,0.0767249449889978,436.3753738469839,54.420063907163126,-2.7808992544165907
46.59387255090177,0.07716663332666533,437.05328461849376,54.420063907163126,-2.7808992544165907
46.73301786861204,0.07739707941588318,437.40637636045483,54.420063907163126,-2.7808992544165907
46.93014040203491,0.0777235447089418,437.90588860845065,54.420063907163126,-2.7808992544165907
47.220026480597944,0.07820364072814563,438.6389815390005,54.420063907163126,-2.7808992544165907
47.451935343448376,0.07858771754350871,439.22419293098955,54.420063907163126,-2.7808992544165907
47.64905787687124,0.07891418283656731,439.7207461446557,54.420063907163126,-2.7808992544165907
47.765012308296456,0.07910622124424885,440.0124620377527,54.420063907163126,-2.7808992544165907
48.02011205743193,0.07952870574114823,440.65326659306754,54.420063907163126,-2.7808992544165907
48.194043704569765,0.07981676335267054,441.0894177865155,54.420063907163126,-2.7808992544165907
48.47233433999028,0.08027765553110623,441.7859849862216,54.420063907163126,-2.7808992544165907
48.53031155570289,0.080373674734947,441.9309066460584,54.420063907163126,-2.7808992544165907
48.785411304838355,0.08079615923184637,442.5677614849194,54.420063907163126,-2.7808992544165907
48.85498396369349,0.0809113822764553,442.7412235976084,54.420063907163126,-2.7808992544165907
48.947747508833665,0.08106501300260052,442.972356629414,54.420063907163126,-2.7808992544165907
49.214442701111665,0.08150670134026806,443.63591441575284,54.420063907163126,-2.7808992544165907
49.43475612081957,0.08187157431486297,444.18301374816224,54.420063907163126,-2.7808992544165907
49.81740574452279,0.08250530106021205,445.1309842212135,54.420063907163126,-2.7808992544165907
49.968146505375564,0.08275495099019804,445.5036469244666,54.420063907163126,-2.7808992544165907
50.51313233307408,0.08365753150630126,446.847323294836,54.420063907163126,-2.7808992544165907
50.73344575278199,0.08402240448089618,447.38890542520215,54.420063907163126,-2.7808992544165907
50.872591070492255,0.08425285057011403,447.73048475929534,54.420063907163126,-2.7808992544165907
50.918972843062335,0.08432966593318664,447.84426354124315,54.420063907163126,-2.7808992544165907
51.243645251052946,0.08486737347469495,448.6395863173097,54.420063907163126,-2.7808992544165907
51.80022652189398,0.08578915783156632,449.9984397443224,54.420063907163126,-2.7808992544165907
51.88139462389163,0.08592358471694339,450.19612908261985,54.420063907163126,-2.7808992544165907
52.13649437302711,0.08634606921384277,450.81665462157633,54.420063907163126,-2.7808992544165907
52.403189565305105,0.0867877575515103,451.46412112871917,54.420063907163126,-2.7808992544165907
52.43797589473267,0.08684536907381477,451.54847843804106,54.420063907163126,-2.7808992544165907
52.62350298501302,0.08715263052610522,451.9980160288443,54.420063907163126,-2.7808992544165907
52.82062551843589,0.08747909581916384,452.47497299847424,54.420063907163126,-2.7808992544165907
52.86700729100597,0.08755591118223645,452.5870972223467,54.420063907163126,-2.7808992544165907
52.91338906357606,0.08763272654530907,452.6991830885294,54.420063907163126,-2.7808992544165907
53.27284780099423,0.08822804560912183,453.5665531170832,54.420063907163126,-2.7808992544165907
53.411993118704494,0.08845849169833968,453.90169610088446,54.420063907163126,-2.7808992544165907
53.49316122070214,0.08859291858371675,454.09703892795375,54.420063907163126,-2.7808992544165907
54.07293337782822,0.08955311062212443,455.48899847944796,54.420063907163126,-2.7808992544165907
54.200483252395955,0.08976435287057412,455.79444705137837,54.420063907163126,-2.7808992544165907
54.68749186438186,0.09057091418283657,456.95813566100037,54.420063907163126,-2.7808992544165907
54.861423511519696,0.09085897179435888,457.372758368738,54.420063907163126,-2.7808992544165907
55.04695060180004,0.09116623324664934,457.8144579286015,54.420063907163126,-2.7808992544165907
55.33683668036308,0.09164632926585317,458.50345296540917,54.420063907163126,-2.7808992544165907
55.39481389607568,0.09174234846969394,458.6410828991946,54.420063907163126,-2.7808992544165907
55.638318202068646,0.09214562912582518,459.21851623239377,54.420063907163126,-2.7808992544165907
56.06734959834194,0.09285617123424686,460.2335064319186,54.420063907163126,-2.7808992544165907
56.160113143482114,0.09300980196039209,460.45256499017785,54.420063907163126,-2.7808992544165907
56.565953653470366,0.09368193638727745,461.40929177425,54.420063907163126,-2.7808992544165907
56.971794163458625,0.09435407081416283,462.36334524534146,54.420063907163126,-2.7808992544165907
57.041366822313755,0.09446929385877176,462.52663077442236,54.420063907163126,-2.7808992544165907
57.77187974029261,0.09567913582716543,464.23646551330563,54.420063907163126,-2.7808992544165907
57.85304784229027,0.09581356271254252,464.4259252206564,54.420063907163126,-2.7808992544165907
58.119743034568266,0.09625525105021004,465.04770706783285,54.420063907163126,-2.7808992544165907
58.25888835227853,0.0964856971394279,465.37167320225814,54.420063907163126,-2.7808992544165907
58.71111063483687,0.09723464692938588,466.4224851969442,54.420063907163126,-2.7808992544165907
59.105355701682605,0.0978875775155031,467.33600485368794,54.420063907163126,-2.7808992544165907
59.44162355281573,0.09844448889777956,468.1133070579605,54.420063907163126,-2.7808992544165907
59.685127858808684,0.09884776955391078,468.6751109062271,54.420063907163126,-2.7808992544165907
59.73150963137877,0.0989245849169834,468.78201973898,54.420063907163126,-2.7808992544165907
59.81267773337642,0.09905901180236047,468.96903232453985,54.420063907163126,-2.7808992544165907
59.89384583537408,0.09919343868773756,469.1559459607767,54.420063907163126,-2.7808992544165907
60.056182039369375,0.0994622924584917,469.5294771300565,54.420063907163126,-2.7808992544165907
60.20692280022216,0.0997119423884777,469.875975065178,54.420063907163126,-2.7808992544165907
60.29968634536233,0.09986557311462294,470.0890364031378,54.420063907163126,-2.7808992544165907
60.33447267478989,0.09992318463692738,470.16890144399207,54.420063907163126,-2.7808992544165907