File: datasets/aisi_316_L/data/M1/train_77.csv
Time(s),Strain(%),Stress(MPa),Temp(C),Log_SR(s-1)
0.0,0.0,0.0,128.02023633523947,-0.21787312203594755
2.1138934432336707e-05,1.28e-05,2.4485804,128.02023633523947,-0.21787312203594755
3.0387218246484018e-05,1.84e-05,3.519834325,128.02023633523947,-0.21787312203594755
5.1526152678820725e-05,3.12e-05,5.968414725,128.02023633523947,-0.21787312203594755
8.323455432732579e-05,5.04e-05,9.641285325,128.02023633523947,-0.21787312203594755
0.00010833703896572561,6.56e-05,12.548974549999999,128.02023633523947,-0.21787312203594755
0.00016646910865465158,0.0001008,19.28257065,128.02023633523947,-0.21787312203594755
0.00019289277669507244,0.00011679999999999999,22.343296149999997,128.02023633523947,-0.21787312203594755
0.00021403171112740918,0.0001296,24.79187655,128.02023633523947,-0.21787312203594755
0.0002246011783435775,0.000136,26.01616675,128.02023633523947,-0.21787312203594755
0.0002748061476203772,0.00016639999999999998,31.831545199999997,128.02023633523947,-0.21787312203594755
0.0002893391650426087,0.0001752,33.514944225,128.02023633523947,-0.21787312203594755
0.0003369017675153663,0.000204,39.024250125,128.02023633523947,-0.21787312203594755
0.0003620042521537661,0.0002192,41.93193935,128.02023633523947,-0.21787312203594755
0.00037653726957599757,0.00022799999999999999,43.615338375,128.02023633523947,-0.21787312203594755
0.00040163975421439745,0.0002432,46.5230276,128.02023633523947,-0.21787312203594755
0.0004148515882346079,0.0002512,48.053390349999994,128.02023633523947,-0.21787312203594755
0.00043070578905886044,0.0002608,49.88982565,128.02023633523947,-0.21787312203594755
0.0004650565575114076,0.0002816,53.868768800000005,128.02023633523947,-0.21787312203594755
0.0004716624745215128,0.0002856,54.633950175,128.02023633523947,-0.21787312203594755
0.0004928014089538495,0.0002984,57.082530575,128.02023633523947,-0.21787312203594755
0.0005007285093659758,0.0003032,58.000748225,128.02023633523947,-0.21787312203594755
0.0005126191599841652,0.0003104,59.3780747,128.02023633523947,-0.21787312203594755
0.0005245098106023545,0.00031759999999999997,60.755401174999996,128.02023633523947,-0.21787312203594755
0.0005945325309094699,0.00035999999999999997,68.86632374999999,128.02023633523947,-0.21787312203594755
0.0006090655483317013,0.00036879999999999997,70.54972277499999,128.02023633523947,-0.21787312203594755
0.000626240932557975,0.0003792,72.53919435,128.02023633523947,-0.21787312203594755
0.0006434163167842485,0.0003896,74.528665925,128.02023633523947,-0.21787312203594755
0.0006526646005983957,0.00039519999999999996,75.59991984999999,128.02023633523947,-0.21787312203594755
0.0006724823516287115,0.0004072,77.895463975,128.02023633523947,-0.21787312203594755
0.000716081403895406,0.00043359999999999997,82.94566105,128.02023633523947,-0.21787312203594755
0.0007425050719358268,0.0004496,86.00638655,128.02023633523947,-0.21787312203594755
0.0007623228229661426,0.0004616,88.301930675,128.02023633523947,-0.21787312203594755
0.0008032795084287949,0.0004864,93.0460552,128.02023633523947,-0.21787312203594755
0.0008640539449217628,0.0005231999999999999,100.08572384999998,128.02023633523947,-0.21787312203594755
0.000901047080178352,0.0005455999999999999,104.37073954999998,128.02023633523947,-0.21787312203594755
0.0009208648312086678,0.0005576,106.666283675,128.02023633523947,-0.21787312203594755
0.0009631427000733412,0.0005832,111.563444475,128.02023633523947,-0.21787312203594755
0.0009803180842996148,0.0005936,113.55291605000001,128.02023633523947,-0.21787312203594755
0.0009974934685258883,0.0006039999999999999,115.54238762499999,128.02023633523947,-0.21787312203594755
0.0010292018701743935,0.0006232,119.215258225,128.02023633523947,-0.21787312203594755
0.0010371289705865196,0.000628,120.133475875,128.02023633523947,-0.21787312203594755
0.0010529831714107723,0.0006376,121.969911175,128.02023633523947,-0.21787312203594755
0.001101866957285551,0.0006672,127.63225334999998,128.02023633523947,-0.21787312203594755
0.0011216847083158664,0.0006791999999999999,129.92779747499998,128.02023633523947,-0.21787312203594755
0.0011309329921300139,0.0006848,130.99905139999998,128.02023633523947,-0.21787312203594755
0.0011652837605825612,0.0007056,134.97799455,128.02023633523947,-0.21787312203594755
0.0011864226950148978,0.0007184,137.42657495,128.02023633523947,-0.21787312203594755
0.0011996345290351082,0.0007264,138.9569377,128.02023633523947,-0.21787312203594755
0.0012154887298593607,0.000736,140.793373,128.02023633523947,-0.21787312203594755
0.0012313429306836134,0.0007456,142.6298083,128.02023633523947,-0.21787312203594755
0.0012789055331563707,0.0007744,148.1391142,128.02023633523947,-0.21787312203594755
0.0012987232841866864,0.0007863999999999999,150.434658325,128.02023633523947,-0.21787312203594755
0.0013106139348048758,0.0007936,151.8119848,128.02023633523947,-0.21787312203594755
0.0013225045854230652,0.0008008,153.189311275,128.02023633523947,-0.21787312203594755
0.001344964703257423,0.0008144,155.79092795,128.02023633523947,-0.21787312203594755
0.0013581765372776334,0.0008223999999999999,157.3212907,128.02023633523947,-0.21787312203594755
0.0013674248210917806,0.000828,158.392544625,128.02023633523947,-0.21787312203594755
0.0014176297903685804,0.0008583999999999999,164.207923075,128.02023633523947,-0.21787312203594755
0.0014546229256251696,0.0008807999999999999,168.492938775,128.02023633523947,-0.21787312203594755
0.0014797254102635695,0.000896,171.40062799999998,128.02023633523947,-0.21787312203594755
0.001499543161293885,0.000908,173.696172125,128.02023633523947,-0.21787312203594755
0.001527288012736327,0.0009247999999999999,176.9099339,128.02023633523947,-0.21787312203594755
0.0015444633969626006,0.0009352,178.89940547499998,128.02023633523947,-0.21787312203594755
0.0015642811479929164,0.0009471999999999999,181.19494959999997,128.02023633523947,-0.21787312203594755
0.0015933471828373793,0.0009647999999999999,184.56174764999997,128.02023633523947,-0.21787312203594755
0.0016078802002596107,0.0009735999999999999,186.24514667499997,128.02023633523947,-0.21787312203594755
0.0016594063529384315,0.0010048,192.21356139999997,128.02023633523947,-0.21787312203594755
0.0016858300209788523,0.0010207999999999999,195.27428689999996,128.02023633523947,-0.21787312203594755
0.0017466044574718203,0.0010576,202.31395554999997,128.02023633523947,-0.21787312203594755
0.001762458658296073,0.0010672,204.15039084999998,128.02023633523947,-0.21787312203594755
0.001803415343758725,0.0010919999999999999,208.89451537499997,128.02023633523947,-0.21787312203594755
0.0018470143960254196,0.0011183999999999999,213.94471244999997,128.02023633523947,-0.21787312203594755
0.001911752382724451,0.0011576,221.443489925,128.02023633523947,-0.21787312203594755
0.0019342125005588084,0.0011711999999999998,224.04510659999997,128.02023633523947,-0.21787312203594755
0.0019606361685992296,0.0011872,227.10583210000001,128.02023633523947,-0.21787312203594755
0.001997629303855819,0.0012096,231.3908478,128.02023633523947,-0.21787312203594755
0.0020240529718962394,0.0012255999999999999,234.45157329999998,128.02023633523947,-0.21787312203594755
0.0020544401901427234,0.0012439999999999999,236.42238846304278,128.02023633523947,-0.21787312203594755
0.0021033239760175023,0.0012736,236.6288271002599,128.02023633523947,-0.21787312203594755
0.0021125722598316493,0.0012791999999999999,236.66767167220524,128.02023633523947,-0.21787312203594755
0.0021363535610680285,0.0012936,236.76725440575862,128.02023633523947,-0.21787312203594755
0.0021759890631286596,0.0013176,236.932270223496,128.02023633523947,-0.21787312203594755
0.0021918432639529122,0.0013272,236.99794781476925,128.02023633523947,-0.21787312203594755
0.0021984491809630175,0.0013311999999999998,237.02525876588498,128.02023633523947,-0.21787312203594755
0.0022618659842600277,0.0013696,237.28583558848158,128.02023633523947,-0.21787312203594755
0.002296216752712575,0.0013904,237.42579099959357,128.02023633523947,-0.21787312203594755
0.002310749770134806,0.0013992,237.48475682483553,128.02023633523947,-0.21787312203594755
0.002325282787557038,0.001408,237.5435781930199,128.02023633523947,-0.21787312203594755
0.0023992690580702165,0.0014528,237.84083799650807,128.02023633523947,-0.21787312203594755
0.002444189293738932,0.00148,238.0195734873939,128.02023633523947,-0.21787312203594755
0.002483824795799563,0.001504,238.17622006592018,128.02023633523947,-0.21787312203594755
0.0025194967476541313,0.0015256,238.31637040556862,128.02023633523947,-0.21787312203594755
0.0025261026646642365,0.0015295999999999999,238.34223902606922,128.02023633523947,-0.21787312203594755
0.0025512051493026366,0.0015448,238.44030010672824,128.02023633523947,-0.21787312203594755
0.0025604534331167836,0.0015504,238.47633292477752,128.02023633523947,-0.21787312203594755
0.002600088935177415,0.0015743999999999999,238.63018790582666,128.02023633523947,-0.21787312203594755
0.0026212278696097517,0.0015872,238.711869759621,128.02023633523947,-0.21787312203594755
0.002627833786619857,0.0015911999999999999,238.73734260098266,128.02023633523947,-0.21787312203594755
0.0026489727210521935,0.001604,238.81868838205946,128.02023633523947,-0.21787312203594755
0.002662184555072404,0.001612,238.86940095518256,128.02023633523947,-0.21787312203594755
0.002718995441359309,0.0016464,239.08635601044205,128.02023633523947,-0.21787312203594755
0.002730886091977498,0.0016535999999999999,239.13154066011305,128.02023633523947,-0.21787312203594755
0.0027374920089876034,0.0016576,239.15661008725826,128.02023633523947,-0.21787312203594755
0.002746740292801751,0.0016631999999999999,239.19166768474722,128.02023633523947,-0.21787312203594755
0.0027599521268219613,0.0016711999999999999,239.24167021527663,128.02023633523947,-0.21787312203594755
0.0027956240786765297,0.0016928,239.37621293629465,128.02023633523947,-0.21787312203594755
0.0028022299956866345,0.0016967999999999998,239.40105460827274,128.02023633523947,-0.21787312203594755
0.002837901947541203,0.0017184,239.5348070435839,128.02023633523947,-0.21787312203594755
0.002849792598159392,0.0017255999999999999,239.5792452697553,128.02023633523947,-0.21787312203594755
0.0028603620653755604,0.0017319999999999998,239.61868524456264,128.02023633523947,-0.21787312203594755
0.002870931532591729,0.0017384,239.65806842286565,128.02023633523947,-0.21787312203594755
0.0028854645500139605,0.0017472,239.7121280880651,128.02023633523947,-0.21787312203594755
0.002938311886094802,0.0017791999999999999,239.90781986143426,128.02023633523947,-0.21787312203594755
0.0029766262047534126,0.0018024,240.04883906004844,128.02023633523947,-0.21787312203594755
0.002989838038773623,0.0018104,240.09730199627862,128.02023633523947,-0.21787312203594755
0.0030149405234120227,0.0018256,240.18915209667816,128.02023633523947,-0.21787312203594755
0.0030360794578443598,0.0018384,240.2662684509715,128.02023633523947,-0.21787312203594755
0.0030717514096989277,0.0018599999999999999,240.39592914711284,128.02023633523947,-0.21787312203594755
0.003114029278563601,0.0018855999999999999,240.5488431039888,128.02023633523947,-0.21787312203594755
0.0031312046627898745,0.001896,240.61073286832763,128.02023633523947,-0.21787312203594755
0.003139131763202001,0.0019008,240.63925270681509,128.02023633523947,-0.21787312203594755
0.003173482531654548,0.0019215999999999999,240.76251552077434,128.02023633523947,-0.21787312203594755
0.0032131180337151796,0.0019456,240.90409709564724,128.02023633523947,-0.21787312203594755
0.003231614601343474,0.0019568,240.96993524628962,128.02023633523947,-0.21787312203594755
0.0032897466710324,0.001992,241.17590481065204,128.02023633523947,-0.21787312203594755
0.0033108856054647365,0.0020047999999999997,241.25045027122525,128.02023633523947,-0.21787312203594755
0.0033452363739172836,0.0020256,241.3711919678788,128.02023633523947,-0.21787312203594755
0.0033558058411334523,0.002032,241.40824585242012,128.02023633523947,-0.21787312203594755
0.003370338858555683,0.0020407999999999997,241.45912071220943,128.02023633523947,-0.21787312203594755
0.0033861930593799363,0.0020504,241.51452308237867,128.02023633523947,-0.21787312203594755
0.0034258285614405678,0.0020744,241.65258824652588,128.02023633523947,-0.21787312203594755
0.0034535734128830096,0.0020912,241.74886342724085,128.02023633523947,-0.21787312203594755
0.0034588581464910935,0.0020943999999999997,241.76716730734285,128.02023633523947,-0.21787312203594755
0.0034971724651497037,0.0021176,241.89954578631287,128.02023633523947,-0.21787312203594755
0.0035354867838083143,0.0021408,242.0313598367984,128.02023633523947,-0.21787312203594755
0.003552662168034588,0.0021512,242.09026792850696,128.02023633523947,-0.21787312203594755
0.0036623203904023343,0.0022175999999999997,242.46378854110634,128.02023633523947,-0.21787312203594755
0.00370724062607105,0.0022448,242.61553456517973,128.02023633523947,-0.21787312203594755
0.003736306660915513,0.0022624,242.7133411906974,128.02023633523947,-0.21787312203594755
0.0037785845297801865,0.002288,242.85507731265795,128.02023633523947,-0.21787312203594755
0.003797081097408481,0.0022992,242.91689223612144,128.02023633523947,-0.21787312203594755
0.003810292931428691,0.0023071999999999997,242.9609738753152,128.02023633523947,-0.21787312203594755
0.003826147132252944,0.0023168,243.01379323389955,128.02023633523947,-0.21787312203594755
0.003873709734725701,0.0023455999999999998,243.1717415284623,128.02023633523947,-0.21787312203594755
0.003882958018539849,0.0023512,243.20236567183065,128.02023633523947,-0.21787312203594755
0.0039027757695701644,0.0023631999999999998,243.2678932121127,128.02023633523947,-0.21787312203594755
0.0039410900882287745,0.0023864,243.39421298898094,128.02023633523947,-0.21787312203594755
0.003946374821836859,0.0023896,243.41159874515668,128.02023633523947,-0.21787312203594755
0.00397279848987728,0.0024056,243.49839169904612,128.02023633523947,-0.21787312203594755
0.003996579791113658,0.00242,243.57631305467334,128.02023633523947,-0.21787312203594755
0.004023003459154079,0.002436,243.6626805642778,128.02023633523947,-0.21787312203594755
0.004075850795234921,0.0024679999999999997,243.8347547178166,128.02023633523947,-0.21787312203594755
0.0041498370657481,0.0025128,244.07420381890793,128.02023633523947,-0.21787312203594755
0.0041683336333763945,0.0025239999999999998,244.13380523164395,128.02023633523947,-0.21787312203594755
0.004210611502241068,0.0025496,244.26965106096492,128.02023633523947,-0.21787312203594755
0.004239677537085531,0.0025672,244.3627366416721,128.02023633523947,-0.21787312203594755
0.004255531737909783,0.0025767999999999998,244.4134056807478,128.02023633523947,-0.21787312203594755
0.004284597772754246,0.0025943999999999997,244.50610812272834,128.02023633523947,-0.21787312203594755
0.004312342624196688,0.0026111999999999997,244.59436829150928,128.02023633523947,-0.21787312203594755
0.004321590908010835,0.0026168,244.6237390978015,128.02023633523947,-0.21787312203594755
0.004351978126257319,0.0026352,244.72007104469768,128.02023633523947,-0.21787312203594755
0.004359905226669446,0.00264,244.74515793091174,128.02023633523947,-0.21787312203594755
0.004386328894709867,0.002656,244.82865270668626,128.02023633523947,-0.21787312203594755
0.004407467829142204,0.0026688,244.89530737659697,128.02023633523947,-0.21787312203594755
0.004431249130378582,0.0026831999999999997,244.97014503115085,128.02023633523947,-0.21787312203594755
0.004473526999243256,0.0027088,245.1028041376893,128.02023633523947,-0.21787312203594755
0.004480132916253361,0.0027128,245.12348787298288,128.02023633523947,-0.21787312203594755
0.004484096466459424,0.0027152,245.1358924050155,128.02023633523947,-0.21787312203594755
0.004575258121198876,0.0027703999999999997,245.4200271281626,128.02023633523947,-0.21787312203594755
0.00458054285480696,0.0027735999999999998,245.4364306691348,128.02023633523947,-0.21787312203594755
0.004596397055631213,0.0027832,245.48559706393752,128.02023633523947,-0.21787312203594755
0.004629426640681739,0.0028032,245.58781513472303,128.02023633523947,-0.21787312203594755
0.004634711374289823,0.0028063999999999997,245.6041435946608,128.02023633523947,-0.21787312203594755
0.0046452808415059915,0.0028128,245.63677874717172,128.02023633523947,-0.21787312203594755
0.004691522260576728,0.0028407999999999997,245.77921839328715,128.02023633523947,-0.21787312203594755
0.004698128177586833,0.0028447999999999998,245.79952212777707,128.02023633523947,-0.21787312203594755
0.0047324789460393805,0.0028656,245.90492260600627,128.02023633523947,-0.21787312203594755
0.004769472081295969,0.002888,246.0180976875833,128.02023633523947,-0.21787312203594755
0.004810428766758621,0.0029127999999999997,246.14300009029762,128.02023633523947,-0.21787312203594755
0.004872524386653611,0.0029503999999999997,246.33158007449467,128.02023633523947,-0.21787312203594755
0.004906875155106158,0.0029712,246.43549818831804,128.02023633523947,-0.21787312203594755
0.004924050539332432,0.0029816,246.4873508229909,128.02023633523947,-0.21787312203594755
0.0049346200065486,0.0029879999999999998,246.51922507863137,128.02023633523947,-0.21787312203594755
0.004939904740156684,0.0029912,246.53515222095578,128.02023633523947,-0.21787312203594755
0.004945189473764769,0.0029944,246.55107271948103,128.02023633523947,-0.21787312203594755
0.004955758940980937,0.0030007999999999996,246.58289382457642,128.02023633523947,-0.21787312203594755
0.004982182609021358,0.0030168,246.662331008441,128.02023633523947,-0.21787312203594755
0.005038993495308263,0.0030512,246.8325666937101,128.02023633523947,-0.21787312203594755
0.005081271364172936,0.0030767999999999998,246.95876833636657,128.02023633523947,-0.21787312203594755
0.005109016215615377,0.0030935999999999997,247.04136567443797,128.02023633523947,-0.21787312203594755
0.005135439883655798,0.0031095999999999997,247.119867320046,128.02023633523947,-0.21787312203594755
0.005157900001490157,0.0031232,247.18646994152337,128.02023633523947,-0.21787312203594755
0.005160542368294199,0.0031248,247.19429810091438,128.02023633523947,-0.21787312203594755
0.005180360119324514,0.0031368,247.25295955011583,128.02023633523947,-0.21787312203594755
0.0051935719533447245,0.0031447999999999997,247.2920185676396,128.02023633523947,-0.21787312203594755
0.005213389704375041,0.0031568,247.3505345144447,128.02023633523947,-0.21787312203594755
0.005234528638807377,0.0031696,247.41285598757347,128.02023633523947,-0.21787312203594755
0.005264915857053861,0.003188,247.50227141901843,128.02023633523947,-0.21787312203594755
0.0053071937259185345,0.0032136,247.626341406184,128.02023633523947,-0.21787312203594755
0.005327011476948851,0.0032256,247.68436646755552,128.02023633523947,-0.21787312203594755
0.005356077511793313,0.0032432,247.7693178359136,128.02023633523947,-0.21787312203594755
0.005381179996431713,0.0032584,247.8425403403371,128.02023633523947,-0.21787312203594755
0.005391749463647882,0.0032648,247.87333100144832,128.02023633523947,-0.21787312203594755
0.0054512027167388285,0.0033008,248.04609185030142,128.02023633523947,-0.21787312203594755
0.005474984017975207,0.0033152,248.11499024562295,128.02023633523947,-0.21787312203594755
0.005485553485191375,0.0033215999999999996,248.1455742803675,128.02023633523947,-0.21787312203594755
0.00551726188683988,0.0033407999999999997,248.23718878822763,128.02023633523947,-0.21787312203594755
0.005653343777248048,0.0034232,248.62805875722825,128.02023633523947,-0.21787312203594755
0.005675803895082406,0.0034368,248.6922168330158,128.02023633523947,-0.21787312203594755
0.005683730995494532,0.0034416,248.71483720968453,128.02023633523947,-0.21787312203594755
0.0056969428295147425,0.0034495999999999997,248.7525105144928,128.02023633523947,-0.21787312203594755
0.005732614781369311,0.0034712,248.85405862559801,128.02023633523947,-0.21787312203594755
0.0057497901655955835,0.0034815999999999996,248.90286424203214,128.02023633523947,-0.21787312203594755
0.005772250283429942,0.0034952,248.96660126632202,128.02023633523947,-0.21787312203594755
0.005778856200440048,0.0034992,248.98532903323309,128.02023633523947,-0.21787312203594755
0.00582113406930472,0.0035248,249.10498964067844,128.02023633523947,-0.21787312203594755
0.00583302471992291,0.003532,249.13858305640662,128.02023633523947,-0.21787312203594755
0.005842273003737057,0.0035375999999999997,249.16469280776076,128.02023633523947,-0.21787312203594755
0.005868696671777478,0.0035535999999999996,249.2392034246055,128.02023633523947,-0.21787312203594755
0.005879266138993647,0.00356,249.2689710229094,128.02023633523947,-0.21787312203594755
0.005995530278371498,0.0036303999999999998,249.5950489516353,128.02023633523947,-0.21787312203594755
0.006008742112391709,0.0036384,249.6319465625307,128.02023633523947,-0.21787312203594755
0.006024596313215961,0.0036479999999999998,249.67618195659034,128.02023633523947,-0.21787312203594755
0.006058947081668508,0.0036688,249.77186986530205,128.02023633523947,-0.21787312203594755
0.006077443649296803,0.0036799999999999997,249.823306480221,128.02023633523947,-0.21787312203594755
0.006093297850121056,0.0036896,249.86734643303998,128.02023633523947,-0.21787312203594755
0.006151429919809982,0.0037248,250.02844533337125,128.02023633523947,-0.21787312203594755
0.006224095006921139,0.0037687999999999997,250.2289864386667,128.02023633523947,-0.21787312203594755
0.006249197491559539,0.003784,250.2980518027581,128.02023633523947,-0.21787312203594755
0.00627562115959996,0.0038,250.37063539925543,128.02023633523947,-0.21787312203594755
0.006295438910630276,0.003812,250.4249949041175,128.02023633523947,-0.21787312203594755
0.006307329561248466,0.0038192,250.4575785740801,128.02023633523947,-0.21787312203594755
0.006333753229288886,0.0038352,250.52990108187194,128.02023633523947,-0.21787312203594755
0.006370746364545475,0.0038575999999999997,250.63095521747118,128.02023633523947,-0.21787312203594755
0.006386600565369728,0.0038672,250.6741940482026,128.02023633523947,-0.21787312203594755
0.006411703050008127,0.0038824,250.74257001653805,128.02023633523947,-0.21787312203594755
0.00643944790145057,0.0038992,250.81802210500112,128.02023633523947,-0.21787312203594755
0.0064500173686667375,0.0039056,250.84673239501254,128.02023633523947,-0.21787312203594755
0.006456623285676843,0.0039096,250.8646670091256,128.02023633523947,-0.21787312203594755
0.006473798669903117,0.00392,250.91126354669254,128.02023633523947,-0.21787312203594755
0.006490974054129389,0.0039304,250.95781189597415,128.02023633523947,-0.21787312203594755
0.006526646005983958,0.003952,251.0543360302972,128.02023633523947,-0.21787312203594755
0.006546463757014274,0.003964,251.10787163994016,128.02023633523947,-0.21787312203594755
0.006587420442476926,0.0039888,251.21831202481548,128.02023633523947,-0.21787312203594755
0.006986493945274316,0.004230446089217844,252.2807605472845,128.02023633523947,-0.21787312203594755
0.0081282247507816,0.004921784356871375,255.19683168504616,128.02023633523947,-0.21787312203594755
0.008762519642730091,0.0053058611722344474,256.74757392661735,128.02023633523947,-0.21787312203594755
0.009555388257665704,0.0057859571914382875,258.6257195736053,128.02023633523947,-0.21787312203594755
0.009777391469847676,0.005920384076815363,259.1405755081156,128.02023633523947,-0.21787312203594755
0.01057026008478329,0.006400480096019204,260.9432459266808,128.02023633523947,-0.21787312203594755
0.011014266509147233,0.006669333866773355,261.92967608763524,128.02023633523947,-0.21787312203594755
0.01260000373901846,0.007629525905181036,265.3325546626581,128.02023633523947,-0.21787312203594755
0.012822006951200431,0.007763952790558111,265.79526207767077,128.02023633523947,-0.21787312203594755
0.013678305055330894,0.00828245649129826,267.5514627968693,128.02023633523947,-0.21787312203594755
0.013900308267512866,0.008416883376675335,267.9997069396639,128.02023633523947,-0.21787312203594755
0.014376029436474235,0.00870494098819764,268.95093492940816,128.02023633523947,-0.21787312203594755
0.014946894839227877,0.009050610122024405,270.07635285135785,128.02023633523947,-0.21787312203594755
0.01656434681369653,0.01003000600120024,273.1774072980323,128.02023633523947,-0.21787312203594755
0.017737792363801238,0.010740548109621925,275.35366178524305,128.02023633523947,-0.21787312203594755
0.018023225065178058,0.010913382676535306,275.8744395677713,128.02023633523947,-0.21787312203594755
0.018435516744944577,0.011163032606521305,276.621031002145,128.02023633523947,-0.21787312203594755
0.01929181484907504,0.011681536307261452,278.1511506564253,128.02023633523947,-0.21787312203594755
0.020021253974815804,0.012123224644928985,279.43380378242153,128.02023633523947,-0.21787312203594755
0.020433545654582323,0.012372874574914983,280.1507166795932,128.02023633523947,-0.21787312203594755
0.020655548866764295,0.012507301460292058,280.53440900229884,128.02023633523947,-0.21787312203594755
0.020940981568141115,0.01268013602720544,281.0253726892969,128.02023633523947,-0.21787312203594755
0.021702135438479306,0.013141028205641128,282.32201426814055,128.02023633523947,-0.21787312203594755
0.022399859819622645,0.013563512702540508,283.49510357653685,128.02023633523947,-0.21787312203594755
0.024683321430637215,0.01494618923784757,287.2383161640251,128.02023633523947,-0.21787312203594755
0.024968754132014034,0.015119023804760953,287.6965271566392,128.02023633523947,-0.21787312203594755
0.025983625959131625,0.01573354670934187,289.3094317871264,128.02023633523947,-0.21787312203594755
0.027030212530846632,0.01636727345469094,290.94720858264515,128.02023633523947,-0.21787312203594755
0.027632792678197696,0.016732146429285857,291.87894954597726,128.02023633523947,-0.21787312203594755
0.02864766450531528,0.017346669333866773,293.43048089504117,128.02023633523947,-0.21787312203594755
0.03004311326760196,0.018191638327665533,295.52927532209793,128.02023633523947,-0.21787312203594755
0.030360260713576205,0.01838367673534707,296.0009303855666,128.02023633523947,-0.21787312203594755
0.030550549181160753,0.01849889977995599,296.28300117505324,128.02023633523947,-0.21787312203594755
0.03191428319885001,0.019324664932986596,298.28482831156623,128.02023633523947,-0.21787312203594755
0.03216800115562941,0.019478295659131825,298.6535511808554,128.02023633523947,-0.21787312203594755
0.03261200757999335,0.019747149429885976,299.29609858711234,128.02023633523947,-0.21787312203594755
0.03343659093952639,0.02024644928985797,300.4804209888023,128.02023633523947,-0.21787312203594755
0.034134315320669725,0.02066893378675735,301.47366933652364,128.02023633523947,-0.21787312203594755
0.034356318532851704,0.020803360672134428,301.7880382373456,128.02023633523947,-0.21787312203594755
0.03464175123422852,0.02097619523904781,302.19106516180636,128.02023633523947,-0.21787312203594755
0.03527604612617701,0.02136027205441088,303.0820725268218,128.02023633523947,-0.21787312203594755
0.03584691152893065,0.021705941188237647,303.87865086898523,128.02023633523947,-0.21787312203594755
0.037115501312827634,0.022474094818963793,305.6313221001297,128.02023633523947,-0.21787312203594755
0.03746436350339931,0.022685337067413484,306.10919060651406,128.02023633523947,-0.21787312203594755
0.038352376352127196,0.023223044608921786,307.3178176568459,128.02023633523947,-0.21787312203594755
0.038606094308906595,0.023376675335067015,307.6611286363555,128.02023633523947,-0.21787312203594755
0.03885981226568599,0.023530306061212244,308.00356080599676,128.02023633523947,-0.21787312203594755
0.03905010073327054,0.023645529105821166,308.25981301066656,128.02023633523947,-0.21787312203594755
0.0395258219022319,0.02393358671734347,308.8983220989145,128.02023633523947,-0.21787312203594755
0.04044554949555721,0.024490498099619923,310.12433771715325,128.02023633523947,-0.21787312203594755
0.040826126430726306,0.024720944188837767,310.6284683633268,128.02023633523947,-0.21787312203594755
0.0412067033658954,0.02495139027805561,311.1307695184513,128.02023633523947,-0.21787312203594755
0.04171413927945419,0.02525865173034607,311.79769896516535,128.02023633523947,-0.21787312203594755
0.04215814570381814,0.02552750550110022,312.37867098486345,128.02023633523947,-0.21787312203594755
0.0431413027863383,0.026122824564912984,313.65668367558436,128.02023633523947,-0.21787312203594755
0.043553594466104815,0.02637247449489898,314.18923816148305,128.02023633523947,-0.21787312203594755
0.04406103037966361,0.026679735947189438,314.84199842531865,128.02023633523947,-0.21787312203594755
0.044885613739196646,0.027179035807161432,315.89651515905706,128.02023633523947,-0.21787312203594755
0.045900485566314236,0.02779355871174235,317.1840666896141,128.02023633523947,-0.21787312203594755
0.046185918267691056,0.027966393278655733,317.54418393785977,128.02023633523947,-0.21787312203594755
0.047010501627224095,0.028465693138627728,318.5796789396675,128.02023633523947,-0.21787312203594755
0.04777165549756228,0.02892658531706341,319.52925047893825,128.02023633523947,-0.21787312203594755
0.04853280936790047,0.0293874774954991,320.47293943990525,128.02023633523947,-0.21787312203594755
0.049452536961225785,0.029944388877775556,321.6055638057472,128.02023633523947,-0.21787312203594755
0.04967454017340776,0.03007881576315263,321.8777214431467,128.02023633523947,-0.21787312203594755
0.050023402363979425,0.03029005801160232,322.30444128348864,128.02023633523947,-0.21787312203594755
0.05062598251133049,0.03065493098619724,323.03877920391324,128.02023633523947,-0.21787312203594755
0.05214829025200687,0.03157671534306861,324.878924910801,128.02023633523947,-0.21787312203594755
0.05357545375889098,0.03244088817763553,326.58512383028335,128.02023633523947,-0.21787312203594755
0.054304892884631736,0.03288257651530306,327.45032959945786,128.02023633523947,-0.21787312203594755
0.05484404354278796,0.03320904180836168,328.0869192258116,128.02023633523947,-0.21787312203594755
0.055668626902321,0.03370834166833367,329.05582626378225,128.02023633523947,-0.21787312203594755
0.05604920383749008,0.033938787757551506,329.50112474642987,128.02023633523947,-0.21787312203594755
0.056556639751048875,0.034246049209841964,330.09302606031736,128.02023633523947,-0.21787312203594755
0.05750808208897162,0.034822164432886576,331.1972883634946,128.02023633523947,-0.21787312203594755
0.057666655811958734,0.03491818363672734,331.38063715198786,128.02023633523947,-0.21787312203594755
0.05833266544850465,0.03532146429285857,332.1485647048278,128.02023633523947,-0.21787312203594755
0.05871324238367376,0.03555191038207642,332.58584510933343,128.02023633523947,-0.21787312203594755
0.059759828955388755,0.03618563712742548,333.7827031071457,128.02023633523947,-0.21787312203594755
0.06036240910273982,0.0365505101020204,334.468094652822,128.02023633523947,-0.21787312203594755
0.06058441231492181,0.036684936987397485,334.71993402021576,128.02023633523947,-0.21787312203594755
0.06102841873928574,0.036953790758151625,335.2225356353534,128.02023633523947,-0.21787312203594755
0.06128213669606513,0.037107421484296854,335.5090962542727,128.02023633523947,-0.21787312203594755
0.06172614312042908,0.03737627525505101,336.0094664564872,128.02023633523947,-0.21787312203594755
0.06210672005559819,0.03760672134426886,336.4372389907611,128.02023633523947,-0.21787312203594755
0.06248729699076727,0.037837167433486696,336.86399043091654,128.02023633523947,-0.21787312203594755
0.06315330662731318,0.03824044808961792,337.6083743430139,128.02023633523947,-0.21787312203594755
0.0640730342206385,0.038797359471894374,338.63131935938884,128.02023633523947,-0.21787312203594755
0.0644536111558076,0.039027805561112225,339.05292997713616,128.02023633523947,-0.21787312203594755
0.06527819451534063,0.039527105421084216,339.96310329398517,128.02023633523947,-0.21787312203594755
0.06559534196131488,0.03971914382876575,340.3119746394889,128.02023633523947,-0.21787312203594755
0.06648335481004276,0.04025685137027406,341.2853319822988,128.02023633523947,-0.21787312203594755
0.06768851510474491,0.0409865973194639,342.59824536405625,128.02023633523947,-0.21787312203594755
0.06800566255071915,0.04117863572714543,342.94222966930704,128.02023633523947,-0.21787312203594755
0.06835452474129082,0.041389877975595124,343.3198906085493,128.02023633523947,-0.21787312203594755
0.06867167218726507,0.04158191638327666,343.66256692600746,128.02023633523947,-0.21787312203594755
0.06968654401438265,0.04219643928785757,344.75500654987474,128.02023633523947,-0.21787312203594755
0.06997197671575947,0.04236927385477096,345.06113497642315,128.02023633523947,-0.21787312203594755
0.07060627160770795,0.04275335067013403,345.7396820962605,128.02023633523947,-0.21787312203594755
0.07165285817942298,0.0433870774154831,346.85411029508305,128.02023633523947,-0.21787312203594755
0.07254087102815085,0.0439247849569914,347.794716242327,128.02023633523947,-0.21787312203594755
0.07279458898493024,0.044078415683136626,348.062634600581,128.02023633523947,-0.21787312203594755
0.07304830694170965,0.044232046409281855,348.3301890227643,128.02023633523947,-0.21787312203594755
0.07355574285526843,0.044539307861572314,348.86421306782296,128.02023633523947,-0.21787312203594755
0.07396803453503495,0.04478895779155831,349.29705044430864,128.02023633523947,-0.21787312203594755
0.07415832300261951,0.044904180836167235,349.49650409407184,128.02023633523947,-0.21787312203594755
0.07485604738376285,0.04532666533306662,350.22613269278486,128.02023633523947,-0.21787312203594755
0.07510976534054226,0.04548029605921185,350.49079396902704,128.02023633523947,-0.21787312203594755
0.07545862753111392,0.04569153830766154,350.8541346239237,128.02023633523947,-0.21787312203594755
0.07571234548789332,0.04584516903380677,351.11797101930506,128.02023633523947,-0.21787312203594755
0.07621978140145211,0.046152430486097226,351.64461164268255,128.02023633523947,-0.21787312203594755
0.07688579103799803,0.04655571114222845,352.33375700015114,128.02023633523947,-0.21787312203594755
0.07752008592994651,0.04693978795759152,352.98792463309246,128.02023633523947,-0.21787312203594755
0.07904239367062288,0.04786157231446289,354.54946794430464,128.02023633523947,-0.21787312203594755
0.07961325907337652,0.04820724144828965,355.1320171778192,128.02023633523947,-0.21787312203594755
0.08002555075314303,0.04845689137827565,355.551734499609,128.02023633523947,-0.21787312203594755
0.08021583922072759,0.048572114422884574,355.74516566928577,128.02023633523947,-0.21787312203594755
0.08065984564509154,0.04884096819363873,356.1958104668931,128.02023633523947,-0.21787312203594755
0.08100870783566322,0.04905221044208842,356.5492101770907,128.02023633523947,-0.21787312203594755
0.08107213732485806,0.049090618123624724,356.6134008499678,128.02023633523947,-0.21787312203594755
0.08132585528163745,0.04924424884976995,356.8699679192273,128.02023633523947,-0.21787312203594755
0.08173814696140397,0.04949389877975595,357.28622461432457,128.02023633523947,-0.21787312203594755
0.08278473353311899,0.050127625525105024,358.33921536300414,128.02023633523947,-0.21787312203594755
0.08341902842506747,0.05051170234046809,358.97486517436016,128.02023633523947,-0.21787312203594755
0.084877906676549,0.05139507901580316,360.42974910191083,128.02023633523947,-0.21787312203594755
0.08586106375906916,0.05199039807961592,361.4047175129854,128.02023633523947,-0.21787312203594755
0.08598792273745887,0.05206721344268854,361.53020198250044,128.02023633523947,-0.21787312203594755
0.08611478171584855,0.05214402880576115,361.65561427256165,128.02023633523947,-0.21787312203594755
0.08671736186319962,0.05250890178035607,362.25034147482467,128.02023633523947,-0.21787312203594755
0.08751023047813525,0.052988997799559914,363.03042750971235,128.02023633523947,-0.21787312203594755
0.08811281062548632,0.053353870774154835,363.6214507616982,128.02023633523947,-0.21787312203594755
0.0886202465390451,0.05366113222644529,364.11793292966195,128.02023633523947,-0.21787312203594755
0.08934968566478586,0.05410282056411282,364.82968804025364,128.02023633523947,-0.21787312203594755
0.09039627223650087,0.0547365473094619,365.8469563021795,128.02023633523947,-0.21787312203594755
0.09052313121489057,0.054813362672534505,365.9699486494327,128.02023633523947,-0.21787312203594755
0.09112571136224164,0.055178235647129426,366.55324678966525,128.02023633523947,-0.21787312203594755
0.09122085559603392,0.05523584716943389,366.64520880738144,128.02023633523947,-0.21787312203594755
0.09207715370016438,0.05575435087017404,367.4711904310342,128.02023633523947,-0.21787312203594755
0.09233087165694377,0.05590798159631927,367.71534970176936,128.02023633523947,-0.21787312203594755
0.09252116012452832,0.05602320464092819,367.89829747572537,128.02023633523947,-0.21787312203594755
0.09293345180429484,0.05627285457091419,368.2941816620186,128.02023633523947,-0.21787312203594755
0.09378974990842531,0.05679135827165434,369.11422073243654,128.02023633523947,-0.21787312203594755
0.09474119224634803,0.05736747349469894,370.0219583051083,128.02023633523947,-0.21787312203594755
0.09499491020312743,0.057521104220844166,370.26342033846515,128.02023633523947,-0.21787312203594755
0.0953437723936991,0.05773234646929386,370.59502036037486,128.02023633523947,-0.21787312203594755
0.09562920509507593,0.057905181036207246,370.86597764736575,128.02023633523947,-0.21787312203594755
0.09613664100863473,0.058212442488497704,371.3469019813986,128.02023633523947,-0.21787312203594755
0.09635864422081669,0.058346869373874774,371.556994961325,128.02023633523947,-0.21787312203594755
0.0965172179438038,0.05844288857771554,371.70694581554886,128.02023633523947,-0.21787312203594755
0.09686608013437548,0.05865413082616523,372.03649990413396,128.02023633523947,-0.21787312203594755
0.09810295517367502,0.05940308061612322,373.20120740439455,128.02023633523947,-0.21787312203594755
0.09822981415206473,0.05947989597919584,373.32033986317145,128.02023633523947,-0.21787312203594755
0.09873725006562353,0.0597871574314863,373.796270893206,128.02023633523947,-0.21787312203594755
0.10006926933871536,0.06059371874374875,375.04107323294176,128.02023633523947,-0.21787312203594755
0.1010207116766381,0.06116983396679336,375.9262645614716,128.02023633523947,-0.21787312203594755
0.10228930146053508,0.061937987597519506,377.1014783708531,128.02023633523947,-0.21787312203594755
0.10247958992811963,0.06205321064212843,377.2772689589638,128.02023633523947,-0.21787312203594755
0.10286016686328872,0.06228365673134627,377.6284686948159,128.02023633523947,-0.21787312203594755
0.1033676027768475,0.06259091818363673,378.09594770988167,128.02023633523947,-0.21787312203594755
0.10368475022282175,0.06278295659131826,378.38766764767394,128.02023633523947,-0.21787312203594755
0.10431904511477025,0.06316703340668134,378.97006562235657,128.02023633523947,-0.21787312203594755
0.10520705796349814,0.06370474094818963,379.78310793868803,128.02023633523947,-0.21787312203594755
0.10584135285544663,0.06408881776355271,380.3622146833969,128.02023633523947,-0.21787312203594755
0.10628535927981059,0.06435767153430687,380.7667843369482,128.02023633523947,-0.21787312203594755
0.10707822789474618,0.0648377675535107,381.4875945284335,128.02023633523947,-0.21787312203594755
0.10771252278669469,0.06522184436887378,382.0627450923149,128.02023633523947,-0.21787312203594755
0.10809309972186376,0.06545229045809162,382.40720143025175,128.02023633523947,-0.21787312203594755
0.10831510293404575,0.0655867173434687,382.6079158701746,128.02023633523947,-0.21787312203594755
0.10907625680438394,0.06604760952190439,383.29486490959533,128.02023633523947,-0.21787312203594755
0.10952026322874787,0.06631646329265853,383.6947218320699,128.02023633523947,-0.21787312203594755
0.1104399908220732,0.066873374674935,384.52099134285106,128.02023633523947,-0.21787312203594755
0.11180372483976246,0.0676991398279656,385.7412270203632,128.02023633523947,-0.21787312203594755
0.11250144922090578,0.06812162432486497,386.36328809086785,128.02023633523947,-0.21787312203594755
0.11332603258043882,0.06862092418483696,387.09651468592045,128.02023633523947,-0.21787312203594755
0.11383346849399761,0.06892818563712742,387.54669698180726,128.02023633523947,-0.21787312203594755
0.11494348455490747,0.0696003200640128,388.52875120773575,128.02023633523947,-0.21787312203594755
0.11519720251168687,0.06975395079015803,388.7527006025889,128.02023633523947,-0.21787312203594755
0.11602178587121992,0.07025325065013004,389.4792112272725,128.02023633523947,-0.21787312203594755
0.11729037565511691,0.07102140428085618,390.5930000644817,128.02023633523947,-0.21787312203594755
0.11763923784568855,0.07123264652930586,390.8984670859864,128.02023633523947,-0.21787312203594755
0.11957383726613148,0.07240408081616324,392.5860521321115,128.02023633523947,-0.21787312203594755
0.1201447026688851,0.07274974994999,393.08198898409444,128.02023633523947,-0.21787312203594755
0.12039842062566451,0.07290338067613523,393.30211028381297,128.02023633523947,-0.21787312203594755
0.12109614500680783,0.0733258651730346,393.9065130227366,128.02023633523947,-0.21787312203594755
0.1225867380028868,0.07422844568913783,395.19320577116184,128.02023633523947,-0.21787312203594755
0.12344303610701726,0.07474694938987798,395.9296101048818,128.02023633523947,-0.21787312203594755
0.12369675406379665,0.07490058011602321,396.14742103634666,128.02023633523947,-0.21787312203594755
0.12467991114631681,0.07549589917983597,396.9897978151904,128.02023633523947,-0.21787312203594755
0.1250287733368885,0.07570714142828566,397.28808247990304,128.02023633523947,-0.21787312203594755
0.12575821246262925,0.07614882976595319,397.9107217470733,128.02023633523947,-0.21787312203594755
0.12598021567481124,0.07628325665133028,398.0999408790553,128.02023633523947,-0.21787312203594755
0.12613878939779835,0.07637927585517104,398.235017792563,128.02023633523947,-0.21787312203594755
0.126709654800552,0.0767249449889978,398.72074729242286,128.02023633523947,-0.21787312203594755
0.12731223494790306,0.07708981796359272,399.232536782108,128.02023633523947,-0.21787312203594755
0.12747080867089017,0.07718583716743349,399.36706110130706,128.02023633523947,-0.21787312203594755
0.12766109713847473,0.07730106021204242,399.5284041642338,128.02023633523947,-0.21787312203594755
0.12870768371018973,0.07793478695739148,400.41412013676677,128.02023633523947,-0.21787312203594755
0.12911997538995623,0.07818443688737747,400.76226679601893,128.02023633523947,-0.21787312203594755
0.12934197860213822,0.07831886377275456,400.9495507943342,128.02023633523947,-0.21787312203594755
0.1295322670697228,0.07843408681736348,401.1099801754433,128.02023633523947,-0.21787312203594755
0.13016656196167126,0.07881816363272655,401.64408219449456,128.02023633523947,-0.21787312203594755
0.13045199466304808,0.07899099819963994,401.88409685082155,128.02023633523947,-0.21787312203594755
0.13105457481039917,0.07935587117423486,402.3901229076407,128.02023633523947,-0.21787312203594755
0.13130829276717856,0.07950950190038009,402.60291495171606,128.02023633523947,-0.21787312203594755
0.13159372546855536,0.07968233646729346,402.8421144219657,128.02023633523947,-0.21787312203594755
0.13222802036050385,0.08006641328265654,403.3729455463294,128.02023633523947,-0.21787312203594755
0.13245002357268582,0.08020084016803361,403.55850170225034,128.02023633523947,-0.21787312203594755
0.13273545627406266,0.080373674734947,403.7968957691957,128.02023633523947,-0.21787312203594755
0.13308431846463434,0.08058491698339669,404.08799495986017,128.02023633523947,-0.21787312203594755
0.13368689861198538,0.0809497899579916,404.5901026690493,128.02023633523947,-0.21787312203594755
0.13444805248232355,0.08141068213642728,405.2230841554157,128.02023633523947,-0.21787312203594755
0.13558978328783086,0.08210202040408082,406.16994223106053,128.02023633523947,-0.21787312203594755
0.13625579292437678,0.08250530106021205,406.72084014972114,128.02023633523947,-0.21787312203594755
0.13635093715816904,0.08256291258251651,406.7994540389568,128.02023633523947,-0.21787312203594755
0.13717552051770207,0.0830622124424885,407.4798805840641,128.02023633523947,-0.21787312203594755
0.13765124168666346,0.0833502700540108,407.87170874421827,128.02023633523947,-0.21787312203594755
0.1377146711758583,0.08338867773554712,407.9239125679682,128.02023633523947,-0.21787312203594755
0.13809524811102739,0.08361912382476495,408.2369388145492,128.02023633523947,-0.21787312203594755
0.13882468723676816,0.0840608121624325,408.8359669879125,128.02023633523947,-0.21787312203594755
0.1390149757043527,0.08417603520704141,408.9920331679551,128.02023633523947,-0.21787312203594755
0.13987127380848316,0.08469453890778156,409.6933025068743,128.02023633523947,-0.21787312203594755
0.14037870972204197,0.08500180036007202,410.10807945862996,128.02023633523947,-0.21787312203594755
0.14079100140180847,0.08525145029005801,410.44465534237014,128.02023633523947,-0.21787312203594755
0.14161558476134153,0.08575075015003002,411.1166561406795,128.02023633523947,-0.21787312203594755
0.14221816490869257,0.08611562312462492,411.6067689926595,128.02023633523947,-0.21787312203594755
0.14278903031144624,0.0864612922584517,412.0703399052346,128.02023633523947,-0.21787312203594755
0.14393076111695352,0.08715263052610522,412.9953190000778,128.02023633523947,-0.21787312203594755
0.14424790856292774,0.08734466893378676,413.25174922872856,128.02023633523947,-0.21787312203594755
0.1445333412643046,0.08751750350070014,413.4823484984805,128.02023633523947,-0.21787312203594755
0.14592879002659126,0.0883624724944989,414.60717607767515,128.02023633523947,-0.21787312203594755
0.14678508813072172,0.08888097619523905,415.29533460252924,128.02023633523947,-0.21787312203594755
0.14865625806196978,0.09001400280056011,416.7936632239675,128.02023633523947,-0.21787312203594755
0.14900512025254145,0.0902252450490098,417.07219724907424,128.02023633523947,-0.21787312203594755
0.14944912667690538,0.09049409881976396,417.42632754433583,128.02023633523947,-0.21787312203594755
0.15071771646080237,0.0912622524504901,418.43587448933533,128.02023633523947,-0.21787312203594755
0.15163744405412768,0.09181916383276656,419.1657249177726,128.02023633523947,-0.21787312203594755
0.15211316522308904,0.09210722144428886,419.54255620202713,128.02023633523947,-0.21787312203594755
0.15328661077319375,0.09281776355271054,420.4701135954687,128.02023633523947,-0.21787312203594755
0.15388919092054482,0.09318263652730546,420.9453504452877,128.02023633523947,-0.21787312203594755
0.15430148260031135,0.09343228645729146,421.27009442401965,128.02023633523947,-0.21787312203594755
0.15455520055709074,0.09358591718343669,421.4697686772446,128.02023633523947,-0.21787312203594755
0.1556335018734032,0.09423884776955392,422.31696204490765,128.02023633523947,-0.21787312203594755
0.15652151472213105,0.09477655531106222,423.0129331531865,128.02023633523947,-0.21787312203594755
0.1578535339952229,0.09558311662332467,424.0540093917446,128.02023633523947,-0.21787312203594755
0.1581072519520023,0.0957367473494699,424.251920584694,128.02023633523947,-0.21787312203594755
0.1585195436317688,0.09598639727945589,424.57326230611534,128.02023633523947,-0.21787312203594755
0.15953441545888639,0.0966009201840368,425.36287177945786,128.02023633523947,-0.21787312203594755
0.1599149923940555,0.09683136627325466,425.6584699720501,128.02023633523947,-0.21787312203594755
0.16023213984002974,0.09702340468093619,425.9045922777416,128.02023633523947,-0.21787312203594755
0.16064443151979624,0.09727305461092219,426.22426742979917,128.02023633523947,-0.21787312203594755
0.16092986422117309,0.09744588917783557,426.4453935822687,128.02023633523947,-0.21787312203594755
0.16172273283610866,0.0979259851970394,427.0588317836768,128.02023633523947,-0.21787312203594755
0.16283274889701854,0.09859811962392478,427.9156784274462,128.02023633523947,-0.21787312203594755
0.1640696239363181,0.09934706941388279,428.86777150377156,128.02023633523947,-0.21787312203594755
0.16425991240390264,0.0994622924584917,429.01399853687144,128.02023633523947,-0.21787312203594755
0.16502106627424082,0.09992318463692738,429.59824722634664,128.02023633523947,-0.21787312203594755