File: datasets/aisi_316_L/data/M1/train_36.csv
Time(s),Strain(%),Stress(MPa),Temp(C),Log_SR(s-1)
0.0,0.0,0.0,328.6289223789483,2.4920074214526693
1.3141736093614928e-07,4.0799999999999996e-05,7.151063174999999,328.6289223789483,2.4920074214526693
1.8810720290860586e-07,5.8399999999999997e-05,10.235835524999999,328.6289223789483,2.4920074214526693
2.2675936788982625e-07,7.04e-05,12.3390894,328.6289223789483,2.4920074214526693
3.0148688685351896e-07,9.36e-05,16.405380225,328.6289223789483,2.4920074214526693
4.0198251580469196e-07,0.0001248,21.8738403,328.6289223789483,2.4920074214526693
4.535187357796525e-07,0.0001408,24.6781788,328.6289223789483,2.4920074214526693
5.07631766753361e-07,0.00015759999999999998,27.622734225,328.6289223789483,2.4920074214526693
6.15857828700778e-07,0.00019119999999999999,33.511845075,328.6289223789483,2.4920074214526693
6.854317256669747e-07,0.0002128,37.29770205,328.6289223789483,2.4920074214526693
7.343911346431872e-07,0.00022799999999999999,39.961823625,328.6289223789483,2.4920074214526693
7.962345986131399e-07,0.0002472,43.327029825,328.6289223789483,2.4920074214526693
8.220027086006201e-07,0.00025519999999999997,44.729199075,328.6289223789483,2.4920074214526693
8.451940075893523e-07,0.0002624,45.9911514,328.6289223789483,2.4920074214526693
8.735389285755805e-07,0.0002712,47.533537575,328.6289223789483,2.4920074214526693
9.250751485505411e-07,0.0002872,50.337876075,328.6289223789483,2.4920074214526693
9.431128255417772e-07,0.00029279999999999996,51.31939454999999,328.6289223789483,2.4920074214526693
9.998026675142339e-07,0.0003104,54.4041669,328.6289223789483,2.4920074214526693
1.015263533506722e-06,0.00031519999999999996,55.24546845,328.6289223789483,2.4920074214526693
1.0616461314841866e-06,0.0003296,57.769373099999996,328.6289223789483,2.4920074214526693
1.0745301864779265e-06,0.0003336,58.470457724999996,328.6289223789483,2.4920074214526693
1.1157591624578949e-06,0.00034639999999999996,60.71392852499999,328.6289223789483,2.4920074214526693
1.2291388464028081e-06,0.0003816,66.883473225,328.6289223789483,2.4920074214526693
1.2961359323702568e-06,0.00040239999999999997,70.529113275,328.6289223789483,2.4920074214526693
1.314173609361493e-06,0.000408,71.51063175,328.6289223789483,2.4920074214526693
1.327057664355233e-06,0.000412,72.211716375,328.6289223789483,2.4920074214526693
1.3657098293364534e-06,0.000424,74.31497025,328.6289223789483,2.4920074214526693
1.3940547503226817e-06,0.0004328,75.857356425,328.6289223789483,2.4920074214526693
1.42239967130891e-06,0.0004416,77.3997426,328.6289223789483,2.4920074214526693
1.520318489261335e-06,0.000472,82.72798575,328.6289223789483,2.4920074214526693
1.538356166252571e-06,0.00047759999999999995,83.70950422499999,328.6289223789483,2.4920074214526693
1.5821619532312877e-06,0.0004912,86.09319195,328.6289223789483,2.4920074214526693
1.620814118212508e-06,0.0005032,88.196445825,328.6289223789483,2.4920074214526693
1.6671967161899726e-06,0.0005176,90.720350475,328.6289223789483,2.4920074214526693
1.7187329361649328e-06,0.0005336,93.52468897499999,328.6289223789483,2.4920074214526693
1.832112620109846e-06,0.0005688,99.69423367499999,328.6289223789483,2.4920074214526693
1.8862256510835543e-06,0.0005855999999999999,102.63878909999998,328.6289223789483,2.4920074214526693
1.960953170047247e-06,0.0006087999999999999,106.70507992499999,328.6289223789483,2.4920074214526693
2.017643012019704e-06,0.0006263999999999999,109.78985227499999,328.6289223789483,2.4920074214526693
2.0743328539921604e-06,0.0006439999999999999,112.87462462499998,328.6289223789483,2.4920074214526693
2.1851357269383256e-06,0.0006784,118.90395240000001,328.6289223789483,2.4920074214526693
2.329437142868215e-06,0.0007232,126.7561002,328.6289223789483,2.4920074214526693
2.399011039834412e-06,0.0007448,130.541957175,328.6289223789483,2.4920074214526693
2.4866226137918447e-06,0.000772,135.309332625,328.6289223789483,2.4920074214526693
2.5098139127805766e-06,0.0007792,136.57128495,328.6289223789483,2.4920074214526693
2.527851589771813e-06,0.0007848,137.552803425,328.6289223789483,2.4920074214526693
2.561350132755537e-06,0.0007951999999999999,139.37562344999998,328.6289223789483,2.4920074214526693
2.5819646207455216e-06,0.0008016,140.49735884999998,328.6289223789483,2.4920074214526693
2.62319359672549e-06,0.0008144,142.74082965,328.6289223789483,2.4920074214526693
2.7056515486854265e-06,0.0008399999999999999,147.22777125,328.6289223789483,2.4920074214526693
2.7597645796591354e-06,0.0008568,150.172326675,328.6289223789483,2.4920074214526693
2.8370689096215757e-06,0.0008807999999999999,154.37883442499998,328.6289223789483,2.4920074214526693
2.875721074602796e-06,0.0008927999999999999,156.4820883,328.6289223789483,2.4920074214526693
2.9556022155639853e-06,0.0009176,160.828812975,328.6289223789483,2.4920074214526693
2.9968311915439536e-06,0.0009304,163.072283775,328.6289223789483,2.4920074214526693
3.141132607473843e-06,0.0009752,170.924431575,328.6289223789483,2.4920074214526693
3.1669007174613234e-06,0.0009832,172.326600825,328.6289223789483,2.4920074214526693
3.22359055943378e-06,0.0010008,175.411373175,328.6289223789483,2.4920074214526693
3.2338978034287717e-06,0.001004,175.97224087499998,328.6289223789483,2.4920074214526693
3.2725499684099923e-06,0.001016,178.07549475,328.6289223789483,2.4920074214526693
3.355007920369929e-06,0.0010416,182.56243634999998,328.6289223789483,2.4920074214526693
3.44519630532611e-06,0.0010696,183.95883277742467,328.6289223789483,2.4920074214526693
3.465810793316094e-06,0.001076,183.9959951565446,328.6289223789483,2.4920074214526693
3.494155714302322e-06,0.0010848,184.04695297687928,328.6289223789483,2.4920074214526693
3.558575989271023e-06,0.0011048,184.1621704129424,328.6289223789483,2.4920074214526693
3.664225240219692e-06,0.0011376,184.34938140282242,328.6289223789483,2.4920074214526693
3.7209150821921483e-06,0.0011551999999999999,184.44896765203106,328.6289223789483,2.4920074214526693
3.7698744911683614e-06,0.0011704,184.5344987032828,328.6289223789483,2.4920074214526693
3.821410711143322e-06,0.0011864,184.62406469308394,328.6289223789483,2.4920074214526693
3.893561419108266e-06,0.0012088,184.74866966107302,328.6289223789483,2.4920074214526693
3.942520828084479e-06,0.001224,184.8327105861008,328.6289223789483,2.4920074214526693
4.01982515804692e-06,0.001248,184.96458278309174,328.6289223789483,2.4920074214526693
4.040439646036904e-06,0.0012544,184.99958119260322,328.6289223789483,2.4920074214526693
4.210509171954273e-06,0.0013072,185.28570789279036,328.6289223789483,2.4920074214526693
4.2388540929405014e-06,0.001316,185.33295400416173,328.6289223789483,2.4920074214526693
4.282659879919218e-06,0.0013296,185.40572908849887,328.6289223789483,2.4920074214526693
4.329042477896683e-06,0.001344,185.48246934115855,328.6289223789483,2.4920074214526693
4.419230862852863e-06,0.001372,185.63077468369346,328.6289223789483,2.4920074214526693
4.444998972840344e-06,0.00138,185.67293022148488,328.6289223789483,2.4920074214526693
4.452729405836588e-06,0.0013824,185.6855582837297,328.6289223789483,2.4920074214526693
4.524880113801533e-06,0.0014047999999999999,185.8030107617091,328.6289223789483,2.4920074214526693
4.550648223789012e-06,0.0014127999999999999,185.8447807702733,328.6289223789483,2.4920074214526693
4.571262711778997e-06,0.0014192,185.8781303995323,328.6289223789483,2.4920074214526693
4.6279525537514535e-06,0.0014368,185.9695408105692,328.6289223789483,2.4920074214526693
4.6846423957239105e-06,0.0014544,186.06051555667273,328.6289223789483,2.4920074214526693
4.705256883713895e-06,0.0014608,186.09349070119208,328.6289223789483,2.4920074214526693
4.754216292690107e-06,0.0014759999999999999,186.17158167475782,328.6289223789483,2.4920074214526693
4.7799844026775865e-06,0.0014839999999999999,186.2125561791593,328.6289223789483,2.4920074214526693
4.823790189656303e-06,0.0014976,186.28201568187262,328.6289223789483,2.4920074214526693
4.9165553856112324e-06,0.0015264,186.42829952218364,328.6289223789483,2.4920074214526693
4.9526307395937045e-06,0.0015375999999999999,186.48489648592957,328.6289223789483,2.4920074214526693
5.011897392564909e-06,0.0015559999999999999,186.57752941401947,328.6289223789483,2.4920074214526693
5.027358258557398e-06,0.0015608,186.60162414317094,328.6289223789483,2.4920074214526693
5.055703179543626e-06,0.0015696,186.6457228901574,328.6289223789483,2.4920074214526693
5.10208577752109e-06,0.001584,186.71767705496723,328.6289223789483,2.4920074214526693
5.1175466435135785e-06,0.0015888,186.74160502623113,328.6289223789483,2.4920074214526693
5.328845145410916e-06,0.0016543999999999999,187.0658455879993,328.6289223789483,2.4920074214526693
5.426763963363342e-06,0.0016848,187.21439929395203,328.6289223789483,2.4920074214526693
5.45510888434957e-06,0.0016936,187.2572060999805,328.6289223789483,2.4920074214526693
5.483453805335798e-06,0.0017024,187.2999262474172,328.6289223789483,2.4920074214526693
5.511798726322026e-06,0.0017112,187.34256035829543,328.6289223789483,2.4920074214526693
5.53241321431201e-06,0.0017176,187.37351329601032,328.6289223789483,2.4920074214526693
5.59941030027946e-06,0.0017384,187.47380111882853,328.6289223789483,2.4920074214526693
5.65094652025442e-06,0.0017544,187.55062747917427,328.6289223789483,2.4920074214526693
5.656100142251916e-06,0.001756,187.5582950556725,328.6289223789483,2.4920074214526693
5.6741378192431515e-06,0.0017615999999999999,187.58511014283584,328.6289223789483,2.4920074214526693
5.70248274022938e-06,0.0017703999999999999,187.62718106657198,328.6289223789483,2.4920074214526693
5.764326204199333e-06,0.0017896,187.71869012229246,328.6289223789483,2.4920074214526693
5.815862424174293e-06,0.0018055999999999999,187.79465554720178,328.6289223789483,2.4920074214526693
5.841630534161773e-06,0.0018135999999999998,187.83253977804762,328.6289223789483,2.4920074214526693
5.875129077145498e-06,0.0018239999999999999,187.88169198652054,328.6289223789483,2.4920074214526693
5.9112044311279705e-06,0.0018352,187.93450306006136,328.6289223789483,2.4920074214526693
5.983355139092915e-06,0.0018575999999999998,188.0397496196815,328.6289223789483,2.4920074214526693
5.998816005085403e-06,0.0018624,188.06223792656644,328.6289223789483,2.4920074214526693
6.076120335047844e-06,0.0018863999999999999,188.17434217391636,328.6289223789483,2.4920074214526693
6.2075376959839934e-06,0.0019272,188.3636511268237,328.6289223789483,2.4920074214526693
6.2358826169702215e-06,0.001936,188.40427680967,328.6289223789483,2.4920074214526693
6.292572458942678e-06,0.0019535999999999998,188.4853127632673,328.6289223789483,2.4920074214526693
6.377607221901363e-06,0.00198,188.6063348734626,328.6289223789483,2.4920074214526693
6.393068087893852e-06,0.0019848,188.62827111386218,328.6289223789483,2.4920074214526693
6.44718111886756e-06,0.0020016,188.70488555549048,328.6289223789483,2.4920074214526693
6.480679661851284e-06,0.002012,188.7521878830844,328.6289223789483,2.4920074214526693
6.48583328384878e-06,0.0020136,188.75945669196946,328.6289223789483,2.4920074214526693
6.552830369816229e-06,0.0020344,188.85374715697665,328.6289223789483,2.4920074214526693
6.658479620764898e-06,0.0020672,189.00167562764565,328.6289223789483,2.4920074214526693
6.673940486757386e-06,0.002072,189.0232466680731,328.6289223789483,2.4920074214526693
6.697131785746118e-06,0.0020792,189.05556672306372,328.6289223789483,2.4920074214526693
6.779589737706055e-06,0.0021048,189.1701306479211,328.6289223789483,2.4920074214526693
6.8208187136860226e-06,0.0021176,189.22720873081767,328.6289223789483,2.4920074214526693
6.867201311663487e-06,0.0021319999999999998,189.29126098300543,328.6289223789483,2.4920074214526693
6.900699854647212e-06,0.0021424,189.33741605808743,328.6289223789483,2.4920074214526693
6.936775208629684e-06,0.0021536,189.3870239104766,328.6289223789483,2.4920074214526693
6.944505641625928e-06,0.002156,189.39764106263758,328.6289223789483,2.4920074214526693
7.001195483598385e-06,0.0021736,189.4753598269725,328.6289223789483,2.4920074214526693
7.063038947568338e-06,0.0021928,189.55986455693977,328.6289223789483,2.4920074214526693
7.091383868554565e-06,0.0022015999999999997,189.59849940369986,328.6289223789483,2.4920074214526693
7.132612844534535e-06,0.0022144,189.65458820610155,328.6289223789483,2.4920074214526693
7.155804143523266e-06,0.0022216,189.68608258900332,328.6289223789483,2.4920074214526693
7.212493985495722e-06,0.0022392,189.76290174094368,328.6289223789483,2.4920074214526693
7.2614533944719346e-06,0.0022543999999999997,189.82905624526444,328.6289223789483,2.4920074214526693
7.3464881574306206e-06,0.0022808,189.9435442130227,328.6289223789483,2.4920074214526693
7.3542185904268645e-06,0.0022832,189.95392651502772,328.6289223789483,2.4920074214526693
7.405754810401825e-06,0.0022992,190.02303341243788,328.6289223789483,2.4920074214526693
7.4186388653955655e-06,0.0023032,190.0402808000325,328.6289223789483,2.4920074214526693
7.485635951363014e-06,0.002324,190.12977959854086,328.6289223789483,2.4920074214526693
7.508827250351746e-06,0.0023312,190.16068709577968,328.6289223789483,2.4920074214526693
7.624783745295407e-06,0.0023672,190.31466964750405,328.6289223789483,2.4920074214526693
7.645398233285392e-06,0.0023736,190.34194843805304,328.6289223789483,2.4920074214526693
7.67116634327287e-06,0.0023815999999999998,190.37600662099032,328.6289223789483,2.4920074214526693
7.72527937424658e-06,0.0023983999999999998,190.44738391671714,328.6289223789483,2.4920074214526693
7.753624295232809e-06,0.0024072,190.4846941904562,328.6289223789483,2.4920074214526693
7.846389491187736e-06,0.002436,190.606430306311,328.6289223789483,2.4920074214526693
7.877311223172714e-06,0.0024456,190.64688410729931,328.6289223789483,2.4920074214526693
7.910809766156437e-06,0.002456,190.6906392345025,328.6289223789483,2.4920074214526693
7.952038742136406e-06,0.0024687999999999997,190.74439262771006,328.6289223789483,2.4920074214526693
8.01130539510761e-06,0.0024871999999999997,190.82147309890115,328.6289223789483,2.4920074214526693
8.065418426081318e-06,0.0025039999999999997,190.89165691687958,328.6289223789483,2.4920074214526693
8.119531457055027e-06,0.0025207999999999997,190.96165732934915,328.6289223789483,2.4920074214526693
8.147876378041256e-06,0.0025296,190.99825158700534,328.6289223789483,2.4920074214526693
8.18137492102498e-06,0.0025399999999999997,191.04143539803658,328.6289223789483,2.4920074214526693
8.20714303101246e-06,0.002548,191.07460680687407,328.6289223789483,2.4920074214526693
8.266409683983666e-06,0.0025664,191.15074728581322,328.6289223789483,2.4920074214526693
8.279293738977406e-06,0.0025704,191.16727135793994,328.6289223789483,2.4920074214526693
8.361751690937343e-06,0.002596,191.2727889327667,328.6289223789483,2.4920074214526693
8.441632831898532e-06,0.0026208,191.37462277674803,328.6289223789483,2.4920074214526693
8.516360350862225e-06,0.002644,191.46954699245646,328.6289223789483,2.4920074214526693
8.609125546817153e-06,0.0026728,191.5869332389062,328.6289223789483,2.4920074214526693
8.683853065780846e-06,0.002696,191.68113603696096,328.6289223789483,2.4920074214526693
8.732812474757057e-06,0.0027112,191.74268374033053,328.6289223789483,2.4920074214526693
8.76888782873953e-06,0.0027224,191.7879486026146,328.6289223789483,2.4920074214526693
8.804963182722003e-06,0.0027336,191.83314089692428,328.6289223789483,2.4920074214526693
8.877113890686947e-06,0.0027559999999999998,191.92330942939967,328.6289223789483,2.4920074214526693
8.944110976654396e-06,0.0027768,192.00678176273163,328.6289223789483,2.4920074214526693
8.975032708639374e-06,0.0027864,192.045225175115,328.6289223789483,2.4920074214526693
9.01626168461934e-06,0.0027992,192.09640280209166,328.6289223789483,2.4920074214526693
9.036876172609324e-06,0.0028055999999999997,192.1219573840846,328.6289223789483,2.4920074214526693
9.129641368564254e-06,0.0028344,192.23667282096528,328.6289223789483,2.4920074214526693
9.230136997515427e-06,0.0028656,192.36043609196045,328.6289223789483,2.4920074214526693
9.258481918501656e-06,0.0028744,192.3952485211706,328.6289223789483,2.4920074214526693
9.310018138476615e-06,0.0028904,192.4584375430006,328.6289223789483,2.4920074214526693
9.358977547452829e-06,0.0029056,192.51834087694684,328.6289223789483,2.4920074214526693
9.377015224444064e-06,0.0029112,192.54037970289608,328.6289223789483,2.4920074214526693
9.454319554406505e-06,0.0029352,192.63464516069118,328.6289223789483,2.4920074214526693
9.500702152383969e-06,0.0029495999999999997,192.69106015701166,328.6289223789483,2.4920074214526693
9.52647026237145e-06,0.0029576,192.72235540582437,328.6289223789483,2.4920074214526693
9.637273135317614e-06,0.002992,192.85655052726875,328.6289223789483,2.4920074214526693
9.753229630261276e-06,0.003028,192.99634450914775,328.6289223789483,2.4920074214526693
9.79961222823874e-06,0.0030424,193.05208042801766,328.6289223789483,2.4920074214526693
9.809919472233732e-06,0.0030456,193.06445220495672,328.6289223789483,2.4920074214526693
9.82795714922497e-06,0.0030512,193.08609062281647,328.6289223789483,2.4920074214526693
9.89237742419367e-06,0.0030712,193.16324457087347,328.6289223789483,2.4920074214526693
9.93102958917489e-06,0.0030832,193.20944288927362,328.6289223789483,2.4920074214526693
9.974835376153605e-06,0.0030968,193.26171629498975,328.6289223789483,2.4920074214526693
1.0077907816103527e-05,0.0031287999999999997,193.38436064469997,328.6289223789483,2.4920074214526693
1.0121713603082245e-05,0.0031424,193.43633624834163,328.6289223789483,2.4920074214526693
1.0227362854030912e-05,0.0031752,193.5613295602882,328.6289223789483,2.4920074214526693
1.0278899074005873e-05,0.0031912,193.62211909286876,328.6289223789483,2.4920074214526693
1.0314974427988346e-05,0.0032023999999999998,193.66460105973476,328.6289223789483,2.4920074214526693
1.0348472970972071e-05,0.0032128,193.70399674573582,328.6289223789483,2.4920074214526693
1.041289324594077e-05,0.0032327999999999996,193.77961817297634,328.6289223789483,2.4920074214526693
1.0451545410921991e-05,0.0032448,193.82490345476776,328.6289223789483,2.4920074214526693
1.0513388874891944e-05,0.003264,193.89722428642776,328.6289223789483,2.4920074214526693
1.0613884503843117e-05,0.0032952,194.01439277946056,328.6289223789483,2.4920074214526693
1.0652536668824337e-05,0.0033071999999999997,194.05934227935938,328.6289223789483,2.4920074214526693
1.0714380132794289e-05,0.0033263999999999998,194.13112940113172,328.6289223789483,2.4920074214526693
1.0755609108774257e-05,0.0033391999999999996,194.17889772586696,328.6289223789483,2.4920074214526693
1.0902487335702895e-05,0.0033848,194.34849506942257,328.6289223789483,2.4920074214526693
1.0979791665665336e-05,0.0034088,194.4373987918099,328.6289223789483,2.4920074214526693
1.100040615365532e-05,0.0034151999999999997,194.46106518058184,328.6289223789483,2.4920074214526693
1.1069980050621517e-05,0.0034368,194.5408118540318,328.6289223789483,2.4920074214526693
1.1108632215602736e-05,0.0034487999999999997,194.58503109363946,328.6289223789483,2.4920074214526693
1.1136977136588966e-05,0.0034576,194.61742040877314,328.6289223789483,2.4920074214526693
1.1155014813580202e-05,0.0034632,194.63801505324813,328.6289223789483,2.4920074214526693
1.1185936545565177e-05,0.0034728,194.67328996762987,328.6289223789483,2.4920074214526693
1.119624378956017e-05,0.003476,194.68503981872888,328.6289223789483,2.4920074214526693
1.1229742332543893e-05,0.0034863999999999997,194.7231977333037,328.6289223789483,2.4920074214526693
1.1289008985515099e-05,0.0035047999999999998,194.7905993206575,328.6289223789483,2.4920074214526693
1.1319930717500077e-05,0.0035144,194.8257105745159,328.6289223789483,2.4920074214526693
1.1345698827487555e-05,0.0035223999999999997,194.8549413885362,328.6289223789483,2.4920074214526693
1.1510614731407428e-05,0.0035735999999999997,195.04140921141268,328.6289223789483,2.4920074214526693
1.1528652408398666e-05,0.0035792,195.06174071896652,328.6289223789483,2.4920074214526693
1.154926689638865e-05,0.0035856,195.08496154262014,328.6289223789483,2.4920074214526693
1.1598226305364862e-05,0.0036008,195.1400463107571,328.6289223789483,2.4920074214526693
1.1636878470346083e-05,0.0036127999999999998,195.1834702537251,328.6289223789483,2.4920074214526693
1.1657492958336068e-05,0.0036192,195.20660668786587,328.6289223789483,2.4920074214526693
1.1688414690321042e-05,0.0036287999999999997,195.24128144380245,328.6289223789483,2.4920074214526693
1.1729643666301012e-05,0.0036416,195.28745885217504,328.6289223789483,2.4920074214526693
1.1799217563267208e-05,0.0036631999999999997,195.36523994643036,328.6289223789483,2.4920074214526693
1.1910020436213373e-05,0.0036975999999999997,195.48874528931358,328.6289223789483,2.4920074214526693
1.1928058113204609e-05,0.0037032,195.5088083215994,328.6289223789483,2.4920074214526693
1.2002785632168302e-05,0.0037264,195.59180086072504,328.6289223789483,2.4920074214526693
1.2054321852143263e-05,0.0037424,195.64891972217626,328.6289223789483,2.4920074214526693
1.2105858072118224e-05,0.0037584,195.70594342383401,328.6289223789483,2.4920074214526693
1.2113588505114467e-05,0.0037608,195.71448880640364,328.6289223789483,2.4920074214526693
1.2129049371106956e-05,0.0037656,195.7315731938143,328.6289223789483,2.4920074214526693
1.2180585591081916e-05,0.0037816,195.7884599116331,328.6289223789483,2.4920074214526693
1.2245005866050617e-05,0.0038016,195.85943647914425,328.6289223789483,2.4920074214526693
1.2386730470981757e-05,0.0038456,196.01507432944433,328.6289223789483,2.4920074214526693
1.257999129588786e-05,0.0039056,196.22619313343236,328.6289223789483,2.4920074214526693
1.2695947790831522e-05,0.0039416,196.35225733811075,328.6289223789483,2.4920074214526693
1.2737176766811488e-05,0.003954399999999999,196.3969718496976,328.6289223789483,2.4920074214526693
1.2819634718771427e-05,0.00398,196.48623189057074,328.6289223789483,2.4920074214526693
1.2837672395762662e-05,0.0039856,196.50572764459415,328.6289223789483,2.4920074214526693
1.286859412774764e-05,0.0039952,196.53912410088776,328.6289223789483,2.4920074214526693
1.3255190004562008e-05,0.004115223044608922,196.95405279396255,328.6289223789483,2.4920074214526693
1.3873748355931808e-05,0.004307261452290458,197.60825803072296,328.6289223789483,2.4920074214526693
1.4925297553260469e-05,0.00463372674534907,198.69487430734154,328.6289223789483,2.4920074214526693
1.733767512360269e-05,0.005382676535307062,201.0806088851089,328.6289223789483,2.4920074214526693
1.8141800980383428e-05,0.005632326465293058,201.84656662628998,328.6289223789483,2.4920074214526693
1.8389224320931347e-05,0.005709141828365673,202.0795667063861,328.6289223789483,2.4920074214526693
1.9564485188533967e-05,0.006074014802960592,203.1700386447866,328.6289223789483,2.4920074214526693
1.981190852908189e-05,0.006150830166033207,203.39632164560547,328.6289223789483,2.4920074214526693
2.0183043539903768e-05,0.0062660532106421285,203.73369052130704,328.6289223789483,2.4920074214526693
2.117273690209545e-05,0.006573314662932587,204.62171663711644,328.6289223789483,2.4920074214526693
2.197686275887619e-05,0.006822964592918584,205.33137356300654,328.6289223789483,2.4920074214526693
2.2595421110245988e-05,0.00701500300060012,205.87039328557154,328.6289223789483,2.4920074214526693
2.3152123626478806e-05,0.007187837567513502,206.35061001659898,328.6289223789483,2.4920074214526693
2.476037534004029e-05,0.007687137427485497,207.71323058494366,328.6289223789483,2.4920074214526693
2.655419455901271e-05,0.008244048809761952,209.19296748407555,328.6289223789483,2.4920074214526693
2.785316709688929e-05,0.008647329465893179,210.24025898914894,328.6289223789483,2.4920074214526693
2.970884215099869e-05,0.009223444688937788,211.70392314093183,328.6289223789483,2.4920074214526693
3.119338219428621e-05,0.009684336867373475,212.84933067661726,328.6289223789483,2.4920074214526693
3.144080553483413e-05,0.00976115223044609,213.03814569849965,328.6289223789483,2.4920074214526693
3.317276891866957e-05,0.01029885977195439,214.3439929145599,328.6289223789483,2.4920074214526693
3.348204809435447e-05,0.01039487897579516,214.5743539135939,328.6289223789483,2.4920074214526693
3.3915038940313325e-05,0.010529305861172233,214.89546997267811,328.6289223789483,2.4920074214526693
3.4100606445724275e-05,0.010586917383476696,215.03260124664232,328.6289223789483,2.4920074214526693
3.6018137334970646e-05,0.011182236447289457,216.43298847687672,328.6289223789483,2.4920074214526693
3.6389272345792525e-05,0.011297459491898379,216.70063974899645,328.6289223789483,2.4920074214526693
3.719339820257327e-05,0.011547109421884378,217.27692563163652,328.6289223789483,2.4920074214526693
3.861608241072381e-05,0.01198879775955191,218.2847431162614,328.6289223789483,2.4920074214526693
3.923464076209361e-05,0.012180836167233446,218.71839620914866,328.6289223789483,2.4920074214526693
3.954391993777851e-05,0.012276855371074214,218.93422226675767,328.6289223789483,2.4920074214526693
4.028618995942227e-05,0.012507301460292058,219.44953635980826,328.6289223789483,2.4920074214526693
4.090474831079207e-05,0.012699339867973595,219.87614213851703,328.6289223789483,2.4920074214526693
4.115217165133999e-05,0.012776155231046209,220.04607908899288,328.6289223789483,2.4920074214526693
4.152330666216187e-05,0.012891378275655131,220.30023927916628,328.6289223789483,2.4920074214526693
4.220372084866865e-05,0.013102620524104821,220.76391042326378,328.6289223789483,2.4920074214526693
4.269856752976449e-05,0.01325625125025005,221.09929660133736,328.6289223789483,2.4920074214526693
4.4554242583873894e-05,0.013832366473294659,222.34371790103353,328.6289223789483,2.4920074214526693
4.473981008928483e-05,0.01388997799559912,222.4670377660913,328.6289223789483,2.4920074214526693
4.5482080110928595e-05,0.014120424084816964,222.95833538303353,328.6289223789483,2.4920074214526693
4.579135928661349e-05,0.014216443288657732,223.16211865806648,328.6289223789483,2.4920074214526693
4.845116019750363e-05,0.015042208441688338,224.89303404262085,328.6289223789483,2.4920074214526693
5.012126774620209e-05,0.015560712142428487,225.96096409299443,328.6289223789483,2.4920074214526693
5.0863537767845856e-05,0.01579115823164633,226.43113517907364,328.6289223789483,2.4920074214526693
5.247178948140734e-05,0.016290458091618325,227.4407558150017,328.6289223789483,2.4920074214526693
5.339962700846203e-05,0.016578515703140628,228.01773875934023,328.6289223789483,2.4920074214526693
5.401818535983183e-05,0.016770554110822164,228.40022335402122,328.6289223789483,2.4920074214526693
5.414189703010579e-05,0.01680896179235847,228.47651488291325,328.6289223789483,2.4920074214526693
5.562643707339331e-05,0.01726985397079416,229.386773430135,328.6289223789483,2.4920074214526693
5.612128375448915e-05,0.017423484696939388,229.68808102479443,328.6289223789483,2.4920074214526693
5.828623798428345e-05,0.018095619123824763,230.99430369362264,328.6289223789483,2.4920074214526693
5.8781084665379286e-05,0.018249249849969992,231.29019566102812,328.6289223789483,2.4920074214526693
6.026562470866681e-05,0.01871014202840568,232.172096924258,328.6289223789483,2.4920074214526693
6.236872310332414e-05,0.019363072614522907,233.407088895495,328.6289223789483,2.4920074214526693
6.391511898174863e-05,0.019843168633726746,234.30483320516288,328.6289223789483,2.4920074214526693
6.52759473547622e-05,0.020265653130626126,235.08786387213613,328.6289223789483,2.4920074214526693
6.577079403585804e-05,0.020419283856771355,235.37102049452167,328.6289223789483,2.4920074214526693
6.985327915489872e-05,0.021686737347469495,237.67617776437498,328.6289223789483,2.4920074214526693
7.220380089010396e-05,0.022416483296659333,238.9795432635638,328.6289223789483,2.4920074214526693
7.418318761448732e-05,0.02303100620124025,240.06432806561247,328.6289223789483,2.4920074214526693
7.535844848208993e-05,0.023395879175835167,240.7030784870753,328.6289223789483,2.4920074214526693
7.628628600914463e-05,0.02368393678735747,241.20461490327668,328.6289223789483,2.4920074214526693
7.678113269024046e-05,0.0238375675135027,241.47112798204046,328.6289223789483,2.4920074214526693
7.894608692003478e-05,0.024509701940388078,242.62933413282994,328.6289223789483,2.4920074214526693
8.036877112818531e-05,0.02495139027805561,243.38370241610892,328.6289223789483,2.4920074214526693
8.073990613900719e-05,0.025066613322664532,243.57963536735204,328.6289223789483,2.4920074214526693
8.22863020174317e-05,0.025546709341868375,244.39227041273932,328.6289223789483,2.4920074214526693
8.370898622558223e-05,0.025988397679535907,245.1346495808345,328.6289223789483,2.4920074214526693
8.636878713647239e-05,0.026814162832566515,246.50950778314538,328.6289223789483,2.4920074214526693
8.847188553112971e-05,0.02746709341868374,247.5849484053469,328.6289223789483,2.4920074214526693
8.964714639873232e-05,0.027831966393278656,248.18158609878168,328.6289223789483,2.4920074214526693
9.100797477174588e-05,0.028254450890178036,248.86863192265642,328.6289223789483,2.4920074214526693
9.205952396907454e-05,0.02858091618323665,249.39679037498695,328.6289223789483,2.4920074214526693
9.416262236373185e-05,0.02923384676935387,250.44610109314024,328.6289223789483,2.4920074214526693
9.62038649232522e-05,0.02986757351470294,251.45584342327575,328.6289223789483,2.4920074214526693
9.886366583414233e-05,0.030693338667733546,252.75911826436771,328.6289223789483,2.4920074214526693
9.9915215031471e-05,0.03101980396079216,253.27058574985455,328.6289223789483,2.4920074214526693
0.00010096676422879965,0.03134626925385077,253.77995816221133,328.6289223789483,2.4920074214526693
0.00010214202509640228,0.03171114222844569,254.34681464781568,328.6289223789483,2.4920074214526693
0.00010313171845859397,0.03201840368073615,254.82219723813083,328.6289223789483,2.4920074214526693
0.00010405955598564865,0.03230646129225845,255.2662551177417,328.6289223789483,2.4920074214526693
0.00010436883516133356,0.03240248049609922,255.41393091153608,328.6289223789483,2.4920074214526693
0.00010826575277496332,0.0336123224644929,257.26025914274464,328.6289223789483,2.4920074214526693
0.00010931730197229195,0.033938787757551506,257.75401068553714,328.6289223789483,2.4920074214526693
0.00011055441867503157,0.034322864572914585,258.3325296319232,328.6289223789483,2.4920074214526693
0.00011154411203722325,0.034630126025205044,258.7935290205652,328.6289223789483,2.4920074214526693
0.00011234823789400398,0.03487977595519104,259.16691753445485,328.6289223789483,2.4920074214526693
0.00011278122873996282,0.03501420284056811,259.36754111479235,328.6289223789483,2.4920074214526693
0.00011296679624537377,0.03507181436287257,259.45343066769226,328.6289223789483,2.4920074214526693
0.00011420391294811339,0.03545589117823565,260.0246279785075,328.6289223789483,2.4920074214526693
0.00011506989464003108,0.03572474494898979,260.423031132139,328.6289223789483,2.4920074214526693
0.00011593587633194881,0.03599359871974395,260.8202666642659,328.6289223789483,2.4920074214526693
0.00011729670470496239,0.03641608321664333,261.44216390003146,328.6289223789483,2.4920074214526693
0.00011896681225366086,0.03693458691738348,262.20156886236435,328.6289223789483,2.4920074214526693
0.00011977093811044158,0.037184236847369476,262.56572444694274,328.6289223789483,2.4920074214526693
0.00012045135229694837,0.03739547909581917,262.8731119566914,328.6289223789483,2.4920074214526693
0.000121626613164551,0.03776035207041409,263.40246373832736,328.6289223789483,2.4920074214526693
0.00012218331568078378,0.03793318663732746,263.65251271283785,328.6289223789483,2.4920074214526693
0.0001228018740321536,0.03812522504500901,263.92982436690977,328.6289223789483,2.4920074214526693
0.0001242864140754411,0.03858611722344468,264.59315907311964,328.6289223789483,2.4920074214526693
0.00012601837745927657,0.03912382476495299,265.36315661959685,328.6289223789483,2.4920074214526693
0.00012669879164578334,0.03933506701340268,265.66452509623906,328.6289223789483,2.4920074214526693
0.00012725549416201613,0.03950790158031606,265.910630097761,328.6289223789483,2.4920074214526693
0.0001286163225350297,0.03993038607721544,266.5104590706049,328.6289223789483,2.4920074214526693
0.0001299152950729063,0.040333666733346665,267.0807183507353,328.6289223789483,2.4920074214526693
0.00013133797928105686,0.04077535507101421,267.70274261343053,328.6289223789483,2.4920074214526693
0.00013263695181893343,0.04117863572714543,268.26838663670526,328.6289223789483,2.4920074214526693
0.00013486376188386469,0.041869973994798956,269.23306135378016,328.6289223789483,2.4920074214526693
0.00013572974357578242,0.04213882776555311,269.6065325121516,328.6289223789483,2.4920074214526693
0.000137028716113659,0.042542108421684335,270.16500152414653,328.6289223789483,2.4920074214526693
0.00013944109368400125,0.043291058211642336,271.1967109330882,328.6289223789483,2.4920074214526693
0.00013975037285968614,0.0433870774154831,271.3284761019317,328.6289223789483,2.4920074214526693
0.00014080192205701477,0.043713542708541706,271.7756294486986,328.6289223789483,2.4920074214526693
0.0001423483179354393,0.04419363872774555,272.4308491987595,328.6289223789483,2.4920074214526693
0.00014383285797872682,0.04465453090618124,273.0572534372645,328.6289223789483,2.4920074214526693
0.00014494626301119243,0.045000200040008,273.52540322976586,328.6289223789483,2.4920074214526693
0.00014624523554906903,0.045403480696139226,274.06980908922014,328.6289223789483,2.4920074214526693
0.00014674008223016486,0.045557111422284455,274.2767053394136,328.6289223789483,2.4920074214526693
0.0001472349289112607,0.045710742148429684,274.48332966121416,328.6289223789483,2.4920074214526693
0.0001475442080869456,0.04580676135227045,274.6123323382289,328.6289223789483,2.4920074214526693
0.00014797719893290447,0.045941188237647534,274.7927590525154,328.6289223789483,2.4920074214526693
0.00014927617147078107,0.04634446889377876,275.3328078481233,328.6289223789483,2.4920074214526693
0.00015001844149242478,0.046574914982996596,275.64058425229274,328.6289223789483,2.4920074214526693
0.0001511937023600274,0.04693978795759152,276.1266850538406,328.6289223789483,2.4920074214526693
0.0001528019540735889,0.04743908781756351,276.78949432355745,328.6289223789483,2.4920074214526693
0.0001547194849628353,0.04803440688137628,277.5762216206046,328.6289223789483,2.4920074214526693
0.00015527618747906809,0.04820724144828965,277.8039128724393,328.6289223789483,2.4920074214526693
0.0001568225833574926,0.0486873374674935,278.43472418670456,328.6289223789483,2.4920074214526693
0.00015737928587372543,0.04886017203440689,278.66122179450355,328.6289223789483,2.4920074214526693
0.00015768856504941035,0.048956191238247654,278.7869187769156,328.6289223789483,2.4920074214526693
0.00016065764513598538,0.04987797559511903,279.9887574612922,328.6289223789483,2.4920074214526693
0.000161832906003588,0.05024284856971395,280.4620884072822,328.6289223789483,2.4920074214526693
0.0001620184735089989,0.0503004600920184,280.53670215073214,328.6289223789483,2.4920074214526693
0.00016375043689283438,0.05083816763352671,281.2314973158836,328.6289223789483,2.4920074214526693
0.0001656061119469438,0.05141428285657132,281.9727478973525,328.6289223789483,2.4920074214526693
0.00016585353528749167,0.05149109821964393,282.0713359888067,328.6289223789483,2.4920074214526693
0.00016869890370379276,0.052374474894979,283.201007136717,328.6289223789483,2.4920074214526693
0.0001722865421417376,0.053488297659531905,284.614838995903,328.6289223789483,2.4920074214526693
0.00017408036136071,0.05404520904180836,285.3174456594983,328.6289223789483,2.4920074214526693
0.00017630717142564132,0.0547365473094619,286.18573110046697,328.6289223789483,2.4920074214526693
0.00017896697233653146,0.055562312462492505,287.21726440732175,328.6289223789483,2.4920074214526693
0.0001793381073473533,0.05567753550710142,287.36072249622765,328.6289223789483,2.4920074214526693
0.00017958553068790127,0.05575435087017404,287.4562969030171,328.6289223789483,2.4920074214526693
0.00017989480986358616,0.055850370074014805,287.57569272561216,328.6289223789483,2.4920074214526693
0.00018113192656632574,0.05623444688937787,288.0524776433948,328.6289223789483,2.4920074214526693
0.00018212161992851742,0.05654170834166833,288.43299181178867,328.6289223789483,2.4920074214526693
0.00018335873663125702,0.05692578515703141,288.9075023638823,328.6289223789483,2.4920074214526693
0.00018626596088269507,0.057828365673134624,290.01771433875564,328.6289223789483,2.4920074214526693
0.00018731751008002376,0.05815483096619324,290.4176134626175,328.6289223789483,2.4920074214526693
0.00019047215767200974,0.05913422684536908,291.6120904508851,328.6289223789483,2.4920074214526693
0.00019146185103420142,0.05944148829765954,291.98523508601716,328.6289223789483,2.4920074214526693
0.0001933793819234478,0.060036807361472294,292.7060690643301,328.6289223789483,2.4920074214526693
0.00019467835446132436,0.06044008801760352,293.19279284344964,328.6289223789483,2.4920074214526693
0.00019597732699920095,0.06084336867373474,293.67825168708913,328.6289223789483,2.4920074214526693
0.00019851341623981712,0.06163072614522905,294.6224506624814,328.6289223789483,2.4920074214526693
0.00019913197459118693,0.06182276455291058,294.85202803350785,328.6289223789483,2.4920074214526693
0.00019937939793173486,0.0618995799159832,294.9437810879585,328.6289223789483,2.4920074214526693
0.0002011732171507073,0.062456491298259656,295.6076677706701,328.6289223789483,2.4920074214526693
0.00020315260387509065,0.06307101420284057,296.33755883631824,328.6289223789483,2.4920074214526693
0.00020426600890755626,0.06341668333666733,296.7469036247044,328.6289223789483,2.4920074214526693
0.00020451343224810417,0.06349349869973994,296.8377508532428,328.6289223789483,2.4920074214526693
0.0002048227114237891,0.06358951790358072,296.95124963371785,328.6289223789483,2.4920074214526693
0.0002054412697751589,0.06378155631126226,297.17804687732576,328.6289223789483,2.4920074214526693
0.00020636910730221358,0.06406961392278455,297.51774404173545,328.6289223789483,2.4920074214526693
0.000208224782356323,0.06464572914582917,298.19535670873586,328.6289223789483,2.4920074214526693
0.0002085340615320079,0.06474174834966993,298.30806278986734,328.6289223789483,2.4920074214526693
0.00020927633155365166,0.06497219443888778,298.57829173859096,328.6289223789483,2.4920074214526693
0.00021144128578344594,0.06564432886577315,299.3643325875688,328.6289223789483,2.4920074214526693
0.00021212169996995272,0.06585557111422284,299.6107249099247,328.6289223789483,2.4920074214526693
0.00021243097914563761,0.06595159031806361,299.72261950568753,328.6289223789483,2.4920074214526693
0.0002134206725078293,0.06625885177035407,300.08025601599155,328.6289223789483,2.4920074214526693
0.00021441036587002102,0.06656611322264454,300.4372463071414,328.6289223789483,2.4920074214526693
0.00021558562673762365,0.06693098619723946,300.8603386639821,328.6289223789483,2.4920074214526693
0.0002184928509890617,0.06783356671334267,301.90308915782947,328.6289223789483,2.4920074214526693
0.00021979182352693826,0.0682368473694739,302.3672484971007,328.6289223789483,2.4920074214526693
0.00022109079606481483,0.06864012802560512,302.8303392177263,328.6289223789483,2.4920074214526693
0.00022251348027296536,0.06908181636327265,303.33631800778375,328.6289223789483,2.4920074214526693
0.00022331760612974614,0.06933146629325866,303.62174789737696,328.6289223789483,2.4920074214526693
0.000223688741140568,0.06944668933786757,303.7533495500752,328.6289223789483,2.4920074214526693
0.0002244310111622118,0.06967713542708542,304.01629766678775,328.6289223789483,2.4920074214526693
0.00022665782122714302,0.07036847369473895,304.8031145179119,328.6289223789483,2.4920074214526693
0.0002283279287758415,0.0708869773954791,305.3912502393325,328.6289223789483,2.4920074214526693
0.00022882277545693735,0.07104060812162433,305.56519016278884,328.6289223789483,2.4920074214526693
0.00022950318964344414,0.07125185037007402,305.8041182116599,328.6289223789483,2.4920074214526693
0.00023061659467590975,0.07159751950390078,306.19449634753,328.6289223789483,2.4920074214526693
0.00023197742304892333,0.07202000400080016,306.6706284023325,328.6289223789483,2.4920074214526693
0.0002333382514219369,0.07244248849769955,307.1456723893872,328.6289223789483,2.4920074214526693
0.0002340186656084437,0.07265373074614924,307.3827891155744,328.6289223789483,2.4920074214526693
0.00023494650313549836,0.07294178835767154,307.7056972521394,328.6289223789483,2.4920074214526693
0.0002357506289922791,0.07319143828765753,307.9851488945543,328.6289223789483,2.4920074214526693
0.00023933826743022393,0.07430526105221044,309.2274315817688,328.6289223789483,2.4920074214526693
0.00024063723996810052,0.07470854170834167,309.67543006879697,328.6289223789483,2.4920074214526693
0.0002413795099897443,0.07493898779755952,309.931005741939,328.6289223789483,2.4920074214526693
0.00024236920335193597,0.07524624924984998,310.27129702236175,328.6289223789483,2.4920074214526693
0.0002435444642195386,0.0756111222244449,310.67468985791083,328.6289223789483,2.4920074214526693
0.0002458949859547439,0.07634086817363474,311.4792051575793,328.6289223789483,2.4920074214526693
0.0002463898326358397,0.07649449889977997,311.64819399527045,328.6289223789483,2.4920074214526693
0.00024731767016289435,0.07678255651130227,311.96469173220817,328.6289223789483,2.4920074214526693
0.0002491733452170038,0.07735867173434688,312.59630139316505,328.6289223789483,2.4920074214526693
0.00025078159693056525,0.07785797159431887,313.1422139970646,328.6289223789483,2.4920074214526693
0.0002512145877765241,0.07799239847969594,313.2889569694509,328.6289223789483,2.4920074214526693
0.0002522661369738528,0.07831886377275456,313.64492269741146,328.6289223789483,2.4920074214526693
0.0002529465511603596,0.07853010602120425,313.87494513644594,328.6289223789483,2.4920074214526693
0.00025362696534686637,0.07874134826965394,314.1047263893947,328.6289223789483,2.4920074214526693
0.00025511150539015386,0.07920224044808963,314.60523447123944,328.6289223789483,2.4920074214526693
0.0002565341895983044,0.07964392878575716,315.0838232458055,328.6289223789483,2.4920074214526693
0.0002583280088172768,0.08020084016803361,315.68578844776226,328.6289223789483,2.4920074214526693
0.0002600599722011123,0.08073854770954192,316.26545127947315,328.6289223789483,2.4920074214526693
0.00026098780972816696,0.08102660532106422,316.57536552777634,328.6289223789483,2.4920074214526693
0.00026123523306871484,0.08110342068413683,316.65793671957266,328.6289223789483,2.4920074214526693
0.0002618537914200847,0.08129545909181837,316.86423137319025,328.6289223789483,2.4920074214526693
0.00026457544816611177,0.08214042808561713,317.7696794048505,328.6289223789483,2.4920074214526693
0.00026507029484720764,0.08229405881176236,317.9339153018019,328.6289223789483,2.4920074214526693
0.00026562699736344046,0.08246689337867574,318.11853782310203,328.6289223789483,2.4920074214526693
0.00026599813237426236,0.08258211642328467,318.2415356755858,328.6289223789483,2.4920074214526693
0.00026797751909864566,0.08319663932786557,318.89639732148873,328.6289223789483,2.4920074214526693
0.0002685960774500155,0.08338867773554712,319.1006543599649,328.6289223789483,2.4920074214526693
0.0002694620591419332,0.08365753150630126,319.38630628360045,328.6289223789483,2.4920074214526693
0.0002717507250420015,0.08436807361472295,320.1395253285839,328.6289223789483,2.4920074214526693
0.0002729259859096041,0.08473294658931786,320.52535182935156,328.6289223789483,2.4920074214526693
0.0002734208325906999,0.08488657731546309,320.687611182744,328.6289223789483,2.4920074214526693
0.0002742249584474807,0.0851362272454491,320.9510385780603,328.6289223789483,2.4920074214526693
0.0002752146518096724,0.08544348869773956,321.2748437106647,328.6289223789483,2.4920074214526693
0.0002758332101610422,0.08563552710542109,321.4769913243598,328.6289223789483,2.4920074214526693
0.00027608063350159005,0.0857123424684937,321.5578008582981,328.6289223789483,2.4920074214526693
0.0002772558943691927,0.08607721544308862,321.94126109861116,328.6289223789483,2.4920074214526693
0.0002778744527205625,0.08626925385077015,322.1428276268511,328.6289223789483,2.4920074214526693
0.0002790497135881651,0.08663412682536507,322.5253225859317,328.6289223789483,2.4920074214526693
0.00027985383944494584,0.08688377675535107,322.7866677443977,328.6289223789483,2.4920074214526693
0.0002808435328071375,0.08719103820764153,323.1079216282085,328.6289223789483,2.4920074214526693
0.0002836270453883016,0.08805521104220844,324.0090896285716,328.6289223789483,2.4920074214526693
0.00028523529710186313,0.08855451090218044,324.52819230050585,328.6289223789483,2.4920074214526693
0.000285606432112685,0.08866973394678936,324.64782297293453,328.6289223789483,2.4920074214526693
0.0002857919996180959,0.08872734546909382,324.7076155726739,328.6289223789483,2.4920074214526693
0.00028709097215597247,0.08913062612522504,325.12574063047333,328.6289223789483,2.4920074214526693
0.0002880806655181642,0.0894378875775155,325.44381706423343,328.6289223789483,2.4920074214526693
0.0002883899446938491,0.08953390678135628,325.5431285144847,328.6289223789483,2.4920074214526693
0.00028913221471549283,0.08976435287057412,325.7813066774572,328.6289223789483,2.4920074214526693
0.0002902456197479585,0.09011002200440088,326.1381272808449,328.6289223789483,2.4920074214526693
0.0002911116014398762,0.09037887577515503,326.415285479411,328.6289223789483,2.4920074214526693
0.00029593635658056066,0.09187677535507102,327.9536064529589,328.6289223789483,2.4920074214526693
0.0002976064641292591,0.09239527905581117,328.4838192162359,328.6289223789483,2.4920074214526693
0.0002984105899860399,0.09264492898579717,328.73869286769695,328.6289223789483,2.4920074214526693
0.00029902914833740966,0.0928369673934787,328.9345672977006,328.6289223789483,2.4920074214526693
0.00030107039089693,0.09347069413882778,329.5798346829828,328.6289223789483,2.4920074214526693
0.0003023693634348066,0.093873974794959,329.98957118317855,328.6289223789483,2.4920074214526693
0.00030434875015918994,0.09448849769953992,330.61261398969526,328.6289223789483,2.4920074214526693
0.00030669927189439514,0.09521824364872974,331.3504285110641,328.6289223789483,2.4920074214526693
0.00030762710942144986,0.09550630126025206,331.6410636217639,328.6289223789483,2.4920074214526693
0.00030898793779446344,0.09592878575715144,332.066710811778,328.6289223789483,2.4920074214526693
0.0003123900087269973,0.09698499699939989,333.1276426797932,328.6289223789483,2.4920074214526693
0.0003137508371000109,0.09740748149629927,333.5507525701619,328.6289223789483,2.4920074214526693
0.0003161013588352161,0.0981372274454891,334.27989685389184,328.6289223789483,2.4920074214526693
0.00031690548469199685,0.09838687737547509,334.5288551153638,328.6289223789483,2.4920074214526693
0.00031913229475692814,0.09907821564312863,335.2169955077457,328.6289223789483,2.4920074214526693
0.00031981270894343493,0.09928945789157832,335.4268867790322,328.6289223789483,2.4920074214526693
0.0003204931231299417,0.09950070014002801,335.63660396712123,328.6289223789483,2.4920074214526693
0.00032154467232727035,0.09982716543308662,335.9603711299945,328.6289223789483,2.4920074214526693
0.0003220395190083662,0.09998079615923185,336.1125892387554,328.6289223789483,2.4920074214526693