File: datasets/aisi_316_L/data/M1/train_85.csv
Time(s),Strain(%),Stress(MPa),Temp(C),Log_SR(s-1)
0.0,0.0,0.0,327.7591885850378,4.167089745568535
4.900526599773686e-10,7.2e-06,1.2624778125,327.7591885850378,4.167089745568535
1.14345620661386e-09,1.68e-05,2.9457815624999997,327.7591885850378,4.167089745568535
2.3958130043338022e-09,3.52e-05,6.17211375,327.7591885850378,4.167089745568535
3.3214680287354987e-09,4.88e-05,8.5567940625,327.7591885850378,4.167089745568535
5.063877486432809e-09,7.439999999999999e-05,13.045604062499999,327.7591885850378,4.167089745568535
5.445029555304096e-09,7.999999999999999e-05,14.02753125,327.7591885850378,4.167089745568535
6.043982806387546e-09,8.879999999999999e-05,15.570559687499998,327.7591885850378,4.167089745568535
7.731941968531817e-09,0.0001136,19.919094375,327.7591885850378,4.167089745568535
8.54869640182743e-09,0.0001256,22.0232240625,327.7591885850378,4.167089745568535
9.09319935735784e-09,0.0001336,23.4259771875,327.7591885850378,4.167089745568535
1.1107860292820355e-08,0.00016319999999999998,28.61616375,327.7591885850378,4.167089745568535
1.1761263839456848e-08,0.0001728,30.2994675,327.7591885850378,4.167089745568535
1.2959170341623748e-08,0.0001904,33.385524374999996,327.7591885850378,4.167089745568535
1.4374878026002812e-08,0.00021119999999999998,37.0326825,327.7591885850378,4.167089745568535
1.5736135414828837e-08,0.00023119999999999998,40.539565312499995,327.7591885850378,4.167089745568535
1.6552889848124452e-08,0.0002432,42.643695,327.7591885850378,4.167089745568535
1.7151843099207903e-08,0.000252,44.1867234375,327.7591885850378,4.167089745568535
1.873090167024609e-08,0.00027519999999999997,48.254707499999995,327.7591885850378,4.167089745568535
1.9819907581306908e-08,0.0002912,51.060213749999996,327.7591885850378,4.167089745568535
2.0854463196814684e-08,0.00030639999999999997,53.725444687499994,327.7591885850378,4.167089745568535
2.2923574427830244e-08,0.0003368,59.0559065625,327.7591885850378,4.167089745568535
2.3685878565572818e-08,0.000348,61.0197609375,327.7591885850378,4.167089745568535
2.4774884476633633e-08,0.00036399999999999996,63.82526718749999,327.7591885850378,4.167089745568535
2.6245042456565742e-08,0.0003856,67.612700625,327.7591885850378,4.167089745568535
2.7551849549838725e-08,0.0004048,70.97930812499999,327.7591885850378,4.167089745568535
2.9947662554172526e-08,0.00043999999999999996,77.151421875,327.7591885850378,4.167089745568535
3.0546615805255974e-08,0.00044879999999999996,78.6944503125,327.7591885850378,4.167089745568535
3.234347555850633e-08,0.0004752,83.323535625,327.7591885850378,4.167089745568535
3.299687910514282e-08,0.00048479999999999997,85.006839375,327.7591885850378,4.167089745568535
3.3323580878461065e-08,0.0004896,85.84849125,327.7591885850378,4.167089745568535
3.381363353843843e-08,0.0004967999999999999,87.11096906249999,327.7591885850378,4.167089745568535
3.473928856284013e-08,0.0005103999999999999,89.49564937499999,327.7591885850378,4.167089745568535
3.5828294473900954e-08,0.0005264,92.301155625,327.7591885850378,4.167089745568535
3.8550809251553e-08,0.0005664,99.31492125,327.7591885850378,4.167089745568535
4.083772166478072e-08,0.0006,105.20648437499999,327.7591885850378,4.167089745568535
4.203562816694762e-08,0.0006175999999999999,108.29254124999999,327.7591885850378,4.167089745568535
4.383248792019797e-08,0.0006439999999999999,112.9216265625,327.7591885850378,4.167089745568535
4.726285654003955e-08,0.0006944,121.75897124999999,327.7591885850378,4.167089745568535
4.7752909200016916e-08,0.0007015999999999999,123.02144906249998,327.7591885850378,4.167089745568535
4.884191511107774e-08,0.0007176,125.8269553125,327.7591885850378,4.167089745568535
4.9331967771055105e-08,0.0007247999999999999,127.08943312499999,327.7591885850378,4.167089745568535
5.014872220435073e-08,0.0007368,129.1935628125,327.7591885850378,4.167089745568535
5.145552929762371e-08,0.0007559999999999999,132.5601703125,327.7591885850378,4.167089745568535
5.156442988872979e-08,0.0007576,132.8407209375,327.7591885850378,4.167089745568535
5.401469318861663e-08,0.0007936,139.15311,327.7591885850378,4.167089745568535
5.6628307375162596e-08,0.000832,145.886325,327.7591885850378,4.167089745568535
5.78262138773295e-08,0.0008495999999999999,148.972381875,327.7591885850378,4.167089745568535
5.978642451723897e-08,0.0008784,154.022293125,327.7591885850378,4.167089745568535
6.120213220161803e-08,0.0008992,157.66945124999998,327.7591885850378,4.167089745568535
6.245448899933798e-08,0.0009176,160.8957834375,327.7591885850378,4.167089745568535
6.376129609261097e-08,0.0009368,164.2623909375,327.7591885850378,4.167089745568535
6.441469963924745e-08,0.0009463999999999999,165.94569468749998,327.7591885850378,4.167089745568535
6.463250082145961e-08,0.0009496,166.5067959375,327.7591885850378,4.167089745568535
6.599375821028564e-08,0.0009695999999999999,170.01367875,327.7591885850378,4.167089745568535
6.670161205247518e-08,0.00098,171.83725781249998,327.7591885850378,4.167089745568535
6.735501559911167e-08,0.0009896,173.5205615625,327.7591885850378,4.167089745568535
6.828067062351336e-08,0.0010031999999999999,175.90524187499997,327.7591885850378,4.167089745568535
6.860737239683161e-08,0.001008,176.74689375,327.7591885850378,4.167089745568535
6.92607759434681e-08,0.0010176,178.4301975,327.7591885850378,4.167089745568535
6.996862978565764e-08,0.001028,180.2537765625,327.7591885850378,4.167089745568535
7.040423215008196e-08,0.0010344,181.3759790625,327.7591885850378,4.167089745568535
7.10031854011654e-08,0.0010432,182.9190075,327.7591885850378,4.167089745568535
7.176548953890799e-08,0.0010544,184.882861875,327.7591885850378,4.167089745568535
7.334454810994617e-08,0.0010776,188.9508459375,327.7591885850378,4.167089745568535
7.37801504743705e-08,0.001084,190.07304843749998,327.7591885850378,4.167089745568535
7.492360668098436e-08,0.0011007999999999999,191.09423315762774,327.7591885850378,4.167089745568535
7.557701022762085e-08,0.0011103999999999999,191.1514067647,327.7591885850378,4.167089745568535
7.61759634787043e-08,0.0011191999999999999,191.2036467830351,327.7591885850378,4.167089745568535
7.759167116308336e-08,0.00114,191.326490482312,327.7591885850378,4.167089745568535
7.802727352750769e-08,0.0011464,191.36411227352954,327.7591885850378,4.167089745568535
7.938853091633371e-08,0.0011664,191.48115586222835,327.7591885850378,4.167089745568535
7.987858357631109e-08,0.0011736,191.52309961004383,327.7591885850378,4.167089745568535
8.18932445117736e-08,0.0012032,191.69449108568784,327.7591885850378,4.167089745568535
8.287334983172833e-08,0.0012175999999999999,191.77727547613708,327.7591885850378,4.167089745568535
8.36356539694709e-08,0.0012288,191.84139963517444,327.7591885850378,4.167089745568535
8.483356047163781e-08,0.0012464,191.94170754622672,327.7591885850378,4.167089745568535
8.586811608714559e-08,0.0012615999999999999,192.02789337092943,327.7591885850378,4.167089745568535
8.646706933822903e-08,0.0012703999999999999,192.07760532705407,327.7591885850378,4.167089745568535
8.673932081599425e-08,0.0012744,192.10015725692767,327.7591885850378,4.167089745568535
8.771942613594898e-08,0.0012887999999999999,192.18111662464716,327.7591885850378,4.167089745568535
8.9080683524775e-08,0.0013088,192.2929773636967,327.7591885850378,4.167089745568535
8.984298766251758e-08,0.00132,192.3553281366828,327.7591885850378,4.167089745568535
9.09319935735784e-08,0.001336,192.44404394401437,327.7591885850378,4.167089745568535
9.229325096240443e-08,0.001356,192.5543581491059,327.7591885850378,4.167089745568535
9.338225687346524e-08,0.001372,192.64215331013514,327.7591885850378,4.167089745568535
9.566916928669296e-08,0.0014056,192.82523393464382,327.7591885850378,4.167089745568535
9.741157874439027e-08,0.0014311999999999999,192.96358054112974,327.7591885850378,4.167089745568535
9.773828051770852e-08,0.001436,192.9894127344438,327.7591885850378,4.167089745568535
9.871838583766326e-08,0.0014504,193.0667080149431,327.7591885850378,4.167089745568535
1.0002519293093624e-07,0.0014696,193.16930442464084,327.7591885850378,4.167089745568535
1.0084194736423186e-07,0.0014816,193.23316178676342,327.7591885850378,4.167089745568535
1.0274770770858828e-07,0.0015095999999999998,193.38138297597112,327.7591885850378,4.167089745568535
1.0345556155077782e-07,0.0015199999999999999,193.4361629835214,327.7591885850378,4.167089745568535
1.038367136196491e-07,0.0015256,193.4655993562086,327.7591885850378,4.167089745568535
1.051435207129221e-07,0.0015448,193.5662056799457,327.7591885850378,4.167089745568535
1.056880236684525e-07,0.0015528,193.60798091650426,327.7591885850378,4.167089745568535
1.0666812898840723e-07,0.0015672,193.68296543141696,327.7591885850378,4.167089745568535
1.0797493608168023e-07,0.0015864,193.78252812933937,327.7591885850378,4.167089745568535
1.089005911060819e-07,0.0015999999999999999,193.8527675723098,327.7591885850378,4.167089745568535
1.092817431749532e-07,0.0016056,193.88162197299377,327.7591885850378,4.167089745568535
1.1129640411041571e-07,0.0016351999999999998,194.03349098399156,327.7591885850378,4.167089745568535
1.119498076570522e-07,0.0016447999999999999,194.08251504906988,327.7591885850378,4.167089745568535
1.1325661475032519e-07,0.001664,194.18022968050812,327.7591885850378,4.167089745568535
1.1652363248350766e-07,0.001712,194.4226119063111,327.7591885850378,4.167089745568535
1.1842939282786409e-07,0.00174,194.56277754362938,327.7591885850378,4.167089745568535
1.189738957833945e-07,0.001748,194.60266294049237,327.7591885850378,4.167089745568535
1.2022625258111444e-07,0.0017664,194.69413016150708,327.7591885850378,4.167089745568535
1.2131525849217525e-07,0.0017824,194.7733652478904,327.7591885850378,4.167089745568535
1.2185976144770566e-07,0.0017904,194.81287873319417,327.7591885850378,4.167089745568535
1.2278541647210736e-07,0.0018039999999999998,194.8798939955211,327.7591885850378,4.167089745568535
1.2327546913208473e-07,0.0018112,194.9152928814398,327.7591885850378,4.167089745568535
1.2452782592980468e-07,0.0018296,195.0055082680211,327.7591885850378,4.167089745568535
1.2539903065865332e-07,0.0018424,195.06805821619076,327.7591885850378,4.167089745568535
1.2599798390973676e-07,0.0018512,195.11096302775258,327.7591885850378,4.167089745568535
1.288293992784949e-07,0.0018927999999999998,195.31271869720086,327.7591885850378,4.167089745568535
1.2953725312068443e-07,0.0019031999999999999,195.36288648656992,327.7591885850378,4.167089745568535
1.3024510696287397e-07,0.0019136,195.4129474741884,327.7591885850378,4.167089745568535
1.325320193761017e-07,0.0019471999999999998,195.57396259069668,327.7591885850378,4.167089745568535
1.3378437617382163e-07,0.0019656,195.6616782349051,327.7591885850378,4.167089745568535
1.3530898444930678e-07,0.0019879999999999997,195.76803145996118,327.7591885850378,4.167089745568535
1.3656134124702672e-07,0.0020063999999999998,195.85504385040477,327.7591885850378,4.167089745568535
1.3781369804474664e-07,0.0020247999999999998,195.94174558690924,327.7591885850378,4.167089745568535
1.3890270395580748e-07,0.0020407999999999997,196.01688893260845,327.7591885850378,4.167089745568535
1.402639613446335e-07,0.0020608,196.1104957953339,327.7591885850378,4.167089745568535
1.4108071577792913e-07,0.0020728,196.16648986480897,327.7591885850378,4.167089745568535
1.423875228712021e-07,0.002092,196.25581812877334,327.7591885850378,4.167089745568535
1.4314982700894468e-07,0.0021032,196.30777862752197,327.7591885850378,4.167089745568535
1.4380323055558116e-07,0.0021127999999999997,196.3522303661055,327.7591885850378,4.167089745568535
1.450555873533011e-07,0.0021311999999999998,196.4372099723114,327.7591885850378,4.167089745568535
1.458178914910437e-07,0.0021424,196.48879661121714,327.7591885850378,4.167089745568535
1.4603569267325587e-07,0.0021456,196.50351631896086,327.7591885850378,4.167089745568535
1.4712469858431668e-07,0.0021616,196.57698682129498,327.7591885850378,4.167089745568535
1.47560300948741e-07,0.002168,196.60631559992171,327.7591885850378,4.167089745568535
1.4766920153984706e-07,0.0021696,196.61364251626497,327.7591885850378,4.167089745568535
1.479414530176123e-07,0.0021736,196.63195059373436,327.7591885850378,4.167089745568535
1.4935716070199134e-07,0.0021944,196.726941613312,327.7591885850378,4.167089745568535
1.5022836543084e-07,0.0022072,196.7852231142851,327.7591885850378,4.167089745568535
1.5158962281966603e-07,0.0022272,196.87602476552294,327.7591885850378,4.167089745568535
1.5229747666185554e-07,0.0022375999999999997,196.92311591792384,327.7591885850378,4.167089745568535
1.5469328966618936e-07,0.0022727999999999997,197.08187176534898,327.7591885850378,4.167089745568535
1.5507444173506063e-07,0.0022784,197.107039697085,327.7591885850378,4.167089745568535
1.5616344764612147e-07,0.0022944,197.17881548229587,327.7591885850378,4.167089745568535
1.5632679853278058e-07,0.0022968,197.1895649901131,327.7591885850378,4.167089745568535
1.5725245355718228e-07,0.0023103999999999998,197.25039632471788,327.7591885850378,4.167089745568535
1.577969565127127e-07,0.0023184,197.28611422922603,327.7591885850378,4.167089745568535
1.599205180392813e-07,0.0023496,197.4249571900727,327.7591885850378,4.167089745568535
1.6095507365478905e-07,0.0023648,197.4923380018517,327.7591885850378,4.167089745568535
1.6139067601921342e-07,0.0023712,197.5206583139501,327.7591885850378,4.167089745568535
1.6400429020575937e-07,0.0024096,197.6899583619928,327.7591885850378,4.167089745568535
1.6411319079686545e-07,0.0024112,197.69698960458763,327.7591885850378,4.167089745568535
1.6514774641237322e-07,0.0024264,197.7636959031065,327.7591885850378,4.167089745568535
1.6531109729903235e-07,0.0024288,197.77421356057118,327.7591885850378,4.167089745568535
1.6596450084566883e-07,0.0024384,197.81624372128712,327.7591885850378,4.167089745568535
1.6661790439230533e-07,0.002448,197.8582093968242,327.7591885850378,4.167089745568535
1.6863256532776785e-07,0.0024776,197.98720134835486,327.7591885850378,4.167089745568535
1.6966712094327563e-07,0.0024928,198.05320681139818,327.7591885850378,4.167089745568535
1.6983047182993476e-07,0.0024952,198.06361436095074,327.7591885850378,4.167089745568535
1.7037497478546514e-07,0.0025031999999999997,198.09827803118313,327.7591885850378,4.167089745568535
1.7157288128763205e-07,0.0025207999999999997,198.17438638761178,327.7591885850378,4.167089745568535
1.72825238085352e-07,0.0025391999999999997,198.25373296355525,327.7591885850378,4.167089745568535
1.7413204517862497e-07,0.0025583999999999997,198.336290683696,327.7591885850378,4.167089745568535
1.7473099842970844e-07,0.0025672,198.3740488504846,327.7591885850378,4.167089745568535
1.774535132073605e-07,0.0026072,198.5450446676263,327.7591885850378,4.167089745568535
1.7832471793620914e-07,0.00262,198.59954683828352,327.7591885850378,4.167089745568535
1.8110168300941423e-07,0.0026608,198.77258351464192,327.7591885850378,4.167089745568535
1.8262629128489935e-07,0.0026831999999999997,198.86714392374586,327.7591885850378,4.167089745568535
1.8404199896927843e-07,0.002704,198.95467471639134,327.7591885850378,4.167089745568535
1.849676539936801e-07,0.0027175999999999997,199.0117644466413,327.7591885850378,4.167089745568535
1.8518545517589228e-07,0.0027207999999999998,199.02518111839012,327.7591885850378,4.167089745568535
1.8643781197361222e-07,0.0027392,199.102207888606,327.7591885850378,4.167089745568535
1.8828912202241563e-07,0.0027664,199.21570494452976,327.7591885850378,4.167089745568535
1.889425255690521e-07,0.002776,199.25565871157028,327.7591885850378,4.167089745568535
1.8970482970679468e-07,0.0027871999999999997,199.30220339803165,327.7591885850378,4.167089745568535
1.9046713384453728e-07,0.0027984,199.3486751982206,327.7591885850378,4.167089745568535
1.9101163680006766e-07,0.0028063999999999997,199.38182494155296,327.7591885850378,4.167089745568535
1.9231844389334064e-07,0.0028255999999999997,199.4612343211014,327.7591885850378,4.167089745568535
1.9444200541990928e-07,0.0028568,199.58982720149123,327.7591885850378,4.167089745568535
1.9471425689767446e-07,0.0028607999999999997,199.60627376591577,327.7591885850378,4.167089745568535
1.965111166509248e-07,0.0028872,199.71459703757523,327.7591885850378,4.167089745568535
1.9770902315309172e-07,0.0029048,199.78659802367125,327.7591885850378,4.167089745568535
1.9896137995081166e-07,0.0029232,199.86169010508436,327.7591885850378,4.167089745568535
1.9934253201968296e-07,0.0029288,199.88450759825105,327.7591885850378,4.167089745568535
2.019561462062289e-07,0.0029671999999999997,200.0405145760258,327.7591885850378,4.167089745568535
2.0250064916175933e-07,0.0029752,200.0729166996099,327.7591885850378,4.167089745568535
2.030451521172897e-07,0.0029831999999999997,200.10528486185282,327.7591885850378,4.167089745568535
2.0397080714169144e-07,0.0029968,200.1602331541203,327.7591885850378,4.167089745568535
2.0446085980166879e-07,0.0030039999999999997,200.1892840502437,327.7591885850378,4.167089745568535
2.0549541541717656e-07,0.0030191999999999997,200.25052469395985,327.7591885850378,4.167089745568535
2.0609436866826003e-07,0.003028,200.28592484505137,327.7591885850378,4.167089745568535
2.0652997103268437e-07,0.0030344,200.31164521307312,327.7591885850378,4.167089745568535
2.0816347989927558e-07,0.0030583999999999997,200.40790874696367,327.7591885850378,4.167089745568535
2.0859908226369992e-07,0.0030648,200.4335292099358,327.7591885850378,4.167089745568535
2.0898023433257122e-07,0.0030704,200.45593000366762,327.7591885850378,4.167089745568535
2.097969887658668e-07,0.0030824,200.5038781203984,327.7591885850378,4.167089745568535
2.1039594201695024e-07,0.0030911999999999997,200.53899381730574,327.7591885850378,4.167089745568535
2.1159384851911715e-07,0.0031087999999999997,200.6091084680581,327.7591885850378,4.167089745568535
2.1290065561239013e-07,0.0031279999999999997,200.6854208556869,327.7591885850378,4.167089745568535
2.1382631063679186e-07,0.0031416,200.7393649750757,327.7591885850378,4.167089745568535
2.156231703900422e-07,0.003168,200.84382074895612,327.7591885850378,4.167089745568535
2.1752893073439863e-07,0.003196,200.95423689239607,327.7591885850378,4.167089745568535
2.1812788398548208e-07,0.0032048,200.9888611074023,327.7591885850378,4.167089745568535
2.1840013546324728e-07,0.0032088,201.0045871275259,327.7591885850378,4.167089745568535
2.192168898965429e-07,0.0032208,201.05171937943084,327.7591885850378,4.167089745568535
2.195980419654142e-07,0.0032264,201.07369098838507,327.7591885850378,4.167089745568535
2.2074149817202804e-07,0.0032432,201.13951675089754,327.7591885850378,4.167089745568535
2.2340956265412706e-07,0.0032824,201.29259520147696,327.7591885850378,4.167089745568535
2.240085159052105e-07,0.0032911999999999998,201.3268615648217,327.7591885850378,4.167089745568535
2.2553312418069564e-07,0.0033136,201.41392418793072,327.7591885850378,4.167089745568535
2.2667658038730952e-07,0.0033304,201.47907060410324,327.7591885850378,4.167089745568535
2.271666330472869e-07,0.0033376,201.50695124878138,327.7591885850378,4.167089745568535
2.278744868894764e-07,0.003348,201.5471819157367,327.7591885850378,4.167089745568535
2.2874569161832504e-07,0.0033607999999999997,201.59662973838442,327.7591885850378,4.167089745568535
2.2988914782493892e-07,0.0033775999999999997,201.66141868641816,327.7591885850378,4.167089745568535
2.309237034404467e-07,0.0033927999999999996,201.7199290434049,327.7591885850378,4.167089745568535
2.3217606023816664e-07,0.0034111999999999996,201.79062076868604,327.7591885850378,4.167089745568535
2.3348286733143962e-07,0.0034303999999999997,201.86422767975708,327.7591885850378,4.167089745568535
2.348985750158187e-07,0.0034511999999999998,201.9437874220343,327.7591885850378,4.167089745568535
2.3593313063132645e-07,0.0034663999999999997,202.0018090224038,327.7591885850378,4.167089745568535
2.3680433536017514e-07,0.0034792,202.05059239742857,327.7591885850378,4.167089745568535
2.3979910161559235e-07,0.0035231999999999998,202.2177539817912,327.7591885850378,4.167089745568535
2.409970081177593e-07,0.0035407999999999998,202.2843904072003,327.7591885850378,4.167089745568535
2.415415110732897e-07,0.0035488,202.31463697573705,327.7591885850378,4.167089745568535
2.4241271580213836e-07,0.0035616,202.36297623309193,327.7591885850378,4.167089745568535
2.442095755553887e-07,0.003588,202.46246249920395,327.7591885850378,4.167089745568535
2.450263299886843e-07,0.0036,202.5075891142996,327.7591885850378,4.167089745568535
2.454074820575556e-07,0.0036056,202.52862812150326,327.7591885850378,4.167089745568535
2.47313242401912e-07,0.0036336,202.63363260524244,327.7591885850378,4.167089745568535
2.4840224831297283e-07,0.0036496,202.69349347876013,327.7591885850378,4.167089745568535
2.4954570451958673e-07,0.0036663999999999998,202.75623734799615,327.7591885850378,4.167089745568535
2.503080086573293e-07,0.0036775999999999996,202.7980043134749,327.7591885850378,4.167089745568535
2.5117921338617794e-07,0.0036904,202.84567729206967,327.7591885850378,4.167089745568535
2.5210486841057965e-07,0.003704,202.89625922769213,327.7591885850378,4.167089745568535
2.5330277491274653e-07,0.0037216,202.9616108139204,327.7591885850378,4.167089745568535
2.5439178082380735e-07,0.0037375999999999998,203.0209168278135,327.7591885850378,4.167089745568535
2.545006814149134e-07,0.0037392,203.0268419783222,327.7591885850378,4.167089745568535
2.5531743584820905e-07,0.0037511999999999997,203.07124913253216,327.7591885850378,4.167089745568535
2.568420441236942e-07,0.0037736,203.1539945366061,327.7591885850378,4.167089745568535
2.5744099737477764e-07,0.0037824,203.18644922286754,327.7591885850378,4.167089745568535
2.5782214944364894e-07,0.0037879999999999997,203.20708687348872,327.7591885850378,4.167089745568535
2.584211026947324e-07,0.0037968,203.23949344321548,327.7591885850378,4.167089745568535
2.5929230742358105e-07,0.0038096,203.28657802945366,327.7591885850378,4.167089745568535
2.6038131333464186e-07,0.0038255999999999997,203.34534708915317,327.7591885850378,4.167089745568535
2.620148222012331e-07,0.0038496,203.43332126195176,327.7591885850378,4.167089745568535
2.632127287034e-07,0.0038672,203.49769976832803,327.7591885850378,4.167089745568535
2.6517293934330945e-07,0.0038959999999999997,203.6028004845536,327.7591885850378,4.167089745568535
2.665886470276885e-07,0.0039168,203.6785182079186,327.7591885850378,4.167089745568535
2.683855067809389e-07,0.0039432,203.77439602257346,327.7591885850378,4.167089745568535
2.6876665884981015e-07,0.0039488,203.794701520186,327.7591885850378,4.167089745568535
2.695834132831058e-07,0.0039607999999999996,203.8381755223971,327.7591885850378,4.167089745568535
2.707813197852727e-07,0.0039784,203.90184458869987,327.7591885850378,4.167089745568535
2.787868203000767e-07,0.004096019203840768,204.32455379627618,327.7591885850378,4.167089745568535
2.8793629984889736e-07,0.004230446089217844,204.80191294563318,327.7591885850378,4.167089745568535
3.166918070023337e-07,0.004652930586117224,206.2650422246021,327.7591885850378,4.167089745568535
3.3499076609997496e-07,0.004921784356871375,207.16918402093663,327.7591885850378,4.167089745568535
3.6636041026736003e-07,0.005382676535307062,208.67553642732946,327.7591885850378,4.167089745568535
3.911947118998732e-07,0.00574754950990198,209.83264970765546,327.7591885850378,4.167089745568535
4.1080073950448883e-07,0.006035607121424285,210.72603606642917,327.7591885850378,4.167089745568535
4.395562466579252e-07,0.006458091618323665,212.00681658659954,327.7591885850378,4.167089745568535
4.6046934276951523e-07,0.006765353070614123,212.91784814943622,327.7591885850378,4.167089745568535
5.036026034996697e-07,0.007399079815963192,214.74738643986043,327.7591885850378,4.167089745568535
5.336651791600804e-07,0.007840768153630726,215.98651111260216,327.7591885850378,4.167089745568535
5.362793161740292e-07,0.007879175835167033,216.09295751509435,327.7591885850378,4.167089745568535
5.480429327367986e-07,0.008052010402080416,216.5694839628604,327.7591885850378,4.167089745568535
5.91176193466953e-07,0.008685737147429486,218.2836189921657,327.7591885850378,4.167089745568535
6.251599746482869e-07,0.00918503700740148,219.6000094335003,327.7591885850378,4.167089745568535
6.330023856901331e-07,0.009300260052010402,219.89979250982228,327.7591885850378,4.167089745568535
6.434589337459282e-07,0.009453890778155631,220.29725969458127,327.7591885850378,4.167089745568535
6.787497834342363e-07,0.00997239447889578,221.62049281929183,327.7591885850378,4.167089745568535
6.996628795458264e-07,0.010279655931186238,222.39196940885432,327.7591885850378,4.167089745568535
7.441032087829553e-07,0.010932586517303462,224.00211069427286,327.7591885850378,4.167089745568535
7.807011269782379e-07,0.011470294058811763,225.30012291116546,327.7591885850378,4.167089745568535
8.042283601037766e-07,0.011815963192638527,226.1220417200257,327.7591885850378,4.167089745568535
8.342909357641872e-07,0.01225765153030606,227.1587500388023,327.7591885850378,4.167089745568535
8.53896963368803e-07,0.012545709141828365,227.82702331120865,327.7591885850378,4.167089745568535
8.735029909734187e-07,0.01283376675335067,228.48933851887958,327.7591885850378,4.167089745568535
9.087938406617269e-07,0.013352270454090818,229.66707623290833,327.7591885850378,4.167089745568535
9.571553754197789e-07,0.014062812562512503,231.25243954721697,327.7591885850378,4.167089745568535
9.98981567642959e-07,0.01467733546709342,232.59852879989253,327.7591885850378,4.167089745568535
1.0251229377824465e-06,0.015061412282456492,233.42868027353117,327.7591885850378,4.167089745568535
1.068256198512601e-06,0.01569513902780556,234.7806020667031,327.7591885850378,4.167089745568535
1.0774056780614216e-06,0.015829565913182637,235.06461721083565,327.7591885850378,4.167089745568535
1.0930905001451141e-06,0.01606001200240048,235.5493215646267,327.7591885850378,4.167089745568535
1.1179248017776273e-06,0.0164248849769954,236.3112591814577,327.7591885850378,4.167089745568535
1.162365131014756e-06,0.017077815563112622,237.65845070248758,327.7591885850378,4.167089745568535
1.2081125287588594e-06,0.017749949989998,239.02444321225994,327.7591885850378,4.167089745568535
1.2224902823355776e-06,0.01796119223844769,239.449568799951,327.7591885850378,4.167089745568535
1.265623543065732e-06,0.01859491898379676,240.7133968311047,327.7591885850378,4.167089745568535
1.2891507761912707e-06,0.018940588117623523,241.39567266216687,327.7591885850378,4.167089745568535
1.3375123109493228e-06,0.01965113022604521,242.7830639664405,327.7591885850378,4.167089745568535
1.400251599284093e-06,0.020572914582916584,244.55410676077258,327.7591885850378,4.167089745568535
1.4067869418189648e-06,0.02066893378675735,244.73679264688548,327.7591885850378,4.167089745568535
1.4407707230002986e-06,0.021168233646729345,245.6814760745943,327.7591885850378,4.167089745568535
1.4773686411955813e-06,0.021705941188237647,246.68916038740815,327.7591885850378,4.167089745568535
1.538800861023377e-06,0.02260852170434087,248.3590126267986,327.7591885850378,4.167089745568535
1.5740917107116852e-06,0.023127025405081016,249.3065283844486,327.7591885850378,4.167089745568535
1.5897765327953777e-06,0.02335747149429886,249.72498330985337,327.7591885850378,4.167089745568535
1.611996697413942e-06,0.02368393678735747,250.3150486899891,327.7591885850378,4.167089745568535
1.6760430542556867e-06,0.024624924984997,251.9983317858334,327.7591885850378,4.167089745568535
1.704798561409123e-06,0.02504740948189638,252.74591145681248,327.7591885850378,4.167089745568535
1.7126409724509693e-06,0.025162632526505302,252.94894125142042,327.7591885850378,4.167089745568535
1.7453176851253286e-06,0.02564272854570914,253.79102529381746,327.7591885850378,4.167089745568535
1.770151986757842e-06,0.026007601520304062,254.42690314212396,327.7591885850378,4.167089745568535
1.7897580143624576e-06,0.026295659131826365,254.92645764448773,327.7591885850378,4.167089745568535
1.8054428364461501e-06,0.02652610522104421,255.32456628800577,327.7591885850378,4.167089745568535
1.8407336861344585e-06,0.02704460892178436,256.2154117795915,327.7591885850378,4.167089745568535
1.8786386728367152e-06,0.027601520304060812,257.1648583975759,327.7591885850378,4.167089745568535
1.912622454018049e-06,0.028100820164032807,258.00975293870664,327.7591885850378,4.167089745568535
1.950527440720306e-06,0.02865773154630926,258.9452581539903,327.7591885850378,4.167089745568535
2.0106525920411273e-06,0.029541108221644328,260.41474915696864,327.7591885850378,4.167089745568535
2.0211091400969223e-06,0.029694738947789557,260.6685534137008,327.7591885850378,4.167089745568535
2.074698948882872e-06,0.030482096419283858,261.96134874855164,327.7591885850378,4.167089745568535
2.095612044994462e-06,0.030789357871574316,262.4623132148492,327.7591885850378,4.167089745568535
2.1426665112455396e-06,0.03148069613922785,263.5824087840481,327.7591885850378,4.167089745568535
2.1557371963152837e-06,0.03167273454690939,263.8918386288564,327.7591885850378,4.167089745568535
2.175343223919899e-06,0.031960792158431686,264.35461499547984,327.7591885850378,4.167089745568535
2.181878566454771e-06,0.03205681136227245,264.5085119295999,327.7591885850378,4.167089745568535
2.2014845940593866e-06,0.03234486897379476,264.96912767846555,327.7591885850378,4.167089745568535
2.2145552791291306e-06,0.0325369073814763,265.2753163543844,327.7591885850378,4.167089745568535
2.2380825122546692e-06,0.03288257651530306,265.82468576345394,327.7591885850378,4.167089745568535
2.261609745380208e-06,0.03322824564912982,266.3718074462002,327.7591885850378,4.167089745568535
2.3021288690964135e-06,0.03382356471294259,267.30889751471324,327.7591885850378,4.167089745568535
2.3151995541661575e-06,0.03401560312062413,267.6098095520423,327.7591885850378,4.167089745568535
2.340033855798671e-06,0.03438047609521905,268.1797233785179,327.7591885850378,4.167089745568535
2.3740176369800045e-06,0.03487977595519104,268.9557975807626,327.7591885850378,4.167089745568535
2.428914514272928e-06,0.03568633726745349,270.2003653397536,327.7591885850378,4.167089745568535
2.46812656948216e-06,0.0362624524904981,271.0826348166983,327.7591885850378,4.167089745568535
2.494267939621647e-06,0.03664652930586117,271.6677793175659,327.7591885850378,4.167089745568535
2.508645693198365e-06,0.03685777155431086,271.98858915899393,327.7591885850378,4.167089745568535
2.5164881042402118e-06,0.036972994598919784,272.1632740792363,327.7591885850378,4.167089745568535
2.5543930909424683e-06,0.03752990598119624,273.0046097376567,327.7591885850378,4.167089745568535
2.5583142964633917e-06,0.0375875175035007,273.0913656452731,327.7591885850378,4.167089745568535
2.5896839406307767e-06,0.03804840968193639,273.78355572741384,327.7591885850378,4.167089745568535
2.636738406881854e-06,0.03873974794958991,274.81574079305216,327.7591885850378,4.167089745568535
2.6537302974725218e-06,0.03898939787957592,275.186705577565,327.7591885850378,4.167089745568535
2.669415119556214e-06,0.03921984396879376,275.5283132241414,327.7591885850378,4.167089745568535
2.704705969244522e-06,0.03973834766953391,276.29408119445384,327.7591885850378,4.167089745568535
2.7256190653561124e-06,0.040045609121824366,276.74603093175995,327.7591885850378,4.167089745568535
2.762216983551394e-06,0.04058331666333266,277.5337021599999,327.7591885850378,4.167089745568535
2.7752876686211387e-06,0.04077535507101421,277.8140255674444,327.7591885850378,4.167089745568535
2.7975078332397025e-06,0.04110182036407281,278.2893965620747,327.7591885850378,4.167089745568535
2.811885586816421e-06,0.0413130626125225,278.5962050619328,327.7591885850378,4.167089745568535
2.848483505011704e-06,0.04185077015403081,279.37442412398514,327.7591885850378,4.167089745568535
2.8837743547000123e-06,0.04236927385477096,280.121164899998,327.7591885850378,4.167089745568535
2.9033803823046276e-06,0.04265733146629326,280.53448066236353,327.7591885850378,4.167089745568535
2.922986409909243e-06,0.04294538907781556,280.9467093374044,327.7591885850378,4.167089745568535
2.966119670639398e-06,0.043579115823164635,281.8498355201879,327.7591885850378,4.167089745568535
2.9818044927230898e-06,0.04380956191238247,282.17697326060426,327.7591885850378,4.167089745568535
3.017095342411398e-06,0.04432806561312262,282.9105893365484,327.7591885850378,4.167089745568535
3.0223236164392962e-06,0.04440488097619524,283.0189879069592,327.7591885850378,4.167089745568535
3.045850849564835e-06,0.044750550110022005,283.50587930017736,327.7591885850378,4.167089745568535
3.0850629047740666e-06,0.04532666533306662,284.31411806208604,327.7591885850378,4.167089745568535
3.1216608229693484e-06,0.04586437287457491,285.06486695330244,327.7591885850378,4.167089745568535
3.1543375356437085e-06,0.04634446889377876,285.73228265177005,327.7591885850378,4.167089745568535
3.1948566593599137e-06,0.04693978795759152,286.5561450454589,327.7591885850378,4.167089745568535
3.2079273444296574e-06,0.04713182636527305,286.82103650547043,327.7591885850378,4.167089745568535
3.2118485499505803e-06,0.04718943788757751,286.9004218193884,327.7591885850378,4.167089745568535
3.231454577555197e-06,0.047477495499099825,287.296782831008,327.7591885850378,4.167089745568535
3.269359564257454e-06,0.04803440688137628,288.06043142253736,327.7591885850378,4.167089745568535
3.3229493730434026e-06,0.04882176435287057,289.13420682261363,327.7591885850378,4.167089745568535
3.368696770787506e-06,0.04949389877975595,290.0455116410758,327.7591885850378,4.167089745568535
3.3804603873502757e-06,0.04966673334666934,290.2790654493326,327.7591885850378,4.167089745568535
3.4131371000246346e-06,0.05014682936587317,290.92616878032453,327.7591885850378,4.167089745568535
3.437971401657148e-06,0.05051170234046809,291.41635266843997,327.7591885850378,4.167089745568535
3.4667269088105842e-06,0.05093418683736747,291.98221211564345,327.7591885850378,4.167089745568535
3.4980965529779696e-06,0.05139507901580316,292.5974296987687,327.7591885850378,4.167089745568535
3.537308608187201e-06,0.05197119423884777,293.363434276603,327.7591885850378,4.167089745568535
3.5712923893685345e-06,0.052470494098819764,294.0246300616636,327.7591885850378,4.167089745568535
3.5791348004103813e-06,0.05258571714342869,294.1768646956843,327.7591885850378,4.167089745568535
3.5987408280149965e-06,0.05287377475495099,294.55688323561446,327.7591885850378,4.167089745568535
3.6314175406893562e-06,0.053353870774154835,295.1884580596241,327.7591885850378,4.167089745568535
3.654944773814895e-06,0.0536995399079816,295.6418203171981,327.7591885850378,4.167089745568535
3.67455080141951e-06,0.053987597519503897,296.0187534303572,327.7591885850378,4.167089745568535
3.682393212461357e-06,0.05410282056411282,296.169306957509,327.7591885850378,4.167089745568535
3.700692171558998e-06,0.054371674334866976,296.5201130641808,327.7591885850378,4.167089745568535
3.732061815726383e-06,0.054832566513302664,297.1199251058998,327.7591885850378,4.167089745568535
3.7372900897542804e-06,0.05490938187637527,297.2197023069413,327.7591885850378,4.167089745568535
3.7961081725681274e-06,0.05577355471094218,298.33847044543234,327.7591885850378,4.167089745568535
3.802643515103e-06,0.05586957391478296,298.4623592893434,327.7591885850378,4.167089745568535
3.8300919537494614e-06,0.05627285457091419,298.9817882564642,327.7591885850378,4.167089745568535
3.8915241735772575e-06,0.057175435087017404,300.13908781194715,327.7591885850378,4.167089745568535
3.935964502814386e-06,0.057828365673134624,300.9718463088941,327.7591885850378,4.167089745568535
3.951649324898079e-06,0.058058811762352475,301.2648845151445,327.7591885850378,4.167089745568535
4.0287663668095675e-06,0.05919183836767354,302.69910978759816,327.7591885850378,4.167089745568535
4.0353017093444395e-06,0.05928785757151431,302.8201599965193,327.7591885850378,4.167089745568535
4.065364285004849e-06,0.059729545909181836,303.3760091375969,327.7591885850378,4.167089745568535
4.100655134693158e-06,0.060248049609921986,304.02648634455056,327.7591885850378,4.167089745568535
4.1045763402140814e-06,0.06030566113222645,304.0986265679137,327.7591885850378,4.167089745568535
4.117647025283825e-06,0.06049769953990798,304.3389000980315,327.7591885850378,4.167089745568535
4.129410641846595e-06,0.06067053410682137,304.55489207152266,327.7591885850378,4.167089745568535
4.155552011986081e-06,0.061054610922184435,305.0340169425485,327.7591885850378,4.167089745568535
4.160780286013979e-06,0.06113142628525706,305.12970070341777,327.7591885850378,4.167089745568535
4.193456998688339e-06,0.06161152230446089,305.7266653333958,327.7591885850378,4.167089745568535
4.2012994097301845e-06,0.061726745349069814,305.8696665629602,327.7591885850378,4.167089745568535
4.2287478483766465e-06,0.06213002600520104,306.36935310478896,327.7591885850378,4.167089745568535
4.2914871367114165e-06,0.06305181036207241,307.5067679630238,327.7591885850378,4.167089745568535
4.326777986399725e-06,0.06357031406281256,308.1437135398907,327.7591885850378,4.167089745568535
4.355533493553162e-06,0.06399279855971195,308.661209502061,327.7591885850378,4.167089745568535
4.375139521157777e-06,0.06428085617123425,309.0132839365969,327.7591885850378,4.167089745568535
4.377753658171726e-06,0.06431926385277055,309.060180661004,327.7591885850378,4.167089745568535
4.392131411748444e-06,0.06453050610122024,309.3179176878696,327.7591885850378,4.167089745568535
4.415658644873982e-06,0.064876175235047,309.7389605589544,327.7591885850378,4.167089745568535
4.458791905604137e-06,0.06550990198039608,310.50860712776404,327.7591885850378,4.167089745568535
4.507153440362189e-06,0.06622044408881776,311.36809952062595,327.7591885850378,4.167089745568535
4.5176099884179845e-06,0.06637407481496299,311.5534619500908,327.7591885850378,4.167089745568535
4.5594361806411644e-06,0.06698859771954391,312.2932445030077,327.7591885850378,4.167089745568535
4.563357386162088e-06,0.06704620924184837,312.362463140592,327.7591885850378,4.167089745568535
4.5790422082457805e-06,0.06727665533106622,312.6391060410356,327.7591885850378,4.167089745568535
4.594727030329472e-06,0.06750710142028406,312.9153796238416,327.7591885850378,4.167089745568535
4.619561331961986e-06,0.06787197439487898,313.35206176363505,327.7591885850378,4.167089745568535
4.6339390855387045e-06,0.06808321664332867,313.60445927377145,327.7591885850378,4.167089745568535
4.680993551789782e-06,0.0687745549109822,314.4283603256809,327.7591885850378,4.167089745568535
4.7032137164083465e-06,0.06910102020404081,314.8163013661361,327.7591885850378,4.167089745568535
4.720205606999013e-06,0.0693506701340268,315.11248005338007,327.7591885850378,4.167089745568535
4.738504566096654e-06,0.06961952390478096,315.4309770782742,327.7591885850378,4.167089745568535
4.746346977138501e-06,0.06973474694938989,315.5673289214529,327.7591885850378,4.167089745568535
4.76987421026404e-06,0.07008041608321665,315.9758582352974,327.7591885850378,4.167089745568535
4.784251963840758e-06,0.07029165833166634,316.2251281931834,327.7591885850378,4.167089745568535
4.788173169361681e-06,0.0703492698539708,316.2930601829114,327.7591885850378,4.167089745568535
4.852219526203425e-06,0.07129025805161032,317.39956297640913,327.7591885850378,4.167089745568535
4.854833663217374e-06,0.07132866573314664,317.4446049648084,327.7591885850378,4.167089745568535
4.878360896342913e-06,0.0716743348669734,317.84955810596233,327.7591885850378,4.167089745568535
4.8888174443987084e-06,0.07182796559311863,318.02929271925797,327.7591885850378,4.167089745568535
4.908423472003324e-06,0.07211602320464093,318.36589153569906,327.7591885850378,4.167089745568535
4.918880020059118e-06,0.07226965393078616,318.5451964832853,327.7591885850378,4.167089745568535
4.929336568114914e-06,0.07242328465693139,318.72435283752503,327.7591885850378,4.167089745568535
4.981619308393889e-06,0.07319143828765753,319.6179209599635,327.7591885850378,4.167089745568535
5.001225335998504e-06,0.07347949589917983,319.9520651191027,327.7591885850378,4.167089745568535
5.0744211723890696e-06,0.07455491098219644,321.19504844739186,327.7591885850378,4.167089745568535
5.080956514923942e-06,0.07465093018603722,321.3056879449787,327.7591885850378,4.167089745568535
5.087491857458814e-06,0.07474694938987798,321.4162719558652,327.7591885850378,4.167089745568535
5.164608899370302e-06,0.07587997599519905,322.717007055929,327.7591885850378,4.167089745568535
5.1842149269749176e-06,0.07616803360672135,323.04649198763053,327.7591885850378,4.167089745568535
5.188136132495841e-06,0.07622564512902581,323.1123306190988,327.7591885850378,4.167089745568535
5.201206817565584e-06,0.07641768353670735,323.33165269883887,327.7591885850378,4.167089745568535
5.212970434128354e-06,0.07659051810362073,323.52885885521266,327.7591885850378,4.167089745568535
5.239111804267841e-06,0.0769745949189838,323.96647444750175,327.7591885850378,4.167089745568535
5.277016790970098e-06,0.07753150630126025,324.59950745690986,327.7591885850378,4.167089745568535
5.287473339025893e-06,0.07768513702740548,324.7738248569293,327.7591885850378,4.167089745568535
5.303158161109586e-06,0.07791558311662333,325.0350490843311,327.7591885850378,4.167089745568535
5.339756079304868e-06,0.07845329065813163,325.6434032993239,327.7591885850378,4.167089745568535
5.360669175416458e-06,0.07876055211042209,325.99030415681625,327.7591885850378,4.167089745568535
5.405109504653587e-06,0.0794134826965393,326.725720888953,327.7591885850378,4.167089745568535
5.433865011807023e-06,0.07983596719343869,327.20032249811646,327.7591885850378,4.167089745568535
5.444321559862819e-06,0.07998959791958392,327.37266192031467,327.7591885850378,4.167089745568535
5.463927587467435e-06,0.08027765553110623,327.6954507983436,327.7591885850378,4.167089745568535
5.512289122225487e-06,0.08098819763952791,328.48973804399907,327.7591885850378,4.167089745568535
5.531895149830102e-06,0.08127625525105021,328.81097160124995,327.7591885850378,4.167089745568535
5.576335479067231e-06,0.08192918583716743,329.5374616741661,327.7591885850378,4.167089745568535
5.607705123234615e-06,0.08239007801560312,330.0489193364359,327.7591885850378,4.167089745568535
5.6116263287555386e-06,0.08244768953790758,330.1127729946652,327.7591885850378,4.167089745568535
5.6181616712904106e-06,0.08254370874174835,330.21915710246884,327.7591885850378,4.167089745568535
5.676979754104257e-06,0.08340788157631526,331.1744520280828,327.7591885850378,4.167089745568535
5.688743370667027e-06,0.08358071614322865,331.3650469558977,327.7591885850378,4.167089745568535
5.7227271518483604e-06,0.08408001600320064,331.9147929994923,327.7591885850378,4.167089745568535
5.725341288862309e-06,0.08411842368473695,331.9570283476511,327.7591885850378,4.167089745568535
5.7567109330296945e-06,0.08457931586317263,332.46326731104097,327.7591885850378,4.167089745568535
5.781545234662208e-06,0.08494418883776755,332.863277228849,327.7591885850378,4.167089745568535
5.805072467787747e-06,0.08528985797159433,333.24161631289354,327.7591885850378,4.167089745568535
5.8455915915039525e-06,0.08588517703540709,333.89180146694656,327.7591885850378,4.167089745568535
5.876961235671338e-06,0.08634606921384277,334.3939642363849,327.7591885850378,4.167089745568535
5.922708633415441e-06,0.08701820364072815,335.12441514817937,327.7591885850378,4.167089745568535
5.9488500035549285e-06,0.08740228045609122,335.54082770021375,327.7591885850378,4.167089745568535
5.9697630996665184e-06,0.08770954190838168,335.87344414509727,327.7591885850378,4.167089745568535
5.9959044698060066e-06,0.08809361872374476,336.288576348486,327.7591885850378,4.167089745568535
5.999825675326929e-06,0.08815123024604922,336.35078524480633,327.7591885850378,4.167089745568535
6.028581182480365e-06,0.08857371474294859,336.806500312079,327.7591885850378,4.167089745568535
6.103084087377905e-06,0.08966833366673335,337.98329044330075,327.7591885850378,4.167089745568535
6.1135406354337005e-06,0.08982196439287858,338.1480045064009,327.7591885850378,4.167089745568535
6.121383046475546e-06,0.0899371874374875,338.2714679593283,327.7591885850378,4.167089745568535
6.156673896163855e-06,0.09045569113822766,338.82629187493836,327.7591885850378,4.167089745568535
6.173665786754522e-06,0.09070534106821365,339.09298683365324,327.7591885850378,4.167089745568535
6.18804354033124e-06,0.09091658331666334,339.3184282779445,327.7591885850378,4.167089745568535
6.195885951373086e-06,0.09103180636127226,339.4413102317835,327.7591885850378,4.167089745568535
6.23901921210324e-06,0.09166553310662133,340.1160798053568,327.7591885850378,4.167089745568535
6.2586252397078555e-06,0.09195359071814363,340.42219156703135,327.7591885850378,4.167089745568535
6.2651605822427276e-06,0.0920496099219844,340.52414568319944,327.7591885850378,4.167089745568535
6.287380746861292e-06,0.09237607521504301,340.87047985357873,327.7591885850378,4.167089745568535
6.310907979986831e-06,0.09272174434886978,341.2366667336661,327.7591885850378,4.167089745568535
6.317443322521703e-06,0.09281776355271054,341.3382907757632,327.7591885850378,4.167089745568535
6.331821076098421e-06,0.09302900580116023,341.5617194589356,327.7591885850378,4.167089745568535
6.3697260628006774e-06,0.09358591718343669,342.1498123225882,327.7591885850378,4.167089745568535
6.449457241726115e-06,0.09475735147029406,343.38239897076744,327.7591885850378,4.167089745568535
6.466449132316782e-06,0.09500700140028007,343.6443115511848,327.7591885850378,4.167089745568535
6.48344102290745e-06,0.09525665133026606,343.9059558598865,327.7591885850378,4.167089745568535
6.508275324539962e-06,0.09562152430486098,344.2878785346289,327.7591885850378,4.167089745568535
6.531802557665501e-06,0.09596719343868775,344.64917607592537,327.7591885850378,4.167089745568535
6.54356617422827e-06,0.09614002800560112,344.8296344949157,327.7591885850378,4.167089745568535
6.551408585270117e-06,0.09625525105021004,344.9498698223358,327.7591885850378,4.167089745568535
6.569707544367758e-06,0.0965241048209642,345.2302008399954,327.7591885850378,4.167089745568535
6.58539236645145e-06,0.09675455091018204,345.4702422828202,327.7591885850378,4.167089745568535
6.5880065034653995e-06,0.09679295859171835,345.51022750232096,327.7591885850378,4.167089745568535
6.604998394056066e-06,0.09704260852170435,345.76998076463786,327.7591885850378,4.167089745568535
6.6298326956885795e-06,0.09740748149629927,346.1491518462998,327.7591885850378,4.167089745568535
6.646824586279246e-06,0.09765713142628527,346.40826559153743,327.7591885850378,4.167089745568535
6.6991073265582214e-06,0.09842528505701141,347.2039231012053,327.7591885850378,4.167089745568535
6.730476970725607e-06,0.0988861772354471,347.68015523837187,327.7591885850378,4.167089745568535
6.742240587288375e-06,0.09905901180236047,347.8585190131054,327.7591885850378,4.167089745568535
6.761846614892991e-06,0.09934706941388279,348.1555224986757,327.7591885850378,4.167089745568535
6.778838505483659e-06,0.09959671934386878,348.4126539555105,327.7591885850378,4.167089745568535
6.794523327567351e-06,0.09982716543308662,348.64978305259194,327.7591885850378,4.167089745568535