File: datasets/aisi_316_L/data/M1/train_32.csv
Time(s),Strain(%),Stress(MPa),Temp(C),Log_SR(s-1)
0.0,0.0,0.0,237.58118112461267,4.6631162412040155
1.5639261996784175e-10,7.2e-06,1.3166413875,237.58118112461267,4.6631162412040155
3.4753915548409275e-10,1.6e-05,2.92586975,237.58118112461267,4.6631162412040155
8.514709309360273e-10,3.92e-05,7.1683808875,237.58118112461267,4.6631162412040155
1.0252405086780736e-09,4.7199999999999995e-05,8.6313157625,237.58118112461267,4.6631162412040155
1.390156621936371e-09,6.4e-05,11.703479,237.58118112461267,4.6631162412040155
1.9983501440335333e-09,9.2e-05,16.8237510625,237.58118112461267,4.6631162412040155
2.3632662572918307e-09,0.00010879999999999999,19.895914299999998,237.58118112461267,4.6631162412040155
2.6065436661306956e-09,0.00011999999999999999,21.944023124999998,237.58118112461267,4.6631162412040155
2.7108054127759235e-09,0.0001248,22.821784049999998,237.58118112461267,4.6631162412040155
2.867198032743765e-09,0.00013199999999999998,24.138425437499997,237.58118112461267,4.6631162412040155
3.701292005905588e-09,0.0001704,31.1605128375,237.58118112461267,4.6631162412040155
4.326862485776955e-09,0.0001992,36.427078387499996,237.58118112461267,4.6631162412040155
4.57013989461582e-09,0.0002104,38.475187212499996,237.58118112461267,4.6631162412040155
4.848171219003094e-09,0.00022319999999999998,40.815883012499995,237.58118112461267,4.6631162412040155
5.4737416988744614e-09,0.000252,46.0824485625,237.58118112461267,4.6631162412040155
5.73439606548753e-09,0.00026399999999999997,48.276850874999994,237.58118112461267,4.6631162412040155
6.22095088316526e-09,0.00028639999999999997,52.373068524999994,237.58118112461267,4.6631162412040155
6.412097418681511e-09,0.00029519999999999997,53.98229688749999,237.58118112461267,4.6631162412040155
6.585866996423558e-09,0.0003032,55.4452317625,237.58118112461267,4.6631162412040155
6.898652236359241e-09,0.00031759999999999997,58.07851453749999,237.58118112461267,4.6631162412040155
7.0897987718754916e-09,0.00032639999999999996,59.687742899999996,237.58118112461267,4.6631162412040155
7.524222716230609e-09,0.00034639999999999996,63.345080087499994,237.58118112461267,4.6631162412040155
7.958646660585724e-09,0.00036639999999999996,67.002417275,237.58118112461267,4.6631162412040155
8.201924069424589e-09,0.00037759999999999996,69.0505261,237.58118112461267,4.6631162412040155
8.323562773844022e-09,0.0003832,70.07458051249999,237.58118112461267,4.6631162412040155
8.72323280265073e-09,0.0004016,73.439330725,237.58118112461267,4.6631162412040155
8.810117591521751e-09,0.0004056,74.17079816249999,237.58118112461267,4.6631162412040155
9.557326775812551e-09,0.00043999999999999996,80.461418125,237.58118112461267,4.6631162412040155
9.904865931296643e-09,0.00045599999999999997,83.387287875,237.58118112461267,4.6631162412040155
1.0200274213458123e-08,0.0004696,85.8742771625,237.58118112461267,4.6631162412040155
1.0582567284490624e-08,0.00048719999999999997,89.09273388749999,237.58118112461267,4.6631162412040155
1.0756336862232672e-08,0.0004952,90.5556687625,237.58118112461267,4.6631162412040155
1.134715342655563e-08,0.0005224,95.52964733750001,237.58118112461267,4.6631162412040155
1.1903216075330177e-08,0.000548,100.21103893749999,237.58118112461267,4.6631162412040155
1.2355016977459498e-08,0.0005688,104.01466961249999,237.58118112461267,4.6631162412040155
1.2563540470749954e-08,0.0005784,105.7701914625,237.58118112461267,4.6631162412040155
1.2858948752911431e-08,0.000592,108.25718074999999,237.58118112461267,4.6631162412040155
1.3223864866169729e-08,0.0006087999999999999,111.3293439875,237.58118112461267,4.6631162412040155
1.344976531723439e-08,0.0006192,113.231159325,237.58118112461267,4.6631162412040155
1.3849435346041096e-08,0.0006376,116.59590953749999,237.58118112461267,4.6631162412040155
1.4092712754879961e-08,0.0006487999999999999,118.64401836249999,237.58118112461267,4.6631162412040155
1.4162220585976781e-08,0.000652,119.2291923125,237.58118112461267,4.6631162412040155
1.4266482332622007e-08,0.0006567999999999999,120.10695323749998,237.58118112461267,4.6631162412040155
1.546549241904213e-08,0.000712,130.201203875,237.58118112461267,4.6631162412040155
1.5535000250138947e-08,0.0007151999999999999,130.786377825,237.58118112461267,4.6631162412040155
1.581303157452622e-08,0.0007279999999999999,133.12707362499998,237.58118112461267,4.6631162412040155
1.6838272083204294e-08,0.0007752,141.7583893875,237.58118112461267,4.6631162412040155
1.7255319069785205e-08,0.0007944,145.2694330875,237.58118112461267,4.6631162412040155
1.775925084523714e-08,0.0008175999999999999,149.51194422499998,237.58118112461267,4.6631162412040155
1.8263182620689076e-08,0.0008408,153.75445536249998,237.58118112461267,4.6631162412040155
1.847170611397953e-08,0.0008504,155.5099772125,237.58118112461267,4.6631162412040155
1.9271046171592946e-08,0.0008872,162.2394776375,237.58118112461267,4.6631162412040155
1.937530791823817e-08,0.000892,163.1172385625,237.58118112461267,4.6631162412040155
1.993137056701272e-08,0.0009176,167.7986301625,237.58118112461267,4.6631162412040155
2.0070386229206356e-08,0.0009239999999999999,168.96897806249999,237.58118112461267,4.6631162412040155
2.0296286680271017e-08,0.0009343999999999999,170.8707934,237.58118112461267,4.6631162412040155
2.1026118906787615e-08,0.000968,177.015119875,237.58118112461267,4.6631162412040155
2.1738574175530006e-08,0.0010008,183.01315286250002,237.58118112461267,4.6631162412040155
2.2120867246562507e-08,0.0010184,186.2316095875,237.58118112461267,4.6631162412040155
2.2242505950981936e-08,0.001024,187.255664,237.58118112461267,4.6631162412040155
2.3024469050821145e-08,0.00106,193.8388709375,237.58118112461267,4.6631162412040155
2.318086167078899e-08,0.0010672,195.155512325,237.58118112461267,4.6631162412040155
2.3702170404015126e-08,0.0010911999999999999,199.54431694999997,237.58118112461267,4.6631162412040155
2.4084463475047627e-08,0.0011087999999999998,202.76277367499998,237.58118112461267,4.6631162412040155
2.4258233052789677e-08,0.0011168,204.22570855,237.58118112461267,4.6631162412040155
2.469265699714479e-08,0.0011367999999999999,207.88304573749997,237.58118112461267,4.6631162412040155
2.495331136375786e-08,0.0011488,210.07744805,237.58118112461267,4.6631162412040155
2.557888184362923e-08,0.0011776,215.3440136,237.58118112461267,4.6631162412040155
2.5943797956887524e-08,0.0011944,218.4161768375,237.58118112461267,4.6631162412040155
2.6100190576855367e-08,0.0012016,219.732818225,237.58118112461267,4.6631162412040155
2.632609102792003e-08,0.001212,220.88646631635595,237.58118112461267,4.6631162412040155
2.6656253225629915e-08,0.0012272,220.98683354737852,237.58118112461267,4.6631162412040155
2.8011655932017876e-08,0.0012896,221.39388662426202,237.58118112461267,4.6631162412040155
2.8324441171953562e-08,0.001304,221.4867222895828,237.58118112461267,4.6631162412040155
2.868935728521186e-08,0.0013208,221.5945267390238,237.58118112461267,4.6631162412040155
2.9610336047244705e-08,0.0013632,221.8642533475474,237.58118112461267,4.6631162412040155
2.9975252160503e-08,0.00138,221.9702186448276,237.58118112461267,4.6631162412040155
3.014902173824505e-08,0.001388,222.0205013764533,237.58118112461267,4.6631162412040155
3.0392299147083914e-08,0.0013992,222.09070772822986,237.58118112461267,4.6631162412040155
3.0461806978180735e-08,0.0014024,222.11072638626334,237.58118112461267,4.6631162412040155
3.0652953513696986e-08,0.0014112,222.1656860489977,237.58118112461267,4.6631162412040155
3.0896230922535844e-08,0.0014223999999999999,222.23544178496098,237.58118112461267,4.6631162412040155
3.141753965576199e-08,0.0014464,222.38420111143606,237.58118112461267,4.6631162412040155
3.192147143121392e-08,0.0014696,222.52708940759504,237.58118112461267,4.6631162412040155
3.216474884005279e-08,0.0014808,222.59575487156283,237.58118112461267,4.6631162412040155
3.247753407998847e-08,0.0014952,222.68374215126732,237.58118112461267,4.6631162412040155
3.270343453105313e-08,0.0015056,222.74708311723595,237.58118112461267,4.6631162412040155
3.305097368653722e-08,0.0015216,222.84419857589867,237.58118112461267,4.6631162412040155
3.317261239095665e-08,0.0015271999999999998,222.87809479014157,237.58118112461267,4.6631162412040155
3.338113588424711e-08,0.0015367999999999998,222.93609002653608,237.58118112461267,4.6631162412040155
3.381555982860222e-08,0.0015568,223.05646159935034,237.58118112461267,4.6631162412040155
3.4197852899634724e-08,0.0015743999999999999,223.1618905815313,237.58118112461267,4.6631162412040155
3.480604642173189e-08,0.0016024,223.32867610422136,237.58118112461267,4.6631162412040155
3.5136208619441777e-08,0.0016175999999999999,223.41874067712558,237.58118112461267,4.6631162412040155
3.555325560602269e-08,0.0016367999999999999,223.53203607080266,237.58118112461267,4.6631162412040155
3.576177909931314e-08,0.0016464,223.58848931802117,237.58118112461267,4.6631162412040155
3.5831286930409964e-08,0.0016496,223.60727851968312,237.58118112461267,4.6631162412040155
3.5918171719280986e-08,0.0016535999999999999,223.6307450440646,237.58118112461267,4.6631162412040155
3.6022433465926214e-08,0.0016584,223.65887567113998,237.58118112461267,4.6631162412040155
3.654374219915235e-08,0.0016824,223.79905529887026,237.58118112461267,4.6631162412040155
3.661325003024917e-08,0.0016856,223.81768681612252,237.58118112461267,4.6631162412040155
3.723882051012054e-08,0.0017143999999999998,223.98475426736536,237.58118112461267,4.6631162412040155
3.741259008786259e-08,0.0017224,224.0309671819643,237.58118112461267,4.6631162412040155
3.7551605750056225e-08,0.0017288,224.06787726996507,237.58118112461267,4.6631162412040155
3.78296370744435e-08,0.0017415999999999998,224.141537963997,237.58118112461267,4.6631162412040155
3.800340665218555e-08,0.0017496,224.18746869636237,237.58118112461267,4.6631162412040155
3.8420453638766456e-08,0.0017687999999999998,224.29736955513977,237.58118112461267,4.6631162412040155
3.906340107641203e-08,0.0017984,224.46589288246437,237.58118112461267,4.6631162412040155
3.918503978083146e-08,0.0018039999999999998,224.49765362074865,237.58118112461267,4.6631162412040155
3.960208676741237e-08,0.0018231999999999999,224.60625685617296,237.58118112461267,4.6631162412040155
4.012339550063851e-08,0.0018472,224.74138568615624,237.58118112461267,4.6631162412040155
4.0279788120606354e-08,0.0018544,224.78179058898937,237.58118112461267,4.6631162412040155
4.069683510718726e-08,0.0018736,224.88923899783603,237.58118112461267,4.6631162412040155
4.170469865809113e-08,0.0019199999999999998,225.14714833970194,237.58118112461267,4.6631162412040155
4.189584519360738e-08,0.0019287999999999998,225.1957867435856,237.58118112461267,4.6631162412040155
4.2017483898026816e-08,0.0019344,225.22669340012766,237.58118112461267,4.6631162412040155
4.210436868689784e-08,0.0019383999999999998,225.24874822317108,237.58118112461267,4.6631162412040155
4.257354654680137e-08,0.00196,225.367538961585,237.58118112461267,4.6631162412040155
4.321649398444693e-08,0.0019896,225.52950036151927,237.58118112461267,4.6631162412040155
4.3911572295415114e-08,0.0020215999999999997,225.70354025695784,237.58118112461267,4.6631162412040155
4.42069805775766e-08,0.0020352,225.77718149274335,237.58118112461267,4.6631162412040155
4.448501190196387e-08,0.002048,225.8463157692404,237.58118112461267,4.6631162412040155
4.467615843748013e-08,0.0020568,225.8937478627356,237.58118112461267,4.6631162412040155
4.5145336297383646e-08,0.0020783999999999998,226.00983777977316,237.58118112461267,4.6631162412040155
4.5232221086254674e-08,0.0020824,226.03128417875678,237.58118112461267,4.6631162412040155
4.538861370622252e-08,0.0020896,226.06984725383703,237.58118112461267,4.6631162412040155
4.544074457954513e-08,0.002092,226.0826900918912,237.58118112461267,4.6631162412040155
4.5510252410641946e-08,0.0020951999999999998,226.09980494112352,237.58118112461267,4.6631162412040155
4.6483362045997406e-08,0.00214,226.33835245566289,237.58118112461267,4.6631162412040155
4.6709262497062064e-08,0.0021504,226.39345006503305,237.58118112461267,4.6631162412040155
4.690040903257832e-08,0.0021592,226.4399899967665,237.58118112461267,4.6631162412040155
4.7386963850256044e-08,0.0021815999999999997,226.55812270813922,237.58118112461267,4.6631162412040155
4.789089562570798e-08,0.0022048,226.6799768213012,237.58118112461267,4.6631162412040155
4.8047288245675824e-08,0.002212,226.71769180340152,237.58118112461267,4.6631162412040155
4.818630390786946e-08,0.0022183999999999997,226.75117605769103,237.58118112461267,4.6631162412040155
4.8238434781192075e-08,0.0022207999999999998,226.76372293748173,237.58118112461267,4.6631162412040155
4.846433523225674e-08,0.0022312,226.81803175717397,237.58118112461267,4.6631162412040155
4.875974351441822e-08,0.0022448,226.88890225146724,237.58118112461267,4.6631162412040155
4.895089004993446e-08,0.0022535999999999997,226.93467041603665,237.58118112461267,4.6631162412040155
4.9402690952063785e-08,0.0022743999999999998,227.0425735308191,237.58118112461267,4.6631162412040155
4.980236098087049e-08,0.0022928,227.13770589061411,237.58118112461267,4.6631162412040155
4.997613055861254e-08,0.0023008,227.1789748662625,237.58118112461267,4.6631162412040155
5.0271538840774016e-08,0.0023144,227.24900392121066,237.58118112461267,4.6631162412040155
5.030629275632243e-08,0.002316,227.25723206912423,237.58118112461267,4.6631162412040155
5.115776368725846e-08,0.0023552,227.45813443524028,237.58118112461267,4.6631162412040155
5.1435795011645726e-08,0.002368,227.52345221415024,237.58118112461267,4.6631162412040155
5.167907242048459e-08,0.0023791999999999997,227.580492399271,237.58118112461267,4.6631162412040155
5.2808574675807894e-08,0.0024311999999999997,227.8439620441839,237.58118112461267,4.6631162412040155
5.332988340903403e-08,0.0024552,227.96482126606773,237.58118112461267,4.6631162412040155
5.3781684311163353e-08,0.002476,228.06919370547843,237.58118112461267,4.6631162412040155
5.400758476222801e-08,0.0024863999999999997,228.12125165328013,237.58118112461267,4.6631162412040155
5.419873129774427e-08,0.0024952,228.1652343914975,237.58118112461267,4.6631162412040155
5.449413957990575e-08,0.0025088,228.23308890988707,237.58118112461267,4.6631162412040155
5.4598401326550976e-08,0.0025136,228.25700329332795,237.58118112461267,4.6631162412040155
5.532823355306757e-08,0.0025472,228.4239081024788,237.58118112461267,4.6631162412040155
5.544987225748701e-08,0.0025528,228.45164187998955,237.58118112461267,4.6631162412040155
5.560626487745484e-08,0.0025599999999999998,228.48726475458426,237.58118112461267,4.6631162412040155
5.5693149666325865e-08,0.002564,228.50703835617765,237.58118112461267,4.6631162412040155
5.597118099071314e-08,0.0025767999999999998,228.57023318739405,237.58118112461267,4.6631162412040155
5.670101321722973e-08,0.0026103999999999997,228.7355398576232,237.58118112461267,4.6631162412040155
5.7065929330488026e-08,0.0026271999999999997,228.81788185530027,237.58118112461267,4.6631162412040155
5.720494499268167e-08,0.0026336,228.8491961875293,237.58118112461267,4.6631162412040155
5.750035327484314e-08,0.0026471999999999997,228.9156407734803,237.58118112461267,4.6631162412040155
5.8108546796940314e-08,0.0026752,229.05202071810993,237.58118112461267,4.6631162412040155
5.826493941690815e-08,0.0026823999999999997,229.08699972518733,237.58118112461267,4.6631162412040155
5.852559378352122e-08,0.0026944,229.14521680923664,237.58118112461267,4.6631162412040155
5.876887119236009e-08,0.0027056,229.19946158855015,237.58118112461267,4.6631162412040155
5.885575598123111e-08,0.0027096,229.21881349156644,237.58118112461267,4.6631162412040155
5.8960017727876345e-08,0.0027144,229.24202107466087,237.58118112461267,4.6631162412040155
5.9342310798908846e-08,0.002732,229.32697895742595,237.58118112461267,4.6631162412040155
5.960296516552191e-08,0.002744,229.3847824413075,237.58118112461267,4.6631162412040155
5.968984995439294e-08,0.002748,229.40402835028743,237.58118112461267,4.6631162412040155
6.017640477207066e-08,0.0027703999999999997,229.51160421541192,237.58118112461267,4.6631162412040155
6.043705913868373e-08,0.0027824,229.56909457944,237.58118112461267,4.6631162412040155
6.113213744965192e-08,0.0028144,229.7219314249188,237.58118112461267,4.6631162412040155
6.123639919629714e-08,0.0028192,229.744798364506,237.58118112461267,4.6631162412040155
6.174033097174907e-08,0.0028423999999999997,229.8551085675834,237.58118112461267,4.6631162412040155
6.238327840939466e-08,0.002872,229.99534069962738,237.58118112461267,4.6631162412040155
6.318261846700806e-08,0.0029088,230.16889981669792,237.58118112461267,4.6631162412040155
6.375605807355682e-08,0.0029352,230.29288251055777,237.58118112461267,4.6631162412040155
6.452064421562182e-08,0.0029703999999999998,230.4575183597874,237.58118112461267,4.6631162412040155
6.474654466668648e-08,0.0029808,230.5060149280405,237.58118112461267,4.6631162412040155
6.511146077994478e-08,0.0029976,230.5842163725233,237.58118112461267,4.6631162412040155
6.580653909091297e-08,0.0030296,230.7327002570869,237.58118112461267,4.6631162412040155
6.585866996423558e-08,0.003032,230.74381182979639,237.58118112461267,4.6631162412040155
6.604981649975183e-08,0.0030407999999999998,230.78452494878636,237.58118112461267,4.6631162412040155
6.624096303526809e-08,0.0030496,230.82519214274504,237.58118112461267,4.6631162412040155
6.650161740188114e-08,0.0030616,230.88057372826998,237.58118112461267,4.6631162412040155
6.664063306407479e-08,0.003068,230.91007595564366,237.58118112461267,4.6631162412040155
6.717931875507513e-08,0.0030927999999999997,231.0241711007832,237.58118112461267,4.6631162412040155
6.775275836162389e-08,0.0031192,231.14523584610407,237.58118112461267,4.6631162412040155
6.801341272823695e-08,0.0031311999999999998,231.20013310573438,237.58118112461267,4.6631162412040155
6.806554360155956e-08,0.0031336,231.21110270485462,237.58118112461267,4.6631162412040155
6.879537582807616e-08,0.0031672,231.3643346779916,237.58118112461267,4.6631162412040155
6.896914540581821e-08,0.0031752,231.40072487911374,237.58118112461267,4.6631162412040155
6.907340715246344e-08,0.0031799999999999997,231.42254183655947,237.58118112461267,4.6631162412040155
6.922979977243128e-08,0.0031872,231.4552432072294,237.58118112461267,4.6631162412040155
6.942094630794754e-08,0.003196,231.4951724497954,237.58118112461267,4.6631162412040155
6.983799329452844e-08,0.0032151999999999997,231.58214226862464,237.58118112461267,4.6631162412040155
6.992487808339947e-08,0.0032191999999999998,231.6002354603949,237.58118112461267,4.6631162412040155
7.016815549223834e-08,0.0032304,231.6508498120387,237.58118112461267,4.6631162412040155
7.030717115443197e-08,0.0032367999999999997,231.67974157081207,237.58118112461267,4.6631162412040155
7.096749554985174e-08,0.0032672,231.81667432855804,237.58118112461267,4.6631162412040155
7.124552687423901e-08,0.00328,231.87418146654252,237.58118112461267,4.6631162412040155
7.171470473414254e-08,0.0033016,231.9710266924255,237.58118112461267,4.6631162412040155
7.183634343856197e-08,0.0033071999999999997,231.99609433877743,237.58118112461267,4.6631162412040155
7.201011301630403e-08,0.0033152,232.0318765649325,237.58118112461267,4.6631162412040155
7.235765217178812e-08,0.0033312,232.1033401511546,237.58118112461267,4.6631162412040155
7.247929087620754e-08,0.0033368,232.12832076440426,237.58118112461267,4.6631162412040155
7.26704374117238e-08,0.0033456,232.16754300497055,237.58118112461267,4.6631162412040155
7.364354704707926e-08,0.0033904,232.36659945775767,237.58118112461267,4.6631162412040155
7.390420141369233e-08,0.0034024,232.4197436300214,237.58118112461267,4.6631162412040155
7.418223273807959e-08,0.0034151999999999997,232.47635023883038,237.58118112461267,4.6631162412040155
7.423436361140222e-08,0.0034176,232.48695476020083,237.58118112461267,4.6631162412040155
7.430387144249903e-08,0.0034208,232.50108960529215,237.58118112461267,4.6631162412040155
7.472091842907995e-08,0.00344,232.58579063721146,237.58118112461267,4.6631162412040155
7.496419583791881e-08,0.0034511999999999998,232.63511442886923,237.58118112461267,4.6631162412040155
7.541599674004812e-08,0.003472,232.72655045189427,237.58118112461267,4.6631162412040155
7.5659274148887e-08,0.0034831999999999997,232.77569673669606,237.58118112461267,4.6631162412040155
7.614582896656473e-08,0.0035055999999999998,232.8738048048609,237.58118112461267,4.6631162412040155
7.623271375543575e-08,0.0035096,232.89129834490072,237.58118112461267,4.6631162412040155
7.661500682646825e-08,0.0035272,232.9681777304866,237.58118112461267,4.6631162412040155
7.687566119308131e-08,0.0035391999999999997,233.02050973569558,237.58118112461267,4.6631162412040155
7.736221601075904e-08,0.0035616,233.1180113690157,237.58118112461267,4.6631162412040155
7.741434688408167e-08,0.003564,233.12844376843708,237.58118112461267,4.6631162412040155
7.769237820846893e-08,0.0035767999999999998,233.18403702795885,237.58118112461267,4.6631162412040155
7.79182786595336e-08,0.0035872,233.22914944209222,237.58118112461267,4.6631162412040155
7.856122609717917e-08,0.0036168,233.35726797309457,237.58118112461267,4.6631162412040155
7.897827308376009e-08,0.003636,233.44015328985836,237.58118112461267,4.6631162412040155
7.90477809148569e-08,0.0036392,233.45395089722015,237.58118112461267,4.6631162412040155
7.918679657705053e-08,0.0036455999999999997,233.48153192520698,237.58118112461267,4.6631162412040155
7.960384356363145e-08,0.0036647999999999997,233.56416192963607,237.58118112461267,4.6631162412040155
7.976023618359929e-08,0.003672,233.5951046327483,237.58118112461267,4.6631162412040155
8.028154491682542e-08,0.0036959999999999996,233.69807650965973,237.58118112461267,4.6631162412040155
8.043793753679327e-08,0.0037032,233.72891717908308,237.58118112461267,4.6631162412040155
8.071596886118054e-08,0.0037159999999999997,233.7836873564507,237.58118112461267,4.6631162412040155
8.123727759440668e-08,0.00374,233.8861835339476,237.58118112461267,4.6631162412040155
8.141104717214874e-08,0.003748,233.9202918813227,237.58118112461267,4.6631162412040155
8.144580108769714e-08,0.0037495999999999996,233.92711014232387,237.58118112461267,4.6631162412040155
8.16543245809876e-08,0.0037592,233.96799590555753,237.58118112461267,4.6631162412040155
8.200186373647168e-08,0.0037752,234.0360484704957,237.58118112461267,4.6631162412040155
8.233202593418157e-08,0.0037903999999999998,234.10059429476186,237.58118112461267,4.6631162412040155
8.245366463860101e-08,0.003796,234.1243488789263,237.58118112461267,4.6631162412040155
8.325300469621443e-08,0.0038328,234.28011181461835,237.58118112461267,4.6631162412040155
8.39307060494084e-08,0.003864,234.41171535770323,237.58118112461267,4.6631162412040155
8.417398345824726e-08,0.0038751999999999997,234.45885648449817,237.58118112461267,4.6631162412040155
8.43129991204409e-08,0.0038816,234.48577041401023,237.58118112461267,4.6631162412040155
8.509496222028012e-08,0.0039176,234.63684003372182,237.58118112461267,4.6631162412040155
8.556414008018364e-08,0.0039391999999999995,234.72722195042124,237.58118112461267,4.6631162412040155
8.565102486905466e-08,0.0039432,234.74393811043615,237.58118112461267,4.6631162412040155
8.596381010899034e-08,0.0039575999999999995,234.8040616066856,237.58118112461267,4.6631162412040155
8.631134926447444e-08,0.0039736,234.87076551675733,237.58118112461267,4.6631162412040155
8.664151146218432e-08,0.0039888,234.9340372739571,237.58118112461267,4.6631162412040155
9.189035382298452e-08,0.004230446089217844,235.9276165985198,237.58118112461267,4.6631162412040155
1.0690704867886851e-07,0.004921784356871375,238.65466447910876,237.58118112461267,4.6631162412040155
1.0899270074218574e-07,0.005017803560712143,239.0212382744734,237.58118112461267,4.6631162412040155
1.1483252651947396e-07,0.005286657331466294,240.033368312197,237.58118112461267,4.6631162412040155
1.1650104817012774e-07,0.005363472694538908,240.3188347367343,237.58118112461267,4.6631162412040155
1.1942096105877184e-07,0.005497899579915984,240.81459354135092,237.58118112461267,4.6631162412040155
1.240093955980697e-07,0.005709141828365673,241.58419620976144,237.58118112461267,4.6631162412040155
1.2818069972470415e-07,0.005901180236047209,242.2742499111003,237.58118112461267,4.6631162412040155
1.3735756880329992e-07,0.006323664732946589,243.76226067625393,237.58118112461267,4.6631162412040155
1.4111174251727091e-07,0.006496499299859972,244.35975331956476,237.58118112461267,4.6631162412040155
1.427802641679247e-07,0.006573314662932587,244.62331222564504,237.58118112461267,4.6631162412040155
1.4903722035787636e-07,0.006861372274454891,245.60113911150165,237.58118112461267,4.6631162412040155
1.532085244845108e-07,0.007053410682136428,246.24414223380052,237.58118112461267,4.6631162412040155
1.6613956727707755e-07,0.0076487297459491895,248.19537492782584,237.58118112461267,4.6631162412040155
1.7364791470501954e-07,0.007994398879775955,249.30115020435895,237.58118112461267,4.6631162412040155
1.7948774048230777e-07,0.008263252650530106,250.14835350517455,237.58118112461267,4.6631162412040155
1.9742434822683587e-07,0.009089017803560712,252.68564198233804,237.58118112461267,4.6631162412040155
2.0326417400412408e-07,0.009357871574314863,253.49211114009975,237.58118112461267,4.6631162412040155
2.0826973895608542e-07,0.009588317663532707,254.17620381423717,237.58118112461267,4.6631162412040155
2.1410956473337363e-07,0.009857171434286858,254.9662593038734,237.58118112461267,4.6631162412040155
2.1786373844734462e-07,0.01003000600120024,255.46971743930538,237.58118112461267,4.6631162412040155
2.3121191165257482e-07,0.010644528905781155,257.23301713410825,237.58118112461267,4.6631162412040155
2.3788599825518991e-07,0.010951790358071613,258.09974197823294,237.58118112461267,4.6631162412040155
2.4247443279448785e-07,0.011163032606521305,258.69012129099434,237.58118112461267,4.6631162412040155
2.453943456831319e-07,0.011297459491898379,259.06354969558623,237.58118112461267,4.6631162412040155
2.524855626984105e-07,0.011623924784956993,259.9633049078575,237.58118112461267,4.6631162412040155
2.5749112765037177e-07,0.011854370874174834,260.5925016756608,237.58118112461267,4.6631162412040155
2.629138230149966e-07,0.012104020804160832,261.2687723312921,237.58118112461267,4.6631162412040155
2.712564312682654e-07,0.012488097619523904,262.29866168358615,237.58118112461267,4.6631162412040155
2.912786910761108e-07,0.013409881976395279,264.72124483509526,237.58118112461267,4.6631162412040155
2.93364343139428e-07,0.013505901180236047,264.96980365790955,237.58118112461267,4.6631162412040155
2.983699080913893e-07,0.013736347269453891,265.563549691588,237.58118112461267,4.6631162412040155
3.058782555193313e-07,0.014082016403280656,266.4469360033238,237.58118112461267,4.6631162412040155
3.104666900586292e-07,0.014293258651730346,266.9826212017312,237.58118112461267,4.6631162412040155
3.192264287245615e-07,0.014696539307861573,267.9967956931472,237.58118112461267,4.6631162412040155
3.246491240891863e-07,0.01494618923784757,268.6191811905887,237.58118112461267,4.6631162412040155
3.292375586284842e-07,0.01515743148629726,269.14265472422886,237.58118112461267,4.6631162412040155
3.329917323424552e-07,0.015330266053210643,269.56883817712276,237.58118112461267,4.6631162412040155
3.42168601421051e-07,0.015752750550110023,270.6028066952677,237.58118112461267,4.6631162412040155
3.446713838970316e-07,0.015867973594718945,270.8829138375362,237.58118112461267,4.6631162412040155
3.4675703596034886e-07,0.015963992798559715,271.11573101876115,237.58118112461267,4.6631162412040155
3.559339050389446e-07,0.01638647729545909,272.1337065963973,237.58118112461267,4.6631162412040155
3.763732952594533e-07,0.017327465493098618,274.3649263762716,237.58118112461267,4.6631162412040155
4.0098398960659656e-07,0.018460492098419684,276.98972129557046,237.58118112461267,4.6631162412040155
4.0682381538388476e-07,0.018729345869173835,277.60323749242326,237.58118112461267,4.6631162412040155
4.093265978598654e-07,0.018844568913782757,277.8651205020146,237.58118112461267,4.6631162412040155
4.1474929322449016e-07,0.019094218843768752,278.4304008972531,237.58118112461267,4.6631162412040155
4.260118143664032e-07,0.019612722544508902,279.59531678949094,237.58118112461267,4.6631162412040155
4.3685720509565277e-07,0.020112022404480897,280.70578755370593,237.58118112461267,4.6631162412040155
4.514567695388733e-07,0.020784156831366273,282.1838194121378,237.58118112461267,4.6631162412040155
4.543766824275174e-07,0.02091858371674335,282.4771758834996,237.58118112461267,4.6631162412040155
4.627192906807863e-07,0.021302660532106422,283.3113132178885,237.58118112461267,4.6631162412040155
4.743989422353627e-07,0.021840368073614724,284.4693181239699,237.58118112461267,4.6631162412040155
4.985925061698425e-07,0.022954190838167635,286.83325471906426,237.58118112461267,4.6631162412040155
5.069351144231113e-07,0.023338267653530708,287.6379753186178,237.58118112461267,4.6631162412040155
5.186147659776878e-07,0.023875975195039006,288.7559605259614,237.58118112461267,4.6631162412040155
5.453111123881482e-07,0.02510502100420084,291.2751180996254,237.58118112461267,4.6631162412040155
5.586592855933784e-07,0.025719543908781756,292.51662289610266,237.58118112461267,4.6631162412040155
5.636648505453397e-07,0.0259499899979996,292.97919769880576,237.58118112461267,4.6631162412040155
5.661676330213203e-07,0.02606521304260852,293.2098841268726,237.58118112461267,4.6631162412040155
5.745102412745893e-07,0.026449289857971594,293.9759826083127,237.58118112461267,4.6631162412040155
5.824357191151947e-07,0.026814162832566515,294.699767356405,237.58118112461267,4.6631162412040155
5.891098057178098e-07,0.027121424284856973,295.30629592787085,237.58118112461267,4.6631162412040155
5.928639794317808e-07,0.027294258851770354,295.6462904576689,237.58118112461267,4.6631162412040155
6.13720500064953e-07,0.028254450890178036,297.52007778309405,237.58118112461267,4.6631162412040155
6.21228847492895e-07,0.0286001200240048,298.18854001208706,237.58118112461267,4.6631162412040155
6.24983021206866e-07,0.028772954590918182,298.52158899743074,237.58118112461267,4.6631162412040155
6.274858036828466e-07,0.028888177635527104,298.7431883005012,237.58118112461267,4.6631162412040155
6.408339768880769e-07,0.02950270054010802,299.9192800131357,237.58118112461267,4.6631162412040155
6.583534542199415e-07,0.030309261852370473,301.44850189530996,237.58118112461267,4.6631162412040155
6.612733671085857e-07,0.03044368873774755,301.7018212503554,237.58118112461267,4.6631162412040155
6.762900619644697e-07,0.03113502700540108,302.99777922949954,237.58118112461267,4.6631162412040155
6.825470181544212e-07,0.031423084616923384,303.5344437603393,237.58118112461267,4.6631162412040155
6.99232234660959e-07,0.03219123824764953,304.9562509840677,237.58118112461267,4.6631162412040155
7.171688424054872e-07,0.03301700340068014,306.4700150627928,237.58118112461267,4.6631162412040155
7.184202336434774e-07,0.033074614922984594,306.5750722119982,237.58118112461267,4.6631162412040155
7.225915377701119e-07,0.033266653330666134,306.9247484140018,237.58118112461267,4.6631162412040155
7.275971027220732e-07,0.03349709941988398,307.3433224085713,237.58118112461267,4.6631162412040155
7.317684068487076e-07,0.03368913782756551,307.6912768736729,237.58118112461267,4.6631162412040155
7.417795367526303e-07,0.0341500300060012,308.52322657672175,237.58118112461267,4.6631162412040155
7.501221450058993e-07,0.03453410682136428,309.213178178198,237.58118112461267,4.6631162412040155
7.597161444971584e-07,0.034975795159031806,310.0029336335595,237.58118112461267,4.6631162412040155
7.659731006871099e-07,0.035263852770554105,310.5158968568893,237.58118112461267,4.6631162412040155
7.672244919251003e-07,0.03532146429285857,310.61829311689354,237.58118112461267,4.6631162412040155
7.74315708940379e-07,0.035647929585917185,311.19731295296486,237.58118112461267,4.6631162412040155
7.868296213202823e-07,0.0362240448089618,312.2140928693766,237.58118112461267,4.6631162412040155
7.893324037962628e-07,0.03633926785357071,312.41668991025483,237.58118112461267,4.6631162412040155
7.960064903988779e-07,0.03664652930586117,312.9557276060228,237.58118112461267,4.6631162412040155
7.976750120495318e-07,0.03672334466893379,313.09021126622554,237.58118112461267,4.6631162412040155
8.076861419534545e-07,0.037184236847369476,313.8948213646571,237.58118112461267,4.6631162412040155
8.160287502067233e-07,0.03756831366273254,314.5623629156653,237.58118112461267,4.6631162412040155
8.360510100145685e-07,0.038490098019603916,316.1536956286791,237.58118112461267,4.6631162412040155
8.539876177590967e-07,0.039315863172634524,317.56668623031004,237.58118112461267,4.6631162412040155
8.623302260123658e-07,0.039699939987997604,318.21994296633505,237.58118112461267,4.6631162412040155
8.760955296302592e-07,0.040333666733346665,319.2924535494317,237.58118112461267,4.6631162412040155
9.023747456280564e-07,0.04154350870174035,321.3218973201113,237.58118112461267,4.6631162412040155
9.111344842939887e-07,0.04194678935787158,321.99323895768197,237.58118112461267,4.6631162412040155
9.128030059446423e-07,0.042023604720944185,322.1208276620677,237.58118112461267,4.6631162412040155
9.144715275952962e-07,0.04210042008401681,322.2483254427501,237.58118112461267,4.6631162412040155
9.319910049271608e-07,0.042906981396279256,323.58162001724634,237.58118112461267,4.6631162412040155
9.42419265243747e-07,0.0433870774154831,324.37060746049775,237.58118112461267,4.6631162412040155
9.570188296869673e-07,0.04405921184236847,325.46949345987076,237.58118112461267,4.6631162412040155
9.591044817502847e-07,0.04415523104620925,325.625941809927,237.58118112461267,4.6631162412040155
9.666128291782268e-07,0.04450090018003601,326.18806059242326,237.58118112461267,4.6631162412040155
9.716183941301879e-07,0.04473134626925385,326.5618606923992,237.58118112461267,4.6631162412040155
9.770410894948127e-07,0.04498099619923984,326.9659642904353,237.58118112461267,4.6631162412040155
9.845494369227548e-07,0.04532666533306662,327.52405128903536,237.58118112461267,4.6631162412040155
1.0070744792065807e-06,0.046363672734546904,329.1884370939541,237.58118112461267,4.6631162412040155
1.014582826634523e-06,0.04670934186837368,329.73999763591723,237.58118112461267,4.6631162412040155
1.0300166519030701e-06,0.04741988397679536,330.8687867900955,237.58118112461267,4.6631162412040155
1.0362736080930217e-06,0.04770794158831766,331.3245225259454,237.58118112461267,4.6631162412040155
1.0429476946956368e-06,0.04801520304060812,331.80945938078656,237.58118112461267,4.6631162412040155
1.0462847379969445e-06,0.04816883376675335,332.05147385171796,237.58118112461267,4.6631162412040155
1.061718563265492e-06,0.04887937587517503,333.16689817198517,237.58118112461267,4.6631162412040155
1.0838264751366543e-06,0.04989717943588717,334.7537137004772,237.58118112461267,4.6631162412040155
1.0892491705012791e-06,0.05014682936587317,335.14099853501466,237.58118112461267,4.6631162412040155
1.0917519529772599e-06,0.050262052410482094,335.3194916994265,237.58118112461267,4.6631162412040155
1.0971746483418845e-06,0.05051170234046809,335.7056803524584,237.58118112461267,4.6631162412040155
1.1071857782458073e-06,0.05097259451890378,336.41669396994956,237.58118112461267,4.6631162412040155
1.1109399519597783e-06,0.051145429085817165,336.6826771066795,237.58118112461267,4.6631162412040155
1.1255395164029988e-06,0.051817563512702544,337.71374077337555,237.58118112461267,4.6631162412040155
1.1326307334182773e-06,0.05214402880576115,338.21266005263556,237.58118112461267,4.6631162412040155
1.136802037544912e-06,0.052336067213442694,338.50557292713955,237.58118112461267,4.6631162412040155
1.1497330803374786e-06,0.05293138627725545,339.4109503511106,237.58118112461267,4.6631162412040155
1.1534872540514496e-06,0.05310422084416884,339.67305689134946,237.58118112461267,4.6631162412040155
1.174343774684622e-06,0.05406441288257652,341.1231910125179,237.58118112461267,4.6631162412040155
1.1847720350012078e-06,0.05454450890178035,341.8444888785873,237.58118112461267,4.6631162412040155
1.194366034492467e-06,0.05498619723944789,342.50589909021625,237.58118112461267,4.6631162412040155
1.2027086427457358e-06,0.05537027405481096,343.07935594013793,237.58118112461267,4.6631162412040155
1.2052114252217165e-06,0.055485497099419884,343.25109021107096,237.58118112461267,4.6631162412040155
1.2227309025535812e-06,0.05629205841168233,344.44935957066195,237.58118112461267,4.6631162412040155
1.226902206680216e-06,0.05648409681936388,344.7336726182607,237.58118112461267,4.6631162412040155
1.2306563803941868e-06,0.056656931386277254,344.9892322016995,237.58118112461267,4.6631162412040155
1.2339934236954942e-06,0.05681056211242248,345.21614114159263,237.58118112461267,4.6631162412040155
1.2369133365841385e-06,0.05694498899779957,345.414490225554,237.58118112461267,4.6631162412040155
1.2385818582347922e-06,0.057021804360872175,345.5277505701731,237.58118112461267,4.6631162412040155
1.24317029277409e-06,0.057233046609321866,345.838910112716,237.58118112461267,4.6631162412040155
1.250678640202032e-06,0.05757871574314863,346.3471158798112,237.58118112461267,4.6631162412040155
1.273203682485858e-06,0.05861572314462893,347.86464145600024,237.58118112461267,4.6631162412040155
1.2773749866124924e-06,0.05880776155231046,348.14451193212136,237.58118112461267,4.6631162412040155
1.282380551564454e-06,0.05903820764152831,348.4798864553237,237.58118112461267,4.6631162412040155
1.2940602031190301e-06,0.05957591518303661,349.2604478338144,237.58118112461267,4.6631162412040155
1.3028199417849624e-06,0.05997919583916783,349.8440670482244,237.58118112461267,4.6631162412040155
1.3049055938482796e-06,0.0600752150430086,349.9827981962284,237.58118112461267,4.6631162412040155
1.3082426371495873e-06,0.06022884576915383,350.20458829630314,237.58118112461267,4.6631162412040155
1.319088027878837e-06,0.06072814562912583,350.92388712615724,237.58118112461267,4.6631162412040155
1.3316019402587401e-06,0.06130426085217043,351.7509875218483,237.58118112461267,4.6631162412040155
1.3370246356233648e-06,0.061553910782156426,352.10845567246923,237.58118112461267,4.6631162412040155
1.3424473309879898e-06,0.061803560712142436,352.46535883960837,237.58118112461267,4.6631162412040155
1.3466186351146242e-06,0.06199559911982397,352.7395172733299,237.58118112461267,4.6631162412040155
1.3666408949224696e-06,0.06291738347669534,354.0508951009447,237.58118112461267,4.6631162412040155
1.386663154730315e-06,0.06383916783356672,355.3548010552768,237.58118112461267,4.6631162412040155
1.3920858500949396e-06,0.06408881776355271,355.70667600539815,237.58118112461267,4.6631162412040155
1.3970914150469009e-06,0.06431926385277055,356.0310094770203,237.58118112461267,4.6631162412040155
1.4133595011407752e-06,0.06506821364272855,357.08197716448944,237.58118112461267,4.6631162412040155
1.4333817609486206e-06,0.06598999799959993,358.36902160715863,237.58118112461267,4.6631162412040155
1.4383873259005819e-06,0.06622044408881776,358.6896848185828,237.58118112461267,4.6631162412040155
1.4475641949791778e-06,0.06664292858571715,359.2764393321906,237.58118112461267,4.6631162412040155
1.4554896728197831e-06,0.06700780156031207,359.78201537965873,237.58118112461267,4.6631162412040155
1.4613294985970714e-06,0.06727665533106622,360.1538583447404,237.58118112461267,4.6631162412040155
1.4700892372630037e-06,0.06767993598719745,360.71053801812786,237.58118112461267,4.6631162412040155
1.483437410468234e-06,0.06829445889177836,361.5563306842253,237.58118112461267,4.6631162412040155
1.4967855836734642e-06,0.06890898179635928,362.3991603867422,237.58118112461267,4.6631162412040155
1.5017911486254252e-06,0.06913942788557711,362.7144651445648,237.58118112461267,4.6631162412040155
1.5076309744027137e-06,0.06940828165633127,363.08180314242617,237.58118112461267,4.6631162412040155
1.5172249738939727e-06,0.0698499699939988,363.6840845859022,237.58118112461267,4.6631162412040155
1.5259847125599054e-06,0.07025325065013004,364.23269780930957,237.58118112461267,4.6631162412040155
1.5284874950358857e-06,0.07036847369473895,364.3892186785582,237.58118112461267,4.6631162412040155
1.541001407415789e-06,0.07094458891778356,365.1703287262379,237.58118112461267,4.6631162412040155
1.562275058461625e-06,0.0719239847969594,366.49256212020293,237.58118112461267,4.6631162412040155
1.5676977538262496e-06,0.0721736347269454,366.82847660669455,237.58118112461267,4.6631162412040155
1.5760403620795185e-06,0.07255771154230847,367.34438462180407,237.58118112461267,4.6631162412040155
1.5889714048720852e-06,0.07315303060612123,368.1419422152917,237.58118112461267,4.6631162412040155
1.597314013125354e-06,0.0735371074214843,368.6551524689738,237.58118112461267,4.6631162412040155
1.609410795092594e-06,0.07409401880376075,369.39745438286093,237.58118112461267,4.6631162412040155
1.614833490457219e-06,0.07434366873374676,369.72950374547827,237.58118112461267,4.6631162412040155
1.6256788811864683e-06,0.07484296859371875,370.392300746294,237.58118112461267,4.6631162412040155
1.6285987940751124e-06,0.07497739547909582,370.57045116962183,237.58118112461267,4.6631162412040155
1.6327700982017467e-06,0.07516943388677735,370.8247358388293,237.58118112461267,4.6631162412040155
1.6665576616274857e-06,0.0767249449889978,372.8751863321374,237.58118112461267,4.6631162412040155
1.6749002698807549e-06,0.07710902180436088,373.3789667529971,237.58118112461267,4.6631162412040155
1.6878313126733216e-06,0.07770434086817364,374.15789669560434,237.58118112461267,4.6631162412040155
1.6928368776252826e-06,0.07793478695739148,374.4587927011369,237.58118112461267,4.6631162412040155
1.700345225053225e-06,0.07828045609121825,374.9094869182091,237.58118112461267,4.6631162412040155
1.7157790503217723e-06,0.07899099819963994,375.8334837471363,237.58118112461267,4.6631162412040155
1.7228702673370506e-06,0.07931746349269854,376.25693546186574,237.58118112461267,4.6631162412040155
1.74456104879555e-06,0.08031606321264254,377.54799982829996,237.58118112461267,4.6631162412040155
1.7508180049855014e-06,0.08060412082416483,377.9192568698687,237.58118112461267,4.6631162412040155
1.7574920915881165e-06,0.0809113822764553,378.3146945037392,237.58118112461267,4.6631162412040155
1.7637490477780685e-06,0.0811994398879776,378.6848857265898,237.58118112461267,4.6631162412040155
1.7679203519047028e-06,0.08139147829565914,378.9313953748228,237.58118112461267,4.6631162412040155
1.7695888735553565e-06,0.08146829365873175,379.0299357081889,237.58118112461267,4.6631162412040155
1.7725087864440008e-06,0.08160272054410883,379.2022941436855,237.58118112461267,4.6631162412040155
1.7837713075859138e-06,0.08212122424484898,379.8660705591716,237.58118112461267,4.6631162412040155
1.7850226988239039e-06,0.08217883576715343,379.93972246102686,237.58118112461267,4.6631162412040155
1.7862740900618942e-06,0.08223644728945789,380.01335422848587,237.58118112461267,4.6631162412040155
1.7921139158391824e-06,0.08250530106021205,380.3567034969608,237.58118112461267,4.6631162412040155
1.8021250457431052e-06,0.08296619323864773,380.9442887943646,237.58118112461267,4.6631162412040155
1.8058792194570762e-06,0.08313902780556112,381.1643049080822,237.58118112461267,4.6631162412040155
1.8188102622496429e-06,0.08373434686937388,381.9207765672513,237.58118112461267,4.6631162412040155
1.8246500880269313e-06,0.08400320064012803,382.2617211086177,237.58118112461267,4.6631162412040155
1.826318609677585e-06,0.08408001600320064,382.3590556351342,237.58118112461267,4.6631162412040155
1.8279871313282387e-06,0.08415683136627326,382.45635548720463,237.58118112461267,4.6631162412040155
1.8442552174221129e-06,0.08490578115623125,383.4032208726531,237.58118112461267,4.6631162412040155
1.8500950431994013e-06,0.0851746349269854,383.74232601119616,237.58118112461267,4.6631162412040155
1.8567691298020164e-06,0.08548189637927586,384.1293639972572,237.58118112461267,4.6631162412040155
1.8680316509439295e-06,0.08600040008001601,384.781262550616,237.58118112461267,4.6631162412040155
1.8701173030072467e-06,0.08609641928385678,384.90181610657515,237.58118112461267,4.6631162412040155
1.8784599112605152e-06,0.08648049609921984,385.38350690918315,237.58118112461267,4.6631162412040155
1.887636780339111e-06,0.08690298059611923,385.91240417978037,237.58118112461267,4.6631162412040155
1.904321996845649e-06,0.08767113422684537,386.8714735649088,237.58118112461267,4.6631162412040155
1.9210072133521867e-06,0.08843928785757152,387.82727126922714,237.58118112461267,4.6631162412040155
1.928098430367465e-06,0.08876575315063014,388.23250426873653,237.58118112461267,4.6631162412040155
1.9335211257320902e-06,0.08901540308061613,388.54199625927095,237.58118112461267,4.6631162412040155
1.936441038620734e-06,0.0891498299659932,388.70850557101363,237.58118112461267,4.6631162412040155
1.9506234726512913e-06,0.08980276055211042,389.51587637651204,237.58118112461267,4.6631162412040155
1.963554515443858e-06,0.0903980796159232,390.2500155244643,237.58118112461267,4.6631162412040155
1.973982775760444e-06,0.09087817563512703,390.84069073192313,237.58118112461267,4.6631162412040155
1.989833731441655e-06,0.09160792158431687,391.7361916315883,237.58118112461267,4.6631162412040155
1.9965078180442702e-06,0.09191518303660733,392.11241183937864,237.58118112461267,4.6631162412040155
2.0035990350595487e-06,0.09224164832966594,392.51160878282224,237.58118112461267,4.6631162412040155
2.0061018175355292e-06,0.09235687137427485,392.65237021600075,237.58118112461267,4.6631162412040155
2.010690252074827e-06,0.09256811362272455,392.9102550920873,237.58118112461267,4.6631162412040155
2.0156958170267887e-06,0.0927985597119424,393.19132242893613,237.58118112461267,4.6631162412040155
2.02195277321674e-06,0.0930866173234647,393.54227410024026,237.58118112461267,4.6631162412040155
2.024872686105384e-06,0.09322104420884177,393.7059065753229,237.58118112461267,4.6631162412040155
2.0273754685813647e-06,0.09333626725345069,393.8460897516501,237.58118112461267,4.6631162412040155
2.030295381470009e-06,0.09347069413882778,394.00955151750264,237.58118112461267,4.6631162412040155
2.0353009464219703e-06,0.09370114022804561,394.2895585439989,237.58118112461267,4.6631162412040155
2.049066250039864e-06,0.09433486697339469,395.0581964625389,237.58118112461267,4.6631162412040155
2.063248684070421e-06,0.09498779755951191,395.8480231143285,237.58118112461267,4.6631162412040155
2.07284268356168e-06,0.09542948589717944,396.381117345137,237.58118112461267,4.6631162412040155
2.0761797268629877e-06,0.09558311662332467,396.5663157499844,237.58118112461267,4.6631162412040155
2.08493946552892e-06,0.09598639727945589,397.0519100625811,237.58118112461267,4.6631162412040155
2.086607987179574e-06,0.09606321264252851,397.14431393631025,237.58118112461267,4.6631162412040155
2.0886936392428913e-06,0.09615923184636928,397.259778264909,237.58118112461267,4.6631162412040155
2.1091330294634e-06,0.09710022004400881,398.38895920306004,237.58118112461267,4.6631162412040155
2.1153899856533518e-06,0.09738827765553111,398.73377260198515,237.58118112461267,4.6631162412040155
2.116641376891342e-06,0.09744588917783557,398.80268752569094,237.58118112461267,4.6631162412040155
2.126235376382601e-06,0.0978875775155031,399.33050839536963,237.58118112461267,4.6631162412040155
2.1479261578411005e-06,0.0988861772354471,400.5204306161313,237.58118112461267,4.6631162412040155
2.1529317227930615e-06,0.09911662332466493,400.7943614358919,237.58118112461267,4.6631162412040155
2.1612743310463307e-06,0.09950070014002801,401.2503614765945,237.58118112461267,4.6631162412040155
2.1662798959982918e-06,0.09973114622924585,401.523632007202,237.58118112461267,4.6631162412040155
2.167531287236282e-06,0.09978875775155031,401.5919111479656,237.58118112461267,4.6631162412040155
2.1696169392995995e-06,0.09988477695539108,401.70567556190286,237.58118112461267,4.6631162412040155
2.17211972177558e-06,0.1,401.8421365747799,237.58118112461267,4.6631162412040155