File: datasets/aisi_316_L/data/M1/train_53.csv
Time(s),Strain(%),Stress(MPa),Temp(C),Log_SR(s-1)
0.0,0.0,0.0,105.21849682456647,-0.8756267250221903
0.0001381797962699878,1.84e-05,3.5464174375,105.21849682456647,-0.8756267250221903
0.00022829705470693635,3.04e-05,5.859298375,105.21849682456647,-0.8756267250221903
0.00031240649591475494,4.1599999999999995e-05,8.01798725,105.21849682456647,-0.8756267250221903
0.0003484533992895344,4.6399999999999996e-05,8.943139624999999,105.21849682456647,-0.8756267250221903
0.0004565941094138727,6.08e-05,11.71859675,105.21849682456647,-0.8756267250221903
0.0006007817229129903,7.999999999999999e-05,15.419206249999998,105.21849682456647,-0.8756267250221903
0.0006428364435168997,8.56e-05,16.4985506875,105.21849682456647,-0.8756267250221903
0.0006969067985790688,9.279999999999999e-05,17.886279249999998,105.21849682456647,-0.8756267250221903
0.0007269458847247183,9.68e-05,18.6572395625,105.21849682456647,-0.8756267250221903
0.000811055325932537,0.000108,20.8159284375,105.21849682456647,-0.8756267250221903
0.0008651256809947062,0.0001152,22.203657,105.21849682456647,-0.8756267250221903
0.0009492351222025247,0.00012639999999999998,24.362345874999995,105.21849682456647,-0.8756267250221903
0.0011655165424512015,0.0001552,29.913260125,105.21849682456647,-0.8756267250221903
0.0012676494353464096,0.00016879999999999998,32.534525187499995,105.21849682456647,-0.8756267250221903
0.0013878057799290076,0.0001848,35.6183664375,105.21849682456647,-0.8756267250221903
0.0015680402968029047,0.00020879999999999998,40.244128312499996,105.21849682456647,-0.8756267250221903
0.001676181006927243,0.00022319999999999998,43.0195854375,105.21849682456647,-0.8756267250221903
0.001802345168738971,0.00023999999999999998,46.25761875,105.21849682456647,-0.8756267250221903
0.0018323842548846206,0.000244,47.0285790625,105.21849682456647,-0.8756267250221903
0.001994595320071128,0.0002656,51.191764750000004,105.21849682456647,-0.8756267250221903
0.0021568063852576355,0.0002872,55.354950437499994,105.21849682456647,-0.8756267250221903
0.002300993998756753,0.00030639999999999997,59.05555993749999,105.21849682456647,-0.8756267250221903
0.0025052597845471695,0.0003336,64.2980900625,105.21849682456647,-0.8756267250221903
0.0028176662804619244,0.00037519999999999996,72.31607731249998,105.21849682456647,-0.8756267250221903
0.0029438304422736527,0.000392,75.55411062499999,105.21849682456647,-0.8756267250221903
0.003009916431794082,0.0004008,77.2502233125,105.21849682456647,-0.8756267250221903
0.003039955517939731,0.0004048,78.02118362499999,105.21849682456647,-0.8756267250221903
0.0031661196797514593,0.0004216,81.2592169375,105.21849682456647,-0.8756267250221903
0.0034004245516875255,0.0004528,87.272707375,105.21849682456647,-0.8756267250221903
0.003562635616874033,0.0004744,91.4358930625,105.21849682456647,-0.8756267250221903
0.0036467450580818517,0.0004856,93.5945819375,105.21849682456647,-0.8756267250221903
0.003682791961456631,0.0004904,94.51973431249999,105.21849682456647,-0.8756267250221903
0.0038450030266431383,0.000512,98.68292,105.21849682456647,-0.8756267250221903
0.004013221909058775,0.0005344,103.00029775,105.21849682456647,-0.8756267250221903
0.004175432974245283,0.000556,107.16348343749999,105.21849682456647,-0.8756267250221903
0.004205472060390933,0.00056,107.93444374999999,105.21849682456647,-0.8756267250221903
0.004319620587744401,0.0005752,110.8640929375,105.21849682456647,-0.8756267250221903
0.0043796987600357,0.0005832,112.4060135625,105.21849682456647,-0.8756267250221903
0.004571948911367856,0.0006087999999999999,117.34015956249999,105.21849682456647,-0.8756267250221903
0.0046440427181174155,0.0006184,119.1904643125,105.21849682456647,-0.8756267250221903
0.004716136524866975,0.000628,121.04076906249999,105.21849682456647,-0.8756267250221903
0.004872339772824351,0.0006487999999999999,125.04976268749999,105.21849682456647,-0.8756267250221903
0.00498648830017782,0.000664,127.979411875,105.21849682456647,-0.8756267250221903
0.005100636827531288,0.0006791999999999999,130.90906106249997,105.21849682456647,-0.8756267250221903
0.0052027697204264966,0.0006927999999999999,133.530326125,105.21849682456647,-0.8756267250221903
0.005316918247779964,0.000708,136.4599753125,105.21849682456647,-0.8756267250221903
0.005647348195382109,0.000752,144.94053875,105.21849682456647,-0.8756267250221903
0.0060739032186503325,0.0008087999999999999,155.8881751875,105.21849682456647,-0.8756267250221903
0.00617603611154554,0.0008223999999999999,158.50944024999998,105.21849682456647,-0.8756267250221903
0.006278169004440749,0.0008359999999999999,161.1307053125,105.21849682456647,-0.8756267250221903
0.006320223725044659,0.0008416,162.21004975,105.21849682456647,-0.8756267250221903
0.0064103409834816065,0.0008535999999999999,164.52293068749998,105.21849682456647,-0.8756267250221903
0.006494450424689426,0.0008648,166.6816195625,105.21849682456647,-0.8756267250221903
0.006560536414209855,0.0008736,168.37773225,105.21849682456647,-0.8756267250221903
0.006776817834458531,0.0009023999999999999,173.92864649999999,105.21849682456647,-0.8756267250221903
0.007023138340852857,0.0009352,180.25052106249998,105.21849682456647,-0.8756267250221903
0.007245427578330663,0.0009647999999999999,185.95562737499998,105.21849682456647,-0.8756267250221903
0.0073775995573715225,0.0009824,189.34785275000002,105.21849682456647,-0.8756267250221903
0.007431669912433691,0.0009896,190.7355813125,105.21849682456647,-0.8756267250221903
0.007527794988099769,0.0010023999999999999,193.2026543125,105.21849682456647,-0.8756267250221903
0.007647951332682368,0.0010184,196.2864955625,105.21849682456647,-0.8756267250221903
0.007720045139431927,0.001028,198.13680031250001,105.21849682456647,-0.8756267250221903
0.007810162397868874,0.00104,200.44968124999997,105.21849682456647,-0.8756267250221903
0.008038459452575811,0.0010704,206.308979625,105.21849682456647,-0.8756267250221903
0.008278772141741006,0.0011024,212.476662125,105.21849682456647,-0.8756267250221903
0.008350865948490566,0.001112,214.32696687499998,105.21849682456647,-0.8756267250221903
0.008416951938010994,0.0011208,216.0230795625,105.21849682456647,-0.8756267250221903
0.00860920208934315,0.0011464,220.95722556249999,105.21849682456647,-0.8756267250221903
0.0086993193477801,0.0011584,223.2701065,105.21849682456647,-0.8756267250221903
0.00873536625115488,0.0011631999999999999,224.19525887499998,105.21849682456647,-0.8756267250221903
0.009005718026465725,0.0011991999999999999,231.13390168749999,105.21849682456647,-0.8756267250221903
0.009095835284902674,0.0012112,233.446782625,105.21849682456647,-0.8756267250221903
0.009185952543339624,0.0012232,235.7596635625,105.21849682456647,-0.8756267250221903
0.009252038532860052,0.001232,237.45577625,105.21849682456647,-0.8756267250221903
0.00943227304973395,0.001256,242.08153812499998,105.21849682456647,-0.8756267250221903
0.009552429394316546,0.001272,242.85905087626728,105.21849682456647,-0.8756267250221903
0.009726656093961315,0.0012952,243.02386241435553,105.21849682456647,-0.8756267250221903
0.00991289842806434,0.00132,243.19877215792332,105.21849682456647,-0.8756267250221903
0.00994894533143912,0.0013248,243.2324771219497,105.21849682456647,-0.8756267250221903
0.010075109493250849,0.0013415999999999999,243.35007126176095,105.21849682456647,-0.8756267250221903
0.010153211117229537,0.001352,243.42257989541235,105.21849682456647,-0.8756267250221903
0.010297398730728654,0.0013712,243.55587305627142,105.21849682456647,-0.8756267250221903
0.010357476903019953,0.0013792,243.61119681023794,105.21849682456647,-0.8756267250221903
0.010405539440852993,0.0013855999999999999,243.65536575671973,105.21849682456647,-0.8756267250221903
0.010459609795915164,0.0013928,243.7049608266514,105.21849682456647,-0.8756267250221903
0.01058577395772689,0.0014096,243.8202954365129,105.21849682456647,-0.8756267250221903
0.010597789592185151,0.0014112,243.83125165054506,105.21849682456647,-0.8756267250221903
0.01064585213001819,0.0014176,243.87502814765185,105.21849682456647,-0.8756267250221903
0.010820078829662957,0.0014408,244.0330758934819,105.21849682456647,-0.8756267250221903
0.011024344615453372,0.001468,244.2171147967829,105.21849682456647,-0.8756267250221903
0.011276672939076828,0.0015015999999999999,244.44263102857028,105.21849682456647,-0.8756267250221903
0.011384813649201167,0.001516,244.538677417526,105.21849682456647,-0.8756267250221903
0.011510977811012896,0.0015328,244.65028299416173,105.21849682456647,-0.8756267250221903
0.011619118521137234,0.0015471999999999999,244.74556574301963,105.21849682456647,-0.8756267250221903
0.011667181058970274,0.0015536,244.78780255049088,105.21849682456647,-0.8756267250221903
0.011697220145115922,0.0015576,244.8141660993279,105.21849682456647,-0.8756267250221903
0.01185943121030243,0.0015792,244.95607559472566,105.21849682456647,-0.8756267250221903
0.011949548468739378,0.0015911999999999999,245.0345870509175,105.21849682456647,-0.8756267250221903
0.011967571920426768,0.0015936,245.05026159534947,105.21849682456647,-0.8756267250221903
0.011991603189343288,0.0015968,245.07114667433018,105.21849682456647,-0.8756267250221903
0.012069704813321976,0.0016072,245.1389107287083,105.21849682456647,-0.8756267250221903
0.012261954964654135,0.0016328,245.30499005272392,105.21849682456647,-0.8756267250221903
0.012304009685258042,0.0016384,245.3411841776803,105.21849682456647,-0.8756267250221903
0.012328040954174562,0.0016416,245.36184487256256,105.21849682456647,-0.8756267250221903
0.01253230673996498,0.0016688,245.53683110314105,105.21849682456647,-0.8756267250221903
0.012580369277798018,0.0016752,245.5778422562359,105.21849682456647,-0.8756267250221903
0.012610408363943667,0.0016791999999999998,245.60344319927455,105.21849682456647,-0.8756267250221903
0.012808666332504954,0.0017055999999999998,245.7718168570133,105.21849682456647,-0.8756267250221903
0.012868744504796255,0.0017136,245.8226381081388,105.21849682456647,-0.8756267250221903
0.013211190086856657,0.0017591999999999998,246.1105716134368,105.21849682456647,-0.8756267250221903
0.013385416786501425,0.0017824,246.25594589038226,105.21849682456647,-0.8756267250221903
0.013421463689876205,0.0017871999999999999,246.28593098269042,105.21849682456647,-0.8756267250221903
0.01365576856181227,0.0018184,246.48007409927325,105.21849682456647,-0.8756267250221903
0.013854026530373558,0.0018448,246.64333644287927,105.21849682456647,-0.8756267250221903
0.013920112519893987,0.0018536,246.69755440482243,105.21849682456647,-0.8756267250221903
0.014094339219538753,0.0018767999999999999,246.8400136382528,105.21849682456647,-0.8756267250221903
0.01432263627424569,0.0019072,247.02564907487948,105.21849682456647,-0.8756267250221903
0.014478839522203068,0.0019279999999999998,247.15199838357552,105.21849682456647,-0.8756267250221903
0.014611011501243927,0.0019456,247.25849466024454,105.21849682456647,-0.8756267250221903
0.014737175663055654,0.0019624,247.35980025669468,105.21849682456647,-0.8756267250221903
0.01492341799715868,0.0019871999999999997,247.50873061036165,105.21849682456647,-0.8756267250221903
0.015049582158970407,0.0020039999999999997,247.60920730111746,105.21849682456647,-0.8756267250221903
0.015193769772469525,0.0020231999999999997,247.72363642709257,105.21849682456647,-0.8756267250221903
0.015434082461634724,0.0020552,247.91341495450664,105.21849682456647,-0.8756267250221903
0.015740481140320346,0.0020959999999999998,248.15371947166085,105.21849682456647,-0.8756267250221903
0.015770520226465995,0.0021,248.1771801139325,105.21849682456647,-0.8756267250221903
0.015962770377798155,0.0021256,248.3269176364594,105.21849682456647,-0.8756267250221903
0.01611897362575553,0.0021463999999999997,248.44806216035167,105.21849682456647,-0.8756267250221903
0.01617905179804683,0.0021544,248.4945341882164,105.21849682456647,-0.8756267250221903
0.016209090884192482,0.0021584,248.5177449608944,105.21849682456647,-0.8756267250221903
0.01626316123925465,0.0021655999999999997,248.55948212101012,105.21849682456647,-0.8756267250221903
0.016275176873712906,0.0021671999999999998,248.5687496920726,105.21849682456647,-0.8756267250221903
0.01631723159431682,0.0021728,248.60116519807528,105.21849682456647,-0.8756267250221903
0.01635928631492073,0.0021784,248.63354813780848,105.21849682456647,-0.8756267250221903
0.016617622455773313,0.0022128,248.83176431825538,105.21849682456647,-0.8756267250221903
0.01671975534866852,0.0022264,248.90979693063795,105.21849682456647,-0.8756267250221903
0.01677983352095982,0.0022344,248.95561163066338,105.21849682456647,-0.8756267250221903
0.016996114941208496,0.0022632,249.1200174860785,105.21849682456647,-0.8756267250221903
0.017044177479041536,0.0022696,249.156441080578,105.21849682456647,-0.8756267250221903
0.017128286920249355,0.0022808,249.22008613082625,105.21849682456647,-0.8756267250221903
0.017242435447602823,0.002296,249.30626694122307,105.21849682456647,-0.8756267250221903
0.01732654488881064,0.0023071999999999997,249.36962627807003,105.21849682456647,-0.8756267250221903
0.01745270905062237,0.002324,249.4644408363875,105.21849682456647,-0.8756267250221903
0.017614920115808876,0.0023455999999999998,249.5859534110184,105.21849682456647,-0.8756267250221903
0.017741084277620604,0.0023623999999999997,249.68016173373695,105.21849682456647,-0.8756267250221903
0.017837209353286684,0.0023752,249.75176423463722,105.21849682456647,-0.8756267250221903
0.01805949859076449,0.0024048,249.91677111118906,105.21849682456647,-0.8756267250221903
0.01814961584920144,0.0024167999999999998,249.98343991100634,105.21849682456647,-0.8756267250221903
0.01823973310763839,0.0024288,250.04997973465177,105.21849682456647,-0.8756267250221903
0.018329850366075335,0.0024408,250.11639146703513,105.21849682456647,-0.8756267250221903
0.018371905086679248,0.0024464,250.1473400195982,105.21849682456647,-0.8756267250221903
0.018492061431261843,0.0024624,250.2356125802916,105.21849682456647,-0.8756267250221903
0.018528108334636622,0.0024671999999999997,250.2620506915853,105.21849682456647,-0.8756267250221903
0.01861822559307357,0.0024792,250.32805835862018,105.21849682456647,-0.8756267250221903
0.01875039757211443,0.0024968,250.42464465676113,105.21849682456647,-0.8756267250221903
0.019044780616341794,0.002536,250.63881946309505,105.21849682456647,-0.8756267250221903
0.019128890057549613,0.0025472,250.69977461439643,105.21849682456647,-0.8756267250221903
0.019375210563943937,0.00258,250.87768768538598,105.21849682456647,-0.8756267250221903
0.01941726528454785,0.0025856,250.90797471477384,105.21849682456647,-0.8756267250221903
0.01944129655346437,0.0025888,250.92527010246218,105.21849682456647,-0.8756267250221903
0.01959149198419262,0.0026088,251.0331779851562,105.21849682456647,-0.8756267250221903
0.019651570156483913,0.0026168,251.0762507433324,105.21849682456647,-0.8756267250221903
0.01989789066287824,0.0026496,251.2523147881159,105.21849682456647,-0.8756267250221903
0.020066109545293878,0.002672,251.3720654582059,105.21849682456647,-0.8756267250221903
0.020234328427709516,0.0026944,251.4914252420114,105.21849682456647,-0.8756267250221903
0.020360492589521245,0.0027112,251.58069127702782,105.21849682456647,-0.8756267250221903
0.02069693035435252,0.0027559999999999998,251.8176856427682,105.21849682456647,-0.8756267250221903
0.020763016343872946,0.0027648,251.8640610454533,105.21849682456647,-0.8756267250221903
0.020871157053997284,0.0027792,251.93982408813875,105.21849682456647,-0.8756267250221903
0.02115352446376639,0.0028168,252.1369315286745,105.21849682456647,-0.8756267250221903
0.02116554009822465,0.0028184,252.14529624183513,105.21849682456647,-0.8756267250221903
0.021261665173890727,0.0028312,252.21214740613064,105.21849682456647,-0.8756267250221903
0.021381821518473326,0.0028472,252.2955458349152,105.21849682456647,-0.8756267250221903
0.021477946594139406,0.0028599999999999997,252.36213305261793,105.21849682456647,-0.8756267250221903
0.021544032583659833,0.0028688,252.40784436019564,105.21849682456647,-0.8756267250221903
0.021718259283304602,0.002892,252.52809462393245,105.21849682456647,-0.8756267250221903
0.02179035309005416,0.0029016,252.57774323806547,105.21849682456647,-0.8756267250221903
0.021898493800178498,0.0029159999999999998,252.65209621058662,105.21849682456647,-0.8756267250221903
0.022048689230906745,0.002936,252.75512710681963,105.21849682456647,-0.8756267250221903
0.022096751768739785,0.0029424,252.78803913645808,105.21849682456647,-0.8756267250221903
0.02233105664067585,0.0029736,252.9480871942805,105.21849682456647,-0.8756267250221903
0.02244520516802932,0.0029888,253.02582196433195,105.21849682456647,-0.8756267250221903
0.02248725988863323,0.0029944,253.05442220554434,105.21849682456647,-0.8756267250221903
0.02263144750213235,0.0030136,253.15232219984887,105.21849682456647,-0.8756267250221903
0.02287176019129754,0.0030456,253.31495001145316,105.21849682456647,-0.8756267250221903
0.022913814911901455,0.0030512,253.3433412283544,105.21849682456647,-0.8756267250221903
0.02293784618081797,0.0030543999999999997,253.3595556566528,105.21849682456647,-0.8756267250221903
0.02303397125648405,0.0030672,253.42434722890627,105.21849682456647,-0.8756267250221903
0.023154127601066648,0.0030832,253.50518859515094,105.21849682456647,-0.8756267250221903
0.02319618232167056,0.0030888,253.53344439847532,105.21849682456647,-0.8756267250221903
0.0233043230317949,0.0031032,253.60601059191762,105.21849682456647,-0.8756267250221903
0.023340369935169674,0.0031079999999999997,253.63017012395719,105.21849682456647,-0.8756267250221903
0.023526612269272704,0.0031328,253.7547633137444,105.21849682456647,-0.8756267250221903
0.02362273734493878,0.0031455999999999997,253.81891893834032,105.21849682456647,-0.8756267250221903
0.023814987496270937,0.0031712,253.9469255605825,105.21849682456647,-0.8756267250221903
0.023905104754707886,0.0031831999999999997,254.0067898758147,105.21849682456647,-0.8756267250221903
0.024109370540498304,0.0032104,254.14215743287653,105.21849682456647,-0.8756267250221903
0.02416344089556047,0.0032175999999999997,254.17791505779914,105.21849682456647,-0.8756267250221903
0.02429561287460133,0.0032351999999999997,254.2651914665013,105.21849682456647,-0.8756267250221903
0.02438573013303828,0.0032472,254.3245919685837,105.21849682456647,-0.8756267250221903
0.024487863025933487,0.0032608,254.39180914186707,105.21849682456647,-0.8756267250221903
0.024577980284370436,0.0032727999999999998,254.45102766800866,105.21849682456647,-0.8756267250221903
0.02488437896305606,0.0033136,254.65174025856615,105.21849682456647,-0.8756267250221903
0.02495647276980562,0.0033231999999999997,254.69882640162228,105.21849682456647,-0.8756267250221903
0.025076629114388217,0.0033391999999999996,254.777185592347,105.21849682456647,-0.8756267250221903
0.025232832362345595,0.0033599999999999997,254.87883397495676,105.21849682456647,-0.8756267250221903
0.02541907469644862,0.0033848,254.99970994685248,105.21849682456647,-0.8756267250221903
0.025461129417052534,0.0033904,255.0269566609408,105.21849682456647,-0.8756267250221903
0.02552120758934383,0.0033983999999999998,255.06585011137523,105.21849682456647,-0.8756267250221903
0.02562334048223904,0.0034119999999999997,255.13188712884835,105.21849682456647,-0.8756267250221903
0.025647371751155557,0.0034151999999999997,255.1474103223252,105.21849682456647,-0.8756267250221903
0.02573148119236338,0.0034264,255.20169688457494,105.21849682456647,-0.8756267250221903
0.025815590633571195,0.0034376,255.25591428586023,105.21849682456647,-0.8756267250221903
0.025947762612612054,0.0034552,255.34097407797336,105.21849682456647,-0.8756267250221903
0.025971793881528572,0.0034584,255.3564213230582,105.21849682456647,-0.8756267250221903
0.025983809515986833,0.00346,255.36414285516673,105.21849682456647,-0.8756267250221903
0.026067918957194652,0.0034712,255.41815464195938,105.21849682456647,-0.8756267250221903
0.026127997129485953,0.0034792,255.4566928861941,105.21849682456647,-0.8756267250221903
0.02627218474298507,0.0034984,255.54904394228407,105.21849682456647,-0.8756267250221903
0.0263983489047968,0.0035152,255.62968908723374,105.21849682456647,-0.8756267250221903
0.026602614690587213,0.0035424,255.75993945209984,105.21849682456647,-0.8756267250221903
0.026674708497336774,0.003552,255.80581696864238,105.21849682456647,-0.8756267250221903
0.02672277103516981,0.0035583999999999998,255.83637511737692,105.21849682456647,-0.8756267250221903
0.02683691956252328,0.0035735999999999997,255.90886494268835,105.21849682456647,-0.8756267250221903
0.027209404230729334,0.0036232,256.1445786663321,105.21849682456647,-0.8756267250221903
0.027293513671937154,0.0036344,256.1976297845498,105.21849682456647,-0.8756267250221903
0.02746774037158192,0.0036576,256.3073189903852,105.21849682456647,-0.8756267250221903
0.02750979509218583,0.0036631999999999997,256.33375500150714,105.21849682456647,-0.8756267250221903
0.02757588108170626,0.003672,256.375265483083,105.21849682456647,-0.8756267250221903
0.027684021791830597,0.0036864,256.443108136724,105.21849682456647,-0.8756267250221903
0.02810456899786969,0.0037424,256.7059640093883,105.21849682456647,-0.8756267250221903
0.028164647170160987,0.0037503999999999997,256.74338924338616,105.21849682456647,-0.8756267250221903
0.028188678439077505,0.0037535999999999997,256.758350617785,105.21849682456647,-0.8756267250221903
0.028260772245827067,0.0037632,256.8032049232571,105.21849682456647,-0.8756267250221903
0.028326858235347495,0.0037719999999999997,256.8442821833054,105.21849682456647,-0.8756267250221903
0.028537131838367043,0.0038,256.9747346030811,105.21849682456647,-0.8756267250221903
0.028627249096803992,0.003812,257.0305279644424,105.21849682456647,-0.8756267250221903
0.02879546797921963,0.0038344,257.13449264593476,105.21849682456647,-0.8756267250221903
0.028999733765010045,0.0038615999999999998,257.2604175789797,105.21849682456647,-0.8756267250221903
0.029216015185258723,0.0038904,257.3933734038682,105.21849682456647,-0.8756267250221903
0.029348187164299582,0.003908,257.4744352382238,105.21849682456647,-0.8756267250221903
0.029552452950089996,0.0039352,257.5994331335256,105.21849682456647,-0.8756267250221903
0.029618538939610424,0.003944,257.6398014278876,105.21849682456647,-0.8756267250221903
0.029858851628775617,0.0039759999999999995,257.7863000383815,105.21849682456647,-0.8756267250221903
0.02997900797335822,0.003992,257.8593768535054,105.21849682456647,-0.8756267250221903
0.03000303924227474,0.0039952,257.87397849946075,105.21849682456647,-0.8756267250221903
0.030904384886392376,0.004115223044608922,258.41839586860425,105.21849682456647,-0.8756267250221903
0.03825942418270664,0.005094618923784757,262.6502548145659,105.21849682456647,-0.8756267250221903
0.04229748497283996,0.005632326465293058,264.83773864616893,105.21849682456647,-0.8756267250221903
0.048354576158039946,0.006438887777555511,267.97185909513206,105.21849682456647,-0.8756267250221903
0.048787225528411374,0.006496499299859972,268.18968115439407,105.21849682456647,-0.8756267250221903
0.053402152145706594,0.007111022204440888,270.468081539374,105.21849682456647,-0.8756267250221903
0.0551327496271923,0.007341468293658731,271.3025066727833,105.21849682456647,-0.8756267250221903
0.059026593960535154,0.00785997199439888,273.14348293999217,105.21849682456647,-0.8756267250221903
0.06364152057783037,0.008474494898979796,275.2651068961087,105.21849682456647,-0.8756267250221903
0.06566055097289704,0.008743348669733947,276.17434932195664,105.21849682456647,-0.8756267250221903
0.0712849927877256,0.009492298459691939,278.65145981115376,105.21849682456647,-0.8756267250221903
0.07344823963958273,0.009780356071214243,279.58374037458395,105.21849682456647,-0.8756267250221903
0.07532305357785891,0.01003000600120024,280.38308736975154,105.21849682456647,-0.8756267250221903
0.07690943460255416,0.01024124824964993,281.05341528866074,105.21849682456647,-0.8756267250221903
0.07878424854083033,0.010490898179635926,281.8387080272699,105.21849682456647,-0.8756267250221903
0.07979376373836367,0.010625325065013003,282.2585376691708,105.21849682456647,-0.8756267250221903
0.08123592830626843,0.01081736347269454,282.8547185557068,105.21849682456647,-0.8756267250221903
0.08873518405937317,0.011815963192638527,285.89071816652057,105.21849682456647,-0.8756267250221903
0.09003313217048745,0.01198879775955191,286.40585130637027,105.21849682456647,-0.8756267250221903
0.09262902839271601,0.012334466893378675,287.42750969865597,105.21849682456647,-0.8756267250221903
0.09320589421987792,0.01241128225645129,287.6530213248781,105.21849682456647,-0.8756267250221903
0.10142623225693503,0.013505901180236047,290.8096206236738,105.21849682456647,-0.8756267250221903
0.10517586013348741,0.014005201040208042,292.21616021625596,105.21849682456647,-0.8756267250221903
0.10719489052855406,0.014274054810962193,292.9654207805205,105.21849682456647,-0.8756267250221903
0.11267511588659215,0.015003800760152031,294.9718852316336,105.21849682456647,-0.8756267250221903
0.11498257919523977,0.01531106221244249,295.80528260986745,105.21849682456647,-0.8756267250221903
0.11757847541746834,0.015656731346269256,296.73509685475585,105.21849682456647,-0.8756267250221903
0.11829955770142071,0.015752750550110023,296.9919533032914,105.21849682456647,-0.8756267250221903
0.12320291723229686,0.016405681136227243,298.7226617089521,105.21849682456647,-0.8756267250221903
0.12450086534341116,0.016578515703140628,299.1762669713463,105.21849682456647,-0.8756267250221903
0.12724097802243017,0.016943388677735545,300.12786573106484,105.21849682456647,-0.8756267250221903
0.12882735904712544,0.017154630926185237,300.6751382288742,105.21849682456647,-0.8756267250221903
0.13171168818293494,0.01753870774154831,301.66349247260297,105.21849682456647,-0.8756267250221903
0.13704769708418255,0.018249249849969992,303.46997431621617,105.21849682456647,-0.8756267250221903
0.13820142873850635,0.01840288057611522,303.8569340566314,105.21849682456647,-0.8756267250221903
0.13993202621999207,0.018633326665333065,304.435019763726,105.21849682456647,-0.8756267250221903
0.1403646755903635,0.018690938187637528,304.5791046936306,105.21849682456647,-0.8756267250221903
0.14108575787431588,0.018786957391478294,304.8188619382417,105.21849682456647,-0.8756267250221903
0.14238370598543015,0.01895979195839168,305.24922412788544,105.21849682456647,-0.8756267250221903
0.14397008701012537,0.019171034206841367,305.77315014998385,105.21849682456647,-0.8756267250221903
0.14642176677556348,0.01949749949989998,306.57844703175743,105.21849682456647,-0.8756267250221903
0.14728706551630633,0.019612722544508902,306.8614116825256,105.21849682456647,-0.8756267250221903
0.15002717819532538,0.01997759551910382,307.75321899944817,105.21849682456647,-0.8756267250221903
0.1559400529237349,0.02076495299059812,309.65628356080697,105.21849682456647,-0.8756267250221903
0.16516990615832533,0.021993998799759953,312.57159969682226,105.21849682456647,-0.8756267250221903
0.16560255552869677,0.022051610322064413,312.7066741144167,105.21849682456647,-0.8756267250221903
0.16675628718302057,0.02220524104820964,313.06620140631554,105.21849682456647,-0.8756267250221903
0.16877531757808723,0.022474094818963793,313.6930485391227,105.21849682456647,-0.8756267250221903
0.17339024419538246,0.02308861772354471,315.11496207174577,105.21849682456647,-0.8756267250221903
0.17569770750403008,0.023395879175835167,315.82037810786034,105.21849682456647,-0.8756267250221903
0.18074528349169672,0.024068013602720543,317.35100031176853,105.21849682456647,-0.8756267250221903
0.18593707593615383,0.024759351870374074,318.90806081125817,105.21849682456647,-0.8756267250221903
0.1953111456275348,0.026007601520304062,321.67713287432156,105.21849682456647,-0.8756267250221903
0.19646487728185857,0.02616123224644929,322.0143221792069,105.21849682456647,-0.8756267250221903
0.19776282539297285,0.026334066813362672,322.392738428621,105.21849682456647,-0.8756267250221903
0.19992607224483,0.02662212442488498,323.0212867841865,105.21849682456647,-0.8756267250221903
0.20208931909668712,0.02691018203640728,323.647188261056,105.21849682456647,-0.8756267250221903
0.20266618492384902,0.026986997399479896,323.81365333188523,105.21849682456647,-0.8756267250221903
0.20338726720780143,0.027083016603320666,324.02147503703225,105.21849682456647,-0.8756267250221903
0.20699267862756332,0.027563112622524505,325.05630423342683,105.21849682456647,-0.8756267250221903
0.20958857484979188,0.02790878175635127,325.7970332601378,105.21849682456647,-0.8756267250221903
0.21232868752881093,0.02827365473094619,326.57504264828856,105.21849682456647,-0.8756267250221903
0.2130497698127633,0.028369673934786958,326.7791299114369,105.21849682456647,-0.8756267250221903
0.2195395103683347,0.02923384676935387,328.6039498955643,105.21849682456647,-0.8756267250221903
0.22343335470167755,0.02975235047009402,329.6887455690039,105.21849682456647,-0.8756267250221903
0.22574081801032517,0.030059611922384478,330.3281085422176,105.21849682456647,-0.8756267250221903
0.22732719903502038,0.030270854170834166,330.76619281728017,105.21849682456647,-0.8756267250221903
0.23064417754120134,0.0307125425085017,331.6783531250058,105.21849682456647,-0.8756267250221903
0.23338429022022036,0.03107741548309662,332.4280242646255,105.21849682456647,-0.8756267250221903
0.24016246368937277,0.031979995999199845,334.2678750702157,105.21849682456647,-0.8756267250221903
0.2424699269980204,0.0322872574514903,334.88957194564745,105.21849682456647,-0.8756267250221903
0.2457869055042013,0.03272894578915783,335.7792339129,105.21849682456647,-0.8756267250221903
0.24910388401038225,0.03317063412682537,336.6642255575997,105.21849682456647,-0.8756267250221903
0.2516997802326108,0.03351630326065213,337.35362584755944,105.21849682456647,-0.8756267250221903
0.2531419448005156,0.03370834166833367,337.7354276746165,105.21849682456647,-0.8756267250221903
0.25516097519558223,0.033977195439087816,338.2685281447178,105.21849682456647,-0.8756267250221903
0.2573242220474394,0.03426525305061012,338.83788488674094,105.21849682456647,-0.8756267250221903
0.259631685356087,0.03457251450290058,339.44314509780145,105.21849682456647,-0.8756267250221903
0.26266023094868696,0.034975795159031806,340.23437492746274,105.21849682456647,-0.8756267250221903
0.2656887765412869,0.03537907581516303,341.02205464210516,105.21849682456647,-0.8756267250221903
0.26871732213388694,0.035782356471294255,341.8062403687537,105.21849682456647,-0.8756267250221903
0.2739091145783441,0.03647369473894779,343.14258646540776,105.21849682456647,-0.8756267250221903
0.2788124741092203,0.03712662532506501,344.39564894119184,105.21849682456647,-0.8756267250221903
0.28184101970182024,0.03752990598119624,345.1653069597999,105.21849682456647,-0.8756267250221903
0.28342740072651545,0.03774114822964593,345.5671735282938,105.21849682456647,-0.8756267250221903
0.2858790804919536,0.038067613522704546,346.18651888450796,105.21849682456647,-0.8756267250221903
0.28732124505985834,0.03825965193038608,346.54987206652436,105.21849682456647,-0.8756267250221903
0.2889076260845536,0.03847089417883577,346.9487400279256,105.21849682456647,-0.8756267250221903
0.2897729248252964,0.03858611722344468,347.1659443180445,105.21849682456647,-0.8756267250221903
0.2919361716771536,0.038874174834966996,347.70785129772287,105.21849682456647,-0.8756267250221903
0.29409941852901067,0.039162232446489295,348.2481944641693,105.21849682456647,-0.8756267250221903
0.29611844892407735,0.03943108621724345,348.7511179347055,105.21849682456647,-0.8756267250221903
0.2969837476648202,0.039546309261852375,348.96624697645353,105.21849682456647,-0.8756267250221903
0.2979932628623535,0.039680736147229445,349.216922140163,105.21849682456647,-0.8756267250221903
0.29943542743025825,0.03987277455491098,349.57445576002476,105.21849682456647,-0.8756267250221903
0.30260818947964874,0.04029525905181036,350.3586742797597,105.21849682456647,-0.8756267250221903
0.3065020338129916,0.04081376275255051,351.31675521353907,105.21849682456647,-0.8756267250221903
0.3073673325537345,0.04092898579715944,351.52901607860355,105.21849682456647,-0.8756267250221903
0.3095305794055916,0.041217043408681736,352.05865120541904,105.21849682456647,-0.8756267250221903
0.31212647562782014,0.0415627125425085,352.69231162094417,105.21849682456647,-0.8756267250221903
0.3134244237389345,0.041735547109421886,353.00837084552376,105.21849682456647,-0.8756267250221903
0.31587610350437256,0.0420620124024805,353.6039823615484,105.21849682456647,-0.8756267250221903
0.3189046490969726,0.04246529305861173,354.33725444627606,105.21849682456647,-0.8756267250221903
0.3215005453192011,0.04281096219243849,354.9636144044595,105.21849682456647,-0.8756267250221903
0.32640390485007725,0.04346389277855571,356.1413833945499,105.21849682456647,-0.8756267250221903
0.3294324504426772,0.043867173434686935,356.8653826471643,105.21849682456647,-0.8756267250221903
0.33202834666490577,0.0442128425685137,357.48388980942644,105.21849682456647,-0.8756267250221903
0.33361472768960104,0.04442408481696339,357.860938104716,105.21849682456647,-0.8756267250221903
0.3364990568254106,0.04480816163232647,358.54469389006766,105.21849682456647,-0.8756267250221903
0.3382296543068962,0.045038607721544305,358.95385028775115,105.21849682456647,-0.8756267250221903
0.34356566320814386,0.04574914982996599,360.210306299212,105.21849682456647,-0.8756267250221903
0.3444309619488867,0.04586437287457491,360.41333660974874,105.21849682456647,-0.8756267250221903
0.348757455652601,0.046440488097619526,361.4255195278823,105.21849682456647,-0.8756267250221903
0.35279551644273427,0.04697819563912782,362.36581419929365,105.21849682456647,-0.8756267250221903
0.35755465951682003,0.047611922384476896,363.46864695210155,105.21849682456647,-0.8756267250221903
0.358131525343982,0.04768873774754952,363.6019335295046,105.21849682456647,-0.8756267250221903
0.3597179063686771,0.047899979995999195,363.96804057993637,105.21849682456647,-0.8756267250221903
0.36274645196127714,0.04830326065213042,364.665228420884,105.21849682456647,-0.8756267250221903
0.36418861652918194,0.04849529905981197,364.9964244254608,105.21849682456647,-0.8756267250221903
0.36808246086252483,0.049013802760552116,365.88810861564684,105.21849682456647,-0.8756267250221903
0.369957274800801,0.04926345269053811,366.3161253327183,105.21849682456647,-0.8756267250221903
0.3777449634674866,0.0503004600920184,368.08506107716374,105.21849682456647,-0.8756267250221903
0.38149459134403907,0.0507997599519904,368.93169329168484,105.21849682456647,-0.8756267250221903
0.3833694052823152,0.0510494098819764,369.3537919477233,105.21849682456647,-0.8756267250221903
0.38683060024528665,0.051510302060412086,370.130942014854,105.21849682456647,-0.8756267250221903
0.3885611977267723,0.05174074814962992,370.51849974078425,105.21849682456647,-0.8756267250221903
0.39014757875146755,0.051951990398079614,370.8731700204753,105.21849682456647,-0.8756267250221903
0.39793526741815327,0.052988997799559914,372.60618687725247,105.21849682456647,-0.8756267250221903
0.3982237003317342,0.05302740548109622,372.6701174078218,105.21849682456647,-0.8756267250221903
0.3990889990724771,0.05314262852570514,372.86180073420695,105.21849682456647,-0.8756267250221903
0.402405977578658,0.05358431686337267,373.59509015712143,105.21849682456647,-0.8756267250221903
0.40442500797372466,0.053853170634126826,374.0402862109898,105.21849682456647,-0.8756267250221903
0.40557873962804847,0.054006801360272055,374.2942947707911,105.21849682456647,-0.8756267250221903
0.40875150167743896,0.05442928585717144,374.9913694110892,105.21849682456647,-0.8756267250221903
0.4090399345910199,0.05446769353870774,375.0546350108126,105.21849682456647,-0.8756267250221903
0.4130779953811532,0.05500540108021604,375.9385345300585,105.21849682456647,-0.8756267250221903
0.42028881822067704,0.05596559311862373,377.50859019377134,105.21849682456647,-0.8756267250221903
0.42576904357871503,0.05669533906781356,378.6948162078678,105.21849682456647,-0.8756267250221903
0.4299513208256389,0.057252250450090025,379.5960920563114,105.21849682456647,-0.8756267250221903
0.43240300059107695,0.05757871574314863,380.1228365747966,105.21849682456647,-0.8756267250221903
0.43571997909725796,0.05802040408081617,380.8336407120075,105.21849682456647,-0.8756267250221903
0.43687371075158166,0.058174034806961386,381.08038185689554,105.21849682456647,-0.8756267250221903
0.4391811740602293,0.058481296259251844,381.57310307904714,105.21849682456647,-0.8756267250221903
0.4436518842207341,0.059076615323064616,382.5248868111868,105.21849682456647,-0.8756267250221903
0.45389125265285785,0.06044008801760352,384.69079529986095,105.21849682456647,-0.8756267250221903
0.455766066591134,0.060689737947589514,385.0852974697965,105.21849682456647,-0.8756267250221903
0.45605449950471505,0.06072814562912583,385.14593389176326,105.21849682456647,-0.8756267250221903
0.4576408805294102,0.06093938787757551,385.47916725215003,105.21849682456647,-0.8756267250221903
0.4598041273812674,0.06122744548909782,385.9328512772585,105.21849682456647,-0.8756267250221903
0.4602367767516388,0.061285057011402286,386.02348810705877,105.21849682456647,-0.8756267250221903
0.46658230085041974,0.06213002600520104,387.34903380975226,105.21849682456647,-0.8756267250221903
0.4706203616405531,0.06266773354670935,388.1889035144889,105.21849682456647,-0.8756267250221903
0.47307204140599113,0.06299419883976795,388.6974533682402,105.21849682456647,-0.8756267250221903
0.47797540093686725,0.06364712942588517,389.71147994030736,105.21849682456647,-0.8756267250221903
0.48143659589983867,0.06410802160432086,390.42482223166405,105.21849682456647,-0.8756267250221903
0.49066644913442914,0.06533706741348269,392.31735731711325,105.21849682456647,-0.8756267250221903
0.4922528301591244,0.06554830966193238,392.6412335289559,105.21849682456647,-0.8756267250221903
0.49672354031962923,0.06614362872574515,393.5517927888769,105.21849682456647,-0.8756267250221903
0.4977330555171625,0.06627805561112222,393.75695994198315,105.21849682456647,-0.8756267250221903
0.5001847352826007,0.06660452090418084,394.25454854699126,105.21849682456647,-0.8756267250221903
0.5035017137887815,0.06704620924184837,394.9262452976449,105.21849682456647,-0.8756267250221903
0.5084050733196578,0.0676991398279656,395.91603576415054,105.21849682456647,-0.8756267250221903
0.5094145885171911,0.06783356671334267,396.1193532257898,105.21849682456647,-0.8756267250221903
0.5105683201715149,0.0679871974394879,396.3515237247955,105.21849682456647,-0.8756267250221903
0.5138852986776958,0.06842888577715543,397.01787690770453,105.21849682456647,-0.8756267250221903
0.5192213075789434,0.06913942788557711,398.08632737484004,105.21849682456647,-0.8756267250221903
0.525134182307353,0.06992678535707142,399.26529663851016,105.21849682456647,-0.8756267250221903
0.5255668316777243,0.06998439687937588,399.3513588732133,105.21849682456647,-0.8756267250221903
0.5264321304184673,0.07009961992398481,399.52340049664025,105.21849682456647,-0.8756267250221903
0.5281627278999529,0.07033006601320264,399.86715324164885,105.21849682456647,-0.8756267250221903
0.5291722430974862,0.07046449289857971,400.0674728164137,105.21849682456647,-0.8756267250221903
0.5314797064061338,0.07077175435087017,400.5247873104023,105.21849682456647,-0.8756267250221903
0.5342198190851529,0.0711366273254651,401.06684377177334,105.21849682456647,-0.8756267250221903
0.5371041482209624,0.07152070414082817,401.63625940495155,105.21849682456647,-0.8756267250221903
0.5378252305049148,0.07161672334466894,401.77842682255215,105.21849682456647,-0.8756267250221903
0.5382578798752863,0.0716743348669734,401.8636915915357,105.21849682456647,-0.8756267250221903
0.53941161152961,0.07182796559311863,402.0909337360149,105.21849682456647,-0.8756267250221903
0.5433054558629529,0.07234646929385878,402.85648037630057,105.21849682456647,-0.8756267250221903
0.5454687027148101,0.07263452690538108,403.28085938760216,105.21849682456647,-0.8756267250221903
0.5506604951592671,0.0733258651730346,404.296699894639,105.21849682456647,-0.8756267250221903
0.5513815774432196,0.07342188437687538,404.43749286109045,105.21849682456647,-0.8756267250221903
0.5526795255543338,0.07359471894378876,404.69073937598216,105.21849682456647,-0.8756267250221903
0.5545543394926099,0.07384436887377475,405.05613079228345,105.21849682456647,-0.8756267250221903
0.5562849369740958,0.0740748149629926,405.3929878021569,105.21849682456647,-0.8756267250221903
0.5594576990234862,0.07449729945989199,406.0094994032354,105.21849682456647,-0.8756267250221903
0.5604672142210195,0.07463172634526906,406.20537603396804,105.21849682456647,-0.8756267250221903
0.5620535952457147,0.07484296859371875,406.51290439503674,105.21849682456647,-0.8756267250221903
0.563351543356829,0.07501580316063212,406.7642667980484,105.21849682456647,-0.8756267250221903
0.5642168420975718,0.07513102620524105,406.93171626625264,105.21849682456647,-0.8756267250221903
0.56969706745561,0.07586077215443089,407.9899132209838,105.21849682456647,-0.8756267250221903
0.5701297168259813,0.07591838367673535,408.073285626501,105.21849682456647,-0.8756267250221903
0.5730140459617908,0.07630246049209842,408.6284724369412,105.21849682456647,-0.8756267250221903
0.574888859900067,0.07655211042208442,408.9887595040369,105.21849682456647,-0.8756267250221903
0.5764752409247623,0.07676335267053411,409.2932600245335,105.21849682456647,-0.8756267250221903
0.5780616219494575,0.0769745949189838,409.5974339217615,105.21849682456647,-0.8756267250221903
0.5800806523445242,0.07724344868973795,409.98409391125415,105.21849682456647,-0.8756267250221903
0.5832534143939148,0.07766593318663734,410.5906437131724,105.21849682456647,-0.8756267250221903
0.5867146093568861,0.07812682536507302,411.25086869705734,105.21849682456647,-0.8756267250221903
0.5907526701470194,0.07866453290658132,412.01921440366107,105.21849682456647,-0.8756267250221903
0.5939254321964099,0.0790870174034807,412.6214786029977,105.21849682456647,-0.8756267250221903
0.602434203147048,0.08022004400880177,414.23047895772766,105.21849682456647,-0.8756267250221903
0.6061838310236003,0.08071934386877376,414.9367139219324,105.21849682456647,-0.8756267250221903
0.611231407011267,0.08139147829565914,415.88473029787866,105.21849682456647,-0.8756267250221903
0.6118082728384289,0.08146829365873175,415.99288027031594,105.21849682456647,-0.8756267250221903
0.6162789829989337,0.08206361272254452,416.82969832701565,105.21849682456647,-0.8756267250221903
0.617000065282886,0.08215963192638528,416.9644469439891,105.21849682456647,-0.8756267250221903
0.6197401779619051,0.0825245049009802,417.4759325398115,105.21849682456647,-0.8756267250221903
0.6244993210359907,0.08315823164632927,418.3622109839963,105.21849682456647,-0.8756267250221903
0.6282489489125431,0.08365753150630126,419.0586370850085,105.21849682456647,-0.8756267250221903
0.6295468970236574,0.08383036607321465,419.29932972856597,105.21849682456647,-0.8756267250221903
0.6299795463940289,0.08388797759551911,419.3795175921389,105.21849682456647,-0.8756267250221903
0.6338733907273717,0.08440648129625926,420.1002444589458,105.21849682456647,-0.8756267250221903
0.6410842135668955,0.08536667333466694,421.43038075983014,105.21849682456647,-0.8756267250221903
0.643968542702705,0.08575075015003002,421.9607999723575,105.21849682456647,-0.8756267250221903
0.6472855212088859,0.08619243848769755,422.5696379825354,105.21849682456647,-0.8756267250221903
0.6513235819990192,0.08673014602920584,423.3091922450224,105.21849682456647,-0.8756267250221903
0.6530541794805049,0.08696059211842369,423.6255964314591,105.21849682456647,-0.8756267250221903
0.6570922402706383,0.08749829965993199,424.36260391075587,105.21849682456647,-0.8756267250221903
0.658822837752124,0.08772874574914984,424.67792329788443,105.21849682456647,-0.8756267250221903
0.6601207858632382,0.08790158031606321,424.91420089373344,105.21849682456647,-0.8756267250221903
0.6644472795669525,0.08847769553910782,425.7004875953707,105.21849682456647,-0.8756267250221903
0.667620041616343,0.0889001800360072,426.27582938779165,105.21849682456647,-0.8756267250221903
0.6689179897274573,0.0890730146029206,426.51088902292554,105.21849682456647,-0.8756267250221903
0.6712254530361049,0.08938027605521105,426.9283340810286,105.21849682456647,-0.8756267250221903
0.6722349682336383,0.08951470294058812,427.11079026473834,105.21849682456647,-0.8756267250221903
0.676994111307724,0.0901484296859372,427.9695056308738,105.21849682456647,-0.8756267250221903
0.6810321720978573,0.09068613722744549,428.69626797387536,105.21849682456647,-0.8756267250221903
0.6844933670608286,0.09114702940588118,429.3178705243741,105.21849682456647,-0.8756267250221903
0.685791315171943,0.09131986397279457,429.55065529164045,105.21849682456647,-0.8756267250221903
0.6869450468262668,0.0914734946989398,429.7574308763133,105.21849682456647,-0.8756267250221903
0.6872334797398477,0.0915119023804761,429.80910360456807,105.21849682456647,-0.8756267250221903
0.6896851595052859,0.09183836767353472,430.2479808287929,105.21849682456647,-0.8756267250221903
0.6924252721843048,0.09220324064812963,430.7377712768069,105.21849682456647,-0.8756267250221903
0.6963191165176477,0.09272174434886978,431.4324909467581,105.21849682456647,-0.8756267250221903
0.6981939304559238,0.09297139427885577,431.76644509526733,105.21849682456647,-0.8756267250221903
0.6990592291966667,0.0930866173234647,431.92045980539206,105.21849682456647,-0.8756267250221903
0.700357177307781,0.09325945189037808,432.1513425385145,105.21849682456647,-0.8756267250221903
0.7042510216411239,0.09377795559111823,432.84299155632584,105.21849682456647,-0.8756267250221903
0.7052605368386572,0.0939123824764953,433.02206431183174,105.21849682456647,-0.8756267250221903
0.7085775153448381,0.09435407081416283,433.60974363213154,105.21849682456647,-0.8756267250221903
0.709442814085581,0.09446929385877176,433.7628747077925,105.21849682456647,-0.8756267250221903
0.7104523292831143,0.09460372074414883,433.94143559684125,105.21849682456647,-0.8756267250221903
0.7126155761349715,0.09489177835567114,434.32373320673594,105.21849682456647,-0.8756267250221903
0.7183842344065905,0.09565993198639729,435.3409872407054,105.21849682456647,-0.8756267250221903
0.7232875939374667,0.09631286257251451,436.2031508675153,105.21849682456647,-0.8756267250221903
0.7250181914189524,0.09654330866173236,436.50689928575014,105.21849682456647,-0.8756267250221903
0.7266045724436476,0.09675455091018204,436.78508702696894,105.21849682456647,-0.8756267250221903
0.7277583040979714,0.09690818163632726,436.9872566279037,105.21849682456647,-0.8756267250221903
0.7349691269374953,0.09786837367473496,438.2479964073353,105.21849682456647,-0.8756267250221903
0.7369881573325618,0.0981372274454891,438.6001379036017,105.21849682456647,-0.8756267250221903
0.7382861054436761,0.09831006201240249,438.82631591826396,105.21849682456647,-0.8756267250221903
0.7431894649745523,0.0989629925985197,439.67937030494727,105.21849682456647,-0.8756267250221903
0.7502560713572857,0.09990398079615924,440.9049211204546,105.21849682456647,-0.8756267250221903
0.7509771536412381,0.1,441.0297236691556,105.21849682456647,-0.8756267250221903