File: datasets/aisi_316_L/data/M1/train_9.csv
Time(s),Strain(%),Stress(MPa),Temp(C),Log_SR(s-1)
0.0,0.0,0.0,399.0094546670478,1.3105338720268556
5.870125333758038e-07,1.2e-05,2.0322924375,399.0094546670478,1.3105338720268556
9.783542222930063e-07,1.9999999999999998e-05,3.3871540624999996,399.0094546670478,1.3105338720268556
1.2131592356433278e-06,2.48e-05,4.2000710375,399.0094546670478,1.3105338720268556
2.034976782369453e-06,4.1599999999999995e-05,7.045280449999999,399.0094546670478,1.3105338720268556
2.5437209779618166e-06,5.2e-05,8.8066005625,399.0094546670478,1.3105338720268556
3.05246517355418e-06,6.24e-05,10.567920675,399.0094546670478,1.3105338720268556
3.952551058063745e-06,8.08e-05,13.6841024125,399.0094546670478,1.3105338720268556
4.930905280356752e-06,0.0001008,17.071256475,399.0094546670478,1.3105338720268556
5.557051982624276e-06,0.0001136,19.239035075,399.0094546670478,1.3105338720268556
6.770211218267604e-06,0.0001384,23.4391061125,399.0094546670478,1.3105338720268556
7.63116293388545e-06,0.000156,26.419801687499998,399.0094546670478,1.3105338720268556
8.335577973936413e-06,0.0001704,28.8585526125,399.0094546670478,1.3105338720268556
8.531248818395014e-06,0.00017439999999999998,29.535983424999998,399.0094546670478,1.3105338720268556
9.2747980273377e-06,0.0001896,32.1102205125,399.0094546670478,1.3105338720268556
9.4704688717963e-06,0.0001936,32.787651325,399.0094546670478,1.3105338720268556
9.979213067388665e-06,0.000204,34.5489714375,399.0094546670478,1.3105338720268556
1.099670145857339e-05,0.0002248,38.0716116625,399.0094546670478,1.3105338720268556
1.1701116498624355e-05,0.0002392,40.5103625875,399.0094546670478,1.3105338720268556
1.2444665707567042e-05,0.0002544,43.084599675,399.0094546670478,1.3105338720268556
1.3227349085401447e-05,0.0002704,45.794322925,399.0094546670478,1.3105338720268556
1.3892629956560688e-05,0.00028399999999999996,48.097587687499995,399.0094546670478,1.3105338720268556
1.5223191698879177e-05,0.0003112,52.704117212499995,399.0094546670478,1.3105338720268556
1.541886254333778e-05,0.00031519999999999996,53.381548024999994,399.0094546670478,1.3105338720268556
1.581020423225498e-05,0.0003232,54.73640965,399.0094546670478,1.3105338720268556
1.671029011676455e-05,0.0003416,57.8525913875,399.0094546670478,1.3105338720268556
1.737557098792379e-05,0.00035519999999999996,60.15585614999999,399.0094546670478,1.3105338720268556
1.7766912676840996e-05,0.0003632,61.510717774999996,399.0094546670478,1.3105338720268556
1.9410547770293245e-05,0.0003968,67.2011366,399.0094546670478,1.3105338720268556
1.9684486952535288e-05,0.00040239999999999997,68.14953973749999,399.0094546670478,1.3105338720268556
2.0662841174828292e-05,0.00042239999999999997,71.5366938,399.0094546670478,1.3105338720268556
2.16411953971213e-05,0.00044239999999999997,74.9238478625,399.0094546670478,1.3105338720268556
2.320656215279011e-05,0.0004744,80.3432943625,399.0094546670478,1.3105338720268556
2.461539223289204e-05,0.0005032,85.22079621249999,399.0094546670478,1.3105338720268556
2.5358941441834728e-05,0.0005184,87.7950333,399.0094546670478,1.3105338720268556
2.559374645518504e-05,0.0005231999999999999,88.607950275,399.0094546670478,1.3105338720268556
2.578941729964365e-05,0.0005272,89.2853810875,399.0094546670478,1.3105338720268556
2.649383233969461e-05,0.0005415999999999999,91.7241320125,399.0094546670478,1.3105338720268556
2.6572100677478052e-05,0.0005432,91.9951043375,399.0094546670478,1.3105338720268556
2.755045489977106e-05,0.0005632,95.3822584,399.0094546670478,1.3105338720268556
2.794179658868826e-05,0.0005712,96.737120025,399.0094546670478,1.3105338720268556
2.82157357709303e-05,0.0005767999999999999,97.68552316249999,399.0094546670478,1.3105338720268556
2.8372272446497185e-05,0.00058,98.2274678125,399.0094546670478,1.3105338720268556
2.864621162873922e-05,0.0005855999999999999,99.17587094999999,399.0094546670478,1.3105338720268556
2.8920150810981265e-05,0.0005912,100.1242740875,399.0094546670478,1.3105338720268556
2.9115821655439865e-05,0.0005951999999999999,100.80170489999999,399.0094546670478,1.3105338720268556
3.13073351133762e-05,0.0006399999999999999,108.38892999999999,399.0094546670478,1.3105338720268556
3.181607930896857e-05,0.0006504,110.15025011249999,399.0094546670478,1.3105338720268556
3.291183603793673e-05,0.0006728,113.9438626625,399.0094546670478,1.3105338720268556
3.3303177726853934e-05,0.0006808,115.2987242875,399.0094546670478,1.3105338720268556
3.47902761447393e-05,0.0007111999999999999,120.44719846249998,399.0094546670478,1.3105338720268556
3.615997205594951e-05,0.0007392,125.18921415,399.0094546670478,1.3105338720268556
3.67078504204336e-05,0.0007503999999999999,127.08602042499999,399.0094546670478,1.3105338720268556
3.7686204642726604e-05,0.0007704,130.4731744875,399.0094546670478,1.3105338720268556
3.831235134499413e-05,0.0007832,132.64095308749998,399.0094546670478,1.3105338720268556
3.8664558865019605e-05,0.0007903999999999999,133.86032855,399.0094546670478,1.3105338720268556
3.9016766385045094e-05,0.0007976,135.0797040125,399.0094546670478,1.3105338720268556
3.956464474952917e-05,0.0008087999999999999,136.9765102875,399.0094546670478,1.3105338720268556
3.968204725620434e-05,0.0008112,137.382968775,399.0094546670478,1.3105338720268556
4.042559646514702e-05,0.0008263999999999999,139.9572058625,399.0094546670478,1.3105338720268556
4.140395068744003e-05,0.0008464,143.344359925,399.0094546670478,1.3105338720268556
4.281278076754195e-05,0.0008751999999999999,148.22186177499998,399.0094546670478,1.3105338720268556
4.332152496313432e-05,0.0008856,149.9831818875,399.0094546670478,1.3105338720268556
4.406507417207701e-05,0.0009008,152.557418975,399.0094546670478,1.3105338720268556
4.4691220874344527e-05,0.0009136,154.725197575,399.0094546670478,1.3105338720268556
4.527823340772033e-05,0.0009256,156.7574900125,399.0094546670478,1.3105338720268556
4.5513038421070656e-05,0.0009304,157.57040698749998,399.0094546670478,1.3105338720268556
4.629572179890506e-05,0.0009463999999999999,160.28013023749998,399.0094546670478,1.3105338720268556
4.797849106124903e-05,0.0009808,161.57437573855537,399.0094546670478,1.3105338720268556
4.817416190570763e-05,0.0009847999999999999,161.59554555624766,399.0094546670478,1.3105338720268556
4.864377193240827e-05,0.0009943999999999999,161.64621676334838,399.0094546670478,1.3105338720268556
4.9856931168051606e-05,0.0010192,161.77624215015436,399.0094546670478,1.3105338720268556
5.040480953253568e-05,0.0010304,161.83455822849237,399.0094546670478,1.3105338720268556
5.130489541704525e-05,0.0010488,161.92982938172565,399.0094546670478,1.3105338720268556
5.189190795042105e-05,0.0010608,161.9916117483511,399.0094546670478,1.3105338720268556
5.263545715936374e-05,0.001076,162.06947951744982,399.0094546670478,1.3105338720268556
5.271372549714718e-05,0.0010776,162.0776510912606,399.0094546670478,1.3105338720268556
5.384861639500706e-05,0.0011007999999999999,162.19561219587442,399.0094546670478,1.3105338720268556
5.5531385657351046e-05,0.0011352,162.36875075503607,399.0094546670478,1.3105338720268556
5.631406903518545e-05,0.0011512,162.44858194665534,399.0094546670478,1.3105338720268556
5.674454489299437e-05,0.00116,162.492304616645,399.0094546670478,1.3105338720268556
5.717502075080329e-05,0.0011688,162.5358981175334,399.0094546670478,1.3105338720268556
5.8309911648663176e-05,0.001192,162.6502172073257,399.0094546670478,1.3105338720268556
5.956220505319822e-05,0.0012175999999999999,162.7753600259145,399.0094546670478,1.3105338720268556
5.999268091100714e-05,0.0012263999999999999,162.8181403216441,399.0094546670478,1.3105338720268556
6.093190096440843e-05,0.0012456,162.9110657911658,399.0094546670478,1.3105338720268556
6.175371851113456e-05,0.0012624,162.99191827664094,399.0094546670478,1.3105338720268556
6.218419436894348e-05,0.0012711999999999999,163.03410204524513,399.0094546670478,1.3105338720268556
6.300601191566961e-05,0.0012879999999999999,163.11431978006772,399.0094546670478,1.3105338720268556
6.421917115131293e-05,0.0013128,163.2319946171973,399.0094546670478,1.3105338720268556
6.484531785358046e-05,0.0013256,163.29239060857017,399.0094546670478,1.3105338720268556
6.629328210257411e-05,0.0013552,163.43119187970413,399.0094546670478,1.3105338720268556
6.660635545370787e-05,0.0013616,163.46104692752476,399.0094546670478,1.3105338720268556
6.746730716932571e-05,0.0013792,163.54286743922543,399.0094546670478,1.3105338720268556
6.97370889650455e-05,0.0014256,163.75664742792875,399.0094546670478,1.3105338720268556
7.024583316063785e-05,0.001436,163.8041893182894,399.0094546670478,1.3105338720268556
7.114591904514742e-05,0.0014544,163.88797424293148,399.0094546670478,1.3105338720268556
7.18894682540901e-05,0.0014696,163.95687651527246,399.0094546670478,1.3105338720268556
7.220254160522387e-05,0.0014759999999999999,163.98580478502973,399.0094546670478,1.3105338720268556
7.294609081416656e-05,0.0014912,164.05431406890463,399.0094546670478,1.3105338720268556
7.443318923205191e-05,0.0015216,164.19052100722095,399.0094546670478,1.3105338720268556
7.509847010321117e-05,0.0015352,164.25111165779316,399.0094546670478,1.3105338720268556
7.607682432550417e-05,0.0015551999999999999,164.33983665168975,399.0094546670478,1.3105338720268556
7.705517854779718e-05,0.0015752,164.42811775087463,399.0094546670478,1.3105338720268556
7.822920361454878e-05,0.0015991999999999998,164.53348011605777,399.0094546670478,1.3105338720268556
7.869881364124943e-05,0.0016087999999999999,164.57545217309223,399.0094546670478,1.3105338720268556
7.909015533016662e-05,0.0016167999999999998,164.61035432460167,399.0094546670478,1.3105338720268556
7.991197287689276e-05,0.0016336,164.68343037127323,399.0094546670478,1.3105338720268556
8.006850955245964e-05,0.0016367999999999999,164.6973163260056,399.0094546670478,1.3105338720268556
8.030331456580996e-05,0.0016416,164.7181254230057,399.0094546670478,1.3105338720268556
8.128166878810296e-05,0.0016615999999999998,164.8045758027029,399.0094546670478,1.3105338720268556
8.155560797034501e-05,0.0016672,164.8287090633882,399.0094546670478,1.3105338720268556
8.17512788148036e-05,0.0016711999999999999,164.8459277551984,399.0094546670478,1.3105338720268556
8.237742551707114e-05,0.001684,164.90091987105657,399.0094546670478,1.3105338720268556
8.257309636152973e-05,0.0016879999999999998,164.91807144444712,399.0094546670478,1.3105338720268556
8.304270638823038e-05,0.0016975999999999998,164.9591706774148,399.0094546670478,1.3105338720268556
8.362971892160617e-05,0.0017096,165.010417474632,399.0094546670478,1.3105338720268556
8.554729319730048e-05,0.0017488,165.17685446034793,399.0094546670478,1.3105338720268556
8.574296404175907e-05,0.0017527999999999999,165.19375560678296,399.0094546670478,1.3105338720268556
8.695612327740239e-05,0.0017775999999999998,165.2982089537891,399.0094546670478,1.3105338720268556
8.738659913521133e-05,0.0017863999999999998,165.3351362304643,399.0094546670478,1.3105338720268556
8.766053831745337e-05,0.001792,165.35859847344028,399.0094546670478,1.3105338720268556
8.83258191886126e-05,0.0018055999999999999,165.4154594767069,399.0094546670478,1.3105338720268556
8.871716087752982e-05,0.0018135999999999998,165.4488291028766,399.0094546670478,1.3105338720268556
8.977378343760626e-05,0.0018352,165.5386415796743,399.0094546670478,1.3105338720268556
9.047819847765723e-05,0.0018495999999999999,165.59828763574856,399.0094546670478,1.3105338720268556
9.071300349100754e-05,0.0018544,165.6181293728946,399.0094546670478,1.3105338720268556
9.110434517992475e-05,0.0018624,165.6511544814529,399.0094546670478,1.3105338720268556
9.176962605108399e-05,0.0018759999999999998,165.707170475634,399.0094546670478,1.3105338720268556
9.333499280675281e-05,0.001908,165.83835177093988,399.0094546670478,1.3105338720268556
9.392200534012861e-05,0.0019199999999999998,165.88732318555333,399.0094546670478,1.3105338720268556
9.505689623798849e-05,0.0019432,165.98166409643997,399.0094546670478,1.3105338720268556
9.54482379269057e-05,0.0019512,166.01409345851667,399.0094546670478,1.3105338720268556
9.611351879806495e-05,0.0019648,166.06910461883626,399.0094546670478,1.3105338720268556
9.728754386481654e-05,0.0019887999999999998,166.16582223725464,399.0094546670478,1.3105338720268556
9.87355081138102e-05,0.0020184,166.2844826692128,399.0094546670478,1.3105338720268556
9.889204478937707e-05,0.0020215999999999997,166.2972700424258,399.0094546670478,1.3105338720268556
0.0001006922165583962,0.0020583999999999997,166.44376194433667,399.0094546670478,1.3105338720268556
0.00010116182658509685,0.002068,166.48180879369812,399.0094546670478,1.3105338720268556
0.00010319680336746632,0.0021096,166.6458888583702,399.0094546670478,1.3105338720268556
0.00010476217012313513,0.0021416,166.77124706552584,399.0094546670478,1.3105338720268556
0.00010558398766986124,0.0021584,166.83676757310167,399.0094546670478,1.3105338720268556
0.00010652320772326254,0.0021776,166.91140510186648,399.0094546670478,1.3105338720268556
0.00010722762276331349,0.002192,166.96721493603985,399.0094546670478,1.3105338720268556
0.00010812770864782306,0.0022104,167.038319859569,399.0094546670478,1.3105338720268556
0.00010867558701230714,0.0022216,167.08148810928228,399.0094546670478,1.3105338720268556
0.00010910606287011606,0.0022304,167.11534650565798,399.0094546670478,1.3105338720268556
0.00011031922210575939,0.0022551999999999997,167.21048645999107,399.0094546670478,1.3105338720268556
0.00011082796630135176,0.0022656,167.25026232676635,399.0094546670478,1.3105338720268556
0.0001109062346391352,0.0022672,167.25637536483583,399.0094546670478,1.3105338720268556
0.0001112975763280524,0.0022752,167.28691535427498,399.0094546670478,1.3105338720268556
0.00011348908978598874,0.00232,167.45717161493826,399.0094546670478,1.3105338720268556
0.00011376302896823077,0.0023255999999999997,167.47836312218905,399.0094546670478,1.3105338720268556
0.00011466311485274034,0.0023439999999999997,167.54785266063806,399.0094546670478,1.3105338720268556
0.00011595454242616711,0.0023704,167.64718460132818,399.0094546670478,1.3105338720268556
0.00011669809163510979,0.0023856,167.70417999254119,399.0094546670478,1.3105338720268556
0.00011716770166181045,0.0023952,167.7401041206831,399.0094546670478,1.3105338720268556
0.00011920267844417988,0.0024368,167.89513092982844,399.0094546670478,1.3105338720268556
0.00011967228847088054,0.0024464,167.93075936064994,399.0094546670478,1.3105338720268556
0.00012076804519984869,0.0024687999999999997,168.0136809920424,399.0094546670478,1.3105338720268556
0.00012151159440879139,0.002484,168.06978220086617,399.0094546670478,1.3105338720268556
0.00012190293609770858,0.002492,168.0992553684582,399.0094546670478,1.3105338720268556
0.0001220986069421672,0.002496,168.1139781128865,399.0094546670478,1.3105338720268556
0.00012315522950224363,0.0025176,168.1933224934121,399.0094546670478,1.3105338720268556
0.00012358570536005254,0.0025264,168.2255718148753,399.0094546670478,1.3105338720268556
0.0001242509862312118,0.0025399999999999997,168.27532563892876,399.0094546670478,1.3105338720268556
0.00012475973042680417,0.0025504,168.3133026103928,399.0094546670478,1.3105338720268556
0.00012546414546685513,0.0025648,168.3657865529921,399.0094546670478,1.3105338720268556
0.0001265599021958233,0.0025872,168.44720039443663,399.0094546670478,1.3105338720268556
0.0001271469147291991,0.0025992,168.49070184941687,399.0094546670478,1.3105338720268556
0.0001277339272625749,0.0026111999999999997,168.53412504781912,399.0094546670478,1.3105338720268556
0.00013016024573386158,0.0026608,168.71278812646904,399.0094546670478,1.3105338720268556
0.0001304341849161036,0.0026663999999999998,168.73287783009224,399.0094546670478,1.3105338720268556
0.00013094292911169597,0.0026768,168.770143677406,399.0094546670478,1.3105338720268556
0.00013313444256963228,0.0027216,168.93003224537333,399.0094546670478,1.3105338720268556
0.00013423019929860046,0.002744,169.0095913685574,399.0094546670478,1.3105338720268556
0.0001346606751564094,0.0027527999999999997,169.04077738963073,399.0094546670478,1.3105338720268556
0.00013477807766308454,0.0027551999999999997,169.0492759171687,399.0094546670478,1.3105338720268556
0.00013552162687202723,0.0027703999999999997,169.1030330345211,399.0094546670478,1.3105338720268556
0.0001364217127565368,0.0027887999999999997,169.16795378424538,399.0094546670478,1.3105338720268556
0.00013685218861434574,0.0027976,169.1989437679842,399.0094546670478,1.3105338720268556
0.00013728266447215464,0.0028063999999999997,169.22989575750577,399.0094546670478,1.3105338720268556
0.0001375957378232884,0.0028128,169.25238252575247,399.0094546670478,1.3105338720268556
0.00013908283624117378,0.0028431999999999997,169.35892336684483,399.0094546670478,1.3105338720268556
0.00013978725128122475,0.0028576,169.4092349343808,399.0094546670478,1.3105338720268556
0.00014096127634797634,0.0028816,169.49286837580772,399.0094546670478,1.3105338720268556
0.0001420178989080528,0.0029032,169.5679064902332,399.0094546670478,1.3105338720268556
0.00014256577727253688,0.0029143999999999997,169.60672940459693,399.0094546670478,1.3105338720268556
0.00014401374152153053,0.002944,169.70905374756452,399.0094546670478,1.3105338720268556
0.0001441311440282057,0.0029464,169.71733268977837,399.0094546670478,1.3105338720268556
0.00014503122991271528,0.0029648,169.78071743784233,399.0094546670478,1.3105338720268556
0.00014530516909495728,0.0029703999999999998,169.79997797266904,399.0094546670478,1.3105338720268556
0.00014569651078387452,0.0029784,169.82746847492578,399.0094546670478,1.3105338720268556
0.0001469096700195178,0.0030031999999999997,169.9125065952694,399.0094546670478,1.3105338720268556
0.00014827936593072804,0.0030312,170.00818890476398,399.0094546670478,1.3105338720268556
0.0001497664643486134,0.0030616,170.1116831093069,399.0094546670478,1.3105338720268556
0.00015082308690868987,0.0030832,170.18497506035106,399.0094546670478,1.3105338720268556
0.0001515275019487408,0.0030976,170.2337251418222,399.0094546670478,1.3105338720268556
0.00015367988123778545,0.0031416,170.38213898944042,399.0094546670478,1.3105338720268556
0.0001543842962778364,0.003156,170.43053443461716,399.0094546670478,1.3105338720268556
0.00015548005300680456,0.0031784,170.50564541666535,399.0094546670478,1.3105338720268556
0.00015818031066033324,0.0032335999999999997,170.68986448674337,399.0094546670478,1.3105338720268556
0.00015888472570038423,0.003248,170.73771941702466,399.0094546670478,1.3105338720268556
0.0001602152874427027,0.0032752,170.82788690814,399.0094546670478,1.3105338720268556
0.00016099797082053712,0.0032911999999999998,170.88079019132283,399.0094546670478,1.3105338720268556
0.00016185892253615497,0.0033087999999999998,170.9388680883181,399.0094546670478,1.3105338720268556
0.00016260247174509763,0.0033239999999999997,170.98892938244958,399.0094546670478,1.3105338720268556
0.00016342428929182377,0.0033407999999999997,171.0441565314099,399.0094546670478,1.3105338720268556
0.0001648331193719257,0.0033696,171.13858031554594,399.0094546670478,1.3105338720268556
0.00016510705855416773,0.0033751999999999996,171.15690388946317,399.0094546670478,1.3105338720268556
0.00016663329114094484,0.0034064,171.2587761512051,399.0094546670478,1.3105338720268556
0.00016765077953212958,0.0034272,171.3264888997269,399.0094546670478,1.3105338720268556
0.00016819865789661364,0.0034384,171.36288321754944,399.0094546670478,1.3105338720268556
0.00016866826792331428,0.0034479999999999997,171.3940415641323,399.0094546670478,1.3105338720268556
0.0001708206472123589,0.003492,171.53641997143023,399.0094546670478,1.3105338720268556
0.00017179900143465192,0.003512,171.6009059644884,399.0094546670478,1.3105338720268556
0.0001719555381102188,0.0035152,171.6112104177592,399.0094546670478,1.3105338720268556
0.00017242514813691943,0.0035248,171.6421018496326,399.0094546670478,1.3105338720268556
0.0001731295631769704,0.0035391999999999997,171.68837754527024,399.0094546670478,1.3105338720268556
0.00017399051489258823,0.0035567999999999997,171.74483712911456,399.0094546670478,1.3105338720268556
0.00017461666159485577,0.0035696,171.78583023177845,399.0094546670478,1.3105338720268556
0.0001762211625194163,0.0036024,171.89061424430946,399.0094546670478,1.3105338720268556
0.00017708211423503415,0.00362,171.94668638948468,399.0094546670478,1.3105338720268556
0.00017766912676840993,0.003632,171.98485645307133,399.0094546670478,1.3105338720268556
0.0001777865292750851,0.0036344,171.99248456028903,399.0094546670478,1.3105338720268556
0.0001787257493284864,0.0036536,172.05343885482384,399.0094546670478,1.3105338720268556
0.00017915622518629531,0.0036623999999999997,172.08133447732695,399.0094546670478,1.3105338720268556
0.00017997804273302143,0.0036791999999999997,172.13451727469058,399.0094546670478,1.3105338720268556
0.00018060418943528897,0.003692,172.17497395671776,399.0094546670478,1.3105338720268556
0.00018130860447533993,0.0037064,172.220422395141,399.0094546670478,1.3105338720268556
0.00018350011793327625,0.0037511999999999997,172.36137913833878,399.0094546670478,1.3105338720268556
0.00018365665460884313,0.0037543999999999998,172.37142228358326,399.0094546670478,1.3105338720268556
0.00018393059379108519,0.00376,172.38898975834655,399.0094546670478,1.3105338720268556
0.00018592643640456293,0.0038008,172.51667477965862,399.0094546670478,1.3105338720268556
0.0001868265222890725,0.0038192,172.57408321139695,399.0094546670478,1.3105338720268556
0.00018792227901804064,0.0038415999999999997,172.64382635445136,399.0094546670478,1.3105338720268556
0.0001890180357470088,0.003864,172.7134110770622,399.0094546670478,1.3105338720268556
0.00018987898746262666,0.0038816,172.76797448214958,399.0094546670478,1.3105338720268556
0.00019062253667156935,0.0038967999999999997,172.81501982106795,399.0094546670478,1.3105338720268556
0.0001908964758538114,0.0039024,172.83233426685948,399.0094546670478,1.3105338720268556
0.00019238357427169678,0.0039328,172.92615843242444,399.0094546670478,1.3105338720268556
0.0001928531842983974,0.0039423999999999996,172.9557282973456,399.0094546670478,1.3105338720268556
0.00019316625764953117,0.0039488,172.97542594117084,399.0094546670478,1.3105338720268556
0.00019406634353404074,0.0039672,173.03198743211476,399.0094546670478,1.3105338720268556
0.0001948098927429834,0.0039824,173.07863501484513,399.0094546670478,1.3105338720268556
0.00019500556358744204,0.0039864,173.09089914722878,399.0094546670478,1.3105338720268556
0.0001955143077830344,0.0039968,173.1227634516332,399.0094546670478,1.3105338720268556
0.00020130729206853097,0.004115223044608922,173.48334564571346,399.0094546670478,1.3105338720268556
0.00020788314761344896,0.004249649929985997,173.88778852583175,399.0094546670478,1.3105338720268556
0.00022197426663827323,0.004537707541508302,174.73801940216276,399.0094546670478,1.3105338720268556
0.0002482776888179452,0.005075415083016604,176.27077162122234,399.0094546670478,1.3105338720268556
0.0002529747284928866,0.005171434286857372,176.53767334523184,399.0094546670478,1.3105338720268556
0.0002792781506725585,0.005709141828365673,177.99806006294398,399.0094546670478,1.3105338720268556
0.00030558157285223047,0.006246849369873975,179.405685941906,399.0094546670478,1.3105338720268556
0.00031967269187705474,0.006534906981396279,180.14028277178826,399.0094546670478,1.3105338720268556
0.00033658203470684383,0.006880576115223045,181.00533088892175,399.0094546670478,1.3105338720268556
0.0003422184823167736,0.006995799159831967,181.28989129250502,399.0094546670478,1.3105338720268556
0.0003610066410165392,0.007379875975195039,182.2254933333866,399.0094546670478,1.3105338720268556
0.00037697657591134,0.00770634126825365,183.0059146557412,399.0094546670478,1.3105338720268556
0.0004136134853758831,0.008455291058211642,184.74911726368134,399.0094546670478,1.3105338720268556
0.00042864401233569567,0.0087625525105021,185.4467212136877,399.0094546670478,1.3105338720268556
0.000466220329735227,0.009530706141228246,187.1502280069748,399.0094546670478,1.3105338720268556
0.0004803114487600513,0.00981876375275055,187.77512320104458,399.0094546670478,1.3105338720268556
0.0005103725026796764,0.010433286657331467,189.08482183762746,399.0094546670478,1.3105338720268556
0.0005385547407293249,0.011009401880376076,190.28558913405058,399.0094546670478,1.3105338720268556
0.0005620399391040319,0.011489497899579915,191.2676154933501,399.0094546670478,1.3105338720268556
0.0005770704660638445,0.011796759351870374,191.88772173361065,399.0094546670478,1.3105338720268556
0.0005864645454137273,0.01198879775955191,192.27209088629112,399.0094546670478,1.3105338720268556
0.0006456472453179892,0.013198639727945589,194.6406136808658,399.0094546670478,1.3105338720268556
0.0006597383643428135,0.013486697339467894,195.19187516208558,399.0094546670478,1.3105338720268556
0.0006663142198877315,0.013621124224844969,195.44755723007535,399.0094546670478,1.3105338720268556
0.0006860417865224855,0.014024404880976196,196.20876304666564,399.0094546670478,1.3105338720268556
0.0007010723134822979,0.014331666333266654,196.783012768801,399.0094546670478,1.3105338720268556
0.0007179816563120871,0.01467733546709342,197.42333481847618,399.0094546670478,1.3105338720268556
0.0007489821181667004,0.01531106221244249,198.58218651325598,399.0094546670478,1.3105338720268556
0.0007752855403463723,0.01584876975395079,199.55085638435574,399.0094546670478,1.3105338720268556
0.0007846796196962553,0.01604080816163233,199.89369250224277,399.0094546670478,1.3105338720268556
0.0007968919228511029,0.016290458091618325,200.3369958385836,399.0094546670478,1.3105338720268556
0.0008166194894858568,0.01669373874774955,201.047544819415,399.0094546670478,1.3105338720268556
0.0008231953450307749,0.016828165633126627,201.28290264936464,399.0094546670478,1.3105338720268556
0.0008551352148203764,0.017481096219243847,202.41580078018922,399.0094546670478,1.3105338720268556
0.0008701657417801889,0.017788357671534305,202.94320745334863,399.0094546670478,1.3105338720268556
0.000906802651244732,0.0185373074614923,204.2140921832366,399.0094546670478,1.3105338720268556
0.0009312272575544275,0.019036607321464293,205.05023936394625,399.0094546670478,1.3105338720268556
0.0009368637051643572,0.019151830366073215,205.2419765442677,399.0094546670478,1.3105338720268556
0.000952833640059158,0.019478295659131825,205.7828039634254,399.0094546670478,1.3105338720268556
0.0009594094956040759,0.019612722544508902,206.00446871947645,399.0094546670478,1.3105338720268556
0.0009875917336537245,0.02018883776755351,206.94782686722786,399.0094546670478,1.3105338720268556
0.0009969858130036073,0.020380876175235048,207.2599387380665,399.0094546670478,1.3105338720268556
0.0010308044986631856,0.02107221444288858,208.37416755182474,399.0094546670478,1.3105338720268556
0.0010467744335579863,0.02139867973594719,208.8953667735405,399.0094546670478,1.3105338720268556
0.001056168512907869,0.021590718143628725,209.20050598398936,399.0094546670478,1.3105338720268556
0.0010646231843227639,0.02176355271054211,209.4742274540382,399.0094546670478,1.3105338720268556
0.001088108382697471,0.02224364872974595,210.23015223434487,399.0094546670478,1.3105338720268556
0.0011068965413972365,0.02262772554510902,210.8303204368629,399.0094546670478,1.3105338720268556
0.001128502923901967,0.023069413882776557,211.51562394121058,399.0094546670478,1.3105338720268556
0.0011388364111868381,0.023280656131226245,211.84156720710214,399.0094546670478,1.3105338720268556
0.0011557457540166273,0.02362632526505301,212.37245187508918,399.0094546670478,1.3105338720268556
0.0011604427936915687,0.023722344468893777,212.51938113707854,399.0094546670478,1.3105338720268556
0.0011933220714161587,0.024394478895779156,213.5414685929226,399.0094546670478,1.3105338720268556
0.0012064737825059947,0.024663332666533307,213.9472210832957,399.0094546670478,1.3105338720268556
0.001217746677725854,0.02489377875575115,214.29363786851144,399.0094546670478,1.3105338720268556
0.0012365348364256198,0.025277855571114224,214.86823273923233,399.0094546670478,1.3105338720268556
0.0012553229951253854,0.025661932386477296,215.43943262381865,399.0094546670478,1.3105338720268556
0.0012684747062152214,0.025930786157231447,215.83729034134953,399.0094546670478,1.3105338720268556
0.0012882022728499753,0.026334066813362672,216.4310736721648,399.0094546670478,1.3105338720268556
0.0013032327998097877,0.02664132826565313,216.88110270193877,399.0094546670478,1.3105338720268556
0.0013145056950296472,0.026871774354870974,217.21729726741106,399.0094546670478,1.3105338720268556
0.0013220209585095536,0.027025405081016203,217.44080251148233,399.0094546670478,1.3105338720268556
0.0013248391823145185,0.027083016603320666,217.524489158524,399.0094546670478,1.3105338720268556
0.001339869709274331,0.027390278055611124,217.96965084261933,399.0094546670478,1.3105338720268556
0.0013642943155840264,0.02788957791558312,218.68890705805302,399.0094546670478,1.3105338720268556
0.0013661731314540029,0.027927985597119426,218.74402557699182,399.0094546670478,1.3105338720268556
0.001393415961568663,0.02848489697939588,219.53995114267434,399.0094546670478,1.3105338720268556
0.0014159617520083819,0.028945789157831567,220.19406865046247,399.0094546670478,1.3105338720268556
0.0014422651741880538,0.02948349669933987,220.95209376632894,399.0094546670478,1.3105338720268556
0.0014676291884327375,0.030002000400080015,221.6779566417476,399.0094546670478,1.3105338720268556
0.001502387282027304,0.0307125425085017,222.66476109403442,399.0094546670478,1.3105338720268556
0.0015080237296372337,0.030827765553110623,222.823940648452,399.0094546670478,1.3105338720268556
0.0015437212311667885,0.03155751150230046,223.82674246068459,399.0094546670478,1.3105338720268556
0.0015681458374764837,0.03205681136227245,224.50766469782772,399.0094546670478,1.3105338720268556
0.0015822369565013082,0.03234486897379476,224.8986228766269,399.0094546670478,1.3105338720268556
0.0016066615628110036,0.03284416883376676,225.57308215529304,399.0094546670478,1.3105338720268556
0.0016404802484705815,0.03353550710142028,226.50038421350206,399.0094546670478,1.3105338720268556
0.0016555107754303942,0.03384276855371074,226.91012217940346,399.0094546670478,1.3105338720268556
0.0016658442627152652,0.03405401080216043,227.1909758171693,399.0094546670478,1.3105338720268556
0.0016677230785852417,0.034092418483696735,227.24196703257118,399.0094546670478,1.3105338720268556
0.0017062388039197616,0.03487977595519104,228.2824003708046,399.0094546670478,1.3105338720268556
0.0017306634102294569,0.03537907581516303,228.93744378929244,399.0094546670478,1.3105338720268556
0.0017475727530592458,0.03572474494898979,229.3888248710675,399.0094546670478,1.3105338720268556
0.0017644820958890354,0.03607041408281657,229.83850579854288,399.0094546670478,1.3105338720268556
0.001779512622848848,0.036377675535107026,230.23681317467882,399.0094546670478,1.3105338720268556
0.0018001795974185897,0.036800160032006396,230.78235006879896,399.0094546670478,1.3105338720268556
0.0018255436116632734,0.037318663732746546,231.4485456206894,399.0094546670478,1.3105338720268556
0.001837755914818121,0.03756831366273254,231.76801813305772,399.0094546670478,1.3105338720268556
0.0018725140084126881,0.03827885577115424,232.67278560157936,399.0094546670478,1.3105338720268556
0.0018743928242826646,0.03831726345269054,232.72150450820234,399.0094546670478,1.3105338720268556
0.0018931809829824298,0.03870134026805361,233.20765064386472,399.0094546670478,1.3105338720268556
0.0019138479575521723,0.03912382476495299,233.7402433126591,399.0094546670478,1.3105338720268556
0.0019166661813571372,0.039181436287257454,233.81269541220146,399.0094546670478,1.3105338720268556
0.0019457878273417737,0.03977675535107021,234.5589502946245,399.0094546670478,1.3105338720268556
0.0019495454590817273,0.03985357071414283,234.65492296559273,399.0094546670478,1.3105338720268556
0.0019636365781065513,0.04014162832566513,235.01417977138988,399.0094546670478,1.3105338720268556
0.0019796065130013524,0.04046809361872375,235.42012424777622,399.0094546670478,1.3105338720268556
0.002005909935181024,0.041005801160232044,236.08596550333874,399.0094546670478,1.3105338720268556
0.0020200010542058486,0.04129385877175436,236.44126506389298,399.0094546670478,1.3105338720268556
0.00204630447638552,0.04183156631326265,237.10191534906147,399.0094546670478,1.3105338720268556
0.0020726078985651925,0.04236927385477096,237.7592619056129,399.0094546670478,1.3105338720268556
0.002078244346175122,0.04248449689937987,237.89969767635222,399.0094546670478,1.3105338720268556
0.002091396057264958,0.04275335067013403,238.22680474375872,399.0094546670478,1.3105338720268556
0.002099850728679853,0.042926185237047415,238.43666430688566,399.0094546670478,1.3105338720268556
0.0021261541508595244,0.04346389277855571,239.08746320673828,399.0094546670478,1.3105338720268556
0.002132730006404442,0.04359831966393278,239.24967137396126,399.0094546670478,1.3105338720268556
0.002149639349234232,0.043943988797759556,239.6658849725445,399.0094546670478,1.3105338720268556
0.002162791060324067,0.0442128425685137,239.9887245260835,399.0094546670478,1.3105338720268556
0.002218216128488376,0.04534586917383476,241.3409353312353,399.0094546670478,1.3105338720268556
0.00224921659034299,0.04597959591918384,242.09150871142083,399.0094546670478,1.3105338720268556
0.002267065341107767,0.04634446889377876,242.52182676072854,399.0094546670478,1.3105338720268556
0.0022745806045876733,0.04649809961992399,242.7026177884789,399.0094546670478,1.3105338720268556
0.0022999446188323573,0.04701660332066414,243.31107490707308,399.0094546670478,1.3105338720268556
0.0023121569219872046,0.047266253250650134,243.60310192141455,399.0094546670478,1.3105338720268556
0.002326248041012029,0.04755431086217243,243.9393097324597,399.0094546670478,1.3105338720268556
0.0023347027124269236,0.04772714542908582,244.1406531956247,399.0094546670478,1.3105338720268556
0.0023741578456964313,0.04853370674134827,245.0765216915594,399.0094546670478,1.3105338720268556
0.002379794293306361,0.048648929785957196,245.20972036141242,399.0094546670478,1.3105338720268556
0.0023938854123311854,0.048936987397479495,245.5421798860448,399.0094546670478,1.3105338720268556
0.0024042188996160566,0.04914822964592919,245.7854986749878,399.0094546670478,1.3105338720268556
0.00243521936147067,0.04978195639127826,246.5130195754995,399.0094546670478,1.3105338720268556
0.0024399164011456114,0.04987797559511903,246.62293412354785,399.0094546670478,1.3105338720268556
0.0024568257439754005,0.05022364472894579,247.01794504882076,399.0094546670478,1.3105338720268556
0.0024962808772449083,0.05103020604120824,247.93553667727156,399.0094546670478,1.3105338720268556
0.002516008443879662,0.051433486697339464,248.39221013171255,399.0094546670478,1.3105338720268556
0.0025282207470345096,0.05168313662732546,248.6742130238538,399.0094546670478,1.3105338720268556
0.002540433050189358,0.05193278655731147,248.95568516140108,399.0094546670478,1.3105338720268556
0.0025460694977992872,0.05204800960192038,249.0854173488881,399.0094546670478,1.3105338720268556
0.0025639182485640644,0.0524128825765153,249.49549895628076,399.0094546670478,1.3105338720268556
0.002578948775523877,0.05272014402880576,249.83996800765047,399.0094546670478,1.3105338720268556
0.0025996157500936196,0.05314262852570514,250.31233723680228,399.0094546670478,1.3105338720268556
0.002609949237378491,0.053353870774154835,250.54797246886886,399.0094546670478,1.3105338720268556
0.0026353132516231744,0.053872374474894985,251.12481253731082,399.0094546670478,1.3105338720268556
0.0026578590420628934,0.05433326665333067,251.63574401302665,399.0094546670478,1.3105338720268556
0.002671950161087717,0.05462132426485297,251.95421798276521,399.0094546670478,1.3105338720268556
0.0026916777277224712,0.055024604920984196,252.39898329852062,399.0094546670478,1.3105338720268556
0.002766830362521534,0.05656091218243649,254.0818066819158,399.0094546670478,1.3105338720268556
0.00277434562600144,0.05671454290858172,254.24910256645975,399.0094546670478,1.3105338720268556
0.0027856185212212997,0.05694498899779957,254.49971538864696,399.0094546670478,1.3105338720268556
0.00281286135133596,0.05750190038007602,255.10373569064055,399.0094546670478,1.3105338720268556
0.0028504376687354914,0.058270054010802166,255.9331367255816,399.0094546670478,1.3105338720268556
0.0028541953004754443,0.058346869373874774,256.01584160994605,399.0094546670478,1.3105338720268556
0.002883316946460081,0.05894218843768753,256.65537091091164,399.0094546670478,1.3105338720268556
0.0029002262892898704,0.05928785757151431,257.02555448323614,399.0094546670478,1.3105338720268556
0.0029114991845097297,0.059518303660732144,257.2718760080559,399.0094546670478,1.3105338720268556
0.0029349843828844367,0.05999839967993599,257.7838544238408,399.0094546670478,1.3105338720268556
0.0029612878050641086,0.060536107221444285,258.35537718940776,399.0094546670478,1.3105338720268556
0.00299886412246364,0.06130426085217043,259.1684157590766,399.0094546670478,1.3105338720268556
0.0030073187938785347,0.06147709541908382,259.35080075480545,399.0094546670478,1.3105338720268556
0.0030401980716031245,0.0621492298459692,260.05818290397616,399.0094546670478,1.3105338720268556
0.0030721379413927263,0.06280216043208642,260.7425027398973,399.0094546670478,1.3105338720268556
0.003107835442922281,0.06353190638127626,261.5040556576547,399.0094546670478,1.3105338720268556
0.003117229522272164,0.06372394478895779,261.7038963517066,399.0094546670478,1.3105338720268556
0.0031491693920617653,0.06437687537507501,262.3816047349184,399.0094546670478,1.3105338720268556
0.0031811092618513667,0.06502980596119223,263.0566376805601,399.0094546670478,1.3105338720268556
0.003200836828486121,0.06543308661732347,263.47224951436334,399.0094546670478,1.3105338720268556
0.003216806763380922,0.06575955191038207,263.80796597731916,399.0094546670478,1.3105338720268556
0.0032280796586007816,0.06598999799959993,264.0445510655139,399.0094546670478,1.3105338720268556
0.003235594922080688,0.06614362872574515,264.20209547542413,399.0094546670478,1.3105338720268556
0.003247807225235535,0.06639327865573115,264.4578011072326,399.0094546670478,1.3105338720268556
0.003253443672845465,0.06650850170034008,264.5756925912937,399.0094546670478,1.3105338720268556
0.003276928871220172,0.06698859771954391,265.0660521765692,399.0094546670478,1.3105338720268556
0.0032966564378549266,0.06739187837567515,265.4768959469535,399.0094546670478,1.3105338720268556
0.0033173234124246683,0.06781436287257452,265.90627662946696,399.0094546670478,1.3105338720268556
0.003322959860034598,0.06792958591718344,266.02319922792026,399.0094546670478,1.3105338720268556
0.0033408086107993757,0.06829445889177836,266.39294488199636,399.0094546670478,1.3105338720268556
0.003398112494833661,0.06946589317863573,267.57484937501624,399.0094546670478,1.3105338720268556
0.00340938539005352,0.06969633926785357,267.8064374427159,399.0094546670478,1.3105338720268556
0.003418779469403403,0.06988837767553512,267.99919946387064,399.0094546670478,1.3105338720268556
0.0034272341408182975,0.07006121224244849,268.1725087366558,399.0094546670478,1.3105338720268556
0.00344226466777811,0.07036847369473895,268.48020296956196,399.0094546670478,1.3105338720268556
0.003446961707453051,0.07046449289857971,268.5762499025292,399.0094546670478,1.3105338720268556
0.0034704469058277586,0.07094458891778356,269.0557210513074,399.0094546670478,1.3105338720268556
0.0035164778946421846,0.0718855771154231,269.9918295165658,399.0094546670478,1.3105338720268556
0.003543720724756845,0.07244248849769955,270.5436018747745,399.0094546670478,1.3105338720268556
0.0035672059231315516,0.07292258451690338,271.01794124815007,399.0094546670478,1.3105338720268556
0.003585054673896329,0.0732874574914983,271.3776250690231,399.0094546670478,1.3105338720268556
0.003597266977051177,0.0735371074214843,271.62332222555676,399.0094546670478,1.3105338720268556
0.0036141763198809665,0.07388277655531107,271.9629819257353,399.0094546670478,1.3105338720268556
0.003646116189670568,0.07453570714142829,272.60287517231615,399.0094546670478,1.3105338720268556
0.003686510730875064,0.0753614722944589,273.4090298217131,399.0094546670478,1.3105338720268556
0.0037212688244696304,0.07607201440288058,274.0999441589039,399.0094546670478,1.3105338720268556
0.0037785727085039157,0.07724344868973795,275.2335491990874,399.0094546670478,1.3105338720268556
0.0038001790910086462,0.07768513702740548,275.6592309324887,399.0094546670478,1.3105338720268556
0.003817088433838435,0.07803080616123224,275.9917150953202,399.0094546670478,1.3105338720268556
0.0038246036973183413,0.07818443688737747,276.1393014010467,399.0094546670478,1.3105338720268556
0.0038405736322131424,0.07851090218043609,276.4525472954281,399.0094546670478,1.3105338720268556
0.003874392317872721,0.07920224044808963,277.11421958308546,399.0094546670478,1.3105338720268556
0.003879089357547662,0.0792982596519304,277.2059400457596,399.0094546670478,1.3105338720268556
0.003895059292442463,0.079624724944989,277.5174661438328,399.0094546670478,1.3105338720268556
0.003899756332117404,0.07972074414882976,277.6089966142913,399.0094546670478,1.3105338720268556
0.0039091504114672875,0.07991278255651131,277.7919286725872,399.0094546670478,1.3105338720268556
0.003922302122557123,0.08018163632726545,278.0477457882035,399.0094546670478,1.3105338720268556
0.003929817386037029,0.08033526705341068,278.1937767978647,399.0094546670478,1.3105338720268556
0.003977727190721432,0.08131466293258652,279.1221772212046,399.0094546670478,1.3105338720268556
0.003983363638331362,0.08142988597719544,279.23111334566795,399.0094546670478,1.3105338720268556
0.0040106064684460214,0.0819867973594719,279.756792828853,399.0094546670478,1.3105338720268556
0.004027515811275811,0.08233246649329866,280.08237629156065,399.0094546670478,1.3105338720268556
0.004067910352480307,0.08315823164632927,280.85800861539695,399.0094546670478,1.3105338720268556
0.00408294087944012,0.08346549309861973,281.1458484626227,399.0094546670478,1.3105338720268556
0.004095153182594967,0.08371514302860572,281.3794141686885,399.0094546670478,1.3105338720268556
0.0041054866698798384,0.08392638527705541,281.5768345950266,399.0094546670478,1.3105338720268556
0.0041073654857498145,0.08396479295859172,281.612708387558,399.0094546670478,1.3105338720268556
0.004116759565099698,0.08415683136627326,281.79198144384,399.0094546670478,1.3105338720268556
0.004131790092059511,0.08446409281856372,282.0784868412368,399.0094546670478,1.3105338720268556
0.004136487131734452,0.08456011202240449,282.16793638130554,399.0094546670478,1.3105338720268556
0.004158093514239182,0.08500180036007202,282.57889512904615,399.0094546670478,1.3105338720268556
0.004168427001524053,0.08521304260852171,282.77514614556526,399.0094546670478,1.3105338720268556
0.004186275752288831,0.08557791558311663,283.1136788613227,399.0094546670478,1.3105338720268556
0.004235124964908222,0.08657651530306061,284.03732311017615,399.0094546670478,1.3105338720268556
0.004256731347412952,0.08701820364072815,284.4445317819035,399.0094546670478,1.3105338720268556
0.004261428387087893,0.08711422284456892,284.5329486482169,399.0094546670478,1.3105338720268556
0.004311217007642272,0.08813202640528106,285.4678426088719,399.0094546670478,1.3105338720268556
0.004352550956781756,0.08897699539907981,286.2407863220529,399.0094546670478,1.3105338720268556
0.004369460299611547,0.08932266453290659,286.5561648474565,399.0094546670478,1.3105338720268556
0.004381672602766394,0.08957231446289259,286.78364227905956,399.0094546670478,1.3105338720268556
0.004384490826571359,0.08962992598519705,286.83610194075334,399.0094546670478,1.3105338720268556
0.004388248458311312,0.08970674134826966,286.9060277044084,399.0094546670478,1.3105338720268556
0.004404218393206113,0.09003320664132827,287.2029520573416,399.0094546670478,1.3105338720268556
0.004409854840816043,0.0901484296859372,287.3076485968785,399.0094546670478,1.3105338720268556
0.004432400631255762,0.09060932186437289,287.72591392009247,399.0094546670478,1.3105338720268556
0.0044389764868006795,0.09074374874974996,287.84775156955186,399.0094546670478,1.3105338720268556
0.004461522277240398,0.09120464092818564,288.2649473003477,399.0094546670478,1.3105338720268556
0.004469976948655293,0.09137747549509903,288.4211836194972,399.0094546670478,1.3105338720268556
0.004491583331160023,0.09181916383276656,288.81993151558567,399.0094546670478,1.3105338720268556
0.004497219778769953,0.09193438687737548,288.9238295888185,399.0094546670478,1.3105338720268556
0.004507553266054824,0.09214562912582518,289.11417758633524,399.0094546670478,1.3105338720268556
0.004514129121599742,0.09228005601120225,289.23521952729,399.0094546670478,1.3105338720268556
0.004528220240624566,0.09256811362272455,289.4943637973041,399.0094546670478,1.3105338720268556
0.004543250767584378,0.092875375075015,289.7704379431292,399.0094546670478,1.3105338720268556
0.004566735965959086,0.09335547109421885,290.2010917646903,399.0094546670478,1.3105338720268556
0.004578948269113934,0.09360512102420485,290.4246903541485,399.0094546670478,1.3105338720268556
0.004611827546838524,0.09427725545109022,291.0255335611366,399.0094546670478,1.3105338720268556
0.004622161034123395,0.09448849769953992,291.2140246619253,399.0094546670478,1.3105338720268556
0.004628736889668313,0.09462292458491699,291.3338879810477,399.0094546670478,1.3105338720268556
0.004644706824563113,0.0949493898779756,291.6247084620274,399.0094546670478,1.3105338720268556
0.004658797943587938,0.0952374474894979,291.88099107157024,399.0094546670478,1.3105338720268556
0.004686980181637586,0.09581356271254252,292.3926511534493,399.0094546670478,1.3105338720268556
0.004713283603817258,0.09635127025405081,292.8691190883682,399.0094546670478,1.3105338720268556
0.004717980643492199,0.09644728945789158,292.9540934096242,399.0094546670478,1.3105338720268556
0.004733950578387,0.0967737547509502,293.2427596355224,399.0094546670478,1.3105338720268556
0.004748981105346813,0.09708101620324065,293.5140987573287,399.0094546670478,1.3105338720268556
0.004759314592631684,0.09729225845169034,293.7004501500708,399.0094546670478,1.3105338720268556
0.004775284527526485,0.09761872374474895,293.9881376797294,399.0094546670478,1.3105338720268556
0.004784678606876367,0.0978107621524305,294.1571903633732,399.0094546670478,1.3105338720268556
0.004803466765576133,0.09819483896779356,294.4949078937611,399.0094546670478,1.3105338720268556
0.004809103213186063,0.09831006201240249,294.59612264442626,399.0094546670478,1.3105338720268556
0.004817557884600958,0.09848289657931587,294.7478580674253,399.0094546670478,1.3105338720268556
0.004826012556015852,0.09865573114622925,294.89948967233545,399.0094546670478,1.3105338720268556
0.004834467227430746,0.09882856571314264,295.0510177118818,399.0094546670478,1.3105338720268556
0.004845740122650606,0.09905901180236047,295.2528944310988,399.0094546670478,1.3105338720268556
0.0048739223607002545,0.09963512702540508,295.756786565379,399.0094546670478,1.3105338720268556
0.004884255847985125,0.09984636927385478,295.94126214132086,399.0094546670478,1.3105338720268556
0.004890831703530043,0.09998079615923185,296.05857644260743,399.0094546670478,1.3105338720268556