File: datasets/aisi_316_L/data/M1/train_89.csv
Time(s),Strain(%),Stress(MPa),Temp(C),Log_SR(s-1)
0.0,0.0,0.0,372.1789490477598,1.9735657616729743
8.502061170917216e-08,8e-06,1.372909625,372.1789490477598,1.9735657616729743
5.781401596223707e-07,5.4399999999999994e-05,9.33578545,372.1789490477598,1.9735657616729743
7.311772606988806e-07,6.879999999999999e-05,11.807022774999998,372.1789490477598,1.9735657616729743
9.947411569973144e-07,9.36e-05,16.0630426125,372.1789490477598,1.9735657616729743
1.1647823804156586e-06,0.0001096,18.8088618625,372.1789490477598,1.9735657616729743
1.3433256650049201e-06,0.00012639999999999998,21.691972074999995,372.1789490477598,1.9735657616729743
1.5898854389615195e-06,0.0001496,25.6734099875,372.1789490477598,1.9735657616729743
1.6493998671579402e-06,0.0001552,26.634446725,372.1789490477598,1.9735657616729743
1.844947274089036e-06,0.0001736,29.7921388625,372.1789490477598,1.9735657616729743
1.9044617022854566e-06,0.0001792,30.7531756,372.1789490477598,1.9735657616729743
2.26154827146398e-06,0.0002128,36.519396025,372.1789490477598,1.9735657616729743
2.3465688831731517e-06,0.0002208,37.89230565,372.1789490477598,1.9735657616729743
3.0267337768465293e-06,0.0002848,48.87558265,372.1789490477598,1.9735657616729743
3.205277061435791e-06,0.0003016,51.758692862500006,372.1789490477598,1.9735657616729743
3.3413100401704663e-06,0.0003144,53.9553482625,372.1789490477598,1.9735657616729743
3.7409069152035753e-06,0.000352,60.4080235,372.1789490477598,1.9735657616729743
3.851433710425499e-06,0.00036239999999999997,62.19280601249999,372.1789490477598,1.9735657616729743
4.063985239698429e-06,0.00038239999999999997,65.625080075,372.1789490477598,1.9735657616729743
4.361557380680532e-06,0.0004104,70.4302637625,372.1789490477598,1.9735657616729743
4.616619215808049e-06,0.0004344,74.54899263749999,372.1789490477598,1.9735657616729743
4.897187234448317e-06,0.0004608,79.07959439999999,372.1789490477598,1.9735657616729743
4.965203723815654e-06,0.00046719999999999997,80.17792209999999,372.1789490477598,1.9735657616729743
5.067228457866661e-06,0.0004768,81.82541365,372.1789490477598,1.9735657616729743
5.313788231823261e-06,0.0005,85.8068515625,372.1789490477598,1.9735657616729743
5.543343883438025e-06,0.0005216,89.51370754999999,372.1789490477598,1.9735657616729743
5.577352128121694e-06,0.0005248,90.06287139999999,372.1789490477598,1.9735657616729743
5.7388912903691215e-06,0.00054,92.6713996875,372.1789490477598,1.9735657616729743
5.857920146761962e-06,0.0005512,94.59347316249999,372.1789490477598,1.9735657616729743
6.334035572333326e-06,0.000596,102.2817670625,372.1789490477598,1.9735657616729743
6.359541755846078e-06,0.0005984,102.69363995,372.1789490477598,1.9735657616729743
6.504076795751671e-06,0.000612,105.0275863125,372.1789490477598,1.9735657616729743
6.563591223948091e-06,0.0006175999999999999,105.98862304999999,372.1789490477598,1.9735657616729743
6.631607713315429e-06,0.000624,107.08695075,372.1789490477598,1.9735657616729743
6.776142753221022e-06,0.0006376,109.4208971125,372.1789490477598,1.9735657616729743
6.988694282493951e-06,0.0006575999999999999,112.85317117499999,372.1789490477598,1.9735657616729743
7.167237567083214e-06,0.0006744,115.7362813875,372.1789490477598,1.9735657616729743
7.328776729330641e-06,0.0006896,118.344809675,372.1789490477598,1.9735657616729743
7.473311769236233e-06,0.0007032,120.6787560375,372.1789490477598,1.9735657616729743
7.685863298509165e-06,0.0007232,124.11103010000001,372.1789490477598,1.9735657616729743
8.119468418225941e-06,0.0007639999999999999,131.1128691875,372.1789490477598,1.9735657616729743
8.30651376398612e-06,0.0007815999999999999,134.13327036249999,372.1789490477598,1.9735657616729743
8.476554987404466e-06,0.0007976,136.8790896125,372.1789490477598,1.9735657616729743
8.629592088480975e-06,0.000812,139.3503269375,372.1789490477598,1.9735657616729743
8.68060445550648e-06,0.0008168,140.1740727125,372.1789490477598,1.9735657616729743
8.791131250728401e-06,0.0008271999999999999,141.95885522499998,372.1789490477598,1.9735657616729743
8.833641556582988e-06,0.0008311999999999999,142.6453100375,372.1789490477598,1.9735657616729743
8.876151862437574e-06,0.0008351999999999999,143.33176484999998,372.1789490477598,1.9735657616729743
8.97817659648858e-06,0.0008447999999999999,144.9792564,372.1789490477598,1.9735657616729743
9.267246676299766e-06,0.0008719999999999999,149.647149125,372.1789490477598,1.9735657616729743
9.547814694940033e-06,0.0008983999999999999,154.1777508875,372.1789490477598,1.9735657616729743
9.683847673674709e-06,0.0009111999999999999,156.3744062875,372.1789490477598,1.9735657616729743
9.7773703465548e-06,0.0009199999999999999,157.88460687499997,372.1789490477598,1.9735657616729743
1.0057938365195067e-05,0.0009463999999999999,162.41520863749997,372.1789490477598,1.9735657616729743
1.0432029056715426e-05,0.0009816,168.4560109875,372.1789490477598,1.9735657616729743
1.044903317905726e-05,0.0009832,168.73059291250001,372.1789490477598,1.9735657616729743
1.0576564096621017e-05,0.0009952,170.47923314718543,372.1789490477598,1.9735657616729743
1.093365066579954e-05,0.0010287999999999999,170.66464721456768,372.1789490477598,1.9735657616729743
1.1120696011559719e-05,0.0010463999999999998,170.7608254474864,372.1789490477598,1.9735657616729743
1.140126403019999e-05,0.0010728,170.9039182024163,372.1789490477598,1.9735657616729743
1.1613815559472917e-05,0.0010927999999999999,171.01140930432553,372.1789490477598,1.9735657616729743
1.181786502757493e-05,0.001112,171.11388123137365,372.1789490477598,1.9735657616729743
1.1860375333429518e-05,0.001116,171.13514243672904,372.1789490477598,1.9735657616729743
1.2021914495676944e-05,0.0011312,171.21566540898058,372.1789490477598,1.9735657616729743
1.2208959841437123e-05,0.0011488,171.30837722815602,372.1789490477598,1.9735657616729743
1.2753091756375824e-05,0.0012,171.5749853290425,372.1789490477598,1.9735657616729743
1.28891247351105e-05,0.0012128,171.64093952719077,372.1789490477598,1.9735657616729743
1.3424754588878284e-05,0.0012632,171.89803754865483,372.1789490477598,1.9735657616729743
1.3577791689954796e-05,0.0012776,171.97075521819346,372.1789490477598,1.9735657616729743
1.3603297873467545e-05,0.0012799999999999999,171.9828436855019,372.1789490477598,1.9735657616729743
1.3722326729860388e-05,0.0012912,172.0391400654579,372.1789490477598,1.9735657616729743
1.3807347341569559e-05,0.0012992,172.07923522852957,372.1789490477598,1.9735657616729743
1.3849857647424146e-05,0.0013032,172.09924669389488,372.1789490477598,1.9735657616729743
1.3977388564987903e-05,0.0013151999999999999,172.15913785328354,372.1789490477598,1.9735657616729743
1.407941329903891e-05,0.0013248,172.20689747822172,372.1789490477598,1.9735657616729743
1.4317471011824594e-05,0.0013472,172.31781476722955,372.1789490477598,1.9735657616729743
1.4555528724610274e-05,0.0013696,172.42801509398373,372.1789490477598,1.9735657616729743
1.4802088498566875e-05,0.0013928,172.54141264600867,372.1789490477598,1.9735657616729743
1.4895611171446965e-05,0.0014016,172.58423250227005,372.1789490477598,1.9735657616729743
1.5193183312429065e-05,0.0014295999999999998,172.7197851615822,372.1789490477598,1.9735657616729743
1.5295208046480073e-05,0.0014391999999999999,172.76602148079576,372.1789490477598,1.9735657616729743
1.551626163692392e-05,0.00146,172.865789546721,372.1789490477598,1.9735657616729743
1.5728813166196853e-05,0.00148,172.96119891928424,372.1789490477598,1.9735657616729743
1.578832759439327e-05,0.0014856,172.98782326540797,372.1789490477598,1.9735657616729743
1.5924360573127947e-05,0.0014984,173.0485323716807,372.1789490477598,1.9735657616729743
1.60008791236662e-05,0.0015056,173.08259235547152,372.1789490477598,1.9735657616729743
1.6672541956168662e-05,0.0015688,173.37888563750056,372.1789490477598,1.9735657616729743
1.6791570812561503e-05,0.00158,173.43090399395402,372.1789490477598,1.9735657616729743
1.682557905724517e-05,0.0015831999999999999,173.4457399422581,372.1789490477598,1.9735657616729743
1.7089142953543604e-05,0.0016079999999999998,173.5603246519366,372.1789490477598,1.9735657616729743
1.7216673871107362e-05,0.00162,173.61552126126776,372.1789490477598,1.9735657616729743
1.7267686238132867e-05,0.0016248,173.6375552293707,372.1789490477598,1.9735657616729743
1.746323364506396e-05,0.0016431999999999998,173.7217846387493,372.1789490477598,1.9735657616729743
1.7573760440285884e-05,0.0016535999999999999,173.7692298410041,372.1789490477598,1.9735657616729743
1.7769307847216982e-05,0.0016719999999999999,173.8528872494631,372.1789490477598,1.9735657616729743
1.7828822275413404e-05,0.0016776,173.87827683281984,372.1789490477598,1.9735657616729743
1.801586762117358e-05,0.0016952,173.95785832785643,372.1789490477598,1.9735657616729743
1.811789235522459e-05,0.0017048,174.0011305756488,372.1789490477598,1.9735657616729743
1.826242739513018e-05,0.0017184,174.06227060293395,372.1789490477598,1.9735657616729743
1.8398460373864856e-05,0.0017312,174.11964199513125,372.1789490477598,1.9735657616729743
1.844947274089036e-05,0.001736,174.14111358638525,372.1789490477598,1.9735657616729743
1.857700365845412e-05,0.001748,174.19469151529154,372.1789490477598,1.9735657616729743
1.8832065493581636e-05,0.001772,174.3014189606542,372.1789490477598,1.9735657616729743
1.894259228880356e-05,0.0017824,174.34749228034192,372.1789490477598,1.9735657616729743
1.9257168552127498e-05,0.001812,174.47805366914167,372.1789490477598,1.9735657616729743
1.9308180919153e-05,0.0018168,174.4991471576342,372.1789490477598,1.9735657616729743
1.958024687662235e-05,0.0018424,174.61128081195363,372.1789490477598,1.9735657616729743
1.9631259243647856e-05,0.0018472,174.63223805111556,372.1789490477598,1.9735657616729743
1.9656765427160605e-05,0.0018495999999999999,174.6427087054548,372.1789490477598,1.9735657616729743
1.9826806650578947e-05,0.0018655999999999998,174.71237814876272,372.1789490477598,1.9735657616729743
1.997984375165546e-05,0.00188,174.7748816599126,372.1789490477598,1.9735657616729743
2.0141382913902886e-05,0.0018951999999999999,174.84065536778417,372.1789490477598,1.9735657616729743
2.031992619849215e-05,0.0019119999999999999,174.91311372995418,372.1789490477598,1.9735657616729743
2.0600494217132414e-05,0.0019383999999999998,175.0264772121481,372.1789490477598,1.9735657616729743
2.0855556052259934e-05,0.0019624,175.12901347331626,372.1789490477598,1.9735657616729743
2.0932074602798184e-05,0.0019695999999999997,175.15967883183825,372.1789490477598,1.9735657616729743
2.1034099336849194e-05,0.0019792,175.20049805621787,372.1789490477598,1.9735657616729743
2.122964674378029e-05,0.0019976,175.27851971647524,372.1789490477598,1.9735657616729743
2.131466735548946e-05,0.0020055999999999997,175.31235470149366,372.1789490477598,1.9735657616729743
2.160373743530065e-05,0.0020328,175.42700197508555,372.1789490477598,1.9735657616729743
2.184179514808633e-05,0.0020552,175.52096881841084,372.1789490477598,1.9735657616729743
2.2088354922042927e-05,0.0020783999999999998,175.6178715039514,372.1789490477598,1.9735657616729743
2.2122363166726596e-05,0.0020816,175.6312042095576,372.1789490477598,1.9735657616729743
2.2241392023119437e-05,0.0020927999999999997,175.6778058611029,372.1789490477598,1.9735657616729743
2.2692001265178052e-05,0.0021352,175.85335222906184,372.1789490477598,1.9735657616729743
2.281103012157089e-05,0.0021463999999999997,175.89949531147371,372.1789490477598,1.9735657616729743
2.2828034243912724e-05,0.0021479999999999997,175.90607950674524,372.1789490477598,1.9735657616729743
2.287054454976731e-05,0.002152,175.9225316322841,372.1789490477598,1.9735657616729743
2.309159814021116e-05,0.0021728,176.00789119442837,372.1789490477598,1.9735657616729743
2.3219129057774917e-05,0.0021847999999999998,176.0569921291192,372.1789490477598,1.9735657616729743
2.3321153791825926e-05,0.0021944,176.09619719107707,372.1789490477598,1.9735657616729743
2.3474190892902437e-05,0.0022088,176.15487959793876,372.1789490477598,1.9735657616729743
2.3584717688124357e-05,0.0022191999999999997,176.19716858416555,372.1789490477598,1.9735657616729743
2.3780265095055455e-05,0.0022375999999999997,176.2717987062811,372.1789490477598,1.9735657616729743
2.3933302196131965e-05,0.002252,176.33003806706637,372.1789490477598,1.9735657616729743
2.400982074667022e-05,0.0022592,176.35910327081416,372.1789490477598,1.9735657616729743
2.4273384642968656e-05,0.002284,176.4589413951922,372.1789490477598,1.9735657616729743
2.4417919682874246e-05,0.0022976,176.51351180873266,372.1789490477598,1.9735657616729743
2.473249594619818e-05,0.0023271999999999998,176.63184913501803,372.1789490477598,1.9735657616729743
2.4843022741420108e-05,0.0023376,176.67328756956965,372.1789490477598,1.9735657616729743
2.4919541291958362e-05,0.0023447999999999997,176.70193360712986,372.1789490477598,1.9735657616729743
2.510658663771854e-05,0.0023623999999999997,176.7718132166626,372.1789490477598,1.9735657616729743
2.5259623738795053e-05,0.0023768,176.82883654690824,372.1789490477598,1.9735657616729743
2.5387154656358808e-05,0.0023888,176.8762531374409,372.1789490477598,1.9735657616729743
2.550618351275165e-05,0.0024,176.92042487789413,372.1789490477598,1.9735657616729743
2.5591204124460823e-05,0.002408,176.95192691536639,372.1789490477598,1.9735657616729743
2.574424122553733e-05,0.0024224,177.00852791751421,372.1789490477598,1.9735657616729743
2.6007805121835768e-05,0.0024472,177.1057007815389,372.1789490477598,1.9735657616729743
2.6024809244177596e-05,0.0024487999999999997,177.11195677843293,372.1789490477598,1.9735657616729743
2.6254364895792364e-05,0.0024703999999999998,177.1962573166971,372.1789490477598,1.9735657616729743
2.641590405803979e-05,0.0024855999999999997,177.2554076829511,372.1789490477598,1.9735657616729743
2.673048032136373e-05,0.0025152,177.37019195213048,372.1789490477598,1.9735657616729743
2.690902360595299e-05,0.002532,177.43510540385088,372.1789490477598,1.9735657616729743
2.7385139031524354e-05,0.0025767999999999998,177.60739194302636,372.1789490477598,1.9735657616729743
2.7453155520891693e-05,0.0025832,177.63190860492395,372.1789490477598,1.9735657616729743
2.7563682316113613e-05,0.0025935999999999997,177.67169771666187,372.1789490477598,1.9735657616729743
2.7784735906557463e-05,0.0026144,177.75108975778343,372.1789490477598,1.9735657616729743
2.7929270946463053e-05,0.0026279999999999997,177.80286678349984,372.1789490477598,1.9735657616729743
2.8048299802855898e-05,0.0026392,177.84542826744726,372.1789490477598,1.9735657616729743
2.849040698374359e-05,0.0026807999999999997,178.00290082480146,372.1789490477598,1.9735657616729743
2.855842347311093e-05,0.0026872,178.0270425242631,372.1789490477598,1.9735657616729743
2.8643444084820105e-05,0.0026952,178.05718813817253,372.1789490477598,1.9735657616729743
2.8855995614093035e-05,0.0027152,178.13239990015234,372.1789490477598,1.9735657616729743
2.9128061571562383e-05,0.0027408,178.22835642590016,372.1789490477598,1.9735657616729743
2.9459641957228153e-05,0.0027719999999999997,178.34483213567714,372.1789490477598,1.9735657616729743
2.9638185241817416e-05,0.0027887999999999997,178.40733800354832,372.1789490477598,1.9735657616729743
2.9748712037039343e-05,0.0027992,178.44595852802917,372.1789490477598,1.9735657616729743
2.9842234709919428e-05,0.0028079999999999997,178.47859374449183,372.1789490477598,1.9735657616729743
3.039486868602905e-05,0.0028599999999999997,178.67063020613278,372.1789490477598,1.9735657616729743
3.0496893420080058e-05,0.0028696,178.70593368892406,372.1789490477598,1.9735657616729743
3.0590416092960146e-05,0.0028783999999999997,178.7382547727125,372.1789490477598,1.9735657616729743
3.067543670466932e-05,0.0028864,178.76760415020877,372.1789490477598,1.9735657616729743
3.0726449071694825e-05,0.0028912,178.7851985492636,372.1789490477598,1.9735657616729743
3.085397998925858e-05,0.0029032,178.82913478010332,372.1789490477598,1.9735657616729743
3.093900060096775e-05,0.0029112,178.85838625948423,372.1789490477598,1.9735657616729743
3.104102533501876e-05,0.0029208,178.8934466860394,372.1789490477598,1.9735657616729743
3.110053976321518e-05,0.0029264,178.91387784722684,372.1789490477598,1.9735657616729743
3.124507480312077e-05,0.00294,178.96343300399067,372.1789490477598,1.9735657616729743
3.1457626332393706e-05,0.00296,179.03614613558685,372.1789490477598,1.9735657616729743
3.169568404517939e-05,0.0029824,179.11735774720998,372.1789490477598,1.9735657616729743
3.1755198473375806e-05,0.0029879999999999998,179.13762343797825,372.1789490477598,1.9735657616729743
3.201026030850332e-05,0.003012,179.22430915963562,372.1789490477598,1.9735657616729743
3.238435100002368e-05,0.0030472,179.3509625187407,372.1789490477598,1.9735657616729743
3.2554392223442026e-05,0.0030632,179.40834347464497,372.1789490477598,1.9735657616729743
3.277544581388587e-05,0.003084,179.4827642700666,372.1789490477598,1.9735657616729743
3.2885972609107796e-05,0.0030943999999999998,179.5199012419727,372.1789490477598,1.9735657616729743
3.302200558784247e-05,0.0031072,179.565541528376,372.1789490477598,1.9735657616729743
3.3183544750089896e-05,0.0031224,179.61964424164202,372.1789490477598,1.9735657616729743
3.3481116891072e-05,0.0031504,179.7190390128539,372.1789490477598,1.9735657616729743
3.3608647808635755e-05,0.0031623999999999997,179.76153123890077,372.1789490477598,1.9735657616729743
3.384670552142144e-05,0.0031848,179.84068219090008,372.1789490477598,1.9735657616729743
3.4144277662403544e-05,0.0032128,179.93931622766806,372.1789490477598,1.9735657616729743
3.42718085799673e-05,0.0032248,179.98148526765894,372.1789490477598,1.9735657616729743
3.432282094699281e-05,0.0032296,179.99833574291588,372.1789490477598,1.9735657616729743
3.4475858048069314e-05,0.003244,180.04882866302646,372.1789490477598,1.9735657616729743
3.462889514914582e-05,0.0032584,180.0992342452715,372.1789490477598,1.9735657616729743
3.472241782202592e-05,0.0032672,180.12999489152995,372.1789490477598,1.9735657616729743
3.475642606670958e-05,0.0032703999999999997,180.14117256761975,372.1789490477598,1.9735657616729743
3.518152912525544e-05,0.0033104,180.2805355520985,372.1789490477598,1.9735657616729743
3.52580476757937e-05,0.0033176,180.30555098684724,372.1789490477598,1.9735657616729743
3.5411084776870206e-05,0.003332,180.35551842802218,372.1789490477598,1.9735657616729743
3.5564121877946714e-05,0.0033464,180.40540172098633,372.1789490477598,1.9735657616729743
3.5674648673168644e-05,0.0033568,180.44137649477182,372.1789490477598,1.9735657616729743
3.5904204324783405e-05,0.0033783999999999997,180.51595473789146,372.1789490477598,1.9735657616729743
3.6006229058834414e-05,0.003388,180.54904090879566,372.1789490477598,1.9735657616729743
3.605724142585991e-05,0.0033927999999999996,180.5655702817769,372.1789490477598,1.9735657616729743
3.622728264927826e-05,0.0034088,180.62060244224094,372.1789490477598,1.9735657616729743
3.6337809444500184e-05,0.0034192,180.65631933317619,372.1789490477598,1.9735657616729743
3.6609875401969536e-05,0.0034448,180.7440578040362,372.1789490477598,1.9735657616729743
3.685643517592613e-05,0.0034679999999999997,180.82335138968838,372.1789490477598,1.9735657616729743
3.69839660934899e-05,0.00348,180.86428412097396,372.1789490477598,1.9735657616729743
3.715400731690824e-05,0.003496,180.91877556942762,372.1789490477598,1.9735657616729743
3.7400567090864835e-05,0.0035191999999999997,180.9976157261528,372.1789490477598,1.9735657616729743
3.775765366004336e-05,0.0035528,181.11143960257783,372.1789490477598,1.9735657616729743
3.7834172210581614e-05,0.00356,181.1357757255293,372.1789490477598,1.9735657616729743
3.785967839409436e-05,0.0035624,181.14388349987127,372.1789490477598,1.9735657616729743
3.8165752596247385e-05,0.0035911999999999997,181.24101122038482,372.1789490477598,1.9735657616729743
3.839530824786215e-05,0.0036127999999999998,181.31365777909195,372.1789490477598,1.9735657616729743
3.853984328776774e-05,0.0036263999999999997,181.35931131394887,372.1789490477598,1.9735657616729743
3.8769398939382506e-05,0.0036479999999999998,181.43168286573024,372.1789490477598,1.9735657616729743
3.900745665216819e-05,0.0036704,181.50655854534907,372.1789490477598,1.9735657616729743
3.91094813862192e-05,0.0036799999999999997,181.53859354380913,372.1789490477598,1.9735657616729743
3.921150612027021e-05,0.0036896,181.57059596667006,372.1789490477598,1.9735657616729743
3.9296526731979374e-05,0.0036975999999999997,181.59723985322577,372.1789490477598,1.9735657616729743
3.9534584444765056e-05,0.0037199999999999998,181.6717233973662,372.1789490477598,1.9735657616729743
3.9645111239986986e-05,0.0037304,181.7062455654565,372.1789490477598,1.9735657616729743
3.967061742349973e-05,0.0037327999999999997,181.71420688676253,372.1789490477598,1.9735657616729743
3.978964627989257e-05,0.003744,181.7513333560565,372.1789490477598,1.9735657616729743
3.991717719745633e-05,0.003756,181.79106368318463,372.1789490477598,1.9735657616729743
4.001920193150734e-05,0.0037656,181.8228123134276,372.1789490477598,1.9735657616729743
4.024025552195119e-05,0.0037863999999999997,181.89149292394816,372.1789490477598,1.9735657616729743
4.030827201131853e-05,0.0037928,181.91259579648803,372.1789490477598,1.9735657616729743
4.046981117356595e-05,0.0038079999999999998,181.96265953795,372.1789490477598,1.9735657616729743
4.064835445815521e-05,0.0038247999999999997,182.01790256205788,372.1789490477598,1.9735657616729743
4.080989362040264e-05,0.0038399999999999997,182.06780285633715,372.1789490477598,1.9735657616729743
4.087791010976998e-05,0.0038464,182.0887904537834,372.1789490477598,1.9735657616729743
4.111596782255566e-05,0.0038688,182.1621400339929,372.1789490477598,1.9735657616729743
4.131151522948676e-05,0.0038872,182.2222676505461,372.1789490477598,1.9735657616729743
4.14815564529051e-05,0.0039032,182.2744623654826,372.1789490477598,1.9735657616729743
4.1626091492810694e-05,0.0039168,182.31876229961676,372.1789490477598,1.9735657616729743
4.193216569496371e-05,0.0039456,182.412376385056,372.1789490477598,1.9735657616729743
4.2195729591262146e-05,0.0039704,182.49277517210732,372.1789490477598,1.9735657616729743
4.2357268753509574e-05,0.0039856,182.5419550511522,372.1789490477598,1.9735657616729743
4.353075728538231e-05,0.004096019203840768,182.89704816848106,372.1789490477598,1.9735657616729743
4.5571660146974765e-05,0.004288057611522305,183.50584982664589,372.1789490477598,1.9735657616729743
5.2510729876389095e-05,0.004940988197639528,185.500502570404,372.1789490477598,1.9735657616729743
5.965388989196267e-05,0.005613122624524905,187.44898169756706,372.1789490477598,1.9735657616729743
6.291933447051059e-05,0.005920384076815363,188.3091544607394,372.1789490477598,1.9735657616729743
6.393978590130681e-05,0.006016403280656131,188.574364047233,372.1789490477598,1.9735657616729743
6.822568191065096e-05,0.006419683936787358,189.67068241563237,372.1789490477598,1.9735657616729743
7.047067505840266e-05,0.006630926185237048,190.23420293159765,372.1789490477598,1.9735657616729743
7.149112648919889e-05,0.006726945389077816,190.48802961925122,372.1789490477598,1.9735657616729743
7.394020992310983e-05,0.006957391478295659,191.09151658309827,372.1789490477598,1.9735657616729743
8.29201825141166e-05,0.007802360472094419,193.24055103280404,372.1789490477598,1.9735657616729743
8.802243966809774e-05,0.00828245649129826,194.42107680444897,372.1789490477598,1.9735657616729743
8.945107167121244e-05,0.008416883376675335,194.74680146318337,372.1789490477598,1.9735657616729743
8.985925224353093e-05,0.008455291058211642,194.83949218630553,372.1789490477598,1.9735657616729743
9.128788424664565e-05,0.008589717943588718,195.1626244644279,372.1789490477598,1.9735657616729743
0.0001019005791269264,0.009588317663532707,197.5041632670281,372.1789490477598,1.9735657616729743
0.0001041455722746781,0.009799559911982397,197.98707006839905,372.1789490477598,1.9735657616729743
0.00010720692656706677,0.010087617523504702,198.6390868106626,372.1789490477598,1.9735657616729743
0.00011190100314872939,0.010529305861172233,199.6249152156862,372.1789490477598,1.9735657616729743
0.00011435008658264034,0.010759751950390077,200.13284960246847,372.1789490477598,1.9735657616729743
0.00011781962144734753,0.01108621724344869,200.84521965658922,372.1789490477598,1.9735657616729743
0.00011986052430893997,0.011278255651130227,201.26043920962863,372.1789490477598,1.9735657616729743
0.0001227177883151694,0.011547109421884378,201.83714371947892,372.1789490477598,1.9735657616729743
0.00012475869117676186,0.011739147829565914,202.24587377350122,372.1789490477598,1.9735657616729743
0.00013108549004769843,0.012334466893378675,203.496672322589,372.1789490477598,1.9735657616729743
0.00013516729577088335,0.012718543708741748,204.29115902432804,372.1789490477598,1.9735657616729743
0.0001368000180601573,0.012872174434886977,204.60632695479447,372.1789490477598,1.9735657616729743
0.00014210636550029767,0.013371474294858972,205.6206373869151,372.1789490477598,1.9735657616729743
0.00014659635179580107,0.013793958791758352,206.46741324749593,372.1789490477598,1.9735657616729743
0.00015108633809130445,0.014216443288657732,207.30413266567868,372.1789490477598,1.9735657616729743
0.000159045859251515,0.014965393078615724,208.76395270684614,372.1789490477598,1.9735657616729743
0.00016006631068231125,0.015061412282456492,208.94902637331043,372.1789490477598,1.9735657616729743
0.00016271948440238143,0.01531106221244249,209.42807711642126,372.1789490477598,1.9735657616729743
0.00016598492898092936,0.015618323664732947,210.01351636254168,372.1789490477598,1.9735657616729743
0.00017006673470411425,0.01600240048009602,210.73903665166165,372.1789490477598,1.9735657616729743
0.00017231172785186596,0.01621364272854571,211.13517692602807,372.1789490477598,1.9735657616729743
0.0001776180752920063,0.0167129425885177,212.06359148930963,372.1789490477598,1.9735657616729743
0.000179863068439758,0.016924184836967393,212.4531185600482,372.1789490477598,1.9735657616729743
0.00018088351987055422,0.01702020404080816,212.6295490271847,372.1789490477598,1.9735657616729743
0.00018210806158750972,0.017135427085417085,212.84075401859403,372.1789490477598,1.9735657616729743
0.0001829244227321467,0.0172122424484897,212.98124971891417,372.1789490477598,1.9735657616729743
0.0001876184993138093,0.01765393078615723,213.78440449485953,372.1789490477598,1.9735657616729743
0.0001884348604584463,0.017730746149229846,213.92327979741324,372.1789490477598,1.9735657616729743
0.00019210848560931271,0.01807641528305661,214.54533752088176,372.1789490477598,1.9735657616729743
0.00019884346505256778,0.01871014202840568,215.67385841053652,372.1789490477598,1.9735657616729743
0.00020190481934495648,0.018998199639927986,216.18188416943303,372.1789490477598,1.9735657616729743
0.00020966025021900778,0.019727945589117824,217.45561789972285,372.1789490477598,1.9735657616729743
0.00021435432680067042,0.020169633926785356,218.21763773223108,372.1789490477598,1.9735657616729743
0.00021884431309617382,0.020592118423684736,218.94045924516908,372.1789490477598,1.9735657616729743
0.00022374247996399569,0.021053010602120423,219.72242689879596,372.1789490477598,1.9735657616729743
0.00023619198741970965,0.022224444888977797,221.68045673392115,372.1789490477598,1.9735657616729743
0.0002382328902813021,0.022416483296659333,221.99756499444933,372.1789490477598,1.9735657616729743
0.0002449678697245572,0.023050210042008402,223.03658505459643,372.1789490477598,1.9735657616729743
0.00025088648802317533,0.02360712142428486,223.94050009469572,372.1789490477598,1.9735657616729743
0.0002570091966079526,0.024183236647329465,224.86687552883834,372.1789490477598,1.9735657616729743
0.0002596623703280228,0.024432886577315464,225.2656275010251,372.1789490477598,1.9735657616729743
0.00026884643320518884,0.025297059411882376,226.63381662009556,372.1789490477598,1.9735657616729743
0.0002733364195006922,0.025719543908781756,227.29606461907318,372.1789490477598,1.9735657616729743
0.00027639777379308094,0.026007601520304062,227.74516667115608,372.1789490477598,1.9735657616729743
0.0002780304960823549,0.02616123224644929,227.98389434742785,372.1789490477598,1.9735657616729743
0.00027966321837162887,0.02631486297259452,228.2220758974947,372.1789490477598,1.9735657616729743
0.00028333684352249526,0.026660532106421286,228.7560104417455,372.1789490477598,1.9735657616729743
0.0002859900172425654,0.02691018203640728,229.13995214562914,372.1789490477598,1.9735657616729743
0.00029394953840277603,0.027659131826365275,230.283527718034,372.1789490477598,1.9735657616729743
0.000296398621836687,0.02788957791558312,230.6329590585032,372.1789490477598,1.9735657616729743
0.0003015008789906681,0.028369673934786958,231.35734499166963,372.1789490477598,1.9735657616729743
0.000304766323569216,0.028676935387077416,231.8184440849962,372.1789490477598,1.9735657616729743
0.0003094604001508786,0.029118623724744948,232.47791260341535,372.1789490477598,1.9735657616729743
0.00031231766415710805,0.0293874774954991,232.87741850209161,372.1789490477598,1.9735657616729743
0.00031456265730485974,0.02959871974394879,233.1903168833238,372.1789490477598,1.9735657616729743
0.0003202771853173186,0.030136427285457092,233.9828808413705,372.1789490477598,1.9735657616729743
0.00032456308132666273,0.030539707941588317,234.57368946590452,372.1789490477598,1.9735657616729743
0.00032639989390209596,0.0307125425085017,234.8259608592743,372.1789490477598,1.9735657616729743
0.00033231851220071404,0.031269453890778155,235.63509472867807,372.1789490477598,1.9735657616729743
0.000334767595634625,0.031499899979996,235.96826249078595,372.1789490477598,1.9735657616729743
0.00033619622763773974,0.031634326865373076,236.1621713732571,372.1789490477598,1.9735657616729743
0.00033905349164396916,0.031903180636127224,236.54902774455448,372.1789490477598,1.9735657616729743
0.00034619665165954274,0.0325753150630126,237.51064728999665,372.1789490477598,1.9735657616729743
0.0003478293739488167,0.03272894578915783,237.72935585720973,372.1789490477598,1.9735657616729743
0.0003541561728197533,0.033324264852970596,238.57309661977504,372.1789490477598,1.9735657616729743
0.00035946252025989366,0.03382356471294259,239.27622694509026,372.1789490477598,1.9735657616729743
0.00036211569397996387,0.03407321464292859,239.626273242485,372.1789490477598,1.9735657616729743
0.0003627279648384416,0.034130826165233046,239.70691094117157,372.1789490477598,1.9735657616729743
0.0003682384025647412,0.034649329865973195,240.43027703188903,372.1789490477598,1.9735657616729743
0.00037068748599865215,0.03487977595519104,240.7504166844655,372.1789490477598,1.9735657616729743
0.0003861983477467547,0.03633926785357071,242.75914112115348,372.1789490477598,1.9735657616729743
0.00039313741747616914,0.03699219843968794,243.64756775045672,372.1789490477598,1.9735657616729743
0.0004037501123564498,0.037990798159631925,244.99459877316076,372.1789490477598,1.9735657616729743
0.00040721964722115705,0.03831726345269054,245.43196974790052,372.1789490477598,1.9735657616729743
0.00040946464036890873,0.038528505701140234,245.71420027053492,372.1789490477598,1.9735657616729743
0.00041722007124296,0.03925825165033006,246.6845686210036,372.1789490477598,1.9735657616729743
0.0004190568838183932,0.03943108621724345,246.9133592776183,372.1789490477598,1.9735657616729743
0.00042681231469244457,0.04016083216643329,247.8750839979865,372.1789490477598,1.9735657616729743
0.00043232275241874424,0.04067933586717344,248.5542775447548,372.1789490477598,1.9735657616729743
0.00043538410671113285,0.04096739347869574,248.93014818347828,372.1789490477598,1.9735657616729743
0.00043864955128968073,0.0412746549309862,249.32994256404388,372.1789490477598,1.9735657616729743
0.0004427313570128656,0.041658731746349265,249.82805702997496,372.1789490477598,1.9735657616729743
0.00044375180844366194,0.041754750950190045,249.95230540014606,372.1789490477598,1.9735657616729743
0.00044803770445300605,0.04215803160632127,250.47293639160415,372.1789490477598,1.9735657616729743
0.00045171132960387245,0.04250370074014803,250.91764747551636,372.1789490477598,1.9735657616729743
0.00045477268389626106,0.04279175835167033,251.28716359179606,372.1789490477598,1.9735657616729743
0.00045681358675785365,0.04298379675935188,251.53296886787703,372.1789490477598,1.9735657616729743
0.0004637526564872679,0.0436367273454691,252.36552172439272,372.1789490477598,1.9735657616729743
0.0004702835456443638,0.044251250250050014,253.1446737184355,372.1789490477598,1.9735657616729743
0.0004727326290782746,0.04448169633926785,253.43576632954995,372.1789490477598,1.9735657616729743
0.00047722261537377805,0.044904180836167235,253.96791314480168,372.1789490477598,1.9735657616729743
0.0004815085113831222,0.04530746149229846,254.4740529020882,372.1789490477598,1.9735657616729743
0.0004825289628139184,0.045403480696139226,254.5943030328693,372.1789490477598,1.9735657616729743
0.00048518213653398856,0.04565313062612522,254.90649013178765,372.1789490477598,1.9735657616729743
0.0004868148588232625,0.04580676135227045,255.09827437111895,372.1789490477598,1.9735657616729743
0.0004927334771218806,0.046363672734546904,255.7913992331818,372.1789490477598,1.9735657616729743
0.000495386650841951,0.046613322664532914,256.10105556915494,372.1789490477598,1.9735657616729743
0.0005000807274236135,0.04705501100220044,256.6473292817045,372.1789490477598,1.9735657616729743
0.0005086525194423017,0.04786157231446289,257.639740099312,372.1789490477598,1.9735657616729743
0.0005192652143225826,0.04886017203440689,258.8594481852029,372.1789490477598,1.9735657616729743
0.000522938839473449,0.04920584116823365,259.2793846166655,372.1789490477598,1.9735657616729743
0.0005260001937658376,0.04949389877975595,259.6284534973808,372.1789490477598,1.9735657616729743
0.0005315106314921372,0.0500124024804961,260.2547873500438,372.1789490477598,1.9735657616729743
0.000535388346929163,0.05037727545509102,260.69402359385924,372.1789490477598,1.9735657616729743
0.0005443683195201696,0.05122224444888977,261.7064662353795,372.1789490477598,1.9735657616729743
0.0005457969515232844,0.05135667133426686,261.8669341578995,372.1789490477598,1.9735657616729743
0.0005498787572464693,0.05174074814962992,262.3245137887378,372.1789490477598,1.9735657616729743
0.0005525319309665394,0.05199039807961592,262.6212303478555,372.1789490477598,1.9735657616729743
0.0005582464589789983,0.05252810562112423,263.25843144026635,372.1789490477598,1.9735657616729743
0.000559675090982113,0.0526625325065013,263.4173336082475,372.1789490477598,1.9735657616729743
0.0005606955424129092,0.052758551710342064,263.5307383212208,372.1789490477598,1.9735657616729743
0.0005709000567208717,0.053718743748749756,264.660393101179,372.1789490477598,1.9735657616729743
0.0005731450498686232,0.053929985997199434,264.9078571675116,372.1789490477598,1.9735657616729743
0.0005755941333025342,0.054160432086417284,265.17738722326766,372.1789490477598,1.9735657616729743
0.0005825332030319484,0.054813362672534505,265.938637564138,372.1789490477598,1.9735657616729743
0.000582941383604267,0.05485177035407081,265.983306544763,372.1789490477598,1.9735657616729743
0.0005864109184689742,0.055178235647129426,266.36250163625544,372.1789490477598,1.9735657616729743
0.0005878395504720889,0.055312662532506496,266.5183863554503,372.1789490477598,1.9735657616729743
0.0005894722727613628,0.055466293258651725,266.6963595154875,372.1789490477598,1.9735657616729743
0.0005925336270537516,0.05575435087017404,267.0295418734312,372.1789490477598,1.9735657616729743
0.0005964113424907772,0.05611922384476896,267.45061068133606,372.1789490477598,1.9735657616729743
0.0005986563356385289,0.05633046609321865,267.69389935164685,372.1789490477598,1.9735657616729743
0.0006011054190724398,0.05656091218243649,267.9588997279363,372.1789490477598,1.9735657616729743
0.0006055954053679432,0.05698339667933587,268.4436426905155,372.1789490477598,1.9735657616729743
0.0006106976625219243,0.0574634926985397,268.99278881787643,372.1789490477598,1.9735657616729743
0.0006157999196759054,0.05794358871774355,269.54014850993883,372.1789490477598,1.9735657616729743
0.0006166162808205426,0.05802040408081617,269.62756165768764,372.1789490477598,1.9735657616729743
0.0006253921631253899,0.058846169233846765,270.5644201052833,372.1789490477598,1.9735657616729743
0.0006284535174177787,0.05913422684536908,270.8900231332386,372.1789490477598,1.9735657616729743
0.0006300862397070527,0.05928785757151431,271.06342512556085,372.1789490477598,1.9735657616729743
0.0006327394134271228,0.0595375075015003,271.3448300788473,372.1789490477598,1.9735657616729743
0.0006433521083074034,0.060536107221444285,272.46587827178337,372.1789490477598,1.9735657616729743
0.0006488625460337031,0.061054610922184435,273.0451150055727,372.1789490477598,1.9735657616729743
0.0006539648031876843,0.06153470694138828,273.5797370579832,372.1789490477598,1.9735657616729743
0.000661312053489417,0.062226045209041805,274.3467437656683,372.1789490477598,1.9735657616729743
0.000665393859212602,0.06261012202440489,274.7714223727773,372.1789490477598,1.9735657616729743
0.0006727411095143348,0.06330146029205841,275.53329233508083,372.1789490477598,1.9735657616729743
0.000673761560945131,0.06339747949589918,275.6388503824143,372.1789490477598,1.9735657616729743
0.0006786597278129529,0.06385837167433486,276.14466364604715,372.1789490477598,1.9735657616729743
0.000681312901533023,0.06410802160432086,276.41805128388347,372.1789490477598,1.9735657616729743
0.0006847824363977302,0.06443448689737948,276.7749325222858,372.1789490477598,1.9735657616729743
0.0006866192489731636,0.06460732146429286,276.96358412165733,372.1789490477598,1.9735657616729743
0.0006904969644101892,0.06497219443888778,277.36120347785214,372.1789490477598,1.9735657616729743
0.0006913133255548261,0.06504900980196039,277.4448017414053,372.1789490477598,1.9735657616729743
0.000694578770133374,0.06535627125425085,277.7788105066305,372.1789490477598,1.9735657616729743
0.0006982523952842405,0.06570194038807761,278.1538392104524,372.1789490477598,1.9735657616729743
0.0007060078261582918,0.06643168633726745,278.943048826586,372.1789490477598,1.9735657616729743
0.0007119264444569098,0.06698859771954391,279.5430677387282,372.1789490477598,1.9735657616729743
0.0007149877987492986,0.06727665533106622,279.8526587947468,372.1789490477598,1.9735657616729743
0.0007188655141863243,0.06764152830566114,280.24406632965565,372.1789490477598,1.9735657616729743
0.0007219268684787129,0.06792958591718344,280.5524909402837,372.1789490477598,1.9735657616729743
0.0007243759519126238,0.06816003200640128,280.7988635331,372.1789490477598,1.9735657616729743
0.0007272332159188533,0.06842888577715543,281.0858880139924,372.1789490477598,1.9735657616729743
0.0007309068410697196,0.0687745549109822,281.4542740730099,372.1789490477598,1.9735657616729743
0.0007329477439313122,0.06896659331866374,281.65862095577427,372.1789490477598,1.9735657616729743
0.0007358050079375415,0.06923544708941788,281.9443341721158,372.1789490477598,1.9735657616729743
0.0007449890708147077,0.07009961992398481,282.8597812412229,372.1789490477598,1.9735657616729743
0.0007484586056794147,0.07042608521704341,283.20447003564146,372.1789490477598,1.9735657616729743
0.0007496831473963703,0.07054130826165234,283.3259760509857,372.1789490477598,1.9735657616729743
0.0007545813142641922,0.07100220044008802,283.8112280776813,372.1789490477598,1.9735657616729743
0.0007672349120060654,0.07219283856771355,285.05914385835433,372.1789490477598,1.9735657616729743
0.0007747862525939574,0.07290338067613523,285.80004381772267,372.1789490477598,1.9735657616729743
0.0007825416834680086,0.07363312662532506,286.55804254629817,372.1789490477598,1.9735657616729743
0.0007915216560590155,0.07447809561912383,287.4320747416246,372.1789490477598,1.9735657616729743
0.000796011642354519,0.07490058011602321,287.8676399899434,372.1789490477598,1.9735657616729743
0.0007986648160745891,0.07515023004600921,288.12456908660374,372.1789490477598,1.9735657616729743
0.0008019302606531371,0.07545749149829967,288.4403330077249,372.1789490477598,1.9735657616729743
0.0008072366080932774,0.07595679135827166,288.9523819683751,372.1789490477598,1.9735657616729743
0.0008109102332441437,0.07630246049209842,289.30610867540474,372.1789490477598,1.9735657616729743
0.0008172370321150804,0.07689777955591119,289.91384316806705,372.1789490477598,1.9735657616729743
0.0008184615738320357,0.0770130026005201,290.0312569638275,372.1789490477598,1.9735657616729743
0.0008211147475521061,0.07726265253050611,290.2854187493204,372.1789490477598,1.9735657616729743
0.000823563830986017,0.07749309861972395,290.51974549734007,372.1789490477598,1.9735657616729743
0.0008258088241337686,0.07770434086817364,290.7343063893743,372.1789490477598,1.9735657616729743
0.0008366256093002086,0.07872214442888578,291.7649281363131,372.1789490477598,1.9735657616729743
0.0008429524081711452,0.07931746349269854,292.3653359231166,372.1789490477598,1.9735657616729743
0.0008466260333220118,0.07966313262652532,292.71315329306776,372.1789490477598,1.9735657616729743
0.0008480546653251264,0.07979755951190239,292.8482565845868,372.1789490477598,1.9735657616729743
0.0008507078390451965,0.08004720944188838,293.0989274408084,372.1789490477598,1.9735657616729743
0.0008582591796330886,0.08075775155031006,293.81071188242385,372.1789490477598,1.9735657616729743
0.000860300082494681,0.0809497899579916,294.00266626484523,372.1789490477598,1.9735657616729743
0.00086601461050714,0.0814874974994999,294.53919601788874,372.1789490477598,1.9735657616729743
0.0008672391522240954,0.08160272054410883,294.6539868402545,372.1789490477598,1.9735657616729743
0.0008709127773749619,0.08194838967793559,294.99798062842086,372.1789490477598,1.9735657616729743
0.0008756068539566244,0.08239007801560312,295.4367058499427,372.1789490477598,1.9735657616729743
0.000877647756818217,0.08258211642328467,295.6271697371084,372.1789490477598,1.9735657616729743
0.0008809132013967647,0.08288937787557511,295.93155306274036,372.1789490477598,1.9735657616729743
0.0008825459236860387,0.08304300860172034,296.08357968692474,372.1789490477598,1.9735657616729743
0.000885199097406109,0.08329265853170635,296.3303892164845,372.1789490477598,1.9735657616729743
0.0008864236391230644,0.08340788157631526,296.4442039851134,372.1789490477598,1.9735657616729743
0.0008896890837016123,0.08371514302860572,296.7474106523641,372.1789490477598,1.9735657616729743
0.0008907095351324085,0.08381116223244649,296.8420736878673,372.1789490477598,1.9735657616729743
0.000894383160283275,0.08415683136627326,297.1825109633901,372.1789490477598,1.9735657616729743
0.0008954036117140712,0.08425285057011403,297.27698003531793,372.1789490477598,1.9735657616729743
0.000896015882572549,0.08431046209241849,297.3336413243344,372.1789490477598,1.9735657616729743
0.0008982608757203008,0.08452170434086818,297.54127032067663,372.1789490477598,1.9735657616729743
0.0008996895077234154,0.08465613122624525,297.6732924998904,372.1789490477598,1.9735657616729743
0.0009031590425881226,0.08498259651930387,297.9935778670337,372.1789490477598,1.9735657616729743
0.0009058122163081928,0.08523224644928987,298.23817830090235,372.1789490477598,1.9735657616729743
0.0009078531191697852,0.0854242848569714,298.4261423952966,372.1789490477598,1.9735657616729743
0.0009100981123175369,0.08563552710542109,298.6327126629446,372.1789490477598,1.9735657616729743
0.0009123431054652887,0.08584676935387078,298.83908429783816,372.1789490477598,1.9735657616729743
0.0009131594666099255,0.08592358471694339,298.91407941369323,372.1789490477598,1.9735657616729743
0.000914384008326881,0.08603880776155232,299.0265230792437,372.1789490477598,1.9735657616729743
0.0009172412723331104,0.08630766153230647,299.28866349396674,372.1789490477598,1.9735657616729743
0.0009192821751947029,0.086499699939988,299.475711704889,372.1789490477598,1.9735657616729743
0.0009249967032071617,0.0870374074814963,299.99858706099224,372.1789490477598,1.9735657616729743
0.0009262212449241172,0.08715263052610522,300.11046770524916,372.1789490477598,1.9735657616729743
0.0009266294254964357,0.08719103820764153,300.1477484320554,372.1789490477598,1.9735657616729743
0.0009315275923642575,0.08765193038607721,300.59461875206193,372.1789490477598,1.9735657616729743
0.0009337725855120092,0.0878631726345269,300.7991279629845,372.1789490477598,1.9735657616729743
0.0009366298495182388,0.08813202640528106,301.0591352923712,372.1789490477598,1.9735657616729743
0.0009378543912351942,0.08824724944988999,301.17047228956676,372.1789490477598,1.9735657616729743
0.000945201641536927,0.08893858771754351,301.8373075708706,372.1789490477598,1.9735657616729743
0.0009488752666877933,0.08928425685137027,302.1699669107933,372.1789490477598,1.9735657616729743
0.0009500998084047489,0.0893994798959792,302.28074168920006,372.1789490477598,1.9735657616729743
0.0009525488918386599,0.08962992598519705,302.5021243434229,372.1789490477598,1.9735657616729743
0.0009556102461310486,0.08991798359671935,302.77854074295817,372.1789490477598,1.9735657616729743
0.0009631615867189406,0.09062852570514103,303.4588954091639,372.1789490477598,1.9735657616729743
0.0009668352118698069,0.09097419483896779,303.7891263136821,372.1789490477598,1.9735657616729743
0.0009721415593099475,0.0914734946989398,304.2652638953152,372.1789490477598,1.9735657616729743
0.0009743865524576991,0.09168473694738949,304.46640146970435,372.1789490477598,1.9735657616729743
0.0009774479067500878,0.09197279455891179,304.7403889568809,372.1789490477598,1.9735657616729743
0.0009841828861933428,0.09260652130426085,305.3419861529112,372.1789490477598,1.9735657616729743
0.0009884687822026871,0.09300980196039209,305.7239849178132,372.1789490477598,1.9735657616729743
0.0009937751296428274,0.09350910182036408,306.19604198015736,372.1789490477598,1.9735657616729743
0.0009978569353660122,0.09389317863572715,306.5584941834152,372.1789490477598,1.9735657616729743
0.0009986732965106492,0.09396999399879977,306.63091518667574,372.1789490477598,1.9735657616729743
0.0010007141993722416,0.0941620324064813,306.8118667578208,372.1789490477598,1.9735657616729743
0.0010017346508030378,0.09425805161032207,306.90228856708467,372.1789490477598,1.9735657616729743
0.0010056123662400636,0.09462292458491699,307.24556431776847,372.1789490477598,1.9735657616729743
0.0010086737205324521,0.09491098219643929,307.51620696728605,372.1789490477598,1.9735657616729743
0.001015204609689548,0.0955255051010202,308.09250960473855,372.1789490477598,1.9735657616729743
0.0010250009434251918,0.09644728945789158,308.95425991327056,372.1789490477598,1.9735657616729743
0.0010321441034407653,0.09711942388477696,309.5805958596564,372.1789490477598,1.9735657616729743
0.001034185006302358,0.0973114622924585,309.7592381886301,372.1789490477598,1.9735657616729743
0.0010374504508809056,0.09761872374474895,310.0447802008338,372.1789490477598,1.9735657616729743
0.0010464304234719126,0.09846369273854771,310.8282190704962,372.1789490477598,1.9735657616729743
0.0010535735834874861,0.0991358271654331,311.4495382879843,372.1789490477598,1.9735657616729743
0.0010558185766352379,0.09934706941388279,311.6444704538662,372.1789490477598,1.9735657616729743
0.0010590840212137858,0.09965433086617324,311.9277198339351,372.1789490477598,1.9735657616729743
0.0010613290143615375,0.09986557311462294,312.12225623807296,372.1789490477598,1.9735657616729743
0.0010615331046476967,0.09988477695539108,312.1399334040487,372.1789490477598,1.9735657616729743