File: datasets/aisi_316_L/data/M1/train_17.csv
Time(s),Strain(%),Stress(MPa),Temp(C),Log_SR(s-1)
0.0,0.0,0.0,371.51907815219886,1.4695186275660133
3.7992633230544905e-07,1.12e-05,1.92269455,371.51907815219886,1.4695186275660133
4.884767129641488e-07,1.44e-05,2.4720358499999997,371.51907815219886,1.4695186275660133
9.498158307636226e-07,2.8e-05,4.806736375,371.51907815219886,1.4695186275660133
1.4111549485630963e-06,4.1599999999999995e-05,7.1414368999999995,371.51907815219886,1.4695186275660133
1.628255709880496e-06,4.8e-05,8.2401195,371.51907815219886,1.4695186275660133
1.8453564711978952e-06,5.4399999999999994e-05,9.338802099999999,371.51907815219886,1.4695186275660133
2.0895948276799695e-06,6.159999999999999e-05,10.574820025,371.51907815219886,1.4695186275660133
3.3379242052550165e-06,9.839999999999999e-05,16.892244975,371.51907815219886,1.4695186275660133
4.23346484568929e-06,0.0001248,21.4243107,371.51907815219886,1.4695186275660133
5.753170174911085e-06,0.0001696,29.1150889,371.51907815219886,1.4695186275660133
6.024546126557834e-06,0.00017759999999999998,30.488442149999997,371.51907815219886,1.4695186275660133
6.187371697545884e-06,0.0001824,31.312454099999997,371.51907815219886,1.4695186275660133
6.892949171827432e-06,0.00020319999999999998,34.88317255,371.51907815219886,1.4695186275660133
7.435701075120931e-06,0.0002192,37.62987905,371.51907815219886,1.4695186275660133
7.788489812261706e-06,0.0002296,39.415238275,371.51907815219886,1.4695186275660133
7.97845297841443e-06,0.0002352,40.37658555,371.51907815219886,1.4695186275660133
8.19555373973183e-06,0.0002416,41.47526815,371.51907815219886,1.4695186275660133
8.575480072037277e-06,0.00025279999999999996,43.397962699999994,371.51907815219886,1.4695186275660133
8.738305643025327e-06,0.0002576,44.22197464999999,371.51907815219886,1.4695186275660133
9.172507165660127e-06,0.0002704,46.41933985,371.51907815219886,1.4695186275660133
9.715259068953625e-06,0.00028639999999999997,49.166046349999995,371.51907815219886,1.4695186275660133
9.823809449612326e-06,0.0002896,49.71538765,371.51907815219886,1.4695186275660133
1.02851485674118e-05,0.0003032,52.050088175,371.51907815219886,1.4695186275660133
1.0447974138399848e-05,0.000308,52.874100125,371.51907815219886,1.4695186275660133
1.0719350090046598e-05,0.000316,54.247453375,371.51907815219886,1.4695186275660133
1.1316377183669446e-05,0.0003336,57.268830525,371.51907815219886,1.4695186275660133
1.2293330609597744e-05,0.00036239999999999997,62.21290222499999,371.51907815219886,1.4695186275660133
1.2863220108055917e-05,0.0003792,65.09694405,371.51907815219886,1.4695186275660133
1.3677347962996166e-05,0.0004032,69.2170038,371.51907815219886,1.4695186275660133
1.3894448724313565e-05,0.0004096,70.31568639999999,371.51907815219886,1.4695186275660133
1.4002999104972265e-05,0.0004128,70.8650277,371.51907815219886,1.4695186275660133
1.4708576579253813e-05,0.00043359999999999997,74.43574615,371.51907815219886,1.4695186275660133
1.5766942790676133e-05,0.00046479999999999997,79.791823825,371.51907815219886,1.4695186275660133
1.5875493171334834e-05,0.000468,80.341165125,371.51907815219886,1.4695186275660133
1.6092593932652233e-05,0.0004744,81.43984772499999,371.51907815219886,1.4695186275660133
1.620114431331093e-05,0.00047759999999999995,81.98918902499999,371.51907815219886,1.4695186275660133
1.633683228913431e-05,0.0004816,82.67586565,371.51907815219886,1.4695186275660133
1.652679545528703e-05,0.00048719999999999997,83.637212925,371.51907815219886,1.4695186275660133
1.6798171406933783e-05,0.0004952,85.010566175,371.51907815219886,1.4695186275660133
1.706954735858053e-05,0.0005032,86.383919425,371.51907815219886,1.4695186275660133
1.8426427116814277e-05,0.0005432,93.250685675,371.51907815219886,1.4695186275660133
1.864352787813168e-05,0.0005496,94.349368275,371.51907815219886,1.4695186275660133
1.8806353449119726e-05,0.0005543999999999999,95.17338022499999,371.51907815219886,1.4695186275660133
1.9620481304059974e-05,0.0005784,99.293439975,371.51907815219886,1.4695186275660133
1.9837582065377376e-05,0.0005848,100.392122575,371.51907815219886,1.4695186275660133
2.0597434729988274e-05,0.0006072,104.23751167500001,371.51907815219886,1.4695186275660133
2.114018663328177e-05,0.0006232,106.984218175,371.51907815219886,1.4695186275660133
2.211714005921007e-05,0.000652,111.928289875,371.51907815219886,1.4695186275660133
2.255134158184487e-05,0.0006648,114.125655075,371.51907815219886,1.4695186275660133
2.333833184162044e-05,0.0006879999999999999,118.10837949999998,371.51907815219886,1.4695186275660133
2.3474019817443818e-05,0.000692,118.795056125,371.51907815219886,1.4695186275660133
2.388108374491394e-05,0.000704,120.855086,371.51907815219886,1.4695186275660133
2.4071046911066666e-05,0.0007096,121.81643327500001,371.51907815219886,1.4695186275660133
2.4776624385348212e-05,0.0007304,125.387151725,371.51907815219886,1.4695186275660133
2.4858037170842235e-05,0.0007327999999999999,125.79915769999998,371.51907815219886,1.4695186275660133
2.5455064264465083e-05,0.0007503999999999999,128.82053484999997,371.51907815219886,1.4695186275660133
2.621491692907598e-05,0.0007727999999999999,132.66592394999998,371.51907815219886,1.4695186275660133
2.6513430475887407e-05,0.0007815999999999999,134.176612525,371.51907815219886,1.4695186275660133
2.762607187763908e-05,0.0008144,139.80736084999998,371.51907815219886,1.4695186275660133
2.7816035043791805e-05,0.00082,140.768708125,371.51907815219886,1.4695186275660133
2.8413062137414653e-05,0.0008376,143.790085275,371.51907815219886,1.4695186275660133
2.8603025303567378e-05,0.0008432,144.75143255,371.51907815219886,1.4695186275660133
2.8765850874555428e-05,0.000848,145.5754445,371.51907815219886,1.4695186275660133
2.9037226826202176e-05,0.000856,146.94879775,371.51907815219886,1.4695186275660133
2.9145777206860877e-05,0.0008592,147.49813905,371.51907815219886,1.4695186275660133
2.9200052397190226e-05,0.0008608,147.7728097,371.51907815219886,1.4695186275660133
2.960711632466035e-05,0.0008728,149.83283957499998,371.51907815219886,1.4695186275660133
2.9688529110154373e-05,0.0008751999999999999,150.24484554999998,371.51907815219886,1.4695186275660133
3.0041317847295148e-05,0.0008856,152.030204775,371.51907815219886,1.4695186275660133
3.0339831394106573e-05,0.0008944,153.54089335,371.51907815219886,1.4695186275660133
3.0719757726412026e-05,0.0009056,155.4635879,371.51907815219886,1.4695186275660133
3.10725464635528e-05,0.0009159999999999999,157.248947125,371.51907815219886,1.4695186275660133
3.13981976055289e-05,0.0009256,158.896971025,371.51907815219886,1.4695186275660133
3.158816077168162e-05,0.0009312,159.8583183,371.51907815219886,1.4695186275660133
3.185953672332837e-05,0.0009392,161.23167155,371.51907815219886,1.4695186275660133
3.280935255409199e-05,0.0009672,166.038407925,371.51907815219886,1.4695186275660133
3.308072850573874e-05,0.0009752,167.41176117499998,371.51907815219886,1.4695186275660133
3.351493002837354e-05,0.000988,168.70635598703842,371.51907815219886,1.4695186275660133
3.411195712199639e-05,0.0010056,168.8030575687462,371.51907815219886,1.4695186275660133
3.4383333073643135e-05,0.0010136,168.8467944027782,371.51907815219886,1.4695186275660133
3.479039700111326e-05,0.0010256,168.912148068964,371.51907815219886,1.4695186275660133
3.5387424094736114e-05,0.0010432,169.00746322676662,371.51907815219886,1.4695186275660133
3.5875900807700254e-05,0.0010576,169.0849827299531,371.51907815219886,1.4695186275660133
3.650006549648778e-05,0.001076,169.18343899385587,371.51907815219886,1.4695186275660133
3.669002866264051e-05,0.0010816,169.21327332519505,371.51907815219886,1.4695186275660133
3.742274373208673e-05,0.0011032,169.3277886765616,371.51907815219886,1.4695186275660133
3.76669820885688e-05,0.0011103999999999999,169.36576570029155,371.51907815219886,1.4695186275660133
3.8616797919332425e-05,0.0011384,169.51255012379457,371.51907815219886,1.4695186275660133
3.934951298877865e-05,0.00116,169.62482379121406,371.51907815219886,1.4695186275660133
4.000081527273085e-05,0.0011792,169.7239399094555,371.51907815219886,1.4695186275660133
4.116773186481187e-05,0.0012136,169.89996303914364,371.51907815219886,1.4695186275660133
4.1411970221293945e-05,0.0012208,169.9365576105179,371.51907815219886,1.4695186275660133
4.209041010041082e-05,0.0012408,170.03777017963836,371.51907815219886,1.4695186275660133
4.2334648456892896e-05,0.001248,170.074050691609,371.51907815219886,1.4695186275660133
4.287740036018639e-05,0.001264,170.15438306501008,371.51907815219886,1.4695186275660133
4.3447289858644566e-05,0.0012808,170.23830640263145,371.51907815219886,1.4695186275660133
4.3772941000620666e-05,0.0012904,170.2860698292595,371.51907815219886,1.4695186275660133
4.439710568940819e-05,0.0013088,170.3772308099259,371.51907815219886,1.4695186275660133
4.5265508734677785e-05,0.0013344,170.5032363434477,371.51907815219886,1.4695186275660133
4.5618297471818556e-05,0.0013448,170.55415636859584,371.51907815219886,1.4695186275660133
4.586253582830063e-05,0.001352,170.58931876365997,371.51907815219886,1.4695186275660133
4.6242462160606086e-05,0.0013632,170.64387101268727,371.51907815219886,1.4695186275660133
4.667666368324088e-05,0.0013759999999999998,170.70600285739263,371.51907815219886,1.4695186275660133
4.711086520587568e-05,0.0013888,170.7679096980608,371.51907815219886,1.4695186275660133
4.8060681036639305e-05,0.0014168,170.9025603862663,371.51907815219886,1.4695186275660133
4.835919458345073e-05,0.0014256,170.94466430354885,371.51907815219886,1.4695186275660133
4.8739120915756176e-05,0.0014368,170.99810479935442,371.51907815219886,1.4695186275660133
4.9824624722343175e-05,0.0014688,171.1499039867504,371.51907815219886,1.4695186275660133
5.0177413459483946e-05,0.0014792,171.1989602870973,371.51907815219886,1.4695186275660133
5.0937266124094845e-05,0.0015015999999999999,171.3041654635194,371.51907815219886,1.4695186275660133
5.259265942914002e-05,0.0015504,171.53126621420472,371.51907815219886,1.4695186275660133
5.324396171309222e-05,0.0015696,171.6198509928703,371.51907815219886,1.4695186275660133
5.4085227163197136e-05,0.0015944,171.7336500196072,371.51907815219886,1.4695186275660133
5.427519032934986e-05,0.0015999999999999999,171.75925078814538,371.51907815219886,1.4695186275660133
5.495363020846673e-05,0.00162,171.8503982125042,371.51907815219886,1.4695186275660133
5.5143593374619456e-05,0.0016255999999999998,171.8758407121578,371.51907815219886,1.4695186275660133
5.555065730208958e-05,0.0016376,171.93024553720622,371.51907815219886,1.4695186275660133
5.598485882472439e-05,0.0016504,171.9881062580955,371.51907815219886,1.4695186275660133
5.6527610728017884e-05,0.0016664,172.0601866361965,371.51907815219886,1.4695186275660133
5.7667389724934225e-05,0.0017,172.21068273347538,371.51907815219886,1.4695186275660133
5.788449048625163e-05,0.0017063999999999998,172.23921665698384,371.51907815219886,1.4695186275660133
5.853579277020383e-05,0.0017255999999999999,172.32456904948847,371.51907815219886,1.4695186275660133
5.9024269483167975e-05,0.00174,172.38834049500485,371.51907815219886,1.4695186275660133
5.9295645434814726e-05,0.001748,172.42368012914247,371.51907815219886,1.4695186275660133
6.0462562026895744e-05,0.0017824,172.5749273916587,371.51907815219886,1.4695186275660133
6.114100190601262e-05,0.0018024,172.6623384896145,371.51907815219886,1.4695186275660133
6.1276689881836e-05,0.0018063999999999999,172.67977522686877,371.51907815219886,1.4695186275660133
6.162947861897677e-05,0.0018168,172.72504041648628,371.51907815219886,1.4695186275660133
6.173802899963547e-05,0.00182,172.73894782196385,371.51907815219886,1.4695186275660133
6.233505609325833e-05,0.0018376,172.81526876647584,371.51907815219886,1.4695186275660133
6.371907344665673e-05,0.0018784,172.99110648890164,371.51907815219886,1.4695186275660133
6.466888927742036e-05,0.0019064,173.11091843312664,371.51907815219886,1.4695186275660133
6.523877877587853e-05,0.0019232,173.1824762177407,371.51907815219886,1.4695186275660133
6.564584270334866e-05,0.0019352,173.23343974516274,371.51907815219886,1.4695186275660133
6.68941720809237e-05,0.001972,173.38896480620465,371.51907815219886,1.4695186275660133
6.76540247455346e-05,0.0019944,173.48307817352983,371.51907815219886,1.4695186275660133
6.84138774101455e-05,0.0020168,173.57678019062456,371.51907815219886,1.4695186275660133
6.876666614728627e-05,0.0020272,173.62014664670238,371.51907815219886,1.4695186275660133
6.903804209893304e-05,0.0020352,173.65344644278036,371.51907815219886,1.4695186275660133
6.920086766992106e-05,0.0020399999999999997,173.6734018176885,371.51907815219886,1.4695186275660133
6.94993812167325e-05,0.0020488,173.7099391762169,371.51907815219886,1.4695186275660133
7.09105361652956e-05,0.0020904,173.88183945266226,371.51907815219886,1.4695186275660133
7.180607680572986e-05,0.0021168,173.9902383393392,371.51907815219886,1.4695186275660133
7.272875504132882e-05,0.002144,174.10137200420857,371.51907815219886,1.4695186275660133
7.324436934945764e-05,0.0021592,174.16323658319322,371.51907815219886,1.4695186275660133
7.432987315604463e-05,0.0021912,174.2929253613323,371.51907815219886,1.4695186275660133
7.495403784483215e-05,0.0022096,174.36716192384438,371.51907815219886,1.4695186275660133
7.590385367559577e-05,0.0022375999999999997,174.47966968185332,371.51907815219886,1.4695186275660133
7.595812886592513e-05,0.0022392,174.48608206211853,371.51907815219886,1.4695186275660133
7.671798153053602e-05,0.0022616,174.57566858545485,371.51907815219886,1.4695186275660133
7.720645824350017e-05,0.002276,174.63307723714635,371.51907815219886,1.4695186275660133
7.823768685975782e-05,0.0023063999999999997,174.75381016241622,371.51907815219886,1.4695186275660133
7.886185154854534e-05,0.0023247999999999997,174.82658389398748,371.51907815219886,1.4695186275660133
7.90246771195334e-05,0.0023296,174.8455313590952,371.51907815219886,1.4695186275660133
7.926891547601547e-05,0.0023368,174.87392403371817,371.51907815219886,1.4695186275660133
8.04358320680965e-05,0.0023712,175.00910981077664,371.51907815219886,1.4695186275660133
8.105999675688402e-05,0.0023896,175.08110440942863,371.51907815219886,1.4695186275660133
8.179271182633025e-05,0.0024112,175.16534451791907,371.51907815219886,1.4695186275660133
8.195553739731829e-05,0.0024159999999999997,175.184024514541,371.51907815219886,1.4695186275660133
8.255256449094114e-05,0.0024335999999999997,175.252394353601,371.51907815219886,1.4695186275660133
8.274252765709387e-05,0.0024392,175.27410791751961,371.51907815219886,1.4695186275660133
8.366520589269282e-05,0.0024664,175.37929849996502,371.51907815219886,1.4695186275660133
8.382803146368086e-05,0.0024712,175.39781448210212,371.51907815219886,1.4695186275660133
8.409940741532761e-05,0.0024792,175.42864331309937,371.51907815219886,1.4695186275660133
8.51849112219146e-05,0.0025112,175.55157263436422,371.51907815219886,1.4695186275660133
8.594476388652552e-05,0.0025336,175.63725990931567,371.51907815219886,1.4695186275660133
8.624327743333693e-05,0.0025423999999999998,175.6708418694889,371.51907815219886,1.4695186275660133
8.716595566893588e-05,0.0025696,175.77435519632937,371.51907815219886,1.4695186275660133
8.74644692157473e-05,0.0025784,175.80775319463052,371.51907815219886,1.4695186275660133
8.80072211190408e-05,0.0025943999999999997,175.868363157983,371.51907815219886,1.4695186275660133
8.868566099815767e-05,0.0026144,175.94392100239227,371.51907815219886,1.4695186275660133
8.911986252079247e-05,0.0026271999999999997,175.9921597443936,371.51907815219886,1.4695186275660133
8.925555049661585e-05,0.0026311999999999998,176.0072155425533,371.51907815219886,1.4695186275660133
8.960833923375663e-05,0.0026416,176.0463189017097,371.51907815219886,1.4695186275660133
9.025964151770883e-05,0.0026608,176.11835234162376,371.51907815219886,1.4695186275660133
9.053101746935557e-05,0.0026688,176.14830641275776,371.51907815219886,1.4695186275660133
9.118231975330777e-05,0.002688,176.22005366871394,371.51907815219886,1.4695186275660133
9.150797089528388e-05,0.0026976,176.25585232638153,371.51907815219886,1.4695186275660133
9.283771305835293e-05,0.0027367999999999997,176.4015174780862,371.51907815219886,1.4695186275660133
9.365184091329318e-05,0.0027608,176.4902987059588,371.51907815219886,1.4695186275660133
9.476448231504485e-05,0.0027936,176.61114780140105,371.51907815219886,1.4695186275660133
9.509013345702096e-05,0.0028032,176.64641342051686,371.51907815219886,1.4695186275660133
9.712545309437158e-05,0.0028631999999999998,176.8657658819744,371.51907815219886,1.4695186275660133
9.78581681638178e-05,0.0028848,176.94429296229504,371.51907815219886,1.4695186275660133
9.848233285260532e-05,0.0029032,177.01100570214035,371.51907815219886,1.4695186275660133
9.86180208284287e-05,0.0029072,177.0254866283049,371.51907815219886,1.4695186275660133
9.9594974254357e-05,0.002936,177.12952087559094,371.51907815219886,1.4695186275660133
0.00010005631337215646,0.0029495999999999997,177.17850974418684,371.51907815219886,1.4695186275660133
0.00010040910210929725,0.00296,177.2159124041213,371.51907815219886,1.4695186275660133
0.00010119609236907281,0.0029831999999999997,177.29916491287534,371.51907815219886,1.4695186275660133
0.00010203735781917774,0.003008,177.38788023742978,371.51907815219886,1.4695186275660133
0.00010236300896115385,0.0030176,177.42214501348002,371.51907815219886,1.4695186275660133
0.00010258010972247123,0.0030239999999999998,177.44496458217856,371.51907815219886,1.4695186275660133
0.0001042355030275164,0.0030727999999999997,177.61834867775667,371.51907815219886,1.4695186275660133
0.00010439832859850446,0.0030775999999999998,177.63534463506858,371.51907815219886,1.4695186275660133
0.00010483253012113925,0.0030903999999999997,177.68061672229103,371.51907815219886,1.4695186275660133
0.00010591803392772625,0.0031224,177.79347817216646,371.51907815219886,1.4695186275660133
0.00010646078583101976,0.0031384,177.8497396695226,371.51907815219886,1.4695186275660133
0.00010675929937783117,0.0031471999999999997,177.880635807917,371.51907815219886,1.4695186275660133
0.00010700353773431326,0.0031544,177.9058894141464,371.51907815219886,1.4695186275660133
0.00010716636330530131,0.0031592,177.92271266367734,371.51907815219886,1.4695186275660133
0.00010732918887628935,0.0031639999999999997,177.93952594745474,371.51907815219886,1.4695186275660133
0.00010874034382485245,0.0032056,178.0848267266391,371.51907815219886,1.4695186275660133
0.0001092288205378166,0.0032199999999999998,178.1349515704882,371.51907815219886,1.4695186275660133
0.00011004294839275685,0.003244,178.2182991397027,371.51907815219886,1.4695186275660133
0.00011042287472506229,0.0032551999999999998,178.25711234048703,371.51907815219886,1.4695186275660133
0.00011110131460417917,0.0032752,178.32629233600304,371.51907815219886,1.4695186275660133
0.00011188830486395474,0.0032984,178.40633506334424,371.51907815219886,1.4695186275660133
0.00011218681841076616,0.0033071999999999997,178.43663862234882,371.51907815219886,1.4695186275660133
0.00011256674474307162,0.0033184,178.4751613458071,371.51907815219886,1.4695186275660133
0.00011310949664636511,0.0033344,178.53010596257974,371.51907815219886,1.4695186275660133
0.00011362511095449394,0.0033496,178.58220818639785,371.51907815219886,1.4695186275660133
0.00011395076209647003,0.0033591999999999997,178.6150673500379,371.51907815219886,1.4695186275660133
0.00011443923880943419,0.0033736,178.66428751043028,371.51907815219886,1.4695186275660133
0.00011536191704503313,0.0034008,178.75703594576882,371.51907815219886,1.4695186275660133
0.00011604035692415,0.0034208,178.8250488588828,371.51907815219886,1.4695186275660133
0.00011644742085162012,0.0034327999999999997,178.86578217181847,371.51907815219886,1.4695186275660133
0.000117125860730737,0.0034528,178.93354783767657,371.51907815219886,1.4695186275660133
0.00011739723668238376,0.0034608,178.96061121943765,371.51907815219886,1.4695186275660133
0.00011769575022919518,0.0034695999999999998,178.99035277498115,371.51907815219886,1.4695186275660133
0.00011869984125028815,0.0034992,179.09017735232644,371.51907815219886,1.4695186275660133
0.00011964965708105177,0.0035272,179.18430333356548,371.51907815219886,1.4695186275660133
0.0001216849767184024,0.0035872,179.38502617386655,371.51907815219886,1.4695186275660133
0.00012225486621686058,0.003604,179.44099338211095,371.51907815219886,1.4695186275660133
0.00012274334292982473,0.0036184,179.48888434068664,371.51907815219886,1.4695186275660133
0.00012315040685729483,0.0036303999999999998,179.52873671944207,371.51907815219886,1.4695186275660133
0.00012344892040410627,0.0036392,179.5579291536549,371.51907815219886,1.4695186275660133
0.00012355747078476496,0.0036423999999999996,179.56853775692005,371.51907815219886,1.4695186275660133
0.00012393739711707042,0.0036536,179.60563927796233,371.51907815219886,1.4695186275660133
0.00012499576332849273,0.0036848,179.70876035642075,371.51907815219886,1.4695186275660133
0.00012524000168497482,0.003692,179.73250910291708,371.51907815219886,1.4695186275660133
0.00012597271675442103,0.0037135999999999996,179.80364720405825,371.51907815219886,1.4695186275660133
0.00012667829422870257,0.0037343999999999997,179.87199820075816,371.51907815219886,1.4695186275660133
0.00012792662360627761,0.0037711999999999997,179.99256427810914,371.51907815219886,1.4695186275660133
0.00012852365069990047,0.0037887999999999997,180.05006404203368,371.51907815219886,1.4695186275660133
0.00012939205374517008,0.0038144,180.13351445493126,371.51907815219886,1.4695186275660133
0.00012985339286296954,0.003828,180.17775863037315,371.51907815219886,1.4695186275660133
0.00013034186957593368,0.0038423999999999997,180.22453863785773,371.51907815219886,1.4695186275660133
0.00013091175907439185,0.0038591999999999997,180.27902898515205,371.51907815219886,1.4695186275660133
0.00013137309819219136,0.0038728,180.32307249202407,371.51907815219886,1.4695186275660133
0.00013153592376317937,0.0038775999999999997,180.33860285220882,371.51907815219886,1.4695186275660133
0.0001320515380713082,0.0038927999999999996,180.38773293578743,371.51907815219886,1.4695186275660133
0.00013267570276009574,0.0039112,180.4471062088451,371.51907815219886,1.4695186275660133
0.00013310990428273053,0.0039239999999999995,180.48834512304012,371.51907815219886,1.4695186275660133
0.00013376120656668274,0.0039432,180.55010526268862,371.51907815219886,1.4695186275660133
0.00013419540808931753,0.0039559999999999994,180.59121354602502,371.51907815219886,1.4695186275660133
0.00013699084096430725,0.004038407681536307,180.85464152079652,371.51907815219886,1.4695186275660133
0.0001474137620917679,0.0043456691338267656,181.81889216958305,371.51907815219886,1.4695186275660133
0.00016174527864202634,0.004768153630726146,183.10237073018789,371.51907815219886,1.4695186275660133
0.00017737966033321736,0.005229045809161833,184.45290908377564,371.51907815219886,1.4695186275660133
0.0001819396883264814,0.005363472694538908,184.8379611315512,371.51907815219886,1.4695186275660133
0.00020669412600420045,0.006093218643728746,186.86599270612587,371.51907815219886,1.4695186275660133
0.00021320845170886337,0.006285257051410282,187.38364009398967,371.51907815219886,1.4695186275660133
0.00023535715910471728,0.006938187637527506,189.09923619096315,371.51907815219886,1.4695186275660133
0.0002483858105140431,0.007322264452890578,190.07897713804894,371.51907815219886,1.4695186275660133
0.00025880873164150375,0.007629525905181036,190.84841045208253,371.51907815219886,1.4695186275660133
0.00028291173674875657,0.00834006801360272,192.58285183032737,371.51907815219886,1.4695186275660133
0.0003135290675606723,0.009242648529705941,194.705033708816,371.51907815219886,1.4695186275660133
0.0003317691795337285,0.009780356071214243,195.9308780162802,371.51907815219886,1.4695186275660133
0.000344146398372588,0.010145229045809162,196.7477635688776,371.51907815219886,1.4695186275660133
0.00036303794291611045,0.010702140428085618,197.9728332495121,371.51907815219886,1.4695186275660133
0.00037802089203683515,0.01114382876575315,198.926845260212,371.51907815219886,1.4695186275660133
0.0003995181668622228,0.011777555511102222,200.2702744842095,371.51907815219886,1.4695186275660133
0.000411243953130616,0.012123224644928985,200.9911574787987,371.51907815219886,1.4695186275660133
0.0004255754696808744,0.012545709141828365,201.86144011913564,371.51907815219886,1.4695186275660133
0.0004294840651036722,0.012660932186437287,202.09679651512428,371.51907815219886,1.4695186275660133
0.0004444670142243969,0.013102620524104821,202.99136152046194,371.51907815219886,1.4695186275660133
0.000453587070210925,0.013371474294858972,203.53012310733683,371.51907815219886,1.4695186275660133
0.0004659642890497845,0.013736347269453891,204.25459007249154,371.51907815219886,1.4695186275660133
0.0004835529684523744,0.01425485097019404,205.27131536257866,371.51907815219886,1.4695186275660133
0.0004998387827140317,0.01473494698939788,206.19993940920335,371.51907815219886,1.4695186275660133
0.0005167760295461553,0.015234246849369875,207.15327486320822,371.51907815219886,1.4695186275660133
0.000542833332364807,0.01600240048009602,208.5964843719706,371.51907815219886,1.4695186275660133
0.0005584677140559979,0.016463292658531706,209.44944366042327,371.51907815219886,1.4695186275660133
0.0005708449328948575,0.016828165633126627,210.11811589867227,371.51907815219886,1.4695186275660133
0.000578662123740453,0.01705861172234447,210.53752324509836,371.51907815219886,1.4695186275660133
0.0005851764494451159,0.017250650130026003,210.88534406215874,371.51907815219886,1.4695186275660133
0.0005884336122974473,0.017346669333866773,211.05868794806466,371.51907815219886,1.4695186275660133
0.0005916907751497789,0.017442688537707543,211.23165802553623,371.51907815219886,1.4695186275660133
0.000594296505431644,0.017519503900780158,211.369766866767,371.51907815219886,1.4695186275660133
0.0006040679939886384,0.01780756151230246,211.88558510798495,371.51907815219886,1.4695186275660133
0.0006203538082502957,0.018287657531506303,212.73810859510323,371.51907815219886,1.4695186275660133
0.0006431539482166158,0.01895979195839168,213.91711984765269,371.51907815219886,1.4695186275660133
0.000665954088182936,0.019631926385277054,215.07993858255162,371.51907815219886,1.4695186275660133
0.0006900570932901888,0.02034246849369874,216.29244476072012,371.51907815219886,1.4695186275660133
0.000703737177269981,0.020745749149829965,216.97327385206427,371.51907815219886,1.4695186275660133
0.0007226287218135035,0.021302660532106422,217.90504085151596,371.51907815219886,1.4695186275660133
0.0007324002103704977,0.021590718143628725,218.3832585074434,371.51907815219886,1.4695186275660133
0.0007454288617798236,0.021974794958991798,219.01702915022187,371.51907815219886,1.4695186275660133
0.0007486860246321552,0.022070814162832568,219.1747949802023,371.51907815219886,1.4695186275660133
0.000766274704034745,0.022589317863572714,220.02214926542007,371.51907815219886,1.4695186275660133
0.0007701832994575427,0.022704540908181636,220.20941613320363,371.51907815219886,1.4695186275660133
0.0007871205462896663,0.02320384076815363,221.01666025945352,371.51907815219886,1.4695186275660133
0.0008170864445311158,0.024087217443488698,222.42845799147398,371.51907815219886,1.4695186275660133
0.0008314179610813742,0.024509701940388078,223.0965142173717,371.51907815219886,1.4695186275660133
0.0008411894496383684,0.02479775955191038,223.54943416111732,371.51907815219886,1.4695186275660133
0.0008600809941818909,0.02535467093418684,224.41930293326092,371.51907815219886,1.4695186275660133
0.0008750639433026156,0.02579635927185437,225.10391150005717,371.51907815219886,1.4695186275660133
0.0008887440272824078,0.0261996399279856,225.72500668273258,371.51907815219886,1.4695186275660133
0.0009082870043963966,0.026775755151030207,226.60585622626706,371.51907815219886,1.4695186275660133
0.0009291328466513179,0.027390278055611124,227.53732063336372,371.51907815219886,1.4695186275660133
0.0009551901494699696,0.02815843168633727,228.6902678425384,371.51907815219886,1.4695186275660133
0.0009597501774632336,0.028292858571714343,228.89076592796135,371.51907815219886,1.4695186275660133
0.0009838531825704863,0.029003400680136026,229.94443271743685,371.51907815219886,1.4695186275660133
0.0009929732385570145,0.029272254450890177,230.34048603392398,371.51907815219886,1.4695186275660133
0.001014470513382402,0.02990598119623925,231.2684690599758,371.51907815219886,1.4695186275660133
0.0010307563276440593,0.030386077215443088,231.96638936067393,371.51907815219886,1.4695186275660133
0.001043784979053385,0.03077015403080616,232.52163408715998,371.51907815219886,1.4695186275660133
0.0010698422818720367,0.0315383076615323,233.62408025354074,371.51907815219886,1.4695186275660133
0.001077008040147166,0.031749549909981994,233.92541065228193,371.51907815219886,1.4695186275660133
0.001090688124126958,0.03215283056611322,234.49851537971153,371.51907815219886,1.4695186275660133
0.0010952481521202225,0.0322872574514903,234.68892640858238,371.51907815219886,1.4695186275660133
0.0010985053149725537,0.03238327665533107,234.82474504122638,371.51907815219886,1.4695186275660133
0.001114791129234211,0.03286337267453491,235.50149651070484,371.51907815219886,1.4695186275660133
0.0011173968595160763,0.03294018803760752,235.60941790774478,371.51907815219886,1.4695186275660133
0.001130425510925402,0.033324264852970596,236.14755961364094,371.51907815219886,1.4695186275660133
0.0011388941343414638,0.03357391478295659,236.49605505322688,371.51907815219886,1.4695186275660133
0.0011460598926165929,0.03378515703140628,236.7901471623963,371.51907815219886,1.4695186275660133
0.0011708143302943121,0.03451490298059612,237.8006292760417,371.51907815219886,1.4695186275660133
0.0011753743582875761,0.034649329865973195,237.98585835015749,371.51907815219886,1.4695186275660133
0.0011812372514217726,0.034822164432886576,238.22359872340488,371.51907815219886,1.4695186275660133
0.0011831915491331715,0.03487977595519104,238.30274319074778,371.51907815219886,1.4695186275660133
0.0011851458468445707,0.0349373874774955,238.38183669201499,371.51907815219886,1.4695186275660133
0.0011903573074083008,0.03509101820364073,238.59250441457743,371.51907815219886,1.4695186275660133
0.00119752306568343,0.03530226045209042,238.88158614834103,371.51907815219886,1.4695186275660133
0.0012001287959652952,0.03537907581516303,238.9865394154289,371.51907815219886,1.4695186275660133
0.0012164146102269526,0.035859171834366876,239.64049523603458,371.51907815219886,1.4695186275660133
0.0012366090199114074,0.036454490898179634,240.44667740961563,371.51907815219886,1.4695186275660133
0.001250940536461666,0.03687697539507902,241.01569477048463,371.51907815219886,1.4695186275660133
0.0012678777832937894,0.03737627525505101,241.68490237318738,371.51907815219886,1.4695186275660133
0.0012730892438575197,0.03752990598119624,241.89010978529834,371.51907815219886,1.4695186275660133
0.001284163597555447,0.037856371274254855,242.32509093712477,371.51907815219886,1.4695186275660133
0.001286117895266846,0.03791398279655932,242.40170020669217,371.51907815219886,1.4695186275660133
0.0013050094398103682,0.03847089417883577,243.1399307028273,371.51907815219886,1.4695186275660133
0.0013160837935082949,0.038797359471894374,243.57074883328016,371.51907815219886,1.4695186275660133
0.0013401867986155478,0.03950790158031606,244.50355469251713,371.51907815219886,1.4695186275660133
0.0013558211803067386,0.039968793758751744,245.1051214326888,371.51907815219886,1.4695186275660133
0.001361032640870469,0.040122424484896974,245.30504168820437,371.51907815219886,1.4695186275660133
0.001377969887702593,0.04062172434486898,245.95273037666135,371.51907815219886,1.4695186275660133
0.0013838327808367893,0.04079455891178235,246.17620595386978,371.51907815219886,1.4695186275660133
0.001396209999675649,0.04115943188637727,246.6467787476899,371.51907815219886,1.4695186275660133
0.001413798679078239,0.04167793558711742,247.31269839197063,371.51907815219886,1.4695186275660133
0.0014170558419305701,0.04177395479095819,247.43566146950067,371.51907815219886,1.4695186275660133
0.001423570167635233,0.04196599319863972,247.68125743950807,371.51907815219886,1.4695186275660133
0.0014313873584808287,0.04219643928785757,247.97539479877764,371.51907815219886,1.4695186275660133
0.0014339930887626938,0.04227325465093018,248.0733012800447,371.51907815219886,1.4695186275660133
0.0014483246053129523,0.042695739147829564,248.6105517984206,371.51907815219886,1.4695186275660133
0.001456141796158548,0.042926185237047415,248.90272350951292,371.51907815219886,1.4695186275660133
0.0014678675824269412,0.04327185437087418,249.33983672016618,371.51907815219886,1.4695186275660133
0.0014776390709839353,0.043559911982396476,249.70305843181603,371.51907815219886,1.4695186275660133
0.0014919705875341938,0.04398239647929586,250.23409368681607,371.51907815219886,1.4695186275660133
0.0015245422160575083,0.04494258851770354,251.4336484370132,371.51907815219886,1.4695186275660133
0.0015336622720440365,0.04521144228845769,251.7677272656499,371.51907815219886,1.4695186275660133
0.0015382223000373005,0.04534586917383476,251.93447607102328,371.51907815219886,1.4695186275660133
0.0015610224400036206,0.04601800360072014,252.76534571180846,371.51907815219886,1.4695186275660133
0.0015779596868357442,0.04651730346069213,253.3795026388516,371.51907815219886,1.4695186275660133
0.001594896933667868,0.04701660332066414,253.9910939470759,371.51907815219886,1.4695186275660133
0.0015981540965201995,0.047112622524504905,254.10841670756483,371.51907815219886,1.4695186275660133
0.0016092284502181261,0.04743908781756351,254.50661840323298,371.51907815219886,1.4695186275660133
0.0016163942084932554,0.0476503300660132,254.7637089470169,371.51907815219886,1.4695186275660133
0.001635285753036778,0.04820724144828965,255.43937141523722,371.51907815219886,1.4695186275660133
0.0016411486461709746,0.04838007601520304,255.64843990015746,371.51907815219886,1.4695186275660133
0.0016606916232849635,0.048956191238247654,256.34324065070115,371.51907815219886,1.4695186275660133
0.0016672059489896264,0.04914822964592919,256.5741313198767,371.51907815219886,1.4695186275660133
0.0016750231398352216,0.04937867573514702,256.8507362075196,371.51907815219886,1.4695186275660133
0.001681537465539885,0.04957071414282857,257.08085591240695,371.51907815219886,1.4695186275660133
0.0016847946283922162,0.04966673334666934,257.1957853656261,371.51907815219886,1.4695186275660133
0.0017036861729357387,0.05022364472894579,257.8606753164478,371.51907815219886,1.4695186275660133
0.0017251834477611265,0.050857371474294866,258.61378653348044,371.51907815219886,1.4695186275660133
0.0017356063688885872,0.051164632926585324,258.977613188888,371.51907815219886,1.4695186275660133
0.0017466807225865139,0.05149109821964393,259.3632465944478,371.51907815219886,1.4695186275660133
0.0017629665368481713,0.05197119423884777,259.92862681824374,371.51907815219886,1.4695186275660133
0.0017688294299823676,0.05214402880576115,260.1316645925457,371.51907815219886,1.4695186275660133
0.0017766466208279633,0.052374474894979,260.4019738209453,371.51907815219886,1.4695186275660133
0.0017838123791030925,0.05258571714342869,260.64935008208664,371.51907815219886,1.4695186275660133
0.0017864181093849576,0.0526625325065013,260.7392089589193,371.51907815219886,1.4695186275660133
0.001792932435089621,0.052854570914182844,260.96363280039867,371.51907815219886,1.4695186275660133
0.0018215954681901373,0.0536995399079816,261.94734382826954,371.51907815219886,1.4695186275660133
0.001832018389317598,0.054006801360272055,262.3035578273286,371.51907815219886,1.4695186275660133
0.0018391841475927273,0.05421804360872175,262.54799659923776,371.51907815219886,1.4695186275660133
0.0018782701018207047,0.05537027405481096,263.87481750138323,371.51907815219886,1.4695186275660133
0.0018815272646730361,0.055466293258651725,263.98489749998186,371.51907815219886,1.4695186275660133
0.0018886930229481654,0.05567753550710142,264.2268122320141,371.51907815219886,1.4695186275660133
0.0018952073486528285,0.05586957391478296,264.4464242734003,371.51907815219886,1.4695186275660133
0.00189846451150516,0.05596559311862373,264.55611988113196,371.51907815219886,1.4695186275660133
0.001903024539498424,0.0561000200040008,264.70957050175303,371.51907815219886,1.4695186275660133
0.0019232189491828788,0.05669533906781356,265.3874211011396,371.51907815219886,1.4695186275660133
0.0019395047634445362,0.057175435087017404,265.9320550354687,371.51907815219886,1.4695186275660133
0.0019779392851020476,0.05830846169233847,267.2103680450425,371.51907815219886,1.4695186275660133
0.0020013908576388337,0.058999799959991994,267.98559789654405,371.51907815219886,1.4695186275660133
0.0020294024581688844,0.0598255651130226,268.9069392340503,371.51907815219886,1.4695186275660133
0.002039173946725879,0.060113622724544916,269.2271688043664,371.51907815219886,1.4695186275660133
0.002050899732994272,0.06045929185837168,269.61065540968394,371.51907815219886,1.4695186275660133
0.0020541568958466036,0.060555311062212444,269.71702759278764,371.51907815219886,1.4695186275660133
0.0020587169238398674,0.060689737947589514,269.86583820407526,371.51907815219886,1.4695186275660133
0.0020606712215512665,0.06074734946989398,269.9295748224442,371.51907815219886,1.4695186275660133
0.002068488412396862,0.06097779555911183,270.1842859081915,371.51907815219886,1.4695186275660133
0.0020880313895108504,0.061553910782156426,270.81942667946043,371.51907815219886,1.4695186275660133
0.002104317203772508,0.06203400680136027,271.3469415815519,371.51907815219886,1.4695186275660133
0.0021127858271885696,0.06228365673134627,271.62061995554467,371.51907815219886,1.4695186275660133
0.0021245116134569627,0.06262932586517303,271.9988540096295,371.51907815219886,1.4695186275660133
0.002137540264866289,0.06301340268053611,272.4181604855845,371.51907815219886,1.4695186275660133
0.0021525232139870134,0.06345509101820364,272.89913268817173,371.51907815219886,1.4695186275660133
0.0021616432699735418,0.06372394478895779,273.19125917292894,371.51907815219886,1.4695186275660133
0.002174020488812401,0.06408881776355271,273.58694887874736,371.51907815219886,1.4695186275660133
0.0021837919773693955,0.06437687537507501,273.8987152297271,371.51907815219886,1.4695186275660133
0.002191609168214991,0.06460732146429286,274.14773676855333,371.51907815219886,1.4695186275660133
0.0022085464150471148,0.06510662132426485,274.686098163172,371.51907815219886,1.4695186275660133
0.002209849280188047,0.06514502900580116,274.7274437647445,371.51907815219886,1.4695186275660133
0.0022176664710336427,0.06537547509501901,274.9753180280548,371.51907815219886,1.4695186275660133
0.00222157506645644,0.06549069813962792,275.0991273574543,371.51907815219886,1.4695186275660133
0.0022658724812481485,0.06679655931186237,276.496413941044,371.51907815219886,1.4695186275660133
0.0022789011326574743,0.06718063612722545,276.90534778197383,371.51907815219886,1.4695186275660133
0.002284112593221205,0.06733426685337068,277.0686658970057,371.51907815219886,1.4695186275660133
0.002289324053784935,0.06748789757951591,277.2318387513305,371.51907815219886,1.4695186275660133
0.002295838379489598,0.06767993598719745,277.4356012460485,371.51907815219886,1.4695186275660133
0.002312124193751255,0.06816003200640128,277.9440234676025,371.51907815219886,1.4695186275660133
0.0023355757662880416,0.06885137027405482,278.67370467290397,371.51907815219886,1.4695186275660133
0.0023375300639994407,0.06890898179635928,278.73438215965325,371.51907815219886,1.4695186275660133
0.002352513013120165,0.0693506701340268,279.1989207364509,371.51907815219886,1.4695186275660133
0.0023942046976300076,0.07057971594318864,280.4855164086327,371.51907815219886,1.4695186275660133
0.002397461860482339,0.0706757351470294,280.5856622145263,371.51907815219886,1.4695186275660133
0.002408536214180266,0.07100220044008802,280.92576175221416,371.51907815219886,1.4695186275660133
0.0024196105678781937,0.07132866573314664,281.2652519658045,371.51907815219886,1.4695186275660133
0.0024319877867170527,0.07169353870774155,281.6439658973939,371.51907815219886,1.4695186275660133
0.002438502112421716,0.0718855771154231,281.8429870562849,371.51907815219886,1.4695186275660133
0.002444365005555912,0.07205841168233647,282.0219288826953,371.51907815219886,1.4695186275660133
0.0024586965221061706,0.07248089617923585,282.45863901184305,371.51907815219886,1.4695186275660133
0.0024749823363678283,0.0729609921984397,282.9536972672915,371.51907815219886,1.4695186275660133
0.0024886624203476204,0.07336427285457092,283.36856517001473,371.51907815219886,1.4695186275660133
0.0024984339089046143,0.07365233046609322,283.6643550406138,371.51907815219886,1.4695186275660133
0.002503645369468345,0.07380596119223845,283.8219251439996,371.51907815219886,1.4695186275660133
0.0025186283185890694,0.07424764952990598,284.27422823073533,371.51907815219886,1.4695186275660133
0.002540125593414457,0.07488137627525505,284.92135620733984,371.51907815219886,1.4695186275660133
0.002545988486548654,0.07505421084216844,285.0974745121742,371.51907815219886,1.4695186275660133
0.00256422859852171,0.07559191838367674,285.64438933974895,371.51907815219886,1.4695186275660133
0.0025674857613740415,0.0756879375875175,285.7418928313121,371.51907815219886,1.4695186275660133
0.0025831201430652324,0.07614882976595319,286.20923973622536,371.51907815219886,1.4695186275660133
0.00258702873848803,0.07626405281056212,286.32590393331526,371.51907815219886,1.4695186275660133
0.0025954973619040918,0.07651370274054811,286.57844079888076,371.51907815219886,1.4695186275660133
0.002603314552749688,0.07674414882976596,286.8112666753423,371.51907815219886,1.4695186275660133
0.002631326153279738,0.07756991398279657,287.64332967411804,371.51907815219886,1.4695186275660133
0.0026417490744071984,0.07787717543508701,287.95205176127905,371.51907815219886,1.4695186275660133
0.0026547777258165246,0.0782612522504501,288.33728716099864,371.51907815219886,1.4695186275660133
0.00266259491666212,0.07849169833966793,288.5680744980252,371.51907815219886,1.4695186275660133
0.002679532163494244,0.07899099819963994,289.0672091386018,371.51907815219886,1.4695186275660133
0.0026945151126149683,0.07943268653730746,289.5077265471453,371.51907815219886,1.4695186275660133
0.0027134066571584906,0.07998959791958392,290.06180228497254,371.51907815219886,1.4695186275660133
0.002716012387440356,0.08006641328265654,290.1381082874174,371.51907815219886,1.4695186275660133
0.0027466297182522715,0.08096899379875976,291.0325757184512,371.51907815219886,1.4695186275660133
0.0027590069370911313,0.08133386677335468,291.3930641804205,371.51907815219886,1.4695186275660133
0.0027687784256481256,0.08162192438487698,291.67721501613386,371.51907815219886,1.4695186275660133
0.0027824585096279174,0.0820252050410082,292.0743700193076,371.51907815219886,1.4695186275660133
0.002794835728466777,0.08239007801560312,292.4330450299993,371.51907815219886,1.4695186275660133
0.0028130758404398336,0.08292778555711143,292.9604916435382,371.51907815219886,1.4695186275660133
0.0028150301381512327,0.08298539707941589,293.01692455910364,371.51907815219886,1.4695186275660133
0.0028528132272382773,0.0840992198439688,294.10497566002425,371.51907815219886,1.4695186275660133
0.002857373255231541,0.08423364672934587,294.23591102533493,371.51907815219886,1.4695186275660133
0.00287691623234553,0.08480976195239048,294.796142073627,371.51907815219886,1.4695186275660133
0.002896459209459519,0.0853858771754351,295.3548908628477,371.51907815219886,1.4695186275660133
0.0029088364282983787,0.08575075015003002,295.70800475116505,371.51907815219886,1.4695186275660133
0.002926425107700968,0.08626925385077015,296.2087918204182,371.51907815219886,1.4695186275660133
0.0029407566242512263,0.08669173834766954,296.6159731977763,371.51907815219886,1.4695186275660133
0.00295248241051962,0.0870374074814963,296.9485462767873,371.51907815219886,1.4695186275660133
0.002977236848197339,0.08776715343068614,297.6489581213946,371.51907815219886,1.4695186275660133
0.002986356904183867,0.0880360072014403,297.9064315999032,371.51907815219886,1.4695186275660133
0.0029967798253113277,0.08834326865373075,298.20031180405766,371.51907815219886,1.4695186275660133
0.003003945583586457,0.08855451090218044,298.4021232480942,371.51907815219886,1.4695186275660133
0.0030130656395729845,0.08882336467293458,298.6587028449002,371.51907815219886,1.4695186275660133
0.0030163228024253164,0.08891938387677537,298.7502649893735,371.51907815219886,1.4695186275660133
0.0030234885607004452,0.08913062612522504,298.9515660842979,371.51907815219886,1.4695186275660133
0.003028700021264176,0.08928425685137027,299.0978500322815,371.51907815219886,1.4695186275660133
0.0030436829703849007,0.08972594518903781,299.5178705610289,371.51907815219886,1.4695186275660133
0.003052803026371429,0.08999479895979197,299.7731404561721,371.51907815219886,1.4695186275660133
0.003067134542921687,0.09041728345669134,300.17367878558446,371.51907815219886,1.4695186275660133
0.003075603166337749,0.09066693338667733,300.4100174466986,371.51907815219886,1.4695186275660133
0.0030847232223242768,0.09093578715743149,300.66425235537343,371.51907815219886,1.4695186275660133
0.0031212034462703895,0.09201120224044809,301.6782741894588,371.51907815219886,1.4695186275660133
0.003135534962820648,0.09243368673734748,302.07537400058845,371.51907815219886,1.4695186275660133
0.0031550779399346367,0.09300980196039209,302.61573486955746,371.51907815219886,1.4695186275660133
0.003194163894162614,0.0941620324064813,303.6925563775383,371.51907815219886,1.4695186275660133
0.003200026787296811,0.09433486697339469,303.85363528596383,371.51907815219886,1.4695186275660133
0.003211752573565204,0.09468053610722145,304.17544822915573,371.51907815219886,1.4695186275660133
0.003216964034128934,0.09483416683336668,304.3183290892688,371.51907815219886,1.4695186275660133
0.003221524062122198,0.09496859371874375,304.4432758072232,371.51907815219886,1.4695186275660133
0.00322999268553826,0.09521824364872974,304.6751368685735,371.51907815219886,1.4695186275660133
0.0032358555786724565,0.09539107821564313,304.83551719986076,371.51907815219886,1.4695186275660133
0.003239112741524788,0.0954870974194839,304.9245684138816,371.51907815219886,1.4695186275660133
0.0032508385277931814,0.09583276655331066,305.2448640238134,371.51907815219886,1.4695186275660133
0.00326517004434344,0.09625525105021004,305.63572520599797,371.51907815219886,1.4695186275660133
0.0032775472631822993,0.09662012402480497,305.9727490078667,371.51907815219886,1.4695186275660133
0.0032808044260346308,0.09671614322864573,306.0613569383249,371.51907815219886,1.4695186275660133
0.00328797018430976,0.09692738547709542,306.2561737108284,371.51907815219886,1.4695186275660133
0.0033224961105444736,0.09794518903780756,307.1925252652404,371.51907815219886,1.4695186275660133
0.003329010436249136,0.0981372274454891,307.36876902204267,371.51907815219886,1.4695186275660133
0.00334594768308126,0.0986365273054611,307.8263744643914,371.51907815219886,1.4695186275660133
0.0033518105762154566,0.09880936187237448,307.9845657515058,371.51907815219886,1.4695186275660133
0.0033720049858999117,0.09940468093618725,308.52862275074864,371.51907815219886,1.4695186275660133
0.0033798221767455073,0.09963512702540508,308.73888412478806,371.51907815219886,1.4695186275660133
0.0033895936653025012,0.09992318463692738,309.0014443210264,371.51907815219886,1.4695186275660133