File: datasets/aisi_316_L/data/M1/train_96.csv
Time(s),Strain(%),Stress(MPa),Temp(C),Log_SR(s-1)
0.0,0.0,0.0,35.1620820009709,4.22703616449803
7.114511431877221e-10,1.2e-05,2.34588375,35.1620820009709,4.22703616449803
8.063112956127516e-10,1.3599999999999999e-05,2.65866825,35.1620820009709,4.22703616449803
2.3240737344132254e-09,3.92e-05,7.663220249999999,35.1620820009709,4.22703616449803
2.798374496538373e-09,4.7199999999999995e-05,9.227142749999999,35.1620820009709,4.22703616449803
3.6521158683636395e-09,6.159999999999999e-05,12.042203249999998,35.1620820009709,4.22703616449803
5.02758807852657e-09,8.48e-05,16.5775785,35.1620820009709,4.22703616449803
5.833899374139321e-09,9.839999999999999e-05,19.23624675,35.1620820009709,4.22703616449803
6.6876407459645875e-09,0.00011279999999999999,22.051307249999997,35.1620820009709,4.22703616449803
6.877361050814647e-09,0.000116,22.67687625,35.1620820009709,4.22703616449803
7.825962575064941e-09,0.00013199999999999998,25.804721249999997,35.1620820009709,4.22703616449803
9.533445318715476e-09,0.0001608,31.434842250000003,35.1620820009709,4.22703616449803
1.005517615705314e-08,0.0001696,33.155157,35.1620820009709,4.22703616449803
1.2616400272528939e-08,0.0002128,41.6003385,35.1620820009709,4.22703616449803
1.3612431872991749e-08,0.0002296,44.884575749999996,35.1620820009709,4.22703616449803
1.5367344692854798e-08,0.0002592,50.671089,35.1620820009709,4.22703616449803
1.8497729722880775e-08,0.000312,60.9929775,35.1620820009709,4.22703616449803
1.8782310180155863e-08,0.0003168,61.931331,35.1620820009709,4.22703616449803
1.935147109470604e-08,0.00032639999999999996,63.808037999999996,35.1620820009709,4.22703616449803
1.9636051551981128e-08,0.0003312,64.7463915,35.1620820009709,4.22703616449803
1.98732019330437e-08,0.00033519999999999996,65.52835275,35.1620820009709,4.22703616449803
2.1865265133969324e-08,0.00036879999999999997,72.09682724999999,35.1620820009709,4.22703616449803
2.2956156886857165e-08,0.0003872,75.693849,35.1620820009709,4.22703616449803
2.3620177953832373e-08,0.0003984,77.8833405,35.1620820009709,4.22703616449803
2.456877947808267e-08,0.0004144,81.0111855,35.1620820009709,4.22703616449803
2.4853359935357757e-08,0.0004192,81.949539,35.1620820009709,4.22703616449803
2.5612241154757994e-08,0.000432,84.451815,35.1620820009709,4.22703616449803
2.603911184067063e-08,0.0004392,85.85934525,35.1620820009709,4.22703616449803
2.8979776565846543e-08,0.0004888,95.55566474999999,35.1620820009709,4.22703616449803
2.959636755660924e-08,0.0004992,97.588764,35.1620820009709,4.22703616449803
3.016552847115942e-08,0.0005088,99.46547100000001,35.1620820009709,4.22703616449803
3.0497539004647016e-08,0.0005143999999999999,100.56021674999998,35.1620820009709,4.22703616449803
3.1256420224047256e-08,0.0005272,103.06249275,35.1620820009709,4.22703616449803
3.196787136723498e-08,0.0005392,105.4083765,35.1620820009709,4.22703616449803
3.2442172129360125e-08,0.0005472,106.97229899999999,35.1620820009709,4.22703616449803
3.3627924034673e-08,0.0005672,110.88210525000001,35.1620820009709,4.22703616449803
3.433937517786072e-08,0.0005792,113.227989,35.1620820009709,4.22703616449803
3.49085360924109e-08,0.0005888,115.104696,35.1620820009709,4.22703616449803
3.623657822636131e-08,0.0006112,119.483679,35.1620820009709,4.22703616449803
3.7185179750611606e-08,0.0006272,122.61152399999999,35.1620820009709,4.22703616449803
3.751719028409921e-08,0.0006328,123.70626975,35.1620820009709,4.22703616449803
3.7849200817586814e-08,0.0006384,124.8010155,35.1620820009709,4.22703616449803
3.950925348502483e-08,0.0006663999999999999,130.27474425,35.1620820009709,4.22703616449803
4.03629948568501e-08,0.0006808,133.08980474999998,35.1620820009709,4.22703616449803
4.0837295618975244e-08,0.0006887999999999999,134.65372724999997,35.1620820009709,4.22703616449803
4.1643606914588e-08,0.0007023999999999999,137.31239549999998,35.1620820009709,4.22703616449803
4.2355058057775723e-08,0.0007144,139.65827925,35.1620820009709,4.22703616449803
4.368310019172614e-08,0.0007368,144.03726225,35.1620820009709,4.22703616449803
4.448941148733888e-08,0.0007503999999999999,146.69593049999997,35.1620820009709,4.22703616449803
4.510600247810158e-08,0.0007608,148.72902975,35.1620820009709,4.22703616449803
4.572259346886427e-08,0.0007712,150.762129,35.1620820009709,4.22703616449803
4.5959743849926845e-08,0.0007752,151.54409024999998,35.1620820009709,4.22703616449803
4.629175438341445e-08,0.0007808,152.638836,35.1620820009709,4.22703616449803
4.6813485221752117e-08,0.0007896,154.35915075,35.1620820009709,4.22703616449803
4.74300762125148e-08,0.0007999999999999999,156.39225,35.1620820009709,4.22703616449803
4.780951682221492e-08,0.0008064,157.643388,35.1620820009709,4.22703616449803
4.847353788919013e-08,0.0008175999999999999,159.8328795,35.1620820009709,4.22703616449803
4.913755895616534e-08,0.0008288,162.022371,35.1620820009709,4.22703616449803
4.994387025177809e-08,0.0008424,164.68103925,35.1620820009709,4.22703616449803
5.070275147117833e-08,0.0008552,167.18331525,35.1620820009709,4.22703616449803
5.103476200466593e-08,0.0008608,168.278061,35.1620820009709,4.22703616449803
5.1509062766791076e-08,0.0008688,169.8419835,35.1620820009709,4.22703616449803
5.2552524443466404e-08,0.0008864,173.282613,35.1620820009709,4.22703616449803
5.4876598177879625e-08,0.0009256,180.94583325,35.1620820009709,4.22703616449803
5.5730339549704897e-08,0.00094,183.76089375,35.1620820009709,4.22703616449803
5.67263711501677e-08,0.0009568,187.045131,35.1620820009709,4.22703616449803
5.7674972674418005e-08,0.0009728,190.172976,35.1620820009709,4.22703616449803
5.8196703512755666e-08,0.0009816,191.89329075,35.1620820009709,4.22703616449803
5.905044488458093e-08,0.000996,194.70835125,35.1620820009709,4.22703616449803
6.028362686610632e-08,0.0010168,198.77454975,35.1620820009709,4.22703616449803
6.047334717095637e-08,0.0010199999999999999,199.40011874999996,35.1620820009709,4.22703616449803
6.090021785686901e-08,0.0010272,200.807649,35.1620820009709,4.22703616449803
6.142194869520667e-08,0.001036,202.52796375,35.1620820009709,4.22703616449803
6.213339983839439e-08,0.0010479999999999999,204.87384749999998,35.1620820009709,4.22703616449803
6.30820013626447e-08,0.001064,208.00169250000002,35.1620820009709,4.22703616449803
6.360373220098236e-08,0.0010728,209.72200725000002,35.1620820009709,4.22703616449803
6.431518334417007e-08,0.0010848,212.06789099999997,35.1620820009709,4.22703616449803
6.469462395387019e-08,0.0010911999999999999,213.31902899999997,35.1620820009709,4.22703616449803
6.573808563054551e-08,0.0011087999999999998,216.75965849999997,35.1620820009709,4.22703616449803
6.607009616403312e-08,0.0011144,217.85440425,35.1620820009709,4.22703616449803
6.682897738343336e-08,0.0011271999999999999,220.35668024999998,35.1620820009709,4.22703616449803
6.79198691363212e-08,0.0011455999999999999,223.95370199999996,35.1620820009709,4.22703616449803
7.010165264209688e-08,0.0011824,231.14774549999998,35.1620820009709,4.22703616449803
7.161941508089735e-08,0.0012079999999999999,236.15229749999997,35.1620820009709,4.22703616449803
7.218857599544752e-08,0.0012175999999999999,238.02900449999999,35.1620820009709,4.22703616449803
7.294745721484778e-08,0.0012304,240.5312805,35.1620820009709,4.22703616449803
7.318460759591034e-08,0.0012343999999999999,241.31324174999997,35.1620820009709,4.22703616449803
7.380119858667304e-08,0.0012448,243.34634099999997,35.1620820009709,4.22703616449803
7.403834896773561e-08,0.0012488,244.12830225,35.1620820009709,4.22703616449803
7.579326178759865e-08,0.0012783999999999998,249.91481549999997,35.1620820009709,4.22703616449803
7.678929338806148e-08,0.0012952,253.19905275000002,35.1620820009709,4.22703616449803
7.740588437882416e-08,0.0013055999999999999,255.23215199999999,35.1620820009709,4.22703616449803
7.797504529337433e-08,0.0013151999999999999,257.108859,35.1620820009709,4.22703616449803
7.954023780838732e-08,0.0013415999999999999,262.26980325,35.1620820009709,4.22703616449803
8.053626940885013e-08,0.0013583999999999998,265.5540405,35.1620820009709,4.22703616449803
8.096314009476278e-08,0.0013656,266.96157075,35.1620820009709,4.22703616449803
8.191174161901307e-08,0.0013816,270.08941575,35.1620820009709,4.22703616449803
8.504212664903904e-08,0.0014344,280.41130425,35.1620820009709,4.22703616449803
8.537413718252664e-08,0.0014399999999999999,281.50604999999996,35.1620820009709,4.22703616449803
8.584843794465179e-08,0.0014479999999999999,283.06997249999995,35.1620820009709,4.22703616449803
8.622787855435191e-08,0.0014544,284.3211105,35.1620820009709,4.22703616449803
8.774564099315239e-08,0.00148,289.3256625,35.1620820009709,4.22703616449803
8.81250816028525e-08,0.0014864,290.5768005,35.1620820009709,4.22703616449803
8.912111320331531e-08,0.0015032,293.86103775,35.1620820009709,4.22703616449803
8.987999442271556e-08,0.001516,296.36331375,35.1620820009709,4.22703616449803
9.059144556590327e-08,0.0015279999999999998,298.70919749999996,35.1620820009709,4.22703616449803
9.158747716636609e-08,0.0015448,301.99343475,35.1620820009709,4.22703616449803
9.22989283095538e-08,0.0015568,304.3393185,35.1620820009709,4.22703616449803
9.263093884304141e-08,0.0015624,305.43406425,35.1620820009709,4.22703616449803
9.324752983380411e-08,0.0015727999999999998,307.46716349999997,35.1620820009709,4.22703616449803
9.538188326336727e-08,0.0016087999999999999,314.50481475,35.1620820009709,4.22703616449803
9.718422615944284e-08,0.0016392,320.44772025,35.1620820009709,4.22703616449803
9.761109684535547e-08,0.0016464,321.85525049999995,35.1620820009709,4.22703616449803
9.836997806475571e-08,0.0016592,324.3575265,35.1620820009709,4.22703616449803
1.0021975103704379e-07,0.0016903999999999999,325.617639758634,35.1620820009709,4.22703616449803
1.0074148187538145e-07,0.0016991999999999999,325.69198577588446,35.1620820009709,4.22703616449803
1.022118142379694e-07,0.0017239999999999998,325.90070277456846,35.1620820009709,4.22703616449803
1.0406158721025749e-07,0.0017552,326.16162642932215,35.1620820009709,4.22703616449803
1.0467817820102018e-07,0.0017656,326.2481981840604,35.1620820009709,4.22703616449803
1.0505761881072029e-07,0.001772,326.3013742699167,35.1620820009709,4.22703616449803
1.0667024140194579e-07,0.0017992,326.52654208843956,35.1620820009709,4.22703616449803
1.070022519354334e-07,0.0018047999999999999,326.5727349348151,35.1620820009709,4.22703616449803
1.0709711208785843e-07,0.0018063999999999999,326.5859226195542,35.1620820009709,4.22703616449803
1.0771370307862112e-07,0.0018168,326.67153179812976,35.1620820009709,4.22703616449803
1.086148745266589e-07,0.0018319999999999999,326.7963099110125,35.1620820009709,4.22703616449803
1.0975319635575925e-07,0.0018512,326.95334875680294,35.1620820009709,4.22703616449803
1.1018006704167189e-07,0.0018583999999999999,327.0120743955644,35.1620820009709,4.22703616449803
1.1070179788000955e-07,0.0018671999999999998,327.08372981306155,35.1620820009709,4.22703616449803
1.1108123848970968e-07,0.0018736,327.135760146049,35.1620820009709,4.22703616449803
1.12124700166385e-07,0.0018912,327.2784873795592,35.1620820009709,4.22703616449803
1.1297844153821026e-07,0.0019056,327.39487929430805,35.1620820009709,4.22703616449803
1.1312073176684781e-07,0.001908,327.4142445493239,35.1620820009709,4.22703616449803
1.1534994534883601e-07,0.0019456,327.71640405478166,35.1620820009709,4.22703616449803
1.1563452580611109e-07,0.0019504,327.7548130171346,35.1620820009709,4.22703616449803
1.1767401908324925e-07,0.0019848,328.0290064524374,35.1620820009709,4.22703616449803
1.1805345969294935e-07,0.0019912,328.07981404961765,35.1620820009709,4.22703616449803
1.1928664167447473e-07,0.002012,328.2445006328735,35.1620820009709,4.22703616449803
1.2033010335115005e-07,0.0020296,328.3833328569463,35.1620820009709,4.22703616449803
1.2156328533267544e-07,0.0020504,328.54680342002706,35.1620820009709,4.22703616449803
1.2331819815253848e-07,0.00208,328.7783239297674,35.1620820009709,4.22703616449803
1.2350791845738854e-07,0.0020832,328.8032759682584,35.1620820009709,4.22703616449803
1.2445651998163883e-07,0.0020992,328.92781263960933,35.1620820009709,4.22703616449803
1.2545255158210165e-07,0.002116,329.0581783813689,35.1620820009709,4.22703616449803
1.265434433349895e-07,0.0021344,329.2004976170153,35.1620820009709,4.22703616449803
1.2678059371605207e-07,0.0021384,329.23137317342486,35.1620820009709,4.22703616449803
1.2734975463060223e-07,0.0021479999999999997,329.3053827544628,35.1620820009709,4.22703616449803
1.2867779676455265e-07,0.0021704,329.47757192076125,35.1620820009709,4.22703616449803
1.2915209752667783e-07,0.0021784,329.53889990742965,35.1620820009709,4.22703616449803
1.2995840882229056e-07,0.002192,329.64295628248976,35.1620820009709,4.22703616449803
1.3119159080381595e-07,0.0022128,329.80161562917175,35.1620820009709,4.22703616449803
1.3247220286155386e-07,0.0022344,329.96576285464914,35.1620820009709,4.22703616449803
1.3408482545277934e-07,0.0022616,330.17158909895886,35.1620820009709,4.22703616449803
1.3541286758672976e-07,0.002284,330.340369130692,35.1620820009709,4.22703616449803
1.3626660895855504e-07,0.0022984,330.44852977817334,35.1620820009709,4.22703616449803
1.374523608638679e-07,0.0023184,330.5983154892616,35.1620820009709,4.22703616449803
1.3911241353130591e-07,0.0023464,330.8071716216223,35.1620820009709,4.22703616449803
1.3982386467449366e-07,0.0023584,330.89638358836544,35.1620820009709,4.22703616449803
1.4157877749435668e-07,0.002388,331.11568620509973,35.1620820009709,4.22703616449803
1.4247994894239447e-07,0.0024032,331.22788892202254,35.1620820009709,4.22703616449803
1.4304910985694466e-07,0.0024128,331.29861121447595,35.1620820009709,4.22703616449803
1.4342855046664476e-07,0.0024192,331.345698451661,35.1620820009709,4.22703616449803
1.4366570084770735e-07,0.0024232,331.3751033056843,35.1620820009709,4.22703616449803
1.4475659260059518e-07,0.0024416,331.510122560106,35.1620820009709,4.22703616449803
1.452308933627203e-07,0.0024495999999999997,331.56870274593405,35.1620820009709,4.22703616449803
1.460372046583331e-07,0.0024632,331.6681181160181,35.1620820009709,4.22703616449803
1.476972573257711e-07,0.0024912,331.87212528816207,35.1620820009709,4.22703616449803
1.5096993258443463e-07,0.0025464,332.27171032904783,35.1620820009709,4.22703616449803
1.518711040324724e-07,0.0025616,332.3811459625338,35.1620820009709,4.22703616449803
1.5244026494702258e-07,0.0025712,332.4501327377287,35.1620820009709,4.22703616449803
1.531042860139978e-07,0.0025824,332.5304904750317,35.1620820009709,4.22703616449803
1.5391059730961053e-07,0.002596,332.62788522897756,35.1620820009709,4.22703616449803
1.5429003791931065e-07,0.0026024,332.6736491808487,35.1620820009709,4.22703616449803
1.5504891913871088e-07,0.0026152,332.7650456184595,35.1620820009709,4.22703616449803
1.5519120936734844e-07,0.0026176,332.78216301076895,35.1620820009709,4.22703616449803
1.5623467104402376e-07,0.0026352,332.90750406356665,35.1620820009709,4.22703616449803
1.5732556279691161e-07,0.0026536,333.0381938592863,35.1620820009709,4.22703616449803
1.5836902447358693e-07,0.0026712,333.1628711845825,35.1620820009709,4.22703616449803
1.5945991622647479e-07,0.0026896,333.2928735955892,35.1620820009709,4.22703616449803
1.6012393729344998e-07,0.0027007999999999997,333.3718356923257,35.1620820009709,4.22703616449803
1.6059823805557514e-07,0.0027088,333.42815902319643,35.1620820009709,4.22703616449803
1.617365598846755e-07,0.002728,333.5630709907748,35.1620820009709,4.22703616449803
1.620685704181631e-07,0.0027336,333.6023504932822,35.1620820009709,4.22703616449803
1.6349147270453854e-07,0.0027576,333.77033701064437,35.1620820009709,4.22703616449803
1.636811930093886e-07,0.0027608,333.79269205417444,35.1620820009709,4.22703616449803
1.639657734666637e-07,0.0027656,333.8262056811309,35.1620820009709,4.22703616449803
1.643926441525763e-07,0.0027727999999999997,333.87643361871284,35.1620820009709,4.22703616449803
1.646297945336389e-07,0.0027768,333.90431604889045,35.1620820009709,4.22703616449803
1.6500923514333902e-07,0.0027832,333.94889537762157,35.1620820009709,4.22703616449803
1.6524638552440156e-07,0.0027871999999999997,333.97673715713864,35.1620820009709,4.22703616449803
1.663372772772894e-07,0.0028055999999999997,334.1046091672913,35.1620820009709,4.22703616449803
1.6652699758213947e-07,0.0028087999999999998,334.1268143500325,35.1620820009709,4.22703616449803
1.6733330887775225e-07,0.0028224,334.22107652000864,35.1620820009709,4.22703616449803
1.6908822169761527e-07,0.002852,334.4256251932604,35.1620820009709,4.22703616449803
1.704162638315657e-07,0.0028744,334.5798688918342,35.1620820009709,4.22703616449803
1.7084313451747831e-07,0.0028816,334.62934757343294,35.1620820009709,4.22703616449803
1.7117514505096594e-07,0.0028872,334.6677976663095,35.1620820009709,4.22703616449803
1.7264547741355386e-07,0.0029119999999999997,334.83772823545576,35.1620820009709,4.22703616449803
1.752541316052422e-07,0.002956,335.1378354314321,35.1620820009709,4.22703616449803
1.7639245343434257e-07,0.0029752,335.2682447739944,35.1620820009709,4.22703616449803
1.787639572449683e-07,0.0030152,335.5388814416898,35.1620820009709,4.22703616449803
1.7952283846436854e-07,0.003028,335.62518897325333,35.1620820009709,4.22703616449803
1.799497091502812e-07,0.0030352,335.6736744288091,35.1620820009709,4.22703616449803
1.8094574075074398e-07,0.003052,335.78663305329593,35.1620820009709,4.22703616449803
1.8189434227499427e-07,0.003068,335.89398745690215,35.1620820009709,4.22703616449803
1.8217892273226934e-07,0.0030727999999999997,335.92615117129776,35.1620820009709,4.22703616449803
1.8360182501864482e-07,0.0030968,336.08667675944906,35.1620820009709,4.22703616449803
1.8559388821957043e-07,0.0031303999999999998,336.31059985517726,35.1620820009709,4.22703616449803
1.8768081157292107e-07,0.0031655999999999998,336.5441829008329,35.1620820009709,4.22703616449803
1.8820254241125876e-07,0.0031744,336.6024201166973,35.1620820009709,4.22703616449803
1.8839226271610882e-07,0.0031776,336.6235816710785,35.1620820009709,4.22703616449803
1.897203048500592e-07,0.0031999999999999997,336.77148053287186,35.1620820009709,4.22703616449803
1.909534868315846e-07,0.0032208,336.9084540629726,35.1620820009709,4.22703616449803
1.915700778223473e-07,0.0032312,336.97681142723354,35.1620820009709,4.22703616449803
1.925661094228101e-07,0.003248,337.0870538813167,35.1620820009709,4.22703616449803
1.9299298010872273e-07,0.0032551999999999998,337.1342325453589,35.1620820009709,4.22703616449803
1.934672808708479e-07,0.0032632,337.1866055778002,35.1620820009709,4.22703616449803
1.9526962376692344e-07,0.0032936,337.3851680810003,35.1620820009709,4.22703616449803
1.9692967643436145e-07,0.0033215999999999996,337.5674231600278,35.1620820009709,4.22703616449803
1.9754626742512417e-07,0.003332,337.6349651720933,35.1620820009709,4.22703616449803
1.980679982634618e-07,0.0033407999999999997,337.692051912453,35.1620820009709,4.22703616449803
1.98637159178012e-07,0.0033504,337.7542615135944,35.1620820009709,4.22703616449803
1.9944347047362475e-07,0.003364,337.8422729126668,35.1620820009709,4.22703616449803
2.008189426837877e-07,0.0033872,337.992090409254,35.1620820009709,4.22703616449803
2.0096123291242523e-07,0.0033896,338.00756589512974,35.1620820009709,4.22703616449803
2.018149742842505e-07,0.003404,338.1003292285579,35.1620820009709,4.22703616449803
2.0262128557986324e-07,0.0034176,338.1877986178354,35.1620820009709,4.22703616449803
2.0328530664683844e-07,0.0034287999999999996,338.25973034860505,35.1620820009709,4.22703616449803
2.0418647809487625e-07,0.003444,338.3572055860798,35.1620820009709,4.22703616449803
2.0480306908563892e-07,0.0034544,338.42380251929103,35.1620820009709,4.22703616449803
2.050402194667015e-07,0.0034584,338.449395897522,35.1620820009709,4.22703616449803
2.0636826160065193e-07,0.0034808,338.59250604416326,35.1620820009709,4.22703616449803
2.0964093685931543e-07,0.0035359999999999996,338.9436457373382,35.1620820009709,4.22703616449803
2.1025752785007814e-07,0.0035464,339.0095624765369,35.1620820009709,4.22703616449803
2.1267646173691638e-07,0.0035872,339.2674341865219,35.1620820009709,4.22703616449803
2.1353020310874164e-07,0.0036016,339.3581743005002,35.1620820009709,4.22703616449803
2.1443137455677943e-07,0.0036168,339.45380216577695,35.1620820009709,4.22703616449803
2.1571198661451734e-07,0.0036384,339.58942521507714,35.1620820009709,4.22703616449803
2.1618628737664247e-07,0.0036463999999999997,339.639576241368,35.1620820009709,4.22703616449803
2.188423716445433e-07,0.0036912,339.9196330085416,35.1620820009709,4.22703616449803
2.1960125286394353e-07,0.003704,339.99940533985506,35.1620820009709,4.22703616449803
2.2059728446440635e-07,0.0037208,340.1039435581137,35.1620820009709,4.22703616449803
2.2192532659835677e-07,0.0037432,340.24304194807496,35.1620820009709,4.22703616449803
2.2382252964685737e-07,0.0037752,340.4411921137316,35.1620820009709,4.22703616449803
2.2415454018034497e-07,0.0037808,340.4758009388017,35.1620820009709,4.22703616449803
2.2496085147595773e-07,0.0037944,340.5597678160316,35.1620820009709,4.22703616449803
2.2728492521037096e-07,0.0038336,340.8011357670826,35.1620820009709,4.22703616449803
2.280438064297712e-07,0.0038464,340.8797410744465,35.1620820009709,4.22703616449803
2.2927698841129657e-07,0.0038672,341.0072574655761,35.1620820009709,4.22703616449803
2.3107933130737212e-07,0.0038975999999999998,341.19314747336165,35.1620820009709,4.22703616449803
2.3150620199328478e-07,0.0039048,341.2370911302306,35.1620820009709,4.22703616449803
2.3311882458451026e-07,0.003932,341.4028160915688,35.1620820009709,4.22703616449803
2.349211674805858e-07,0.0039624,341.5875099154706,35.1620820009709,4.22703616449803
2.3525317801407346e-07,0.003968,341.621472100805,35.1620820009709,4.22703616449803
2.367709404528739e-07,0.0039936,341.7764903759231,35.1620820009709,4.22703616449803
2.644755699987698e-07,0.004460892178435687,344.5413752138868,35.1620820009709,4.22703616449803
2.815538130838922e-07,0.004748949789957992,346.1895075195155,35.1620820009709,4.22703616449803
3.0546335340306346e-07,0.005152230446089218,348.43280710621957,35.1620820009709,4.22703616449803
3.464511368073571e-07,0.0058435687137427484,352.1251340052385,35.1620820009709,4.22703616449803
3.863003706726426e-07,0.006515703140628126,355.5546099024957,35.1620820009709,4.22703616449803
4.0451716329677314e-07,0.006822964592918584,357.07609503948555,35.1620820009709,4.22703616449803
4.4208929808404224e-07,0.007456691338267653,360.1322271290993,35.1620820009709,4.22703616449803
4.603060907081728e-07,0.007763952790558111,361.5773602568024,35.1620820009709,4.22703616449803
4.921854778004012e-07,0.008301660332066413,364.05377179711047,35.1620820009709,4.22703616449803
5.12679369502548e-07,0.008647329465893179,365.6127624203488,35.1620820009709,4.22703616449803
5.582213510628744e-07,0.009415483096619324,368.9926750102681,35.1620820009709,4.22703616449803
5.855465399990701e-07,0.009876375275055011,370.9690007196619,35.1620820009709,4.22703616449803
6.242572243253473e-07,0.010529305861172233,373.7082839704126,35.1620820009709,4.22703616449803
6.413354674104699e-07,0.01081736347269454,374.8956385194224,35.1620820009709,4.22703616449803
6.527209628005514e-07,0.011009401880376076,375.68036434058143,35.1620820009709,4.22703616449803
6.720763049636899e-07,0.011335867173434686,377.0022554505788,35.1620820009709,4.22703616449803
7.005400434388939e-07,0.011815963192638527,378.91955234505156,35.1620820009709,4.22703616449803
7.221724846800488e-07,0.012180836167233446,380.3564427415516,35.1620820009709,4.22703616449803
7.711301148573997e-07,0.013006601320264053,383.547757616074,35.1620820009709,4.22703616449803
7.904854570205383e-07,0.013333066613322665,384.7875178388129,35.1620820009709,4.22703616449803
7.984553037935955e-07,0.01346749349869974,385.29455954281144,35.1620820009709,4.22703616449803
8.0187095241062e-07,0.013525105021004201,385.5112584723802,35.1620820009709,4.22703616449803
8.257804927297912e-07,0.013928385677135427,387.01819677879047,35.1620820009709,4.22703616449803
8.405816367368972e-07,0.014178035607121425,387.94253954471617,35.1620820009709,4.22703616449803
8.599369789000359e-07,0.014504500900180036,389.14177351521545,35.1620820009709,4.22703616449803
8.906778164532562e-07,0.015023004600920185,391.02502445360153,35.1620820009709,4.22703616449803
9.259728521625091e-07,0.015618323664732947,393.15628876104586,35.1620820009709,4.22703616449803
9.407739961696151e-07,0.015867973594718945,394.04058781875193,35.1620820009709,4.22703616449803
9.703762841838271e-07,0.01636727345469094,395.79307332670425,35.1620820009709,4.22703616449803
9.97701473120023e-07,0.016828165633126627,397.39233300306535,35.1620820009709,4.22703616449803
1.0090869685101044e-06,0.01702020404080816,398.0536387579539,35.1620820009709,4.22703616449803
1.0329965088292757e-06,0.017423484696939388,399.43298301795886,35.1620820009709,4.22703616449803
1.0375507069853085e-06,0.017500300060012002,399.6942975949037,35.1620820009709,4.22703616449803
1.0671529949995206e-06,0.017999599919983997,401.3820677145741,35.1620820009709,4.22703616449803
1.085369787623651e-06,0.018306861372274455,402.4116233674039,35.1620820009709,4.22703616449803
1.1149720756378632e-06,0.01880616123224645,404.0703925069097,35.1620820009709,4.22703616449803
1.151405660886124e-06,0.019420684136827366,406.0885598944875,35.1620820009709,4.22703616449803
1.16620680489323e-06,0.01967033406681336,406.9013074896807,35.1620820009709,4.22703616449803
1.1821464984393443e-06,0.019939187837567512,407.77208812601333,35.1620820009709,4.22703616449803
1.194670543368434e-06,0.020150430086017204,408.45306457209284,35.1620820009709,4.22703616449803
1.2481823717018175e-06,0.021053010602120423,411.3318771729714,35.1620820009709,4.22703616449803
1.2607064166309072e-06,0.021264252850570115,411.9986418315594,35.1620820009709,4.22703616449803
1.2652606147869398e-06,0.02134106821364273,412.24046058830953,35.1620820009709,4.22703616449803
1.2812003083330542e-06,0.02160992198439688,413.084165925469,35.1620820009709,4.22703616449803
1.3142182449642904e-06,0.022166833366673334,414.8189288038457,35.1620820009709,4.22703616449803
1.3221880917373478e-06,0.02230126025205041,415.2351078810155,35.1620820009709,4.22703616449803
1.375699920070731e-06,0.02320384076815363,418.00453938681596,35.1620820009709,4.22703616449803
1.381392667765772e-06,0.0232998599719944,418.2966657852273,35.1620820009709,4.22703616449803
1.4360430456381632e-06,0.024221644328865772,421.07759283507045,35.1620820009709,4.22703616449803
1.4656453336523753e-06,0.024720944188837767,422.56668058516516,35.1620820009709,4.22703616449803
1.4861392253545222e-06,0.025066613322664532,423.59072322392495,35.1620820009709,4.22703616449803
1.528265558297824e-06,0.02577715543108622,425.6785642875326,35.1620820009709,4.22703616449803
1.6250422691135175e-06,0.027409481896379276,430.39174045563874,35.1620820009709,4.22703616449803
1.6318735663475662e-06,0.027524704940988198,430.72023906363546,35.1620820009709,4.22703616449803
1.6478132598936806e-06,0.02779355871174235,431.4846572232521,35.1620820009709,4.22703616449803
1.6694457011348357e-06,0.02815843168633727,432.5174851504391,35.1620820009709,4.22703616449803
1.6819697460639253e-06,0.028369673934786958,433.11305248330893,35.1620820009709,4.22703616449803
1.7036021873050802e-06,0.028734546909381875,434.137702059283,35.1620820009709,4.22703616449803
1.7172647817731781e-06,0.02896499299859972,434.7822354466399,35.1620820009709,4.22703616449803
1.7309273762412759e-06,0.029195439087817562,435.4247720191061,35.1620820009709,4.22703616449803
1.766222411950529e-06,0.029790758151630327,437.07556950564907,35.1620820009709,4.22703616449803
1.773053709184578e-06,0.02990598119623925,437.39358730073104,35.1620820009709,4.22703616449803
1.8151800421278796e-06,0.03061652330466093,439.3442415972168,35.1620820009709,4.22703616449803
1.8311197356739937e-06,0.030885377075415082,440.07771272049905,35.1620820009709,4.22703616449803
1.8345353842910183e-06,0.030942988597719545,440.2345606620337,35.1620820009709,4.22703616449803
1.8573063750711814e-06,0.03132706541308262,441.2773182230371,35.1620820009709,4.22703616449803
1.8709689695392794e-06,0.03155751150230046,441.90057975204024,35.1620820009709,4.22703616449803
1.910818203404565e-06,0.03222964592918584,443.7083664973131,35.1620820009709,4.22703616449803
1.9187880501776218e-06,0.03236407281456291,444.0681529125226,35.1620820009709,4.22703616449803
1.942697590496793e-06,0.032767353470694136,445.14403142336573,35.1620820009709,4.22703616449803
1.948390338191834e-06,0.03286337267453491,445.39943033390585,35.1620820009709,4.22703616449803
1.9518059868088584e-06,0.032920984196839365,445.5525299922491,35.1620820009709,4.22703616449803
1.9654685812769564e-06,0.033151430286057215,446.1638866102083,35.1620820009709,4.22703616449803
1.968884229893981e-06,0.03320904180836168,446.3164665207236,35.1620820009709,4.22703616449803
1.9962094188301767e-06,0.03366993398679736,447.5334114337789,35.1620820009709,4.22703616449803
2.01898040961034e-06,0.03405401080216043,448.54257728239736,35.1620820009709,4.22703616449803
2.0474441480855437e-06,0.03453410682136428,449.7978139873285,35.1620820009709,4.22703616449803
2.063383841631658e-06,0.034802960592118425,450.49777339707845,35.1620820009709,4.22703616449803
2.087293381950829e-06,0.03520624124824965,451.54377141398584,35.1620820009709,4.22703616449803
2.1146185708870255e-06,0.035667133426685343,452.7334927522453,35.1620820009709,4.22703616449803
2.120311318582066e-06,0.03576315263052611,452.98059500632326,35.1620820009709,4.22703616449803
2.15446780475231e-06,0.03633926785357071,454.45781128321187,35.1620820009709,4.22703616449803
2.1749616964544576e-06,0.036684936987397485,455.33975745961226,35.1620820009709,4.22703616449803
2.187485741383547e-06,0.036896179235847176,455.8771292785424,35.1620820009709,4.22703616449803
2.2000097863126363e-06,0.037107421484296854,456.413302545308,35.1620820009709,4.22703616449803
2.207979633085694e-06,0.03724184836967394,456.7538840155107,35.1620820009709,4.22703616449803
2.2113952817027187e-06,0.0372994598919784,456.89970069611627,35.1620820009709,4.22703616449803
2.2250578761708162e-06,0.03752990598119624,457.4820911886671,35.1620820009709,4.22703616449803
2.2637685604970933e-06,0.03818283656731346,459.12467182024864,35.1620820009709,4.22703616449803
2.271738407270151e-06,0.03831726345269054,459.4614862922628,35.1620820009709,4.22703616449803
2.2876781008162644e-06,0.03858611722344468,460.13373590470604,35.1620820009709,4.22703616449803
2.310449091596428e-06,0.03897019403880776,461.0909322574487,35.1620820009709,4.22703616449803
2.319557487908493e-06,0.03912382476495299,461.47277977469554,35.1620820009709,4.22703616449803
2.3366357309936154e-06,0.03941188237647529,462.1871714066698,35.1620820009709,4.22703616449803
2.3514368750007213e-06,0.039661532306461286,462.804665225451,35.1620820009709,4.22703616449803
2.366238019007828e-06,0.039911182236447296,463.42064503108173,35.1620820009709,4.22703616449803
2.4140570996461703e-06,0.040717743548709745,465.4005417683435,35.1620820009709,4.22703616449803
2.4299967931922847e-06,0.0409865973194639,466.05710056317236,35.1620820009709,4.22703616449803
2.449352135355423e-06,0.0413130626125225,466.85209678853124,35.1620820009709,4.22703616449803
2.4539063335114558e-06,0.041389877975595124,467.03879820708835,35.1620820009709,4.22703616449803
2.4664303784405457e-06,0.041601120224044816,467.5515316175784,35.1620820009709,4.22703616449803
2.476677324291619e-06,0.04177395479095819,467.97028594592916,35.1620820009709,4.22703616449803
2.498309765532774e-06,0.04213882776555311,468.8521104011145,35.1620820009709,4.22703616449803
2.502863963688807e-06,0.04221564312862573,469.03737763882043,35.1620820009709,4.22703616449803
2.5256349544689695e-06,0.0425997199439888,469.9617490368288,35.1620820009709,4.22703616449803
2.539297548937068e-06,0.04283016603320665,470.51481185568383,35.1620820009709,4.22703616449803
2.5859780800364017e-06,0.04361752350470094,472.3957480052147,35.1620820009709,4.22703616449803
2.5916708277314424e-06,0.043713542708541706,472.6242210650829,35.1620820009709,4.22703616449803
2.608749070816565e-06,0.04400160032006402,473.3084687888076,35.1620820009709,4.22703616449803
2.6451826560648263e-06,0.044616123224644935,474.7623857367311,35.1620820009709,4.22703616449803
2.6827547908520953e-06,0.045249849969994,476.2535809296198,35.1620820009709,4.22703616449803
2.7066643311712664e-06,0.04565313062612522,477.1982840776473,35.1620820009709,4.22703616449803
2.726019673334405e-06,0.04597959591918384,477.9606622359443,35.1620820009709,4.22703616449803
2.744236465958536e-06,0.046286857371474296,478.6762684267844,35.1620820009709,4.22703616449803
2.748790664114568e-06,0.046363672734546904,478.8548802064147,35.1620820009709,4.22703616449803
2.7692845558167154e-06,0.04670934186837368,479.6572092905705,35.1620820009709,4.22703616449803
2.7795315016677885e-06,0.046882176435287054,480.0575052208614,35.1620820009709,4.22703616449803
2.789778447518862e-06,0.04705501100220044,480.4572260322676,35.1620820009709,4.22703616449803
2.8057181410649765e-06,0.047323864772954596,481.07787772736754,35.1620820009709,4.22703616449803
2.8205192850720824e-06,0.04757351470294059,481.6529669671581,35.1620820009709,4.22703616449803
2.83418187954018e-06,0.04780396079215843,482.18277479150305,35.1620820009709,4.22703616449803
2.8933864555686045e-06,0.048802560512102425,484.4671939141259,35.1620820009709,4.22703616449803
2.9298200408168656e-06,0.04941708341668334,485.8639318195744,35.1620820009709,4.22703616449803
2.9503139325190123e-06,0.0497627525505101,486.64661972882317,35.1620820009709,4.22703616449803
2.9708078242211586e-06,0.050108421684336865,487.42719012806356,35.1620820009709,4.22703616449803
2.9810547700722326e-06,0.05028125625125025,487.8166876111718,35.1620820009709,4.22703616449803
3.0163498057814853e-06,0.05087657531506301,489.1543114718472,35.1620820009709,4.22703616449803
3.0277353011715664e-06,0.051068613722744544,489.5844990601711,35.1620820009709,4.22703616449803
3.0766929313489174e-06,0.05189437887577515,491.4271628093589,35.1620820009709,4.22703616449803
3.097186823051065e-06,0.05224004800960193,492.1951109831835,35.1620820009709,4.22703616449803
3.1199578138312277e-06,0.05262412482496499,493.0460661956684,35.1620820009709,4.22703616449803
3.1336204082993256e-06,0.052854570914182844,493.5554767563047,35.1620820009709,4.22703616449803
3.1643612458525455e-06,0.05337307461492298,494.698494088709,35.1620820009709,4.22703616449803
3.2121803264908885e-06,0.05417963592718544,496.4679507515354,35.1620820009709,4.22703616449803
3.219011623724937e-06,0.054294858971794355,496.71988910115294,35.1620820009709,4.22703616449803
3.259999407129231e-06,0.05498619723944789,498.22716352587247,35.1620820009709,4.22703616449803
3.264553605285263e-06,0.0550630126025205,498.3941809848349,35.1620820009709,4.22703616449803
3.304402839150549e-06,0.05573514702940588,499.8517279542378,35.1620820009709,4.22703616449803
3.332866577625753e-06,0.056215243048609725,500.8886390114271,35.1620820009709,4.22703616449803
3.3465291720938504e-06,0.05644568913782756,501.3851290863424,35.1620820009709,4.22703616449803
3.3749929105690547e-06,0.05692578515703141,502.4169515919129,35.1620820009709,4.22703616449803
3.39662535181021e-06,0.05729065813162633,503.1988684895619,35.1620820009709,4.22703616449803
3.4091493967393e-06,0.05750190038007602,503.6506695280459,35.1620820009709,4.22703616449803
3.4171192435123566e-06,0.05763632726545309,503.9378422843583,35.1620820009709,4.22703616449803
3.435336036136487e-06,0.05794358871774355,504.5932580707453,35.1620820009709,4.22703616449803
3.5264199992571398e-06,0.05947989597919584,507.8502226215482,35.1620820009709,4.22703616449803
3.568546332200441e-06,0.06019043808761752,509.34545652130424,35.1620820009709,4.22703616449803
3.6220581605338246e-06,0.06109301860372074,511.23491861666366,35.1620820009709,4.22703616449803
3.644829151313988e-06,0.06147709541908382,512.0356394984184,35.1620820009709,4.22703616449803
3.6915096824133228e-06,0.06226445289057812,513.6710438394008,35.1620820009709,4.22703616449803
3.739328763051665e-06,0.06307101420284057,515.337994806413,35.1620820009709,4.22703616449803
3.798533339080089e-06,0.06406961392278455,517.3903646769356,35.1620820009709,4.22703616449803
3.813334483087195e-06,0.06431926385277055,517.9015031570761,35.1620820009709,4.22703616449803
3.826997077555293e-06,0.0645497099419884,518.3726369661889,35.1620820009709,4.22703616449803
3.83496692432835e-06,0.06468413682736547,518.6471620925921,35.1620820009709,4.22703616449803
3.866846311420579e-06,0.06522184436887378,519.7430448650283,35.1620820009709,4.22703616449803
3.879370356349669e-06,0.06543308661732347,520.1726055117036,35.1620820009709,4.22703616449803
3.901002797590823e-06,0.06579795959191838,520.9133021906589,35.1620820009709,4.22703616449803
3.920358139753962e-06,0.066124424884977,521.5746740516271,35.1620820009709,4.22703616449803
3.924912337909995e-06,0.06620124024804962,521.7301057436811,35.1620820009709,4.22703616449803
3.927189436988011e-06,0.06623964792958592,521.8077952120672,35.1620820009709,4.22703616449803
3.960207373619247e-06,0.06679655931186237,522.9323256258413,35.1620820009709,4.22703616449803
3.987532562555443e-06,0.06725745149029806,523.8602088917391,35.1620820009709,4.22703616449803
4.009165003796599e-06,0.06762232446489298,524.5930256389346,35.1620820009709,4.22703616449803
4.046737138583868e-06,0.06825605121024206,525.8621580110761,35.1620820009709,4.22703616449803
4.064953931207998e-06,0.06856331266253252,526.4758400224271,35.1620820009709,4.22703616449803
4.077477976137087e-06,0.0687745549109822,526.8971243710652,35.1620820009709,4.22703616449803
4.08886347152717e-06,0.06896659331866374,527.2796724253,35.1620820009709,4.22703616449803
4.1070802641513e-06,0.0692738547709542,527.8908863479993,35.1620820009709,4.22703616449803
4.1332669035484875e-06,0.06971554310862173,528.7676572805739,35.1620820009709,4.22703616449803
4.149206597094602e-06,0.06998439687937588,529.3002833498309,35.1620820009709,4.22703616449803
4.153760795250634e-06,0.07006121224244849,529.452315578881,35.1620820009709,4.22703616449803
4.184501632803854e-06,0.07057971594318864,530.476838051166,35.1620820009709,4.22703616449803
4.187917281420879e-06,0.0706373274654931,530.5904923979417,35.1620820009709,4.22703616449803
4.202718425427985e-06,0.0708869773954791,531.0825774085885,35.1620820009709,4.22703616449803
4.2334592629812055e-06,0.07140548109621925,532.1024457588579,35.1620820009709,4.22703616449803
4.251676055605336e-06,0.0717127425485097,532.7054493543412,35.1620820009709,4.22703616449803
4.272169947307482e-06,0.07205841168233647,533.3826252790375,35.1620820009709,4.22703616449803
4.297218037165662e-06,0.07248089617923585,534.2085667088177,35.1620820009709,4.22703616449803
4.301772235321695e-06,0.07255771154230847,534.3585359359628,35.1620820009709,4.22703616449803
4.448645125853747e-06,0.07503500700140028,539.1623501850578,35.1620820009709,4.22703616449803
4.4907714587970485e-06,0.07574554910982197,540.5287213118447,35.1620820009709,4.22703616449803
4.50215695418713e-06,0.0759375875175035,540.897151560567,35.1620820009709,4.22703616449803
4.526066494506302e-06,0.07634086817363474,541.6696744082436,35.1620820009709,4.22703616449803
4.538590539435391e-06,0.07655211042208442,542.0736939600857,35.1620820009709,4.22703616449803
4.565915728371587e-06,0.0770130026005201,542.9536850178553,35.1620820009709,4.22703616449803
4.592102367768775e-06,0.07745469093818765,543.7950844845342,35.1620820009709,4.22703616449803
4.629674502556044e-06,0.0780884176835367,544.9990486279781,35.1620820009709,4.22703616449803
4.646752745641167e-06,0.07837647529505902,545.5450447547006,35.1620820009709,4.22703616449803
4.680909231811411e-06,0.07895259051810362,546.6346948185266,35.1620820009709,4.22703616449803
4.688879078584469e-06,0.0790870174034807,546.8884997837982,35.1620820009709,4.22703616449803
4.702541673052565e-06,0.07931746349269854,547.3232029289084,35.1620820009709,4.22703616449803
4.725312663832729e-06,0.07970154030806162,548.0466151930503,35.1620820009709,4.22703616449803
4.745806555534876e-06,0.08004720944188838,548.696524625329,35.1620820009709,4.22703616449803
4.754914951846941e-06,0.08020084016803361,548.9850218325182,35.1620820009709,4.22703616449803
4.7583306004639656e-06,0.08025845169033807,549.0931527090975,35.1620820009709,4.22703616449803
4.766300447237023e-06,0.08039287857571514,549.3453404341728,35.1620820009709,4.22703616449803
4.825505023265447e-06,0.08139147829565914,551.213613517268,35.1620820009709,4.22703616449803
4.830059221421479e-06,0.08146829365873175,551.356955488651,35.1620820009709,4.22703616449803
4.839167617733545e-06,0.08162192438487698,551.6434813978389,35.1620820009709,4.22703616449803
4.851691662662635e-06,0.08183316663332667,552.037111332551,35.1620820009709,4.22703616449803
4.858522959896684e-06,0.08194838967793559,552.2516515349355,35.1620820009709,4.22703616449803
4.886986698371888e-06,0.08242848569713944,553.1443056800246,35.1620820009709,4.22703616449803
4.8983721937619695e-06,0.08262052410482097,553.5007993122373,35.1620820009709,4.22703616449803
4.9108962386910594e-06,0.08283176635327066,553.8925692676254,35.1620820009709,4.22703616449803
4.967823715641466e-06,0.08379195839167834,555.6684537157562,35.1620820009709,4.22703616449803
4.9860405082655975e-06,0.0840992198439688,556.2350581979748,35.1620820009709,4.22703616449803
5.014504246740801e-06,0.08457931586317263,557.1187641081526,35.1620820009709,4.22703616449803
5.048660732911046e-06,0.08515543108621725,558.176633070305,35.1620820009709,4.22703616449803
5.069154624613192e-06,0.08550110022004401,558.8100147439404,35.1620820009709,4.22703616449803
5.119250804329552e-06,0.08634606921384277,560.3540914079612,35.1620820009709,4.22703616449803
5.136329047414674e-06,0.08663412682536507,560.8791327984559,35.1620820009709,4.22703616449803
5.180732479435992e-06,0.08738307661532307,562.2410639241282,35.1620820009709,4.22703616449803
5.201226371138139e-06,0.08772874574914984,562.8681113499157,35.1620820009709,4.22703616449803
5.218304614223261e-06,0.08801680336067214,563.3899151499279,35.1620820009709,4.22703616449803
5.2456298031594565e-06,0.08847769553910782,564.2234180500858,35.1620820009709,4.22703616449803
5.282063388407718e-06,0.08909221844368874,565.3321259756215,35.1620820009709,4.22703616449803
5.284340487485734e-06,0.08913062612522504,565.4013210286447,35.1620820009709,4.22703616449803
5.305972928726889e-06,0.08949549909981996,566.0580950819633,35.1620820009709,4.22703616449803
5.321912622273003e-06,0.08976435287057412,566.5413658256746,35.1620820009709,4.22703616449803
5.334436667202093e-06,0.08997559511902381,566.9206826487168,35.1620820009709,4.22703616449803
5.34240651397515e-06,0.09011002200440088,567.1618852595847,35.1620820009709,4.22703616449803
5.361761856138289e-06,0.0904364872974595,567.7470795306928,35.1620820009709,4.22703616449803
5.369731702911346e-06,0.09057091418283657,567.9878023466897,35.1620820009709,4.22703616449803
5.402749639542582e-06,0.09112782556511302,568.9836017995635,35.1620820009709,4.22703616449803
5.411858035854647e-06,0.09128145629125825,569.2578870627468,35.1620820009709,4.22703616449803
5.4232435312447295e-06,0.0914734946989398,569.600490596417,35.1620820009709,4.22703616449803
5.438044675251835e-06,0.09172314462892579,570.0454561202397,35.1620820009709,4.22703616449803
5.452845819258941e-06,0.09197279455891179,570.4899495661913,35.1620820009709,4.22703616449803
5.468785512805056e-06,0.09224164832966594,570.9681089122843,35.1620820009709,4.22703616449803
5.491556503585219e-06,0.09262572514502901,571.6502519062767,35.1620820009709,4.22703616449803
5.516604593443399e-06,0.09304820964192839,572.3993363543229,35.1620820009709,4.22703616449803
5.546206881457611e-06,0.09354750950190038,573.2829099700164,35.1620820009709,4.22703616449803
5.566700773159757e-06,0.09389317863572715,573.8935376581471,35.1620820009709,4.22703616449803
5.616796952876116e-06,0.09473814762952591,575.3825038552328,35.1620820009709,4.22703616449803
5.622489700571157e-06,0.09483416683336668,575.5513762111708,35.1620820009709,4.22703616449803
5.641845042734296e-06,0.0951606321264253,576.1250440897069,35.1620820009709,4.22703616449803
5.711296564613794e-06,0.09633206641328267,578.1772110988863,35.1620820009709,4.22703616449803
5.790995032344364e-06,0.09767633526705341,580.520202408881,35.1620820009709,4.22703616449803
5.80579617635147e-06,0.0979259851970394,580.9539412541241,35.1620820009709,4.22703616449803
5.812627473585519e-06,0.09804120824164833,581.1539829428767,35.1620820009709,4.22703616449803
5.8240129689756e-06,0.09823324664932986,581.4871821252945,35.1620820009709,4.22703616449803
5.877524797308984e-06,0.0991358271654331,583.0498280799475,35.1620820009709,4.22703616449803
5.907127085323196e-06,0.09963512702540508,583.9118865423246,35.1620820009709,4.22703616449803
5.918512580713278e-06,0.09982716543308662,584.2429986682168,35.1620820009709,4.22703616449803
5.925343877947326e-06,0.09994238847769554,584.4415467063772,35.1620820009709,4.22703616449803
5.928759526564351e-06,0.1,584.5407872466855,35.1620820009709,4.22703616449803