File: datasets/aisi_316_L/data/M1/train_79.csv
Time(s),Strain(%),Stress(MPa),Temp(C),Log_SR(s-1)
0.0,0.0,0.0,166.93115322821933,2.8079838828036117
8.091321557557817e-08,5.2e-05,9.801974,166.93115322821933,2.8079838828036117
9.460622128836834e-08,6.08e-05,11.4607696,166.93115322821933,2.8079838828036117
9.709585869069381e-08,6.24e-05,11.762368799999999,166.93115322821933,2.8079838828036117
1.1576813920813493e-07,7.439999999999999e-05,14.024362799999999,166.93115322821933,2.8079838828036117
1.2074741401278592e-07,7.76e-05,14.6275612,166.93115322821933,2.8079838828036117
1.331956010244133e-07,8.56e-05,16.135557199999997,166.93115322821933,2.8079838828036117
1.668057059558073e-07,0.00010719999999999999,20.2071464,166.93115322821933,2.8079838828036117
1.7302979946162104e-07,0.00011119999999999999,20.9611444,166.93115322821933,2.8079838828036117
1.904572612778994e-07,0.0001224,23.072338799999997,166.93115322821933,2.8079838828036117
2.078847230941778e-07,0.0001336,25.1835332,166.93115322821933,2.8079838828036117
2.3278109711743263e-07,0.0001496,28.1995252,166.93115322821933,2.8079838828036117
2.5269819633603645e-07,0.0001624,30.612318799999997,166.93115322821933,2.8079838828036117
2.7137047685347755e-07,0.00017439999999999998,32.8743128,166.93115322821933,2.8079838828036117
2.9502203217556967e-07,0.0001896,35.7395052,166.93115322821933,2.8079838828036117
3.0373576308370885e-07,0.0001952,36.7951024,166.93115322821933,2.8079838828036117
3.0622540048603433e-07,0.00019679999999999999,37.096701599999996,166.93115322821933,2.8079838828036117
3.199184061988245e-07,0.00020559999999999998,38.75549719999999,166.93115322821933,2.8079838828036117
3.273873184058009e-07,0.0002104,39.660294799999996,166.93115322821933,2.8079838828036117
3.398355054174284e-07,0.0002184,41.1682908,166.93115322821933,2.8079838828036117
3.597526046360322e-07,0.00023119999999999998,43.581084399999995,166.93115322821933,2.8079838828036117
3.809145225557988e-07,0.0002448,46.144677599999994,166.93115322821933,2.8079838828036117
4.107901713837046e-07,0.00026399999999999997,49.763867999999995,166.93115322821933,2.8079838828036117
4.3568654540695943e-07,0.00028,52.77985999999999,166.93115322821933,2.8079838828036117
4.85479293453469e-07,0.000312,58.811844,166.93115322821933,2.8079838828036117
5.24068673189514e-07,0.0003368,63.4866316,166.93115322821933,2.8079838828036117
5.315375853964905e-07,0.0003416,64.3914292,166.93115322821933,2.8079838828036117
5.439857724081179e-07,0.0003496,65.8994252,166.93115322821933,2.8079838828036117
5.800855147418374e-07,0.0003728,70.2726136,166.93115322821933,2.8079838828036117
6.634883677197411e-07,0.00042639999999999996,80.37618679999999,166.93115322821933,2.8079838828036117
7.058122035592742e-07,0.00045359999999999997,85.5033732,166.93115322821933,2.8079838828036117
7.195052092720644e-07,0.00046239999999999996,87.16216879999999,166.93115322821933,2.8079838828036117
7.294637588813664e-07,0.00046879999999999996,88.3685656,166.93115322821933,2.8079838828036117
7.331982149848545e-07,0.00047119999999999996,88.8209644,166.93115322821933,2.8079838828036117
7.468912206976447e-07,0.00047999999999999996,90.47976,166.93115322821933,2.8079838828036117
7.605842264104348e-07,0.0004888,92.13855559999999,166.93115322821933,2.8079838828036117
7.854806004336897e-07,0.0005048,95.1545476,166.93115322821933,2.8079838828036117
8.07887337054619e-07,0.0005191999999999999,97.86894039999999,166.93115322821933,2.8079838828036117
8.701282721127561e-07,0.0005591999999999999,105.40892039999999,166.93115322821933,2.8079838828036117
8.763523656185699e-07,0.0005632,106.16291840000001,166.93115322821933,2.8079838828036117
9.124521079522892e-07,0.0005863999999999999,110.53610679999998,166.93115322821933,2.8079838828036117
9.174313827569403e-07,0.0005896,111.13930520000001,166.93115322821933,2.8079838828036117
9.560207624929852e-07,0.0006144,115.8140928,166.93115322821933,2.8079838828036117
9.846515926197283e-07,0.0006328,119.28248359999999,166.93115322821933,2.8079838828036117
9.995894170336812e-07,0.0006424,121.0920788,166.93115322821933,2.8079838828036117
1.0717889017011202e-06,0.0006887999999999999,129.83845559999997,166.93115322821933,2.8079838828036117
1.086726726115073e-06,0.0006984,131.6480508,166.93115322821933,2.8079838828036117
1.1439883863685593e-06,0.0007352,138.5848324,166.93115322821933,2.8079838828036117
1.1527021172766985e-06,0.0007408,139.6404296,166.93115322821933,2.8079838828036117
1.1950259531162316e-06,0.000768,144.767616,166.93115322821933,2.8079838828036117
1.1987604092197198e-06,0.0007704,145.2200148,166.93115322821933,2.8079838828036117
1.2199223271394864e-06,0.000784,147.783608,166.93115322821933,2.8079838828036117
1.2460635198639039e-06,0.0008008,150.9503996,166.93115322821933,2.8079838828036117
1.298345905312739e-06,0.0008344,157.2839828,166.93115322821933,2.8079838828036117
1.3107940923243666e-06,0.0008424,158.7919788,166.93115322821933,2.8079838828036117
1.3431593785545977e-06,0.0008632,162.7127684,166.93115322821933,2.8079838828036117
1.395441764003433e-06,0.0008968,169.0463516,166.93115322821933,2.8079838828036117
1.4103795884173858e-06,0.0009063999999999999,170.85594679999997,166.93115322821933,2.8079838828036117
1.429051868934827e-06,0.0009184,173.11794079999999,166.93115322821933,2.8079838828036117
1.4551930616592445e-06,0.0009352,176.2847324,166.93115322821933,2.8079838828036117
1.4639067925673837e-06,0.0009408,177.3403296,166.93115322821933,2.8079838828036117
1.509965084510405e-06,0.0009704,182.9199148,166.93115322821933,2.8079838828036117
1.5385959146371481e-06,0.0009888,186.3883056,166.93115322821933,2.8079838828036117
1.5858990252813326e-06,0.0010192,192.11869040000002,166.93115322821933,2.8079838828036117
1.592123118787146e-06,0.0010232,192.8726884,166.93115322821933,2.8079838828036117
1.635691773327842e-06,0.0010512,198.15067439999999,166.93115322821933,2.8079838828036117
1.6668122408569106e-06,0.0010712,201.9206644,166.93115322821933,2.8079838828036117
1.6917086148801654e-06,0.0010872,204.9366564,166.93115322821933,2.8079838828036117
1.726563538512722e-06,0.0011095999999999999,209.15904519999998,166.93115322821933,2.8079838828036117
1.736522088122024e-06,0.001116,210.365442,166.93115322821933,2.8079838828036117
1.7950285670766727e-06,0.0011535999999999999,217.45302319999996,166.93115322821933,2.8079838828036117
1.8199249410999277e-06,0.0011696,220.4690152,166.93115322821933,2.8079838828036117
1.8460661338243452e-06,0.0011864,223.6358068,166.93115322821933,2.8079838828036117
1.8958588818708549e-06,0.0012184,229.66779079999998,166.93115322821933,2.8079838828036117
1.9020829753766687e-06,0.0012224,230.4217888,166.93115322821933,2.8079838828036117
1.915775981089459e-06,0.0012312,232.0805844,166.93115322821933,2.8079838828036117
1.938182717710388e-06,0.0012456,234.79497719999998,166.93115322821933,2.8079838828036117
1.954365360825504e-06,0.001256,236.755372,166.93115322821933,2.8079838828036117
1.9979340153661997e-06,0.001284,237.28754933113555,166.93115322821933,2.8079838828036117
2.0464819447115466e-06,0.0013151999999999999,237.50298938757112,166.93115322821933,2.8079838828036117
2.058930131723174e-06,0.0013231999999999999,237.55790820629318,166.93115322821933,2.8079838828036117
2.0763575935394524e-06,0.0013344,237.63457749922335,166.93115322821933,2.8079838828036117
2.1087228797696835e-06,0.0013552,237.77630077064063,166.93115322821933,2.8079838828036117
2.1249055228847993e-06,0.0013656,237.84684409461633,166.93115322821933,2.8079838828036117
2.1560259904138677e-06,0.0013855999999999999,237.9819182044737,166.93115322821933,2.8079838828036117
2.1709638148278204e-06,0.0013951999999999999,238.04648350617038,166.93115322821933,2.8079838828036117
2.17967754573596e-06,0.0014008,238.08406658696748,166.93115322821933,2.8079838828036117
2.2356943872882835e-06,0.0014368,238.32428790565933,166.93115322821933,2.8079838828036117
2.2693044922196774e-06,0.0014583999999999999,238.46729414342298,166.93115322821933,2.8079838828036117
2.302914597151071e-06,0.00148,238.60947669473273,166.93115322821933,2.8079838828036117
2.319097240266187e-06,0.0014904,238.67764612801548,166.93115322821933,2.8079838828036117
2.337769520783628e-06,0.0015023999999999999,238.75607306689022,166.93115322821933,2.8079838828036117
2.3502177077952554e-06,0.0015103999999999999,238.80822201274862,166.93115322821933,2.8079838828036117
2.4174379176580435e-06,0.0015536,239.08798652186945,166.93115322821933,2.8079838828036117
2.4560272973940885e-06,0.0015784,239.24722108681343,166.93115322821933,2.8079838828036117
2.4647410283022278e-06,0.001584,239.2830418872277,166.93115322821933,2.8079838828036117
2.4946166771301335e-06,0.0016032,239.4054828420125,166.93115322821933,2.8079838828036117
2.5033304080382723e-06,0.0016087999999999999,239.44108688980947,166.93115322821933,2.8079838828036117
2.5182682324522254e-06,0.0016183999999999999,239.50201015552562,166.93115322821933,2.8079838828036117
2.5705506179010604e-06,0.0016519999999999998,239.71414048516138,166.93115322821933,2.8079838828036117
2.60665036023478e-06,0.0016752,239.8596303723834,166.93115322821933,2.8079838828036117
2.6141192724417566e-06,0.0016799999999999999,239.88963338225932,166.93115322821933,2.8079838828036117
2.6477293773731504e-06,0.0017016,240.02423533761922,166.93115322821933,2.8079838828036117
2.661422383085941e-06,0.0017104,240.07888193215385,166.93115322821933,2.8079838828036117
2.6713809326952428e-06,0.0017167999999999999,240.11855606233593,166.93115322821933,2.8079838828036117
2.680094663603382e-06,0.0017224,240.15322363391317,166.93115322821933,2.8079838828036117
2.716194405937101e-06,0.0017456,240.29638063258193,166.93115322821933,2.8079838828036117
2.7410907799603562e-06,0.0017615999999999999,240.39467754579323,166.93115322821933,2.8079838828036117
2.74731487346617e-06,0.0017656,240.41919729346967,166.93115322821933,2.8079838828036117
2.7821697970987266e-06,0.0017879999999999999,240.55610961506363,166.93115322821933,2.8079838828036117
2.813290264627795e-06,0.001808,240.67778850006584,166.93115322821933,2.8079838828036117
2.83818663865105e-06,0.0018239999999999999,240.77475407011988,166.93115322821933,2.8079838828036117
2.844410732156864e-06,0.001828,240.79894356095178,166.93115322821933,2.8079838828036117
2.894203480203373e-06,0.0018599999999999999,240.9917218693555,166.93115322821933,2.8079838828036117
2.9514651404568593e-06,0.0018968,241.21182500157562,166.93115322821933,2.8079838828036117
2.9664029648708124e-06,0.0019064,241.26896852265781,166.93115322821933,2.8079838828036117
2.9937889762963928e-06,0.001924,241.37344101953906,166.93115322821933,2.8079838828036117
3.0000130698022062e-06,0.0019279999999999998,241.39713271128798,166.93115322821933,2.8079838828036117
3.022419806423136e-06,0.0019424,241.4822645359219,166.93115322821933,2.8079838828036117
3.062254004860343e-06,0.0019679999999999997,241.6330047312113,166.93115322821933,2.8079838828036117
3.0771918292742962e-06,0.0019776,241.6893349012623,166.93115322821933,2.8079838828036117
3.0883951975847613e-06,0.0019848,241.73151256999793,166.93115322821933,2.8079838828036117
3.1244949399184805e-06,0.002008,241.86701427217454,166.93115322821933,2.8079838828036117
3.170553231861502e-06,0.0020376,242.03901257167377,166.93115322821933,2.8079838828036117
3.1805117814708035e-06,0.002044,242.0760729532686,166.93115322821933,2.8079838828036117
3.2228356173103374e-06,0.0020712,242.23307735826847,166.93115322821933,2.8079838828036117
3.256445722241731e-06,0.0020927999999999997,242.35718522602676,166.93115322821933,2.8079838828036117
3.3037488328859155e-06,0.0021232,242.53101256318286,166.93115322821933,2.8079838828036117
3.3336244817138213e-06,0.0021424,242.64029829435765,166.93115322821933,2.8079838828036117
3.3498071248289366e-06,0.0021528,242.699335220246,166.93115322821933,2.8079838828036117
3.3784379549556797e-06,0.0021712,242.8035134095178,166.93115322821933,2.8079838828036117
3.4020895102777716e-06,0.0021864,242.88931419870664,166.93115322821933,2.8079838828036117
3.4132928785882366e-06,0.0021936,242.92987545405907,166.93115322821933,2.8079838828036117
3.446902983519631e-06,0.0022152,243.0512488284252,166.93115322821933,2.8079838828036117
3.4854923632556755e-06,0.00224,243.19003569642965,166.93115322821933,2.8079838828036117
3.4904716380603262e-06,0.0022432,243.20789992728513,166.93115322821933,2.8079838828036117
3.5054094624742797e-06,0.0022528,243.2614330826363,166.93115322821933,2.8079838828036117
3.5153680120835812e-06,0.0022592,243.2970724343742,166.93115322821933,2.8079838828036117
3.540264386106836e-06,0.0022752,243.38599898083783,166.93115322821933,2.8079838828036117
3.562671122727765e-06,0.0022895999999999997,243.46582456157998,166.93115322821933,2.8079838828036117
3.5888123154521828e-06,0.0023063999999999997,243.5587073589359,166.93115322821933,2.8079838828036117
3.6311361512917163e-06,0.0023336,243.70853154547677,166.93115322821933,2.8079838828036117
3.654787706613808e-06,0.0023488,243.79196014829276,166.93115322821933,2.8079838828036117
3.6597669814184593e-06,0.002352,243.80949720446228,166.93115322821933,2.8079838828036117
3.7008459985568293e-06,0.0023783999999999997,243.95382456512476,166.93115322821933,2.8079838828036117
3.733211284787061e-06,0.0023991999999999998,244.06709744715988,166.93115322821933,2.8079838828036117
3.7493939279021766e-06,0.0024096,244.12359022007834,166.93115322821933,2.8079838828036117
3.784248851534733e-06,0.0024319999999999997,244.24494499613368,166.93115322821933,2.8079838828036117
3.796697038546361e-06,0.00244,244.28818024290553,166.93115322821933,2.8079838828036117
3.800431494649849e-06,0.0024424,244.30114003189303,166.93115322821933,2.8079838828036117
3.830307143477755e-06,0.0024616,244.4046401483779,166.93115322821933,2.8079838828036117
3.845244967891707e-06,0.0024712,244.45627210725522,166.93115322821933,2.8079838828036117
3.89628253463938e-06,0.0025039999999999997,244.63209407065003,166.93115322821933,2.8079838828036117
3.917444452559147e-06,0.0025176,244.7047321679198,166.93115322821933,2.8079838828036117
3.949809738789377e-06,0.0025383999999999997,244.81553042582547,166.93115322821933,2.8079838828036117
3.961013107099842e-06,0.0025456,244.85380109906387,166.93115322821933,2.8079838828036117
3.998357668134725e-06,0.0025696,244.9810662135466,166.93115322821933,2.8079838828036117
4.013295492548678e-06,0.0025792,245.03184235662687,166.93115322821933,2.8079838828036117
4.020764404755654e-06,0.002584,245.05720278411334,166.93115322821933,2.8079838828036117
4.046905597480072e-06,0.0026008,245.14581995862684,166.93115322821933,2.8079838828036117
4.06433305929635e-06,0.0026119999999999997,245.2047740808897,166.93115322821933,2.8079838828036117
4.074291608905652e-06,0.0026184,245.23841788602314,166.93115322821933,2.8079838828036117
4.115370626044022e-06,0.0026447999999999997,245.3768609338968,166.93115322821933,2.8079838828036117
4.131553269159138e-06,0.0026552,245.43125100037446,166.93115322821933,2.8079838828036117
4.1340429065614636e-06,0.0026568,245.43961132283633,166.93115322821933,2.8079838828036117
4.145246274871928e-06,0.0026639999999999997,245.47720850114507,166.93115322821933,2.8079838828036117
4.177611561102159e-06,0.0026847999999999998,245.5856006026872,166.93115322821933,2.8079838828036117
4.231138765252157e-06,0.0027191999999999997,245.76414849926107,166.93115322821933,2.8079838828036117
4.269728144988202e-06,0.002744,245.89232305148337,166.93115322821933,2.8079838828036117
4.290890062907969e-06,0.0027576,245.96242048576164,166.93115322821933,2.8079838828036117
4.305827887321922e-06,0.0027672,246.01181987518854,166.93115322821933,2.8079838828036117
4.310807162126573e-06,0.0027703999999999997,246.02827147978,166.93115322821933,2.8079838828036117
4.328234623942851e-06,0.0027816,246.08579382475526,166.93115322821933,2.8079838828036117
4.351886179264943e-06,0.0027968,246.16371559372897,166.93115322821933,2.8079838828036117
4.42284084523122e-06,0.0028423999999999997,246.39649592010593,166.93115322821933,2.8079838828036117
4.467654318473078e-06,0.0028712,246.54276493561525,166.93115322821933,2.8079838828036117
4.487571417691682e-06,0.002884,246.6075896016654,166.93115322821933,2.8079838828036117
4.506243698209123e-06,0.0028959999999999997,246.66826089411254,166.93115322821933,2.8079838828036117
4.5398538031405174e-06,0.0029176,246.7772227204118,166.93115322821933,2.8079838828036117
4.556036446255633e-06,0.002928,246.8295735785548,166.93115322821933,2.8079838828036117
4.583422457681213e-06,0.0029456,246.9180024342936,166.93115322821933,2.8079838828036117
4.600849919497492e-06,0.0029568,246.9741680706193,166.93115322821933,2.8079838828036117
4.639439299233537e-06,0.0029816,247.09824040945864,166.93115322821933,2.8079838828036117
4.7016802342916736e-06,0.0030215999999999997,247.29751233850322,166.93115322821933,2.8079838828036117
4.768900444154462e-06,0.0030648,247.5115739647891,166.93115322821933,2.8079838828036117
4.793796818177717e-06,0.0030808,247.59055700816702,166.93115322821933,2.8079838828036117
4.8025105490858555e-06,0.0030864,247.61816325806555,166.93115322821933,2.8079838828036117
4.829896560511436e-06,0.003104,247.70479885568668,166.93115322821933,2.8079838828036117
4.8485688410288775e-06,0.003116,247.76375876820273,166.93115322821933,2.8079838828036117
4.856037753235854e-06,0.0031208,247.78731793029374,166.93115322821933,2.8079838828036117
4.872220396350969e-06,0.0031311999999999998,247.8383143560426,166.93115322821933,2.8079838828036117
4.889647858167248e-06,0.0031424,247.8931597643955,166.93115322821933,2.8079838828036117
4.900851226477712e-06,0.0031496,247.92837727367893,166.93115322821933,2.8079838828036117
4.936950968811432e-06,0.0031728,248.0416429268407,166.93115322821933,2.8079838828036117
4.946909518420733e-06,0.0031791999999999996,248.07283172295428,166.93115322821933,2.8079838828036117
4.976785167248639e-06,0.0031983999999999997,248.16625152327703,166.93115322821933,2.8079838828036117
5.015374546984684e-06,0.0032232,248.28659570185926,166.93115322821933,2.8079838828036117
5.039026102306776e-06,0.0032384,248.36017656299916,166.93115322821933,2.8079838828036117
5.052719108019567e-06,0.0032472,248.4027144458009,166.93115322821933,2.8079838828036117
5.0689017511346824e-06,0.0032576,248.45292856951687,166.93115322821933,2.8079838828036117
5.0726362072381705e-06,0.00326,248.46450756091045,166.93115322821933,2.8079838828036117
5.08632921295096e-06,0.0032687999999999997,248.5069354494761,166.93115322821933,2.8079838828036117
5.0950429438591e-06,0.0032744,248.53391182310173,166.93115322821933,2.8079838828036117
5.10873594957189e-06,0.0032832,248.57626694262095,166.93115322821933,2.8079838828036117
5.129897867491657e-06,0.0032968,248.64163787297736,166.93115322821933,2.8079838828036117
5.156039060216074e-06,0.0033136,248.7222451786684,166.93115322821933,2.8079838828036117
5.17222170333119e-06,0.0033239999999999997,248.77206507321694,166.93115322821933,2.8079838828036117
5.214545539170723e-06,0.0033512,248.90207669440744,166.93115322821933,2.8079838828036117
5.2232592700788625e-06,0.0033568,248.92879263393195,166.93115322821933,2.8079838828036117
5.225748907481187e-06,0.0033583999999999997,248.93642256618875,166.93115322821933,2.8079838828036117
5.26309346851607e-06,0.0033824,249.05070196978485,166.93115322821933,2.8079838828036117
5.271807199424209e-06,0.003388,249.0773216083458,166.93115322821933,2.8079838828036117
5.284255386435837e-06,0.0033959999999999997,249.11531991581936,166.93115322821933,2.8079838828036117
5.3041724856544405e-06,0.0034088,249.1760446754472,166.93115322821933,2.8079838828036117
5.311641397861417e-06,0.0034135999999999997,249.19879352536395,166.93115322821933,2.8079838828036117
5.321599947470719e-06,0.00342,249.22910592867746,166.93115322821933,2.8079838828036117
5.358944508505601e-06,0.003444,249.34258094989596,166.93115322821933,2.8079838828036117
5.371392695517228e-06,0.0034519999999999998,249.38033736912027,166.93115322821933,2.8079838828036117
5.3776167890230425e-06,0.003456,249.39920278070505,166.93115322821933,2.8079838828036117
5.387575338632344e-06,0.0034624,249.42936973639937,166.93115322821933,2.8079838828036117
5.44483699888583e-06,0.0034992,249.60240956163258,166.93115322821933,2.8079838828036117
5.467243735506759e-06,0.0035136,249.6699274232496,166.93115322821933,2.8079838828036117
5.490895290828851e-06,0.0035288,249.74107930502197,166.93115322821933,2.8079838828036117
5.518281302254432e-06,0.0035464,249.82331653962663,166.93115322821933,2.8079838828036117
5.530729489266059e-06,0.0035543999999999997,249.86064446779906,166.93115322821933,2.8079838828036117
5.543177676277687e-06,0.0035624,249.89793964440904,166.93115322821933,2.8079838828036117
5.558115500691639e-06,0.0035719999999999997,249.94265076812243,166.93115322821933,2.8079838828036117
5.602928973933498e-06,0.0036008,250.07650379833308,166.93115322821933,2.8079838828036117
5.632804622761404e-06,0.00362,250.1655072647026,166.93115322821933,2.8079838828036117
5.681352552106751e-06,0.0036512,250.30974624039493,166.93115322821933,2.8079838828036117
5.711228200934657e-06,0.0036704,250.39826979563608,166.93115322821933,2.8079838828036117
5.73114530015326e-06,0.0036831999999999998,250.45718518820922,166.93115322821933,2.8079838828036117
5.764755405084654e-06,0.0037048,250.55642416758096,166.93115322821933,2.8079838828036117
5.788406960406746e-06,0.0037199999999999998,250.62612378343462,166.93115322821933,2.8079838828036117
5.80832405962535e-06,0.0037327999999999997,250.68473209117278,166.93115322821933,2.8079838828036117
5.820772246636978e-06,0.0037408,250.72132248457697,166.93115322821933,2.8079838828036117
5.870564994683488e-06,0.0037727999999999998,250.86737990656815,166.93115322821933,2.8079838828036117
5.896706187407905e-06,0.0037895999999999997,250.94386660277397,166.93115322821933,2.8079838828036117
5.916623286626509e-06,0.0038023999999999996,251.00205345343159,166.93115322821933,2.8079838828036117
5.919112924028834e-06,0.0038039999999999997,251.00932143471704,166.93115322821933,2.8079838828036117
5.966416034673019e-06,0.0038344,251.147187365916,166.93115322821933,2.8079838828036117
5.98508831519046e-06,0.0038464,251.20149070214313,166.93115322821933,2.8079838828036117
5.996291683500924e-06,0.0038536,251.23404099020416,166.93115322821933,2.8079838828036117
6.0149639640183655e-06,0.0038656,251.28823881227353,166.93115322821933,2.8079838828036117
6.017453601420691e-06,0.0038672,251.2954602277,166.93115322821933,2.8079838828036117
6.034881063236969e-06,0.0038783999999999997,251.34597754943815,166.93115322821933,2.8079838828036117
6.056042981156736e-06,0.0038919999999999996,251.4072435880696,166.93115322821933,2.8079838828036117
6.097121998295106e-06,0.0039184,251.52593395864642,166.93115322821933,2.8079838828036117
6.117039097513711e-06,0.0039312,251.5833685092161,166.93115322821933,2.8079838828036117
6.1382010154334775e-06,0.0039448,251.6443128646031,166.93115322821933,2.8079838828036117
6.189238582181149e-06,0.0039775999999999995,251.79096016276654,166.93115322821933,2.8079838828036117
6.209155681399753e-06,0.0039904,251.84806034869385,166.93115322821933,2.8079838828036117
6.3735016315783885e-06,0.004096019203840768,252.31652662663677,166.93115322821933,2.8079838828036117
6.791844383719498e-06,0.004364872974594919,253.48822857453837,166.93115322821933,2.8079838828036117
7.837701264072271e-06,0.0050370074014802965,256.30049845155935,166.93115322821933,2.8079838828036117
9.391545772024962e-06,0.006035607121424285,260.2215959962117,166.93115322821933,2.8079838828036117
9.959296649930754e-06,0.006400480096019204,261.58996273005204,166.93115322821933,2.8079838828036117
1.0855745404518846e-05,0.006976595319063813,263.690135431195,166.93115322821933,2.8079838828036117
1.1722312533953999e-05,0.007533506701340268,265.65687173123933,166.93115322821933,2.8079838828036117
1.2110773660942172e-05,0.007783156631326265,266.5200123155918,166.93115322821933,2.8079838828036117
1.2857814289765583e-05,0.008263252650530106,268.1501322635884,166.93115322821933,2.8079838828036117
1.3007222415530264e-05,0.008359271854370874,268.47167690424976,166.93115322821933,2.8079838828036117
1.4082960921035974e-05,0.009050610122024405,270.7457049741228,166.93115322821933,2.8079838828036117
1.4590948548635892e-05,0.009377075415083017,271.795898686157,166.93115322821933,2.8079838828036117
1.4919646425318193e-05,0.009588317663532707,272.46784444509484,166.93115322821933,2.8079838828036117
1.5427634052918113e-05,0.009914782956591319,273.49505925876684,166.93115322821933,2.8079838828036117
1.590574005536509e-05,0.010222044408881775,274.4498636234514,166.93115322821933,2.8079838828036117
1.6204556306894454e-05,0.010414082816563312,275.04093535057,166.93115322821933,2.8079838828036117
1.674242555964731e-05,0.010759751950390077,276.0942616693806,166.93115322821933,2.8079838828036117
1.6861952060259056e-05,0.010836567313462692,276.3265322332041,166.93115322821933,2.8079838828036117
1.707112343632961e-05,0.010970994198839769,276.73146651362094,166.93115322821933,2.8079838828036117
1.7489466188470722e-05,0.01123984796959392,277.53557604467443,166.93115322821933,2.8079838828036117
1.7698637564541274e-05,0.011374274854970993,277.9348151834147,166.93115322821933,2.8079838828036117
1.8116980316682385e-05,0.011643128625725144,278.72781521583426,166.93115322821933,2.8079838828036117
1.8296270067600003e-05,0.011758351670334066,279.06548257984986,166.93115322821933,2.8079838828036117
1.8744494444894047e-05,0.01204640928185637,279.9040536934856,166.93115322821933,2.8079838828036117
1.898354744611754e-05,0.0122000400080016,280.3480921344199,166.93115322821933,2.8079838828036117
1.922260044734103e-05,0.012353670734146829,280.78995512244893,166.93115322821933,2.8079838828036117
2.053739195407023e-05,0.013198639727945589,283.1829381433463,166.93115322821933,2.8079838828036117
2.0597155204376104e-05,0.013237047409481896,283.2902672532805,166.93115322821933,2.8079838828036117
2.1643012084728877e-05,0.013909181836367274,285.14930059774997,166.93115322821933,2.8079838828036117
2.2001591586564114e-05,0.014139627925585117,285.77857352675875,166.93115322821933,2.8079838828036117
2.230040783809348e-05,0.014331666333266654,286.2999179808218,166.93115322821933,2.8079838828036117
2.253946083931697e-05,0.014485297059411883,286.71503456411756,166.93115322821933,2.8079838828036117
2.2838277090846335e-05,0.01467733546709342,287.2315235484157,166.93115322821933,2.8079838828036117
2.3674962595128553e-05,0.015215043008601721,288.6638563237445,166.93115322821933,2.8079838828036117
2.51092806024695e-05,0.016136827365473096,291.0741735482009,166.93115322821933,2.8079838828036117
2.591608448159878e-05,0.016655331066213242,292.4063601407215,166.93115322821933,2.8079838828036117
2.6752769985880998e-05,0.017193038607721544,293.77091183944844,166.93115322821933,2.8079838828036117
2.7141231112869175e-05,0.017442688537707543,294.39878612185487,166.93115322821933,2.8079838828036117
2.744004736439853e-05,0.017634726945389076,294.879384390435,166.93115322821933,2.8079838828036117
2.824685124352782e-05,0.018153230646129226,296.16691152182943,166.93115322821933,2.8079838828036117
2.8934128622045358e-05,0.01859491898379676,297.2524205851491,166.93115322821933,2.8079838828036117
2.911341837296297e-05,0.01871014202840568,297.5339371698487,166.93115322821933,2.8079838828036117
2.932258974903353e-05,0.018844568913782757,297.861520053986,166.93115322821933,2.8079838828036117
2.93823529993394e-05,0.018882976595319064,297.95494760949236,166.93115322821933,2.8079838828036117
2.9471997874798206e-05,0.018940588117623523,298.0949501034886,166.93115322821933,2.8079838828036117
2.962140600056289e-05,0.019036607321464293,298.3279190913638,166.93115322821933,2.8079838828036117
2.9860459001786383e-05,0.019190238047609522,298.6997185097994,166.93115322821933,2.8079838828036117
3.0069630377856935e-05,0.019324664932986596,299.0240917861763,166.93115322821933,2.8079838828036117
3.099596075759797e-05,0.01991998399679936,300.4501528869635,166.93115322821933,2.8079838828036117
3.132465863428026e-05,0.02013122624524905,300.9521664610171,166.93115322821933,2.8079838828036117
3.207169926310368e-05,0.02061132226445289,302.085527939524,166.93115322821933,2.8079838828036117
3.2310752264327166e-05,0.02076495299059812,302.4460229595289,166.93115322821933,2.8079838828036117
3.240039713978597e-05,0.02082256451290258,302.5809402298933,166.93115322821933,2.8079838828036117
3.290838476738589e-05,0.021149029805961193,303.3427393174384,166.93115322821933,2.8079838828036117
3.3296845894374065e-05,0.02139867973594719,303.9222010697887,166.93115322821933,2.8079838828036117
3.3625543771056365e-05,0.02160992198439688,304.4104584768121,166.93115322821933,2.8079838828036117
3.425305789926803e-05,0.022013202640528105,305.3374481428675,166.93115322821933,2.8079838828036117
3.517938827900906e-05,0.02260852170434087,306.693846912279,166.93115322821933,2.8079838828036117
3.5448322905385485e-05,0.02278135627125425,307.08502169239233,166.93115322821933,2.8079838828036117
3.6075837033597154e-05,0.02318463692738548,307.9932892604721,166.93115322821933,2.8079838828036117
3.6524061410891195e-05,0.023472694538907782,308.63828341685394,166.93115322821933,2.8079838828036117
3.748027341578516e-05,0.024087217443488698,310.004043161606,166.93115322821933,2.8079838828036117
3.771932641700865e-05,0.024240848169633927,310.34335139448746,166.93115322821933,2.8079838828036117
3.903411792373785e-05,0.025085817163432687,312.1947677306124,166.93115322821933,2.8079838828036117
3.936281580042015e-05,0.025297059411882376,312.653801678879,166.93115322821933,2.8079838828036117
4.0079974804090625e-05,0.025757951590318063,313.65017309094753,166.93115322821933,2.8079838828036117
4.034890943046705e-05,0.025930786157231447,314.02201669984976,166.93115322821933,2.8079838828036117
4.163381931204331e-05,0.026756551310262052,315.7854313369873,166.93115322821933,2.8079838828036117
4.1783227437808e-05,0.026852570514102822,315.9890927837605,166.93115322821933,2.8079838828036117
4.1932635563572675e-05,0.02694858971794359,316.19247040988887,166.93115322821933,2.8079838828036117
4.270955781754902e-05,0.027447889577915583,317.2455127414953,166.93115322821933,2.8079838828036117
4.378529632305473e-05,0.028139227845569114,318.6913201151388,166.93115322821933,2.8079838828036117
4.4263402325501717e-05,0.028446489297859572,319.3294473241064,166.93115322821933,2.8079838828036117
4.480127157825457e-05,0.028792158431686338,320.0441359468029,166.93115322821933,2.8079838828036117
4.581724683345441e-05,0.02944508901780356,321.38503877426666,166.93115322821933,2.8079838828036117
4.6145944710136704e-05,0.02965633126625325,321.8163708776519,166.93115322821933,2.8079838828036117
4.650452421197194e-05,0.029886777355471093,322.28555070564653,166.93115322821933,2.8079838828036117
4.7072275089877736e-05,0.030251650330066014,323.0255435548579,166.93115322821933,2.8079838828036117
4.796872384446583e-05,0.030827765553110623,324.1869053339833,166.93115322821933,2.8079838828036117
4.8148013595383446e-05,0.030942988597719545,324.41815858090007,166.93115322821933,2.8079838828036117
4.9223752100889156e-05,0.031634326865373076,325.7986905650542,166.93115322821933,2.8079838828036117
4.994091110455963e-05,0.03209521904380876,326.71251371800645,166.93115322821933,2.8079838828036117
5.03293722315478e-05,0.03234486897379476,327.2053638045861,166.93115322821933,2.8079838828036117
5.0986767984912395e-05,0.032767353470694136,328.03605141876113,166.93115322821933,2.8079838828036117
5.1345347486747646e-05,0.032997799559911986,328.48739278255664,166.93115322821933,2.8079838828036117
5.358646937321786e-05,0.034438087617523504,331.2809233676156,166.93115322821933,2.8079838828036117
5.376575912413548e-05,0.03455331066213242,331.50241795357925,166.93115322821933,2.8079838828036117
5.499090575540588e-05,0.035340668133626726,333.00832828598254,166.93115322821933,2.8079838828036117
5.627581563698215e-05,0.036166433286657335,334.5737065362888,166.93115322821933,2.8079838828036117
5.762048876886428e-05,0.03703060612122425,336.19703833857983,166.93115322821933,2.8079838828036117
5.8038831521005394e-05,0.0372994598919784,336.6990527347337,166.93115322821933,2.8079838828036117
5.9353623027734586e-05,0.038144428885777154,338.2677025317425,166.93115322821933,2.8079838828036117
6.0190308532016814e-05,0.03868213642728546,339.2588819726562,166.93115322821933,2.8079838828036117
6.0728177784769666e-05,0.039027805561112225,339.89323234353685,166.93115322821933,2.8079838828036117
6.114652053691078e-05,0.03929665933186638,340.38510228401935,166.93115322821933,2.8079838828036117
6.237166716818115e-05,0.04008401680336067,341.8180842746306,166.93115322821933,2.8079838828036117
6.258083854425172e-05,0.040218443688737754,342.0616385077139,166.93115322821933,2.8079838828036117
6.287965479578108e-05,0.04041048209641929,342.409023111542,166.93115322821933,2.8079838828036117
6.311870779700457e-05,0.040564112822564516,342.68646746284224,166.93115322821933,2.8079838828036117
6.395539330128678e-05,0.04110182036407281,343.6543118923239,166.93115322821933,2.8079838828036117
6.440361767858084e-05,0.041389877975595124,344.17076812944333,166.93115322821933,2.8079838828036117
6.473231555526314e-05,0.041601120224044816,344.5486122237915,166.93115322821933,2.8079838828036117
6.524030318286306e-05,0.04192758551710342,345.1310846380456,166.93115322821933,2.8079838828036117
6.571840918531003e-05,0.04223484696939388,345.6776802759254,166.93115322821933,2.8079838828036117
6.628616006321582e-05,0.0425997199439888,346.3247524154133,166.93115322821933,2.8079838828036117
6.709296394234511e-05,0.04311822364472895,347.2405700557483,166.93115322821933,2.8079838828036117
6.745154344418034e-05,0.043348669733946785,347.64622041571164,166.93115322821933,2.8079838828036117
6.795953107178027e-05,0.0436751350270054,348.2194550366902,166.93115322821933,2.8079838828036117
6.804917594723908e-05,0.043732746549309864,348.320440374939,166.93115322821933,2.8079838828036117
6.903526957728597e-05,0.044366473294658926,349.427876408856,166.93115322821933,2.8079838828036117
6.945361232942707e-05,0.04463532706541308,349.8958320096975,166.93115322821933,2.8079838828036117
7.124650983860328e-05,0.045787557511502305,351.8890318672572,166.93115322821933,2.8079838828036117
7.187402396681494e-05,0.04619083816763353,352.5820177061967,166.93115322821933,2.8079838828036117
7.259118297048541e-05,0.04665173034606922,353.3711187286593,166.93115322821933,2.8079838828036117
7.306928897293239e-05,0.046958991798359676,353.8954976281957,166.93115322821933,2.8079838828036117
7.342786847476762e-05,0.04718943788757751,354.2879041026166,166.93115322821933,2.8079838828036117
7.369680310114405e-05,0.0473622724544909,354.58171869641546,166.93115322821933,2.8079838828036117
7.465301510603802e-05,0.04797679535907182,355.62302318813914,166.93115322821933,2.8079838828036117
7.569887198639079e-05,0.048648929785957196,356.7560118111123,166.93115322821933,2.8079838828036117
7.671484724159063e-05,0.049301860372074416,357.8507980938239,166.93115322821933,2.8079838828036117
7.761129599617873e-05,0.04987797559511903,358.81209875934957,166.93115322821933,2.8079838828036117
7.793999387286102e-05,0.05008921784356872,359.1634894246087,166.93115322821933,2.8079838828036117
7.85973896262256e-05,0.05051170234046809,359.8645416880088,166.93115322821933,2.8079838828036117
7.877667937714323e-05,0.050626925385077015,360.05534039790905,166.93115322821933,2.8079838828036117
7.964324650657838e-05,0.05118383676735347,360.97515736868775,166.93115322821933,2.8079838828036117
7.976277300719015e-05,0.05126065213042609,361.10172167526,166.93115322821933,2.8079838828036117
8.080862988754291e-05,0.05193278655731147,362.2060219512448,166.93115322821933,2.8079838828036117
8.110744613907228e-05,0.052124824964993,362.52051070216066,166.93115322821933,2.8079838828036117
8.12867358899899e-05,0.05224004800960193,362.70898706262534,166.93115322821933,2.8079838828036117
8.164531539182512e-05,0.052470494098819764,363.0854541046003,166.93115322821933,2.8079838828036117
8.188436839304861e-05,0.05262412482496499,363.3360739561532,166.93115322821933,2.8079838828036117
8.254176414641323e-05,0.05304660932186438,364.0238115266185,166.93115322821933,2.8079838828036117
8.394620052860122e-05,0.05394918983796759,365.4859530520439,166.93115322821933,2.8079838828036117
8.44243065310482e-05,0.05425645129025805,365.9815226113651,166.93115322821933,2.8079838828036117
8.460359628196584e-05,0.054371674334866976,366.16707886164613,166.93115322821933,2.8079838828036117
8.481276765803638e-05,0.054506101220244046,366.3833674375519,166.93115322821933,2.8079838828036117
8.508170228441281e-05,0.054678935787157434,366.66114730954,166.93115322821933,2.8079838828036117
8.618732241507145e-05,0.05538947789557912,367.79955203038185,166.93115322821933,2.8079838828036117
8.678495491813018e-05,0.05577355471094218,368.41253399701253,166.93115322821933,2.8079838828036117
8.69642446690478e-05,0.05588877775555111,368.59610727611556,166.93115322821933,2.8079838828036117
8.726306092057716e-05,0.05608081616323264,368.901735079355,166.93115322821933,2.8079838828036117
8.780093017333002e-05,0.05642648529705942,369.4508385440961,166.93115322821933,2.8079838828036117
8.857785242730637e-05,0.05692578515703141,370.24167759606405,166.93115322821933,2.8079838828036117
8.902607680460041e-05,0.05721384276855371,370.6967003107929,166.93115322821933,2.8079838828036117
8.923524818067097e-05,0.05734826965393079,370.9087384008418,166.93115322821933,2.8079838828036117
8.968347255796501e-05,0.05763632726545309,371.3624541137095,166.93115322821933,2.8079838828036117
9.090861918923541e-05,0.058423684736947396,372.5981204891846,166.93115322821933,2.8079838828036117
9.117755381561183e-05,0.05859651930386077,372.8684930707679,166.93115322821933,2.8079838828036117
9.159589656775293e-05,0.058865373074614924,373.28845526728213,166.93115322821933,2.8079838828036117
9.282104319902334e-05,0.05965273054610923,374.51406257724653,166.93115322821933,2.8079838828036117
9.353820220269381e-05,0.060113622724544916,375.22856388054885,166.93115322821933,2.8079838828036117
9.431512445667016e-05,0.06061292258451691,376.0002003091517,166.93115322821933,2.8079838828036117
9.509204671064649e-05,0.0611122224444889,376.7693616991252,166.93115322821933,2.8079838828036117
9.539086296217586e-05,0.06130426085217043,377.0645399266252,166.93115322821933,2.8079838828036117
9.580920571431696e-05,0.061573114622924585,377.4771843276675,166.93115322821933,2.8079838828036117
9.628731171676395e-05,0.06188037607521504,377.94791846523475,166.93115322821933,2.8079838828036117
9.68251809695168e-05,0.062226045209041805,378.4764061064301,166.93115322821933,2.8079838828036117
9.781127459956371e-05,0.06285977195439088,379.4423359501527,166.93115322821933,2.8079838828036117
9.825949897685775e-05,0.06314782956591318,379.88013873341015,166.93115322821933,2.8079838828036117
9.846867035292831e-05,0.06328225645129026,380.0841800889169,166.93115322821933,2.8079838828036117
9.891689473022235e-05,0.06357031406281256,380.52084322542913,166.93115322821933,2.8079838828036117
9.960417210873989e-05,0.06401200240048009,381.1888975851261,166.93115322821933,2.8079838828036117
9.996275161057513e-05,0.06424244848969794,381.53673388580444,166.93115322821933,2.8079838828036117
0.00010100860849092791,0.06491458291658332,382.54848770029736,166.93115322821933,2.8079838828036117
0.00010160624099398662,0.06529865973194639,383.12479830566673,166.93115322821933,2.8079838828036117
0.00010256245299888059,0.0659131826365273,384.0441530902385,166.93115322821933,2.8079838828036117
0.00010393700775591567,0.06679655931186237,385.35989061567955,166.93115322821933,2.8079838828036117
0.0001050426278865743,0.06750710142028406,386.4132834150945,166.93115322821933,2.8079838828036117
0.00010581955014055065,0.06800640128025605,387.1509200241063,166.93115322821933,2.8079838828036117
0.00010626777451784471,0.06829445889177836,387.575518827899,166.93115322821933,2.8079838828036117
0.00010632753776815058,0.06833286657331467,387.63207918364077,166.93115322821933,2.8079838828036117
0.00010659647239452701,0.06850570114022805,387.8864475108674,166.93115322821933,2.8079838828036117
0.00010773197415033858,0.06923544708941788,388.9576994968012,166.93115322821933,2.8079838828036117
0.00010994321441165588,0.07065653130626126,391.0312678545497,166.93115322821933,2.8079838828036117
0.00011069025504047928,0.0711366273254651,391.7281136518057,166.93115322821933,2.8079838828036117
0.0001113476507938439,0.07155911182236448,392.3398221547197,166.93115322821933,2.8079838828036117
0.00011224409954843199,0.07213522704540909,393.17170506654526,166.93115322821933,2.8079838828036117
0.00011236362604904372,0.0722120424084817,393.2824266896582,166.93115322821933,2.8079838828036117
0.00011275208717603189,0.07246169233846769,393.64195514890235,166.93115322821933,2.8079838828036117
0.00011287161367664365,0.07253850770154031,393.7524820598818,166.93115322821933,2.8079838828036117
0.00011367841755577294,0.07305701140228046,394.4973483546834,166.93115322821933,2.8079838828036117
0.00011517249881341974,0.07401720344068814,395.87130874104093,166.93115322821933,2.8079838828036117
0.00011600918431770195,0.07455491098219644,396.6376898330329,166.93115322821933,2.8079838828036117
0.00011681598819683125,0.07507341468293659,397.3746612285757,166.93115322821933,2.8079838828036117
0.00011738373907473704,0.07543828765753151,397.8920812287589,166.93115322821933,2.8079838828036117
0.00011828018782932513,0.07601440288057612,398.7070774214897,166.93115322821933,2.8079838828036117
0.00011872841220661917,0.07630246049209842,399.11367189263404,166.93115322821933,2.8079838828036117
0.00011926628145937204,0.0766481296259252,399.60079590579636,166.93115322821933,2.8079838828036117
0.00011953521608574846,0.07682096419283857,399.84403657056674,166.93115322821933,2.8079838828036117
0.00012040178321518361,0.07737787557511502,400.62636419025216,166.93115322821933,2.8079838828036117
0.00012132811359492465,0.0779731946389278,401.4602210338515,166.93115322821933,2.8079838828036117
0.00012183610122252456,0.0782996599319864,401.91644310799,166.93115322821933,2.8079838828036117
0.00012207515422374806,0.07845329065813163,402.130879097801,166.93115322821933,2.8079838828036117
0.00012273254997711264,0.07887577515503101,402.7197352984362,166.93115322821933,2.8079838828036117
0.00012392781498323012,0.07964392878575716,403.7872410629811,166.93115322821933,2.8079838828036117
0.00012440592098567708,0.07995119023804761,404.21311814213544,166.93115322821933,2.8079838828036117
0.00012542189624087691,0.08060412082416483,405.11599334798757,166.93115322821933,2.8079838828036117
0.00012572071249240628,0.08079615923184637,405.38100146085196,166.93115322821933,2.8079838828036117
0.00012625858174515915,0.08114182836567314,405.85739784962726,166.93115322821933,2.8079838828036117
0.00012706538562428843,0.0816603320664133,406.57051106190886,166.93115322821933,2.8079838828036117
0.0001278721895034177,0.08217883576715343,407.2818605540329,166.93115322821933,2.8079838828036117
0.00012891804638377047,0.08285097019403881,408.2013804871093,166.93115322821933,2.8079838828036117
0.00012930650751075864,0.0831006201240248,408.54217490498166,166.93115322821933,2.8079838828036117
0.00012969496863774683,0.0833502700540108,408.8825702697883,166.93115322821933,2.8079838828036117
0.00013005354813958207,0.08358071614322865,409.19642862280546,166.93115322821933,2.8079838828036117
0.00013121893152054657,0.08432966593318664,410.21414538580916,166.93115322821933,2.8079838828036117
0.00013151774777207594,0.08452170434086818,410.47452983622327,166.93115322821933,2.8079838828036117
0.00013244407815181698,0.08511702340468094,411.28025923321155,166.93115322821933,2.8079838828036117
0.00013372898803339325,0.08594278855771155,412.39425473815595,166.93115322821933,2.8079838828036117
0.00013408756753522847,0.08617323464692939,412.70439117493726,166.93115322821933,2.8079838828036117
0.00013432662053645196,0.08632686537307462,412.9109691213563,166.93115322821933,2.8079838828036117
0.00013573105691863999,0.08722944588917785,414.1217315713502,166.93115322821933,2.8079838828036117
0.00013588046504440466,0.08732546509301861,414.2502478947791,166.93115322821933,2.8079838828036117
0.00013677691379899274,0.08790158031606321,415.02019168327274,166.93115322821933,2.8079838828036117
0.00013695620354991036,0.08801680336067214,415.1739440018748,166.93115322821933,2.8079838828036117
0.00013725501980143973,0.08820884176835367,415.4300235405232,166.93115322821933,2.8079838828036117
0.00013782277067934552,0.08857371474294859,415.9159764457336,166.93115322821933,2.8079838828036117
0.00013856981130816893,0.08905381076215244,416.554200364635,166.93115322821933,2.8079838828036117
0.00013877898268423947,0.0891882376475295,416.73266241685025,166.93115322821933,2.8079838828036117
0.00013928697031183942,0.08951470294058812,417.1656340805531,166.93115322821933,2.8079838828036117
0.0001393766151872982,0.08957231446289259,417.2419768732885,166.93115322821933,2.8079838828036117
0.00013964554981367463,0.08974514902980596,417.4708904344416,166.93115322821933,2.8079838828036117
0.00014012365581612162,0.09005241048209642,417.87742380696176,166.93115322821933,2.8079838828036117
0.0001411695126964744,0.0907245449089818,418.7648343313558,166.93115322821933,2.8079838828036117
0.00014140856569769787,0.09087817563512703,418.9673105787181,166.93115322821933,2.8079838828036117
0.00014203607982590953,0.09128145629125825,419.4981766102788,166.93115322821933,2.8079838828036117
0.00014370945083447398,0.09235687137427485,420.9093665085989,166.93115322821933,2.8079838828036117
0.00014409791196146214,0.09260652130426085,421.2360459115277,166.93115322821933,2.8079838828036117
0.00014427720171237976,0.09272174434886978,421.38670516190797,166.93115322821933,2.8079838828036117
0.00014520353209212082,0.09331706341268255,422.16395116377043,166.93115322821933,2.8079838828036117
0.00014672749497492054,0.09429645929185837,423.43845168160027,166.93115322821933,2.8079838828036117
0.00014723548260252048,0.09462292458491699,423.8621365758048,166.93115322821933,2.8079838828036117
0.00014807216810680272,0.0951606321264253,424.5587298617591,166.93115322821933,2.8079838828036117
0.0001485801557344026,0.0954870974194839,424.9809126098173,166.93115322821933,2.8079838828036117
0.00014878932711047318,0.09562152430486098,425.1545889003878,166.93115322821933,2.8079838828036117
0.00014887897198593197,0.09567913582716543,425.228992444003,166.93115322821933,2.8079838828036117
0.00014911802498715547,0.09583276655331066,425.42731652315825,166.93115322821933,2.8079838828036117
0.00014956624936444954,0.09612082416483297,425.7988402873835,166.93115322821933,2.8079838828036117
0.00015034317161842587,0.09662012402480497,426.44178782800265,166.93115322821933,2.8079838828036117
0.00015043281649388467,0.09667773554710943,426.515890607026,166.93115322821933,2.8079838828036117
0.00015073163274541404,0.09686977395479096,426.762775584256,166.93115322821933,2.8079838828036117
0.0001511798571227081,0.09715783156631327,427.13274545326465,166.93115322821933,2.8079838828036117
0.00015189701612637854,0.09761872374474895,427.7238086802257,166.93115322821933,2.8079838828036117
0.00015225559562821378,0.0978491698339668,428.0189320943906,166.93115322821933,2.8079838828036117
0.00015243488537913143,0.09796439287857572,428.16639214161336,166.93115322821933,2.8079838828036117
0.00015333133413371949,0.09854050810162032,428.9026801984519,166.93115322821933,2.8079838828036117
0.0001542277828883076,0.09911662332466493,429.63729132565203,166.93115322821933,2.8079838828036117
0.00015434730938891934,0.09919343868773756,429.7351135039094,166.93115322821933,2.8079838828036117
0.000154974823517131,0.09959671934386878,430.2481960463477,166.93115322821933,2.8079838828036117