File: datasets/aisi_316_L/data/M1/train_61.csv
Time(s),Strain(%),Stress(MPa),Temp(C),Log_SR(s-1)
0.0,0.0,0.0,212.69479427943008,0.31244790255654653
3.5065868018983397e-06,7.2e-06,1.3312768499999998,212.69479427943008,0.31244790255654653
1.2078243428760948e-05,2.48e-05,4.58550915,212.69479427943008,0.31244790255654653
1.6753692497958733e-05,3.4399999999999996e-05,6.3605449499999995,212.69479427943008,0.31244790255654653
2.9611177438252647e-05,6.08e-05,11.2418934,212.69479427943008,0.31244790255654653
3.7403592553582286e-05,7.68e-05,14.2002864,212.69479427943008,0.31244790255654653
4.402714540161249e-05,9.04e-05,16.71492045,212.69479427943008,0.31244790255654653
4.7144111447744345e-05,9.68e-05,17.89827765,212.69479427943008,0.31244790255654653
4.9481835982343235e-05,0.00010159999999999999,18.78579555,212.69479427943008,0.31244790255654653
5.3378043540008055e-05,0.0001096,20.26499205,212.69479427943008,0.31244790255654653
5.8443113364972326e-05,0.00011999999999999999,22.187947499999996,212.69479427943008,0.31244790255654653
6.740439074760142e-05,0.0001384,25.59009945,212.69479427943008,0.31244790255654653
7.948263417636235e-05,0.00016319999999999998,30.175608599999997,212.69479427943008,0.31244790255654653
9.078163609359035e-05,0.0001864,34.46527845,212.69479427943008,0.31244790255654653
0.00010597684556848314,0.00021759999999999998,40.234144799999996,212.69479427943008,0.31244790255654653
0.00012039281353184299,0.0002472,45.70717185,212.69479427943008,0.31244790255654653
0.0001242890210895078,0.00025519999999999997,47.186368349999995,212.69479427943008,0.31244790255654653
0.0001270163663798732,0.0002608,48.2218059,212.69479427943008,0.31244790255654653
0.00012974371167023856,0.00026639999999999997,49.25724345,212.69479427943008,0.31244790255654653
0.00013169181544907098,0.0002704,49.996841700000004,212.69479427943008,0.31244790255654653
0.00014532854190089784,0.0002984,55.17402945,212.69479427943008,0.31244790255654653
0.00015623792306235937,0.0003208,59.315779649999996,212.69479427943008,0.31244790255654653
0.00016870578724688677,0.00034639999999999996,64.04920845,212.69479427943008,0.31244790255654653
0.00017377085707185106,0.0003568,65.9721639,212.69479427943008,0.31244790255654653
0.00018000478916411477,0.0003696,68.33887829999999,212.69479427943008,0.31244790255654653
0.00018390099672177957,0.00037759999999999996,69.81807479999999,212.69479427943008,0.31244790255654653
0.00018935568730251033,0.00038879999999999996,71.8889499,212.69479427943008,0.31244790255654653
0.00019286227410440868,0.000396,73.22022675,212.69479427943008,0.31244790255654653
0.000196368860906307,0.0004032,74.5515036,212.69479427943008,0.31244790255654653
0.0002014339307312713,0.00041359999999999997,76.47445905,212.69479427943008,0.31244790255654653
0.00020338203451010368,0.00041759999999999996,77.2140573,212.69479427943008,0.31244790255654653
0.00021117444962543333,0.00043359999999999997,80.1724503,212.69479427943008,0.31244790255654653
0.00022286307229842778,0.00045759999999999996,84.6100398,212.69479427943008,0.31244790255654653
0.00023143472892529041,0.0004752,87.8642721,212.69479427943008,0.31244790255654653
0.00024078562706368598,0.0004944,91.4143437,212.69479427943008,0.31244790255654653
0.0002489676629347821,0.0005112,94.52065635,212.69479427943008,0.31244790255654653
0.0002524742497366805,0.0005184,95.8519332,212.69479427943008,0.31244790255654653
0.0002552015950270458,0.0005239999999999999,96.88737074999999,212.69479427943008,0.31244790255654653
0.0002676694592115733,0.0005496,101.62079955,212.69479427943008,0.31244790255654653
0.000273124149792304,0.0005608,103.69167465,212.69479427943008,0.31244790255654653
0.0002746826328153699,0.0005639999999999999,104.28335324999999,212.69479427943008,0.31244790255654653
0.00027857884037303475,0.000572,105.76254975,212.69479427943008,0.31244790255654653
0.00028325428944223253,0.0005815999999999999,107.53758554999999,212.69479427943008,0.31244790255654653
0.0002933844290921611,0.0006024,111.38349645,212.69479427943008,0.31244790255654653
0.0002961117743825264,0.0006079999999999999,112.418934,212.69479427943008,0.31244790255654653
0.000304683431009389,0.0006255999999999999,115.67316629999999,212.69479427943008,0.31244790255654653
0.0003078003970555209,0.000632,116.8565235,212.69479427943008,0.31244790255654653
0.0003116966046131857,0.0006399999999999999,118.33572,212.69479427943008,0.31244790255654653
0.0003171512951939165,0.0006512,120.4065951,212.69479427943008,0.31244790255654653
0.000327281434843845,0.000672,124.252506,212.69479427943008,0.31244790255654653
0.0003339049876918752,0.0006856,126.76714005,212.69479427943008,0.31244790255654653
0.00033935967827260596,0.0006967999999999999,128.83801515,212.69479427943008,0.31244790255654653
0.00034481436885333675,0.000708,130.90889024999998,212.69479427943008,0.31244790255654653
0.0003487105764110015,0.000716,132.38808674999999,212.69479427943008,0.31244790255654653
0.00035182754245713344,0.0007224,133.57144395,212.69479427943008,0.31244790255654653
0.00035338602548019935,0.0007256,134.16312255,212.69479427943008,0.31244790255654653
0.00036351616513012787,0.0007463999999999999,138.00903344999998,212.69479427943008,0.31244790255654653
0.00036585388966472673,0.0007511999999999999,138.89655134999998,212.69479427943008,0.31244790255654653
0.00037871137460502067,0.0007775999999999999,143.7778998,212.69479427943008,0.31244790255654653
0.00038299720291845194,0.0007863999999999999,145.40501594999998,212.69479427943008,0.31244790255654653
0.00038884151425494924,0.0007984,147.6238107,212.69479427943008,0.31244790255654653
0.0003931273425683805,0.0008072,149.25092685,212.69479427943008,0.31244790255654653
0.00039897165390487775,0.0008192,151.46972159999999,212.69479427943008,0.31244790255654653
0.00040325748221830903,0.000828,153.09683775,212.69479427943008,0.31244790255654653
0.00041377724262400405,0.0008495999999999999,157.09066829999998,212.69479427943008,0.31244790255654653
0.0004172838294259024,0.0008568,158.42194515,212.69479427943008,0.31244790255654653
0.00042001117471626774,0.0008623999999999999,159.45738269999998,212.69479427943008,0.31244790255654653
0.000426634727564298,0.0008759999999999999,161.97201675,212.69479427943008,0.31244790255654653
0.00043403752192386114,0.0008912,164.7824901,212.69479427943008,0.31244790255654653
0.00043715448796999295,0.0008975999999999999,165.96584729999998,212.69479427943008,0.31244790255654653
0.00044299879930649025,0.0009096,168.18464205,212.69479427943008,0.31244790255654653
0.00044923273139875394,0.0009224,170.55135645,212.69479427943008,0.31244790255654653
0.0004554666634910177,0.0009352,172.91807085,212.69479427943008,0.31244790255654653
0.0004620902163390479,0.0009488,175.4327049,212.69479427943008,0.31244790255654653
0.0004757269427908747,0.0009767999999999999,180.60989264999998,212.69479427943008,0.31244790255654653
0.0004831297371504379,0.000992,183.420366,212.69479427943008,0.31244790255654653
0.0005068966032521933,0.0010408,192.44346464999998,212.69479427943008,0.31244790255654653
0.0005213125712155532,0.0010704,197.9164917,212.69479427943008,0.31244790255654653
0.0005267672617962839,0.0010816,199.98736680000002,212.69479427943008,0.31244790255654653
0.0005380662637135119,0.0011048,204.27703664999999,212.69479427943008,0.31244790255654653
0.0005567680599903031,0.0011432,208.12242150949527,212.69479427943008,0.31244790255654653
0.0005598850260364349,0.0011496,208.16329738492274,212.69479427943008,0.31244790255654653
0.0005723528902209623,0.0011752,208.32592112143598,212.69479427943008,0.31244790255654653
0.000578586822313226,0.001188,208.40671445527008,212.69479427943008,0.31244790255654653
0.0005852103751612562,0.0012016,208.49218627341975,212.69479427943008,0.31244790255654653
0.0005949508940554183,0.0012216,208.61719791320482,212.69479427943008,0.31244790255654653
0.0006000159638803826,0.001232,208.68188836309034,212.69479427943008,0.31244790255654653
0.000601184826147682,0.0012343999999999999,208.69678664212321,212.69479427943008,0.31244790255654653
0.0006144319318437424,0.0012615999999999999,208.8648518326164,212.69479427943008,0.31244790255654653
0.0006233932092263714,0.0012799999999999999,208.977742402542,212.69479427943008,0.31244790255654653
0.0006378091771897313,0.0013096,209.15802993093928,212.69479427943008,0.31244790255654653
0.0006428742470146956,0.00132,209.22099599809874,212.69479427943008,0.31244790255654653
0.0006463808338165939,0.0013272,209.26447459768093,212.69479427943008,0.31244790255654653
0.0006502770413742587,0.0013352,209.31267640775658,212.69479427943008,0.31244790255654653
0.0006654722508491516,0.0013664,209.49959702813456,212.69479427943008,0.31244790255654653
0.0006798882188125113,0.0013959999999999999,209.67539912499166,212.69479427943008,0.31244790255654653
0.0006865117716605417,0.0014096,209.75568504372467,212.69479427943008,0.31244790255654653
0.0006978107735777695,0.0014328,209.89194961931116,212.69479427943008,0.31244790255654653
0.0007020966018912009,0.0014416,209.94341073824896,212.69479427943008,0.31244790255654653
0.0007126163622968959,0.0014632,210.06920770909122,212.69479427943008,0.31244790255654653
0.0007145644660757282,0.0014671999999999999,210.0924237502983,212.69479427943008,0.31244790255654653
0.0007180710528776266,0.0014743999999999998,210.13415051526795,212.69479427943008,0.31244790255654653
0.0007301492963063877,0.0014992,210.27727166327446,212.69479427943008,0.31244790255654653
0.000733655883108286,0.0015064,210.3186496308842,212.69479427943008,0.31244790255654653
0.000744175643513981,0.0015279999999999998,210.4423232103187,212.69479427943008,0.31244790255654653
0.0007484614718274122,0.0015367999999999998,210.49251304395798,212.69479427943008,0.31244790255654653
0.0007515784378735441,0.0015432,210.52894436828254,212.69479427943008,0.31244790255654653
0.0007617085775234726,0.0015639999999999999,210.64694129520706,212.69479427943008,0.31244790255654653
0.0007726179586849341,0.0015864,210.77333253509298,212.69479427943008,0.31244790255654653
0.0007784622700214314,0.0015983999999999998,210.84075573396646,212.69479427943008,0.31244790255654653
0.0007866443058925275,0.0016152,210.93481750239198,212.69479427943008,0.31244790255654653
0.0008076838267039176,0.0016584,211.17495511382054,212.69479427943008,0.31244790255654653
0.000820930932399978,0.0016856,211.32490193042963,212.69479427943008,0.31244790255654653
0.0008372950041421702,0.0017192,211.50883379229666,212.69479427943008,0.31244790255654653
0.0008579449041977937,0.0017615999999999999,211.73894959100653,212.69479427943008,0.31244790255654653
0.0008696335268707882,0.0017855999999999998,211.86824622505614,212.69479427943008,0.31244790255654653
0.0008754778382072854,0.0017976,211.9326402500109,212.69479427943008,0.31244790255654653
0.0008832702533226151,0.0018135999999999998,212.01823876815675,212.69479427943008,0.31244790255654653
0.0008840494948341481,0.0018151999999999999,212.02678238970006,212.69479427943008,0.31244790255654653
0.0008895041854148788,0.0018264,212.08650571970875,212.69479427943008,0.31244790255654653
0.0008922315307052441,0.0018319999999999999,212.11631380980242,212.69479427943008,0.31244790255654653
0.0009093748439589693,0.0018671999999999998,212.302871761313,212.69479427943008,0.31244790255654653
0.0009124918100051013,0.0018736,212.33664350874372,212.69479427943008,0.31244790255654653
0.0009175568798300655,0.0018839999999999998,212.39142680013325,212.69479427943008,0.31244790255654653
0.0009280766402357606,0.0019056,212.50483206197802,212.69479427943008,0.31244790255654653
0.000940544504420288,0.0019311999999999999,212.6385911607432,212.69479427943008,0.31244790255654653
0.0009424926081991204,0.0019352,212.6594283906249,212.69479427943008,0.31244790255654653
0.0009662594743008758,0.001984,212.91230490947657,212.69479427943008,0.31244790255654653
0.0009834027875546012,0.0020192,213.09320402761034,212.69479427943008,0.31244790255654653
0.0009872989951122658,0.0020272,213.13414544731506,212.69479427943008,0.31244790255654653
0.0009884678573795652,0.0020296,213.14641557966243,212.69479427943008,0.31244790255654653
0.0010184686555735846,0.0020912,213.45943859913643,212.69479427943008,0.31244790255654653
0.0010250922084216146,0.0021048,213.52806055280627,212.69479427943008,0.31244790255654653
0.0010340534858042437,0.0021232,213.62062741006054,212.69479427943008,0.31244790255654653
0.0010367808310946089,0.0021287999999999997,213.64873776439615,212.69479427943008,0.31244790255654653
0.001038339314117675,0.0021319999999999998,213.6647878756457,212.69479427943008,0.31244790255654653
0.001040677038652274,0.0021368,213.68884543780655,212.69479427943008,0.31244790255654653
0.00104223552167534,0.00214,213.70487210460493,212.69479427943008,0.31244790255654653
0.0010445732462099388,0.0021448,213.7288945914785,212.69479427943008,0.31244790255654653
0.001051976040569502,0.00216,213.80482784526103,212.69479427943008,0.31244790255654653
0.0010558722481271666,0.002168,213.84470899658817,212.69479427943008,0.31244790255654653
0.0010695089745789937,0.002196,213.98384329167726,212.69479427943008,0.31244790255654653
0.0010800287349846886,0.0022175999999999997,214.0907032565278,212.69479427943008,0.31244790255654653
0.0011037956010864442,0.0022664,214.33064426446674,212.69479427943008,0.31244790255654653
0.0011154842237594384,0.0022903999999999997,214.4479082194227,212.69479427943008,0.31244790255654653
0.0011193804313171032,0.0022984,214.48688958422298,212.69479427943008,0.31244790255654653
0.001123276638874768,0.0023063999999999997,214.5258180689155,212.69479427943008,0.31244790255654653
0.0011244455011420675,0.0023087999999999997,214.53748634084747,212.69479427943008,0.31244790255654653
0.0011349652615477625,0.0023304,214.6422887796838,212.69479427943008,0.31244790255654653
0.0011408095728842598,0.0023423999999999997,214.70034864100597,212.69479427943008,0.31244790255654653
0.001148212367243823,0.0023576,214.77372487676664,212.69479427943008,0.31244790255654653
0.0011606802314283503,0.0023832,214.8968902328811,212.69479427943008,0.31244790255654653
0.0011649660597417818,0.002392,214.9391090138647,212.69479427943008,0.31244790255654653
0.0011801612692166744,0.0024232,215.08830812895164,212.69479427943008,0.31244790255654653
0.0011906810296223695,0.0024448,215.19116123140947,212.69479427943008,0.31244790255654653
0.0012074347221203282,0.0024792,215.35423567867048,212.69479427943008,0.31244790255654653
0.0012082139636318612,0.0024808,215.36179898564504,212.69479427943008,0.31244790255654653
0.0012136686542125919,0.002492,215.41468896886536,212.69479427943008,0.31244790255654653
0.0012280846221759518,0.0025215999999999997,215.55402527648388,212.69479427943008,0.31244790255654653
0.0012366562788028144,0.0025391999999999997,215.63657150948438,212.69479427943008,0.31244790255654653
0.0012506826260104077,0.002568,215.77116746587663,212.69479427943008,0.31244790255654653
0.0012561373165911386,0.0025792,215.8233511931978,212.69479427943008,0.31244790255654653
0.0012619816279276356,0.0025911999999999997,215.87916435634816,212.69479427943008,0.31244790255654653
0.001266267456241067,0.0026,215.92002996322037,212.69479427943008,0.31244790255654653
0.0012721117675775643,0.0026119999999999997,215.97566896503946,212.69479427943008,0.31244790255654653
0.001275228733623696,0.0026184,216.0053023330987,212.69479427943008,0.31244790255654653
0.0012787353204255945,0.0026256,216.03860612764825,212.69479427943008,0.31244790255654653
0.0012869173562966908,0.0026424,216.11617677693957,212.69479427943008,0.31244790255654653
0.0012958786336793198,0.0026608,216.20091474927958,212.69479427943008,0.31244790255654653
0.0013071776355965477,0.0026839999999999998,216.30743325123026,212.69479427943008,0.31244790255654653
0.0013227624658272068,0.0027159999999999997,216.45376797248534,212.69479427943008,0.31244790255654653
0.0013289963979194706,0.0027288,216.51211340019228,212.69479427943008,0.31244790255654653
0.0013399057790809323,0.0027512,216.61396171578198,212.69479427943008,0.31244790255654653
0.0013449708489058966,0.0027616,216.66113845298239,212.69479427943008,0.31244790255654653
0.0013465293319289624,0.0027648,216.6756404256743,212.69479427943008,0.31244790255654653
0.0013574387130904238,0.0027871999999999997,216.7769715737854,212.69479427943008,0.31244790255654653
0.0013671792319845859,0.0028071999999999997,216.8671777390328,212.69479427943008,0.31244790255654653
0.0013738027848326161,0.0028208,216.9283748101809,212.69479427943008,0.31244790255654653
0.0013815951999479458,0.0028368,217.00022423867006,212.69479427943008,0.31244790255654653
0.001388997994307509,0.002852,217.06833494799665,212.69479427943008,0.31244790255654653
0.0013905564773305748,0.0028552,217.08265598871287,212.69479427943008,0.31244790255654653
0.0013921149603536406,0.0028583999999999997,217.09697077110823,212.69479427943008,0.31244790255654653
0.0014069205490727672,0.0028888,217.23265092110555,212.69479427943008,0.31244790255654653
0.0014162714472111628,0.002908,217.3180568086703,212.69479427943008,0.31244790255654653
0.0014267912076168577,0.0029295999999999997,217.4138759981965,212.69479427943008,0.31244790255654653
0.0014353628642437203,0.0029472,217.49174734019024,212.69479427943008,0.31244790255654653
0.0014396486925571516,0.002956,217.5306149854296,212.69479427943008,0.31244790255654653
0.001458350488833943,0.0029944,217.6996938997189,212.69479427943008,0.31244790255654653
0.0014677013869723384,0.0030136,217.7839160943248,212.69479427943008,0.31244790255654653
0.0014751041813319016,0.0030288,217.85044367602714,212.69479427943008,0.31244790255654653
0.001482896596447231,0.0030448,217.92033219494488,212.69479427943008,0.31244790255654653
0.001496533322899058,0.0030727999999999997,218.04229343401448,212.69479427943008,0.31244790255654653
0.0015015983927240224,0.0030832,218.08748283532555,212.69479427943008,0.31244790255654653
0.0015164039814431487,0.0031136,218.21923531739898,212.69479427943008,0.31244790255654653
0.001517572843710448,0.003116,218.22961541361641,212.69479427943008,0.31244790255654653
0.001521469051268113,0.003124,218.2641932373611,212.69479427943008,0.31244790255654653
0.0015728989910292887,0.0032296,218.71743153959915,212.69479427943008,0.31244790255654653
0.0015764055778311869,0.0032367999999999997,218.7481220237166,212.69479427943008,0.31244790255654653
0.0015912111665503134,0.0032672,218.87741163444113,212.69479427943008,0.31244790255654653
0.0016028997892233077,0.0032911999999999998,218.97915127067688,212.69479427943008,0.31244790255654653
0.0016060167552694395,0.0032976,219.0062329217974,212.69479427943008,0.31244790255654653
0.0016099129628271043,0.0033055999999999997,219.04005617705837,212.69479427943008,0.31244790255654653
0.0016173157571866676,0.0033208,219.10423254081516,212.69479427943008,0.31244790255654653
0.0016270562760808294,0.0033407999999999997,219.18850085560334,212.69479427943008,0.31244790255654653
0.001643420347823022,0.0033744,219.3296300502515,212.69479427943008,0.31244790255654653
0.0016488750384037526,0.0033856,219.37655118576183,212.69479427943008,0.31244790255654653
0.001659784419565214,0.003408,219.47021224183746,212.69479427943008,0.31244790255654653
0.001660563661076747,0.0034096,219.47689311594257,212.69479427943008,0.31244790255654653
0.0016706938007266755,0.0034303999999999997,219.5636335144051,212.69479427943008,0.31244790255654653
0.0016769277328189394,0.0034432,219.61691027873331,212.69479427943008,0.31244790255654653
0.00168238242339967,0.0034544,219.66346411755947,212.69479427943008,0.31244790255654653
0.0016909540800265326,0.003472,219.73650139302146,212.69479427943008,0.31244790255654653
0.001694460666828431,0.0034792,219.7663386446858,212.69479427943008,0.31244790255654653
0.0017014738404322277,0.0034936,219.8259410028354,212.69479427943008,0.31244790255654653
0.0017213444989763182,0.0035344,219.99429626548576,212.69479427943008,0.31244790255654653
0.001731864259382013,0.0035559999999999997,220.08311858758967,212.69479427943008,0.31244790255654653
0.0017330331216493127,0.0035583999999999998,220.09297472868406,212.69479427943008,0.31244790255654653
0.0017431632612992412,0.0035792,220.1782862924349,212.69479427943008,0.31244790255654653
0.001768878231179829,0.003632,220.393982584797,212.69479427943008,0.31244790255654653
0.0017708263349586616,0.003636,220.41027321103658,212.69479427943008,0.31244790255654653
0.0017829045783874222,0.0036607999999999996,220.51111953596288,212.69479427943008,0.31244790255654653
0.0017875800274566203,0.0036704,220.55008524817998,212.69479427943008,0.31244790255654653
0.001791476235014285,0.0036783999999999996,220.58252632200404,212.69479427943008,0.31244790255654653
0.001802775236931513,0.0037015999999999998,220.67645019362615,212.69479427943008,0.31244790255654653
0.0018055025822218784,0.0037072,220.6990870426516,212.69479427943008,0.31244790255654653
0.0018105676520468426,0.0037175999999999997,220.7410915557345,212.69479427943008,0.31244790255654653
0.0018277109653005677,0.0037527999999999997,220.88292185697287,212.69479427943008,0.31244790255654653
0.0018339448973928316,0.0037656,220.9343677560341,212.69479427943008,0.31244790255654653
0.0018382307257062628,0.0037744,220.96969725638255,212.69479427943008,0.31244790255654653
0.0018506985898907903,0.0038,221.0722917839867,212.69479427943008,0.31244790255654653
0.0018514778314023233,0.0038016,221.0786949774559,212.69479427943008,0.31244790255654653
0.0018581013842503536,0.0038152,221.1330797520455,212.69479427943008,0.31244790255654653
0.0018662834201214496,0.003832,221.20015667176037,212.69479427943008,0.31244790255654653
0.0018686211446560486,0.0038368,221.21930042805337,212.69479427943008,0.31244790255654653
0.0018799201465732765,0.0038599999999999997,221.31169723379978,212.69479427943008,0.31244790255654653
0.0018869333201770731,0.0038743999999999996,221.36893805261653,212.69479427943008,0.31244790255654653
0.0018888814239559056,0.0038783999999999997,221.38482354753805,212.69479427943008,0.31244790255654653
0.0018935568730251034,0.003888,221.4229226884851,212.69479427943008,0.31244790255654653
0.0019017389088961994,0.0039048,221.48950802239457,212.69479427943008,0.31244790255654653
0.0019138171523249605,0.0039296,221.5875968242138,212.69479427943008,0.31244790255654653
0.0019173237391268588,0.0039368,221.6160289592957,212.69479427943008,0.31244790255654653
0.0019317397070902189,0.0039664,221.73270419769497,212.69479427943008,0.31244790255654653
0.001934467052380584,0.003972,221.75473964037567,212.69479427943008,0.31244790255654653
0.0019364151561594163,0.0039759999999999995,221.77047182488312,212.69479427943008,0.31244790255654653
0.001939532122205548,0.0039824,221.7956304872155,212.69479427943008,0.31244790255654653
0.0019438179505189793,0.0039911999999999994,221.83019791633558,212.69479427943008,0.31244790255654653
0.001947324537320878,0.0039984,221.85845825477966,212.69479427943008,0.31244790255654653
0.0022473923769806992,0.0046145229045809165,224.20803369118744,212.69479427943008,0.31244790255654653
0.002368978369978441,0.004864172834566914,225.12479509752845,212.69479427943008,0.31244790255654653
0.002565386512513255,0.00526745349069814,226.56785485475018,212.69479427943008,0.31244790255654653
0.0026869725055109974,0.0055171034206841375,227.4395992713526,212.69479427943008,0.31244790255654653
0.002930144491506481,0.006016403280656131,229.13823279750724,212.69479427943008,0.31244790255654653
0.003051730484504223,0.0062660532106421285,229.96685394929935,212.69479427943008,0.31244790255654653
0.003079788790580625,0.006323664732946589,230.15623369421084,212.69479427943008,0.31244790255654653
0.003135905402733429,0.006438887777555511,230.53298650265873,212.69479427943008,0.31244790255654653
0.003266844164423305,0.006707741548309662,231.40199598709344,212.69479427943008,0.31244790255654653
0.003285549701807573,0.006746149229845969,231.52502210678745,212.69479427943008,0.31244790255654653
0.003397782926113181,0.006976595319063813,232.25752276930365,212.69479427943008,0.31244790255654653
0.003846715823335613,0.007898379675935187,235.09774212549314,212.69479427943008,0.31244790255654653
0.0040898878093310964,0.008397679535907181,236.58202157864127,212.69479427943008,0.31244790255654653
0.004164709958868169,0.00855131026205241,237.03174428224224,212.69479427943008,0.31244790255654653
0.004314354257942313,0.008858571714342869,237.9218457646862,212.69479427943008,0.31244790255654653
0.004407881944863653,0.009050610122024405,238.4720483945694,212.69479427943008,0.31244790255654653
0.004576231781322065,0.00939627925585117,239.45107377336703,212.69479427943008,0.31244790255654653
0.004772639923856879,0.009799559911982397,240.57568790668748,212.69479427943008,0.31244790255654653
0.004903578685546755,0.010068413682736548,241.31541754285996,212.69479427943008,0.31244790255654653
0.004997106372468094,0.010260452090418083,241.83908678329306,212.69479427943008,0.31244790255654653
0.005137397902850105,0.010548509701940389,242.61747958084018,212.69479427943008,0.31244790255654653
0.005268336664539981,0.01081736347269454,243.33653255682714,212.69479427943008,0.31244790255654653
0.005492803113151197,0.011278255651130227,244.55318518795826,212.69479427943008,0.31244790255654653
0.005539566956611866,0.011374274854970993,244.8041962596962,212.69479427943008,0.31244790255654653
0.005698564024378145,0.011700740148029607,245.65151944514437,212.69479427943008,0.31244790255654653
0.0060913803094477725,0.012507301460292058,247.70630399010807,212.69479427943008,0.31244790255654653
0.0062690829145983186,0.012872174434886977,248.61880041057736,212.69479427943008,0.31244790255654653
0.006671251968360081,0.013697939587917584,250.64746676585713,212.69479427943008,0.31244790255654653
0.006783485192665689,0.013928385677135427,251.20501911538688,212.69479427943008,0.31244790255654653
0.006858307342202761,0.014082016403280656,251.57472325600787,212.69479427943008,0.31244790255654653
0.007176301477735317,0.01473494698939788,253.12873376785288,212.69479427943008,0.31244790255654653
0.007344651314193729,0.015080616123224646,253.94055927811596,212.69479427943008,0.31244790255654653
0.007550412225420677,0.015503100620124026,254.9230006834035,212.69479427943008,0.31244790255654653
0.007662645449726286,0.01573354670934187,255.4544745948798,212.69479427943008,0.31244790255654653
0.007700056524494822,0.015810362072414486,255.6309567777498,212.69479427943008,0.31244790255654653
0.008008697891335244,0.016444088817763554,257.07439039527435,212.69479427943008,0.31244790255654653
0.008279928183407129,0.017001000200040008,258.3250437455284,212.69479427943008,0.31244790255654653
0.008345397564252068,0.017135427085417085,258.6245192421487,212.69479427943008,0.31244790255654653
0.00863533339370822,0.017730746149229846,259.93990505914263,212.69479427943008,0.31244790255654653
0.009074913522238518,0.018633326665333065,261.90180767157506,212.69479427943008,0.31244790255654653
0.009252616127389065,0.018998199639927986,262.68435347347594,212.69479427943008,0.31244790255654653
0.009364849351694673,0.01922864572914583,263.17557417808206,212.69479427943008,0.31244790255654653
0.009430318732539612,0.019363072614522907,263.46105931433004,212.69479427943008,0.31244790255654653
0.009626726875074425,0.01976635327065413,264.3129125909134,212.69479427943008,0.31244790255654653
0.00977637117414857,0.02007361472294459,264.9574017330908,212.69479427943008,0.31244790255654653
0.009832487786301372,0.02018883776755351,265.1980918039885,212.69479427943008,0.31244790255654653
0.010122423615757527,0.020784156831366273,266.4332243439508,212.69479427943008,0.31244790255654653
0.01015048192183393,0.020841768353670735,266.5520163182119,212.69479427943008,0.31244790255654653
0.010412359445213681,0.021379475895179037,267.6546340849503,212.69479427943008,0.31244790255654653
0.010580709281672093,0.021725145029005802,268.3577524244241,212.69479427943008,0.31244790255654653
0.010861292342436112,0.02230126025205041,269.5199969428068,212.69479427943008,0.31244790255654653
0.01111381709712373,0.022819763952790558,270.55604248580914,212.69479427943008,0.31244790255654653
0.01117928647796867,0.022954190838167635,270.8231430954359,212.69479427943008,0.31244790255654653
0.01130087247096641,0.02320384076815363,271.3175741630609,212.69479427943008,0.31244790255654653
0.011450516770040555,0.02351110222044409,271.92326583203345,212.69479427943008,0.31244790255654653
0.011562749994346163,0.023741548309661933,272.3755107157282,212.69479427943008,0.31244790255654653
0.011628219375191099,0.023875975195039006,272.6385296355418,212.69479427943008,0.31244790255654653
0.011796569211649512,0.024221644328865772,273.31222572372803,212.69479427943008,0.31244790255654653
0.011833980286418048,0.024298459691938386,273.46142554696047,212.69479427943008,0.31244790255654653
0.011899449667262987,0.024432886577315464,273.72208336164783,212.69479427943008,0.31244790255654653
0.012133268884566336,0.024912982596519303,274.6484728122938,212.69479427943008,0.31244790255654653
0.012320324258409015,0.025297059411882376,275.3845810105757,212.69479427943008,0.31244790255654653
0.01242320471402249,0.025508301660332067,275.7875822047451,212.69479427943008,0.31244790255654653
0.012479321326175295,0.02562352470494099,276.00685236373454,212.69479427943008,0.31244790255654653
0.0125634962444045,0.02579635927185437,276.33503796101047,212.69479427943008,0.31244790255654653
0.012890843148629191,0.02646849369873975,277.60324578824645,212.69479427943008,0.31244790255654653
0.012975018066858397,0.02664132826565313,277.92731847239946,212.69479427943008,0.31244790255654653
0.01307789852247187,0.026852570514102822,278.3222959481009,212.69479427943008,0.31244790255654653
0.013143367903316808,0.026986997399479896,278.57301443893357,212.69479427943008,0.31244790255654653
0.013321070508467356,0.027351870374074817,279.2510928744305,212.69479427943008,0.31244790255654653
0.013433303732772963,0.02758231646329266,279.677535859236,212.69479427943008,0.31244790255654653
0.013573595263154973,0.027870374074814963,280.20864060974156,212.69479427943008,0.31244790255654653
0.013826120017842591,0.028388877775555113,281.1592654244,212.69479427943008,0.31244790255654653
0.013985117085608869,0.028715343068613723,281.7543343785248,212.69479427943008,0.31244790255654653
0.014209583534220084,0.02917623524704941,282.5899593651954,212.69479427943008,0.31244790255654653
0.014265700146372889,0.029291458291658332,282.79805926380817,212.69479427943008,0.31244790255654653
0.014462108288907701,0.029694738947789557,283.52390806583355,212.69479427943008,0.31244790255654653
0.014593047050597578,0.029963592718543708,284.0056725637698,212.69479427943008,0.31244790255654653
0.014864277342669464,0.030520504100820165,284.9982832528233,212.69479427943008,0.31244790255654653
0.014976510566975073,0.03075095019003801,285.4069495272028,212.69479427943008,0.31244790255654653
0.015079391022588547,0.030962192438487697,285.780512263145,212.69479427943008,0.31244790255654653
0.015144860403433484,0.031096619323864774,286.017716568462,212.69479427943008,0.31244790255654653
0.015406737926813237,0.031634326865373076,286.9625618280546,212.69479427943008,0.31244790255654653
0.01592114020488061,0.03269053810762153,288.8004674081685,212.69479427943008,0.31244790255654653
0.016145606653491823,0.033151430286057215,289.59518853986566,212.69479427943008,0.31244790255654653
0.016388778639487307,0.033650730146029206,290.45128939906346,212.69479427943008,0.31244790255654653
0.016575834013329988,0.03403480696139228,291.10646174353445,212.69479427943008,0.31244790255654653
0.016762889387172665,0.03441888377675535,291.75875688421615,212.69479427943008,0.31244790255654653
0.016847064305401872,0.03459171834366873,292.05136291844076,212.69479427943008,0.31244790255654653
0.01712764736616589,0.03516783356671334,293.0226244450725,212.69479427943008,0.31244790255654653
0.017295997202624307,0.035513502700540114,293.60240317894977,212.69479427943008,0.31244790255654653
0.017511110882543385,0.03595519103820764,294.34003874124693,212.69479427943008,0.31244790255654653
0.017576580263388323,0.03608961792358471,294.5638339667322,212.69479427943008,0.31244790255654653
0.01781975224938381,0.03658891778355672,295.39224234984306,212.69479427943008,0.31244790255654653
0.018044218697995027,0.037049809961992405,296.15302223588566,212.69479427943008,0.31244790255654653
0.018156451922300632,0.03728025605121024,296.532027421399,212.69479427943008,0.31244790255654653
0.018352860064835445,0.03768353670734147,297.1930952407483,212.69479427943008,0.31244790255654653
0.018493151595217458,0.03797159431886378,297.6635984040928,212.69479427943008,0.31244790255654653
0.01885790957421068,0.03872054410882177,298.8804376540759,212.69479427943008,0.31244790255654653
0.01898884833590056,0.03898939787957592,299.31500824069974,212.69479427943008,0.31244790255654653
0.01927878416535671,0.03958471694338868,300.2731342582286,212.69479427943008,0.31244790255654653
0.019325548008817382,0.039680736147229445,300.42714287270724,212.69479427943008,0.31244790255654653
0.01941907569573872,0.03987277455491098,300.7347247711952,212.69479427943008,0.31244790255654653
0.019521956151352195,0.04008401680336067,301.0723983343323,212.69479427943008,0.31244790255654653
0.019587425532197136,0.040218443688737754,301.2869202114719,212.69479427943008,0.31244790255654653
0.019774480906039813,0.04060252050410082,301.89830439895167,212.69479427943008,0.31244790255654653
0.019970889048574626,0.041005801160232044,302.5378352649061,212.69479427943008,0.31244790255654653
0.020083122272880238,0.041236247249449895,302.9021800994906,212.69479427943008,0.31244790255654653
0.02041046917710493,0.041908381676335274,303.96034404987324,212.69479427943008,0.31244790255654653
0.0205414079387948,0.042177235447089415,304.3817538766418,212.69479427943008,0.31244790255654653
0.020681699469176813,0.04246529305861173,304.83210353686127,212.69479427943008,0.31244790255654653
0.021130632366399248,0.0433870774154831,306.2652812912809,212.69479427943008,0.31244790255654653
0.021345746046318326,0.04382876575315063,306.94779964369235,212.69479427943008,0.31244790255654653
0.021429920964547534,0.04400160032006402,307.21414119327727,212.69479427943008,0.31244790255654653
0.02161697633839021,0.044385677135427085,307.80455488798765,212.69479427943008,0.31244790255654653
0.021934970473922767,0.045038607721544305,308.8037057431705,212.69479427943008,0.31244790255654653
0.022056556466920507,0.0452882576515303,309.1842391040192,212.69479427943008,0.31244790255654653
0.02215943692253398,0.04549949989997999,309.505590318664,212.69479427943008,0.31244790255654653
0.022281022915531724,0.04574914982996599,309.8846198276172,212.69479427943008,0.31244790255654653
0.02240260890852947,0.045998799759952,310.2628435378523,212.69479427943008,0.31244790255654653
0.02249613659545081,0.04619083816763353,310.55324034604104,212.69479427943008,0.31244790255654653
0.022636428125832816,0.04647889577915583,310.98795426093585,212.69479427943008,0.31244790255654653
0.022860894574444034,0.04693978795759152,311.6813173648358,212.69479427943008,0.31244790255654653
0.022888952880520435,0.04699739947989598,311.7678006771683,212.69479427943008,0.31244790255654653
0.023225652553437264,0.04768873774754952,312.80239618347525,212.69479427943008,0.31244790255654653
0.023384649621203537,0.04801520304060812,313.2889203740202,212.69479427943008,0.31244790255654653
0.023543646688969817,0.04834166833366674,313.77415615005526,212.69479427943008,0.31244790255654653
0.02395516851142371,0.04918663732746549,315.02416287050954,212.69479427943008,0.31244790255654653
0.02416092942265066,0.049609121824364874,315.64602362769364,212.69479427943008,0.31244790255654653
0.024338632027801208,0.049973994798959795,316.1814248892981,212.69479427943008,0.31244790255654653
0.02449762909556748,0.0503004600920184,316.6591772123641,212.69479427943008,0.31244790255654653
0.024731448312870833,0.050780556111222244,317.35956318768115,212.69479427943008,0.31244790255654653
0.02517102844140113,0.05168313662732546,318.66933696817694,212.69479427943008,0.31244790255654653
0.025273908897014603,0.05189437887577515,318.9745879000763,212.69479427943008,0.31244790255654653
0.025648019644699965,0.0526625325065013,320.08052958941374,212.69479427943008,0.31244790255654653
0.02570413625685277,0.05277775555111022,320.2458766278502,212.69479427943008,0.31244790255654653
0.025760252869005577,0.05289297859571915,320.41108294331593,212.69479427943008,0.31244790255654653
0.026115658079306662,0.053622724544908976,321.45414899386236,212.69479427943008,0.31244790255654653
0.026209185766228008,0.05381476295259052,321.72771809117273,212.69479427943008,0.31244790255654653
0.02649912159568416,0.05441008201640328,322.57337276385636,212.69479427943008,0.31244790255654653
0.026751646350371777,0.05492858571714343,323.3069748610741,212.69479427943008,0.31244790255654653
0.027097698791980734,0.05563912782556511,324.3079101184677,212.69479427943008,0.31244790255654653
0.027219284784978478,0.05588877775555111,324.65840498116484,212.69479427943008,0.31244790255654653
0.027303459703207685,0.056061612322464496,324.90069766780994,212.69479427943008,0.31244790255654653
0.027555984457895304,0.056580116023204646,325.62583381945916,212.69479427943008,0.31244790255654653
0.027714981525661576,0.05690658131626325,326.08107171147805,212.69479427943008,0.31244790255654653
0.028014270123809866,0.057521104220844166,326.9352365043585,212.69479427943008,0.31244790255654653
0.02811715057942334,0.05773234646929386,327.22803272897283,212.69479427943008,0.31244790255654653
0.028257442109805356,0.05802040408081617,327.62662784994825,212.69479427943008,0.31244790255654653
0.02844449748364803,0.05840448089617924,328.1568895316718,212.69479427943008,0.31244790255654653
0.02862220008879858,0.05876935387077416,328.65937987667814,212.69479427943008,0.31244790255654653
0.02877184438787272,0.059076615323064616,329.08158664850015,212.69479427943008,0.31244790255654653
0.028827961000025527,0.05919183836767354,329.23969328521923,212.69479427943008,0.31244790255654653
0.0288747248434862,0.05928785757151431,329.3713571466863,212.69479427943008,0.31244790255654653
0.0289588997617154,0.05946069213842768,329.60814272136395,212.69479427943008,0.31244790255654653
0.029230130053787284,0.060017603520704135,330.3692989823661,212.69479427943008,0.31244790255654653
0.02944524373370637,0.06045929185837168,330.9710177884183,212.69479427943008,0.31244790255654653
0.03004382093000295,0.06168833766753351,332.6364097761188,212.69479427943008,0.31244790255654653
0.030389873371611906,0.06239887977595519,333.5933110962596,212.69479427943008,0.31244790255654653
0.030595634282838853,0.06282136427285458,334.1602649943058,212.69479427943008,0.31244790255654653
0.030670456432375925,0.0629749949989998,334.3660611170902,212.69479427943008,0.31244790255654653
0.030960392261832077,0.06357031406281256,335.1616785554176,212.69479427943008,0.31244790255654653
0.031053919948753415,0.0637623524704941,335.4177087846246,212.69479427943008,0.31244790255654653
0.031175505941751155,0.06401200240048009,335.75009893908015,212.69479427943008,0.31244790255654653
0.03140932515905451,0.06449209841968394,336.38789322260976,212.69479427943008,0.31244790255654653
0.03144673623382304,0.06456891378275655,336.48976822223284,212.69479427943008,0.31244790255654653
0.03161508607028146,0.06491458291658332,336.94762205315095,212.69479427943008,0.31244790255654653
0.031689908219818534,0.06506821364272855,337.150807332774,212.69479427943008,0.31244790255654653
0.03171796652589493,0.06512582516503301,337.2269535659739,212.69479427943008,0.31244790255654653
0.03213884111704096,0.06598999799959993,338.36601308570715,212.69479427943008,0.31244790255654653
0.03215754665442523,0.06602840568113623,338.41650248968284,212.69479427943008,0.31244790255654653
0.032410071409112846,0.06654690938187638,339.09699228187316,212.69479427943008,0.31244790255654653
0.032466188021265656,0.0666621324264853,339.24793105862557,212.69479427943008,0.31244790255654653
0.032569068476879126,0.066873374674935,339.52438815221933,212.69479427943008,0.31244790255654653
0.03277482938810607,0.06729585917183437,340.0762827136161,212.69479427943008,0.31244790255654653
0.03294317922456449,0.06764152830566114,340.5268284223437,212.69479427943008,0.31244790255654653
0.03307411798625436,0.06791038207641528,340.8766323491206,212.69479427943008,0.31244790255654653
0.033167645673175705,0.06810242048409683,341.1261617083419,212.69479427943008,0.31244790255654653
0.03324246782271278,0.06825605121024206,341.32558767187743,212.69479427943008,0.31244790255654653
0.03334534827832625,0.06846729345869174,341.5995127706745,212.69479427943008,0.31244790255654653
0.03349499257740039,0.0687745549109822,341.9973616256831,212.69479427943008,0.31244790255654653
0.033672695182550935,0.06913942788557711,342.46890791251786,212.69479427943008,0.31244790255654653
0.03380363394424082,0.06940828165633127,342.81574228239106,212.69479427943008,0.31244790255654653
0.03389716163116215,0.0696003200640128,343.06316040814727,212.69479427943008,0.31244790255654653
0.03401874762415989,0.0698499699939988,343.3844063088479,212.69479427943008,0.31244790255654653
0.03406551146762057,0.06994598919783958,343.50784315382475,212.69479427943008,0.31244790255654653
0.03417774469192617,0.07017643528705741,343.80382226546703,212.69479427943008,0.31244790255654653
0.03431803622230818,0.07046449289857971,344.1732636492893,212.69479427943008,0.31244790255654653
0.034411563909229524,0.07065653130626126,344.4192307335498,212.69479427943008,0.31244790255654653
0.03453314990222727,0.07090618123624726,344.7385985167654,212.69479427943008,0.31244790255654653
0.034907260649912626,0.0716743348669734,345.7185291858993,212.69479427943008,0.31244790255654653
0.035290724166290116,0.07246169233846769,346.71871669164267,212.69479427943008,0.31244790255654653
0.035449721234056396,0.07278815763152631,347.13218448903876,212.69479427943008,0.31244790255654653
0.035590012764438406,0.07307621524304861,347.4964087776351,212.69479427943008,0.31244790255654653
0.03567418768266761,0.073249049809962,347.71467459221674,212.69479427943008,0.31244790255654653
0.03573965706351255,0.07338347669533907,347.88429806095183,212.69479427943008,0.31244790255654653
0.03602959289296871,0.07397879575915184,348.6340357863415,212.69479427943008,0.31244790255654653
0.03656270070842034,0.07507341468293659,350.00647361085083,212.69479427943008,0.31244790255654653
0.036712345007494485,0.07538067613522705,350.39031365189356,212.69479427943008,0.31244790255654653
0.0368245782318001,0.0756111222244449,350.67779337569175,212.69479427943008,0.31244790255654653
0.03705839744910344,0.07609121824364873,351.2756142880517,212.69479427943008,0.31244790255654653
0.037264158360330396,0.07651370274054811,351.80048089455704,212.69479427943008,0.31244790255654653
0.037488624808941606,0.0769745949189838,352.3717752478152,212.69479427943008,0.31244790255654653
0.03756344695847868,0.07712822564512903,352.5619100371147,212.69479427943008,0.31244790255654653
0.03761021080193935,0.0772242448489698,352.68066927785463,212.69479427943008,0.31244790255654653
0.03774114956362923,0.07749309861972395,353.01288917176566,212.69479427943008,0.31244790255654653
0.03788144109401124,0.07778115623124625,353.3683406282542,212.69479427943008,0.31244790255654653
0.03807784923654605,0.07818443688737747,353.86511137721425,212.69479427943008,0.31244790255654653
0.03837713783469434,0.07879895979195839,354.62017808018925,212.69479427943008,0.31244790255654653
0.038545487671152755,0.07914462892578517,355.04389382617774,212.69479427943008,0.31244790255654653
0.038629662589381955,0.07931746349269854,355.2554810042616,212.69479427943008,0.31244790255654653
0.03867642643284262,0.0794134826965393,355.37295173861884,212.69479427943008,0.31244790255654653
0.03911600656137293,0.08031606321264254,356.4744823017181,212.69479427943008,0.31244790255654653
0.039621056070748166,0.08135307061412284,357.73412824339033,212.69479427943008,0.31244790255654653
0.03993905020628072,0.08200600120024006,358.5240268806916,212.69479427943008,0.31244790255654653
0.04006063619927846,0.08225565113022605,358.8253982705297,212.69479427943008,0.31244790255654653
0.0405376274025773,0.08323504700940189,360.00427268474635,212.69479427943008,0.31244790255654653
0.04068727170165144,0.08354230846169235,360.3729991791378,212.69479427943008,0.31244790255654653
0.04091173815026266,0.08400320064012803,360.92509878989995,212.69479427943008,0.31244790255654653
0.0411174990614896,0.0844256851370274,361.4301531843254,212.69479427943008,0.31244790255654653
0.04119232121102667,0.08457931586317263,361.61356481985143,212.69479427943008,0.31244790255654653
0.04149160980917496,0.08519383876775355,362.3459157983969,212.69479427943008,0.31244790255654653
0.041538373652635636,0.08528985797159433,362.46015927075223,212.69479427943008,0.31244790255654653
0.04157578472740417,0.08536667333466694,362.5515179376577,212.69479427943008,0.31244790255654653
0.04159449026478843,0.08540508101620324,362.59718524792,212.69479427943008,0.31244790255654653
0.041847015019476054,0.08592358471694339,363.212912111382,212.69479427943008,0.31244790255654653
0.042267889610622084,0.0867877575515103,364.23591309661106,212.69479427943008,0.31244790255654653
0.04239882837231196,0.08705661132226446,364.55336883050944,212.69479427943008,0.31244790255654653
0.04259523651484677,0.08745989197839568,365.0288364647396,212.69479427943008,0.31244790255654653
0.04283840850084226,0.08795919183836767,365.6163276974134,212.69479427943008,0.31244790255654653
0.04352116061536804,0.0893610722144429,367.2589103793822,212.69479427943008,0.31244790255654653
0.04369886322051859,0.08972594518903781,367.6847797976266,212.69479427943008,0.31244790255654653
0.04394203520651407,0.0902252450490098,368.2664556017259,212.69479427943008,0.31244790255654653
0.04417585442381742,0.09070534106821365,368.82457651963324,212.69479427943008,0.31244790255654653
0.04449384855934998,0.09135827165433087,369.5817756068424,212.69479427943008,0.31244790255654653
0.04469025670188479,0.0917615523104621,370.0484031660191,212.69479427943008,0.31244790255654653
0.04498019253134094,0.09235687137427485,370.73577521519593,212.69479427943008,0.31244790255654653
0.04523271728602856,0.092875375075015,371.3330474014913,212.69479427943008,0.31244790255654653
0.04607446646832062,0.09460372074414883,373.3146288315175,212.69479427943008,0.31244790255654653
0.046242816304779034,0.0949493898779756,373.70924535797275,212.69479427943008,0.31244790255654653
0.046504693828158784,0.0954870974194839,374.3219814635398,212.69479427943008,0.31244790255654653
0.04660757428377226,0.09569833966793359,374.5623308671508,212.69479427943008,0.31244790255654653
0.046803982426307074,0.09610162032406482,375.0206059445418,212.69479427943008,0.31244790255654653
0.047037801643610426,0.09658171634326866,375.5651947647559,212.69479427943008,0.31244790255654653
0.04718744594268457,0.09688897779555912,375.91317762108406,212.69479427943008,0.31244790255654653
0.04735579577914298,0.09723464692938588,376.3041443022268,212.69479427943008,0.31244790255654653
0.04741191239129579,0.09734986997399481,376.4343460235258,212.69479427943008,0.31244790255654653
0.04767378991467554,0.0978875775155031,377.04116115635435,212.69479427943008,0.31244790255654653
0.04802919512497663,0.09861732346469294,377.862620753821,212.69479427943008,0.31244790255654653
0.04815078111797437,0.09886697339467894,378.14310172626733,212.69479427943008,0.31244790255654653
0.04821625049881931,0.09900140028005601,378.2940155278392,212.69479427943008,0.31244790255654653
0.04840330587266199,0.09938547709541909,378.72475808947763,212.69479427943008,0.31244790255654653
0.0485716557091204,0.09973114622924585,379.1118716474897,212.69479427943008,0.31244790255654653
0.04860906678388894,0.09980796159231847,379.19782577928714,212.69479427943008,0.31244790255654653