File: datasets/aisi_316_L/data/M1/train_24.csv
Time(s),Strain(%),Stress(MPa),Temp(C),Log_SR(s-1)
0.0,0.0,0.0,348.21034101266855,4.0111132183683065
4.2888361823692535e-09,4.4e-05,7.6395983124999995,348.21034101266855,4.0111132183683065
5.848412975958073e-09,5.9999999999999995e-05,10.4176340625,348.21034101266855,4.0111132183683065
8.03182048698242e-09,8.24e-05,14.306884112499999,348.21034101266855,4.0111132183683065
1.0917037555121736e-08,0.000112,19.44625025,348.21034101266855,4.0111132183683065
1.286650854710776e-08,0.00013199999999999998,22.918794937499996,348.21034101266855,4.0111132183683065
1.3412360424863847e-08,0.00013759999999999998,23.891107449999996,348.21034101266855,4.0111132183683065
1.512789489781155e-08,0.0001552,26.946946775,348.21034101266855,4.0111132183683065
1.614161981364428e-08,0.0001656,28.752670012499998,348.21034101266855,4.0111132183683065
1.6921408210438693e-08,0.0001736,30.141687887499998,348.21034101266855,4.0111132183683065
1.7155344729477014e-08,0.000176,30.558393249999998,348.21034101266855,4.0111132183683065
2.105428671344906e-08,0.000216,37.503482625,348.21034101266855,4.0111132183683065
2.1366202072166826e-08,0.0002192,38.059089775,348.21034101266855,4.0111132183683065
2.237992698799956e-08,0.0002296,39.8648130125,348.21034101266855,4.0111132183683065
2.4407376819665027e-08,0.0002504,43.4762594875,348.21034101266855,4.0111132183683065
2.643482665133049e-08,0.0002712,47.087705962499996,348.21034101266855,4.0111132183683065
2.994387443690533e-08,0.0003072,53.338286399999994,348.21034101266855,4.0111132183683065
3.0333768635302534e-08,0.0003112,54.0327953375,348.21034101266855,4.0111132183683065
3.0801641673379184e-08,0.000316,54.8662060625,348.21034101266855,4.0111132183683065
3.103557819241751e-08,0.0003184,55.282911424999995,348.21034101266855,4.0111132183683065
3.251717614632688e-08,0.0003336,57.9220453875,348.21034101266855,4.0111132183683065
3.314100686376241e-08,0.00033999999999999997,59.03325968749999,348.21034101266855,4.0111132183683065
3.376483758119794e-08,0.00034639999999999996,60.14447398749999,348.21034101266855,4.0111132183683065
3.3920795260556825e-08,0.000348,60.4222775625,348.21034101266855,4.0111132183683065
3.735186420645223e-08,0.0003832,66.5339562125,348.21034101266855,4.0111132183683065
3.758580072549055e-08,0.0003856,66.950661575,348.21034101266855,4.0111132183683065
3.8833462160361604e-08,0.0003984,69.173090175,348.21034101266855,4.0111132183683065
4.070495431266819e-08,0.00041759999999999996,72.506733075,348.21034101266855,4.0111132183683065
4.273240414433365e-08,0.0004384,76.11817955,348.21034101266855,4.0111132183683065
4.507176933471688e-08,0.00046239999999999996,80.28523317499999,348.21034101266855,4.0111132183683065
4.6865282647344024e-08,0.0004808,83.4799742875,348.21034101266855,4.0111132183683065
4.9360605517086136e-08,0.0005064,87.92483148749999,348.21034101266855,4.0111132183683065
5.0452309272598314e-08,0.0005176,89.8694565125,348.21034101266855,4.0111132183683065
5.185592838682825e-08,0.000532,92.3696886875,348.21034101266855,4.0111132183683065
5.349348402009651e-08,0.0005488,95.286626225,348.21034101266855,4.0111132183683065
5.4741145454967565e-08,0.0005616,97.50905482499999,348.21034101266855,4.0111132183683065
5.6378701088235825e-08,0.0005784,100.4259923625,348.21034101266855,4.0111132183683065
5.7860299042145206e-08,0.0005936,103.06512632500001,348.21034101266855,4.0111132183683065
5.91859393166957e-08,0.0006072,105.4264567125,348.21034101266855,4.0111132183683065
5.973179119445178e-08,0.0006127999999999999,106.398769225,348.21034101266855,4.0111132183683065
5.996572771349011e-08,0.0006152,106.81547458749999,348.21034101266855,4.0111132183683065
6.019966423252843e-08,0.0006175999999999999,107.23217994999999,348.21034101266855,4.0111132183683065
6.168126218643781e-08,0.0006328,109.8713139125,348.21034101266855,4.0111132183683065
6.214913522451446e-08,0.0006376,110.7047246375,348.21034101266855,4.0111132183683065
6.316286014034718e-08,0.0006479999999999999,112.51044787499998,348.21034101266855,4.0111132183683065
6.409860621650048e-08,0.0006575999999999999,114.17726932499998,348.21034101266855,4.0111132183683065
6.464445809425657e-08,0.0006632,115.1495818375,348.21034101266855,4.0111132183683065
6.503435229265377e-08,0.0006672,115.844090775,348.21034101266855,4.0111132183683065
6.651595024656315e-08,0.0006824,118.4832247375,348.21034101266855,4.0111132183683065
6.815350587983141e-08,0.0006992,121.400162275,348.21034101266855,4.0111132183683065
6.877733659726695e-08,0.0007056,122.511376575,348.21034101266855,4.0111132183683065
6.901127311630527e-08,0.000708,122.9280819375,348.21034101266855,4.0111132183683065
7.018095571149687e-08,0.0007199999999999999,125.01160875,348.21034101266855,4.0111132183683065
7.220840554316235e-08,0.0007408,128.623055225,348.21034101266855,4.0111132183683065
7.2676278581239e-08,0.0007456,129.45646595,348.21034101266855,4.0111132183683065
7.501564377162222e-08,0.0007696,133.623519575,348.21034101266855,4.0111132183683065
7.618532636681382e-08,0.0007815999999999999,135.7070463875,348.21034101266855,4.0111132183683065
7.751096664136433e-08,0.0007951999999999999,138.068376775,348.21034101266855,4.0111132183683065
7.844671271751761e-08,0.0008047999999999999,139.73519822499998,348.21034101266855,4.0111132183683065
7.946043763335035e-08,0.0008152,141.5409214625,348.21034101266855,4.0111132183683065
8.12539509459775e-08,0.0008336,144.735662575,348.21034101266855,4.0111132183683065
8.312544309828407e-08,0.0008527999999999999,148.069305475,348.21034101266855,4.0111132183683065
8.359331613636072e-08,0.0008575999999999999,148.9027162,348.21034101266855,4.0111132183683065
8.749225812033277e-08,0.0008975999999999999,155.847805575,348.21034101266855,4.0111132183683065
8.81160888377683e-08,0.000904,156.959019875,348.21034101266855,4.0111132183683065
8.920779259328047e-08,0.0009151999999999999,158.9036449,348.21034101266855,4.0111132183683065
9.092332706622816e-08,0.0009327999999999999,161.95948422499998,348.21034101266855,4.0111132183683065
9.15471577836637e-08,0.0009392,163.07069852499998,348.21034101266855,4.0111132183683065
9.341864993597029e-08,0.0009584,166.40434142499998,348.21034101266855,4.0111132183683065
9.599195164539183e-08,0.0009847999999999999,170.9881004125,348.21034101266855,4.0111132183683065
9.856525335481338e-08,0.0010111999999999999,175.57185939999997,348.21034101266855,4.0111132183683065
1.0035876666744053e-07,0.0010295999999999999,178.7666005125,348.21034101266855,4.0111132183683065
1.0254217417846488e-07,0.001052,182.6558505625,348.21034101266855,4.0111132183683065
1.0394579329269482e-07,0.0010664,184.7690156562054,348.21034101266855,4.0111132183683065
1.0519345472756587e-07,0.0010792,184.8436754864879,348.21034101266855,4.0111132183683065
1.0589526428468084e-07,0.0010864,184.8855198594449,348.21034101266855,4.0111132183683065
1.0753281991794909e-07,0.0011032,184.98273837256554,348.21034101266855,4.0111132183683065
1.0854654483378183e-07,0.0011136,185.04263198551837,348.21034101266855,4.0111132183683065
1.0893643903217903e-07,0.0011175999999999998,185.0656098546037,348.21034101266855,4.0111132183683065
1.0987218510833233e-07,0.0011271999999999999,185.12062627305176,348.21034101266855,4.0111132183683065
1.1127580422256227e-07,0.0011416,185.2028095015852,348.21034101266855,4.0111132183683065
1.1182165610031835e-07,0.0011472,185.23466033870957,348.21034101266855,4.0111132183683065
1.1392708477166327e-07,0.0011688,185.35694972813783,348.21034101266855,4.0111132183683065
1.1767006907627642e-07,0.0012071999999999999,185.57219866394962,348.21034101266855,4.0111132183683065
1.1844985747307084e-07,0.0012152,185.61670421464453,348.21034101266855,4.0111132183683065
1.1915166703018581e-07,0.0012224,185.6566616067559,348.21034101266855,4.0111132183683065
1.2156901106024848e-07,0.0012472,185.79359548433348,348.21034101266855,4.0111132183683065
1.2211486293800456e-07,0.0012527999999999999,185.82436858583486,348.21034101266855,4.0111132183683065
1.2242677829672232e-07,0.001256,185.84192912859677,348.21034101266855,4.0111132183683065
1.2289465133479895e-07,0.0012607999999999999,185.86823726190488,348.21034101266855,4.0111132183683065
1.236744397315934e-07,0.0012688,185.91199751304393,348.21034101266855,4.0111132183683065
1.2624774144101495e-07,0.0012952,186.0556488616787,348.21034101266855,4.0111132183683065
1.2858710663139816e-07,0.0013192,186.18525307004217,348.21034101266855,4.0111132183683065
1.3100445066146083e-07,0.001344,186.3182149837596,348.21034101266855,4.0111132183683065
1.3256402745504964e-07,0.0013599999999999999,186.40348932975135,348.21034101266855,4.0111132183683065
1.3373371005024126e-07,0.001372,186.46718855949328,348.21034101266855,4.0111132183683065
1.3388966772960017e-07,0.0013736,186.47566534337798,348.21034101266855,4.0111132183683065
1.3537126568350954e-07,0.0013888,186.55600364831815,348.21034101266855,4.0111132183683065
1.3716477899613667e-07,0.0014072,186.6527979243728,348.21034101266855,4.0111132183683065
1.389582923087638e-07,0.0014256,186.74909983884126,348.21034101266855,4.0111132183683065
1.4207744589594146e-07,0.0014575999999999999,186.91543470796665,348.21034101266855,4.0111132183683065
1.4316914965145364e-07,0.0014688,186.97331465271247,348.21034101266855,4.0111132183683065
1.45352557162478e-07,0.0014912,187.08856072868858,348.21034101266855,4.0111132183683065
1.457424513608752e-07,0.0014952,187.10906913908246,348.21034101266855,4.0111132183683065
1.5057713942100053e-07,0.0015448,187.36162129147652,348.21034101266855,4.0111132183683065
1.5338437764946038e-07,0.0015735999999999999,187.5068130859947,348.21034101266855,4.0111132183683065
1.549439544430492e-07,0.0015895999999999998,187.58702728315163,348.21034101266855,4.0111132183683065
1.5689342543503523e-07,0.0016095999999999999,187.68685359715292,348.21034101266855,4.0111132183683065
1.5767321383182965e-07,0.0016175999999999999,187.7266485306598,348.21034101266855,4.0111132183683065
1.592327906254185e-07,0.0016336,187.8060088751095,348.21034101266855,4.0111132183683065
1.6141619813644282e-07,0.001656,187.91660596006616,348.21034101266855,4.0111132183683065
1.62507901891955e-07,0.0016672,187.97168559971502,348.21034101266855,4.0111132183683065
1.648472670823382e-07,0.0016912,188.08922981205768,348.21034101266855,4.0111132183683065
1.6586099199817094e-07,0.0017016,188.13996340681715,348.21034101266855,4.0111132183683065
1.6601694967752985e-07,0.0017032,188.147757828787,348.21034101266855,4.0111132183683065
1.7038376469957853e-07,0.001748,188.3648558801445,348.21034101266855,4.0111132183683065
1.7350291828675616e-07,0.00178,188.5185993613524,348.21034101266855,4.0111132183683065
1.7412674900419167e-07,0.0017863999999999998,188.5492182927131,348.21034101266855,4.0111132183683065
1.760762199961777e-07,0.0018063999999999999,188.64462787050388,348.21034101266855,4.0111132183683065
1.7670005071361322e-07,0.0018127999999999998,188.67507180914905,348.21034101266855,4.0111132183683065
1.7997516198014978e-07,0.0018464,188.83421997479118,348.21034101266855,4.0111132183683065
1.8091090805630306e-07,0.001856,188.87948290275364,348.21034101266855,4.0111132183683065
1.8278240020860963e-07,0.0018751999999999998,188.96973576634184,348.21034101266855,4.0111132183683065
1.848098500402751e-07,0.001896,189.06710396758191,348.21034101266855,4.0111132183683065
1.8582357495610784e-07,0.0019064,189.11563178278345,348.21034101266855,4.0111132183683065
1.9081422069559207e-07,0.0019576,189.3530488979668,348.21034101266855,4.0111132183683065
1.94167310801808e-07,0.001992,189.5112047818107,348.21034101266855,4.0111132183683065
1.9455720500020524e-07,0.001996,189.52952561292238,348.21034101266855,4.0111132183683065
1.960388029541146e-07,0.0020112,189.59901457166345,348.21034101266855,4.0111132183683065
1.969745490302679e-07,0.0020208,189.64279682404688,348.21034101266855,4.0111132183683065
1.9869008350321563e-07,0.0020384,189.7228541866779,348.21034101266855,4.0111132183683065
2.0032763913648388e-07,0.0020552,189.79902147317145,348.21034101266855,4.0111132183683065
2.0071753333488105e-07,0.0020591999999999997,189.81712070479003,348.21034101266855,4.0111132183683065
2.0243306780782874e-07,0.0020767999999999997,189.89659498814027,348.21034101266855,4.0111132183683065
2.032128562046232e-07,0.0020848,189.9326327864364,348.21034101266855,4.0111132183683065
2.0368072924269983e-07,0.0020896,189.9542295788533,348.21034101266855,4.0111132183683065
2.0547424255532698e-07,0.002108,190.03683866461003,348.21034101266855,4.0111132183683065
2.0664392515051858e-07,0.00212,190.09056269291798,348.21034101266855,4.0111132183683065
2.085933961425046e-07,0.00214,190.17983993499018,348.21034101266855,4.0111132183683065
2.0929520569961954e-07,0.0021471999999999997,190.21190000716567,348.21034101266855,4.0111132183683065
2.121804227677589e-07,0.0021768,190.34326443585363,348.21034101266855,4.0111132183683065
2.1350606304230937e-07,0.0021904,190.40338731032287,348.21034101266855,4.0111132183683065
2.1514361867557765e-07,0.0022072,190.4774561209332,348.21034101266855,4.0111132183683065
2.177169203849992e-07,0.0022336,190.59340727855195,348.21034101266855,4.0111132183683065
2.220837354070479e-07,0.0022784,190.78895717298963,348.21034101266855,4.0111132183683065
2.228635238038423e-07,0.0022864,190.82371841394684,348.21034101266855,4.0111132183683065
2.2325341800223948e-07,0.0022903999999999997,190.84108124404554,348.21034101266855,4.0111132183683065
2.2528086783390495e-07,0.0023112,190.9311780361875,348.21034101266855,4.0111132183683065
2.2754225418460877e-07,0.0023344,191.03129837375636,348.21034101266855,4.0111132183683065
2.2886789445915924e-07,0.002348,191.08980919163918,348.21034101266855,4.0111132183683065
2.3019353473370974e-07,0.0023615999999999997,191.14818798516555,348.21034101266855,4.0111132183683065
2.310513019701836e-07,0.0023704,191.18589264349157,348.21034101266855,4.0111132183683065
2.31831090366978e-07,0.0023783999999999997,191.2201222600546,348.21034101266855,4.0111132183683065
2.3596396886998838e-07,0.0024208,191.4007950359117,348.21034101266855,4.0111132183683065
2.4087663576979317e-07,0.0024712,191.61395941594557,348.21034101266855,4.0111132183683065
2.429820644411381e-07,0.0024928,191.7047957819435,348.21034101266855,4.0111132183683065
2.4469759891408575e-07,0.0025104,191.7785838492529,348.21034101266855,4.0111132183683065
2.449315354331241e-07,0.0025128,191.78863020415432,348.21034101266855,4.0111132183683065
2.4633515454735403e-07,0.0025272,191.8488299353431,348.21034101266855,4.0111132183683065
2.479727101806223e-07,0.002544,191.918894136229,348.21034101266855,4.0111132183683065
2.4922037161549334e-07,0.0025567999999999997,191.97215533417702,348.21034101266855,4.0111132183683065
2.502340965313261e-07,0.0025672,192.0153535283772,348.21034101266855,4.0111132183683065
2.5085792724876157e-07,0.0025735999999999997,192.04190311157018,348.21034101266855,4.0111132183683065
2.5210558868363265e-07,0.0025864,192.09492515685136,348.21034101266855,4.0111132183683065
2.5374314431690093e-07,0.0026032,192.1643615457075,348.21034101266855,4.0111132183683065
2.5522474227081033e-07,0.0026184,192.22703449975617,348.21034101266855,4.0111132183683065
2.563164460263225e-07,0.0026295999999999997,192.27312381522407,348.21034101266855,4.0111132183683065
2.590457054151029e-07,0.0026576,192.38801342185477,348.21034101266855,4.0111132183683065
2.616969859642039e-07,0.0026847999999999998,192.49916928446564,348.21034101266855,4.0111132183683065
2.623208166816394e-07,0.0026912,192.52525967422415,348.21034101266855,4.0111132183683065
2.6302262623875437e-07,0.0026983999999999997,192.55458245590248,348.21034101266855,4.0111132183683065
2.6481613955138153e-07,0.0027167999999999997,192.62938016033297,348.21034101266855,4.0111132183683065
2.6692156822272645e-07,0.0027383999999999998,192.71693453507686,348.21034101266855,4.0111132183683065
2.6715550474176477e-07,0.0027408,192.72664614451023,348.21034101266855,4.0111132183683065
2.6777933545920033e-07,0.0027472,192.75252756901622,348.21034101266855,4.0111132183683065
2.7035263716862183e-07,0.0027735999999999998,192.85904083151493,348.21034101266855,4.0111132183683065
2.7331583307644063e-07,0.002804,192.98120389796787,348.21034101266855,4.0111132183683065
2.76746902022336e-07,0.0028392,193.12201241236127,348.21034101266855,4.0111132183683065
2.7846243649528374e-07,0.0028568,193.19216123701375,348.21034101266855,4.0111132183683065
2.789303095333603e-07,0.0028615999999999997,193.211263457202,348.21034101266855,4.0111132183683065
2.832971245554091e-07,0.0029064,193.38895230931683,348.21034101266855,4.0111132183683065
2.8477872250931843e-07,0.0029216,193.44899648428907,348.21034101266855,4.0111132183683065
2.8516861670771563e-07,0.0029256,193.46477731854182,348.21034101266855,4.0111132183683065
2.8704010886002223e-07,0.0029448,193.5404085020421,348.21034101266855,4.0111132183683065
2.874300030584194e-07,0.0029487999999999997,193.55614076518808,348.21034101266855,4.0111132183683065
2.8852170681393163e-07,0.00296,193.60014688625492,348.21034101266855,4.0111132183683065
2.8953543172976434e-07,0.0029703999999999998,193.64095160171718,348.21034101266855,4.0111132183683065
2.9093905084399425e-07,0.0029847999999999997,193.69735857454873,348.21034101266855,4.0111132183683065
2.9242064879790365e-07,0.003,193.75678425038524,348.21034101266855,4.0111132183683065
2.932784160343775e-07,0.0030088,193.79113491807112,348.21034101266855,4.0111132183683065
2.947600139882869e-07,0.0030239999999999998,193.85037574389483,348.21034101266855,4.0111132183683065
2.9507192934700464e-07,0.0030272,193.86283268612252,348.21034101266855,4.0111132183683065
2.956177812247607e-07,0.0030328,193.88461998473934,348.21034101266855,4.0111132183683065
2.9694342149931124e-07,0.0030464,193.9374667787031,348.21034101266855,4.0111132183683065
3.015441730403982e-07,0.0030935999999999997,194.12016667528565,348.21034101266855,4.0111132183683065
3.0310374983398705e-07,0.0031095999999999997,194.18185169912005,348.21034101266855,4.0111132183683065
3.040394959101404e-07,0.0031192,194.2188033005088,348.21034101266855,4.0111132183683065
3.054431150243703e-07,0.0031336,194.27414764899547,348.21034101266855,4.0111132183683065
3.0575503038308804e-07,0.0031368,194.28643291293344,348.21034101266855,4.0111132183683065
3.075485436957152e-07,0.0031552,194.35697855799012,348.21034101266855,4.0111132183683065
3.100438665654573e-07,0.0031807999999999997,194.45486270011378,348.21034101266855,4.0111132183683065
3.1191535871776386e-07,0.0031999999999999997,194.52807430566946,348.21034101266855,4.0111132183683065
3.1339695667167326e-07,0.0032151999999999997,194.58591206753852,348.21034101266855,4.0111132183683065
3.1487855462558266e-07,0.0032304,194.6436432892561,348.21034101266855,4.0111132183683065
3.186215389301958e-07,0.0032687999999999997,194.78902068384963,348.21034101266855,4.0111132183683065
3.2119484063961736e-07,0.0032952,194.888581504375,348.21034101266855,4.0111132183683065
3.224425020744884e-07,0.0033079999999999997,194.9367413991984,348.21034101266855,4.0111132183683065
3.2384612118871835e-07,0.0033223999999999997,194.99083449428437,348.21034101266855,4.0111132183683065
3.2408005770775667e-07,0.0033247999999999997,194.99984111314316,348.21034101266855,4.0111132183683065
3.260295286997427e-07,0.0033447999999999998,195.07479792040814,348.21034101266855,4.0111132183683065
3.2860283040916425e-07,0.0033712,195.17347380170722,348.21034101266855,4.0111132183683065
3.3024038604243253e-07,0.003388,195.23611066585315,348.21034101266855,4.0111132183683065
3.3265773007249515e-07,0.0034127999999999997,195.3283536724794,348.21034101266855,4.0111132183683065
3.3406134918672517e-07,0.0034272,195.3817941629187,348.21034101266855,4.0111132183683065
3.3710252393422336e-07,0.0034584,195.49728239958768,348.21034101266855,4.0111132183683065
3.3983178332300373e-07,0.0034863999999999997,195.60058018673456,348.21034101266855,4.0111132183683065
3.413913601165926e-07,0.0035023999999999997,195.65946222271342,348.21034101266855,4.0111132183683065
3.424830638721048e-07,0.0035136,195.7006172444236,348.21034101266855,4.0111132183683065
3.4365274646729637e-07,0.0035256,195.74465517678163,348.21034101266855,4.0111132183683065
3.466159423751151e-07,0.0035559999999999997,195.85595711123406,348.21034101266855,4.0111132183683065
3.502809478400488e-07,0.0035935999999999997,195.99310802279697,348.21034101266855,4.0111132183683065
3.5145063043524046e-07,0.0036056,196.03676163144812,348.21034101266855,4.0111132183683065
3.523083976717143e-07,0.0036144,196.0687382747331,348.21034101266855,4.0111132183683065
3.541798898240209e-07,0.0036336,196.13840029428772,348.21034101266855,4.0111132183683065
3.562853184953658e-07,0.0036552,196.21659869866002,348.21034101266855,4.0111132183683065
3.568311703731219e-07,0.0036607999999999996,196.2368429144075,348.21034101266855,4.0111132183683065
3.5714308573183964e-07,0.0036639999999999997,196.24840561510294,348.21034101266855,4.0111132183683065
3.587806413651079e-07,0.0036807999999999997,196.3090453013837,348.21034101266855,4.0111132183683065
3.603402181586967e-07,0.0036967999999999997,196.36669710851996,348.21034101266855,4.0111132183683065
3.609640488761323e-07,0.0037032,196.3897305738494,348.21034101266855,4.0111132183683065
3.6112000655549116e-07,0.0037048,196.39548651378786,348.21034101266855,4.0111132183683065
3.623676679903622e-07,0.0037175999999999997,196.44149918395803,348.21034101266855,4.0111132183683065
3.642391601426688e-07,0.0037367999999999998,196.5104025101905,348.21034101266855,4.0111132183683065
3.6642256765369314e-07,0.0037592,196.59061545897586,348.21034101266855,4.0111132183683065
3.6767022908856417e-07,0.0037719999999999997,196.63636773474371,348.21034101266855,4.0111132183683065
3.682160809663203e-07,0.0037776,196.65636531092872,348.21034101266855,4.0111132183683065
3.7156917107253624e-07,0.003812,196.77895488364734,348.21034101266855,4.0111132183683065
3.754681130565083e-07,0.003852,196.9209596970604,348.21034101266855,4.0111132183683065
3.767937533310588e-07,0.0038656,196.96911017424597,348.21034101266855,4.0111132183683065
3.779634359262504e-07,0.0038775999999999997,197.0115410507441,348.21034101266855,4.0111132183683065
3.7999088575791585e-07,0.0038983999999999998,197.08496678975382,348.21034101266855,4.0111132183683065
3.8170642023086357e-07,0.003916,197.14697700186144,348.21034101266855,4.0111132183683065
3.8264216630701685e-07,0.0039256,197.1807549382458,348.21034101266855,4.0111132183683065
3.85137489176759e-07,0.0039512,197.27067230901147,348.21034101266855,4.0111132183683065
3.8552738337515615e-07,0.0039552,197.28470134809268,348.21034101266855,4.0111132183683065
3.873988755274627e-07,0.0039743999999999995,197.35196386406895,348.21034101266855,4.0111132183683065
3.878667485655394e-07,0.0039792,197.36875967741435,348.21034101266855,4.0111132183683065
3.8919238884008986e-07,0.0039927999999999995,197.41630495948365,348.21034101266855,4.0111132183683065
3.895822830384871e-07,0.0039968,197.4302768407261,348.21034101266855,4.0111132183683065
4.2733152890943904e-07,0.004384076815363073,198.75828917989418,348.21034101266855,4.0111132183683065
4.516657937423912e-07,0.00463372674534907,199.59015231393363,348.21034101266855,4.0111132183683065
4.891031242546253e-07,0.005017803560712143,200.83658091046243,348.21034101266855,4.0111132183683065
5.54618452651035e-07,0.005689937987597519,202.93169869238073,348.21034101266855,4.0111132183683065
6.444680458803969e-07,0.006611722344468894,205.65404824699783,348.21034101266855,4.0111132183683065
6.800335098670193e-07,0.006976595319063813,206.69018010194307,348.21034101266855,4.0111132183683065
7.380613721609821e-07,0.007571914382876575,208.33643076122615,348.21034101266855,4.0111132183683065
8.110641666598386e-07,0.008320864172834567,210.3374516738042,348.21034101266855,4.0111132183683065
8.391421645440143e-07,0.008608921784356871,211.08820331935343,348.21034101266855,4.0111132183683065
8.990418933635889e-07,0.009223444688937788,212.65781723084257,348.21034101266855,4.0111132183683065
9.402229569270464e-07,0.009645929185837168,213.71333288632707,348.21034101266855,4.0111132183683065
9.477104230294932e-07,0.009722744548909782,213.90329167828236,348.21034101266855,4.0111132183683065
9.795321539648922e-07,0.010049209841968394,214.70417273454606,348.21034101266855,4.0111132183683065
9.982508192210094e-07,0.01024124824964993,215.1705393323291,348.21034101266855,4.0111132183683065
1.0450474823613017e-06,0.01072134426885377,216.32177647310277,348.21034101266855,4.0111132183683065
1.0806129463479243e-06,0.01108621724344869,217.18331670002888,348.21034101266855,4.0111132183683065
1.0937160120272061e-06,0.011220644128825764,217.49792936931473,348.21034101266855,4.0111132183683065
1.1292814760138287e-06,0.011585517103420685,218.3445542675048,348.21034101266855,4.0111132183683065
1.1367689421162757e-06,0.0116623324664933,218.5214587665169,348.21034101266855,4.0111132183683065
1.146128274744334e-06,0.011758351670334066,218.74195164845432,348.21034101266855,4.0111132183683065
1.1629750734748393e-06,0.011931186237247449,219.1370773439918,348.21034101266855,4.0111132183683065
1.1816937387309564e-06,0.012123224644928985,219.5734970006502,348.21034101266855,4.0111132183683065
1.2266185353456373e-06,0.012584116823364673,220.610047572773,348.21034101266855,4.0111132183683065
1.2659277323834832e-06,0.012987397479495899,221.50494196283253,348.21034101266855,4.0111132183683065
1.3220837281518343e-06,0.013563512702540508,222.76478519159605,348.21034101266855,4.0111132183683065
1.3464179929847865e-06,0.013813162632526505,223.30421617224934,348.21034101266855,4.0111132183683065
1.3913427895994675e-06,0.014274054810962193,224.29020309297275,348.21034101266855,4.0111132183683065
1.3969583891763026e-06,0.014331666333266654,224.41257240761777,348.21034101266855,4.0111132183683065
1.4287801201117017e-06,0.014658131626325266,225.10240866885252,348.21034101266855,4.0111132183683065
1.4474987853678186e-06,0.014850170034006802,225.50539578660653,348.21034101266855,4.0111132183683065
1.4606018510471006e-06,0.014984596919383877,225.78627832952392,348.21034101266855,4.0111132183683065
1.5148859802898401e-06,0.015541508301660333,226.93961728132166,348.21034101266855,4.0111132183683065
1.5186297133410636e-06,0.01557991598319664,227.0185586422747,348.21034101266855,4.0111132183683065
1.5579389103789094e-06,0.015983196639327867,227.84291181578214,348.21034101266855,4.0111132183683065
1.6271979718265424e-06,0.01669373874774955,229.275871297738,348.21034101266855,4.0111132183683065
1.6534041031851062e-06,0.0169625925185037,229.81184347162818,348.21034101266855,4.0111132183683065
1.6889695671717284e-06,0.017327465493098618,230.53396481816273,348.21034101266855,4.0111132183683065
1.7207912981071277e-06,0.01765393078615723,231.17506160376712,348.21034101266855,4.0111132183683065
1.7338943637864095e-06,0.017788357671534305,231.43769676281437,348.21034101266855,4.0111132183683065
1.7619723616705852e-06,0.01807641528305661,231.9978940249752,348.21034101266855,4.0111132183683065
1.7900503595547609e-06,0.018364472894578918,232.5546203584438,348.21034101266855,4.0111132183683065
1.8667968871048408e-06,0.019151830366073215,234.05922734010235,348.21034101266855,4.0111132183683065
1.8911311519377928e-06,0.01940148029605921,234.53123461070825,348.21034101266855,4.0111132183683065
1.939799681603697e-06,0.019900780156031205,235.46820224618685,348.21034101266855,4.0111132183683065
1.960390213385426e-06,0.020112022404480897,235.8618465080795,348.21034101266855,4.0111132183683065
2.0184180756793887e-06,0.020707341468293658,236.96262504977688,348.21034101266855,4.0111132183683065
2.0277774083074476e-06,0.020803360672134428,237.13900756379584,348.21034101266855,4.0111132183683065
2.035264874409894e-06,0.020880176035207042,237.27988508166516,348.21034101266855,4.0111132183683065
2.175654863830772e-06,0.022320464092818564,239.88502749441778,348.21034101266855,4.0111132183683065
2.248657658329629e-06,0.023069413882776557,241.21373387456845,348.21034101266855,4.0111132183683065
2.317916719777262e-06,0.02377995599119824,242.4588332968882,348.21034101266855,4.0111132183683065
2.4208693786859058e-06,0.02483616723344669,244.283168471916,348.21034101266855,4.0111132183683065
2.4695379083518097e-06,0.025335467093418683,245.13502462066063,348.21034101266855,4.0111132183683065
2.4863847070823156e-06,0.025508301660332067,245.42836914866103,348.21034101266855,4.0111132183683065
2.499487772761597e-06,0.02564272854570914,245.65599042065747,348.21034101266855,4.0111132183683065
2.514462704966491e-06,0.02579635927185437,245.91555995097028,348.21034101266855,4.0111132183683065
2.5500281689531135e-06,0.02616123224644929,246.52963318332533,348.21034101266855,4.0111132183683065
2.579978033362901e-06,0.02646849369873975,247.04416108772855,348.21034101266855,4.0111132183683065
2.591209232516571e-06,0.02658371674334867,247.23650782413677,348.21034101266855,4.0111132183683065
2.6679557600666506e-06,0.02737107421484297,248.5422825336366,348.21034101266855,4.0111132183683065
2.6829306922715445e-06,0.027524704940988198,248.79535089179927,348.21034101266855,4.0111132183683065
2.742830421091119e-06,0.028139227845569114,249.80216360316473,348.21034101266855,4.0111132183683065
2.806473882961917e-06,0.028792158431686338,250.86255119572363,348.21034101266855,4.0111132183683065
2.858886145679045e-06,0.02932986597319464,251.72878723668046,348.21034101266855,4.0111132183683065
2.8738610778839385e-06,0.02948349669933987,251.97514278942077,348.21034101266855,4.0111132183683065
2.896323476191279e-06,0.029713942788557712,252.34373949228038,348.21034101266855,4.0111132183683065
2.9281452071266778e-06,0.030040408081616322,252.86401540514703,348.21034101266855,4.0111132183683065
2.9693262706901352e-06,0.030462892578515702,253.5340519691591,348.21034101266855,4.0111132183683065
2.9899168024718644e-06,0.030674134826965394,253.86771048556912,348.21034101266855,4.0111132183683065
3.016122933830428e-06,0.030942988597719545,254.29107355790129,348.21034101266855,4.0111132183683065
3.055432130868274e-06,0.03134626925385077,254.923438163135,348.21034101266855,4.0111132183683065
3.0778945291756142e-06,0.03157671534306861,255.28336471424333,348.21034101266855,4.0111132183683065
3.10597252705979e-06,0.03186477295459092,255.73183554555942,348.21034101266855,4.0111132183683065
3.135922391469577e-06,0.03217203440688138,256.20846519992193,348.21034101266855,4.0111132183683065
3.1640003893537524e-06,0.03246009201840368,256.6536956821278,348.21034101266855,4.0111132183683065
3.1976939868147634e-06,0.032805761152230446,257.18594339419417,348.21034101266855,4.0111132183683065
3.2501062495318915e-06,0.03334346869373875,258.0095573562514,348.21034101266855,4.0111132183683065
3.289415446569737e-06,0.03374674934986997,258.62387270777117,348.21034101266855,4.0111132183683065
3.3193653109795242e-06,0.03405401080216043,259.0900027068352,348.21034101266855,4.0111132183683065
3.35867450801737e-06,0.034457291458291656,259.69931667274597,348.21034101266855,4.0111132183683065
3.4073430376832745e-06,0.034956591318263654,260.44986567416777,348.21034101266855,4.0111132183683065
3.4316773025162265e-06,0.03520624124824965,260.82357145829724,348.21034101266855,4.0111132183683065
3.470986499554073e-06,0.03560952190438088,261.4250742341236,348.21034101266855,4.0111132183683065
3.5009363639638605e-06,0.03591678335667134,261.88158055267087,348.21034101266855,4.0111132183683065
3.5290143618480353e-06,0.03620484096819364,262.3081739068304,348.21034101266855,4.0111132183683065
3.547733027104152e-06,0.03639687937587517,262.59183431537457,348.21034101266855,4.0111132183683065
3.5552204932065998e-06,0.03647369473894779,262.70513497165473,348.21034101266855,4.0111132183683065
3.5945296902444452e-06,0.03687697539507902,263.2984435565475,348.21034101266855,4.0111132183683065
3.613248355500562e-06,0.03706901380276055,263.5800815923205,348.21034101266855,4.0111132183683065
3.6525575525384078e-06,0.037472294458891775,264.16967599808197,348.21034101266855,4.0111132183683065
3.661916885166466e-06,0.03756831366273254,264.3096902483296,348.21034101266855,4.0111132183683065
3.6712762177945257e-06,0.03766433286657332,264.44956500398257,348.21034101266855,4.0111132183683065
3.746150878818993e-06,0.03843248649729945,265.56359990792276,348.21034101266855,4.0111132183683065
3.824769272894685e-06,0.03923904780956192,266.72403039995197,348.21034101266855,4.0111132183683065
3.875309669086202e-06,0.03975755151030207,267.4651118204145,348.21034101266855,4.0111132183683065
3.895900200867929e-06,0.039968793758751744,267.76595209877075,348.21034101266855,4.0111132183683065
3.927721931803328e-06,0.04029525905181036,268.22967024652,348.21034101266855,4.0111132183683065
3.9501843301106695e-06,0.04052570514102821,268.5561189435412,348.21034101266855,4.0111132183683065
4.00634032587902e-06,0.04110182036407281,269.36908922164696,348.21034101266855,4.0111132183683065
4.0344183237631965e-06,0.041389877975595124,269.77390691606104,348.21034101266855,4.0111132183683065
4.04939325596809e-06,0.04154350870174035,269.98936034014235,348.21034101266855,4.0111132183683065
4.07185565427543e-06,0.04177395479095819,270.3119587599682,348.21034101266855,4.0111132183683065
4.126139783518169e-06,0.042330866173234644,271.0887195881466,348.21034101266855,4.0111132183683065
4.159833380979181e-06,0.04267653530706142,271.5688428744965,348.21034101266855,4.0111132183683065
4.172936446658463e-06,0.04281096219243849,271.7551475982436,348.21034101266855,4.0111132183683065
4.197270711491414e-06,0.043060612122424485,272.10053791150136,348.21034101266855,4.0111132183683065
4.2964796373488344e-06,0.044078415683136626,273.5006603353434,348.21034101266855,4.0111132183683065
4.318942035656176e-06,0.04430886177235448,273.81591190143996,348.21034101266855,4.0111132183683065
4.354507499642797e-06,0.044673734746949384,274.3137556141896,348.21034101266855,4.0111132183683065
4.408791628885538e-06,0.04523064612922585,275.07057581455985,348.21034101266855,4.0111132183683065
4.440613359820936e-06,0.045557111422284455,275.5125394436748,348.21034101266855,4.0111132183683065
4.45558829202583e-06,0.045710742148429684,275.7200947719323,348.21034101266855,4.0111132183683065
4.545437885255191e-06,0.04663252650530106,276.9597612216786,348.21034101266855,4.0111132183683065
4.562284683985697e-06,0.046805361072214446,277.19113088484,348.21034101266855,4.0111132183683065
4.595978281446707e-06,0.04715103020604121,277.6528730270091,348.21034101266855,4.0111132183683065
4.644646811112611e-06,0.0476503300660132,278.3175100041555,348.21034101266855,4.0111132183683065
4.659621743317505e-06,0.04780396079215843,278.52146653017985,348.21034101266855,4.0111132183683065
4.683956008150458e-06,0.048053610722144424,278.8523515142721,348.21034101266855,4.0111132183683065
4.768190001802984e-06,0.048917783556711336,279.9925812313121,348.21034101266855,4.0111132183683065
4.822474131045725e-06,0.049474694938987804,280.72323538721156,348.21034101266855,4.0111132183683065
4.858039595032346e-06,0.04983956791358271,281.20020129999926,348.21034101266855,4.0111132183683065
4.87301452723724e-06,0.04999319863972794,281.4006214180068,348.21034101266855,4.0111132183683065
4.891733192493358e-06,0.05018523704740949,281.6508091057938,348.21034101266855,4.0111132183683065
4.910451857749474e-06,0.05037727545509102,281.90062369817736,348.21034101266855,4.0111132183683065
4.936657989108039e-06,0.050646129225845174,282.2497410850887,348.21034101266855,4.0111132183683065
4.972223453094661e-06,0.051011002200440095,282.72238937381394,348.21034101266855,4.0111132183683065
4.987198385299555e-06,0.051164632926585324,282.9210045161521,348.21034101266855,4.0111132183683065
5.020891982760566e-06,0.051510302060412086,283.3670401589755,348.21034101266855,4.0111132183683065
5.095766643785033e-06,0.05227845569113823,284.3540722282412,348.21034101266855,4.0111132183683065
5.101382243361869e-06,0.052336067213442694,284.42787083111006,348.21034101266855,4.0111132183683065
5.163153838707054e-06,0.052969793958791755,285.2375754447386,348.21034101266855,4.0111132183683065
5.187488103540006e-06,0.05321944388877775,285.55551159979285,348.21034101266855,4.0111132183683065
5.269850230666922e-06,0.05406441288257652,286.6273133166062,348.21034101266855,4.0111132183683065
5.309159427704768e-06,0.05446769353870774,287.1365502229579,348.21034101266855,4.0111132183683065
5.327878092960884e-06,0.054659731946389276,287.378526974341,348.21034101266855,4.0111132183683065
5.3465967582170014e-06,0.05485177035407081,287.6201723944638,348.21034101266855,4.0111132183683065
5.404624620510965e-06,0.05544708941788358,288.367184918551,348.21034101266855,4.0111132183683065
5.442061951023198e-06,0.055831166233246646,288.8474689944589,348.21034101266855,4.0111132183683065
5.462652482804927e-06,0.05604240848169634,289.111075934076,348.21034101266855,4.0111132183683065
5.501961679842773e-06,0.05644568913782756,289.61325196640445,348.21034101266855,4.0111132183683065
5.539399010355008e-06,0.05682976595319064,290.09021555224285,348.21034101266855,4.0111132183683065
5.559989542136737e-06,0.057041008201640334,290.35200960643215,348.21034101266855,4.0111132183683065
5.580580073918465e-06,0.057252250450090025,290.61342582267605,348.21034101266855,4.0111132183683065
5.616145537905087e-06,0.05761712342468493,291.06407863219437,348.21034101266855,4.0111132183683065
5.638607936212428e-06,0.05784756951390278,291.3481280853361,348.21034101266855,4.0111132183683065
5.702251398083226e-06,0.05850050010002,292.15054821855875,348.21034101266855,4.0111132183683065
5.719098196813732e-06,0.05867333466693339,292.36236793824804,348.21034101266855,4.0111132183683065
5.730329395967401e-06,0.0587885577115423,292.5034459095328,348.21034101266855,4.0111132183683065
5.773382326056471e-06,0.059230246049209845,293.0432487424869,348.21034101266855,4.0111132183683065
5.82766645529921e-06,0.0597871574314863,293.72163730674146,348.21034101266855,4.0111132183683065
5.857616319708998e-06,0.06009441888377676,294.09486557697915,348.21034101266855,4.0111132183683065
5.883822451067562e-06,0.06036327265453091,294.4208302289551,348.21034101266855,4.0111132183683065
5.913772315477349e-06,0.06067053410682137,294.79266874260475,348.21034101266855,4.0111132183683065
5.953081512515195e-06,0.061073814762952594,295.2795941474135,348.21034101266855,4.0111132183683065
5.986775109976205e-06,0.061419483896779356,295.69596158134857,348.21034101266855,4.0111132183683065
5.994262576078653e-06,0.06149629925985198,295.7883634527958,348.21034101266855,4.0111132183683065
6.042931105744557e-06,0.06199559911982397,296.38788215058946,348.21034101266855,4.0111132183683065
6.097215234987296e-06,0.06255251050210042,297.05435896066865,348.21034101266855,4.0111132183683065
6.187064828216658e-06,0.0634742948589718,298.1524302588439,348.21034101266855,4.0111132183683065
6.27691442144602e-06,0.06439607921584317,299.2442997889231,348.21034101266855,4.0111132183683065
6.3162236184838656e-06,0.0647993598719744,299.72007413504326,348.21034101266855,4.0111132183683065
6.334942283739982e-06,0.06499139827965593,299.9462273473846,348.21034101266855,4.0111132183683065
6.374251480777828e-06,0.06539467893578715,300.4203025503356,348.21034101266855,4.0111132183683065
6.383610813405887e-06,0.06549069813962792,300.53300937915725,348.21034101266855,4.0111132183683065
6.428535610020567e-06,0.06595159031806361,301.0731076360786,348.21034101266855,4.0111132183683065
6.495922804942589e-06,0.06664292858571715,301.8805031639246,348.21034101266855,4.0111132183683065
6.5651818663902225e-06,0.06735347069413883,302.7069296977094,348.21034101266855,4.0111132183683065
6.591387997748786e-06,0.06762232446489298,303.01874407612087,348.21034101266855,4.0111132183683065
6.60636292995368e-06,0.06777595519103821,303.19670664065416,348.21034101266855,4.0111132183683065
6.613850396056127e-06,0.06785277055411083,303.2856289213863,348.21034101266855,4.0111132183683065
6.67187825835009e-06,0.06844808961792359,303.97345040217283,348.21034101266855,4.0111132183683065
6.771087184207511e-06,0.06946589317863573,305.1440234344682,348.21034101266855,4.0111132183683065
6.808524514719744e-06,0.0698499699939988,305.5840083796626,348.21034101266855,4.0111132183683065
6.851577444808814e-06,0.07029165833166634,306.0888263178795,348.21034101266855,4.0111132183683065
6.879655442692989e-06,0.07057971594318864,306.41738904545184,348.21034101266855,4.0111132183683065
6.892758508372272e-06,0.07071414282856572,306.57053930568065,348.21034101266855,4.0111132183683065
6.898374107949106e-06,0.07077175435087017,306.6361403686621,348.21034101266855,4.0111132183683065
6.937683304986953e-06,0.07117503500700141,307.09476606351166,348.21034101266855,4.0111132183683065
6.960145703294292e-06,0.07140548109621925,307.3563828594571,348.21034101266855,4.0111132183683065
6.976992502024798e-06,0.07157831566313264,307.5523794199604,348.21034101266855,4.0111132183683065
7.0013267668577506e-06,0.07182796559311863,307.835160030908,348.21034101266855,4.0111132183683065
7.020045432113867e-06,0.07202000400080016,308.05242282372103,348.21034101266855,4.0111132183683065
7.091176360087112e-06,0.07274974994999,308.87596905209597,348.21034101266855,4.0111132183683065
7.1211262244969e-06,0.07305701140228046,309.2217607906857,348.21034101266855,4.0111132183683065
7.2016164850982035e-06,0.07388277655531107,310.1482771041151,348.21034101266855,4.0111132183683065
7.257772480866553e-06,0.07445889177835567,310.7922935526655,348.21034101266855,4.0111132183683065
7.2989535444300115e-06,0.07488137627525505,311.2633378372018,348.21034101266855,4.0111132183683065
7.31954407621174e-06,0.07509261852370475,311.4984712155672,348.21034101266855,4.0111132183683065
7.33077527536541e-06,0.07520784156831367,311.6266170512529,348.21034101266855,4.0111132183683065
7.3625970063008085e-06,0.07553430686137227,311.98928177771614,348.21034101266855,4.0111132183683065
7.392546870710596e-06,0.07584156831366273,312.3300552576709,348.21034101266855,4.0111132183683065
7.452446599530171e-06,0.07645609121824365,313.0099912057594,348.21034101266855,4.0111132183683065
7.547911792336368e-06,0.07743548709741949,314.0892503015613,348.21034101266855,4.0111132183683065
7.570374190643709e-06,0.07766593318663734,314.3424183685267,348.21034101266855,4.0111132183683065
7.590964722425437e-06,0.07787717543508701,314.5742318559744,348.21034101266855,4.0111132183683065
7.617170853784001e-06,0.07814602920584117,314.8689128401712,348.21034101266855,4.0111132183683065
7.650864451245012e-06,0.07849169833966793,315.24720806167403,348.21034101266855,4.0111132183683065
7.759432709730492e-06,0.07960552110422085,316.46176320055935,348.21034101266855,4.0111132183683065
7.787510707614667e-06,0.07989357871574315,316.7747913688776,348.21034101266855,4.0111132183683065
7.80248563981956e-06,0.08004720944188838,316.9415597326987,348.21034101266855,4.0111132183683065
7.922285097458709e-06,0.08127625525105021,318.2712422410134,348.21034101266855,4.0111132183683065
7.94474749576605e-06,0.08150670134026806,318.5196822785613,348.21034101266855,4.0111132183683065
7.965338027547779e-06,0.08171794358871774,318.7471784332475,348.21034101266855,4.0111132183683065
7.991544158906342e-06,0.0819867973594719,319.03638756150553,348.21034101266855,4.0111132183683065
8.01026282416246e-06,0.08217883576715343,319.2427391055477,348.21034101266855,4.0111132183683065
8.049572021200306e-06,0.08258211642328467,319.67546621188,348.21034101266855,4.0111132183683065
8.085137485186928e-06,0.08294698939787958,320.0662715909777,348.21034101266855,4.0111132183683065
8.113215483071104e-06,0.08323504700940189,320.3743287686248,348.21034101266855,4.0111132183683065
8.124446682224773e-06,0.0833502700540108,320.49743518623114,348.21034101266855,4.0111132183683065
8.165627745788231e-06,0.08377275455091018,320.9482586638172,348.21034101266855,4.0111132183683065
8.171243345365067e-06,0.08383036607321465,321.00966581998915,348.21034101266855,4.0111132183683065
8.208680675877301e-06,0.08421444288857773,321.4186270668242,348.21034101266855,4.0111132183683065
8.266708538171264e-06,0.08480976195239048,322.0510823926902,348.21034101266855,4.0111132183683065
8.281683470376157e-06,0.08496339267853571,322.2140153150133,348.21034101266855,4.0111132183683065
8.341583199195732e-06,0.08557791558311663,322.8646012839513,348.21034101266855,4.0111132183683065
8.36217373097746e-06,0.08578915783156632,323.08781907788733,348.21034101266855,4.0111132183683065
8.397739194964083e-06,0.08615403080616124,323.4728728497543,348.21034101266855,4.0111132183683065
8.423945326322645e-06,0.08642288457691538,323.75618984170774,348.21034101266855,4.0111132183683065
8.431432792425093e-06,0.086499699939988,323.8370743918058,348.21034101266855,4.0111132183683065
8.58118211447403e-06,0.0880360072014403,325.4489291265249,348.21034101266855,4.0111132183683065
8.594285180153312e-06,0.08817043408681736,325.5894423877752,348.21034101266855,4.0111132183683065
8.644825576344828e-06,0.08868893778755751,326.1306412762725,348.21034101266855,4.0111132183683065
8.714084637792461e-06,0.0893994798959792,326.87028432569093,348.21034101266855,4.0111132183683065
8.817037296701105e-06,0.09045569113822766,327.9655307540318,348.21034101266855,4.0111132183683065
8.826396629329164e-06,0.09055171034206842,328.06485063497956,348.21034101266855,4.0111132183683065
8.832012228906e-06,0.09060932186437289,328.12442284844366,348.21034101266855,4.0111132183683065
8.86757769289262e-06,0.09097419483896779,328.50137107081963,348.21034101266855,4.0111132183683065
8.890040091199962e-06,0.09120464092818564,328.73913986987066,348.21034101266855,4.0111132183683065
8.929349288237807e-06,0.09160792158431687,329.1546722548132,348.21034101266855,4.0111132183683065
8.961171019173206e-06,0.09193438687737548,329.49053333208604,348.21034101266855,4.0111132183683065
8.983633417480546e-06,0.09216483296659332,329.7273317480285,348.21034101266855,4.0111132183683065
9.007967682313498e-06,0.09241448289657932,329.9836029387115,348.21034101266855,4.0111132183683065
9.047276879351344e-06,0.09281776355271054,330.39700987037696,348.21034101266855,4.0111132183683065
9.077226743761131e-06,0.093125025005001,330.7115165636075,348.21034101266855,4.0111132183683065
9.122151540375812e-06,0.09358591718343669,331.18251885006686,348.21034101266855,4.0111132183683065
9.159588870888046e-06,0.09396999399879977,331.57433010789947,348.21034101266855,4.0111132183683065
9.165204470464882e-06,0.09402760552110423,331.63304788486164,348.21034101266855,4.0111132183683065
9.208257400553951e-06,0.09446929385877176,332.0827523030024,348.21034101266855,4.0111132183683065
9.270028995899138e-06,0.09510302060412083,332.72655072468064,348.21034101266855,4.0111132183683065
9.27377272895036e-06,0.09514142828565714,332.76551495168934,348.21034101266855,4.0111132183683065
9.331800591244323e-06,0.0957367473494699,333.3686782024312,348.21034101266855,4.0111132183683065
9.341159923872382e-06,0.09583276655331066,333.46582544193063,348.21034101266855,4.0111132183683065
9.352391123026053e-06,0.09594798959791959,333.58235203506376,348.21034101266855,4.0111132183683065
9.37110978828217e-06,0.09614002800560112,333.77644181929793,348.21034101266855,4.0111132183683065
9.38234098743584e-06,0.09625525105021004,333.892823115314,348.21034101266855,4.0111132183683065
9.431009517101744e-06,0.09675455091018204,334.39651552137894,348.21034101266855,4.0111132183683065
9.524602843382331e-06,0.09771474294858973,335.36231463282434,348.21034101266855,4.0111132183683065
9.537705909061611e-06,0.0978491698339668,335.4972305542117,348.21034101266855,4.0111132183683065
9.577015106099456e-06,0.09825245049009802,335.90154526642704,348.21034101266855,4.0111132183683065
9.638786701444645e-06,0.0988861772354471,336.5355917759904,348.21034101266855,4.0111132183683065
9.69119896416177e-06,0.09942388477695539,337.0723288721916,348.21034101266855,4.0111132183683065
9.747354959930123e-06,0.1,337.6461495976311,348.21034101266855,4.0111132183683065