File: datasets/aisi_316_L/data/M1/train_11.csv
Time(s),Strain(%),Stress(MPa),Temp(C),Log_SR(s-1)
0.0,0.0,0.0,80.74022736268478,2.481756003174076
5.012883189446802e-08,1.52e-05,2.949596575,80.74022736268478,2.481756003174076
9.234258506875688e-08,2.8e-05,5.433467375,80.74022736268478,2.481756003174076
1.4247141696322488e-07,4.32e-05,8.38306395,80.74022736268478,2.481756003174076
1.6093993397697628e-07,4.88e-05,9.469757425000001,80.74022736268478,2.481756003174076
2.1634548501823038e-07,6.56e-05,12.72983785,80.74022736268478,2.481756003174076
2.796661147796637e-07,8.48e-05,16.45564405,80.74022736268478,2.481756003174076
3.113264296603803e-07,9.439999999999999e-05,18.318547149999997,80.74022736268478,2.481756003174076
3.95753936008958e-07,0.00011999999999999999,23.286288749999997,80.74022736268478,2.481756003174076
4.590745657703913e-07,0.0001392,27.012094949999998,80.74022736268478,2.481756003174076
4.696280040639635e-07,0.0001424,27.63306265,80.74022736268478,2.481756003174076
4.960115997978941e-07,0.0001504,29.1854819,80.74022736268478,2.481756003174076
5.382253529721829e-07,0.00016319999999999998,31.669352699999997,80.74022736268478,2.481756003174076
5.593322295593274e-07,0.0001696,32.9112881,80.74022736268478,2.481756003174076
5.830774657198648e-07,0.0001768,34.308465424999994,80.74022736268478,2.481756003174076
6.279295784675467e-07,0.0001904,36.94757815,80.74022736268478,2.481756003174076
6.886118486555869e-07,0.00020879999999999998,40.51814242499999,80.74022736268478,2.481756003174076
7.519324784170202e-07,0.00022799999999999999,44.243948624999994,80.74022736268478,2.481756003174076
7.83592793297737e-07,0.0002376,46.106851725,80.74022736268478,2.481756003174076
8.258065464720259e-07,0.0002504,48.590722525000004,80.74022736268478,2.481756003174076
8.38998344338991e-07,0.0002544,49.366932150000004,80.74022736268478,2.481756003174076
8.442750634857771e-07,0.000256,49.677416,80.74022736268478,2.481756003174076
8.548285017793494e-07,0.0002592,50.2983837,80.74022736268478,2.481756003174076
8.812120975132799e-07,0.0002672,51.850802949999995,80.74022736268478,2.481756003174076
9.445327272747131e-07,0.00028639999999999997,55.576609149999996,80.74022736268478,2.481756003174076
1.0131300761829326e-06,0.0003072,59.612899199999994,80.74022736268478,2.481756003174076
1.1450480548525851e-06,0.0003472,67.37499545,80.74022736268478,2.481756003174076
1.2611358760818795e-06,0.00038239999999999997,74.20564015,80.74022736268478,2.481756003174076
1.4642895632331448e-06,0.000444,86.159268375,80.74022736268478,2.481756003174076
1.5196951142743988e-06,0.0004608,89.4193488,80.74022736268478,2.481756003174076
1.630506216356907e-06,0.0004944,95.93950964999999,80.74022736268478,2.481756003174076
1.6674432503844097e-06,0.0005055999999999999,98.11289659999998,80.74022736268478,2.481756003174076
1.7043802844119125e-06,0.0005168,100.28628355,80.74022736268478,2.481756003174076
1.7545091163063808e-06,0.000532,103.23588012500001,80.74022736268478,2.481756003174076
1.8969805332696055e-06,0.0005752,111.618944075,80.74022736268478,2.481756003174076
1.9444710055906805e-06,0.0005896,114.413298725,80.74022736268478,2.481756003174076
2.0051532757787205e-06,0.0006079999999999999,117.98386299999999,80.74022736268478,2.481756003174076
2.068473905540154e-06,0.0006272,121.7096692,80.74022736268478,2.481756003174076
2.0869424225539056e-06,0.0006328,122.796362675,80.74022736268478,2.481756003174076
2.126517816154801e-06,0.0006448,125.12499154999999,80.74022736268478,2.481756003174076
2.213583682076772e-06,0.0006711999999999999,130.247975075,80.74022736268478,2.481756003174076
2.2373289182373097e-06,0.0006784,131.6451524,80.74022736268478,2.481756003174076
2.3481400203198175e-06,0.000712,138.16531325,80.74022736268478,2.481756003174076
2.416737369228037e-06,0.0007327999999999999,142.2016033,80.74022736268478,2.481756003174076
2.4272908075216095e-06,0.000736,142.822571,80.74022736268478,2.481756003174076
2.5275484713105453e-06,0.0007664,148.72176414999998,80.74022736268478,2.481756003174076
2.567123864911441e-06,0.0007784,151.05039302499998,80.74022736268478,2.481756003174076
2.577677303205013e-06,0.0007815999999999999,151.67136072499997,80.74022736268478,2.481756003174076
2.6436362925398394e-06,0.0008016,155.55240885,80.74022736268478,2.481756003174076
2.675296607420556e-06,0.0008112,157.41531195,80.74022736268478,2.481756003174076
2.7201487201682382e-06,0.0008248,160.054424675,80.74022736268478,2.481756003174076
2.820406383957174e-06,0.0008552,165.95361782499998,80.74022736268478,2.481756003174076
2.8441516201177114e-06,0.0008623999999999999,167.35079514999998,80.74022736268478,2.481756003174076
2.896918811585573e-06,0.0008784,170.45563365,80.74022736268478,2.481756003174076
2.9681545200671854e-06,0.0009,174.64716562499999,80.74022736268478,2.481756003174076
2.9760695987873644e-06,0.0009023999999999999,175.1128914,80.74022736268478,2.481756003174076
3.010368273241474e-06,0.0009128,177.131036425,80.74022736268478,2.481756003174076
3.0816039817230864e-06,0.0009343999999999999,181.3225684,80.74022736268478,2.481756003174076
3.0921574200166585e-06,0.0009375999999999999,181.9435361,80.74022736268478,2.481756003174076
3.121179375323982e-06,0.0009463999999999999,183.651197275,80.74022736268478,2.481756003174076
3.1633931284982715e-06,0.0009592,186.135068075,80.74022736268478,2.481756003174076
3.2187986795395252e-06,0.000976,189.3951485,80.74022736268478,2.481756003174076
3.2504589944202416e-06,0.0009855999999999999,191.2580516,80.74022736268478,2.481756003174076
3.2662891518606004e-06,0.0009904,192.18950315,80.74022736268478,2.481756003174076
3.2847576688743515e-06,0.000996,193.27619662499998,80.74022736268478,2.481756003174076
3.311141264608282e-06,0.001004,194.82861587499997,80.74022736268478,2.481756003174076
3.3401632199156057e-06,0.0010128,196.53627704999997,80.74022736268478,2.481756003174076
3.4008454901036457e-06,0.0010312,200.10684132499998,80.74022736268478,2.481756003174076
3.479996277305437e-06,0.0010551999999999998,204.76409907499996,80.74022736268478,2.481756003174076
3.498464794319189e-06,0.0010608,205.85079255,80.74022736268478,2.481756003174076
3.588169019814553e-06,0.001088,211.129018,80.74022736268478,2.481756003174076
3.6145526155484833e-06,0.001096,212.68143725,80.74022736268478,2.481756003174076
3.6541280091493795e-06,0.001108,215.010066125,80.74022736268478,2.481756003174076
3.743832234644743e-06,0.0011352,220.28829157500002,80.74022736268478,2.481756003174076
3.852004977153858e-06,0.001168,226.6532105,80.74022736268478,2.481756003174076
3.89685708990154e-06,0.0011815999999999999,229.292323225,80.74022736268478,2.481756003174076
3.9074105281951125e-06,0.0011848,229.91329092499998,80.74022736268478,2.481756003174076
3.9443475622226155e-06,0.001196,232.086677875,80.74022736268478,2.481756003174076
4.0261367089978e-06,0.0012208,236.89917755,80.74022736268478,2.481756003174076
4.041966866438158e-06,0.0012255999999999999,237.83062909999998,80.74022736268478,2.481756003174076
4.078903900465661e-06,0.0012368,240.00401605,80.74022736268478,2.481756003174076
4.1263943727867355e-06,0.0012511999999999998,242.79837069999996,80.74022736268478,2.481756003174076
4.189715002548169e-06,0.0012703999999999999,246.5241769,80.74022736268478,2.481756003174076
4.250397272736209e-06,0.0012887999999999999,250.09474117499997,80.74022736268478,2.481756003174076
4.289972666337105e-06,0.0013008,252.42337005,80.74022736268478,2.481756003174076
4.340101498231573e-06,0.001316,255.37296662499998,80.74022736268478,2.481756003174076
4.355931655671931e-06,0.0013208,256.304418175,80.74022736268478,2.481756003174076
4.387591970552648e-06,0.0013304,258.167321275,80.74022736268478,2.481756003174076
4.479934555621405e-06,0.0013583999999999998,263.60078864999997,80.74022736268478,2.481756003174076
4.508956510928728e-06,0.0013671999999999998,265.30844982499997,80.74022736268478,2.481756003174076
4.56172370239659e-06,0.0013832,268.413288325,80.74022736268478,2.481756003174076
4.62240597258463e-06,0.0014016,271.9838526,80.74022736268478,2.481756003174076
4.672534804479098e-06,0.0014168,274.93344917499996,80.74022736268478,2.481756003174076
4.677811523625884e-06,0.0014184,275.243933025,80.74022736268478,2.481756003174076
4.751685591680889e-06,0.0014408,276.42755265636464,80.74022736268478,2.481756003174076
4.775430827841427e-06,0.0014479999999999999,276.48288400643304,80.74022736268478,2.481756003174076
4.8281980193092885e-06,0.001464,276.605459845541,80.74022736268478,2.481756003174076
4.857219974616612e-06,0.0014728,276.6726538249297,80.74022736268478,2.481756003174076
4.9047104469376865e-06,0.0014872,276.7822708460195,80.74022736268478,2.481756003174076
4.923178963951438e-06,0.0014927999999999999,276.8247878021319,80.74022736268478,2.481756003174076
4.96803107669912e-06,0.0015064,276.9277851259912,80.74022736268478,2.481756003174076
5.0471818639009115e-06,0.0015304,277.1086647807365,80.74022736268478,2.481756003174076
5.065650380914663e-06,0.001536,277.150710449603,80.74022736268478,2.481756003174076
5.110502493662344e-06,0.0015496,277.25257323762344,80.74022736268478,2.481756003174076
5.126332651102702e-06,0.0015543999999999998,277.2884414890623,80.74022736268478,2.481756003174076
5.147439527689847e-06,0.0015608,277.336198701299,80.74022736268478,2.481756003174076
5.205483438304495e-06,0.0015784,277.4671388527847,80.74022736268478,2.481756003174076
5.268804068065928e-06,0.0015976,277.60933492895026,80.74022736268478,2.481756003174076
5.30574110209343e-06,0.0016087999999999999,277.69197485896416,80.74022736268478,2.481756003174076
5.3268479786805755e-06,0.0016152,277.73909693415425,80.74022736268478,2.481756003174076
5.3796151701484365e-06,0.0016312,277.8565846570208,80.74022736268478,2.481756003174076
5.413913844602546e-06,0.0016416,277.93271074031753,80.74022736268478,2.481756003174076
5.474596114790586e-06,0.00166,278.0669361833736,80.74022736268478,2.481756003174076
5.527363306258447e-06,0.001676,278.183183000642,80.74022736268478,2.481756003174076
5.5537469019923775e-06,0.001684,278.2411440491874,80.74022736268478,2.481756003174076
5.601237374313452e-06,0.0016983999999999999,278.3452040461611,80.74022736268478,2.481756003174076
5.661919644501492e-06,0.0017167999999999999,278.47767022507117,80.74022736268478,2.481756003174076
5.677749801941851e-06,0.0017216,278.5121354137839,80.74022736268478,2.481756003174076
5.688303240235423e-06,0.0017247999999999999,278.53509138854275,80.74022736268478,2.481756003174076
5.709410116822568e-06,0.0017312,278.5809535685509,80.74022736268478,2.481756003174076
5.8254979380518624e-06,0.0017664,278.83202345457215,80.74022736268478,2.481756003174076
5.8940952869600814e-06,0.0017871999999999999,278.9794658202637,80.74022736268478,2.481756003174076
6.047120142216878e-06,0.0018336,279.3059852261765,80.74022736268478,2.481756003174076
6.0972489741113465e-06,0.0018487999999999998,279.41224564506365,80.74022736268478,2.481756003174076
6.223890233634213e-06,0.0018872,279.6791864918263,80.74022736268478,2.481756003174076
6.303041020836004e-06,0.0019111999999999998,279.84494921720017,80.74022736268478,2.481756003174076
6.337339695290115e-06,0.0019215999999999999,279.9165274000629,80.74022736268478,2.481756003174076
6.379553448464403e-06,0.0019344,280.0044165581784,80.74022736268478,2.481756003174076
6.416490482491906e-06,0.0019456,280.081133683132,80.74022736268478,2.481756003174076
6.477172752679947e-06,0.001964,280.20679610548956,80.74022736268478,2.481756003174076
6.6117290909229915e-06,0.0020047999999999997,280.4838125550987,80.74022736268478,2.481756003174076
6.651304484523888e-06,0.0020168,280.5648684075365,80.74022736268478,2.481756003174076
6.690879878124784e-06,0.0020288,280.6457363859828,80.74022736268478,2.481756003174076
6.772669024899969e-06,0.0020536,280.81227479236765,80.74022736268478,2.481756003174076
6.780584103620148e-06,0.002056,280.8283496735593,80.74022736268478,2.481756003174076
6.899310284422835e-06,0.002092,281.06860149396294,80.74022736268478,2.481756003174076
7.007483026931951e-06,0.0021248,281.28609745120707,80.74022736268478,2.481756003174076
7.065526937546597e-06,0.0021424,281.4022626147542,80.74022736268478,2.481756003174076
7.105102331147493e-06,0.0021544,281.4812528286733,80.74022736268478,2.481756003174076
7.149954443895174e-06,0.002168,281.57056793237035,80.74022736268478,2.481756003174076
7.1842531183492854e-06,0.0021784,281.6387203593764,80.74022736268478,2.481756003174076
7.247573748110718e-06,0.0021976,281.764207774679,80.74022736268478,2.481756003174076
7.3135327374455436e-06,0.0022175999999999997,281.89447000039115,80.74022736268478,2.481756003174076
7.3214478161657226e-06,0.0022199999999999998,281.91007061885966,80.74022736268478,2.481756003174076
7.424343839528053e-06,0.0022512,282.1122837943333,80.74022736268478,2.481756003174076
7.503494626729843e-06,0.0022752,282.26708952884877,80.74022736268478,2.481756003174076
7.532516582037168e-06,0.002284,282.3236918953936,80.74022736268478,2.481756003174076
7.580007054358243e-06,0.0022984,282.41613083464614,80.74022736268478,2.481756003174076
7.611667369238959e-06,0.0023079999999999997,282.47763134265375,80.74022736268478,2.481756003174076
7.672349639427e-06,0.0023263999999999997,282.5952291739628,80.74022736268478,2.481756003174076
7.73303190961504e-06,0.0023447999999999997,282.71246481805576,80.74022736268478,2.481756003174076
7.762053864922364e-06,0.0023536,282.76840716170784,80.74022736268478,2.481756003174076
7.79371417980308e-06,0.0023631999999999998,282.8293422195463,80.74022736268478,2.481756003174076
7.862311528711299e-06,0.002384,282.96103797994016,80.74022736268478,2.481756003174076
7.936185596766305e-06,0.0024064,283.102364031261,80.74022736268478,2.481756003174076
7.970484271220414e-06,0.0024167999999999998,283.167805209247,80.74022736268478,2.481756003174076
7.986314428660772e-06,0.0024216,283.1979717789209,80.74022736268478,2.481756003174076
8.076018654156137e-06,0.0024487999999999997,283.3684772284764,80.74022736268478,2.481756003174076
8.094487171169888e-06,0.0024544,283.40348942626315,80.74022736268478,2.481756003174076
8.131424205197391e-06,0.0024656,283.47342049704,80.74022736268478,2.481756003174076
8.205298273252395e-06,0.0024879999999999998,283.6129120786197,80.74022736268478,2.481756003174076
8.236958588133113e-06,0.0024976,283.67254415372724,80.74022736268478,2.481756003174076
8.271257262587223e-06,0.002508,283.7370447835763,80.74022736268478,2.481756003174076
8.28708742002758e-06,0.0025128,283.76677911486934,80.74022736268478,2.481756003174076
8.355684768935801e-06,0.0025336,283.89537275550344,80.74022736268478,2.481756003174076
8.543008298646708e-06,0.0025904,284.244451931816,80.74022736268478,2.481756003174076
8.645904322009037e-06,0.0026216,284.43492896746005,80.74022736268478,2.481756003174076
8.764630502811723e-06,0.0026576,284.6536150287674,80.74022736268478,2.481756003174076
8.846419649586908e-06,0.0026823999999999997,284.80359379585997,80.74022736268478,2.481756003174076
8.917655358068521e-06,0.002704,284.9337803913184,80.74022736268478,2.481756003174076
8.941400594229058e-06,0.0027112,284.97708571136656,80.74022736268478,2.481756003174076
9.025828100577635e-06,0.0027367999999999997,285.130698263766,80.74022736268478,2.481756003174076
9.041658258017995e-06,0.0027416,285.1594381239923,80.74022736268478,2.481756003174076
9.073318572898712e-06,0.0027512,285.2168590402981,80.74022736268478,2.481756003174076
9.110255606926214e-06,0.0027624,285.2837514401427,80.74022736268478,2.481756003174076
9.168299517540862e-06,0.00278,285.38865476133594,80.74022736268478,2.481756003174076
9.21051327071515e-06,0.0027928,285.4647854696779,80.74022736268478,2.481756003174076
9.292302417490335e-06,0.0028176,285.6119025839904,80.74022736268478,2.481756003174076
9.437412194026952e-06,0.0028615999999999997,285.8716799927228,80.74022736268478,2.481756003174076
9.46907250890767e-06,0.0028712,285.9281511433623,80.74022736268478,2.481756003174076
9.558776734403032e-06,0.0028983999999999998,286.08775423267326,80.74022736268478,2.481756003174076
9.56405345354982e-06,0.0029,286.0971244171441,80.74022736268478,2.481756003174076
9.593075408857143e-06,0.0029088,286.148624437319,80.74022736268478,2.481756003174076
9.635289162031432e-06,0.0029216,286.2234252203409,80.74022736268478,2.481756003174076
9.653757679045183e-06,0.0029272,286.2561103614731,80.74022736268478,2.481756003174076
9.754015342834118e-06,0.0029576,286.4331202819712,80.74022736268478,2.481756003174076
9.769845500274478e-06,0.0029624,286.4610042219854,80.74022736268478,2.481756003174076
9.825251051315731e-06,0.0029792,286.55845955445244,80.74022736268478,2.481756003174076
9.838442849182695e-06,0.0029831999999999997,286.58163158642236,80.74022736268478,2.481756003174076
9.878018242783592e-06,0.0029952,286.6510750875262,80.74022736268478,2.481756003174076
9.972999187425741e-06,0.0030239999999999998,286.8172982751753,80.74022736268478,2.481756003174076
1.0046873255480747e-05,0.0030464,286.94615650003993,80.74022736268478,2.481756003174076
1.0078533570361463e-05,0.0030559999999999997,287.0012682765442,80.74022736268478,2.481756003174076
1.015240763841647e-05,0.0030784,287.12960051459015,80.74022736268478,2.481756003174076
1.0189344672443973e-05,0.0030896,287.19363002659685,80.74022736268478,2.481756003174076
1.0294879055379695e-05,0.0031216,287.37607458378443,80.74022736268478,2.481756003174076
1.0334454448980591e-05,0.0031336,287.4443030588362,80.74022736268478,2.481756003174076
1.0400413438315417e-05,0.0031536,287.55779117771027,80.74022736268478,2.481756003174076
1.0474287506370423e-05,0.003176,287.6845651528745,80.74022736268478,2.481756003174076
1.0516501259544711e-05,0.0031888,287.75685085663855,80.74022736268478,2.481756003174076
1.0595652046746503e-05,0.0032128,287.8920822762688,80.74022736268478,2.481756003174076
1.0637865799920791e-05,0.0032256,287.9640445811028,80.74022736268478,2.481756003174076
1.0656334316934544e-05,0.0032312,287.99549305957134,80.74022736268478,2.481756003174076
1.0674802833948294e-05,0.0032367999999999997,288.026920288872,80.74022736268478,2.481756003174076
1.0753953621150086e-05,0.0032608,288.16136894330555,80.74022736268478,2.481756003174076
1.0782975576457408e-05,0.0032695999999999997,288.2105700158416,80.74022736268478,2.481756003174076
1.0811997531764734e-05,0.0032784,288.2597194705245,80.74022736268478,2.481756003174076
1.0822550970058307e-05,0.0032816,288.277579239325,80.74022736268478,2.481756003174076
1.0859488004085808e-05,0.0032928,288.340035012694,80.74022736268478,2.481756003174076
1.090434011683349e-05,0.0033063999999999997,288.4157628953075,80.74022736268478,2.481756003174076
1.0996682701902248e-05,0.0033344,288.5712918004699,80.74022736268478,2.481756003174076
1.1012512859342604e-05,0.0033391999999999996,288.5979026741022,80.74022736268478,2.481756003174076
1.1091663646544397e-05,0.0033632,288.7307339221835,80.74022736268478,2.481756003174076
1.1107493803984755e-05,0.003368,288.7572557546052,80.74022736268478,2.481756003174076
1.1123323961425115e-05,0.0033728,288.7837628497658,80.74022736268478,2.481756003174076
1.1149707557159044e-05,0.0033807999999999998,288.8279086713455,80.74022736268478,2.481756003174076
1.1178729512466368e-05,0.0033896,288.87642204678514,80.74022736268478,2.481756003174076
1.1278987176255304e-05,0.00342,289.0436370660074,80.74022736268478,2.481756003174076
1.1366053042177273e-05,0.0034463999999999996,289.18838037616024,80.74022736268478,2.481756003174076
1.1402990076204778e-05,0.0034576,289.2496559183729,80.74022736268478,2.481756003174076
1.1461033986819424e-05,0.0034752,289.3457898891323,80.74022736268478,2.481756003174076
1.1484779222979961e-05,0.0034823999999999996,289.3850626734448,80.74022736268478,2.481756003174076
1.1558653291034967e-05,0.0035047999999999998,289.5070426444412,80.74022736268478,2.481756003174076
1.1592951965489078e-05,0.0035152,289.56357281475726,80.74022736268478,2.481756003174076
1.1598228684635864e-05,0.0035168,289.5722639712665,80.74022736268478,2.481756003174076
1.1701124707998192e-05,0.003548,289.7414345174813,80.74022736268478,2.481756003174076
1.1748615180319268e-05,0.0035624,289.819317454809,80.74022736268478,2.481756003174076
1.182776596752106e-05,0.0035864,289.9488500595759,80.74022736268478,2.481756003174076
1.1856787922828382e-05,0.0035952,289.9962605885111,80.74022736268478,2.481756003174076
1.190691675472285e-05,0.0036103999999999997,290.0780450402037,80.74022736268478,2.481756003174076
1.1935938710030175e-05,0.0036192,290.12533255688476,80.74022736268478,2.481756003174076
1.1978152463204464e-05,0.003632,290.19403443022907,80.74022736268478,2.481756003174076
1.2004536058938394e-05,0.00364,290.23692515325035,80.74022736268478,2.481756003174076
1.2067856688699828e-05,0.0036592,290.33971317071325,80.74022736268478,2.481756003174076
1.2154922554621798e-05,0.0036856,290.4807039094377,80.74022736268478,2.481756003174076
1.2186582869502514e-05,0.0036952,290.5318755453397,80.74022736268478,2.481756003174076
1.228684053329145e-05,0.0037256,290.69357807008873,80.74022736268478,2.481756003174076
1.2302670690731809e-05,0.0037304,290.71906293261037,80.74022736268478,2.481756003174076
1.2318500848172167e-05,0.0037351999999999997,290.7445350094495,80.74022736268478,2.481756003174076
1.2358076241773063e-05,0.0037472,290.80815941385384,80.74022736268478,2.481756003174076
1.2392374916227173e-05,0.0037576,290.8632363152358,80.74022736268478,2.481756003174076
1.2474164063002358e-05,0.0037824,290.9943341813345,80.74022736268478,2.481756003174076
1.2521654535323432e-05,0.0037968,291.07030168626096,80.74022736268478,2.481756003174076
1.2545399771483969e-05,0.0038039999999999997,291.1082432953225,80.74022736268478,2.481756003174076
1.2613997120392188e-05,0.0038247999999999997,291.2176953804186,80.74022736268478,2.481756003174076
1.265884923313987e-05,0.0038383999999999996,291.28913471681074,80.74022736268478,2.481756003174076
1.278812885223613e-05,0.0038775999999999997,291.49449783814947,80.74022736268478,2.481756003174076
1.2909493392612212e-05,0.0039144,291.68655209957075,80.74022736268478,2.481756003174076
1.297545238194704e-05,0.0039344,291.7906340256006,80.74022736268478,2.481756003174076
1.3044049730855257e-05,0.0039552,291.8986605754199,80.74022736268478,2.481756003174076
1.3117923798910261e-05,0.0039775999999999995,292.01474937929385,80.74022736268478,2.481756003174076
1.3141669035070801e-05,0.0039848,292.0520094533921,80.74022736268478,2.481756003174076
1.3173329349951516e-05,0.0039943999999999995,292.1016487347228,80.74022736268478,2.481756003174076
1.3825130831172443e-05,0.0041920384076815365,293.1134739864765,80.74022736268478,2.481756003174076
1.5345129945269663e-05,0.004652930586117224,295.4033541931584,80.74022736268478,2.481756003174076
1.6801795762946162e-05,0.005094618923784757,297.5160923458255,80.74022736268478,2.481756003174076
1.882846124840912e-05,0.005709141828365673,300.34025225072367,80.74022736268478,2.481756003174076
2.0411793658927056e-05,0.006189237847569514,302.46481771613855,80.74022736268478,2.481756003174076
2.0981793326713514e-05,0.006362072414482897,303.21379328828283,80.74022736268478,2.481756003174076
2.2375125847969295e-05,0.006784556911382277,305.01196861679523,80.74022736268478,2.481756003174076
2.2628459033652165e-05,0.006861372274454891,305.3341618827009,80.74022736268478,2.481756003174076
2.5035124297639425e-05,0.007591118223644729,308.3278911026032,80.74022736268478,2.481756003174076
2.5541790669005168e-05,0.007744748949789958,308.9435981314303,80.74022736268478,2.481756003174076
2.5858457151108752e-05,0.007840768153630726,309.3259970522068,80.74022736268478,2.481756003174076
2.7315122968785255e-05,0.00828245649129826,311.06202809400645,80.74022736268478,2.481756003174076
2.8645122193620322e-05,0.008685737147429486,312.61580983506167,80.74022736268478,2.481756003174076
2.9088455268565343e-05,0.008820164032806561,313.1274502565391,80.74022736268478,2.481756003174076
3.041845449340041e-05,0.009223444688937788,314.6444280088905,80.74022736268478,2.481756003174076
3.345845272159485e-05,0.010145229045809162,318.0178266618222,80.74022736268478,2.481756003174076
3.58651179855821e-05,0.010874974994998999,320.6043055946115,80.74022736268478,2.481756003174076
3.7131783913996454e-05,0.011259051810362072,321.93836350385124,80.74022736268478,2.481756003174076
3.966511577082515e-05,0.012027205441088217,324.55437871715867,80.74022736268478,2.481756003174076
4.1818447849129545e-05,0.01268013602720544,326.727133018798,80.74022736268478,2.481756003174076
4.245178081333672e-05,0.012872174434886977,327.35781567262336,80.74022736268478,2.481756003174076
4.428844640953752e-05,0.013429085817163433,329.16636839641524,80.74022736268478,2.481756003174076
4.618844530215905e-05,0.014005201040208042,331.00676094611856,80.74022736268478,2.481756003174076
4.7391777934152684e-05,0.014370074014802961,332.1570841934663,80.74022736268478,2.481756003174076
5.049510945876784e-05,0.01531106221244249,335.0723258938933,80.74022736268478,2.481756003174076
5.0748442644450705e-05,0.015387877575515104,335.3071748091053,80.74022736268478,2.481756003174076
5.252177494423079e-05,0.015925585117023404,336.9385013957562,80.74022736268478,2.481756003174076
5.359844098338299e-05,0.016252050410082017,337.91847254281555,80.74022736268478,2.481756003174076
5.518177339390092e-05,0.016732146429285857,339.34577316309196,80.74022736268478,2.481756003174076
5.6258439433053126e-05,0.01705861172234447,340.3072256510275,80.74022736268478,2.481756003174076
5.758843865788819e-05,0.017461892378475695,341.4850513022429,80.74022736268478,2.481756003174076
5.847510480777823e-05,0.017730746149229846,342.2643797885921,80.74022736268478,2.481756003174076
6.316176874291132e-05,0.019151830366073215,346.30954396887455,80.74022736268478,2.481756003174076
6.626510026752648e-05,0.02009281856371274,348.9238155830806,80.74022736268478,2.481756003174076
6.708843312099581e-05,0.02034246849369874,349.60932698020827,80.74022736268478,2.481756003174076
6.784843267804441e-05,0.020572914582916584,350.239200204267,80.74022736268478,2.481756003174076
6.822843245656872e-05,0.020688137627525506,350.55310451398447,80.74022736268478,2.481756003174076
7.202843024181176e-05,0.021840368073614724,353.65552922493816,80.74022736268478,2.481756003174076
7.43717622093783e-05,0.022550910182036407,355.53689020642764,80.74022736268478,2.481756003174076
7.50684284700062e-05,0.0227621524304861,356.0917366978645,80.74022736268478,2.481756003174076
7.817175999462135e-05,0.023703140628125625,358.5393253330536,80.74022736268478,2.481756003174076
7.950175921945641e-05,0.02410642128425685,359.57665731345656,80.74022736268478,2.481756003174076
8.133842481565722e-05,0.024663332666533307,360.99810484325343,80.74022736268478,2.481756003174076
8.311175711543732e-05,0.02520104020804161,362.35870586201725,80.74022736268478,2.481756003174076
8.653175512215605e-05,0.026238047609521906,364.9511641488909,80.74022736268478,2.481756003174076
8.710175478994251e-05,0.026410882176435287,365.3793254852678,80.74022736268478,2.481756003174076
8.855842060761902e-05,0.026852570514102822,366.4685804295413,80.74022736268478,2.481756003174076
8.963508664677121e-05,0.027179035807161432,367.2691961613717,80.74022736268478,2.481756003174076
9.071175268592341e-05,0.027505501100220046,368.06607003513335,80.74022736268478,2.481756003174076
9.109175246444771e-05,0.027620724144828968,368.34643783962224,80.74022736268478,2.481756003174076
9.147175224297202e-05,0.02773594718943789,368.62634987456534,80.74022736268478,2.481756003174076
9.261175157854494e-05,0.028081616323264655,369.46337752963734,80.74022736268478,2.481756003174076
9.43217505819043e-05,0.0286001200240048,370.71142372137734,80.74022736268478,2.481756003174076
9.476508365684932e-05,0.028734546909381875,371.03354688045437,80.74022736268478,2.481756003174076
9.558841651031865e-05,0.028984196839367874,371.63022064915896,80.74022736268478,2.481756003174076
9.717174892083658e-05,0.029464292858571713,372.7720665843233,80.74022736268478,2.481756003174076
0.00010078174681681748,0.030558911782356472,375.3486835718046,80.74022736268478,2.481756003174076
0.00010204841274523183,0.030942988597719545,376.24419562502777,80.74022736268478,2.481756003174076
0.00010299841219154258,0.031231046209241848,376.91298753277033,80.74022736268478,2.481756003174076
0.00010318841208080473,0.03128865773154631,377.0464567552714,80.74022736268478,2.481756003174076
0.00010401174493427405,0.0315383076615323,377.62371937756916,80.74022736268478,2.481756003174076
0.00010546841075195059,0.031979995999199845,378.6406834360243,80.74022736268478,2.481756003174076
0.0001073684096445721,0.03255611122224445,379.95896367415924,80.74022736268478,2.481756003174076
0.0001081284092016207,0.032786557311462294,380.4837244851876,80.74022736268478,2.481756003174076
0.00010869840886940716,0.032959391878375675,380.87635161858464,80.74022736268478,2.481756003174076
0.00010914174194435218,0.03309381876375275,381.181173407495,80.74022736268478,2.481756003174076
0.00010964840831571792,0.03324744948989798,381.52895049470567,80.74022736268478,2.481756003174076
0.00011002840809424223,0.03336267253450691,381.78937216311107,80.74022736268478,2.481756003174076
0.00011123174072623585,0.03372754550910182,382.61173620188816,80.74022736268478,2.481756003174076
0.00011218174017254661,0.03401560312062413,383.25852264672636,80.74022736268478,2.481756003174076
0.00011268840654391236,0.034169233846769356,383.60260181536444,80.74022736268478,2.481756003174076
0.00011382840587948526,0.03451490298059612,384.37458159317606,80.74022736268478,2.481756003174076
0.00011465173873295458,0.034764552910582114,384.9302485319442,80.74022736268478,2.481756003174076
0.00011629840443989323,0.035263852770554105,386.0369355820037,80.74022736268478,2.481756003174076
0.00011648840432915539,0.03532146429285857,386.16423579055083,80.74022736268478,2.481756003174076
0.00011693173740410044,0.03545589117823565,386.4609551144566,80.74022736268478,2.481756003174076
0.0001180084034432526,0.035782356471294255,387.1797384918811,80.74022736268478,2.481756003174076
0.00011927506937166698,0.036166433286657335,388.02209976060595,80.74022736268478,2.481756003174076
0.00012016173552155703,0.03643528705741149,388.60967801777383,80.74022736268478,2.481756003174076
0.00012218840100701998,0.037049809961992405,389.9464010922836,80.74022736268478,2.481756003174076
0.00012288506726764785,0.03726105221044208,390.40389892780837,80.74022736268478,2.481756003174076
0.00012370840012111722,0.03751070214042809,390.9432761169992,80.74022736268478,2.481756003174076
0.00012541839912447655,0.03802920584116823,392.05906809655664,80.74022736268478,2.481756003174076
0.00012567173231015942,0.03810602120424085,392.2238646282815,80.74022736268478,2.481756003174076
0.00012668506505289091,0.03841328265653131,392.8817592860017,80.74022736268478,2.481756003174076
0.0001271283981278359,0.03854770954190838,393.1689424933929,80.74022736268478,2.481756003174076
0.0001278250643884638,0.03875895179035807,393.61944251772485,80.74022736268478,2.481756003174076
0.00012921839690971962,0.039181436287257454,394.5175801055905,80.74022736268478,2.481756003174076
0.0001310550625059204,0.03973834766953391,395.6957390757685,80.74022736268478,2.481756003174076
0.00013213172854507262,0.040064812962592525,396.38339023690895,80.74022736268478,2.481756003174076
0.00013422172732695627,0.040698539707941586,397.7120359852116,80.74022736268478,2.481756003174076
0.0001358683930338949,0.04119783956791358,398.7531732984294,80.74022736268478,2.481756003174076
0.00013738839214799212,0.041658731746349265,399.70986362087075,80.74022736268478,2.481756003174076
0.0001386550580764065,0.042042808561712344,400.5039563413735,80.74022736268478,2.481756003174076
0.000140111723894083,0.04248449689937987,401.4136737513878,80.74022736268478,2.481756003174076
0.00014099839004397304,0.04275335067013403,401.9656090876669,80.74022736268478,2.481756003174076
0.00014125172322965594,0.04283016603320665,402.12305605921546,80.74022736268478,2.481756003174076
0.00014182172289744236,0.04300300060012002,402.476909647795,80.74022736268478,2.481756003174076
0.00014391172167932607,0.0436367273454691,403.7696544986695,80.74022736268478,2.481756003174076
0.00014505172101489895,0.04398239647929586,404.4717011642829,80.74022736268478,2.481756003174076
0.00014581172057194755,0.0442128425685137,404.9385371728485,80.74022736268478,2.481756003174076
0.00014701505320394119,0.04457771554310862,405.6757581013109,80.74022736268478,2.481756003174076
0.0001478383860574105,0.04482736547309461,406.1788170030742,80.74022736268478,2.481756003174076
0.00014834505242877625,0.04498099619923984,406.4878486799897,80.74022736268478,2.481756003174076
0.00014973838495003204,0.045403480696139226,407.3355705268482,80.74022736268478,2.481756003174076
0.00015068838439634283,0.04569153830766154,407.91179962318006,80.74022736268478,2.481756003174076
0.00015157505054623285,0.04596039207841568,408.4483365055305,80.74022736268478,2.481756003174076
0.0001525883832889643,0.04626765353070614,409.06002496162137,80.74022736268478,2.481756003174076
0.0001535383827352751,0.04655571114222845,409.63204563623225,80.74022736268478,2.481756003174076
0.00015391838251379938,0.04667093418683736,409.8604672138326,80.74022736268478,2.481756003174076
0.00015480504866368944,0.04693978795759152,410.39259730165395,80.74022736268478,2.481756003174076
0.0001552483817386345,0.0470742148429686,410.658216503061,80.74022736268478,2.481756003174076
0.00015543838162789659,0.04713182636527305,410.77196272848823,80.74022736268478,2.481756003174076
0.00015759171370620102,0.047784756951390284,412.0573198102939,80.74022736268478,2.481756003174076
0.00015841504655967034,0.04803440688137628,412.5469674104394,80.74022736268478,2.481756003174076
0.0001607583785272369,0.04874494898979796,413.9351769167194,80.74022736268478,2.481756003174076
0.0001620250444556512,0.04912902580516103,414.6822736205283,80.74022736268478,2.481756003174076
0.00016253171082701695,0.04928265653130626,414.98047409165787,80.74022736268478,2.481756003174076
0.00016386171005185201,0.04968593718743748,415.76153049832004,80.74022736268478,2.481756003174076
0.00016436837642321776,0.04983956791358271,416.0584249671815,80.74022736268478,2.481756003174076
0.00016563504235163213,0.05022364472894579,416.79910387890317,80.74022736268478,2.481756003174076
0.0001659517088337357,0.05031966393278656,416.98392803897866,80.74022736268478,2.481756003174076
0.00016677504168720504,0.05056931386277255,417.46382829275143,80.74022736268478,2.481756003174076
0.00016747170794783293,0.050780556111222244,417.86917649175996,80.74022736268478,2.481756003174076
0.00016835837409772298,0.0510494098819764,418.3841243595304,80.74022736268478,2.481756003174076
0.00017044837287960663,0.05168313662732546,419.5937632209225,80.74022736268478,2.481756003174076
0.00017190503869728317,0.052124824964993,420.4334262402136,80.74022736268478,2.481756003174076
0.00017310837132927679,0.05248969793958792,421.12496996543103,80.74022736268478,2.481756003174076
0.00017393170418274613,0.05273934786957392,421.59705161054427,80.74022736268478,2.481756003174076
0.0001746917037397947,0.052969793958791755,422.0320463227061,80.74022736268478,2.481756003174076
0.00017532503670400192,0.0531618323664733,422.3939784100311,80.74022736268478,2.481756003174076
0.0001759583696682091,0.053353870774154835,422.75540096109785,80.74022736268478,2.481756003174076
0.00017627503615031266,0.0534498899779956,422.9359219574744,80.74022736268478,2.481756003174076
0.00017728836889304415,0.05375715143028606,423.5127410835524,80.74022736268478,2.481756003174076
0.000177541702078727,0.05383396679335867,423.6567447817758,80.74022736268478,2.481756003174076
0.00017880836800714136,0.05421804360872175,424.3755647249078,80.74022736268478,2.481756003174076
0.0001796950341570314,0.0544868973794759,424.87755753073617,80.74022736268478,2.481756003174076
0.0001822916993102808,0.05527425485097019,426.34215182530266,80.74022736268478,2.481756003174076
0.0001836850318315366,0.055696739347869575,427.12467641243296,80.74022736268478,2.481756003174076
0.00018577503061342028,0.05633046609321865,428.2941366715578,80.74022736268478,2.481756003174076
0.00018824502917382825,0.05707941588317664,429.6696313243728,80.74022736268478,2.481756003174076
0.00018957502839866332,0.05748269653930786,430.4073660465276,80.74022736268478,2.481756003174076
0.000191665027180547,0.05811642328465694,431.56259826362526,80.74022736268478,2.481756003174076
0.00019362835936958923,0.058711742348469695,432.643349158285,80.74022736268478,2.481756003174076
0.00019502169189084502,0.05913422684536908,433.4077424692534,80.74022736268478,2.481756003174076
0.00019559169155863146,0.05930706141228245,433.7198345967489,80.74022736268478,2.481756003174076
0.00019711169067272868,0.05976795359071814,434.55035100401346,80.74022736268478,2.481756003174076
0.00019844168989756374,0.060171234246849364,435.2750060929641,80.74022736268478,2.481756003174076
0.00020274835405417255,0.06147709541908382,437.60861715335903,80.74022736268478,2.481756003174076
0.00020306502053627612,0.061573114622924585,437.77943936743986,80.74022736268478,2.481756003174076
0.00020483835283605624,0.062110822164432894,438.7341307982898,80.74022736268478,2.481756003174076
0.0002059150188752084,0.0624372874574915,439.3121924304619,80.74022736268478,2.481756003174076
0.00020648501854299487,0.06261012202440489,439.6177477790573,80.74022736268478,2.481756003174076
0.0002088916838069821,0.06333986797359471,440.9042604821398,80.74022736268478,2.481756003174076
0.00020971501666045147,0.06358951790358072,441.34305449468275,80.74022736268478,2.481756003174076
0.00021104501588528653,0.06399279855971195,442.0504590251438,80.74022736268478,2.481756003174076
0.0002128183481850666,0.06453050610122024,442.9909664360055,80.74022736268478,2.481756003174076
0.0002139583475206395,0.064876175235047,443.5939647678417,80.74022736268478,2.481756003174076
0.00021611167959894394,0.06552910582116424,444.72955387823515,80.74022736268478,2.481756003174076
0.00022238167594459496,0.06743028605721145,448.0112566100663,80.74022736268478,2.481756003174076
0.00022326834209448503,0.0676991398279656,448.4724065497756,80.74022736268478,2.481756003174076
0.00022504167439426508,0.0682368473694739,449.39256930377525,80.74022736268478,2.481756003174076
0.00022573834065489298,0.06844808961792359,449.7532875918608,80.74022736268478,2.481756003174076
0.00022694167328688662,0.06881296259251851,450.3753255118411,80.74022736268478,2.481756003174076
0.0002277016728439352,0.06904340868173635,450.7675288859856,80.74022736268478,2.481756003174076
0.0002301083381079225,0.06977315463092619,452.0061515348483,80.74022736268478,2.481756003174076
0.00023219833688980617,0.07040688137627527,453.07770433406324,80.74022736268478,2.481756003174076
0.00023397166918958623,0.07094458891778356,453.98395410306415,80.74022736268478,2.481756003174076
0.0002348583353394763,0.07121344268853771,454.436074154158,80.74022736268478,2.481756003174076
0.00023587166808220777,0.07152070414082817,454.9519684529494,80.74022736268478,2.481756003174076
0.0002362516678607321,0.0716359271854371,455.14520587762934,80.74022736268478,2.481756003174076
0.00023688500082493926,0.07182796559311863,455.4669990984114,80.74022736268478,2.481756003174076
0.00023764500038198785,0.07205841168233647,455.8527083986483,80.74022736268478,2.481756003174076
0.00023910166619966436,0.07250010002000401,456.5906425506731,80.74022736268478,2.481756003174076
0.00024131833157438944,0.07317223444688938,457.71023060753515,80.74022736268478,2.481756003174076
0.00024157166476007234,0.073249049809962,457.83792763800335,80.74022736268478,2.481756003174076
0.00024340833035627312,0.07380596119223845,458.76217424789525,80.74022736268478,2.481756003174076
0.00024435832980258386,0.07409401880376075,459.2391653541482,80.74022736268478,2.481756003174076
0.0002446749962846875,0.07419003800760153,459.3980016023541,80.74022736268478,2.481756003174076
0.00024575166232383965,0.07451650330066013,459.93744616586014,80.74022736268478,2.481756003174076
0.00024600499550952255,0.07459331866373275,460.06424025323116,80.74022736268478,2.481756003174076
0.0002462583286952054,0.07467013402680536,460.19098342807536,80.74022736268478,2.481756003174076
0.00024708166154867474,0.07491978395679136,460.6025480101656,80.74022736268478,2.481756003174076
0.0002486649939591927,0.0753998799759952,461.3925181705402,80.74022736268478,2.481756003174076
0.00024942499351624127,0.07563032606521304,461.771006844571,80.74022736268478,2.481756003174076
0.00025113499251960066,0.07614882976595319,462.620965750305,80.74022736268478,2.481756003174076
0.0002526549916336979,0.07660972194438888,463.37459176195057,80.74022736268478,2.481756003174076
0.00025366832437642933,0.07691698339667934,463.87602699436775,80.74022736268478,2.481756003174076
0.0002549349903048437,0.07730106021204242,464.5017238229155,80.74022736268478,2.481756003174076
0.00025518832349052657,0.07737787557511502,464.62671756813063,80.74022736268478,2.481756003174076
0.00025696165579030666,0.07791558311662333,465.5003227609308,80.74022736268478,2.481756003174076
0.00025791165523661745,0.07820364072814563,465.96735820551,80.74022736268478,2.481756003174076
0.0002591783211650318,0.07858771754350871,466.58902982566605,80.74022736268478,2.481756003174076
0.000259811654129239,0.07877975595119024,466.8994212099109,80.74022736268478,2.481756003174076
0.0002606349869827083,0.07902940588117624,467.3024892149847,80.74022736268478,2.481756003174076
0.000261584986429019,0.07931746349269854,467.76695115263897,80.74022736268478,2.481756003174076
0.0002624716525789091,0.0795863172634527,468.19985578858854,80.74022736268478,2.481756003174076
0.00026304165224669556,0.07975915183036608,468.4778504806312,80.74022736268478,2.481756003174076
0.00026437165147153065,0.0801624324864973,469.1255927226573,80.74022736268478,2.481756003174076
0.0002657016506963657,0.08056571314262853,469.77206532776364,80.74022736268478,2.481756003174076
0.00026684165003193857,0.0809113822764553,470.3251808688364,80.74022736268478,2.481756003174076
0.0002680449826639322,0.08127625525105021,470.90802619259966,80.74022736268478,2.481756003174076
0.0002715916472634924,0.08235167033406682,472.61997890684245,80.74022736268478,2.481756003174076
0.00027323831297043107,0.08285097019403881,473.411848233826,80.74022736268478,2.481756003174076
0.00027406164582390036,0.0831006201240248,473.80708480808795,80.74022736268478,2.481756003174076
0.0002755183116415769,0.08354230846169235,474.50521699828636,80.74022736268478,2.481756003174076
0.00027570831153083905,0.08359991998399681,474.59617147603296,80.74022736268478,2.481756003174076
0.00027646831108788764,0.08383036607321465,474.9597452023813,80.74022736268478,2.481756003174076
0.00027836830998050917,0.08440648129625926,475.8669783632745,80.74022736268478,2.481756003174076
0.00027881164305545417,0.08454090818163633,476.07831822746186,80.74022736268478,2.481756003174076
0.00028014164228028926,0.08494418883776755,476.7115528672995,80.74022736268478,2.481756003174076
0.00028052164205881355,0.08505941188237648,476.8922615583559,80.74022736268478,2.481756003174076
0.0002807116419480757,0.08511702340468094,476.9825801013684,80.74022736268478,2.481756003174076
0.0002828649740263801,0.08576995399079816,478.0045295903183,80.74022736268478,2.481756003174076
0.0002838149734726909,0.08605801160232047,478.4544246322653,80.74022736268478,2.481756003174076
0.0002846383063261602,0.08630766153230647,478.8438588148359,80.74022736268478,2.481756003174076
0.00028603163884741595,0.08673014602920584,479.5019019483643,80.74022736268478,2.481756003174076
0.000286918304997306,0.08699899979996,479.9200058509369,80.74022736268478,2.481756003174076
0.0002902116364111833,0.08799759951990399,481.46857111124075,80.74022736268478,2.481756003174076
0.00029116163585749406,0.08828565713142629,481.91399703257156,80.74022736268478,2.481756003174076
0.00029204830200738415,0.08855451090218044,482.3292167862962,80.74022736268478,2.481756003174076
0.0002923649684894877,0.08865053010602121,482.47739037048206,80.74022736268478,2.481756003174076
0.00029356830112148134,0.08901540308061613,483.03988008050834,80.74022736268478,2.481756003174076
0.0002938216343071642,0.08909221844368874,483.15818430706025,80.74022736268478,2.481756003174076
0.0002948349670498957,0.0893994798959792,483.6310039480834,80.74022736268478,2.481756003174076
0.0002963549661639929,0.08986037207441488,484.33904682260925,80.74022736268478,2.481756003174076
0.00029863496483513875,0.09055171034206842,485.3984613498341,80.74022736268478,2.481756003174076
0.00030072496361702243,0.09118543708741748,486.3668235082636,80.74022736268478,2.481756003174076
0.0003013582965812296,0.09137747549509903,486.65974793264473,80.74022736268478,2.481756003174076
0.0003028782956953268,0.09183836767353472,487.36178872637146,80.74022736268478,2.481756003174076
0.00030439829480942405,0.0922992598519704,488.0624568082624,80.74022736268478,2.481756003174076
0.0003049049611807898,0.09245289057811563,488.29570943695796,80.74022736268478,2.481756003174076
0.0003072482931483563,0.09316343268653732,489.3725426271178,80.74022736268478,2.481756003174076
0.0003090849587445571,0.09372034406881377,490.2143095573588,80.74022736268478,2.481756003174076
0.000312251623565593,0.09468053610722145,491.6610649851544,80.74022736268478,2.481756003174076
0.0003130749564190623,0.09493018603720745,492.03628269713516,80.74022736268478,2.481756003174076
0.0003149116220152631,0.0954870974194839,492.87192283041577,80.74022736268478,2.481756003174076
0.000315164955200946,0.09556391278255652,492.9870341928614,80.74022736268478,2.481756003174076
0.00031598828805441535,0.09581356271254252,493.3608971503999,80.74022736268478,2.481756003174076
0.00031915495287545117,0.0967737547509502,494.7953048953835,80.74022736268478,2.481756003174076
0.00031940828606113407,0.09685057011402282,494.90981717718046,80.74022736268478,2.481756003174076
0.00031972495254323766,0.09694658931786358,495.052907730713,80.74022736268478,2.481756003174076
0.00032048495210028626,0.09717703540708142,495.3960997396806,80.74022736268478,2.481756003174076
0.00032219495110364564,0.09769553910782157,496.1671233878942,80.74022736268478,2.481756003174076
0.00032358828362490143,0.09811802360472095,496.7941855881722,80.74022736268478,2.481756003174076
0.00032536161592468146,0.09865573114622925,497.5907438849534,80.74022736268478,2.481756003174076
0.0003265016152602544,0.09900140028005601,498.1019231076231,80.74022736268478,2.481756003174076
0.0003271349482244616,0.09919343868773756,498.38561077890165,80.74022736268478,2.481756003174076