File: datasets/aisi_316_L/data/M1/train_95.csv
Time(s),Strain(%),Stress(MPa),Temp(C),Log_SR(s-1)
0.0,0.0,0.0,374.8296656028298,-1.1037841580557783
7.11167964545185e-05,5.6e-06,0.9597892499999999,374.8296656028298,-1.1037841580557783
0.00024382901641549197,1.92e-05,3.2907059999999997,374.8296656028298,-1.1037841580557783
0.0007111679645451849,5.6e-05,9.5978925,374.8296656028298,-1.1037841580557783
0.0008635610998048674,6.8e-05,11.65458375,374.8296656028298,-1.1037841580557783
0.0011683473703242324,9.2e-05,15.76796625,374.8296656028298,-1.1037841580557783
0.0012597832514800419,9.92e-05,17.001981,374.8296656028298,-1.1037841580557783
0.0013512191326358514,0.0001064,18.23599575,374.8296656028298,-1.1037841580557783
0.0015340908949474704,0.0001208,20.70402525,374.8296656028298,-1.1037841580557783
0.001645845860804571,0.0001296,22.2122655,374.8296656028298,-1.1037841580557783
0.0018693557925187718,0.0001472,25.228746,374.8296656028298,-1.1037841580557783
0.002021748927778454,0.0001592,27.285437249999998,374.8296656028298,-1.1037841580557783
0.002184301605388782,0.00017199999999999998,29.479241249999998,374.8296656028298,-1.1037841580557783
0.0023671733677004016,0.0001864,31.94727075,374.8296656028298,-1.1037841580557783
0.0024890878759081473,0.000196,33.59262375,374.8296656028298,-1.1037841580557783
0.002529726045310729,0.0001992,34.14107475,374.8296656028298,-1.1037841580557783
0.0025906832994146024,0.000204,34.96375125,374.8296656028298,-1.1037841580557783
0.0032307344675052687,0.0002544,43.6018545,374.8296656028298,-1.1037841580557783
0.003291691721609142,0.0002592,44.424531,374.8296656028298,-1.1037841580557783
0.003423765772167533,0.0002696,46.20699675,374.8296656028298,-1.1037841580557783
0.0036574352462323797,0.000288,49.36059,374.8296656028298,-1.1037841580557783
0.0041146146520114266,0.00032399999999999996,55.530663749999995,374.8296656028298,-1.1037841580557783
0.004327965041374983,0.0003408,58.410031499999995,374.8296656028298,-1.1037841580557783
0.004561634515439829,0.0003592,61.56362475,374.8296656028298,-1.1037841580557783
0.004795303989504675,0.00037759999999999996,64.71721799999999,374.8296656028298,-1.1037841580557783
0.0048461017012579035,0.0003816,65.40278175,374.8296656028298,-1.1037841580557783
0.005120409344725332,0.0004032,69.104826,374.8296656028298,-1.1037841580557783
0.005161047514127913,0.00040639999999999996,69.65327699999999,374.8296656028298,-1.1037841580557783
0.005425195615244696,0.0004272,73.2182085,374.8296656028298,-1.1037841580557783
0.005465833784647278,0.0004304,73.7666595,374.8296656028298,-1.1037841580557783
0.005506471954049861,0.00043359999999999997,74.31511049999999,374.8296656028298,-1.1037841580557783
0.005608067377556316,0.0004416,75.686238,374.8296656028298,-1.1037841580557783
0.005923013190426325,0.00046639999999999995,79.93673324999999,374.8296656028298,-1.1037841580557783
0.005983970444530199,0.00047119999999999996,80.75940974999999,374.8296656028298,-1.1037841580557783
0.006278597172698918,0.0004944,84.7356795,374.8296656028298,-1.1037841580557783
0.006684978866724738,0.0005264,90.2201895,374.8296656028298,-1.1037841580557783
0.006776414747880547,0.0005336,91.45420424999999,374.8296656028298,-1.1037841580557783
0.006867850629036358,0.0005408,92.688219,374.8296656028298,-1.1037841580557783
0.00692880788314023,0.0005455999999999999,93.51089549999999,374.8296656028298,-1.1037841580557783
0.0072843918654128224,0.0005736,98.30984174999999,374.8296656028298,-1.1037841580557783
0.007325030034815404,0.0005767999999999999,98.85829274999999,374.8296656028298,-1.1037841580557783
0.007457104085373796,0.0005872,100.64075849999999,374.8296656028298,-1.1037841580557783
0.007670454474737351,0.0006039999999999999,103.52012624999999,374.8296656028298,-1.1037841580557783
0.0077822094405944515,0.0006127999999999999,105.02836649999999,374.8296656028298,-1.1037841580557783
0.007944762118204779,0.0006255999999999999,107.22217049999999,374.8296656028298,-1.1037841580557783
0.008005719372308652,0.0006303999999999999,108.04484699999999,374.8296656028298,-1.1037841580557783
0.008117474338165754,0.0006391999999999999,109.55308724999999,374.8296656028298,-1.1037841580557783
0.008340984269879954,0.0006567999999999999,112.56956774999999,374.8296656028298,-1.1037841580557783
0.008412101066334473,0.0006624,113.52935699999999,374.8296656028298,-1.1037841580557783
0.008777844590957712,0.0006912,118.465416,374.8296656028298,-1.1037841580557783
0.008909918641516102,0.0007015999999999999,120.24788174999999,374.8296656028298,-1.1037841580557783
0.009031833149723847,0.0007111999999999999,121.89323474999999,374.8296656028298,-1.1037841580557783
0.009092790403827721,0.000716,122.71591124999999,374.8296656028298,-1.1037841580557783
0.00923502399673676,0.0007272,124.63548975,374.8296656028298,-1.1037841580557783
0.009407736216697733,0.0007408,126.9664065,374.8296656028298,-1.1037841580557783
0.009803958368372907,0.000772,132.31380375,374.8296656028298,-1.1037841580557783
0.010017308757736463,0.0007888,135.1931715,374.8296656028298,-1.1037841580557783
0.01020018052004808,0.0008032,137.661201,374.8296656028298,-1.1037841580557783
0.010484647705866155,0.0008256,141.500358,374.8296656028298,-1.1037841580557783
0.01069799809522971,0.0008424,144.37972575,374.8296656028298,-1.1037841580557783
0.010799593518736165,0.0008504,145.75085325,374.8296656028298,-1.1037841580557783
0.01110437978925553,0.0008744,149.86423575,374.8296656028298,-1.1037841580557783
0.011266932466865859,0.0008872,152.05803975,374.8296656028298,-1.1037841580557783
0.011378687432722958,0.000896,153.56628,374.8296656028298,-1.1037841580557783
0.011419325602125541,0.0008992,154.114731,374.8296656028298,-1.1037841580557783
0.011602197364437159,0.0009136,156.5827605,374.8296656028298,-1.1037841580557783
0.011835866838502006,0.000932,157.9921456433888,374.8296656028298,-1.1037841580557783
0.01221176990547589,0.0009616,158.14782971863423,374.8296656028298,-1.1037841580557783
0.012465758464242027,0.0009816,158.25196493743005,374.8296656028298,-1.1037841580557783
0.012994054666475593,0.0010232,158.46595215139092,374.8296656028298,-1.1037841580557783
0.013095650089982048,0.0010312,158.50671164095516,374.8296656028298,-1.1037841580557783
0.013156607344085922,0.001036,158.5311081441559,374.8296656028298,-1.1037841580557783
0.013268362309943023,0.0010448,158.57572087917393,374.8296656028298,-1.1037841580557783
0.01328868139464431,0.0010463999999999998,158.58381651643032,374.8296656028298,-1.1037841580557783
0.01354266995341045,0.0010664,158.68460804870392,374.8296656028298,-1.1037841580557783
0.013674744003968842,0.0010768,158.7367281339273,374.8296656028298,-1.1037841580557783
0.013959211189786916,0.0010992,158.8483246190618,374.8296656028298,-1.1037841580557783
0.014050647070942725,0.0011064,158.8840060931641,374.8296656028298,-1.1037841580557783
0.014771974577838555,0.0011631999999999999,159.16238606621798,374.8296656028298,-1.1037841580557783
0.014995484509552756,0.0011807999999999999,159.2475619640886,374.8296656028298,-1.1037841580557783
0.015351068491825349,0.0012088,159.3820556495167,374.8296656028298,-1.1037841580557783
0.015747290643500524,0.00124,159.53049685675222,374.8296656028298,-1.1037841580557783
0.01607239599872118,0.0012656,159.6512097863335,374.8296656028298,-1.1037841580557783
0.016163831879876987,0.0012728,159.68498823470765,374.8296656028298,-1.1037841580557783
0.016346703642188605,0.0012871999999999998,159.75232239589832,374.8296656028298,-1.1037841580557783
0.016377182269240544,0.0012896,159.7635161330649,374.8296656028298,-1.1037841580557783
0.017047712064383148,0.0013423999999999999,160.0077599215908,374.8296656028298,-1.1037841580557783
0.01710866931848702,0.0013472,160.02977643114227,374.8296656028298,-1.1037841580557783
0.01740329604665574,0.0013704,160.1357612821385,374.8296656028298,-1.1037841580557783
0.017596327351318004,0.0013855999999999999,160.20482042686893,374.8296656028298,-1.1037841580557783
0.01776903957127898,0.0013992,160.266360142821,374.8296656028298,-1.1037841580557783
0.01790111362183737,0.0014096,160.3132626507956,374.8296656028298,-1.1037841580557783
0.018155102180603504,0.0014295999999999998,160.40308218845522,374.8296656028298,-1.1037841580557783
0.018368452569967064,0.0014464,160.47815250790276,374.8296656028298,-1.1037841580557783
0.01867323884048643,0.0014704,160.58480858636574,374.8296656028298,-1.1037841580557783
0.0187341960945903,0.0014751999999999999,160.60605809431095,374.8296656028298,-1.1037841580557783
0.018896748772200628,0.001488,160.66259203157205,374.8296656028298,-1.1037841580557783
0.019059301449810953,0.0015007999999999998,160.71893662159374,374.8296656028298,-1.1037841580557783
0.0191812159580187,0.0015103999999999999,160.76107215482156,374.8296656028298,-1.1037841580557783
0.019282811381525156,0.0015183999999999998,160.79610537311459,374.8296656028298,-1.1037841580557783
0.019496161770888712,0.0015352,160.86944168060134,374.8296656028298,-1.1037841580557783
0.019719671702602914,0.0015528,160.9459352815427,374.8296656028298,-1.1037841580557783
0.019760309872005496,0.0015559999999999999,160.95980680439115,374.8296656028298,-1.1037841580557783
0.02002445797312228,0.0015768,161.04970203078557,374.8296656028298,-1.1037841580557783
0.020410520582446808,0.0016072,161.18025987633263,374.8296656028298,-1.1037841580557783
0.020481637378901327,0.0016128,161.20420459081478,374.8296656028298,-1.1037841580557783
0.020501956463602616,0.0016144,161.21103997935396,374.8296656028298,-1.1037841580557783
0.02060355188710907,0.0016224,161.24517737191445,374.8296656028298,-1.1037841580557783
0.02069498776826488,0.0016296,161.27584493635499,374.8296656028298,-1.1037841580557783
0.02089817861527779,0.0016455999999999999,161.3438065175101,374.8296656028298,-1.1037841580557783
0.021416315275160712,0.0016864,161.51595230776567,374.8296656028298,-1.1037841580557783
0.021487432071615232,0.001692,161.5394527548871,374.8296656028298,-1.1037841580557783
0.021924292392692987,0.0017264,161.68315276553787,374.8296656028298,-1.1037841580557783
0.022157961866757832,0.0017448,161.7595569552391,374.8296656028298,-1.1037841580557783
0.02224939774791364,0.0017519999999999999,161.78936862903512,374.8296656028298,-1.1037841580557783
0.022361152713770743,0.0017607999999999999,161.82574031143466,374.8296656028298,-1.1037841580557783
0.022432269510225263,0.0017664,161.84884902128002,374.8296656028298,-1.1037841580557783
0.02258466264548494,0.0017783999999999999,161.89827169372455,374.8296656028298,-1.1037841580557783
0.02288944891600431,0.0018024,161.99672857757292,374.8296656028298,-1.1037841580557783
0.023143437474770445,0.0018223999999999998,162.07838600962486,374.8296656028298,-1.1037841580557783
0.023285671067679484,0.0018336,162.1239614931685,374.8296656028298,-1.1037841580557783
0.02345838328764046,0.0018472,162.17915745241172,374.8296656028298,-1.1037841580557783
0.024403220726250487,0.0019215999999999999,162.47835245191916,374.8296656028298,-1.1037841580557783
0.024768964250873726,0.0019504,162.59295260026394,374.8296656028298,-1.1037841580557783
0.024961995555535993,0.0019656,162.65316983938752,374.8296656028298,-1.1037841580557783
0.02514486731784761,0.00198,162.71005044745615,374.8296656028298,-1.1037841580557783
0.02525662228370471,0.0019887999999999998,162.74473140490866,374.8296656028298,-1.1037841580557783
0.025439494046016333,0.0020032,162.8013532480203,374.8296656028298,-1.1037841580557783
0.025967790248249894,0.0020448,162.96404254610346,374.8296656028298,-1.1037841580557783
0.026211619264665385,0.002064,163.03869404666568,374.8296656028298,-1.1037841580557783
0.026313214688171844,0.002072,163.06971884978591,374.8296656028298,-1.1037841580557783
0.026648479585743144,0.0020984,163.17177084471356,374.8296656028298,-1.1037841580557783
0.02688214905980799,0.0021168,163.24260207503505,374.8296656028298,-1.1037841580557783
0.02705486127976896,0.0021303999999999997,163.29480136072493,374.8296656028298,-1.1037841580557783
0.027115818533872835,0.0021352,163.31319358882402,374.8296656028298,-1.1037841580557783
0.027207254415028647,0.0021424,163.34075172539198,374.8296656028298,-1.1037841580557783
0.0273088498385351,0.0021504,163.37132954926594,374.8296656028298,-1.1037841580557783
0.027420604804392203,0.0021592,163.40491395960223,374.8296656028298,-1.1037841580557783
0.027501881143197363,0.0021655999999999997,163.42930546561857,374.8296656028298,-1.1037841580557783
0.027633955193755756,0.002176,163.46888178902014,374.8296656028298,-1.1037841580557783
0.028040336887781576,0.002208,163.5901949344559,374.8296656028298,-1.1037841580557783
0.02815209185363868,0.0022168,163.6234355925084,374.8296656028298,-1.1037841580557783
0.028355282700651588,0.0022328,163.68374160568405,374.8296656028298,-1.1037841580557783
0.028467037666508686,0.0022416,163.7168380666377,374.8296656028298,-1.1037841580557783
0.028629590344119014,0.0022543999999999997,163.76488806053277,374.8296656028298,-1.1037841580557783
0.02898517432639161,0.0022824,163.86962803790624,374.8296656028298,-1.1037841580557783
0.02920868425810581,0.0023,163.93520816971713,374.8296656028298,-1.1037841580557783
0.029422034647469366,0.0023168,163.9976250552524,374.8296656028298,-1.1037841580557783
0.02951347052862518,0.002324,164.02432108549007,374.8296656028298,-1.1037841580557783
0.029828416341495183,0.0023488,164.11602819132762,374.8296656028298,-1.1037841580557783
0.02997064993440422,0.0023599999999999997,164.15732044211387,374.8296656028298,-1.1037841580557783
0.03018400032376778,0.0023768,164.21911580880987,374.8296656028298,-1.1037841580557783
0.030600541560144245,0.0024096,164.3392751358829,374.8296656028298,-1.1037841580557783
0.03086468966126103,0.0024304,164.41514331760163,374.8296656028298,-1.1037841580557783
0.031179635474131034,0.0024552,164.5052713760048,374.8296656028298,-1.1037841580557783
0.03141330494819588,0.0024736,164.57191131803998,374.8296656028298,-1.1037841580557783
0.0317282507610659,0.0024984,164.66142528981936,374.8296656028298,-1.1037841580557783
0.0318196866422217,0.0025055999999999998,164.68734822282053,374.8296656028298,-1.1037841580557783
0.03234798284445527,0.0025472,164.83656023096728,374.8296656028298,-1.1037841580557783
0.03245973781031237,0.0025559999999999997,164.86800218194216,374.8296656028298,-1.1037841580557783
0.03252069506441624,0.0025608,164.88513454174668,374.8296656028298,-1.1037841580557783
0.03275436453848109,0.0025792,164.9506928920549,374.8296656028298,-1.1037841580557783
0.03303883172429916,0.0026016,165.03025738445515,374.8296656028298,-1.1037841580557783
0.03309978897840304,0.0026064,165.0472721080118,374.8296656028298,-1.1037841580557783
0.03321154394426013,0.0026152,165.07843406234986,374.8296656028298,-1.1037841580557783
0.03335377753716918,0.0026264,165.11803565000295,374.8296656028298,-1.1037841580557783
0.03350617067242886,0.0026384,165.1603929066799,374.8296656028298,-1.1037841580557783
0.03369920197709112,0.0026536,165.21393772914504,374.8296656028298,-1.1037841580557783
0.033810956942948216,0.0026623999999999997,165.2448826907108,374.8296656028298,-1.1037841580557783
0.03391255236645468,0.0026704,165.27297987609052,374.8296656028298,-1.1037841580557783
0.034511965365142755,0.0027175999999999997,165.4380899447948,374.8296656028298,-1.1037841580557783
0.03469483712745438,0.002732,165.48823935952657,374.8296656028298,-1.1037841580557783
0.034877708889766,0.0027464,165.538285790586,374.8296656028298,-1.1037841580557783
0.035141856990882785,0.0027672,165.61039478692172,374.8296656028298,-1.1037841580557783
0.035212973787337294,0.0027727999999999997,165.62977259124045,374.8296656028298,-1.1037841580557783
0.035345047837895695,0.0027832,165.66571949686517,374.8296656028298,-1.1037841580557783
0.03547712188845408,0.0027936,165.70161405452106,374.8296656028298,-1.1037841580557783
0.03561935548136312,0.0028048,165.74021149943408,374.8296656028298,-1.1037841580557783
0.03597493946363571,0.0028328,165.83644306374254,374.8296656028298,-1.1037841580557783
0.03658451200467444,0.0028807999999999998,166.0005528497228,374.8296656028298,-1.1037841580557783
0.03696041507164833,0.0029104,166.10122244056313,374.8296656028298,-1.1037841580557783
0.037041691410453485,0.0029167999999999998,166.1229362467983,374.8296656028298,-1.1037841580557783
0.03731599905392092,0.0029384,166.19608354946106,374.8296656028298,-1.1037841580557783
0.03771222120559609,0.0029695999999999998,166.30137162936066,374.8296656028298,-1.1037841580557783
0.037793497544401256,0.002976,166.32291576170593,374.8296656028298,-1.1037841580557783
0.038118602899621906,0.0030015999999999997,166.4089122111016,374.8296656028298,-1.1037841580557783
0.03852498459364773,0.0030336,166.51600658066045,374.8296656028298,-1.1037841580557783
0.03873833498301129,0.0030504,166.57205470687487,374.8296656028298,-1.1037841580557783
0.03888056857592032,0.0030616,166.6093532575685,374.8296656028298,-1.1037841580557783
0.039215833473491626,0.003088,166.69706135262555,374.8296656028298,-1.1037841580557783
0.039398705235803244,0.0031024,166.74477885609247,374.8296656028298,-1.1037841580557783
0.03956125791341357,0.0031152,166.7871219472324,374.8296656028298,-1.1037841580557783
0.039886363268634234,0.0031408,166.87160511716925,374.8296656028298,-1.1037841580557783
0.03993716098038745,0.0031447999999999997,166.8847813143594,374.8296656028298,-1.1037841580557783
0.04001843731919262,0.0031512,166.90584964285011,374.8296656028298,-1.1037841580557783
0.04022162816620553,0.0031672,166.95844758656668,374.8296656028298,-1.1037841580557783
0.04040449992851715,0.0031815999999999997,167.00569719993103,374.8296656028298,-1.1037841580557783
0.040617850317880705,0.0031983999999999997,167.06071646643449,374.8296656028298,-1.1037841580557783
0.04080072208019232,0.0032128,167.1077861913702,374.8296656028298,-1.1037841580557783
0.04100391292720523,0.0032288,167.1599894926435,374.8296656028298,-1.1037841580557783
0.04109534880836104,0.0032359999999999997,167.1834480535172,374.8296656028298,-1.1037841580557783
0.041176625147166204,0.0032424,167.20428302417835,374.8296656028298,-1.1037841580557783
0.04138997553652976,0.0032592,167.25889865505266,374.8296656028298,-1.1037841580557783
0.041583006841192025,0.0032744,167.30821826302434,374.8296656028298,-1.1037841580557783
0.04200970761991914,0.0033079999999999997,167.4169248202328,374.8296656028298,-1.1037841580557783
0.04227385572103592,0.0033288,167.48400359520076,374.8296656028298,-1.1037841580557783
0.04240592977159431,0.0033391999999999996,167.51748166891883,374.8296656028298,-1.1037841580557783
0.04329996949845112,0.0034096,167.74304259997618,374.8296656028298,-1.1037841580557783
0.04351331988781467,0.0034264,167.7966003131126,374.8296656028298,-1.1037841580557783
0.04365555348072371,0.0034376,167.83224856986223,374.8296656028298,-1.1037841580557783
0.0437876275312821,0.0034479999999999997,167.86530998492358,374.8296656028298,-1.1037841580557783
0.04386890387008727,0.0034544,167.88563614150044,374.8296656028298,-1.1037841580557783
0.04410257334415211,0.0034728,167.94399219229038,374.8296656028298,-1.1037841580557783
0.044224487852359856,0.0034823999999999996,167.9743909518296,374.8296656028298,-1.1037841580557783
0.04432608327586631,0.0034904,167.99969829384816,374.8296656028298,-1.1037841580557783
0.045159165748619244,0.0035559999999999997,168.20637203603653,374.8296656028298,-1.1037841580557783
0.04523028254507376,0.0035616,168.22394573825733,374.8296656028298,-1.1037841580557783
0.04532171842622957,0.0035688,168.24652467178987,374.8296656028298,-1.1037841580557783
0.045626504696748935,0.0035927999999999997,168.32165980589934,374.8296656028298,-1.1037841580557783
0.045890652797865715,0.0036136,168.3866187275562,374.8296656028298,-1.1037841580557783
0.04628687494954089,0.0036447999999999997,168.48378435869995,374.8296656028298,-1.1037841580557783
0.046408789457748637,0.0036544,168.5136161447219,374.8296656028298,-1.1037841580557783
0.04656118259300832,0.0036663999999999998,168.5508629327268,374.8296656028298,-1.1037841580557783
0.04674405435531994,0.0036807999999999997,168.59549637926065,374.8296656028298,-1.1037841580557783
0.046845649778826395,0.0036888,168.6202633113327,374.8296656028298,-1.1037841580557783
0.046876128405878334,0.0036912,168.62768930495477,374.8296656028298,-1.1037841580557783
0.04705900016818995,0.0037056,168.67220578697544,374.8296656028298,-1.1037841580557783
0.04723171238815092,0.0037191999999999998,168.71418722308053,374.8296656028298,-1.1037841580557783
0.047546658201020935,0.003744,168.7905878003455,374.8296656028298,-1.1037841580557783
0.04772952996333255,0.0037584,168.83485885414694,374.8296656028298,-1.1037841580557783
0.04789208264094288,0.0037711999999999997,168.87415539721786,374.8296656028298,-1.1037841580557783
0.04798351852209869,0.0037784,168.89623684281966,374.8296656028298,-1.1037841580557783
0.04813591165735837,0.0037903999999999998,168.9330028197473,374.8296656028298,-1.1037841580557783
0.0485219742666829,0.0038207999999999996,169.0259407067745,374.8296656028298,-1.1037841580557783
0.04863372923254,0.0038296,169.05278989846275,374.8296656028298,-1.1037841580557783
0.04905027046891647,0.0038623999999999998,169.15265288426127,374.8296656028298,-1.1037841580557783
0.04928393994298132,0.0038808,169.20852876294413,374.8296656028298,-1.1037841580557783
0.04933473765473454,0.0038848,169.22066201032547,374.8296656028298,-1.1037841580557783
0.04947697124764358,0.0038959999999999997,169.2546092098334,374.8296656028298,-1.1037841580557783
0.04981223614521488,0.0039223999999999995,169.33447737473705,374.8296656028298,-1.1037841580557783
0.049842714772266816,0.0039248,169.34172770535667,374.8296656028298,-1.1037841580557783
0.04995446973812392,0.0039336,169.36829747060986,374.8296656028298,-1.1037841580557783
0.05017797966983813,0.0039512,169.42136755821633,374.8296656028298,-1.1037841580557783
0.050330372805097806,0.0039632,169.45749886131205,374.8296656028298,-1.1037841580557783
0.05046244685565619,0.0039736,169.48877815901545,374.8296656028298,-1.1037841580557783
0.050624999533266525,0.0039864,169.52723196066614,374.8296656028298,-1.1037841580557783
0.05072659495677297,0.0039943999999999995,169.55124113509677,374.8296656028298,-1.1037841580557783
0.05226097850507082,0.004115223044608922,169.91159860795108,374.8296656028298,-1.1037841580557783
0.05591914538467912,0.0044032806561312265,170.75448269805102,374.8296656028298,-1.1037841580557783
0.06055282343218297,0.004768153630726146,171.79186447120034,374.8296656028298,-1.1037841580557783
0.06664976823153014,0.0052482496499299865,173.11080747862874,374.8296656028298,-1.1037841580557783
0.07445385757469451,0.005862772554510902,174.73224222526517,374.8296656028298,-1.1037841580557783
0.07664875770245949,0.006035607121424285,175.17614099549957,374.8296656028298,-1.1037841580557783
0.07957529120614613,0.0062660532106421285,175.76036926229727,374.8296656028298,-1.1037841580557783
0.08323345808575444,0.006554110822164433,176.4790003142635,374.8296656028298,-1.1037841580557783
0.08396509146167609,0.006611722344468894,176.62123664946904,374.8296656028298,-1.1037841580557783
0.08567223600549331,0.006746149229845969,176.9512548444136,374.8296656028298,-1.1037841580557783
0.08859876950917994,0.006976595319063813,177.51109459835092,374.8296656028298,-1.1037841580557783
0.094939592100501,0.007475895179035807,178.69991419168738,374.8296656028298,-1.1037841580557783
0.09811000339616152,0.007725545109021804,179.28267762318492,374.8296656028298,-1.1037841580557783
0.09981714793997873,0.00785997199439888,179.59342901917668,374.8296656028298,-1.1037841580557783
0.10445082598748258,0.008224844968993799,180.4266206737842,374.8296656028298,-1.1037841580557783
0.107865115075117,0.00849369873974795,181.0313544051759,374.8296656028298,-1.1037841580557783
0.11640083779420304,0.009165833166633327,182.51140457070068,374.8296656028298,-1.1037841580557783
0.1188396157139419,0.009357871574314863,182.9264195378096,374.8296656028298,-1.1037841580557783
0.12444880492934131,0.009799559911982397,183.86854894894043,374.8296656028298,-1.1037841580557783
0.13176513868855788,0.010375675135027004,185.07288422721663,374.8296656028298,-1.1037841580557783
0.13883759465580062,0.010932586517303462,186.21251582742008,374.8296656028298,-1.1037841580557783
0.14030086140764395,0.011047809561912383,186.44544928948835,374.8296656028298,-1.1037841580557783
0.14371515049527836,0.011316663332666534,186.9853069022533,374.8296656028298,-1.1037841580557783
0.14688556179093887,0.01156631326265253,187.48214117280648,374.8296656028298,-1.1037841580557783
0.15273862879831215,0.012027205441088217,188.38852148109464,374.8296656028298,-1.1037841580557783
0.1539580177581816,0.012123224644928985,188.57563420840393,374.8296656028298,-1.1037841580557783
0.1615182293093721,0.012718543708741748,189.72309131057673,374.8296656028298,-1.1037841580557783
0.17005395202845813,0.013390678135627125,190.99371756787852,374.8296656028298,-1.1037841580557783
0.17200497436424922,0.013544308861772355,191.28062455613673,374.8296656028298,-1.1037841580557783
0.183223352795048,0.014427685537107422,192.90635390024346,374.8296656028298,-1.1037841580557783
0.18468661954689133,0.014542908581716344,193.11550583571733,374.8296656028298,-1.1037841580557783
0.19395397564189903,0.015272654530906182,194.42543476766846,374.8296656028298,-1.1037841580557783
0.1980998981054551,0.015599119823964794,195.00352774333527,374.8296656028298,-1.1037841580557783
0.19980704264927235,0.01573354670934187,195.24019228615018,374.8296656028298,-1.1037841580557783
0.20809888757638445,0.01638647729545909,196.37867371627655,374.8296656028298,-1.1037841580557783
0.20956215432822778,0.016501700340068013,196.57773170412074,374.8296656028298,-1.1037841580557783
0.21151317666401886,0.016655331066213242,196.84230117756087,374.8296656028298,-1.1037841580557783
0.21541522133560106,0.0169625925185037,197.3686019635439,374.8296656028298,-1.1037841580557783
0.21931726600718324,0.01726985397079416,197.89119756681075,374.8296656028298,-1.1037841580557783
0.2224876773028438,0.017519503900780158,198.31314143055062,374.8296656028298,-1.1037841580557783
0.23638871144535534,0.018614122824564913,200.1361922463157,374.8296656028298,-1.1037841580557783
0.23736422261325088,0.018690938187637528,200.262533195922,374.8296656028298,-1.1037841580557783
0.24199790066075474,0.01905581116223245,200.8599090212332,374.8296656028298,-1.1037841580557783
0.2571183237631357,0.02024644928985797,202.7789236240434,374.8296656028298,-1.1037841580557783
0.26687343544209113,0.021014602920584116,203.9936718669895,374.8296656028298,-1.1037841580557783
0.2685805799859084,0.021149029805961193,204.2044599303981,374.8296656028298,-1.1037841580557783
0.2717509912815689,0.02139867973594719,204.59454236472726,374.8296656028298,-1.1037841580557783
0.2766285471210466,0.02178275655131026,205.19122121030233,374.8296656028298,-1.1037841580557783
0.2790673250407855,0.021974794958991798,205.48802092848385,374.8296656028298,-1.1037841580557783
0.2873591699678977,0.02262772554510902,206.48965839989313,374.8296656028298,-1.1037841580557783
0.2944316259351404,0.02318463692738548,207.33512012563938,374.8296656028298,-1.1037841580557783
0.308088782285678,0.02426005201040208,208.9456486782314,374.8296656028298,-1.1037841580557783
0.3136979715010774,0.024701740348069615,209.59902002186053,374.8296656028298,-1.1037841580557783
0.3161367494208163,0.02489377875575115,209.8816716165389,374.8296656028298,-1.1037841580557783
0.31881940513252904,0.02510502100420084,210.1916079943384,374.8296656028298,-1.1037841580557783
0.3227214498041112,0.025412282456491297,210.6406150599069,374.8296656028298,-1.1037841580557783
0.325404105515824,0.02562352470494099,210.94807993968362,374.8296656028298,-1.1037841580557783
0.32955002797938004,0.0259499899979996,211.42131561041964,374.8296656028298,-1.1037841580557783
0.3358908505707011,0.026449289857971594,212.1406212082362,374.8296656028298,-1.1037841580557783
0.3429633065379439,0.02700620124024805,212.93670476600917,374.8296656028298,-1.1037841580557783
0.34710922900149993,0.02733266653330666,213.40039784420335,374.8296656028298,-1.1037841580557783
0.3497918847132127,0.027543908781756353,213.6992839590794,374.8296656028298,-1.1037841580557783
0.35393780717676876,0.027870374074814963,214.15944645184626,374.8296656028298,-1.1037841580557783
0.3573520962644032,0.028139227845569114,214.5368274020738,374.8296656028298,-1.1037841580557783
0.36564394119151533,0.028792158431686338,215.4475168318319,374.8296656028298,-1.1037841580557783
0.36637557456743697,0.028849769953990797,215.52748307288326,374.8296656028298,-1.1037841580557783
0.3714970081988886,0.029253050610122025,216.0855132360666,374.8296656028298,-1.1037841580557783
0.3729602749507319,0.029368273654730947,216.24439831411766,374.8296656028298,-1.1037841580557783
0.374911297286523,0.029521904380876176,216.45586742495917,374.8296656028298,-1.1037841580557783
0.3768623196223141,0.029675535107021405,216.66690778300477,374.8296656028298,-1.1037841580557783
0.3805204865019224,0.029963592718543708,217.0614635333509,374.8296656028298,-1.1037841580557783
0.3829592644216612,0.030155631126225244,217.3236791730753,374.8296656028298,-1.1037841580557783
0.3846664089654785,0.03029005801160232,217.50684276746975,374.8296656028298,-1.1037841580557783
0.38856845363706066,0.03059731946389278,217.92431611137965,374.8296656028298,-1.1037841580557783
0.3975919319400945,0.031307861572314466,218.8835108058122,374.8296656028298,-1.1037841580557783
0.4022256099875984,0.03167273454690939,219.3727685203428,374.8296656028298,-1.1037841580557783
0.4075909214110239,0.03209521904380876,219.93653965942462,374.8296656028298,-1.1037841580557783
0.4100296993307628,0.0322872574514903,220.19184174237225,374.8296656028298,-1.1037841580557783
0.4144194995862927,0.032632926585317065,220.64989810646895,374.8296656028298,-1.1037841580557783
0.41807766646590094,0.032920984196839365,221.03016801821965,374.8296656028298,-1.1037841580557783
0.42246746672143093,0.033266653330666134,221.48478326367479,374.8296656028298,-1.1037841580557783
0.4256378780170914,0.03351630326065213,221.81197151727767,374.8296656028298,-1.1037841580557783
0.42953992268867364,0.03382356471294259,222.21336287855527,374.8296656028298,-1.1037841580557783
0.43636850086394247,0.03436127225445089,222.91239258230226,374.8296656028298,-1.1037841580557783
0.4431970790392113,0.03489897979595919,223.60716891100708,374.8296656028298,-1.1037841580557783
0.4444164679990808,0.034994998999799964,223.73079552482133,374.8296656028298,-1.1037841580557783
0.44734300150276735,0.0352254450890178,224.02696089693413,374.8296656028298,-1.1037841580557783
0.44905014604658466,0.035359871974394885,224.19937507713826,374.8296656028298,-1.1037841580557783
0.45222055734224514,0.03560952190438088,224.5188961559097,374.8296656028298,-1.1037841580557783
0.45563484642987945,0.03587837567513502,224.862020324427,374.8296656028298,-1.1037841580557783
0.4644144469409395,0.03656971394278856,225.73976655183097,374.8296656028298,-1.1037841580557783
0.4688042471964694,0.03691538307661532,226.17621108777743,374.8296656028298,-1.1037841580557783
0.4717307807001561,0.03714582916583317,226.46628896659033,374.8296656028298,-1.1037841580557783
0.47587670316371206,0.037472294458891775,226.8760340862967,374.8296656028298,-1.1037841580557783
0.4797787478352943,0.03777955591118223,227.26040661315872,374.8296656028298,-1.1037841580557783
0.4809981367951637,0.037875575115023,227.38027274752656,374.8296656028298,-1.1037841580557783
0.48514405925871984,0.03820204040808162,227.78693406134627,374.8296656028298,-1.1037841580557783
0.4909971262660931,0.038662932586517304,228.35874432857344,374.8296656028298,-1.1037841580557783
0.49392365976977964,0.03889337867573514,228.64365210900263,374.8296656028298,-1.1037841580557783
0.49636243768951865,0.03908541708341669,228.8805726943924,374.8296656028298,-1.1037841580557783
0.4988012156092575,0.03927745549109822,229.11703972807354,374.8296656028298,-1.1037841580557783
0.5034348936567613,0.03964232846569314,229.56508855738912,374.8296656028298,-1.1037841580557783
0.5075808161203174,0.039968793758751744,229.96461287991087,374.8296656028298,-1.1037841580557783
0.5131900053357168,0.04041048209641929,230.5031259265352,374.8296656028298,-1.1037841580557783
0.5141655165036123,0.040487297459491894,230.59654555926292,374.8296656028298,-1.1037841580557783
0.5185553167591423,0.04083296659331867,231.01608142409813,374.8296656028298,-1.1037841580557783
0.5229451170146723,0.04117863572714543,231.43423444605432,374.8296656028298,-1.1037841580557783
0.528066550646124,0.04158191638327666,231.92035335216914,374.8296656028298,-1.1037841580557783
0.53221247310968,0.041908381676335274,232.31253284475093,374.8296656028298,-1.1037841580557783
0.5351390066133666,0.04213882776555311,232.5886483900293,374.8296656028298,-1.1037841580557783
0.5436747293324526,0.04281096219243849,233.39064143786646,374.8296656028298,-1.1037841580557783
0.5485522851719303,0.043195039007801556,233.84671822314397,374.8296656028298,-1.1037841580557783
0.5497716741318,0.043291058211642336,233.96048996292572,374.8296656028298,-1.1037841580557783
0.5536737188033819,0.04359831966393278,234.32389995864224,374.8296656028298,-1.1037841580557783
0.5578196412669381,0.0439247849569914,234.70893035116217,374.8296656028298,-1.1037841580557783
0.564160463858259,0.04442408481696339,235.2956486256891,374.8296656028298,-1.1037841580557783
0.5690380196977369,0.04480816163232647,235.7452220322418,374.8296656028298,-1.1037841580557783
0.5702574086576063,0.044904180836167235,235.85738024908798,374.8296656028298,-1.1037841580557783
0.5778176202087968,0.04549949989997999,236.5506850615392,374.8296656028298,-1.1037841580557783
0.579524764752614,0.045633926785357076,236.7067470821601,374.8296656028298,-1.1037841580557783
0.5853778317599874,0.046094818963792764,237.2404609754364,374.8296656028298,-1.1037841580557783
0.5917186543513083,0.046594118823764755,237.81630784069375,374.8296656028298,-1.1037841580557783
0.5980594769426294,0.047093418683736746,238.38975308381316,374.8296656028298,-1.1037841580557783
0.6065951996617154,0.047765553110622125,239.15796817922492,374.8296656028298,-1.1037841580557783
0.6136676556289581,0.04832246449289858,239.79130059692585,374.8296656028298,-1.1037841580557783
0.6178135780925142,0.048648929785957196,240.16124098679848,374.8296656028298,-1.1037841580557783
0.6212278671801486,0.048917783556711336,240.46517134618657,374.8296656028298,-1.1037841580557783
0.6241544006838353,0.04914822964592919,240.72516493776476,374.8296656028298,-1.1037841580557783
0.6278125675634435,0.049436287257451486,241.04948932003643,374.8296656028298,-1.1037841580557783
0.6356166569066078,0.0500508101620324,241.73892831295095,374.8296656028298,-1.1037841580557783
0.6607360694799184,0.052028805761152236,243.93597427411694,374.8296656028298,-1.1037841580557783
0.6651258697354483,0.052374474894979,244.31655590413115,374.8296656028298,-1.1037841580557783
0.6763442481662472,0.05325785157031407,245.28472944538132,374.8296656028298,-1.1037841580557783
0.684879970885333,0.053929985997199434,246.01719337397228,374.8296656028298,-1.1037841580557783
0.6895136489328368,0.054294858971794355,246.41332537810794,374.8296656028298,-1.1037841580557783
0.700244271779688,0.05513982796559312,247.32671898874045,374.8296656028298,-1.1037841580557783
0.7078044833308784,0.05573514702940588,247.96697129257592,374.8296656028298,-1.1037841580557783
0.7092677500827218,0.055850370074014805,248.09058244114246,374.8296656028298,-1.1037841580557783
0.713413672546278,0.05617683536707342,248.44027508136713,374.8296656028298,-1.1037841580557783
0.7180473505937817,0.05654170834166833,248.83017147803204,374.8296656028298,-1.1037841580557783
0.7270708288968156,0.057252250450090025,249.58663879104589,374.8296656028298,-1.1037841580557783
0.7285340956486588,0.05736747349469894,249.7089633176689,374.8296656028298,-1.1037841580557783
0.7375575739516925,0.05807801560312062,250.46119149324534,374.8296656028298,-1.1037841580557783
0.7399963518714315,0.058270054010802166,250.66387920946448,374.8296656028298,-1.1037841580557783
0.749751463550387,0.05903820764152831,251.4720384137857,374.8296656028298,-1.1037841580557783
0.7509708525102564,0.05913422684536908,251.57276917652325,374.8296656028298,-1.1037841580557783
0.7531657526380213,0.05930706141228245,251.7539239484822,374.8296656028298,-1.1037841580557783
0.7536535082219692,0.05934546909381877,251.79415259038788,374.8296656028298,-1.1037841580557783
0.7614575975651336,0.059959991998399687,252.43643628457906,374.8296656028298,-1.1037841580557783
0.762433108733029,0.060036807361472294,252.51654084517634,374.8296656028298,-1.1037841580557783
0.767066786780533,0.060401680336067215,252.896492989626,374.8296656028298,-1.1037841580557783
0.7704810758681674,0.06067053410682137,253.1758851932845,374.8296656028298,-1.1037841580557783
0.7741392427477757,0.06095859171834367,253.4746987000477,374.8296656028298,-1.1037841580557783
0.7834065988427834,0.06168833766753351,254.22923872857373,374.8296656028298,-1.1037841580557783
0.7873086435143656,0.06199559911982397,254.54589744074428,374.8296656028298,-1.1037841580557783
0.7909668103939738,0.06228365673134627,254.842209551431,374.8296656028298,-1.1037841580557783
0.7960882440254254,0.06268693738747749,255.25615017667627,374.8296656028298,-1.1037841580557783
0.8009657998649032,0.06307101420284057,255.64941485174688,374.8296656028298,-1.1037841580557783
0.8090137670000414,0.06370474094818963,256.29626577656785,374.8296656028298,-1.1037841580557783
0.8109647893358325,0.06385837167433486,256.4526995982656,374.8296656028298,-1.1037841580557783
0.8121841782957019,0.06395439087817563,256.550396205817,374.8296656028298,-1.1037841580557783
0.820719901014788,0.06462652530506101,257.2326778364878,374.8296656028298,-1.1037841580557783
0.8287678681499263,0.06526025205041008,257.87344160980166,374.8296656028298,-1.1037841580557783
0.8392546132048034,0.06608601720344069,258.70474679753045,374.8296656028298,-1.1037841580557783
0.8414495133325683,0.06625885177035407,258.8782271147218,374.8296656028298,-1.1037841580557783
0.8436444134603334,0.06643168633726745,259.051531038966,374.8296656028298,-1.1037841580557783
0.8458393135880984,0.06660452090418084,259.22465920783895,374.8296656028298,-1.1037841580557783
0.8504729916356023,0.06696939387877576,259.5895776833894,374.8296656028298,-1.1037841580557783
0.8541311585152105,0.06725745149029806,259.8771237847422,374.8296656028298,-1.1037841580557783
0.8590087143546884,0.06764152830566114,260.25977256889996,374.8296656028298,-1.1037841580557783
0.8612036144824532,0.06781436287257452,260.4316879746385,374.8296656028298,-1.1037841580557783
0.8624230034423226,0.06791038207641528,260.5271226947284,374.8296656028298,-1.1037841580557783
0.8651056591540354,0.06812162432486497,260.73689403487634,374.8296656028298,-1.1037841580557783
0.8724219929132521,0.06869773954790959,261.30771222311535,374.8296656028298,-1.1037841580557783
0.8765679153768082,0.0690242048409682,261.63034710418265,374.8296656028298,-1.1037841580557783
0.8785189377125993,0.06917783556711343,261.7819693068384,374.8296656028298,-1.1037841580557783
0.8812015934243119,0.06938907781556311,261.99023558595036,374.8296656028298,-1.1037841580557783
0.8863230270557637,0.06979235847169435,262.3871494922765,374.8296656028298,-1.1037841580557783
0.891688338479189,0.07021484296859372,262.802005893287,374.8296656028298,-1.1037841580557783
0.8977852832785362,0.07069493898779756,263.2722537468241,374.8296656028298,-1.1037841580557783
0.9009556945741968,0.07094458891778356,263.51629032911825,374.8296656028298,-1.1037841580557783
0.9065648837895961,0.07138627725545109,263.9472285072919,374.8296656028298,-1.1037841580557783
0.9119301952130217,0.07180876175235047,264.3584582487502,374.8296656028298,-1.1037841580557783
0.9148567287167084,0.07203920784156832,264.5823676316607,374.8296656028298,-1.1037841580557783
0.9185148955963166,0.07232726545309062,264.861861923896,374.8296656028298,-1.1037841580557783
0.9229046958518465,0.07267293458691738,265.1966826832236,374.8296656028298,-1.1037841580557783
0.9260751071475071,0.07292258451690338,265.438111523109,374.8296656028298,-1.1037841580557783
0.9268067405234287,0.07298019603920784,265.4937800683842,374.8296656028298,-1.1037841580557783
0.930708785195011,0.0732874574914983,265.79039002437077,374.8296656028298,-1.1037841580557783
0.9375373633702798,0.07382516503300661,266.30829309188294,374.8296656028298,-1.1037841580557783
0.9441220637535749,0.07434366873374676,266.8063081468914,374.8296656028298,-1.1037841580557783
0.9548526866004258,0.07518863772754551,267.61499553535856,374.8296656028298,-1.1037841580557783
0.9582669756880602,0.07545749149829967,267.8715608557538,374.8296656028298,-1.1037841580557783
0.9648516760713551,0.07597599519903982,268.3653608471735,374.8296656028298,-1.1037841580557783
0.9653394316553029,0.07601440288057612,268.4018862573851,374.8296656028298,-1.1037841580557783
0.9707047430787284,0.0764368873774755,268.8031918895338,374.8296656028298,-1.1037841580557783
0.973631276582415,0.07666733346669334,269.02172122472024,374.8296656028298,-1.1037841580557783
0.9743629099583367,0.0767249449889978,269.0763135131017,374.8296656028298,-1.1037841580557783
0.9789965880058406,0.07708981796359272,269.4216941588653,374.8296656028298,-1.1037841580557783
0.9833863882613705,0.07743548709741949,269.74830925739485,374.8296656028298,-1.1037841580557783
0.9907027220205872,0.0780116023204641,270.29140698439534,374.8296656028298,-1.1037841580557783
1.0004578336995427,0.07877975595119024,271.01311031384256,374.8296656028298,-1.1037841580557783
1.0075302896667853,0.0793366673334667,271.5346301904028,374.8296656028298,-1.1037841580557783
1.0116762121303415,0.07966313262652532,271.83968496362695,374.8296656028298,-1.1037841580557783
1.0128956010902108,0.07975915183036608,271.92931411842176,374.8296656028298,-1.1037841580557783
1.0163098901778451,0.08002800560112022,272.1800521548806,374.8296656028298,-1.1037841580557783
1.0250894906889052,0.08071934386877376,272.82330325838495,374.8296656028298,-1.1037841580557783
1.0265527574407485,0.08083456691338269,272.9303025391178,374.8296656028298,-1.1037841580557783
1.0372833802875994,0.08167953590718144,273.713154474111,374.8296656028298,-1.1037841580557783
1.0394782804153646,0.08185237047409483,273.87289348166047,374.8296656028298,-1.1037841580557783
1.0480140031344505,0.0825245049009802,274.49285427130235,374.8296656028298,-1.1037841580557783
1.057769114813406,0.08329265853170635,275.1989746395378,374.8296656028298,-1.1037841580557783
1.0650854485726224,0.08386877375475095,275.7268994243877,374.8296656028298,-1.1037841580557783
1.072889537915787,0.08448329665933187,276.2884627075726,374.8296656028298,-1.1037841580557783
1.0819130162188206,0.08519383876775355,276.93578821342817,374.8296656028298,-1.1037841580557783
1.0833762829706641,0.08530906181236247,277.040561189648,374.8296656028298,-1.1037841580557783
1.0848395497225074,0.0854242848569714,277.14527899067645,374.8296656028298,-1.1037841580557783
1.092155883481724,0.08600040008001601,277.66804397601476,374.8296656028298,-1.1037841580557783
1.0999599728248886,0.08661492298459693,278.22415683112314,374.8296656028298,-1.1037841580557783
1.1019109951606796,0.08676855371074216,278.36294435112586,374.8296656028298,-1.1037841580557783
1.1033742619125226,0.08688377675535107,278.4669721072396,374.8296656028298,-1.1037841580557783
1.1109344734637134,0.08747909581916384,279.0035941259639,374.8296656028298,-1.1037841580557783
1.1209334629346426,0.08826645329065813,279.71113764468333,374.8296656028298,-1.1037841580557783
1.1226406074784598,0.08840088017603522,279.8316913399408,374.8296656028298,-1.1037841580557783
1.1280059189018854,0.08882336467293458,280.21010977449157,374.8296656028298,-1.1037841580557783
1.130932452405572,0.08905381076215244,280.41622393402423,374.8296656028298,-1.1037841580557783
1.135566130453076,0.08941868373674736,280.7421464496801,374.8296656028298,-1.1037841580557783
1.1470283866758486,0.09032126425285057,281.5461553423757,374.8296656028298,-1.1037841580557783
1.1480038978437441,0.0903980796159232,281.61443661262797,374.8296656028298,-1.1037841580557783
1.1565396205628302,0.09107021404280857,282.21093557343187,374.8296656028298,-1.1037841580557783
1.157027376146778,0.09110862172434488,282.24496927694236,374.8296656028298,-1.1037841580557783
1.158734520690595,0.09124304860972195,282.3640432004389,374.8296656028298,-1.1037841580557783
1.1640998321140206,0.09166553310662133,282.73783089640483,374.8296656028298,-1.1037841580557783
1.1701967769133679,0.09214562912582518,283.1617750457597,374.8296656028298,-1.1037841580557783
1.171903921457185,0.09228005601120225,283.2803249250561,374.8296656028298,-1.1037841580557783
1.1740988215849502,0.09245289057811563,283.4326472808342,374.8296656028298,-1.1037841580557783
1.1745865771688977,0.09249129825965194,283.4664816070093,374.8296656028298,-1.1037841580557783
1.1821467887200883,0.0930866173234647,283.99021497807973,374.8296656028298,-1.1037841580557783
1.1843416888478533,0.09325945189037808,284.142021718246,374.8296656028298,-1.1037841580557783
1.2001937453261557,0.09450770154030806,285.23516437436706,374.8296656028298,-1.1037841580557783
1.2101927347970853,0.09529505901180237,285.92178990990817,374.8296656028298,-1.1037841580557783
1.215070290636563,0.09567913582716543,286.25592603324634,374.8296656028298,-1.1037841580557783
1.2162896795964324,0.09577515503100621,286.33937827874803,374.8296656028298,-1.1037841580557783
1.223849891147623,0.09637047409481897,286.856055809212,374.8296656028298,-1.1037841580557783
1.229702958154996,0.09683136627325466,287.2552098015269,374.8296656028298,-1.1037841580557783
1.2326294916586826,0.0970618123624725,287.4545088925927,374.8296656028298,-1.1037841580557783
1.2421407255456645,0.0978107621524305,288.1009601851605,374.8296656028298,-1.1037841580557783
1.2467744035931683,0.09817563512702542,288.4151984209293,374.8296656028298,-1.1037841580557783
1.2528713483925153,0.09865573114622925,288.82797672822926,374.8296656028298,-1.1037841580557783
1.2550662485202804,0.09882856571314264,288.97638504568147,374.8296656028298,-1.1037841580557783
1.2570172708560714,0.09898219643928786,289.10821859564237,374.8296656028298,-1.1037841580557783
1.2633580934473925,0.09948149629925986,289.53612755860314,374.8296656028298,-1.1037841580557783
1.2672601381189748,0.09978875775155031,289.79903986456895,374.8296656028298,-1.1037841580557783
1.2696989160387135,0.09998079615923185,289.9631997395749,374.8296656028298,-1.1037841580557783