File: datasets/aisi_316_L/data/M1/train_74.csv
Time(s),Strain(%),Stress(MPa),Temp(C),Log_SR(s-1)
0.0,0.0,0.0,233.85084107362184,0.18141469588426862
1.3170895371887097e-05,1.9999999999999998e-05,3.6634737499999996,233.85084107362184,0.18141469588426862
1.5278238631389034e-05,2.3199999999999998e-05,4.24962955,233.85084107362184,0.18141469588426862
2.8975969818151618e-05,4.4e-05,8.05964225,233.85084107362184,0.18141469588426862
3.740534285615936e-05,5.68e-05,10.40426545,233.85084107362184,0.18141469588426862
4.214686519003871e-05,6.4e-05,11.723116,233.85084107362184,0.18141469588426862
4.9522566598295494e-05,7.52e-05,13.7746613,233.85084107362184,0.18141469588426862
6.111295452555614e-05,9.279999999999999e-05,16.9985182,233.85084107362184,0.18141469588426862
7.586435734206969e-05,0.0001152,21.101608799999998,233.85084107362184,0.18141469588426862
9.85182973817155e-05,0.0001496,27.40278365,233.85084107362184,0.18141469588426862
0.0001243332523106142,0.00018879999999999998,34.5831922,233.85084107362184,0.18141469588426862
0.0001375041476825013,0.00020879999999999998,38.24666594999999,233.85084107362184,0.18141469588426862
0.0001443530132758826,0.0002192,40.1516723,233.85084107362184,0.18141469588426862
0.00015225555049901485,0.00023119999999999998,42.349756549999995,233.85084107362184,0.18141469588426862
0.00016858746076015485,0.000256,46.892464,233.85084107362184,0.18141469588426862
0.00017385581890890967,0.00026399999999999997,48.35785349999999,233.85084107362184,0.18141469588426862
0.0001780705054279136,0.0002704,49.530165100000005,233.85084107362184,0.18141469588426862
0.00018649987846592133,0.0002832,51.8747883,233.85084107362184,0.18141469588426862
0.00019229507242955166,0.000292,53.48671675,233.85084107362184,0.18141469588426862
0.00020019760965268388,0.00030399999999999996,55.68480099999999,233.85084107362184,0.18141469588426862
0.00021126116176506905,0.0003208,58.76211895,233.85084107362184,0.18141469588426862
0.00022443205713695616,0.0003408,62.425592699999996,233.85084107362184,0.18141469588426862
0.00024550548973197554,0.0003728,68.2871507,233.85084107362184,0.18141469588426862
0.0002491933404361039,0.0003784,69.31292334999999,233.85084107362184,0.18141469588426862
0.00026131056417824005,0.0003968,72.6833192,233.85084107362184,0.18141469588426862
0.0002702667730311233,0.0004104,75.17448135,233.85084107362184,0.18141469588426862
0.00027764247443938007,0.0004216,77.22602665,233.85084107362184,0.18141469588426862
0.00029028653399639165,0.0004408,80.74296145,233.85084107362184,0.18141469588426862
0.0002945012205153955,0.0004472,81.91527305,233.85084107362184,0.18141469588426862
0.0003039842651831542,0.0004616,84.55297415,233.85084107362184,0.18141469588426862
0.0003066184442575317,0.0004656,85.2856689,233.85084107362184,0.18141469588426862
0.00031715516055504133,0.0004816,88.2164479,233.85084107362184,0.18141469588426862
0.00034402378711369106,0.0005224,95.68993435,233.85084107362184,0.18141469588426862
0.0003666777271533368,0.0005568,101.9911092,233.85084107362184,0.18141469588426862
0.000378794950895473,0.0005752,105.36150505,233.85084107362184,0.18141469588426862
0.0003877511597483562,0.0005888,107.8526672,233.85084107362184,0.18141469588426862
0.0004009220551202433,0.0006087999999999999,111.51614095,233.85084107362184,0.18141469588426862
0.00041251244304750393,0.0006263999999999999,114.73999785,233.85084107362184,0.18141469588426862
0.0004225223235301381,0.0006416,117.5242379,233.85084107362184,0.18141469588426862
0.0004293711891235194,0.000652,119.42924425,233.85084107362184,0.18141469588426862
0.00044148841286565553,0.0006703999999999999,122.79964009999999,233.85084107362184,0.18141469588426862
0.0004457030993846594,0.0006768,123.97195169999999,233.85084107362184,0.18141469588426862
0.00046203500964579937,0.0007015999999999999,128.51465915,233.85084107362184,0.18141469588426862
0.00047415223338793553,0.0007199999999999999,131.885055,233.85084107362184,0.18141469588426862
0.0004815279347961923,0.0007312,133.9366003,233.85084107362184,0.18141469588426862
0.00048679629294494717,0.0007392,135.4019898,233.85084107362184,0.18141469588426862
0.0005094502329845929,0.0007735999999999999,141.70316465,233.85084107362184,0.18141469588426862
0.0005126112478738459,0.0007784,142.58239834999998,233.85084107362184,0.18141469588426862
0.000521567456726729,0.000792,145.07356049999999,233.85084107362184,0.18141469588426862
0.0005252553074308575,0.0007976,146.09933315,233.85084107362184,0.18141469588426862
0.0005394798744324955,0.0008192,150.0558848,233.85084107362184,0.18141469588426862
0.000556338620508511,0.0008447999999999999,154.74513119999997,233.85084107362184,0.18141469588426862
0.0005600264712126395,0.0008504,155.77090385,233.85084107362184,0.18141469588426862
0.000573724202399402,0.0008711999999999999,159.58091654999998,233.85084107362184,0.18141469588426862
0.0005763583814737794,0.0008751999999999999,160.3136113,233.85084107362184,0.18141469588426862
0.0005800462321779078,0.0008807999999999999,161.33938394999998,233.85084107362184,0.18141469588426862
0.0005837340828820362,0.0008864,162.3651566,233.85084107362184,0.18141469588426862
0.0005995391573283007,0.0009104,166.7613251,233.85084107362184,0.18141469588426862
0.000622719933182822,0.0009456,173.2090389,233.85084107362184,0.18141469588426862
0.0006364176643695846,0.0009664,177.01905159999998,233.85084107362184,0.18141469588426862
0.0006464275448522188,0.0009816,179.80329165,233.85084107362184,0.18141469588426862
0.0006864670667827556,0.0010424,190.94025184999998,233.85084107362184,0.18141469588426862
0.0006991111263397672,0.0010616,194.45718665,233.85084107362184,0.18141469588426862
0.0007201845589347865,0.0010936,200.31874464999999,233.85084107362184,0.18141469588426862
0.0007323017826769226,0.001112,200.80439586425683,233.85084107362184,0.18141469588426862
0.0007523215436421911,0.0011424,200.99315209633323,233.85084107362184,0.18141469588426862
0.0007586435734206969,0.001152,201.0523509938232,233.85084107362184,0.18141469588426862
0.0007865658716090975,0.0011944,201.31154474803722,233.85084107362184,0.18141469588426862
0.0008007904386107355,0.0012159999999999999,201.4422053957537,233.85084107362184,0.18141469588426862
0.0008165955130570001,0.00124,201.58632683426717,233.85084107362184,0.18141469588426862
0.000820810199576004,0.0012464,201.62457496419086,233.85084107362184,0.18141469588426862
0.0008239712144652568,0.0012511999999999998,201.6532108167548,233.85084107362184,0.18141469588426862
0.0008266053935396343,0.0012552,201.6770413139336,233.85084107362184,0.18141469588426862
0.0008508398410239066,0.001292,201.894909632729,233.85084107362184,0.18141469588426862
0.0008619033931362918,0.0013088,201.9935652610396,233.85084107362184,0.18141469588426862
0.0008750742885081788,0.0013288,202.1103707974885,233.85084107362184,0.18141469588426862
0.0008824499899164357,0.00134,202.17548236087822,233.85084107362184,0.18141469588426862
0.0008924598703990698,0.0013552,202.26350958514456,233.85084107362184,0.18141469588426862
0.0009082649448453343,0.0013792,202.4017199863774,233.85084107362184,0.18141469588426862
0.0009140601388089646,0.001388,202.45216170970545,233.85084107362184,0.18141469588426862
0.000917747989513093,0.0013935999999999998,202.48419606017225,233.85084107362184,0.18141469588426862
0.0009188016611428439,0.0013951999999999999,202.49333950570622,233.85084107362184,0.18141469588426862
0.0009256505267362253,0.0014056,202.55267253512312,233.85084107362184,0.18141469588426862
0.0009319725565147311,0.0014152,202.6072897000932,233.85084107362184,0.18141469588426862
0.0009346067355891085,0.0014192,202.6300041846422,233.85084107362184,0.18141469588426862
0.000950411810035373,0.0014432,202.76577043856926,233.85084107362184,0.18141469588426862
0.0009540996607395013,0.0014487999999999999,202.79732219222151,233.85084107362184,0.18141469588426862
0.0009620021979626337,0.0014608,202.86477337848294,233.85084107362184,0.18141469588426862
0.0009651632128518865,0.0014655999999999998,202.89169330471194,233.85084107362184,0.18141469588426862
0.0009725389142601433,0.0014768,202.95437310216582,233.85084107362184,0.18141469588426862
0.0009746462575196453,0.00148,202.97224752901252,233.85084107362184,0.18141469588426862
0.0009888708245212833,0.0015015999999999999,203.09250808663487,233.85084107362184,0.18141469588426862
0.0009988807050039176,0.0015168,203.1767317824783,233.85084107362184,0.18141469588426862
0.001000461212448544,0.0015191999999999998,203.1900001116666,233.85084107362184,0.18141469588426862
0.0010073100780419253,0.0015295999999999999,203.24740199898116,233.85084107362184,0.18141469588426862
0.0010215346450435634,0.0015512,203.36613722237092,233.85084107362184,0.18141469588426862
0.0010241688241179408,0.0015551999999999999,203.38805428456325,233.85084107362184,0.18141469588426862
0.0010315445255261976,0.0015664,203.44930540822898,233.85084107362184,0.18141469588426862
0.0010447154208980847,0.0015864,203.5582592707454,233.85084107362184,0.18141469588426862
0.001066842525122855,0.00162,203.74010342496305,233.85084107362184,0.18141469588426862
0.001080013420494742,0.00164,203.8476457123071,233.85084107362184,0.18141469588426862
0.0011000331814600105,0.0016703999999999998,204.01013553656955,233.85084107362184,0.18141469588426862
0.0011263749722037846,0.0017104,204.2221915283107,233.85084107362184,0.18141469588426862
0.001136384852686419,0.0017255999999999999,204.30226456263364,233.85084107362184,0.18141469588426862
0.0011427068824649245,0.0017352,204.3526953048554,233.85084107362184,0.18141469588426862
0.0011553509420219362,0.0017544,204.45323152999055,233.85084107362184,0.18141469588426862
0.0011637803150599442,0.0017672,204.52001739249818,233.85084107362184,0.18141469588426862
0.0011758975388020802,0.0017855999999999998,204.61569249581194,233.85084107362184,0.18141469588426862
0.001184326911840088,0.0017984,204.6820224367518,233.85084107362184,0.18141469588426862
0.0012048735086202318,0.0018296,204.84293498715775,233.85084107362184,0.18141469588426862
0.0012133028816582396,0.0018424,204.90864038738033,233.85084107362184,0.18141469588426862
0.0012196249114367454,0.001852,204.95780266916907,233.85084107362184,0.18141469588426862
0.0012370104933276363,0.0018784,205.09248913153291,233.85084107362184,0.18141469588426862
0.001244386194735893,0.0018896,205.14940557853228,233.85084107362184,0.18141469588426862
0.0012591375975524067,0.0019119999999999999,205.26284529650218,233.85084107362184,0.18141469588426862
0.0012849525524813053,0.0019512,205.46012543451172,233.85084107362184,0.18141469588426862
0.001288113567370558,0.001956,205.48417550518693,233.85084107362184,0.18141469588426862
0.0012975966120383168,0.0019703999999999998,205.55618799216666,233.85084107362184,0.18141469588426862
0.0013012844627424453,0.001976,205.5841373823681,233.85084107362184,0.18141469588426862
0.001323938402782091,0.0020104,205.75515367386595,233.85084107362184,0.18141469588426862
0.0013265725818564686,0.0020144,205.77496494821793,233.85084107362184,0.18141469588426862
0.0013365824623391028,0.0020296,205.85010828146903,233.85084107362184,0.18141469588426862
0.0013687194470465072,0.0020783999999999998,206.0898878369422,233.85084107362184,0.18141469588426862
0.0013745146410101376,0.0020872,206.1328920750577,233.85084107362184,0.18141469588426862
0.001390319715456402,0.0021111999999999997,206.24981845325777,233.85084107362184,0.18141469588426862
0.001408758968977044,0.0021392,206.38557937311336,233.85084107362184,0.18141469588426862
0.0014224567001638068,0.00216,206.48598215154433,233.85084107362184,0.18141469588426862
0.00144774481927783,0.0021984,206.67035601990239,233.85084107362184,0.18141469588426862
0.0014572278639455886,0.0022128,206.73917186364403,233.85084107362184,0.18141469588426862
0.0014725061025769775,0.0022359999999999997,206.84967560666328,233.85084107362184,0.18141469588426862
0.0014788281323554835,0.0022456,206.89527039125426,233.85084107362184,0.18141469588426862
0.0014856769979488646,0.0022559999999999998,206.94457904186834,233.85084107362184,0.18141469588426862
0.0014941063709868726,0.0022688,207.0051450824576,233.85084107362184,0.18141469588426862
0.0015004284007653782,0.0022784,207.05048219810902,233.85084107362184,0.18141469588426862
0.0015099114454331368,0.0022928,207.11834843291226,233.85084107362184,0.18141469588426862
0.0015178139826562693,0.0023048,207.17477673886305,233.85084107362184,0.18141469588426862
0.0015299312063984055,0.0023232,207.2610781103478,233.85084107362184,0.18141469588426862
0.0015378337436215376,0.0023352,207.31721803484356,233.85084107362184,0.18141469588426862
0.0015647023701801873,0.002376,207.5072577915558,233.85084107362184,0.18141469588426862
0.0015784001013669498,0.0023967999999999997,207.6036507210083,233.85084107362184,0.18141469588426862
0.0015831416237008292,0.002404,207.6369414217024,233.85084107362184,0.18141469588426862
0.0015852489669603313,0.0024072,207.6517248046279,233.85084107362184,0.18141469588426862
0.0015942051758132145,0.0024208,207.71446886915206,233.85084107362184,0.18141469588426862
0.001608956578629728,0.0024432,207.81751318034952,233.85084107362184,0.18141469588426862
0.0016205469665569886,0.0024608,207.89821831270314,233.85084107362184,0.18141469588426862
0.00162739583215037,0.0024712,207.9458018997816,233.85084107362184,0.18141469588426862
0.0016352983693735024,0.0024832,208.00060910049254,233.85084107362184,0.18141469588426862
0.0016400398917073814,0.0024904,208.03344384235305,233.85084107362184,0.18141469588426862
0.0016432009065966344,0.0024952,208.05531310478932,233.85084107362184,0.18141469588426862
0.00164952293637514,0.0025047999999999997,208.09900247022313,233.85084107362184,0.18141469588426862
0.0016574254735982725,0.0025168,208.15352245248556,233.85084107362184,0.18141469588426862
0.0016595328168577742,0.0025199999999999997,208.16804398058443,233.85084107362184,0.18141469588426862
0.0016648011750065293,0.002528,208.20431637300854,233.85084107362184,0.18141469588426862
0.0016753378913040389,0.002544,208.2767271368035,233.85084107362184,0.18141469588426862
0.0016806062494527938,0.002552,208.3128658988104,233.85084107362184,0.18141469588426862
0.0016911429657503036,0.002568,208.3850111486826,233.85084107362184,0.18141469588426862
0.0017080017118263188,0.0025935999999999997,208.50007997848945,233.85084107362184,0.18141469588426862
0.0017153774132345758,0.0026048,208.55028321139145,233.85084107362184,0.18141469588426862
0.00172538729371721,0.00262,208.6182817234034,233.85084107362184,0.18141469588426862
0.0017274946369767118,0.0026232,208.6325775755676,233.85084107362184,0.18141469588426862
0.001736450845829595,0.0026368,208.69325922697837,233.85084107362184,0.18141469588426862
0.0017411923681634744,0.002644,208.7253353846441,233.85084107362184,0.18141469588426862
0.001753836427720486,0.0026631999999999997,208.81070569808912,233.85084107362184,0.18141469588426862
0.0017643731440179957,0.0026792,208.88166442233418,233.85084107362184,0.18141469588426862
0.0017728025170560035,0.002692,208.93831248176556,233.85084107362184,0.18141469588426862
0.001775436696130381,0.002696,208.9559934447463,233.85084107362184,0.18141469588426862
0.001787553919872517,0.0027144,209.03719446419143,233.85084107362184,0.18141469588426862
0.0017933491138361474,0.0027232,209.07595382492897,233.85084107362184,0.18141469588426862
0.0017970369645402757,0.0027288,209.1005934417031,233.85084107362184,0.18141469588426862
0.0018186372329501706,0.0027616,209.24451715334547,233.85084107362184,0.18141469588426862
0.0018217982478394236,0.0027664,209.26552310658593,233.85084107362184,0.18141469588426862
0.0018286471134328047,0.0027768,209.31098730353852,233.85084107362184,0.18141469588426862
0.0018376033222856879,0.0027903999999999997,209.37034040835297,233.85084107362184,0.18141469588426862
0.001840764337174941,0.0027952,209.39126161325296,233.85084107362184,0.18141469588426862
0.001853935232546828,0.0028152,209.4782829124874,233.85084107362184,0.18141469588426862
0.0018681597995484662,0.0028368,209.57199554659312,233.85084107362184,0.18141469588426862
0.0018744818293269718,0.0028464,209.6135562375636,233.85084107362184,0.18141469588426862
0.0018902869037732365,0.0028704,209.71721951240215,233.85084107362184,0.18141469588426862
0.0018997699484409952,0.0028848,209.77925523347338,233.85084107362184,0.18141469588426862
0.0019182092019616368,0.0029127999999999997,209.89953561322412,233.85084107362184,0.18141469588426862
0.0019319069331483994,0.0029335999999999997,209.98859505475716,233.85084107362184,0.18141469588426862
0.0019434973210756602,0.0029511999999999997,210.06376085988188,233.85084107362184,0.18141469588426862
0.001948765679224415,0.0029592,210.09786932204528,233.85084107362184,0.18141469588426862
0.0019698391118194345,0.0029912,210.23394508286037,233.85084107362184,0.18141469588426862
0.001983536843006197,0.003012,210.32208997893304,233.85084107362184,0.18141469588426862
0.0019903857085995782,0.0030223999999999997,210.36607338112594,233.85084107362184,0.18141469588426862
0.001996180902563209,0.0030312,210.40324402334676,233.85084107362184,0.18141469588426862
0.0020056639472309673,0.0030456,210.46397805975815,233.85084107362184,0.18141469588426862
0.0020341130812342434,0.0030888,210.64551175081874,233.85084107362184,0.18141469588426862
0.002040961946827625,0.0030992,210.68906609633163,233.85084107362184,0.18141469588426862
0.0020625622152375196,0.003132,210.82605791533794,233.85084107362184,0.18141469588426862
0.0020762599464242823,0.0031528,210.91264094045317,233.85084107362184,0.18141469588426862
0.0020852161552771652,0.0031663999999999998,210.96913249574607,233.85084107362184,0.18141469588426862
0.0020925918566854222,0.0031776,211.01558393426137,233.85084107362184,0.18141469588426862
0.00210102122972343,0.0031904,211.06859317669634,233.85084107362184,0.18141469588426862
0.0021036554087978075,0.0031944,211.08514154665227,233.85084107362184,0.18141469588426862
0.002112084781835815,0.0032072,211.1380421053904,233.85084107362184,0.18141469588426862
0.002125255677207702,0.0032272,211.2205346867739,233.85084107362184,0.18141469588426862
0.0021284166920969554,0.003232,211.24030320941242,233.85084107362184,0.18141469588426862
0.0021400070800242157,0.0032496,211.31269003802845,233.85084107362184,0.18141469588426862
0.0021442217665432195,0.0032559999999999998,211.3389745915047,233.85084107362184,0.18141469588426862
0.0021558121544704802,0.0032735999999999998,211.4111534232604,233.85084107362184,0.18141469588426862
0.0021626610200638618,0.003284,211.4537334156254,233.85084107362184,0.18141469588426862
0.0021679293782126165,0.003292,211.486451479968,233.85084107362184,0.18141469588426862
0.0021932174973266394,0.0033304,211.64306858606514,233.85084107362184,0.18141469588426862
0.0022037542136241492,0.0033464,211.7081176730925,233.85084107362184,0.18141469588426862
0.002208495735958029,0.0033536,211.73735017788405,233.85084107362184,0.18141469588426862
0.0022195592880704137,0.0033704,211.8054643343547,233.85084107362184,0.18141469588426862
0.002221666631329916,0.0033736,211.81842343309617,233.85084107362184,0.18141469588426862
0.0022258813178489194,0.0033799999999999998,211.84432725762272,233.85084107362184,0.18141469588426862
0.0022522231085926937,0.00342,212.0057949111067,233.85084107362184,0.18141469588426862
0.002259071974186075,0.0034303999999999997,212.0476556488037,233.85084107362184,0.18141469588426862
0.0022875211081893514,0.0034736,212.22101155347454,233.85084107362184,0.18141469588426862
0.002304379854265367,0.0034992,212.32334423245484,233.85084107362184,0.18141469588426862
0.0023096482124141215,0.0035072,212.35526326188182,233.85084107362184,0.18141469588426862
0.002320711764526507,0.003524,212.4222009456565,233.85084107362184,0.18141469588426862
0.0023275606301198883,0.0035344,212.4635761966659,233.85084107362184,0.18141469588426862
0.0023375705106025223,0.0035496,212.52396240958336,233.85084107362184,0.18141469588426862
0.00234599988364053,0.0035624,212.57473577793948,233.85084107362184,0.18141469588426862
0.0023565365999380396,0.0035784,212.638102546632,233.85084107362184,0.18141469588426862
0.002363912301346296,0.0035895999999999996,212.68239355425482,233.85084107362184,0.18141469588426862
0.002375502689273557,0.0036071999999999996,212.7518849739265,233.85084107362184,0.18141469588426862
0.0023849857339413158,0.0036216,212.8086432880235,233.85084107362184,0.18141469588426862
0.002389727256275195,0.0036287999999999997,212.83698943462224,233.85084107362184,0.18141469588426862
0.0023997371367578293,0.0036439999999999997,212.89675936896091,233.85084107362184,0.18141469588426862
0.0024102738530553387,0.0036599999999999996,212.95957014129783,233.85084107362184,0.18141469588426862
0.0024218642409825995,0.0036775999999999996,213.0285384349981,233.85084107362184,0.18141469588426862
0.002423444748427226,0.0036799999999999997,213.03793321898945,233.85084107362184,0.18141469588426862
0.0024397766586883663,0.0037048,213.13487314332278,233.85084107362184,0.18141469588426862
0.0024492597033561247,0.0037191999999999998,213.19104470456702,233.85084107362184,0.18141469588426862
0.0024682257926916425,0.003748,213.30313401481953,233.85084107362184,0.18141469588426862
0.0024792893448040273,0.0037648,213.3683643223535,233.85084107362184,0.18141469588426862
0.002491933404361039,0.003784,213.44277439951676,233.85084107362184,0.18141469588426862
0.0024972017625097937,0.003792,213.4737351233015,233.85084107362184,0.18141469588426862
0.002511426329511432,0.0038136,213.55720209768546,233.85084107362184,0.18141469588426862
0.0025314460904767005,0.0038439999999999998,213.67436246345574,233.85084107362184,0.18141469588426862
0.002564636746813856,0.0038943999999999997,213.8678089755321,233.85084107362184,0.18141469588426862
0.0025809686570749954,0.003919199999999999,213.96263832664414,233.85084107362184,0.18141469588426862
0.0025994079105956377,0.0039472,214.06942290548352,233.85084107362184,0.18141469588426862
0.0026067836120038947,0.0039584,214.1120539698737,233.85084107362184,0.18141469588426862
0.0026083641194485207,0.0039607999999999996,214.12118307471727,233.85084107362184,0.18141469588426862
0.002621535014820408,0.0039808,214.1971752334658,233.85084107362184,0.18141469588426862
0.002632598566932793,0.0039976,214.26089364671154,233.85084107362184,0.18141469588426862
0.0028491710852487917,0.004326465293058612,215.48791224991243,233.85084107362184,0.18141469588426862
0.003102102862744523,0.004710542108421685,216.87576076841364,233.85084107362184,0.18141469588426862
0.0034435607623637607,0.005229045809161833,218.68122020464034,233.85084107362184,0.18141469588426862
0.0034815005289881205,0.005286657331466294,218.8774189590225,233.85084107362184,0.18141469588426862
0.0038608981952317173,0.005862772554510902,220.7955944707871,233.85084107362184,0.18141469588426862
0.00403795043947873,0.006131626325265053,221.66542951537522,233.85084107362184,0.18141469588426862
0.004202356094850955,0.00638127625525105,222.4599042419022,233.85084107362184,0.18141469588426862
0.0045058742278458325,0.006842168433686738,223.89547727621724,233.85084107362184,0.18141469588426862
0.004746159416466777,0.007207041408281656,225.00538427520448,233.85084107362184,0.18141469588426862
0.004859978716339856,0.007379875975195039,225.52345971156274,233.85084107362184,0.18141469588426862
0.005176143438209521,0.00785997199439888,226.93829952811416,233.85084107362184,0.18141469588426862
0.005315255915832173,0.00807121424284857,227.5501053098917,233.85084107362184,0.18141469588426862
0.00573259334870013,0.00870494098819764,229.34910325995676,233.85084107362184,0.18141469588426862
0.0061372841926933,0.009319463892778556,231.0453952090609,233.85084107362184,0.18141469588426862
0.006314336436940312,0.009588317663532707,231.7737398048075,233.85084107362184,0.18141469588426862
0.006364922792439459,0.009665133026605321,231.98036963938375,233.85084107362184,0.18141469588426862
0.006630501158809977,0.010068413682736548,233.05484493413834,233.85084107362184,0.18141469588426862
0.006870786347430922,0.010433286657331467,234.0126094308304,233.85084107362184,0.18141469588426862
0.006921372702930069,0.010510102020404082,234.2125693556456,233.85084107362184,0.18141469588426862
0.007098424947177081,0.010778955791158232,234.9079843314455,233.85084107362184,0.18141469588426862
0.007199597658175373,0.010932586517303462,235.30232661360034,233.85084107362184,0.18141469588426862
0.007528408968919824,0.011431886377275456,236.56926585018945,233.85084107362184,0.18141469588426862
0.00809750546828522,0.012296059211842368,238.71217563926908,233.85084107362184,0.18141469588426862
0.008274557712532231,0.012564912982596519,239.36676858358445,233.85084107362184,0.18141469588426862
0.008679248556525401,0.013179435887177435,240.84280527016668,233.85084107362184,0.18141469588426862
0.008932180334021133,0.013563512702540508,241.75170761511944,233.85084107362184,0.18141469588426862
0.009071292811643785,0.013774754950990198,242.24732336440158,233.85084107362184,0.18141469588426862
0.00927363823364037,0.014082016403280656,242.96295990853673,233.85084107362184,0.18141469588426862
0.009627742722134394,0.014619723944788958,244.20083935415852,233.85084107362184,0.18141469588426862
0.00994390744400406,0.0150998199639928,245.29116084337946,233.85084107362184,0.18141469588426862
0.01004508015500235,0.015253450690138028,245.63719710102964,233.85084107362184,0.18141469588426862
0.010437124410120735,0.01584876975395079,246.96544208482462,233.85084107362184,0.18141469588426862
0.010588883476618174,0.016079215843168633,247.47435931519038,233.85084107362184,0.18141469588426862
0.010867108431863478,0.016501700340068013,248.40004671475776,233.85084107362184,0.18141469588426862
0.011056807264985275,0.016789757951590316,249.0259037729667,233.85084107362184,0.18141469588426862
0.011094747031609637,0.01684736947389478,249.1505711309547,233.85084107362184,0.18141469588426862
0.011410911753479299,0.017327465493098618,250.1830781294297,233.85084107362184,0.18141469588426862
0.011777662830848112,0.017884376875375075,251.3669098133376,233.85084107362184,0.18141469588426862
0.012093827552717777,0.018364472894578918,252.3759603075745,233.85084107362184,0.18141469588426862
0.012207646852590855,0.0185373074614923,252.7366931407368,233.85084107362184,0.18141469588426862
0.012498518396710947,0.018978995799159834,253.65265674530153,233.85084107362184,0.18141469588426862
0.012700863818707532,0.019286257251450292,254.28495135556437,233.85084107362184,0.18141469588426862
0.013004381951702408,0.019747149429885976,255.22607622901444,233.85084107362184,0.18141469588426862
0.01333319326244686,0.02024644928985797,256.2360124126144,233.85084107362184,0.18141469588426862
0.013788470461939177,0.0209377875575115,257.61849355791577,233.85084107362184,0.18141469588426862
0.013965522706186189,0.021206641328265653,258.15130276658607,233.85084107362184,0.18141469588426862
0.014332273783555,0.02176355271054211,259.2466708783284,233.85084107362184,0.18141469588426862
0.014496679438927225,0.022013202640528105,259.73414368457566,233.85084107362184,0.18141469588426862
0.014951956638419542,0.022704540908181636,261.07294300622186,233.85084107362184,0.18141469588426862
0.015053129349417833,0.022858171634326865,261.36828381329195,233.85084107362184,0.18141469588426862
0.015318707715788353,0.023261452290458094,262.13989338587845,233.85084107362184,0.18141469588426862
0.015609579259908444,0.023703140628125625,262.97902782328805,233.85084107362184,0.18141469588426862
0.015748691737531094,0.023914382876575314,263.378195310967,233.85084107362184,0.18141469588426862
0.01606485645940076,0.024394478895779156,264.28031505370325,233.85084107362184,0.18141469588426862
0.017152463102632406,0.02604600920184037,267.3320539342407,233.85084107362184,0.18141469588426862
0.017228342635881126,0.02616123224644929,267.54210612120715,233.85084107362184,0.18141469588426862
0.01758244712437515,0.026698939787957593,268.517618322341,233.85084107362184,0.18141469588426862
0.017670973246498654,0.026833366673334667,268.76029543656216,233.85084107362184,0.18141469588426862
0.01798713796836832,0.02731346269253851,269.6231554999101,233.85084107362184,0.18141469588426862
0.01812625044599097,0.027524704940988198,270.0009378639635,233.85084107362184,0.18141469588426862
0.018214776568114478,0.027659131826365275,270.24075620365994,233.85084107362184,0.18141469588426862
0.01846770834561021,0.028043208641728348,270.92345946165983,233.85084107362184,0.18141469588426862
0.018670053767606797,0.028350470094018806,271.4670001231099,233.85084107362184,0.18141469588426862
0.018745933300855513,0.028465693138627728,271.67023494763225,233.85084107362184,0.18141469588426862
0.018998865078351242,0.028849769953990797,272.3453791002112,233.85084107362184,0.18141469588426862
0.019036804844975604,0.02890738147629526,272.44634757646537,233.85084107362184,0.18141469588426862
0.019340322977970482,0.029368273654730947,273.2512893366829,233.85084107362184,0.18141469588426862
0.01954266839996707,0.029675535107021405,273.7851818121894,233.85084107362184,0.18141469588426862
0.019846186532961944,0.030136427285457092,274.5819958720869,233.85084107362184,0.18141469588426862
0.020314110321329047,0.030846969393878775,275.8011687153264,233.85084107362184,0.18141469588426862
0.02070615457644743,0.031442288457691536,276.8142281002991,233.85084107362184,0.18141469588426862
0.021287897664687614,0.03232566513302661,278.30379890692177,233.85084107362184,0.18141469588426862
0.021528182853308563,0.03269053810762153,278.9144134844311,233.85084107362184,0.18141469588426862
0.021616708975432063,0.0328249649929986,279.13870599441066,233.85084107362184,0.18141469588426862
0.021743174864179933,0.03301700340068014,279.4585034445325,233.85084107362184,0.18141469588426862
0.021781114630804288,0.033074614922984594,279.55430111559355,233.85084107362184,0.18141469588426862
0.022021399819425233,0.033439487897579515,280.15951541600225,233.85084107362184,0.18141469588426862
0.022337564541294902,0.03391958391678336,280.9519406239029,233.85084107362184,0.18141469588426862
0.022577849729915844,0.034284456891378275,281.5512616852059,233.85084107362184,0.18141469588426862
0.022767548563037643,0.03457251450290058,282.02265456171824,233.85084107362184,0.18141469588426862
0.022982540573909013,0.03489897979595919,282.55505199770573,233.85084107362184,0.18141469588426862
0.02314694622928124,0.035148629725945194,282.9608699110625,233.85084107362184,0.18141469588426862
0.023551637073274415,0.03576315263052611,283.9550464398165,233.85084107362184,0.18141469588426862
0.023652809784272706,0.03591678335667134,284.20254681233644,233.85084107362184,0.18141469588426862
0.02381721543964493,0.036166433286657335,284.6038561438322,233.85084107362184,0.18141469588426862
0.02417131992813895,0.03670414082816563,285.46456361041146,233.85084107362184,0.18141469588426862
0.024310432405761605,0.03691538307661532,285.801351521003,233.85084107362184,0.18141469588426862
0.024664536894255632,0.03745309061812363,286.6552557829125,233.85084107362184,0.18141469588426862
0.024816295960753066,0.03768353670734147,287.0197496375363,233.85084107362184,0.18141469588426862
0.025170400449247097,0.038221244248849776,287.86687131715246,233.85084107362184,0.18141469588426862
0.02536009928236889,0.038509301860372075,288.31877401745203,233.85084107362184,0.18141469588426862
0.025562444704365476,0.03881656331266253,288.7993529097664,233.85084107362184,0.18141469588426862
0.025828023070735992,0.03921984396879376,289.4278672134802,233.85084107362184,0.18141469588426862
0.026422412747850958,0.040122424484896974,290.8254800923883,233.85084107362184,0.18141469588426862
0.02651093886997447,0.04025685137027406,291.0325813385308,233.85084107362184,0.18141469588426862
0.026763870647470198,0.040640928185637124,291.62281824637313,233.85084107362184,0.18141469588426862
0.027143268313713796,0.041217043408681736,292.50411094842707,233.85084107362184,0.18141469588426862
0.027358260324585174,0.04154350870174035,293.0013774125265,233.85084107362184,0.18141469588426862
0.0276111921020809,0.04192758551710342,293.5844498361298,233.85084107362184,0.18141469588426862
0.028192935190321084,0.04281096219243849,294.9176681070536,233.85084107362184,0.18141469588426862
0.028648212389813396,0.043502300460092014,295.9535864836958,233.85084107362184,0.18141469588426862
0.028686152156437758,0.043559911982396476,296.03962213412007,233.85084107362184,0.18141469588426862
0.0293058350113023,0.04450090018003601,297.4386490500745,233.85084107362184,0.18141469588426862
0.029419654311175377,0.044673734746949384,297.69435409196217,233.85084107362184,0.18141469588426862
0.02955876678879803,0.044884976995399076,298.0063591279029,233.85084107362184,0.18141469588426862
0.02959670655542239,0.04494258851770354,298.091351954432,233.85084107362184,0.18141469588426862
0.029735819033045043,0.04515383076615323,298.40262944802765,233.85084107362184,0.18141469588426862
0.029811698566293766,0.045269053810762155,298.57217777623504,233.85084107362184,0.18141469588426862
0.030406088243408732,0.04617163432686537,299.8945327065336,233.85084107362184,0.18141469588426862
0.030823425676276692,0.046805361072214446,300.81697683743323,233.85084107362184,0.18141469588426862
0.03121546993139507,0.047400680136027204,301.6790880705656,233.85084107362184,0.18141469588426862
0.031341935820142934,0.04759271854370874,301.9562863187267,233.85084107362184,0.18141469588426862
0.03153163465326474,0.04788077615523105,302.37126718572074,233.85084107362184,0.18141469588426862
0.03180985960851004,0.04830326065213042,302.9781488619584,233.85084107362184,0.18141469588426862
0.03198691185275705,0.048572114422884574,303.363268682187,233.85084107362184,0.18141469588426862
0.03249277540774852,0.04934026805361072,304.45905656189746,233.85084107362184,0.18141469588426862
0.032606594707621596,0.04951310262052411,304.7046895596096,233.85084107362184,0.18141469588426862
0.03302393214048955,0.05014682936587317,305.60249711317374,233.85084107362184,0.18141469588426862
0.03337803662898358,0.05068453690738148,306.3608085396032,233.85084107362184,0.18141469588426862
0.033529795695481014,0.050914982996599314,306.68483797145274,233.85084107362184,0.18141469588426862
0.03380802065072632,0.0513374674934987,307.2774102834814,233.85084107362184,0.18141469588426862
0.03393448653947418,0.05152950590118023,307.5461323116795,233.85084107362184,0.18141469588426862
0.03412418537259599,0.051817563512702544,307.94848419296534,233.85084107362184,0.18141469588426862
0.03435182397234214,0.052163232646529306,308.4301568259835,233.85084107362184,0.18141469588426862
0.03460475574983788,0.052547309461892386,308.96389101329635,233.85084107362184,0.18141469588426862
0.03468063528308659,0.0526625325065013,309.12371430494557,233.85084107362184,0.18141469588426862
0.03474386822746053,0.052758551710342064,309.256796230929,233.85084107362184,0.18141469588426862
0.03484504093845882,0.05291218243648729,309.46953100404295,233.85084107362184,0.18141469588426862
0.035502663559947724,0.05391078215643129,310.8464814959384,233.85084107362184,0.18141469588426862
0.03567971580419474,0.05417963592718544,311.2154948040652,233.85084107362184,0.18141469588426862
0.03600852711493919,0.054678935787157434,311.8989160945866,233.85084107362184,0.18141469588426862
0.036097053237062686,0.054813362672534505,312.08249774208923,233.85084107362184,0.18141469588426862
0.03643851113668193,0.055331866373274655,312.78895968533243,233.85084107362184,0.18141469588426862
0.03666614973642808,0.05567753550710142,313.258500484998,233.85084107362184,0.18141469588426862
0.037172013291419545,0.05644568913782756,314.29787320571285,233.85084107362184,0.18141469588426862
0.03729847918016742,0.05663772754550911,314.5568526477289,233.85084107362184,0.18141469588426862
0.037538764368788356,0.057002600520104016,315.0479720545934,233.85084107362184,0.18141469588426862
0.037981394979405884,0.057674734946989395,315.94946822872953,233.85084107362184,0.18141469588426862
0.038183740401402474,0.05798199639927985,316.3602151909378,233.85084107362184,0.18141469588426862
0.03885400961176616,0.058999799959991994,317.71479146837197,233.85084107362184,0.18141469588426862
0.0391069413892619,0.059383876775355074,318.2235800479285,233.85084107362184,0.18141469588426862
0.03929664022238369,0.05967193438687737,318.6043296977116,233.85084107362184,0.18141469588426862
0.03938516634450721,0.05980636127225446,318.78176749171837,233.85084107362184,0.18141469588426862
0.039448399288881136,0.059902380476095224,318.90841355629334,233.85084107362184,0.18141469588426862
0.03963809812200293,0.06019043808761752,319.2878775709974,233.85084107362184,0.18141469588426862
0.03982779695512473,0.06047849569913982,319.6666339922533,233.85084107362184,0.18141469588426862
0.03994161625499781,0.06065133026605321,319.89355014938496,233.85084107362184,0.18141469588426862
0.04006808214374567,0.06084336867373474,320.1453836467197,233.85084107362184,0.18141469588426862
0.040321013921241405,0.06122744548909782,320.6481225844917,233.85084107362184,0.18141469588426862
0.04059923887648671,0.06164992998599721,321.19971698702534,233.85084107362184,0.18141469588426862
0.04086481724285723,0.06205321064212843,321.7248653135006,233.85084107362184,0.18141469588426862
0.041067162664853815,0.06236047209441889,322.12408541643754,233.85084107362184,0.18141469588426862
0.041345387620099115,0.06278295659131826,322.6717627228125,233.85084107362184,0.18141469588426862
0.04159831939759485,0.06316703340668134,323.16840518017716,233.85084107362184,0.18141469588426862
0.04212947613033589,0.06397359471894379,324.2075372042045,233.85084107362184,0.18141469588426862
0.04234446814120726,0.0643000600120024,324.6266841634739,233.85084107362184,0.18141469588426862
0.042458287441080336,0.06447289457891578,324.8482494504605,233.85084107362184,0.18141469588426862
0.04267327945195171,0.0647993598719744,325.26613066942866,233.85084107362184,0.18141469588426862
0.043229729362442314,0.06564432886577315,326.3439105749921,233.85084107362184,0.18141469588426862
0.04345736796218848,0.06598999799959993,326.7832594934229,233.85084107362184,0.18141469588426862
0.043899998572806014,0.0666621324264853,327.6349881501161,233.85084107362184,0.18141469588426862
0.04403911105042867,0.066873374674935,327.901981721163,233.85084107362184,0.18141469588426862
0.044380568950047904,0.06739187837567515,328.55593886584984,233.85084107362184,0.18141469588426862
0.044544974605420125,0.06764152830566114,328.8701070240897,233.85084107362184,0.18141469588426862
0.04535435629340647,0.06887057411482297,330.41023624647676,233.85084107362184,0.18141469588426862
0.04551876194877869,0.06912022404480897,330.72176109137814,233.85084107362184,0.18141469588426862
0.045695814193025694,0.06938907781556311,331.0567590448815,233.85084107362184,0.18141469588426862
0.04580963349289878,0.0695619123824765,331.27184759167216,233.85084107362184,0.18141469588426862
0.04618903115914238,0.07013802760552111,331.9873089019554,233.85084107362184,0.18141469588426862
0.0464546095255129,0.07054130826165234,332.4867687189001,233.85084107362184,0.18141469588426862
0.04656842882538598,0.07071414282856572,332.7004818912123,233.85084107362184,0.18141469588426862
0.046859300369506064,0.07115583116623325,333.245714325353,233.85084107362184,0.18141469588426862
0.04707429238037744,0.07148229645929187,333.6478642471856,233.85084107362184,0.18141469588426862
0.04732722415787317,0.07186637327465493,334.1200659015731,233.85084107362184,0.18141469588426862
0.047554862757619325,0.0722120424084817,334.544206561374,233.85084107362184,0.18141469588426862
0.047618095701993254,0.07230806161232246,334.6618827937655,233.85084107362184,0.18141469588426862
0.04769397523524198,0.07242328465693139,334.8030138583921,233.85084107362184,0.18141469588426862
0.047820441123989844,0.07261532306461292,335.03803785828234,233.85084107362184,0.18141469588426862
0.048465417156603956,0.07359471894378876,336.2329104111821,233.85084107362184,0.18141469588426862
0.048629822811976184,0.07384436887377475,336.53649190536623,233.85084107362184,0.18141469588426862
0.049047160244844144,0.07447809561912383,337.30532967374097,233.85084107362184,0.18141469588426862
0.0491862727224668,0.07468933786757352,337.5610414059392,233.85084107362184,0.18141469588426862
0.049375971555588594,0.07497739547909582,337.9092851331946,233.85084107362184,0.18141469588426862
0.04961625674420954,0.07534226845369074,338.34964570682257,233.85084107362184,0.18141469588426862
0.049793308988456554,0.0756111222244449,338.6735898981759,233.85084107362184,0.18141469588426862
0.05004624076595228,0.07599519903980796,339.1355891304329,233.85084107362184,0.18141469588426862
0.05010947371032621,0.07609121824364873,339.25094654387675,233.85084107362184,0.18141469588426862
0.050375052076696736,0.07649449889977997,339.7348290391278,233.85084107362184,0.18141469588426862
0.050767096331815115,0.07708981796359272,340.44731737856563,233.85084107362184,0.18141469588426862
0.050969441753811705,0.07739707941588318,340.8142135256244,233.85084107362184,0.18141469588426862
0.051083261053684784,0.07756991398279657,341.0203429661962,233.85084107362184,0.18141469588426862
0.05119708035355786,0.07774274854970994,341.2262933652806,233.85084107362184,0.18141469588426862
0.051361486008930084,0.07799239847969594,341.52346230980675,233.85084107362184,0.18141469588426862
0.051462658719928375,0.07814602920584117,341.70615112508943,233.85084107362184,0.18141469588426862
0.05166500414192496,0.07845329065813163,342.07110908558496,233.85084107362184,0.18141469588426862
0.051816763208422406,0.07868373674734948,342.3444618432903,233.85084107362184,0.18141469588426862
0.052044401808168564,0.07902940588117624,342.7539062807233,233.85084107362184,0.18141469588426862
0.05215822110804164,0.07920224044808963,342.95836654045655,233.85084107362184,0.18141469588426862
0.052360566530038226,0.07950950190038009,343.3214223191171,233.85084107362184,0.18141469588426862
0.05271467101853225,0.08004720944188838,343.9554560370877,233.85084107362184,0.18141469588426862
0.053018189151527124,0.08050810162032407,344.4975926004497,233.85084107362184,0.18141469588426862
0.053448173173269865,0.08116103220644129,345.2635519835719,233.85084107362184,0.18141469588426862
0.053637872006391675,0.0814490898179636,345.60071084983156,233.85084107362184,0.18141469588426862
0.05373904471738997,0.08160272054410883,345.7803387467293,233.85084107362184,0.18141469588426862
0.05391609696163697,0.08187157431486297,346.0943705294092,233.85084107362184,0.18141469588426862
0.05421961509463185,0.08233246649329866,346.6317766523816,233.85084107362184,0.18141469588426862
0.05429549462788057,0.08244768953790758,346.7659447036541,233.85084107362184,0.18141469588426862
0.05447254687212758,0.08271654330866174,347.0787194316157,233.85084107362184,0.18141469588426862
0.05466224570524938,0.08300460092018404,347.4133955664444,233.85084107362184,0.18141469588426862
0.05475077182737289,0.08313902780556112,347.5694227190978,233.85084107362184,0.18141469588426862
0.055003703604868615,0.08352310462092419,348.0146733636401,233.85084107362184,0.18141469588426862
0.056053370481475906,0.08511702340468094,349.8539946411216,233.85084107362184,0.18141469588426862
0.05621777613684813,0.08536667333466694,350.1408598503254,233.85084107362184,0.18141469588426862
0.056470707914343866,0.08575075015003002,350.58155289865425,233.85084107362184,0.18141469588426862
0.05666040674746566,0.08603880776155232,350.91156767769814,233.85084107362184,0.18141469588426862
0.056748932869589166,0.08617323464692939,351.0654270829258,233.85084107362184,0.18141469588426862
0.057191563480206695,0.08684536907381477,351.8333244889262,233.85084107362184,0.18141469588426862
0.057280089602330206,0.08697979595919185,351.9866254533272,233.85084107362184,0.18141469588426862
0.05736861572445371,0.08711422284456892,352.1398340444034,233.85084107362184,0.18141469588426862
0.057937712223819104,0.08797839567913583,353.1225539884802,233.85084107362184,0.18141469588426862
0.05801359175706783,0.08809361872374476,353.25329829759175,233.85084107362184,0.18141469588426862
0.05840563601218621,0.08868893778755751,353.9277510417173,233.85084107362184,0.18141469588426862
0.05867121437855672,0.08909221844368874,354.38363553539625,233.85084107362184,0.18141469588426862
0.058747093911805444,0.08920744148829766,354.51374033649967,233.85084107362184,0.18141469588426862
0.0588862063894281,0.08941868373674736,354.7520957148172,233.85084107362184,0.18141469588426862
0.05896208592267682,0.08953390678135628,354.88201517512954,233.85084107362184,0.18141469588426862
0.05908855181142468,0.08972594518903781,355.09840279956074,233.85084107362184,0.18141469588426862
0.059265604055671696,0.08999479895979197,355.40104227772736,233.85084107362184,0.18141469588426862
0.05955647559979178,0.0904364872974595,355.8974713518526,233.85084107362184,0.18141469588426862
0.05967029489966487,0.09060932186437289,356.09146870144235,233.85084107362184,0.18141469588426862
0.05993587326603538,0.09101260252050411,356.5435688178698,233.85084107362184,0.18141469588426862
0.060340564110028555,0.09162712542508503,357.2309838605612,233.85084107362184,0.18141469588426862
0.06037850387665292,0.09168473694738949,357.2953366969659,233.85084107362184,0.18141469588426862
0.06059349588752428,0.09201120224044809,357.6597053235834,233.85084107362184,0.18141469588426862
0.06068202200964779,0.09214562912582518,357.80959287427766,233.85084107362184,0.18141469588426862
0.0610487730870166,0.09270254050810163,358.429649283471,233.85084107362184,0.18141469588426862
0.06127641168676276,0.09304820964192839,358.81378127101243,233.85084107362184,0.18141469588426862
0.061693749119630714,0.09368193638727745,359.5165808919686,233.85084107362184,0.18141469588426862
0.06175698206400465,0.09377795559111823,359.62290371773094,233.85084107362184,0.18141469588426862
0.062275492207870896,0.09456531306261252,360.49315517527,233.85084107362184,0.18141469588426862
0.06240195809661876,0.09475735147029406,360.70498240196696,233.85084107362184,0.18141469588426862
0.06274341599623799,0.09527585517103421,361.2760812835755,233.85084107362184,0.18141469588426862
0.0630216409514833,0.09569833966793359,361.7405254386992,233.85084107362184,0.18141469588426862
0.06335045226222775,0.09619763952790558,362.2883842861009,233.85084107362184,0.18141469588426862
0.06346427156210084,0.09637047409481897,362.47776920464764,233.85084107362184,0.18141469588426862
0.06354015109534956,0.0964856971394279,362.603952231435,233.85084107362184,0.18141469588426862
0.06366661698409742,0.09667773554710943,362.814126758686,233.85084107362184,0.18141469588426862
0.06384366922834443,0.09694658931786358,363.10809776634784,233.85084107362184,0.18141469588426862
0.06412189418358974,0.09736907381476295,363.5694106437023,233.85084107362184,0.18141469588426862
0.06431159301671154,0.09765713142628527,363.88349466545793,233.85084107362184,0.18141469588426862
0.06460246456083163,0.0980988197639528,364.36438932381134,233.85084107362184,0.18141469588426862
0.06466569750520555,0.09819483896779356,364.4688198161712,233.85084107362184,0.18141469588426862
0.06470363727182991,0.09825245049009802,364.5314589955198,233.85084107362184,0.18141469588426862
0.06494392246045086,0.09861732346469294,364.9278416723957,233.85084107362184,0.18141469588426862
0.0652853803600701,0.0991358271654331,365.490139830068,233.85084107362184,0.18141469588426862
0.06556360531531541,0.09955831166233248,365.94746114486145,233.85084107362184,0.18141469588426862
0.06574065755956242,0.09982716543308662,366.2380897721576,233.85084107362184,0.18141469588426862
0.06581653709281114,0.09994238847769554,366.3625514334691,233.85084107362184,0.18141469588426862