File: datasets/aisi_316_L/data/M1/train_69.csv
Time(s),Strain(%),Stress(MPa),Temp(C),Log_SR(s-1)
0.0,0.0,0.0,240.4750317219981,1.6924403240159434
2.11150938117967e-07,1.0399999999999999e-05,1.8993355874999998,240.4750317219981,1.6924403240159434
5.035137755120752e-07,2.48e-05,4.5291848625,240.4750317219981,1.6924403240159434
7.309070934852705e-07,3.6e-05,6.5746231875,240.4750317219981,1.6924403240159434
1.3806022876943998e-06,6.8e-05,12.4187326875,240.4750317219981,1.6924403240159434
1.8029041639303337e-06,8.879999999999999e-05,16.2174038625,240.4750317219981,1.6924403240159434
2.2089636603110392e-06,0.00010879999999999999,19.869972299999997,240.4750317219981,1.6924403240159434
2.809931714954484e-06,0.0001384,25.2757735875,240.4750317219981,1.6924403240159434
3.1997488314799613e-06,0.00015759999999999998,28.782239287499998,240.4750317219981,1.6924403240159434
3.557081188294983e-06,0.0001752,31.9964995125,240.4750317219981,1.6924403240159434
3.7844745062681782e-06,0.0001864,34.0419378375,240.4750317219981,1.6924403240159434
4.466654460187764e-06,0.00021999999999999998,40.1782528125,240.4750317219981,1.6924403240159434
5.035137755120752e-06,0.000248,45.291848625,240.4750317219981,1.6924403240159434
5.4574396313566855e-06,0.0002688,49.090519799999996,240.4750317219981,1.6924403240159434
5.554893910488055e-06,0.0002736,49.967136225,240.4750317219981,1.6924403240159434
6.090892445710587e-06,0.0003,54.788526562499996,240.4750317219981,1.6924403240159434
6.43198242267038e-06,0.0003168,57.85668405,240.4750317219981,1.6924403240159434
6.838041919051086e-06,0.0003368,61.5092524875,240.4750317219981,1.6924403240159434
7.3090709348527045e-06,0.00035999999999999997,65.74623187499999,240.4750317219981,1.6924403240159434
7.845069470075236e-06,0.00038639999999999996,70.5676222125,240.4750317219981,1.6924403240159434
7.99125088877229e-06,0.00039359999999999997,71.88254685,240.4750317219981,1.6924403240159434
8.299856106021626e-06,0.00040879999999999996,74.6584988625,240.4750317219981,1.6924403240159434
8.575976563560507e-06,0.00042239999999999997,77.1422454,240.4750317219981,1.6924403240159434
9.01452081965167e-06,0.000444,81.0870193125,240.4750317219981,1.6924403240159434
9.599246494439886e-06,0.0004728,86.3467178625,240.4750317219981,1.6924403240159434
9.696700773571253e-06,0.00047759999999999995,87.2233342875,240.4750317219981,1.6924403240159434
9.842882192268308e-06,0.00048479999999999997,88.538258925,240.4750317219981,1.6924403240159434
1.0362638347635612e-05,0.0005103999999999999,93.21354652499998,240.4750317219981,1.6924403240159434
1.0573789285753578e-05,0.0005208,95.11288211249999,240.4750317219981,1.6924403240159434
1.0882394503002916e-05,0.000536,97.888834125,240.4750317219981,1.6924403240159434
1.102857592169997e-05,0.0005432,99.2037587625,240.4750317219981,1.6924403240159434
1.1223484479962708e-05,0.0005528,100.9569916125,240.4750317219981,1.6924403240159434
1.1515847317356817e-05,0.0005672,103.5868408875,240.4750317219981,1.6924403240159434
1.1791967774895698e-05,0.0005808,106.070587425,240.4750317219981,1.6924403240159434
1.2344208689973455e-05,0.0006079999999999999,111.03808049999999,240.4750317219981,1.6924403240159434
1.2571602007946652e-05,0.0006192,113.083518825,240.4750317219981,1.6924403240159434
1.2847722465485532e-05,0.0006328,115.5672653625,240.4750317219981,1.6924403240159434
1.304263102374827e-05,0.0006424,117.3204982125,240.4750317219981,1.6924403240159434
1.3611114318681258e-05,0.0006703999999999999,122.434094025,240.4750317219981,1.6924403240159434
1.3854750016509683e-05,0.0006824,124.6256350875,240.4750317219981,1.6924403240159434
1.442323331144267e-05,0.0007103999999999999,129.7392309,240.4750317219981,1.6924403240159434
1.4601899489850179e-05,0.0007191999999999999,131.34636101249998,240.4750317219981,1.6924403240159434
1.5170382784783168e-05,0.0007472,136.45995682499998,240.4750317219981,1.6924403240159434
1.5381533722901135e-05,0.0007576,138.3592924125,240.4750317219981,1.6924403240159434
1.5495230381887734e-05,0.0007632,139.382011575,240.4750317219981,1.6924403240159434
1.5803835599137068e-05,0.0007784,142.15796358749998,240.4750317219981,1.6924403240159434
1.6014986537255038e-05,0.0007888,144.057299175,240.4750317219981,1.6924403240159434
1.617741033580732e-05,0.0007968,145.51832654999998,240.4750317219981,1.6924403240159434
1.635607651421483e-05,0.0008056,147.1254566625,240.4750317219981,1.6924403240159434
1.7054498847989642e-05,0.0008399999999999999,153.40787437499998,240.4750317219981,1.6924403240159434
1.72006802666867e-05,0.0008472,154.7227990125,240.4750317219981,1.6924403240159434
1.7899102600461512e-05,0.0008816,161.005216725,240.4750317219981,1.6924403240159434
1.8158980678145164e-05,0.0008944,163.342860525,240.4750317219981,1.6924403240159434
1.856504017452587e-05,0.0009144,166.9954289625,240.4750317219981,1.6924403240159434
1.8743706352933382e-05,0.0009232,168.602559075,240.4750317219981,1.6924403240159434
1.9133523469458858e-05,0.0009423999999999999,172.109024775,240.4750317219981,1.6924403240159434
1.9393401547142507e-05,0.0009551999999999999,174.446668575,240.4750317219981,1.6924403240159434
1.9604552485260477e-05,0.0009655999999999999,176.34600416249998,240.4750317219981,1.6924403240159434
1.9637037244970934e-05,0.0009672,176.63820963749998,240.4750317219981,1.6924403240159434
1.9766976283812758e-05,0.0009735999999999999,177.8070315375,240.4750317219981,1.6924403240159434
2.0059339121206867e-05,0.000988,180.4368808125,240.4750317219981,1.6924403240159434
2.0400429098166658e-05,0.0010048,183.5050383,240.4750317219981,1.6924403240159434
2.057909527657417e-05,0.0010136,185.11216841249998,240.4750317219981,1.6924403240159434
2.1017639532665333e-05,0.0010352,189.056942325,240.4750317219981,1.6924403240159434
2.1212548090928074e-05,0.0010448,190.810175175,240.4750317219981,1.6924403240159434
2.1391214269335584e-05,0.0010536,192.4173052875,240.4750317219981,1.6924403240159434
2.2154606122531308e-05,0.0010911999999999999,199.28413394999998,240.4750317219981,1.6924403240159434
2.2381999440504503e-05,0.0011024,201.32957227499998,240.4750317219981,1.6924403240159434
2.259315037862247e-05,0.0011128,203.2289078625,240.4750317219981,1.6924403240159434
2.2771816557029982e-05,0.0011216,204.83603797499998,240.4750317219981,1.6924403240159434
2.334029985196297e-05,0.0011496,205.96345819999127,240.4750317219981,1.6924403240159434
2.360017792964662e-05,0.0011623999999999998,206.04408353458882,240.4750317219981,1.6924403240159434
2.3762601728198905e-05,0.0011704,206.0942985767992,240.4750317219981,1.6924403240159434
2.3908783146895958e-05,0.0011776,206.13937777890612,240.4750317219981,1.6924403240159434
2.413617646486915e-05,0.0011887999999999998,206.2092879124572,240.4750317219981,1.6924403240159434
2.434732740298712e-05,0.0011991999999999999,206.27397480800758,240.4750317219981,1.6924403240159434
2.4412296922408033e-05,0.0012024,206.29383440339112,240.4750317219981,1.6924403240159434
2.4574720720960314e-05,0.0012104,206.34339342376532,240.4750317219981,1.6924403240159434
2.470465975980214e-05,0.0012167999999999999,206.38294872427429,240.4750317219981,1.6924403240159434
2.5029507356906708e-05,0.0012328,206.4814836401907,240.4750317219981,1.6924403240159434
2.5321870194300813e-05,0.0012472,206.56973944318742,240.4750317219981,1.6924403240159434
2.5516778752563555e-05,0.0012568,206.6283559636161,240.4750317219981,1.6924403240159434
2.5662960171260608e-05,0.001264,206.67220382898503,240.4750317219981,1.6924403240159434
2.580914158995766e-05,0.0012711999999999999,206.71595439297823,240.4750317219981,1.6924403240159434
2.590659586908903e-05,0.001276,206.74506775762472,240.4750317219981,1.6924403240159434
2.6783684381271355e-05,0.0013192,207.00519366441551,240.4750317219981,1.6924403240159434
2.7319682916493887e-05,0.0013456,207.16252462262833,240.4750317219981,1.6924403240159434
2.7660772893453678e-05,0.0013624,207.26201782868986,240.4750317219981,1.6924403240159434
2.7904408591282105e-05,0.0013744,207.3327916781238,240.4750317219981,1.6924403240159434
2.7936893350992558e-05,0.0013759999999999998,207.3422099499783,240.4750317219981,1.6924403240159434
2.8164286668965753e-05,0.0013871999999999999,207.40801867451535,240.4750317219981,1.6924403240159434
2.837543760708372e-05,0.0013976,207.4689414715081,240.4750317219981,1.6924403240159434
2.857034616534646e-05,0.0014072,207.5250211562368,240.4750317219981,1.6924403240159434
2.915507184013468e-05,0.001436,207.69237174135023,240.4750317219981,1.6924403240159434
2.949616181709447e-05,0.0014528,207.7893884204661,240.4750317219981,1.6924403240159434
2.9772282274633347e-05,0.0014663999999999999,207.86760565729472,240.4750317219981,1.6924403240159434
3.012961463144837e-05,0.0014839999999999999,207.96840927638388,240.4750317219981,1.6924403240159434
3.0178341771014055e-05,0.0014864,207.98211901116852,240.4750317219981,1.6924403240159434
3.029203843000065e-05,0.0014919999999999998,208.01407486293226,240.4750317219981,1.6924403240159434
3.040573508898725e-05,0.0014976,208.0459839715861,240.4750317219981,1.6924403240159434
3.0568158887539535e-05,0.0015056,208.09148780838396,240.4750317219981,1.6924403240159434
3.107167266305161e-05,0.0015304,208.23195413369666,240.4750317219981,1.6924403240159434
3.146148977957709e-05,0.0015496,208.34009344149368,240.4750317219981,1.6924403240159434
3.178633737668165e-05,0.0015655999999999999,208.42981093143305,240.4750317219981,1.6924403240159434
3.190003403566825e-05,0.0015712,208.46112748057257,240.4750317219981,1.6924403240159434
3.198124593494439e-05,0.0015752,208.48346979873074,240.4750317219981,1.6924403240159434
3.2273608772338496e-05,0.0015895999999999998,208.56371958241257,240.4750317219981,1.6924403240159434
3.27933649277058e-05,0.0016152,208.705689299498,240.4750317219981,1.6924403240159434
3.297203110611331e-05,0.001624,208.75428835679722,240.4750317219981,1.6924403240159434
3.328063632336265e-05,0.0016392,208.83799096876993,240.4750317219981,1.6924403240159434
3.401154341684792e-05,0.0016752,209.03503569805648,240.4750317219981,1.6924403240159434
3.41739672154002e-05,0.0016832,209.07859833659424,240.4750317219981,1.6924403240159434
3.4336391013952483e-05,0.0016912,209.12208030132433,240.4750317219981,1.6924403240159434
3.470996575062273e-05,0.0017096,209.22178553531123,240.4750317219981,1.6924403240159434
3.5034813347727294e-05,0.0017255999999999999,209.30814603659522,240.4750317219981,1.6924403240159434
3.5457115223963234e-05,0.0017464,209.41994924458467,240.4750317219981,1.6924403240159434
3.5700750921791654e-05,0.0017584,209.48421485746135,240.4750317219981,1.6924403240159434
3.609056803831713e-05,0.0017775999999999998,209.58668520681442,240.4750317219981,1.6924403240159434
3.6366688495856014e-05,0.0017912,209.6590073733055,240.4750317219981,1.6924403240159434
3.651286991455306e-05,0.0017984,209.69720886340545,240.4750317219981,1.6924403240159434
3.6821475131802404e-05,0.0018135999999999998,209.77766112828633,240.4750317219981,1.6924403240159434
3.695141417064423e-05,0.00182,209.81145704501463,240.4750317219981,1.6924403240159434
3.7146322728906966e-05,0.0018296,209.8620641461973,240.4750317219981,1.6924403240159434
3.717880748861742e-05,0.0018311999999999998,209.8704885846214,240.4750317219981,1.6924403240159434
3.724377700803834e-05,0.0018344,209.88732885427885,240.4750317219981,1.6924403240159434
3.735747366702493e-05,0.0018399999999999998,209.91677178389213,240.4750317219981,1.6924403240159434
3.7519897465577214e-05,0.0018479999999999998,209.95877256110973,240.4750317219981,1.6924403240159434
3.774729078355041e-05,0.0018591999999999999,210.01745471495474,240.4750317219981,1.6924403240159434
3.794219934181315e-05,0.0018687999999999999,210.06764405696177,240.4750317219981,1.6924403240159434
3.799092648137883e-05,0.0018712,210.08017566908626,240.4750317219981,1.6924403240159434
3.8185835039641574e-05,0.0018808,210.13023955977604,240.4750317219981,1.6924403240159434
3.8429470737469994e-05,0.0018927999999999998,210.1926794983867,240.4750317219981,1.6924403240159434
3.911165069138958e-05,0.0019264,210.36669530104433,240.4750317219981,1.6924403240159434
3.9533952567625516e-05,0.0019471999999999998,210.47382633993777,240.4750317219981,1.6924403240159434
3.96963763661778e-05,0.0019552,210.51491163097643,240.4750317219981,1.6924403240159434
4.018364776183465e-05,0.0019792,210.63777592614588,240.4750317219981,1.6924403240159434
4.037855632009738e-05,0.0019887999999999998,210.68675878458546,240.4750317219981,1.6924403240159434
4.138558387112154e-05,0.0020384,210.9383827445471,240.4750317219981,1.6924403240159434
4.1694189088370874e-05,0.0020536,211.01501380698875,240.4750317219981,1.6924403240159434
4.195406716605452e-05,0.0020664,211.0793738084605,240.4750317219981,1.6924403240159434
4.2181460484027714e-05,0.0020775999999999998,211.13556137447,240.4750317219981,1.6924403240159434
4.312351851563096e-05,0.002124,211.3670910390905,240.4750317219981,1.6924403240159434
4.322097279476232e-05,0.0021287999999999997,211.39092925036118,240.4750317219981,1.6924403240159434
4.354582039186689e-05,0.0021448,211.4702389918556,240.4750317219981,1.6924403240159434
4.380569846955054e-05,0.0021576,211.53352077702974,240.4750317219981,1.6924403240159434
4.4309212245062616e-05,0.0021823999999999997,211.655714129116,240.4750317219981,1.6924403240159434
4.471527174144332e-05,0.0022023999999999998,211.75386315768046,240.4750317219981,1.6924403240159434
4.559236025362565e-05,0.0022456,211.9646865493132,240.4750317219981,1.6924403240159434
4.586848071116453e-05,0.0022592,212.0307287332817,240.4750317219981,1.6924403240159434
4.638823686653183e-05,0.0022848,212.15462433125654,240.4750317219981,1.6924403240159434
4.6501933525518424e-05,0.0022903999999999997,212.18165418927373,240.4750317219981,1.6924403240159434
4.661563018450502e-05,0.002296,212.20865828535247,240.4750317219981,1.6924403240159434
4.759017297581872e-05,0.0023439999999999997,212.43907768220205,240.4750317219981,1.6924403240159434
4.801247485205465e-05,0.0023648,212.53835378415215,240.4750317219981,1.6924403240159434
4.8386049588724905e-05,0.0023832,212.6258914266888,240.4750317219981,1.6924403240159434
4.86134429066981e-05,0.0023944,212.6790461709463,240.4750317219981,1.6924403240159434
4.8727139565684696e-05,0.0024,212.7055871737907,240.4750317219981,1.6924403240159434
4.877586670525038e-05,0.0024024,212.71695449452267,240.4750317219981,1.6924403240159434
4.91331990620654e-05,0.00242,212.80017994254482,240.4750317219981,1.6924403240159434
4.983162139584022e-05,0.0024544,212.9621694010689,240.4750317219981,1.6924403240159434
5.05138013497598e-05,0.0024879999999999998,213.11953903140713,240.4750317219981,1.6924403240159434
5.127719320295553e-05,0.0025256,213.29466368420736,240.4750317219981,1.6924403240159434
5.13746474820869e-05,0.0025304,213.3169466056147,240.4750317219981,1.6924403240159434
5.225173599426922e-05,0.0025735999999999997,213.516756508843,240.4750317219981,1.6924403240159434
5.2706522630215614e-05,0.002596,213.61984641858967,240.4750317219981,1.6924403240159434
5.2820219289202213e-05,0.0026016,213.64556461867767,240.4750317219981,1.6924403240159434
5.3145066886306776e-05,0.0026176,213.71892649430066,240.4750317219981,1.6924403240159434
5.337246020427997e-05,0.0026287999999999997,213.77017578593666,240.4750317219981,1.6924403240159434
5.348615686326657e-05,0.0026344,213.7957684933714,240.4750317219981,1.6924403240159434
5.387597397979204e-05,0.0026536,213.8833542917508,240.4750317219981,1.6924403240159434
5.434700299559367e-05,0.0026768,213.98885807113584,240.4750317219981,1.6924403240159434
5.447694203443549e-05,0.0026831999999999997,214.01789972688815,240.4750317219981,1.6924403240159434
5.491548629052665e-05,0.0027048,214.11571647799744,240.4750317219981,1.6924403240159434
5.511039484878939e-05,0.0027144,214.15909275238388,240.4750317219981,1.6924403240159434
5.5386515306328276e-05,0.002728,214.2204401982437,240.4750317219981,1.6924403240159434
5.642602761706288e-05,0.0027792,214.45033329625997,240.4750317219981,1.6924403240159434
5.67833599738779e-05,0.0027968,214.52897678869232,240.4750317219981,1.6924403240159434
5.705948043141678e-05,0.0028104,214.5896146383755,240.4750317219981,1.6924403240159434
5.803402322273047e-05,0.0028583999999999997,214.80272183658494,240.4750317219981,1.6924403240159434
5.82776589205589e-05,0.0028704,214.85577999862733,240.4750317219981,1.6924403240159434
5.857002175795301e-05,0.0028848,214.91933573939826,240.4750317219981,1.6924403240159434
5.8699960796794835e-05,0.0028912,214.94754300782523,240.4750317219981,1.6924403240159434
5.910602029317554e-05,0.0029112,215.0355341760984,240.4750317219981,1.6924403240159434
5.926844409172782e-05,0.0029192,215.07066459393124,240.4750317219981,1.6924403240159434
5.9528322169411466e-05,0.0029319999999999997,215.12679526583173,240.4750317219981,1.6924403240159434
6.003183594492355e-05,0.0029568,215.2352772285593,240.4750317219981,1.6924403240159434
6.0324198782317654e-05,0.0029712,215.29810391264803,240.4750317219981,1.6924403240159434
6.0502864960725167e-05,0.00298,215.33643954190563,240.4750317219981,1.6924403240159434
6.068153113913267e-05,0.0029888,215.37473104620517,240.4750317219981,1.6924403240159434
6.116880253478953e-05,0.0030128,215.4789395912088,240.4750317219981,1.6924403240159434
6.13312263333418e-05,0.0030207999999999997,215.51360376283924,240.4750317219981,1.6924403240159434
6.175352820957774e-05,0.0030415999999999998,215.60356346705018,240.4750317219981,1.6924403240159434
6.207837580668231e-05,0.0030575999999999997,215.6726000747192,240.4750317219981,1.6924403240159434
6.263061672176006e-05,0.0030848,215.7896398361155,240.4750317219981,1.6924403240159434
6.303667621814077e-05,0.0031048,215.8754418751795,240.4750317219981,1.6924403240159434
6.381631045119173e-05,0.0031432,216.03957994408873,240.4750317219981,1.6924403240159434
6.391376473032309e-05,0.0031479999999999998,216.06004207268163,240.4750317219981,1.6924403240159434
6.433606660655903e-05,0.0031688,216.14857105916016,240.4750317219981,1.6924403240159434
6.444976326554562e-05,0.0031744,216.17236702796535,240.4750317219981,1.6924403240159434
6.51806703590309e-05,0.0032104,216.3249520530122,240.4750317219981,1.6924403240159434
6.555424509570114e-05,0.0032288,216.40268216761564,240.4750317219981,1.6924403240159434
6.563545699497728e-05,0.0032327999999999996,216.4195571368741,240.4750317219981,1.6924403240159434
6.570042651439819e-05,0.0032359999999999997,216.4330512500035,240.4750317219981,1.6924403240159434
6.62689098093312e-05,0.003264,216.5509035768646,240.4750317219981,1.6924403240159434
6.664248454600144e-05,0.0032824,216.62813477179307,240.4750317219981,1.6924403240159434
6.691860500354032e-05,0.003296,216.6851102237858,240.4750317219981,1.6924403240159434
6.716224070136874e-05,0.0033079999999999997,216.73530658451526,240.4750317219981,1.6924403240159434
6.768199685673605e-05,0.0033336,216.8421554217183,240.4750317219981,1.6924403240159434
6.773072399630173e-05,0.003336,216.85215606509294,240.4750317219981,1.6924403240159434
6.784442065528832e-05,0.0033415999999999997,216.87547999403452,240.4750317219981,1.6924403240159434
6.873775154732588e-05,0.0033856,217.05821197987777,240.4750317219981,1.6924403240159434
6.969605195878434e-05,0.0034327999999999997,217.25320691222663,240.4750317219981,1.6924403240159434
6.993968765661277e-05,0.0034448,217.30261483327894,240.4750317219981,1.6924403240159434
7.000465717603367e-05,0.0034479999999999997,217.3157789366479,240.4750317219981,1.6924403240159434
7.016708097458596e-05,0.003456,217.34866836655453,240.4750317219981,1.6924403240159434
7.062186761053235e-05,0.0034784,217.4406011844213,240.4750317219981,1.6924403240159434
7.07680490292294e-05,0.0034855999999999997,217.47010194631022,240.4750317219981,1.6924403240159434
7.130404756445194e-05,0.003512,217.57806867488728,240.4750317219981,1.6924403240159434
7.161265278170127e-05,0.0035272,217.64008775113675,240.4750317219981,1.6924403240159434
7.198622751837153e-05,0.0035456,217.71502419205052,240.4750317219981,1.6924403240159434
7.205119703779245e-05,0.0035488,217.72804111954125,240.4750317219981,1.6924403240159434
7.248974129388361e-05,0.0035704,217.81578595380955,240.4750317219981,1.6924403240159434
7.292828554997476e-05,0.0035919999999999997,217.9033240054891,240.4750317219981,1.6924403240159434
7.323689076722409e-05,0.0036071999999999996,217.96480183425274,240.4750317219981,1.6924403240159434
7.367543502331526e-05,0.0036287999999999997,218.05199155251552,240.4750317219981,1.6924403240159434
7.3870343581578e-05,0.0036384,218.09067754462035,240.4750317219981,1.6924403240159434
7.404900975998551e-05,0.0036471999999999997,218.1261047475034,240.4750317219981,1.6924403240159434
7.432513021752439e-05,0.0036607999999999996,218.1807903782184,240.4750317219981,1.6924403240159434
7.442258449665576e-05,0.0036655999999999998,218.20007226467885,240.4750317219981,1.6924403240159434
7.515349159014103e-05,0.0037015999999999998,218.3443738457489,240.4750317219981,1.6924403240159434
7.581942916420538e-05,0.0037343999999999997,218.47537280935524,240.4750317219981,1.6924403240159434
7.590064106348153e-05,0.0037384,218.49131753694093,240.4750317219981,1.6924403240159434
7.594936820304721e-05,0.0037408,218.50088117980246,240.4750317219981,1.6924403240159434
7.606306486203381e-05,0.0037464,218.52318704538746,240.4750317219981,1.6924403240159434
7.625797342029654e-05,0.003756,218.56139544299302,240.4750317219981,1.6924403240159434
7.677772957566385e-05,0.0037816,218.663098761825,240.4750317219981,1.6924403240159434
7.685894147493999e-05,0.0037855999999999996,218.6789656178378,240.4750317219981,1.6924403240159434
7.73786976303073e-05,0.0038112,218.7803591031673,240.4750317219981,1.6924403240159434
7.763857570799094e-05,0.0038239999999999997,218.83095621511308,240.4750317219981,1.6924403240159434
7.770354522741186e-05,0.0038272,218.8435951672785,240.4750317219981,1.6924403240159434
7.814208948350303e-05,0.0038488,218.92880055093894,240.4750317219981,1.6924403240159434
7.832075566191054e-05,0.0038575999999999997,218.96346036520515,240.4750317219981,1.6924403240159434
7.867808801872555e-05,0.0038751999999999997,219.03268762461454,240.4750317219981,1.6924403240159434
7.918160179423764e-05,0.0039,219.13002736403516,240.4750317219981,1.6924403240159434
7.965263081003926e-05,0.0039232,219.22086880452244,240.4750317219981,1.6924403240159434
8.051347694236634e-05,0.0039656,219.38634987913014,240.4750317219981,1.6924403240159434
8.472095513604244e-05,0.004172834566913383,220.18543365949833,240.4750317219981,1.6924403240159434
9.797738838455839e-05,0.0048257651530306065,222.6073624894551,240.4750317219981,1.6924403240159434
0.00010109654914891508,0.004979395879175836,223.15821582480848,240.4750317219981,1.6924403240159434
0.00010733487067762848,0.005286657331466294,224.24042567351532,240.4750317219981,1.6924403240159434
0.00011201361182416352,0.0055171034206841375,225.0360509563148,240.4750317219981,1.6924403240159434
0.00011630245787515394,0.005728345669133827,225.75405896239934,240.4750317219981,1.6924403240159434
0.0001178620382573323,0.005805161032206441,226.01258274650297,240.4750317219981,1.6924403240159434
0.0001205913039261444,0.005939587917583517,226.4618117940645,240.4750317219981,1.6924403240159434
0.00012955889112366989,0.00638127625525105,227.91069019245342,240.4750317219981,1.6924403240159434
0.00013384773717466035,0.00659251850370074,228.58975411399493,240.4750317219981,1.6924403240159434
0.00013618710774792786,0.006707741548309662,228.95657364492874,240.4750317219981,1.6924403240159434
0.00014983343609198838,0.007379875975195039,231.04930990872356,240.4750317219981,1.6924403240159434
0.0001556818625251572,0.007667933586717343,231.92327636774525,240.4750317219981,1.6924403240159434
0.00015763133800288012,0.007763952790558111,232.2117404959176,240.4750317219981,1.6924403240159434
0.00016153028895832597,0.007955991198239648,232.78452818598322,240.4750317219981,1.6924403240159434
0.0001638696595315935,0.00807121424284857,233.1256130459774,240.4750317219981,1.6924403240159434
0.00017751598787565402,0.008743348669733947,235.07867989640175,240.4750317219981,1.6924403240159434
0.00018336441430882283,0.009031406281256251,235.897676046586,240.4750317219981,1.6924403240159434
0.00019116231621971457,0.009415483096619324,236.97399426093313,240.4750317219981,1.6924403240159434
0.00020714801513704262,0.010202840568113623,239.12832641761472,240.4750317219981,1.6924403240159434
0.00022313371405437062,0.01099019803960792,241.21871194845122,240.4750317219981,1.6924403240159434
0.0002270326650098165,0.011182236447289457,241.7195985708056,240.4750317219981,1.6924403240159434
0.00022937203558308402,0.011297459491898379,242.01852046117475,240.4750317219981,1.6924403240159434
0.00023444067182516368,0.011547109421884378,242.66213580463088,240.4750317219981,1.6924403240159434
0.00025861416774892803,0.012737747549509902,245.65997914237226,240.4750317219981,1.6924403240159434
0.00026992112551972103,0.013294658931786357,247.0244651381192,240.4750317219981,1.6924403240159434
0.00027771902743061274,0.01367873574714943,247.95252667238853,240.4750317219981,1.6924403240159434
0.00028122808329051404,0.013851570314062813,248.36683289678726,240.4750317219981,1.6924403240159434
0.00028941588029695036,0.01425485097019404,249.32578499990825,240.4750317219981,1.6924403240159434
0.0002937047263479408,0.01446609321864373,249.82386719493803,240.4750317219981,1.6924403240159434
0.0003069611595964568,0.015119023804760953,251.34575681846428,240.4750317219981,1.6924403240159434
0.000323726648704874,0.01594478895779156,253.23427226628542,240.4750317219981,1.6924403240159434
0.0003404921378132912,0.016770554110822164,255.0850066394327,240.4750317219981,1.6924403240159434
0.0003603767876860651,0.017749949989998,257.2345954708935,240.4750317219981,1.6924403240159434
0.00037402311603012563,0.018422084416883377,258.68309999811476,240.4750317219981,1.6924403240159434
0.00038182101794101734,0.01880616123224645,259.50156022007974,240.4750317219981,1.6924403240159434
0.0003853300738009187,0.018978995799159834,259.86773780639845,240.4750317219981,1.6924403240159434
0.0003900088149474537,0.019209441888377678,260.3539579471983,240.4750317219981,1.6924403240159434
0.00039585724138062247,0.01949749949989998,260.9585458962994,240.4750317219981,1.6924403240159434
0.0004192509471132977,0.0206497299459892,263.34284981138836,240.4750317219981,1.6924403240159434
0.00042276000297319894,0.02082256451290258,263.6959689478019,240.4750317219981,1.6924403240159434
0.0004313376950751798,0.02124504900980196,264.55437085670485,240.4750317219981,1.6924403240159434
0.00043679622641280407,0.02151390278055611,265.0971619902981,240.4750317219981,1.6924403240159434
0.00044225475775042827,0.02178275655131026,265.6373140602053,240.4750317219981,1.6924403240159434
0.00044537391851478495,0.02193638727745549,265.9448049379331,240.4750317219981,1.6924403240159434
0.00045278192533013215,0.02230126025205041,266.67174915923596,240.4750317219981,1.6924403240159434
0.00047071709972518313,0.02318463692738548,268.41277173391853,240.4750317219981,1.6924403240159434
0.00048241395259152064,0.023760752150430085,269.5342984521761,240.4750317219981,1.6924403240159434
0.00048475332316478815,0.023875975195039006,269.7573256560269,240.4750317219981,1.6924403240159434
0.00048787248392914484,0.024029605921184236,270.05404339714465,240.4750317219981,1.6924403240159434
0.0004952804907444921,0.024394478895779156,270.7557985041301,240.4750317219981,1.6924403240159434
0.0005038581828464729,0.024816963392678536,271.5632631272142,240.4750317219981,1.6924403240159434
0.0005116560847573647,0.02520104020804161,272.29268156847104,240.4750317219981,1.6924403240159434
0.0005178944062860781,0.025508301660332067,272.8730994997096,240.4750317219981,1.6924403240159434
0.0005229630425281576,0.025757951590318063,273.3426839146693,240.4750317219981,1.6924403240159434
0.0005342700002989507,0.02631486297259452,274.3838688681757,240.4750317219981,1.6924403240159434
0.0005412881120187532,0.026660532106421286,275.02580074701683,240.4750317219981,1.6924403240159434
0.000562342447178161,0.027697539507901582,276.93239716907794,240.4750317219981,1.6924403240159434
0.0005666312932291514,0.02790878175635127,277.3173420377036,240.4750317219981,1.6924403240159434
0.0005689706638024189,0.028024004800960192,277.5268329588807,240.4750317219981,1.6924403240159434
0.000594313845012817,0.029272254450890177,279.7751960434802,240.4750317219981,1.6924403240159434
0.0005982127959682629,0.029464292858571713,280.1177506763628,240.4750317219981,1.6924403240159434
0.0006134187046945018,0.030213242648529707,281.445476040491,240.4750317219981,1.6924403240159434
0.0006141984948855909,0.030251650330066014,281.51321639053214,240.4750317219981,1.6924403240159434
0.0006180974458410368,0.03044368873774755,281.8514163233395,240.4750317219981,1.6924403240159434
0.0006219963967964827,0.030635727145429087,282.1887852613832,240.4750317219981,1.6924403240159434
0.0006239458722742055,0.030731746349269853,282.3571603715416,240.4750317219981,1.6924403240159434
0.0006290145085162852,0.030981396279255852,282.79397825833246,240.4750317219981,1.6924403240159434
0.0006317437741850973,0.031115823164632926,283.02861919916137,240.4750317219981,1.6924403240159434
0.0006414911515737119,0.031595919183836765,283.8634144270345,240.4750317219981,1.6924403240159434
0.0006457799976247024,0.03180716143228646,284.2291555448668,240.4750317219981,1.6924403240159434
0.0006555273750133172,0.0322872574514903,285.056880471828,240.4750317219981,1.6924403240159434
0.0006578667455865847,0.03240248049609922,285.2548185182224,240.4750317219981,1.6924403240159434
0.0006664444376885655,0.0328249649929986,285.9782546406012,240.4750317219981,1.6924403240159434
0.0006687838082618331,0.03294018803760752,286.1749239997755,240.4750317219981,1.6924403240159434
0.0006742423395994573,0.03320904180836168,286.63277874797575,240.4750317219981,1.6924403240159434
0.0006789210807459922,0.033439487897579515,287.0240762713473,240.4750317219981,1.6924403240159434
0.0006816503464148044,0.03357391478295659,287.25184749450216,240.4750317219981,1.6924403240159434
0.000688668458134607,0.03391958391678336,287.8359177430678,240.4750317219981,1.6924403240159434
0.0006960764649499541,0.034284456891378275,288.4499235666966,240.4750317219981,1.6924403240159434
0.0006995855208098553,0.034457291458291656,288.7398784593009,240.4750317219981,1.6924403240159434
0.0007120621638672821,0.03507181436287257,289.7662669178237,240.4750317219981,1.6924403240159434
0.0007167409050138172,0.03530226045209042,290.14935127811873,240.4750317219981,1.6924403240159434
0.0007175206952049064,0.035340668133626726,290.21310373462984,240.4750317219981,1.6924403240159434
0.0007214196461603522,0.03553270654130826,290.531461598323,240.4750317219981,1.6924403240159434
0.0007241489118291645,0.035667133426685343,290.75391296105613,240.4750317219981,1.6924403240159434
0.0007533910439950082,0.037107421484296854,293.1171556047165,240.4750317219981,1.6924403240159434
0.0007600192606192663,0.03743388677735547,293.6478182863796,240.4750317219981,1.6924403240159434
0.0007670373723390688,0.03777955591118223,294.2077329082078,240.4750317219981,1.6924403240159434
0.0007697666380078811,0.03791398279655932,294.42493746675586,240.4750317219981,1.6924403240159434
0.0007775645399187727,0.03829805961192238,295.04387311287246,240.4750317219981,1.6924403240159434
0.0007814634908742185,0.038490098019603916,295.35243280768304,240.4750317219981,1.6924403240159434
0.0007841927565430308,0.038624524904981,295.5680674528157,240.4750317219981,1.6924403240159434
0.0007884816025940212,0.03883576715343069,295.9063314867824,240.4750317219981,1.6924403240159434
0.0007912108682628332,0.03897019403880776,296.1212168547908,240.4750317219981,1.6924403240159434
0.0007931603437405561,0.03906621324264853,296.2745294507022,240.4750317219981,1.6924403240159434
0.0007970592946960019,0.03925825165033006,296.5807144735158,240.4750317219981,1.6924403240159434
0.0007993986652692695,0.03937347469493899,296.7641451197092,240.4750317219981,1.6924403240159434
0.0008227923710019448,0.04052570514102821,298.58708192510755,240.4750317219981,1.6924403240159434
0.0008333195385816485,0.04104420884176835,299.4007969881078,240.4750317219981,1.6924403240159434
0.0008407275453969956,0.04140908181636327,299.97100978504375,240.4750317219981,1.6924403240159434
0.0008489153424034319,0.041812362472494494,300.598970068344,240.4750317219981,1.6924403240159434
0.0008582728246965019,0.04227325465093018,301.31375379904364,240.4750317219981,1.6924403240159434
0.0008606121952697695,0.042388477695539106,301.4919740462693,240.4750317219981,1.6924403240159434
0.000866850516798483,0.042695739147829564,301.9663067726488,240.4750317219981,1.6924403240159434
0.0008738686285182855,0.043041408281656326,302.49834266129596,240.4750317219981,1.6924403240159434
0.0008820564255247217,0.04344468893778755,303.11694961648664,240.4750317219981,1.6924403240159434
0.0008828362157158111,0.04348309661932387,303.17574752125046,240.4750317219981,1.6924403240159434
0.0008879048519578906,0.043732746549309864,303.55744138810843,240.4750317219981,1.6924403240159434
0.0008957027538687822,0.04411682336467293,304.14300757902373,240.4750317219981,1.6924403240159434
0.0008984320195375945,0.044251250250050014,304.3474856018467,240.4750317219981,1.6924403240159434
0.0009011612852064066,0.044385677135427085,304.55172151318334,240.4750317219981,1.6924403240159434
0.000905450131257397,0.044596919383876776,304.8721769430879,240.4750317219981,1.6924403240159434
0.0009116884527861105,0.044904180836167235,305.3372391912962,240.4750317219981,1.6924403240159434
0.0009140278233593781,0.04501940388077616,305.5113173618567,240.4750317219981,1.6924403240159434
0.0009233853056524481,0.04548029605921185,306.20589945489917,240.4750317219981,1.6924403240159434
0.0009249448860346263,0.045557111422284455,306.32139572868005,240.4750317219981,1.6924403240159434
0.0009378114241875978,0.04619083816763353,307.2713592666047,240.4750317219981,1.6924403240159434
0.0009588657593470056,0.04722784556911383,308.81495348274564,240.4750317219981,1.6924403240159434
0.0009639343955890851,0.047477495499099825,309.1845784407747,240.4750317219981,1.6924403240159434
0.0009740716680732443,0.04797679535907182,309.9215621727332,240.4750317219981,1.6924403240159434
0.0009896674718950277,0.04874494898979796,311.0495691004384,240.4750317219981,1.6924403240159434
0.0009939563179460183,0.048956191238247654,311.3585529072315,240.4750317219981,1.6924403240159434
0.000999024954188098,0.04920584116823365,311.7230460248451,240.4750317219981,1.6924403240159434
0.001002534010047999,0.04937867573514702,311.9749650340999,240.4750317219981,1.6924403240159434
0.001013061177627703,0.04989717943588717,312.728666784162,240.4750317219981,1.6924403240159434
0.0010228085550163177,0.05037727545509102,313.42381977378113,240.4750317219981,1.6924403240159434
0.0010458123656534482,0.051510302060412086,315.0542164805816,240.4750317219981,1.6924403240159434
0.0010477618411311711,0.05160632126425285,315.1917395508007,240.4750317219981,1.6924403240159434
0.0010547799528509737,0.051951990398079614,315.68599846964753,240.4750317219981,1.6924403240159434
0.0010645273302395885,0.05243208641728346,316.37034676046943,240.4750317219981,1.6924403240159434
0.001066866700812856,0.052547309461892386,316.53422618044465,240.4750317219981,1.6924403240159434
0.0010758342880103813,0.052988997799559914,317.1611366058632,240.4750317219981,1.6924403240159434
0.0010777837634881042,0.05308501700340068,317.2971514259348,240.4750317219981,1.6924403240159434
0.001091430091832165,0.05375715143028606,318.24658296457926,240.4750317219981,1.6924403240159434
0.0011011774692207793,0.05423724744948989,318.9219160259424,240.4750317219981,1.6924403240159434
0.001116773273042563,0.05500540108021604,319.9976197517484,240.4750317219981,1.6924403240159434
0.0011249610700489994,0.055408681736347276,320.5600180303339,240.4750317219981,1.6924403240159434
0.0011339286572465248,0.055850370074014805,321.17414953027327,240.4750317219981,1.6924403240159434
0.0011374377131064262,0.05602320464092819,321.41394588650934,240.4750317219981,1.6924403240159434
0.001144065929730684,0.056349669933986796,321.8661088418748,240.4750317219981,1.6924403240159434
0.0011530335169282096,0.05679135827165434,322.476235912085,240.4750317219981,1.6924403240159434
0.0011655101599856363,0.057405881176235254,323.3220387459508,240.4750317219981,1.6924403240159434
0.0011736979569920726,0.05780916183236648,323.8751785357671,240.4750317219981,1.6924403240159434
0.0011783766981386075,0.058039607921584316,324.19058272153404,240.4750317219981,1.6924403240159434
0.0011861746000494994,0.058423684736947396,324.7151731892812,240.4750317219981,1.6924403240159434
0.001193192711769302,0.05876935387077416,325.1861557712247,240.4750317219981,1.6924403240159434
0.0011982613480113816,0.05901900380076015,325.5256382098226,240.4750317219981,1.6924403240159434
0.0012048895646356397,0.05934546909381877,325.96873294898,240.4750317219981,1.6924403240159434
0.0012068390401133624,0.05944148829765954,326.09887388370487,240.4750317219981,1.6924403240159434
0.0012130773616420758,0.059748749749949995,326.5147749970433,240.4750317219981,1.6924403240159434
0.001227113585081681,0.06044008801760352,327.44751476526267,240.4750317219981,1.6924403240159434
0.0012314024311326714,0.06065133026605321,327.731687429756,240.4750317219981,1.6924403240159434
0.0012376407526613847,0.06095859171834367,328.144341398948,240.4750317219981,1.6924403240159434
0.0012419295987123752,0.06116983396679336,328.4275705653433,240.4750317219981,1.6924403240159434
0.0012462184447633658,0.06138107621524305,328.71041853018016,240.4750317219981,1.6924403240159434
0.0012528466613876234,0.061707541508301655,329.1468016330814,240.4750317219981,1.6924403240159434
0.0012625940387762382,0.0621876375275055,329.7869093846194,240.4750317219981,1.6924403240159434
0.0012645435142539612,0.06228365673134627,329.91469934782594,240.4750317219981,1.6924403240159434
0.0012700020455915855,0.06255251050210042,330.2721031422346,240.4750317219981,1.6924403240159434
0.0012766302622158436,0.06287897579515904,330.7052890630833,240.4750317219981,1.6924403240159434
0.0012813090033623785,0.06310942188437688,331.01053941219715,240.4750317219981,1.6924403240159434
0.0012957351218975282,0.06381996399279856,331.94900296698614,240.4750317219981,1.6924403240159434
0.001298854282661885,0.06397359471894379,332.1513772183307,240.4750317219981,1.6924403240159434
0.0013039229189039643,0.06422324464892978,332.479831596038,240.4750317219981,1.6924403240159434
0.0013140601913881236,0.06472254450890177,333.1352503284039,240.4750317219981,1.6924403240159434
0.0013187389325346587,0.06495299059811963,333.4370859125069,240.4750317219981,1.6924403240159434
0.0013230277785856494,0.06516423284656932,333.7134018461332,240.4750317219981,1.6924403240159434
0.001336284211834165,0.06581716343268654,334.5652689536041,240.4750317219981,1.6924403240159434
0.0013421326382673337,0.06610522104420884,334.9400442372873,240.4750317219981,1.6924403240159434
0.0013464214843183244,0.06631646329265853,335.2144747775284,240.4750317219981,1.6924403240159434
0.001352659805847038,0.066623724744949,335.6130386659049,240.4750317219981,1.6924403240159434
0.0013588981273757513,0.06693098619723946,336.01088632338525,240.4750317219981,1.6924403240159434
0.0013631869734267415,0.06714222844568914,336.2839934929442,240.4750317219981,1.6924403240159434
0.0013690353998599106,0.06743028605721145,336.65587292848994,240.4750317219981,1.6924403240159434
0.0013709848753376335,0.06752630526105222,336.77969499063596,240.4750317219981,1.6924403240159434
0.0013748838262930792,0.06771834366873375,337.0271333065608,240.4750317219981,1.6924403240159434
0.0013912594203059519,0.0685249049809962,338.0633999689983,240.4750317219981,1.6924403240159434
0.0014010067976945666,0.06900500100020004,338.67796706925503,240.4750317219981,1.6924403240159434
0.0014076350143188247,0.06933146629325866,339.0949204906502,240.4750317219981,1.6924403240159434
0.0014154329162297163,0.06971554310862173,339.58447489042123,240.4750317219981,1.6924403240159434
0.001429859034764866,0.07042608521704341,340.4873865227762,240.4750317219981,1.6924403240159434
0.0014357074611980349,0.07071414282856572,340.8524188373968,240.4750317219981,1.6924403240159434
0.0014442851533000155,0.0711366273254651,341.38675230179734,240.4750317219981,1.6924403240159434
0.0014520830552109075,0.07152070414082817,341.8714369790259,240.4750317219981,1.6924403240159434
0.0014715778099881366,0.07248089617923585,343.0787286437974,240.4750317219981,1.6924403240159434
0.001479765606994573,0.07288417683536708,343.5839292658713,240.4750317219981,1.6924403240159434
0.0014832746628544744,0.07305701140228046,343.80010995632915,240.4750317219981,1.6924403240159434
0.0014938018304341784,0.07357551510302061,344.4474584450317,240.4750317219981,1.6924403240159434
0.0014953614108163566,0.07365233046609322,344.54321039483625,240.4750317219981,1.6924403240159434
0.0015012098372495252,0.07394038807761552,344.9019338652759,240.4750317219981,1.6924403240159434
0.001506278473491605,0.07419003800760153,345.21238689690847,240.4750317219981,1.6924403240159434
0.0015086178440648723,0.07430526105221044,345.3555354710273,240.4750317219981,1.6924403240159434
0.0015129066901158627,0.07451650330066013,345.6177498821999,240.4750317219981,1.6924403240159434
0.001517585431262398,0.07474694938987798,345.90347155796206,240.4750317219981,1.6924403240159434
0.0015261631233643787,0.07516943388677735,346.4264039598639,240.4750317219981,1.6924403240159434
0.0015281125988421019,0.07526545309061813,346.5450922266474,240.4750317219981,1.6924403240159434
0.0015390296615173501,0.07580316063212643,347.2086584641285,240.4750317219981,1.6924403240159434
0.0015483871438104202,0.07626405281056212,347.77596975927196,240.4750317219981,1.6924403240159434
0.0015515063045747769,0.07641768353670735,347.96477618425934,240.4750317219981,1.6924403240159434
0.0015557951506257675,0.07662892578515704,348.22414348336076,240.4750317219981,1.6924403240159434
0.0015632031574411146,0.07699379875975196,348.6714857141856,240.4750317219981,1.6924403240159434
0.0015663223182054713,0.07714742948589719,348.85959290404486,240.4750317219981,1.6924403240159434
0.0015690515838742832,0.07728185637127426,349.0240668866533,240.4750317219981,1.6924403240159434
0.0015803585416450763,0.07783876775355071,349.7042738745795,240.4750317219981,1.6924403240159434
0.001592055394511414,0.07841488297659532,350.40594196740483,240.4750317219981,1.6924403240159434
0.0015955644503713154,0.07858771754350871,350.61604997022175,240.4750317219981,1.6924403240159434
0.001600633086613395,0.07883736747349471,350.9192214358427,240.4750317219981,1.6924403240159434
0.0016115501492886433,0.079375075015003,351.5709373773826,240.4750317219981,1.6924403240159434
0.0016173985757218122,0.07966313262652532,351.9193625476832,240.4750317219981,1.6924403240159434
0.001621297526677258,0.07985517103420685,352.15137305865204,240.4750317219981,1.6924403240159434
0.0016263661629193375,0.08010482096419284,352.4526616727076,240.4750317219981,1.6924403240159434
0.001629875218779239,0.08027765553110623,352.66103161218615,240.4750317219981,1.6924403240159434
0.0016392327010723092,0.08073854770954192,353.2158312052159,240.4750317219981,1.6924403240159434
0.001651709344129736,0.08135307061412284,353.9536464630604,240.4750317219981,1.6924403240159434
0.0016528790294163694,0.08141068213642728,354.02270501479273,240.4750317219981,1.6924403240159434
0.0016661354626648856,0.08206361272254452,354.8040412330209,240.4750317219981,1.6924403240159434
0.0016762727351490446,0.08256291258251651,355.3998988423316,240.4750317219981,1.6924403240159434
0.0016809514762955796,0.08279335867173435,355.67443589584536,240.4750317219981,1.6924403240159434
0.0017109733986525127,0.08427205441088217,357.4290101509741,240.4750317219981,1.6924403240159434
0.00171838140546786,0.0846369273854771,357.86010508709836,240.4750317219981,1.6924403240159434
0.0017253995171876628,0.08498259651930387,358.26784272066226,240.4750317219981,1.6924403240159434
0.0017339772092896434,0.08540508101620324,358.76531139467653,240.4750317219981,1.6924403240159434
0.0017421650062960797,0.08580836167233447,359.2392733195198,240.4750317219981,1.6924403240159434
0.0017445043768693472,0.08592358471694339,359.37453134698524,240.4750317219981,1.6924403240159434
0.0017472336425381596,0.08605801160232047,359.53224300626755,240.4750317219981,1.6924403240159434
0.0017491831180158825,0.08615403080616124,359.64483537403436,240.4750317219981,1.6924403240159434
0.001753471964066873,0.08636527305461093,359.8923664614157,240.4750317219981,1.6924403240159434
0.001764778921837666,0.08692218443688739,360.54381922398,240.4750317219981,1.6924403240159434
0.001797530109863411,0.08853530706141229,362.4216621527954,240.4750317219981,1.6924403240159434
0.0018111764382074717,0.08920744148829766,363.2001529360587,240.4750317219981,1.6924403240159434
0.00182209350088272,0.08974514902980596,363.8212997717954,240.4750317219981,1.6924403240159434
0.0018302812978891565,0.0901484296859372,364.2862078488583,240.4750317219981,1.6924403240159434
0.0018357398292267804,0.09041728345669134,364.59569602957686,240.4750317219981,1.6924403240159434
0.001849386157570841,0.09108941788357672,365.36785043027504,240.4750317219981,1.6924403240159434
0.0018599133251505449,0.09160792158431687,365.9619951211821,240.4750317219981,1.6924403240159434
0.0018653718564881692,0.09187677535507102,366.26955372898965,240.4750317219981,1.6924403240159434
0.0018743394436856946,0.09231846369273855,366.77406769496645,240.4750317219981,1.6924403240159434
0.0018875958769342105,0.09297139427885577,367.51814998659694,240.4750317219981,1.6924403240159434
0.001901242205278271,0.09364352870574115,368.2819913572192,240.4750317219981,1.6924403240159434
0.001907870421902529,0.09396999399879977,368.6522282853055,240.4750317219981,1.6924403240159434
0.001921126855151045,0.09462292458491699,369.39120064774005,240.4750317219981,1.6924403240159434
0.0019293146521574813,0.09502620524104821,369.8466313938569,240.4750317219981,1.6924403240159434
0.0019382822393550069,0.09546789357871575,370.3445724763905,240.4750317219981,1.6924403240159434
0.0019410115050238189,0.09560232046409282,370.4959413226766,240.4750317219981,1.6924403240159434
0.001947639721648077,0.09592878575715144,370.8632062100199,240.4750317219981,1.6924403240159434
0.0019546578333678793,0.0962744548909782,371.25154400852176,240.4750317219981,1.6924403240159434
0.00198701912629808,0.09786837367473496,373.03522472529926,240.4750317219981,1.6924403240159434
0.0019963766085911504,0.09832926585317064,373.5488715318054,240.4750317219981,1.6924403240159434
0.001999495769355507,0.09848289657931587,373.71987836498704,240.4750317219981,1.6924403240159434
0.0020053441957886757,0.09877095419083817,374.04023602225203,240.4750317219981,1.6924403240159434
0.0020108027271263,0.09903980796159233,374.3389079109796,240.4750317219981,1.6924403240159434
0.002013531992795112,0.0991742348469694,374.48812526750754,240.4750317219981,1.6924403240159434
0.002022889475088182,0.09963512702540508,374.99912985134716,240.4750317219981,1.6924403240159434
0.00202951769171244,0.0999615923184637,375.36053381252407,240.4750317219981,1.6924403240159434