File: datasets/aisi_316_L/data/M1/train_34.csv
Time(s),Strain(%),Stress(MPa),Temp(C),Log_SR(s-1)
0.0,0.0,0.0,326.23408889182804,2.535016911603787
5.83462682083679e-08,1.9999999999999998e-05,3.5094424999999996,326.23408889182804,2.535016911603787
7.701707403504563e-08,2.6399999999999998e-05,4.6324641,326.23408889182804,2.535016911603787
9.335402913338863e-08,3.2e-05,5.615107999999999,326.23408889182804,2.535016911603787
1.2602793933007467e-07,4.32e-05,7.5803958,326.23408889182804,2.535016911603787
1.797065060817731e-07,6.159999999999999e-05,10.809082899999998,326.23408889182804,2.535016911603787
2.1004656555012446e-07,7.2e-05,12.633993,326.23408889182804,2.535016911603787
2.5905743084515347e-07,8.879999999999999e-05,15.581924699999998,326.23408889182804,2.535016911603787
2.7539438594349645e-07,9.439999999999999e-05,16.564568599999998,326.23408889182804,2.535016911603787
2.9873289322684367e-07,0.0001024,17.9683456,326.23408889182804,2.535016911603787
3.314068034235297e-07,0.0001136,19.933633399999998,326.23408889182804,2.535016911603787
3.9442077308856704e-07,0.0001352,23.7238313,326.23408889182804,2.535016911603787
4.714378471236126e-07,0.0001616,28.3562954,326.23408889182804,2.535016911603787
4.877748022219556e-07,0.0001672,29.3389393,326.23408889182804,2.535016911603787
5.134471602336375e-07,0.000176,30.883094,326.23408889182804,2.535016911603787
5.717934284420055e-07,0.000196,34.3925365,326.23408889182804,2.535016911603787
7.048229199570843e-07,0.0002416,42.394065399999995,326.23408889182804,2.535016911603787
7.491660837954438e-07,0.0002568,45.061241700000004,326.23408889182804,2.535016911603787
7.631691881654521e-07,0.00026159999999999996,45.903507899999994,326.23408889182804,2.535016911603787
8.425201129288324e-07,0.00028879999999999997,50.676349699999996,326.23408889182804,2.535016911603787
8.681924709405143e-07,0.00029759999999999997,52.220504399999996,326.23408889182804,2.535016911603787
8.751940231255184e-07,0.0003,52.641637499999995,326.23408889182804,2.535016911603787
9.032002318655351e-07,0.0003096,54.3261699,326.23408889182804,2.535016911603787
9.685480522589072e-07,0.000332,58.2567455,326.23408889182804,2.535016911603787
9.988881117272585e-07,0.0003424,60.0816556,326.23408889182804,2.535016911603787
1.0455651262939527e-06,0.0003584,62.889209599999994,326.23408889182804,2.535016911603787
1.0922421408606472e-06,0.0003744,65.6967636,326.23408889182804,2.535016911603787
1.1692592148956927e-06,0.0004008,70.3292277,326.23408889182804,2.535016911603787
1.173926916352362e-06,0.00040239999999999997,70.6099831,326.23408889182804,2.535016911603787
1.2159362294623871e-06,0.0004168,73.1367817,326.23408889182804,2.535016911603787
1.2206039309190564e-06,0.0004184,73.41753709999999,326.23408889182804,2.535016911603787
1.2439424382024035e-06,0.00042639999999999996,74.8213141,326.23408889182804,2.535016911603787
1.2649470947574161e-06,0.00043359999999999997,76.0847134,326.23408889182804,2.535016911603787
1.3116241093241103e-06,0.0004496,78.8922674,326.23408889182804,2.535016911603787
1.35596727316247e-06,0.00046479999999999997,81.55944369999999,326.23408889182804,2.535016911603787
1.4376520486541849e-06,0.0004927999999999999,86.47266319999999,326.23408889182804,2.535016911603787
1.5496768836142514e-06,0.0005312,93.21079280000001,326.23408889182804,2.535016911603787
1.6196924054642929e-06,0.0005551999999999999,97.4221238,326.23408889182804,2.535016911603787
1.633695509834301e-06,0.00056,98.26438999999999,326.23408889182804,2.535016911603787
1.6547001663893137e-06,0.0005672,99.52778930000001,326.23408889182804,2.535016911603787
1.6873740765859995e-06,0.0005784,101.4930771,326.23408889182804,2.535016911603787
1.7643911506210453e-06,0.0006048,106.12554119999999,326.23408889182804,2.535016911603787
1.8110681651877397e-06,0.0006208,108.9330952,326.23408889182804,2.535016911603787
1.8624128812111035e-06,0.0006384,112.0214046,326.23408889182804,2.535016911603787
1.8764159855811118e-06,0.0006432,112.86367080000001,326.23408889182804,2.535016911603787
1.9207591494194713e-06,0.0006584,115.53084709999999,326.23408889182804,2.535016911603787
1.9510992088878226e-06,0.0006688,117.3557572,326.23408889182804,2.535016911603787
2.0327839843795374e-06,0.0006967999999999999,122.26897669999998,326.23408889182804,2.535016911603787
2.0934641033162405e-06,0.0007176,125.9187969,326.23408889182804,2.535016911603787
2.1191364613279222e-06,0.0007264,127.4629516,326.23408889182804,2.535016911603787
2.1494765207962735e-06,0.0007368,129.2878617,326.23408889182804,2.535016911603787
2.17748272953629e-06,0.0007463999999999999,130.97239409999997,326.23408889182804,2.535016911603787
2.2054889382763066e-06,0.0007559999999999999,132.6569265,326.23408889182804,2.535016911603787
2.2544998035713356e-06,0.0007727999999999999,135.6048582,326.23408889182804,2.535016911603787
2.308178370323034e-06,0.0007911999999999999,138.8335453,326.23408889182804,2.535016911603787
2.3408522805197204e-06,0.0008024,140.7988331,326.23408889182804,2.535016911603787
2.3548553848897285e-06,0.0008072,141.6410993,326.23408889182804,2.535016911603787
2.3805277429014103e-06,0.000816,143.185254,326.23408889182804,2.535016911603787
2.438874011109778e-06,0.0008359999999999999,146.6946965,326.23408889182804,2.535016911603787
2.473881772034799e-06,0.000848,148.800362,326.23408889182804,2.535016911603787
2.5088895329598196e-06,0.00086,150.9060275,326.23408889182804,2.535016911603787
2.562568099711518e-06,0.0008784,154.1347146,326.23408889182804,2.535016911603787
2.5765712040815267e-06,0.0008832,154.9769808,326.23408889182804,2.535016911603787
2.6279159201048902e-06,0.0009008,158.0652902,326.23408889182804,2.535016911603787
2.6722590839432497e-06,0.0009159999999999999,160.7324665,326.23408889182804,2.535016911603787
2.6932637404982623e-06,0.0009232,161.9958658,326.23408889182804,2.535016911603787
2.7329392028799527e-06,0.0009368,164.3822867,326.23408889182804,2.535016911603787
2.760945411619969e-06,0.0009463999999999999,166.06681909999998,326.23408889182804,2.535016911603787
2.7982870232733244e-06,0.0009592,168.3128623,326.23408889182804,2.535016911603787
2.8893072016783787e-06,0.0009904,173.7875926,326.23408889182804,2.535016911603787
2.917313410418395e-06,0.001,175.472125,326.23408889182804,2.535016911603787
3.015335141008453e-06,0.0010336,181.3679884,326.23408889182804,2.535016911603787
3.0223366931934575e-06,0.001036,181.7891215,326.23408889182804,2.535016911603787
3.0480090512051393e-06,0.0010448,183.3332762,326.23408889182804,2.535016911603787
3.0900183643151638e-06,0.0010592,184.70375456570292,326.23408889182804,2.535016911603787
3.1040214686851724e-06,0.001064,184.73186323559287,326.23408889182804,2.535016911603787
3.174036990535214e-06,0.001088,184.87167153353192,326.23408889182804,2.535016911603787
3.181038542720218e-06,0.0010904,184.8855858835744,326.23408889182804,2.535016911603787
3.211378602188569e-06,0.0011007999999999999,184.9457439052875,326.23408889182804,2.535016911603787
3.2393848109285857e-06,0.0011103999999999999,185.00107794188818,326.23408889182804,2.535016911603787
3.2720587211252716e-06,0.0011216,185.0653990602377,326.23408889182804,2.535016911603787
3.2767264225819415e-06,0.0011232,185.0745673013904,326.23408889182804,2.535016911603787
3.3117341835069624e-06,0.0011352,185.1431674927035,326.23408889182804,2.535016911603787
3.337406541518644e-06,0.001144,185.19329468933788,326.23408889182804,2.535016911603787
3.3817497053570036e-06,0.0011592,185.2795252605753,326.23408889182804,2.535016911603787
3.4190913170103585e-06,0.0011719999999999999,185.35179898652177,326.23408889182804,2.535016911603787
3.482105286675396e-06,0.0011936,185.47306670910783,326.23408889182804,2.535016911603787
3.5171130476004174e-06,0.0012056,185.54006776107246,326.23408889182804,2.535016911603787
3.5287823012420905e-06,0.0012096,185.56234358109447,326.23408889182804,2.535016911603787
3.5777931665371195e-06,0.0012263999999999999,185.65559003345155,326.23408889182804,2.535016911603787
3.5964639723637976e-06,0.0012328,185.6909812872501,326.23408889182804,2.535016911603787
3.6641456434855043e-06,0.001256,185.81867826117318,326.23408889182804,2.535016911603787
3.7341611653355456e-06,0.0012799999999999999,185.949814239106,326.23408889182804,2.535016911603787
3.773836627717236e-06,0.0012936,186.02369890364722,326.23408889182804,2.535016911603787
3.867190656850624e-06,0.0013256,186.19636034730513,326.23408889182804,2.535016911603787
3.911533820688983e-06,0.0013407999999999998,186.27780438686867,326.23408889182804,2.535016911603787
3.94887543234234e-06,0.0013536,186.34610993147496,326.23408889182804,2.535016911603787
3.9838831932673604e-06,0.0013656,186.40991795192778,326.23408889182804,2.535016911603787
4.151920445707459e-06,0.0014232,186.7132035312663,326.23408889182804,2.535016911603787
4.212600564644163e-06,0.001444,186.82154185086335,326.23408889182804,2.535016911603787
4.259277579210856e-06,0.00146,186.9044653854559,326.23408889182804,2.535016911603787
4.266279131395861e-06,0.0014624,186.91687328050756,326.23408889182804,2.535016911603787
4.3456300561592415e-06,0.0014896,187.05694555091935,326.23408889182804,2.535016911603787
4.408644025824279e-06,0.0015111999999999999,187.16747007275168,326.23408889182804,2.535016911603787
4.490328801315993e-06,0.0015392,187.30982991528137,326.23408889182804,2.535016911603787
4.539339666611022e-06,0.0015559999999999999,187.39476109343465,326.23408889182804,2.535016911603787
4.555676621709366e-06,0.0015616,187.42299191459495,326.23408889182804,2.535016911603787
4.60702133773273e-06,0.0015792,187.51146139982166,326.23408889182804,2.535016911603787
4.632693695744412e-06,0.001588,187.55555188164521,326.23408889182804,2.535016911603787
4.6583660537560935e-06,0.0015968,187.5995471770334,326.23408889182804,2.535016911603787
4.6933738146811135e-06,0.0016087999999999999,187.65938867658105,326.23408889182804,2.535016911603787
4.791395545271172e-06,0.0016424,187.8260257927807,326.23408889182804,2.535016911603787
4.821735604739523e-06,0.0016527999999999998,187.8773337999505,326.23408889182804,2.535016911603787
4.866078768577883e-06,0.001668,187.9520965141113,326.23408889182804,2.535016911603787
4.975769752809614e-06,0.0017055999999999998,188.1359032955547,326.23408889182804,2.535016911603787
4.999108260092962e-06,0.0017136,188.17480646235947,326.23408889182804,2.535016911603787
5.01311136446297e-06,0.0017184,188.19811436447998,326.23408889182804,2.535016911603787
5.064456080486334e-06,0.001736,188.283360298392,326.23408889182804,2.535016911603787
5.073791483399673e-06,0.0017392,188.29882327854946,326.23408889182804,2.535016911603787
5.227825631469764e-06,0.001792,188.55238185403906,326.23408889182804,2.535016911603787
5.265167243123119e-06,0.0018047999999999999,188.6134097537751,326.23408889182804,2.535016911603787
5.381859779539855e-06,0.0018448,188.8030429481946,326.23408889182804,2.535016911603787
5.479881510129913e-06,0.0018784,188.96109873491204,326.23408889182804,2.535016911603787
5.491550763771587e-06,0.0018824,188.97984117163213,326.23408889182804,2.535016911603787
5.54756318125162e-06,0.0019015999999999998,189.06958954985413,326.23408889182804,2.535016911603787
5.5685678378066325e-06,0.0019088,189.1031539913637,326.23408889182804,2.535016911603787
5.622246404558331e-06,0.0019272,189.1887062309116,326.23408889182804,2.535016911603787
5.661921866940021e-06,0.0019408,189.2517358935113,326.23408889182804,2.535016911603787
5.7156004336917194e-06,0.0019592,189.33673782809817,326.23408889182804,2.535016911603787
5.797285209183434e-06,0.0019871999999999997,189.4654936534385,326.23408889182804,2.535016911603787
5.843962223750129e-06,0.0020032,189.5387507185324,326.23408889182804,2.535016911603787
5.869634581761811e-06,0.002012,189.5789448241879,326.23408889182804,2.535016911603787
5.91864544705684e-06,0.0020288,189.65548914991393,326.23408889182804,2.535016911603787
5.923313148513509e-06,0.0020304,189.6627661691626,326.23408889182804,2.535016911603787
6.0143333269185625e-06,0.0020616,189.8042240969483,326.23408889182804,2.535016911603787
6.058676490756922e-06,0.0020767999999999997,189.8728368374637,326.23408889182804,2.535016911603787
6.100685803866948e-06,0.0020912,189.93765794749277,326.23408889182804,2.535016911603787
6.154364370618647e-06,0.0021096,190.02023215306858,326.23408889182804,2.535016911603787
6.173035176445324e-06,0.002116,190.04888771337346,326.23408889182804,2.535016911603787
6.261721504122042e-06,0.0021463999999999997,190.18454269621054,326.23408889182804,2.535016911603787
6.3270693245154145e-06,0.0021688,190.2840200041149,326.23408889182804,2.535016911603787
6.418089502920468e-06,0.0021999999999999997,190.42191250933598,326.23408889182804,2.535016911603787
6.511443532053858e-06,0.002232,190.56255075202424,326.23408889182804,2.535016911603787
6.583792904632233e-06,0.0022567999999999998,190.67100520525895,326.23408889182804,2.535016911603787
6.658476127938945e-06,0.0022824,190.78247176297984,326.23408889182804,2.535016911603787
6.716822396147313e-06,0.0023024,190.86921609329153,326.23408889182804,2.535016911603787
6.7518301570723336e-06,0.0023144,190.92112164452962,326.23408889182804,2.535016911603787
6.803174873095697e-06,0.002332,190.99706032898948,326.23408889182804,2.535016911603787
6.819511828194041e-06,0.0023376,191.02117572058194,326.23408889182804,2.535016911603787
6.931536663154107e-06,0.002376,191.18593564201063,326.23408889182804,2.535016911603787
6.975879826992467e-06,0.0023912,191.25086581829868,326.23408889182804,2.535016911603787
7.0552307517558465e-06,0.0024184,191.36665633060332,326.23408889182804,2.535016911603787
7.10657546777921e-06,0.002436,191.44130904886794,326.23408889182804,2.535016911603787
7.1975956461842636e-06,0.0024671999999999997,191.57313303685962,326.23408889182804,2.535016911603787
7.213932601282607e-06,0.0024728,191.59672477166885,326.23408889182804,2.535016911603787
7.218600302739276e-06,0.0024744,191.60346143904707,326.23408889182804,2.535016911603787
7.269945018762641e-06,0.002492,191.6774530034739,326.23408889182804,2.535016911603787
7.332958988427678e-06,0.0025136,191.76798287349388,326.23408889182804,2.535016911603787
7.337626689884348e-06,0.0025152,191.7746766960431,326.23408889182804,2.535016911603787
7.351629794254355e-06,0.0025199999999999997,191.79474820670495,326.23408889182804,2.535016911603787
7.365632898624363e-06,0.0025248,191.81480481262778,326.23408889182804,2.535016911603787
7.412309913191058e-06,0.0025407999999999997,191.88155302455465,326.23408889182804,2.535016911603787
7.479991584312765e-06,0.002564,191.9780474890742,326.23408889182804,2.535016911603787
7.500996240867777e-06,0.0025712,192.00792473160433,326.23408889182804,2.535016911603787
7.564010210532814e-06,0.0025927999999999997,192.09736129785793,326.23408889182804,2.535016911603787
7.582681016359492e-06,0.0025992,192.1238051559142,326.23408889182804,2.535016911603787
7.61068722509951e-06,0.0026088,192.16342337928813,326.23408889182804,2.535016911603787
7.648028836752864e-06,0.0026216,192.21615934493488,326.23408889182804,2.535016911603787
7.671367344036212e-06,0.0026295999999999997,192.2490683346772,326.23408889182804,2.535016911603787
7.704041254232897e-06,0.0026408,192.2950753982482,326.23408889182804,2.535016911603787
7.753052119527927e-06,0.0026576,192.36394356735565,326.23408889182804,2.535016911603787
7.783392178996277e-06,0.002668,192.4064911673071,326.23408889182804,2.535016911603787
7.820733790649633e-06,0.0026807999999999997,192.45876875324703,326.23408889182804,2.535016911603787
7.879080058858001e-06,0.0027007999999999997,192.54025801742304,326.23408889182804,2.535016911603787
7.953763282164712e-06,0.0027264,192.644221681316,326.23408889182804,2.535016911603787
7.965432535806385e-06,0.0027304,192.66043154969805,326.23408889182804,2.535016911603787
7.986437192361397e-06,0.0027375999999999998,192.68958599330085,326.23408889182804,2.535016911603787
8.084458922951455e-06,0.0027711999999999997,192.82524661889065,326.23408889182804,2.535016911603787
8.210486862281531e-06,0.0028144,192.99872851895736,326.23408889182804,2.535016911603787
8.231491518836543e-06,0.0028216,193.02754090247174,326.23408889182804,2.535016911603787
8.252496175391555e-06,0.0028288,193.05632462670295,326.23408889182804,2.535016911603787
8.29917318995825e-06,0.0028447999999999998,193.12018636072787,326.23408889182804,2.535016911603787
8.331847100154936e-06,0.002856,193.16480625332343,326.23408889182804,2.535016911603787
8.399528771276643e-06,0.0028791999999999997,193.2570166724611,326.23408889182804,2.535016911603787
8.448539636571671e-06,0.0028959999999999997,193.32360893686968,326.23408889182804,2.535016911603787
8.572233725173411e-06,0.0029384,193.49100865450416,326.23408889182804,2.535016911603787
8.595572232456759e-06,0.0029464,193.52248758755647,326.23408889182804,2.535016911603787
8.691260112318483e-06,0.0029792,193.65120424312977,326.23408889182804,2.535016911603787
8.751940231255185e-06,0.003,193.732543147615,326.23408889182804,2.535016911603787
8.821955753105226e-06,0.0030239999999999998,193.82612293180034,326.23408889182804,2.535016911603787
8.847628111116909e-06,0.0030328,193.86036288831403,326.23408889182804,2.535016911603787
8.86863276767192e-06,0.0030399999999999997,193.8883485874187,326.23408889182804,2.535016911603787
8.898972827140273e-06,0.0030504,193.92872678190722,326.23408889182804,2.535016911603787
8.943315990978632e-06,0.0030656,193.9876446230023,326.23408889182804,2.535016911603787
9.085680885407049e-06,0.0031144,194.17603645692427,326.23408889182804,2.535016911603787
9.202373421823785e-06,0.0031544,194.3295988875914,326.23408889182804,2.535016911603787
9.265387391488824e-06,0.003176,194.41220674704613,326.23408889182804,2.535016911603787
9.298061301685509e-06,0.0031872,194.45495417420008,326.23408889182804,2.535016911603787
9.382079927905558e-06,0.0032159999999999997,194.564607986644,326.23408889182804,2.535016911603787
9.442760046842261e-06,0.0032367999999999997,194.64356437113378,326.23408889182804,2.535016911603787
9.468432404853942e-06,0.0032456,194.67690939885094,326.23408889182804,2.535016911603787
9.477767807767282e-06,0.0032488,194.6890261189319,326.23408889182804,2.535016911603787
9.510441717963968e-06,0.00326,194.73139803347857,326.23408889182804,2.535016911603787
9.601461896369021e-06,0.0032911999999999998,194.84913576386762,326.23408889182804,2.535016911603787
9.692482074774075e-06,0.0033223999999999997,194.96643899826847,326.23408889182804,2.535016911603787
9.715820582057423e-06,0.0033304,194.99644745158253,326.23408889182804,2.535016911603787
9.760163745895782e-06,0.0033456,195.05338617603653,326.23408889182804,2.535016911603787
9.781168402450794e-06,0.0033528,195.0803219297018,326.23408889182804,2.535016911603787
9.844182372115833e-06,0.0033744,195.16099416183573,326.23408889182804,2.535016911603787
9.918865595422542e-06,0.0034,195.25634537211852,326.23408889182804,2.535016911603787
1.005656278839429e-05,0.0034471999999999997,195.4314183417328,326.23408889182804,2.535016911603787
1.0079901295677639e-05,0.0034552,195.46099882752077,326.23408889182804,2.535016911603787
1.0112575205874324e-05,0.0034663999999999997,195.50236667291622,326.23408889182804,2.535016911603787
1.0170921474082693e-05,0.0034863999999999997,195.57610840483244,326.23408889182804,2.535016911603787
1.0236269294476065e-05,0.0035088,195.65850356040193,326.23408889182804,2.535016911603787
1.0245604697389403e-05,0.003512,195.67025752889538,326.23408889182804,2.535016911603787
1.026427550321608e-05,0.0035183999999999997,195.69375294296313,326.23408889182804,2.535016911603787
1.0306284816326107e-05,0.0035328,195.74655676797892,326.23408889182804,2.535016911603787
1.0320287920696114e-05,0.0035375999999999997,195.7641393807678,326.23408889182804,2.535016911603787
1.034829412943613e-05,0.0035472,195.79927671853824,326.23408889182804,2.535016911603787
1.036229723380614e-05,0.003552,195.8168314784932,326.23408889182804,2.535016911603787
1.0376300338176147e-05,0.0035567999999999997,195.8343769890494,326.23408889182804,2.535016911603787
1.043231275565618e-05,0.0035759999999999998,195.9044668833676,326.23408889182804,2.535016911603787
1.0467320516581202e-05,0.003588,195.94819854623645,326.23408889182804,2.535016911603787
1.048132362095121e-05,0.0035927999999999997,195.965675235368,326.23408889182804,2.535016911603787
1.0530334486246237e-05,0.0036095999999999997,196.02677206615581,326.23408889182804,2.535016911603787
1.060035000809628e-05,0.0036336,196.11386122518044,326.23408889182804,2.535016911603787
1.0656362425576313e-05,0.0036528,196.18337113707958,326.23408889182804,2.535016911603787
1.0707707141599677e-05,0.0036704,196.24696348437158,326.23408889182804,2.535016911603787
1.0752050305438036e-05,0.0036856,196.30178850387594,326.23408889182804,2.535016911603787
1.0796393469276397e-05,0.0037007999999999997,196.35652541219517,326.23408889182804,2.535016911603787
1.0922421408606471e-05,0.003744,196.51161680447075,326.23408889182804,2.535016911603787
1.0948093766618152e-05,0.0037527999999999997,196.5431237589801,326.23408889182804,2.535016911603787
1.0994770781184846e-05,0.0037687999999999997,196.60033540980743,326.23408889182804,2.535016911603787
1.1022776989924864e-05,0.0037784,196.634616933927,326.23408889182804,2.535016911603787
1.104611549720821e-05,0.0037863999999999997,196.6631589295733,326.23408889182804,2.535016911603787
1.109512636250324e-05,0.0038031999999999996,196.7230206808632,326.23408889182804,2.535016911603787
1.1144137227798268e-05,0.0038199999999999996,196.7827793931163,326.23408889182804,2.535016911603787
1.1158140332168277e-05,0.0038247999999999997,196.79983447360328,326.23408889182804,2.535016911603787
1.1204817346734971e-05,0.0038407999999999997,196.8566245514651,326.23408889182804,2.535016911603787
1.1265497465671675e-05,0.0038615999999999998,196.9303139080888,326.23408889182804,2.535016911603787
1.1281834420770017e-05,0.0038672,196.9501268812412,326.23408889182804,2.535016911603787
1.130283907732503e-05,0.0038743999999999996,196.9755842701242,326.23408889182804,2.535016911603787
1.138219000208841e-05,0.0039016,197.07159057534224,326.23408889182804,2.535016911603787
1.141253006155676e-05,0.003912,197.1082298410276,326.23408889182804,2.535016911603787
1.1424199315198436e-05,0.003916,197.12231174872545,326.23408889182804,2.535016911603787
1.1435868568840108e-05,0.00392,197.13638804779066,326.23408889182804,2.535016911603787
1.1473210180493464e-05,0.0039328,197.18139460730634,326.23408889182804,2.535016911603787
1.1503550239961816e-05,0.0039432,197.21792038673658,326.23408889182804,2.535016911603787
1.1552561105256844e-05,0.00396,197.2768443038832,326.23408889182804,2.535016911603787
1.1603905821280208e-05,0.0039775999999999995,197.3384696511129,326.23408889182804,2.535016911603787
1.1627244328563555e-05,0.0039856,197.36644600827952,326.23408889182804,2.535016911603787
1.2005395374900425e-05,0.004115223044608922,197.81673487490744,326.23408889182804,2.535016911603787
1.2173466241513847e-05,0.004172834566913383,198.0150884262272,326.23408889182804,2.535016911603787
1.3237915063398856e-05,0.004537707541508302,199.24739362148762,326.23408889182804,2.535016911603787
1.385417490764807e-05,0.004748949789957992,199.94315645263296,326.23408889182804,2.535016911603787
1.424634026307939e-05,0.004883376675335067,200.3796360258619,326.23408889182804,2.535016911603787
1.50866945961465e-05,0.005171434286857372,201.29947340815315,326.23408889182804,2.535016911603787
1.547885995157782e-05,0.0053058611722344474,201.72187030777738,326.23408889182804,2.535016911603787
1.6487285151258352e-05,0.005651530306061212,202.78929974670407,326.23408889182804,2.535016911603787
1.8560159172823893e-05,0.006362072414482897,204.9065880124391,326.23408889182804,2.535016911603787
1.8840277283846264e-05,0.006458091618323665,205.18546142759615,326.23408889182804,2.535016911603787
2.0128820594549167e-05,0.0068997799559911985,206.44800573467307,326.23408889182804,2.535016911603787
2.3098072571386293e-05,0.00791758351670334,209.24295588492112,326.23408889182804,2.535016911603787
2.3770356037839982e-05,0.008148029605921184,209.8558744525507,326.23408889182804,2.535016911603787
2.5058899348542886e-05,0.008589717943588718,211.0120578767709,326.23408889182804,2.535016911603787
2.550708832617868e-05,0.008743348669733947,211.40874222766158,326.23408889182804,2.535016911603787
2.5731182814996575e-05,0.008820164032806561,211.60606431944134,326.23408889182804,2.535016911603787
2.6571537148063686e-05,0.009108221644328866,212.34012799434902,326.23408889182804,2.535016911603787
2.842031668081133e-05,0.009741948389677936,213.923922229116,326.23408889182804,2.535016911603787
3.0101025346945556e-05,0.010318063612722545,215.3291860715657,326.23408889182804,2.535016911603787
3.0941379680012664e-05,0.010606121224244848,216.02031515544664,326.23408889182804,2.535016911603787
3.200582850189767e-05,0.010970994198839769,216.88532452000845,326.23408889182804,2.535016911603787
3.2173899368511094e-05,0.011028605721144228,217.02087253597983,326.23408889182804,2.535016911603787
3.301425370157821e-05,0.011316663332666534,217.69451399449864,326.23408889182804,2.535016911603787
3.5087127723143745e-05,0.012027205441088217,219.32818308236202,326.23408889182804,2.535016911603787
3.760819072234508e-05,0.012891378275655131,221.26518042233135,326.23408889182804,2.535016911603787
3.80003560777764e-05,0.013025805161032206,221.56187749356565,326.23408889182804,2.535016911603787
3.9737088366115094e-05,0.013621124224844969,222.86172466080419,326.23408889182804,2.535016911603787
4.052141907697773e-05,0.01388997799559912,223.4414697432919,326.23408889182804,2.535016911603787
4.1025631676818e-05,0.014062812562512503,223.81185321638463,326.23408889182804,2.535016911603787
4.214610412090748e-05,0.014446889377875576,224.62862999148635,326.23408889182804,2.535016911603787
4.281838758736117e-05,0.01467733546709342,225.11463181982705,326.23408889182804,2.535016911603787
4.444307263129092e-05,0.015234246849369875,226.27701053058684,326.23408889182804,2.535016911603787
4.645992303065198e-05,0.015925585117023404,227.69715698714162,326.23408889182804,2.535016911603787
5.010145847394279e-05,0.01717383476695339,230.20183929473944,326.23408889182804,2.535016911603787
5.122193091803228e-05,0.01755791158231646,230.9580883043173,326.23408889182804,2.535016911603787
5.195023800669044e-05,0.01780756151230246,231.44619270160703,326.23408889182804,2.535016911603787
5.2118308873303864e-05,0.01786517303460692,231.5584523213801,326.23408889182804,2.535016911603787
5.329480493959782e-05,0.018268453690738148,232.34035388809772,326.23408889182804,2.535016911603787
5.374299391723361e-05,0.018422084416883377,232.63644678562332,326.23408889182804,2.535016911603787
5.59279151832081e-05,0.019171034206841367,234.0663325138816,326.23408889182804,2.535016911603787
5.7496576604933376e-05,0.01970874174834967,235.07951268051087,326.23408889182804,2.535016911603787
5.839295456020496e-05,0.020016003200640127,235.65363165582664,326.23408889182804,2.535016911603787
5.951342700429444e-05,0.0204000800160032,236.36646958357218,326.23408889182804,2.535016911603787
5.984956873752129e-05,0.02051530306061212,236.57929779033384,326.23408889182804,2.535016911603787
6.018571047074813e-05,0.020630526105221043,236.79166032268577,326.23408889182804,2.535016911603787
6.141823015924656e-05,0.021053010602120423,237.56639668495563,326.23408889182804,2.535016911603787
6.281882071435842e-05,0.021533106621324266,238.4394562301656,326.23408889182804,2.535016911603787
6.343508055860763e-05,0.021744348869773954,238.8211938458001,326.23408889182804,2.535016911603787
6.371519866963e-05,0.021840368073614724,238.99423254903706,326.23408889182804,2.535016911603787
6.472362386931054e-05,0.02218603720744149,239.61473024340256,326.23408889182804,2.535016911603787
6.713263962410292e-05,0.023011802360472094,241.081963180395,326.23408889182804,2.535016911603787
6.836515931260135e-05,0.023434286857371475,241.8246901000778,326.23408889182804,2.535016911603787
6.95416553788953e-05,0.0238375675135027,242.5288001254696,326.23408889182804,2.535016911603787
7.088622231180269e-05,0.024298459691938386,243.32783337312904,326.23408889182804,2.535016911603787
7.239886011132348e-05,0.024816963392678536,244.21971366465306,326.23408889182804,2.535016911603787
7.351933255541297e-05,0.02520104020804161,244.87568738073702,326.23408889182804,2.535016911603787
7.391149791084429e-05,0.025335467093418683,245.10435553545977,326.23408889182804,2.535016911603787
7.430366326627561e-05,0.02546989397879576,245.3325509955357,326.23408889182804,2.535016911603787
7.699279713209037e-05,0.026391678335667135,246.88485660352885,326.23408889182804,2.535016911603787
7.794519870956642e-05,0.026718143628725745,247.42954186123762,326.23408889182804,2.535016911603787
7.811326957617985e-05,0.026775755151030207,247.5253927289497,326.23408889182804,2.535016911603787
7.917771839806485e-05,0.027140628125625125,248.13059104568683,326.23408889182804,2.535016911603787
7.956988375349618e-05,0.027275055011002202,248.3527579137553,326.23408889182804,2.535016911603787
7.996204910892749e-05,0.027409481896379276,248.5744981539966,326.23408889182804,2.535016911603787
8.024216721994986e-05,0.027505501100220046,248.73262445004036,326.23408889182804,2.535016911603787
8.248311210812883e-05,0.02827365473094619,249.98997618252258,326.23408889182804,2.535016911603787
8.36035845522183e-05,0.02865773154630926,250.6136507035918,326.23408889182804,2.535016911603787
8.5340316840557e-05,0.029253050610122025,251.57394216951943,326.23408889182804,2.535016911603787
8.634874204023753e-05,0.02959871974394879,252.1280331083844,326.23408889182804,2.535016911603787
8.679693101787332e-05,0.02975235047009402,252.37348507737528,326.23408889182804,2.535016911603787
8.954208850589255e-05,0.030693338667733546,253.86623314232457,326.23408889182804,2.535016911603787
9.127882079423124e-05,0.03128865773154631,254.80141301635132,326.23408889182804,2.535016911603787
9.223122237170732e-05,0.031615123024604924,255.3113064895127,326.23408889182804,2.535016911603787
9.335169481579678e-05,0.03199919983996799,255.908559597332,326.23408889182804,2.535016911603787
9.374386017122812e-05,0.032133626725345074,256.1169368320448,326.23408889182804,2.535016911603787
9.475228537090864e-05,0.032479295859171836,256.65120890595256,326.23408889182804,2.535016911603787
9.570468694838471e-05,0.032805761152230446,257.1537666066355,326.23408889182804,2.535016911603787
9.604082868161154e-05,0.032920984196839365,257.33067374112943,326.23408889182804,2.535016911603787
9.693720663688312e-05,0.03322824564912982,257.8012495170216,326.23408889182804,2.535016911603787
9.878598616963078e-05,0.0338619723944789,258.76648606638116,326.23408889182804,2.535016911603787
9.906610428065315e-05,0.033957991598319665,258.9121171373326,326.23408889182804,2.535016911603787
9.968236412490237e-05,0.034169233846769356,259.23194139109785,326.23408889182804,2.535016911603787
0.00010052271845796947,0.034457291458291656,259.6668254345724,326.23408889182804,2.535016911603787
0.00010164319090205896,0.034841368273654735,260.2444716361764,326.23408889182804,2.535016911603787
0.000102595592479535,0.03516783356671334,260.7335209816764,326.23408889182804,2.535016911603787
0.00010354799405701108,0.035494298859771956,261.22080294606104,326.23408889182804,2.535016911603787
0.00010466846650110053,0.03587837567513502,261.7918436550552,326.23408889182804,2.535016911603787
0.00010539677358975873,0.03612802560512103,262.1617420945613,326.23408889182804,2.535016911603787
0.00010758169485573321,0.03687697539507902,263.2655020280524,326.23408889182804,2.535016911603787
0.00010819795469998243,0.03708821764352871,263.5752337791227,326.23408889182804,2.535016911603787
0.00010965456887729875,0.0375875175035007,264.3046047952381,326.23408889182804,2.535016911603787
0.00011066299407697927,0.03793318663732746,264.8073419488292,326.23408889182804,2.535016911603787
0.00011127925392122849,0.038144428885777154,265.1136907649913,326.23408889182804,2.535016911603787
0.00011273586809854481,0.038643728745749145,265.83516970252316,326.23408889182804,2.535016911603787
0.00011290393896515823,0.03870134026805361,265.9181826734461,326.23408889182804,2.535016911603787
0.00011318405707618061,0.038797359471894374,266.05643060716943,326.23408889182804,2.535016911603787
0.00011368826967602088,0.03897019403880776,266.30494109369965,326.23408889182804,2.535016911603787
0.00011419248227586117,0.03914302860572115,266.5530221095441,326.23408889182804,2.535016911603787
0.00011486476574231483,0.03937347469493899,266.883133279775,326.23408889182804,2.535016911603787
0.00011721775787490274,0.040180036007201436,268.03263489050033,326.23408889182804,2.535016911603787
0.00011744185236372065,0.04025685137027406,268.1416397560858,326.23408889182804,2.535016911603787
0.00011777799409694751,0.04037207441488298,268.3049950812383,326.23408889182804,2.535016911603787
0.0001182261830745833,0.04052570514102821,268.5225196220822,326.23408889182804,2.535016911603787
0.00011923460827426382,0.040871374274854974,269.0107774094457,326.23408889182804,2.535016911603787
0.00012181169489566964,0.041754750950190045,270.25128647591714,326.23408889182804,2.535016911603787
0.00012326830907298595,0.042254050810162036,270.9479153520176,326.23408889182804,2.535016911603787
0.0001246688996280978,0.04273414682936587,271.6147295003369,326.23408889182804,2.535016911603787
0.0001248929941169157,0.04281096219243849,271.72114804314793,326.23408889182804,2.535016911603787
0.00012629358467202757,0.043291058211642336,272.38458465091367,326.23408889182804,2.535016911603787
0.00012763815160493492,0.04375195039007801,273.01878945860733,326.23408889182804,2.535016911603787
0.0001280863405825707,0.04390558111622324,273.2296113532418,326.23408889182804,2.535016911603787
0.0001289827185378423,0.0442128425685137,273.65039402395496,326.23408889182804,2.535016911603787
0.00012954295475988705,0.04440488097619524,273.9128041325971,326.23408889182804,2.535016911603787
0.00013083149807058996,0.04484656931386277,274.5146735049866,326.23408889182804,2.535016911603787
0.00013172787602586155,0.04515383076615323,274.9320024573085,326.23408889182804,2.535016911603787
0.0001329043720921555,0.045557111422284455,275.47806979757195,326.23408889182804,2.535016911603787
0.00013508929335813,0.046306061212242455,276.487219183305,326.23408889182804,2.535016911603787
0.0001360977185578105,0.04665173034606922,276.9508315300002,326.23408889182804,2.535016911603787
0.0001368260256464687,0.04690138027605521,277.2848298849807,326.23408889182804,2.535016911603787
0.00013783445084614921,0.047247049409881975,277.74614675765434,326.23408889182804,2.535016911603787
0.00013985130124551028,0.04793838767753551,278.66485048646314,326.23408889182804,2.535016911603787
0.00014119586817841769,0.0483992798559712,279.2744506247612,326.23408889182804,2.535016911603787
0.00014141996266723555,0.04847609521904381,279.3758301371057,326.23408889182804,2.535016911603787
0.000143716931177619,0.04926345269053811,280.4113832600004,326.23408889182804,2.535016911603787
0.00014466933275509504,0.049589917983596715,280.83886353283225,326.23408889182804,2.535016911603787
0.00014573378157698005,0.049954790958191636,281.31533888989685,326.23408889182804,2.535016911603787
0.00014635004142122927,0.05016603320664133,281.59057267599115,326.23408889182804,2.535016911603787
0.0001474144902431143,0.05053090618123625,282.06491423566854,326.23408889182804,2.535016911603787
0.00014915122253145296,0.051126225245049006,282.83598224379074,326.23408889182804,2.535016911603787
0.00014971145875349774,0.05131826365273055,283.0839658609958,326.23408889182804,2.535016911603787
0.00015150421466404092,0.05193278655731147,283.8750923546686,326.23408889182804,2.535016911603787
0.00015217649813049458,0.052163232646529306,284.17082245972085,326.23408889182804,2.535016911603787
0.00015290480521915273,0.0524128825765153,284.4906223465884,326.23408889182804,2.535016911603787
0.00015374515955221988,0.052700940188037615,284.8588849562518,326.23408889182804,2.535016911603787
0.00015480960837410484,0.05306581316263252,285.32422593292125,326.23408889182804,2.535016911603787
0.0001559861044403988,0.05346909381876375,285.8371007919278,326.23408889182804,2.535016911603787
0.00015805897846196438,0.05417963592718544,286.73708184306105,326.23408889182804,2.535016911603787
0.0001586192146840091,0.054371674334866976,286.9795283058015,326.23408889182804,2.535016911603787
0.0001590674036616449,0.054525305061012205,287.17324511044285,326.23408889182804,2.535016911603787
0.00016170051390525516,0.05542788557711542,288.3070618186194,326.23408889182804,2.535016911603787
0.00016192460839407308,0.05550470094018804,288.40322312451764,326.23408889182804,2.535016911603787
0.00016315712808257147,0.05592718543708741,288.9311854746194,326.23408889182804,2.535016911603787
0.00016422157690445648,0.05629205841168233,289.3859024428164,326.23408889182804,2.535016911603787
0.0001644456713932744,0.056368873774754955,289.48148569727954,326.23408889182804,2.535016911603787
0.00016618240368161308,0.05696419283856771,290.2205412656373,326.23408889182804,2.535016911603787
0.00016713480525908916,0.05729065813162633,290.6245507268145,326.23408889182804,2.535016911603787
0.00016987996274710838,0.05823164632926585,291.7840551539616,326.23408889182804,2.535016911603787
0.00017234500212410524,0.059076615323064616,292.8190304062474,326.23408889182804,2.535016911603787
0.0001737455926792171,0.05955671134226845,293.4045122630841,326.23408889182804,2.535016911603787
0.00017469799425669314,0.059883176635327065,293.80158892304246,326.23408889182804,2.535016911603787
0.00017559437221196473,0.06019043808761752,294.1745376148812,326.23408889182804,2.535016911603787
0.0001785076005665974,0.06118903780756152,295.38152506829255,326.23408889182804,2.535016911603787
0.0001788997659220287,0.06132346469293859,295.5434154822682,326.23408889182804,2.535016911603787
0.0001808605926991853,0.06199559911982397,296.35080076972906,326.23408889182804,2.535016911603787
0.0001817569706544569,0.06230286057211443,296.7187534644195,326.23408889182804,2.535016911603787
0.00018226118325429715,0.0624756951390278,296.92541583613377,326.23408889182804,2.535016911603787
0.00018248527774311507,0.06255251050210042,297.0171941962359,326.23408889182804,2.535016911603787
0.00018506236436452087,0.0634358871774355,298.06950553967806,326.23408889182804,2.535016911603787
0.00018595874231979245,0.06374314862972595,298.4341852174625,326.23408889182804,2.535016911603787
0.00018859185256340274,0.06464572914582917,299.50148769311676,326.23408889182804,2.535016911603787
0.00018988039587410562,0.0650874174834967,300.02166550836614,326.23408889182804,2.535016911603787
0.00019144905729583092,0.065625125025005,300.6530710216704,326.23408889182804,2.535016911603787
0.0001931857895841696,0.06622044408881776,301.3497782882683,326.23408889182804,2.535016911603787
0.00019346590769519196,0.06631646329265853,301.46192126165755,326.23408889182804,2.535016911603787
0.00019503456911691727,0.06685417083416684,302.0887555941784,326.23408889182804,2.535016911603787
0.00019604299431659779,0.0671998399679936,302.490682468667,326.23408889182804,2.535016911603787
0.00019654720691643807,0.06737267453490699,302.691343480378,326.23408889182804,2.535016911603787
0.0001986200809380036,0.06808321664332867,303.5141827883463,326.23408889182804,2.535016911603787
0.00019968452975988862,0.06844808961792359,303.93541998337156,326.23408889182804,2.535016911603787
0.00020002067149311548,0.06856331266253252,304.0682601976361,326.23408889182804,2.535016911603787
0.00020046886047075127,0.06871694338867775,304.24524512885233,326.23408889182804,2.535016911603787
0.00020175740378145415,0.06915863172634527,304.7532192457085,326.23408889182804,2.535016911603787
0.00020282185260333917,0.0695235047009402,305.1718964110469,326.23408889182804,2.535016911603787
0.00020388630142522418,0.06988837767553512,305.5897175011731,326.23408889182804,2.535016911603787
0.0002040543722918376,0.06994598919783958,305.6556114052111,326.23408889182804,2.535016911603787
0.00020562303371356286,0.07048369673934787,306.269603857877,326.23408889182804,2.535016911603787
0.00020674350615765237,0.07086777355471095,306.7070519867621,326.23408889182804,2.535016911603787
0.00020797602584615076,0.07129025805161032,307.1871783878685,326.23408889182804,2.535016911603787
0.00020825614395717312,0.07138627725545109,307.2961431142126,326.23408889182804,2.535016911603787
0.00021245791562250868,0.07282656531306261,308.9238156985351,326.23408889182804,2.535016911603787
0.0002130741754667579,0.0730378075615123,309.1614811063312,326.23408889182804,2.535016911603787
0.00021425067153305185,0.07344108821764353,309.6144628784412,326.23408889182804,2.535016911603787
0.00021559523846595923,0.07390198039607922,310.1309701562278,326.23408889182804,2.535016911603787
0.00021806027784295612,0.07474694938987798,311.0746490769697,326.23408889182804,2.535016911603787
0.0002208054353309753,0.0756879375875175,312.12068134532825,326.23408889182804,2.535016911603787
0.00022102952981979324,0.07576475295059013,312.20584717485417,326.23408889182804,2.535016911603787
0.00022142169517522453,0.0758991798359672,312.3548063899618,326.23408889182804,2.535016911603787
0.00022243012037490508,0.07624484896979396,312.73737267926816,326.23408889182804,2.535016911603787
0.00022310240384135877,0.07647529505901181,312.99204114702826,326.23408889182804,2.535016911603787
0.00022349456919679007,0.07660972194438888,313.1404595414469,326.23408889182804,2.535016911603787
0.0002241108290410393,0.07682096419283857,313.37348340445794,326.23408889182804,2.535016911603787
0.00022506323061851537,0.07714742948589719,313.73312025744053,326.23408889182804,2.535016911603787
0.0002252313014851288,0.07720504100820165,313.79652392332395,326.23408889182804,2.535016911603787
0.00022579153770717353,0.07739707941588318,314.00773633877225,326.23408889182804,2.535016911603787
0.00022651984479583168,0.07764672934586918,314.28200717684217,326.23408889182804,2.535016911603787
0.00022937704952825987,0.07862612522504502,315.3546880611146,326.23408889182804,2.535016911603787
0.0002315059471720299,0.07935587117423486,316.15055575756156,326.23408889182804,2.535016911603787
0.0002318981125274612,0.07949029805961193,316.29685111485776,326.23408889182804,2.535016911603787
0.0002353715771041386,0.08068093618723746,317.5884251354062,326.23408889182804,2.535016911603787
0.00023671614403704598,0.08114182836567314,318.0863909349823,326.23408889182804,2.535016911603787
0.00023828480545877125,0.08167953590718144,318.6659589691251,326.23408889182804,2.535016911603787
0.00023873299443640704,0.08183316663332667,318.83127628471436,326.23408889182804,2.535016911603787
0.00024030165585813235,0.08237087417483498,319.40893610539007,326.23408889182804,2.535016911603787
0.00024203838814647102,0.08296619323864773,320.0467753245422,326.23408889182804,2.535016911603787
0.00024355102594599183,0.08348469693938788,320.6008597768593,326.23408889182804,2.535016911603787
0.00024388716767921869,0.08359991998399681,320.7238072064262,326.23408889182804,2.535016911603787
0.00024584799445637526,0.08427205441088217,321.43968778876973,326.23408889182804,2.535016911603787
0.00024730460863369157,0.08477135427085418,321.9700441506575,326.23408889182804,2.535016911603787
0.00024797689210014523,0.08500180036007202,322.2144129796933,326.23408889182804,2.535016911603787
0.0002482570102111676,0.08509781956391278,322.31615705279233,326.23408889182804,2.535016911603787
0.0002493214590330526,0.0854626925385077,322.7023768892321,326.23408889182804,2.535016911603787
0.0002501618133661198,0.08575075015003002,323.0068332216465,326.23408889182804,2.535016911603787
0.0002507220495881645,0.08594278855771155,323.20958254550203,326.23408889182804,2.535016911603787
0.0002526268527431166,0.08659571914382877,323.89761247570823,326.23408889182804,2.535016911603787
0.0002530750417207524,0.086749349869974,324.059207484501,326.23408889182804,2.535016911603787
0.0002538033488094106,0.08699899979996,324.32156153374245,326.23408889182804,2.535016911603787
0.00025447563227586425,0.08722944588917785,324.5634740211925,326.23408889182804,2.535016911603787
0.00025514791574231797,0.08745989197839568,324.8051373901228,326.23408889182804,2.535016911603787
0.0002587334275634043,0.08868893778755751,326.08983874942277,326.23408889182804,2.535016911603787
0.0002608063015849698,0.0893994798959792,326.8293892613682,326.23408889182804,2.535016911603787
0.00026181472678465034,0.08974514902980596,327.1883414280037,326.23408889182804,2.535016911603787
0.00026203882127346826,0.08982196439287858,327.2680353045416,326.23408889182804,2.535016911603787
0.0002631032700953533,0.0901868373674735,327.6462188333053,326.23408889182804,2.535016911603787
0.0002639996480506249,0.09049409881976396,327.964226575388,326.23408889182804,2.535016911603787
0.0002644478370282607,0.09064772954590919,328.123072512295,326.23408889182804,2.535016911603787
0.00026596047482778146,0.09116623324664934,328.65840409892814,326.23408889182804,2.535016911603787
0.0002674731126273023,0.09168473694738949,329.1925495712295,326.23408889182804,2.535016911603787
0.0002695459866488678,0.09239527905581117,329.9226172541448,326.23408889182804,2.535016911603787
0.0002714507898038199,0.09304820964192839,330.5915620669816,326.23408889182804,2.535016911603787
0.00027296342760334074,0.09356671334266854,331.1214797226686,326.23408889182804,2.535016911603787
0.0002764368921800181,0.09475735147029406,332.33401224225196,326.23408889182804,2.535016911603787
0.0002781736244683568,0.09535267053410683,332.9380492264247,326.23408889182804,2.535016911603787
0.0002790700024236284,0.09565993198639729,333.2492346905621,326.23408889182804,2.535016911603787
0.00027929409691244625,0.0957367473494699,333.32697011762815,326.23408889182804,2.535016911603787
0.000281030829200785,0.09633206641328267,333.9285970981511,326.23408889182804,2.535016911603787
0.0002823753961336924,0.09679295859171835,334.39337753113773,326.23408889182804,2.535016911603787
0.0002831037032223505,0.09704260852170435,334.6447731883337,326.23408889182804,2.535016911603787
0.00028343984495557737,0.09715783156631327,334.7607168706047,326.23408889182804,2.535016911603787
0.00028360791582219077,0.09721544308861772,334.81866860121323,326.23408889182804,2.535016911603787
0.0002843922465330534,0.09748429685937188,335.08893311282594,326.23408889182804,2.535016911603787
0.00028540067173273394,0.09782996599319864,335.43598929959836,326.23408889182804,2.535016911603787
0.0002867452386656413,0.09829085817163433,335.89798785579757,326.23408889182804,2.535016911603787
0.0002869133095322547,0.09834846969393879,335.95567821142555,326.23408889182804,2.535016911603787
0.0002871934276432771,0.09844448889777956,336.05179952428335,326.23408889182804,2.535016911603787
0.0002894343725314561,0.0992126425285057,336.81945812533525,326.23408889182804,2.535016911603787
0.000289658467020274,0.09928945789157832,336.89609627529023,326.23408889182804,2.535016911603787
0.00028993858513129634,0.09938547709541909,336.9918614530506,326.23408889182804,2.535016911603787
0.00029044279773113665,0.09955831166233248,337.1641478924973,326.23408889182804,2.535016911603787
0.00029094701033097686,0.09973114622924585,337.3363177256384,326.23408889182804,2.535016911603787