File: datasets/aisi_316_L/data/M1/train_5.csv
Time(s),Strain(%),Stress(MPa),Temp(C),Log_SR(s-1)
0.0,0.0,0.0,260.64324284296697,-2.2612912418496176
0.0035042289286278615,1.92e-05,3.4743956999999996,260.64324284296697,-2.2612912418496176
0.005840381547713103,3.2e-05,5.790659499999999,260.64324284296697,-2.2612912418496176
0.00832254370549117,4.56e-05,8.2516897875,260.64324284296697,-2.2612912418496176
0.010074658169805102,5.52e-05,9.9888876375,260.64324284296697,-2.2612912418496176
0.013578887098432963,7.439999999999999e-05,13.463283337499998,260.64324284296697,-2.2612912418496176
0.019565278184838893,0.00010719999999999999,19.398709325,260.64324284296697,-2.2612912418496176
0.022193449881309793,0.0001216,22.0045061,260.64324284296697,-2.2612912418496176
0.02452960250039503,0.0001344,24.3207699,260.64324284296697,-2.2612912418496176
0.0286178695837942,0.0001568,28.374231549999998,260.64324284296697,-2.2612912418496176
0.030515993586800964,0.0001672,30.2561958875,260.64324284296697,-2.2612912418496176
0.0328521462058862,0.00017999999999999998,32.5724596875,260.64324284296697,-2.2612912418496176
0.03387421297673599,0.00018559999999999998,33.585825099999994,260.64324284296697,-2.2612912418496176
0.03956858498575627,0.00021679999999999998,39.2317181125,260.64324284296697,-2.2612912418496176
0.045846995149547855,0.0002512,45.456677074999995,260.64324284296697,-2.2612912418496176
0.04657704284301199,0.00025519999999999997,46.180509512499995,260.64324284296697,-2.2612912418496176
0.04759910961386179,0.0002608,47.193874925,260.64324284296697,-2.2612912418496176
0.05548362470327447,0.00030399999999999996,55.011265249999994,260.64324284296697,-2.2612912418496176
0.059571891786673645,0.00032639999999999996,59.0647269,260.64324284296697,-2.2612912418496176
0.06015592994144496,0.0003296,59.64379285,260.64324284296697,-2.2612912418496176
0.06161602532837323,0.00033759999999999997,61.09145772499999,260.64324284296697,-2.2612912418496176
0.06614232102785089,0.00036239999999999997,65.5792188375,260.64324284296697,-2.2612912418496176
0.07008457857255723,0.000384,69.487914,260.64324284296697,-2.2612912418496176
0.07782308412327708,0.00042639999999999996,77.16053783749999,260.64324284296697,-2.2612912418496176
0.08088928443582648,0.0004432,80.200634075,260.64324284296697,-2.2612912418496176
0.08249538936144758,0.000452,81.79306543749999,260.64324284296697,-2.2612912418496176
0.0852695705966113,0.00046719999999999997,84.5436287,260.64324284296697,-2.2612912418496176
0.08775173275438937,0.0004808,87.0046589875,260.64324284296697,-2.2612912418496176
0.08877379952523917,0.0004864,88.0180244,260.64324284296697,-2.2612912418496176
0.08994187583478178,0.0004927999999999999,89.17615629999999,260.64324284296697,-2.2612912418496176
0.09154798076040288,0.0005015999999999999,90.7685876625,260.64324284296697,-2.2612912418496176
0.09519821922772358,0.0005216,94.38774985,260.64324284296697,-2.2612912418496176
0.09914047677242992,0.0005432,98.2964450125,260.64324284296697,-2.2612912418496176
0.10293672477844343,0.0005639999999999999,102.06037368749999,260.64324284296697,-2.2612912418496176
0.10498085832014302,0.0005752,104.0871045125,260.64324284296697,-2.2612912418496176
0.1086310967874637,0.0005951999999999999,107.70626669999999,260.64324284296697,-2.2612912418496176
0.11052922079047046,0.0006056,109.5882310375,260.64324284296697,-2.2612912418496176
0.11315739248694137,0.00062,112.1940278125,260.64324284296697,-2.2612912418496176
0.11417945925779115,0.0006255999999999999,113.20739322499999,260.64324284296697,-2.2612912418496176
0.11680763095426205,0.0006399999999999999,115.81318999999999,260.64324284296697,-2.2612912418496176
0.11797570726380467,0.0006464,116.97132189999999,260.64324284296697,-2.2612912418496176
0.12147993619243252,0.0006655999999999999,120.44571759999998,260.64324284296697,-2.2612912418496176
0.1223559934245895,0.0006703999999999999,121.31431652499998,260.64324284296697,-2.2612912418496176
0.12323205065674646,0.0006751999999999999,122.18291544999998,260.64324284296697,-2.2612912418496176
0.12790435589491697,0.0007008,126.81544305,260.64324284296697,-2.2612912418496176
0.13009449897530936,0.0007128,128.9869403625,260.64324284296697,-2.2612912418496176
0.13111656574615915,0.0007184,130.00030577500002,260.64324284296697,-2.2612912418496176
0.13213863251700894,0.0007239999999999999,131.0136711875,260.64324284296697,-2.2612912418496176
0.13535084236825115,0.0007415999999999999,134.19853391249998,260.64324284296697,-2.2612912418496176
0.13885507129687902,0.0007608,137.67292961249998,260.64324284296697,-2.2612912418496176
0.14265131930289252,0.0007815999999999999,141.43685828749997,260.64324284296697,-2.2612912418496176
0.14498747192197778,0.0007944,143.7531220875,260.64324284296697,-2.2612912418496176
0.14659357684759888,0.0008032,145.34555345,260.64324284296697,-2.2612912418496176
0.14703160546367736,0.0008056,145.7798529125,260.64324284296697,-2.2612912418496176
0.14790766269583433,0.0008104,146.6484518375,260.64324284296697,-2.2612912418496176
0.15184992024054067,0.000832,150.557147,260.64324284296697,-2.2612912418496176
0.15433208239831875,0.0008456,153.01817728749998,260.64324284296697,-2.2612912418496176
0.15564616824655417,0.0008527999999999999,154.32107567499997,260.64324284296697,-2.2612912418496176
0.16061049256211032,0.0008799999999999999,159.24313625,260.64324284296697,-2.2612912418496176
0.16294664518119556,0.0008927999999999999,161.55940005,260.64324284296697,-2.2612912418496176
0.16353068333596688,0.000896,162.138466,260.64324284296697,-2.2612912418496176
0.16601284549374495,0.0009096,164.5994962875,260.64324284296697,-2.2612912418496176
0.17097716980930108,0.0009368,169.5215568625,260.64324284296697,-2.2612912418496176
0.1743353891992361,0.0009551999999999999,172.851186075,260.64324284296697,-2.2612912418496176
0.17667154181832137,0.000968,175.167449875,260.64324284296697,-2.2612912418496176
0.1784236562826353,0.0009776,176.904647725,260.64324284296697,-2.2612912418496176
0.18148985659518466,0.0009943999999999999,179.94474396249998,260.64324284296697,-2.2612912418496176
0.18221990428864882,0.0009984,180.6685764,260.64324284296697,-2.2612912418496176
0.18660019044943363,0.0010224,181.68346765434836,260.64324284296697,-2.2612912418496176
0.1874762476815906,0.0010272,181.71153274447465,260.64324284296697,-2.2612912418496176
0.19536076277100328,0.0010704,181.9618578984371,260.64324284296697,-2.2612912418496176
0.19652883908054591,0.0010768,181.99860524546128,260.64324284296697,-2.2612912418496176
0.20120114431871639,0.0011024,182.144750748969,260.64324284296697,-2.2612912418496176
0.2022232110895662,0.001108,182.17654294892748,260.64324284296697,-2.2612912418496176
0.20353729693780165,0.0011152,182.21732670515638,260.64324284296697,-2.2612912418496176
0.2049973923247299,0.0011232,182.26252174033655,260.64324284296697,-2.2612912418496176
0.20777157355989362,0.0011384,182.3480479336885,260.64324284296697,-2.2612912418496176
0.21361195510760675,0.0011704,182.5266608233389,260.64324284296697,-2.2612912418496176
0.2160941172653848,0.001184,182.60199340707257,260.64324284296697,-2.2612912418496176
0.22018238434878398,0.0012064,182.7253390690984,260.64324284296697,-2.2612912418496176
0.22222651789048356,0.0012175999999999999,182.78667671200114,260.64324284296697,-2.2612912418496176
0.2245626705095688,0.0012304,182.85650807737701,260.64324284296697,-2.2612912418496176
0.22514670866434008,0.0012335999999999998,182.87392157907556,260.64324284296697,-2.2612912418496176
0.23011103297989624,0.0012607999999999999,183.02123175028325,260.64324284296697,-2.2612912418496176
0.23449131914068108,0.0012848,183.15018506463224,260.64324284296697,-2.2612912418496176
0.2393096339175444,0.0013112,183.2909534402407,260.64324284296697,-2.2612912418496176
0.24076972930447266,0.0013192,183.3333917220155,260.64324284296697,-2.2612912418496176
0.2436899200783292,0.0013352,183.41796836965358,260.64324284296697,-2.2612912418496176
0.244711986849179,0.0013407999999999998,183.44747669470166,260.64324284296697,-2.2612912418496176
0.2508443874742778,0.0013744,183.62352770320206,260.64324284296697,-2.2612912418496176
0.25814486440891915,0.0014144,183.83093843915498,260.64324284296697,-2.2612912418496176
0.26062702656669723,0.001428,183.90093529350315,260.64324284296697,-2.2612912418496176
0.2622331314923183,0.0014368,183.94608887513664,260.64324284296697,-2.2612912418496176
0.26456928411140357,0.0014495999999999999,184.01157475131356,260.64324284296697,-2.2612912418496176
0.26602937949833183,0.0014575999999999999,184.05238892531963,260.64324284296697,-2.2612912418496176
0.26661341765310315,0.0014608,184.06869012207852,260.64324284296697,-2.2612912418496176
0.2705556751978095,0.0014824,184.17836119566869,260.64324284296697,-2.2612912418496176
0.2755199995133656,0.0015095999999999998,184.31558298233736,260.64324284296697,-2.2612912418496176
0.2763960567455226,0.0015144,184.3396981553369,260.64324284296697,-2.2612912418496176
0.27858619982591504,0.0015264,184.39985603706577,260.64324284296697,-2.2612912418496176
0.2801923047515361,0.0015352,184.44385465588937,260.64324284296697,-2.2612912418496176
0.28179840967715725,0.001544,184.48775502328996,260.64324284296697,-2.2612912418496176
0.28457259091232096,0.0015592,184.56335378168407,260.64324284296697,-2.2612912418496176
0.2872007626087918,0.0015735999999999999,184.63470896435172,260.64324284296697,-2.2612912418496176
0.2874927816861775,0.0015752,184.64262156696847,260.64324284296697,-2.2612912418496176
0.2943552300047404,0.0016128,184.82767498192854,260.64324284296697,-2.2612912418496176
0.2980054684720611,0.0016328,184.9254217440473,260.64324284296697,-2.2612912418496176
0.29888152570421805,0.0016376,184.94881135098052,260.64324284296697,-2.2612912418496176
0.3015096974006889,0.0016519999999999998,185.01882027133252,260.64324284296697,-2.2612912418496176
0.30311580232631,0.0016607999999999998,185.0614863526432,260.64324284296697,-2.2612912418496176
0.3088101743353303,0.001692,185.21205167275204,260.64324284296697,-2.2612912418496176
0.31173036510918684,0.0017079999999999999,185.28884438671489,260.64324284296697,-2.2612912418496176
0.31450454634435054,0.0017231999999999998,185.36153801526532,260.64324284296697,-2.2612912418496176
0.3161106512699717,0.0017319999999999998,185.4035094992329,260.64324284296697,-2.2612912418496176
0.3254552617463127,0.0017832,185.6460776140821,260.64324284296697,-2.2612912418496176
0.32706136667193375,0.001792,185.68749395425903,260.64324284296697,-2.2612912418496176
0.328521462058862,0.0018,185.72507639282202,260.64324284296697,-2.2612912418496176
0.33304775775833967,0.0018248,185.84117010035035,260.64324284296697,-2.2612912418496176
0.33552991991611775,0.0018384,185.90457309132475,260.64324284296697,-2.2612912418496176
0.33699001530304606,0.0018464,185.94178352103899,260.64324284296697,-2.2612912418496176
0.3396181869995169,0.0018608,186.00860423016053,260.64324284296697,-2.2612912418496176
0.342976406389452,0.0018792,186.0936934987129,260.64324284296697,-2.2612912418496176
0.3461886162406942,0.0018968,186.1747797062026,260.64324284296697,-2.2612912418496176
0.3502768833240933,0.0019191999999999998,186.27755720634227,260.64324284296697,-2.2612912418496176
0.3507149119401718,0.0019215999999999999,186.28854126236388,260.64324284296697,-2.2612912418496176
0.35261303594317855,0.001932,186.33607714701014,260.64324284296697,-2.2612912418496176
0.35290505502056424,0.0019336,186.34338149299,260.64324284296697,-2.2612912418496176
0.3546571694848782,0.0019432,186.3871581699209,260.64324284296697,-2.2612912418496176
0.3574313507200419,0.0019584,186.45629913805158,260.64324284296697,-2.2612912418496176
0.3580153888748132,0.0019616,186.47082842766926,260.64324284296697,-2.2612912418496176
0.36151961780344105,0.0019808,186.55781083724216,260.64324284296697,-2.2612912418496176
0.36473182765468326,0.0019984,186.63725628707417,260.64324284296697,-2.2612912418496176
0.36838206612200397,0.0020184,186.72720472583083,260.64324284296697,-2.2612912418496176
0.37042619966370355,0.0020296,186.77742400434383,260.64324284296697,-2.2612912418496176
0.3746604762857956,0.0020528,186.88110714121353,260.64324284296697,-2.2612912418496176
0.3756825430566453,0.0020583999999999997,186.9060655151073,260.64324284296697,-2.2612912418496176
0.3777266765983449,0.0020696,186.95590296080067,260.64324284296697,-2.2612912418496176
0.382691000913901,0.0020968,187.0765008602721,260.64324284296697,-2.2612912418496176
0.38648724891991454,0.0021176,187.1683115583345,260.64324284296697,-2.2612912418496176
0.38750931569076436,0.0021232,187.19296964640057,260.64324284296697,-2.2612912418496176
0.38999147784854243,0.0021368,187.25274821437884,260.64324284296697,-2.2612912418496176
0.39276565908370614,0.002152,187.31938423647674,260.64324284296697,-2.2612912418496176
0.39451777354802015,0.0021616,187.36137558484788,260.64324284296697,-2.2612912418496176
0.4003581550957332,0.0021936,187.50082441612992,260.64324284296697,-2.2612912418496176
0.40196426002135427,0.0022023999999999998,187.5390334692389,260.64324284296697,-2.2612912418496176
0.4031323363308969,0.0022088,187.56678448391068,260.64324284296697,-2.2612912418496176
0.4060525271047535,0.0022248,187.63602517563098,260.64324284296697,-2.2612912418496176
0.4078046415690674,0.0022344,187.67747637931282,260.64324284296697,-2.2612912418496176
0.41393704219416616,0.002268,187.82201177496157,260.64324284296697,-2.2612912418496176
0.41437507081024466,0.0022704,187.83230366445986,260.64324284296697,-2.2612912418496176
0.4180253092775653,0.0022903999999999997,187.9179050298114,260.64324284296697,-2.2612912418496176
0.42050747143534345,0.002304,187.97594750994313,260.64324284296697,-2.2612912418496176
0.42094550005142184,0.0023063999999999997,187.98617641478057,260.64324284296697,-2.2612912418496176
0.42167554774488597,0.0023103999999999998,188.00321536952177,260.64324284296697,-2.2612912418496176
0.4235736717478928,0.0023208,188.04746289626232,260.64324284296697,-2.2612912418496176
0.4288300151408346,0.0023496,188.16959274860886,260.64324284296697,-2.2612912418496176
0.4348164062272405,0.0023824,188.30797622116003,260.64324284296697,-2.2612912418496176
0.4364225111528616,0.0023912,188.34497682385762,260.64324284296697,-2.2612912418496176
0.44197087362318904,0.0024216,188.4723904700149,260.64324284296697,-2.2612912418496176
0.44386899762619575,0.0024319999999999997,188.51583594092762,260.64324284296697,-2.2612912418496176
0.4467891884000524,0.002448,188.58253391097352,260.64324284296697,-2.2612912418496176
0.4532136081025368,0.0024832,188.7286739048162,260.64324284296697,-2.2612912418496176
0.4586159610341714,0.0025128,188.85094006784453,260.64324284296697,-2.2612912418496176
0.4613901422693351,0.002528,188.9135070337814,260.64324284296697,-2.2612912418496176
0.4667924952009697,0.0025575999999999997,189.0349285146949,260.64324284296697,-2.2612912418496176
0.4719028290552187,0.0025856,189.1492832375795,260.64324284296697,-2.2612912418496176
0.47350893398083976,0.0025943999999999997,189.18512341257994,260.64324284296697,-2.2612912418496176
0.47423898167430395,0.0025984,189.2013987250218,260.64324284296697,-2.2612912418496176
0.4751150389064609,0.0026032,189.2209162076696,260.64324284296697,-2.2612912418496176
0.4789112869124745,0.002624,189.3053302976705,260.64324284296697,-2.2612912418496176
0.4811014299928668,0.002636,189.3539120250431,260.64324284296697,-2.2612912418496176
0.4866497924631943,0.0026663999999999998,189.4766012847673,260.64324284296697,-2.2612912418496176
0.48854791646620105,0.0026768,189.51844852985565,260.64324284296697,-2.2612912418496176
0.4901540213918221,0.0026856,189.5538082345865,260.64324284296697,-2.2612912418496176
0.4932202217043715,0.0027023999999999998,189.6211878994812,260.64324284296697,-2.2612912418496176
0.5003746891003201,0.0027416,189.77777499858306,260.64324284296697,-2.2612912418496176
0.5040249275676407,0.0027616,189.85732981736226,260.64324284296697,-2.2612912418496176
0.5053390134158763,0.0027688,189.88591450516614,260.64324284296697,-2.2612912418496176
0.5078211755736542,0.0027824,189.93982883426764,260.64324284296697,-2.2612912418496176
0.5082592041897328,0.0027848,189.9493324491798,260.64324284296697,-2.2612912418496176
0.5136615571213674,0.0028144,190.06628228534302,260.64324284296697,-2.2612912418496176
0.5164357383565311,0.0028296,190.12615113079627,260.64324284296697,-2.2612912418496176
0.5197939577464661,0.002848,190.19845639354568,260.64324284296697,-2.2612912418496176
0.5228601580590155,0.0028648,190.26431528945517,260.64324284296697,-2.2612912418496176
0.5237362152911725,0.0028696,190.2831044290792,260.64324284296697,-2.2612912418496176
0.5262183774489505,0.0028832,190.33627387720966,260.64324284296697,-2.2612912418496176
0.5287005396067286,0.0028967999999999997,190.38934560310005,260.64324284296697,-2.2612912418496176
0.5298686159162712,0.0029032,190.4142869008344,260.64324284296697,-2.2612912418496176
0.5341028925383633,0.0029264,190.5045199085373,260.64324284296697,-2.2612912418496176
0.5389212073152265,0.0029527999999999998,190.60686017635095,260.64324284296697,-2.2612912418496176
0.5440315411694755,0.0029808,190.7150137125743,260.64324284296697,-2.2612912418496176
0.546221684249868,0.0029928,190.76124385728946,260.64324284296697,-2.2612912418496176
0.5481198082528747,0.0030031999999999997,190.80125153715375,260.64324284296697,-2.2612912418496176
0.5519160562588882,0.0030239999999999998,190.88110516650661,260.64324284296697,-2.2612912418496176
0.5555662947262089,0.003044,190.95768573593222,260.64324284296697,-2.2612912418496176
0.558924514116144,0.0030624,191.02796672658332,260.64324284296697,-2.2612912418496176
0.5662249910507853,0.0031024,191.18018583681186,260.64324284296697,-2.2612912418496176
0.5687071532085634,0.003116,191.23176572106104,260.64324284296697,-2.2612912418496176
0.5748395538336621,0.0031496,191.35882339741,260.64324284296697,-2.2612912418496176
0.5755696015271263,0.0031536,191.37391401888001,260.64324284296697,-2.2612912418496176
0.5771757064527473,0.0031623999999999997,191.4070871345832,260.64324284296697,-2.2612912418496176
0.5856442596969313,0.0032088,191.58140813967316,260.64324284296697,-2.2612912418496176
0.5888564695481736,0.0032264,191.64727238267614,260.64324284296697,-2.2612912418496176
0.5963029560215078,0.0032672,191.79942110046935,260.64324284296697,-2.2612912418496176
0.6012672803370639,0.0032944,191.90044211309316,260.64324284296697,-2.2612912418496176
0.6049175188043846,0.0033144,191.97451486505548,260.64324284296697,-2.2612912418496176
0.60623160465262,0.0033215999999999996,192.00113835582732,260.64324284296697,-2.2612912418496176
0.6101738621973264,0.0033431999999999997,192.0808741140544,260.64324284296697,-2.2612912418496176
0.6129480434324901,0.0033583999999999997,192.13686406878116,260.64324284296697,-2.2612912418496176
0.6157222246676539,0.0033736,192.19275528093834,260.64324284296697,-2.2612912418496176
0.6228766920636024,0.0034127999999999997,192.3364444163652,260.64324284296697,-2.2612912418496176
0.6237527492957594,0.0034176,192.35399466225658,260.64324284296697,-2.2612912418496176
0.6295931308434725,0.0034495999999999997,192.4707515987772,260.64324284296697,-2.2612912418496176
0.6298851499208581,0.0034511999999999998,192.47657833214717,260.64324284296697,-2.2612912418496176
0.6309072166917079,0.0034568,192.49696360773302,260.64324284296697,-2.2612912418496176
0.6408358653228202,0.0035112,192.6943262989312,260.64324284296697,-2.2612912418496176
0.6439020656353696,0.003528,192.75503505844804,260.64324284296697,-2.2612912418496176
0.6450701419449122,0.0035344,192.77813253565455,260.64324284296697,-2.2612912418496176
0.646968265947919,0.0035448,192.81563117724443,260.64324284296697,-2.2612912418496176
0.6507645139539325,0.0035656,192.89049998898068,260.64324284296697,-2.2612912418496176
0.6517865807247822,0.0035711999999999996,192.91062784969128,260.64324284296697,-2.2612912418496176
0.6522246093408607,0.0035735999999999997,192.91925030712022,260.64324284296697,-2.2612912418496176
0.6539767238051747,0.0035832,192.9537175768319,260.64324284296697,-2.2612912418496176
0.6558748478081814,0.0035935999999999997,192.99101650355323,260.64324284296697,-2.2612912418496176
0.6566048955016456,0.0035976,193.0053510320601,260.64324284296697,-2.2612912418496176
0.6582110004272667,0.0036063999999999996,193.03686513349544,260.64324284296697,-2.2612912418496176
0.6604011435076591,0.0036184,193.07979061973623,260.64324284296697,-2.2612912418496176
0.663905372436287,0.0036376,193.14835609789793,260.64324284296697,-2.2612912418496176
0.6659495059779865,0.0036488,193.1882874470969,260.64324284296697,-2.2612912418496176
0.6677016204423005,0.0036584,193.22247628628566,260.64324284296697,-2.2612912418496176
0.6710598398322355,0.0036768,193.28790725469264,260.64324284296697,-2.2612912418496176
0.6716438779870068,0.0036799999999999997,193.29927350557676,260.64324284296697,-2.2612912418496176
0.6761701736864845,0.0037048,193.38723162957928,260.64324284296697,-2.2612912418496176
0.6809884884633477,0.0037311999999999996,193.48061251882442,260.64324284296697,-2.2612912418496176
0.6830326220050473,0.0037424,193.52015076597183,260.64324284296697,-2.2612912418496176
0.6840546887758971,0.003748,193.5399025822509,260.64324284296697,-2.2612912418496176
0.6888730035527605,0.0037744,193.63286370228255,260.64324284296697,-2.2612912418496176
0.6925232420200812,0.0037944,193.70312006640654,260.64324284296697,-2.2612912418496176
0.6950054041778592,0.0038079999999999998,193.75081191945165,260.64324284296697,-2.2612912418496176
0.6973415567969444,0.0038207999999999996,193.79563772399578,260.64324284296697,-2.2612912418496176
0.7034739574220432,0.0038544,193.91302769312756,260.64324284296697,-2.2612912418496176
0.7049340528089715,0.0038623999999999998,193.94091878050565,260.64324284296697,-2.2612912418496176
0.7062481386572069,0.0038696,193.96600150184082,260.64324284296697,-2.2612912418496176
0.7177828922139404,0.0039328,194.18539643471618,260.64324284296697,-2.2612912418496176
0.7193889971395615,0.0039416,194.21583567784515,260.64324284296697,-2.2612912418496176
0.7233312546842678,0.0039632,194.29043803348608,260.64324284296697,-2.2612912418496176
0.7259594263807386,0.0039775999999999995,194.34008486113854,260.64324284296697,-2.2612912418496176
0.8351955909024614,0.004576115223044609,196.3454950972844,260.64324284296697,-2.2612912418496176
0.8632350302193478,0.004729745949189838,196.84340373347783,260.64324284296697,-2.2612912418496176
0.8807596797924017,0.0048257651530306065,197.15139540723277,260.64324284296697,-2.2612912418496176
0.9052941891946772,0.004960192038407682,197.57859830701491,260.64324284296697,-2.2612912418496176
0.9964223669745575,0.0054594918983796765,199.1272875750139,260.64324284296697,-2.2612912418496176
1.066520965266773,0.0058435687137427484,200.28125326730208,260.64324284296697,-2.2612912418496176
1.0945604045836594,0.0059971994398879775,200.73450813769878,260.64324284296697,-2.2612912418496176
1.18568858236354,0.006496499299859972,202.17725650105328,260.64324284296697,-2.2612912418496176
1.392479447325576,0.007629525905181036,205.29946055185673,260.64324284296697,-2.2612912418496176
1.424023816557073,0.007802360472094419,205.75932311298982,260.64324284296697,-2.2612912418496176
1.5466963635684505,0.008474494898979796,207.51113123806556,260.64324284296697,-2.2612912418496176
1.58875552254378,0.00870494098819764,208.09916041446772,260.64324284296697,-2.2612912418496176
1.6939034199821035,0.009281056211242249,209.5432731695907,260.64324284296697,-2.2612912418496176
1.8516252661395889,0.010145229045809162,211.64551294817488,260.64324284296697,-2.2612912418496176
2.0268717618701277,0.011105421084216843,213.90099328516098,260.64324284296697,-2.2612912418496176
2.0654259909308466,0.011316663332666534,214.38683698263182,260.64324284296697,-2.2612912418496176
2.128514729393841,0.0116623324664933,215.17429301791606,260.64324284296697,-2.2612912418496176
2.174078818283781,0.011911982396479295,215.73736063435376,260.64324284296697,-2.2612912418496176
2.247682346490607,0.012315263052610522,216.6373049362656,260.64324284296697,-2.2612912418496176
2.3282957345266553,0.012756951390278055,217.60987053353932,260.64324284296697,-2.2612912418496176
2.398394332818871,0.013141028205641128,218.444952240608,260.64324284296697,-2.2612912418496176
2.4404534917942002,0.013371474294858972,218.94143305154938,260.64324284296697,-2.2612912418496176
2.5701358986347995,0.014082016403280656,220.45164881884267,260.64324284296697,-2.2612912418496176
2.6367295670124045,0.014446889377875576,221.21559517496013,260.64324284296697,-2.2612912418496176
2.6717788661585122,0.014638927785557112,221.61464769163814,260.64324284296697,-2.2612912418496176
2.7804316935114466,0.015234246849369875,222.8389300189903,260.64324284296697,-2.2612912418496176
2.804966202913722,0.01536867373474695,223.1127816390808,260.64324284296697,-2.2612912418496176
2.8330056422306082,0.01552230446089218,223.42461361636643,260.64324284296697,-2.2612912418496176
2.850530291803662,0.015618323664732947,223.6188974849269,260.64324284296697,-2.2612912418496176
2.9311436798397104,0.01606001200240048,224.5066709998287,260.64324284296697,-2.2612912418496176
2.9767077687296504,0.016309661932386477,225.0042428225536,260.64324284296697,-2.2612912418496176
2.997737348217315,0.0164248849769954,225.23288866298313,260.64324284296697,-2.2612912418496176
3.0503112969364765,0.0167129425885177,225.80178336555628,260.64324284296697,-2.2612912418496176
3.127419755057914,0.017135427085417085,226.62929309433565,260.64324284296697,-2.2612912418496176
3.2851416012153996,0.017999599919983997,228.29754481456598,260.64324284296697,-2.2612912418496176
3.3622500593368367,0.018422084416883377,229.10174022349733,260.64324284296697,-2.2612912418496176
3.46739795677516,0.018998199639927986,230.18687288074568,260.64324284296697,-2.2612912418496176
3.551516274725819,0.019459091818363673,231.04576620263373,260.64324284296697,-2.2612912418496176
3.611100083274202,0.019785557111422283,231.6493551807241,260.64324284296697,-2.2612912418496176
3.6601691020787532,0.020054410882176434,232.1435173091071,260.64324284296697,-2.2612912418496176
3.8634550371261787,0.021168233646729345,234.16382587498978,260.64324284296697,-2.2612912418496176
4.0387015328567175,0.022128425685137027,235.87240908119082,260.64324284296697,-2.2612912418496176
4.101790271319712,0.022474094818963793,236.48038829868477,260.64324284296697,-2.2612912418496176
4.248997327733365,0.023280656131226245,237.8849971708468,260.64324284296697,-2.2612912418496176
4.31559099611097,0.023645529105821166,238.51416725462468,260.64324284296697,-2.2612912418496176
4.375174804659353,0.023971994398879776,239.07390649061335,260.64324284296697,-2.2612912418496176
4.413729033720071,0.024183236647329465,239.4345071573114,260.64324284296697,-2.2612912418496176
4.455788192695401,0.02441368273654731,239.8264915348745,260.64324284296697,-2.2612912418496176
4.508362141414563,0.024701740348069615,240.31444866754123,260.64324284296697,-2.2612912418496176
4.53990651064606,0.024874574914982996,240.60615782949878,260.64324284296697,-2.2612912418496176
4.599490319194444,0.02520104020804161,241.1550163033997,260.64324284296697,-2.2612912418496176
4.662579057657438,0.025546709341868375,241.73314671745024,260.64324284296697,-2.2612912418496176
4.67659877731588,0.02562352470494099,241.86120489921313,260.64324284296697,-2.2612912418496176
4.687113567059713,0.02568113622724545,241.95715030466883,260.64324284296697,-2.2612912418496176
4.781746674754205,0.0261996399279856,242.8169141951771,260.64324284296697,-2.2612912418496176
4.8238058337295335,0.026430086017203442,243.1968987154424,260.64324284296697,-2.2612912418496176
4.953488240570133,0.027140628125625125,244.36046456485377,260.64324284296697,-2.2612912418496176
4.98503260980163,0.02731346269253851,244.6416902892117,260.64324284296697,-2.2612912418496176
5.07616078758151,0.027812762552510504,245.45024774520013,260.64324284296697,-2.2612912418496176
5.163784035446779,0.028292858571714343,246.22238487079323,260.64324284296697,-2.2612912418496176
5.202338264507499,0.028504100820164035,246.56050457701505,260.64324284296697,-2.2612912418496176
5.219862914080553,0.0286001200240048,246.713872152495,260.64324284296697,-2.2612912418496176
5.275941792714325,0.02890738147629526,247.20330440703108,260.64324284296697,-2.2612912418496176
5.293466442287379,0.029003400680136026,247.355835356277,260.64324284296697,-2.2612912418496176
5.447683358530253,0.029848369673934786,248.68972096548782,260.64324284296697,-2.2612912418496176
5.496752377334804,0.030117223444688937,249.1110399522568,260.64324284296697,-2.2612912418496176
5.591385485029296,0.030635727145429087,249.91946429978938,260.64324284296697,-2.2612912418496176
5.598395344858517,0.030674134826965394,249.97913446191671,260.64324284296697,-2.2612912418496176
5.7175629619552835,0.03132706541308262,250.98911096425496,260.64324284296697,-2.2612912418496176
5.738592541442948,0.031442288457691536,251.1664865467504,260.64324284296697,-2.2612912418496176
5.777146770503666,0.03165353070614123,251.49101810594888,260.64324284296697,-2.2612912418496176
5.787661560247499,0.03171114222844569,251.57937998014359,260.64324284296697,-2.2612912418496176
5.8822946679419905,0.03222964592918584,252.37183928468792,260.64324284296697,-2.2612912418496176
6.008472144867978,0.032920984196839365,253.42076008109458,260.64324284296697,-2.2612912418496176
6.047026373928697,0.033132226445289056,253.7395455315154,260.64324284296697,-2.2612912418496176
6.19072850042774,0.03391958391678336,254.92082650256182,260.64324284296697,-2.2612912418496176
6.243302449146901,0.03420764152830566,255.35032428463046,260.64324284296697,-2.2612912418496176
6.295876397866063,0.034495699139827966,255.77841383234872,260.64324284296697,-2.2612912418496176
6.323915837182949,0.034649329865973195,256.006158094385,260.64324284296697,-2.2612912418496176
6.408034155133608,0.03511022204440888,256.68703963031277,260.64324284296697,-2.2612912418496176
6.457103173938158,0.03537907581516303,257.08261077427915,260.64324284296697,-2.2612912418496176
6.502667262828099,0.035628725745149026,257.4488783804394,260.64324284296697,-2.2612912418496176
6.681418688473249,0.03660812162432486,258.8762120238059,260.64324284296697,-2.2612912418496176
6.744507426936242,0.036953790758151625,259.37641092802255,260.64324284296697,-2.2612912418496176
6.772546866253128,0.037107421484296854,259.59813547499476,260.64324284296697,-2.2612912418496176
6.828625744886901,0.03741468293658731,260.0405134491044,260.64324284296697,-2.2612912418496176
6.926763782496004,0.03795239047809562,260.8112806462342,260.64324284296697,-2.2612912418496176
7.021396890190496,0.03847089417883577,261.55049703407985,260.64324284296697,-2.2612912418496176
7.063456049165824,0.03870134026805361,261.8777893547216,260.64324284296697,-2.2612912418496176
7.133554647458041,0.03908541708341669,262.4215925820041,260.64324284296697,-2.2612912418496176
7.189633526091813,0.039392678535707146,262.8551361277536,260.64324284296697,-2.2612912418496176
7.277256773957082,0.03987277455491098,263.5299169759003,260.64324284296697,-2.2612912418496176
7.392919461139239,0.04050650130026005,264.41579560104645,260.64324284296697,-2.2612912418496176
7.434978620114567,0.04073694738947789,264.7365910096837,260.64324284296697,-2.2612912418496176
7.592700466272054,0.041601120224044816,265.9333222093204,260.64324284296697,-2.2612912418496176
7.736402592771094,0.042388477695539106,267.0152627594195,260.64324284296697,-2.2612912418496176
7.817015980807144,0.04283016603320665,267.61877269994386,260.64324284296697,-2.2612912418496176
8.083390654317563,0.04428965793158632,269.5959381772087,260.64324284296697,-2.2612912418496176
8.153489252609777,0.044673734746949384,270.11200072776023,260.64324284296697,-2.2612912418496176
8.2901815192796,0.045422684536907385,271.1133726736671,260.64324284296697,-2.2612912418496176
8.346260397913372,0.04572994598919784,271.52232668913723,260.64324284296697,-2.2612912418496176
8.38481462697409,0.045941188237647534,271.80286114921284,260.64324284296697,-2.2612912418496176
8.444398435522473,0.04626765353070614,272.23542692045237,260.64324284296697,-2.2612912418496176
8.532021683387743,0.046747749549909984,272.8693968990832,260.64324284296697,-2.2612912418496176
8.563566052619242,0.04692058411682337,273.0970038348595,260.64324284296697,-2.2612912418496176
8.602120281679957,0.04713182636527305,273.3747465322085,260.64324284296697,-2.2612912418496176
8.735307618435169,0.04786157231446289,274.3305079938522,260.64324284296697,-2.2612912418496176
8.889524534678044,0.04870654130826166,275.43010755496357,260.64324284296697,-2.2612912418496176
8.931583693653373,0.048936987397479495,275.72870394416657,260.64324284296697,-2.2612912418496176
9.001682291945588,0.049321064212842575,276.22514884721147,260.64324284296697,-2.2612912418496176
9.029721731262475,0.049474694938987804,276.42330437069546,260.64324284296697,-2.2612912418496176
9.089305539810857,0.04980116023204641,276.8435898311768,260.64324284296697,-2.2612912418496176
9.141879488530021,0.05008921784356872,277.21353843950556,260.64324284296697,-2.2612912418496176
9.22599780648068,0.05055011002200441,277.80373502098746,260.64324284296697,-2.2612912418496176
9.310116124431339,0.051011002200440095,278.3918366518236,260.64324284296697,-2.2612912418496176
9.3626900731505,0.051299059811962394,278.7583480228528,260.64324284296697,-2.2612912418496176
9.387224582552774,0.051433486697339464,278.929111899347,260.64324284296697,-2.2612912418496176
9.49587740990571,0.052028805761152236,279.68326932897827,260.64324284296697,-2.2612912418496176
9.59401544751481,0.05256651330266053,280.3615560736141,260.64324284296697,-2.2612912418496176
9.699163344953135,0.05314262852570514,281.085296056139,260.64324284296697,-2.2612912418496176
9.755242223586906,0.0534498899779956,281.47003923174987,260.64324284296697,-2.2612912418496176
9.804311242391458,0.053718743748749756,281.8059824827968,260.64324284296697,-2.2612912418496176
9.867399980854453,0.05406441288257652,282.23694757787155,260.64324284296697,-2.2612912418496176
9.888429560342118,0.05417963592718544,282.38036362973014,260.64324284296697,-2.2612912418496176
9.965538018463553,0.05460212042408481,282.90520788205185,260.64324284296697,-2.2612912418496176
10.116250004791818,0.05542788557711542,283.9264891379481,260.64324284296697,-2.2612912418496176
10.238922551803194,0.0561000200040008,284.7533909147661,260.64324284296697,-2.2612912418496176
10.287991570607746,0.056368873774754955,285.0830686768757,260.64324284296697,-2.2612912418496176
10.435198627021398,0.057175435087017404,286.06844203156766,260.64324284296697,-2.2612912418496176
10.473752856082118,0.057386677335467096,286.3256182832579,260.64324284296697,-2.2612912418496176
10.543851454374332,0.05777075415083016,286.7922675661137,260.64324284296697,-2.2612912418496176
10.564881033861997,0.05788597719543909,286.93202620794267,260.64324284296697,-2.2612912418496176
10.596425403093495,0.058058811762352475,287.14146091516517,260.64324284296697,-2.2612912418496176
10.61395005266655,0.05815483096619324,287.2577084615979,260.64324284296697,-2.2612912418496176
10.750642319336368,0.05890378075615123,288.1618843843706,260.64324284296697,-2.2612912418496176
10.764662038994814,0.05898059611922385,288.2543661491139,260.64324284296697,-2.2612912418496176
10.771671898824033,0.05901900380076015,288.3005894153057,260.64324284296697,-2.2612912418496176
10.827750777457807,0.05932626525305061,288.6699541549498,260.64324284296697,-2.2612912418496176
10.862800076603914,0.059518303660732144,288.90042829263507,260.64324284296697,-2.2612912418496176
10.964443044127627,0.0600752150430086,289.56716890010836,260.64324284296697,-2.2612912418496176
11.013512062932177,0.06034406881376275,289.8881805652601,260.64324284296697,-2.2612912418496176
11.041551502249064,0.06049769953990798,290.07136536375947,260.64324284296697,-2.2612912418496176
11.192263488577328,0.06132346469293859,291.05289276094686,260.64324284296697,-2.2612912418496176
11.297411386015652,0.0618995799159832,291.73462886827247,260.64324284296697,-2.2612912418496176
11.314936035588707,0.06199559911982397,291.84801053782127,260.64324284296697,-2.2612912418496176
11.392044493710143,0.06241808361672335,292.34607848652337,260.64324284296697,-2.2612912418496176
11.423588862941639,0.06259091818363673,292.5494544021216,260.64324284296697,-2.2612912418496176
11.462143092002359,0.06280216043208642,292.79772777530934,260.64324284296697,-2.2612912418496176
11.483172671490024,0.06291738347669534,292.9330123346463,260.64324284296697,-2.2612912418496176
11.546261409953017,0.0632630526105221,293.33828746017343,260.64324284296697,-2.2612912418496176
11.679448746708228,0.06399279855971195,294.19104309785,260.64324284296697,-2.2612912418496176
11.746042415085833,0.06435767153430687,294.6159981002971,260.64324284296697,-2.2612912418496176
11.78109171423194,0.0645497099419884,294.83928116735905,260.64324284296697,-2.2612912418496176
11.823150873207268,0.06478015603120624,295.10687916947063,260.64324284296697,-2.2612912418496176
11.889744541584873,0.06514502900580116,295.52981798532534,260.64324284296697,-2.2612912418496176
11.914279050987151,0.06527945589117824,295.68540453851165,260.64324284296697,-2.2612912418496176
11.994892439023198,0.06572114422884577,296.1957399912867,260.64324284296697,-2.2612912418496176
12.166634004839127,0.0666621324264853,297.2785373360003,260.64324284296697,-2.2612912418496176
12.233227673216733,0.06702700540108023,297.6967916645651,260.64324284296697,-2.2612912418496176
12.299821341594338,0.06739187837567515,298.11415896260877,260.64324284296697,-2.2612912418496176
12.331365710825834,0.06756471294258852,298.3115515834638,260.64324284296697,-2.2612912418496176
12.383939659544996,0.06785277055411083,298.6401022307871,260.64324284296697,-2.2612912418496176
12.436513608264157,0.06814082816563313,298.96810935153286,260.64324284296697,-2.2612912418496176
12.457543187751822,0.06825605121024206,299.0991607282981,260.64324284296697,-2.2612912418496176
12.580215734763199,0.06892818563712742,299.86191453278286,260.64324284296697,-2.2612912418496176
12.604750244165475,0.06906261252250451,300.0141166054396,260.64324284296697,-2.2612912418496176
12.667838982628469,0.06940828165633127,300.40496377810786,260.64324284296697,-2.2612912418496176
12.744947440749906,0.06983076615323065,300.881636471177,260.64324284296697,-2.2612912418496176
12.801026319383679,0.07013802760552111,301.2276013673762,260.64324284296697,-2.2612912418496176
12.881639707419726,0.07057971594318864,301.72389214506507,260.64324284296697,-2.2612912418496176
12.906174216822004,0.07071414282856572,301.8746965519012,260.64324284296697,-2.2612912418496176
12.98678760485805,0.07115583116623325,302.36941142177716,260.64324284296697,-2.2612912418496176
13.03235169374799,0.07140548109621925,302.64850307900844,260.64324284296697,-2.2612912418496176
13.267181998026913,0.07269213842768554,304.0809080367117,260.64324284296697,-2.2612912418496176
13.319755946746074,0.07298019603920784,304.4002370580781,260.64324284296697,-2.2612912418496176
13.361815105721405,0.0732106421284257,304.6553464933882,260.64324284296697,-2.2612912418496176
13.400369334782123,0.07342188437687538,304.88892182897433,260.64324284296697,-2.2612912418496176
13.470467933074339,0.07380596119223845,305.31293389777744,260.64324284296697,-2.2612912418496176
13.540566531366554,0.07419003800760153,305.73608629773406,260.64324284296697,-2.2612912418496176
13.586130620256496,0.07443968793758753,306.0106772908103,260.64324284296697,-2.2612912418496176
13.649219358719488,0.07478535707141429,306.39028802480243,260.64324284296697,-2.2612912418496176
13.799931345047753,0.0756111222244449,307.2943766101449,260.64324284296697,-2.2612912418496176
13.845495433937693,0.07586077215443089,307.5669465732904,260.64324284296697,-2.2612912418496176
13.8805447330838,0.07605281056211242,307.7763777944523,260.64324284296697,-2.2612912418496176
14.080325738216615,0.07714742948589719,308.96622094199427,260.64324284296697,-2.2612912418496176
14.206503215142602,0.07783876775355071,309.71430955035163,260.64324284296697,-2.2612912418496176
14.308146182666315,0.07839567913582716,310.31505374892765,260.64324284296697,-2.2612912418496176
14.371234921129311,0.07874134826965394,310.6870924383138,260.64324284296697,-2.2612912418496176
14.392264500616974,0.07885657131426285,310.8109637176119,260.64324284296697,-2.2612912418496176
14.42030393993386,0.07901020204040808,310.97601567429615,260.64324284296697,-2.2612912418496176
14.521946907457572,0.07956711342268454,311.57328265604946,260.64324284296697,-2.2612912418496176
14.528956767286795,0.07960552110422085,311.6144132857918,260.64324284296697,-2.2612912418496176
14.634104664725118,0.08018163632726545,312.2304469902431,260.64324284296697,-2.2612912418496176
14.721727912590389,0.0806617323464693,312.74249085224045,260.64324284296697,-2.2612912418496176
14.823370880114101,0.08121864372874575,313.3349750357432,260.64324284296697,-2.2612912418496176
14.837390599772545,0.08129545909181837,313.41657247460466,260.64324284296697,-2.2612912418496176
14.865430039089432,0.0814490898179636,313.57967720055143,260.64324284296697,-2.2612912418496176
14.942538497210867,0.08187157431486297,314.0275976998705,260.64324284296697,-2.2612912418496176
14.963568076698532,0.0819867973594719,314.14960127044293,260.64324284296697,-2.2612912418496176
14.981092726271585,0.08208281656331266,314.2512198396274,260.64324284296697,-2.2612912418496176
15.04067653481997,0.08240928185637128,314.59637673087644,260.64324284296697,-2.2612912418496176
15.075725833966077,0.08260132026405281,314.79916109757346,260.64324284296697,-2.2612912418496176
15.18437866131901,0.08319663932786557,315.4266273282406,260.64324284296697,-2.2612912418496176
15.229942750208952,0.08344628925785158,315.6892369246844,260.64324284296697,-2.2612912418496176
15.247467399782007,0.08354230846169235,315.7901590057106,260.64324284296697,-2.2612912418496176
15.314061068159612,0.08390718143628727,316.173251049749,260.64324284296697,-2.2612912418496176
15.377149806622604,0.08425285057011403,316.5355814927125,260.64324284296697,-2.2612912418496176
15.443743475000211,0.08461772354470895,316.9174130078076,260.64324284296697,-2.2612912418496176
15.506832213463204,0.08496339267853571,317.27855624445164,260.64324284296697,-2.2612912418496176
15.71362307842524,0.08609641928385678,318.45830643367947,260.64324284296697,-2.2612912418496176
15.745167447656737,0.08626925385077015,318.63773466804645,260.64324284296697,-2.2612912418496176
15.815266045948952,0.08665333066613323,319.03596291136824,260.64324284296697,-2.2612912418496176
15.853820275009673,0.08686457291458292,319.2546950041506,260.64324284296697,-2.2612912418496176
15.885364644241168,0.0870374074814963,319.4335033646453,260.64324284296697,-2.2612912418496176
15.892374504070391,0.08707581516303262,319.47321974418867,260.64324284296697,-2.2612912418496176
15.913404083558055,0.08719103820764153,319.5923279104278,260.64324284296697,-2.2612912418496176
15.93443366304572,0.08730626125225045,319.711374705853,260.64324284296697,-2.2612912418496176
16.036076630569433,0.0878631726345269,320.28590599565536,260.64324284296697,-2.2612912418496176
16.064116069886317,0.08801680336067214,320.44414722951274,260.64324284296697,-2.2612912418496176
16.130709738263924,0.08838167633526706,320.81953906332916,260.64324284296697,-2.2612912418496176
16.16575903741003,0.08857371474294859,321.0168709206889,260.64324284296697,-2.2612912418496176
16.214828056214582,0.08884256851370274,321.292855431442,260.64324284296697,-2.2612912418496176
16.34451046305518,0.08955311062212443,322.0206796388617,260.64324284296697,-2.2612912418496176
16.397084411774344,0.08984116823364674,322.3151014970998,260.64324284296697,-2.2612912418496176
16.453163290408117,0.0901484296859372,322.6287459760623,260.64324284296697,-2.2612912418496176
16.47769779981039,0.09028285657131427,322.76583430449585,260.64324284296697,-2.2612912418496176
16.544291468187996,0.09064772954590919,323.1375305062183,260.64324284296697,-2.2612912418496176
16.568825977590272,0.09078215643128626,323.274324067949,260.64324284296697,-2.2612912418496176
16.64943936562632,0.0912238447689538,323.72323344755875,260.64324284296697,-2.2612912418496176
16.723042893833146,0.09162712542508503,324.13236746409535,260.64324284296697,-2.2612912418496176
16.796646422039974,0.09203040608121625,324.540799795109,260.64324284296697,-2.2612912418496176
16.835200651100692,0.09224164832966594,324.7544619377056,260.64324284296697,-2.2612912418496176
16.891279529734465,0.0925489097819564,325.06490289702623,260.64324284296697,-2.2612912418496176
16.950863338282847,0.092875375075015,325.39430631622207,260.64324284296697,-2.2612912418496176
17.041991516062726,0.093374674934987,325.89722766718165,260.64324284296697,-2.2612912418496176
17.0980703946965,0.09368193638727745,326.20619647201863,260.64324284296697,-2.2612912418496176
17.27331689042704,0.09464212842568515,327.1691865080686,260.64324284296697,-2.2612912418496176
17.315376049402367,0.09487257451490298,327.39973623294156,260.64324284296697,-2.2612912418496176
17.441553526328356,0.09556391278255652,328.0900785461325,260.64324284296697,-2.2612912418496176
17.525671844279017,0.09602480496099221,328.5492250000645,260.64324284296697,-2.2612912418496176
17.588760582742008,0.09637047409481897,328.8930210243657,260.64324284296697,-2.2612912418496176
17.63432467163195,0.09662012402480497,329.14101912656645,260.64324284296697,-2.2612912418496176
17.71844298958261,0.09708101620324065,329.5982062114859,260.64324284296697,-2.2612912418496176
17.756997218643328,0.09729225845169034,329.8074673169416,260.64324284296697,-2.2612912418496176
17.799056377618655,0.09752270454090818,330.0355501709554,260.64324284296697,-2.2612912418496176
17.85163032633782,0.0978107621524305,330.3203583693527,260.64324284296697,-2.2612912418496176
17.890184555398537,0.09802200440088019,330.5290098540948,260.64324284296697,-2.2612912418496176
17.900699345142367,0.09807961592318463,330.58588435987883,260.64324284296697,-2.2612912418496176
17.963788083605365,0.09842528505701141,330.92685818730075,260.64324284296697,-2.2612912418496176
18.04440147164141,0.09886697339467894,331.3618681006984,260.64324284296697,-2.2612912418496176
18.075945840872908,0.09903980796159233,331.53188297339085,260.64324284296697,-2.2612912418496176
18.153054298994345,0.0994622924584917,331.9469884907052,260.64324284296697,-2.2612912418496176
18.209133177628118,0.09976955391078215,332.24845161685226,260.64324284296697,-2.2612912418496176
18.237172616945003,0.09992318463692738,332.3990473831011,260.64324284296697,-2.2612912418496176