File: datasets/aisi_316_L/data/M1/train_23.csv
Time(s),Strain(%),Stress(MPa),Temp(C),Log_SR(s-1)
0.0,0.0,0.0,121.09809501312698,2.5385809253545126
3.009209428895076e-08,1.0399999999999999e-05,1.9942269749999997,121.09809501312698,2.5385809253545126
7.407284748049417e-08,2.56e-05,4.9088664,121.09809501312698,2.5385809253545126
8.796150638308684e-08,3.04e-05,5.82927885,121.09809501312698,2.5385809253545126
1.5971957737981559e-07,5.52e-05,10.584743175,121.09809501312698,2.5385809253545126
1.9444122463629722e-07,6.72e-05,12.8857743,121.09809501312698,2.5385809253545126
2.986061664057422e-07,0.0001032,19.788867675,121.09809501312698,2.5385809253545126
3.5184602553234734e-07,0.0001216,23.3171154,121.09809501312698,2.5385809253545126
3.7962334333753263e-07,0.0001312,25.1579403,121.09809501312698,2.5385809253545126
4.4212230839919964e-07,0.0001528,29.299796325,121.09809501312698,2.5385809253545126
4.6295529675308857e-07,0.00015999999999999999,30.680414999999996,121.09809501312698,2.5385809253545126
4.953621675258048e-07,0.0001712,32.828044049999995,121.09809501312698,2.5385809253545126
5.810088974251263e-07,0.0002008,38.503920825,121.09809501312698,2.5385809253545126
5.85638450392657e-07,0.0002024,38.810724975,121.09809501312698,2.5385809253545126
6.11100991714077e-07,0.00021119999999999998,40.4981478,121.09809501312698,2.5385809253545126
6.342487565517314e-07,0.0002192,42.032168549999994,121.09809501312698,2.5385809253545126
7.060068275484602e-07,0.000244,46.787632875,121.09809501312698,2.5385809253545126
7.360989218374109e-07,0.0002544,48.781859850000004,121.09809501312698,2.5385809253545126
8.610968519607448e-07,0.00029759999999999997,57.065571899999995,121.09809501312698,2.5385809253545126
8.98133275700992e-07,0.0003104,59.5200051,121.09809501312698,2.5385809253545126
9.444288053763007e-07,0.00032639999999999996,62.58804659999999,121.09809501312698,2.5385809253545126
9.907243350516097e-07,0.0003424,65.65608809999999,121.09809501312698,2.5385809253545126
1.018501652856795e-06,0.000352,67.49691299999999,121.09809501312698,2.5385809253545126
1.0948892768210546e-06,0.0003784,72.559181475,121.09809501312698,2.5385809253545126
1.1411848064963636e-06,0.0003944,75.627222975,121.09809501312698,2.5385809253545126
1.1851655596879068e-06,0.0004096,78.5418624,121.09809501312698,2.5385809253545126
1.2013689950742648e-06,0.00041519999999999995,79.61567692499999,121.09809501312698,2.5385809253545126
1.217572430460623e-06,0.0004208,80.68949144999999,121.09809501312698,2.5385809253545126
1.2615531836521665e-06,0.00043599999999999997,83.604130875,121.09809501312698,2.5385809253545126
1.3171078192625372e-06,0.0004552,87.285780675,121.09809501312698,2.5385809253545126
1.3587737959703151e-06,0.0004696,90.047018025,121.09809501312698,2.5385809253545126
1.4189579845482166e-06,0.0004904,94.035471975,121.09809501312698,2.5385809253545126
1.4444205258696366e-06,0.0004992,95.72289479999999,121.09809501312698,2.5385809253545126
1.453679631804698e-06,0.0005024,96.33650309999999,121.09809501312698,2.5385809253545126
1.4860865025774145e-06,0.0005136,98.48413215000001,121.09809501312698,2.5385809253545126
1.525437702801427e-06,0.0005272,101.091967425,121.09809501312698,2.5385809253545126
1.5647889030254397e-06,0.0005408,103.6998027,121.09809501312698,2.5385809253545126
1.5809923384117975e-06,0.0005463999999999999,104.773617225,121.09809501312698,2.5385809253545126
1.687472056665008e-06,0.0005832,111.830112675,121.09809501312698,2.5385809253545126
1.7383971393078478e-06,0.0006008,115.20495832499999,121.09809501312698,2.5385809253545126
1.7569153511779713e-06,0.0006072,116.432174925,121.09809501312698,2.5385809253545126
1.770804010080564e-06,0.000612,117.352587375,121.09809501312698,2.5385809253545126
1.8078404338208112e-06,0.0006248,119.807020575,121.09809501312698,2.5385809253545126
1.9096905991064907e-06,0.00066,126.556711875,121.09809501312698,2.5385809253545126
1.9513565758142686e-06,0.0006744,129.317949225,121.09809501312698,2.5385809253545126
1.9883929995545156e-06,0.0006872,131.772382425,121.09809501312698,2.5385809253545126
2.0346885292298246e-06,0.0007032,134.84042392499998,121.09809501312698,2.5385809253545126
2.111076153194084e-06,0.0007296,139.90269239999998,121.09809501312698,2.5385809253545126
2.1620012358369238e-06,0.0007472,143.27753805,121.09809501312698,2.5385809253545126
2.1990376595771707e-06,0.0007599999999999999,145.73197125,121.09809501312698,2.5385809253545126
2.2129263184797637e-06,0.0007647999999999999,146.6523837,121.09809501312698,2.5385809253545126
2.252277518703776e-06,0.0007784,149.260218975,121.09809501312698,2.5385809253545126
2.3124617072816774e-06,0.0007991999999999999,153.248672925,121.09809501312698,2.5385809253545126
2.3356094721193323e-06,0.0008072,154.782693675,121.09809501312698,2.5385809253545126
2.361072013440752e-06,0.000816,156.4701165,121.09809501312698,2.5385809253545126
2.3680163428920483e-06,0.0008183999999999999,156.930322725,121.09809501312698,2.5385809253545126
2.398108437180999e-06,0.0008288,158.9245497,121.09809501312698,2.5385809253545126
2.481440390596555e-06,0.0008575999999999999,164.44702439999998,121.09809501312698,2.5385809253545126
2.490699496531617e-06,0.0008608,165.0606327,121.09809501312698,2.5385809253545126
2.5069029319179747e-06,0.0008663999999999999,166.13444722499997,121.09809501312698,2.5385809253545126
2.5369950262069255e-06,0.0008768,168.12867419999998,121.09809501312698,2.5385809253545126
2.5670871204958766e-06,0.0008872,170.122901175,121.09809501312698,2.5385809253545126
2.6990293800705064e-06,0.0009327999999999999,178.86681944999998,121.09809501312698,2.5385809253545126
2.738380580294519e-06,0.0009463999999999999,181.474654725,121.09809501312698,2.5385809253545126
2.7916204394211243e-06,0.0009647999999999999,185.00290245,121.09809501312698,2.5385809253545126
2.817082980742544e-06,0.0009735999999999999,186.690325275,121.09809501312698,2.5385809253545126
2.858748957450322e-06,0.000988,189.45156262499998,121.09809501312698,2.5385809253545126
2.8865262752555074e-06,0.0009976,191.29238752499998,121.09809501312698,2.5385809253545126
2.9212479225119896e-06,0.0010096,193.59341865000002,121.09809501312698,2.5385809253545126
2.9906912170249526e-06,0.0010336,198.1954809,121.09809501312698,2.5385809253545126
3.0161537583463723e-06,0.0010424,199.882903725,121.09809501312698,2.5385809253545126
3.0601345115379156e-06,0.0010576,202.79754314999997,121.09809501312698,2.5385809253545126
3.1180039236320517e-06,0.0010776,206.632595025,121.09809501312698,2.5385809253545126
3.2406870772716204e-06,0.00112,214.762905,121.09809501312698,2.5385809253545126
3.3564259014598927e-06,0.00116,222.43300875,121.09809501312698,2.5385809253545126
3.384203219265078e-06,0.0011696,224.27383365,121.09809501312698,2.5385809253545126
3.411980537070263e-06,0.0011792,226.11465855,121.09809501312698,2.5385809253545126
3.4467021843267445e-06,0.0011912,228.41568967499998,121.09809501312698,2.5385809253545126
3.462905619713103e-06,0.0011968,229.4895042,121.09809501312698,2.5385809253545126
3.4976272669695844e-06,0.0012088,231.79053532499998,121.09809501312698,2.5385809253545126
3.543922796644893e-06,0.0012247999999999998,234.85857682499997,121.09809501312698,2.5385809253545126
3.5855887733526713e-06,0.0012392,237.619814175,121.09809501312698,2.5385809253545126
3.597162655771498e-06,0.0012431999999999999,238.38682454999997,121.09809501312698,2.5385809253545126
3.6341990795117456e-06,0.001256,240.84125774999998,121.09809501312698,2.5385809253545126
3.661976397316931e-06,0.0012656,242.68208264999998,121.09809501312698,2.5385809253545126
3.7152162564435362e-06,0.001284,246.21033037499998,121.09809501312698,2.5385809253545126
3.745308350732487e-06,0.0012944,248.20455735000002,121.09809501312698,2.5385809253545126
3.7754004450214373e-06,0.0013047999999999998,250.19878432499996,121.09809501312698,2.5385809253545126
3.81475164524545e-06,0.0013184,252.8066196,121.09809501312698,2.5385809253545126
3.824010751180512e-06,0.0013216,253.42022790000001,121.09809501312698,2.5385809253545126
3.8286403041480425e-06,0.0013231999999999999,253.72703204999996,121.09809501312698,2.5385809253545126
3.858732398436994e-06,0.0013335999999999999,255.27031540032925,121.09809501312698,2.5385809253545126
3.874935833823352e-06,0.0013392,255.31140440694648,121.09809501312698,2.5385809253545126
3.898083598661007e-06,0.0013472,255.36998693823338,121.09809501312698,2.5385809253545126
3.918916587014895e-06,0.0013544,255.4225953183461,121.09809501312698,2.5385809253545126
3.999933763946686e-06,0.0013824,255.62615497407694,121.09809501312698,2.5385809253545126
4.041599740654463e-06,0.0013968,255.73021625943858,121.09809501312698,2.5385809253545126
4.0902100468135375e-06,0.0014135999999999999,255.8510937605918,121.09809501312698,2.5385809253545126
4.104098705716131e-06,0.0014184,255.8855271160521,121.09809501312698,2.5385809253545126
4.194374988582983e-06,0.0014495999999999999,256.10824635477894,121.09809501312698,2.5385809253545126
4.236040965290761e-06,0.001464,256.21040853237355,121.09809501312698,2.5385809253545126
4.270762612547242e-06,0.0014759999999999999,256.29524465355615,121.09809501312698,2.5385809253545126
4.280021718482305e-06,0.0014792,256.3178221355594,121.09809501312698,2.5385809253545126
4.3054842598037244e-06,0.001488,256.3798122046306,121.09809501312698,2.5385809253545126
4.335576354092675e-06,0.0014984,256.45288916373045,121.09809501312698,2.5385809253545126
4.372612777832922e-06,0.0015111999999999999,256.54255904997575,121.09809501312698,2.5385809253545126
4.467518613667306e-06,0.001544,256.7709964810655,121.09809501312698,2.5385809253545126
4.506869813891317e-06,0.0015576,256.86515845809157,121.09809501312698,2.5385809253545126
4.643441626433479e-06,0.0016048,257.1894969931128,121.09809501312698,2.5385809253545126
4.6781632736899605e-06,0.0016167999999999998,257.27136009996747,121.09809501312698,2.5385809253545126
4.722144026881504e-06,0.001632,257.37471399516465,121.09809501312698,2.5385809253545126
4.731403132816565e-06,0.0016351999999999998,257.3964247962274,121.09809501312698,2.5385809253545126
4.766124780073047e-06,0.0016472,257.47769314707415,121.09809501312698,2.5385809253545126
4.807790756780825e-06,0.0016615999999999998,257.5749110159274,121.09809501312698,2.5385809253545126
4.8286237451347145e-06,0.0016688,257.6233966910918,121.09809501312698,2.5385809253545126
4.8656601688749615e-06,0.0016816,257.7093924845317,121.09809501312698,2.5385809253545126
4.8749192748100235e-06,0.0016848,257.73085149771634,121.09809501312698,2.5385809253545126
4.879548827777554e-06,0.0016864,257.74157504305424,121.09809501312698,2.5385809253545126
4.918900028001566e-06,0.0017,257.8325655290147,121.09809501312698,2.5385809253545126
5.011491087352184e-06,0.0017319999999999998,258.04554822185816,121.09809501312698,2.5385809253545126
5.097137817251505e-06,0.0017615999999999999,258.2411948425797,121.09809501312698,2.5385809253545126
5.1364890174755185e-06,0.0017752,258.3306562560652,121.09809501312698,2.5385809253545126
5.196673206053419e-06,0.0017959999999999999,258.4669643050107,121.09809501312698,2.5385809253545126
5.240653959244964e-06,0.0018112,258.5661849991216,121.09809501312698,2.5385809253545126
5.254542618147555e-06,0.001816,258.59745031227294,121.09809501312698,2.5385809253545126
5.280005159468976e-06,0.0018248,258.6546864741787,121.09809501312698,2.5385809253545126
5.323985912660519e-06,0.0018399999999999998,258.7532960333057,121.09809501312698,2.5385809253545126
5.381855324754655e-06,0.0018599999999999999,258.882562784103,121.09809501312698,2.5385809253545126
5.421206524978668e-06,0.0018736,258.9701546856541,121.09809501312698,2.5385809253545126
5.453613395751384e-06,0.0018847999999999998,259.04210315585937,121.09809501312698,2.5385809253545126
5.550834008069533e-06,0.0019184,259.2569547245233,121.09809501312698,2.5385809253545126
5.624906855550027e-06,0.001944,259.41966752697186,121.09809501312698,2.5385809253545126
5.64342506742015e-06,0.0019504,259.46021489097086,121.09809501312698,2.5385809253545126
5.654998949838977e-06,0.0019544,259.4855306448905,121.09809501312698,2.5385809253545126
5.66888760874157e-06,0.0019592,259.5158828920134,121.09809501312698,2.5385809253545126
5.685091044127928e-06,0.0019648,259.5512572169125,121.09809501312698,2.5385809253545126
5.71981269138441e-06,0.0019768,259.6269272072344,121.09809501312698,2.5385809253545126
5.754534338640891e-06,0.0019887999999999998,259.70241826226845,121.09809501312698,2.5385809253545126
5.823977633153855e-06,0.0020128,259.852869540924,121.09809501312698,2.5385809253545126
5.923513021955769e-06,0.0020472,260.06730197203046,121.09809501312698,2.5385809253545126
5.999900645920029e-06,0.0020736,260.2309147056736,121.09809501312698,2.5385809253545126
6.053140505046634e-06,0.002092,260.34446772888606,121.09809501312698,2.5385809253545126
6.148046340881017e-06,0.0021248,260.54592697734336,121.09809501312698,2.5385809253545126
6.2267487413290415e-06,0.002152,260.71207243292514,121.09809501312698,2.5385809253545126
6.252211282650462e-06,0.0021608,260.76564976256924,121.09809501312698,2.5385809253545126
6.2568408356179935e-06,0.0021624,260.77538194571787,121.09809501312698,2.5385809253545126
6.289247706390709e-06,0.0021736,260.8434287651473,121.09809501312698,2.5385809253545126
6.310080694744598e-06,0.0021808,260.8871009501755,121.09809501312698,2.5385809253545126
6.326284130130955e-06,0.0021864,260.9210293402622,121.09809501312698,2.5385809253545126
6.4304490719004e-06,0.0022224,261.1383367448013,121.09809501312698,2.5385809253545126
6.4975775899295985e-06,0.0022456,261.2776521914382,121.09809501312698,2.5385809253545126
6.567020884442563e-06,0.0022696,261.42118219192594,121.09809501312698,2.5385809253545126
6.638778955439291e-06,0.0022944,261.5688760394734,121.09809501312698,2.5385809253545126
6.678130155663303e-06,0.0023079999999999997,261.6496050655423,121.09809501312698,2.5385809253545126
6.7035926969847235e-06,0.0023168,261.70174265213257,121.09809501312698,2.5385809253545126
6.807757638754168e-06,0.0023528,261.91423344673757,121.09809501312698,2.5385809253545126
6.923496462942441e-06,0.0023928,262.14885267481384,121.09809501312698,2.5385809253545126
7.0207170752605894e-06,0.0024264,262.3447530722811,121.09809501312698,2.5385809253545126
7.097104699224848e-06,0.0024527999999999998,262.49793357009656,121.09809501312698,2.5385809253545126
7.134141122965096e-06,0.0024656,262.5719713348122,121.09809501312698,2.5385809253545126
7.229046958799479e-06,0.0024984,262.7610121269224,121.09809501312698,2.5385809253545126
7.249879947153367e-06,0.0025055999999999998,262.802379047564,121.09809501312698,2.5385809253545126
7.256824276604664e-06,0.002508,262.8161577156242,121.09809501312698,2.5385809253545126
7.28460159440985e-06,0.0025176,262.87122104290074,121.09809501312698,2.5385809253545126
7.326267571117627e-06,0.002532,262.95366274562673,121.09809501312698,2.5385809253545126
7.363303994857874e-06,0.0025448,263.0267908743879,121.09809501312698,2.5385809253545126
7.3841369832117635e-06,0.002552,263.0678624039336,121.09809501312698,2.5385809253545126
7.39571086563059e-06,0.0025559999999999997,263.09066039251155,121.09809501312698,2.5385809253545126
7.432747289370838e-06,0.0025688,263.16352062924835,121.09809501312698,2.5385809253545126
7.460524607176023e-06,0.0025784,263.2180729241839,121.09809501312698,2.5385809253545126
7.485987148497443e-06,0.0025872,263.26800964811275,121.09809501312698,2.5385809253545126
7.54848611355911e-06,0.0026088,263.3903015858708,121.09809501312698,2.5385809253545126
7.567004325429233e-06,0.0026152,263.42646031518547,121.09809501312698,2.5385809253545126
7.57857820784806e-06,0.0026192,263.44904199697817,121.09809501312698,2.5385809253545126
7.608670302137011e-06,0.0026295999999999997,263.507691514883,121.09809501312698,2.5385809253545126
7.657280608296085e-06,0.0026463999999999997,263.60224230787446,121.09809501312698,2.5385809253545126
7.763760326549296e-06,0.0026831999999999997,263.8085394218473,121.09809501312698,2.5385809253545126
7.784593314903185e-06,0.0026904,263.84877251743137,121.09809501312698,2.5385809253545126
7.870240044802506e-06,0.0027199999999999998,264.01373599085053,121.09809501312698,2.5385809253545126
7.884128703705099e-06,0.0027248,264.04042071252366,121.09809501312698,2.5385809253545126
7.946627668766766e-06,0.0027464,264.16027581160165,121.09809501312698,2.5385809253545126
7.99060842195831e-06,0.0027616,264.24439801050306,121.09809501312698,2.5385809253545126
8.050792610536211e-06,0.0027824,264.3592205621506,121.09809501312698,2.5385809253545126
8.113291575597878e-06,0.002804,264.4781056024535,121.09809501312698,2.5385809253545126
8.171160987692014e-06,0.0028239999999999997,264.587866275002,121.09809501312698,2.5385809253545126
8.226715623302384e-06,0.0028431999999999997,264.6929516580382,121.09809501312698,2.5385809253545126
8.273011152977693e-06,0.0028591999999999997,264.78031156443734,121.09809501312698,2.5385809253545126
8.395694306617262e-06,0.0029016,265.01089815819677,121.09809501312698,2.5385809253545126
8.446619389260101e-06,0.0029192,265.10622696239267,121.09809501312698,2.5385809253545126
8.504488801354238e-06,0.0029392,265.2142834875736,121.09809501312698,2.5385809253545126
8.546154778062016e-06,0.0029536,265.2919067024524,121.09809501312698,2.5385809253545126
8.597079860704856e-06,0.0029712,265.3865793747579,121.09809501312698,2.5385809253545126
8.657264049282758e-06,0.002992,265.4981837495395,121.09809501312698,2.5385809253545126
8.705874355441831e-06,0.0030088,265.58810500933265,121.09809501312698,2.5385809253545126
8.724392567311955e-06,0.0030152,265.6223091942376,121.09809501312698,2.5385809253545126
8.754484661600906e-06,0.0030256,265.67783066731636,121.09809501312698,2.5385809253545126
8.800780191276214e-06,0.0030415999999999998,265.76310320291486,121.09809501312698,2.5385809253545126
8.837816615016461e-06,0.0030543999999999997,265.8311953410953,121.09809501312698,2.5385809253545126
8.881797368208006e-06,0.0030696,265.9119103820723,121.09809501312698,2.5385809253545126
8.907259909529425e-06,0.0030784,265.95856889686866,121.09809501312698,2.5385809253545126
8.997536192396277e-06,0.0031095999999999997,266.12357702418007,121.09809501312698,2.5385809253545126
9.039202169104055e-06,0.003124,266.19951672491857,121.09809501312698,2.5385809253545126
9.094756804714427e-06,0.0031432,266.30055764068936,121.09809501312698,2.5385809253545126
9.106330687133252e-06,0.0031471999999999997,266.3215775020695,121.09809501312698,2.5385809253545126
9.205866075935167e-06,0.0031815999999999997,266.501920228,121.09809501312698,2.5385809253545126
9.215125181870228e-06,0.0031848,266.5186575403756,121.09809501312698,2.5385809253545126
9.229013840772821e-06,0.0031896,266.5437512166319,121.09809501312698,2.5385809253545126
9.268365040996834e-06,0.0032032,266.61477011199844,121.09809501312698,2.5385809253545126
9.333178782542266e-06,0.0032256,266.7314865945092,121.09809501312698,2.5385809253545126
9.381789088701342e-06,0.0032424,266.8188166236278,121.09809501312698,2.5385809253545126
9.386418641668872e-06,0.003244,266.8271245548857,121.09809501312698,2.5385809253545126
9.48363925398702e-06,0.0032776,267.00122366859057,121.09809501312698,2.5385809253545126
9.548452995532453e-06,0.0033,267.11690320170203,121.09809501312698,2.5385809253545126
9.553082548499984e-06,0.0033016,267.12515428853175,121.09809501312698,2.5385809253545126
9.604007631142823e-06,0.0033192,267.21581356006516,121.09809501312698,2.5385809253545126
9.629470172464242e-06,0.003328,267.2610728767612,121.09809501312698,2.5385809253545126
9.659562266753195e-06,0.0033384,267.31450103011593,121.09809501312698,2.5385809253545126
9.81465229116548e-06,0.003392,267.58883886050086,121.09809501312698,2.5385809253545126
9.870206926775848e-06,0.0034111999999999996,267.6866971772228,121.09809501312698,2.5385809253545126
9.9002990210648e-06,0.0034216,267.73961406533147,121.09809501312698,2.5385809253545126
9.974371868545293e-06,0.0034471999999999997,267.8696044813051,121.09809501312698,2.5385809253545126
1.0173442646149122e-05,0.003516,268.2171015719297,121.09809501312698,2.5385809253545126
1.0187331305051714e-05,0.0035207999999999997,268.2412461314917,121.09809501312698,2.5385809253545126
1.0203534740438074e-05,0.0035264,268.2693985650293,121.09809501312698,2.5385809253545126
1.0231312058243257e-05,0.0035359999999999996,268.3176193490143,121.09809501312698,2.5385809253545126
1.029149624682116e-05,0.0035567999999999997,268.4219229078657,121.09809501312698,2.5385809253545126
1.0300755352756222e-05,0.00356,268.4379484707348,121.09809501312698,2.5385809253545126
1.0363254317817889e-05,0.0035816,268.5459744518874,121.09809501312698,2.5385809253545126
1.045353060068474e-05,0.0036127999999999998,268.7015644976453,121.09809501312698,2.5385809253545126
1.052065911871394e-05,0.003636,268.8169201724194,121.09809501312698,2.5385809253545126
1.0550751213002889e-05,0.0036463999999999997,268.868538118025,121.09809501312698,2.5385809253545126
1.0571584201356779e-05,0.0036536,268.9042399894866,121.09809501312698,2.5385809253545126
1.0638712719385976e-05,0.0036768,269.0190931493624,121.09809501312698,2.5385809253545126
1.0673434366642458e-05,0.0036888,269.07838903258505,121.09809501312698,2.5385809253545126
1.0821580061603446e-05,0.00374,269.3305442205108,121.09809501312698,2.5385809253545126
1.0935004109307954e-05,0.0037792,269.52269164078734,121.09809501312698,2.5385809253545126
1.0995188297885855e-05,0.0038,269.6243316931474,121.09809501312698,2.5385809253545126
1.1018336062723509e-05,0.0038079999999999998,269.6633662179512,121.09809501312698,2.5385809253545126
1.1076205474817645e-05,0.003828,269.7608128691678,121.09809501312698,2.5385809253545126
1.1106297569106595e-05,0.0038383999999999996,269.81140664580687,121.09809501312698,2.5385809253545126
1.12266659462624e-05,0.0038799999999999998,270.01324941388634,121.09809501312698,2.5385809253545126
1.1275276252421473e-05,0.0038967999999999997,270.0945233821431,121.09809501312698,2.5385809253545126
1.130768312319419e-05,0.003908,270.14863012273844,121.09809501312698,2.5385809253545126
1.1342404770450672e-05,0.00392,270.2065345649609,121.09809501312698,2.5385809253545126
1.1365552535288326e-05,0.003928,270.2450991251552,121.09809501312698,2.5385809253545126
1.144425493573635e-05,0.0039552,270.37599011184733,121.09809501312698,2.5385809253545126
1.1907276911387952e-05,0.004115223044608922,271.1390572731122,121.09809501312698,2.5385809253545126
1.246293439898918e-05,0.004307261452290458,272.03967642078675,121.09809501312698,2.5385809253545126
1.3185289132870774e-05,0.004556911382276456,273.18740194666884,121.09809501312698,2.5385809253545126
1.4296604108073227e-05,0.004940988197639528,274.9063466387957,121.09809501312698,2.5385809253545126
1.4963393093194699e-05,0.005171434286857372,275.9127001260798,121.09809501312698,2.5385809253545126
1.5074524590714945e-05,0.005209841968393679,276.0787104894436,121.09809501312698,2.5385809253545126
1.7574983284920464e-05,0.006074014802960592,279.6963655371801,121.09809501312698,2.5385809253545126
1.7963943526241323e-05,0.0062084416883376676,280.24052220876274,121.09809501312698,2.5385809253545126
2.0131007727886108e-05,0.006957391478295659,283.19206670390844,121.09809501312698,2.5385809253545126
2.0353270722926596e-05,0.007034206841368274,283.48760609558684,121.09809501312698,2.5385809253545126
2.1464585698129048e-05,0.007418283656731346,284.94683197581634,121.09809501312698,2.5385809253545126
2.2075808934490398e-05,0.007629525905181036,285.73683416696485,121.09809501312698,2.5385809253545126
2.3020426663412483e-05,0.007955991198239648,286.94116921582304,121.09809501312698,2.5385809253545126
2.4965227870016776e-05,0.008628125625125025,289.3616128769481,121.09809501312698,2.5385809253545126
2.7799081056783033e-05,0.00960752150430086,292.7607342891422,121.09809501312698,2.5385809253545126
2.857700153942475e-05,0.009876375275055011,293.6698190899802,121.09809501312698,2.5385809253545126
2.9354922022066468e-05,0.010145229045809162,294.5693021934632,121.09809501312698,2.5385809253545126
3.0799631489829654e-05,0.010644528905781155,296.2154816047847,121.09809501312698,2.5385809253545126
3.157755197247137e-05,0.010913382676535306,297.0893982078503,121.09809501312698,2.5385809253545126
3.3300090184035176e-05,0.01150870174034807,298.99515811900136,121.09809501312698,2.5385809253545126
3.385574767163641e-05,0.011700740148029607,299.6016652531073,121.09809501312698,2.5385809253545126
3.5022628395598975e-05,0.012104020804160832,300.8628366865376,121.09809501312698,2.5385809253545126
3.568941738072045e-05,0.012334466893378675,301.5761465127185,121.09809501312698,2.5385809253545126
3.674516660716278e-05,0.012699339867973595,302.6950146522389,121.09809501312698,2.5385809253545126
3.7467521341044376e-05,0.012948989797959592,303.4533415928592,121.09809501312698,2.5385809253545126
3.863440206500695e-05,0.013352270454090818,304.66639555864333,121.09809501312698,2.5385809253545126
4.024580877905051e-05,0.013909181836367274,306.31832970121224,121.09809501312698,2.5385809253545126
4.2635135975735785e-05,0.01473494698939788,308.7210302283282,121.09809501312698,2.5385809253545126
4.3301924960857254e-05,0.014965393078615724,309.3821027613209,121.09809501312698,2.5385809253545126
4.374645095093824e-05,0.015119023804760953,309.8206135130452,121.09809501312698,2.5385809253545126
4.4524371433579954e-05,0.015387877575515104,310.5838485243542,121.09809501312698,2.5385809253545126
4.5969080901343153e-05,0.0158871774354871,311.98762692847083,121.09809501312698,2.5385809253545126
4.696926437902535e-05,0.016232846569313862,312.94940954456035,121.09809501312698,2.5385809253545126
4.8525105344308784e-05,0.016770554110822164,314.42978889072106,121.09809501312698,2.5385809253545126
5.019207780711246e-05,0.017346669333866773,315.99551274677793,121.09809501312698,2.5385809253545126
5.108112978727443e-05,0.01765393078615723,316.82226621314305,121.09809501312698,2.5385809253545126
5.235914200875724e-05,0.018095619123824763,318.0009593631867,121.09809501312698,2.5385809253545126
5.341489123519958e-05,0.018460492098419684,318.9662221718859,121.09809501312698,2.5385809253545126
5.352602273271982e-05,0.01849889977995599,319.0673940515202,121.09809501312698,2.5385809253545126
5.5859784180644975e-05,0.019305461092218444,321.1734420862044,121.09809501312698,2.5385809253545126
5.6471007417006335e-05,0.019516703340668136,321.71931960098243,121.09809501312698,2.5385809253545126
5.752675664344866e-05,0.019881576315263053,322.6568023715495,121.09809501312698,2.5385809253545126
5.8082414131049885e-05,0.02007361472294459,323.1475179134685,121.09809501312698,2.5385809253545126
5.824911137733025e-05,0.02013122624524905,323.2943751117422,121.09809501312698,2.5385809253545126
5.952712359881308e-05,0.020572914582916584,324.4148854418702,121.09809501312698,2.5385809253545126
5.986051809137381e-05,0.020688137627525506,324.7056445305653,121.09809501312698,2.5385809253545126
6.147192480541737e-05,0.02124504900980196,326.1021730539146,121.09809501312698,2.5385809253545126
6.186088504673823e-05,0.021379475895179037,326.437118181429,121.09809501312698,2.5385809253545126
6.308333151946092e-05,0.021801960392078417,327.4844951836623,121.09809501312698,2.5385809253545126
6.536152721862595e-05,0.022589317863572714,329.41554099816454,121.09809501312698,2.5385809253545126
6.808424890787197e-05,0.023530306061212244,331.68927381998213,121.09809501312698,2.5385809253545126
6.880660364175356e-05,0.02377995599119824,332.2865212865288,121.09809501312698,2.5385809253545126
6.91399981343143e-05,0.023895179035807162,332.5613487220558,121.09809501312698,2.5385809253545126
7.014018161199651e-05,0.024240848169633927,333.3827466304713,121.09809501312698,2.5385809253545126
7.097366784339834e-05,0.02452890578115623,334.0637611431406,121.09809501312698,2.5385809253545126
7.152932533099957e-05,0.024720944188837767,334.51603880690965,121.09809501312698,2.5385809253545126
7.252950880868177e-05,0.025066613322664532,335.3267006570416,121.09809501312698,2.5385809253545126
7.408534977396521e-05,0.025604320864172834,336.57911759931534,121.09809501312698,2.5385809253545126
7.436317851776583e-05,0.025700340068013604,336.8016798171829,121.09809501312698,2.5385809253545126
7.475213875908668e-05,0.025834766953390677,337.1127228838412,121.09809501312698,2.5385809253545126
7.508553325164742e-05,0.0259499899979996,337.378829177632,121.09809501312698,2.5385809253545126
7.547449349296828e-05,0.026084416883376677,337.6887048083483,121.09809501312698,2.5385809253545126
7.580788798552902e-05,0.0261996399279856,337.9538171109625,121.09809501312698,2.5385809253545126
7.791938643841368e-05,0.026929385877175437,339.62242401630255,121.09809501312698,2.5385809253545126
7.830834667973453e-05,0.02706381276255251,339.92786584442683,121.09809501312698,2.5385809253545126
7.891956991609589e-05,0.027275055011002202,340.40665313020867,121.09809501312698,2.5385809253545126
7.925296440865662e-05,0.027390278055611124,340.6672002067048,121.09809501312698,2.5385809253545126
8.080880537394005e-05,0.027927985597119426,341.87747912236887,121.09809501312698,2.5385809253545126
8.11421998665008e-05,0.028043208641728348,342.13563837328303,121.09809501312698,2.5385809253545126
8.169785735410202e-05,0.028235247049409884,342.56498639792005,121.09809501312698,2.5385809253545126
8.308700107310508e-05,0.028715343068613723,343.63340378579284,121.09809501312698,2.5385809253545126
8.519849952598974e-05,0.02944508901780356,345.2441512636468,121.09809501312698,2.5385809253545126
8.53651967722701e-05,0.02950270054010802,345.3706486105328,121.09809501312698,2.5385809253545126
8.858801020035723e-05,0.03061652330466093,347.7976426541908,121.09809501312698,2.5385809253545126
9.02549826631609e-05,0.03119263852770554,349.03945653439206,121.09809501312698,2.5385809253545126
9.286657285488667e-05,0.03209521904380876,350.9671294469021,121.09809501312698,2.5385809253545126
9.381119058380876e-05,0.032421684336867373,351.6591511495448,121.09809501312698,2.5385809253545126
9.447797956893023e-05,0.03265213042608522,352.1460017985577,121.09809501312698,2.5385809253545126
9.747853000197684e-05,0.03368913782756551,354.32045536055307,121.09809501312698,2.5385809253545126
9.931219971106091e-05,0.034322864572914585,355.63644186927394,121.09809501312698,2.5385809253545126
9.986785719866212e-05,0.03451490298059612,356.03335029771415,121.09809501312698,2.5385809253545126
0.0001019793556515468,0.03524464892978596,357.53381199566684,121.09809501312698,2.5385809253545126
0.00010303510487798912,0.03560952190438088,358.27949558744496,121.09809501312698,2.5385809253545126
0.00010381302536063082,0.03587837567513502,358.8270412779193,121.09809501312698,2.5385809253545126
0.00010492434033583329,0.0362624524904981,359.606481707409,121.09809501312698,2.5385809253545126
0.00010664687854739707,0.03685777155431086,360.80828149750164,121.09809501312698,2.5385809253545126
0.00010836941675896091,0.03745309061812363,362.0025343143927,121.09809501312698,2.5385809253545126
0.00011020308646804492,0.03808681736347269,363.265729159394,121.09809501312698,2.5385809253545126
0.00011192562467960876,0.03868213642728546,364.4449200622895,121.09809501312698,2.5385809253545126
0.00011320363690109157,0.03912382476495299,365.31523520423985,121.09809501312698,2.5385809253545126
0.00011420382037877376,0.03946949389877975,365.993681270303,121.09809501312698,2.5385809253545126
0.00011614862158537806,0.04014162832566513,367.3062847148454,121.09809501312698,2.5385809253545126
0.00011681541057049955,0.04037207441488298,367.75434330162864,121.09809501312698,2.5385809253545126
0.00011853794878206334,0.04096739347869574,368.90723559846697,121.09809501312698,2.5385809253545126
0.00011998265824982652,0.04146669333866773,369.8691481296873,121.09809501312698,2.5385809253545126
0.00012020492124486703,0.04154350870174035,370.0167327867466,121.09809501312698,2.5385809253545126
0.00012170519646139034,0.0420620124024805,371.0101601059298,121.09809501312698,2.5385809253545126
0.00012242755119527195,0.0423116623324665,371.4867726175773,121.09809501312698,2.5385809253545126
0.0001251502728845179,0.04325265053010602,373.27346236346983,121.09809501312698,2.5385809253545126
0.0001253169701307983,0.04331026205241048,373.3823564523766,121.09809501312698,2.5385809253545126
0.00012615045636220012,0.04359831966393278,373.92598181565336,121.09809501312698,2.5385809253545126
0.0001270395083423621,0.04390558111622324,374.50430717231546,121.09809501312698,2.5385809253545126
0.00012748403433244306,0.04405921184236847,374.7928777844959,121.09809501312698,2.5385809253545126
0.00012815082331756457,0.04428965793158632,375.22499899394745,121.09809501312698,2.5385809253545126
0.00012870648080516578,0.04448169633926785,375.58443057488444,121.09809501312698,2.5385809253545126
0.000129706664282848,0.04482736547309461,376.22988606105577,121.09809501312698,2.5385809253545126
0.00013037345326796947,0.045057811562312464,376.65911165738805,121.09809501312698,2.5385809253545126
0.00013092911075557068,0.045249849969994,377.0161460424794,121.09809501312698,2.5385809253545126
0.00013131807099689156,0.04538427685537108,377.26571858363155,121.09809501312698,2.5385809253545126
0.00013154033399193204,0.04546109221844369,377.4082020227207,121.09809501312698,2.5385809253545126
0.0001340963584348977,0.04634446889377876,379.0400699923425,121.09809501312698,2.5385809253545126
0.00013570776514894124,0.04690138027605521,380.06262421979596,121.09809501312698,2.5385809253545126
0.00013698577737042406,0.04734306861372274,380.87025228657984,121.09809501312698,2.5385809253545126
0.00013837492108942714,0.04782316463292659,381.7447831547726,121.09809501312698,2.5385809253545126
0.0001390417100745486,0.048053610722144424,382.1633412043438,121.09809501312698,2.5385809253545126
0.0001407642482861124,0.048648929785957196,383.2410089022261,121.09809501312698,2.5385809253545126
0.00014193112901007498,0.04905221044208842,383.96812132707277,121.09809501312698,2.5385809253545126
0.00014232008925139583,0.04918663732746549,384.2099735599105,121.09809501312698,2.5385809253545126
0.0001432091412315578,0.04949389877975595,384.76181274687724,121.09809501312698,2.5385809253545126
0.00014387593021667928,0.0497243448689738,385.17481575824894,121.09809501312698,2.5385809253545126
0.0001448761136943615,0.05007001400280056,385.79292337890007,121.09809501312698,2.5385809253545126
0.00014587629717204367,0.05041568313662732,386.4093689989215,121.09809501312698,2.5385809253545126
0.00014620969166460442,0.05053090618123625,386.61448428032656,121.09809501312698,2.5385809253545126
0.00014676534915220564,0.05072294458891778,386.9559381951218,121.09809501312698,2.5385809253545126
0.00014698761214724615,0.0507997599519904,387.0923785477821,121.09809501312698,2.5385809253545126
0.00014743213813732715,0.05095339067813563,387.36501810522867,121.09809501312698,2.5385809253545126
0.00014871015035880993,0.05139507901580316,388.1470767087429,121.09809501312698,2.5385809253545126
0.00014971033383649214,0.05174074814962992,388.7572956417745,121.09809501312698,2.5385809253545126
0.0001502659913240934,0.05193278655731147,389.09561909934206,121.09809501312698,2.5385809253545126
0.00015054382006789402,0.052028805761152236,389.2645978353307,121.09809501312698,2.5385809253545126
0.00015165513504309644,0.0524128825765153,389.9393001045816,121.09809501312698,2.5385809253545126
0.00015259975277201853,0.05273934786957392,390.5112823495954,121.09809501312698,2.5385809253545126
0.0001537666334959811,0.05314262852570514,391.21594577048603,121.09809501312698,2.5385809253545126
0.00015510021146622406,0.05360352070414083,392.01872673814825,121.09809501312698,2.5385809253545126
0.00015654492093398724,0.05410282056411282,392.88537436832877,121.09809501312698,2.5385809253545126
0.00015721170991910872,0.05433326665333067,393.28431299247353,121.09809501312698,2.5385809253545126
0.00015771180165794982,0.054506101220244046,393.5830840493458,121.09809501312698,2.5385809253545126
0.00015782293315547003,0.05454450890178035,393.6494274151462,121.09809501312698,2.5385809253545126
0.0001581007618992707,0.05464052810562113,393.8152061705709,121.09809501312698,2.5385809253545126
0.00015832302489431115,0.05471734346869374,393.94774738658776,121.09809501312698,2.5385809253545126
0.00015882311663315227,0.054890178035607126,394.24570008763027,121.09809501312698,2.5385809253545126
0.00015904537962819275,0.054966993398679734,394.3780060416548,121.09809501312698,2.5385809253545126
0.000159156511125713,0.05500540108021604,394.4441319763616,121.09809501312698,2.5385809253545126
0.0001611568780810774,0.055696739347869575,395.63133677475537,121.09809501312698,2.5385809253545126
0.00016337950803148234,0.05646489297859572,396.94373310021325,121.09809501312698,2.5385809253545126
0.00016465752025296513,0.05690658131626325,397.6952078820442,121.09809501312698,2.5385809253545126
0.0001652131777405664,0.057098619723944796,398.02122616160347,121.09809501312698,2.5385809253545126
0.00016599109822320807,0.05736747349469894,398.4769342487404,121.09809501312698,2.5385809253545126
0.00016621336121824858,0.05744428885777156,398.60698347676527,121.09809501312698,2.5385809253545126
0.0001694361746463357,0.058558111622324466,400.4851407205419,121.09809501312698,2.5385809253545126
0.0001703807923752578,0.05888457691538308,401.0329880509591,121.09809501312698,2.5385809253545126
0.00017399256604466574,0.06013282656531306,403.116864892523,121.09809501312698,2.5385809253545126
0.00017477048652730746,0.060401680336067215,403.56348394496626,121.09809501312698,2.5385809253545126
0.00017543727551242892,0.06063212642528505,403.9456835529112,121.09809501312698,2.5385809253545126
0.00017943800942315776,0.062014802960592114,406.2270961635987,121.09809501312698,2.5385809253545126
0.00018032706140331972,0.06232206441288257,406.7313726430236,121.09809501312698,2.5385809253545126
0.00018049375864960009,0.062379675935187034,406.8258164405779,121.09809501312698,2.5385809253545126
0.00018154950787604244,0.06274454890978196,407.42317246476637,121.09809501312698,2.5385809253545126
0.00018260525710248477,0.06310942188437688,408.0191752512495,121.09809501312698,2.5385809253545126
0.0001829386515950455,0.0632246449289858,408.20710726019837,121.09809501312698,2.5385809253545126
0.00018582807053057189,0.06422324464892978,409.83029397308377,121.09809501312698,2.5385809253545126
0.00018766174023965594,0.06485697139427886,410.85528973158364,121.09809501312698,2.5385809253545126
0.00018888418671237863,0.06527945589117824,411.5364510705653,121.09809501312698,2.5385809253545126
0.00018993993593882094,0.06564432886577315,412.12334434113257,121.09809501312698,2.5385809253545126
0.0001908289879189829,0.06595159031806361,412.6165841391154,121.09809501312698,2.5385809253545126
0.00019149577690410439,0.06618203640728146,412.9859260705653,121.09809501312698,2.5385809253545126
0.00019232926313550623,0.06647009401880376,413.446898927401,121.09809501312698,2.5385809253545126
0.00019332944661318847,0.06681576315263053,413.99903922014266,121.09809501312698,2.5385809253545126
0.0001947185903321915,0.06729585917183437,414.76405618910906,121.09809501312698,2.5385809253545126
0.00019577433955863383,0.06766073214642929,415.3440463788928,121.09809501312698,2.5385809253545126
0.00019588547105615412,0.0676991398279656,415.4050269353966,121.09809501312698,2.5385809253545126
0.00019755244351895776,0.0682752550510102,416.3181222951378,121.09809501312698,2.5385809253545126
0.00019788583801151852,0.06839047809561913,416.50038024451356,121.09809501312698,2.5385809253545126
0.0001995528104743222,0.06896659331866374,417.40987982976435,121.09809501312698,2.5385809253545126
0.00020166430892720684,0.06969633926785357,418.55767024563863,121.09809501312698,2.5385809253545126
0.00020244222940984856,0.06996519303860772,418.979357706557,121.09809501312698,2.5385809253545126
0.00020272005815364917,0.07006121224244849,419.12980715690344,121.09809501312698,2.5385809253545126
0.00020344241288753075,0.07031086217243449,419.52059986868505,121.09809501312698,2.5385809253545126
0.00020383137312885165,0.07044528905781157,419.7308025519469,121.09809501312698,2.5385809253545126
0.00020416476762141238,0.0705605121024205,419.91085180059775,121.09809501312698,2.5385809253545126
0.00020460929361149337,0.07071414282856572,420.15073919819577,121.09809501312698,2.5385809253545126
0.0002054427798428952,0.07100220044008802,420.5999809423343,121.09809501312698,2.5385809253545126
0.00020694305505941852,0.07152070414082817,421.4068289361597,121.09809501312698,2.5385809253545126
0.0002079432385371007,0.07186637327465493,421.94346059107335,121.09809501312698,2.5385809253545126
0.00020927681650734366,0.07232726545309062,422.6574061924328,121.09809501312698,2.5385809253545126
0.00021055482872882645,0.07276895379075815,423.3399409639714,121.09809501312698,2.5385809253545126
0.0002115550122065087,0.07311462292458493,423.872972234136,121.09809501312698,2.5385809253545126
0.00021333311616683262,0.07372914582916584,424.8181630020844,121.09809501312698,2.5385809253545126
0.00021405547090071422,0.07397879575915184,425.20126853448585,121.09809501312698,2.5385809253545126
0.00021538904887095716,0.07443968793758753,425.90721824268365,121.09809501312698,2.5385809253545126
0.0002170560213337608,0.07501580316063212,426.787262808061,121.09809501312698,2.5385809253545126
0.00022000100601804736,0.07603360672134428,428.33559337459593,121.09809501312698,2.5385809253545126
0.00022200137297341175,0.0767249449889978,429.3826823959545,121.09809501312698,2.5385809253545126
0.00022294599070233384,0.07705141028205642,429.87586145508413,121.09809501312698,2.5385809253545126
0.00022472409466265777,0.07766593318663734,430.80199336178606,121.09809501312698,2.5385809253545126
0.00022722455335686328,0.07853010602120425,432.0995456487227,121.09809501312698,2.5385809253545126
0.00022772464509570437,0.07870294058811762,432.35838656141414,121.09809501312698,2.5385809253545126
0.0002290026573171872,0.07914462892578517,433.0188637486681,121.09809501312698,2.5385809253545126
0.0002309474585237915,0.07981676335267054,434.02118620024623,121.09809501312698,2.5385809253545126
0.00023189207625271357,0.08014322864572915,434.5068403547619,121.09809501312698,2.5385809253545126
0.00023289225973039578,0.08048889777955591,435.02022220006137,121.09809501312698,2.5385809253545126
0.0002332256542229565,0.08060412082416483,435.19115830713054,121.09809501312698,2.5385809253545126
0.00023400357470559823,0.08087297459491899,435.58963905275584,121.09809501312698,2.5385809253545126
0.00023467036369071969,0.08110342068413683,435.9307829527723,121.09809501312698,2.5385809253545126
0.0002358928101634424,0.08152590518103621,436.55523320984815,121.09809501312698,2.5385809253545126
0.00023628177040476328,0.0816603320664133,436.75365709536254,121.09809501312698,2.5385809253545126
0.00023817100586260746,0.08231326265253051,437.7156240877654,121.09809501312698,2.5385809253545126
0.0002403380700642522,0.0830622124424885,438.8153998398508,121.09809501312698,2.5385809253545126
0.00024194947677829578,0.08361912382476495,439.630676436173,121.09809501312698,2.5385809253545126
0.0002422828712708565,0.08373434686937388,439.79908965870055,121.09809501312698,2.5385809253545126
0.00024378314648737984,0.08425285057011403,440.55583348248103,121.09809501312698,2.5385809253545126
0.00024422767247746083,0.08440648129625926,440.77970478819594,121.09809501312698,2.5385809253545126
0.00024706152566422707,0.0853858771754351,442.20316674876784,121.09809501312698,2.5385809253545126
0.0002476171831518283,0.08557791558311663,442.48152871311885,121.09809501312698,2.5385809253545126
0.0002493397213633921,0.08617323464692939,443.34290668100635,121.09809501312698,2.5385809253545126
0.00025022877334355403,0.08648049609921984,443.7865806399539,121.09809501312698,2.5385809253545126
0.00025089556232867554,0.0867109421884377,444.1189327736929,121.09809501312698,2.5385809253545126
0.00025217357455015833,0.08715263052610522,444.75497975320997,121.09809501312698,2.5385809253545126
0.0002535071525204013,0.08761352270454091,445.41734206951963,121.09809501312698,2.5385809253545126
0.00025534082222948535,0.08824724944988999,446.3258757004301,121.09809501312698,2.5385809253545126
0.00025778571517493074,0.08909221844368874,447.533305583329,121.09809501312698,2.5385809253545126
0.0002591192931451737,0.08955311062212443,448.1900210013512,121.09809501312698,2.5385809253545126
0.00025928599039145406,0.08961072214442889,448.27201764646,121.09809501312698,2.5385809253545126
0.0002593971218889743,0.0896491298259652,448.32667065495065,121.09809501312698,2.5385809253545126
0.00026006391087409576,0.08987957591518304,448.65439714664404,121.09809501312698,2.5385809253545126
0.00026056400261293685,0.09005241048209642,448.89997700174666,121.09809501312698,2.5385809253545126
0.00026278663256334176,0.09082056411282256,449.9892266357141,121.09809501312698,2.5385809253545126
0.000263342290050943,0.09101260252050411,450.2609769112797,121.09809501312698,2.5385809253545126
0.00026417577628234484,0.09130066013202641,450.6681834035654,121.09809501312698,2.5385809253545126
0.00026645397198150986,0.09208801760352071,451.7786660001907,121.09809501312698,2.5385809253545126
0.00026734302396167186,0.09239527905581117,452.21101982061776,121.09809501312698,2.5385809253545126
0.00026862103618315465,0.0928369673934787,452.83154734032246,121.09809501312698,2.5385809253545126
0.00026978791690711725,0.09324024804960993,453.39711112341547,121.09809501312698,2.5385809253545126
0.0002702324428971982,0.09339387877575515,453.6123129532037,121.09809501312698,2.5385809253545126
0.0002708992318823197,0.093624324864973,453.93485701532586,121.09809501312698,2.5385809253545126
0.0002715660208674412,0.09385477095419084,454.2570916018624,121.09809501312698,2.5385809253545126
0.00027323299333024487,0.09443088617723545,455.0613310254659,121.09809501312698,2.5385809253545126
0.0002735108220740455,0.09452690538107622,455.19518466980145,121.09809501312698,2.5385809253545126
0.00027417761105916693,0.09475735147029406,455.5162172509663,121.09809501312698,2.5385809253545126
0.00027451100555172766,0.09487257451490298,455.67661934830153,121.09809501312698,2.5385809253545126
0.00027523336028560923,0.09512222444488898,456.02389682028337,121.09809501312698,2.5385809253545126
0.00027612241226577123,0.09542948589717944,456.45082766423656,121.09809501312698,2.5385809253545126
0.00027673363550213256,0.09564072814562913,456.7440316880955,121.09809501312698,2.5385809253545126
0.0002776782532310547,0.09596719343868775,457.1966688896386,121.09809501312698,2.5385809253545126
0.0002792896599450982,0.0965241048209642,457.96743117521765,121.09809501312698,2.5385809253545126
0.00028028984342278043,0.09686977395479096,458.44496311787236,121.09809501312698,2.5385809253545126
0.0002807343694128614,0.09702340468093619,458.65698617095086,121.09809501312698,2.5385809253545126
0.00028256803912194545,0.09765713142628527,459.5302008480592,121.09809501312698,2.5385809253545126
0.0002831792623583068,0.09786837367473496,459.8207809405862,121.09809501312698,2.5385809253545126
0.00028429057733350926,0.09825245049009802,460.34848247693463,121.09809501312698,2.5385809253545126
0.00028456840607730987,0.09834846969393879,460.4802820822901,121.09809501312698,2.5385809253545126
0.00028540189230871174,0.0986365273054611,460.8753801207782,121.09809501312698,2.5385809253545126
0.000286457641535154,0.09900140028005601,461.3751922374511,121.09809501312698,2.5385809253545126
0.00028845800849051846,0.09969273854770955,462.32023892243615,121.09809501312698,2.5385809253545126
0.0002885691399880387,0.09973114622924585,462.3726664478212,121.09809501312698,2.5385809253545126