File: datasets/aisi_316_L/data/M1/train_12.csv
Time(s),Strain(%),Stress(MPa),Temp(C),Log_SR(s-1)
0.0,0.0,0.0,375.06032132375054,-1.3643820021478605
0.00024066633339594378,1.0399999999999999e-05,1.7822639249999999,375.06032132375054,-1.3643820021478605
0.0004072814872854434,1.76e-05,3.01613895,375.06032132375054,-1.3643820021478605
0.0006664606155579981,2.88e-05,4.9355001,375.06032132375054,-1.3643820021478605
0.0007960501796942755,3.4399999999999996e-05,5.895180674999999,375.06032132375054,-1.3643820021478605
0.0009996909233369973,4.32e-05,7.40325015,375.06032132375054,-1.3643820021478605
0.001240357256732941,5.3599999999999995e-05,9.185514074999999,375.06032132375054,-1.3643820021478605
0.0016106131542651624,6.96e-05,11.927458575,375.06032132375054,-1.3643820021478605
0.0019438434620441614,8.4e-05,14.395208624999999,375.06032132375054,-1.3643820021478605
0.0023140993595763826,9.999999999999999e-05,17.137153124999998,375.06032132375054,-1.3643820021478605
0.002813944821244881,0.0001216,20.8387782,375.06032132375054,-1.3643820021478605
0.0030360983597642137,0.0001312,22.483944899999997,375.06032132375054,-1.3643820021478605
0.0034804054368028792,0.0001504,25.7742783,375.06032132375054,-1.3643820021478605
0.0036655333855689903,0.0001584,27.14525055,375.06032132375054,-1.3643820021478605
0.004054302077977822,0.0001752,30.024292275,375.06032132375054,-1.3643820021478605
0.0044800963601398765,0.0001936,33.17752845,375.06032132375054,-1.3643820021478605
0.0047948138730422646,0.0002072,35.508181275,375.06032132375054,-1.3643820021478605
0.004979941821808376,0.0002152,36.879153525,375.06032132375054,-1.3643820021478605
0.00507250579619143,0.0002192,37.56463965,375.06032132375054,-1.3643820021478605
0.0052391209500809305,0.0002264,38.798514675,375.06032132375054,-1.3643820021478605
0.0056834280271195955,0.0002456,42.088848075,375.06032132375054,-1.3643820021478605
0.005775992001502651,0.0002496,42.7743342,375.06032132375054,-1.3643820021478605
0.006405427027307427,0.0002768,47.43563985,375.06032132375054,-1.3643820021478605
0.0067756829248396475,0.00029279999999999996,50.17758435,375.06032132375054,-1.3643820021478605
0.007756861053300034,0.00033519999999999996,57.443737275,375.06032132375054,-1.3643820021478605
0.007941989002066146,0.0003432,58.814709525,375.06032132375054,-1.3643820021478605
0.008312244899598366,0.0003592,61.556654025,375.06032132375054,-1.3643820021478605
0.008478860053487865,0.00036639999999999996,62.790529049999996,375.06032132375054,-1.3643820021478605
0.008682500797130586,0.00037519999999999996,64.29859852499999,375.06032132375054,-1.3643820021478605
0.008867628745896698,0.0003832,65.669570775,375.06032132375054,-1.3643820021478605
0.009848806874357085,0.0004256,72.9357237,375.06032132375054,-1.3643820021478605
0.009996909233369973,0.000432,74.0325015,375.06032132375054,-1.3643820021478605
0.01031162674627236,0.0004456,76.363154325,375.06032132375054,-1.3643820021478605
0.010404190720655416,0.0004496,77.04864045,375.06032132375054,-1.3643820021478605
0.010922548977200526,0.000472,80.88736275,375.06032132375054,-1.3643820021478605
0.011089164131090026,0.0004792,82.121237775,375.06032132375054,-1.3643820021478605
0.011311317669609357,0.0004888,83.76640447499999,375.06032132375054,-1.3643820021478605
0.011459420028622247,0.0004952,84.863182275,375.06032132375054,-1.3643820021478605
0.01170008636201819,0.0005055999999999999,86.6454462,375.06032132375054,-1.3643820021478605
0.012107367849303632,0.0005231999999999999,89.66158515,375.06032132375054,-1.3643820021478605
0.012977469208504353,0.0005608,96.10515472499999,375.06032132375054,-1.3643820021478605
0.01345880187529624,0.0005815999999999999,99.66968257499998,375.06032132375054,-1.3643820021478605
0.01395864733696474,0.0006032,103.37130765,375.06032132375054,-1.3643820021478605
0.014088236901101015,0.0006087999999999999,104.33098822499998,375.06032132375054,-1.3643820021478605
0.014662133542275961,0.0006336,108.5810022,375.06032132375054,-1.3643820021478605
0.01482874869616546,0.0006408,109.81487722499999,375.06032132375054,-1.3643820021478605
0.015050902234684792,0.0006504,111.460043925,375.06032132375054,-1.3643820021478605
0.015180491798821071,0.000656,112.4197245,375.06032132375054,-1.3643820021478605
0.015402645337340402,0.0006655999999999999,114.06489119999999,375.06032132375054,-1.3643820021478605
0.015476696516846846,0.0006688,114.6132801,375.06032132375054,-1.3643820021478605
0.0160691059528984,0.0006944,119.00039129999999,375.06032132375054,-1.3643820021478605
0.0165689514145669,0.000716,122.70201637499999,375.06032132375054,-1.3643820021478605
0.016698540978703175,0.0007216,123.66169694999999,375.06032132375054,-1.3643820021478605
0.017031771286482176,0.000736,126.129447,375.06032132375054,-1.3643820021478605
0.017179873645495062,0.0007423999999999999,127.22622479999998,375.06032132375054,-1.3643820021478605
0.01730946320963134,0.000748,128.185905375,375.06032132375054,-1.3643820021478605
0.017698231902040173,0.0007647999999999999,131.06494709999998,375.06032132375054,-1.3643820021478605
0.018049975004695785,0.00078,133.669794375,375.06032132375054,-1.3643820021478605
0.018864537979266672,0.0008152,139.702072275,375.06032132375054,-1.3643820021478605
0.018975614748526336,0.00082,140.524655625,375.06032132375054,-1.3643820021478605
0.01934587064605856,0.0008359999999999999,143.266600125,375.06032132375054,-1.3643820021478605
0.02014192082575283,0.0008703999999999999,149.16178079999997,375.06032132375054,-1.3643820021478605
0.020327048774518946,0.0008784,150.53275305,375.06032132375054,-1.3643820021478605
0.020493663928408443,0.0008856,151.766628075,375.06032132375054,-1.3643820021478605
0.020641766287421332,0.000892,152.863405875,375.06032132375054,-1.3643820021478605
0.020956483800323722,0.0009056,155.1940587,375.06032132375054,-1.3643820021478605
0.02117863733884305,0.0009151999999999999,156.83922539999998,375.06032132375054,-1.3643820021478605
0.02145632926199222,0.0009272,156.94227203961884,375.06032132375054,-1.3643820021478605
0.021752533980017995,0.00094,157.0095243225638,375.06032132375054,-1.3643820021478605
0.021919149133907495,0.0009471999999999999,157.04719676002873,375.06032132375054,-1.3643820021478605
0.023011404031627547,0.0009943999999999999,157.2914512352195,375.06032132375054,-1.3643820021478605
0.02304842962138077,0.000996,157.2996508398377,375.06032132375054,-1.3643820021478605
0.02325207036502349,0.0010048,157.34465717410768,375.06032132375054,-1.3643820021478605
0.023862992595951656,0.0010312,157.47876275069996,375.06032132375054,-1.3643820021478605
0.024048120544717767,0.0010391999999999999,157.51913556803,375.06032132375054,-1.3643820021478605
0.02425176128836049,0.0010479999999999999,157.56340592550325,375.06032132375054,-1.3643820021478605
0.024436889237126596,0.0010559999999999999,157.60352605834817,375.06032132375054,-1.3643820021478605
0.02484417072441204,0.0010735999999999999,157.69137544991744,375.06032132375054,-1.3643820021478605
0.02504781146805476,0.0010823999999999999,157.73508939031151,375.06032132375054,-1.3643820021478605
0.025362528980957155,0.001096,157.8023756531395,375.06032132375054,-1.3643820021478605
0.026251143135034485,0.0011344,157.9906248908832,375.06032132375054,-1.3643820021478605
0.026399245494047374,0.0011408,158.021756551948,375.06032132375054,-1.3643820021478605
0.026510322263307035,0.0011455999999999999,158.04506061747517,375.06032132375054,-1.3643820021478605
0.026584373442813482,0.0011488,158.0605755087801,375.06032132375054,-1.3643820021478605
0.02691760375059248,0.0011631999999999999,158.13018499136547,375.06032132375054,-1.3643820021478605
0.027158270083988426,0.0011736,158.18024966153033,375.06032132375054,-1.3643820021478605
0.027324885237877922,0.0011807999999999999,158.21480850587773,375.06032132375054,-1.3643820021478605
0.02808390982781898,0.0012136,158.3712147682513,375.06032132375054,-1.3643820021478605
0.028361601750968142,0.0012255999999999999,158.42802353354674,375.06032132375054,-1.3643820021478605
0.02882442162288342,0.0012456,158.5222251015212,375.06032132375054,-1.3643820021478605
0.029546420623071255,0.0012768,158.66801008740123,375.06032132375054,-1.3643820021478605
0.029583446212824473,0.0012783999999999998,158.67544856282464,375.06032132375054,-1.3643820021478605
0.02971303577696075,0.001284,158.70145468259508,375.06032132375054,-1.3643820021478605
0.03015734285399942,0.0013032,158.79028461541952,375.06032132375054,-1.3643820021478605
0.030286932418135695,0.0013088,158.81609701116918,375.06032132375054,-1.3643820021478605
0.030453547572025192,0.001316,158.84922117407396,375.06032132375054,-1.3643820021478605
0.031120008187583193,0.0013448,158.9810170920738,375.06032132375054,-1.3643820021478605
0.03178646880314119,0.0013736,159.1117167124393,375.06032132375054,-1.3643820021478605
0.031860519982647634,0.0013767999999999999,159.12617261762975,375.06032132375054,-1.3643820021478605
0.03200862234166053,0.0013832,159.15504517732234,375.06032132375054,-1.3643820021478605
0.0323048270596863,0.0013959999999999999,159.21263446734886,375.06032132375054,-1.3643820021478605
0.03267508295721852,0.0014119999999999998,159.2843323005972,375.06032132375054,-1.3643820021478605
0.032749134136724964,0.0014152,159.2986337688372,375.06032132375054,-1.3643820021478605
0.03284169811110802,0.0014192,159.31649288121548,375.06032132375054,-1.3643820021478605
0.0329712876752443,0.0014248,159.34146269382805,375.06032132375054,-1.3643820021478605
0.034563388034632846,0.0014935999999999999,159.64517571799888,375.06032132375054,-1.3643820021478605
0.0349891823167949,0.0015119999999999999,159.72547021420348,375.06032132375054,-1.3643820021478605
0.03522984865019085,0.0015224,159.77068547514978,375.06032132375054,-1.3643820021478605
0.035322412624573904,0.0015264,159.78804386423832,375.06032132375054,-1.3643820021478605
0.03567415572722951,0.0015416,159.85384457843904,375.06032132375054,-1.3643820021478605
0.03572969411185935,0.001544,159.86421099022346,375.06032132375054,-1.3643820021478605
0.036155488394021405,0.0015624,159.9434790936578,375.06032132375054,-1.3643820021478605
0.036933025778839064,0.001596,160.08729641056235,375.06032132375054,-1.3643820021478605
0.037099640932728564,0.0016032,160.11796022637367,375.06032132375054,-1.3643820021478605
0.03745138403538417,0.0016183999999999999,160.18251913439187,375.06032132375054,-1.3643820021478605
0.037729075958533344,0.0016304,160.23331980735736,375.06032132375054,-1.3643820021478605
0.03806230626631234,0.0016447999999999999,160.2940885350501,375.06032132375054,-1.3643820021478605
0.03869174129211712,0.0016719999999999999,160.40831077347184,375.06032132375054,-1.3643820021478605
0.039506304266688004,0.0017071999999999999,160.5550577447546,375.06032132375054,-1.3643820021478605
0.0396544066257009,0.0017136,160.5816117452909,375.06032132375054,-1.3643820021478605
0.039765483394960555,0.0017184,160.6015018706444,375.06032132375054,-1.3643820021478605
0.040431944010518556,0.0017472,160.72039075534735,375.06032132375054,-1.3643820021478605
0.04063558475416128,0.001756,160.7565651474034,375.06032132375054,-1.3643820021478605
0.04082071270292739,0.001764,160.78938965318076,375.06032132375054,-1.3643820021478605
0.041061379036323335,0.0017744,160.8319748463847,375.06032132375054,-1.3643820021478605
0.04139460934410233,0.0017888,160.8907786068731,375.06032132375054,-1.3643820021478605
0.04241281306231594,0.0018327999999999999,161.06932329160588,375.06032132375054,-1.3643820021478605
0.042597941011082045,0.0018407999999999999,161.10160555600208,375.06032132375054,-1.3643820021478605
0.04282009454960138,0.0018503999999999999,161.1402721384239,375.06032132375054,-1.3643820021478605
0.04298670970349088,0.0018575999999999998,161.16922075381981,375.06032132375054,-1.3643820021478605
0.043356965601023104,0.0018736,161.23339480006686,375.06032132375054,-1.3643820021478605
0.043523580754912604,0.0018808,161.26220335502924,375.06032132375054,-1.3643820021478605
0.043727221498555326,0.0018896,161.29735546792728,375.06032132375054,-1.3643820021478605
0.044449220498743156,0.0019207999999999999,161.42147449083316,375.06032132375054,-1.3643820021478605
0.04448624608849638,0.0019223999999999999,161.427818289188,375.06032132375054,-1.3643820021478605
0.0446898868321391,0.0019311999999999999,161.4626724423019,375.06032132375054,-1.3643820021478605
0.04489352757578182,0.0019399999999999999,161.49746470968662,375.06032132375054,-1.3643820021478605
0.045597013781093036,0.0019703999999999998,161.61718543470226,375.06032132375054,-1.3643820021478605
0.04628198719152765,0.002,161.73306535148296,375.06032132375054,-1.3643820021478605
0.04659670470443004,0.0020136,161.78608303026013,375.06032132375054,-1.3643820021478605
0.04726316531998803,0.0020423999999999998,161.89789696021452,375.06032132375054,-1.3643820021478605
0.04761490842264364,0.0020575999999999997,161.95666186922801,375.06032132375054,-1.3643820021478605
0.04796665152529926,0.0020728,162.01525771679962,375.06032132375054,-1.3643820021478605
0.048262856243325034,0.0020856,162.06447172577452,375.06032132375054,-1.3643820021478605
0.048522035371597584,0.0020968,162.10743743433693,375.06032132375054,-1.3643820021478605
0.04941064952567492,0.0021352,162.25407366654633,375.06032132375054,-1.3643820021478605
0.04989198219246681,0.002156,162.33307204681583,375.06032132375054,-1.3643820021478605
0.050206699705369194,0.0021696,162.38456417742051,375.06032132375054,-1.3643820021478605
0.05085464752605059,0.0021976,162.49018269985052,375.06032132375054,-1.3643820021478605
0.05100274988506347,0.002204,162.51425023298475,375.06032132375054,-1.3643820021478605
0.05161367211599164,0.0022304,162.6132420657528,375.06032132375054,-1.3643820021478605
0.05183582565451097,0.00224,162.64912566262254,375.06032132375054,-1.3643820021478605
0.05202095360327708,0.002248,162.67898286733228,375.06032132375054,-1.3643820021478605
0.05246526068031575,0.0022672,162.75047159311382,375.06032132375054,-1.3643820021478605
0.05324279806513341,0.0023008,162.87501130829574,375.06032132375054,-1.3643820021478605
0.05348346439852935,0.0023112,162.9134152991239,375.06032132375054,-1.3643820021478605
0.053872233090938186,0.0023279999999999998,162.97531045113752,375.06032132375054,-1.3643820021478605
0.054223976193593794,0.0023431999999999997,163.03116088459998,375.06032132375054,-1.3643820021478605
0.054464642526989744,0.0023536,163.06929295361238,375.06032132375054,-1.3643820021478605
0.0545572065013728,0.0023576,163.08394162927746,375.06032132375054,-1.3643820021478605
0.05487192401427519,0.0023712,163.13367478401003,375.06032132375054,-1.3643820021478605
0.054964487988658245,0.0023752,163.14828099511845,375.06032132375054,-1.3643820021478605
0.055279205501560624,0.0023888,163.19787051339588,375.06032132375054,-1.3643820021478605
0.055612435809339625,0.0024032,163.25025720060262,375.06032132375054,-1.3643820021478605
0.05585310214273556,0.0024135999999999997,163.28801592443574,375.06032132375054,-1.3643820021478605
0.056075255681254904,0.0024232,163.32281385057144,375.06032132375054,-1.3643820021478605
0.056445511578787126,0.0024392,163.38069115367514,375.06032132375054,-1.3643820021478605
0.05711197219434512,0.0024679999999999997,163.4844985548019,375.06032132375054,-1.3643820021478605
0.05751925368163056,0.0024855999999999997,163.5477038761292,375.06032132375054,-1.3643820021478605
0.05766735604064345,0.002492,163.57064432367022,375.06032132375054,-1.3643820021478605
0.05790802237403939,0.0025023999999999997,163.60787360552325,375.06032132375054,-1.3643820021478605
0.05838935504083128,0.0025231999999999997,163.68215163325607,375.06032132375054,-1.3643820021478605
0.05863002137422723,0.0025336,163.7192010689069,375.06032132375054,-1.3643820021478605
0.05918540522052556,0.0025575999999999997,163.80447413856814,375.06032132375054,-1.3643820021478605
0.05977781465657712,0.0025832,163.89508882816426,375.06032132375054,-1.3643820021478605
0.0600925321694795,0.0025968,163.94308539984155,375.06032132375054,-1.3643820021478605
0.06027766011824562,0.0026048,163.97127288388694,375.06032132375054,-1.3643820021478605
0.060907095144050384,0.002632,164.06685879237884,375.06032132375054,-1.3643820021478605
0.061480991785225335,0.0026568,164.1536754181221,375.06032132375054,-1.3643820021478605
0.061925298862264,0.002676,164.22067140930028,375.06032132375054,-1.3643820021478605
0.06209191401615349,0.0026831999999999997,164.24574654118612,375.06032132375054,-1.3643820021478605
0.0624436571188091,0.0026983999999999997,164.29859691874043,375.06032132375054,-1.3643820021478605
0.0630916049394905,0.0027264,164.3956499415387,375.06032132375054,-1.3643820021478605
0.06403575747819766,0.0027672,164.5363770385657,375.06032132375054,-1.3643820021478605
0.06436898778597666,0.0027816,164.58585192015116,375.06032132375054,-1.3643820021478605
0.06483180765789194,0.0028016,164.6544016427773,375.06032132375054,-1.3643820021478605
0.06501693560665804,0.0028095999999999998,164.68176806163325,375.06032132375054,-1.3643820021478605
0.06525760194005399,0.00282,164.71729901644673,375.06032132375054,-1.3643820021478605
0.06549826827344993,0.0028304,164.7527789037591,375.06032132375054,-1.3643820021478605
0.06570190901709266,0.0028392,164.782760653027,375.06032132375054,-1.3643820021478605
0.06610919050437811,0.0028568,164.84261564748573,375.06032132375054,-1.3643820021478605
0.06622026727363776,0.0028615999999999997,164.85891475569144,375.06032132375054,-1.3643820021478605
0.06647944640191032,0.0028728,164.89690459912103,375.06032132375054,-1.3643820021478605
0.06672011273530626,0.0028832,164.93212919392911,375.06032132375054,-1.3643820021478605
0.06701631745333203,0.0028959999999999997,164.97541458988357,375.06032132375054,-1.3643820021478605
0.06753467570987715,0.0029184,165.0509849222765,375.06032132375054,-1.3643820021478605
0.06773831645351987,0.0029272,165.0806113343554,375.06032132375054,-1.3643820021478605
0.06899718650512943,0.0029816,165.26299130750527,375.06032132375054,-1.3643820021478605
0.06908975047951248,0.0029855999999999997,165.27635015900577,375.06032132375054,-1.3643820021478605
0.06968215991556403,0.0030112,165.36168211388176,375.06032132375054,-1.3643820021478605
0.07040415891575186,0.0030424,165.465298855252,375.06032132375054,-1.3643820021478605
0.07057077406964136,0.0030496,165.48915146140283,375.06032132375054,-1.3643820021478605
0.07084846599279053,0.0030616,165.52885705640324,375.06032132375054,-1.3643820021478605
0.07108913232618648,0.003072,165.5632195024889,375.06032132375054,-1.3643820021478605
0.07195923368538719,0.0031095999999999997,165.6870762270991,375.06032132375054,-1.3643820021478605
0.07286636063434113,0.0031487999999999998,165.81558315980902,375.06032132375054,-1.3643820021478605
0.07338471889088624,0.0031712,165.88873554575042,375.06032132375054,-1.3643820021478605
0.07349579566014591,0.003176,165.90438480745354,375.06032132375054,-1.3643820021478605
0.07432887142959341,0.003212,166.02146167065087,375.06032132375054,-1.3643820021478605
0.0748287168912619,0.0032335999999999997,166.09146216869794,375.06032132375054,-1.3643820021478605
0.07518045999391752,0.0032488,166.14061250304908,375.06032132375054,-1.3643820021478605
0.07568030545558602,0.0032703999999999997,166.21030371995505,375.06032132375054,-1.3643820021478605
0.07597651017361179,0.0032832,166.25151751350944,375.06032132375054,-1.3643820021478605
0.07688363712256573,0.0033223999999999997,166.3773466765564,375.06032132375054,-1.3643820021478605
0.07721686743034474,0.0033368,166.42342405028944,375.06032132375054,-1.3643820021478605
0.0774945593534939,0.0033488,166.46176265168467,375.06032132375054,-1.3643820021478605
0.07788332804590273,0.0033656,166.51534680346606,375.06032132375054,-1.3643820021478605
0.07792035363565596,0.0033672,166.5204446094345,375.06032132375054,-1.3643820021478605
0.07806845599466884,0.0033736,166.54082639330497,375.06032132375054,-1.3643820021478605
0.07845722468707768,0.0033904,166.5942569581204,375.06032132375054,-1.3643820021478605
0.07875342940510345,0.0034032,166.63489668350385,375.06032132375054,-1.3643820021478605
0.07888301896923973,0.0034088,166.65265781334423,375.06032132375054,-1.3643820021478605
0.0795124539950445,0.003436,166.73876481583412,375.06032132375054,-1.3643820021478605
0.07979014591819367,0.0034479999999999997,166.77666864396755,375.06032132375054,-1.3643820021478605
0.07995676107208317,0.0034552,166.79938624699005,375.06032132375054,-1.3643820021478605
0.08036404255936862,0.0034728,166.85484058090535,375.06032132375054,-1.3643820021478605
0.08043809373887506,0.003476,166.86491140023708,375.06032132375054,-1.3643820021478605
0.08114157994418628,0.0035064,166.96040453050395,375.06032132375054,-1.3643820021478605
0.08130819509807578,0.0035136,166.9829739666351,375.06032132375054,-1.3643820021478605
0.08315947458573689,0.0035935999999999997,167.23254384903152,375.06032132375054,-1.3643820021478605
0.08354824327814571,0.0036103999999999997,167.28467717053303,375.06032132375054,-1.3643820021478605
0.08364080725252877,0.0036144,167.2970759111577,375.06032132375054,-1.3643820021478605
0.08382593520129489,0.0036224,167.32185734994022,375.06032132375054,-1.3643820021478605
0.08441834463734643,0.0036479999999999998,167.40101490244257,375.06032132375054,-1.3643820021478605
0.0847145493553722,0.0036607999999999996,167.44051241670206,375.06032132375054,-1.3643820021478605
0.08493670289389155,0.0036704,167.4701002163289,375.06032132375054,-1.3643820021478605
0.08515885643241088,0.0036799999999999997,167.49965785019918,375.06032132375054,-1.3643820021478605
0.08530695879142376,0.0036864,167.51934623470976,375.06032132375054,-1.3643820021478605
0.08601044499673498,0.0037167999999999997,167.61268462185274,375.06032132375054,-1.3643820021478605
0.08606598338136481,0.0037191999999999998,167.62004073722625,375.06032132375054,-1.3643820021478605
0.08660285443278654,0.0037424,167.69105466650433,375.06032132375054,-1.3643820021478605
0.08712121268933165,0.0037648,167.75945710716834,375.06032132375054,-1.3643820021478605
0.08725080225346793,0.0037703999999999997,167.7765328941304,375.06032132375054,-1.3643820021478605
0.08758403256124692,0.0037847999999999996,167.82039670426929,375.06032132375054,-1.3643820021478605
0.08767659653562998,0.0037887999999999997,167.83256953898652,375.06032132375054,-1.3643820021478605
0.0878802372792727,0.0037976,167.85933214694614,375.06032132375054,-1.3643820021478605
0.0885281850999541,0.0038255999999999997,167.94432543940502,375.06032132375054,-1.3643820021478605
0.08906505615137582,0.0038488,168.01456481790623,375.06032132375054,-1.3643820021478605
0.08936126086940159,0.0038615999999999998,168.05324688984115,375.06032132375054,-1.3643820021478605
0.0895463888181677,0.0038696,168.07739779318015,375.06032132375054,-1.3643820021478605
0.0903794645876152,0.0039056,168.18583678593504,375.06032132375054,-1.3643820021478605
0.09113848917755625,0.0039384,168.28429784812593,375.06032132375054,-1.3643820021478605
0.10234068542011336,0.00442248449689938,169.70216045380536,375.06032132375054,-1.3643820021478605
0.11300618836963124,0.004883376675335067,170.9967743232624,375.06032132375054,-1.3643820021478605
0.13389279831243706,0.0057859571914382875,173.40143379805178,375.06032132375054,-1.3643820021478605
0.14500269721818485,0.0062660532106421285,174.62052682494186,375.06032132375054,-1.3643820021478605
0.14766907295556433,0.00638127625525105,174.90761989135413,375.06032132375054,-1.3643820021478605
0.14900226082425405,0.006438887777555511,175.05040775353064,375.06032132375054,-1.3643820021478605
0.15611259612393266,0.006746149229845969,175.8036892671363,375.06032132375054,-1.3643820021478605
0.15922336781754204,0.006880576115223045,176.12902885633775,375.06032132375054,-1.3643820021478605
0.16722249502968042,0.0072262452490498095,176.95443260385798,375.06032132375054,-1.3643820021478605
0.16900007885460006,0.007303060612122424,177.13574743567494,375.06032132375054,-1.3643820021478605
0.17922118584788804,0.007744748949789958,178.164224976614,375.06032132375054,-1.3643820021478605
0.18499833327887688,0.007994398879775955,178.7354119482656,375.06032132375054,-1.3643820021478605
0.19477504431593493,0.008416883376675335,179.68643457971913,375.06032132375054,-1.3643820021478605
0.19966339983446396,0.008628125625125025,180.15494961419026,375.06032132375054,-1.3643820021478605
0.20366296344053317,0.008800960192038408,180.53496135270166,375.06032132375054,-1.3643820021478605
0.20632933917791263,0.00891618323664733,180.7866867922334,375.06032132375054,-1.3643820021478605
0.21521725830251087,0.009300260052010402,181.6167561539312,375.06032132375054,-1.3643820021478605
0.21699484212743053,0.009377075415083017,181.78115379354418,375.06032132375054,-1.3643820021478605
0.21921682190858008,0.009473094618923785,181.98591411731732,375.06032132375054,-1.3643820021478605
0.22055000977726982,0.009530706141228246,182.1083818207483,375.06032132375054,-1.3643820021478605
0.23343749250793724,0.010087617523504702,183.27771757487346,375.06032132375054,-1.3643820021478605
0.24943574693221407,0.010778955791158232,184.69484005625822,375.06032132375054,-1.3643820021478605
0.25876806201304214,0.011182236447289457,185.50511883146893,375.06032132375054,-1.3643820021478605
0.26276762561911143,0.011355071014202842,185.84888312650756,375.06032132375054,-1.3643820021478605
0.27209994069993954,0.011758351670334066,186.6431600054935,375.06032132375054,-1.3643820021478605
0.2809878598245378,0.012142428485697139,187.3897929698513,375.06032132375054,-1.3643820021478605
0.28987577894913596,0.012526505301060212,188.12727017519435,375.06032132375054,-1.3643820021478605
0.2960973223363548,0.012795359071814363,188.638265451991,375.06032132375054,-1.3643820021478605
0.29698611424881455,0.01283376675335067,188.71092147894052,375.06032132375054,-1.3643820021478605
0.31876151610408027,0.013774754950990198,190.46534654912335,375.06032132375054,-1.3643820021478605
0.32231668375391953,0.013928385677135427,190.74728390496423,375.06032132375054,-1.3643820021478605
0.32809383118490837,0.014178035607121425,191.20285905224418,375.06032132375054,-1.3643820021478605
0.33831493817819636,0.014619723944788958,192.00128550114474,375.06032132375054,-1.3643820021478605
0.34586966943410485,0.01494618923784757,192.5853930796112,375.06032132375054,-1.3643820021478605
0.3596459440772321,0.015541508301660333,193.63787778530815,375.06032132375054,-1.3643820021478605
0.3676450712893706,0.0158871774354871,194.24178159198775,375.06032132375054,-1.3643820021478605
0.36897825915806026,0.01594478895779156,194.34193191909233,375.06032132375054,-1.3643820021478605
0.3756441985015089,0.016232846569313862,194.84058216203815,375.06032132375054,-1.3643820021478605
0.3791993661513482,0.01638647729545909,195.10511729947513,375.06032132375054,-1.3643820021478605
0.3809769499762678,0.016463292658531706,195.237022019795,375.06032132375054,-1.3643820021478605
0.38408772166987726,0.016597719543908783,195.46727917412397,375.06032132375054,-1.3643820021478605
0.40275235183153346,0.017404280856171232,196.83385071579826,375.06032132375054,-1.3643820021478605
0.405418727568913,0.017519503900780158,197.0270395895237,375.06032132375054,-1.3643820021478605
0.4116402709561317,0.017788357671534305,197.47589679380133,375.06032132375054,-1.3643820021478605
0.4187506062558103,0.018095619123824763,197.98564931175443,375.06032132375054,-1.3643820021478605
0.4205281900807299,0.018172434486897378,198.11255861257112,375.06032132375054,-1.3643820021478605
0.42674973346794876,0.018441288257651532,198.55510293778704,375.06032132375054,-1.3643820021478605
0.435637652592547,0.018825365073014605,199.1829689168314,375.06032132375054,-1.3643820021478605
0.44541436362960496,0.01924784956991398,199.86787911132882,375.06032132375054,-1.3643820021478605
0.4494139272356742,0.019420684136827366,200.14637675816095,375.06032132375054,-1.3643820021478605
0.45252469892928354,0.01955511102220444,200.36231830310263,375.06032132375054,-1.3643820021478605
0.45607986657912286,0.01970874174834967,200.60840100869183,375.06032132375054,-1.3643820021478605
0.4574130544478126,0.01976635327065413,200.70048900801922,375.06032132375054,-1.3643820021478605
0.4818548320404577,0.02082256451290258,202.37064906721807,375.06032132375054,-1.3643820021478605
0.48496560373406716,0.020956991398279657,202.58081886089496,375.06032132375054,-1.3643820021478605
0.49074275116505595,0.021206641328265653,202.96974455970766,375.06032132375054,-1.3643820021478605
0.5000750662458842,0.02160992198439688,203.59425817765302,375.06032132375054,-1.3643820021478605
0.5080741934580225,0.021955591118223646,204.1259463650698,375.06032132375054,-1.3643820021478605
0.5102961732391721,0.022051610322064413,204.27305686432604,375.06032132375054,-1.3643820021478605
0.5147401328014711,0.02224364872974595,204.56653054090486,375.06032132375054,-1.3643820021478605
0.5214060721449199,0.022531706341268255,205.00489506392574,375.06032132375054,-1.3643820021478605
0.5236280519260694,0.02262772554510902,205.15053015097615,375.06032132375054,-1.3643820021478605
0.5276276155321387,0.022800560112022406,205.41206739494373,375.06032132375054,-1.3643820021478605
0.5440702659126454,0.02351110222044409,206.47925177085318,375.06032132375054,-1.3643820021478605
0.5569577486433127,0.024068013602720543,207.30692466422147,375.06032132375054,-1.3643820021478605
0.5578465405557725,0.02410642128425685,207.36372871102392,375.06032132375054,-1.3643820021478605
0.57028962733021,0.024644128825765152,208.15531549227725,375.06032132375054,-1.3643820021478605
0.5725116071113597,0.024740148029605922,208.2959585505102,375.06032132375054,-1.3643820021478605
0.5773999626298887,0.02495139027805561,208.60462610655486,375.06032132375054,-1.3643820021478605
0.5885098615356366,0.025431486297259453,209.3023778955307,375.06032132375054,-1.3643820021478605
0.5969533847040048,0.02579635927185437,209.82923878056116,375.06032132375054,-1.3643820021478605
0.6085076795659825,0.026295659131826365,210.5455206063296,375.06032132375054,-1.3643820021478605
0.611174055303362,0.026410882176435287,210.71006080490795,375.06032132375054,-1.3643820021478605
0.6151736189094312,0.02658371674334867,210.95634715365713,375.06032132375054,-1.3643820021478605
0.6178399946468107,0.026698939787957593,211.1201912079639,375.06032132375054,-1.3643820021478605
0.6240615380340294,0.026967793558711744,211.50142531600537,375.06032132375054,-1.3643820021478605
0.6267279137714089,0.027083016603320666,211.6643572861017,375.06032132375054,-1.3643820021478605
0.6356158328960071,0.02746709341868374,212.20552189401513,375.06032132375054,-1.3643820021478605
0.6391710005458464,0.027620724144828968,212.42116042383324,375.06032132375054,-1.3643820021478605
0.6445037520206054,0.02785117023404681,212.74374321509006,375.06032132375054,-1.3643820021478605
0.6485033156266745,0.028024004800960192,212.98499762268077,375.06032132375054,-1.3643820021478605
0.6640571740947214,0.028696139227845568,213.91774436109046,375.06032132375054,-1.3643820021478605
0.6707231134381701,0.028984196839367874,214.3148802574572,375.06032132375054,-1.3643820021478605
0.6725006972630898,0.02906101220244049,214.42052281659596,375.06032132375054,-1.3643820021478605
0.6849437840375273,0.02959871974394879,215.15699515712296,375.06032132375054,-1.3643820021478605
0.6902765355122862,0.029829165833166634,215.47102676923078,375.06032132375054,-1.3643820021478605
0.7071635818490228,0.030558911782356472,216.45927512022303,375.06032132375054,-1.3643820021478605
0.7347161311352773,0.031749549909981994,218.0521454358914,375.06032132375054,-1.3643820021478605
0.7431596543036457,0.032114422884576915,218.535596822076,375.06032132375054,-1.3643820021478605
0.7476036138659448,0.03230646129225845,218.7891842298332,375.06032132375054,-1.3643820021478605
0.7613798885090721,0.03290178035607122,219.5715948462202,375.06032132375054,-1.3643820021478605
0.77160099550236,0.03334346869373875,220.14852996274647,375.06032132375054,-1.3643820021478605
0.7742673712397395,0.03345869173834767,220.29854362384307,375.06032132375054,-1.3643820021478605
0.7804889146269582,0.03372754550910182,220.6477941593931,375.06032132375054,-1.3643820021478605
0.7942651892700855,0.034322864572914585,221.41729384531314,375.06032132375054,-1.3643820021478605
0.7987091488323845,0.03451490298059612,221.66440685113363,375.06032132375054,-1.3643820021478605
0.8147074032566614,0.03520624124824965,222.54960794686335,375.06032132375054,-1.3643820021478605
0.8231509264250296,0.03557111422284456,223.014062896731,375.06032132375054,-1.3643820021478605
0.8360384091556973,0.03612802560512103,223.71940152317276,375.06032132375054,-1.3643820021478605
0.8404823687179963,0.036320064012802564,223.96163686758806,375.06032132375054,-1.3643820021478605
0.8449263282802953,0.0365121024204841,224.2033732145535,375.06032132375054,-1.3643820021478605
0.852481059536204,0.036838567713542714,224.61319009807593,375.06032132375054,-1.3643820021478605
0.8689237099167108,0.037549109821964397,225.50028004088756,375.06032132375054,-1.3643820021478605
0.87247887756655,0.037702740548109626,225.69121972084142,375.06032132375054,-1.3643820021478605
0.8853663602972174,0.03825965193038608,226.38084691811943,375.06032132375054,-1.3643820021478605
0.8893659239032864,0.03843248649729945,226.59407167084007,375.06032132375054,-1.3643820021478605
0.8938098834655858,0.038624524904981,226.83054994219398,375.06032132375054,-1.3643820021478605
0.8986982389841148,0.03883576715343069,227.09014705466817,375.06032132375054,-1.3643820021478605
0.9351387073949675,0.04041048209641929,229.0082653616826,375.06032132375054,-1.3643820021478605
0.9533589416003937,0.04119783956791358,229.9563755564758,375.06032132375054,-1.3643820021478605
0.9618024647687621,0.0415627125425085,230.39334491784743,375.06032132375054,-1.3643820021478605
0.9662464243310613,0.041754750950190045,230.62272774130298,375.06032132375054,-1.3643820021478605
0.97335675963074,0.0420620124024805,230.98888631319622,375.06032132375054,-1.3643820021478605
0.9826890747115681,0.04246529305861173,231.46789025733906,375.06032132375054,-1.3643820021478605
0.9951321614860055,0.04300300060012002,232.10381154386835,375.06032132375054,-1.3643820021478605
1.0120192078227421,0.043732746549309864,232.9619094596614,375.06032132375054,-1.3643820021478605
1.0195739390786505,0.04405921184236847,233.34398554702784,375.06032132375054,-1.3643820021478605
1.0337946096780075,0.044673734746949384,234.0602056211416,375.06032132375054,-1.3643820021478605
1.0395717571089969,0.04492338467693539,234.35007124887716,375.06032132375054,-1.3643820021478605
1.053348031752124,0.04551870374074815,235.03876573849308,375.06032132375054,-1.3643820021478605
1.0600139710955725,0.04580676135227045,235.37074316391718,375.06032132375054,-1.3643820021478605
1.0653467225703315,0.0460372074414883,235.63573926477198,375.06032132375054,-1.3643820021478605
1.0680130983077112,0.046152430486097226,235.7680432817374,375.06032132375054,-1.3643820021478605
1.0729014538262398,0.046363672734546904,236.01026655658347,375.06032132375054,-1.3643820021478605
1.0800117891259184,0.04667093418683736,236.36182439566295,375.06032132375054,-1.3643820021478605
1.087566520381827,0.04699739947989598,236.73436700274715,375.06032132375054,-1.3643820021478605
1.0906772920754364,0.04713182636527305,236.8874733908857,375.06032132375054,-1.3643820021478605
1.1062311505434832,0.04780396079215843,237.65046554079422,375.06032132375054,-1.3643820021478605
1.1262289685738291,0.04866813362672534,238.6253356124475,375.06032132375054,-1.3643820021478605
1.1360056796108873,0.049090618123624724,239.0994798233314,375.06032132375054,-1.3643820021478605
1.1422272229981063,0.04935947189437888,239.40037954337566,375.06032132375054,-1.3643820021478605
1.1502263502102446,0.04970514102820564,239.7863130546631,375.06032132375054,-1.3643820021478605
1.1600030612473027,0.050127625525105024,240.25659100130463,375.06032132375054,-1.3643820021478605
1.168002188459441,0.050473294658931786,240.6402151589764,375.06032132375054,-1.3643820021478605
1.1800008792776486,0.050991798359671936,241.21373577452582,375.06032132375054,-1.3643820021478605
1.1808896711901085,0.05103020604120824,241.25612809017792,375.06032132375054,-1.3643820021478605
1.1875556105335572,0.05131826365273055,241.57367477511167,375.06032132375054,-1.3643820021478605
1.1915551741396262,0.05149109821964393,241.76386913007562,375.06032132375054,-1.3643820021478605
1.2044426568702937,0.05204800960192038,242.37503085949348,375.06032132375054,-1.3643820021478605
1.207997824520133,0.05220164032806561,242.54317770235062,375.06032132375054,-1.3643820021478605
1.2226628910757202,0.052835367073414685,243.23475319841415,375.06032132375054,-1.3643820021478605
1.2426607091060662,0.0536995399079816,244.17261961288378,375.06032132375054,-1.3643820021478605
1.2457714807996754,0.05383396679335867,244.31797922561077,375.06032132375054,-1.3643820021478605
1.2613253392677224,0.054506101220244046,245.04266468151218,375.06032132375054,-1.3643820021478605
1.2662136947862515,0.05471734346869374,245.26970207079745,375.06032132375054,-1.3643820021478605
1.2862115128165974,0.05558151630326065,246.19495392642693,375.06032132375054,-1.3643820021478605
1.3057649348907137,0.05642648529705942,247.09423514181495,375.06032132375054,-1.3643820021478605
1.3266515448335194,0.05732906581316263,248.0490490927419,375.06032132375054,-1.3643820021478605
1.3368726518268073,0.05777075415083016,248.5141605564333,375.06032132375054,-1.3643820021478605
1.3524265102948543,0.05844288857771554,249.21928671045058,375.06032132375054,-1.3643820021478605
1.3702023485440507,0.059211042208441686,250.02128398615864,375.06032132375054,-1.3643820021478605
1.3746463081063498,0.05940308061612322,250.2211480195361,375.06032132375054,-1.3643820021478605
1.3773126838437293,0.059518303660732144,250.34094548935946,375.06032132375054,-1.3643820021478605
1.3902001665743966,0.0600752150430086,250.91869636033408,375.06032132375054,-1.3643820021478605
1.3990880856989951,0.06045929185837168,251.31592878486168,375.06032132375054,-1.3643820021478605
1.4075316088673635,0.0608241648329666,251.69238900032832,375.06032132375054,-1.3643820021478605
1.409309192692283,0.060900980196039206,251.7715314394671,375.06032132375054,-1.3643820021478605
1.419530299685571,0.06134266853370675,252.225847229071,375.06032132375054,-1.3643820021478605
1.4288626147663992,0.06174594918983797,252.63954433072982,375.06032132375054,-1.3643820021478605
1.4359729500660778,0.06205321064212843,252.95403521643485,375.06032132375054,-1.3643820021478605
1.4444164732344462,0.06241808361672335,253.32670543600048,375.06032132375054,-1.3643820021478605
1.47285781443316,0.06364712942588517,254.5758114308725,375.06032132375054,-1.3643820021478605
1.479523753776609,0.06393518703740748,254.86720563668857,375.06032132375054,-1.3643820021478605
1.5004103637194148,0.0648377675535107,255.77694274359922,375.06032132375054,-1.3643820021478605
1.5035211354130242,0.06497219443888778,255.91201174668362,375.06032132375054,-1.3643820021478605
1.5172974100561514,0.06556751350270054,256.5088692017662,375.06032132375054,-1.3643820021478605
1.5252965372682898,0.0659131826365273,256.8544617261501,375.06032132375054,-1.3643820021478605
1.5359620402178076,0.06637407481496299,257.31415424312104,375.06032132375054,-1.3643820021478605
1.5524046905983147,0.06708461692338469,258.02041536649205,375.06032132375054,-1.3643820021478605
1.555071066335694,0.0671998399679936,258.13466872605966,375.06032132375054,-1.3643820021478605
1.5608482137666828,0.0674494898979796,258.38195590027647,375.06032132375054,-1.3643820021478605
1.5750688843660399,0.06806401280256051,258.9891468976701,375.06032132375054,-1.3643820021478605
1.5759576762785,0.06810242048409683,259.02702519213403,375.06032132375054,-1.3643820021478605
1.6030658296085245,0.0692738547709542,260.17834201893857,375.06032132375054,-1.3643820021478605
1.620397271901491,0.07002280456091219,260.9104524743558,375.06032132375054,-1.3643820021478605
1.6226192516826405,0.07011882376475295,261.0040914322603,375.06032132375054,-1.3643820021478605
1.6461722373628258,0.0711366273254651,261.993609238448,375.06032132375054,-1.3643820021478605
1.6483942171439752,0.07123264652930586,262.08667403196785,375.06032132375054,-1.3643820021478605
1.6510605928813549,0.07134786957391479,262.1982872284634,375.06032132375054,-1.3643820021478605
1.6666144513494017,0.07202000400080016,262.84796862181594,375.06032132375054,-1.3643820021478605
1.6835014976861384,0.07274974994999,263.5506654265036,375.06032132375054,-1.3643820021478605
1.691500624898277,0.07309541908381677,263.8825618465411,375.06032132375054,-1.3643820021478605
1.7048325035851741,0.07367153430686138,264.4343655001081,375.06032132375054,-1.3643820021478605
1.7190531741845314,0.0742860572114423,265.0211043803597,375.06032132375054,-1.3643820021478605
1.7266079054404397,0.0746125225045009,265.3320393260191,375.06032132375054,-1.3643820021478605
1.7297186771340494,0.07474694938987798,265.4599170897652,375.06032132375054,-1.3643820021478605
1.7337182407401184,0.07491978395679136,265.62419964298374,375.06032132375054,-1.3643820021478605
1.7483833072957056,0.07555351070214043,266.22530859998955,375.06032132375054,-1.3643820021478605
1.7523828709017748,0.07572634526905382,266.38890572675996,375.06032132375054,-1.3643820021478605
1.764381561719982,0.07624484896979396,266.87882560873015,375.06032132375054,-1.3643820021478605
1.7746026687132703,0.0766865373074615,267.29514076373914,375.06032132375054,-1.3643820021478605
1.785712567619018,0.07716663332666533,267.7465979975331,375.06032132375054,-1.3643820021478605
1.7879345474001678,0.07726265253050611,267.83675784994585,375.06032132375054,-1.3643820021478605
1.791489715050007,0.07741628325665134,267.9809227743303,375.06032132375054,-1.3643820021478605
1.8128207209490426,0.0783380676135227,268.84358082553695,375.06032132375054,-1.3643820021478605
1.8279301834608597,0.07899099819963994,269.45223672827507,375.06032132375054,-1.3643820021478605
1.8425952500164466,0.079624724944989,270.0411173667617,375.06032132375054,-1.3643820021478605
1.847039209578746,0.07981676335267054,270.2192048004911,375.06032132375054,-1.3643820021478605
1.851038773184815,0.07998959791958392,270.3793406662237,375.06032132375054,-1.3643820021478605
1.8528163570097347,0.08006641328265654,270.4504688412105,375.06032132375054,-1.3643820021478605
1.871036591215161,0.08085377075415083,271.1780047512583,375.06032132375054,-1.3643820021478605
1.8772581346023798,0.08112262452490498,271.425798137398,375.06032132375054,-1.3643820021478605
1.8905900132892772,0.0816987397479496,271.95570805215,375.06032132375054,-1.3643820021478605
1.8981447445451856,0.0820252050410082,272.2553434103596,375.06032132375054,-1.3643820021478605
1.9123654151445426,0.08263972794558912,272.8181041976845,375.06032132375054,-1.3643820021478605
1.9145873949256922,0.08273574714942988,272.9058879271749,375.06032132375054,-1.3643820021478605
1.9283636695688198,0.08333106621324265,273.4492628943762,375.06032132375054,-1.3643820021478605
1.938140380605878,0.08375355071014204,273.833965785983,375.06032132375054,-1.3643820021478605
1.9448063199493264,0.08404160832166434,274.0958293891572,375.06032132375054,-1.3643820021478605
1.956360614811304,0.08454090818163633,274.54889859566373,375.06032132375054,-1.3643820021478605
1.9616933662860632,0.08477135427085418,274.7576553706039,375.06032132375054,-1.3643820021478605
1.9679149096732815,0.08504020804160832,275.00092542082007,375.06032132375054,-1.3643820021478605
1.9745808490167305,0.08532826565313063,275.26123929261286,375.06032132375054,-1.3643820021478605
2.0256863839831705,0.0875367073414683,277.24571713967174,375.06032132375054,-1.3643820021478605
2.0381294707576076,0.0880744148829766,277.72592675673286,375.06032132375054,-1.3643820021478605
2.041684638407447,0.08822804560912183,277.86291932017593,375.06032132375054,-1.3643820021478605
2.0532389332694247,0.08872734546909382,278.3075040278677,375.06032132375054,-1.3643820021478605
2.061238060481563,0.0890730146029206,278.61472203422215,375.06032132375054,-1.3643820021478605
2.07768071086207,0.08978355671134228,279.24476936087314,375.06032132375054,-1.3643820021478605
2.07901389873076,0.08984116823364674,279.29576889568017,375.06032132375054,-1.3643820021478605
2.0892350057240474,0.09028285657131427,279.6863424847657,375.06032132375054,-1.3643820021478605
2.0945677571988064,0.0905133026605321,279.88982414054146,375.06032132375054,-1.3643820021478605
2.097678528892416,0.09064772954590919,280.0084284682442,375.06032132375054,-1.3643820021478605
2.0994561127173355,0.0907245449089818,280.0761715717285,375.06032132375054,-1.3643820021478605
2.1083440318419338,0.09110862172434488,280.4145521296512,375.06032132375054,-1.3643820021478605
2.1145655752291526,0.09137747549509903,280.65108758410946,375.06032132375054,-1.3643820021478605
2.1212315145726013,0.09166553310662133,280.90421743932006,375.06032132375054,-1.3643820021478605
2.1358965811281885,0.0922992598519704,281.46001368325443,375.06032132375054,-1.3643820021478605
2.1452288962090167,0.09270254050810163,281.81292745003407,375.06032132375054,-1.3643820021478605
2.146562084077706,0.09276015203040608,281.86329478140647,375.06032132375054,-1.3643820021478605
2.1532280234211547,0.09304820964192839,282.1149486699657,375.06032132375054,-1.3643820021478605
2.157227587027224,0.09322104420884177,282.2657951658954,375.06032132375054,-1.3643820021478605
2.173225841451501,0.0939123824764953,282.8680936125905,375.06032132375054,-1.3643820021478605
2.1910016797006975,0.09468053610722145,283.53528969061705,375.06032132375054,-1.3643820021478605
2.1950012433067667,0.09485337067413484,283.6851174850957,375.06032132375054,-1.3643820021478605
2.2003339947815252,0.09508381676335267,283.8847223600941,375.06032132375054,-1.3643820021478605
2.2034447664751347,0.09521824364872974,284.00107140954685,375.06032132375054,-1.3643820021478605
2.211888289643503,0.09558311662332467,284.31655350276884,375.06032132375054,-1.3643820021478605
2.22833094002401,0.09629365873174635,284.92956873075065,375.06032132375054,-1.3643820021478605
2.231886107673849,0.09644728945789158,285.0618803232383,375.06032132375054,-1.3643820021478605
2.2465511742294364,0.09708101620324065,285.60679906989157,375.06032132375054,-1.3643820021478605
2.255883489310264,0.09748429685937188,285.95284336339137,375.06032132375054,-1.3643820021478605
2.262105032697483,0.09775315063012603,286.1832294427248,375.06032132375054,-1.3643820021478605
2.2656602003473223,0.09790678135627126,286.3147676783203,375.06032132375054,-1.3643820021478605
2.2687709720409317,0.09804120824164833,286.42979761560576,375.06032132375054,-1.3643820021478605
2.27810328712176,0.09844448889777956,286.77451892747996,375.06032132375054,-1.3643820021478605
2.2856580183776685,0.09877095419083817,287.05317583395527,375.06032132375054,-1.3643820021478605
2.2981011051521056,0.09930866173234647,287.51135838450506,375.06032132375054,-1.3643820021478605
2.3109885878827736,0.09986557311462294,287.98488578514326,375.06032132375054,-1.3643820021478605