File: datasets/aisi_316_L/data/M1/train_88.csv
Time(s),Strain(%),Stress(MPa),Temp(C),Log_SR(s-1)
0.0,0.0,0.0,224.12801437578148,2.3075319825475846
1.4580074009966836e-07,2.9599999999999998e-05,5.445516625,224.12801437578148,2.3075319825475846
2.1673082987788543e-07,4.4e-05,8.094686874999999,224.12801437578148,2.3075319825475846
3.7041269106402236e-07,7.52e-05,13.83455575,224.12801437578148,2.3075319825475846
4.5316446247194225e-07,9.2e-05,16.925254375,224.12801437578148,2.3075319825475846
4.846889468178165e-07,9.839999999999999e-05,18.102663375,224.12801437578148,2.3075319825475846
7.526470637577476e-07,0.0001528,28.110639875,224.12801437578148,2.3075319825475846
8.038743508197932e-07,0.00016319999999999998,30.023929499999998,224.12801437578148,2.3075319825475846
1.0009023779815071e-06,0.00020319999999999998,37.382735749999995,224.12801437578148,2.3075319825475846
1.0324268623273815e-06,0.0002096,38.56014475,224.12801437578148,2.3075319825475846
1.0954758310191298e-06,0.00022239999999999998,40.914962749999994,224.12801437578148,2.3075319825475846
1.138821996994707e-06,0.00023119999999999998,42.533900124999995,224.12801437578148,2.3075319825475846
1.1782276024270498e-06,0.0002392,44.005661374999995,224.12801437578148,2.3075319825475846
1.292503858180844e-06,0.0002624,48.273768999999994,224.12801437578148,2.3075319825475846
1.4501262799102153e-06,0.0002944,54.160814,224.12801437578148,2.3075319825475846
1.489531885342558e-06,0.0003024,55.632575249999995,224.12801437578148,2.3075319825475846
1.6589759887016322e-06,0.0003368,61.961148625,224.12801437578148,2.3075319825475846
1.769311683912192e-06,0.0003592,66.082080125,224.12801437578148,2.3075319825475846
1.7890144866283633e-06,0.0003632,66.81796075,224.12801437578148,2.3075319825475846
1.8205389709742375e-06,0.0003696,67.99536975,224.12801437578148,2.3075319825475846
1.9545180294442033e-06,0.0003968,72.999358,224.12801437578148,2.3075319825475846
2.009685877049483e-06,0.000408,75.05982374999999,224.12801437578148,2.3075319825475846
2.064853724654763e-06,0.0004192,77.1202895,224.12801437578148,2.3075319825475846
2.120021572260043e-06,0.0004304,79.18075525,224.12801437578148,2.3075319825475846
2.1397243749762145e-06,0.0004344,79.916635875,224.12801437578148,2.3075319825475846
2.183070540951791e-06,0.0004432,81.53557325,224.12801437578148,2.3075319825475846
2.2500600701867742e-06,0.0004568,84.037567375,224.12801437578148,2.3075319825475846
2.3091684783352883e-06,0.00046879999999999996,86.24520924999999,224.12801437578148,2.3075319825475846
2.3919202497432083e-06,0.0004856,89.335907875,224.12801437578148,2.3075319825475846
2.4116230524593795e-06,0.0004896,90.0717885,224.12801437578148,2.3075319825475846
2.4470880973484877e-06,0.0004967999999999999,91.39637362499998,224.12801437578148,2.3075319825475846
2.4628503395214256e-06,0.0005,91.985078125,224.12801437578148,2.3075319825475846
2.4825531422375968e-06,0.000504,92.72095875,224.12801437578148,2.3075319825475846
2.6165322007075624e-06,0.0005312,97.724947,224.12801437578148,2.3075319825475846
2.766273501350465e-06,0.0005616,103.31763975,224.12801437578148,2.3075319825475846
2.8175007884125106e-06,0.000572,105.230929375,224.12801437578148,2.3075319825475846
2.9081336809068986e-06,0.0005903999999999999,108.61598024999999,224.12801437578148,2.3075319825475846
2.9357176047095388e-06,0.000596,109.64621312499999,224.12801437578148,2.3075319825475846
2.971182649598648e-06,0.0006032,110.97079825,224.12801437578148,2.3075319825475846
3.0105882550309903e-06,0.0006112,112.4425595,224.12801437578148,2.3075319825475846
3.1524484345874244e-06,0.0006399999999999999,117.7409,224.12801437578148,2.3075319825475846
3.20367572164947e-06,0.0006504,119.654189625,224.12801437578148,2.3075319825475846
3.235200205995344e-06,0.0006567999999999999,120.83159862499998,224.12801437578148,2.3075319825475846
3.3612981433788415e-06,0.0006824,125.541234625,224.12801437578148,2.3075319825475846
3.3731198250085438e-06,0.0006848,125.98276299999999,224.12801437578148,2.3075319825475846
3.444049914786761e-06,0.0006992,128.63193325,224.12801437578148,2.3075319825475846
3.4913366413055724e-06,0.0007088,130.39804675,224.12801437578148,2.3075319825475846
3.554385609997321e-06,0.0007216,132.75286475,224.12801437578148,2.3075319825475846
3.6528996235781777e-06,0.0007415999999999999,136.43226787499998,224.12801437578148,2.3075319825475846
3.739591955529332e-06,0.0007591999999999999,139.67014262499998,224.12801437578148,2.3075319825475846
3.869630453456063e-06,0.0007856,144.52695475000002,224.12801437578148,2.3075319825475846
4.157291373112166e-06,0.0008439999999999999,155.270811875,224.12801437578148,2.3075319825475846
4.208518660174212e-06,0.0008544,157.1841015,224.12801437578148,2.3075319825475846
4.287329871038897e-06,0.0008703999999999999,160.12762399999997,224.12801437578148,2.3075319825475846
4.460714534941206e-06,0.0009056,166.6033735,224.12801437578148,2.3075319825475846
4.65774256210292e-06,0.0009456,173.96217975,224.12801437578148,2.3075319825475846
4.764137696770245e-06,0.0009672,177.935935125,224.12801437578148,2.3075319825475846
4.795662181116119e-06,0.0009735999999999999,179.113344125,224.12801437578148,2.3075319825475846
4.8153649838322906e-06,0.0009776,179.84922475,224.12801437578148,2.3075319825475846
4.8981167552402106e-06,0.0009943999999999999,182.93992337499998,224.12801437578148,2.3075319825475846
4.949344042302256e-06,0.0010048,184.85321299999998,224.12801437578148,2.3075319825475846
5.134550387834268e-06,0.0010424,191.770490875,224.12801437578148,2.3075319825475846
5.17395599326661e-06,0.0010504,193.242252125,224.12801437578148,2.3075319825475846
5.2606483252177645e-06,0.001068,196.480126875,224.12801437578148,2.3075319825475846
5.3079350517365754e-06,0.0010776,198.24624037499999,224.12801437578148,2.3075319825475846
5.398567944230964e-06,0.001096,201.63129125,224.12801437578148,2.3075319825475846
5.47737915509565e-06,0.001112,204.57481374999998,224.12801437578148,2.3075319825475846
5.497081957811822e-06,0.001116,205.310694375,224.12801437578148,2.3075319825475846
5.540428123787398e-06,0.0011248,206.92963175,224.12801437578148,2.3075319825475846
5.599536531935912e-06,0.0011367999999999999,209.13727362499998,224.12801437578148,2.3075319825475846
5.705931666603238e-06,0.0011584,213.111029,224.12801437578148,2.3075319825475846
5.765040074751753e-06,0.0011704,214.0658754176925,224.12801437578148,2.3075319825475846
5.800505119640861e-06,0.0011776,214.11269825038985,224.12801437578148,2.3075319825475846
5.97388978354317e-06,0.0012128,214.34002195311402,224.12801437578148,2.3075319825475846
6.04876043386462e-06,0.001228,214.43738734780257,224.12801437578148,2.3075319825475846
6.068463236580792e-06,0.001232,214.4629315579382,224.12801437578148,2.3075319825475846
6.099987720926666e-06,0.0012384,214.503735119611,224.12801437578148,2.3075319825475846
6.2339667793966315e-06,0.0012656,214.6762407293643,224.12801437578148,2.3075319825475846
6.3679458378665975e-06,0.0012928,214.84730634324558,224.12801437578148,2.3075319825475846
6.529508820139202e-06,0.0013256,215.05173559508762,224.12801437578148,2.3075319825475846
6.691071802411807e-06,0.0013583999999999998,215.25420136038798,224.12801437578148,2.3075319825475846
6.872337587400585e-06,0.0013951999999999999,215.47910193734052,224.12801437578148,2.3075319825475846
6.907802632289694e-06,0.0014024,215.5228323363207,224.12801437578148,2.3075319825475846
7.0417816907596585e-06,0.0014295999999999998,215.68725180163656,224.12801437578148,2.3075319825475846
7.049662811846128e-06,0.0014311999999999999,215.69688536472756,224.12801437578148,2.3075319825475846
7.081187296192003e-06,0.0014376,215.73537768919732,224.12801437578148,2.3075319825475846
7.136355143797281e-06,0.0014487999999999999,215.80257883023347,224.12801437578148,2.3075319825475846
7.148176825426985e-06,0.0014512,215.81695268075956,224.12801437578148,2.3075319825475846
7.266393641724013e-06,0.0014751999999999999,215.96018493184,224.12801437578148,2.3075319825475846
7.2939775655266535e-06,0.0014808,215.9934746804178,224.12801437578148,2.3075319825475846
7.329442610415762e-06,0.001488,216.036203730201,224.12801437578148,2.3075319825475846
7.400372700193978e-06,0.0015023999999999999,216.12142069389574,224.12801437578148,2.3075319825475846
7.412194381823682e-06,0.0015048,216.13559249470967,224.12801437578148,2.3075319825475846
7.4240160634533845e-06,0.0015072,216.14975548326433,224.12801437578148,2.3075319825475846
7.491005592688367e-06,0.0015207999999999999,216.22984690170546,224.12801437578148,2.3075319825475846
7.688033619850081e-06,0.0015608,216.46380653624905,224.12801437578148,2.3075319825475846
7.735320346368892e-06,0.0015704,216.51960746938653,224.12801437578148,2.3075319825475846
7.743201467455361e-06,0.0015719999999999998,216.52889467575403,224.12801437578148,2.3075319825475846
7.940229494617075e-06,0.001612,216.7598903070285,224.12801437578148,2.3075319825475846
7.995397342222356e-06,0.0016232,216.82416708900195,224.12801437578148,2.3075319825475846
8.10179247688968e-06,0.0016447999999999999,216.94764308601867,224.12801437578148,2.3075319825475846
8.164841445581428e-06,0.0016576,217.02051565173556,224.12801437578148,2.3075319825475846
8.223949853729942e-06,0.0016695999999999998,217.08863461937432,224.12801437578148,2.3075319825475846
8.369750593829611e-06,0.0016991999999999999,217.25585009800412,224.12801437578148,2.3075319825475846
8.41309675980519e-06,0.0017079999999999999,217.30534322963436,224.12801437578148,2.3075319825475846
8.43279956252136e-06,0.001712,217.32780722177705,224.12801437578148,2.3075319825475846
8.484026849583406e-06,0.0017224,217.38611801275175,224.12801437578148,2.3075319825475846
8.558897499904858e-06,0.0017376,217.4710950805998,224.12801437578148,2.3075319825475846
8.5983031053372e-06,0.0017456,217.51570338219236,224.12801437578148,2.3075319825475846
8.673173755658651e-06,0.0017607999999999999,217.60024010966796,224.12801437578148,2.3075319825475846
8.700757679461291e-06,0.0017664,217.63131341606098,224.12801437578148,2.3075319825475846
8.74410384543687e-06,0.0017752,217.6800653873162,224.12801437578148,2.3075319825475846
8.783509450869212e-06,0.0017832,217.724303633554,224.12801437578148,2.3075319825475846
8.913547948795942e-06,0.0018096,217.86974375684645,224.12801437578148,2.3075319825475846
9.051467567809142e-06,0.0018376,218.0230970770022,224.12801437578148,2.3075319825475846
9.11451653650089e-06,0.0018503999999999999,218.0928976618282,224.12801437578148,2.3075319825475846
9.185446626279108e-06,0.0018648,218.17119862408822,224.12801437578148,2.3075319825475846
9.20514942899528e-06,0.0018687999999999999,218.19290699703032,224.12801437578148,2.3075319825475846
9.299722882032901e-06,0.001888,218.2968559882794,224.12801437578148,2.3075319825475846
9.350950169094948e-06,0.0018984,218.35298952145087,224.12801437578148,2.3075319825475846
9.39035577452729e-06,0.0019064,218.39608759128424,224.12801437578148,2.3075319825475846
9.477048106478444e-06,0.001924,218.49065584313803,224.12801437578148,2.3075319825475846
9.563740438429599e-06,0.0019416,218.5848873118562,224.12801437578148,2.3075319825475846
9.630729967664581e-06,0.0019552,218.6574745539136,224.12801437578148,2.3075319825475846
9.733184541788673e-06,0.001976,218.76811061465645,224.12801437578148,2.3075319825475846
9.87898528188834e-06,0.0020055999999999997,218.9247743509207,224.12801437578148,2.3075319825475846
9.910509766234216e-06,0.002012,218.95852873107475,224.12801437578148,2.3075319825475846
1.0076013309050054e-05,0.0020456,219.13505691062028,224.12801437578148,2.3075319825475846
1.0261219654582065e-05,0.0020832,219.33126498435917,224.12801437578148,2.3075319825475846
1.0324268623273813e-05,0.0020959999999999998,219.39774346453348,224.12801437578148,2.3075319825475846
1.0501593847719356e-05,0.0021319999999999998,219.58387063657003,224.12801437578148,2.3075319825475846
1.065133514836226e-05,0.0021624,219.74009208213536,224.12801437578148,2.3075319825475846
1.0714384117054009e-05,0.0021752,219.80561301636047,224.12801437578148,2.3075319825475846
1.0805017009548398e-05,0.0021936,219.89953653414824,224.12801437578148,2.3075319825475846
1.1108440171377437e-05,0.0022551999999999997,220.21176362784365,224.12801437578148,2.3075319825475846
1.119513250332859e-05,0.0022727999999999997,220.30035814232582,224.12801437578148,2.3075319825475846
1.122271642713123e-05,0.0022784,220.32849114271534,224.12801437578148,2.3075319825475846
1.1415803893749711e-05,0.0023176,220.52467252429014,224.12801437578148,2.3075319825475846
1.1530080149503506e-05,0.0023408,220.64017031846294,224.12801437578148,2.3075319825475846
1.1604950799824957e-05,0.002356,220.71559930412312,224.12801437578148,2.3075319825475846
1.1841384432419013e-05,0.002404,220.95255960408423,224.12801437578148,2.3075319825475846
1.1916255082740464e-05,0.0024192,221.02721140632605,224.12801437578148,2.3075319825475846
1.1991125733061914e-05,0.0024343999999999998,221.1016805045322,224.12801437578148,2.3075319825475846
1.2113283109902177e-05,0.0024592,221.22279459195568,224.12801437578148,2.3075319825475846
1.2160569836420988e-05,0.0024687999999999997,221.26954946522645,224.12801437578148,2.3075319825475846
1.2266964971088315e-05,0.0024904,221.37448945978392,224.12801437578148,2.3075319825475846
1.2274846092174783e-05,0.002492,221.38224864307608,224.12801437578148,2.3075319825475846
1.2310311137063893e-05,0.0024992,221.4171409523821,224.12801437578148,2.3075319825475846
1.2353657303039468e-05,0.002508,221.4597339143216,224.12801437578148,2.3075319825475846
1.2432468513904155e-05,0.0025239999999999998,221.53702663731858,224.12801437578148,2.3075319825475846
1.2444290195533857e-05,0.0025264,221.5486040435633,224.12801437578148,2.3075319825475846
1.254674476965795e-05,0.0025472,221.6487625274021,224.12801437578148,2.3075319825475846
1.2645258783238806e-05,0.0025672,221.7447683871078,224.12801437578148,2.3075319825475846
1.2716188873017022e-05,0.0025816,221.81371207729805,224.12801437578148,2.3075319825475846
1.290533577909227e-05,0.00262,221.99683260299685,224.12801437578148,2.3075319825475846
1.2956563066154313e-05,0.0026303999999999998,222.04624723159813,224.12801437578148,2.3075319825475846
1.3035374277019e-05,0.0026463999999999997,222.1221212125267,224.12801437578148,2.3075319825475846
1.322058062255101e-05,0.0026839999999999998,222.2997243158783,224.12801437578148,2.3075319825475846
1.3271807909613057e-05,0.0026944,222.3486769259483,224.12801437578148,2.3075319825475846
1.3512182102750348e-05,0.0027432,222.5774006571788,224.12801437578148,2.3075319825475846
1.3571290510898862e-05,0.0027551999999999997,222.6334004394934,224.12801437578148,2.3075319825475846
1.3657982842850015e-05,0.0027727999999999997,222.71536169587324,224.12801437578148,2.3075319825475846
1.3685566766652656e-05,0.0027784,222.7413976957487,224.12801437578148,2.3075319825475846
1.3780140219690278e-05,0.0027976,222.83050901853193,224.12801437578148,2.3075319825475846
1.3795902461863217e-05,0.0028008,222.84533768630646,224.12801437578148,2.3075319825475846
1.3878654233271136e-05,0.0028176,222.9230800555475,224.12801437578148,2.3075319825475846
1.3961406004679055e-05,0.0028344,223.0006418527334,224.12801437578148,2.3075319825475846
1.3996871049568164e-05,0.0028415999999999997,223.03382771478985,224.12801437578148,2.3075319825475846
1.4044157776086976e-05,0.0028512,223.07802456385707,224.12801437578148,2.3075319825475846
1.4134790668581364e-05,0.0028696,223.16257330884488,224.12801437578148,2.3075319825475846
1.4233304682162222e-05,0.0028896,223.25423466978944,224.12801437578148,2.3075319825475846
1.4446094951496871e-05,0.0029327999999999997,223.45138303807747,224.12801437578148,2.3075319825475846
1.4465797754213044e-05,0.0029368,223.46958003690452,224.12801437578148,2.3075319825475846
1.4552490086164197e-05,0.0029544,223.54953227471484,224.12801437578148,2.3075319825475846
1.4584014570510073e-05,0.0029608,223.57855973341745,224.12801437578148,2.3075319825475846
1.461159849431271e-05,0.0029663999999999997,223.60393869217845,224.12801437578148,2.3075319825475846
1.4678588023547695e-05,0.00298,223.66549564052934,224.12801437578148,2.3075319825475846
1.4725874750066506e-05,0.0029896,223.7088816562276,224.12801437578148,2.3075319825475846
1.4769220916042084e-05,0.0029984,223.74860446348848,224.12801437578148,2.3075319825475846
1.4808626521474425e-05,0.0030064,223.7846766691332,224.12801437578148,2.3075319825475846
1.4875616050709407e-05,0.0030199999999999997,223.8459136232252,224.12801437578148,2.3075319825475846
1.4918962216684985e-05,0.0030288,223.88548023232195,224.12801437578148,2.3075319825475846
1.4962308382660562e-05,0.0030375999999999997,223.92500203293858,224.12801437578148,2.3075319825475846
1.503323847243878e-05,0.003052,223.9895778882933,224.12801437578148,2.3075319825475846
1.506082239624142e-05,0.0030575999999999997,224.01465861706265,224.12801437578148,2.3075319825475846
1.5127811925476404e-05,0.0030712,224.07549449099443,224.12801437578148,2.3075319825475846
1.5301196589378712e-05,0.0031064,224.23246616742696,224.12801437578148,2.3075319825475846
1.5316958831551646e-05,0.0031095999999999997,224.24670183281776,224.12801437578148,2.3075319825475846
1.5387888921329866e-05,0.003124,224.31069175666897,224.12801437578148,2.3075319825475846
1.541941340567574e-05,0.0031303999999999998,224.33909478750306,224.12801437578148,2.3075319825475846
1.5506105737626893e-05,0.0031479999999999998,224.4170865883367,224.12801437578148,2.3075319825475846
1.565978759881303e-05,0.0031791999999999996,224.55492812742852,224.12801437578148,2.3075319825475846
1.5691312083158906e-05,0.0031856,224.58313799397308,224.12801437578148,2.3075319825475846
1.577800441511006e-05,0.0032032,224.6606013870701,224.12801437578148,2.3075319825475846
1.5876518428690915e-05,0.0032232,224.74842676484826,224.12801437578148,2.3075319825475846
1.5923805155209726e-05,0.0032327999999999996,224.79050743245347,224.12801437578148,2.3075319825475846
1.59553296395556e-05,0.0032392,224.8185341391699,224.12801437578148,2.3075319825475846
1.604596253204999e-05,0.0032576,224.898990874923,224.12801437578148,2.3075319825475846
1.6089308698025568e-05,0.0032664,224.93740751484708,224.12801437578148,2.3075319825475846
1.6120833182371442e-05,0.0032727999999999998,224.96532154122318,224.12801437578148,2.3075319825475846
1.6152357666717316e-05,0.0032792,224.99321428707455,224.12801437578148,2.3075319825475846
1.6250871680298172e-05,0.0032992,225.08024259207954,224.12801437578148,2.3075319825475846
1.6274515043557577e-05,0.0033039999999999996,225.1010987399302,224.12801437578148,2.3075319825475846
1.6459721389089587e-05,0.0033415999999999997,225.26406505250873,224.12801437578148,2.3075319825475846
1.651488923669487e-05,0.0033528,225.31246976674853,224.12801437578148,2.3075319825475846
1.6723738945486285e-05,0.0033951999999999997,225.4951477472459,224.12801437578148,2.3075319825475846
1.6786787914178036e-05,0.003408,225.55012069438573,224.12801437578148,2.3075319825475846
1.6877420806672424e-05,0.0034264,225.62900344191596,224.12801437578148,2.3075319825475846
1.6960172578080343e-05,0.0034432,225.70088265697512,224.12801437578148,2.3075319825475846
1.7042924349488262e-05,0.00346,225.77262522384464,224.12801437578148,2.3075319825475846
1.712173556035295e-05,0.003476,225.84082527861293,224.12801437578148,2.3075319825475846
1.731482302697143e-05,0.0035152,226.0074000409421,224.12801437578148,2.3075319825475846
1.7405455919465816e-05,0.0035336,226.08533821768947,224.12801437578148,2.3075319825475846
1.7460623767071095e-05,0.0035448,226.13270135983365,224.12801437578148,2.3075319825475846
1.7472445448700798e-05,0.0035472,226.1428430074783,224.12801437578148,2.3075319825475846
1.7551256659565486e-05,0.0035632,226.21038573328883,224.12801437578148,2.3075319825475846
1.7598543386084294e-05,0.0035727999999999997,226.2508545951759,224.12801437578148,2.3075319825475846
1.7649770673146343e-05,0.0035832,226.29464803588436,224.12801437578148,2.3075319825475846
1.7673414036405748e-05,0.003588,226.31484367094322,224.12801437578148,2.3075319825475846
1.7862560942480992e-05,0.0036263999999999997,226.47603115849518,224.12801437578148,2.3075319825475846
1.7901966547913338e-05,0.0036344,226.50952794649234,224.12801437578148,2.3075319825475846
1.794531271388891e-05,0.0036431999999999997,226.5463412179732,224.12801437578148,2.3075319825475846
1.8059588969642707e-05,0.0036663999999999998,226.64322853872645,224.12801437578148,2.3075319825475846
1.8138400180507392e-05,0.0036823999999999997,226.70990811580523,224.12801437578148,2.3075319825475846
1.830390372332323e-05,0.0037159999999999997,226.8495685591855,224.12801437578148,2.3075319825475846
1.8453645023966135e-05,0.0037464,226.975504208349,224.12801437578148,2.3075319825475846
1.853245623483082e-05,0.0037624,227.04162601728666,224.12801437578148,2.3075319825475846
1.856004015863346e-05,0.0037679999999999996,227.06474273053348,224.12801437578148,2.3075319825475846
1.8595505203522568e-05,0.0037752,227.094444540438,224.12801437578148,2.3075319825475846
1.862308912732521e-05,0.0037808,227.11753067715574,224.12801437578148,2.3075319825475846
1.8697959777646662e-05,0.003796,227.18012592301253,224.12801437578148,2.3075319825475846
1.8784652109597815e-05,0.0038136,227.25248263765067,224.12801437578148,2.3075319825475846
1.8827998275573392e-05,0.0038223999999999997,227.2886121492236,224.12801437578148,2.3075319825475846
1.891863116806778e-05,0.0038407999999999997,227.36405101699305,224.12801437578148,2.3075319825475846
1.9068372468710684e-05,0.0038712,227.4883810732271,224.12801437578148,2.3075319825475846
1.9159005361205072e-05,0.0038896,227.563448509985,224.12801437578148,2.3075319825475846
1.9218113769353586e-05,0.0039016,227.61233093203825,224.12801437578148,2.3075319825475846
1.92654004958724e-05,0.0039112,227.65139466581084,224.12801437578148,2.3075319825475846
1.934027114619385e-05,0.0039264,227.7131691892003,224.12801437578148,2.3075319825475846
1.9399379554342364e-05,0.0039384,227.76187269409758,224.12801437578148,2.3075319825475846
1.9438785159774707e-05,0.0039464,227.79430954887027,224.12801437578148,2.3075319825475846
1.950971524955292e-05,0.0039607999999999996,227.8526313375398,224.12801437578148,2.3075319825475846
1.9592467020960842e-05,0.0039775999999999995,227.9205690110825,224.12801437578148,2.3075319825475846
1.9631872626393185e-05,0.0039856,227.9528809432443,224.12801437578148,2.3075319825475846
1.9679159352911996e-05,0.0039952,227.99162189251166,224.12801437578148,2.3075319825475846
2.0648726431290656e-05,0.0041920384076815365,228.77813506960473,224.12801437578148,2.3075319825475846
2.1783834889433756e-05,0.00442248449689938,229.68085768807435,224.12801437578148,2.3075319825475846
2.3391905205136485e-05,0.004748949789957992,230.92891147440298,224.12801437578148,2.3075319825475846
2.4999975520839214e-05,0.005075415083016604,232.14391822272498,224.12801437578148,2.3075319825475846
2.622967635049424e-05,0.005325065013002601,233.05257593181585,224.12801437578148,2.3075319825475846
2.6513453465030013e-05,0.005382676535307062,233.25988838393673,224.12801437578148,2.3075319825475846
2.849989326678044e-05,0.0057859571914382875,234.68758401528828,224.12801437578148,2.3075319825475846
2.8972855124340065e-05,0.005881976395279056,235.02172534226068,224.12801437578148,2.3075319825475846
2.9918778839459316e-05,0.006074014802960592,235.68369322136377,224.12801437578148,2.3075319825475846
3.294573472784092e-05,0.0066885377075415085,237.74912358559288,224.12801437578148,2.3075319825475846
3.559432113017482e-05,0.0072262452490498095,239.49633725036813,224.12801437578148,2.3075319825475846
3.8053722789484876e-05,0.007725545109021804,241.07384661568975,224.12801437578148,2.3075319825475846
3.9378015990651824e-05,0.007994398879775955,241.9067771779119,224.12801437578148,2.3075319825475846
4.098608630635456e-05,0.008320864172834567,242.90364623185854,224.12801437578148,2.3075319825475846
4.183741764996188e-05,0.00849369873974795,243.42521844876856,224.12801437578148,2.3075319825475846
4.240497187903343e-05,0.008608921784356871,243.77063549443304,224.12801437578148,2.3075319825475846
4.268874899356921e-05,0.008666533306661332,243.9426675420219,224.12801437578148,2.3075319825475846
4.458059642380771e-05,0.009050610122024405,245.07835823461727,224.12801437578148,2.3075319825475846
4.732377519765354e-05,0.00960752150430086,246.69226915031666,224.12801437578148,2.3075319825475846
4.997236159998744e-05,0.010145229045809162,248.21624305792662,224.12801437578148,2.3075319825475846
5.7255974206405684e-05,0.011623924784956993,252.25268805710905,224.12801437578148,2.3075319825475846
5.84856750360607e-05,0.011873574714942988,252.91389059191013,224.12801437578148,2.3075319825475846
5.943159875117995e-05,0.012065613122624524,253.41882506897494,224.12801437578148,2.3075319825475846
6.11342614383946e-05,0.01241128225645129,254.31987847613468,224.12801437578148,2.3075319825475846
6.160722329595423e-05,0.012507301460292058,254.56842726412864,224.12801437578148,2.3075319825475846
6.340447835468081e-05,0.012872174434886977,255.50620226178185,224.12801437578148,2.3075319825475846
6.435040206980005e-05,0.013064212842568514,255.99560075090295,224.12801437578148,2.3075319825475846
6.548551052794316e-05,0.013294658931786357,256.57919090698994,224.12801437578148,2.3075319825475846
6.908002064539632e-05,0.014024404880976196,258.40172266996126,224.12801437578148,2.3075319825475846
7.16340146762183e-05,0.014542908581716344,259.6742666394141,224.12801437578148,2.3075319825475846
7.399882396401642e-05,0.015023004600920185,260.83685754465466,224.12801437578148,2.3075319825475846
7.494474767913568e-05,0.015215043008601721,261.29782556018165,224.12801437578148,2.3075319825475846
7.636363325181455e-05,0.015503100620124026,261.98504564509574,224.12801437578148,2.3075319825475846
7.825548068205307e-05,0.0158871774354871,262.8936418699963,224.12801437578148,2.3075319825475846
7.88230349111246e-05,0.01600240048009602,263.1645449315407,224.12801437578148,2.3075319825475846
8.336346874369701e-05,0.016924184836967393,265.30503865573644,224.12801437578148,2.3075319825475846
8.66742017466144e-05,0.017596319263852772,266.83724766877674,224.12801437578148,2.3075319825475846
8.866064154836482e-05,0.017999599919983997,267.7456190015999,224.12801437578148,2.3075319825475846
9.074167372162717e-05,0.018422084416883377,268.68877324242834,224.12801437578148,2.3075319825475846
9.27281135233776e-05,0.018825365073014605,269.5812181491237,224.12801437578148,2.3075319825475846
9.679558549839038e-05,0.01965113022604521,271.38567065355943,224.12801437578148,2.3075319825475846
9.811987869955733e-05,0.01991998399679936,271.9667527428164,224.12801437578148,2.3075319825475846
0.0001018089811885224,0.02066893378675735,273.5695707969852,224.12801437578148,2.3075319825475846
0.00010379542099027284,0.02107221444288858,274.42323685871526,224.12801437578148,2.3075319825475846
0.00010502512181992786,0.021321864372874574,274.9485047513915,224.12801437578148,2.3075319825475846
0.0001074845234792379,0.02182116423284657,275.99189945922296,224.12801437578148,2.3075319825475846
0.00010861963193738102,0.022051610322064413,276.47032175488795,224.12801437578148,2.3075319825475846
0.00010956555565250026,0.02224364872974595,276.86751932482605,224.12801437578148,2.3075319825475846
0.00011211954968332226,0.0227621524304861,277.933328439186,224.12801437578148,2.3075319825475846
0.00011297088102692958,0.02293498699739948,278.2864884538532,224.12801437578148,2.3075319825475846
0.00011495732082868,0.023338267653530708,279.1065165414146,224.12801437578148,2.3075319825475846
0.00011798427671706159,0.02395279055811162,280.3455355038962,224.12801437578148,2.3075319825475846
0.0001202544936333478,0.02441368273654731,281.266679767158,224.12801437578148,2.3075319825475846
0.00012205174869207439,0.02477855571114223,281.99111783354226,224.12801437578148,2.3075319825475846
0.00012347063426475325,0.025066613322664532,282.56010797566364,224.12801437578148,2.3075319825475846
0.0001269705520106945,0.02577715543108622,283.9528216590016,224.12801437578148,2.3075319825475846
0.00012791647572581375,0.025969193838767755,284.3266503435815,224.12801437578148,2.3075319825475846
0.00013633519679037508,0.027678335667133427,287.607532450252,224.12801437578148,2.3075319825475846
0.00013784867473456587,0.027985597119423885,288.18887556544905,224.12801437578148,2.3075319825475846
0.00013936215267875668,0.028292858571714343,288.76773468075646,224.12801437578148,2.3075319825475846
0.0001408756306229475,0.0286001200240048,289.344147215449,224.12801437578148,2.3075319825475846
0.00014295666279620983,0.02902260452090418,290.13278645801864,224.12801437578148,2.3075319825475846
0.000143997178882841,0.02923384676935387,290.5254261516426,224.12801437578148,2.3075319825475846
0.0001466457652851749,0.02977155431086217,291.5199121480926,224.12801437578148,2.3075319825475846
0.0001473079118857584,0.02990598119623925,291.76743606404096,224.12801437578148,2.3075319825475846
0.00014929435168750882,0.030309261852370473,292.50741730965774,224.12801437578148,2.3075319825475846
0.0001508078296316996,0.03061652330466093,293.0686380460939,224.12801437578148,2.3075319825475846
0.00015251049231891428,0.030962192438487697,293.69739234602235,224.12801437578148,2.3075319825475846
0.00015317263891949774,0.031096619323864774,293.9411678413252,224.12801437578148,2.3075319825475846
0.00015478070923520047,0.031423084616923384,294.5314892946289,224.12801437578148,2.3075319825475846
0.00015572663295031975,0.031615123024604924,294.8776199234322,224.12801437578148,2.3075319825475846
0.0001561050024363674,0.03169193838767753,295.0158424667748,224.12801437578148,2.3075319825475846
0.0001571455185229986,0.031903180636127224,295.3952823808889,224.12801437578148,2.3075319825475846
0.00015818603460962977,0.032114422884576915,295.7737437121951,224.12801437578148,2.3075319825475846
0.0001647129082439526,0.033439487897579515,298.1259577643516,224.12801437578148,2.3075319825475846
0.00016906415733350117,0.034322864572914585,299.6739335631926,224.12801437578148,2.3075319825475846
0.00017086141239222778,0.034687737547509506,300.3087712500526,224.12801437578148,2.3075319825475846
0.0001725640750794424,0.03503340668133627,300.9077983682195,224.12801437578148,2.3075319825475846
0.00017559103096782401,0.035647929585917185,301.96707468524755,224.12801437578148,2.3075319825475846
0.00017663154705445519,0.035859171834366876,302.3295529923812,224.12801437578148,2.3075319825475846
0.0001789017639707414,0.036320064012802564,303.1175366737602,224.12801437578148,2.3075319825475846
0.00018050983428644408,0.03664652930586117,303.67333404792987,224.12801437578148,2.3075319825475846
0.00018296923594575418,0.03714582916583317,304.5196565208818,224.12801437578148,2.3075319825475846
0.00018476649100448078,0.03751070214042809,305.1353198187509,224.12801437578148,2.3075319825475846
0.00018627996894867157,0.03781796359271855,305.6519637108793,224.12801437578148,2.3075319825475846
0.00018760426214983847,0.03808681736347269,306.10268569134024,224.12801437578148,2.3075319825475846
0.00018911774009402929,0.03839407881576315,306.6162799137429,224.12801437578148,2.3075319825475846
0.00019063121803822007,0.03870134026805361,307.1282736330018,224.12801437578148,2.3075319825475846
0.00019252306546845862,0.03908541708341669,307.7660419095818,224.12801437578148,2.3075319825475846
0.0001943203205271852,0.03945029005801161,308.3696616403331,224.12801437578148,2.3075319825475846
0.0001953608366138163,0.039661532306461286,308.7181305163158,224.12801437578148,2.3075319825475846
0.00019687431455800712,0.039968793758751744,309.2237049748233,224.12801437578148,2.3075319825475846
0.00019763105353010253,0.040122424484896974,309.47592362186214,224.12801437578148,2.3075319825475846
0.00020056341704697224,0.040717743548709745,310.44973396284234,224.12801437578148,2.3075319825475846
0.00020217148736267494,0.04104420884176835,310.98140099266743,224.12801437578148,2.3075319825475846
0.00020283363396325844,0.04117863572714543,311.19984304190535,224.12801437578148,2.3075319825475846
0.00020330659582081808,0.0412746549309862,311.35570284081217,224.12801437578148,2.3075319825475846
0.00020453629665047307,0.041524304860972194,311.76027796556946,224.12801437578148,2.3075319825475846
0.00020519844325105654,0.041658731746349265,311.9777331434716,224.12801437578148,2.3075319825475846
0.00020737406779583085,0.04210042008401681,312.69030967138946,224.12801437578148,2.3075319825475846
0.00020926591522606934,0.04248449689937987,313.3075747876342,224.12801437578148,2.3075319825475846
0.00021040102368421245,0.04271494298859772,313.6768893017551,224.12801437578148,2.3075319825475846
0.00021323879482957022,0.043291058211642336,314.59679216749976,224.12801437578148,2.3075319825475846
0.00021475227277376096,0.04359831966393278,315.08545424421254,224.12801437578148,2.3075319825475846
0.00021626575071795177,0.04390558111622324,315.5727750418207,224.12801437578148,2.3075319825475846
0.0002181575981481903,0.04428965793158632,316.18005969448484,224.12801437578148,2.3075319825475846
0.00021853596763423796,0.044366473294658926,316.3012697833052,224.12801437578148,2.3075319825475846
0.00021957648372086916,0.04457771554310862,316.63417624277486,224.12801437578148,2.3075319825475846
0.00022014403794994071,0.04469293858771754,316.81550224529605,224.12801437578148,2.3075319825475846
0.00022194129300866732,0.045057811562312464,317.38850217233414,224.12801437578148,2.3075319825475846
0.00022742765055635896,0.04617163432686537,319.12656851462145,224.12801437578148,2.3075319825475846
0.00022818438952845437,0.0463252650530106,319.3650121135734,224.12801437578148,2.3075319825475846
0.00022960327510113327,0.046613322664532914,319.8112642829739,224.12801437578148,2.3075319825475846
0.00023177889964590752,0.04705501100220044,320.49343439846507,224.12801437578148,2.3075319825475846
0.000232441046246491,0.04718943788757751,320.70055511370583,224.12801437578148,2.3075319825475846
0.00023508963264882491,0.04772714542908582,321.52674722542724,224.12801437578148,2.3075319825475846
0.0002361301487354561,0.04793838767753551,321.8503285170517,224.12801437578148,2.3075319825475846
0.0002412381367971,0.0489753950790158,323.43082328022393,224.12801437578148,2.3075319825475846
0.0002430353918558266,0.04934026805361072,323.98381223200136,224.12801437578148,2.3075319825475846
0.00024388672319943395,0.04951310262052411,324.2451975095735,224.12801437578148,2.3075319825475846
0.00024644071723025593,0.05003160632126426,325.0272266014105,224.12801437578148,2.3075319825475846
0.0002496568578616614,0.05068453690738148,326.0075222921146,224.12801437578148,2.3075319825475846
0.00025031900446224485,0.05081896379275855,326.20873512797056,224.12801437578148,2.3075319825475846
0.0002519270747779476,0.051145429085817165,326.69653262227234,224.12801437578148,2.3075319825475846
0.00025344055272213836,0.05145269053810762,327.1545280467391,224.12801437578148,2.3075319825475846
0.0002558999543814484,0.051951990398079614,327.8965021651544,224.12801437578148,2.3075319825475846
0.0002572242475826154,0.05222084416883377,328.29487454531215,224.12801437578148,2.3075319825475846
0.0002584539484122704,0.052470494098819764,328.66407612756336,224.12801437578148,2.3075319825475846
0.00026025120347099697,0.052835367073414685,329.2024484824767,224.12801437578148,2.3075319825475846
0.0002610079424430924,0.052988997799559914,329.42869756634536,224.12801437578148,2.3075319825475846
0.0002625214203872832,0.05329625925185037,329.88042971691505,224.12801437578148,2.3075319825475846
0.00026289978987333084,0.05337307461492298,329.99320391445417,224.12801437578148,2.3075319825475846
0.00026431867544600976,0.05366113222644529,330.4155445823045,224.12801437578148,2.3075319825475846
0.0002685753321640464,0.054525305061012205,331.67729305922535,224.12801437578148,2.3075319825475846
0.00027377791259720224,0.05558151630326065,333.2088880016949,224.12801437578148,2.3075319825475846
0.00027680486848558387,0.05619603920784157,334.0947744098458,224.12801437578148,2.3075319825475846
0.0002776561998291912,0.056368873774754955,334.3432482016586,224.12801437578148,2.3075319825475846
0.0002798318243739655,0.05681056211242248,334.9768906597595,224.12801437578148,2.3075319825475846
0.00028011560148850126,0.056868173634726946,335.0593977999848,224.12801437578148,2.3075319825475846
0.0002818182641757159,0.05721384276855371,335.5537578106447,224.12801437578148,2.3075319825475846
0.00028399388872049023,0.05765553110622125,336.18374820596586,224.12801437578148,2.3075319825475846
0.0002851289971786333,0.05788597719543909,336.51169148940966,224.12801437578148,2.3075319825475846
0.0002881559530670149,0.05850050010002,337.38372717844607,224.12801437578148,2.3075319825475846
0.0002914666860699323,0.05917263452690538,338.33343571111527,224.12801437578148,2.3075319825475846
0.0002921288326705157,0.05930706141228245,338.52287154264246,224.12801437578148,2.3075319825475846
0.0002944936419583139,0.0597871574314863,339.1980653528311,224.12801437578148,2.3075319825475846
0.00029666926650308815,0.06022884576915383,339.8173784526523,224.12801437578148,2.3075319825475846
0.00029761519021820744,0.060420884176835374,340.086092266237,224.12801437578148,2.3075319825475846
0.0003002637766205413,0.06095859171834367,340.8367246935361,224.12801437578148,2.3075319825475846
0.00030111510796414865,0.06113142628525706,341.0774504154182,224.12801437578148,2.3075319825475846
0.0003043312485955541,0.06178435687137428,341.98447322962903,224.12801437578148,2.3075319825475846
0.0003066014655118403,0.062245249049809964,342.6224752629726,224.12801437578148,2.3075319825475846
0.000306979834997888,0.06232206441288257,342.7286295601145,224.12801437578148,2.3075319825475846
0.00031208782305953194,0.06335907181436287,344.1567546994369,224.12801437578148,2.3075319825475846
0.0003137904857467466,0.06370474094818963,344.6307668042332,224.12801437578148,2.3075319825475846
0.000314547224718842,0.06385837167433486,344.84111675905007,224.12801437578148,2.3075319825475846
0.0003149255942048897,0.06393518703740748,344.9462177184958,224.12801437578148,2.3075319825475846
0.0003179525500932713,0.0645497099419884,345.7852597856961,224.12801437578148,2.3075319825475846
0.0003198443975235098,0.06493378675735147,346.30807941963195,224.12801437578148,2.3075319825475846
0.00032041195175258136,0.06504900980196039,346.46468995008934,224.12801437578148,2.3075319825475846
0.00032145246783921253,0.06526025205041008,346.7515285529288,224.12801437578148,2.3075319825475846
0.0003224929839258437,0.06547149429885978,347.03800527871255,224.12801437578148,2.3075319825475846
0.0003241010542415464,0.06579795959191838,347.4800340118465,224.12801437578148,2.3075319825475846
0.0003254253474427134,0.06606681336267253,347.8434157863327,224.12801437578148,2.3075319825475846
0.0003328981447921555,0.06758391678335668,349.883220061693,224.12801437578148,2.3075319825475846
0.00033441162273634633,0.06789117823564714,350.29416171571654,224.12801437578148,2.3075319825475846
0.00033810072522531137,0.06864012802560512,351.2928049942248,224.12801437578148,2.3075319825475846
0.00033951961079799024,0.06892818563712742,351.67576588174626,224.12801437578148,2.3075319825475846
0.00034018175739857376,0.06906261252250451,351.85426731149187,224.12801437578148,2.3075319825475846
0.0003407493116276453,0.06917783556711343,352.00716071449784,224.12801437578148,2.3075319825475846
0.000341033088742181,0.06923544708941788,352.08357016965635,224.12801437578148,2.3075319825475846
0.00034216819720032417,0.06946589317863573,352.3889603504364,224.12801437578148,2.3075319825475846
0.00034557352257475344,0.07015723144628926,353.30276900389657,224.12801437578148,2.3075319825475846
0.00034633026154684885,0.07031086217243449,353.5053598912436,224.12801437578148,2.3075319825475846
0.00034964099454976624,0.07098299659931986,354.38967291660816,224.12801437578148,2.3075319825475846
0.00035153284198000476,0.07136707341468294,354.8935283605863,224.12801437578148,2.3075319825475846
0.00035238417332361205,0.07153990798159632,355.1199181805848,224.12801437578148,2.3075319825475846
0.0003534246894102432,0.07175115023004601,355.3963273822021,224.12801437578148,2.3075319825475846
0.00035560031395501755,0.07219283856771355,355.97325044271486,224.12801437578148,2.3075319825475846
0.0003573029766422322,0.07253850770154031,356.4237957653462,224.12801437578148,2.3075319825475846
0.0003589110469579349,0.07286497299459892,356.8485425669416,224.12801437578148,2.3075319825475846
0.00036099207913119723,0.0732874574914983,357.3971148028709,224.12801437578148,2.3075319825475846
0.00036174881810329264,0.07344108821764353,357.5962896543981,224.12801437578148,2.3075319825475846
0.00036316770367597156,0.07372914582916584,357.9693050767843,224.12801437578148,2.3075319825475846
0.00036591088244981737,0.0742860572114423,358.6888605115384,224.12801437578148,2.3075319825475846
0.00036997835442483017,0.0751118223644729,359.7519271678728,224.12801437578148,2.3075319825475846
0.00037205938659809246,0.07553430686137227,360.2940585521232,224.12801437578148,2.3075319825475846
0.00037385664165681903,0.0758991798359672,360.76131193077356,224.12801437578148,2.3075319825475846
0.0003775457441457842,0.0766481296259252,361.71767533375714,224.12801437578148,2.3075319825475846
0.00038095106952021346,0.07733946789357872,362.597242528297,224.12801437578148,2.3075319825475846
0.000382842916950452,0.0777235447089418,363.0845658579057,224.12801437578148,2.3075319825475846
0.00038482935675220243,0.07812682536507302,363.5952456488065,224.12801437578148,2.3075319825475846
0.0003867212041824409,0.07851090218043609,364.0806524051502,224.12801437578148,2.3075319825475846
0.00038700498129697666,0.07856851370274055,364.1533834644438,224.12801437578148,2.3075319825475846
0.00038899142109872706,0.07897179435887178,364.6619197702026,224.12801437578148,2.3075319825475846
0.0003900319371853583,0.07918303660732147,364.9278916765176,224.12801437578148,2.3075319825475846
0.00039107245327198945,0.07939427885577116,365.19358700096177,224.12801437578148,2.3075319825475846
0.00039249133884466833,0.07968233646729346,365.5554549221647,224.12801437578148,2.3075319825475846
0.0003960858489621215,0.0804120824164833,366.469911036699,224.12801437578148,2.3075319825475846
0.0003973155497917765,0.0806617323464693,366.7820075303446,224.12801437578148,2.3075319825475846
0.0003981668811353838,0.08083456691338269,366.99785368767976,224.12801437578148,2.3075319825475846
0.00040270731496795626,0.08175635127025406,368.1460076241885,224.12801437578148,2.3075319825475846
0.0004056396784848259,0.08235167033406682,368.88484142469673,224.12801437578148,2.3075319825475846
0.00041036929706042216,0.0833118623724745,370.0721346660494,224.12801437578148,2.3075319825475846
0.00041112603603251757,0.08346549309861973,370.2616052218376,224.12801437578148,2.3075319825475846
0.0004132070682057799,0.08388797759551911,370.78194923234884,224.12801437578148,2.3075319825475846
0.0004135854376918276,0.08396479295859172,370.87644732662244,224.12801437578148,2.3075319825475846
0.0004150043232645065,0.08425285057011403,371.23051529807924,224.12801437578148,2.3075319825475846
0.00041547728512206613,0.0843488697739548,371.3484330002433,224.12801437578148,2.3075319825475846
0.000416896170694745,0.0846369273854771,371.70187240279586,224.12801437578148,2.3075319825475846
0.000419450164725567,0.08515543108621725,372.33688337046567,224.12801437578148,2.3075319825475846
0.0004205852731837101,0.0853858771754351,372.6186262498223,224.12801437578148,2.3075319825475846
0.00042124741978429356,0.08552030406081217,372.78283931401967,224.12801437578148,2.3075319825475846
0.00042512570701628254,0.08630766153230647,373.74264485107085,224.12801437578148,2.3075319825475846
0.0004261662231029137,0.08651890378075616,373.99957189511434,224.12801437578148,2.3075319825475846
0.00042805807053315217,0.08690298059611923,374.46608606332103,224.12801437578148,2.3075319825475846
0.0004312742111645576,0.08755591118223645,375.25731894141586,224.12801437578148,2.3075319825475846
0.00043222013487967685,0.08774794958991798,375.48959611927415,224.12801437578148,2.3075319825475846
0.000433260650966308,0.08795919183836767,375.74487215203715,224.12801437578148,2.3075319825475846
0.00043553086788259424,0.08842008401680336,376.3010095931623,224.12801437578148,2.3075319825475846
0.0004364767915977135,0.08861212242448491,376.53239972167955,224.12801437578148,2.3075319825475846
0.0004398821169721428,0.08930346069213843,377.3637897455756,224.12801437578148,2.3075319825475846
0.00044082804068726203,0.08949549909981996,377.59428546858237,224.12801437578148,2.3075319825475846
0.0004410172254302859,0.08953390678135628,377.6403614573984,224.12801437578148,2.3075319825475846
0.0004419631491454052,0.08972594518903781,377.8706258754607,224.12801437578148,2.3075319825475846
0.00044357121946110784,0.09005241048209642,378.26163476798246,224.12801437578148,2.3075319825475846
0.00044640899060646564,0.09062852570514103,378.9503045313031,224.12801437578148,2.3075319825475846
0.00044716572957856105,0.09078215643128626,379.1336611841406,224.12801437578148,2.3075319825475846
0.00044915216938031145,0.09118543708741748,379.6143975526756,224.12801437578148,2.3075319825475846
0.0004505710549529904,0.0914734946989398,379.9572731455514,224.12801437578148,2.3075319825475846
0.00045094942443903803,0.0915503100620124,380.0486354853723,224.12801437578148,2.3075319825475846
0.00045653037435824164,0.09268333666733347,381.3927763259323,224.12801437578148,2.3075319825475846
0.000458611406531504,0.09310582116423285,381.892339150107,224.12801437578148,2.3075319825475846
0.00045984110736115903,0.09335547109421885,382.1871198222909,224.12801437578148,2.3075319825475846
0.00046059784633325444,0.09350910182036408,382.3683705109682,224.12801437578148,2.3075319825475846
0.00046258428613500484,0.0939123824764953,382.84360187161917,224.12801437578148,2.3075319825475846
0.00046466531830826723,0.09433486697339469,383.340610444966,224.12801437578148,2.3075319825475846
0.0004654220572803626,0.09448849769953992,383.521125508532,224.12801437578148,2.3075319825475846
0.0004673139047106011,0.09487257451490298,383.971913100734,224.12801437578148,2.3075319825475846
0.00046788145893967263,0.09498779755951191,384.1070105185599,224.12801437578148,2.3075319825475846
0.0004692057521408396,0.09525665133026606,384.42198952431755,224.12801437578148,2.3075319825475846
0.0004696787139983992,0.09535267053410683,384.53439797767567,224.12801437578148,2.3075319825475846
0.0004710975995710781,0.09564072814562913,384.8713587619229,224.12801437578148,2.3075319825475846
0.00047147596905712584,0.09571754350870175,384.9611480949043,224.12801437578148,2.3075319825475846
0.0004733678164873643,0.09610162032406482,385.40967391267924,224.12801437578148,2.3075319825475846
0.00047421914783097165,0.0962744548909782,385.61128239430434,224.12801437578148,2.3075319825475846
0.0004763947723757459,0.09671614322864573,386.1258638289257,224.12801437578148,2.3075319825475846
0.0004770569189763294,0.09685057011402282,386.28229354839647,224.12801437578148,2.3075319825475846
0.0004780974350629605,0.0970618123624725,386.52794070496236,224.12801437578148,2.3075319825475846
0.0004854756400408907,0.09855971194238848,388.26386021996615,224.12801437578148,2.3075319825475846
0.00048613778664147417,0.09869413882776555,388.4191429966394,224.12801437578148,2.3075319825475846
0.0004867999332420577,0.09882856571314264,388.574343308726,224.12801437578148,2.3075319825475846
0.0004881242264432246,0.09909741948389679,388.8844971621256,224.12801437578148,2.3075319825475846
0.0004888809654153201,0.09925105021004202,389.06158059342886,224.12801437578148,2.3075319825475846
0.0004920971060467255,0.09990398079615924,389.8129956794093,224.12801437578148,2.3075319825475846
0.0004922862907897494,0.09994238847769554,389.8571368276143,224.12801437578148,2.3075319825475846