File: datasets/aisi_316_L/data/M1/valid_29.csv
Time(s),Strain(%),Stress(MPa),Temp(C),Log_SR(s-1)
0.0,0.0,0.0,49.83188801480947,5.140036467271932
1.564650286131049e-10,2.16e-05,4.2164566875,49.83188801480947,5.140036467271932
2.3759504344952965e-10,3.28e-05,6.402767562499999,49.83188801480947,5.140036467271932
2.491850455690189e-10,3.4399999999999996e-05,6.715097687499999,49.83188801480947,5.140036467271932
2.9554505404697593e-10,4.0799999999999996e-05,7.964418187499999,49.83188801480947,5.140036467271932
3.766750688834007e-10,5.2e-05,10.1507290625,49.83188801480947,5.140036467271932
5.041650921977825e-10,6.96e-05,13.5863604375,49.83188801480947,5.140036467271932
6.258601144524196e-10,8.64e-05,16.86582675,49.83188801480947,5.140036467271932
6.664251218706321e-10,9.2e-05,17.9589821875,49.83188801480947,5.140036467271932
7.533501377668013e-10,0.000104,20.301458125,49.83188801480947,5.140036467271932
8.634551579019493e-10,0.0001192,23.2685943125,49.83188801480947,5.140036467271932
9.735601780370972e-10,0.0001344,26.2357305,49.83188801480947,5.140036467271932
1.0025351833358204e-09,0.0001384,27.016555812500002,49.83188801480947,5.140036467271932
1.2459252278450945e-09,0.00017199999999999998,33.5754884375,49.83188801480947,5.140036467271932
1.2633102310243284e-09,0.00017439999999999998,34.043983624999996,49.83188801480947,5.140036467271932
1.3154652405620302e-09,0.0001816,35.4494691875,49.83188801480947,5.140036467271932
1.425570260697178e-09,0.00019679999999999999,38.416605374999996,49.83188801480947,5.140036467271932
1.6283952977882398e-09,0.0002248,43.8823825625,49.83188801480947,5.140036467271932
1.8138353317000682e-09,0.0002504,48.879664562500004,49.83188801480947,5.140036467271932
1.8486053380585356e-09,0.00025519999999999997,49.8166549375,49.83188801480947,5.140036467271932
1.94132535501445e-09,0.000268,52.315295937500004,49.83188801480947,5.140036467271932
2.0688153783288317e-09,0.0002856,55.7509273125,49.83188801480947,5.140036467271932
2.2716404154198935e-09,0.0003136,61.2167045,49.83188801480947,5.140036467271932
2.375950434495297e-09,0.000328,64.027675625,49.83188801480947,5.140036467271932
2.6367254821838048e-09,0.00036399999999999996,71.0551034375,49.83188801480947,5.140036467271932
2.770010506557931e-09,0.00038239999999999997,74.64689987499999,49.83188801480947,5.140036467271932
2.8685255245735897e-09,0.000396,77.30170593749999,49.83188801480947,5.140036467271932
2.903295530932058e-09,0.0004008,78.2386963125,49.83188801480947,5.140036467271932
2.9670405425892487e-09,0.0004096,79.95651199999999,49.83188801480947,5.140036467271932
3.0076055500074607e-09,0.00041519999999999995,81.04966743749999,49.83188801480947,5.140036467271932
3.2162255881582677e-09,0.000444,86.6716096875,49.83188801480947,5.140036467271932
3.33212560935316e-09,0.00045999999999999996,89.79491093749999,49.83188801480947,5.140036467271932
3.3553056135921387e-09,0.0004632,90.4195711875,49.83188801480947,5.140036467271932
3.5871056559819236e-09,0.0004952,96.6661736875,49.83188801480947,5.140036467271932
3.6276706634001364e-09,0.0005008,97.75932912500001,49.83188801480947,5.140036467271932
3.7203906803560503e-09,0.0005136,100.257970125,49.83188801480947,5.140036467271932
3.784135692013241e-09,0.0005224,101.9757858125,49.83188801480947,5.140036467271932
3.8884457110886436e-09,0.0005367999999999999,104.78675693749999,49.83188801480947,5.140036467271932
3.957985723805579e-09,0.0005463999999999999,106.66073768749999,49.83188801480947,5.140036467271932
4.044910739701749e-09,0.0005584,109.003213625,49.83188801480947,5.140036467271932
4.073885745000472e-09,0.0005624,109.7840389375,49.83188801480947,5.140036467271932
4.149220758777152e-09,0.0005727999999999999,111.81418474999998,49.83188801480947,5.140036467271932
4.444765812824128e-09,0.0006136,119.7786029375,49.83188801480947,5.140036467271932
4.624410845676212e-09,0.0006384,124.619719875,49.83188801480947,5.140036467271932
4.7171308626321254e-09,0.0006512,127.118360875,49.83188801480947,5.140036467271932
4.862005889125741e-09,0.0006711999999999999,131.0224874375,49.83188801480947,5.140036467271932
4.983700911380378e-09,0.0006879999999999999,134.30195375,49.83188801480947,5.140036467271932
5.0242659187985906e-09,0.0006935999999999999,135.3951091875,49.83188801480947,5.140036467271932
5.377760983443013e-09,0.0007423999999999999,144.921178,49.83188801480947,5.140036467271932
5.777616056565393e-09,0.0007976,155.6965673125,49.83188801480947,5.140036467271932
5.928286084118752e-09,0.0008183999999999999,159.7568589375,49.83188801480947,5.140036467271932
5.96305609047722e-09,0.0008232,160.6938493125,49.83188801480947,5.140036467271932
5.997826096835688e-09,0.000828,161.63083968749999,49.83188801480947,5.140036467271932
6.177471129687771e-09,0.0008527999999999999,166.471956625,49.83188801480947,5.140036467271932
6.218036137105984e-09,0.0008583999999999999,167.5651120625,49.83188801480947,5.140036467271932
6.3629111635996e-09,0.0008784,171.469238625,49.83188801480947,5.140036467271932
6.50199118903347e-09,0.0008975999999999999,175.21720012499998,49.83188801480947,5.140036467271932
6.785946240960957e-09,0.0009368,182.8692881875,49.83188801480947,5.140036467271932
6.91343626427534e-09,0.0009544,186.3049195625,49.83188801480947,5.140036467271932
7.081491295007933e-09,0.0009776,190.833706375,49.83188801480947,5.140036467271932
7.145236306665123e-09,0.0009864,192.55152206249997,49.83188801480947,5.140036467271932
7.168416310904103e-09,0.0009896,193.1761823125,49.83188801480947,5.140036467271932
7.371241347995165e-09,0.0010176,198.6419595,49.83188801480947,5.140036467271932
7.539296378727758e-09,0.0010408,203.17074631249997,49.83188801480947,5.140036467271932
7.724736412639586e-09,0.0010664,208.16802831249998,49.83188801480947,5.140036467271932
7.736326414759076e-09,0.001068,208.4803584375,49.83188801480947,5.140036467271932
7.759506418998055e-09,0.0010712,209.1050186875,49.83188801480947,5.140036467271932
7.794276425356522e-09,0.001076,210.04200906249997,49.83188801480947,5.140036467271932
7.915971447611158e-09,0.0010927999999999999,213.32147537499998,49.83188801480947,5.140036467271932
7.97971645926835e-09,0.0011015999999999999,215.03929106249998,49.83188801480947,5.140036467271932
8.037666469865796e-09,0.0011095999999999999,216.60094168749998,49.83188801480947,5.140036467271932
8.402751536629708e-09,0.00116,226.439340625,49.83188801480947,5.140036467271932
8.651936582198727e-09,0.0011944,233.1544383125,49.83188801480947,5.140036467271932
8.895326626708e-09,0.001228,239.71337093749997,49.83188801480947,5.140036467271932
8.93009663306647e-09,0.0012328,240.6503613125,49.83188801480947,5.140036467271932
8.953276637305447e-09,0.001236,241.27502156249997,49.83188801480947,5.140036467271932
9.063381657440594e-09,0.0012511999999999998,244.24215774999996,49.83188801480947,5.140036467271932
9.156101674396509e-09,0.001264,246.74079874999998,49.83188801480947,5.140036467271932
9.277796696651146e-09,0.0012808,250.0202650625,49.83188801480947,5.140036467271932
9.428466724204507e-09,0.0013016,254.0805566875,49.83188801480947,5.140036467271932
9.561751748578633e-09,0.00132,257.672353125,49.83188801480947,5.140036467271932
9.648676764474802e-09,0.0013319999999999999,260.0148290625,49.83188801480947,5.140036467271932
9.700831774012504e-09,0.0013392,261.420314625,49.83188801480947,5.140036467271932
9.776166787789184e-09,0.0013495999999999998,263.45046043749994,49.83188801480947,5.140036467271932
9.886271807924333e-09,0.0013648,266.417596625,49.83188801480947,5.140036467271932
9.973196823820501e-09,0.0013767999999999999,268.7600725625,49.83188801480947,5.140036467271932
1.0141251854553096e-08,0.0014,273.288859375,49.83188801480947,5.140036467271932
1.0152841856672585e-08,0.0014016,273.60118950000003,49.83188801480947,5.140036467271932
1.0176021860911564e-08,0.0014047999999999999,274.22584974999995,49.83188801480947,5.140036467271932
1.0257151875747988e-08,0.001416,276.412160625,49.83188801480947,5.140036467271932
1.0425206906480582e-08,0.0014391999999999999,280.9409474375,49.83188801480947,5.140036467271932
1.0575876934033943e-08,0.00146,285.00123906249996,49.83188801480947,5.140036467271932
1.0732341962647048e-08,0.0014816,289.21769575,49.83188801480947,5.140036467271932
1.0836651981722451e-08,0.001496,292.028666875,49.83188801480947,5.140036467271932
1.0877216989140662e-08,0.0015015999999999999,293.12182231249994,49.83188801480947,5.140036467271932
1.0940962000797853e-08,0.0015103999999999999,294.839638,49.83188801480947,5.140036467271932
1.1027887016694023e-08,0.0015224,297.1821139375,49.83188801480947,5.140036467271932
1.1091632028351215e-08,0.0015312,298.89992962499997,49.83188801480947,5.140036467271932
1.1253892058024064e-08,0.0015536,303.27255137500003,49.83188801480947,5.140036467271932
1.1271277061203298e-08,0.0015559999999999999,303.7410465625,49.83188801480947,5.140036467271932
1.1421947088756658e-08,0.0015768,307.8013381875,49.83188801480947,5.140036467271932
1.1543642111011295e-08,0.0015936,311.0808045,49.83188801480947,5.140036467271932
1.1659542132206187e-08,0.0016095999999999999,314.20410575,49.83188801480947,5.140036467271932
1.1723287143863379e-08,0.0016183999999999999,315.9219214375,49.83188801480947,5.140036467271932
1.1955087186253165e-08,0.0016504,316.57143877091374,49.83188801480947,5.140036467271932
1.2099962212746779e-08,0.0016703999999999998,316.737205265958,49.83188801480947,5.140036467271932
1.2233247237120905e-08,0.0016887999999999998,316.88902807101454,49.83188801480947,5.140036467271932
1.232596725407682e-08,0.0017016,316.9942636656638,49.83188801480947,5.140036467271932
1.2447662276331458e-08,0.0017184,317.131918048643,49.83188801480947,5.140036467271932
1.2604127304944562e-08,0.00174,317.30813348184694,49.83188801480947,5.140036467271932
1.276638733461741e-08,0.0017624,317.4899766461192,49.83188801480947,5.140036467271932
1.2905467360051283e-08,0.0017816,317.64512594919785,49.83188801480947,5.140036467271932
1.301557238018643e-08,0.0017967999999999999,317.76749050206575,49.83188801480947,5.140036467271932
1.3229987419396981e-08,0.0018264,318.0046269590464,49.83188801480947,5.140036467271932
1.3276347427874939e-08,0.0018327999999999999,318.055702090546,49.83188801480947,5.140036467271932
1.3293732431054172e-08,0.0018352,318.07483732632505,49.83188801480947,5.140036467271932
1.3351682441651618e-08,0.0018432,318.13855107783996,49.83188801480947,5.140036467271932
1.3519737472384212e-08,0.0018663999999999998,318.32271389686747,49.83188801480947,5.140036467271932
1.365302249675834e-08,0.0018847999999999998,318.4681400038299,49.83188801480947,5.140036467271932
1.3942772549745571e-08,0.0019248,318.7823871604624,49.83188801480947,5.140036467271932
1.3989132558223527e-08,0.0019311999999999999,318.83242938867244,49.83188801480947,5.140036467271932
1.4006517561402761e-08,0.0019336,318.85117854430916,49.83188801480947,5.140036467271932
1.4076057574119697e-08,0.0019432,318.92608458562023,49.83188801480947,5.140036467271932
1.4197752596374335e-08,0.00196,319.0568238062012,49.83188801480947,5.140036467271932
1.4510682653600546e-08,0.0020032,319.39101920808923,49.83188801480947,5.140036467271932
1.456863266419799e-08,0.0020112,319.4525975638739,49.83188801480947,5.140036467271932
1.4620787673735693e-08,0.0020184,319.5079364563071,49.83188801480947,5.140036467271932
1.4643967677974668e-08,0.0020215999999999997,319.53250680203274,49.83188801480947,5.140036467271932
1.4788842704468285e-08,0.0020415999999999998,319.6857292319029,49.83188801480947,5.140036467271932
1.4852587716125477e-08,0.0020504,319.75296153006246,49.83188801480947,5.140036467271932
1.4927922729902156e-08,0.0020608,319.83227296939117,49.83188801480947,5.140036467271932
1.502064274685807e-08,0.0020736,319.92967308463807,49.83188801480947,5.140036467271932
1.5235057786068623e-08,0.0021032,320.15401717987135,49.83188801480947,5.140036467271932
1.5298802797725813e-08,0.0021119999999999997,320.22047617152356,49.83188801480947,5.140036467271932
1.5374137811502492e-08,0.0021224,320.2988795431456,49.83188801480947,5.140036467271932
1.5687067868728702e-08,0.0021655999999999997,320.62296412004054,49.83188801480947,5.140036467271932
1.575660788144564e-08,0.0021752,320.6946393688199,49.83188801480947,5.140036467271932
1.599999792595491e-08,0.0022088,320.9445369580307,49.83188801480947,5.140036467271932
1.6179642958806996e-08,0.0022336,321.12803524445343,49.83188801480947,5.140036467271932
1.637087799377857e-08,0.00226,321.3225011444408,49.83188801480947,5.140036467271932
1.6452008008614993e-08,0.0022711999999999997,321.4047339483832,49.83188801480947,5.140036467271932
1.6515753020272183e-08,0.00228,321.46923454126284,49.83188801480947,5.140036467271932
1.6579498031929373e-08,0.0022887999999999997,321.53363811652525,49.83188801480947,5.140036467271932
1.6747553062661967e-08,0.002312,321.70296814103153,49.83188801480947,5.140036467271932
1.6788118070080183e-08,0.0023176,321.7437414659673,49.83188801480947,5.140036467271932
1.6921403094454307e-08,0.002336,321.8774412493138,49.83188801480947,5.140036467271932
1.7008328110350477e-08,0.002348,321.96441554384285,49.83188801480947,5.140036467271932
1.7356028173935154e-08,0.0023959999999999997,322.3105930349507,49.83188801480947,5.140036467271932
1.7518288203608004e-08,0.0024184,322.4712159184837,49.83188801480947,5.140036467271932
1.770952323857958e-08,0.0024448,322.65977847132376,49.83188801480947,5.140036467271932
1.781383325765498e-08,0.0024592,322.76229600446646,49.83188801480947,5.140036467271932
1.7929733278849874e-08,0.0024752,322.8759301877169,49.83188801480947,5.140036467271932
1.8034043297925276e-08,0.0024896,322.9779562518917,49.83188801480947,5.140036467271932
1.820209832865787e-08,0.0025128,323.1418488136545,49.83188801480947,5.140036467271932
1.827743334243455e-08,0.0025231999999999997,323.2151262171446,49.83188801480947,5.140036467271932
1.835276835621123e-08,0.0025336,323.2882859227122,49.83188801480947,5.140036467271932
1.8486053380585358e-08,0.002552,323.4174360611817,49.83188801480947,5.140036467271932
1.8659903412377694e-08,0.0025759999999999997,323.5853483075031,49.83188801480947,5.140036467271932
1.8775803433572587e-08,0.0025919999999999997,323.69695097591733,49.83188801480947,5.140036467271932
1.8868523450528502e-08,0.0026048,323.78603978702546,49.83188801480947,5.140036467271932
1.9042373482320842e-08,0.0026287999999999997,323.9526224722088,49.83188801480947,5.140036467271932
1.927996852577037e-08,0.0026616,324.179329420071,49.83188801480947,5.140036467271932
1.9436433554383476e-08,0.0026831999999999997,324.328029471924,49.83188801480947,5.140036467271932
1.947699856180169e-08,0.0026888,324.36650503860255,49.83188801480947,5.140036467271932
1.952915357133939e-08,0.002696,324.4159277341249,49.83188801480947,5.140036467271932
1.9563923577697855e-08,0.0027007999999999997,324.4488476031746,49.83188801480947,5.140036467271932
1.9645053592534283e-08,0.002712,324.5255720233703,49.83188801480947,5.140036467271932
1.972618360737071e-08,0.0027232,324.60217296876374,49.83188801480947,5.140036467271932
1.98420836285656e-08,0.0027392,324.711390096604,49.83188801480947,5.140036467271932
2.0189783692150277e-08,0.0027871999999999997,325.0375583524328,49.83188801480947,5.140036467271932
2.023034869956849e-08,0.0027928,325.07546808544413,49.83188801480947,5.140036467271932
2.0299888712285428e-08,0.0028024,325.1403872998261,49.83188801480947,5.140036467271932
2.0409993732420575e-08,0.0028176,325.24299895871735,49.83188801480947,5.140036467271932
2.0491123747256997e-08,0.0028288,325.3184694598784,49.83188801480947,5.140036467271932
2.0635998773750614e-08,0.0028488,325.452948998511,49.83188801480947,5.140036467271932
2.08156438066027e-08,0.0028736,325.6191933553056,49.83188801480947,5.140036467271932
2.103005884581325e-08,0.0029032,325.8168833449512,49.83188801480947,5.140036467271932
2.105903385111197e-08,0.0029072,325.84353779060086,49.83188801480947,5.140036467271932
2.1250268886083543e-08,0.0029335999999999997,326.01909978853166,49.83188801480947,5.140036467271932
2.1348783904099203e-08,0.0029472,326.109300282376,49.83188801480947,5.140036467271932
2.1493658930592818e-08,0.0029671999999999997,326.24165373375814,49.83188801480947,5.140036467271932
2.1742843976161834e-08,0.0030015999999999997,326.46849068534686,49.83188801480947,5.140036467271932
2.1812383988878772e-08,0.0030112,326.5316127788393,49.83188801480947,5.140036467271932
2.1881924001595707e-08,0.0030207999999999997,326.5946564375762,49.83188801480947,5.140036467271932
2.1928284010073664e-08,0.0030272,326.63664213963835,49.83188801480947,5.140036467271932
2.221223906200115e-08,0.0030664,326.8930532563595,49.83188801480947,5.140036467271932
2.2310754080016812e-08,0.00308,326.9817131033546,49.83188801480947,5.140036467271932
2.2548349123466338e-08,0.0031127999999999998,327.19491398196254,49.83188801480947,5.140036467271932
2.2704814152079446e-08,0.0031344,327.3348362729238,49.83188801480947,5.140036467271932
2.2948204196588717e-08,0.003168,327.5517480157429,49.83188801480947,5.140036467271932
2.3006154207186165e-08,0.003176,327.6032612014127,49.83188801480947,5.140036467271932
2.3035129212484887e-08,0.0031799999999999997,327.62899881564687,49.83188801480947,5.140036467271932
2.311046422626157e-08,0.0031904,327.695857592431,49.83188801480947,5.140036467271932
2.3434984285607267e-08,0.0032351999999999997,327.9828983585105,49.83188801480947,5.140036467271932
2.3545089305742414e-08,0.0032503999999999996,328.07993443718505,49.83188801480947,5.140036467271932
2.3689964332236032e-08,0.0032703999999999997,328.20734429129004,49.83188801480947,5.140036467271932
2.370155433435552e-08,0.0032719999999999997,328.217523933539,49.83188801480947,5.140036467271932
2.3805864353430924e-08,0.0032863999999999997,328.3090535192763,49.83188801480947,5.140036467271932
2.3881199367207604e-08,0.0032968,328.37506097375274,49.83188801480947,5.140036467271932
2.395073937992454e-08,0.0033063999999999997,328.43591888979745,49.83188801480947,5.140036467271932
2.400289438946224e-08,0.0033136,328.48151711339074,49.83188801480947,5.140036467271932
2.407822940323892e-08,0.0033239999999999997,328.5473130558967,49.83188801480947,5.140036467271932
2.4159359418075346e-08,0.0033352,328.618080502797,49.83188801480947,5.140036467271932
2.4205719426553303e-08,0.0033415999999999997,328.65847743110936,49.83188801480947,5.140036467271932
2.4281054440329983e-08,0.003352,328.7240581429027,49.83188801480947,5.140036467271932
2.441433946470411e-08,0.0033704,328.839891493021,49.83188801480947,5.140036467271932
2.4460699473182065e-08,0.0033767999999999997,328.88012351024355,49.83188801480947,5.140036467271932
2.4611369500735428e-08,0.0033975999999999998,329.0106726683829,49.83188801480947,5.140036467271932
2.4848964544184954e-08,0.0034303999999999997,329.2159071251685,49.83188801480947,5.140036467271932
2.5161894601411167e-08,0.0034736,329.48505191357503,49.83188801480947,5.140036467271932
2.5329949632143762e-08,0.0034968,329.62905371102283,49.83188801480947,5.140036467271932
2.5509594664995844e-08,0.0035215999999999997,329.7825752453768,49.83188801480947,5.140036467271932
2.559072467983227e-08,0.0035328,329.85176928511817,49.83188801480947,5.140036467271932
2.570082969996742e-08,0.003548,329.9455387975444,49.83188801480947,5.140036467271932
2.5764574711624605e-08,0.0035567999999999997,329.9997548015809,49.83188801480947,5.140036467271932
2.5915244739177968e-08,0.0035776,330.1276941863316,49.83188801480947,5.140036467271932
2.597898975083516e-08,0.0035864,330.1817350216203,49.83188801480947,5.140036467271932
2.601955475825337e-08,0.0035919999999999997,330.21609772018326,49.83188801480947,5.140036467271932
2.6158634783687243e-08,0.0036111999999999997,330.33375439485275,49.83188801480947,5.140036467271932
2.6332484815479583e-08,0.0036352,330.4804827235304,49.83188801480947,5.140036467271932
2.6390434826077027e-08,0.0036431999999999997,330.529308147449,49.83188801480947,5.140036467271932
2.6465769839853707e-08,0.0036536,330.59271873294404,49.83188801480947,5.140036467271932
2.65816698610486e-08,0.0036696,330.69013619650593,49.83188801480947,5.140036467271932
2.659325986316809e-08,0.0036712,330.6998688230368,49.83188801480947,5.140036467271932
2.6639619871646044e-08,0.0036775999999999996,330.7387827978676,49.83188801480947,5.140036467271932
2.6662799875885024e-08,0.0036807999999999997,330.7582298805036,49.83188801480947,5.140036467271932
2.6888804917215067e-08,0.003712,330.9474946570959,49.83188801480947,5.140036467271932
2.714378496384383e-08,0.0037472,331.1602809046529,49.83188801480947,5.140036467271932
2.717275996914255e-08,0.0037511999999999997,331.18441173374777,49.83188801480947,5.140036467271932
2.723070997974e-08,0.0037592,331.23264330740096,49.83188801480947,5.140036467271932
2.725388998397898e-08,0.0037624,331.25192472634797,49.83188801480947,5.140036467271932
2.759579504650391e-08,0.0038096,331.53558687233016,49.83188801480947,5.140036467271932
2.7665335059220845e-08,0.0038192,331.5931127644618,49.83188801480947,5.140036467271932
2.7966675114327565e-08,0.0038607999999999997,331.84174280625007,49.83188801480947,5.140036467271932
2.805939513128348e-08,0.0038735999999999996,331.91803387322204,49.83188801480947,5.140036467271932
2.819847515671735e-08,0.0038927999999999996,332.03228638618486,49.83188801480947,5.140036467271932
2.844766020228637e-08,0.0039272,332.2364407018734,49.83188801480947,5.140036467271932
2.8528790217122794e-08,0.0039384,332.30275889344125,49.83188801480947,5.140036467271932
2.8557765222421516e-08,0.0039423999999999996,332.3264261314866,49.83188801480947,5.140036467271932
2.8679460244676153e-08,0.0039591999999999995,332.4257264382354,49.83188801480947,5.140036467271932
2.87895652648113e-08,0.0039743999999999995,332.5154280634692,49.83188801480947,5.140036467271932
2.8847515275408748e-08,0.0039824,332.5625857000437,49.83188801480947,5.140036467271932
2.885910527752824e-08,0.003984,332.5720127923302,49.83188801480947,5.140036467271932
2.8963415296603644e-08,0.0039984,332.6567902828346,49.83188801480947,5.140036467271932
3.370467209683437e-08,0.004652930586117224,336.393098295311,49.83188801480947,5.140036467271932
3.704326042491289e-08,0.005113822764552911,338.9017143586338,49.83188801480947,5.140036467271932
3.843433889494561e-08,0.0053058611722344474,339.92074712911705,49.83188801480947,5.140036467271932
3.99645252119816e-08,0.0055171034206841375,341.02520891917493,49.83188801480947,5.140036467271932
4.413776062207975e-08,0.006093218643728746,343.9565528999993,49.83188801480947,5.140036467271932
4.5528839092112466e-08,0.006285257051410282,344.9093651724138,49.83188801480947,5.140036467271932
4.8310996032177895e-08,0.006669333866773355,346.7815871804278,49.83188801480947,5.140036467271932
5.192780005426296e-08,0.007168633726745349,349.1537492054126,49.83188801480947,5.140036467271932
5.6379251158367654e-08,0.007783156631326265,351.98660225833964,49.83188801480947,5.140036467271932
6.444750628455741e-08,0.008896979395879176,356.90794363464965,49.83188801480947,5.140036467271932
7.098557509371119e-08,0.009799559911982397,360.72159154382604,49.83188801480947,5.140036467271932
7.293308495175699e-08,0.010068413682736548,361.830749555569,49.83188801480947,5.140036467271932
7.460237911579624e-08,0.01029885977195439,362.7722933685307,49.83188801480947,5.140036467271932
7.52979183508126e-08,0.01039487897579516,363.16217407750645,49.83188801480947,5.140036467271932
7.808007529087804e-08,0.010778955791158232,364.7078526569789,49.83188801480947,5.140036467271932
8.07231243839402e-08,0.01114382876575315,366.15646851579885,49.83188801480947,5.140036467271932
8.169687931296311e-08,0.011278255651130227,366.6854907314187,49.83188801480947,5.140036467271932
8.447903625302854e-08,0.0116623324664933,368.18359939326314,49.83188801480947,5.140036467271932
9.046067367416922e-08,0.012488097619523904,371.3408695457573,49.83188801480947,5.140036467271932
9.672052678931644e-08,0.013352270454090818,374.5589583051436,49.83188801480947,5.140036467271932
9.852892880035898e-08,0.013601920384076815,375.4733674381055,49.83188801480947,5.140036467271932
1.0534521330351929e-07,0.014542908581716344,378.8626875833754,49.83188801480947,5.140036467271932
1.0576253684452911e-07,0.014600520104020805,379.067373824106,49.83188801480947,5.140036467271932
1.0771004670257492e-07,0.014869373874774956,380.0184422217913,49.83188801480947,5.140036467271932
1.1174417426566979e-07,0.015426285257051411,381.9674384283859,49.83188801480947,5.140036467271932
1.1230060565368288e-07,0.015503100620124026,382.23409575498084,49.83188801480947,5.140036467271932
1.1508276259374832e-07,0.0158871774354871,383.55973041315804,49.83188801480947,5.140036467271932
1.166129489107843e-07,0.01609841968393679,384.28349986576717,49.83188801480947,5.140036467271932
1.2189904709690863e-07,0.016828165633126627,386.7557804378423,49.83188801480947,5.140036467271932
1.2551585111899366e-07,0.017327465493098618,388.423294573744,49.83188801480947,5.140036467271932
1.298281943760951e-07,0.017922784556911382,390.3871871155221,49.83188801480947,5.140036467271932
1.319148120811442e-07,0.01821084216843369,391.32831001320255,49.83188801480947,5.140036467271932
1.3636626318524888e-07,0.018825365073014605,393.3168509600596,49.83188801480947,5.140036467271932
1.3845288089029795e-07,0.019113422684536908,394.24024925617687,49.83188801480947,5.140036467271932
1.406786064423503e-07,0.019420684136827366,395.2192452280163,49.83188801480947,5.140036467271932
1.4193057706537975e-07,0.01959351870374075,395.7672754449649,49.83188801480947,5.140036467271932
1.4346076338241574e-07,0.01980476095219044,396.43453649645954,49.83188801480947,5.140036467271932
1.4832953802753024e-07,0.020476895379075814,398.5394061584116,49.83188801480947,5.140036467271932
1.504161557325793e-07,0.02076495299059812,399.43322478168915,49.83188801480947,5.140036467271932
1.5361563621365455e-07,0.021206641328265653,400.7944113119702,49.83188801480947,5.140036467271932
1.554240382246971e-07,0.02145629125825165,401.5588858306755,49.83188801480947,5.140036467271932
1.5723244023573961e-07,0.021705941188237647,402.31989911420493,49.83188801480947,5.140036467271932
1.6001459717580506e-07,0.02209001800360072,403.48405685458755,49.83188801480947,5.140036467271932
1.6377050904489342e-07,0.02260852170434087,405.043224222743,49.83188801480947,5.140036467271932
1.6655266598495884e-07,0.022992598519703943,406.18918676690436,49.83188801480947,5.140036467271932
1.67665528760985e-07,0.02314622924584917,406.64547845560526,49.83188801480947,5.140036467271932
1.6850017584300465e-07,0.023261452290458094,406.98692249472083,49.83188801480947,5.140036467271932
1.7030857785404717e-07,0.02351110222044409,407.7244632748252,49.83188801480947,5.140036467271932
1.7267341125310277e-07,0.0238375675135027,408.68434747900227,49.83188801480947,5.140036467271932
1.7545556819316822e-07,0.024221644328865772,409.80708362221844,49.83188801480947,5.140036467271932
1.769857545102042e-07,0.024432886577315464,410.4216282619668,49.83188801480947,5.140036467271932
1.8227185269632853e-07,0.025162632526505302,412.5288373656117,49.83188801480947,5.140036467271932
1.8408025470737104e-07,0.025412282456491297,413.24423531117395,49.83188801480947,5.140036467271932
1.8547133317740377e-07,0.025604320864172834,413.7926778701717,49.83188801480947,5.140036467271932
1.8755795088245287e-07,0.02589237847569514,414.61234329553173,49.83188801480947,5.140036467271932
1.8839259796447248e-07,0.026007601520304062,414.93921274582175,49.83188801480947,5.140036467271932
1.8908813719948883e-07,0.02610362072414483,415.2111727502175,49.83188801480947,5.140036467271932
1.921485098335608e-07,0.02652610522104421,416.40319172942424,49.83188801480947,5.140036467271932
1.9451334323261644e-07,0.026852570514102822,417.3192330035936,49.83188801480947,5.140036467271932
1.9534799031463608e-07,0.026967793558711744,417.64150334354196,49.83188801480947,5.140036467271932
1.9701728447867533e-07,0.027198239647929588,418.2844375124838,49.83188801480947,5.140036467271932
1.9840836294870806e-07,0.027390278055611124,418.81859469332994,49.83188801480947,5.140036467271932
1.9993854926574405e-07,0.027601520304060812,419.4044834550121,49.83188801480947,5.140036467271932
2.0091230419476695e-07,0.02773594718943789,419.776411430024,49.83188801480947,5.140036467271932
2.055028631458749e-07,0.028369673934786958,421.5204036905921,49.83188801480947,5.140036467271932
2.0675483376890435e-07,0.028542508501700342,421.9933925600348,49.83188801480947,5.140036467271932
2.0884145147395343e-07,0.028830566113222645,422.77923263575053,49.83188801480947,5.140036467271932
2.123191476490352e-07,0.029310662132426484,424.08219520144814,49.83188801480947,5.140036467271932
2.163532752121301e-07,0.02986757351470294,425.5832494262705,49.83188801480947,5.140036467271932
2.18857216458189e-07,0.030213242648529707,426.5094497445532,49.83188801480947,5.140036467271932
2.1983097138721188e-07,0.03034766953390678,426.8685215351254,49.83188801480947,5.140036467271932
2.2497796172633296e-07,0.031058211642328467,428.75626590547614,49.83188801480947,5.140036467271932
2.2817744220740817e-07,0.031499899979996,429.9212426857037,49.83188801480947,5.140036467271932
2.2887298144242452e-07,0.031595919183836765,430.173653501776,49.83188801480947,5.140036467271932
2.3123781484148018e-07,0.03192238447689538,431.0296214120343,49.83188801480947,5.140036467271932
2.324897854645096e-07,0.03209521904380876,431.4813984126275,49.83188801480947,5.140036467271932
2.3888874642666007e-07,0.03297859571914383,433.7758278827107,49.83188801480947,5.140036467271932
2.404189327436961e-07,0.03318983796759352,434.32092934246987,49.83188801480947,5.140036467271932
2.4222733475473863e-07,0.033439487897579515,434.96339879458196,49.83188801480947,5.140036467271932
2.4306198183675827e-07,0.03355471094218844,435.25929197263343,49.83188801480947,5.140036467271932
2.4598324662382696e-07,0.033957991598319665,436.2918119082616,49.83188801480947,5.140036467271932
2.466787858588433e-07,0.03405401080216043,436.5369437943249,49.83188801480947,5.140036467271932
2.477916486348695e-07,0.03420764152830566,436.9285948741292,49.83188801480947,5.140036467271932
2.514084526569545e-07,0.03470694138827765,438.19674935159946,49.83188801480947,5.140036467271932
2.5822473716011487e-07,0.035647929585917185,440.5675578004237,49.83188801480947,5.140036467271932
2.632326196522326e-07,0.03633926785357071,442.2938513953576,49.83188801480947,5.140036467271932
2.6504102166327523e-07,0.03658891778355672,442.91408129097556,49.83188801480947,5.140036467271932
2.661538844393014e-07,0.03674254850970195,443.29494097999856,49.83188801480947,5.140036467271932
2.66988531521321e-07,0.03685777155431086,443.58017830542207,49.83188801480947,5.140036467271932
2.707444433904093e-07,0.03737627525505101,444.85946696029964,49.83188801480947,5.140036467271932
2.7909091421060566e-07,0.038528505701140234,447.67780722188087,49.83188801480947,5.140036467271932
2.8048199268063836e-07,0.03872054410882177,448.1443162025209,49.83188801480947,5.140036467271932
2.8242950253868417e-07,0.03898939787957592,448.79591568461774,49.83188801480947,5.140036467271932
2.856289830197594e-07,0.03943108621724345,449.8626092162727,49.83188801480947,5.140036467271932
2.8632452225477574e-07,0.039527105421084216,450.09388131960964,49.83188801480947,5.140036467271932
2.882720321128216e-07,0.03979595919183837,450.7402804754253,49.83188801480947,5.140036467271932
2.898022184298576e-07,0.04000720144028806,451.24697150698995,49.83188801480947,5.140036467271932
2.959229636980015e-07,0.040852170434086815,453.2633878695044,49.83188801480947,5.140036467271932
2.973140421680342e-07,0.04104420884176835,453.7193881137638,49.83188801480947,5.140036467271932
2.9842690494406036e-07,0.04119783956791358,454.083589495181,49.83188801480947,5.140036467271932
2.991224441790768e-07,0.04129385877175436,454.3109464036006,49.83188801480947,5.140036467271932
3.0093084619011933e-07,0.04154350870174035,454.90111153857,49.83188801480947,5.140036467271932
3.04408542365201e-07,0.042023604720944185,456.032171399815,49.83188801480947,5.140036467271932
3.0621694437624354e-07,0.04227325465093018,456.6183302758329,49.83188801480947,5.140036467271932
3.099728562453319e-07,0.04279175835167033,457.83144098274306,49.83188801480947,5.140036467271932
3.1066839548034827e-07,0.0428877775555111,458.0554606127733,49.83188801480947,5.140036467271932
3.1219858179738426e-07,0.04309901980396079,458.5476164307113,49.83188801480947,5.140036467271932
3.153980622784596e-07,0.04354070814162833,459.5736398831209,49.83188801480947,5.140036467271932
3.185975427595348e-07,0.04398239647929586,460.59561205408767,49.83188801480947,5.140036467271932
3.215188075466035e-07,0.044385677135427085,461.5252267997254,49.83188801480947,5.140036467271932
3.23327209557646e-07,0.04463532706541308,462.0990520877417,49.83188801480947,5.140036467271932
3.2597025865070816e-07,0.045000200040008,462.9354733713835,49.83188801480947,5.140036467271932
3.272222292737377e-07,0.04517303460692139,463.33074938747836,49.83188801480947,5.140036467271932
3.281959842027605e-07,0.04530746149229846,463.63777865765,49.83188801480947,5.140036467271932
3.2986527836679983e-07,0.04553790758151631,464.16328928381995,49.83188801480947,5.140036467271932
3.336211902358881e-07,0.046056411282256446,465.3419108546066,49.83188801480947,5.140036467271932
3.347340530119143e-07,0.046210042008401675,465.6901367762652,49.83188801480947,5.140036467271932
3.3626423932895027e-07,0.04642128425685137,466.1682110878391,49.83188801480947,5.140036467271932
3.389072884220124e-07,0.04678615723144629,466.9919822159095,49.83188801480947,5.140036467271932
3.409939061270616e-07,0.0470742148429686,467.6405593538474,49.83188801480947,5.140036467271932
3.4530624938416296e-07,0.04766953390678136,468.97606772948313,49.83188801480947,5.140036467271932
3.4669732785419566e-07,0.04786157231446289,469.4054872444683,49.83188801480947,5.140036467271932
3.536527202043592e-07,0.04882176435287057,471.54258718405026,49.83188801480947,5.140036467271932
3.635293773415916e-07,0.05018523704740949,474.5493154491306,49.83188801480947,5.140036467271932
3.6603331858765046e-07,0.05053090618123625,475.30650117218414,49.83188801480947,5.140036467271932
3.7048476969175514e-07,0.051145429085817165,476.6476400425013,49.83188801480947,5.140036467271932
3.717367403147846e-07,0.05131826365273055,477.0237011431931,49.83188801480947,5.140036467271932
3.7368425017283036e-07,0.051587117423484694,477.60770476895266,49.83188801480947,5.140036467271932
3.747971129488565e-07,0.05174074814962992,477.94088817084446,49.83188801480947,5.140036467271932
3.79109456205958e-07,0.052336067213442694,479.22834600080137,49.83188801480947,5.140036467271932
3.8370001515706593e-07,0.052969793958791755,480.5926054230745,49.83188801480947,5.140036467271932
3.868994956381412e-07,0.0534114822964593,481.5396909045395,49.83188801480947,5.140036467271932
3.882905741081739e-07,0.05360352070414083,481.9505139512059,49.83188801480947,5.140036467271932
3.9315934875328845e-07,0.05427565513102621,483.3838960915213,49.83188801480947,5.140036467271932
3.953850743053408e-07,0.05458291658331667,484.03684915229326,49.83188801480947,5.140036467271932
3.971934763163833e-07,0.054832566513302664,484.5663186242184,49.83188801480947,5.140036467271932
3.9928009402143235e-07,0.05512062412482496,485.17607811025965,49.83188801480947,5.140036467271932
4.019231431144945e-07,0.055485497099419884,485.9466590236305,49.83188801480947,5.140036467271932
4.024795745025077e-07,0.055562312462492505,486.1086344771647,49.83188801480947,5.140036467271932
4.0553994713657955e-07,0.055984796959391875,486.997943281221,49.83188801480947,5.140036467271932
4.066528099126057e-07,0.056138427685537104,487.3206788842207,49.83188801480947,5.140036467271932
4.1026961393469086e-07,0.05663772754550911,488.36719873183966,49.83188801480947,5.140036467271932
4.166685748968413e-07,0.057521104220844166,490.20996206961735,49.83188801480947,5.140036467271932
4.1722500628485445e-07,0.05759791958391679,490.369678918657,49.83188801480947,5.140036467271932
4.1958983968391e-07,0.05792438487697539,491.0475508459714,49.83188801480947,5.140036467271932
4.237630750940082e-07,0.05850050010002,492.24017181193085,49.83188801480947,5.140036467271932
4.2543236925804746e-07,0.058730946189237854,492.71593658538256,49.83188801480947,5.140036467271932
4.269625555750834e-07,0.05894218843768753,493.15141511611563,49.83188801480947,5.140036467271932
4.297447125151489e-07,0.05932626525305061,493.94163804041494,49.83188801480947,5.140036467271932
4.3544813424228303e-07,0.060113622724544916,495.55538483991023,49.83188801480947,5.140036467271932
4.387867225703616e-07,0.0605745149029806,496.4961922269073,49.83188801480947,5.140036467271932
4.4421192860348915e-07,0.06132346469293859,498.01907173746025,49.83188801480947,5.140036467271932
4.4560300707352185e-07,0.06151550310062012,498.40838310710996,49.83188801480947,5.140036467271932
4.4615943846153496e-07,0.061592318463692744,498.5639749044604,49.83188801480947,5.140036467271932
4.483851640135873e-07,0.0618995799159832,499.18558679978975,49.83188801480947,5.140036467271932
4.4949802678961346e-07,0.06205321064212843,499.4959413950222,49.83188801480947,5.140036467271932
4.5088910525964616e-07,0.062245249049809964,499.883463558017,49.83188801480947,5.140036467271932
4.5186286018866904e-07,0.062379675935187034,500.1544516854723,49.83188801480947,5.140036467271932
4.525583994236854e-07,0.0624756951390278,500.3478752137613,49.83188801480947,5.140036467271932
4.54366801434728e-07,0.06272534506901381,500.8502345824494,49.83188801480947,5.140036467271932
4.5561877205775737e-07,0.06289817963592718,501.19756514265504,49.83188801480947,5.140036467271932
4.6076576239687845e-07,0.06360872174434887,502.6215865230894,49.83188801480947,5.140036467271932
4.629914879489308e-07,0.06391598319663933,503.2354566731029,49.83188801480947,5.140036467271932
4.647998899599733e-07,0.06416563312662532,503.7333791630302,49.83188801480947,5.140036467271932
4.679993704410486e-07,0.06460732146429286,504.61247206462303,49.83188801480947,5.140036467271932
4.6883401752306816e-07,0.06472254450890177,504.8414147813129,49.83188801480947,5.140036467271932
4.7119885092212384e-07,0.06504900980196039,505.4892241960347,49.83188801480947,5.140036467271932
4.7592851772023505e-07,0.06570194038807761,506.7810516078477,49.83188801480947,5.140036467271932
4.7634584126124487e-07,0.06575955191038207,506.8947954561896,49.83188801480947,5.140036467271932
4.766240569552514e-07,0.06579795959191838,506.97060309829345,49.83188801480947,5.140036467271932
4.791279982013103e-07,0.06614362872574515,507.65209704329305,49.83188801480947,5.140036467271932
4.858051748574674e-07,0.06706541308261653,509.4626576407863,49.83188801480947,5.140036467271932
4.895610867265558e-07,0.06758391678335668,510.47683241162025,49.83188801480947,5.140036467271932
4.912303808905949e-07,0.06781436287257452,510.9266022474806,49.83188801480947,5.140036467271932
4.947080770656768e-07,0.06829445889177836,511.8617127677675,49.83188801480947,5.140036467271932
4.97907557546752e-07,0.06873614722944589,512.71975266293,49.83188801480947,5.140036467271932
4.997159595577945e-07,0.06898579715943189,513.2037805093997,49.83188801480947,5.140036467271932
5.011070380278273e-07,0.06917783556711343,513.5756449139257,49.83188801480947,5.140036467271932
5.034718714268829e-07,0.06950430086017204,514.20689176958,49.83188801480947,5.140036467271932
5.054193812849287e-07,0.06977315463092619,514.725874317337,49.83188801480947,5.140036467271932
5.059758126729418e-07,0.0698499699939988,514.8740117210166,49.83188801480947,5.140036467271932
5.097317245420301e-07,0.07036847369473895,515.872282567816,49.83188801480947,5.140036467271932
5.158524698101741e-07,0.07121344268853771,517.4929695006671,49.83188801480947,5.140036467271932
5.225296464663312e-07,0.07213522704540909,519.252462012569,49.83188801480947,5.140036467271932
5.251726955593933e-07,0.07250010002000401,519.9465027057064,49.83188801480947,5.140036467271932
5.336582742265929e-07,0.07367153430686138,522.1655871971248,49.83188801480947,5.140036467271932
5.357448919316419e-07,0.07395959191838368,522.7091504735823,49.83188801480947,5.140036467271932
5.458997647628808e-07,0.0753614722944589,525.3427952181994,49.83188801480947,5.140036467271932
5.488210295499495e-07,0.07576475295059013,526.0968712407566,49.83188801480947,5.140036467271932
5.524378335720345e-07,0.07626405281056212,527.0283238628629,49.83188801480947,5.140036467271932
5.541071277360738e-07,0.07649449889977997,527.4574226341441,49.83188801480947,5.140036467271932
5.556373140531098e-07,0.07670574114822964,527.8503204993158,49.83188801480947,5.140036467271932
5.559155297471164e-07,0.07674414882976596,527.9217111145297,49.83188801480947,5.140036467271932
5.589759023811882e-07,0.07716663332666533,528.7060904470727,49.83188801480947,5.140036467271932
5.606451965452276e-07,0.07739707941588318,529.1332277345189,49.83188801480947,5.140036467271932
5.644011084143159e-07,0.07791558311662333,530.0924773136629,49.83188801480947,5.140036467271932
5.656530790373452e-07,0.0780884176835367,530.4116735145197,49.83188801480947,5.140036467271932
5.714956086114828e-07,0.07889497899579917,531.897627865262,49.83188801480947,5.140036467271932
5.75251520480571e-07,0.0794134826965393,532.8497565909629,49.83188801480947,5.140036467271932
5.769208146446103e-07,0.07964392878575716,533.2721463659979,49.83188801480947,5.140036467271932
5.819286971367281e-07,0.08033526705341068,534.5364650560333,49.83188801480947,5.140036467271932
5.826242363717445e-07,0.08043128625725146,534.7117286802614,49.83188801480947,5.140036467271932
5.859628246998231e-07,0.08089217843568715,535.5518608491661,49.83188801480947,5.140036467271932
5.888840894868918e-07,0.08129545909181837,536.2854462990676,49.83188801480947,5.140036467271932
5.923617856619735e-07,0.0817755551110222,537.1569144117564,49.83188801480947,5.140036467271932
5.954221582960455e-07,0.08219803960792159,537.9221571315638,49.83188801480947,5.140036467271932
5.991780701651338e-07,0.08271654330866174,538.8592253562405,49.83188801480947,5.140036467271932
6.016820114111927e-07,0.0830622124424885,539.482665132435,49.83188801480947,5.140036467271932
6.054379232802811e-07,0.08358071614322865,540.4159309306863,49.83188801480947,5.140036467271932
6.087765116083595e-07,0.08404160832166434,541.243606634077,49.83188801480947,5.140036467271932
6.122542077834414e-07,0.08452170434086818,542.1038886174076,49.83188801480947,5.140036467271932
6.151754725705101e-07,0.08492498499699941,542.8250537248615,49.83188801480947,5.140036467271932
6.190704922866017e-07,0.0854626925385077,543.7845330561586,49.83188801480947,5.140036467271932
6.233828355437032e-07,0.08605801160232047,544.8440717091751,49.83188801480947,5.140036467271932
6.272778552597947e-07,0.08659571914382877,545.7986199418807,49.83188801480947,5.140036467271932
6.281125023418143e-07,0.0867109421884377,546.0028649312821,49.83188801480947,5.140036467271932
6.293644729648437e-07,0.08688377675535107,546.3090340632862,49.83188801480947,5.140036467271932
6.313119828228896e-07,0.08715263052610522,546.7848254545103,49.83188801480947,5.140036467271932
6.333986005279387e-07,0.08744068813762754,547.2939671766256,49.83188801480947,5.140036467271932
6.365980810090139e-07,0.08788237647529507,548.0733825135787,49.83188801480947,5.140036467271932
6.379891594790466e-07,0.0880744148829766,548.4117820712521,49.83188801480947,5.140036467271932
6.385455908670598e-07,0.08815123024604922,548.5470613064737,49.83188801480947,5.140036467271932
6.396584536430859e-07,0.08830486097219445,548.8174819329436,49.83188801480947,5.140036467271932
6.413277478071252e-07,0.08853530706141229,549.2227690952708,49.83188801480947,5.140036467271932
6.434143655121741e-07,0.08882336467293458,549.7287999623782,49.83188801480947,5.140036467271932
6.455009832172233e-07,0.0891114222844569,550.2341912124173,49.83188801480947,5.140036467271932
6.470311695342593e-07,0.08932266453290659,550.6044066142784,49.83188801480947,5.140036467271932
6.477267087692756e-07,0.08941868373674736,550.7725734480056,49.83188801480947,5.140036467271932
6.492568950863117e-07,0.08962992598519705,551.1422927812927,49.83188801480947,5.140036467271932
6.500915421683312e-07,0.08974514902980596,551.3438146317625,49.83188801480947,5.140036467271932
6.535692383434131e-07,0.0902252450490098,552.1824051829536,49.83188801480947,5.140036467271932
6.562122874364752e-07,0.09059011802360473,552.8185706286815,49.83188801480947,5.140036467271932
6.574642580595047e-07,0.09076295259051811,553.1195633004721,49.83188801480947,5.140036467271932
6.589944443765406e-07,0.09097419483896779,553.4871398406059,49.83188801480947,5.140036467271932
6.612201699285929e-07,0.09128145629125825,554.0212029698407,49.83188801480947,5.140036467271932
6.624721405516224e-07,0.09145429085817164,554.3213053690922,49.83188801480947,5.140036467271932
6.674800230437403e-07,0.09214562912582518,555.5195096864874,49.83188801480947,5.140036467271932
6.72487905535858e-07,0.0928369673934787,556.7142130936129,49.83188801480947,5.140036467271932
6.737398761588875e-07,0.09300980196039209,557.0123461828854,49.83188801480947,5.140036467271932
6.752700624759234e-07,0.09322104420884177,557.3764378155414,49.83188801480947,5.140036467271932
6.766611409459562e-07,0.09341308261652331,557.7071510856201,49.83188801480947,5.140036467271932
6.79165082192015e-07,0.09375875175035008,558.3017675611563,49.83188801480947,5.140036467271932
6.815299155910707e-07,0.09408521704340869,558.8625652348401,49.83188801480947,5.140036467271932
6.861204745421786e-07,0.09471894378875775,559.9490107871101,49.83188801480947,5.140036467271932
6.890417393292473e-07,0.09512222444488898,560.6389094604951,49.83188801480947,5.140036467271932
6.911283570342965e-07,0.09541028205641129,561.130996016847,49.83188801480947,5.140036467271932
6.922412198103226e-07,0.09556391278255652,561.3932052481543,49.83188801480947,5.140036467271932
6.93493190433352e-07,0.0957367473494699,561.687994206053,49.83188801480947,5.140036467271932
6.973882101494436e-07,0.0962744548909782,562.603790899485,49.83188801480947,5.140036467271932
6.979446415374567e-07,0.09635127025405081,562.7344559735401,49.83188801480947,5.140036467271932
6.996139357014959e-07,0.09658171634326866,563.1262076513588,49.83188801480947,5.140036467271932
7.005876906305189e-07,0.09671614322864573,563.3545611156645,49.83188801480947,5.140036467271932
7.039262789585973e-07,0.09717703540708142,564.1365492616455,49.83188801480947,5.140036467271932
7.061520045106498e-07,0.09748429685937188,564.6570712666002,49.83188801480947,5.140036467271932
7.096297006857315e-07,0.09796439287857572,565.4691077857258,49.83188801480947,5.140036467271932
7.126900733198035e-07,0.09838687737547509,566.1824169549932,49.83188801480947,5.140036467271932
7.140811517898363e-07,0.09857891578315664,566.5062533937167,49.83188801480947,5.140036467271932