File: datasets/aisi_316_L/data/M1/valid_28.csv
Time(s),Strain(%),Stress(MPa),Temp(C),Log_SR(s-1)
0.0,0.0,0.0,309.3852092767066,5.224184700162683
6.683952001672995e-11,1.12e-05,1.9811156749999999,309.3852092767066,5.224184700162683
8.593652573579564e-11,1.44e-05,2.547148725,309.3852092767066,5.224184700162683
1.9574430862042343e-10,3.28e-05,5.801838762499999,309.3852092767066,5.224184700162683
2.3871257148832123e-10,3.9999999999999996e-05,7.075413124999999,309.3852092767066,5.224184700162683
2.7213233149668624e-10,4.56e-05,8.0659709625,309.3852092767066,5.224184700162683
3.5806885723248184e-10,5.9999999999999995e-05,10.6131196875,309.3852092767066,5.224184700162683
3.8671436581108043e-10,6.48e-05,11.4621692625,309.3852092767066,5.224184700162683
4.249083772492118e-10,7.12e-05,12.5942353625,309.3852092767066,5.224184700162683
4.726508915468761e-10,7.92e-05,14.0093179875,309.3852092767066,5.224184700162683
6.349754401589346e-10,0.0001064,18.8205989125,309.3852092767066,5.224184700162683
7.113634630351973e-10,0.0001192,21.0847311125,309.3852092767066,5.224184700162683
7.782029830519273e-10,0.0001304,23.0658467875,309.3852092767066,5.224184700162683
7.972999887709929e-10,0.0001336,23.631879837499998,309.3852092767066,5.224184700162683
9.834957945318835e-10,0.0001648,29.150702074999998,309.3852092767066,5.224184700162683
1.0694323202676793e-09,0.0001792,31.697850799999998,309.3852092767066,5.224184700162683
1.0933035774165112e-09,0.00018319999999999998,32.405392112499996,309.3852092767066,5.224184700162683
1.136271840284409e-09,0.0001904,33.678966474999996,309.3852092767066,5.224184700162683
1.1935628574416061e-09,0.00019999999999999998,35.377065625,309.3852092767066,5.224184700162683
1.2890478860369348e-09,0.000216,38.207230875,309.3852092767066,5.224184700162683
1.336790400334599e-09,0.000224,39.6223135,309.3852092767066,5.224184700162683
1.480017943227592e-09,0.000248,43.867561375,309.3852092767066,5.224184700162683
1.5325347089550225e-09,0.0002568,45.4241522625,309.3852092767066,5.224184700162683
1.6900850061373145e-09,0.0002832,50.093924925,309.3852092767066,5.224184700162683
1.866732309038672e-09,0.00031279999999999996,55.32973063749999,309.3852092767066,5.224184700162683
1.9813143433530663e-09,0.000332,58.7259289375,309.3852092767066,5.224184700162683
2.1722844005437232e-09,0.00036399999999999996,64.38625943749999,309.3852092767066,5.224184700162683
2.2438981719902197e-09,0.000376,66.508883375,309.3852092767066,5.224184700162683
2.282092183428351e-09,0.00038239999999999997,67.640949475,309.3852092767066,5.224184700162683
2.5351275092059715e-09,0.00042479999999999997,75.1408873875,309.3852092767066,5.224184700162683
2.6449352920905994e-09,0.0004432,78.395577425,309.3852092767066,5.224184700162683
2.707000560677563e-09,0.00045359999999999997,80.2351848375,309.3852092767066,5.224184700162683
2.936164629306351e-09,0.0004919999999999999,87.02758143749999,309.3852092767066,5.224184700162683
3.079392172199344e-09,0.000516,91.2728293125,309.3852092767066,5.224184700162683
3.127134686497008e-09,0.0005239999999999999,92.68791193749999,309.3852092767066,5.224184700162683
3.1939742065137383e-09,0.0005352,94.6690276125,309.3852092767066,5.224184700162683
3.332427497976965e-09,0.0005584,98.77276722500001,309.3852092767066,5.224184700162683
3.5997855780438847e-09,0.0006032,106.697229925,309.3852092767066,5.224184700162683
3.743013120936877e-09,0.0006272,110.94247779999999,309.3852092767066,5.224184700162683
3.867143658110804e-09,0.0006479999999999999,114.62169262499998,309.3852092767066,5.224184700162683
3.938757429557301e-09,0.00066,116.7443165625,309.3852092767066,5.224184700162683
4.010371201003797e-09,0.000672,118.8669405,309.3852092767066,5.224184700162683
4.206115509624221e-09,0.0007048,124.6687792625,309.3852092767066,5.224184700162683
4.268180778211184e-09,0.0007151999999999999,126.50838667499998,309.3852092767066,5.224184700162683
4.282503532500483e-09,0.0007176,126.9329114625,309.3852092767066,5.224184700162683
4.40663406967441e-09,0.0007384,130.6121262875,309.3852092767066,5.224184700162683
4.5737328697162355e-09,0.0007664,135.564915475,309.3852092767066,5.224184700162683
4.6119268811543665e-09,0.0007727999999999999,136.696981575,309.3852092767066,5.224184700162683
4.645346641162732e-09,0.0007784,137.6875394125,309.3852092767066,5.224184700162683
4.659669395452031e-09,0.0007808,138.1120642,309.3852092767066,5.224184700162683
4.712186161179462e-09,0.0007896,139.6686550875,309.3852092767066,5.224184700162683
4.812445441204556e-09,0.0008064,142.6403286,309.3852092767066,5.224184700162683
4.864962206931987e-09,0.0008152,144.1969194875,309.3852092767066,5.224184700162683
5.003415498395214e-09,0.0008384,148.3006591,309.3852092767066,5.224184700162683
5.108449029850075e-09,0.000856,151.413840875,309.3852092767066,5.224184700162683
5.146643041288206e-09,0.0008623999999999999,152.54590697499998,309.3852092767066,5.224184700162683
5.199159807015637e-09,0.0008711999999999999,154.10249786249997,309.3852092767066,5.224184700162683
5.2421280698835345e-09,0.0008784,155.376072225,309.3852092767066,5.224184700162683
5.2755478298919e-09,0.0008839999999999999,156.36663006249998,309.3852092767066,5.224184700162683
5.375807109916995e-09,0.0009008,159.338303575,309.3852092767066,5.224184700162683
5.51426040138022e-09,0.0009239999999999999,163.4420431875,309.3852092767066,5.224184700162683
5.609745429975549e-09,0.00094,166.27220843749998,309.3852092767066,5.224184700162683
5.681359201422045e-09,0.0009519999999999999,168.394832375,309.3852092767066,5.224184700162683
5.7625214757280746e-09,0.0009655999999999999,170.8004728375,309.3852092767066,5.224184700162683
5.900974767191301e-09,0.0009888,174.90421245,309.3852092767066,5.224184700162683
5.948717281488965e-09,0.0009968,176.31929507499999,309.3852092767066,5.224184700162683
5.9582657843484986e-09,0.0009984,176.6023116,309.3852092767066,5.224184700162683
6.0871705729521915e-09,0.0010199999999999999,180.42303468749998,309.3852092767066,5.224184700162683
6.239946618704718e-09,0.0010456,184.95129908750002,309.3852092767066,5.224184700162683
6.3354316473000465e-09,0.0010616,187.7814643375,309.3852092767066,5.224184700162683
6.483433441622805e-09,0.0010864,192.168220475,309.3852092767066,5.224184700162683
6.521627453060936e-09,0.0010927999999999999,193.30028657499997,309.3852092767066,5.224184700162683
6.674403498813462e-09,0.0011183999999999999,197.82855097499998,309.3852092767066,5.224184700162683
6.712597510251594e-09,0.0011248,198.96061707500002,309.3852092767066,5.224184700162683
6.731694515970659e-09,0.0011279999999999999,199.52665012499997,309.3852092767066,5.224184700162683
6.765114275979025e-09,0.0011336,200.5172079625,309.3852092767066,5.224184700162683
6.936987327450614e-09,0.0011623999999999998,200.9433261746395,309.3852092767066,5.224184700162683
7.185248401798469e-09,0.001204,201.1965707355725,309.3852092767066,5.224184700162683
7.261636424674732e-09,0.0012167999999999999,201.27380253276687,309.3852092767066,5.224184700162683
7.280733430393798e-09,0.00122,201.29306089450475,309.3852092767066,5.224184700162683
7.548091510460718e-09,0.0012648,201.560642440864,309.3852092767066,5.224184700162683
7.595834024758382e-09,0.0012728,201.60803327925967,309.3852092767066,5.224184700162683
7.657899293345346e-09,0.0012832,201.66946805922623,309.3852092767066,5.224184700162683
7.739061567651374e-09,0.0012967999999999999,201.74951364053302,309.3852092767066,5.224184700162683
7.98732264199923e-09,0.0013384,201.99235064257053,309.3852092767066,5.224184700162683
7.996871144858763e-09,0.00134,202.00163127614897,309.3852092767066,5.224184700162683
8.21171245919825e-09,0.0013759999999999998,202.20931661332992,309.3852092767066,5.224184700162683
8.335842996372178e-09,0.0013968,202.32834659312044,309.3852092767066,5.224184700162683
8.42655377353774e-09,0.0014119999999999998,202.41489332404186,309.3852092767066,5.224184700162683
8.436102276397273e-09,0.0014135999999999999,202.42398231934152,309.3852092767066,5.224184700162683
8.459973533546105e-09,0.0014176,202.4466872722158,309.3852092767066,5.224184700162683
8.655717842166529e-09,0.0014504,202.63193468803658,309.3852092767066,5.224184700162683
8.751202870761857e-09,0.0014663999999999999,202.72170580293906,309.3852092767066,5.224184700162683
8.81326813934882e-09,0.0014768,202.77985224779545,309.3852092767066,5.224184700162683
8.970818436531113e-09,0.0015032,202.9267420726698,309.3852092767066,5.224184700162683
9.056754962266908e-09,0.0015176,203.00643960305328,309.3852092767066,5.224184700162683
9.137917236572938e-09,0.0015312,203.0814391178465,309.3852092767066,5.224184700162683
9.26682202517663e-09,0.0015528,203.2000242171182,309.3852092767066,5.224184700162683
9.276370528036162e-09,0.0015543999999999998,203.2087826226773,309.3852092767066,5.224184700162683
9.352758550912426e-09,0.0015672,203.2787237375307,309.3852092767066,5.224184700162683
9.443469328077989e-09,0.0015823999999999999,203.3614901144889,309.3852092767066,5.224184700162683
9.467340585226821e-09,0.0015864,203.3832191335014,309.3852092767066,5.224184700162683
9.529405853813784e-09,0.0015968,203.4396148185505,309.3852092767066,5.224184700162683
9.634439385268646e-09,0.0016144,203.53472842024757,309.3852092767066,5.224184700162683
9.834957945318835e-09,0.001648,203.71519341695736,309.3852092767066,5.224184700162683
9.854054951037902e-09,0.0016512,203.73230537449007,309.3852092767066,5.224184700162683
9.978185488211827e-09,0.0016719999999999999,203.84321950904342,309.3852092767066,5.224184700162683
1.0126187282534587e-08,0.0016967999999999998,203.97476244106417,309.3852092767066,5.224184700162683
1.0484256139767069e-08,0.0017568,204.28994781104115,309.3852092767066,5.224184700162683
1.0565418414073098e-08,0.0017703999999999999,204.36080286086982,309.3852092767066,5.224184700162683
1.0746839968404222e-08,0.0018008,204.51842163632372,309.3852092767066,5.224184700162683
1.0770711225553055e-08,0.0018047999999999999,204.539083421727,309.3852092767066,5.224184700162683
1.0890067511297215e-08,0.0018248,204.64212566805355,309.3852092767066,5.224184700162683
1.0942584277024646e-08,0.0018336,204.68732462213947,309.3852092767066,5.224184700162683
1.0971229785603246e-08,0.0018384,204.71194293642154,309.3852092767066,5.224184700162683
1.1076263317058106e-08,0.001856,204.80199641239608,309.3852092767066,5.224184700162683
1.1143102837074835e-08,0.0018671999999999998,204.85912980909794,309.3852092767066,5.224184700162683
1.1252910619959462e-08,0.0018855999999999999,204.9527025179337,309.3852092767066,5.224184700162683
1.1262459122818996e-08,0.0018872,204.96082240826672,309.3852092767066,5.224184700162683
1.1314975888546427e-08,0.001896,205.00543390626947,309.3852092767066,5.224184700162683
1.1357944151414324e-08,0.0019031999999999999,205.04187418966598,309.3852092767066,5.224184700162683
1.1496397442877552e-08,0.0019264,205.15892883215233,309.3852092767066,5.224184700162683
1.1587108220043114e-08,0.0019416,205.23532182450649,309.3852092767066,5.224184700162683
1.1668270494349141e-08,0.0019552,205.30347596895453,309.3852092767066,5.224184700162683
1.1773304025804003e-08,0.0019728,205.39140162719232,309.3852092767066,5.224184700162683
1.1811498037242135e-08,0.0019792,205.4232986773571,309.3852092767066,5.224184700162683
1.1825820791531436e-08,0.0019816,205.4352496972544,309.3852092767066,5.224184700162683
1.1873563305829098e-08,0.0019896,205.47504572357536,309.3852092767066,5.224184700162683
1.2117050128747186e-08,0.0020304,205.67704280471182,309.3852092767066,5.224184700162683
1.226027767164018e-08,0.0020544,205.79512516753942,309.3852092767066,5.224184700162683
1.2327117191656909e-08,0.0020656,205.85004604255428,309.3852092767066,5.224184700162683
1.2460796231690369e-08,0.002088,205.9595406138328,309.3852092767066,5.224184700162683
1.2484667488839202e-08,0.002092,205.97904491197323,309.3852092767066,5.224184700162683
1.2537184254566631e-08,0.0021008,206.02190324521274,309.3852092767066,5.224184700162683
1.2604023774583361e-08,0.0021119999999999997,206.07634908755546,309.3852092767066,5.224184700162683
1.2747251317476355e-08,0.002136,206.19264101953019,309.3852092767066,5.224184700162683
1.2823639340352617e-08,0.0021487999999999998,206.25445496330286,309.3852092767066,5.224184700162683
1.2895253111799115e-08,0.0021608,206.3122752425001,309.3852092767066,5.224184700162683
1.2923898620377711e-08,0.0021655999999999997,206.33536827325455,309.3852092767066,5.224184700162683
1.2976415386105142e-08,0.0021744,206.37765371661436,309.3852092767066,5.224184700162683
1.3133965683287434e-08,0.0022007999999999997,206.5041113995453,309.3852092767066,5.224184700162683
1.3186482449014866e-08,0.0022096,206.54613231077423,309.3852092767066,5.224184700162683
1.3286741729039961e-08,0.0022264,206.6261732533717,309.3852092767066,5.224184700162683
1.3372678254775756e-08,0.0022408,206.6945924774504,309.3852092767066,5.224184700162683
1.3463389031941317e-08,0.0022559999999999998,206.7666270017636,309.3852092767066,5.224184700162683
1.3616165077693845e-08,0.0022816,206.88752191898357,309.3852092767066,5.224184700162683
1.365913334056174e-08,0.0022887999999999997,206.9214281487761,309.3852092767066,5.224184700162683
1.3926491420628661e-08,0.0023336,207.13147318120335,309.3852092767066,5.224184700162683
1.396945968349656e-08,0.0023408,207.16508318398957,309.3852092767066,5.224184700162683
1.4041073454943055e-08,0.0023528,207.22101039762097,309.3852092767066,5.224184700162683
1.4184300997836049e-08,0.0023768,207.33253220027552,309.3852092767066,5.224184700162683
1.4236817763563478e-08,0.0023856,207.37331337826964,309.3852092767066,5.224184700162683
1.4284560277861145e-08,0.0023936,207.4103362938214,309.3852092767066,5.224184700162683
1.4427787820754136e-08,0.0024176,207.5211165684536,309.3852092767066,5.224184700162683
1.4499401592200633e-08,0.0024296,207.57634580879122,309.3852092767066,5.224184700162683
1.4733339912259187e-08,0.0024687999999999997,207.75602445776278,309.3852092767066,5.224184700162683
1.4814502186565218e-08,0.0024824,207.81810152211415,309.3852092767066,5.224184700162683
1.484792194657358e-08,0.0024879999999999998,207.84362409798484,309.3852092767066,5.224184700162683
1.4867018952292647e-08,0.0024912,207.8581983680004,309.3852092767066,5.224184700162683
1.4962503980887976e-08,0.0025072,207.93096048749564,309.3852092767066,5.224184700162683
1.5053214758053537e-08,0.0025223999999999997,207.99991694642569,309.3852092767066,5.224184700162683
1.5124828529500035e-08,0.0025344,208.05424184990778,309.3852092767066,5.224184700162683
1.5349218346699056e-08,0.002572,208.22381388709954,309.3852092767066,5.224184700162683
1.5468574632443216e-08,0.0025919999999999997,208.313617746792,309.3852092767066,5.224184700162683
1.5564059661038546e-08,0.002608,208.38526641127768,309.3852092767066,5.224184700162683
1.5616576426765977e-08,0.0026168,208.42460009862748,309.3852092767066,5.224184700162683
1.570728720393154e-08,0.002632,208.49241881365808,309.3852092767066,5.224184700162683
1.5740706963939903e-08,0.0026376,208.51736613017687,309.3852092767066,5.224184700162683
1.6074904564023552e-08,0.0026936,208.76571355772828,309.3852092767066,5.224184700162683
1.622290635834631e-08,0.0027183999999999997,208.87505178216438,309.3852092767066,5.224184700162683
1.6366133901239306e-08,0.0027424,208.98049316756385,309.3852092767066,5.224184700162683
1.64234249183965e-08,0.0027519999999999997,209.02256888168714,309.3852092767066,5.224184700162683
1.6471167432694164e-08,0.00276,209.05758826772296,309.3852092767066,5.224184700162683
1.6595297969868093e-08,0.0027808,209.14845390410127,309.3852092767066,5.224184700162683
1.661439497558716e-08,0.002784,209.1624096711744,309.3852092767066,5.224184700162683
1.670510575275272e-08,0.0027992,209.2286143199675,309.3852092767066,5.224184700162683
1.6819687787067115e-08,0.0028184,209.31204118416628,309.3852092767066,5.224184700162683
1.6896075809943378e-08,0.0028312,209.36753598761015,309.3852092767066,5.224184700162683
1.6924721318521977e-08,0.002836,209.38832130136836,309.3852092767066,5.224184700162683
1.7058400358555434e-08,0.0028583999999999997,209.48513860124214,309.3852092767066,5.224184700162683
1.70918201185638e-08,0.002864,209.5092966365363,309.3852092767066,5.224184700162683
1.7263693170035392e-08,0.0028928,209.6332481614672,309.3852092767066,5.224184700162683
1.727801592432469e-08,0.0028951999999999997,209.6435556811845,309.3852092767066,5.224184700162683
1.7301887181473522e-08,0.0028991999999999998,209.66072747856683,309.3852092767066,5.224184700162683
1.7349629695771187e-08,0.0029072,209.6950433790883,309.3852092767066,5.224184700162683
1.7621762027267874e-08,0.0029527999999999998,209.8899453352526,309.3852092767066,5.224184700162683
1.7731569810152502e-08,0.0029712,209.96825716686067,309.3852092767066,5.224184700162683
1.7807957833028762e-08,0.0029839999999999997,210.02262344759566,309.3852092767066,5.224184700162683
1.7831829090177598e-08,0.0029879999999999998,210.0395942484351,309.3852092767066,5.224184700162683
1.7898668610194327e-08,0.0029992,210.08706541899664,309.3852092767066,5.224184700162683
1.8027573398798018e-08,0.0030207999999999997,210.1784221759437,309.3852092767066,5.224184700162683
1.8089638667384984e-08,0.0030312,210.22231787059633,309.3852092767066,5.224184700162683
1.8285382976005407e-08,0.003064,210.36037496375175,309.3852092767066,5.224184700162683
1.860048357036999e-08,0.0031168,210.5814086192475,309.3852092767066,5.224184700162683
1.8648226084667658e-08,0.0031248,210.61477074285725,309.3852092767066,5.224184700162683
1.8691194347535554e-08,0.003132,210.64476818411148,309.3852092767066,5.224184700162683
1.8810550633279714e-08,0.003152,210.7279536271332,309.3852092767066,5.224184700162683
1.8886938656155977e-08,0.0031647999999999997,210.78108429815134,309.3852092767066,5.224184700162683
1.904448895333827e-08,0.0031912,210.8904023634093,309.3852092767066,5.224184700162683
1.9101779970495464e-08,0.0032007999999999997,210.9300668678081,309.3852092767066,5.224184700162683
1.9240233261958694e-08,0.003224,211.02573169625646,309.3852092767066,5.224184700162683
1.9359589547702853e-08,0.003244,211.10798609194106,309.3852092767066,5.224184700162683
1.9512365593455377e-08,0.0032695999999999997,211.21298369812237,309.3852092767066,5.224184700162683
1.9636496130629306e-08,0.0032903999999999997,211.2980583697796,309.3852092767066,5.224184700162683
1.9674690142067436e-08,0.0032968,211.32419296206191,309.3852092767066,5.224184700162683
1.971288415350557e-08,0.0033032,211.35030777537546,309.3852092767066,5.224184700162683
1.9798820679241365e-08,0.0033176,211.40899406388448,309.3852092767066,5.224184700162683
1.9903854210696227e-08,0.0033352,211.48058701250227,309.3852092767066,5.224184700162683
2.0142566782184546e-08,0.0033751999999999996,211.64275254619554,309.3852092767066,5.224184700162683
2.0242826062209642e-08,0.003392,211.71063836465916,309.3852092767066,5.224184700162683
2.0400376359391935e-08,0.0034184,211.81705174618008,309.3852092767066,5.224184700162683
2.0462441627978895e-08,0.0034287999999999996,211.85888410982687,309.3852092767066,5.224184700162683
2.0548378153714693e-08,0.0034432,211.91672424311716,309.3852092767066,5.224184700162683
2.061999192516119e-08,0.0034552,211.96485232448413,309.3852092767066,5.224184700162683
2.068205719374815e-08,0.0034655999999999997,212.00651062233788,309.3852092767066,5.224184700162683
2.0710702702326752e-08,0.0034704,212.02572108227002,309.3852092767066,5.224184700162683
2.073934821090535e-08,0.0034752,212.04492118250383,309.3852092767066,5.224184700162683
2.0791864976632778e-08,0.0034839999999999997,212.0800945257706,309.3852092767066,5.224184700162683
2.0958963776674606e-08,0.003512,212.19177989571597,309.3852092767066,5.224184700162683
2.1130836828146197e-08,0.0035407999999999998,212.3062945799469,309.3852092767066,5.224184700162683
2.128838712532849e-08,0.0035672,212.4109476623157,309.3852092767066,5.224184700162683
2.131225838247732e-08,0.0035711999999999996,212.4267778006484,309.3852092767066,5.224184700162683
2.1393420656783352e-08,0.0035848,212.48054862197466,309.3852092767066,5.224184700162683
2.149845418823821e-08,0.0036024,212.55001643998273,309.3852092767066,5.224184700162683
2.1574842211114474e-08,0.0036152,212.60045537948432,309.3852092767066,5.224184700162683
2.1679875742569336e-08,0.0036328,212.66969534719806,309.3852092767066,5.224184700162683
2.1775360771164663e-08,0.0036488,212.7325273296389,309.3852092767066,5.224184700162683
2.186129729690046e-08,0.0036631999999999997,212.78898430176386,309.3852092767066,5.224184700162683
2.2066590108380417e-08,0.0036975999999999997,212.9235045289812,309.3852092767066,5.224184700162683
2.2157300885545978e-08,0.0037128,212.98278812766122,309.3852092767066,5.224184700162683
2.223368890842224e-08,0.0037256,213.03263777831515,309.3852092767066,5.224184700162683
2.2295754177009204e-08,0.0037359999999999997,213.07309145500338,309.3852092767066,5.224184700162683
2.2443755971331965e-08,0.0037608,213.1693810919126,309.3852092767066,5.224184700162683
2.2539240999927292e-08,0.0037768,213.23137204379904,309.3852092767066,5.224184700162683
2.2615629022803553e-08,0.0037895999999999997,213.2808910939608,309.3852092767066,5.224184700162683
2.280659907999421e-08,0.0038215999999999997,213.4044041874612,309.3852092767066,5.224184700162683
2.2868664348581176e-08,0.003832,213.4444590102359,309.3852092767066,5.224184700162683
2.2959375125746737e-08,0.0038472,213.50292449561448,309.3852092767066,5.224184700162683
2.319808769723506e-08,0.0038872,213.65635217105458,309.3852092767066,5.224184700162683
2.332221823440899e-08,0.003908,213.7358911536633,309.3852092767066,5.224184700162683
2.3384283502995948e-08,0.0039184,213.7755987192868,309.3852092767066,5.224184700162683
2.3489317034450806e-08,0.003935999999999999,213.8427026311881,309.3852092767066,5.224184700162683
2.3560930805897308e-08,0.003948,213.88838821787232,309.3852092767066,5.224184700162683
2.3594350565905672e-08,0.0039536,213.9096896219273,309.3852092767066,5.224184700162683
2.3627770325914036e-08,0.0039591999999999995,213.93097926216254,309.3852092767066,5.224184700162683
2.3732803857368898e-08,0.0039768,213.99781323276028,309.3852092767066,5.224184700162683
2.380919188024516e-08,0.003989599999999999,214.0463473235264,309.3852092767066,5.224184700162683
2.6850985986773967e-08,0.004499299859971995,215.93231028477817,309.3852092767066,5.224184700162683
2.742401076330124e-08,0.004595319063812763,216.27806297400372,309.3852092767066,5.224184700162683
2.776782562921761e-08,0.004652930586117224,216.48416236136234,309.3852092767066,5.224184700162683
2.868466527166125e-08,0.004806561312262453,217.0289522493175,309.3852092767066,5.224184700162683
3.258123375204673e-08,0.0054594918983796765,219.27235706630867,309.3852092767066,5.224184700162683
3.303965357326855e-08,0.005536307261452291,219.52921950446822,309.3852092767066,5.224184700162683
3.659240718773766e-08,0.006131626325265053,221.47481898773748,309.3852092767066,5.224184700162683
3.8426086472624946e-08,0.006438887777555511,222.4500620995985,309.3852092767066,5.224184700162683
4.117660539995588e-08,0.0068997799559911985,223.87955300918523,309.3852092767066,5.224184700162683
4.209344504239952e-08,0.007053410682136428,224.34770752183968,309.3852092767066,5.224184700162683
4.28956797295377e-08,0.007187837567513502,224.75408996770085,309.3852092767066,5.224184700162683
4.484396396973044e-08,0.007514302860572114,225.7288708367485,309.3852092767066,5.224184700162683
4.793829776297774e-08,0.008032806561312262,227.24376120792948,309.3852092767066,5.224184700162683
5.023039686908684e-08,0.008416883376675335,228.34141915849253,309.3852092767066,5.224184700162683
5.160565633275231e-08,0.008647329465893179,228.9906391838575,309.3852092767066,5.224184700162683
5.2178681109279586e-08,0.008743348669733947,229.25915192899254,309.3852092767066,5.224184700162683
5.722129914271962e-08,0.009588317663532707,231.5744371217804,309.3852092767066,5.224184700162683
5.836734869577417e-08,0.009780356071214243,232.08937169139497,309.3852092767066,5.224184700162683
5.985721311474509e-08,0.01003000600120024,232.7529293847833,309.3852092767066,5.224184700162683
6.570206583532331e-08,0.011009401880376076,235.29618110066883,309.3852092767066,5.224184700162683
6.868179467326516e-08,0.01150870174034807,236.55865492325603,309.3852092767066,5.224184700162683
7.475585730445428e-08,0.012526505301060212,239.06784034472417,309.3852092767066,5.224184700162683
7.922545056136704e-08,0.013275455091018204,240.86369121291423,309.3852092767066,5.224184700162683
8.231978435461432e-08,0.013793958791758352,242.08388428822985,309.3852092767066,5.224184700162683
8.28928091311416e-08,0.01388997799559912,242.30786919847694,309.3852092767066,5.224184700162683
8.495569832663979e-08,0.014235647129425886,243.1092625339365,309.3852092767066,5.224184700162683
8.552872310316708e-08,0.014331666333266654,243.33052030211516,309.3852092767066,5.224184700162683
8.747700734335982e-08,0.014658131626325266,244.0785096619297,309.3852092767066,5.224184700162683
8.976910644946893e-08,0.015042208441688338,244.95022913796325,309.3852092767066,5.224184700162683
9.561395917004714e-08,0.016021604320864174,247.13470366333993,309.3852092767066,5.224184700162683
9.67600087231017e-08,0.01621364272854571,247.55685624281156,309.3852092767066,5.224184700162683
9.779145332085078e-08,0.01638647729545909,247.93512917905397,309.3852092767066,5.224184700162683
1.0008355242695989e-07,0.016770554110822164,248.77020884126935,309.3852092767066,5.224184700162683
1.0100039206940353e-07,0.016924184836967393,249.10214818506265,309.3852092767066,5.224184700162683
1.02375651533069e-07,0.017154630926185237,249.59786224072758,309.3852092767066,5.224184700162683
1.026048614436799e-07,0.017193038607721544,249.68022810369163,309.3852092767066,5.224184700162683
1.0409472586265085e-07,0.017442688537707543,250.21386771106484,309.3852092767066,5.224184700162683
1.0581380019223266e-07,0.017730746149229846,250.82591823319456,309.3852092767066,5.224184700162683
1.0822050425364723e-07,0.018134026805361074,251.67631352792282,309.3852092767066,5.224184700162683
1.0856431911956358e-07,0.018191638327665533,251.79719373768253,309.3852092767066,5.224184700162683
1.1062720831506178e-07,0.0185373074614923,252.51936437396293,309.3852092767066,5.224184700162683
1.1108562813628361e-07,0.018614122824564913,252.67913128736808,309.3852092767066,5.224184700162683
1.1154404795750543e-07,0.018690938187637528,252.83864127421373,309.3852092767066,5.224184700162683
1.131485173317818e-07,0.01895979195839168,253.3949239759403,309.3852092767066,5.224184700162683
1.1566982634850181e-07,0.01938227645529106,254.2629067999013,309.3852092767066,5.224184700162683
1.175035056333891e-07,0.019689537907581517,254.8895390745013,309.3852092767066,5.224184700162683
1.1773271554400001e-07,0.019727945589117824,254.9675990678422,309.3852092767066,5.224184700162683
1.1887876509705457e-07,0.01991998399679936,255.35701352080784,309.3852092767066,5.224184700162683
1.1991020969480367e-07,0.02009281856371274,255.7062364804492,309.3852092767066,5.224184700162683
1.205978394266364e-07,0.020208041608321663,255.93840115194163,309.3852092767066,5.224184700162683
1.2174388897969093e-07,0.0204000800160032,256.3241982813776,309.3852092767066,5.224184700162683
1.2415059304110552e-07,0.020803360672134428,257.12979212953803,309.3852092767066,5.224184700162683
1.2586966737068733e-07,0.02109141828365673,257.701491741755,309.3852092767066,5.224184700162683
1.2781795161088008e-07,0.021417883576715344,258.3457494631666,309.3852092767066,5.224184700162683
1.30568470538211e-07,0.02187877575515103,259.24880741789957,309.3852092767066,5.224184700162683
1.3331898946554195e-07,0.02233966793358672,260.14447592453234,309.3852092767066,5.224184700162683
1.346942489292074e-07,0.022570114022804563,260.5896055052327,309.3852092767066,5.224184700162683
1.359549034375674e-07,0.02278135627125425,260.99608631533584,309.3852092767066,5.224184700162683
1.390492372308147e-07,0.0232998599719944,261.987629295362,309.3852092767066,5.224184700162683
1.4283120075589472e-07,0.02393358671734347,263.1879043793992,309.3852092767066,5.224184700162683
1.4604013950444748e-07,0.02447129425885177,264.1966304569411,309.3852092767066,5.224184700162683
1.485614485211675e-07,0.02489377875575115,264.98314903452444,309.3852092767066,5.224184700162683
1.4993670798483295e-07,0.025124224844968995,265.40996430287043,309.3852092767066,5.224184700162683
1.5096815258258204e-07,0.025297059411882376,265.72907450868416,309.3852092767066,5.224184700162683
1.5303104177808024e-07,0.02564272854570914,266.3647554282965,309.3852092767066,5.224184700162683
1.5681300530316027e-07,0.026276455291058213,267.52155752707955,309.3852092767066,5.224184700162683
1.6116799360476758e-07,0.02700620124024805,268.84023811770334,309.3852092767066,5.224184700162683
1.6380390757679305e-07,0.027447889577915583,269.6316374218116,309.3852092767066,5.224184700162683
1.6403311748740396e-07,0.02748629725945189,269.7002191630874,309.3852092767066,5.224184700162683
1.657521918169858e-07,0.027774354870974197,270.2133962166104,309.3852092767066,5.224184700162683
1.6678363641473488e-07,0.027947189437887578,270.5203061934936,309.3852092767066,5.224184700162683
1.726284891353131e-07,0.02892658531706341,272.2456802291818,309.3852092767066,5.224184700162683
1.7388914364367311e-07,0.029137827565513103,272.6148154074818,309.3852092767066,5.224184700162683
1.7446216842020038e-07,0.02923384676935387,272.7822589553752,309.3852092767066,5.224184700162683
1.7629584770508765e-07,0.029541108221644328,273.31664265437263,309.3852092767066,5.224184700162683
1.772126873475313e-07,0.029694738947789557,273.5830212967728,309.3852092767066,5.224184700162683
1.8122386078322225e-07,0.030366873374674936,274.7421649980798,309.3852092767066,5.224184700162683
1.8752713332502228e-07,0.031423084616923384,276.54366107475903,309.3852092767066,5.224184700162683
1.887877878333823e-07,0.031634326865373076,276.9011093263845,309.3852092767066,5.224184700162683
1.9073607207357502e-07,0.031960792158431686,277.4517037712123,309.3852092767066,5.224184700162683
1.914237018054078e-07,0.03207601520304061,277.6455069746482,309.3852092767066,5.224184700162683
1.926843563137678e-07,0.0322872574514903,278.00010914344,309.3852092767066,5.224184700162683
1.944034306433496e-07,0.0325753150630126,278.48220283968453,309.3852092767066,5.224184700162683
1.9784157930251328e-07,0.033151430286057215,279.44143114501793,309.3852092767066,5.224184700162683
2.0483248157614606e-07,0.034322864572914585,281.3720424756996,309.3852092767066,5.224184700162683
2.0540550635267333e-07,0.03441888377675535,281.529140673528,309.3852092767066,5.224184700162683
2.056347162632842e-07,0.034457291458291656,281.5919320834715,309.3852092767066,5.224184700162683
2.1205259376038971e-07,0.03553270654130826,283.3391633987209,309.3852092767066,5.224184700162683
2.1388627304527698e-07,0.03583996799359872,283.8345684003112,309.3852092767066,5.224184700162683
2.2041875549768797e-07,0.03693458691738348,285.5861438598302,309.3852092767066,5.224184700162683
2.2534676857582257e-07,0.03776035207041409,286.89414113191106,309.3852092767066,5.224184700162683
2.2878491723498617e-07,0.03833646729345869,287.8000983984337,309.3852092767066,5.224184700162683
2.311916212964007e-07,0.03873974794958991,288.43111177568784,309.3852092767066,5.224184700162683
2.3336911544720438e-07,0.03910462092418483,288.99982457186405,309.3852092767066,5.224184700162683
2.3887015330186623e-07,0.04002640528105621,290.4274308749688,309.3852092767066,5.224184700162683
2.401308078102263e-07,0.0402376475295059,290.7527779297542,309.3852092767066,5.224184700162683
2.425375118716408e-07,0.040640928185637124,291.37205122609987,309.3852092767066,5.224184700162683
2.5010143892180094e-07,0.041908381676335274,293.3029170163022,309.3852092767066,5.224184700162683
2.5285195784913184e-07,0.04236927385477096,293.9993858825203,309.3852092767066,5.224184700162683
2.5365419253627e-07,0.04250370074014803,294.20196524922784,309.3852092767066,5.224184700162683
2.5594629164237904e-07,0.0428877775555111,294.77939115966234,309.3852092767066,5.224184700162683
2.581237857931827e-07,0.04325265053010602,295.3260806320645,309.3852092767066,5.224184700162683
2.588114155250155e-07,0.043367873574714944,295.498345355346,309.3852092767066,5.224184700162683
2.6064509480990277e-07,0.0436751350270054,295.9568475289355,309.3852092767066,5.224184700162683
2.616765394076519e-07,0.04384796959391879,296.2142021373997,309.3852092767066,5.224184700162683
2.6603152770925916e-07,0.04457771554310862,297.29647763392563,309.3852092767066,5.224184700162683
2.668337623963974e-07,0.0447121424284857,297.49508824299073,309.3852092767066,5.224184700162683
2.6855283672597915e-07,0.045000200040008,297.91989992667953,309.3852092767066,5.224184700162683
2.695842813237283e-07,0.04517303460692139,298.17427790791476,309.3852092767066,5.224184700162683
2.7176177547453197e-07,0.04553790758151631,298.71005495864875,309.3852092767066,5.224184700162683
2.7382466467003014e-07,0.04588357671534307,299.21609092738413,309.3852092767066,5.224184700162683
2.7554373899961195e-07,0.04617163432686537,299.63665282314423,309.3852092767066,5.224184700162683
2.7817965297163745e-07,0.046613322664532914,300.2795323840226,309.3852092767066,5.224184700162683
2.8161780163080107e-07,0.04718943788757751,301.11451183793355,309.3852092767066,5.224184700162683
2.8345148091568834e-07,0.04749669933986797,301.55820817745337,309.3852092767066,5.224184700162683
2.841391106475211e-07,0.047611922384476896,301.7243055251125,309.3852092767066,5.224184700162683
2.8952554354687746e-07,0.04851450290058011,303.0200213838321,309.3852092767066,5.224184700162683
2.9113001292115387e-07,0.048783356671334266,303.40415755154766,309.3852092767066,5.224184700162683
2.9468276653562294e-07,0.04937867573514702,304.2518187455996,309.3852092767066,5.224184700162683
2.9617263095459395e-07,0.04962832566513303,304.6061023412764,309.3852092767066,5.224184700162683
2.966310507758157e-07,0.04970514102820564,304.71497275657015,309.3852092767066,5.224184700162683
2.9766249537356485e-07,0.04987797559511903,304.9596915625209,309.3852092767066,5.224184700162683
2.983501251053975e-07,0.04999319863972794,305.1226537281908,309.3852092767066,5.224184700162683
2.986939399713139e-07,0.0500508101620324,305.20407987616375,309.3852092767066,5.224184700162683
2.9983998952436853e-07,0.05024284856971395,305.4752367601385,309.3852092767066,5.224184700162683
3.020174836751721e-07,0.050607721544308856,305.9893238538265,309.3852092767066,5.224184700162683
3.0373655800475397e-07,0.05089577915583117,306.3941617160201,309.3852092767066,5.224184700162683
3.0751852152983396e-07,0.05152950590118023,307.28167280312624,309.3852092767066,5.224184700162683
3.1324876929510677e-07,0.05248969793958792,308.61831823618354,309.3852092767066,5.224184700162683
3.159992882224377e-07,0.05295059011802361,309.2565178978225,309.3852092767066,5.224184700162683
3.166869179542704e-07,0.05306581316263252,309.41572885257375,309.3852092767066,5.224184700162683
3.180621774179359e-07,0.05329625925185037,309.7337468713707,309.3852092767066,5.224184700162683
3.189790170603795e-07,0.0534498899779956,309.9454610038916,309.3852092767066,5.224184700162683
3.2161493103240497e-07,0.05389157831566313,310.55282117518215,309.3852092767066,5.224184700162683
3.2448005491504137e-07,0.054371674334866976,311.2107975625701,309.3852092767066,5.224184700162683
3.2528228960217955e-07,0.054506101220244046,311.3946244112879,309.3852092767066,5.224184700162683
3.261991292446232e-07,0.054659731946389276,311.60449587158735,309.3852092767066,5.224184700162683
3.273451787976777e-07,0.05485177035407081,311.8665119662128,309.3852092767066,5.224184700162683
3.2803280852951045e-07,0.054966993398679734,312.0235499044382,309.3852092767066,5.224184700162683
3.290642531272596e-07,0.05513982796559312,312.2588663089767,309.3852092767066,5.224184700162683
3.302103026803141e-07,0.055331866373274655,312.5199918594733,309.3852092767066,5.224184700162683
3.307833274568414e-07,0.05542788557711542,312.65042207430486,309.3852092767066,5.224184700162683
3.321585869205069e-07,0.05565833166633327,312.9630955859333,309.3852092767066,5.224184700162683
3.3479450089253234e-07,0.0561000200040008,313.560978853706,309.3852092767066,5.224184700162683
3.3548213062436507e-07,0.056215243048609725,313.71664612541264,309.3852092767066,5.224184700162683
3.368573900880305e-07,0.05644568913782756,314.0276078622258,309.3852092767066,5.224184700162683
3.4407750227227423e-07,0.05765553110622125,315.6521047897616,309.3852092767066,5.224184700162683
3.456819716465506e-07,0.05792438487697539,316.01129233384864,309.3852092767066,5.224184700162683
3.478594657973542e-07,0.05828925785157031,316.49772290200184,309.3852092767066,5.224184700162683
3.501515649034634e-07,0.05867333466693339,317.0084739189836,309.3852092767066,5.224184700162683
3.5381892347323793e-07,0.05928785757151431,317.8229717258463,309.3852092767066,5.224184700162683
3.559964176240416e-07,0.05965273054610923,318.3050220555244,309.3852092767066,5.224184700162683
3.574862820430125e-07,0.059902380476095224,318.63418360032324,309.3852092767066,5.224184700162683
3.6080982574687073e-07,0.06045929185837168,319.3665452269316,309.3852092767066,5.224184700162683
3.619558752999252e-07,0.06065133026605321,319.6184730725706,309.3852092767066,5.224184700162683
3.63904159540118e-07,0.06097779555911183,320.04603762409505,309.3852092767066,5.224184700162683
3.641333694507289e-07,0.06101620324064813,320.0962805755113,309.3852092767066,5.224184700162683
3.687175676629471e-07,0.06178435687137428,321.0985639740531,309.3852092767066,5.224184700162683
3.7502084020474714e-07,0.06284056811362272,322.4688042821654,309.3852092767066,5.224184700162683
3.7960503841696536e-07,0.06360872174434887,323.459707391704,309.3852092767066,5.224184700162683
3.813241127465472e-07,0.06389677935587118,323.83009148366637,309.3852092767066,5.224184700162683
3.8396002671857267e-07,0.06433846769353871,324.3967514824509,309.3852092767066,5.224184700162683
3.8693975555651447e-07,0.0648377675535107,325.0354999290855,309.3852092767066,5.224184700162683
3.8831501502017997e-07,0.06506821364272855,325.3296596113822,309.3852092767066,5.224184700162683
3.914093488134273e-07,0.0655867173434687,325.9900374097713,309.3852092767066,5.224184700162683
4.0470352362886006e-07,0.06781436287257452,328.8043603634913,309.3852092767066,5.224184700162683
4.0688101777966374e-07,0.06817923584716944,329.26186850547236,309.3852092767066,5.224184700162683
4.077978574221074e-07,0.06833286657331467,329.4542177265463,309.3852092767066,5.224184700162683
4.115798209471874e-07,0.06896659331866374,330.2458820584222,309.3852092767066,5.224184700162683
4.1295508041085286e-07,0.06919703940788158,330.533055941774,309.3852092767066,5.224184700162683
4.1421573491921286e-07,0.06940828165633127,330.79597118114964,309.3852092767066,5.224184700162683
4.1501796960635103e-07,0.06954270854170834,330.9631184099367,309.3852092767066,5.224184700162683
4.1731006871246017e-07,0.06992678535707142,331.4399890024297,309.3852092767066,5.224184700162683
4.186853281761256e-07,0.07015723144628926,331.72562106067886,309.3852092767066,5.224184700162683
4.230403164777329e-07,0.0708869773954791,332.62771806741114,309.3852092767066,5.224184700162683
4.2533241558384206e-07,0.07127105421084218,333.1010508467619,309.3852092767066,5.224184700162683
4.2613465027098024e-07,0.07140548109621925,333.2664821626948,309.3852092767066,5.224184700162683
4.2636386018159115e-07,0.07144388877775555,333.31372593807663,309.3852092767066,5.224184700162683
4.2762451468995114e-07,0.07165513102620524,333.5733898642868,309.3852092767066,5.224184700162683
4.296874038854493e-07,0.072000800160032,333.99765142874554,309.3852092767066,5.224184700162683
4.325525277680857e-07,0.07248089617923585,334.5855881461323,309.3852092767066,5.224184700162683
4.333547624552239e-07,0.07261532306461292,334.7499380074643,309.3852092767066,5.224184700162683
4.359906764272494e-07,0.07305701140228046,335.2891111878702,309.3852092767066,5.224184700162683
4.413771093266058e-07,0.07395959191838368,336.3869626705421,309.3852092767066,5.224184700162683
4.4492986294107486e-07,0.07455491098219644,337.1082189585748,309.3852092767066,5.224184700162683
4.4607591249412946e-07,0.07474694938987798,337.3404026839892,309.3852092767066,5.224184700162683
4.487118264661549e-07,0.07518863772754551,337.8735441719793,309.3852092767066,5.224184700162683
4.4974327106390404e-07,0.0753614722944589,338.0818320938004,309.3852092767066,5.224184700162683
4.5066011070634767e-07,0.07551510302060413,338.26682056557627,309.3852092767066,5.224184700162683
4.5444207423142766e-07,0.07614882976595319,339.02835170846805,309.3852092767066,5.224184700162683
4.5639035847162043e-07,0.07647529505901181,339.4196907742784,309.3852092767066,5.224184700162683
4.576510129799805e-07,0.0766865373074615,339.67256303414945,309.3852092767066,5.224184700162683
4.604015319073114e-07,0.07714742948589719,340.2233432939195,309.3852092767066,5.224184700162683
4.6257902605811505e-07,0.07751230246049211,340.6584680936916,309.3852092767066,5.224184700162683
4.649857301195296e-07,0.07791558311662333,341.13846718866347,309.3852092767066,5.224184700162683
4.6578796480666777e-07,0.0780500100020004,341.29825144382994,309.3852092767066,5.224184700162683
4.6853848373399867e-07,0.07851090218043609,341.84527020772816,309.3852092767066,5.224184700162683
4.711743977060241e-07,0.07895259051810362,342.3683225331536,309.3852092767066,5.224184700162683
4.7358110176743875e-07,0.07935587117423486,342.84489624750535,309.3852092767066,5.224184700162683
4.7552938600763147e-07,0.07968233646729346,343.2300025784306,309.3852092767066,5.224184700162683
4.778214851137406e-07,0.08006641328265654,343.6822819247583,309.3852092767066,5.224184700162683
4.825202882812642e-07,0.08085377075415083,344.6068179509621,309.3852092767066,5.224184700162683
4.842393626108461e-07,0.08114182836567314,344.94418469874574,309.3852092767066,5.224184700162683
4.850415972979842e-07,0.08127625525105021,345.10146263568885,309.3852092767066,5.224184700162683
4.877921162253152e-07,0.0817371474294859,345.6399327558541,309.3852092767066,5.224184700162683
4.906572401079516e-07,0.08221724344868975,346.1995814576152,309.3852092767066,5.224184700162683
4.916886847057007e-07,0.08239007801560312,346.4007428026453,309.3852092767066,5.224184700162683
4.940953887671152e-07,0.08279335867173435,346.8694803469179,309.3852092767066,5.224184700162683
4.951268333648643e-07,0.08296619323864773,347.07009518792194,309.3852092767066,5.224184700162683
5.009716860854426e-07,0.08394558911782357,348.2038489599556,309.3852092767066,5.224184700162683
5.028053653703299e-07,0.08425285057011403,348.55847179214436,309.3852092767066,5.224184700162683
5.075041685378534e-07,0.08504020804160832,349.4648982677086,309.3852092767066,5.224184700162683
5.104838973757953e-07,0.08553950790158033,350.0380098020766,309.3852092767066,5.224184700162683
5.119737617947663e-07,0.08578915783156632,350.32407621396385,309.3852092767066,5.224184700162683
5.122029717053772e-07,0.08582756551310262,350.36805759853434,309.3852092767066,5.224184700162683
5.159849352304572e-07,0.0864612922584517,351.0926458895987,309.3852092767066,5.224184700162683
5.206837383979808e-07,0.08724864972994599,351.9900130769978,309.3852092767066,5.224184700162683
5.253825415655046e-07,0.0880360072014403,352.8842275034467,309.3852092767066,5.224184700162683
5.264139861632536e-07,0.08820884176835367,353.0801003722499,309.3852092767066,5.224184700162683
5.282476654481409e-07,0.08851610322064413,353.42794963207973,309.3852092767066,5.224184700162683
5.301959496883336e-07,0.08884256851370274,353.79702388843793,309.3852092767066,5.224184700162683
5.320296289732209e-07,0.0891498299659932,354.1439050204821,309.3852092767066,5.224184700162683
5.348947528558573e-07,0.08962992598519705,354.6849748086582,309.3852092767066,5.224184700162683
5.362700123195228e-07,0.08986037207441488,354.9442867251018,309.3852092767066,5.224184700162683
5.376452717831883e-07,0.09009081816363274,355.2033394196878,309.3852092767066,5.224184700162683
5.397081609786865e-07,0.0904364872974595,355.5914344341986,309.3852092767066,5.224184700162683
5.441777542355991e-07,0.09118543708741748,356.4303278651856,309.3852092767066,5.224184700162683
5.448653839674319e-07,0.09130066013202641,356.55914949707534,309.3852092767066,5.224184700162683
5.477305078500684e-07,0.09178075615123026,357.09522524674605,309.3852092767066,5.224184700162683
5.48418137581901e-07,0.09189597919583917,357.2237205614847,309.3852092767066,5.224184700162683
5.512832614645374e-07,0.09237607521504301,357.75844277317884,309.3852092767066,5.224184700162683
5.538045704812575e-07,0.0927985597119424,358.2281024198269,309.3852092767066,5.224184700162683
5.564404844532829e-07,0.09324024804960993,358.71821947951827,309.3852092767066,5.224184700162683
5.610246826655012e-07,0.09400840168033607,359.5684457242007,309.3852092767066,5.224184700162683
5.621707322185556e-07,0.0942004400880176,359.78057840388874,309.3852092767066,5.224184700162683
5.687032146709666e-07,0.09529505901180237,360.98652962103085,309.3852092767066,5.224184700162683
5.696200543134103e-07,0.0954486897379476,361.15535259089006,309.3852092767066,5.224184700162683
5.71339128642992e-07,0.0957367473494699,361.4716102985698,309.3852092767066,5.224184700162683
5.729435980172685e-07,0.09600560112022405,361.7664494972094,309.3852092767066,5.224184700162683
5.762671417211267e-07,0.0965625125025005,362.37616545987555,309.3852092767066,5.224184700162683
5.775277962294866e-07,0.0967737547509502,362.6070780854145,309.3852092767066,5.224184700162683
5.785592408272358e-07,0.09694658931786358,362.79586041722166,309.3852092767066,5.224184700162683
5.807367349780395e-07,0.0973114622924585,363.1939703965658,309.3852092767066,5.224184700162683
5.834872539053704e-07,0.09777235447089418,363.6960150211646,309.3852092767066,5.224184700162683
5.850917232796467e-07,0.09804120824164833,363.9884481530539,309.3852092767066,5.224184700162683
5.853209331902576e-07,0.09807961592318463,364.0301987698871,309.3852092767066,5.224184700162683
5.865815876986176e-07,0.09829085817163433,364.25971328823874,309.3852092767066,5.224184700162683
5.883006620281995e-07,0.09857891578315664,364.57237785167104,309.3852092767066,5.224184700162683
5.923118354638905e-07,0.09925105021004202,365.3005460927512,309.3852092767066,5.224184700162683
5.927702552851122e-07,0.09932786557311463,365.38364268621706,309.3852092767066,5.224184700162683
5.933432800616395e-07,0.09942388477695539,365.4874781923396,309.3852092767066,5.224184700162683
5.943747246593887e-07,0.09959671934386878,365.6742836021951,309.3852092767066,5.224184700162683
5.95749984123054e-07,0.09982716543308662,365.9231609369073,309.3852092767066,5.224184700162683
5.962084039442759e-07,0.09990398079615924,366.0060702435355,309.3852092767066,5.224184700162683