File: datasets/aisi_316_L/data/M1/valid_0.csv
Time(s),Strain(%),Stress(MPa),Temp(C),Log_SR(s-1)
0.0,0.0,0.0,26.743371399751158,0.5988026581680694
8.261733571919054e-06,3.28e-05,6.4143234125,26.743371399751158,0.5988026581680694
1.5515938659457737e-05,6.159999999999999e-05,12.046412262499999,26.743371399751158,0.5988026581680694
2.05535810813596e-05,8.159999999999999e-05,15.957585074999999,26.743371399751158,0.5988026581680694
2.3979177928252866e-05,9.52e-05,18.6171825875,26.743371399751158,0.5988026581680694
2.5389717806385386e-05,0.0001008,19.712310975,26.743371399751158,0.5988026581680694
2.8412303259526505e-05,0.00011279999999999999,22.059014662499997,26.743371399751158,0.5988026581680694
3.0024348834535103e-05,0.0001192,23.3105899625,26.743371399751158,0.5988026581680694
3.445747416580874e-05,0.0001368,26.752422037499997,26.743371399751158,0.5988026581680694
4.070415076896705e-05,0.0001616,31.602276325,26.743371399751158,0.5988026581680694
4.332372482835601e-05,0.00017199999999999998,33.6360861875,26.743371399751158,0.5988026581680694
5.380202106591189e-05,0.0002136,41.7713256375,26.743371399751158,0.5988026581680694
5.883966348781375e-05,0.00023359999999999999,45.68249845,26.743371399751158,0.5988026581680694
6.428031730346776e-05,0.00025519999999999997,49.90656508749999,26.743371399751158,0.5988026581680694
7.516162493477578e-05,0.0002984,58.354698362499995,26.743371399751158,0.5988026581680694
7.717668190353653e-05,0.00030639999999999997,59.91916748749999,26.743371399751158,0.5988026581680694
8.06022787504298e-05,0.00031999999999999997,62.578765,26.743371399751158,0.5988026581680694
8.443088699107521e-05,0.00033519999999999996,65.55125633749999,26.743371399751158,0.5988026581680694
8.604293256608382e-05,0.0003416,66.8028316375,26.743371399751158,0.5988026581680694
8.725196674734026e-05,0.00034639999999999996,67.74151311249999,26.743371399751158,0.5988026581680694
9.289412625987034e-05,0.00036879999999999997,72.12202666249999,26.743371399751158,0.5988026581680694
9.833478007552437e-05,0.0003904,76.3460933,26.743371399751158,0.5988026581680694
0.00010538747946618697,0.0004184,81.8217352375,26.743371399751158,0.5988026581680694
0.00010720103073807164,0.0004256,83.22975745,26.743371399751158,0.5988026581680694
0.00011264168455372564,0.0004472,87.4538240875,26.743371399751158,0.5988026581680694
0.00011505975291623855,0.0004568,89.3311870375,26.743371399751158,0.5988026581680694
0.00012009739533814041,0.0004768,93.24235985,26.743371399751158,0.5988026581680694
0.00012271696939752938,0.00048719999999999997,95.27616971249999,26.743371399751158,0.5988026581680694
0.00012835912891005948,0.0005096,99.65668326250001,26.743371399751158,0.5988026581680694
0.00012896364600068768,0.000512,100.126024,26.743371399751158,0.5988026581680694
0.00013420279411946562,0.0005327999999999999,104.19364372499999,26.743371399751158,0.5988026581680694
0.00013581483969447422,0.0005392,105.445219025,26.743371399751158,0.5988026581680694
0.0001422630219945086,0.0005648,110.451520225,26.743371399751158,0.5988026581680694
0.00014347205617576503,0.0005696,111.39020169999999,26.743371399751158,0.5988026581680694
0.00014730066441641048,0.0005848,114.36269303750001,26.743371399751158,0.5988026581680694
0.00014971873277892333,0.0005943999999999999,116.24005598749999,26.743371399751158,0.5988026581680694
0.00015274131823206447,0.0006064,118.586759675,26.743371399751158,0.5988026581680694
0.00015757745495709026,0.0006255999999999999,122.34148557499998,26.743371399751158,0.5988026581680694
0.0001636226258633725,0.0006496,127.03489294999999,26.743371399751158,0.5988026581680694
0.00016543617713525715,0.0006567999999999999,128.4429151625,26.743371399751158,0.5988026581680694
0.00017329489931342405,0.0006879999999999999,134.54434475,26.743371399751158,0.5988026581680694
0.0001761159790696891,0.0006992,136.734601525,26.743371399751158,0.5988026581680694
0.0001793400702197063,0.000712,139.237752125,26.743371399751158,0.5988026581680694
0.00018357168985410388,0.0007287999999999999,142.5231372875,26.743371399751158,0.5988026581680694
0.00018457921833848424,0.0007327999999999999,143.30537184999997,26.743371399751158,0.5988026581680694
0.00018538524112598855,0.000736,143.9311595,26.743371399751158,0.5988026581680694
0.00018820632088225358,0.0007472,146.121416275,26.743371399751158,0.5988026581680694
0.00019001987215413825,0.0007544,147.52943848750002,26.743371399751158,0.5988026581680694
0.00019082589494164257,0.0007576,148.1552261375,26.743371399751158,0.5988026581680694
0.00019425149178853583,0.0007712,150.81482365,26.743371399751158,0.5988026581680694
0.00020352075384483527,0.000808,158.011381625,26.743371399751158,0.5988026581680694
0.0002069463506917285,0.0008215999999999999,160.67097913749998,26.743371399751158,0.5988026581680694
0.00021258851020425858,0.0008439999999999999,165.05149268749997,26.743371399751158,0.5988026581680694
0.00021682012983865618,0.0008608,168.33687785,26.743371399751158,0.5988026581680694
0.0002188351868074169,0.0008688,169.901346975,26.743371399751158,0.5988026581680694
0.0002196412095949212,0.0008719999999999999,170.527134625,26.743371399751158,0.5988026581680694
0.00022709692037933596,0.0009015999999999999,176.31567038749998,26.743371399751158,0.5988026581680694
0.00022749993177308811,0.0009031999999999999,176.62856421249998,26.743371399751158,0.5988026581680694
0.00022971649443872494,0.0009119999999999999,178.34948025,26.743371399751158,0.5988026581680694
0.0002468444786731913,0.00098,191.6474678125,26.743371399751158,0.5988026581680694
0.0002502700755200845,0.0009935999999999999,194.30706532499997,26.743371399751158,0.5988026581680694
0.000254300189457606,0.0010096,197.436003575,26.743371399751158,0.5988026581680694
0.00025591223503261464,0.001016,198.68757887499999,26.743371399751158,0.5988026581680694
0.00025671825782011895,0.0010192,199.31336652500002,26.743371399751158,0.5988026581680694
0.00026256192302952507,0.0010424,203.85032698749998,26.743371399751158,0.5988026581680694
0.0002629649344232772,0.001044,204.16322081250001,26.743371399751158,0.5988026581680694
0.00026780107114830304,0.0010632,207.9179467125,26.743371399751158,0.5988026581680694
0.00027183118508582454,0.0010792,211.0468849625,26.743371399751158,0.5988026581680694
0.0002740477477514613,0.001088,212.767801,26.743371399751158,0.5988026581680694
0.000275861299023346,0.0010952,214.17582321249998,26.743371399751158,0.5988026581680694
0.0002806974357483718,0.0011144,217.9305491125,26.743371399751158,0.5988026581680694
0.0002819064699296282,0.0011191999999999999,218.86923058749997,26.743371399751158,0.5988026581680694
0.00028372002120151293,0.0011264,220.2772528,26.743371399751158,0.5988026581680694
0.0002873471237452822,0.0011408,223.093297225,26.743371399751158,0.5988026581680694
0.0002881531465327866,0.001144,223.71908487500002,26.743371399751158,0.5988026581680694
0.00029077272059217546,0.0011543999999999999,225.7528947375,26.743371399751158,0.5988026581680694
0.00030084800543597924,0.0011944,233.57524036249998,26.743371399751158,0.5988026581680694
0.0003050796250703768,0.0012112,236.860625525,26.743371399751158,0.5988026581680694
0.0003091097390078983,0.0012272,239.989563775,26.743371399751158,0.5988026581680694
0.00031152780737041117,0.0012368,241.86692672499998,26.743371399751158,0.5988026581680694
0.00031656544979231303,0.0012568,245.7780995375,26.743371399751158,0.5988026581680694
0.0003203940580329584,0.001272,248.75059087499997,26.743371399751158,0.5988026581680694
0.0003232151377892235,0.0012832,250.94084765,26.743371399751158,0.5988026581680694
0.00032643922893924065,0.0012959999999999998,253.44399824999996,26.743371399751158,0.5988026581680694
0.0003344994568142837,0.001328,259.70187475,26.743371399751158,0.5988026581680694
0.000338126559358053,0.0013423999999999999,262.517919175,26.743371399751158,0.5988026581680694
0.00033994011062993767,0.0013495999999999998,263.92594138749996,26.743371399751158,0.5988026581680694
0.00034135065050807024,0.0013552,265.021069775,26.743371399751158,0.5988026581680694
0.0003492093726862371,0.0013863999999999999,271.1224993625,26.743371399751158,0.5988026581680694
0.0003560605663800236,0.0014135999999999999,276.4416943875,26.743371399751158,0.5988026581680694
0.00035827712904566044,0.0014223999999999999,278.16261042499997,26.743371399751158,0.5988026581680694
0.0003627102543769341,0.0014399999999999999,281.60444249999995,26.743371399751158,0.5988026581680694
0.0003721810221301096,0.0014776,288.9574473875,26.743371399751158,0.5988026581680694
0.0003737930677051182,0.0014839999999999999,290.20902268749995,26.743371399751158,0.5988026581680694
0.00037621113606763106,0.0014935999999999999,292.0863856375,26.743371399751158,0.5988026581680694
0.0003772186645520115,0.0014976,292.8686202,26.743371399751158,0.5988026581680694
0.00037963673291452435,0.0015072,294.74598315,26.743371399751158,0.5988026581680694
0.0003852788924270544,0.0015295999999999999,299.12649669999996,26.743371399751158,0.5988026581680694
0.0003856819038208066,0.0015312,299.43939052499996,26.743371399751158,0.5988026581680694
0.0003907195462427085,0.0015512,303.3505633375,26.743371399751158,0.5988026581680694
0.00039495116587710604,0.001568,306.6359485,26.743371399751158,0.5988026581680694
0.0003991827855115036,0.0015848,309.9213336625,26.743371399751158,0.5988026581680694
0.0004046234393271576,0.0016064,311.21394468827464,26.743371399751158,0.5988026581680694
0.0004076460247802987,0.0016183999999999999,311.31296115639384,26.743371399751158,0.5988026581680694
0.0004130866785959527,0.00164,311.49047224549673,26.743371399751158,0.5988026581680694
0.0004171167925334742,0.001656,311.6213746506228,26.743371399751158,0.5988026581680694
0.0004261845488928976,0.001692,311.91411490134595,26.743371399751158,0.5988026581680694
0.0004284011115585344,0.0017008,311.98530292611986,26.743371399751158,0.5988026581680694
0.0004304161685272951,0.0017088,312.0498947566119,26.743371399751158,0.5988026581680694
0.000432834236889808,0.0017184,312.12724948823575,26.743371399751158,0.5988026581680694
0.0004382748907054621,0.00174,312.3006840602643,26.743371399751158,0.5988026581680694
0.00043988693628047064,0.0017464,312.3519105646282,26.743371399751158,0.5988026581680694
0.00044472307300549645,0.0017656,312.50515258586245,26.743371399751158,0.5988026581680694
0.0004479471641555136,0.0017783999999999999,312.6069530273185,26.743371399751158,0.5988026581680694
0.0004554028749399284,0.001808,312.8412783419769,26.743371399751158,0.5988026581680694
0.0004566119091211848,0.0018127999999999998,312.8791356095823,26.743371399751158,0.5988026581680694
0.0004600375059680781,0.0018264,312.98618615246113,26.743371399751158,0.5988026581680694
0.00046185105723996276,0.0018336,313.04273408782905,26.743371399751158,0.5988026581680694
0.00046346310281497133,0.0018399999999999998,313.092926260239,26.743371399751158,0.5988026581680694
0.00046426912560247564,0.0018432,313.1179968106137,26.743371399751158,0.5988026581680694
0.0004668886996618646,0.0018536,313.1993591177647,26.743371399751158,0.5988026581680694
0.0004711203192962622,0.0018704,313.3304154580013,26.743371399751158,0.5988026581680694
0.0004771654902025444,0.0018943999999999999,313.5168452089776,26.743371399751158,0.5988026581680694
0.00048099409844318985,0.0019096,313.63444109921124,26.743371399751158,0.5988026581680694
0.00048421818959320704,0.0019223999999999999,313.7331863438868,26.743371399751158,0.5988026581680694
0.0004886513149244807,0.0019399999999999999,313.86854339480936,26.743371399751158,0.5988026581680694
0.0004963085314057715,0.0019703999999999998,314.10121930487634,26.743371399751158,0.5988026581680694
0.0004987265997682844,0.00198,314.17440448978016,26.743371399751158,0.5988026581680694
0.0005013461738276733,0.0019904,314.2535324506767,26.743371399751158,0.5988026581680694
0.0005025552080089299,0.0019952,314.2899986477998,26.743371399751158,0.5988026581680694
0.0005039657478870624,0.0020008,314.3324993293952,26.743371399751158,0.5988026581680694
0.0005073913447339556,0.0020144,314.4355225886779,26.743371399751158,0.5988026581680694
0.0005118244700652293,0.002032,314.5684450276388,26.743371399751158,0.5988026581680694
0.0005188771694558918,0.0020599999999999998,314.77899088596456,26.743371399751158,0.5988026581680694
0.0005214967435152808,0.0020704,314.856908992859,26.743371399751158,0.5988026581680694
0.0005251238460590501,0.0020848,314.96454407280527,26.743371399751158,0.5988026581680694
0.0005313705226622085,0.0021096,315.14923839347153,26.743371399751158,0.5988026581680694
0.0005364081650841103,0.0021295999999999997,315.29756937600996,26.743371399751158,0.5988026581680694
0.0005404382790216318,0.0021456,315.4158433665319,26.743371399751158,0.5988026581680694
0.0005452744157466576,0.0021647999999999997,315.55731907627296,26.743371399751158,0.5988026581680694
0.0005503120581685594,0.0021847999999999998,315.7041702149765,26.743371399751158,0.5988026581680694
0.0005555512062873374,0.0022056,315.8563403229114,26.743371399751158,0.5988026581680694
0.0005563572290748417,0.0022088,315.87970134125777,26.743371399751158,0.5988026581680694
0.0005593798145279828,0.0022207999999999998,315.96718785343916,26.743371399751158,0.5988026581680694
0.0005611933657998675,0.002228,316.0195912700527,26.743371399751158,0.5988026581680694
0.0005640144455561325,0.0022392,316.10097661201166,26.743371399751158,0.5988026581680694
0.0005660295025248933,0.0022472,316.1590118303761,26.743371399751158,0.5988026581680694
0.0005728806962186798,0.0022743999999999998,316.3557316498927,26.743371399751158,0.5988026581680694
0.0005809409240937227,0.0023063999999999997,316.5859958924632,26.743371399751158,0.5988026581680694
0.0005835604981531118,0.0023168,316.66056305545027,26.743371399751158,0.5988026581680694
0.0005879936234843854,0.0023344,316.78645693065425,26.743371399751158,0.5988026581680694
0.0005906131975437743,0.0023447999999999997,316.8606747746094,26.743371399751158,0.5988026581680694
0.0005966583684500566,0.0023688,317.0314584769257,26.743371399751158,0.5988026581680694
0.0006010914937813303,0.0023864,317.15627127117915,26.743371399751158,0.5988026581680694
0.0006115697900188862,0.002428,317.44986484253656,26.743371399751158,0.5988026581680694
0.000613987858381399,0.0024376,317.51733782643794,26.743371399751158,0.5988026581680694
0.000619428512197053,0.0024592,317.668774276229,26.743371399751158,0.5988026581680694
0.0006212420634689377,0.0024664,317.71913769966017,26.743371399751158,0.5988026581680694
0.0006284962685564764,0.0024952,317.9200206396244,26.743371399751158,0.5988026581680694
0.0006329293938877501,0.0025128,318.0423373508521,26.743371399751158,0.5988026581680694
0.0006363549907346433,0.0025264,318.1366261055611,26.743371399751158,0.5988026581680694
0.0006397805875815365,0.0025399999999999997,318.2307171141363,26.743371399751158,0.5988026581680694
0.0006474378040628274,0.0025704,318.44033063423666,26.743371399751158,0.5988026581680694
0.0006482438268503316,0.0025735999999999997,318.4623388252693,26.743371399751158,0.5988026581680694
0.0006506618952128446,0.0025832,318.5282994536902,26.743371399751158,0.5988026581680694
0.0006538859863628617,0.002596,318.61609843788244,26.743371399751158,0.5988026581680694
0.0006617447085410286,0.0026271999999999997,318.82940412092444,26.743371399751158,0.5988026581680694
0.0006623492256316568,0.0026295999999999997,318.8457712162077,26.743371399751158,0.5988026581680694
0.0006663793395691784,0.0026455999999999997,318.9547366843366,26.743371399751158,0.5988026581680694
0.0006694019250223195,0.0026576,319.03629220272944,26.743371399751158,0.5988026581680694
0.0006704094535066999,0.0026616,319.06344544388395,26.743371399751158,0.5988026581680694
0.0006714169819910802,0.0026655999999999997,319.09058277481006,26.743371399751158,0.5988026581680694
0.0006746410731410975,0.0026784,319.17731570271735,26.743371399751158,0.5988026581680694
0.0006794772098661232,0.0026976,319.30711261037317,26.743371399751158,0.5988026581680694
0.0006806862440473796,0.0027023999999999998,319.33950548051644,26.743371399751158,0.5988026581680694
0.0006851193693786533,0.0027199999999999998,319.45808784454596,26.743371399751158,0.5988026581680694
0.0006875374377411662,0.0027296,319.5226429921582,26.743371399751158,0.5988026581680694
0.0006935826086474484,0.0027535999999999997,319.6836446794549,26.743371399751158,0.5988026581680694
0.0006968066997974656,0.0027664,319.7692884281172,26.743371399751158,0.5988026581680694
0.0007018443422193675,0.0027864,319.90279804216095,26.743371399751158,0.5988026581680694
0.0007050684333693847,0.0027992,319.9880480974647,26.743371399751158,0.5988026581680694
0.0007074865017318976,0.0028087999999999998,320.0518859036768,26.743371399751158,0.5988026581680694
0.0007117181213662951,0.0028255999999999997,320.16339768800896,26.743371399751158,0.5988026581680694
0.0007185693150600817,0.0028528,320.3433939140298,26.743371399751158,0.5988026581680694
0.0007236069574819836,0.0028728,320.47531736722453,26.743371399751158,0.5988026581680694
0.0007304581511757701,0.0029,320.65415988019066,26.743371399751158,0.5988026581680694
0.0007342867594164155,0.0029151999999999997,320.7538163200271,26.743371399751158,0.5988026581680694
0.0007371078391726805,0.0029264,320.8271177567175,26.743371399751158,0.5988026581680694
0.0007381153676570608,0.0029303999999999997,320.85327031532387,26.743371399751158,0.5988026581680694
0.0007403319303226978,0.0029392,320.9107569878022,26.743371399751158,0.5988026581680694
0.0007443620442602192,0.0029552,321.0151065314515,26.743371399751158,0.5988026581680694
0.0007457725841383517,0.0029608,321.0515767869339,26.743371399751158,0.5988026581680694
0.0007473846297133603,0.0029671999999999997,321.09322415409616,26.743371399751158,0.5988026581680694
0.0007502057094696254,0.0029784,321.16602284530904,26.743371399751158,0.5988026581680694
0.0007649156253415788,0.0030367999999999997,321.54390009503277,26.743371399751158,0.5988026581680694
0.0007679382107947199,0.0030488,321.6211939199936,26.743371399751158,0.5988026581680694
0.0007731773589134979,0.0030696,321.7548894073108,26.743371399751158,0.5988026581680694
0.0007759984386697629,0.0030808,321.82673292187036,26.743371399751158,0.5988026581680694
0.0007784165070322757,0.0030903999999999997,321.88823204217226,26.743371399751158,0.5988026581680694
0.0007800285526072844,0.0030968,321.92919006876053,26.743371399751158,0.5988026581680694
0.0007832526437573015,0.0031095999999999997,322.01100722063006,26.743371399751158,0.5988026581680694
0.0007840586665448059,0.0031127999999999998,322.03144097298116,26.743371399751158,0.5988026581680694
0.000787081251997947,0.0031248,322.10799469062016,26.743371399751158,0.5988026581680694
0.0007886932975729556,0.0031311999999999998,322.14877645530584,26.743371399751158,0.5988026581680694
0.0007909098602385925,0.00314,322.20479834103276,26.743371399751158,0.5988026581680694
0.0007939324456917335,0.003152,322.2810932428196,26.743371399751158,0.5988026581680694
0.0007975595482355029,0.0031663999999999998,322.37249775779605,26.743371399751158,0.5988026581680694
0.000800582133688644,0.0031784,322.4485444133441,26.743371399751158,0.5988026581680694
0.0008056197761105458,0.0031983999999999997,322.57504047930587,26.743371399751158,0.5988026581680694
0.0008175086122262343,0.0032456,322.8723543523572,26.743371399751158,0.5988026581680694
0.0008185161407106146,0.0032496,322.89747267577997,26.743371399751158,0.5988026581680694
0.0008231507717387643,0.0032679999999999996,323.01286200784267,26.743371399751158,0.5988026581680694
0.0008334275622794441,0.0033087999999999998,323.2678253206709,26.743371399751158,0.5988026581680694
0.0008356441249450809,0.0033176,323.32265632318416,26.743371399751158,0.5988026581680694
0.0008374576762169656,0.0033247999999999997,323.36747587514435,26.743371399751158,0.5988026581680694
0.0008392712274888503,0.003332,323.41225759015526,26.743371399751158,0.5988026581680694
0.0008420923072451153,0.0033431999999999997,323.481843096371,26.743371399751158,0.5988026581680694
0.0008451148926982565,0.0033552,323.55629818405936,26.743371399751158,0.5988026581680694
0.0008457194097888847,0.0033575999999999996,323.57117673131035,26.743371399751158,0.5988026581680694
0.0008485404895451497,0.0033688,323.64055518408685,26.743371399751158,0.5988026581680694
0.0008523690977857952,0.003384,323.73456794320424,26.743371399751158,0.5988026581680694
0.000854384154754556,0.003392,323.78398218598886,26.743371399751158,0.5988026581680694
0.0008584142686920774,0.003408,323.88267452727695,26.743371399751158,0.5988026581680694
0.0008596233028733338,0.0034127999999999997,323.912246970851,26.743371399751158,0.5988026581680694
0.0008676835307483768,0.0034448,324.10898368899944,26.743371399751158,0.5988026581680694
0.0008692955763233854,0.0034511999999999998,324.1482453625001,26.743371399751158,0.5988026581680694
0.0008717136446858983,0.0034608,324.20708467399425,26.743371399751158,0.5988026581680694
0.000873728701654659,0.0034687999999999997,324.2560688246747,26.743371399751158,0.5988026581680694
0.0008781618269859327,0.0034863999999999997,324.36367913755674,26.743371399751158,0.5988026581680694
0.0008791693554703131,0.0034904,324.38810645552036,26.743371399751158,0.5988026581680694
0.0008827964580140824,0.0035047999999999998,324.47595454751445,26.743371399751158,0.5988026581680694
0.0008852145263765954,0.0035144,324.53444175198325,26.743371399751158,0.5988026581680694
0.0008856175377703475,0.003516,324.54418355848134,26.743371399751158,0.5988026581680694
0.0008930732485547623,0.0035456,324.72409629699933,26.743371399751158,0.5988026581680694
0.0009003274536423008,0.0035743999999999997,324.8985851389058,26.743371399751158,0.5988026581680694
0.0009081861758204678,0.0036056,325.0869971258968,26.743371399751158,0.5988026581680694
0.0009186644720580237,0.0036471999999999997,325.33722698180196,26.743371399751158,0.5988026581680694
0.0009249111486611819,0.003672,325.4858729210764,26.743371399751158,0.5988026581680694
0.0009315608366580924,0.0036983999999999997,325.64367933310393,26.743371399751158,0.5988026581680694
0.0009343819164143575,0.0037096,325.71049471585405,26.743371399751158,0.5988026581680694
0.0009376060075643747,0.0037224,325.78675889332146,26.743371399751158,0.5988026581680694
0.0009470767753175502,0.00376,326.0101956426638,26.743371399751158,0.5988026581680694
0.000949494843680063,0.0037695999999999997,326.0671034669204,26.743371399751158,0.5988026581680694
0.000951912912042576,0.0037792,326.1239547978101,26.743371399751158,0.5988026581680694
0.0009555400145863453,0.0037936,326.2091263048829,26.743371399751158,0.5988026581680694
0.0009611821740988754,0.003816,326.34136512728526,26.743371399751158,0.5988026581680694
0.0009644062652488925,0.0038288,326.41679424323087,26.743371399751158,0.5988026581680694
0.0009678318620957858,0.0038423999999999997,326.4968300027193,26.743371399751158,0.5988026581680694
0.0009720634817301834,0.0038591999999999997,326.59554533744455,26.743371399751158,0.5988026581680694
0.0009730710102145637,0.0038632,326.61902426930754,26.743371399751158,0.5988026581680694
0.0009805267209989784,0.0038927999999999996,326.7924746543926,26.743371399751158,0.5988026581680694
0.0009841538235427479,0.0039071999999999996,326.876669878788,26.743371399751158,0.5988026581680694
0.0009877809260865173,0.0039216,326.9607441720811,26.743371399751158,0.5988026581680694
0.0009922140514177908,0.0039391999999999995,327.0633383134748,26.743371399751158,0.5988026581680694
0.0009988637394147014,0.0039656,327.2168949698008,26.743371399751158,0.5988026581680694
0.0009994682565053297,0.003968,327.2308348665232,26.743371399751158,0.5988026581680694
0.0010123655885262276,0.004019203840768154,327.5274627133954,26.743371399751158,0.5988026581680694
0.001094596359005762,0.0043456691338267656,329.3851790474516,26.743371399751158,0.5988026581680694
0.0011478045046101665,0.004556911382276456,330.55827463509945,26.743371399751158,0.5988026581680694
0.001215523962652136,0.0048257651530306065,332.0210669047904,26.743371399751158,0.5988026581680694
0.0013364515662985098,0.0053058611722344474,334.5564473555248,26.743371399751158,0.5988026581680694
0.0013944968160487694,0.005536307261452291,335.741488696036,26.743371399751158,0.5988026581680694
0.0014718904823824487,0.0058435687137427484,337.29203515644303,26.743371399751158,0.5988026581680694
0.0016024922943205326,0.006362072414482897,339.8383131218704,26.743371399751158,0.5988026581680694
0.0018298361891757155,0.007264652930586117,344.0853635377262,26.743371399751158,0.5988026581680694
0.00189271854307183,0.007514302860572114,345.2230518901957,26.743371399751158,0.5988026581680694
0.001907229855509395,0.007571914382876575,345.4834904660531,26.743371399751158,0.5988026581680694
0.0019749493135513643,0.007840768153630726,346.6887963867072,26.743371399751158,0.5988026581680694
0.0020039719384264943,0.007955991198239648,347.2004094693839,26.743371399751158,0.5988026581680694
0.002187781895968983,0.008685737147429486,350.3759783400335,26.743371399751158,0.5988026581680694
0.002274849770594372,0.009031406281256251,351.8437000710534,26.743371399751158,0.5988026581680694
0.002376428957657326,0.009434686937387478,353.5286289635237,26.743371399751158,0.5988026581680694
0.0024731710405744255,0.00981876375275055,355.10739251625506,26.743371399751158,0.5988026581680694
0.002521542082032975,0.010010802160432087,355.8877279962255,26.743371399751158,0.5988026581680694
0.002608609956658364,0.010356471294258852,357.2777760181377,26.743371399751158,0.5988026581680694
0.0027247004561588833,0.01081736347269454,359.1033433177452,26.743371399751158,0.5988026581680694
0.0029472072468682115,0.011700740148029607,362.5196800370881,26.743371399751158,0.5988026581680694
0.003077809058806295,0.012219243848769754,364.47805245423234,26.743371399751158,0.5988026581680694
0.003193899558306814,0.01268013602720544,366.1917768717285,26.743371399751158,0.5988026581680694
0.0032519448080570736,0.012910582116423285,367.03951572416906,26.743371399751158,0.5988026581680694
0.0032712932246404935,0.012987397479495899,367.32078122479936,26.743371399751158,0.5988026581680694
0.003348686890974173,0.013294658931786357,368.4394152535215,26.743371399751158,0.5988026581680694
0.003474451598766402,0.013793958791758352,370.235925239077,26.743371399751158,0.5988026581680694
0.0035131484319332416,0.013947589517903581,370.78357139441516,26.743371399751158,0.5988026581680694
0.0035470081609542264,0.014082016403280656,371.26083480445436,26.743371399751158,0.5988026581680694
0.0037598407433718445,0.014926985397079416,374.2210822558796,26.743371399751158,0.5988026581680694
0.003851745722143089,0.015291858371674336,375.4790826789728,26.743371399751158,0.5988026581680694
0.003924302284330913,0.01557991598319664,376.4639902571586,26.743371399751158,0.5988026581680694
0.0040355556796855775,0.016021604320864174,377.96049885147363,26.743371399751158,0.5988026581680694
0.0040694154087065615,0.016156031206241248,378.4127528748049,26.743371399751158,0.5988026581680694
0.004238714053811486,0.016828165633126627,380.65237556196934,26.743371399751158,0.5988026581680694
0.0043015964077076,0.017077815563112622,381.47531436451635,26.743371399751158,0.5988026581680694
0.0044080126989164085,0.017500300060012002,382.85737102255376,26.743371399751158,0.5988026581680694
0.004461220844520813,0.01771154230846169,383.54351508500145,26.743371399751158,0.5988026581680694
0.0045869855523130425,0.01821084216843369,385.1527459073533,26.743371399751158,0.5988026581680694
0.004654705010355011,0.018479695939187836,386.01212320205997,26.743371399751158,0.5988026581680694
0.004727261572542836,0.018767753550710142,386.92749131501523,26.743371399751158,0.5988026581680694
0.004746609989126256,0.018844568913782757,387.1706620012751,26.743371399751158,0.5988026581680694
0.004853026280335065,0.019267053410682137,388.50125405992856,26.743371399751158,0.5988026581680694
0.004891723113501905,0.019420684136827366,388.9822781537746,26.743371399751158,0.5988026581680694
0.005027162029585844,0.019958391678335668,390.654298737055,26.743371399751158,0.5988026581680694
0.005094881487627813,0.02022724544908982,391.483713920809,26.743371399751158,0.5988026581680694
0.005220646195420042,0.020726545309061813,393.01273792400514,26.743371399751158,0.5988026581680694
0.0052932027576078665,0.021014602920584116,393.8883320498476,26.743371399751158,0.5988026581680694
0.005385107736379111,0.021379475895179037,394.9907272223795,26.743371399751158,0.5988026581680694
0.005525383756608904,0.02193638727745549,396.659287841217,26.743371399751158,0.5988026581680694
0.005564080589775744,0.02209001800360072,397.11666253366656,26.743371399751158,0.5988026581680694
0.005665659776838698,0.022493298659731948,398.31140720981614,26.743371399751158,0.5988026581680694
0.005796261588776782,0.023011802360472094,399.835302935017,26.743371399751158,0.5988026581680694
0.005893003671693882,0.023395879175835167,400.9554949109718,26.743371399751158,0.5988026581680694
0.005926863400714867,0.023530306061212244,401.3458647346652,26.743371399751158,0.5988026581680694
0.0060090941711944,0.023856771354270855,402.29030226629897,26.743371399751158,0.5988026581680694
0.006081650733382225,0.024144828965793157,403.1194516207501,26.743371399751158,0.5988026581680694
0.0062461122743412935,0.02479775955191038,404.9847049361491,26.743371399751158,0.5988026581680694
0.006294483315799843,0.024989797959591917,405.5296507086298,26.743371399751158,0.5988026581680694
0.006391225398716942,0.02537387477495499,406.61466714865713,26.743371399751158,0.5988026581680694
0.0064589448567589115,0.02564272854570914,407.3703706755611,26.743371399751158,0.5988026581680694
0.006512153002363317,0.025853970794158833,407.9619720932012,26.743371399751158,0.5988026581680694
0.00663308060600969,0.026334066813362672,409.29955428083247,26.743371399751158,0.5988026581680694
0.00667177743917653,0.0264876975395079,409.7255675347194,26.743371399751158,0.5988026581680694
0.006768519522093629,0.026871774354870974,410.78640624547603,26.743371399751158,0.5988026581680694
0.006787867938677049,0.02694858971794359,410.99786258469084,26.743371399751158,0.5988026581680694
0.006807216355260469,0.027025405081016203,411.2090839840542,26.743371399751158,0.5988026581680694
0.006865261605010728,0.027255851170234047,411.84134778869867,26.743371399751158,0.5988026581680694
0.007034560250115653,0.027927985597119426,413.6736497730199,26.743371399751158,0.5988026581680694
0.0071313023330327515,0.0283120624124825,414.7129567283208,26.743371399751158,0.5988026581680694
0.007334460707158659,0.029118623724744948,416.8777712500288,26.743371399751158,0.5988026581680694
0.007537619081284567,0.0299251850370074,419.0193223171153,26.743371399751158,0.5988026581680694
0.007581153018597263,0.030098019603920785,419.47528382302477,26.743371399751158,0.5988026581680694
0.007726266142972911,0.030674134826965394,420.9878340274569,26.743371399751158,0.5988026581680694
0.0077794742885773155,0.030885377075415082,421.5396545600786,26.743371399751158,0.5988026581680694
0.007823008225890011,0.031058211642328467,421.9900500756157,26.743371399751158,0.5988026581680694
0.007948772933682239,0.03155751150230046,423.2857342104991,26.743371399751158,0.5988026581680694
0.007972958454411514,0.03165353070614123,423.5339850171093,26.743371399751158,0.5988026581680694
0.008031003704161774,0.03188397679535907,424.12859174464495,26.743371399751158,0.5988026581680694
0.00821481366170426,0.032613722744548906,426.000550158337,26.743371399751158,0.5988026581680694
0.008306718640475505,0.03297859571914383,426.9303981907798,26.743371399751158,0.5988026581680694
0.008326067057058927,0.03305541108221645,427.1256434444358,26.743371399751158,0.5988026581680694
0.008364763890225767,0.03320904180836168,427.5156039113295,26.743371399751158,0.5988026581680694
0.008451831764851156,0.03355471094218844,428.39045168823674,26.743371399751158,0.5988026581680694
0.008529225431184834,0.0338619723944789,429.16514774007436,26.743371399751158,0.5988026581680694
0.00865982724312292,0.03438047609521905,430.46625937185036,26.743371399751158,0.5988026581680694
0.008688849867998049,0.034495699139827966,430.75435340649824,26.743371399751158,0.5988026581680694
0.00897423901260349,0.035628725745149026,433.5675692112257,26.743371399751158,0.5988026581680694
0.009133863449416704,0.0362624524904981,435.1258414324879,26.743371399751158,0.5988026581680694
0.00933218471939676,0.037049809961992405,437.0471597548755,26.743371399751158,0.5988026581680694
0.00938539286500116,0.03726105221044208,437.5599177366136,26.743371399751158,0.5988026581680694
0.009477297843772405,0.037625925185037004,438.442928299907,26.743371399751158,0.5988026581680694
0.009694967530335878,0.038490098019603916,440.5210535584939,26.743371399751158,0.5988026581680694
0.00974333857179443,0.03868213642728546,440.9803787322344,26.743371399751158,0.5988026581680694
0.009893288800315933,0.03927745549109822,442.39866755049735,26.743371399751158,0.5988026581680694
0.010110958486879406,0.04014162832566513,444.4426458642868,26.743371399751158,0.5988026581680694
0.010270582923692621,0.04077535507101421,445.93067246273745,26.743371399751158,0.5988026581680694
0.010575320484881481,0.04198519703940788,448.7466399864822,26.743371399751158,0.5988026581680694
0.010681736776090292,0.042407681536307265,449.72251506258164,26.743371399751158,0.5988026581680694
0.010763967546569823,0.04273414682936587,450.4740056812822,26.743371399751158,0.5988026581680694
0.010967125920695734,0.04354070814162833,452.3210941259254,26.743371399751158,0.5988026581680694
0.011010659858008427,0.043713542708541706,452.71515717733155,26.743371399751158,0.5988026581680694
0.011088053524342107,0.044020804160832164,453.41421665108874,26.743371399751158,0.5988026581680694
0.011160610086529934,0.04430886177235448,454.06785862274035,26.743371399751158,0.5988026581680694
0.011329908731634855,0.04498099619923984,455.58661201341863,26.743371399751158,0.5988026581680694
0.011416976606260246,0.04532666533306662,456.3642371875028,26.743371399751158,0.5988026581680694
0.01148953316844807,0.04561472294458892,457.01049299806596,26.743371399751158,0.5988026581680694
0.011600786563802732,0.046056411282256446,457.9983358356562,26.743371399751158,0.5988026581680694
0.011697528646719833,0.046440488097619526,458.8543301859545,26.743371399751158,0.5988026581680694
0.01182329335451206,0.04693978795759152,459.96300653808885,26.743371399751158,0.5988026581680694
0.011953895166450146,0.04745829165833167,461.1094671540278,26.743371399751158,0.5988026581680694
0.012099008290825795,0.04803440688137628,462.37759822163315,26.743371399751158,0.5988026581680694
0.012215098790326314,0.04849529905981197,463.38783733032136,26.743371399751158,0.5988026581680694
0.012244121415201441,0.04861052210442088,463.6398111830453,26.743371399751158,0.5988026581680694
0.012316677977389268,0.04889857971594319,464.26872887924725,26.743371399751158,0.5988026581680694
0.012336026393972686,0.0489753950790158,464.4361960262319,26.743371399751158,0.5988026581680694
0.01246662820591077,0.04949389877975595,465.56393179473935,26.743371399751158,0.5988026581680694
0.012519836351515176,0.04970514102820564,466.0220576203553,26.743371399751158,0.5988026581680694
0.012640763955161552,0.05018523704740949,467.0604380948596,26.743371399751158,0.5988026581680694
0.012979361245371395,0.05152950590118023,469.9474926791239,26.743371399751158,0.5988026581680694
0.013080940432434353,0.05193278655731147,470.8078615669953,26.743371399751158,0.5988026581680694
0.013143822786330467,0.052182436487297465,471.3391652799868,26.743371399751158,0.5988026581680694
0.013259913285830986,0.05264332866573315,472.3174365255939,26.743371399751158,0.5988026581680694
0.013366329577039792,0.05306581316263252,473.21125481802994,26.743371399751158,0.5988026581680694
0.013458234555811037,0.05343068613722744,473.98095768868836,26.743371399751158,0.5988026581680694
0.013608184784332542,0.054026005201040214,475.2324024118027,26.743371399751158,0.5988026581680694
0.01383069157504187,0.05490938187637527,477.07951910704605,26.743371399751158,0.5988026581680694
0.014019338636730215,0.05565833166633327,478.63649247294126,26.743371399751158,0.5988026581680694
0.014067709678188763,0.055850370074014805,479.03439759020273,26.743371399751158,0.5988026581680694
0.014275705156460526,0.05667613522704541,480.73934508358514,26.743371399751158,0.5988026581680694
0.014420818280836176,0.057252250450090025,481.9231104356691,26.743371399751158,0.5988026581680694
0.01452239746789913,0.05765553110622125,482.7489835356277,26.743371399751158,0.5988026581680694
0.014619139550816227,0.058039607921584316,483.5334373129201,26.743371399751158,0.5988026581680694
0.014672347696420633,0.05825085017003401,483.96402385033394,26.743371399751158,0.5988026581680694
0.014696533217149907,0.058346869373874774,484.1595436453254,26.743371399751158,0.5988026581680694
0.01476908977933773,0.05863492698539707,484.74535149884684,26.743371399751158,0.5988026581680694
0.014812623716650427,0.05880776155231046,485.09629748902944,26.743371399751158,0.5988026581680694
0.014894854487129962,0.05913422684536908,485.7580999116138,26.743371399751158,0.5988026581680694
0.014962573945171928,0.05940308061612322,486.30204441072044,26.743371399751158,0.5988026581680694
0.015073827340526594,0.05984476895379076,487.1935877951758,26.743371399751158,0.5988026581680694
0.015146383902714418,0.06013282656531306,487.7736469019038,26.743371399751158,0.5988026581680694
0.015344705172694473,0.060920184036807365,489.35363879640494,26.743371399751158,0.5988026581680694
0.015393076214153022,0.0611122224444889,489.73779212705693,26.743371399751158,0.5988026581680694
0.015465632776340844,0.0614002800560112,490.3131405671025,26.743371399751158,0.5988026581680694
0.015605908796570641,0.061957191438287665,491.42250462960544,26.743371399751158,0.5988026581680694
0.01571232508777945,0.062379675935187034,492.26149888810033,26.743371399751158,0.5988026581680694
0.015818741378988258,0.06280216043208642,493.0982799409094,26.743371399751158,0.5988026581680694
0.015910646357759503,0.06316703340668134,493.81918929034725,26.743371399751158,0.5988026581680694
0.01604608527384344,0.06370474094818963,494.8786288976688,26.743371399751158,0.5988026581680694
0.0161041305235937,0.06393518703740748,495.33160620257524,26.743371399751158,0.5988026581680694
0.016394356772344996,0.0650874174834967,497.58701121014064,26.743371399751158,0.5988026581680694
0.01645723912624111,0.06533706741348269,498.0736237087441,26.743371399751158,0.5988026581680694
0.016524958584283083,0.06560592118423685,498.5968576983637,26.743371399751158,0.5988026581680694
0.01657332962574163,0.06579795959191838,498.97008440566685,26.743371399751158,0.5988026581680694
0.016626537771346036,0.06600920184036807,499.3801434520307,26.743371399751158,0.5988026581680694
0.016732954062554845,0.06643168633726745,500.1987294117108,26.743371399751158,0.5988026581680694
0.016800673520596814,0.06670054010802161,500.7185908139551,26.743371399751158,0.5988026581680694
0.01682485904132609,0.06679655931186237,500.9040574672747,26.743371399751158,0.5988026581680694
0.017018343207160287,0.06756471294258852,502.38406592140933,26.743371399751158,0.5988026581680694
0.01705704004032713,0.06771834366873375,502.67927855085213,26.743371399751158,0.5988026581680694
0.017182804748119358,0.06821764352870574,503.6369207336082,26.743371399751158,0.5988026581680694
0.017279546831036458,0.06860172034406882,504.3717096183427,26.743371399751158,0.5988026581680694
0.017410148642974542,0.06912022404480897,505.36113470549736,26.743371399751158,0.5988026581680694
0.017589121496371176,0.06983076615323065,506.7123250478121,26.743371399751158,0.5988026581680694
0.017618144121246307,0.06994598919783958,506.93093074135385,26.743371399751158,0.5988026581680694
0.01764232964197558,0.07004200840168034,507.1129948899369,26.743371399751158,0.5988026581680694
0.01767618937099656,0.07017643528705741,507.3677212529393,26.743371399751158,0.5988026581680694
0.017729397516600968,0.0703876775355071,507.76762139668386,26.743371399751158,0.5988026581680694
0.017845488016101488,0.0708485697139428,508.6385097401318,26.743371399751158,0.5988026581680694
0.01795674141145615,0.07129025805161032,509.47104009004806,26.743371399751158,0.5988026581680694
0.01809218032754009,0.07182796559311863,510.48184509575213,26.743371399751158,0.5988026581680694
0.018135714264852783,0.072000800160032,510.80611940764607,26.743371399751158,0.5988026581680694
0.018222782139478175,0.07234646929385878,511.45375873182644,26.743371399751158,0.5988026581680694
0.018261478972645014,0.07250010002000401,511.74121094196227,26.743371399751158,0.5988026581680694
0.01831468711824942,0.0727113422684537,512.1360701455554,26.743371399751158,0.5988026581680694
0.018435614721895793,0.07319143828765753,513.0318173594784,26.743371399751158,0.5988026581680694
0.018585564950417292,0.07378675735147029,514.1393678310417,26.743371399751158,0.5988026581680694
0.01864844730431341,0.0740364072814563,514.6027867024598,26.743371399751158,0.5988026581680694
0.01878388622039735,0.0745741148229646,515.5988548237178,26.743371399751158,0.5988026581680694
0.01889513961575201,0.07501580316063212,516.4149599314627,26.743371399751158,0.5988026581680694
0.018948347761356416,0.07522704540908182,516.8046084249268,26.743371399751158,0.5988026581680694
0.019045089844273517,0.0756111222244449,517.511968734459,26.743371399751158,0.5988026581680694
0.019257922426691134,0.07645609121824365,519.063247447361,26.743371399751158,0.5988026581680694
0.019325641884733104,0.0767249449889978,519.5554320572443,26.743371399751158,0.5988026581680694
0.019436895280087768,0.07716663332666533,520.3625633595519,26.743371399751158,0.5988026581680694
0.01948526632154632,0.07735867173434688,520.7129278122875,26.743371399751158,0.5988026581680694
0.019538474467150724,0.07756991398279657,521.0979371612557,26.743371399751158,0.5988026581680694
0.019591682612755127,0.07778115623124625,521.482537820808,26.743371399751158,0.5988026581680694
0.019640053654213677,0.0779731946389278,521.8318214339432,26.743371399751158,0.5988026581680694
0.019678750487380516,0.07812682536507302,522.1110068289535,26.743371399751158,0.5988026581680694
0.019920605694673264,0.0790870174034807,523.8510895191796,26.743371399751158,0.5988026581680694
0.020007673569298653,0.07943268653730746,524.4754998034523,26.743371399751158,0.5988026581680694
0.020065718819048915,0.07966313262652532,524.8911846887833,26.743371399751158,0.5988026581680694
0.020462361359009022,0.08123784756951391,527.7192507247344,26.743371399751158,0.5988026581680694
0.020530080817050992,0.08150670134026806,528.1999466615415,26.743371399751158,0.5988026581680694
0.020641334212405653,0.08194838967793559,528.9883211289148,26.743371399751158,0.5988026581680694
0.020709053670447623,0.08221724344868975,529.4673899305624,26.743371399751158,0.5988026581680694
0.02076226181605203,0.08242848569713944,529.8433726552379,26.743371399751158,0.5988026581680694
0.020839655482385706,0.08273574714942988,530.3895864962875,26.743371399751158,0.5988026581680694
0.021023465439928193,0.08346549309861973,531.6836834527862,26.743371399751158,0.5988026581680694
0.021129881731137005,0.08388797759551911,532.430880613576,26.743371399751158,0.5988026581680694
0.021255646438929233,0.0843872774554911,533.3120423240023,26.743371399751158,0.5988026581680694
0.02136206273013804,0.08480976195239048,534.0560536957443,26.743371399751158,0.5988026581680694
0.021434619292325867,0.08509781956391278,534.5625056139987,26.743371399751158,0.5988026581680694
0.02149750164622198,0.08534746949389878,535.0008900327438,26.743371399751158,0.5988026581680694
0.0215603840001181,0.08559711942388479,535.4387746315687,26.743371399751158,0.5988026581680694
0.02175870527009815,0.08638447689537908,536.8165440250453,26.743371399751158,0.5988026581680694
0.021797402103264987,0.08653810762152431,537.0848051072301,26.743371399751158,0.5988026581680694
0.021836098936431826,0.08669173834766954,537.3528805189161,26.743371399751158,0.5988026581680694
0.021961863644224058,0.08719103820764153,538.2228488326135,26.743371399751158,0.5988026581680694
0.021995723373245044,0.08732546509301861,538.4567388313362,26.743371399751158,0.5988026581680694
0.022150510705912403,0.08793998799759953,539.524167149583,26.743371399751158,0.5988026581680694
0.02227627541370463,0.08843928785757152,540.3893122251957,26.743371399751158,0.5988026581680694
0.022479433787830537,0.08924584916983397,541.7828411691985,26.743371399751158,0.5988026581680694
0.022590687183185205,0.08968753750750151,542.5438825302176,26.743371399751158,0.5988026581680694
0.022624546912206188,0.08982196439287858,542.7752135029086,26.743371399751158,0.5988026581680694
0.022784171349019403,0.09045569113822766,543.863960342659,26.743371399751158,0.5988026581680694
0.0228809134319365,0.09083976795359072,544.5223592397581,26.743371399751158,0.5988026581680694
0.02290993605681163,0.09095499099819965,544.7196670880842,26.743371399751158,0.5988026581680694
0.0229776555148536,0.0912238447689538,545.1796733627573,26.743371399751158,0.5988026581680694
0.023277555971896607,0.09241448289657932,547.2105215745476,26.743371399751158,0.5988026581680694
0.02333076411750101,0.09262572514502901,547.5697649583088,26.743371399751158,0.5988026581680694
0.02338880936725127,0.09285617123424686,547.9613026130639,26.743371399751158,0.5988026581680694
0.02351941117918935,0.093374674934987,548.8408794057227,26.743371399751158,0.5988026581680694
0.023572619324793757,0.09358591718343669,549.1986791536946,26.743371399751158,0.5988026581680694
0.02367419851185671,0.09398919783956791,549.8808779739,26.743371399751158,0.5988026581680694
0.02375159217819039,0.09429645929185837,550.3998825516173,26.743371399751158,0.5988026581680694
0.023780614803065522,0.0944116823364673,550.5943391751355,26.743371399751158,0.5988026581680694
0.02388703109427433,0.09483416683336668,551.3065563120791,26.743371399751158,0.5988026581680694
0.023949913448170445,0.09508381676335267,551.726830259387,26.743371399751158,0.5988026581680694
0.024032144218649982,0.09541028205641129,552.2757704964541,26.743371399751158,0.5988026581680694
0.02412888630156708,0.09579435887177436,552.9206455706121,26.743371399751158,0.5988026581680694
0.024172420238879774,0.09596719343868775,553.21051029497,26.743371399751158,0.5988026581680694
0.024182094447171485,0.09600560112022405,553.2748970211699,26.743371399751158,0.5988026581680694
0.0242449768010676,0.09625525105021004,553.6931661445741,26.743371399751158,0.5988026581680694
0.02431269625910957,0.0965241048209642,554.1431369441468,26.743371399751158,0.5988026581680694
0.02445297227933936,0.09708101620324065,555.0736673722165,26.743371399751158,0.5988026581680694
0.024617433820298427,0.09773394678935787,556.1619870483968,26.743371399751158,0.5988026581680694
0.024719013007361384,0.0981372274454891,556.8327680904079,26.743371399751158,0.5988026581680694
0.024767384048819934,0.09832926585317064,557.1518097158427,26.743371399751158,0.5988026581680694
0.024815755090278484,0.09852130426085218,557.4706084274706,26.743371399751158,0.5988026581680694
0.024883474548320454,0.09879015803160633,557.9165197806143,26.743371399751158,0.5988026581680694
0.024941519798070712,0.09902060412082417,558.2983529534122,26.743371399751158,0.5988026581680694
0.02506728450586294,0.09951990398079616,559.1244712865397,26.743371399751158,0.5988026581680694
0.025154352380488333,0.09986557311462294,559.6954527031774,26.743371399751158,0.5988026581680694