File: datasets/aisi_316_L/data/M1/valid_4.csv
Time(s),Strain(%),Stress(MPa),Temp(C),Log_SR(s-1)
0.0,0.0,0.0,124.6271923703238,-3.146098608768294
0.054876281568904416,3.92e-05,7.5076354499999995,124.6271923703238,-3.146098608768294
0.07279506738732218,5.2e-05,9.95910825,124.6271923703238,-3.146098608768294
0.09519354966034439,6.8e-05,13.02344925,124.6271923703238,-3.146098608768294
0.1366307418654355,9.76e-05,18.6924801,124.6271923703238,-3.146098608768294
0.16462884470671324,0.0001176,22.52290635,124.6271923703238,-3.146098608768294
0.1847874787524332,0.00013199999999999998,25.280813249999998,124.6271923703238,-3.146098608768294
0.2161453539346643,0.00015439999999999999,29.570890649999996,124.6271923703238,-3.146098608768294
0.25198292557149987,0.00017999999999999998,34.47383625,124.6271923703238,-3.146098608768294
0.2867005730946843,0.0002048,39.2235648,124.6271923703238,-3.146098608768294
0.30685920714040427,0.0002192,41.9814717,124.6271923703238,-3.146098608768294
0.3113389035950087,0.00022239999999999998,42.594339899999994,124.6271923703238,-3.146098608768294
0.3169385241632643,0.0002264,43.36042515,124.6271923703238,-3.146098608768294
0.3314975376407287,0.00023679999999999998,45.352246799999996,124.6271923703238,-3.146098608768294
0.3426967787772398,0.0002448,46.884417299999996,124.6271923703238,-3.146098608768294
0.38525389509598196,0.00027519999999999997,52.706665199999996,124.6271923703238,-3.146098608768294
0.4098922255963064,0.00029279999999999996,56.07744029999999,124.6271923703238,-3.146098608768294
0.4143719220509109,0.000296,56.6903085,124.6271923703238,-3.146098608768294
0.4412501007785375,0.00031519999999999996,60.36751769999999,124.6271923703238,-3.146098608768294
0.4703681277334664,0.000336,64.35116099999999,124.6271923703238,-3.146098608768294
0.4782075965290242,0.0003416,65.42368035,124.6271923703238,-3.146098608768294
0.49276661000648864,0.000352,67.415502,124.6271923703238,-3.146098608768294
0.5207647128477664,0.000372,71.24592824999999,124.6271923703238,-3.146098608768294
0.5521225880299975,0.0003944,75.53600564999999,124.6271923703238,-3.146098608768294
0.5622019050528575,0.0004016,76.9149591,124.6271923703238,-3.146098608768294
0.576760918530322,0.000412,78.90678075,124.6271923703238,-3.146098608768294
0.6025191731442975,0.0004304,82.4307729,124.6271923703238,-3.146098608768294
0.6081187937125531,0.0004344,83.19685815,124.6271923703238,-3.146098608768294
0.6125984901671574,0.00043759999999999996,83.80972634999999,124.6271923703238,-3.146098608768294
0.6215578830763664,0.000444,85.03546275000001,124.6271923703238,-3.146098608768294
0.6305172759855753,0.0004504,86.26119915,124.6271923703238,-3.146098608768294
0.6428364412357375,0.0004592,87.9465867,124.6271923703238,-3.146098608768294
0.6887533298954329,0.0004919999999999999,94.22848574999999,124.6271923703238,-3.146098608768294
0.7122717362821063,0.0005088,97.4460438,124.6271923703238,-3.146098608768294
0.7268307497595706,0.0005191999999999999,99.43786544999999,124.6271923703238,-3.146098608768294
0.7548288526008485,0.0005392,103.26829169999999,124.6271923703238,-3.146098608768294
0.7671480178510107,0.000548,104.95367925,124.6271923703238,-3.146098608768294
0.7951461206922884,0.0005679999999999999,108.78410549999998,124.6271923703238,-3.146098608768294
0.8444227816929374,0.0006032,115.5256557,124.6271923703238,-3.146098608768294
0.8892197462389817,0.0006351999999999999,121.65433769999999,124.6271923703238,-3.146098608768294
0.9239373937621662,0.00066,126.40406625,124.6271923703238,-3.146098608768294
0.9317768625577239,0.0006655999999999999,127.47658559999998,124.6271923703238,-3.146098608768294
0.9698542824218617,0.0006927999999999999,132.6859653,124.6271923703238,-3.146098608768294
1.0101715505133018,0.0007216,138.20177909999998,124.6271923703238,-3.146098608768294
1.046009122150137,0.0007472,143.1047247,124.6271923703238,-3.146098608768294
1.0784869214460193,0.0007704,147.54801915,124.6271923703238,-3.146098608768294
1.1176842654238084,0.0007984,152.9106159,124.6271923703238,-3.146098608768294
1.125523734219366,0.0008039999999999999,153.98313524999998,124.6271923703238,-3.146098608768294
1.1445624441514348,0.0008175999999999999,156.58782509999998,124.6271923703238,-3.146098608768294
1.1859996363565262,0.0008472,162.25685595,124.6271923703238,-3.146098608768294
1.2218372079933615,0.0008728,167.15980155,124.6271923703238,-3.146098608768294
1.2386360696981282,0.0008847999999999999,169.45805729999998,124.6271923703238,-3.146098608768294
1.2677540966530572,0.0009056,173.4417006,124.6271923703238,-3.146098608768294
1.2979920477216371,0.0009272,177.57856095,124.6271923703238,-3.146098608768294
1.3181506817673572,0.0009416,180.33646785,124.6271923703238,-3.146098608768294
1.3439089363813326,0.0009599999999999999,183.86046,124.6271923703238,-3.146098608768294
1.3506284810632392,0.0009647999999999999,184.7797623,124.6271923703238,-3.146098608768294
1.3551081775178437,0.000968,185.3926305,124.6271923703238,-3.146098608768294
1.3752668115635638,0.0009824,188.15053740000002,124.6271923703238,-3.146098608768294
1.3887059009273772,0.000992,189.98914200000002,124.6271923703238,-3.146098608768294
1.3987852179502371,0.0009992,191.36809545,124.6271923703238,-3.146098608768294
1.4424622583826303,0.0010304,197.34356039999997,124.6271923703238,-3.146098608768294
1.4760599817921638,0.0010544,201.94007190000002,124.6271923703238,-3.146098608768294
1.5376558080429747,0.0010984,210.36700965,124.6271923703238,-3.146098608768294
1.549974973293137,0.0011072,212.0523972,124.6271923703238,-3.146098608768294
1.561174214429648,0.0011152,213.5845677,124.6271923703238,-3.146098608768294
1.5835726967026702,0.0011312,216.6489087,124.6271923703238,-3.146098608768294
1.602611406634739,0.0011447999999999999,219.25359854999996,124.6271923703238,-3.146098608768294
1.6597275364309458,0.0011856,221.33459813390357,124.6271923703238,-3.146098608768294
1.7078842733179436,0.00122,221.56362585117498,124.6271923703238,-3.146098608768294
1.7347624520455702,0.0012392,221.69035973036426,124.6271923703238,-3.146098608768294
1.7594007825458946,0.0012568,221.80586131472256,124.6271923703238,-3.146098608768294
1.7706000236824058,0.0012648,221.85815332946336,124.6271923703238,-3.146098608768294
1.7918785818417766,0.0012799999999999999,221.95715414480313,124.6271923703238,-3.146098608768294
1.8456349392970302,0.0013184,222.20524066135076,124.6271923703238,-3.146098608768294
1.864673649229099,0.0013319999999999999,222.29242675024818,124.6271923703238,-3.146098608768294
1.8971514485249812,0.0013552,222.44035891845508,124.6271923703238,-3.146098608768294
1.9273893995935611,0.0013767999999999999,222.57720344844728,124.6271923703238,-3.146098608768294
1.9497878818665835,0.0013928,222.6780305660258,124.6271923703238,-3.146098608768294
1.9587472747757924,0.0013992,222.71823480799068,124.6271923703238,-3.146098608768294
1.988985225844372,0.0014207999999999998,222.8533977419611,124.6271923703238,-3.146098608768294
2.0113837081173944,0.0014368,222.95300233414113,124.6271923703238,-3.146098608768294
2.0315423421631142,0.0014512,223.04227721377598,124.6271923703238,-3.146098608768294
2.0707396861409033,0.0014792,223.21488438295157,124.6271923703238,-3.146098608768294
2.105457333664088,0.001504,223.366703680469,124.6271923703238,-3.146098608768294
2.1636933875739452,0.0015455999999999998,223.61919393445524,124.6271923703238,-3.146098608768294
2.2017708074380833,0.0015727999999999998,223.78285191513913,124.6271923703238,-3.146098608768294
2.21856966914285,0.0015848,223.8547026555607,124.6271923703238,-3.146098608768294
2.2275290620520587,0.0015911999999999999,223.8929362782617,124.6271923703238,-3.146098608768294
2.237608379074919,0.0015983999999999998,223.93587748836518,124.6271923703238,-3.146098608768294
2.253287316666034,0.0016095999999999999,224.0025252871139,124.6271923703238,-3.146098608768294
2.2723260265981033,0.0016232,224.08321210080138,124.6271923703238,-3.146098608768294
2.2969643570984277,0.0016408,224.1872400314626,124.6271923703238,-3.146098608768294
2.3148831429168455,0.0016535999999999999,224.2626235671137,124.6271923703238,-3.146098608768294
2.3283222322806587,0.0016631999999999999,224.3190119642884,124.6271923703238,-3.146098608768294
2.3910379826451207,0.0017079999999999999,224.5804975124175,124.6271923703238,-3.146098608768294
2.4268755542819562,0.0017335999999999999,224.728716653584,124.6271923703238,-3.146098608768294
2.4470341883276765,0.001748,224.81171474620365,124.6271923703238,-3.146098608768294
2.452633808895932,0.0017519999999999999,224.83472239368814,124.6271923703238,-3.146098608768294
2.4795119876235585,0.0017712,224.94487519784147,124.6271923703238,-3.146098608768294
2.4851116081918145,0.0017752,224.96776497372508,124.6271923703238,-3.146098608768294
2.504150318123883,0.0017888,225.04544019299556,124.6271923703238,-3.146098608768294
2.5310284968515098,0.001808,225.15470837144534,124.6271923703238,-3.146098608768294
2.555666827351834,0.0018256,225.25447397222518,124.6271923703238,-3.146098608768294
2.575825461397554,0.0018399999999999998,225.33582166298046,124.6271923703238,-3.146098608768294
2.626222046511854,0.0018759999999999998,225.53811210709978,124.6271923703238,-3.146098608768294
2.6284618947391563,0.0018775999999999999,225.5470674863586,124.6271923703238,-3.146098608768294
2.6508603770121786,0.0018935999999999998,225.63645819248055,124.6271923703238,-3.146098608768294
2.677738555739805,0.0019127999999999999,225.74333914382618,124.6271923703238,-3.146098608768294
2.7012569621264784,0.0019295999999999998,225.83651721958296,124.6271923703238,-3.146098608768294
2.706856582694734,0.0019336,225.85865577799711,124.6271923703238,-3.146098608768294
2.716935899717594,0.0019408,225.89846022580036,124.6271923703238,-3.146098608768294
2.7314949131950588,0.0019512,225.95585401846637,124.6271923703238,-3.146098608768294
2.7594930160363362,0.0019711999999999998,226.06589247546032,124.6271923703238,-3.146098608768294
2.7785317259684055,0.0019848,226.14047002875532,124.6271923703238,-3.146098608768294
2.7998102841277763,0.002,226.22358596897328,124.6271923703238,-3.146098608768294
2.8322880834236583,0.0020231999999999997,226.34997374336027,124.6271923703238,-3.146098608768294
2.840127552219216,0.0020288,226.38039630158798,124.6271923703238,-3.146098608768294
2.8636459586058893,0.0020456,226.47146808255604,124.6271923703238,-3.146098608768294
2.880444820310656,0.0020575999999999997,226.53634085273515,124.6271923703238,-3.146098608768294
2.9286015571976542,0.002092,226.72149669370293,124.6271923703238,-3.146098608768294
2.947640267129723,0.0021056,226.79436985662417,124.6271923703238,-3.146098608768294
2.967798901175443,0.00212,226.8713298793773,124.6271923703238,-3.146098608768294
2.984597762880209,0.0021319999999999998,226.9353076198917,124.6271923703238,-3.146098608768294
2.9913173075621162,0.0021368,226.96085937469343,124.6271923703238,-3.146098608768294
3.0081161692668825,0.0021487999999999998,227.024641021169,124.6271923703238,-3.146098608768294
3.0159556380624406,0.0021544,227.05435823611958,124.6271923703238,-3.146098608768294
3.039474044449114,0.0021712,227.14332965240516,124.6271923703238,-3.146098608768294
3.060752602608485,0.0021864,227.22359651786147,124.6271923703238,-3.146098608768294
3.083151084881507,0.0022023999999999998,227.30785320035918,124.6271923703238,-3.146098608768294
3.0943503260180183,0.0022104,227.34989199642789,124.6271923703238,-3.146098608768294
3.113389035950087,0.002224,227.4212220235625,124.6271923703238,-3.146098608768294
3.1391472905640625,0.0022424,227.51745717377128,124.6271923703238,-3.146098608768294
3.168265317518992,0.0022632,227.62587466503197,124.6271923703238,-3.146098608768294
3.200743116814874,0.0022864,227.74634445707198,124.6271923703238,-3.146098608768294
3.243300233133616,0.0023168,227.9034822557842,124.6271923703238,-3.146098608768294
3.292576894134265,0.002352,228.08443015606488,124.6271923703238,-3.146098608768294
3.316095300520938,0.0023688,228.170419058054,124.6271923703238,-3.146098608768294
3.3295343898847514,0.0023783999999999997,228.21944878409244,124.6271923703238,-3.146098608768294
3.362012189180634,0.0024016,228.33761973735636,124.6271923703238,-3.146098608768294
3.3956099125901673,0.0024256,228.4593979952151,124.6271923703238,-3.146098608768294
3.4258478636587473,0.0024472,228.56859722691755,124.6271923703238,-3.146098608768294
3.4415268012498625,0.0024584,228.6250710260288,124.6271923703238,-3.146098608768294
3.4829639934549537,0.0024879999999999998,228.77384228029953,124.6271923703238,-3.146098608768294
3.4885636140232092,0.002492,228.79389343013437,124.6271923703238,-3.146098608768294
3.5344805026829045,0.0025248,228.95784205681724,124.6271923703238,-3.146098608768294
3.5523992885013227,0.0025376,229.0215964199021,124.6271923703238,-3.146098608768294
3.574797770774345,0.0025536,229.1011132791413,124.6271923703238,-3.146098608768294
3.5994361012746694,0.0025712,229.18835773547022,124.6271923703238,-3.146098608768294
3.6016759495019715,0.0025728,229.196277482714,124.6271923703238,-3.146098608768294
3.617354887093087,0.002584,229.2516620293114,124.6271923703238,-3.146098608768294
3.6789507133438977,0.0026279999999999997,229.46834384376456,124.6271923703238,-3.146098608768294
3.7058288920715245,0.0026471999999999997,229.56245200225962,124.6271923703238,-3.146098608768294
3.749505932503918,0.0026784,229.7148119861245,124.6271923703238,-3.146098608768294
3.776384111231545,0.0026976,229.80822799901657,124.6271923703238,-3.146098608768294
3.788703276481707,0.0027064,229.85095697676275,124.6271923703238,-3.146098608768294
3.805502138186473,0.0027183999999999997,229.90913654476438,124.6271923703238,-3.146098608768294
3.824540848118543,0.002732,229.9749524403671,124.6271923703238,-3.146098608768294
3.849179178618867,0.0027496,230.05993658715008,124.6271923703238,-3.146098608768294
3.9275738665744444,0.0028055999999999997,230.32894003177094,124.6271923703238,-3.146098608768294
3.9365332594836535,0.002812,230.35954936839656,124.6271923703238,-3.146098608768294
3.97349075523414,0.0028384,230.48552675869945,124.6271923703238,-3.146098608768294
4.046285822621463,0.0028904,230.73233545517851,124.6271923703238,-3.146098608768294
4.072044077235438,0.0029088,230.81925218412104,124.6271923703238,-3.146098608768294
4.079883546030995,0.0029143999999999997,230.84566250678515,124.6271923703238,-3.146098608768294
4.105641800644971,0.0029327999999999997,230.9323002679194,124.6271923703238,-3.146098608768294
4.145959068736412,0.0029616,231.0674828346609,124.6271923703238,-3.146098608768294
4.1672376268957825,0.0029768,231.13862244299972,124.6271923703238,-3.146098608768294
4.176197019804991,0.0029831999999999997,231.168533563834,124.6271923703238,-3.146098608768294
4.194115805623409,0.002996,231.22828083264298,124.6271923703238,-3.146098608768294
4.21539436378278,0.0030112,231.2991015681676,124.6271923703238,-3.146098608768294
4.2321932254875465,0.0030231999999999998,231.35491424004192,124.6271923703238,-3.146098608768294
4.254591707760569,0.0030391999999999997,231.4291969221007,124.6271923703238,-3.146098608768294
4.2691507212380335,0.0030496,231.47739889305095,124.6271923703238,-3.146098608768294
4.271390569465336,0.0030512,231.48480888689903,124.6271923703238,-3.146098608768294
4.282589810601847,0.0030591999999999998,231.52183614928265,124.6271923703238,-3.146098608768294
4.320667230465984,0.0030864,231.64744733321095,124.6271923703238,-3.146098608768294
4.345305560966309,0.003104,231.72849516416593,124.6271923703238,-3.146098608768294
4.35650480210282,0.0031119999999999997,231.76527582001938,124.6271923703238,-3.146098608768294
4.3643442708983775,0.0031176,231.7910003415066,124.6271923703238,-3.146098608768294
4.400181842535213,0.0031432,231.90836942054167,124.6271923703238,-3.146098608768294
4.413620931899026,0.0031528,231.95228663568787,124.6271923703238,-3.146098608768294
4.452818275876815,0.0031807999999999997,232.0800816059141,124.6271923703238,-3.146098608768294
4.461777668786024,0.0031872,232.10923019457732,124.6271923703238,-3.146098608768294
4.476336682263488,0.0031975999999999997,232.15654801226495,124.6271923703238,-3.146098608768294
4.488655847513651,0.0032064,232.19653930467072,124.6271923703238,-3.146098608768294
4.4987351645365115,0.0032136,232.22922762417318,124.6271923703238,-3.146098608768294
4.525613343264137,0.0032327999999999996,232.3162571382398,124.6271923703238,-3.146098608768294
4.551371597878113,0.0032511999999999997,232.3994714596423,124.6271923703238,-3.146098608768294
4.554731370219066,0.0032535999999999997,232.41031194473783,124.6271923703238,-3.146098608768294
4.572650156037485,0.0032664,232.4680752808508,124.6271923703238,-3.146098608768294
4.580489624833042,0.0032719999999999997,232.49331897360423,124.6271923703238,-3.146098608768294
4.609607651787971,0.0032928,232.58693410546903,124.6271923703238,-3.146098608768294
4.633126058174644,0.0033095999999999998,232.66237807493337,124.6271923703238,-3.146098608768294
4.652164768106712,0.0033231999999999997,232.72334243098817,124.6271923703238,-3.146098608768294
4.674563250379735,0.0033391999999999996,232.79494076943868,124.6271923703238,-3.146098608768294
4.683522643288944,0.0033456,232.82354262678018,124.6271923703238,-3.146098608768294
4.685762491516246,0.0033472,232.83068975599394,124.6271923703238,-3.146098608768294
4.710400822016571,0.0033648,232.90922044128786,124.6271923703238,-3.146098608768294
4.740638773085151,0.0033864,233.00538040313737,124.6271923703238,-3.146098608768294
4.746238393653407,0.0033904,233.02316152234485,124.6271923703238,-3.146098608768294
4.761917331244522,0.0034016,233.0729051832972,124.6271923703238,-3.146098608768294
4.768636875926429,0.0034064,233.0942043367687,124.6271923703238,-3.146098608768294
4.784315813517544,0.0034176,233.14385689399782,124.6271923703238,-3.146098608768294
4.824633081608984,0.0034463999999999996,233.27124437526047,124.6271923703238,-3.146098608768294
4.8403120192001,0.0034576,233.32067174839048,124.6271923703238,-3.146098608768294
4.850391336222959,0.0034647999999999997,233.35241351827554,124.6271923703238,-3.146098608768294
4.861590577359471,0.0034728,233.3876519959724,124.6271923703238,-3.146098608768294
4.878389439064237,0.0034847999999999997,233.44045041080133,124.6271923703238,-3.146098608768294
4.906387541905515,0.0035047999999999998,233.52829047012997,124.6271923703238,-3.146098608768294
4.923186403610282,0.0035168,233.58090067545206,124.6271923703238,-3.146098608768294
4.967983368156326,0.0035488,233.72085340208997,124.6271923703238,-3.146098608768294
4.980302533406488,0.0035575999999999997,233.75925400813455,124.6271923703238,-3.146098608768294
4.998221319224906,0.0035704,233.81504337156457,124.6271923703238,-3.146098608768294
5.063176917816671,0.0036168,234.0166292152196,124.6271923703238,-3.146098608768294
5.087815248316995,0.0036344,234.09282865065276,124.6271923703238,-3.146098608768294
5.12365281995383,0.0036599999999999996,234.20340779466727,124.6271923703238,-3.146098608768294
5.137091909317644,0.0036696,234.24479715387486,124.6271923703238,-3.146098608768294
5.1572505433633635,0.0036839999999999998,234.30680210234016,124.6271923703238,-3.146098608768294
5.199807659682106,0.0037143999999999996,234.43739188837898,124.6271923703238,-3.146098608768294
5.225565914296081,0.0037327999999999997,234.5162305957721,124.6271923703238,-3.146098608768294
5.242364776000849,0.0037448,234.56756550363565,124.6271923703238,-3.146098608768294
5.282682044092288,0.0037736,234.69050823462362,124.6271923703238,-3.146098608768294
5.319639539842775,0.0038,234.80288465421938,124.6271923703238,-3.146098608768294
5.343157946229448,0.0038168,234.87423841805608,124.6271923703238,-3.146098608768294
5.37563574552533,0.0038399999999999997,234.9725735276716,124.6271923703238,-3.146098608768294
5.3890748348891435,0.0038496,235.0131961112978,124.6271923703238,-3.146098608768294
5.394674455457399,0.0038536,235.03011052519162,124.6271923703238,-3.146098608768294
5.399154151912003,0.0038567999999999996,235.04363712682388,124.6271923703238,-3.146098608768294
5.422672558298677,0.0038735999999999996,235.11458010390862,124.6271923703238,-3.146098608768294
5.440591344117095,0.0038864,235.16855138346386,124.6271923703238,-3.146098608768294
5.446190964685351,0.0038904,235.18540318548597,124.6271923703238,-3.146098608768294
5.46522967461742,0.003904,235.24264883513047,124.6271923703238,-3.146098608768294
5.496587549799651,0.0039264,235.33676653591758,124.6271923703238,-3.146098608768294
5.503307094481557,0.0039312,235.35690734412293,124.6271923703238,-3.146098608768294
5.508906715049813,0.0039352,235.3736840256602,124.6271923703238,-3.146098608768294
5.530185273209184,0.0039504,235.43737485340029,124.6271923703238,-3.146098608768294
5.544744286686647,0.0039607999999999996,235.48089773026717,124.6271923703238,-3.146098608768294
5.562663072505066,0.0039736,235.53440321287508,124.6271923703238,-3.146098608768294
5.653387679132981,0.004038407681536307,235.80428192721482,124.6271923703238,-3.146098608768294
6.7824970075589865,0.00484496899379876,239.03288813656468,124.6271923703238,-3.146098608768294
7.051332561946131,0.0050370074014802965,239.76979489447623,124.6271923703238,-3.146098608768294
7.562120115281704,0.005401880376075216,241.1404027521787,124.6271923703238,-3.146098608768294
8.019140557739847,0.005728345669133827,242.33640760451482,124.6271923703238,-3.146098608768294
8.15355833493342,0.005824364872974595,242.68307484442187,124.6271923703238,-3.146098608768294
8.583695221952851,0.006131626325265053,243.77772244902744,124.6271923703238,-3.146098608768294
9.363318329675568,0.0066885377075415085,245.70871412752388,124.6271923703238,-3.146098608768294
9.605270328623998,0.006861372274454891,246.2950959509799,124.6271923703238,-3.146098608768294
9.820338772133713,0.00701500300060012,246.81150512428422,124.6271923703238,-3.146098608768294
10.384893436346715,0.007418283656731346,248.14651445162315,124.6271923703238,-3.146098608768294
10.438660547224144,0.007456691338267653,248.2721634779742,124.6271923703238,-3.146098608768294
10.949448100559717,0.007821564312862572,249.45350105659892,124.6271923703238,-3.146098608768294
11.729071208282434,0.008378475695139028,251.21596370148436,124.6271923703238,-3.146098608768294
12.13232453986315,0.008666533306661332,252.10961141991115,124.6271923703238,-3.146098608768294
12.347392983372867,0.008820164032806561,252.58148295717905,124.6271923703238,-3.146098608768294
12.911947647585869,0.009223444688937788,253.80513961835027,124.6271923703238,-3.146098608768294
13.153899646534299,0.00939627925585117,254.32315556973577,124.6271923703238,-3.146098608768294
14.121707642328017,0.010087617523504702,256.3590964401171,124.6271923703238,-3.146098608768294
14.417426752153872,0.01029885977195439,256.9702357939738,124.6271923703238,-3.146098608768294
15.519652525141167,0.01108621724344869,259.20628141307105,124.6271923703238,-3.146098608768294
15.842255190405739,0.011316663332666534,259.8489006126325,124.6271923703238,-3.146098608768294
16.433693410057455,0.011739147829565914,261.0139338222816,124.6271923703238,-3.146098608768294
16.83694674163817,0.012027205441088217,261.79891353972386,124.6271923703238,-3.146098608768294
17.025131629709172,0.012161632326465293,262.1627248587444,124.6271923703238,-3.146098608768294
17.4552685167286,0.01246889377875575,262.9884550356709,124.6271923703238,-3.146098608768294
17.724104071115747,0.012660932186437287,263.5005083713013,124.6271923703238,-3.146098608768294
18.12735740269646,0.012948989797959592,264.2629451004271,124.6271923703238,-3.146098608768294
18.342425846206176,0.013102620524104821,264.6668719047282,124.6271923703238,-3.146098608768294
18.987631176735324,0.013563512702540508,265.86771247741746,124.6271923703238,-3.146098608768294
19.44465161919347,0.01388997799559912,266.70869742511036,124.6271923703238,-3.146098608768294
19.95543917252904,0.01425485097019404,267.6395513673436,124.6271923703238,-3.146098608768294
20.2511582823549,0.01446609321864373,268.1742192727184,124.6271923703238,-3.146098608768294
20.519993836742042,0.014658131626325266,268.6576444947116,124.6271923703238,-3.146098608768294
21.59533605429062,0.015426285257051411,270.5671422895855,124.6271923703238,-3.146098608768294
21.97170583043262,0.01569513902780556,271.2266571393304,124.6271923703238,-3.146098608768294
22.29430849569719,0.015925585117023404,271.7884563559831,124.6271923703238,-3.146098608768294
22.643794716400482,0.016175235047009403,272.3935063222923,124.6271923703238,-3.146098608768294
22.805096049032766,0.016290458091618325,272.67153073068715,124.6271923703238,-3.146098608768294
23.880438266581343,0.01705861172234447,274.5058079244041,124.6271923703238,-3.146098608768294
24.014856043774913,0.017154630926185237,274.73280557714145,124.6271923703238,-3.146098608768294
24.391225819916915,0.017423484696939388,275.36577786686127,124.6271923703238,-3.146098608768294
24.740712040620206,0.017673134626925387,275.95013544726714,124.6271923703238,-3.146098608768294
25.09019826132349,0.017922784556911382,276.53128245411955,124.6271923703238,-3.146098608768294
25.81605425816878,0.018441288257651532,277.72828828420484,124.6271923703238,-3.146098608768294
25.923588479923637,0.018518103620724147,277.9044998003413,124.6271923703238,-3.146098608768294
26.730095143085066,0.019094218843768752,279.2171182623284,124.6271923703238,-3.146098608768294
26.998930697472215,0.019286257251450292,279.65121322728186,124.6271923703238,-3.146098608768294
27.3484169181755,0.019535907181436288,280.2130247989466,124.6271923703238,-3.146098608768294
28.181807136775642,0.02013122624524905,281.5415485391434,124.6271923703238,-3.146098608768294
28.423759135724076,0.020304060812162433,281.9243674867714,124.6271923703238,-3.146098608768294
29.12273157713065,0.020803360672134428,283.0232140413273,124.6271923703238,-3.146098608768294
29.767936907659795,0.021264252850570115,284.02843859025256,124.6271923703238,-3.146098608768294
30.278724460995367,0.021629125825165033,284.8182275270286,124.6271923703238,-3.146098608768294
31.515368011176232,0.0225125025005001,286.70913160291394,124.6271923703238,-3.146098608768294
31.56913512205366,0.022550910182036407,286.79068187969546,124.6271923703238,-3.146098608768294
31.730436454685947,0.02266613322664533,287.0350083200416,124.6271923703238,-3.146098608768294
31.811087121002092,0.02272374474894979,287.15698985882943,124.6271923703238,-3.146098608768294
33.02084711574424,0.023587917583516704,288.9724793501182,124.6271923703238,-3.146098608768294
33.34344978100881,0.023818363672734547,289.45220504685005,124.6271923703238,-3.146098608768294
34.6338604420671,0.024740148029605922,291.35327759809235,124.6271923703238,-3.146098608768294
35.09088088452524,0.025066613322664532,292.01992313313315,124.6271923703238,-3.146098608768294
35.76296977049311,0.025546709341868375,292.99416559445956,124.6271923703238,-3.146098608768294
35.95115465856411,0.02568113622724545,293.265670537073,124.6271923703238,-3.146098608768294
36.13933954663511,0.025815563112622526,293.53662178112023,124.6271923703238,-3.146098608768294
36.38129154558354,0.025988397679535907,293.88418050591076,124.6271923703238,-3.146098608768294
37.56416798488697,0.026833366673334667,295.5705490454406,124.6271923703238,-3.146098608768294
37.9943048719064,0.027140628125625125,296.17862255000983,124.6271923703238,-3.146098608768294
38.585743091558115,0.027563112622524505,297.0103579518709,124.6271923703238,-3.146098608768294
38.77392797962912,0.027697539507901582,297.273956391804,124.6271923703238,-3.146098608768294
39.20406486664855,0.02800480096019204,297.87460066308324,124.6271923703238,-3.146098608768294
39.76861953086155,0.028408081616323265,298.6590602445172,124.6271923703238,-3.146098608768294
40.655776860339124,0.029041808361672333,299.88306394791834,124.6271923703238,-3.146098608768294
41.27409863542956,0.02948349669933987,300.7300043270988,124.6271923703238,-3.146098608768294
41.65046841157156,0.02975235047009402,301.24311098988846,124.6271923703238,-3.146098608768294
41.7311190778877,0.02980996199239848,301.3528267944883,124.6271923703238,-3.146098608768294
42.2956737421007,0.030213242648529707,302.1185351602249,124.6271923703238,-3.146098608768294
42.403207963855564,0.03029005801160232,302.2639313494136,124.6271923703238,-3.146098608768294
43.07529684982342,0.03077015403080616,303.169421019037,124.6271923703238,-3.146098608768294
44.043104845617144,0.031461492298459695,304.46370550622294,124.6271923703238,-3.146098608768294
44.93026217509472,0.03209521904380876,305.6404216023426,124.6271923703238,-3.146098608768294
45.225981284920564,0.03230646129225845,306.0306420343585,124.6271923703238,-3.146098608768294
45.441049728430286,0.03246009201840368,306.3138139683704,124.6271923703238,-3.146098608768294
45.52170039474643,0.03251770354070814,306.419868627296,124.6271923703238,-3.146098608768294
46.46262483510144,0.03318983796759352,307.65180710758744,124.6271923703238,-3.146098608768294
46.650809723172436,0.033324264852970596,307.89702301975797,124.6271923703238,-3.146098608768294
47.618617718966156,0.03401560312062413,309.15209103123397,124.6271923703238,-3.146098608768294
48.50577504844373,0.034649329865973195,310.29385790266116,124.6271923703238,-3.146098608768294
49.231631045289014,0.03516783356671334,311.2219850503974,124.6271923703238,-3.146098608768294
49.50046659967617,0.035359871974394885,311.56437955998325,124.6271923703238,-3.146098608768294
49.66176793230844,0.0354750950190038,311.769468177927,124.6271923703238,-3.146098608768294
50.118788374766595,0.035801560312062414,312.3491465518784,124.6271923703238,-3.146098608768294
50.280089707398886,0.03591678335667134,312.55324624861674,124.6271923703238,-3.146098608768294
50.62957592810217,0.036166433286657335,312.99458829750307,124.6271923703238,-3.146098608768294
50.979062148805454,0.03641608321664333,313.43474379829115,124.6271923703238,-3.146098608768294
52.16193858810888,0.03726105221044208,314.915845489312,124.6271923703238,-3.146098608768294
52.807143918638026,0.03772194438887777,315.71819582894614,124.6271923703238,-3.146098608768294
54.4201572449609,0.038874174834966996,317.7075233786302,124.6271923703238,-3.146098608768294
55.19978035268362,0.03943108621724345,318.6607766866077,124.6271923703238,-3.146098608768294
55.68368435058047,0.03977675535107021,319.2498108285031,124.6271923703238,-3.146098608768294
55.871869238651485,0.039911182236447296,319.47834010695345,124.6271923703238,-3.146098608768294
56.0869376821612,0.040064812962592525,319.7391491662807,124.6271923703238,-3.146098608768294
57.02786212251618,0.04073694738947789,320.87563347639417,124.6271923703238,-3.146098608768294
57.43111545409691,0.0410250050010002,321.3604568652623,124.6271923703238,-3.146098608768294
57.75371811936147,0.04125545109021804,321.7473603579481,124.6271923703238,-3.146098608768294
57.86125234111634,0.04133226645329066,321.87614076694337,124.6271923703238,-3.146098608768294
58.31827278357448,0.041658731746349265,322.42241944376764,124.6271923703238,-3.146098608768294
58.64087544883906,0.041889177835567115,322.8070231552012,124.6271923703238,-3.146098608768294
58.9097110032262,0.04208121624324865,323.12689631190227,124.6271923703238,-3.146098608768294
59.74310122182636,0.04267653530706142,324.1149043062728,124.6271923703238,-3.146098608768294
59.87751899901993,0.042772554510902186,324.2737556736349,124.6271923703238,-3.146098608768294
60.09258744252964,0.042926185237047415,324.5276288921772,124.6271923703238,-3.146098608768294
60.25388877516191,0.043041408281656326,324.7178013267421,124.6271923703238,-3.146098608768294
60.92597766112978,0.04352150430086017,325.5080587710742,124.6271923703238,-3.146098608768294
61.86690210148479,0.04419363872774555,326.6087311533066,124.6271923703238,-3.146098608768294
62.673408764646226,0.044769753950790164,327.5469783697303,124.6271923703238,-3.146098608768294
63.2110798734205,0.04515383076615323,328.1698618439534,124.6271923703238,-3.146098608768294
63.37238120605279,0.045269053810762155,328.35632351001374,124.6271923703238,-3.146098608768294
64.68967542254978,0.046210042008401675,329.87222685376565,124.6271923703238,-3.146098608768294
65.95320252816937,0.047112622524504905,331.3149843959002,124.6271923703238,-3.146098608768294
66.30268874887267,0.0473622724544909,331.71213664743914,124.6271923703238,-3.146098608768294
66.84035985764694,0.047746349269853966,332.32154960603134,124.6271923703238,-3.146098608768294
67.40491452185996,0.048149629925985205,332.9593791608354,124.6271923703238,-3.146098608768294
69.12546206993767,0.04937867573514702,334.89051154336056,124.6271923703238,-3.146098608768294
69.5555989569571,0.04968593718743748,335.3703542879314,124.6271923703238,-3.146098608768294
69.7437838450281,0.049820364072814566,335.57992142947415,124.6271923703238,-3.146098608768294
70.71159184082181,0.05051170234046809,336.6542315431209,124.6271923703238,-3.146098608768294
71.16861228327997,0.05083816763352671,337.15954991452384,124.6271923703238,-3.146098608768294
71.70628339205425,0.05122224444888977,337.75242473092453,124.6271923703238,-3.146098608768294
72.13642027907368,0.05152950590118023,338.22547722872673,124.6271923703238,-3.146098608768294
72.51279005521569,0.051798359671934385,338.6384964830057,124.6271923703238,-3.146098608768294
74.01826915978369,0.05287377475495099,340.2822808788859,124.6271923703238,-3.146098608768294
75.28179626540326,0.053776355271054205,341.6518455110507,124.6271923703238,-3.146098608768294
76.51843981558413,0.054659731946389276,342.98361617651346,124.6271923703238,-3.146098608768294
77.35183003418429,0.05525505101020205,343.87638243690765,124.6271923703238,-3.146098608768294
77.51313136681655,0.05537027405481096,344.04874177604955,124.6271923703238,-3.146098608768294
77.80885047664242,0.05558151630326065,344.3643710311447,124.6271923703238,-3.146098608768294
77.91638469839728,0.05565833166633327,344.47902926950934,124.6271923703238,-3.146098608768294
78.48093936261029,0.056061612322464496,345.0799755272454,124.6271923703238,-3.146098608768294
80.73915801946228,0.057674734946989395,347.46709011943,124.6271923703238,-3.146098608768294
81.6800824598173,0.058346869373874774,348.4540193431638,124.6271923703238,-3.146098608768294
82.32528779034644,0.05880776155231046,349.1282095894536,124.6271923703238,-3.146098608768294
82.70165756648845,0.059076615323064616,349.5205356045088,124.6271923703238,-3.146098608768294
83.13179445350788,0.059383876775355074,349.96805655831395,124.6271923703238,-3.146098608768294
83.42751356333373,0.059595119023804766,350.27520350177656,124.6271923703238,-3.146098608768294
83.58881489596601,0.05971034206841368,350.44255922404324,124.6271923703238,-3.146098608768294
83.80388333947572,0.059863972794558906,350.66550439813034,124.6271923703238,-3.146098608768294
84.07271889386288,0.06005601120224045,350.9438723263234,124.6271923703238,-3.146098608768294
84.63727355807588,0.06045929185837168,351.5273175418931,124.6271923703238,-3.146098608768294
86.27717043983746,0.06163072614522905,353.2135404751691,124.6271923703238,-3.146098608768294
86.57288954966332,0.06184196839367874,353.5162784801091,124.6271923703238,-3.146098608768294
87.80953309984419,0.06272534506901381,354.7779288297868,124.6271923703238,-3.146098608768294
88.69669042932175,0.06335907181436287,355.67876078860377,124.6271923703238,-3.146098608768294
89.04617665002503,0.06360872174434887,356.0326683294154,124.6271923703238,-3.146098608768294
90.25593664476717,0.06447289457891578,357.2535715908463,124.6271923703238,-3.146098608768294
90.39035442196075,0.06456891378275655,357.38883239339054,124.6271923703238,-3.146098608768294
91.06244330792862,0.06504900980196039,358.0639632834649,124.6271923703238,-3.146098608768294
91.5732308612642,0.06541388277655531,358.5757638734846,124.6271923703238,-3.146098608768294
91.65388152758034,0.06547149429885978,358.6564726061539,124.6271923703238,-3.146098608768294
91.9496006374062,0.06568273654730947,358.95216795525283,124.6271923703238,-3.146098608768294
92.32597041354819,0.06595159031806361,359.3279716397979,124.6271923703238,-3.146098608768294
93.80456596267749,0.06700780156031207,360.7985953157177,124.6271923703238,-3.146098608768294
94.01963440618721,0.0671614322864573,361.0117486828869,124.6271923703238,-3.146098608768294
94.23470284969692,0.06731506301260252,361.2247119765069,124.6271923703238,-3.146098608768294
94.5573055149615,0.06754550910182038,361.54380184656753,124.6271923703238,-3.146098608768294
94.9067917356648,0.06779515903180637,361.88900380280825,124.6271923703238,-3.146098608768294
95.36381217812293,0.06812162432486497,362.3396746330051,124.6271923703238,-3.146098608768294
95.98213395321336,0.06856331266253252,362.94806733415584,124.6271923703238,-3.146098608768294
96.4391543956715,0.06888977795559112,363.39676694174796,124.6271923703238,-3.146098608768294
96.60045572830379,0.06900500100020004,363.554933415542,124.6271923703238,-3.146098608768294
96.89617483812965,0.06921624324864974,363.84463802894714,124.6271923703238,-3.146098608768294
97.5682637240975,0.06969633926785357,364.501778273015,124.6271923703238,-3.146098608768294
97.9177499448008,0.06994598919783958,364.842793382167,124.6271923703238,-3.146098608768294
98.32100327638152,0.07023404680936188,365.2356830656018,124.6271923703238,-3.146098608768294
98.56295527532995,0.07040688137627527,365.47111523366726,124.6271923703238,-3.146098608768294
98.8317908297171,0.0705989197839568,365.7324423378881,124.6271923703238,-3.146098608768294
99.10062638410423,0.07079095819163833,365.99349235941435,124.6271923703238,-3.146098608768294
99.2350441612978,0.0708869773954791,366.12391379076064,124.6271923703238,-3.146098608768294
99.36946193849137,0.07098299659931986,366.25426634249953,124.6271923703238,-3.146098608768294
100.33726993428509,0.0716743348669734,367.1907830520035,124.6271923703238,-3.146098608768294
100.47168771147867,0.07177035407081417,367.3205756372937,124.6271923703238,-3.146098608768294
100.7136397104271,0.07194318863772756,367.55403176120944,124.6271923703238,-3.146098608768294
100.79429037674323,0.072000800160032,367.63180184891286,124.6271923703238,-3.146098608768294
101.09000948656909,0.0722120424084817,367.91675144090044,124.6271923703238,-3.146098608768294
101.35884504095625,0.07240408081616324,368.17551454720495,124.6271923703238,-3.146098608768294
101.8696325942918,0.07276895379075815,368.6664282243402,124.6271923703238,-3.146098608768294
102.24600237043381,0.0730378075615123,369.0275400292516,124.6271923703238,-3.146098608768294
102.51483792482095,0.07322984596919384,369.2851597104614,124.6271923703238,-3.146098608768294
104.12785125114382,0.07438207641528306,370.8253808748415,124.6271923703238,-3.146098608768294
104.96124146974397,0.07497739547909582,371.61751430633205,124.6271923703238,-3.146098608768294
105.25696057956982,0.07518863772754551,371.8980038023483,124.6271923703238,-3.146098608768294
105.84839879922154,0.0756111222244449,372.4580624931713,124.6271923703238,-3.146098608768294
106.43983701887326,0.07603360672134428,373.0169020461146,124.6271923703238,-3.146098608768294
106.84309035045398,0.07632166433286658,373.3972348508864,124.6271923703238,-3.146098608768294
107.00439168308627,0.0764368873774755,373.5492111697046,124.6271923703238,-3.146098608768294
107.81089834624768,0.0770130026005201,374.30775668793063,124.6271923703238,-3.146098608768294
108.05285034519612,0.07718583716743349,374.5348883783024,124.6271923703238,-3.146098608768294
108.64428856484784,0.07760832166433287,375.08926575241577,124.6271923703238,-3.146098608768294
109.02065834098983,0.07787717543508701,375.4414386275441,124.6271923703238,-3.146098608768294
109.1281925627447,0.07795399079815964,375.54197231710566,124.6271923703238,-3.146098608768294
109.28949389537699,0.07806921384276856,375.69270044040474,124.6271923703238,-3.146098608768294
109.80028144871257,0.07843408681736348,376.16943480054334,124.6271923703238,-3.146098608768294
110.01534989222228,0.07858771754350871,376.36990621028144,124.6271923703238,-3.146098608768294
110.0960005585384,0.07864532906581316,376.44504357725805,124.6271923703238,-3.146098608768294
110.60678811187398,0.07901020204040808,376.92041604405523,124.6271923703238,-3.146098608768294
110.71432233362886,0.0790870174034807,377.0203852760841,124.6271923703238,-3.146098608768294
110.983157888016,0.07927905581116224,377.2701428260855,124.6271923703238,-3.146098608768294
111.76278099573871,0.07983596719343869,377.99310890625316,124.6271923703238,-3.146098608768294
111.97784943924842,0.07998959791958392,378.1922013566715,124.6271923703238,-3.146098608768294
112.13915077188071,0.08010482096419284,378.3414228429856,124.6271923703238,-3.146098608768294
112.62305476977757,0.0804504900980196,378.78858585092394,124.6271923703238,-3.146098608768294
113.69839698732615,0.08121864372874575,379.77960742580757,124.6271923703238,-3.146098608768294
113.88658187539716,0.08135307061412284,379.9526597068317,124.6271923703238,-3.146098608768294
114.31671876241658,0.0816603320664133,380.3477895532871,124.6271923703238,-3.146098608768294
114.42425298417143,0.0817371474294859,380.44648136419676,124.6271923703238,-3.146098608768294
115.04257475926185,0.08217883576715343,381.0132588865709,124.6271923703238,-3.146098608768294
115.687780089791,0.08263972794558912,381.6034137158661,124.6271923703238,-3.146098608768294
116.84377297365573,0.08346549309861973,382.65757424379245,124.6271923703238,-3.146098608768294
117.22014274979773,0.08373434686937388,382.99991054845555,124.6271923703238,-3.146098608768294
117.46209474874617,0.08390718143628727,383.2197575406879,124.6271923703238,-3.146098608768294
117.65027963681716,0.08404160832166434,383.39062756771324,124.6271923703238,-3.146098608768294
117.94599874664303,0.08425285057011403,383.65892241007845,124.6271923703238,-3.146098608768294
118.32236852278503,0.08452170434086818,384.0000094531187,124.6271923703238,-3.146098608768294
118.88692318699803,0.08492498499699941,384.5108477147402,124.6271923703238,-3.146098608768294
119.63966273928203,0.0854626925385077,385.1904961733185,124.6271923703238,-3.146098608768294
119.72031340559818,0.08552030406081217,385.26321660100393,124.6271923703238,-3.146098608768294
119.98914895998531,0.0857123424684937,385.50548016004416,124.6271923703238,-3.146098608768294
120.5268200687596,0.08609641928385678,385.98937314633906,124.6271923703238,-3.146098608768294
120.87630628946289,0.08634606921384277,386.30345219762165,124.6271923703238,-3.146098608768294
121.70969650806303,0.08694138827765553,387.0509841864793,124.6271923703238,-3.146098608768294
122.5968538375406,0.08757511502300461,387.8445537944453,124.6271923703238,-3.146098608768294
122.97322361368262,0.08784396879375876,388.1805427227441,124.6271923703238,-3.146098608768294
123.1076413908762,0.08793998799759953,388.3004415457014,124.6271923703238,-3.146098608768294
124.85507249439262,0.0891882376475295,389.8545090516163,124.6271923703238,-3.146098608768294
125.1776751596572,0.08941868373674736,390.14048386547813,124.6271923703238,-3.146098608768294
125.4196271586056,0.08959151830366073,390.3547763876396,124.6271923703238,-3.146098608768294
127.38212670563178,0.09099339867973595,392.08700917939814,124.6271923703238,-3.146098608768294
128.10798270247707,0.0915119023804761,392.72505732081714,124.6271923703238,-3.146098608768294
128.99514003195463,0.09214562912582518,393.50298245426217,124.6271923703238,-3.146098608768294
129.15644136458693,0.09226085217043409,393.6441989273645,124.6271923703238,-3.146098608768294
129.64034536248377,0.09260652130426085,394.0674362342532,124.6271923703238,-3.146098608768294
129.98983158318708,0.09285617123424686,394.372724541214,124.6271923703238,-3.146098608768294
130.68880402459365,0.09335547109421885,394.9823425272452,124.6271923703238,-3.146098608768294
130.9845231344195,0.09356671334266854,395.2398748887989,124.6271923703238,-3.146098608768294
131.38777646600022,0.09385477095419084,395.59069025024536,124.6271923703238,-3.146098608768294
131.8985640193358,0.09421964392878576,396.0344541441804,124.6271923703238,-3.146098608768294
132.4631186835488,0.09462292458491699,396.5241510036434,124.6271923703238,-3.146098608768294
132.78572134881338,0.09485337067413484,396.8036123227993,124.6271923703238,-3.146098608768294
133.3771595684651,0.09527585517103421,397.3152713220486,124.6271923703238,-3.146098608768294
134.10301556531036,0.09579435887177436,397.942008694631,124.6271923703238,-3.146098608768294
134.18366623162652,0.09585197039407882,398.0115644172408,124.6271923703238,-3.146098608768294
135.2590084491751,0.09662012402480497,398.93742158007836,124.6271923703238,-3.146098608768294
135.36654267092996,0.09669693938787759,399.0298491275416,124.6271923703238,-3.146098608768294
136.22681644496882,0.0973114622924585,399.7682414423668,124.6271923703238,-3.146098608768294
136.46876844391724,0.09748429685937188,399.97558633484067,124.6271923703238,-3.146098608768294
136.68383688742696,0.0976379275855171,400.1597725777011,124.6271923703238,-3.146098608768294
137.3290422179561,0.0980988197639528,400.7116543390833,124.6271923703238,-3.146098608768294
137.8935968821691,0.09850210042008402,401.19372189373337,124.6271923703238,-3.146098608768294
138.0548982148014,0.09861732346469294,401.3313140241625,124.6271923703238,-3.146098608768294
138.7807542116467,0.0991358271654331,401.94970438171316,124.6271923703238,-3.146098608768294
139.45284309761453,0.09961592318463693,402.52116429120423,124.6271923703238,-3.146098608768294
139.90986354007268,0.09994238847769554,402.9091436329315,124.6271923703238,-3.146098608768294