File: datasets/aisi_316_L/data/M1/valid_7.csv
Time(s),Strain(%),Stress(MPa),Temp(C),Log_SR(s-1)
0.0,0.0,0.0,26.157022024310734,3.378073776039841
4.689691197499136e-09,1.12e-05,2.190278475,26.157022024310734,3.378073776039841
1.1389250051069331e-08,2.7199999999999997e-05,5.319247724999999,26.157022024310734,3.378073776039841
1.2729161821783371e-08,3.04e-05,5.945041575,26.157022024310734,3.378073776039841
1.473902947785443e-08,3.52e-05,6.883732350000001,26.157022024310734,3.378073776039841
2.3448455987495682e-08,5.6e-05,10.951392375,26.157022024310734,3.378073776039841
2.914308101303035e-08,6.96e-05,13.6110162375,26.157022024310734,3.378073776039841
3.684757369463607e-08,8.8e-05,17.209330875,26.157022024310734,3.378073776039841
4.153726489213521e-08,9.92e-05,19.39960935,26.157022024310734,3.378073776039841
5.024669140177646e-08,0.00011999999999999999,23.467269374999997,26.157022024310734,3.378073776039841
6.130096351016728e-08,0.00014639999999999998,28.630068637499996,26.157022024310734,3.378073776039841
6.364580910891684e-08,0.00015199999999999998,29.725207874999995,26.157022024310734,3.378073776039841
6.53206988223094e-08,0.000156,30.507450187499998,26.157022024310734,3.378073776039841
7.871981652944979e-08,0.000188,36.7653886875,26.157022024310734,3.378073776039841
8.374448566962743e-08,0.00019999999999999998,39.112115624999994,26.157022024310734,3.378073776039841
8.809919892444806e-08,0.0002104,41.1459456375,26.157022024310734,3.378073776039841
1.0719294165712311e-07,0.000256,50.063508,26.157022024310734,3.378073776039841
1.1590236816676438e-07,0.0002768,54.131168025,26.157022024310734,3.378073776039841
1.172422799374784e-07,0.00028,54.756961874999995,26.157022024310734,3.378073776039841
1.242768167337271e-07,0.0002968,58.0423795875,26.157022024310734,3.378073776039841
1.3131135352997582e-07,0.0003136,61.32779729999999,26.157022024310734,3.378073776039841
1.413606918103311e-07,0.00033759999999999997,66.02125117499999,26.157022024310734,3.378073776039841
1.4940016243461534e-07,0.0003568,69.776014275,26.157022024310734,3.378073776039841
1.5074007420532938e-07,0.00035999999999999997,70.40180812499999,26.157022024310734,3.378073776039841
1.5241496391872193e-07,0.00036399999999999996,71.18405043749999,26.157022024310734,3.378073776039841
1.654791036831838e-07,0.00039519999999999996,77.28554047499999,26.157022024310734,3.378073776039841
1.7083875076603998e-07,0.000408,79.788715875,26.157022024310734,3.378073776039841
1.788782213903242e-07,0.0004272,83.543478975,26.157022024310734,3.378073776039841
1.8155804493175227e-07,0.00043359999999999997,84.79506667499999,26.157022024310734,3.378073776039841
1.8758764789996545e-07,0.000448,87.611139,26.157022024310734,3.378073776039841
1.936172508681786e-07,0.00046239999999999996,90.42721132499999,26.157022024310734,3.378073776039841
1.956271185242497e-07,0.00046719999999999997,91.3659021,26.157022024310734,3.378073776039841
2.1438588331424623e-07,0.000512,100.127016,26.157022024310734,3.378073776039841
2.197455303971024e-07,0.0005248,102.63019139999999,26.157022024310734,3.378073776039841
2.3481953781763531e-07,0.0005608,109.6703722125,26.157022024310734,3.378073776039841
2.4051416284317e-07,0.0005744,112.329996075,26.157022024310734,3.378073776039841
2.415190966712055e-07,0.0005767999999999999,112.79934146249998,26.157022024310734,3.378073776039841
2.472137216967402e-07,0.0005903999999999999,115.45896532499998,26.157022024310734,3.378073776039841
2.5357830260763185e-07,0.0006056,118.4314861125,26.157022024310734,3.378073776039841
2.5692808203441695e-07,0.0006136,119.99597073749999,26.157022024310734,3.378073776039841
2.606128394038806e-07,0.0006224,121.71690382499999,26.157022024310734,3.378073776039841
2.659724864867367e-07,0.0006351999999999999,124.22007922499999,26.157022024310734,3.378073776039841
2.7099715562691437e-07,0.0006472,126.5668061625,26.157022024310734,3.378073776039841
2.723370673976284e-07,0.0006504,127.1926000125,26.157022024310734,3.378073776039841
2.783666703658416e-07,0.0006648,130.0086723375,26.157022024310734,3.378073776039841
2.8004156007923417e-07,0.0006688,130.79091465,26.157022024310734,3.378073776039841
2.8607116304744735e-07,0.0006832,133.606986975,26.157022024310734,3.378073776039841
2.9478058955708856e-07,0.000704,137.674647,26.157022024310734,3.378073776039841
3.0081019252530174e-07,0.0007184,140.49071932500001,26.157022024310734,3.378073776039841
3.101895749203e-07,0.0007408,144.871276275,26.157022024310734,3.378073776039841
3.1387433228976365e-07,0.0007496,146.5922093625,26.157022024310734,3.378073776039841
3.1822904554458426e-07,0.0007599999999999999,148.62603937499998,26.157022024310734,3.378073776039841
3.289483397102966e-07,0.0007856,153.632390175,26.157022024310734,3.378073776039841
3.3866270004797334e-07,0.0008087999999999999,158.1693955875,26.157022024310734,3.378073776039841
3.4033758976136587e-07,0.0008127999999999999,158.95163789999998,26.157022024310734,3.378073776039841
3.45027280958865e-07,0.000824,161.141916375,26.157022024310734,3.378073776039841
3.467021706722576e-07,0.000828,161.92415868749998,26.157022024310734,3.378073776039841
3.507219059843997e-07,0.0008376,163.8015402375,26.157022024310734,3.378073776039841
3.5976631043671945e-07,0.0008592,168.025648725,26.157022024310734,3.378073776039841
3.641210236915401e-07,0.0008696,170.0594787375,26.157022024310734,3.378073776039841
3.684757369463607e-07,0.0008799999999999999,172.09330874999998,26.157022024310734,3.378073776039841
3.728304502011813e-07,0.0008904,174.12713876249998,26.157022024310734,3.378073776039841
3.7383538402921687e-07,0.0008927999999999999,174.59648414999998,26.157022024310734,3.378073776039841
3.8388472230957217e-07,0.0009168,179.289938025,26.157022024310734,3.378073776039841
3.9091925910582085e-07,0.0009335999999999999,182.5753557375,26.157022024310734,3.378073776039841
4.029784650422472e-07,0.0009624,188.2075003875,26.157022024310734,3.378073776039841
4.1101793566653145e-07,0.0009816,191.9622634875,26.157022024310734,3.378073776039841
4.257569651443859e-07,0.0010168,198.8459958375,26.157022024310734,3.378073776039841
4.31786568112599e-07,0.0010312,201.6620681625,26.157022024310734,3.378073776039841
4.441807519917039e-07,0.0010608,207.450661275,26.157022024310734,3.378073776039841
4.5155026673063114e-07,0.0010784,210.89252745,26.157022024310734,3.378073776039841
4.585848035268798e-07,0.0010952,214.17794516249998,26.157022024310734,3.378073776039841
4.6092964912562937e-07,0.0011007999999999999,215.2730844,26.157022024310734,3.378073776039841
4.649493844377715e-07,0.0011103999999999999,217.15046594999998,26.157022024310734,3.378073776039841
4.6997405357794917e-07,0.0011224,219.4971928875,26.157022024310734,3.378073776039841
4.7131396534866326e-07,0.0011256,220.1229867375,26.157022024310734,3.378073776039841
4.756686786034838e-07,0.0011359999999999999,222.15681674999996,26.157022024310734,3.378073776039841
4.8102832568634e-07,0.0011488,224.65999215,26.157022024310734,3.378073776039841
4.860529948265176e-07,0.0011608,227.00671908750002,26.157022024310734,3.378073776039841
4.954323772215159e-07,0.0011832,231.3872760375,26.157022024310734,3.378073776039841
5.031368699031216e-07,0.0012016,234.985590675,26.157022024310734,3.378073776039841
5.068216272725852e-07,0.0012104,236.70652376249998,26.157022024310734,3.378073776039841
5.17205943495619e-07,0.0012351999999999999,241.55642609999998,26.157022024310734,3.378073776039841
5.269203038332958e-07,0.0012584,246.0934315125,26.157022024310734,3.378073776039841
5.403194215404362e-07,0.0012904,252.35137001249998,26.157022024310734,3.378073776039841
5.560633848463262e-07,0.001328,259.70444775,26.157022024310734,3.378073776039841
5.574032966170401e-07,0.0013311999999999998,260.33024159999997,26.157022024310734,3.378073776039841
5.607530760438253e-07,0.0013392,261.894726225,26.157022024310734,3.378073776039841
5.634328995852534e-07,0.0013456,263.146313925,26.157022024310734,3.378073776039841
5.721423260948947e-07,0.0013664,267.21397395,26.157022024310734,3.378073776039841
5.751571275790013e-07,0.0013736,268.6220101125,26.157022024310734,3.378073776039841
5.781719290631078e-07,0.0013808,270.030046275,26.157022024310734,3.378073776039841
5.831965982032855e-07,0.0013928,272.3767732125,26.157022024310734,3.378073776039841
5.935809144263192e-07,0.0014176,277.22667555,26.157022024310734,3.378073776039841
5.982706056238184e-07,0.0014288,279.416954025,26.157022024310734,3.378073776039841
6.059750983054241e-07,0.0014471999999999998,283.0152686625,26.157022024310734,3.378073776039841
6.093248777322092e-07,0.0014552,284.5797532875,26.157022024310734,3.378073776039841
6.17029370413815e-07,0.0014736,288.178067925,26.157022024310734,3.378073776039841
6.193742160125645e-07,0.0014792,289.2732071625,26.157022024310734,3.378073776039841
6.213840836686355e-07,0.0014839999999999999,290.2118979375,26.157022024310734,3.378073776039841
6.243988851527422e-07,0.0014912,291.6199341,26.157022024310734,3.378073776039841
6.287535984075628e-07,0.0015015999999999999,293.65376411249997,26.157022024310734,3.378073776039841
6.344482234330974e-07,0.0015152,296.313387975,26.157022024310734,3.378073776039841
6.40142848458632e-07,0.0015287999999999999,298.9730118375,26.157022024310734,3.378073776039841
6.448325396561312e-07,0.00154,301.1632903125,26.157022024310734,3.378073776039841
6.485172970255949e-07,0.0015488,302.8842234,26.157022024310734,3.378073776039841
6.55216855879165e-07,0.0015647999999999999,306.01319264999995,26.157022024310734,3.378073776039841
6.578966794205932e-07,0.0015712,307.26478035,26.157022024310734,3.378073776039841
6.629213485607707e-07,0.0015831999999999999,309.6115072875,26.157022024310734,3.378073776039841
6.70290863299698e-07,0.0016007999999999999,313.05337346249996,26.157022024310734,3.378073776039841
6.9005456191773e-07,0.001648,322.28383275,26.157022024310734,3.378073776039841
7.004388781407638e-07,0.0016728,327.1337350875,26.157022024310734,3.378073776039841
7.047935913955845e-07,0.0016832,329.1675651,26.157022024310734,3.378073776039841
7.0579852522362e-07,0.0016856,329.6369104875,26.157022024310734,3.378073776039841
7.114931502491547e-07,0.0016991999999999999,332.29653435,26.157022024310734,3.378073776039841
7.124980840771902e-07,0.0017016,332.72601486582045,26.157022024310734,3.378073776039841
7.178577311600464e-07,0.0017143999999999998,332.83614949817024,26.157022024310734,3.378073776039841
7.248922679562951e-07,0.0017312,332.98021575475883,26.157022024310734,3.378073776039841
7.336016944659363e-07,0.0017519999999999999,333.1578302907539,26.157022024310734,3.378073776039841
7.372864518353999e-07,0.0017607999999999999,333.2327271204711,26.157022024310734,3.378073776039841
7.500156136571833e-07,0.0017912,333.49034580399143,26.157022024310734,3.378073776039841
7.547053048546824e-07,0.0018024,333.5848273866043,26.157022024310734,3.378073776039841
7.627447754789667e-07,0.0018215999999999998,333.74626483636644,26.157022024310734,3.378073776039841
7.681044225618228e-07,0.0018344,333.8535212792464,26.157022024310734,3.378073776039841
7.781537608421781e-07,0.0018583999999999999,334.05384366975017,26.157022024310734,3.378073776039841
7.92557812377354e-07,0.0018927999999999998,334.3392218135129,26.157022024310734,3.378073776039841
7.959075918041392e-07,0.0019008,334.40529806754796,26.157022024310734,3.378073776039841
7.995923491736028e-07,0.0019096,334.4778568040749,26.157022024310734,3.378073776039841
8.072968418552085e-07,0.0019279999999999998,334.6291504859299,26.157022024310734,3.378073776039841
8.096416874539581e-07,0.0019336,334.6750844810623,26.157022024310734,3.378073776039841
8.146663565941357e-07,0.0019456,334.7733401296501,26.157022024310734,3.378073776039841
8.2270582721842e-07,0.0019648,334.93005898998956,26.157022024310734,3.378073776039841
8.290704081293116e-07,0.00198,335.05370490607925,26.157022024310734,3.378073776039841
8.354349890402033e-07,0.0019952,335.1769811830658,26.157022024310734,3.378073776039841
8.367749008109173e-07,0.0019984,335.20288735095204,26.157022024310734,3.378073776039841
8.431394817218091e-07,0.0020136,335.3257213928377,26.157022024310734,3.378073776039841
8.58883445027699e-07,0.0020512,335.6280305298508,26.157022024310734,3.378073776039841
8.608933126837701e-07,0.002056,335.66646702336163,26.157022024310734,3.378073776039841
8.639081141678765e-07,0.0020632,335.72405621009904,26.157022024310734,3.378073776039841
8.645780700532336e-07,0.0020648,335.7368431570071,26.157022024310734,3.378073776039841
8.77977187760374e-07,0.0020968,335.9917761940387,26.157022024310734,3.378073776039841
8.917112834101929e-07,0.0021295999999999997,336.2515127191086,26.157022024310734,3.378073776039841
9.014256437478697e-07,0.0021528,336.43428758279197,26.157022024310734,3.378073776039841
9.024305775759052e-07,0.0021552,336.45315137852316,26.157022024310734,3.378073776039841
9.057803570026904e-07,0.0021632,336.5159716133403,26.157022024310734,3.378073776039841
9.128148937989392e-07,0.00218,336.647599948282,26.157022024310734,3.378073776039841
9.191794747098308e-07,0.0021952,336.7663517557307,26.157022024310734,3.378073776039841
9.292288129901859e-07,0.0022191999999999997,336.9532037756752,26.157022024310734,3.378073776039841
9.46982643952147e-07,0.0022616,337.28139431218705,26.157022024310734,3.378073776039841
9.530122469203601e-07,0.002276,337.3923082227279,26.157022024310734,3.378073776039841
9.543521586910743e-07,0.0022792,337.4169185531271,26.157022024310734,3.378073776039841
9.583718940032163e-07,0.0022887999999999997,337.490668817451,26.157022024310734,3.378073776039841
9.75790747022499e-07,0.0023304,337.8088692943706,26.157022024310734,3.378073776039841
9.861750632455327e-07,0.0023552,337.99751186231947,26.157022024310734,3.378073776039841
9.94884489755174e-07,0.002376,338.1551316127583,26.157022024310734,3.378073776039841
1.003593916264815e-06,0.0023967999999999997,338.3122141364852,26.157022024310734,3.378073776039841
1.0159881001439201e-06,0.0024264,338.53484111148384,26.157022024310734,3.378073776039841
1.019337879570705e-06,0.0024343999999999998,338.5948284262525,26.157022024310734,3.378073776039841
1.0300571737364175e-06,0.00246,338.7862732381252,26.157022024310734,3.378073776039841
1.0367567325899876e-06,0.002476,338.90553176432786,26.157022024310734,3.378073776039841
1.0464710929276646e-06,0.0024992,339.077924149321,26.157022024310734,3.378073776039841
1.050825806182485e-06,0.0025096,339.15500077988577,26.157022024310734,3.378073776039841
1.0585302988640908e-06,0.002528,339.29106265855205,26.157022024310734,3.378073776039841
1.067239725373732e-06,0.0025488,339.44440751887004,26.157022024310734,3.378073776039841
1.0779590195394441e-06,0.0025743999999999997,339.6324713097209,26.157022024310734,3.378073776039841
1.082983688679622e-06,0.0025864,339.7203750124216,26.157022024310734,3.378073776039841
1.0903532034185492e-06,0.002604,339.84901326973295,26.157022024310734,3.378073776039841
1.100737519641583e-06,0.0026287999999999997,340.0297022226052,26.157022024310734,3.378073776039841
1.1054272108390821e-06,0.00264,340.11108565147964,26.157022024310734,3.378073776039841
1.1251909094571142e-06,0.0026872,340.45258967146475,26.157022024310734,3.378073776039841
1.1318904683106843e-06,0.0027032,340.5678217757769,26.157022024310734,3.378073776039841
1.134905269794791e-06,0.0027104,340.619589409506,26.157022024310734,3.378073776039841
1.1402649168776472e-06,0.0027232,340.7114885289996,26.157022024310734,3.378073776039841
1.1432797183617538e-06,0.0027304,340.7631077489325,26.157022024310734,3.378073776039841
1.1452895860178247e-06,0.0027351999999999997,340.79749107297204,26.157022024310734,3.378073776039841
1.1472994536738959e-06,0.00274,340.8318508727351,26.157022024310734,3.378073776039841
1.1583537257822868e-06,0.0027664,341.0204118219518,26.157022024310734,3.378073776039841
1.1650532846358569e-06,0.0027824,341.1343496727217,26.157022024310734,3.378073776039841
1.1700779537760344e-06,0.0027944,341.2196354481595,26.157022024310734,3.378073776039841
1.1838120494258534e-06,0.0028271999999999998,341.4520242274736,26.157022024310734,3.378073776039841
1.1948663215342443e-06,0.0028536,341.63830602560853,26.157022024310734,3.378073776039841
1.199890990674422e-06,0.0028656,341.72275726157943,26.157022024310734,3.378073776039841
1.20257081421585e-06,0.002872,341.7677415205095,26.157022024310734,3.378073776039841
1.2072605054133492e-06,0.0028832,341.8463700148218,26.157022024310734,3.378073776039841
1.2099403289547773e-06,0.0028896,341.8912470993278,26.157022024310734,3.378073776039841
1.220994601063168e-06,0.0029159999999999998,342.0759568054395,26.157022024310734,3.378073776039841
1.2219995348912035e-06,0.0029184,342.09271619060695,26.157022024310734,3.378073776039841
1.2273591819740597e-06,0.0029311999999999997,342.18200896218184,26.157022024310734,3.378073776039841
1.2357336305410223e-06,0.0029511999999999997,342.32122508215696,26.157022024310734,3.378073776039841
1.2394183879104861e-06,0.00296,342.3823635577841,26.157022024310734,3.378073776039841
1.2424331893945926e-06,0.0029671999999999997,342.43233323791554,26.157022024310734,3.378073776039841
1.255162351216376e-06,0.0029976,342.64279711141756,26.157022024310734,3.378073776039841
1.259182086528518e-06,0.0030072,342.7090862311485,26.157022024310734,3.378073776039841
1.2611919541845892e-06,0.003012,342.74219983832614,26.157022024310734,3.378073776039841
1.2635367997833389e-06,0.0030176,342.7808063797465,26.157022024310734,3.378073776039841
1.269566402751552e-06,0.003032,342.8799522590968,26.157022024310734,3.378073776039841
1.2745910718917296e-06,0.003044,342.9624336208872,26.157022024310734,3.378073776039841
1.2869852557708344e-06,0.0030735999999999997,343.1653473169376,26.157022024310734,3.378073776039841
1.3157933588411863e-06,0.0031424,343.63406280572457,26.157022024310734,3.378073776039841
1.3174682485545788e-06,0.0031463999999999997,343.6611899404135,26.157022024310734,3.378073776039841
1.322827895637435e-06,0.0031592,343.74790652820434,26.157022024310734,3.378073776039841
1.3285225206629695e-06,0.0031728,343.8398928996964,26.157022024310734,3.378073776039841
1.3332122118604687e-06,0.0031839999999999998,343.91553097389465,26.157022024310734,3.378073776039841
1.3385718589433249e-06,0.0031967999999999996,344.00184754462435,26.157022024310734,3.378073776039841
1.341251682484753e-06,0.0032032,344.04495527673936,26.157022024310734,3.378073776039841
1.3486211972236802e-06,0.0032208,344.16332868623897,26.157022024310734,3.378073776039841
1.3553207560772503e-06,0.0032367999999999997,344.27072214528573,26.157022024310734,3.378073776039841
1.3593404913893926e-06,0.0032464,344.33505884772893,26.157022024310734,3.378073776039841
1.3663750281856412e-06,0.0032632,344.4474698232978,26.157022024310734,3.378073776039841
1.37340956498189e-06,0.00328,344.55965532029325,26.157022024310734,3.378073776039841
1.378769212064746e-06,0.0032928,344.6449796347469,26.157022024310734,3.378073776039841
1.391833351829208e-06,0.0033239999999999997,344.85241752910173,26.157022024310734,3.378073776039841
1.3988678886254566e-06,0.0033407999999999997,344.96380027125343,26.157022024310734,3.378073776039841
1.410257138676526e-06,0.003368,345.1436722082316,26.157022024310734,3.378073776039841
1.4146118519313465e-06,0.0033783999999999997,345.2122969416635,26.157022024310734,3.378073776039841
1.4206414548995596e-06,0.0033927999999999996,345.3071799446289,26.157022024310734,3.378073776039841
1.4353804843774144e-06,0.003428,345.5384573931637,26.157022024310734,3.378073776039841
1.4414100873456275e-06,0.0034424,345.632803726742,26.157022024310734,3.378073776039841
1.4427499991163414e-06,0.0034456,345.6537486616387,26.157022024310734,3.378073776039841
1.4494495579699117e-06,0.0034616,345.7583597578301,26.157022024310734,3.378073776039841
1.4561491168234818e-06,0.0034776,345.8627824475013,26.157022024310734,3.378073776039841
1.457489028594196e-06,0.0034808,345.883644482823,26.157022024310734,3.378073776039841
1.4668684109891941e-06,0.0035031999999999997,346.0294698652337,26.157022024310734,3.378073776039841
1.4739029477854428e-06,0.0035199999999999997,346.1386003775927,26.157022024310734,3.378073776039841
1.4822773963524054e-06,0.0035399999999999997,346.26825315634864,26.157022024310734,3.378073776039841
1.4849572198938337e-06,0.0035464,346.30968166973463,26.157022024310734,3.378073776039841
1.4913218008047252e-06,0.0035616,346.40795770464075,26.157022024310734,3.378073776039841
1.49701642583026e-06,0.0035751999999999997,346.4957503282126,26.157022024310734,3.378073776039841
1.4990262934863311e-06,0.00358,346.5267048510506,26.157022024310734,3.378073776039841
1.5067307861679368e-06,0.0035984,346.64521420960193,26.157022024310734,3.378073776039841
1.5117554553081143e-06,0.0036103999999999997,346.7223756179639,26.157022024310734,3.378073776039841
1.5184550141616846e-06,0.0036263999999999997,346.82510208780343,26.157022024310734,3.378073776039841
1.5211348377031127e-06,0.0036328,346.86614316388744,26.157022024310734,3.378073776039841
1.5295092862700755e-06,0.0036528,346.99421515667336,26.157022024310734,3.378073776039841
1.5348689333529315e-06,0.0036655999999999998,347.07603773225105,26.157022024310734,3.378073776039841
1.546928139289358e-06,0.0036944,347.25973220674064,26.157022024310734,3.378073776039841
1.5573124555123917e-06,0.0037191999999999998,347.4174664924321,26.157022024310734,3.378073776039841
1.5633420584806048e-06,0.0037335999999999997,347.5088659037368,26.157022024310734,3.378073776039841
1.5687017055634612e-06,0.0037464,347.5899944723067,26.157022024310734,3.378073776039841
1.5700416173341751e-06,0.0037495999999999996,347.61025971467006,26.157022024310734,3.378073776039841
1.577076154130424e-06,0.0037664,347.7165417808896,26.157022024310734,3.378073776039841
1.5784160659011377e-06,0.0037695999999999997,347.7367650047996,26.157022024310734,3.378073776039841
1.5958349189204204e-06,0.0038112,347.99906060094395,26.157022024310734,3.378073776039841
1.6011945660032765e-06,0.0038239999999999997,348.07954199103955,26.157022024310734,3.378073776039841
1.6055492792580971e-06,0.0038344,348.1448557870849,26.157022024310734,3.378073776039841
1.6125838160543458e-06,0.0038512,348.25021693360674,26.157022024310734,3.378073776039841
1.6256479558188078e-06,0.0038824,348.4454132957368,26.157022024310734,3.378073776039841
1.6279928014175573e-06,0.003888,348.48038368631006,26.157022024310734,3.378073776039841
1.633687426443092e-06,0.0039016,348.5652300958116,26.157022024310734,3.378073776039841
1.6400520073539836e-06,0.0039168,348.65992205729736,26.157022024310734,3.378073776039841
1.641056941182019e-06,0.003919199999999999,348.6748603089276,26.157022024310734,3.378073776039841
1.6484264559209464e-06,0.0039368,348.78429868538626,26.157022024310734,3.378073776039841
1.6614905956854084e-06,0.003968,348.9778352873571,26.157022024310734,3.378073776039841
1.666515264825586e-06,0.00398,349.05211430007836,26.157022024310734,3.378073776039841
1.6705350001377278e-06,0.003989599999999999,349.11147464249035,26.157022024310734,3.378073776039841
1.7311772652729145e-06,0.0041344268853770755,350.00034042303986,26.157022024310734,3.378073776039841
1.908080999754064e-06,0.004556911382276456,352.52640896611956,26.157022024310734,3.378073776039841
1.9322042362742206e-06,0.0046145229045809165,352.86365412211825,26.157022024310734,3.378073776039841
2.0447793400349523e-06,0.004883376675335067,354.4162491100767,26.157022024310734,3.378073776039841
2.197559837995945e-06,0.0052482496499299865,356.4710185111025,26.157022024310734,3.378073776039841
2.294052784076572e-06,0.00547869573914783,357.7400930742412,26.157022024310734,3.378073776039841
2.3503403359569372e-06,0.005613122624524905,358.4707713240706,26.157022024310734,3.378073776039841
2.3664224936370417e-06,0.005651530306061212,358.678278897611,26.157022024310734,3.378073776039841
2.3985868089972506e-06,0.005728345669133827,359.09165140696456,26.157022024310734,3.378073776039841
2.6478602530388706e-06,0.006323664732946589,362.2250652810376,26.157022024310734,3.378073776039841
2.929298012440699e-06,0.006995799159831967,365.6275146677731,26.157022024310734,3.378073776039841
3.0579552738815348e-06,0.007303060612122424,367.1401840059227,26.157022024310734,3.378073776039841
3.138366062282057e-06,0.00749509901980396,368.0730065870639,26.157022024310734,3.378073776039841
3.3876395063236766e-06,0.008090418083616723,370.9072108514679,26.157022024310734,3.378073776039841
3.5484610831247217e-06,0.008474494898979796,372.69263239420695,26.157022024310734,3.378073776039841
3.837939921366602e-06,0.009165833166633327,375.82879558366966,26.157022024310734,3.378073776039841
4.264117099889371e-06,0.010183636727345468,380.2828657713679,26.157022024310734,3.378073776039841
4.424938676690416e-06,0.01056771354270854,381.91805797017287,26.157022024310734,3.378073776039841
4.72245859377235e-06,0.011278255651130227,384.88331185974744,26.157022024310734,3.378073776039841
4.9395677224537595e-06,0.011796759351870374,387.00133963631464,26.157022024310734,3.378073776039841
5.028019589694335e-06,0.012008001600320064,387.85379241711115,26.157022024310734,3.378073776039841
5.229046560695641e-06,0.012488097619523904,389.76972722472493,26.157022024310734,3.378073776039841
5.33358058561632e-06,0.012737747549509902,390.75464689442225,26.157022024310734,3.378073776039841
5.40595029517679e-06,0.012910582116423285,391.4321085132074,26.157022024310734,3.378073776039841
5.8080042371794026e-06,0.013870774154830966,395.13328004889934,26.157022024310734,3.378073776039841
5.9768668928205e-06,0.014274054810962193,396.65780782152666,26.157022024310734,3.378073776039841
6.0572776812210225e-06,0.01446609321864373,397.37786086426985,26.157022024310734,3.378073776039841
6.081400917741179e-06,0.01452370474094819,397.5931485723742,26.157022024310734,3.378073776039841
6.314592204102694e-06,0.015080616123224646,399.65737267072956,26.157022024310734,3.378073776039841
6.419126229023373e-06,0.015330266053210643,400.5730408618326,26.157022024310734,3.378073776039841
6.499537017423896e-06,0.01552230446089218,401.2734492532489,26.157022024310734,3.378073776039841
6.596029963504523e-06,0.015752750550110023,402.1094940968189,26.157022024310734,3.378073776039841
6.628194278864732e-06,0.015829565913182637,402.3871139493201,26.157022024310734,3.378073776039841
6.756851540305568e-06,0.016136827365473096,403.49237925423796,26.157022024310734,3.378073776039841
6.9015909594265065e-06,0.016482496499299858,404.7260382433929,26.157022024310734,3.378073776039841
6.990042826667082e-06,0.01669373874774955,405.47497501544063,26.157022024310734,3.378073776039841
7.343850295629381e-06,0.01753870774154831,408.4344811246898,26.157022024310734,3.378073776039841
7.633329133871261e-06,0.01823004600920184,410.81473962056,26.157022024310734,3.378073776039841
7.705698843431732e-06,0.01840288057611522,411.4042709653724,26.157022024310734,3.378073776039841
8.300738677595598e-06,0.01982396479295859,416.1722652113461,26.157022024310734,3.378073776039841
8.622381831197687e-06,0.020592118423684736,418.6939538902849,26.157022024310734,3.378073776039841
8.751039092638523e-06,0.020899379875975194,419.69232390038246,26.157022024310734,3.378073776039841
9.137010876961032e-06,0.02182116423284657,422.6536389555644,26.157022024310734,3.378073776039841
9.281750296081972e-06,0.022166833366673334,423.75150168391673,26.157022024310734,3.378073776039841
9.563188055483801e-06,0.022838967793558713,425.8673061575353,26.157022024310734,3.378073776039841
9.764215026485107e-06,0.023319063812762553,427.36375289170195,26.157022024310734,3.378073776039841
9.973283076326466e-06,0.023818363672734547,428.9073661737497,26.157022024310734,3.378073776039841
1.0053693864726987e-05,0.024010402080416084,429.4976967838654,26.157022024310734,3.378073776039841
1.0093899258927247e-05,0.02410642128425685,429.79217135584656,26.157022024310734,3.378073776039841
1.0246679756888242e-05,0.02447129425885177,430.9070274158427,26.157022024310734,3.378073776039841
1.0399460254849234e-05,0.02483616723344669,432.0154191202067,26.157022024310734,3.378073776039841
1.0471829964409704e-05,0.025009001800360073,432.5382285725329,26.157022024310734,3.378073776039841
1.0656774777730905e-05,0.025450690138027605,433.86793540058216,26.157022024310734,3.378073776039841
1.0737185566131428e-05,0.02564272854570914,434.44325830893547,26.157022024310734,3.378073776039841
1.0922130379452631e-05,0.026084416883376677,435.7601617286386,26.157022024310734,3.378073776039841
1.1107075192773832e-05,0.02652610522104421,437.06839663088437,26.157022024310734,3.378073776039841
1.1227691375374615e-05,0.026814162832566515,437.9170187084633,26.157022024310734,3.378073776039841
1.1372430794495556e-05,0.02715983196639328,438.93068635042977,26.157022024310734,3.378073776039841
1.1533252371296602e-05,0.027543908781756353,440.0511008961171,26.157022024310734,3.378073776039841
1.1702115026937698e-05,0.027947189437887578,441.22099814766716,26.157022024310734,3.378073776039841
1.1790566894178273e-05,0.02815843168633727,441.83117285787307,26.157022024310734,3.378073776039841
1.2039840338219892e-05,0.02875375075015003,443.5412251542306,26.157022024310734,3.378073776039841
1.2192620836180884e-05,0.029118623724744948,444.5824986193447,26.157022024310734,3.378073776039841
1.2256949466901301e-05,0.029272254450890177,445.0194057715418,26.157022024310734,3.378073776039841
1.235344241298193e-05,0.02950270054010802,445.6730934493784,26.157022024310734,3.378073776039841
1.2441894280222504e-05,0.029713942788557712,446.27055994506964,26.157022024310734,3.378073776039841
1.2683126645424071e-05,0.03029005801160232,447.89165335056384,26.157022024310734,3.378073776039841
1.3133427060467e-05,0.03136547309461893,450.885877559838,26.157022024310734,3.378073776039841
1.3221878927707571e-05,0.03157671534306861,451.46929479965155,26.157022024310734,3.378073776039841
1.3519398844789507e-05,0.0322872574514903,453.42062253062454,26.157022024310734,3.378073776039841
1.3599809633190028e-05,0.032479295859171836,453.94512433526194,26.157022024310734,3.378073776039841
1.3640015027390288e-05,0.0325753150630126,454.20692158835794,26.157022024310734,3.378073776039841
1.3841041998391596e-05,0.03305541108221645,455.51142057183864,26.157022024310734,3.378073776039841
1.4001863575192638e-05,0.033439487897579515,456.5497073033944,26.157022024310734,3.378073776039841
1.4347629965314887e-05,0.03426525305061012,458.7664041304972,26.157022024310734,3.378073776039841
1.4452163990235565e-05,0.03451490298059612,459.4324539062447,26.157022024310734,3.378073776039841
1.4476287226755723e-05,0.03457251450290058,459.58589056627267,26.157022024310734,3.378073776039841
1.4564739093996298e-05,0.03478375675135027,460.14764053926,26.157022024310734,3.378073776039841
1.4749683907317497e-05,0.0352254450890178,461.31792744792085,26.157022024310734,3.378073776039841
1.4854217932238176e-05,0.0354750950190038,461.9768622178633,26.157022024310734,3.378073776039841
1.5095450297439744e-05,0.03605121024204841,463.4906172151936,26.157022024310734,3.378073776039841
1.5288436189601e-05,0.0365121024204841,464.69483934422243,26.157022024310734,3.378073776039841
1.5553791791322725e-05,0.03714582916583317,466.3410093348239,26.157022024310734,3.378073776039841
1.557791502784288e-05,0.037203440688137634,466.4901159153021,26.157022024310734,3.378073776039841
1.5851311708404657e-05,0.037856371274254855,468.17374500326343,26.157022024310734,3.378073776039841
1.5979968969845493e-05,0.03816363272654531,468.96211882619076,26.157022024310734,3.378073776039841
1.607646191592612e-05,0.03839407881576315,469.55177569517156,26.157022024310734,3.378073776039841
1.6221201335047056e-05,0.03873974794958991,470.43367954597994,26.157022024310734,3.378073776039841
1.6301612123447584e-05,0.03893178635727146,470.92229989917456,26.157022024310734,3.378073776039841
1.651068017328894e-05,0.03943108621724345,472.18833385433106,26.157022024310734,3.378073776039841
1.6776035775010667e-05,0.040064812962592525,473.78625534861004,26.157022024310734,3.378073776039841
1.6792117932690768e-05,0.04010322064412883,473.88278105149675,26.157022024310734,3.378073776039841
1.699314490369207e-05,0.04058331666333266,475.0863263085971,26.157022024310734,3.378073776039841
1.7089637849772703e-05,0.04081376275255051,475.66205459576184,26.157022024310734,3.378073776039841
1.7186130795853326e-05,0.04104420884176835,476.23651648685427,26.157022024310734,3.378073776039841
1.7314788057294162e-05,0.041351470294058806,477.00051277026057,26.157022024310734,3.378073776039841
1.7523856107135525e-05,0.04185077015403081,478.23730159130776,26.157022024310734,3.378073776039841
1.7636431210896253e-05,0.04211962392478495,478.9008806492558,26.157022024310734,3.378073776039841
1.7740965235816936e-05,0.04236927385477096,479.5155835773141,26.157022024310734,3.378073776039841
1.7869622497257772e-05,0.04267653530706142,480.27020530439466,26.157022024310734,3.378073776039841
1.8231471045060124e-05,0.04354070814162833,482.3813023221392,26.157022024310734,3.378073776039841
1.83360050699808e-05,0.04379035807161433,482.9881243031002,26.157022024310734,3.378073776039841
1.8448580173741528e-05,0.04405921184236847,483.6401179921142,26.157022024310734,3.378073776039841
1.8681771460103047e-05,0.044616123224644935,484.98576108640106,26.157022024310734,3.378073776039841
1.8858675194584194e-05,0.045038607721544305,486.00222847085894,26.157022024310734,3.378073776039841
1.9107948638625815e-05,0.045633926785357076,487.4282342611365,26.157022024310734,3.378073776039841
1.9268770215426857e-05,0.04601800360072014,488.344389148075,26.157022024310734,3.378073776039841
1.9574331211348847e-05,0.046747749549909984,490.0769092404423,26.157022024310734,3.378073776039841
1.9936179759151195e-05,0.047611922384476896,492.1149954413431,26.157022024310734,3.378073776039841
2.0016590547551716e-05,0.04780396079215843,492.56593833170075,26.157022024310734,3.378073776039841
2.016937104551271e-05,0.04816883376675335,493.42078818487136,26.157022024310734,3.378073776039841
2.0257822912753286e-05,0.04838007601520304,493.91454698083015,26.157022024310734,3.378073776039841
2.0724205485476315e-05,0.04949389877975595,496.50422819069195,26.157022024310734,3.378073776039841
2.0820698431556944e-05,0.0497243448689738,497.0371754183226,26.157022024310734,3.378073776039841
2.097347892951794e-05,0.05008921784356872,497.87904272857605,26.157022024310734,3.378073776039841
2.1045848639078406e-05,0.050262052410482094,498.27698690464774,26.157022024310734,3.378073776039841
2.1118218348638876e-05,0.05043488697739548,498.6743977618008,26.157022024310734,3.378073776039841
2.117450590051924e-05,0.05056931386277255,498.9831280067115,26.157022024310734,3.378073776039841
2.1214711294719502e-05,0.05066533306661332,499.20345368236906,26.157022024310734,3.378073776039841
2.1295122083120026e-05,0.050857371474294866,499.6436171038899,26.157022024310734,3.378073776039841
2.1689134946282585e-05,0.051798359671934385,501.79111811587563,26.157022024310734,3.378073776039841
2.181779220772342e-05,0.052105621124224843,502.4890406507265,26.157022024310734,3.378073776039841
2.191428515380405e-05,0.052336067213442694,503.0114297076369,26.157022024310734,3.378073776039841
2.2163558597845667e-05,0.05293138627725545,504.35679955936087,26.157022024310734,3.378073776039841
2.228417478044645e-05,0.05321944388877775,505.00566534141757,26.157022024310734,3.378073776039841
2.2412832041887284e-05,0.05352670534106821,505.6962809527396,26.157022024310734,3.378073776039841
2.279880382620979e-05,0.054448489697939584,507.7589102710033,26.157022024310734,3.378073776039841
2.2983748639531e-05,0.054890178035607126,508.7424233763089,26.157022024310734,3.378073776039841
2.3482295527614234e-05,0.05608081616323264,511.3783781766422,26.157022024310734,3.378073776039841
2.35225009218145e-05,0.05617683536707342,511.5899994191104,26.157022024310734,3.378073776039841
2.3731568971655855e-05,0.05667613522704541,512.6881641614344,26.157022024310734,3.378073776039841
2.392455486381711e-05,0.0571370274054811,513.6985104761787,26.157022024310734,3.378073776039841
2.396476025801737e-05,0.057233046609321866,513.9085986680988,26.157022024310734,3.378073776039841
2.4181869386698782e-05,0.057751550310062016,515.0407084427972,26.157022024310734,3.378073776039841
2.4342690963499824e-05,0.05813562712542508,515.8767542528288,26.157022024310734,3.378073776039841
2.455175901334118e-05,0.05863492698539707,516.9604004484444,26.157022024310734,3.378073776039841
2.459196440754145e-05,0.058730946189237854,517.1683807308348,26.157022024310734,3.378073776039841
2.4776909220862646e-05,0.05917263452690538,518.1233871857495,26.157022024310734,3.378073776039841
2.4873402166943272e-05,0.05940308061612322,518.6205475516792,26.157022024310734,3.378073776039841
2.4921648639983587e-05,0.059518303660732144,518.8688456267494,26.157022024310734,3.378073776039841
2.499401834954406e-05,0.05969113822764553,519.2409415268772,26.157022024310734,3.378073776039841
2.507442913794458e-05,0.059883176635327065,519.6538889572897,26.157022024310734,3.378073776039841
2.5307620424306094e-05,0.06044008801760352,520.8485258984816,26.157022024310734,3.378073776039841
2.5339784739666307e-05,0.06051690338067614,521.012965863153,26.157022024310734,3.378073776039841
2.5444318764586984e-05,0.060766553310662136,521.5468344359018,26.157022024310734,3.378073776039841
2.54925652376273e-05,0.06088177635527106,521.7929467451193,26.157022024310734,3.378073776039841
2.5765961918189075e-05,0.06153470694138828,523.1841670926748,26.157022024310734,3.378073776039841
2.589461917962991e-05,0.06184196839367874,523.8368658407963,26.157022024310734,3.378073776039841
2.5918742416150067e-05,0.0618995799159832,523.9591059273193,26.157022024310734,3.378073776039841
2.6023276441070747e-05,0.0621492298459692,524.488301064633,26.157022024310734,3.378073776039841
2.6127810465991427e-05,0.06239887977595519,525.0166678070709,26.157022024310734,3.378073776039841
2.6168015860191687e-05,0.06249489897979596,525.2196661821487,26.157022024310734,3.378073776039841
2.622430341207205e-05,0.06262932586517303,525.5036596739598,26.157022024310734,3.378073776039841
2.6385124988873098e-05,0.06301340268053611,526.313762673995,26.157022024310734,3.378073776039841
2.6674603827114976e-05,0.06370474094818963,527.76711190169,26.157022024310734,3.378073776039841
2.6883671876956336e-05,0.06420404080816164,528.8129302396935,26.157022024310734,3.378073776039841
2.6996246980717064e-05,0.06447289457891578,529.3747491831813,26.157022024310734,3.378073776039841
2.7076657769117592e-05,0.06466493298659733,529.7754891697912,26.157022024310734,3.378073776039841
2.7695820839801615e-05,0.06614362872574515,532.8457910697125,26.157022024310734,3.378073776039841
2.7792313785882238e-05,0.06637407481496299,533.321857974793,26.157022024310734,3.378073776039841
2.7880765653122813e-05,0.06658531706341268,533.7576866635692,26.157022024310734,3.378073776039841
2.8073751545284068e-05,0.06704620924184837,534.7067182659331,26.157022024310734,3.378073776039841
2.865270922176783e-05,0.06842888577715543,537.5386634388689,26.157022024310734,3.378073776039841
2.874920216784846e-05,0.06865933186637328,538.0084761410727,26.157022024310734,3.378073776039841
2.900651669073013e-05,0.0692738547709542,539.2583131639018,26.157022024310734,3.378073776039841
2.925579013477175e-05,0.06986917383476696,540.4649758803752,26.157022024310734,3.378073776039841
2.949702249997332e-05,0.07044528905781157,541.6289019981635,26.157022024310734,3.378073776039841
2.9585474367213894e-05,0.07065653130626126,542.0547440060184,26.157022024310734,3.378073776039841
2.964980299793431e-05,0.07081016203240649,542.3641354807805,26.157022024310734,3.378073776039841
2.99714461515364e-05,0.07157831566313264,543.90718332199,26.157022024310734,3.378073776039841
2.9987528309216503e-05,0.07161672334466894,543.9841657381421,26.157022024310734,3.378073776039841
3.0092062334137183e-05,0.07186637327465493,544.4841595512022,26.157022024310734,3.378073776039841
3.0469993039619636e-05,0.07276895379075815,546.2862053539789,26.157022024310734,3.378073776039841
3.0574527064540316e-05,0.07301860372074415,546.7831018523179,26.157022024310734,3.378073776039841
3.077555403554162e-05,0.07349869973994799,547.7368137499624,26.157022024310734,3.378073776039841
3.093637561234267e-05,0.07388277655531107,548.4980351315047,26.157022024310734,3.378073776039841
3.125801876594476e-05,0.07465093018603722,550.0158637304306,26.157022024310734,3.378073776039841
3.1386676027385595e-05,0.07495819163832768,550.621288168957,26.157022024310734,3.378073776039841
3.142688142158586e-05,0.07505421084216844,550.8102847177694,26.157022024310734,3.378073776039841
3.154749760418664e-05,0.07534226845369074,551.376709387447,26.157022024310734,3.378073776039841
3.172440133866779e-05,0.07576475295059013,552.205940186779,26.157022024310734,3.378073776039841
3.184501752126857e-05,0.07605281056211242,552.7702911386125,26.157022024310734,3.378073776039841
3.187718183662878e-05,0.07612962592518505,552.9206438560101,26.157022024310734,3.378073776039841
3.1925428309669094e-05,0.07624484896979396,553.1460620440541,26.157022024310734,3.378073776039841
3.202192125574972e-05,0.07647529505901181,553.596500246759,26.157022024310734,3.378073776039841
3.2182742832550765e-05,0.07685937187437487,554.3460560173309,26.157022024310734,3.378073776039841
3.227119469979134e-05,0.07707061412282457,554.7576889826915,26.157022024310734,3.378073776039841
3.2504385986152856e-05,0.07762752550510102,555.8407994906195,26.157022024310734,3.378073776039841
3.2777782666714636e-05,0.07828045609121825,557.1068015068572,26.157022024310734,3.378073776039841
3.288231669163531e-05,0.07853010602120425,557.5897719221069,26.157022024310734,3.378073776039841
3.292252208583558e-05,0.07862612522504502,557.7753702849993,26.157022024310734,3.378073776039841
3.299489179539604e-05,0.07879895979195839,558.1092247352877,26.157022024310734,3.378073776039841
3.305117934727641e-05,0.07893338667733547,558.3686919075506,26.157022024310734,3.378073776039841
3.3075302583796565e-05,0.07899099819963994,558.4798393624676,26.157022024310734,3.378073776039841
3.3187877687557296e-05,0.07925985197039408,558.9981100385055,26.157022024310734,3.378073776039841
3.342106897391881e-05,0.07981676335267054,560.0694947721546,26.157022024310734,3.378073776039841
3.350952084115939e-05,0.08002800560112022,560.4751189323252,26.157022024310734,3.378073776039841
3.377487644288111e-05,0.0806617323464693,561.6894933868572,26.157022024310734,3.378073776039841
3.389549262548189e-05,0.0809497899579916,562.2402511491492,26.157022024310734,3.378073776039841
3.400806772924262e-05,0.08121864372874575,562.7536025201077,26.157022024310734,3.378073776039841
3.4530737853846025e-05,0.08246689337867574,565.1283917289677,26.157022024310734,3.378073776039841
3.4587025405726384e-05,0.08260132026405281,565.3832993197092,26.157022024310734,3.378073776039841
3.4763929140207534e-05,0.0830238047609522,566.1833862183968,26.157022024310734,3.378073776039841
3.498103826888895e-05,0.08354230846169235,567.1631441737044,26.157022024310734,3.378073776039841
3.5037325820769314e-05,0.08367673534706942,567.4167680154551,26.157022024310734,3.378073776039841
3.5230311712930566e-05,0.0841376275255051,568.2851316463102,26.157022024310734,3.378073776039841
3.5326804659011196e-05,0.08436807361472295,568.7186176444168,26.157022024310734,3.378073776039841
3.549566731465229e-05,0.08477135427085418,569.4761086348818,26.157022024310734,3.378073776039841
3.558411918189287e-05,0.08498259651930387,569.8723286742802,26.157022024310734,3.378073776039841
3.568061212797349e-05,0.08521304260852171,570.3041309027127,26.157022024310734,3.378073776039841
3.5849474783614586e-05,0.08561632326465293,571.0586905489396,26.157022024310734,3.378073776039841
3.60505017546159e-05,0.08609641928385678,571.955170907946,26.157022024310734,3.378073776039841
3.632389843517767e-05,0.086749349869974,573.1712617314946,26.157022024310734,3.378073776039841
3.66053361945795e-05,0.08742148429685938,574.419397009639,26.157022024310734,3.378073776039841
3.6774198850220595e-05,0.0878247649529906,575.1664818870535,26.157022024310734,3.378073776039841
3.6822445323260913e-05,0.08793998799759953,575.3796888177593,26.157022024310734,3.378073776039841
3.687873287514128e-05,0.0880744148829766,575.6282925879184,26.157022024310734,3.378073776039841
3.706367768846248e-05,0.08851610322064413,576.4440936216131,26.157022024310734,3.378073776039841
3.7296868974824e-05,0.0890730146029206,577.4704530013015,26.157022024310734,3.378073776039841
3.788386773014781e-05,0.0904748949789958,580.0430298843453,26.157022024310734,3.378073776039841
3.799644283390854e-05,0.09074374874974996,580.5346192153237,26.157022024310734,3.378073776039841
3.8205510883749894e-05,0.09124304860972195,581.4460664623707,26.157022024310734,3.378073776039841
3.826983951447031e-05,0.09139667933586718,581.7261201624216,26.157022024310734,3.378073776039841
3.8326127066350685e-05,0.09153110622124426,581.971016581836,26.157022024310734,3.378073776039841
3.842262001243131e-05,0.0917615523104621,582.3905129245541,26.157022024310734,3.378073776039841
3.8607564825752506e-05,0.09220324064812963,583.193400932417,26.157022024310734,3.378073776039841
3.9090029556155646e-05,0.09335547109421885,585.2808624867037,26.157022024310734,3.378073776039841
3.9331261921357216e-05,0.09393158631726346,586.3208234687582,26.157022024310734,3.378073776039841
3.947600134047815e-05,0.09427725545109022,586.9436060786038,26.157022024310734,3.378073776039841
3.950012457699831e-05,0.09433486697339469,587.047316538906,26.157022024310734,3.378073776039841
3.99906303862415e-05,0.09550630126025206,589.1507681330764,26.157022024310734,3.378073776039841
4.010320549000223e-05,0.09577515503100621,589.6321050172581,26.157022024310734,3.378073776039841
4.0159493041882596e-05,0.09590958191638328,589.8725758291257,26.157022024310734,3.378073776039841
4.019969843608285e-05,0.09600560112022405,590.0442602239501,26.157022024310734,3.378073776039841
4.023990383028312e-05,0.09610162032406482,590.215877665419,26.157022024310734,3.378073776039841
4.043288972244437e-05,0.0965625125025005,591.0387123204284,26.157022024310734,3.378073776039841
4.057762914156531e-05,0.09690818163632726,591.654833523248,26.157022024310734,3.378073776039841
4.069020424532604e-05,0.09717703540708142,592.133446534397,26.157022024310734,3.378073776039841
4.0762573954886514e-05,0.09734986997399481,592.4408536488232,26.157022024310734,3.378073776039841
4.0955559847047766e-05,0.0978107621524305,593.2595671353995,26.157022024310734,3.378073776039841
4.132544947369017e-05,0.09869413882776555,594.8245747400516,26.157022024310734,3.378073776039841
4.151843536585142e-05,0.09915503100620124,595.6389312122003,26.157022024310734,3.378073776039841
4.161492831193205e-05,0.09938547709541909,596.0455557539686,26.157022024310734,3.378073776039841
4.169533910033257e-05,0.09957751550310062,596.3841287261804,26.157022024310734,3.378073776039841
4.174358557337288e-05,0.09969273854770955,596.5871502797245,26.157022024310734,3.378073776039841
4.177574988873309e-05,0.09976955391078215,596.7224471439312,26.157022024310734,3.378073776039841