File: datasets/aisi_316_L/data/M1/valid_20.csv
Time(s),Strain(%),Stress(MPa),Temp(C),Log_SR(s-1)
0.0,0.0,0.0,424.33079162893785,-2.1939725852970504
0.003751317534121441,2.4e-05,4.0134075000000005,424.33079162893785,-2.1939725852970504
0.007752722903850978,4.96e-05,8.2943755,424.33079162893785,-2.1939725852970504
0.008502986410675265,5.4399999999999994e-05,9.097057,424.33079162893785,-2.1939725852970504
0.011003864766756228,7.04e-05,11.772662,424.33079162893785,-2.1939725852970504
0.011879172191384561,7.599999999999999e-05,12.709123749999998,424.33079162893785,-2.1939725852970504
0.013129611369425044,8.4e-05,14.046926249999999,424.33079162893785,-2.1939725852970504
0.01463013838307362,9.36e-05,15.652289249999999,424.33079162893785,-2.1939725852970504
0.016380753232330292,0.0001048,17.52521275,424.33079162893785,-2.1939725852970504
0.02013207076645173,0.0001288,21.538620249999997,424.33079162893785,-2.1939725852970504
0.02100737819108007,0.0001344,22.475081999999997,424.33079162893785,-2.1939725852970504
0.024383563971789365,0.000156,26.08714875,424.33079162893785,-2.1939725852970504
0.028384969341518903,0.0001816,30.36811675,424.33079162893785,-2.1939725852970504
0.029635408519559384,0.0001896,31.70591925,424.33079162893785,-2.1939725852970504
0.033261682135876776,0.0002128,35.5855465,424.33079162893785,-2.1939725852970504
0.03738813142341036,0.0002392,40.000294749999995,424.33079162893785,-2.1939725852970504
0.03813839493023465,0.000244,40.80297625,424.33079162893785,-2.1939725852970504
0.04151458071094395,0.0002656,44.415043000000004,424.33079162893785,-2.1939725852970504
0.042890063806788475,0.0002744,45.88662575,424.33079162893785,-2.1939725852970504
0.04626624958749777,0.000296,49.4986925,424.33079162893785,-2.1939725852970504
0.05089287454624755,0.0003256,54.44856175,424.33079162893785,-2.1939725852970504
0.051893225888679936,0.000332,55.51880375,424.33079162893785,-2.1939725852970504
0.05351879682013255,0.0003424,57.257946999999994,424.33079162893785,-2.1939725852970504
0.05576958734060542,0.0003568,59.6659915,424.33079162893785,-2.1939725852970504
0.056019675176213514,0.0003584,59.933552,424.33079162893785,-2.1939725852970504
0.05889568528570662,0.0003768,63.01049775,424.33079162893785,-2.1939725852970504
0.059395860956922814,0.00037999999999999997,63.545618749999996,424.33079162893785,-2.1939725852970504
0.06027116838155115,0.0003856,64.4820805,424.33079162893785,-2.1939725852970504
0.06302213457324021,0.0004032,67.425246,424.33079162893785,-2.1939725852970504
0.06527292509371307,0.00041759999999999996,69.83329049999999,424.33079162893785,-2.1939725852970504
0.06602318860053735,0.00042239999999999997,70.635972,424.33079162893785,-2.1939725852970504
0.06789884736759808,0.0004344,72.64267575,424.33079162893785,-2.1939725852970504
0.06877415479222641,0.00043999999999999996,73.57913749999999,424.33079162893785,-2.1939725852970504
0.07052476964148309,0.00045119999999999996,75.452061,424.33079162893785,-2.1939725852970504
0.0784025364631381,0.0005015999999999999,83.88021674999999,424.33079162893785,-2.1939725852970504
0.08127854657263121,0.00052,86.9571625,424.33079162893785,-2.1939725852970504
0.0820288100794555,0.0005248,87.75984399999999,424.33079162893785,-2.1939725852970504
0.08265402966847574,0.0005288,88.42874524999999,424.33079162893785,-2.1939725852970504
0.08352933709310409,0.0005344,89.365207,424.33079162893785,-2.1939725852970504
0.08690552287381338,0.000556,92.97727375,424.33079162893785,-2.1939725852970504
0.08878118164087409,0.0005679999999999999,94.9839775,424.33079162893785,-2.1939725852970504
0.09040675257232672,0.0005784,96.72312074999999,424.33079162893785,-2.1939725852970504
0.09428311402425223,0.0006032,100.87030850000001,424.33079162893785,-2.1939725852970504
0.09690903629813723,0.00062,103.67969375,424.33079162893785,-2.1939725852970504
0.09928487073641414,0.0006351999999999999,106.22151849999999,424.33079162893785,-2.1939725852970504
0.10241096868151534,0.0006552,109.56602475,424.33079162893785,-2.1939725852970504
0.10578715446222463,0.0006768,113.1780915,424.33079162893785,-2.1939725852970504
0.1080379449826975,0.0006912,115.586136,424.33079162893785,-2.1939725852970504
0.10928838416073798,0.0006992,116.92393849999999,424.33079162893785,-2.1939725852970504
0.11266456994144727,0.0007208,120.53600524999999,424.33079162893785,-2.1939725852970504
0.1137899652016837,0.0007279999999999999,121.74002749999998,424.33079162893785,-2.1939725852970504
0.11679101922898086,0.0007472,124.95075349999999,424.33079162893785,-2.1939725852970504
0.11829154624262944,0.0007568,126.55611649999999,424.33079162893785,-2.1939725852970504
0.11979207325627801,0.0007664,128.16147949999998,424.33079162893785,-2.1939725852970504
0.12216790769455492,0.0007815999999999999,130.70330424999997,424.33079162893785,-2.1939725852970504
0.12379347862600755,0.000792,132.4424475,424.33079162893785,-2.1939725852970504
0.1284201035847573,0.0008215999999999999,137.39231675,424.33079162893785,-2.1939725852970504
0.1342971677215476,0.0008592,143.00021911178868,424.33079162893785,-2.1939725852970504
0.13579769473519615,0.0008688,143.04769728120513,424.33079162893785,-2.1939725852970504
0.13892379268029736,0.0008887999999999999,143.1459579779156,424.33079162893785,-2.1939725852970504
0.14042431969394592,0.0008983999999999999,143.1928164813533,424.33079162893785,-2.1939725852970504
0.1434253737212431,0.0009176,143.28595171649073,424.33079162893785,-2.1939725852970504
0.14517598857049976,0.0009287999999999999,143.3399296168563,424.33079162893785,-2.1939725852970504
0.14842713043340502,0.0009496,143.43950554772195,424.33079162893785,-2.1939725852970504
0.15055287703607384,0.0009632,143.5041532869522,424.33079162893785,-2.1939725852970504
0.15392906281678312,0.0009847999999999999,143.60610216807876,424.33079162893785,-2.1939725852970504
0.15455428240580338,0.0009888,143.62488550154984,424.33079162893785,-2.1939725852970504
0.15868073169333696,0.0010152,143.7481205405343,424.33079162893785,-2.1939725852970504
0.16205691747404627,0.0010368,143.84802215566987,424.33079162893785,-2.1939725852970504
0.1658082350081677,0.0010608,143.95807673428814,424.33079162893785,-2.1939725852970504
0.16968459646009318,0.0010856,144.07078437054986,424.33079162893785,-2.1939725852970504
0.1713101673915458,0.001096,144.11774949871818,424.33079162893785,-2.1939725852970504
0.17493644100786318,0.0011191999999999999,144.22189603263965,424.33079162893785,-2.1939725852970504
0.17968810988441702,0.0011496,144.35709820981086,424.33079162893785,-2.1939725852970504
0.18343942741853844,0.0011736,144.46285426319298,424.33079162893785,-2.1939725852970504
0.18744083278826798,0.0011991999999999999,144.57473524538474,424.33079162893785,-2.1939725852970504
0.1876909206238761,0.0012008,144.58169671922346,424.33079162893785,-2.1939725852970504
0.19156728207580156,0.0012255999999999999,144.6891411785312,424.33079162893785,-2.1939725852970504
0.19444329218529469,0.0012439999999999999,144.76831091519455,424.33079162893785,-2.1939725852970504
0.19494346785651087,0.0012472,144.78203281584112,424.33079162893785,-2.1939725852970504
0.1958187752811392,0.0012527999999999999,144.806013148316,424.33079162893785,-2.1939725852970504
0.1963189509523554,0.001256,144.81969742560116,424.33079162893785,-2.1939725852970504
0.19982018065086873,0.0012783999999999998,144.91510950278231,424.33079162893785,-2.1939725852970504
0.203071322513774,0.0012992,145.0031242438576,424.33079162893785,-2.1939725852970504
0.20557220086985495,0.0013151999999999999,145.07045444909255,424.33079162893785,-2.1939725852970504
0.20782299139032784,0.0013296,145.1307789904569,424.33079162893785,-2.1939725852970504
0.20994873799299663,0.0013432,145.18751863143217,424.33079162893785,-2.1939725852970504
0.21357501160931405,0.0013664,145.2837953810041,424.33079162893785,-2.1939725852970504
0.2155757142941788,0.0013792,145.3366406202275,424.33079162893785,-2.1939725852970504
0.21595084604759096,0.0013816,145.34652777247913,424.33079162893785,-2.1939725852970504
0.2189519000748881,0.0014008,145.4253852800846,424.33079162893785,-2.1939725852970504
0.21982720749951642,0.0014064,145.44830583638978,424.33079162893785,-2.1939725852970504
0.22070251492414475,0.0014119999999999998,145.47119082684952,424.33079162893785,-2.1939725852970504
0.22445383245826622,0.001436,145.56887113335483,424.33079162893785,-2.1939725852970504
0.22532913988289455,0.0014416,145.59157134411913,424.33079162893785,-2.1939725852970504
0.22582931555411076,0.0014448,145.6045274522792,424.33079162893785,-2.1939725852970504
0.2350825654716103,0.001504,145.8422330611843,424.33079162893785,-2.1939725852970504
0.23608291681404267,0.0015103999999999999,145.8677104776779,424.33079162893785,-2.1939725852970504
0.23733335599208313,0.0015183999999999998,145.89949811926655,424.33079162893785,-2.1939725852970504
0.23895892692353576,0.0015287999999999999,145.9407245751759,424.33079162893785,-2.1939725852970504
0.24020936610157625,0.0015367999999999998,145.97236284996225,424.33079162893785,-2.1939725852970504
0.24221006878644102,0.0015496,146.02285081449537,424.33079162893785,-2.1939725852970504
0.24358555188228556,0.0015584,146.05746698109346,424.33079162893785,-2.1939725852970504
0.24421077147130582,0.0015624,146.07317639273222,424.33079162893785,-2.1939725852970504
0.24821217684103536,0.001588,146.17334773964404,424.33079162893785,-2.1939725852970504
0.2543393288134337,0.0016271999999999999,146.32552310819707,424.33079162893785,-2.1939725852970504
0.25896595377218345,0.0016568,146.43948541999922,424.33079162893785,-2.1939725852970504
0.2599663051146158,0.0016631999999999999,146.4640211987465,424.33079162893785,-2.1939725852970504
0.26171691996387253,0.0016744,146.50687039423357,424.33079162893785,-2.1939725852970504
0.2644678861555616,0.001692,146.5739796912998,424.33079162893785,-2.1939725852970504
0.265468237497994,0.0016983999999999999,146.59831550247745,424.33079162893785,-2.1939725852970504
0.26646858884042635,0.0017048,146.62261557546375,424.33079162893785,-2.1939725852970504
0.26871937936089924,0.0017192,146.67716103448222,424.33079162893785,-2.1939725852970504
0.27259574081282467,0.0017439999999999999,146.77068459215207,424.33079162893785,-2.1939725852970504
0.2735960921552571,0.0017503999999999998,146.79473532779105,424.33079162893785,-2.1939725852970504
0.27559679484012184,0.0017632,146.84273415938878,424.33079162893785,-2.1939725852970504
0.278597848867419,0.0017824,146.91447838640798,424.33079162893785,-2.1939725852970504
0.2906020649766076,0.0018591999999999999,147.19849142668218,424.33079162893785,-2.1939725852970504
0.29272781157927646,0.0018728,147.2483047791905,424.33079162893785,-2.1939725852970504
0.2961039973599857,0.0018943999999999999,147.3271311145232,424.33079162893785,-2.1939725852970504
0.29822974396265456,0.001908,147.3765827258759,424.33079162893785,-2.1939725852970504
0.29960522705849907,0.0019168,147.40850758977413,424.33079162893785,-2.1939725852970504
0.3016059297433638,0.0019295999999999998,147.45484190508972,424.33079162893785,-2.1939725852970504
0.30185601757897196,0.0019311999999999999,147.46062525434675,424.33079162893785,-2.1939725852970504
0.3061075107843096,0.0019584,147.5586580697457,424.33079162893785,-2.1939725852970504
0.307232906044546,0.0019656,147.58451886635265,424.33079162893785,-2.1939725852970504
0.3103590039896472,0.0019856,147.65616128933033,424.33079162893785,-2.1939725852970504
0.31598598029082936,0.0020215999999999997,147.7844124340213,424.33079162893785,-2.1939725852970504
0.3221131322632277,0.0020608,147.9230548756121,424.33079162893785,-2.1939725852970504
0.3283653281534301,0.0021008,148.063470574353,424.33079162893785,-2.1939725852970504
0.32911559166025445,0.0021056,148.08025010258666,424.33079162893785,-2.1939725852970504
0.33061611867390295,0.0021152,148.11376447210853,424.33079162893785,-2.1939725852970504
0.3369933584819094,0.002156,148.2555437823342,424.33079162893785,-2.1939725852970504
0.33961928075579445,0.0021728,148.31361890277472,424.33079162893785,-2.1939725852970504
0.34174502735846324,0.0021864,148.36050393510857,424.33079162893785,-2.1939725852970504
0.3456213888103888,0.0022112,148.4457084044491,424.33079162893785,-2.1939725852970504
0.3492476624267062,0.0022344,148.52507902639255,424.33079162893785,-2.1939725852970504
0.34962279418011827,0.0022367999999999997,148.5332713940604,424.33079162893785,-2.1939725852970504
0.351373409029375,0.002248,148.57145720742525,424.33079162893785,-2.1939725852970504
0.35349915563204376,0.0022616,148.6177260905526,424.33079162893785,-2.1939725852970504
0.3571254292483612,0.0022848,148.69640570180536,424.33079162893785,-2.1939725852970504
0.3590010880154219,0.0022968,148.73697975539258,424.33079162893785,-2.1939725852970504
0.3647531082344081,0.0023336,148.86089440638213,424.33079162893785,-2.1939725852970504
0.36700389875488093,0.002348,148.90917500700183,424.33079162893785,-2.1939725852970504
0.3691296453575498,0.0023615999999999997,148.9546674276531,424.33079162893785,-2.1939725852970504
0.3716305237136307,0.0023775999999999997,149.00805731999154,424.33079162893785,-2.1939725852970504
0.37363122639849555,0.0023904,149.05066841510293,424.33079162893785,-2.1939725852970504
0.3742564459875158,0.0023944,149.0639661209063,424.33079162893785,-2.1939725852970504
0.3787580270284615,0.0024232,149.15945515091582,424.33079162893785,-2.1939725852970504
0.3821342128091708,0.0024448,149.2307817276909,424.33079162893785,-2.1939725852970504
0.38313456415160313,0.0024511999999999997,149.25186827482682,424.33079162893785,-2.1939725852970504
0.3892617161240015,0.0024904,149.38055796531424,424.33079162893785,-2.1939725852970504
0.39088728705545417,0.0025008,149.41456722277584,424.33079162893785,-2.1939725852970504
0.3933881654115351,0.0025168,149.4667816486316,424.33079162893785,-2.1939725852970504
0.3941384289183594,0.0025215999999999997,149.48242071136224,424.33079162893785,-2.1939725852970504
0.3965142633566363,0.0025368,149.5318679889821,424.33079162893785,-2.1939725852970504
0.3985149660415011,0.0025496,149.5734182444725,424.33079162893785,-2.1939725852970504
0.400890800479778,0.0025648,149.62265365738068,424.33079162893785,-2.1939725852970504
0.40264141532903464,0.0025759999999999997,149.65885959612254,424.33079162893785,-2.1939725852970504
0.4037668105892711,0.0025832,149.68210242744604,424.33079162893785,-2.1939725852970504
0.4042669862604873,0.0025864,149.69242446336614,424.33079162893785,-2.1939725852970504
0.406142645027548,0.0025984,149.73108781973892,424.33079162893785,-2.1939725852970504
0.4068929085343723,0.0026032,149.74653365644022,424.33079162893785,-2.1939725852970504
0.408768567301433,0.0026152,149.78509973313265,424.33079162893785,-2.1939725852970504
0.4120197091643383,0.002636,149.85178450841593,424.33079162893785,-2.1939725852970504
0.4153958949450476,0.0026576,149.92081723810654,424.33079162893785,-2.1939725852970504
0.41652129020528394,0.0026647999999999997,149.9437794763554,424.33079162893785,-2.1939725852970504
0.4195223442325811,0.0026839999999999998,150.00489412703556,424.33079162893785,-2.1939725852970504
0.4227734860954864,0.0027048,150.0709095778797,424.33079162893785,-2.1939725852970504
0.4250242766159592,0.0027191999999999997,150.11649664712746,424.33079162893785,-2.1939725852970504
0.42890063806788475,0.002744,150.19478762185432,424.33079162893785,-2.1939725852970504
0.4311514285883576,0.0027584,150.24012026051267,424.33079162893785,-2.1939725852970504
0.4386540636566005,0.0028063999999999997,150.3905668710811,424.33079162893785,-2.1939725852970504
0.43940432716342476,0.0028112,150.40555612542184,424.33079162893785,-2.1939725852970504
0.43990450283464094,0.0028144,150.41554341677454,424.33079162893785,-2.1939725852970504
0.44640678656045146,0.002856,150.54497780660597,424.33079162893785,-2.1939725852970504
0.44940784058774863,0.0028752,150.60446856133328,424.33079162893785,-2.1939725852970504
0.45078332368359314,0.002884,150.63168335842886,424.33079162893785,-2.1939725852970504
0.4521588067794377,0.0028928,150.65886578874077,424.33079162893785,-2.1939725852970504
0.45478472905332273,0.0029096,150.7106701354253,424.33079162893785,-2.1939725852970504
0.46028666143670083,0.0029448,150.81883582632298,424.33079162893785,-2.1939725852970504
0.4672891208337275,0.0029896,150.95577473787728,424.33079162893785,-2.1939725852970504
0.468539560011768,0.0029976,150.98014366268714,424.33079162893785,-2.1939725852970504
0.4714155701212611,0.003016,151.03609613749973,424.33079162893785,-2.1939725852970504
0.4727910532171056,0.0030248,151.06280894267132,424.33079162893785,-2.1939725852970504
0.4742915802307542,0.0030344,151.0919156412768,424.33079162893785,-2.1939725852970504
0.47504184373757846,0.0030391999999999997,151.1064555214949,424.33079162893785,-2.1939725852970504
0.4787931612716999,0.0030632,151.17902101720608,424.33079162893785,-2.1939725852970504
0.479043249107308,0.0030648,151.18385081834757,424.33079162893785,-2.1939725852970504
0.4800436004497404,0.0030712,151.20316019745917,424.33079162893785,-2.1939725852970504
0.48079386395656465,0.0030759999999999997,151.21763193498194,424.33079162893785,-2.1939725852970504
0.4817942152989971,0.0030824,151.23691389230797,424.33079162893785,-2.1939725852970504
0.48254447880582135,0.0030872,151.2513651154689,424.33079162893785,-2.1939725852970504
0.48567057675092257,0.0031072,151.31148446572027,424.33079162893785,-2.1939725852970504
0.4880464111891995,0.0031224,151.35707429207685,424.33079162893785,-2.1939725852970504
0.4904222456274764,0.0031376,151.4025776460469,424.33079162893785,-2.1939725852970504
0.49092242129869257,0.0031408,151.41214633561768,424.33079162893785,-2.1939725852970504
0.4941735631615978,0.0031615999999999997,151.47425039896888,424.33079162893785,-2.1939725852970504
0.49717461718889494,0.0031807999999999997,151.5314359424285,424.33079162893785,-2.1939725852970504
0.5003007151339961,0.0032007999999999997,151.59086124816548,424.33079162893785,-2.1939725852970504
0.5039269887503136,0.003224,151.65961348416002,424.33079162893785,-2.1939725852970504
0.50505238401055,0.0032312,151.68091111725005,424.33079162893785,-2.1939725852970504
0.5070530866954148,0.003244,151.7187279331736,424.33079162893785,-2.1939725852970504
0.5090537893802796,0.0032568,151.7564865996052,424.33079162893785,-2.1939725852970504
0.5105543163939281,0.0032664,151.7847676298913,424.33079162893785,-2.1939725852970504
0.5115546677363605,0.0032727999999999998,151.8036036432246,424.33079162893785,-2.1939725852970504
0.5176818197087588,0.003312,151.91866233389993,424.33079162893785,-2.1939725852970504
0.5203077419826438,0.0033288,151.9678104817515,424.33079162893785,-2.1939725852970504
0.5230587081743329,0.0033464,152.0191953739819,424.33079162893785,-2.1939725852970504
0.5239340155989612,0.003352,152.0355229950798,424.33079162893785,-2.1939725852970504
0.5270601135440625,0.003372,152.0937492848706,424.33079162893785,-2.1939725852970504
0.5286856844755151,0.0033824,152.1239737183406,424.33079162893785,-2.1939725852970504
0.5306863871603799,0.0033951999999999997,152.16112331260234,424.33079162893785,-2.1939725852970504
0.5325620459274406,0.0034072,152.19590148075437,424.33079162893785,-2.1939725852970504
0.5374387587217985,0.0034384,152.28610188756855,424.33079162893785,-2.1939725852970504
0.5404398127490956,0.0034576,152.34145119408066,424.33079162893785,-2.1939725852970504
0.5420653836805482,0.0034679999999999997,152.37138201438623,424.33079162893785,-2.1939725852970504
0.5435659106941968,0.0034776,152.39897940863625,424.33079162893785,-2.1939725852970504
0.5443161742010211,0.0034823999999999996,152.41276696281903,424.33079162893785,-2.1939725852970504
0.5489427991597708,0.003512,152.49762701839802,424.33079162893785,-2.1939725852970504
0.5541946437075409,0.0035456,152.59361735189842,424.33079162893785,-2.1939725852970504
0.5564454342280137,0.00356,152.63464739167932,424.33079162893785,-2.1939725852970504
0.5585711808306826,0.0035735999999999997,152.673338593207,424.33079162893785,-2.1939725852970504
0.5603217956799392,0.0035848,152.70515883482,424.33079162893785,-2.1939725852970504
0.5615722348579797,0.0035927999999999997,152.72786384531912,424.33079162893785,-2.1939725852970504
0.5629477179538243,0.0036016,152.75281659581404,424.33079162893785,-2.1939725852970504
0.5644482449674728,0.0036111999999999997,152.78001067544923,424.33079162893785,-2.1939725852970504
0.5659487719811214,0.0036208,152.80717657552745,424.33079162893785,-2.1939725852970504
0.567699386830378,0.003632,152.83883464823165,424.33079162893785,-2.1939725852970504
0.5691999138440267,0.0036416,152.8659398478161,424.33079162893785,-2.1939725852970504
0.5704503530220671,0.0036496,152.8885062331353,424.33079162893785,-2.1939725852970504
0.5773277685012898,0.0036936,153.0122782237419,424.33079162893785,-2.1939725852970504
0.5794535151039586,0.0037072,153.05041850926807,424.33079162893785,-2.1939725852970504
0.5854556231585529,0.0037456,153.1578152875698,424.33079162893785,-2.1939725852970504
0.5878314575968298,0.0037608,153.20020778125132,424.33079162893785,-2.1939725852970504
0.5925831264733836,0.0037911999999999998,153.28479283435436,424.33079162893785,-2.1939725852970504
0.5949589609116605,0.0038063999999999997,153.32698613681194,424.33079162893785,-2.1939725852970504
0.5977099271033496,0.0038239999999999997,153.37575953409214,424.33079162893785,-2.1939725852970504
0.598585234527978,0.0038296,153.39125997246646,424.33079162893785,-2.1939725852970504
0.6028367277333155,0.0038567999999999996,153.46642243705202,424.33079162893785,-2.1939725852970504
0.6037120351579439,0.0038623999999999998,153.48187136802784,424.33079162893785,-2.1939725852970504
0.6179670417876053,0.0039536,153.7322514548762,424.33079162893785,-2.1939725852970504
0.622218534992943,0.0039808,153.80648880290818,424.33079162893785,-2.1939725852970504
0.6225936667463552,0.0039832,153.8130296445819,424.33079162893785,-2.1939725852970504
0.624719413349024,0.0039968,153.85006542276045,424.33079162893785,-2.1939725852970504
0.6249695011846321,0.0039984,153.85441933954564,424.33079162893785,-2.1939725852970504
0.6762477131091096,0.004326465293058612,154.7333158175559,424.33079162893785,-2.1939725852970504
0.7212725284816414,0.0046145229045809165,155.4838030795509,424.33079162893785,-2.1939725852970504
0.7963138874358611,0.005094618923784757,156.69520199652627,424.33079162893785,-2.1939725852970504
0.8383370484502242,0.005363472694538908,157.35410152611507,424.33079162893785,-2.1939725852970504
0.8983701356135997,0.00574754950990198,158.2734592124729,424.33079162893785,-2.1939725852970504
0.9313883335534564,0.00595879175835167,158.76887846430031,424.33079162893785,-2.1939725852970504
0.964406531493313,0.00617003400680136,159.25749363774239,424.33079162893785,-2.1939725852970504
1.0274412730148577,0.006573314662932587,160.1725538898216,424.33079162893785,-2.1939725852970504
1.090476014536402,0.006976595319063813,161.06596333539912,424.33079162893785,-2.1939725852970504
1.1385024842671025,0.00728385677135427,161.73319691278934,424.33079162893785,-2.1939725852970504
1.2135438432213224,0.007763952790558111,162.75417649907044,424.33079162893785,-2.1939725852970504
1.2555670042356852,0.008032806561312262,163.31515931472882,424.33079162893785,-2.1939725852970504
1.2915868565337107,0.008263252650530106,163.79019753971468,424.33079162893785,-2.1939725852970504
1.3816364872787743,0.008839367873574715,164.9557264132085,424.33079162893785,-2.1939725852970504
1.459679500591163,0.00933866773354671,165.94207703988144,424.33079162893785,-2.1939725852970504
1.4896960441728508,0.009530706141228246,166.31593817413722,424.33079162893785,-2.1939725852970504
1.5467274769780577,0.009895579115823165,167.0182777064571,424.33079162893785,-2.1939725852970504
1.6067605641414335,0.010279655931186238,167.7467560384605,424.33079162893785,-2.1939725852970504
1.6307737990067839,0.010433286657331467,168.0351655101515,424.33079162893785,-2.1939725852970504
1.6637919969466402,0.010644528905781155,168.4290386075272,424.33079162893785,-2.1939725852970504
1.693808540528328,0.010836567313462692,168.78446755883462,424.33079162893785,-2.1939725852970504
1.7448366646171978,0.011163032606521305,169.38310995897976,424.33079162893785,-2.1939725852970504
1.7658482451243789,0.011297459491898379,169.6276205116098,424.33079162893785,-2.1939725852970504
1.807871406138742,0.01156631326265253,170.11326387518034,424.33079162893785,-2.1939725852970504
1.8528962215112739,0.011854370874174834,170.62873582312824,424.33079162893785,-2.1939725852970504
1.9519508153308438,0.012488097619523904,171.7458820318346,424.33079162893785,-2.1939725852970504
2.023990519926895,0.012948989797959592,172.5445081730031,424.33079162893785,-2.1939725852970504
2.1230451137464645,0.013582716543308662,173.6247465096696,424.33079162893785,-2.1939725852970504
2.1980864727006844,0.014062812562512503,174.43006895950163,424.33079162893785,-2.1939725852970504
2.288136103445748,0.014638927785557112,175.3824363840117,424.33079162893785,-2.1939725852970504
2.321154301385605,0.014850170034006802,175.72796052422996,424.33079162893785,-2.1939725852970504
2.3271576101019424,0.01488857771554311,175.79057660671052,424.33079162893785,-2.1939725852970504
2.35717415368363,0.015080616123224646,176.1027170288302,424.33079162893785,-2.1939725852970504
2.411203932130668,0.015426285257051411,176.6606910264697,424.33079162893785,-2.1939725852970504
2.4502254387868625,0.01567593518703741,177.06064398360022,424.33079162893785,-2.1939725852970504
2.5132601803084067,0.016079215843168633,177.70151372692698,424.33079162893785,-2.1939725852970504
2.525266797741082,0.016156031206241248,177.82287015880456,424.33079162893785,-2.1939725852970504
2.543276723890095,0.016271254250850173,178.00448372639974,424.33079162893785,-2.1939725852970504
2.6153164284861457,0.016732146429285857,178.72597765451317,424.33079162893785,-2.1939725852970504
2.639329663351496,0.016885777155431086,178.9647476971068,424.33079162893785,-2.1939725852970504
2.7293792940965593,0.017461892378475695,179.8526885409662,424.33079162893785,-2.1939725852970504
2.8434421597069734,0.018191638327665533,180.9611783913579,424.33079162893785,-2.1939725852970504
2.8854653207213365,0.018460492098419684,181.36518002919226,424.33079162893785,-2.1939725852970504
2.9304901360938684,0.01874854970994199,181.79550086710296,424.33079162893785,-2.1939725852970504
2.9875215688990755,0.019113422684536908,182.3368901564151,424.33079162893785,-2.1939725852970504
3.029544729913438,0.01938227645529106,182.73323285586835,424.33079162893785,-2.1939725852970504
3.119594360658502,0.019958391678335668,183.5753898713898,424.33079162893785,-2.1939725852970504
3.14961090424019,0.020150430086017204,183.85399493966787,424.33079162893785,-2.1939725852970504
3.27267873292511,0.0209377875575115,184.9856138469139,424.33079162893785,-2.1939725852970504
3.3086985852231354,0.021168233646729345,185.3136637073776,424.33079162893785,-2.1939725852970504
3.401749870326368,0.02176355271054211,186.15474334887043,424.33079162893785,-2.1939725852970504
3.4917995010714318,0.02233966793358672,186.96018893819974,424.33079162893785,-2.1939725852970504
3.5938557492491703,0.022992598519703943,187.8632972406488,424.33079162893785,-2.1939725852970504
3.6058623666818455,0.023069413882776557,187.9688836551104,424.33079162893785,-2.1939725852970504
3.623872292830858,0.02318463692738548,188.12700655053612,424.33079162893785,-2.1939725852970504
3.7109202692177528,0.023741548309661933,188.88698845709996,424.33079162893785,-2.1939725852970504
3.8009698999628165,0.024317663532706542,189.66589558526988,424.33079162893785,-2.1939725852970504
3.9120311112150614,0.025028205641128225,190.6167055464461,424.33079162893785,-2.1939725852970504
4.071118792198007,0.02604600920184037,191.96053596542075,424.33079162893785,-2.1939725852970504
4.155165114226733,0.02658371674334867,192.66220719694545,424.33079162893785,-2.1939725852970504
4.272229634195316,0.02733266653330666,193.63037973882984,424.33079162893785,-2.1939725852970504
4.335264375716861,0.02773594718943789,194.14741535290153,424.33079162893785,-2.1939725852970504
4.413307389029249,0.028235247049409884,194.78351032504008,424.33079162893785,-2.1939725852970504
4.4253140064619245,0.0283120624124825,194.88098035076604,424.33079162893785,-2.1939725852970504
4.482345439267131,0.028676935387077416,195.3425618438675,424.33079162893785,-2.1939725852970504
4.530371908997831,0.028984196839367874,195.72948822191893,424.33079162893785,-2.1939725852970504
4.593406650519376,0.0293874774954991,196.2349100622288,424.33079162893785,-2.1939725852970504
4.647436428966414,0.029733146629325864,196.66597957477217,424.33079162893785,-2.1939725852970504
4.695462898697115,0.030040408081616322,197.047514371508,424.33079162893785,-2.1939725852970504
4.836540653531048,0.030942988597719545,198.15956766787474,424.33079162893785,-2.1939725852970504
4.845545616605554,0.031000600120024004,198.23011723982168,424.33079162893785,-2.1939725852970504
4.881565468903579,0.031231046209241848,198.511805700618,424.33079162893785,-2.1939725852970504
4.902577049410762,0.03136547309461893,198.67574962425124,424.33079162893785,-2.1939725852970504
4.989625025797657,0.03192238447689538,199.35204708765775,424.33079162893785,-2.1939725852970504
4.998629988872163,0.031979995999199845,199.42174524847368,424.33079162893785,-2.1939725852970504
5.031648186812019,0.03219123824764953,199.67688729407539,424.33079162893785,-2.1939725852970504
5.064666384751876,0.03240248049609922,199.9313772041654,424.33079162893785,-2.1939725852970504
5.151714361138771,0.032959391878375675,200.59922265717904,424.33079162893785,-2.1939725852970504
5.1967391765113025,0.03324744948989798,200.94293217524313,424.33079162893785,-2.1939725852970504
5.307800387763548,0.033957991598319665,201.78582053494787,424.33079162893785,-2.1939725852970504
5.349823548777911,0.03422684536907382,202.10295400316892,424.33079162893785,-2.1939725852970504
5.424864907732129,0.03470694138827765,202.66685784662792,424.33079162893785,-2.1939725852970504
5.505909575402687,0.0352254450890178,203.27246785115423,424.33079162893785,-2.1939725852970504
5.571945971282401,0.035647929585917185,203.76336141401043,424.33079162893785,-2.1939725852970504
5.619972441013101,0.03595519103820764,204.11895090746808,424.33079162893785,-2.1939725852970504
5.740038615339853,0.03672334466893379,205.00277868103294,424.33079162893785,-2.1939725852970504
5.749043578414359,0.03678095619123825,205.06877367321292,424.33079162893785,-2.1939725852970504
5.79406839378689,0.03706901380276055,205.39814584684805,424.33079162893785,-2.1939725852970504
5.8060750112195665,0.03714582916583317,205.48580964998231,424.33079162893785,-2.1939725852970504
5.830088246084917,0.0372994598919784,205.66092544249435,424.33079162893785,-2.1939725852970504
5.890121333248292,0.03768353670734147,206.0974887307572,424.33079162893785,-2.1939725852970504
5.929142839904485,0.03793318663732746,206.38032460443048,424.33079162893785,-2.1939725852970504
6.0552123229475745,0.03873974794958991,207.2891802203066,424.33079162893785,-2.1939725852970504
6.157268571125314,0.039392678535707146,208.01952700473922,424.33079162893785,-2.1939725852970504
6.187285114707002,0.03958471694338868,208.23343440668623,424.33079162893785,-2.1939725852970504
6.202293386497845,0.039680736147229445,208.34023631155966,424.33079162893785,-2.1939725852970504
6.217301658288689,0.03977675535107021,208.44693747280618,424.33079162893785,-2.1939725852970504
6.295344671601077,0.0402760552110422,209.00017251722622,424.33079162893785,-2.1939725852970504
6.391397611062478,0.04089057811562312,209.67741885584536,424.33079162893785,-2.1939725852970504
6.466438970016699,0.041370674134826965,210.20375942731363,424.33079162893785,-2.1939725852970504
6.553486946403593,0.04192758551710342,210.811339352218,424.33079162893785,-2.1939725852970504
6.676554775088515,0.04271494298859772,211.6649884052364,424.33079162893785,-2.1939725852970504
6.80862756684794,0.043559911982396476,212.57430111933027,424.33079162893785,-2.1939725852970504
6.886670580160328,0.04405921184236847,213.10838900181042,424.33079162893785,-2.1939725852970504
6.955708630398211,0.04450090018003601,213.57888681215826,424.33079162893785,-2.1939725852970504
6.991728482696236,0.04473134626925385,213.82364074060723,424.33079162893785,-2.1939725852970504
7.066769841650457,0.04521144228845769,214.3319709578635,424.33079162893785,-2.1939725852970504
7.1027896939484805,0.04544188837767553,214.5752213265074,424.33079162893785,-2.1939725852970504
7.207847596484388,0.04611402280456091,215.28196860235906,424.33079162893785,-2.1939725852970504
7.2888922641549465,0.04663252650530106,215.82443212498035,424.33079162893785,-2.1939725852970504
7.300898881587623,0.04670934186837368,215.90459658338196,424.33079162893785,-2.1939725852970504
7.435973327705217,0.04757351470294059,216.80293241091832,424.33079162893785,-2.1939725852970504
7.474994834361412,0.04782316463292659,217.06126388756147,424.33079162893785,-2.1939725852970504
7.496006414868592,0.04795759151830366,217.2001475853951,424.33079162893785,-2.1939725852970504
7.526022958450282,0.048149629925985205,217.39828978694732,424.33079162893785,-2.1939725852970504
7.616072589195344,0.0487257451490298,217.9908753865395,424.33079162893785,-2.1939725852970504
7.685110639433227,0.049167433486697346,218.4433423372729,424.33079162893785,-2.1939725852970504
7.703120565582238,0.04928265653130626,218.56111613896357,424.33079162893785,-2.1939725852970504
7.7241321460894214,0.04941708341668334,218.6983832663999,424.33079162893785,-2.1939725852970504
7.835193357341666,0.050127625525105024,219.4215331298349,424.33079162893785,-2.1939725852970504
7.859206592207016,0.05028125625125025,219.57736296949724,424.33079162893785,-2.1939725852970504
7.895226444505041,0.05051170234046809,219.8107600136415,424.33079162893785,-2.1939725852970504
7.904231407579547,0.05056931386277255,219.86904434244693,424.33079162893785,-2.1939725852970504
7.949256222952081,0.050857371474294866,220.16007844449229,424.33079162893785,-2.1939725852970504
8.009289310115456,0.05124144828965793,220.5471258363631,424.33079162893785,-2.1939725852970504
8.102340595218687,0.05183676735347069,221.14482079214002,424.33079162893785,-2.1939725852970504
8.108343903935026,0.05187517503500701,221.18328957604098,424.33079162893785,-2.1939725852970504
8.117348867009532,0.05193278655731147,221.240971931172,424.33079162893785,-2.1939725852970504
8.126353830084037,0.05199039807961592,221.29862933567526,424.33079162893785,-2.1939725852970504
8.17137864545657,0.05227845569113823,221.58654344002275,424.33079162893785,-2.1939725852970504
8.204396843396427,0.05248969793958792,221.79728738105072,424.33079162893785,-2.1939725852970504
8.222406769545438,0.052604920984196835,221.91209919704525,424.33079162893785,-2.1939725852970504
8.249421658768957,0.05277775555111022,222.08413319937142,424.33079162893785,-2.1939725852970504
8.333467980797684,0.05331546309261852,222.61795037273683,424.33079162893785,-2.1939725852970504
8.375491141812047,0.05358431686337267,222.88407128487614,424.33079162893785,-2.1939725852970504
8.486552353064292,0.054294858971794355,223.58489603428322,424.33079162893785,-2.1939725852970504
8.759702899657652,0.05604240848169634,225.29349934906708,424.33079162893785,-2.1939725852970504
8.798724406313845,0.05629205841168233,225.53587843359475,424.33079162893785,-2.1939725852970504
8.849752530402716,0.05661852370474095,225.8522040865329,424.33079162893785,-2.1939725852970504
8.91578892628243,0.057041008201640334,226.26051276632185,424.33079162893785,-2.1939725852970504
8.936800506789611,0.057175435087017404,226.39018159975086,424.33079162893785,-2.1939725852970504
8.981825322162141,0.0574634926985397,226.66764369251192,424.33079162893785,-2.1939725852970504
9.044860063683688,0.05786677335467094,227.05518104299256,424.33079162893785,-2.1939725852970504
9.146916311861427,0.05851970394078816,227.68039669762604,424.33079162893785,-2.1939725852970504
9.1589229292941,0.05859651930386077,227.75377219043685,424.33079162893785,-2.1939725852970504
9.200946090308463,0.058865373074614924,228.0102915161803,424.33079162893785,-2.1939725852970504
9.212952707741138,0.05894218843768753,228.08349877558578,424.33079162893785,-2.1939725852970504
9.230962633890151,0.05905741148229646,228.19323993774606,424.33079162893785,-2.1939725852970504
9.25797752311367,0.059230246049209845,228.35769524398378,424.33079162893785,-2.1939725852970504
9.266982486188178,0.05928785757151431,228.41247207571723,424.33079162893785,-2.1939725852970504
9.28499241233719,0.05940308061612322,228.52196350216184,424.33079162893785,-2.1939725852970504
9.444080093320137,0.060420884176835374,229.48556693657707,424.33079162893785,-2.1939725852970504
9.513118143558017,0.0608625725145029,229.90176247608386,424.33079162893785,-2.1939725852970504
9.6301826635266,0.06161152230446089,230.60480322402935,424.33079162893785,-2.1939725852970504
9.663200861466457,0.06182276455291058,230.80249313651615,424.33079162893785,-2.1939725852970504
9.675207478899132,0.0618995799159832,230.8743150393917,424.33079162893785,-2.1939725852970504
9.867313357821935,0.06312862572514504,232.0187795298825,424.33079162893785,-2.1939725852970504
9.903333210119959,0.06335907181436287,232.23239574708603,424.33079162893785,-2.1939725852970504
9.942354716776153,0.06360872174434887,232.4634716648423,424.33079162893785,-2.1939725852970504
10.032404347521217,0.06418483696739348,232.99537808458436,424.33079162893785,-2.1939725852970504
10.1494688674898,0.06493378675735147,233.6840810241545,424.33079162893785,-2.1939725852970504
10.17948541107149,0.06512582516503301,233.86017163679205,424.33079162893785,-2.1939725852970504
10.281541659249227,0.06577875575115023,234.45737078509563,424.33079162893785,-2.1939725852970504
10.39860617921781,0.06652770554110822,235.13955384268473,424.33079162893785,-2.1939725852970504
10.404609487934149,0.06656611322264454,235.17445662906417,424.33079162893785,-2.1939725852970504
10.431624377157666,0.06673894778955791,235.33142207653054,424.33079162893785,-2.1939725852970504
10.485654155604706,0.06708461692338469,235.644878180283,424.33079162893785,-2.1939725852970504
10.566698823275262,0.06760312062412482,236.1138838350305,424.33079162893785,-2.1939725852970504
10.674758380169338,0.06829445889177836,236.7370482143856,424.33079162893785,-2.1939725852970504
10.686764997602014,0.06837127425485097,236.80613650090444,424.33079162893785,-2.1939725852970504
10.734791467332713,0.06867853570714143,237.08218746297553,424.33079162893785,-2.1939725852970504
10.815836135003272,0.06919703940788158,237.54693375507892,424.33079162893785,-2.1939725852970504
10.821839443719607,0.06923544708941788,237.58130528367738,424.33079162893785,-2.1939725852970504
10.866864259092141,0.0695235047009402,237.83885513881214,424.33079162893785,-2.1939725852970504
10.917892383181009,0.0698499699939988,238.130242400908,424.33079162893785,-2.1939725852970504
10.99293374213523,0.07033006601320264,238.55779006653867,424.33079162893785,-2.1939725852970504
11.049965174940438,0.07069493898779756,238.88196546340149,424.33079162893785,-2.1939725852970504
11.0919883359548,0.07096379275855172,239.12041415659377,424.33079162893785,-2.1939725852970504
11.185039621058031,0.07155911182236448,239.64715747464135,424.33079162893785,-2.1939725852970504
11.221059473356059,0.07178955791158233,239.85059894834222,424.33079162893785,-2.1939725852970504
11.23906939950507,0.07190478095619124,239.9522241650333,424.33079162893785,-2.1939725852970504
11.299102486668447,0.07228885777155432,240.29051713306453,424.33079162893785,-2.1939725852970504
11.344127302040977,0.07257691538307662,240.5437770339054,424.33079162893785,-2.1939725852970504
11.356133919473654,0.07265373074614924,240.61124676092842,424.33079162893785,-2.1939725852970504
11.41016369792069,0.072999399879976,240.91451691418155,424.33079162893785,-2.1939725852970504
11.491208365591248,0.07351790358071615,241.36837413948618,424.33079162893785,-2.1939725852970504
11.53623318096378,0.07380596119223845,241.6199775795024,424.33079162893785,-2.1939725852970504
11.599267922485325,0.07420924184836968,241.97157995049142,424.33079162893785,-2.1939725852970504
11.668305972723207,0.07465093018603722,242.35581434322313,424.33079162893785,-2.1939725852970504
11.722335751170245,0.07499659931986398,242.65590140081017,424.33079162893785,-2.1939725852970504
11.770362220900946,0.07530386077215444,242.9221928993161,424.33079162893785,-2.1939725852970504
11.857410197287841,0.07586077215443089,243.40376867268847,424.33079162893785,-2.1939725852970504
11.992484643405435,0.0767249449889978,244.14832067137854,424.33079162893785,-2.1939725852970504
12.112550817732187,0.07749309861972395,244.8074033784434,424.33079162893785,-2.1939725852970504
12.169582250537394,0.07785797159431887,245.1195746518573,424.33079162893785,-2.1939725852970504
12.20560210283542,0.0780884176835367,245.31644151952864,424.33079162893785,-2.1939725852970504
12.292650079222314,0.07864532906581316,245.79127003038056,424.33079162893785,-2.1939725852970504
12.349681512027521,0.07901020204040808,246.1016537220908,424.33079162893785,-2.1939725852970504
12.439731142772585,0.0795863172634527,246.59059750038674,424.33079162893785,-2.1939725852970504
12.481754303786948,0.07985517103420685,246.8182986905671,424.33079162893785,-2.1939725852970504
12.50276588429413,0.07998959791958392,246.93203715395495,424.33079162893785,-2.1939725852970504
12.547790699666661,0.08027765553110623,247.17551171519287,424.33079162893785,-2.1939725852970504
12.571803934532012,0.08043128625725146,247.30522548540145,424.33079162893785,-2.1939725852970504
12.6498469478444,0.08093058611722345,247.7261294717372,424.33079162893785,-2.1939725852970504
12.685866800142424,0.08116103220644129,247.92005116002449,424.33079162893785,-2.1939725852970504
12.706878380649608,0.08129545909181837,248.0330729772262,424.33079162893785,-2.1939725852970504
12.748901541663969,0.08156431286257251,248.25889818982108,424.33079162893785,-2.1939725852970504
12.757906504738475,0.08162192438487698,248.30725151657626,424.33079162893785,-2.1939725852970504
12.793926357036502,0.08185237047409483,248.50053186752524,424.33079162893785,-2.1939725852970504
12.85095778984171,0.08221724344868975,248.80612563312016,424.33079162893785,-2.1939725852970504
12.859962752916216,0.08227485497099421,248.85432888854038,424.33079162893785,-2.1939725852970504
12.953014038019449,0.08287017403480697,249.3516608064391,424.33079162893785,-2.1939725852970504
13.013047125182823,0.08325425085017003,249.67178081510832,424.33079162893785,-2.1939725852970504
13.208154658463794,0.08450250050010003,250.70821565198466,424.33079162893785,-2.1939725852970504
13.2171596215383,0.08456011202240449,250.75590642704492,424.33079162893785,-2.1939725852970504
13.310210906641533,0.08515543108621725,251.24797136596223,424.33079162893785,-2.1939725852970504
13.382250611237584,0.08561632326465293,251.62800404897794,424.33079162893785,-2.1939725852970504
13.41526880917744,0.08582756551310262,251.80191896727007,424.33079162893785,-2.1939725852970504
13.547341600936868,0.08667253450690139,252.49591573358262,424.33079162893785,-2.1939725852970504
13.61637965117475,0.08711422284456892,252.85763634826125,424.33079162893785,-2.1939725852970504
13.63739123168193,0.08724864972994599,252.96758316838435,424.33079162893785,-2.1939725852970504
13.652399503472774,0.08734466893378676,253.04607616695515,424.33079162893785,-2.1939725852970504
13.70943093627798,0.08770954190838168,253.34404315303453,424.33079162893785,-2.1939725852970504
13.748452442934175,0.08795919183836767,253.54763681961495,424.33079162893785,-2.1939725852970504
13.790475603948538,0.08822804560912183,253.76663967080742,424.33079162893785,-2.1939725852970504
13.86251530854459,0.08868893778755751,254.14146857120326,424.33079162893785,-2.1939725852970504
13.874521925977266,0.08876575315063014,254.20386612378442,424.33079162893785,-2.1939725852970504
14.069629459258236,0.09001400280056011,255.2148932144057,424.33079162893785,-2.1939725852970504
14.10865096591443,0.09026365273054611,255.41644087510932,424.33079162893785,-2.1939725852970504
14.1596790900033,0.09059011802360473,255.6796754753701,424.33079162893785,-2.1939725852970504
14.312763462269908,0.09156951390278056,256.46716838394195,424.33079162893785,-2.1939725852970504
14.360789932000609,0.09187677535507102,256.71354715543225,424.33079162893785,-2.1939725852970504
14.387804821224126,0.0920496099219844,256.85199399493507,424.33079162893785,-2.1939725852970504
14.420823019163983,0.09226085217043409,257.021069197825,424.33079162893785,-2.1939725852970504
14.537887539132567,0.09300980196039209,257.619304912015,424.33079162893785,-2.1939725852970504
14.594918971937773,0.093374674934987,257.9100722556701,424.33079162893785,-2.1939725852970504
14.636942132952136,0.09364352870574115,258.1240384089699,424.33079162893785,-2.1939725852970504
14.70598018319002,0.09408521704340869,258.4750348601319,424.33079162893785,-2.1939725852970504
14.778019887786071,0.09454610922184438,258.84060756549974,424.33079162893785,-2.1939725852970504
14.811038085725926,0.09475735147029406,259.00792938325094,424.33079162893785,-2.1939725852970504
14.904089370829158,0.09535267053410683,259.47869181736326,424.33079162893785,-2.1939725852970504
15.009147273365066,0.09602480496099221,260.00882230838357,424.33079162893785,-2.1939725852970504
15.027157199514079,0.09614002800560112,260.09955632034223,424.33079162893785,-2.1939725852970504
15.063177051812104,0.09637047409481897,260.28089721403234,424.33079162893785,-2.1939725852970504
15.114205175900976,0.09669693938787759,260.5375075869766,424.33079162893785,-2.1939725852970504
15.135216756408155,0.09683136627325466,260.64307244841325,424.33079162893785,-2.1939725852970504
15.156228336915337,0.09696579315863173,260.7485801703191,424.33079162893785,-2.1939725852970504
15.186244880497025,0.09715783156631327,260.8992065858871,424.33079162893785,-2.1939725852970504
15.1982514979297,0.09723464692938588,260.95942463548784,424.33079162893785,-2.1939725852970504
15.26728954816758,0.09767633526705341,261.3053190526843,424.33079162893785,-2.1939725852970504
15.309312709181945,0.09794518903780756,261.5155648370717,424.33079162893785,-2.1939725852970504
15.432380537866866,0.09873254650930187,262.1299937354869,424.33079162893785,-2.1939725852970504
15.459395427090383,0.09890538107621524,262.2646122524198,424.33079162893785,-2.1939725852970504
15.627488071147836,0.09998079615923185,263.10018651816284,424.33079162893785,-2.1939725852970504
15.630489725506004,0.1,263.1150755425728,424.33079162893785,-2.1939725852970504