File: datasets/aisi_316_L/data/M1/valid_19.csv
Time(s),Strain(%),Stress(MPa),Temp(C),Log_SR(s-1)
0.0,0.0,0.0,323.28339714630687,5.8654917660789145
6.542586471507216e-12,4.8e-06,0.84345465,323.28339714630687,5.8654917660789145
4.57981053005505e-11,3.36e-05,5.90418255,323.28339714630687,5.8654917660789145
5.452155392922679e-11,3.9999999999999996e-05,7.0287887499999995,323.28339714630687,5.8654917660789145
7.633017550091751e-11,5.6e-05,9.840304249999999,323.28339714630687,5.8654917660789145
8.614405520817832e-11,6.319999999999999e-05,11.105486224999998,323.28339714630687,5.8654917660789145
1.1667612540854534e-10,8.56e-05,15.041607925,323.28339714630687,5.8654917660789145
1.2103784972288347e-10,8.879999999999999e-05,15.603911024999999,323.28339714630687,5.8654917660789145
1.2539957403722163e-10,9.2e-05,16.166214125,323.28339714630687,5.8654917660789145
1.5375078208041954e-10,0.00011279999999999999,19.821184274999997,323.28339714630687,5.8654917660789145
1.8646371443795564e-10,0.0001368,24.038457525,323.28339714630687,5.8654917660789145
1.951871630666319e-10,0.00014319999999999998,25.163063724999997,323.28339714630687,5.8654917660789145
2.2244794003124532e-10,0.00016319999999999998,28.677458099999996,323.28339714630687,5.8654917660789145
2.4207569944576695e-10,0.00017759999999999998,31.207822049999997,323.28339714630687,5.8654917660789145
2.540704413101969e-10,0.0001864,32.754155575,323.28339714630687,5.8654917660789145
2.638843210174577e-10,0.0001936,34.019337549999996,323.28339714630687,5.8654917660789145
2.7587906288188757e-10,0.0002024,35.565671075,323.28339714630687,5.8654917660789145
2.8896423582490204e-10,0.000212,37.252580375,323.28339714630687,5.8654917660789145
2.9441639121782467e-10,0.000216,37.95545925,323.28339714630687,5.8654917660789145
3.227675992610226e-10,0.00023679999999999998,41.610429399999994,323.28339714630687,5.8654917660789145
3.445762208327133e-10,0.00025279999999999996,44.42194489999999,323.28339714630687,5.8654917660789145
3.6529441132581955e-10,0.000268,47.092884625,323.28339714630687,5.8654917660789145
3.849221707403412e-10,0.0002824,49.623248575,323.28339714630687,5.8654917660789145
3.9691691260477107e-10,0.0002912,51.16958209999999,323.28339714630687,5.8654917660789145
4.0782122339061643e-10,0.0002992,52.57533985,323.28339714630687,5.8654917660789145
4.263585517265535e-10,0.00031279999999999996,54.96512802499999,323.28339714630687,5.8654917660789145
4.427150179053216e-10,0.0003248,57.073764649999994,323.28339714630687,5.8654917660789145
4.6343320839842774e-10,0.00033999999999999997,59.744704375,323.28339714630687,5.8654917660789145
4.667045016341814e-10,0.0003424,60.1664317,323.28339714630687,5.8654917660789145
5.103217447775628e-10,0.0003744,65.7894627,323.28339714630687,5.8654917660789145
5.146834690919009e-10,0.00037759999999999996,66.3517658,323.28339714630687,5.8654917660789145
5.855614891998958e-10,0.0004296,75.489191175,323.28339714630687,5.8654917660789145
7.087802010799483e-10,0.00052,91.37425375,323.28339714630687,5.8654917660789145
7.305888226516391e-10,0.000536,94.18576925,323.28339714630687,5.8654917660789145
7.491261509875762e-10,0.0005496,96.575557425,323.28339714630687,5.8654917660789145
7.905625319737885e-10,0.00058,101.917436875,323.28339714630687,5.8654917660789145
8.134615846240638e-10,0.0005968,104.86952815,323.28339714630687,5.8654917660789145
8.189137400169864e-10,0.0006008,105.57240702499999,323.28339714630687,5.8654917660789145
8.494458102173534e-10,0.0006232,109.50852872499999,323.28339714630687,5.8654917660789145
8.52717103453107e-10,0.0006255999999999999,109.93025604999998,323.28339714630687,5.8654917660789145
8.963343465964884e-10,0.0006575999999999999,115.55328705,323.28339714630687,5.8654917660789145
9.050577952251648e-10,0.000664,116.67789325,323.28339714630687,5.8654917660789145
9.105099506180874e-10,0.000668,117.380772125,323.28339714630687,5.8654917660789145
9.235951235611019e-10,0.0006776,119.067681425,323.28339714630687,5.8654917660789145
9.410420208184545e-10,0.0006904,121.316893825,323.28339714630687,5.8654917660789145
9.519463316042998e-10,0.0006984,122.72265157499999,323.28339714630687,5.8654917660789145
1.0010157301406039e-09,0.0007344,129.04856145,323.28339714630687,5.8654917660789145
1.0206434895551257e-09,0.0007488,131.5789254,323.28339714630687,5.8654917660789145
1.0293669381838019e-09,0.0007551999999999999,132.7035316,323.28339714630687,5.8654917660789145
1.0773459056415214e-09,0.0007903999999999999,138.8888657,323.28339714630687,5.8654917660789145
1.094792802898874e-09,0.0008032,141.1380781,323.28339714630687,5.8654917660789145
1.1013353893703813e-09,0.000808,141.98153275,323.28339714630687,5.8654917660789145
1.1198727177063182e-09,0.0008215999999999999,144.371320925,323.28339714630687,5.8654917660789145
1.1580378054567771e-09,0.0008495999999999999,149.29147304999998,323.28339714630687,5.8654917660789145
1.1613090986925307e-09,0.000852,149.713200375,323.28339714630687,5.8654917660789145
1.1798464270284678e-09,0.0008656,152.10298855,323.28339714630687,5.8654917660789145
1.2256445323290182e-09,0.0008992,158.0071711,323.28339714630687,5.8654917660789145
1.2583574646865546e-09,0.0009232,162.22444435,323.28339714630687,5.8654917660789145
1.2834373794939987e-09,0.0009416,165.457687175,323.28339714630687,5.8654917660789145
1.289979965965506e-09,0.0009463999999999999,166.30114182499997,323.28339714630687,5.8654917660789145
1.3063364321442741e-09,0.0009584,168.40977845,323.28339714630687,5.8654917660789145
1.3259641915587957e-09,0.0009728,170.9401424,323.28339714630687,5.8654917660789145
1.3586771239163316e-09,0.0009968,175.15741565,323.28339714630687,5.8654917660789145
1.4350072994172494e-09,0.0010528,184.9977199,323.28339714630687,5.8654917660789145
1.4557254899103554e-09,0.001068,187.66865962499998,323.28339714630687,5.8654917660789145
1.4742628182462927e-09,0.0010816,190.0584478,323.28339714630687,5.8654917660789145
1.4808054047177998e-09,0.0010864,190.90190245,323.28339714630687,5.8654917660789145
1.5026140262894903e-09,0.0011024,193.71341794999998,323.28339714630687,5.8654917660789145
1.5124279059967512e-09,0.0011095999999999999,194.97859992499997,323.28339714630687,5.8654917660789145
1.5266035100183502e-09,0.00112,196.806085,323.28339714630687,5.8654917660789145
1.5516834248257945e-09,0.0011384,199.42016212307624,323.28339714630687,5.8654917660789145
1.5636781666902244e-09,0.0011472,199.47409046331364,323.28339714630687,5.8654917660789145
1.5745824774760697e-09,0.0011551999999999999,199.52297638940448,323.28339714630687,5.8654917660789145
1.6007528233620986e-09,0.0011744,199.63976703351412,323.28339714630687,5.8654917660789145
1.6094762719907748e-09,0.0011807999999999999,199.6785314555861,323.28339714630687,5.8654917660789145
1.6367370489553883e-09,0.0012008,199.79914548084582,323.28339714630687,5.8654917660789145
1.6509126529769873e-09,0.0012112,199.86155499611175,323.28339714630687,5.8654917660789145
1.686896878570277e-09,0.0012376,200.01904775218782,323.28339714630687,5.8654917660789145
1.6978011893561224e-09,0.0012456,200.06651343365033,323.28339714630687,5.8654917660789145
1.7185193798492285e-09,0.0012607999999999999,200.1563719556749,323.28339714630687,5.8654917660789145
1.7566844675996871e-09,0.0012887999999999999,200.32080252226814,323.28339714630687,5.8654917660789145
1.7654079162283638e-09,0.0012952,200.3581903320997,323.28339714630687,5.8654917660789145
1.7763122270142091e-09,0.0013032,200.40482392799277,323.28339714630687,5.8654917660789145
1.7795835202499625e-09,0.0013055999999999999,200.418792218458,323.28339714630687,5.8654917660789145
1.8003017107430688e-09,0.0013208,200.50702664186252,323.28339714630687,5.8654917660789145
1.8199294701575904e-09,0.0013352,200.5902525584646,323.28339714630687,5.8654917660789145
1.8635467133009716e-09,0.0013671999999999998,200.7739558817231,323.28339714630687,5.8654917660789145
1.8689988686938944e-09,0.0013712,200.79680030394664,323.28339714630687,5.8654917660789145
1.8733605930082327e-09,0.0013744,200.81505713458517,323.28339714630687,5.8654917660789145
1.8973500767370924e-09,0.001392,200.9151749361098,323.28339714630687,5.8654917660789145
1.9137065429158604e-09,0.0014039999999999999,200.98315418514707,323.28339714630687,5.8654917660789145
1.959504648216411e-09,0.0014376,201.1723010314458,323.28339714630687,5.8654917660789145
1.9889462873381932e-09,0.0014592,201.29298556110615,323.28339714630687,5.8654917660789145
1.996579304888285e-09,0.0014647999999999998,201.3241601608557,323.28339714630687,5.8654917660789145
2.0085740467527154e-09,0.0014736,201.37305507142042,323.28339714630687,5.8654917660789145
2.0314730994029906e-09,0.0014904,201.46608483849562,323.28339714630687,5.8654917660789145
2.040196548031667e-09,0.0014968,201.50141706174074,323.28339714630687,5.8654917660789145
2.07945206686071e-09,0.0015256,201.65968854880185,323.28339714630687,5.8654917660789145
2.0947181019608935e-09,0.0015367999999999998,201.72092334675617,323.28339714630687,5.8654917660789145
2.120888447846922e-09,0.0015559999999999999,201.82549390190044,323.28339714630687,5.8654917660789145
2.1448779315757818e-09,0.0015735999999999999,201.92090901136322,323.28339714630687,5.8654917660789145
2.1557822423616274e-09,0.0015815999999999998,201.9641418388436,323.28339714630687,5.8654917660789145
2.18522388148341e-09,0.0016032,202.0804465751287,323.28339714630687,5.8654917660789145
2.2092133652122695e-09,0.0016208,202.17476220365202,323.28339714630687,5.8654917660789145
2.2266602624696223e-09,0.0016336,202.2431046943688,323.28339714630687,5.8654917660789145
2.2332028489411296e-09,0.0016384,202.26867924583988,323.28339714630687,5.8654917660789145
2.241926297569806e-09,0.0016447999999999999,202.30273323942004,323.28339714630687,5.8654917660789145
2.2637349191414965e-09,0.0016607999999999998,202.3876429135243,323.28339714630687,5.8654917660789145
2.2888148339489407e-09,0.0016791999999999998,202.48489563892517,323.28339714630687,5.8654917660789145
2.3291607838565687e-09,0.0017088,202.64047811127944,323.28339714630687,5.8654917660789145
2.3346129392494915e-09,0.0017128,202.66142186543792,323.28339714630687,5.8654917660789145
2.358602422978351e-09,0.0017304,202.7533486997704,323.28339714630687,5.8654917660789145
2.3760493202357036e-09,0.0017431999999999999,202.81997570103454,323.28339714630687,5.8654917660789145
2.4011292350431478e-09,0.0017615999999999999,202.91541871159257,323.28339714630687,5.8654917660789145
2.4371134606364375e-09,0.0017879999999999999,203.05168236045492,323.28339714630687,5.8654917660789145
2.4687359619153893e-09,0.0018112,203.17078274726487,323.28339714630687,5.8654917660789145
2.4774594105440655e-09,0.0018176,203.2035331316958,323.28339714630687,5.8654917660789145
2.4861828591727417e-09,0.0018239999999999999,203.23623857276232,323.28339714630687,5.8654917660789145
2.5003584631943407e-09,0.0018344,203.2892896225092,323.28339714630687,5.8654917660789145
2.5188957915302776e-09,0.0018479999999999998,203.35848741776886,323.28339714630687,5.8654917660789145
2.5875929494811037e-09,0.0018984,203.61321267580405,323.28339714630687,5.8654917660789145
2.6126728642885482e-09,0.0019168,203.70554863690242,323.28339714630687,5.8654917660789145
2.636662348017408e-09,0.0019344,203.79354706365677,323.28339714630687,5.8654917660789145
2.7129925235183253e-09,0.0019904,204.07148707302775,323.28339714630687,5.8654917660789145
2.765333215290383e-09,0.0020288,204.26031413868026,323.28339714630687,5.8654917660789145
2.814402613826687e-09,0.0020648,204.43607748682012,323.28339714630687,5.8654917660789145
2.8373016664769624e-09,0.0020816,204.51769099536878,323.28339714630687,5.8654917660789145
2.8492964083413925e-09,0.0020904,204.56033838547745,323.28339714630687,5.8654917660789145
2.8602007191272376e-09,0.0020984,204.59904801950603,323.28339714630687,5.8654917660789145
2.876557185306005e-09,0.0021103999999999997,204.65700472914074,323.28339714630687,5.8654917660789145
2.879828478541759e-09,0.0021127999999999997,204.66858063270834,323.28339714630687,5.8654917660789145
2.8852806339346818e-09,0.0021168,204.68786241564092,323.28339714630687,5.8654917660789145
2.905998824427788e-09,0.0021319999999999998,204.7610039600941,323.28339714630687,5.8654917660789145
2.9190839973708025e-09,0.0021416,204.80709385421594,323.28339714630687,5.8654917660789145
2.9452543432568316e-09,0.0021608,204.89903262501358,323.28339714630687,5.8654917660789145
2.960520378357015e-09,0.002172,204.95251644312737,323.28339714630687,5.8654917660789145
2.9703342580642757e-09,0.0021792,204.9868421085462,323.28339714630687,5.8654917660789145
2.988871586400213e-09,0.0021928,205.05155904002984,323.28339714630687,5.8654917660789145
2.9932333107145514e-09,0.002196,205.066763781144,323.28339714630687,5.8654917660789145
3.0128610701290727e-09,0.0022104,205.13507846641951,323.28339714630687,5.8654917660789145
3.0215845187577494e-09,0.0022168,205.16538481259474,323.28339714630687,5.8654917660789145
3.0684730551368842e-09,0.0022512,205.32770051050434,323.28339714630687,5.8654917660789145
3.08919124562999e-09,0.0022664,205.3991129532689,323.28339714630687,5.8654917660789145
3.1077285739659274e-09,0.00228,205.46285012198828,323.28339714630687,5.8654917660789145
3.1262659023018643e-09,0.0022936,205.52643918920836,323.28339714630687,5.8654917660789145
3.1328084887733715e-09,0.0022984,205.54884725837104,323.28339714630687,5.8654917660789145
3.162250127895154e-09,0.00232,205.64945856660077,323.28339714630687,5.8654917660789145
3.1840587494668447e-09,0.002336,205.7237500920733,323.28339714630687,5.8654917660789145
3.2058673710385355e-09,0.002352,205.79784343054837,323.28339714630687,5.8654917660789145
3.2549367695748397e-09,0.002388,205.9638384661933,323.28339714630687,5.8654917660789145
3.268021942517854e-09,0.0023975999999999997,206.00793861811738,323.28339714630687,5.8654917660789145
3.2756549600679456e-09,0.0024032,206.03363190463958,323.28339714630687,5.8654917660789145
3.2832879776180377e-09,0.0024088,206.05930185198557,323.28339714630687,5.8654917660789145
3.3094583235040668e-09,0.002428,206.14713694496328,323.28339714630687,5.8654917660789145
3.322543496447081e-09,0.0024376,206.19095287936065,323.28339714630687,5.8654917660789145
3.3356286693900954e-09,0.0024472,206.2347015666929,323.28339714630687,5.8654917660789145
3.3541659977260323e-09,0.0024608,206.29656447347654,323.28339714630687,5.8654917660789145
3.3628894463547085e-09,0.0024671999999999997,206.32563027853647,323.28339714630687,5.8654917660789145
3.390150223319322e-09,0.0024871999999999997,206.41627197138828,323.28339714630687,5.8654917660789145
3.415230138126766e-09,0.0025055999999999998,206.4994115882491,323.28339714630687,5.8654917660789145
3.443581346169964e-09,0.0025264,206.59310931356845,323.28339714630687,5.8654917660789145
3.4642995366630704e-09,0.0025415999999999998,206.6613905777942,323.28339714630687,5.8654917660789145
3.4806560028418388e-09,0.0025536,206.71518440835297,323.28339714630687,5.8654917660789145
3.5024646244135295e-09,0.0025696,206.786756406721,323.28339714630687,5.8654917660789145
3.5046454865706985e-09,0.0025712,206.7939040340261,323.28339714630687,5.8654917660789145
3.510097641963621e-09,0.0025751999999999997,206.81176551741552,323.28339714630687,5.8654917660789145
3.5744330756001086e-09,0.0026224,207.02172041538952,323.28339714630687,5.8654917660789145
3.6038747147218914e-09,0.002644,207.11730941176236,323.28339714630687,5.8654917660789145
3.608236439036229e-09,0.0026471999999999997,207.1314448003656,323.28339714630687,5.8654917660789145
3.637678078158012e-09,0.0026688,207.22668496747835,323.28339714630687,5.8654917660789145
3.6431302335509346e-09,0.0026728,207.24428899628907,323.28339714630687,5.8654917660789145
3.6671197172797943e-09,0.0026904,207.32162498144785,323.28339714630687,5.8654917660789145
3.679114459144224e-09,0.0026991999999999997,207.36021896588184,323.28339714630687,5.8654917660789145
3.6900187699300695e-09,0.0027072,207.39526184446152,323.28339714630687,5.8654917660789145
3.6998326496373306e-09,0.0027144,207.42676592001249,323.28339714630687,5.8654917660789145
3.7107369604231753e-09,0.0027224,207.4617322499849,323.28339714630687,5.8654917660789145
3.72600299552336e-09,0.0027336,207.51061786417574,323.28339714630687,5.8654917660789145
3.730364719837697e-09,0.0027367999999999997,207.52457082703438,323.28339714630687,5.8654917660789145
3.7467211860164655e-09,0.0027488,207.57683786749914,323.28339714630687,5.8654917660789145
3.7608967900380645e-09,0.0027592,207.62206402958373,323.28339714630687,5.8654917660789145
3.765258514352402e-09,0.0027624,207.63596639031354,323.28339714630687,5.8654917660789145
3.779434118374001e-09,0.0027727999999999997,207.68110574778973,323.28339714630687,5.8654917660789145
3.801242739945692e-09,0.0027887999999999997,207.75042219479587,323.28339714630687,5.8654917660789145
3.816508775045876e-09,0.0028,207.79885145418632,323.28339714630687,5.8654917660789145
3.864487742503595e-09,0.0028352,207.95056817352565,323.28339714630687,5.8654917660789145
3.872120760053687e-09,0.0028407999999999997,207.97463702812468,323.28339714630687,5.8654917660789145
3.9048336924112225e-09,0.0028648,208.07758038110273,323.28339714630687,5.8654917660789145
3.919009296432822e-09,0.0028752,208.12208465492768,323.28339714630687,5.8654917660789145
3.953903090947527e-09,0.0029008,208.23136700433366,323.28339714630687,5.8654917660789145
3.9778925746763865e-09,0.0029184,208.30628052970084,323.28339714630687,5.8654917660789145
4.000791627326662e-09,0.0029352,208.37762470260523,323.28339714630687,5.8654917660789145
4.0160576624268456e-09,0.0029464,208.42509902936322,323.28339714630687,5.8654917660789145
4.04113757723429e-09,0.0029648,208.50294006175992,323.28339714630687,5.8654917660789145
4.078212233906164e-09,0.002992,208.61766518523814,323.28339714630687,5.8654917660789145
4.108744304106532e-09,0.0030144,208.71183959245056,323.28339714630687,5.8654917660789145
4.125100770285299e-09,0.0030264,208.76217788165465,323.28339714630687,5.8654917660789145
4.142547667542651e-09,0.0030391999999999997,208.81578633334686,323.28339714630687,5.8654917660789145
4.18289361745028e-09,0.0030688,208.9394197583109,323.28339714630687,5.8654917660789145
4.2308725849079995e-09,0.003104,209.08583954442068,323.28339714630687,5.8654917660789145
4.238505602458091e-09,0.0031095999999999997,209.10907376263594,323.28339714630687,5.8654917660789145
4.269037672658458e-09,0.003132,209.20184791580246,323.28339714630687,5.8654917660789145
4.275580259129965e-09,0.0031368,209.22169438378114,323.28339714630687,5.8654917660789145
4.313745346880424e-09,0.0031647999999999997,209.33723026212735,323.28339714630687,5.8654917660789145
4.345367848159375e-09,0.003188,209.43265829594904,323.28339714630687,5.8654917660789145
4.378080780516912e-09,0.003212,209.5310923773224,323.28339714630687,5.8654917660789145
4.405341557481525e-09,0.003232,209.61290185224522,323.28339714630687,5.8654917660789145
4.422788454738878e-09,0.0032448,209.66515631923295,323.28339714630687,5.8654917660789145
4.456591818174998e-09,0.0032695999999999997,209.76617114381446,323.28339714630687,5.8654917660789145
4.464224835725089e-09,0.0032752,209.7889395356396,323.28339714630687,5.8654917660789145
4.47621957758952e-09,0.003284,209.82468778602546,323.28339714630687,5.8654917660789145
4.505661216711302e-09,0.0033055999999999997,209.91227546765157,323.28339714630687,5.8654917660789145
4.523108113968655e-09,0.0033184,209.96407395517693,323.28339714630687,5.8654917660789145
4.538374149068839e-09,0.0033296,210.00933374457998,323.28339714630687,5.8654917660789145
4.5569114774047755e-09,0.0033431999999999997,210.06421231609016,323.28339714630687,5.8654917660789145
4.588533978683727e-09,0.0033664,210.15762818490285,323.28339714630687,5.8654917660789145
4.607071307019664e-09,0.0033799999999999998,210.2122724818565,323.28339714630687,5.8654917660789145
4.619066048884094e-09,0.0033888,210.24758486853446,323.28339714630687,5.8654917660789145
4.647417256927292e-09,0.0034096,210.3309086503211,323.28339714630687,5.8654917660789145
4.674678033891905e-09,0.0034295999999999997,210.41084092122674,323.28339714630687,5.8654917660789145
4.689944068992089e-09,0.0034408,210.45552358203855,323.28339714630687,5.8654917660789145
4.6964866554635965e-09,0.0034456,210.4746559255476,323.28339714630687,5.8654917660789145
4.729199587821132e-09,0.0034695999999999998,210.5701621666709,323.28339714630687,5.8654917660789145
4.756460364785745e-09,0.0034896,210.6495540445892,323.28339714630687,5.8654917660789145
4.774997693121682e-09,0.0035031999999999997,210.70343918439198,323.28339714630687,5.8654917660789145
4.790263728221866e-09,0.0035144,210.7477539497091,323.28339714630687,5.8654917660789145
4.824067091657987e-09,0.0035391999999999997,210.84568396719115,323.28339714630687,5.8654917660789145
4.843694851072508e-09,0.0035535999999999996,210.90242374546915,323.28339714630687,5.8654917660789145
4.878588645587214e-09,0.0035792,211.00307355131972,323.28339714630687,5.8654917660789145
4.894945111765982e-09,0.0035911999999999997,211.050156464404,323.28339714630687,5.8654917660789145
4.94510494138087e-09,0.0036279999999999997,211.1941629290328,323.28339714630687,5.8654917660789145
4.960370976481054e-09,0.0036392,211.23787776277092,323.28339714630687,5.8654917660789145
4.978908304816991e-09,0.0036528,211.29088958542997,323.28339714630687,5.8654917660789145
5.010530806095943e-09,0.003676,211.38114420661364,323.28339714630687,5.8654917660789145
5.0290681344318795e-09,0.0036896,211.43394880700578,323.28339714630687,5.8654917660789145
5.0454246006106474e-09,0.0037015999999999998,211.48047809494517,323.28339714630687,5.8654917660789145
5.091222705911198e-09,0.0037351999999999997,211.61044817533477,323.28339714630687,5.8654917660789145
5.102127016697043e-09,0.0037432,211.6413261304448,323.28339714630687,5.8654917660789145
5.110850465325719e-09,0.0037495999999999996,211.66600996783927,323.28339714630687,5.8654917660789145
5.12066434503298e-09,0.0037568,211.69375965281503,323.28339714630687,5.8654917660789145
5.161010294940608e-09,0.0037863999999999997,211.80762445903653,323.28339714630687,5.8654917660789145
5.173005036805038e-09,0.0037952,211.84140914416105,323.28339714630687,5.8654917660789145
5.20462753808399e-09,0.0038184,211.93033173673842,323.28339714630687,5.8654917660789145
5.237340470441526e-09,0.0038423999999999997,212.0220991747869,323.28339714630687,5.8654917660789145
5.267872540641893e-09,0.0038648,212.10754730295275,323.28339714630687,5.8654917660789145
5.289681162213584e-09,0.0038808,212.16846346925084,323.28339714630687,5.8654917660789145
5.331117543199796e-09,0.0039112,212.28393501559765,323.28339714630687,5.8654917660789145
5.34420271614281e-09,0.0039207999999999995,212.32032692446364,323.28339714630687,5.8654917660789145
5.348564440457148e-09,0.0039239999999999995,212.33244983617314,323.28339714630687,5.8654917660789145
5.361649613400163e-09,0.0039336,212.3687954588008,323.28339714630687,5.8654917660789145
5.374734786343178e-09,0.0039432,212.40510650408626,323.28339714630687,5.8654917660789145
5.392181683600529e-09,0.0039559999999999994,212.45346764620555,323.28339714630687,5.8654917660789145
5.408538149779298e-09,0.003968,212.49875082260505,323.28339714630687,5.8654917660789145
5.421623322722312e-09,0.0039775999999999995,212.53493892138704,323.28339714630687,5.8654917660789145
5.433618064586743e-09,0.0039864,212.5680814332965,323.28339714630687,5.8654917660789145
5.447793668608342e-09,0.0039968,212.60721309236595,323.28339714630687,5.8654917660789145
6.473003052009623e-09,0.004748949789957992,215.3402051791478,323.28339714630687,5.8654917660789145
7.886484426130004e-09,0.0057859571914382875,218.8451509695548,323.28339714630687,5.8654917660789145
8.09588907414784e-09,0.005939587917583517,219.34273544547622,323.28339714630687,5.8654917660789145
8.357644884170133e-09,0.006131626325265053,219.95771268601263,323.28339714630687,5.8654917660789145
8.776454180205802e-09,0.006438887777555511,220.9262753658612,323.28339714630687,5.8654917660789145
9.116736733234782e-09,0.0066885377075415085,221.70002329811788,323.28339714630687,5.8654917660789145
9.561721610272682e-09,0.00701500300060012,222.69505837671844,323.28339714630687,5.8654917660789145
9.797301839292744e-09,0.007187837567513502,223.214520603622,323.28339714630687,5.8654917660789145
9.902004163301662e-09,0.007264652930586117,223.44382661228522,323.28339714630687,5.8654917660789145
1.0373164621341788e-08,0.007610322064412882,224.46422026564068,323.28339714630687,5.8654917660789145
1.0922851822388605e-08,0.008013602720544109,225.63210309772666,323.28339714630687,5.8654917660789145
1.2493386682522364e-08,0.009165833166633327,228.848773501425,323.28339714630687,5.8654917660789145
1.2755142492544657e-08,0.009357871574314863,229.36915559168952,323.28339714630687,5.8654917660789145
1.3461883179604849e-08,0.009876375275055011,230.75378945611791,323.28339714630687,5.8654917660789145
1.3854516894638289e-08,0.010164432886577316,231.51076946708474,323.28339714630687,5.8654917660789145
1.3959219218647205e-08,0.01024124824964993,231.71121187219603,323.28339714630687,5.8654917660789145
1.4194799447667267e-08,0.010414082816563312,232.16007579393104,323.28339714630687,5.8654917660789145
1.4980066877734146e-08,0.01099019803960792,233.635736198744,323.28339714630687,5.8654917660789145
1.5765334307801026e-08,0.01156631326265253,235.0815181206792,323.28339714630687,5.8654917660789145
1.5922387793814403e-08,0.011681536307261452,235.36727382767708,323.28339714630687,5.8654917660789145
1.6210319184838924e-08,0.011892778555711142,235.88832044412231,323.28339714630687,5.8654917660789145
1.6838533128892427e-08,0.012353670734146829,237.01278204392622,323.28339714630687,5.8654917660789145
1.7859380787979372e-08,0.013102620524104821,238.80574148894368,323.28339714630687,5.8654917660789145
1.8539945894037335e-08,0.013601920384076815,239.97888422766474,323.28339714630687,5.8654917660789145
1.908963309508415e-08,0.014005201040208042,240.91420679875384,323.28339714630687,5.8654917660789145
2.0267534240184468e-08,0.014869373874774956,242.8838092367601,323.28339714630687,5.8654917660789145
2.0764870279226826e-08,0.015234246849369875,243.70195379267307,323.28339714630687,5.8654917660789145
2.1393084223280325e-08,0.01569513902780556,244.7245569632177,323.28339714630687,5.8654917660789145
2.1838069100318227e-08,0.016021604320864174,245.44182671228882,323.28339714630687,5.8654917660789145
2.2623336530385107e-08,0.016597719543908783,246.69384377921963,323.28339714630687,5.8654917660789145
2.3225374893436378e-08,0.017039407881576315,247.64227800137058,323.28339714630687,5.8654917660789145
2.408916906650995e-08,0.017673134626925387,248.98649474037862,323.28339714630687,5.8654917660789145
2.4795909753570137e-08,0.018191638327665533,250.07237864980013,323.28339714630687,5.8654917660789145
2.4979138820585742e-08,0.018326065213042607,250.3519252457136,323.28339714630687,5.8654917660789145
2.5345596954616955e-08,0.01859491898379676,250.90863076442292,323.28339714630687,5.8654917660789145
2.542412369762364e-08,0.01865253050610122,251.02751538698286,323.28339714630687,5.8654917660789145
2.5869108574661542e-08,0.018978995799159834,251.6985093995313,323.28339714630687,5.8654917660789145
2.6366444613703897e-08,0.01934386877375475,252.44313941304742,323.28339714630687,5.8654917660789145
2.6811429490741795e-08,0.01967033406681336,253.10475661239357,323.28339714630687,5.8654917660789145
2.746581901579753e-08,0.020150430086017204,254.069995827496,323.28339714630687,5.8654917660789145
2.7936979473837656e-08,0.02049609921984397,254.7594226496622,323.28339714630687,5.8654917660789145
2.8172559702857718e-08,0.02066893378675735,255.10243446812444,323.28339714630687,5.8654917660789145
2.921958294294689e-08,0.021437087417483496,256.61359567964627,323.28339714630687,5.8654917660789145
2.9507514333971415e-08,0.021648329665933188,257.02544352296115,323.28339714630687,5.8654917660789145
3.0423659669049437e-08,0.022320464092818564,258.32556168331905,323.28339714630687,5.8654917660789145
3.1496858490140844e-08,0.023107821564312864,259.8292933813049,323.28339714630687,5.8654917660789145
3.165391197615422e-08,0.023223044608921786,260.0476639045393,323.28339714630687,5.8654917660789145
3.225595033920549e-08,0.023664732946589318,260.88086539977763,323.28339714630687,5.8654917660789145
3.2570057311232246e-08,0.023895179035807162,261.3131702878152,323.28339714630687,5.8654917660789145
3.264858405423893e-08,0.02395279055811162,261.42099207512473,323.28339714630687,5.8654917660789145
3.3119744512279054e-08,0.024298459691938386,262.06581157370283,323.28339714630687,5.8654917660789145
3.455940146740167e-08,0.02535467093418684,264.01427942541784,323.28339714630687,5.8654917660789145
3.516143983045294e-08,0.02579635927185437,264.81967555261696,323.28339714630687,5.8654917660789145
3.5842004936510906e-08,0.026295659131826365,265.7236750228844,323.28339714630687,5.8654917660789145
3.6574921204573326e-08,0.026833366673334667,266.6897584088221,323.28339714630687,5.8654917660789145
3.7778997930675875e-08,0.027716743348669734,268.2606630103148,323.28339714630687,5.8654917660789145
3.811928048370486e-08,0.027966393278655733,268.70105953869444,323.28339714630687,5.8654917660789145
3.830250955072046e-08,0.028100820164032807,268.93756095818884,323.28339714630687,5.8654917660789145
3.877367000876059e-08,0.028446489297859572,269.54369028561047,323.28339714630687,5.8654917660789145
3.8878372332769505e-08,0.028523304660932187,269.6779948074306,323.28339714630687,5.8654917660789145
3.919247930479626e-08,0.02875375075015003,270.08006455765985,323.28339714630687,5.8654917660789145
3.9820693248849764e-08,0.029214642928585718,270.8804535619667,323.28339714630687,5.8654917660789145
4.0187151382880974e-08,0.02948349669933987,271.3450729759545,323.28339714630687,5.8654917660789145
4.136505252798129e-08,0.03034766953390678,272.8274237101485,323.28339714630687,5.8654917660789145
4.2857060645108356e-08,0.031442288457691536,274.6816433442214,323.28339714630687,5.8654917660789145
4.398261062820422e-08,0.032268053610722144,276.0638251048721,323.28339714630687,5.8654917660789145
4.450612224824881e-08,0.03265213042608522,276.7019934450275,323.28339714630687,5.8654917660789145
4.505580944929563e-08,0.03305541108221645,277.36892739116814,323.28339714630687,5.8654917660789145
4.605048152738033e-08,0.03378515703140628,278.5677491241031,323.28339714630687,5.8654917660789145
4.678339779544276e-08,0.034322864572914585,279.4446391676391,323.28339714630687,5.8654917660789145
4.686192453844945e-08,0.03438047609521905,279.5382728070525,323.28339714630687,5.8654917660789145
4.7542489644507406e-08,0.03487977595519104,280.34721704538845,323.28339714630687,5.8654917660789145
4.793512335954084e-08,0.03516783356671334,280.8118612380568,323.28339714630687,5.8654917660789145
4.874656637060996e-08,0.03576315263052611,281.7674486143555,323.28339714630687,5.8654917660789145
4.8955971018627796e-08,0.03591678335667134,282.0130422369038,323.28339714630687,5.8654917660789145
4.929625357165678e-08,0.036166433286657335,282.4112598697948,323.28339714630687,5.8654917660789145
5.000299425871697e-08,0.036684936987397485,283.23491806593483,323.28339714630687,5.8654917660789145
5.03956279737504e-08,0.036972994598919784,283.6905437859678,323.28339714630687,5.8654917660789145
5.105001749880614e-08,0.03745309061812363,284.4468554671936,323.28339714630687,5.8654917660789145
5.144265121383957e-08,0.03774114822964593,284.8988277877759,323.28339714630687,5.8654917660789145
5.2097040738895314e-08,0.038221244248849776,285.6491366805921,323.28339714630687,5.8654917660789145
5.256820119693544e-08,0.03856691338267654,286.1870849675723,323.28339714630687,5.8654917660789145
5.366757559902907e-08,0.03937347469493899,287.4350375324576,323.28339714630687,5.8654917660789145
5.4348140705087023e-08,0.03987277455491098,288.2025849090855,323.28339714630687,5.8654917660789145
5.463607209611155e-08,0.04008401680336067,288.5261870266182,323.28339714630687,5.8654917660789145
5.5133408135153906e-08,0.04044888977795559,289.083573950248,323.28339714630687,5.8654917660789145
5.568309533620072e-08,0.040852170434086815,289.6973567642067,323.28339714630687,5.8654917660789145
5.6154255794240844e-08,0.04119783956791358,290.2215778889021,323.28339714630687,5.8654917660789145
5.7122752291323345e-08,0.041908381676335274,291.2937870133814,323.28339714630687,5.8654917660789145
5.759391274936347e-08,0.042254050810162036,291.81283680788624,323.28339714630687,5.8654917660789145
5.79865464643969e-08,0.042542108421684335,292.24411449153564,323.28339714630687,5.8654917660789145
6.002824178257079e-08,0.04404000800160032,294.4686602131249,323.28339714630687,5.8654917660789145
6.047322665960867e-08,0.044366473294658926,294.9495578474234,323.28339714630687,5.8654917660789145
6.104908944165772e-08,0.04478895779155831,295.56985230909885,323.28339714630687,5.8654917660789145
6.117996734666888e-08,0.044884976995399076,295.7105095863103,323.28339714630687,5.8654917660789145
6.199141035773799e-08,0.04548029605921185,296.57997992640094,323.28339714630687,5.8654917660789145
6.225316616776028e-08,0.04567233446689338,296.8595059001177,323.28339714630687,5.8654917660789145
6.295990685482047e-08,0.04619083816763353,297.6119458360406,323.28339714630687,5.8654917660789145
6.332636498885169e-08,0.046459691938387684,298.0008026083786,323.28339714630687,5.8654917660789145
6.434721264793862e-08,0.04720864172834567,299.07944605983204,323.28339714630687,5.8654917660789145
6.447809055294976e-08,0.04730466093218644,299.21724941248283,323.28339714630687,5.8654917660789145
6.492307542998767e-08,0.047631126225245055,299.6849669860147,323.28339714630687,5.8654917660789145
6.518483124000997e-08,0.04782316463292659,299.95951096042785,323.28339714630687,5.8654917660789145
6.570834286005454e-08,0.04820724144828965,300.5073124263786,323.28339714630687,5.8654917660789145
6.641508354711474e-08,0.0487257451490298,301.2441520134767,323.28339714630687,5.8654917660789145
6.686006842415263e-08,0.04905221044208842,301.70651959104066,323.28339714630687,5.8654917660789145
6.793326724524404e-08,0.04983956791358271,302.81673143595873,323.28339714630687,5.8654917660789145
6.848295444629086e-08,0.05024284856971395,303.38272615858176,323.28339714630687,5.8654917660789145
6.908499280934214e-08,0.05068453690738148,304.0005960800238,323.28339714630687,5.8654917660789145
6.96085044293867e-08,0.051068613722744544,304.5361693239775,323.28339714630687,5.8654917660789145
6.981790907740454e-08,0.05122224444888977,304.7499584934496,323.28339714630687,5.8654917660789145
7.039377185945359e-08,0.051644728945789156,305.3365931319502,323.28339714630687,5.8654917660789145
7.060317650747143e-08,0.051798359671934385,305.5494503990491,323.28339714630687,5.8654917660789145
7.068170325047812e-08,0.05185597119423885,305.62920837894535,323.28339714630687,5.8654917660789145
7.1466970680545e-08,0.05243208641728346,306.42489664164214,323.28339714630687,5.8654917660789145
7.154549742355169e-08,0.05248969793958792,306.50427747270624,323.28339714630687,5.8654917660789145
7.188577997658067e-08,0.05273934786957392,306.84786917080817,323.28339714630687,5.8654917660789145
7.219988694860741e-08,0.052969793958791755,307.16446816033505,323.28339714630687,5.8654917660789145
7.264487182564532e-08,0.05329625925185037,307.6120654026462,323.28339714630687,5.8654917660789145
7.30898567026832e-08,0.053622724544908976,308.0585946310879,323.28339714630687,5.8654917660789145
7.392747529475454e-08,0.05423724744948989,308.89625451842346,323.28339714630687,5.8654917660789145
7.468656714381921e-08,0.05479415883176636,309.65219199673965,323.28339714630687,5.8654917660789145
7.63094531659574e-08,0.055984796959391875,311.2583559446734,323.28339714630687,5.8654917660789145
7.701619385301761e-08,0.056503300660132025,311.95364440262625,323.28339714630687,5.8654917660789145
7.733030082504436e-08,0.056733746749349875,312.26186230783316,323.28339714630687,5.8654917660789145
7.76444077970711e-08,0.05696419283856771,312.56959233886636,323.28339714630687,5.8654917660789145
7.82464461601224e-08,0.057405881176235254,313.1580545369629,323.28339714630687,5.8654917660789145
7.871760661816252e-08,0.057751550310062016,313.61735932817555,323.28339714630687,5.8654917660789145
7.934582056221602e-08,0.058212442488497704,314.2281013666423,323.28339714630687,5.8654917660789145
7.981698102025615e-08,0.058558111622324466,314.68492107395025,323.28339714630687,5.8654917660789145
8.007873683027843e-08,0.058750150030006,314.9382553401223,323.28339714630687,5.8654917660789145
8.089017984134755e-08,0.05934546909381877,315.7215469941727,323.28339714630687,5.8654917660789145
8.157074494740551e-08,0.05984476895379076,316.3761411955169,323.28339714630687,5.8654917660789145
8.217278331045678e-08,0.06028645729145829,316.95343187633625,323.28339714630687,5.8654917660789145
8.240836353947684e-08,0.06045929185837168,317.17887892455747,323.28339714630687,5.8654917660789145
8.248689028248354e-08,0.06051690338067614,317.25397206712404,323.28339714630687,5.8654917660789145
8.303657748353035e-08,0.060920184036807365,317.77884561871565,323.28339714630687,5.8654917660789145
8.348156236056825e-08,0.06124664932986597,318.20275145241976,323.28339714630687,5.8654917660789145
8.363861584658162e-08,0.06136187237447489,318.35215476073904,323.28339714630687,5.8654917660789145
8.382184491359724e-08,0.06149629925985198,318.5263204061841,323.28339714630687,5.8654917660789145
8.463328792466635e-08,0.062091618323664735,319.2958475507402,323.28339714630687,5.8654917660789145
8.51306239637087e-08,0.062456491298259656,319.7660711682757,323.28339714630687,5.8654917660789145
8.583736465076889e-08,0.0629749949989998,320.4324448835469,323.28339714630687,5.8654917660789145
8.641322743281792e-08,0.06339747949589918,320.97383538728565,323.28339714630687,5.8654917660789145
8.696291463386473e-08,0.0638007601520304,321.4893061591854,323.28339714630687,5.8654917660789145
8.743407509190488e-08,0.06414642928585718,321.93012767553904,323.28339714630687,5.8654917660789145
8.751260183491157e-08,0.06420404080816164,322.00350776503115,323.28339714630687,5.8654917660789145
8.7905235549945e-08,0.06449209841968394,322.37002372319114,323.28339714630687,5.8654917660789145
8.87952053040208e-08,0.06514502900580116,323.19843772755144,323.28339714630687,5.8654917660789145
8.976370180110327e-08,0.06585557111422284,324.09627634777934,323.28339714630687,5.8654917660789145
9.060132039317462e-08,0.06647009401880376,324.86974304004485,323.28339714630687,5.8654917660789145
9.125570991823035e-08,0.0669501900380076,325.4720750951991,323.28339714630687,5.8654917660789145
9.177922153827494e-08,0.06733426685337068,325.95272876288004,323.28339714630687,5.8654917660789145
9.19100994432861e-08,0.06743028605721145,326.07272496375487,323.28339714630687,5.8654917660789145
9.230273315831952e-08,0.06771834366873375,326.43231436314835,323.28339714630687,5.8654917660789145
9.253831338733959e-08,0.06789117823564714,326.64778167146557,323.28339714630687,5.8654917660789145
9.35329854654243e-08,0.06862092418483696,327.55518413209853,323.28339714630687,5.8654917660789145
9.400414592346444e-08,0.06896659331866374,327.98369211249764,323.28339714630687,5.8654917660789145
9.413502382847559e-08,0.06906261252250451,328.1025733515131,323.28339714630687,5.8654917660789145
9.437060405749564e-08,0.06923544708941788,328.31639726905576,323.28339714630687,5.8654917660789145
9.478941335353131e-08,0.06954270854170834,328.6960153827252,323.28339714630687,5.8654917660789145
9.51296959065603e-08,0.06979235847169435,329.00397366993974,323.28339714630687,5.8654917660789145
9.533910055457814e-08,0.06994598919783958,329.1932729377959,323.28339714630687,5.8654917660789145
9.570555868860934e-08,0.07021484296859372,329.5241569361514,323.28339714630687,5.8654917660789145
9.625524588965615e-08,0.07061812362472494,330.01955797616307,323.28339714630687,5.8654917660789145
9.654317728068067e-08,0.07082936587317464,330.27861335428577,323.28339714630687,5.8654917660789145
9.732844471074756e-08,0.07140548109621925,330.9836010543431,323.28339714630687,5.8654917660789145
9.790430749279661e-08,0.07182796559311863,331.4991829688463,323.28339714630687,5.8654917660789145
9.850634585584788e-08,0.07226965393078616,332.03693744675394,323.28339714630687,5.8654917660789145
9.866339934186126e-08,0.07238487697539508,332.1770102320267,323.28339714630687,5.8654917660789145
9.942249119092591e-08,0.07294178835767154,332.85280665569405,323.28339714630687,5.8654917660789145
1.0078362140304182e-07,0.07394038807761552,334.0595618975223,323.28339714630687,5.8654917660789145
1.0115007953707303e-07,0.07420924184836968,334.3833694153235,323.28339714630687,5.8654917660789145
1.0172594231912208e-07,0.07463172634526906,334.891286957541,323.28339714630687,5.8654917660789145
1.0188299580513546e-07,0.07474694938987798,335.0296151503211,323.28339714630687,5.8654917660789145
1.021971027771622e-07,0.07497739547909582,335.30602230469924,323.28339714630687,5.8654917660789145
1.0243268300618227e-07,0.07515023004600921,335.5131102917138,323.28339714630687,5.8654917660789145
1.0264208765420011e-07,0.07530386077215444,335.6970326186751,323.28339714630687,5.8654917660789145
1.027991411402135e-07,0.07541908381676336,335.8348783444185,323.28339714630687,5.8654917660789145
1.0329647717925583e-07,0.07578395679135827,336.2708489512548,323.28339714630687,5.8654917660789145
1.033488283412603e-07,0.07582236447289459,336.31669292262853,323.28339714630687,5.8654917660789145
1.0426497367633833e-07,0.07649449889977997,337.1175021679997,323.28339714630687,5.8654917660789145
1.0455290506736283e-07,0.07670574114822964,337.368617691699,323.28339714630687,5.8654917660789145
1.0463143181036953e-07,0.07676335267053411,337.437056916749,323.28339714630687,5.8654917660789145
1.0497171436339851e-07,0.0770130026005201,337.73339571225546,323.28339714630687,5.8654917660789145
1.0528582133542527e-07,0.07724344868973795,338.00660686130317,323.28339714630687,5.8654917660789145
1.0557375272644979e-07,0.07745469093818765,338.2567712908236,323.28339714630687,5.8654917660789145
1.0586168411747431e-07,0.07766593318663734,338.50666977467847,323.28339714630687,5.8654917660789145
1.0656842480453449e-07,0.07818443688737747,339.11893575192096,323.28339714630687,5.8654917660789145
1.0690870735756349e-07,0.07843408681736348,339.4131655258959,323.28339714630687,5.8654917660789145
1.0795573059765266e-07,0.07920224044808963,340.3162054439233,323.28339714630687,5.8654917660789145
1.085315933797017e-07,0.079624724944989,340.8114212420094,323.28339714630687,5.8654917660789145
1.0868864686571508e-07,0.07973994798959792,340.9463021107262,323.28339714630687,5.8654917660789145
1.0900275383774183e-07,0.07997039407881577,341.2158360306667,323.28339714630687,5.8654917660789145
1.0934303639077082e-07,0.08022004400880177,341.50748951090117,323.28339714630687,5.8654917660789145
1.0981419684881094e-07,0.08056571314262853,341.9107336997059,323.28339714630687,5.8654917660789145
1.1083504450789787e-07,0.08131466293258652,342.7821219354152,323.28339714630687,5.8654917660789145
1.1117532706092685e-07,0.08156431286257251,343.07188836405135,323.28339714630687,5.8654917660789145
1.1151560961395585e-07,0.08181396279255852,343.3613091036809,323.28339714630687,5.8654917660789145
1.1206529681500267e-07,0.08221724344868975,343.82810839767814,323.28339714630687,5.8654917660789145
1.131646712170963e-07,0.0830238047609522,344.759036655875,323.28339714630687,5.8654917660789145
1.133479002841119e-07,0.08315823164632927,344.91384781455173,323.28339714630687,5.8654917660789145
1.1384523632315425e-07,0.08352310462092419,345.3335583342574,323.28339714630687,5.8654917660789145
1.1465667933422335e-07,0.08411842368473695,346.01681730982534,323.28339714630687,5.8654917660789145
1.150493130492568e-07,0.08440648129625926,346.34674925195776,323.28339714630687,5.8654917660789145
1.1538959560228578e-07,0.08465613122624525,346.6323352223171,323.28339714630687,5.8654917660789145
1.1586075606032591e-07,0.08500180036007202,347.0272203048043,323.28339714630687,5.8654917660789145
1.1622721419435712e-07,0.08527065413082617,347.3339203246994,323.28339714630687,5.8654917660789145
1.167507258144017e-07,0.08565473094618924,347.77140980834497,323.28339714630687,5.8654917660789145
1.1682925255740838e-07,0.0857123424684937,347.8369671849587,323.28339714630687,5.8654917660789145
1.1706483278642845e-07,0.08588517703540709,348.0335362818187,323.28339714630687,5.8654917660789145
1.180856804455154e-07,0.08663412682536507,348.8835591896538,323.28339714630687,5.8654917660789145
1.1855684090355553e-07,0.08697979595919185,349.27491039107605,323.28339714630687,5.8654917660789145
1.191588792666068e-07,0.08742148429685938,349.7740886962413,323.28339714630687,5.8654917660789145
1.199441466966737e-07,0.08799759951990399,350.42371514180434,323.28339714630687,5.8654917660789145
1.203106048307049e-07,0.08826645329065813,350.72630631077885,323.28339714630687,5.8654917660789145
1.2062471180273164e-07,0.08849689937987598,350.9853841869589,323.28339714630687,5.8654917660789145
1.2143615481380075e-07,0.08909221844368874,351.653453838694,323.28339714630687,5.8654917660789145
1.2159320829981412e-07,0.08920744148829766,351.7825563086766,323.28339714630687,5.8654917660789145
1.2235230014887878e-07,0.08976435287057412,352.4056371133606,323.28339714630687,5.8654917660789145
1.225617047968966e-07,0.08991798359671935,352.5772559289166,323.28339714630687,5.8654917660789145
1.2269258270190777e-07,0.09001400280056011,352.6844596190423,323.28339714630687,5.8654917660789145
1.2292816293092783e-07,0.0901868373674735,352.8773139402282,323.28339714630687,5.8654917660789145
1.2332079664596125e-07,0.0904748949789958,353.19841780865045,323.28339714630687,5.8654917660789145
1.2447252221005935e-07,0.09131986397279457,354.1380302954021,323.28339714630687,5.8654917660789145
1.246819268580772e-07,0.0914734946989398,354.3085040157122,323.28339714630687,5.8654917660789145
1.2538866754513738e-07,0.09199199839967995,354.8830302305975,323.28339714630687,5.8654917660789145
1.2546719428814405e-07,0.0920496099219844,354.9467884230195,323.28339714630687,5.8654917660789145
1.2554572103115075e-07,0.09210722144428886,355.01053105452996,323.28339714630687,5.8654917660789145
1.2565042335515966e-07,0.09218403680736148,355.09549704739254,323.28339714630687,5.8654917660789145
1.2640951520422432e-07,0.09274094818963793,355.7106768354133,323.28339714630687,5.8654917660789145
1.2714243147228674e-07,0.09327865573114623,356.30327792477505,323.28339714630687,5.8654917660789145
1.2753506518732018e-07,0.09356671334266854,356.6201946981593,323.28339714630687,5.8654917660789145
1.284512105223982e-07,0.09423884776955392,357.3581910882537,323.28339714630687,5.8654917660789145
1.2897472214244278e-07,0.09462292458491699,357.7789816202807,323.28339714630687,5.8654917660789145
1.292626535334673e-07,0.09483416683336668,358.01013246326556,323.28339714630687,5.8654917660789145
1.2981234073451414e-07,0.0952374474894979,358.45086359022577,323.28339714630687,5.8654917660789145
1.302311500305498e-07,0.09554470894178836,358.786170378578,323.28339714630687,5.8654917660789145
1.315661046616635e-07,0.0965241048209642,359.8521649880057,323.28339714630687,5.8654917660789145
1.3232519651072814e-07,0.09708101620324065,360.4564373624226,323.28339714630687,5.8654917660789145
1.330057616167861e-07,0.09758031606321264,360.99705039589435,323.28339714630687,5.8654917660789145
1.3342457091282178e-07,0.0978875775155031,361.32919916400823,323.28339714630687,5.8654917660789145
1.3431454066689757e-07,0.09854050810162032,362.0336682471451,323.28339714630687,5.8654917660789145
1.353353883259845e-07,0.09928945789157832,362.8394979008024,323.28339714630687,5.8654917660789145
1.357541976220202e-07,0.09959671934386878,363.1694084991599,323.28339714630687,5.8654917660789145
1.3591125110803356e-07,0.0997119423884777,363.2930226077111,323.28339714630687,5.8654917660789145