File: datasets/aisi_316_L/data/M1/valid_9.csv
Time(s),Strain(%),Stress(MPa),Temp(C),Log_SR(s-1)
0.0,0.0,0.0,28.04349988420079,1.266093357063074
1.907433063404512e-06,3.52e-05,6.88346395,28.04349988420079,1.266093357063074
2.6010450864606983e-06,4.8e-05,9.386541750000001,28.04349988420079,1.266093357063074
4.76858265851128e-06,8.8e-05,17.208659875,28.04349988420079,1.266093357063074
5.28879167580342e-06,9.76e-05,19.085968225,28.04349988420079,1.266093357063074
7.022821733443886e-06,0.0001296,25.343662725,28.04349988420079,1.266093357063074
7.456329247854001e-06,0.00013759999999999998,26.908086349999998,28.04349988420079,1.266093357063074
8.279993525233223e-06,0.0001528,29.8804912375,28.04349988420079,1.266093357063074
8.973605548289408e-06,0.0001656,32.383569037499996,28.04349988420079,1.266093357063074
1.0274128091519757e-05,0.0001896,37.0768399125,28.04349988420079,1.266093357063074
1.0707635605929874e-05,0.00019759999999999998,38.641263537499995,28.04349988420079,1.266093357063074
1.244166566357034e-05,0.0002296,44.8989580375,28.04349988420079,1.266093357063074
1.2831822426539444e-05,0.00023679999999999998,46.306939299999996,28.04349988420079,1.266093357063074
1.4132344969769794e-05,0.0002608,51.000210175,28.04349988420079,1.266093357063074
1.4435800229856873e-05,0.00026639999999999997,52.0953067125,28.04349988420079,1.266093357063074
1.6083128784615318e-05,0.0002968,58.0401164875,28.04349988420079,1.266093357063074
1.781715884225578e-05,0.00032879999999999997,64.2978109875,28.04349988420079,1.266093357063074
1.8424069362429945e-05,0.00033999999999999997,66.4880040625,28.04349988420079,1.266093357063074
1.8814226125399048e-05,0.0003472,67.895985325,28.04349988420079,1.266093357063074
1.9551188899896247e-05,0.0003608,70.5555054875,28.04349988420079,1.266093357063074
2.150197271474177e-05,0.0003968,77.5954118,28.04349988420079,1.266093357063074
2.2195584737797956e-05,0.0004096,80.0984896,28.04349988420079,1.266093357063074
2.249903999788504e-05,0.00041519999999999995,81.19358613749999,28.04349988420079,1.266093357063074
2.362615953535134e-05,0.00043599999999999997,85.2610875625,28.04349988420079,1.266093357063074
2.4839980575699666e-05,0.0004584,89.6414737125,28.04349988420079,1.266093357063074
2.492668207858169e-05,0.00045999999999999996,89.95435843749999,28.04349988420079,1.266093357063074
2.57069956045199e-05,0.0004744,92.7703209625,28.04349988420079,1.266093357063074
2.6487309130458108e-05,0.0004888,95.5862834875,28.04349988420079,1.266093357063074
2.7354324159278344e-05,0.0005048,98.7151307375,28.04349988420079,1.266093357063074
2.7744480922247447e-05,0.000512,100.12311199999999,28.04349988420079,1.266093357063074
2.865484670250869e-05,0.0005288,103.40840161249999,28.04349988420079,1.266093357063074
2.9478510979887913e-05,0.000544,106.3808065,28.04349988420079,1.266093357063074
2.969526473709297e-05,0.000548,107.1630183125,28.04349988420079,1.266093357063074
3.060563051735421e-05,0.0005648,110.448307925,28.04349988420079,1.266093357063074
3.142929479473344e-05,0.00058,113.4207128125,28.04349988420079,1.266093357063074
3.173275005482051e-05,0.0005855999999999999,114.51580934999998,28.04349988420079,1.266093357063074
3.2513063580758726e-05,0.0006,117.33177187499999,28.04349988420079,1.266093357063074
3.2903220343727835e-05,0.0006072,118.7397531375,28.04349988420079,1.266093357063074
3.4550548898486274e-05,0.0006376,124.6845629125,28.04349988420079,1.266093357063074
3.476730265569133e-05,0.0006416,125.466774725,28.04349988420079,1.266093357063074
3.5027407164337404e-05,0.0006464,126.4054289,28.04349988420079,1.266093357063074
3.5460914678747514e-05,0.0006544,127.969852525,28.04349988420079,1.266093357063074
3.606782519892168e-05,0.0006655999999999999,130.1600456,28.04349988420079,1.266093357063074
3.7715153753680124e-05,0.000696,136.104855375,28.04349988420079,1.266093357063074
3.866887028538238e-05,0.0007136,139.54658735,28.04349988420079,1.266093357063074
3.927578080555654e-05,0.0007247999999999999,141.73678042499998,28.04349988420079,1.266093357063074
3.992604207717172e-05,0.0007368,144.0834158625,28.04349988420079,1.266093357063074
4.122656462040206e-05,0.0007608,148.7766867375,28.04349988420079,1.266093357063074
4.183347514057623e-05,0.000772,150.9668798125,28.04349988420079,1.266093357063074
4.231033340642736e-05,0.0007808,152.6877458,28.04349988420079,1.266093357063074
4.300394542948354e-05,0.0007936,155.1908236,28.04349988420079,1.266093357063074
4.348080369533467e-05,0.0008024,156.9116895875,28.04349988420079,1.266093357063074
4.3784258955421755e-05,0.000808,158.006786125,28.04349988420079,1.266093357063074
4.4434520227036927e-05,0.00082,160.3534215625,28.04349988420079,1.266093357063074
4.5344886007298167e-05,0.0008368,163.638711175,28.04349988420079,1.266093357063074
4.569169201882626e-05,0.0008432,164.890250075,28.04349988420079,1.266093357063074
4.6818811556292564e-05,0.000864,168.9577515,28.04349988420079,1.266093357063074
4.716561756782065e-05,0.0008703999999999999,170.2092904,28.04349988420079,1.266093357063074
4.742572207646673e-05,0.0008751999999999999,171.147944575,28.04349988420079,1.266093357063074
4.8422789359609996e-05,0.0008935999999999999,174.74611891249998,28.04349988420079,1.266093357063074
4.8812946122579105e-05,0.0009008,176.154100175,28.04349988420079,1.266093357063074
4.941985664275326e-05,0.0009119999999999999,178.34429325,28.04349988420079,1.266093357063074
4.95499088970763e-05,0.0009144,178.8136203375,28.04349988420079,1.266093357063074
4.985336415716338e-05,0.0009199999999999999,179.90871687499998,28.04349988420079,1.266093357063074
5.0286871671573496e-05,0.000928,181.4731405,28.04349988420079,1.266093357063074
5.124058820327576e-05,0.0009456,184.914872475,28.04349988420079,1.266093357063074
5.163074496624486e-05,0.0009528,186.3228537375,28.04349988420079,1.266093357063074
5.258446149794711e-05,0.0009704,189.76458571249998,28.04349988420079,1.266093357063074
5.3451476526767346e-05,0.0009864,192.8934329625,28.04349988420079,1.266093357063074
5.397168554405948e-05,0.000996,194.77074131249998,28.04349988420079,1.266093357063074
5.423179005270556e-05,0.0010008,195.70939548750002,28.04349988420079,1.266093357063074
5.462194681567466e-05,0.001008,197.11737675,28.04349988420079,1.266093357063074
5.505545433008478e-05,0.001016,198.681800375,28.04349988420079,1.266093357063074
5.609587236466906e-05,0.0010352,202.436417075,28.04349988420079,1.266093357063074
5.696288739348929e-05,0.0010512,205.565264325,28.04349988420079,1.266093357063074
5.8740268202570765e-05,0.001084,211.97940118749997,28.04349988420079,1.266093357063074
5.943388022562695e-05,0.0010968,214.4824789875,28.04349988420079,1.266093357063074
6.0517649011652245e-05,0.0011168,218.39353805000002,28.04349988420079,1.266093357063074
6.0864455023180334e-05,0.0011232,219.64507695,28.04349988420079,1.266093357063074
6.173147005200057e-05,0.0011392,222.77392419999998,28.04349988420079,1.266093357063074
6.277188808658485e-05,0.0011584,226.5285409,28.04349988420079,1.266093357063074
6.433251513846127e-05,0.0011872,232.16046595,28.04349988420079,1.266093357063074
6.489607490719442e-05,0.0011976,234.1942166625,28.04349988420079,1.266093357063074
6.524288091872251e-05,0.001204,235.4457555625,28.04349988420079,1.266093357063074
6.610989594754275e-05,0.00122,238.5746028125,28.04349988420079,1.266093357063074
6.702026172780399e-05,0.0012368,241.859892425,28.04349988420079,1.266093357063074
6.762717224797815e-05,0.001248,244.0500855,28.04349988420079,1.266093357063074
6.797397825950625e-05,0.0012544,245.30162439999998,28.04349988420079,1.266093357063074
6.957795606282368e-05,0.001284,251.0899918125,28.04349988420079,1.266093357063074
7.131198612046413e-05,0.001316,257.3476863125,28.04349988420079,1.266093357063074
7.183219513775628e-05,0.0013256,259.22499466249997,28.04349988420079,1.266093357063074
7.356622519539675e-05,0.0013576,265.4826891625,28.04349988420079,1.266093357063074
7.469334473286305e-05,0.0013784,269.55019058749997,28.04349988420079,1.266093357063074
7.478004623574508e-05,0.00138,269.8630753125,28.04349988420079,1.266093357063074
7.668747929914958e-05,0.0014152,276.7465392625,28.04349988420079,1.266093357063074
7.772789733373386e-05,0.0014344,280.5011559625,28.04349988420079,1.266093357063074
7.93318751370513e-05,0.001464,286.289523375,28.04349988420079,1.266093357063074
7.985208415434344e-05,0.0014736,288.166831725,28.04349988420079,1.266093357063074
8.006883791154849e-05,0.0014776,288.94904353749996,28.04349988420079,1.266093357063074
8.097920369180973e-05,0.0014944,292.23433315,28.04349988420079,1.266093357063074
8.188956947207097e-05,0.0015111999999999999,295.5196227625,28.04349988420079,1.266093357063074
8.319009201530134e-05,0.0015352,300.21289363750003,28.04349988420079,1.266093357063074
8.38403532869165e-05,0.0015471999999999999,302.559529075,28.04349988420079,1.266093357063074
8.535762958735191e-05,0.0015752,308.0350117625,28.04349988420079,1.266093357063074
8.648474912481822e-05,0.001596,312.1025131875,28.04349988420079,1.266093357063074
8.743846565652048e-05,0.0016136,313.93318102976644,28.04349988420079,1.266093357063074
8.808872692813563e-05,0.0016255999999999998,314.032870206897,28.04349988420079,1.266093357063074
8.839218218822272e-05,0.0016312,314.07929356714436,28.04349988420079,1.266093357063074
8.882568970263285e-05,0.0016392,314.1455049769784,28.04349988420079,1.266093357063074
8.947595097424802e-05,0.0016512,314.24458628488753,28.04349988420079,1.266093357063074
9.003951074298116e-05,0.0016615999999999998,314.33022981217033,28.04349988420079,1.266093357063074
9.01695629973042e-05,0.001664,314.34996398430803,28.04349988420079,1.266093357063074
9.099322727468342e-05,0.0016791999999999998,314.4746902827754,28.04349988420079,1.266093357063074
9.23804513207958e-05,0.0017048,314.68376490813426,28.04349988420079,1.266093357063074
9.294401108952894e-05,0.0017151999999999998,314.76835129518525,28.04349988420079,1.266093357063074
9.39410783726722e-05,0.0017335999999999999,314.91751575873354,28.04349988420079,1.266093357063074
9.554505617598965e-05,0.0017632,315.1561868769002,28.04349988420079,1.266093357063074
9.740913848795314e-05,0.0017976,315.4316068950825,28.04349988420079,1.266093357063074
0.00010053039259170599,0.0018552,315.888216556849,28.04349988420079,1.266093357063074
0.0001017008628806133,0.0018767999999999999,316.05801542164573,28.04349988420079,1.266093357063074
0.00010248117640655151,0.0018912,316.17079144351834,28.04349988420079,1.266093357063074
0.00010269793016375656,0.0018951999999999999,316.20205861949614,28.04349988420079,1.266093357063074
0.00010308808692672566,0.0019023999999999998,316.25827475620594,28.04349988420079,1.266093357063074
0.00010365164669545882,0.0019127999999999999,316.33932957415504,28.04349988420079,1.266093357063074
0.00010412850496130994,0.0019215999999999999,316.4077802658564,28.04349988420079,1.266093357063074
0.00010560243051030434,0.0019487999999999999,316.61858628862615,28.04349988420079,1.266093357063074
0.0001072931098165038,0.00198,316.85898528703973,28.04349988420079,1.266093357063074
0.00010768326657947288,0.0019871999999999997,316.9142516370319,28.04349988420079,1.266093357063074
0.000108030072591001,0.0019936,316.9633117552097,28.04349988420079,1.266093357063074
0.00010889708761982123,0.0020096,317.0856940864216,28.04349988420079,1.266093357063074
0.0001095039981399954,0.0020208,317.17113571182955,28.04349988420079,1.266093357063074
0.00011063111767746168,0.0020415999999999998,317.3293246356695,28.04349988420079,1.266093357063074
0.000111758237214928,0.0020624,317.4868862529917,28.04349988420079,1.266093357063074
0.00011232179698366115,0.0020728,317.5654345727699,28.04349988420079,1.266093357063074
0.0001136223195268915,0.0020968,317.7461156547313,28.04349988420079,1.266093357063074
0.00011466273756147577,0.002116,317.8900804718696,28.04349988420079,1.266093357063074
0.00011709037964217243,0.0021608,318.2240315786029,28.04349988420079,1.266093357063074
0.00011969142472863313,0.0022088,318.57885368577155,28.04349988420079,1.266093357063074
0.00012021163374592525,0.0022183999999999997,318.64945584880957,28.04349988420079,1.266093357063074
0.00012125205178050954,0.0022375999999999997,318.79030372107394,28.04349988420079,1.266093357063074
0.00012177226079780169,0.0022472,318.8605508479124,28.04349988420079,1.266093357063074
0.0001222057683122118,0.0022551999999999997,318.91900076182094,28.04349988420079,1.266093357063074
0.0001225092235722989,0.0022608,318.95986759715146,28.04349988420079,1.266093357063074
0.000122942731086709,0.0022688,319.01818037381497,28.04349988420079,1.266093357063074
0.00012402649987273428,0.0022887999999999997,319.1636125776255,28.04349988420079,1.266093357063074
0.00012493686565299555,0.0023056,319.28539301446983,28.04349988420079,1.266093357063074
0.00012506691790731855,0.0023079999999999997,319.3027619271112,28.04349988420079,1.266093357063074
0.00012550042542172868,0.002316,319.36060749739545,28.04349988420079,1.266093357063074
0.0001270610524736051,0.0023447999999999997,319.56820941381096,28.04349988420079,1.266093357063074
0.00012723445547936914,0.002348,319.5912147430629,28.04349988420079,1.266093357063074
0.00012745120923657422,0.002352,319.61995421669144,28.04349988420079,1.266093357063074
0.0001281014705081894,0.0023639999999999998,319.7060584836957,28.04349988420079,1.266093357063074
0.00013143947836914729,0.0024256,320.1454052678654,28.04349988420079,1.266093357063074
0.00013195968738643942,0.0024351999999999998,320.21348099944925,28.04349988420079,1.266093357063074
0.0001333902621839928,0.0024616,320.4001517178871,28.04349988420079,1.266093357063074
0.0001344740309700181,0.0024816,320.541049579336,28.04349988420079,1.266093357063074
0.00013456073247290014,0.0024832,320.55230224085653,28.04349988420079,1.266093357063074
0.00013616471027621754,0.0025128,320.75996914824265,28.04349988420079,1.266093357063074
0.0001374652328194479,0.0025368,320.92764822013834,28.04349988420079,1.266093357063074
0.00013846230010259116,0.0025552,321.0557835277452,28.04349988420079,1.266093357063074
0.00014036973316599569,0.0025904,321.29991367065884,28.04349988420079,1.266093357063074
0.0001405431361717597,0.0025935999999999997,321.32204296679265,28.04349988420079,1.266093357063074
0.00014149685270346197,0.0026111999999999997,321.4435642909206,28.04349988420079,1.266093357063074
0.00014206041247219513,0.0026216,321.51522220066795,28.04349988420079,1.266093357063074
0.00014279737524669232,0.0026352,321.6087616391193,28.04349988420079,1.266093357063074
0.00014327423351254346,0.002644,321.66918684943477,28.04349988420079,1.266093357063074
0.00014483486056441987,0.0026728,321.86639595676235,28.04349988420079,1.266093357063074
0.000145311718830271,0.0026815999999999997,321.9264887672356,28.04349988420079,1.266093357063074
0.00014617873385909123,0.0026976,322.0355517533846,28.04349988420079,1.266093357063074
0.00014708909963935247,0.0027144,322.14979672051123,28.04349988420079,1.266093357063074
0.00014769601015952665,0.0027256,322.2258068675402,28.04349988420079,1.266093357063074
0.00014908323420563904,0.0027512,322.39908840523907,28.04349988420079,1.266093357063074
0.0001493866894657261,0.0027568,322.4369097867815,28.04349988420079,1.266093357063074
0.00014964679397437217,0.0027616,322.4693042719674,28.04349988420079,1.266093357063074
0.00015081726426327947,0.0027832,322.6148085644868,28.04349988420079,1.266093357063074
0.0001513374732805716,0.0027928,322.67933570581084,28.04349988420079,1.266093357063074
0.00015328825709541713,0.0028288,322.9205459162886,28.04349988420079,1.266093357063074
0.00015441537663288344,0.0028496,323.05936612178755,28.04349988420079,1.266093357063074
0.0001556725484246728,0.0028728,323.2137386730496,28.04349988420079,1.266093357063074
0.00015627945894484694,0.002884,323.28808927353924,28.04349988420079,1.266093357063074
0.00015749327998519527,0.0029064,323.4364535077835,28.04349988420079,1.266093357063074
0.00015784008599672335,0.0029127999999999997,323.478761293427,28.04349988420079,1.266093357063074
0.00015814354125681044,0.0029184,323.5157508753047,28.04349988420079,1.266093357063074
0.00015970416830868688,0.0029472,323.70554752210694,28.04349988420079,1.266093357063074
0.00016113474310624026,0.0029736,323.8788933162513,28.04349988420079,1.266093357063074
0.00016156825062065038,0.0029816,323.9313037115385,28.04349988420079,1.266093357063074
0.0001617850043778554,0.0029855999999999997,323.95748834094894,28.04349988420079,1.266093357063074
0.0001624352656494706,0.0029976,324.0359602621631,28.04349988420079,1.266093357063074
0.0001636057359383779,0.0030191999999999997,324.1769016802429,28.04349988420079,1.266093357063074
0.00016625013177627962,0.003068,324.4938850264342,28.04349988420079,1.266093357063074
0.0001668570422964538,0.0030792,324.56635714273267,28.04349988420079,1.266093357063074
0.000167724057325274,0.0030951999999999998,324.66971065592725,28.04349988420079,1.266093357063074
0.00016980489339444256,0.0031336,324.91691264419444,28.04349988420079,1.266093357063074
0.000171452221949201,0.0031639999999999997,325.11177734463985,28.04349988420079,1.266093357063074
0.0001720591324693752,0.0031752,325.1833853641823,28.04349988420079,1.266093357063074
0.0001722758862265802,0.0031791999999999996,325.20893577497793,28.04349988420079,1.266093357063074
0.0001728827967467544,0.0031904,325.2804103128395,28.04349988420079,1.266093357063074
0.00017379316252701566,0.0032072,325.3874389127908,28.04349988420079,1.266093357063074
0.0001743567222957488,0.0032175999999999997,325.4535851505484,28.04349988420079,1.266093357063074
0.00017448677455007182,0.0032199999999999998,325.468837819567,28.04349988420079,1.266093357063074
0.00017518038657312801,0.0032327999999999996,325.550110630131,28.04349988420079,1.266093357063074
0.00017596070009906625,0.0032472,325.6413926808084,28.04349988420079,1.266093357063074
0.00017682771512788647,0.0032632,325.74263222516043,28.04349988420079,1.266093357063074
0.00017752132715094263,0.003276,325.82348454261876,28.04349988420079,1.266093357063074
0.00017778143165958873,0.0032808,325.85377238646663,28.04349988420079,1.266093357063074
0.00017877849894273198,0.0032992,325.96971604117374,28.04349988420079,1.266093357063074
0.00017973221547443424,0.0033168,326.08038291866615,28.04349988420079,1.266093357063074
0.00018051252900037245,0.0033312,326.1707582986888,28.04349988420079,1.266093357063074
0.0001822032083065719,0.0033623999999999998,326.3660505878846,28.04349988420079,1.266093357063074
0.00018272341732386406,0.003372,326.4259981730008,28.04349988420079,1.266093357063074
0.00018311357408683313,0.0033791999999999997,326.4709151909605,28.04349988420079,1.266093357063074
0.00018341702934692022,0.0033848,326.50582484981567,28.04349988420079,1.266093357063074
0.0001840672906185354,0.0033967999999999997,326.5805555027958,28.04349988420079,1.266093357063074
0.00018437074587862248,0.0034024,326.6153945652893,28.04349988420079,1.266093357063074
0.00018497765639879663,0.0034135999999999997,326.6850056732482,28.04349988420079,1.266093357063074
0.00018536781316176576,0.0034208,326.7297086394484,28.04349988420079,1.266093357063074
0.0001867983879593191,0.0034471999999999997,326.8933065111192,28.04349988420079,1.266093357063074
0.00018822896275687252,0.0034736,327.0564164765639,28.04349988420079,1.266093357063074
0.00018874917177416465,0.0034831999999999997,327.115609231081,28.04349988420079,1.266093357063074
0.0001889225747799287,0.0034863999999999997,327.13532600597455,28.04349988420079,1.266093357063074
0.0001903965003289231,0.0035136,327.30263458680054,28.04349988420079,1.266093357063074
0.00019135021686062537,0.0035312,327.4106239764699,28.04349988420079,1.266093357063074
0.00019282414240961974,0.0035583999999999998,327.57710470218154,28.04349988420079,1.266093357063074
0.00019343105292979391,0.0035696,327.6455112500815,28.04349988420079,1.266093357063074
0.0001944281202129372,0.003588,327.75771199526855,28.04349988420079,1.266093357063074
0.00019572864275616754,0.0036119999999999998,327.9037241327185,28.04349988420079,1.266093357063074
0.00019624885177345968,0.0036216,327.96202298509326,28.04349988420079,1.266093357063074
0.00019633555327634172,0.0036232,327.9717335980114,28.04349988420079,1.266093357063074
0.00019663900853642878,0.0036287999999999997,328.0057075809758,28.04349988420079,1.266093357063074
0.00019741932206236698,0.0036431999999999997,328.0929754941904,28.04349988420079,1.266093357063074
0.00020093073292908894,0.003708,328.4840282009907,28.04349988420079,1.266093357063074
0.0002018844494607912,0.0037256,328.589778635113,28.04349988420079,1.266093357063074
0.00020210120321799625,0.0037296,328.61378563169393,28.04349988420079,1.266093357063074
0.00020283816599249343,0.0037432,328.69533441443014,28.04349988420079,1.266093357063074
0.00020314162125258052,0.0037487999999999996,328.72887972937207,28.04349988420079,1.266093357063074
0.0002042687407900468,0.0037695999999999997,328.85330588212645,28.04349988420079,1.266093357063074
0.00020582936784192325,0.0037984,329.0251471120337,28.04349988420079,1.266093357063074
0.0002060461215991283,0.0038023999999999996,329.0489736985234,28.04349988420079,1.266093357063074
0.00020725994263947662,0.0038247999999999997,329.18222237646944,28.04349988420079,1.266093357063074
0.00020743334564524068,0.003828,329.2012330278552,28.04349988420079,1.266093357063074
0.00020812695766829684,0.0038407999999999997,329.27721373705407,28.04349988420079,1.266093357063074
0.00020847376367982495,0.0038472,329.3151670542023,28.04349988420079,1.266093357063074
0.0002093841294600862,0.003864,329.41467754202034,28.04349988420079,1.266093357063074
0.00020999103998026034,0.0038751999999999997,329.4809241417622,28.04349988420079,1.266093357063074
0.00021111815951772666,0.0038959999999999997,329.6037557723019,28.04349988420079,1.266093357063074
0.0002116383685350188,0.0039056,329.6603610091485,28.04349988420079,1.266093357063074
0.00021254873431528004,0.0039223999999999995,329.75928977661516,28.04349988420079,1.266093357063074
0.00021328569708977722,0.003935999999999999,329.8392539899767,28.04349988420079,1.266093357063074
0.00021449951813012558,0.0039584,329.97072525110707,28.04349988420079,1.266093357063074
0.00021484632414165369,0.0039648,330.008235134391,28.04349988420079,1.266093357063074
0.00021553993616470982,0.0039775999999999995,330.0831841341712,28.04349988420079,1.266093357063074
0.000216103495933443,0.003988,330.1440109591635,28.04349988420079,1.266093357063074
0.00021658035419929412,0.0039968,330.19543150680767,28.04349988420079,1.266093357063074
0.00025213504663881045,0.004652930586117224,333.9135436249515,28.04349988420079,1.266093357063074
0.00026150068207715665,0.0048257651530306065,334.8581451892094,28.04349988420079,1.266093357063074
0.0002791913267940328,0.005152230446089218,336.6071423444886,28.04349988420079,1.266093357063074
0.0002948007191912764,0.005440288057611523,338.1147753469489,28.04349988420079,1.266093357063074
0.0003052069807894388,0.005632326465293058,339.102598689425,28.04349988420079,1.266093357063074
0.0003197757470268662,0.005901180236047209,340.4637596265825,28.04349988420079,1.266093357063074
0.0003468320271820885,0.006400480096019204,342.9291019012651,28.04349988420079,1.266093357063074
0.0003551570364606185,0.006554110822164433,343.6724210352732,28.04349988420079,1.266093357063074
0.0003666039242185971,0.006765353070614123,344.68348300707663,28.04349988420079,1.266093357063074
0.00042904149380757167,0.00791758351670334,349.9955242292575,28.04349988420079,1.266093357063074
0.00044881339084408025,0.00828245649129826,351.6135568999558,28.04349988420079,1.266093357063074
0.0004800321756385676,0.008858571714342869,354.11284470606734,28.04349988420079,1.266093357063074
0.0005102103342732386,0.009415483096619324,356.4692168708182,28.04349988420079,1.266093357063074
0.0005154134650723198,0.009511502300460092,356.8699306721899,28.04349988420079,1.266093357063074
0.0005216572220312172,0.009626725345069014,357.34871073148116,28.04349988420079,1.266093357063074
0.0005310228574695635,0.009799559911982397,358.0627114670808,28.04349988420079,1.266093357063074
0.0005455916237069909,0.010068413682736548,359.16369387135114,28.04349988420079,1.266093357063074
0.0005539166329855207,0.010222044408881775,359.7876778874685,28.04349988420079,1.266093357063074
0.0005684853992229481,0.010490898179635926,360.87091965018124,28.04349988420079,1.266093357063074
0.0005747291561818455,0.010606121224244848,361.33184568746793,28.04349988420079,1.266093357063074
0.0005913791747389055,0.010913382676535306,362.551532853518,28.04349988420079,1.266093357063074
0.0006153135764146792,0.011355071014202842,364.28162487077606,28.04349988420079,1.266093357063074
0.0006225979595333928,0.011489497899579915,364.80293851564613,28.04349988420079,1.266093357063074
0.0006371667257708202,0.011758351670334066,365.83848368642646,28.04349988420079,1.266093357063074
0.0006434104827297176,0.011873574714942988,366.27945727127326,28.04349988420079,1.266093357063074
0.0006517354920082476,0.012027205441088217,366.86483466798404,28.04349988420079,1.266093357063074
0.0006933605384008973,0.012795359071814363,369.7490815959329,28.04349988420079,1.266093357063074
0.0007037667999990597,0.012987397479495899,370.4594911312028,28.04349988420079,1.266093357063074
0.0007745293788665642,0.014293258651730346,375.18600099950805,28.04349988420079,1.266093357063074
0.0007922200235834404,0.014619723944788958,376.34092324367,28.04349988420079,1.266093357063074
0.0008140731729395814,0.015023004600920185,377.75379752454177,28.04349988420079,1.266093357063074
0.0008276013130171925,0.015272654530906182,378.62102436240826,28.04349988420079,1.266093357063074
0.0008619419762911286,0.015906381276255252,380.7979758840254,28.04349988420079,1.266093357063074
0.0009087701534828595,0.016770554110822164,383.712790240277,28.04349988420079,1.266093357063074
0.0009285420505193682,0.017135427085417085,384.925831107391,28.04349988420079,1.266093357063074
0.0010232390310626462,0.018882976595319064,390.60146469076784,28.04349988420079,1.266093357063074
0.001027401535701911,0.01895979195839168,390.84612970506515,28.04349988420079,1.266093357063074
0.0010586203204963984,0.019535907181436288,392.66895200114317,28.04349988420079,1.266093357063074
0.0010711078344141933,0.01976635327065413,393.39219595112377,28.04349988420079,1.266093357063074
0.0010731890867338259,0.01980476095219044,393.51241618114125,28.04349988420079,1.266093357063074
0.0010887984791310694,0.02009281856371274,394.41118749214223,28.04349988420079,1.266093357063074
0.0011075297500077617,0.020438487697539507,395.48310675563715,28.04349988420079,1.266093357063074
0.001121057890085373,0.020688137627525506,396.2528782948515,28.04349988420079,1.266093357063074
0.0011678860672771037,0.021552310462092418,398.8899374294847,28.04349988420079,1.266093357063074
0.0011793329550350827,0.02176355271054211,399.52823964172234,28.04349988420079,1.266093357063074
0.0011928610951126937,0.022013202640528105,400.27948999141177,28.04349988420079,1.266093357063074
0.001206389235190305,0.022262852570514104,401.02742484491233,28.04349988420079,1.266093357063074
0.0012469736554231383,0.023011802360472094,403.25184534262974,28.04349988420079,1.266093357063074
0.0012646643001400146,0.023338267653530708,404.2126083324544,28.04349988420079,1.266093357063074
0.0012823549448568905,0.023664732946589318,405.1681439666171,28.04349988420079,1.266093357063074
0.0012865174494961556,0.023741548309661933,405.3922270895999,28.04349988420079,1.266093357063074
0.001297964337254134,0.02395279055811162,406.0070024326142,28.04349988420079,1.266093357063074
0.0013094112250121128,0.024164032806561313,406.61966688479106,28.04349988420079,1.266093357063074
0.0013395893836467838,0.024720944188837767,408.2249429469116,28.04349988420079,1.266093357063074
0.0013427112621262327,0.02477855571114223,408.3901969704362,28.04349988420079,1.266093357063074
0.0013541581498842112,0.024989797959591917,408.99485060223594,28.04349988420079,1.266093357063074
0.0013895394393179635,0.02564272854570914,410.8512992899215,28.04349988420079,1.266093357063074
0.0013937019439572284,0.025719543908781756,411.06848631673506,28.04349988420079,1.266093357063074
0.0014290832333909806,0.02637247449489898,412.90447233891575,28.04349988420079,1.266093357063074
0.0014509363827471219,0.026775755151030207,414.02961080261,28.04349988420079,1.266093357063074
0.0014592613920256518,0.026929385877175437,414.4564941102106,28.04349988420079,1.266093357063074
0.0014800739152219767,0.02731346269253851,415.51956797964965,28.04349988420079,1.266093357063074
0.0014998458122584852,0.027678335667133427,416.5241009359493,28.04349988420079,1.266093357063074
0.0015258614662538915,0.02815843168633727,417.838021338018,28.04349988420079,1.266093357063074
0.0015414708586511349,0.028446489297859572,418.62218044844997,28.04349988420079,1.266093357063074
0.001550836494089481,0.028619323864772953,419.09118955595795,28.04349988420079,1.266093357063074
0.0015570802510483784,0.028734546909381875,419.4032487578859,28.04349988420079,1.266093357063074
0.0015810146527241522,0.02917623524704941,420.59498182925626,28.04349988420079,1.266093357063074
0.0015987052974410281,0.02950270054010802,421.4713106953734,28.04349988420079,1.266093357063074
0.001622639699116802,0.029944388877775556,422.6509361094685,28.04349988420079,1.266093357063074
0.001630964708395332,0.030098019603920785,423.0596473987435,28.04349988420079,1.266093357063074
0.0016434522223131268,0.03032846569313863,423.6711920994102,28.04349988420079,1.266093357063074
0.001652817857751473,0.03050130026005201,424.1286620584411,28.04349988420079,1.266093357063074
0.0016590616147103704,0.03061652330466093,424.43308050628724,28.04349988420079,1.266093357063074
0.0016809147640665116,0.03101980396079216,425.4950442549776,28.04349988420079,1.266093357063074
0.0017069304180619175,0.031499899979996,426.75229174530045,28.04349988420079,1.266093357063074
0.0017183773058198962,0.03171114222844569,427.30311075907105,28.04349988420079,1.266093357063074
0.001729824193577875,0.03192238447689538,427.8525006082738,28.04349988420079,1.266093357063074
0.0017485554644545672,0.032268053610722144,428.74845367697543,28.04349988420079,1.266093357063074
0.0017704086138107082,0.03267133426685337,429.78901496410975,28.04349988420079,1.266093357063074
0.0017933023893266658,0.03309381876375275,430.8737682524312,28.04349988420079,1.266093357063074
0.0018016273986051956,0.03324744948989798,431.2668832185738,28.04349988420079,1.266093357063074
0.0018078711555640932,0.03336267253450691,431.561254697095,28.04349988420079,1.266093357063074
0.001817236791002439,0.03353550710142028,432.0020695760763,28.04349988420079,1.266093357063074
0.0018786337344315976,0.03466853370674135,434.87022017295527,28.04349988420079,1.266093357063074
0.0019108931453859007,0.035263852770554105,436.36255073128547,28.04349988420079,1.266093357063074
0.0019556400702579993,0.03608961792358471,438.41639198046005,28.04349988420079,1.266093357063074
0.001986858855052487,0.036665733146629326,439.83846350119427,28.04349988420079,1.266093357063074
0.001999346368970282,0.036896179235847176,440.40484884616376,28.04349988420079,1.266093357063074
0.0020118338828880766,0.03712662532506501,440.96985622323984,28.04349988420079,1.266093357063074
0.002040971415362932,0.03766433286657332,442.2829143815755,28.04349988420079,1.266093357063074
0.002048255798481645,0.03779875975195039,442.61003409835246,28.04349988420079,1.266093357063074
0.002061783938559256,0.03804840968193639,443.2163409427024,28.04349988420079,1.266093357063074
0.0020877995925546624,0.038528505701140234,444.3779725839573,28.04349988420079,1.266093357063074
0.0021075714895911705,0.03889337867573514,445.2570409777914,28.04349988420079,1.266093357063074
0.00213254651742676,0.03935427085417083,446.36285946583723,28.04349988420079,1.266093357063074
0.002168968433020329,0.04002640528105621,447.9665004198934,28.04349988420079,1.266093357063074
0.0022105934794129788,0.04079455891178235,449.7864284591658,28.04349988420079,1.266093357063074
0.002277193553641218,0.042023604720944185,452.6707567151537,28.04349988420079,1.266093357063074
0.0022980060768375433,0.042407681536307265,453.5653374274174,28.04349988420079,1.266093357063074
0.002304249833796441,0.04252290458091619,453.83309475581393,28.04349988420079,1.266093357063074
0.0023146560953946032,0.04271494298859772,454.2787290294572,28.04349988420079,1.266093357063074
0.002338590497070377,0.04315663132626525,455.3007331555324,28.04349988420079,1.266093357063074
0.00237917491730321,0.04390558111622324,457.02442242848076,28.04349988420079,1.266093357063074
0.0024114343282575137,0.04450090018003601,458.38636790888967,28.04349988420079,1.266093357063074
0.0024155968328967783,0.04457771554310862,458.56158377190366,28.04349988420079,1.266093357063074
0.0024260030944949413,0.044769753950790164,458.9991090523592,28.04349988420079,1.266093357063074
0.0024374499822529196,0.04498099619923984,459.4795423496311,28.04349988420079,1.266093357063074
0.002446815617691266,0.04515383076615323,459.87196998099546,28.04349988420079,1.266093357063074
0.002467628140887591,0.04553790758151631,460.7419401016118,28.04349988420079,1.266093357063074
0.002475953150166121,0.04569153830766154,461.0891263257084,28.04349988420079,1.266093357063074
0.0025050906826409756,0.046229245849169834,462.30070905452413,28.04349988420079,1.266093357063074
0.0025560813644719717,0.04717023404680937,464.40783636113963,28.04349988420079,1.266093357063074
0.002585218896946826,0.04770794158831766,465.6045478917292,28.04349988420079,1.266093357063074
0.002625803317179659,0.04845689137827565,467.2626668622314,28.04349988420079,1.266093357063074
0.002639331457257271,0.04870654130826166,467.8131481373018,28.04349988420079,1.266093357063074
0.002652859597334882,0.048956191238247654,468.36253010387594,28.04349988420079,1.266093357063074
0.002689281512928451,0.04962832566513303,469.83623158898405,28.04349988420079,1.266093357063074
0.002729865933161284,0.05037727545509102,471.4692172525829,28.04349988420079,1.266093357063074
0.002754840960996874,0.05083816763352671,472.4694264911661,28.04349988420079,1.266093357063074
0.0027621253441155874,0.05097259451890378,472.76048722545937,28.04349988420079,1.266093357063074
0.002785019119631545,0.05139507901580316,473.673306695763,28.04349988420079,1.266093357063074
0.002795425381229707,0.051587117423484694,474.08725675452905,28.04349988420079,1.266093357063074
0.0028141566521064,0.05193278655731147,474.83085556745885,28.04349988420079,1.266093357063074
0.0028204004090652966,0.05204800960192038,475.07829255825965,28.04349988420079,1.266093357063074
0.0028474566892205196,0.052547309461892386,476.148060344169,28.04349988420079,1.266093357063074
0.0028703504647364765,0.052969793958791755,477.05015569578876,28.04349988420079,1.266093357063074
0.0029088536326496773,0.05368033606721344,478.5610134391567,28.04349988420079,1.266093357063074
0.002926544277366554,0.054006801360272055,479.2525743507249,28.04349988420079,1.266093357063074
0.0029681693237592036,0.0547749549909982,480.87337698094086,28.04349988420079,1.266093357063074
0.0029952256039144256,0.05527425485097019,481.92214709785105,28.04349988420079,1.266093357063074
0.003013956874791118,0.055619923984796954,482.6460553458763,28.04349988420079,1.266093357063074
0.0030295662671883617,0.05590798159631927,483.24797287134515,28.04349988420079,1.266093357063074
0.0030670288089417463,0.05659931986397279,484.6876614424138,28.04349988420079,1.266093357063074
0.0030711913135810114,0.05667613522704541,484.8472023623932,28.04349988420079,1.266093357063074
0.0030878413321380714,0.05698339667933587,485.48452454324166,28.04349988420079,1.266093357063074
0.0031044913506951314,0.05729065813162633,486.1205078820722,28.04349988420079,1.266093357063074
0.003119060116932559,0.057559511902380484,486.6759028760032,28.04349988420079,1.266093357063074
0.0031263445000512726,0.057693938787757554,486.95322090748067,28.04349988420079,1.266093357063074
0.0031398726401288836,0.05794358871774355,487.46757245998947,28.04349988420079,1.266093357063074
0.0031575632848457598,0.058270054010802166,488.1388838366362,28.04349988420079,1.266093357063074
0.0031679695464439223,0.0584620924184837,488.5330876972368,28.04349988420079,1.266093357063074
0.0031752539295626355,0.05859651930386077,488.8087299740527,28.04349988420079,1.266093357063074
0.00318253831268135,0.058730946189237854,489.08412574291305,28.04349988420079,1.266093357063074
0.0032075133405169397,0.05919183836767354,490.0264790930214,28.04349988420079,1.266093357063074
0.003239772751471243,0.0597871574314863,491.2394609648813,28.04349988420079,1.266093357063074
0.003261625900827384,0.06019043808761752,492.0584832688242,28.04349988420079,1.266093357063074
0.00327099153626573,0.06036327265453091,492.4088373763983,28.04349988420079,1.266093357063074
0.0032834790501835246,0.06059371874374875,492.87536821702804,28.04349988420079,1.266093357063074
0.003331347853535072,0.06147709541908382,494.6573625529844,28.04349988420079,1.266093357063074
0.0033490384982519487,0.061803560712142436,495.31339485190347,28.04349988420079,1.266093357063074
0.0033656885168090083,0.062110822164432894,495.9296035219591,28.04349988420079,1.266093357063074
0.0033937854231240465,0.06262932586517303,496.96676661310846,28.04349988420079,1.266093357063074
0.003396907301603495,0.06268693738747749,497.0817998693723,28.04349988420079,1.266093357063074
0.003416679198640004,0.06305181036207241,497.8093886960251,28.04349988420079,1.266093357063074
0.00345934487119247,0.06383916783356672,499.37387738494704,28.04349988420079,1.266093357063074
0.00348431989902806,0.0643000600120024,500.2861839079612,28.04349988420079,1.266093357063074
0.0034957667867860386,0.0645113022604521,500.7034717331577,28.04349988420079,1.266093357063074
0.0035353105808590556,0.06524104820964192,502.14092901536486,28.04349988420079,1.266093357063074
0.0035394730854983207,0.06531786357271455,502.29187463421766,28.04349988420079,1.266093357063074
0.0035623668610142785,0.06574034806961393,503.1208413374008,28.04349988420079,1.266093357063074
0.003574854374932073,0.06597079415883177,503.5721291816751,28.04349988420079,1.266093357063074
0.003582138758050786,0.06610522104420884,503.83509650631004,28.04349988420079,1.266093357063074
0.0036029512812471116,0.06648929785957192,504.585285006794,28.04349988420079,1.266093357063074
0.0036310481875621503,0.06700780156031207,505.595364126129,28.04349988420079,1.266093357063074
0.0036476982061192102,0.06731506301260252,506.19249119665824,28.04349988420079,1.266093357063074
0.0036789169909136974,0.06789117823564714,507.3092471838807,28.04349988420079,1.266093357063074
0.003690363878671676,0.06810242048409683,507.7177975732244,28.04349988420079,1.266093357063074
0.003693485757151124,0.06816003200640128,507.8291345934942,28.04349988420079,1.266093357063074
0.003707013897228736,0.06840968193638729,508.31117153066066,28.04349988420079,1.266093357063074
0.003735110803543774,0.06892818563712742,509.31013856597417,28.04349988420079,1.266093357063074
0.0037580045790597317,0.0693506701340268,510.12194659964007,28.04349988420079,1.266093357063074
0.003764248336018629,0.06946589317863573,510.3430137564562,28.04349988420079,1.266093357063074
0.0037850608592149538,0.0698499699939988,511.0788736314449,28.04349988420079,1.266093357063074
0.0038027515039318303,0.07017643528705741,511.7031146591494,28.04349988420079,1.266093357063074
0.003814198391689809,0.0703876775355071,512.1064318993581,28.04349988420079,1.266093357063074
0.003848539054963745,0.07102140428085618,513.313560752859,28.04349988420079,1.266093357063074
0.003862067195041356,0.07127105421084218,513.7879420840671,28.04349988420079,1.266093357063074
0.0038880828490367616,0.07175115023004601,514.6983963795011,28.04349988420079,1.266093357063074
0.003913057876872352,0.0722120424084817,515.570199906377,28.04349988420079,1.266093357063074
0.003921382886150882,0.07236567313462693,515.8603184925576,28.04349988420079,1.266093357063074
0.003956764175584633,0.07301860372074415,517.090652298834,28.04349988420079,1.266093357063074
0.003976536072621143,0.07338347669533907,517.7763228046616,28.04349988420079,1.266093357063074
0.0040077548574156295,0.07395959191838368,518.8562595496473,28.04349988420079,1.266093357063074
0.00401607986669416,0.07411322264452891,519.1436879651156,28.04349988420079,1.266093357063074
0.0040525017822877285,0.07478535707141429,520.398465047887,28.04349988420079,1.266093357063074
0.004078517436283135,0.07526545309061813,521.292043127889,28.04349988420079,1.266093357063074
0.004083720567082216,0.0753614722944589,521.4704916899045,28.04349988420079,1.266093357063074
0.004113898725716887,0.07591838367673535,522.5037501039704,28.04349988420079,1.266093357063074
0.0041461581366711905,0.07651370274054811,523.6050042321274,28.04349988420079,1.266093357063074
0.004168011286027331,0.07691698339667934,524.3491171568435,28.04349988420079,1.266093357063074
0.004190905061543289,0.07733946789357872,525.1270339106202,28.04349988420079,1.266093357063074
0.004201311323141451,0.07753150630126025,525.4800843849571,28.04349988420079,1.266093357063074
0.004245017621853733,0.0783380676135227,526.9591875488436,28.04349988420079,1.266093357063074
0.004249180126492998,0.07841488297659532,527.0997440439156,28.04349988420079,1.266093357063074
0.00430953644376234,0.07952870574114823,529.1318166212842,28.04349988420079,1.266093357063074
0.004323064583839951,0.07977835567113423,529.5857549339926,28.04349988420079,1.266093357063074
0.004340755228556828,0.08010482096419284,530.1785315403191,28.04349988420079,1.266093357063074
0.004358445873273704,0.08043128625725146,530.7703667115887,28.04349988420079,1.266093357063074
0.004365730256392418,0.08056571314262853,531.0137911536237,28.04349988420079,1.266093357063074
0.004368852134871867,0.080623324664933,531.1180674179813,28.04349988420079,1.266093357063074
0.004377177144150396,0.08077695539107822,531.3959954822174,28.04349988420079,1.266093357063074
0.004380299022629845,0.08083456691338269,531.5001653481553,28.04349988420079,1.266093357063074
0.004412558433584148,0.08142988597719544,532.5748972754706,28.04349988420079,1.266093357063074
0.004432330330620657,0.08179475895179036,533.2320894933677,28.04349988420079,1.266093357063074
0.00446458974157496,0.08239007801560312,534.3019012655075,28.04349988420079,1.266093357063074
0.004496849152529264,0.08298539707941589,535.3687025310022,28.04349988420079,1.266093357063074
0.004507255414127427,0.08317743548709743,535.712194737088,28.04349988420079,1.266093357063074
0.004519742928045221,0.08340788157631526,536.1239773937749,28.04349988420079,1.266093357063074
0.004537433572762098,0.08373434686937388,536.7065774315819,28.04349988420079,1.266093357063074
0.004552002338999525,0.08400320064012803,537.1857008234421,28.04349988420079,1.266093357063074
0.004572814862195849,0.0843872774554911,537.8691266927796,28.04349988420079,1.266093357063074
0.00457801799299493,0.08448329665933187,538.0397934810318,28.04349988420079,1.266093357063074
0.00460299302083052,0.08494418883776755,538.8579433691481,28.04349988420079,1.266093357063074
0.004617561787067948,0.08521304260852171,539.3343979691117,28.04349988420079,1.266093357063074
0.00464461806722317,0.0857123424684937,540.2176897157248,28.04349988420079,1.266093357063074
0.004674796225857841,0.08626925385077015,541.2005357498934,28.04349988420079,1.266093357063074
0.0046862431136158195,0.08648049609921984,541.5726917265173,28.04349988420079,1.266093357063074
0.004696649375213983,0.08667253450690139,541.9107078067107,28.04349988420079,1.266093357063074
0.0047195431507299395,0.08709501900380076,542.6533167510029,28.04349988420079,1.266093357063074
0.004798630738875974,0.08855451090218044,545.2079527358653,28.04349988420079,1.266093357063074
0.004856905803825684,0.08962992598519705,547.0798210688118,28.04349988420079,1.266093357063074
0.004882921457821089,0.09011002200440088,547.9126464281031,28.04349988420079,1.266093357063074
0.004923505878053924,0.09085897179435888,549.2084068271046,28.04349988420079,1.266093357063074
0.004939115270451167,0.09114702940588118,549.7056662046502,28.04349988420079,1.266093357063074
0.004962009045967125,0.09156951390278056,550.4338727394307,28.04349988420079,1.266093357063074
0.004994268456921427,0.09216483296659332,551.4577618404569,28.04349988420079,1.266093357063074
0.0050088372231588555,0.09243368673734748,551.91931759096,28.04349988420079,1.266093357063074
0.005024446615556098,0.09272174434886978,552.4132609913214,28.04349988420079,1.266093357063074
0.005033812250994445,0.09289457891578316,552.7093397760981,28.04349988420079,1.266093357063074
0.005056706026510403,0.09331706341268255,553.432184923239,28.04349988420079,1.266093357063074
0.005092087315944155,0.09396999399879977,554.5468038566515,28.04349988420079,1.266093357063074
0.005102493577542317,0.0941620324064813,554.8740576019898,28.04349988420079,1.266093357063074
0.005140996745455518,0.09487257451490298,556.0826398613316,28.04349988420079,1.266093357063074
0.005160768642492027,0.0952374474894979,556.7018910395205,28.04349988420079,1.266093357063074
0.005174296782569638,0.0954870974194839,557.1250561966685,28.04349988420079,1.266093357063074
0.005182621791848168,0.09564072814562913,557.3852510696532,28.04349988420079,1.266093357063074
0.005203434315044493,0.09602480496099221,558.0350261261082,28.04349988420079,1.266093357063074
0.005230490595199715,0.0965241048209642,558.8782203981582,28.04349988420079,1.266093357063074
0.005255465623035305,0.09698499699939989,559.6550449983565,28.04349988420079,1.266093357063074
0.005260668753834386,0.09708101620324065,559.8167020917758,28.04349988420079,1.266093357063074
0.005290846912469057,0.0976379275855171,560.7530864914041,28.04349988420079,1.266093357063074
0.005303334426386852,0.09786837367473496,561.139946337897,28.04349988420079,1.266093357063074
0.005349121977418767,0.09871334266853371,562.5554031876674,28.04349988420079,1.266093357063074
0.005372015752934724,0.0991358271654331,563.2613590677387,28.04349988420079,1.266093357063074
0.005379300136053438,0.09927025405081016,563.4857352048498,28.04349988420079,1.266093357063074
0.005413640799327374,0.09990398079615924,564.5419164624969,28.04349988420079,1.266093357063074
0.005417803303966638,0.09998079615923185,564.6697606410912,28.04349988420079,1.266093357063074