File: datasets/aisi_316_L/data/M1/valid_11.csv
Time(s),Strain(%),Stress(MPa),Temp(C),Log_SR(s-1)
0.0,0.0,0.0,441.8502130723463,3.737279834022938
3.95524979890221e-09,2.16e-05,3.5801379,441.8502130723463,3.737279834022938
5.420157131828953e-09,2.9599999999999998e-05,4.9061148999999995,441.8502130723463,3.737279834022938
7.91049959780442e-09,4.32e-05,7.1602758,441.8502130723463,3.737279834022938
9.375406930731163e-09,5.12e-05,8.486252799999999,441.8502130723463,3.737279834022938
1.0400842063779884e-08,5.68e-05,9.4144367,441.8502130723463,3.737279834022938
1.4356091862682093e-08,7.84e-05,12.9945746,441.8502130723463,3.737279834022938
1.5381526995730815e-08,8.4e-05,13.922758499999999,441.8502130723463,3.737279834022938
2.094817486085244e-08,0.00011439999999999999,18.961471099999997,441.8502130723463,3.737279834022938
2.2999045126949884e-08,0.0001256,20.817838899999998,441.8502130723463,3.737279834022938
2.475693392646198e-08,0.0001352,22.4090113,441.8502130723463,3.737279834022938
2.6954294925852095e-08,0.0001472,24.3979768,441.8502130723463,3.737279834022938
3.003060032499826e-08,0.000164,27.1825285,441.8502130723463,3.737279834022938
3.193497985780302e-08,0.00017439999999999998,28.906298599999996,441.8502130723463,3.737279834022938
4.1310386788534186e-08,0.00022559999999999998,37.392551399999995,441.8502130723463,3.737279834022938
5.127175665243605e-08,0.00028,46.409195,441.8502130723463,3.737279834022938
5.464104351816756e-08,0.0002984,49.4589421,441.8502130723463,3.737279834022938
5.771734891731372e-08,0.00031519999999999996,52.243493799999996,441.8502130723463,3.737279834022938
6.064716358316721e-08,0.0003312,54.89544779999999,441.8502130723463,3.737279834022938
6.445592264877675e-08,0.000352,58.342988,441.8502130723463,3.737279834022938
6.899713538084966e-08,0.0003768,62.4535167,441.8502130723463,3.737279834022938
7.456378324597127e-08,0.0004072,67.49222929999999,441.8502130723463,3.737279834022938
7.778657937841012e-08,0.00042479999999999997,70.40937869999999,441.8502130723463,3.737279834022938
8.056990331097093e-08,0.00043999999999999996,72.92873499999999,441.8502130723463,3.737279834022938
8.452515310987314e-08,0.0004616,76.5088729,441.8502130723463,3.737279834022938
8.672251410926325e-08,0.00047359999999999997,78.49783839999999,441.8502130723463,3.737279834022938
8.745496777572663e-08,0.00047759999999999995,79.16082689999999,441.8502130723463,3.737279834022938
9.023829170828744e-08,0.0004927999999999999,81.68018319999999,441.8502130723463,3.737279834022938
9.39005600406043e-08,0.0005128,84.9951257,441.8502130723463,3.737279834022938
9.4486522973775e-08,0.000516,85.5255165,441.8502130723463,3.737279834022938
9.653739323987245e-08,0.0005272,87.38188430000001,441.8502130723463,3.737279834022938
1.0107860597194534e-07,0.000552,91.492413,441.8502130723463,3.737279834022938
1.0283649477145745e-07,0.0005616,93.0835854,441.8502130723463,3.737279834022938
1.0664525383706697e-07,0.0005824,96.5311256,441.8502130723463,3.737279834022938
1.122119017021886e-07,0.0006127999999999999,101.56983819999999,441.8502130723463,3.737279834022938
1.1499522563474942e-07,0.000628,104.08919449999999,441.8502130723463,3.737279834022938
1.168996051675542e-07,0.0006384,105.8129646,441.8502130723463,3.737279834022938
1.1895047543365163e-07,0.0006496,107.66933239999999,441.8502130723463,3.737279834022938
1.2012240129999304e-07,0.000656,108.730114,441.8502130723463,3.737279834022938
1.2407765109889524e-07,0.0006776,112.3102519,441.8502130723463,3.737279834022938
1.3184165996340697e-07,0.0007199999999999999,119.33792999999999,441.8502130723463,3.737279834022938
1.3652936342877256e-07,0.0007456,123.58105640000001,441.8502130723463,3.737279834022938
1.3828725222828466e-07,0.0007551999999999999,125.17222879999998,441.8502130723463,3.737279834022938
1.387267244281627e-07,0.0007576,125.5700219,441.8502130723463,3.737279834022938
1.3945917809462604e-07,0.0007616,126.2330104,441.8502130723463,3.737279834022938
1.4268197422706488e-07,0.0007792,129.15015979999998,441.8502130723463,3.737279834022938
1.454652981596257e-07,0.0007944,131.6695161,441.8502130723463,3.737279834022938
1.4927405722523523e-07,0.0008152,135.1170563,441.8502130723463,3.737279834022938
1.522038718910887e-07,0.0008311999999999999,137.7690103,441.8502130723463,3.737279834022938
1.5264334409096676e-07,0.0008336,138.1668034,441.8502130723463,3.737279834022938
1.5586614022340558e-07,0.0008512,141.0839528,441.8502130723463,3.737279834022938
1.5777051975621034e-07,0.0008615999999999999,142.8077229,441.8502130723463,3.737279834022938
1.6216524175499059e-07,0.0008856,146.7856539,441.8502130723463,3.737279834022938
1.6685294522035615e-07,0.0009111999999999999,151.0287803,441.8502130723463,3.737279834022938
1.7051521355267303e-07,0.0009312,154.3437228,441.8502130723463,3.737279834022938
1.7198012088559978e-07,0.0009392,155.6696998,441.8502130723463,3.737279834022938
1.735915189518192e-07,0.000948,157.1282745,441.8502130723463,3.737279834022938
1.8062307414986754e-07,0.0009864,160.1585790779652,441.8502130723463,3.737279834022938
1.8296692588255035e-07,0.0009992,160.22545225747183,441.8502130723463,3.737279834022938
1.8589674054840383e-07,0.0010152,160.30857575153448,441.8502130723463,3.737279834022938
1.9043795328047674e-07,0.00104,160.43641448496956,441.8502130723463,3.737279834022938
1.9366074941291558e-07,0.0010576,160.5264184717978,441.8502130723463,3.737279834022938
1.9556512894572034e-07,0.001068,160.57932809120985,441.8502130723463,3.737279834022938
1.9629758261218374e-07,0.001072,160.59962439323527,441.8502130723463,3.737279834022938
2.0069230461096396e-07,0.001096,160.72078769295092,441.8502130723463,3.737279834022938
2.0538000807632953e-07,0.0011216,160.8488935250456,441.8502130723463,3.737279834022938
2.0728438760913431e-07,0.001132,160.90061017320798,441.8502130723463,3.737279834022938
2.125580540076706e-07,0.0011608,161.04286729964113,441.8502130723463,3.737279834022938
2.1402296134059735e-07,0.0011688,161.08213802113644,441.8502130723463,3.737279834022938
2.182711926060849e-07,0.001192,161.1954346135425,441.8502130723463,3.737279834022938
2.198825906723043e-07,0.0012008,161.23818380125076,441.8502130723463,3.737279834022938
2.2120100727193836e-07,0.0012079999999999999,161.2730696037308,441.8502130723463,3.737279834022938
2.233983682713285e-07,0.00122,161.33103294049826,441.8502130723463,3.737279834022938
2.337992103351084e-07,0.0012768,161.60243125219932,441.8502130723463,3.737279834022938
2.45225487531937e-07,0.0013392,161.89521459277154,441.8502130723463,3.737279834022938
2.490342465975465e-07,0.0013599999999999999,161.99162016787523,441.8502130723463,3.737279834022938
2.507921353970586e-07,0.0013696,162.0359209368505,441.8502130723463,3.737279834022938
2.535754593296194e-07,0.0013847999999999998,162.10581695077425,441.8502130723463,3.737279834022938
2.5679825546205827e-07,0.0014024,162.18637646162034,441.8502130723463,3.737279834022938
2.588491257281557e-07,0.0014135999999999999,162.23743637453956,441.8502130723463,3.737279834022938
2.613394681941312e-07,0.0014272,162.29922607795746,441.8502130723463,3.737279834022938
2.6368331992681393e-07,0.0014399999999999999,162.35717165558458,441.8502130723463,3.737279834022938
2.6602717165949674e-07,0.0014528,162.41491669984543,441.8502130723463,3.737279834022938
2.6998242145839896e-07,0.0014743999999999998,162.5119135459526,441.8502130723463,3.737279834022938
2.7174031025791103e-07,0.0014839999999999999,162.55484519967135,441.8502130723463,3.737279834022938
2.736446897907158e-07,0.0014944,162.6012324466812,441.8502130723463,3.737279834022938
2.759885415233986e-07,0.0015072,162.65815196874635,441.8502130723463,3.737279834022938
2.7891835618925207e-07,0.0015232,162.72903695398406,441.8502130723463,3.737279834022938
2.799437913223008e-07,0.0015287999999999999,162.7537780168493,441.8502130723463,3.737279834022938
2.833130781880323e-07,0.0015471999999999999,162.83482236210574,441.8502130723463,3.737279834022938
2.8492447625425173e-07,0.0015559999999999999,162.8734497498266,441.8502130723463,3.737279834022938
2.868288557870565e-07,0.0015664,162.91899062840352,441.8502130723463,3.737279834022938
2.8829376311998326e-07,0.0015743999999999999,162.95394187671977,441.8502130723463,3.737279834022938
2.896121797196173e-07,0.0015815999999999998,162.98533882466074,441.8502130723463,3.737279834022938
2.9620426271778765e-07,0.0016175999999999999,163.1414951163855,441.8502130723463,3.737279834022938
3.008919661831532e-07,0.0016431999999999998,163.25171605895912,441.8502130723463,3.737279834022938
3.0264985498266534e-07,0.0016527999999999998,163.29287599742673,441.8502130723463,3.737279834022938
3.054331789152262e-07,0.001668,163.3578557284341,441.8502130723463,3.737279834022938
3.067515955148602e-07,0.0016752,163.38855496099592,441.8502130723463,3.737279834022938
3.1422262291278663e-07,0.0017159999999999999,163.56155498994767,441.8502130723463,3.737279834022938
3.1524805804583535e-07,0.0017216,163.58517427287055,441.8502130723463,3.737279834022938
3.1744541904522545e-07,0.0017335999999999999,163.6356863624734,441.8502130723463,3.737279834022938
3.189103263781522e-07,0.0017415999999999998,163.66928535317982,441.8502130723463,3.737279834022938
3.224261039771764e-07,0.0017607999999999999,163.7496782962335,441.8502130723463,3.737279834022938
3.2418399277668846e-07,0.0017703999999999999,163.78974650980496,441.8502130723463,3.737279834022938
3.2711380744254196e-07,0.0017863999999999998,163.85633907630947,441.8502130723463,3.737279834022938
3.285787147754687e-07,0.0017943999999999998,163.8895481007388,441.8502130723463,3.737279834022938
3.2975064064181014e-07,0.0018008,163.9160737649115,441.8502130723463,3.737279834022938
3.3238747384107827e-07,0.0018151999999999999,163.97562245189587,441.8502130723463,3.737279834022938
3.3429185337388305e-07,0.0018256,164.01851531721067,441.8502130723463,3.737279834022938
3.356102699735171e-07,0.0018327999999999999,164.0481545696073,441.8502130723463,3.737279834022938
3.3648921437327315e-07,0.0018376,164.0678888475243,441.8502130723463,3.737279834022938
3.4103042710534606e-07,0.0018624,164.16953078418769,441.8502130723463,3.737279834022938
3.436672603046142e-07,0.0018767999999999999,164.22830644804455,441.8502130723463,3.737279834022938
3.442532232377849e-07,0.00188,164.24134379182513,441.8502130723463,3.737279834022938
3.46011112037297e-07,0.0018896,164.2804039945353,441.8502130723463,3.737279834022938
3.4747601937022375e-07,0.0018976,164.3128950790891,441.8502130723463,3.737279834022938
3.479154915701018e-07,0.0019,164.32263198161033,441.8502130723463,3.737279834022938
3.492339081697358e-07,0.0019072,164.35181394962254,441.8502130723463,3.737279834022938
3.5274968576876e-07,0.0019264,164.42942324178694,441.8502130723463,3.737279834022938
3.5860931510046696e-07,0.0019584,164.55810501048157,441.8502130723463,3.737279834022938
3.624180741660765e-07,0.0019792,164.6413086392054,441.8502130723463,3.737279834022938
3.7076804596375894e-07,0.0020247999999999998,164.82253251128446,441.8502130723463,3.737279834022938
3.738443513629051e-07,0.0020415999999999998,164.888897064335,441.8502130723463,3.737279834022938
3.7692065676205126e-07,0.0020583999999999997,164.95504897562438,441.8502130723463,3.737279834022938
3.8497764709314836e-07,0.0021024,165.12731366161705,441.8502130723463,3.737279834022938
3.8746798955912383e-07,0.002116,165.18027389015964,441.8502130723463,3.737279834022938
3.9274165595766014e-07,0.0021448,165.29198873649386,441.8502130723463,3.737279834022938
3.947925262237576e-07,0.002156,165.33527521365755,441.8502130723463,3.737279834022938
4.002126833555865e-07,0.0021855999999999998,165.44925511316399,441.8502130723463,3.737279834022938
4.019705721550986e-07,0.0021952,165.48609207000496,441.8502130723463,3.737279834022938
4.0460740535436675e-07,0.0022096,165.54122992359808,441.8502130723463,3.737279834022938
4.106135254193664e-07,0.0022424,165.66630121180356,441.8502130723463,3.737279834022938
4.1237141421887853e-07,0.002252,165.70277220586013,441.8502130723463,3.737279834022938
4.138363215518052e-07,0.00226,165.73311840650345,441.8502130723463,3.737279834022938
4.183775342838782e-07,0.0022848,165.82692648636817,441.8502130723463,3.737279834022938
4.2145383968302435e-07,0.0023016,165.89024838323724,441.8502130723463,3.737279834022938
4.251161080153412e-07,0.0023216,165.965397043822,441.8502130723463,3.737279834022938
4.2614154314838986e-07,0.0023271999999999998,165.9863933698446,441.8502130723463,3.737279834022938
4.2877837634765805e-07,0.0023416,166.04029364349435,441.8502130723463,3.737279834022938
4.3097573734704815e-07,0.0023536,166.0851118594407,441.8502130723463,3.737279834022938
4.3463800567936505e-07,0.0023736,166.15961135071095,441.8502130723463,3.737279834022938
4.3712834814534046e-07,0.0023872,166.21013121940956,441.8502130723463,3.737279834022938
4.3932570914473056e-07,0.0023991999999999998,166.25461443222258,441.8502130723463,3.737279834022938
4.4210903307729135e-07,0.0024143999999999997,166.3108354676647,441.8502130723463,3.737279834022938
4.4606428287619357e-07,0.002436,166.3904916416803,441.8502130723463,3.737279834022938
4.47236208742535e-07,0.0024424,166.4140405084636,441.8502130723463,3.737279834022938
4.5060549560826654e-07,0.0024608,166.48160981914612,441.8502130723463,3.737279834022938
4.5324232880753466e-07,0.0024752,166.53435280075976,441.8502130723463,3.737279834022938
4.5880897667265624e-07,0.0025055999999999998,166.6453077183365,441.8502130723463,3.737279834022938
4.648150967376559e-07,0.0025383999999999997,166.76443504138254,441.8502130723463,3.737279834022938
4.687703465365581e-07,0.0025599999999999998,166.8425570484505,441.8502130723463,3.737279834022938
4.7565541100131384e-07,0.0025976,166.9779367349866,441.8502130723463,3.737279834022938
4.7638786466777724e-07,0.0026016,166.9922937095295,441.8502130723463,3.737279834022938
4.79171188600338e-07,0.0026168,167.04677187925765,441.8502130723463,3.737279834022938
4.812220588664354e-07,0.0026279999999999997,167.08683475114583,441.8502130723463,3.737279834022938
4.85909762331801e-07,0.0026536,167.1781578204826,441.8502130723463,3.737279834022938
4.879606325978985e-07,0.0026647999999999997,167.21800354863515,441.8502130723463,3.737279834022938
4.888395769976545e-07,0.0026696,167.2350602895903,441.8502130723463,3.737279834022938
4.903044843305813e-07,0.0026776,167.26346163593368,441.8502130723463,3.737279834022938
4.957246414624102e-07,0.0027072,167.3682601009503,441.8502130723463,3.737279834022938
4.993869097947271e-07,0.0027272,167.43881701253466,441.8502130723463,3.737279834022938
5.012912893275319e-07,0.0027375999999999998,167.4754268394236,441.8502130723463,3.737279834022938
5.113991499247264e-07,0.0027928,167.66884003257596,441.8502130723463,3.737279834022938
5.119851128578971e-07,0.002796,167.68000645131127,441.8502130723463,3.737279834022938
5.172587792564334e-07,0.0028247999999999997,167.78028092850812,441.8502130723463,3.737279834022938
5.194561402558235e-07,0.0028368,167.82194419352498,441.8502130723463,3.737279834022938
5.238508622546037e-07,0.0028607999999999997,167.9050650931682,441.8502130723463,3.737279834022938
5.253157695875304e-07,0.0028688,167.9327115668764,441.8502130723463,3.737279834022938
5.267806769204572e-07,0.0028767999999999997,167.96032798960732,441.8502130723463,3.737279834022938
5.310289081859447e-07,0.0029,168.04024674620834,441.8502130723463,3.737279834022938
5.336657413852129e-07,0.0029143999999999997,168.0897260955156,441.8502130723463,3.737279834022938
5.390858985170419e-07,0.002944,168.19113522499242,441.8502130723463,3.737279834022938
5.414297502497246e-07,0.0029568,168.23486457935735,441.8502130723463,3.737279834022938
5.48900777647651e-07,0.0029976,168.37376173208838,441.8502130723463,3.737279834022938
5.519770830467973e-07,0.0030144,168.43074014513667,441.8502130723463,3.737279834022938
5.550533884459434e-07,0.0030312,168.48759484552585,441.8502130723463,3.737279834022938
5.578367123785041e-07,0.0030464,168.53892900663277,441.8502130723463,3.737279834022938
5.620849436439917e-07,0.0030696,168.61708897837283,441.8502130723463,3.737279834022938
5.650147583098452e-07,0.0030856,168.67085822629707,441.8502130723463,3.737279834022938
5.675051007758207e-07,0.0030992,168.71647664748912,441.8502130723463,3.737279834022938
5.707278969082595e-07,0.0031168,168.7753965270236,441.8502130723463,3.737279834022938
5.749761281737471e-07,0.00314,168.8528657674973,441.8502130723463,3.737279834022938
5.792243594392346e-07,0.0031631999999999997,168.93011209702684,441.8502130723463,3.737279834022938
5.803962853055761e-07,0.0031696,168.9513825051464,441.8502130723463,3.737279834022938
5.820076833717955e-07,0.0031784,168.98060198694918,441.8502130723463,3.737279834022938
5.842050443711856e-07,0.0031904,169.02039593944784,441.8502130723463,3.737279834022938
5.868418775704537e-07,0.0032048,169.06807171209607,441.8502130723463,3.737279834022938
5.884532756366731e-07,0.0032136,169.09716578093847,441.8502130723463,3.737279834022938
5.909436181026486e-07,0.0032272,169.1420683010552,441.8502130723463,3.737279834022938
5.92994488368746e-07,0.0032384,169.1789914604921,441.8502130723463,3.737279834022938
5.935804513019168e-07,0.0032416,169.18953178290977,441.8502130723463,3.737279834022938
5.951918493681361e-07,0.0032503999999999996,169.21849676638064,441.8502130723463,3.737279834022938
5.972427196342336e-07,0.0032616,169.25531709718487,441.8502130723463,3.737279834022938
6.013444601664285e-07,0.003284,169.32881016013442,441.8502130723463,3.737279834022938
6.041277840989893e-07,0.0032992,169.37856914457362,441.8502130723463,3.737279834022938
6.052997099653307e-07,0.0033055999999999997,169.39949353905865,441.8502130723463,3.737279834022938
6.061786543650867e-07,0.0033104,169.41517646799232,441.8502130723463,3.737279834022938
6.098409226974036e-07,0.0033304,169.4804267743893,441.8502130723463,3.737279834022938
6.111593392970377e-07,0.0033376,169.5038794513578,441.8502130723463,3.737279834022938
6.135031910297204e-07,0.0033504,169.5455244383099,441.8502130723463,3.737279834022938
6.140891539628912e-07,0.0033536,169.55592598409734,441.8502130723463,3.737279834022938
6.184838759616714e-07,0.0033775999999999997,169.63381457154142,441.8502130723463,3.737279834022938
6.222926350272809e-07,0.0033983999999999998,169.7011435832719,441.8502130723463,3.737279834022938
6.278592828924025e-07,0.0034287999999999996,169.79925914571245,441.8502130723463,3.737279834022938
6.302031346250854e-07,0.0034416,169.84046939836128,441.8502130723463,3.737279834022938
6.324004956244754e-07,0.0034536,169.87904975576623,441.8502130723463,3.737279834022938
6.337189122241095e-07,0.0034608,169.902172876356,441.8502130723463,3.737279834022938
6.354768010236216e-07,0.0034704,169.93297454045737,441.8502130723463,3.737279834022938
6.369417083565484e-07,0.0034784,169.95861721807594,441.8502130723463,3.737279834022938
6.389925786226458e-07,0.0034896,169.99447835951372,441.8502130723463,3.737279834022938
6.41629411821914e-07,0.0035039999999999997,170.04051965242417,441.8502130723463,3.737279834022938
6.432408098881334e-07,0.0035128,170.0686196735072,441.8502130723463,3.737279834022938
6.449986986876455e-07,0.0035223999999999997,170.09924294970568,441.8502130723463,3.737279834022938
6.457311523541088e-07,0.0035264,170.11199303942058,441.8502130723463,3.737279834022938
6.476355318869136e-07,0.0035367999999999997,170.14511690381252,441.8502130723463,3.737279834022938
6.495399114197184e-07,0.0035472,170.17820280348545,441.8502130723463,3.737279834022938
6.515907816858158e-07,0.0035583999999999998,170.21379149211933,441.8502130723463,3.737279834022938
6.55985503684596e-07,0.0035824,170.2899061966715,441.8502130723463,3.737279834022938
6.580363739506935e-07,0.0035935999999999997,170.32535831014005,441.8502130723463,3.737279834022938
6.619916237495958e-07,0.0036152,170.3936087889698,441.8502130723463,3.737279834022938
6.646284569488638e-07,0.0036295999999999998,170.43902077660078,441.8502130723463,3.737279834022938
6.650679291487419e-07,0.003632,170.44658260469825,441.8502130723463,3.737279834022938
6.658003828152052e-07,0.003636,170.4591813224058,441.8502130723463,3.737279834022938
6.737108824130097e-07,0.0036791999999999997,170.5949048239965,441.8502130723463,3.737279834022938
6.742968453461803e-07,0.0036823999999999997,170.60493362425458,441.8502130723463,3.737279834022938
6.770801692787412e-07,0.0036975999999999997,170.6525240876258,441.8502130723463,3.737279834022938
6.788380580782533e-07,0.0037072,170.68254191524233,441.8502130723463,3.737279834022938
6.819143634773994e-07,0.003724,170.73500026832838,441.8502130723463,3.737279834022938
6.848441781432529e-07,0.00374,170.7848748639024,441.8502130723463,3.737279834022938
6.890924094087405e-07,0.0037632,170.85704547393075,441.8502130723463,3.737279834022938
6.92461696274472e-07,0.0037816,170.91416092369582,441.8502130723463,3.737279834022938
6.948055480071548e-07,0.0037944,170.95382950374446,441.8502130723463,3.737279834022938
7.005186866055691e-07,0.0038255999999999997,171.0503036564739,441.8502130723463,3.737279834022938
7.016906124719105e-07,0.003832,171.0700552444492,441.8502130723463,3.737279834022938
7.057923530041053e-07,0.0038544,171.13908471603895,441.8502130723463,3.737279834022938
7.100405842695929e-07,0.0038775999999999997,171.2104147906965,441.8502130723463,3.737279834022938
7.137028526019098e-07,0.0038975999999999998,171.27177274949167,441.8502130723463,3.737279834022938
7.176581024008119e-07,0.003919199999999999,171.337901588909,441.8502130723463,3.737279834022938
7.217598429330069e-07,0.0039416,171.40632968645568,441.8502130723463,3.737279834022938
7.283519259311772e-07,0.0039775999999999995,171.5159865349847,441.8502130723463,3.737279834022938
7.314282313303233e-07,0.0039943999999999995,171.56702720572937,441.8502130723463,3.737279834022938
7.570690327297947e-07,0.0041344268853770755,171.98923900150197,441.8502130723463,3.737279834022938
8.133327270530464e-07,0.004441688337667534,172.89662754707857,441.8502130723463,3.737279834022938
8.449810551098755e-07,0.0046145229045809165,173.39626375905462,441.8502130723463,3.737279834022938
9.364095583851594e-07,0.005113822764552911,174.8002015231364,441.8502130723463,3.737279834022938
1.027838061660443e-06,0.005613122624524905,176.15158628071387,441.8502130723463,3.737279834022938
1.0946511986693046e-06,0.005977995599119824,177.10964002401982,441.8502130723463,3.737279834022938
1.1227830458309303e-06,0.006131626325265053,177.50617512010325,441.8502130723463,3.737279834022938
1.179046740154182e-06,0.006438887777555511,178.28780652808857,441.8502130723463,3.737279834022938
1.2458598771630433e-06,0.00680376075215043,179.19734162311326,441.8502130723463,3.737279834022938
1.2704752434294659e-06,0.006938187637527506,179.52761168606418,441.8502130723463,3.737279834022938
1.3232224568575142e-06,0.0072262452490498095,180.2270445938336,441.8502130723463,3.737279834022938
1.3619037467047497e-06,0.0074374874974994995,180.73306929353086,441.8502130723463,3.737279834022938
1.5025629825128789e-06,0.008205641128225645,182.52769851465547,441.8502130723463,3.737279834022938
1.551793715045724e-06,0.008474494898979796,183.14017109089258,441.8502130723463,3.737279834022938
1.6467386992162112e-06,0.008992998599719944,184.3003759385475,441.8502130723463,3.737279834022938
1.6994859126442595e-06,0.009281056211242249,184.93364992164277,441.8502130723463,3.737279834022938
1.7698155305483242e-06,0.009665133026605321,185.76621626413123,441.8502130723463,3.737279834022938
1.79794737770995e-06,0.00981876375275055,186.09561741575456,441.8502130723463,3.737279834022938
1.8717934765092174e-06,0.010222044408881775,186.95087021130118,441.8502130723463,3.737279834022938
2.0089362314221436e-06,0.010970994198839769,188.50506171339296,441.8502130723463,3.737279834022938
2.0862988111166147e-06,0.011393478695739149,189.36351182577454,441.8502130723463,3.737279834022938
2.12498010096385e-06,0.011604720944188837,189.7880743479714,441.8502130723463,3.737279834022938
2.216408604239134e-06,0.012104020804160832,190.77977978108575,441.8502130723463,3.737279834022938
2.265639336771979e-06,0.012372874574914983,191.30716026818808,441.8502130723463,3.737279834022938
2.2761887794575888e-06,0.012430486097219444,191.41958674903935,441.8502130723463,3.737279834022938
2.325419511990434e-06,0.012699339867973595,191.94157999764235,441.8502130723463,3.737279834022938
2.4133315343705147e-06,0.013179435887177435,192.86311474987045,441.8502130723463,3.737279834022938
2.5047600376457986e-06,0.01367873574714943,193.8077265212534,441.8502130723463,3.737279834022938
2.5153094803314084e-06,0.013736347269453891,193.9158479445136,441.8502130723463,3.737279834022938
2.5539907701786437e-06,0.013947589517903581,194.3107890751772,441.8502130723463,3.737279834022938
2.5961885409210824e-06,0.014178035607121425,194.73898278672448,441.8502130723463,3.737279834022938
2.6313533498731148e-06,0.014370074014802961,195.09374133026583,441.8502130723463,3.737279834022938
2.6419027925587246e-06,0.014427685537107422,195.199807717068,441.8502130723463,3.737279834022938
2.7684961047860407e-06,0.015119023804760953,196.45998511688057,441.8502130723463,3.737279834022938
2.8915729361181535e-06,0.01579115823164633,197.66378209215318,441.8502130723463,3.737279834022938
2.9935508820790467e-06,0.016348069613922784,198.64614558909062,441.8502130723463,3.737279834022938
3.1306936369919723e-06,0.017097019403880774,199.9469168250903,441.8502130723463,3.737279834022938
3.193990293105631e-06,0.017442688537707543,200.5397580745184,441.8502130723463,3.737279834022938
3.23618806384807e-06,0.017673134626925387,200.9324419599533,441.8502130723463,3.737279834022938
3.2854187963809144e-06,0.017941988397679534,201.38805809230686,441.8502130723463,3.737279834022938
3.2994847199617276e-06,0.01801880376075215,201.51774406963318,441.8502130723463,3.737279834022938
3.352231933389776e-06,0.018306861372274455,202.00215807240687,441.8502130723463,3.737279834022938
3.422561551293841e-06,0.018690938187637528,202.64344425374367,441.8502130723463,3.737279834022938
3.4788252456170923e-06,0.018998199639927986,203.1527804351547,441.8502130723463,3.737279834022938
3.4858582074074987e-06,0.019036607321464293,203.21622079207114,441.8502130723463,3.737279834022938
3.601902076949205e-06,0.01967033406681336,204.2558849259558,441.8502130723463,3.737279834022938
3.6581657712724566e-06,0.01997759551910382,204.7552550952423,441.8502130723463,3.737279834022938
3.721462427386115e-06,0.020323264652930585,205.31347981603471,441.8502130723463,3.737279834022938
3.7742096408141634e-06,0.02061132226445289,205.77584401360446,441.8502130723463,3.737279834022938
3.858605182299041e-06,0.02107221444288858,206.5104189681874,441.8502130723463,3.737279834022938
3.925418319307902e-06,0.021437087417483496,207.08752285460218,441.8502130723463,3.737279834022938
3.971132570945545e-06,0.021686737347469495,207.4801779046819,441.8502130723463,3.737279834022938
3.9851984945263575e-06,0.02176355271054211,207.60063967051943,441.8502130723463,3.737279834022938
4.0977258831728605e-06,0.022378075615123026,208.55843559279643,441.8502130723463,3.737279834022938
4.146956615705706e-06,0.022646929385877177,208.97423964838677,441.8502130723463,3.737279834022938
4.255967523457005e-06,0.023242248449689938,209.888158312122,441.8502130723463,3.737279834022938
4.322780660465867e-06,0.02360712142428486,210.44379098213582,441.8502130723463,3.737279834022938
4.382560835684322e-06,0.02393358671734347,210.93810329222688,441.8502130723463,3.737279834022938
4.502121186121232e-06,0.024586517303460693,211.91890860006723,441.8502130723463,3.737279834022938
4.530253033282857e-06,0.024740148029605922,212.1482036815598,441.8502130723463,3.737279834022938
4.5408024759684665e-06,0.02479775955191038,212.23404608672007,441.8502130723463,3.737279834022938
4.6462969028245636e-06,0.02537387477495499,213.08823507487844,441.8502130723463,3.737279834022938
4.829153909375131e-06,0.02637247449489898,214.551123237862,441.8502130723463,3.737279834022938
4.948714259812041e-06,0.027025405081016203,215.4959597679357,441.8502130723463,3.737279834022938
5.061241648458544e-06,0.02763992798559712,216.3771172112979,441.8502130723463,3.737279834022938
5.117505342781796e-06,0.027947189437887578,216.81482826896416,441.8502130723463,3.737279834022938
5.222999769637893e-06,0.028523304660932187,217.63051082759395,441.8502130723463,3.737279834022938
5.314428272913177e-06,0.02902260452090418,218.33225193936505,441.8502130723463,3.737279834022938
5.349593081865209e-06,0.029214642928585718,218.60089668790735,441.8502130723463,3.737279834022938
5.381241409922038e-06,0.0293874774954991,218.8420886931579,441.8502130723463,3.737279834022938
5.398823814398055e-06,0.02948349669933987,218.97584519076457,441.8502130723463,3.737279834022938
5.430472142454883e-06,0.02965633126625325,219.21617955826497,441.8502130723463,3.737279834022938
5.5570654546821994e-06,0.03034766953390678,220.17210426165633,441.8502130723463,3.737279834022938
5.627395072586264e-06,0.030731746349269853,220.6995026548332,441.8502130723463,3.737279834022938
5.690691728699922e-06,0.03107741548309662,221.1719673652961,441.8502130723463,3.737279834022938
5.725856537651954e-06,0.031269453890778155,221.43356204960196,441.8502130723463,3.737279834022938
5.76453782749919e-06,0.03148069613922785,221.7205935931701,441.8502130723463,3.737279834022938
5.85244984987927e-06,0.031960792158431686,222.37015901889342,441.8502130723463,3.737279834022938
5.877065216145693e-06,0.03209521904380876,222.55135397809627,441.8502130723463,3.737279834022938
5.912230025097726e-06,0.0322872574514903,222.80969133450557,441.8502130723463,3.737279834022938
6.031790375534635e-06,0.03294018803760752,223.6835903715967,441.8502130723463,3.737279834022938
6.059922222696262e-06,0.03309381876375275,223.88822874364527,441.8502130723463,3.737279834022938
6.123218878809919e-06,0.033439487897579515,224.34731529278343,441.8502130723463,3.737279834022938
6.204097939399594e-06,0.03388117623524705,224.93124142127746,441.8502130723463,3.737279834022938
6.2287133056660166e-06,0.03401560312062413,225.10836781162666,441.8502130723463,3.737279834022938
6.263878114618048e-06,0.03420764152830566,225.36093268149287,441.8502130723463,3.737279834022938
6.337724213417315e-06,0.034610922184436885,225.8895260530748,441.8502130723463,3.737279834022938
6.432669197587803e-06,0.035129425885177035,226.56562986792565,441.8502130723463,3.737279834022938
6.471350487435039e-06,0.035340668133626726,226.83996245700953,441.8502130723463,3.737279834022938
6.54871306712951e-06,0.03576315263052611,227.38671659257088,441.8502130723463,3.737279834022938
6.5592625098151204e-06,0.03582076415283057,227.46107832653527,441.8502130723463,3.737279834022938
6.587394356976746e-06,0.0359743948789758,227.6591486039905,441.8502130723463,3.737279834022938
6.6225591659287775e-06,0.036166433286657335,227.9062731566793,441.8502130723463,3.737279834022938
6.640141570404794e-06,0.0362624524904981,228.0296434865741,441.8502130723463,3.737279834022938
6.738603035470483e-06,0.036800160032006396,228.7181773206955,441.8502130723463,3.737279834022938
6.791350248898532e-06,0.03708821764352871,229.0854202312423,441.8502130723463,3.737279834022938
6.826515057850565e-06,0.03728025605121024,229.329631027352,441.8502130723463,3.737279834022938
6.900361156649832e-06,0.03768353670734147,229.84088251142856,441.8502130723463,3.737279834022938
6.932009484706662e-06,0.037856371274254855,230.05933658884516,441.8502130723463,3.737279834022938
7.051569835143571e-06,0.038509301860372075,230.88112071894128,441.8502130723463,3.737279834022938
7.104317048571618e-06,0.038797359471894374,231.24194309524495,441.8502130723463,3.737279834022938
7.153547781104464e-06,0.03906621324264853,231.57776913829252,441.8502130723463,3.737279834022938
7.455965138091943e-06,0.040717743548709745,233.6212682391616,441.8502130723463,3.737279834022938
7.547393641367226e-06,0.041217043408681736,234.23267243284872,441.8502130723463,3.737279834022938
7.554426603157631e-06,0.04125545109021804,234.27958354180916,441.8502130723463,3.737279834022938
7.593107893004868e-06,0.04146669333866773,234.53729083036652,441.8502130723463,3.737279834022938
7.712668243441776e-06,0.04211962392478495,235.33062259442485,441.8502130723463,3.737279834022938
7.74783305239381e-06,0.0423116623324665,235.56304079326299,441.8502130723463,3.737279834022938
7.800580265821858e-06,0.0425997199439888,235.91089820546196,441.8502130723463,3.737279834022938
8.145195393551774e-06,0.04448169633926785,238.16140186478265,441.8502130723463,3.737279834022938
8.180360202503805e-06,0.044673734746949384,238.3889371709564,441.8502130723463,3.737279834022938
8.212008530560636e-06,0.04484656931386277,238.59339300532312,441.8502130723463,3.737279834022938
8.282338148464702e-06,0.04523064612922585,239.0466422969419,441.8502130723463,3.737279834022938
8.296404072045514e-06,0.04530746149229846,239.13711176253855,441.8502130723463,3.737279834022938
8.34915128547356e-06,0.04559551910382076,239.47584081037323,441.8502130723463,3.737279834022938
8.52145884933852e-06,0.04653650730146029,240.57658470837566,441.8502130723463,3.737279834022938
8.577722543661771e-06,0.04684376875375075,240.93412678154388,441.8502130723463,3.737279834022938
8.602337909928193e-06,0.04697819563912782,241.0902637034792,441.8502130723463,3.737279834022938
8.616403833509007e-06,0.04705501100220044,241.1794065684579,441.8502130723463,3.737279834022938
8.67266752783226e-06,0.0473622724544909,241.5354119551085,441.8502130723463,3.737279834022938
8.7183817794699e-06,0.047611922384476896,241.824003556348,441.8502130723463,3.737279834022938
8.778161954688356e-06,0.04793838767753551,242.20050367427282,441.8502130723463,3.737279834022938
8.806293801849982e-06,0.04809201840368074,242.37733407264136,441.8502130723463,3.737279834022938
8.827392687221199e-06,0.04820724144828965,242.50981233185195,441.8502130723463,3.737279834022938
9.013766174666971e-06,0.049225045009001794,243.6747220792768,441.8502130723463,3.737279834022938
9.098161716151848e-06,0.04968593718743748,244.19913452416498,441.8502130723463,3.737279834022938
9.147392448684694e-06,0.049954790958191636,244.5041656724538,441.8502130723463,3.737279834022938
9.200139662112743e-06,0.05024284856971395,244.8302751483562,441.8502130723463,3.737279834022938
9.35134834060648e-06,0.051068613722744544,245.76110536116212,441.8502130723463,3.737279834022938
9.474425171938593e-06,0.05174074814962992,246.51443185088755,441.8502130723463,3.737279834022938
9.657282178489163e-06,0.05273934786957392,247.62665030080422,441.8502130723463,3.737279834022938
9.702996430126804e-06,0.052988997799559914,247.90341784939753,441.8502130723463,3.737279834022938
9.945633611895827e-06,0.054314062812562514,249.36398863068055,441.8502130723463,3.737279834022938
1.005816100054233e-05,0.05492858571714343,250.0366314499118,441.8502130723463,3.737279834022938
1.007925988591355e-05,0.055043808761752355,250.16242457722853,441.8502130723463,3.737279834022938
1.0142556542027208e-05,0.05538947789557912,250.53918922600306,441.8502130723463,3.737279834022938
1.0170688389188833e-05,0.055543108621724346,250.7063457203282,441.8502130723463,3.737279834022938
1.0209369679036069e-05,0.05575435087017404,250.9358917761873,441.8502130723463,3.737279834022938
1.0272666335149727e-05,0.0561000200040008,251.31078231660564,441.8502130723463,3.737279834022938
1.0318380586787368e-05,0.056349669933986796,251.5809765524465,441.8502130723463,3.737279834022938
1.0455523341700295e-05,0.057098619723944796,252.38877194534606,441.8502130723463,3.737279834022938
1.0532885921394765e-05,0.057521104220844166,252.84262819556065,441.8502130723463,3.737279834022938
1.0564534249451594e-05,0.057693938787757554,253.02792173255887,441.8502130723463,3.737279834022938
1.0592666096613221e-05,0.05784756951390278,253.1924454371703,441.8502130723463,3.737279834022938
1.0772006622268587e-05,0.05882696539307862,254.23730645564228,441.8502130723463,3.737279834022938
1.0803654950325414e-05,0.058999799959991994,254.42098723256322,441.8502130723463,3.737279834022938
1.0863435125543868e-05,0.05932626525305061,254.76736827233756,441.8502130723463,3.737279834022938
1.0895083453600699e-05,0.059499099819964,254.95044547901614,441.8502130723463,3.737279834022938
1.0933764743447933e-05,0.05971034206841368,255.17392509139975,441.8502130723463,3.737279834022938
1.0986511956875982e-05,0.05999839967993599,255.47817373792986,441.8502130723463,3.737279834022938
1.104980861298964e-05,0.06034406881376275,255.8425211659706,441.8502130723463,3.737279834022938
1.1120138230893705e-05,0.06072814562912583,256.2463983294508,441.8502130723463,3.737279834022938
1.1186951367902565e-05,0.06109301860372074,256.6291599093568,441.8502130723463,3.737279834022938
1.121508321506419e-05,0.06124664932986597,256.7900558396911,441.8502130723463,3.737279834022938
1.1310028199234679e-05,0.06176515303060612,257.3319213047206,441.8502130723463,3.737279834022938
1.1369808374453133e-05,0.062091618323664735,257.6721858867904,441.8502130723463,3.737279834022938
1.1478819282204433e-05,0.06268693738747749,258.2908775459644,441.8502130723463,3.737279834022938
1.1503434648470857e-05,0.06282136427285458,258.4302644862171,441.8502130723463,3.737279834022938
1.1622994998907766e-05,0.0634742948589718,259.105639107319,441.8502130723463,3.737279834022938
1.1647610365174188e-05,0.06360872174434887,259.244349885881,441.8502130723463,3.737279834022938
1.1682775174126219e-05,0.0638007601520304,259.44230998525825,441.8502130723463,3.737279834022938
1.1802335524563131e-05,0.06445369073814763,260.11364289365923,441.8502130723463,3.737279834022938
1.1837500333515164e-05,0.06464572914582917,260.31058830647424,441.8502130723463,3.737279834022938
1.1879698104257601e-05,0.064876175235047,260.54662187387635,441.8502130723463,3.737279834022938
1.206255511080817e-05,0.065874774954991,261.5656786847482,441.8502130723463,3.737279834022938
1.20977199197602e-05,0.06606681336267253,261.76095855302447,441.8502130723463,3.737279834022938
1.2146950652293046e-05,0.06633566713342669,262.03397886996737,441.8502130723463,3.737279834022938
1.2178598980349877e-05,0.06650850170034008,262.20926407414436,441.8502130723463,3.737279834022938
1.224892859825394e-05,0.06689257851570314,262.5981519756651,441.8502130723463,3.737279834022938
1.2368488948690852e-05,0.06754550910182038,263.2572687915879,441.8502130723463,3.737279834022938
1.2488049299127761e-05,0.0681984396879376,263.9139054045357,441.8502130723463,3.737279834022938
1.2526730588974997e-05,0.06840968193638729,264.1258211336116,441.8502130723463,3.737279834022938
1.2723653519106377e-05,0.06948509701940389,265.2007334003547,441.8502130723463,3.737279834022938
1.2860796274019303e-05,0.07023404680936188,265.945503416167,441.8502130723463,3.737279834022938
1.297684014356101e-05,0.07086777355471095,266.5732773328502,441.8502130723463,3.737279834022938
1.3135081783845155e-05,0.07173194638927786,267.4258156922844,441.8502130723463,3.737279834022938
1.3201894920854017e-05,0.07209681936387279,267.78457259501886,441.8502130723463,3.737279834022938
1.3212444363539624e-05,0.07215443088617723,267.8411536288971,441.8502130723463,3.737279834022938
1.3237059729806049e-05,0.07228885777155432,267.97310756726847,441.8502130723463,3.737279834022938
1.3328488233081332e-05,0.07278815763152631,268.4623866057482,441.8502130723463,3.737279834022938
1.3448048583518241e-05,0.07344108821764353,269.100242542576,441.8502130723463,3.737279834022938
1.359925726201198e-05,0.07426685337067414,269.90378427754655,441.8502130723463,3.737279834022938
1.360980670469759e-05,0.0743244648929786,269.9597149546652,441.8502130723463,3.737279834022938
1.3644971513649622e-05,0.07451650330066013,270.1460285523256,441.8502130723463,3.737279834022938
1.370826816976328e-05,0.0748621724344869,270.4809218189178,441.8502130723463,3.737279834022938
1.3803213153933767e-05,0.07538067613522705,270.9821331749616,441.8502130723463,3.737279834022938
1.3813762596619377e-05,0.07543828765753151,271.0377402043862,441.8502130723463,3.737279834022938
1.3866509810047426e-05,0.07572634526905382,271.31552730978365,441.8502130723463,3.737279834022938
1.3989586641379537e-05,0.07639847969593919,271.96209951465914,441.8502130723463,3.737279834022938
1.4003652564960352e-05,0.07647529505901181,272.0358519544663,441.8502130723463,3.737279834022938
1.4049366816597993e-05,0.0767249449889978,272.2753481004374,441.8502130723463,3.737279834022938
1.410211403002604e-05,0.0770130026005201,272.55131248243345,441.8502130723463,3.737279834022938
1.4130245877187666e-05,0.07716663332666533,272.69832886964696,441.8502130723463,3.737279834022938
1.4151344762558887e-05,0.07728185637127426,272.8085162603701,441.8502130723463,3.737279834022938
1.4256839189414984e-05,0.07785797159431887,273.3584950780681,441.8502130723463,3.737279834022938
1.4344751211795064e-05,0.0783380676135227,273.8155994016822,441.8502130723463,3.737279834022938
1.443969619596555e-05,0.07885657131426285,274.3080466698693,441.8502130723463,3.737279834022938
1.4513542294764819e-05,0.07925985197039408,274.6901886798039,441.8502130723463,3.737279834022938
1.4573322469983273e-05,0.0795863172634527,274.99898663273314,441.8502130723463,3.737279834022938
1.4671783935048965e-05,0.080124024804961,275.50652028887475,441.8502130723463,3.737279834022938
1.4801893728171484e-05,0.08083456691338269,276.1751570057007,441.8502130723463,3.737279834022938
1.4865190384285142e-05,0.08118023604720945,276.49961061394146,441.8502130723463,3.737279834022938
1.4879256307865954e-05,0.08125705141028206,276.5716381937511,441.8502130723463,3.737279834022938
1.4960135368455629e-05,0.0816987397479496,276.9852826031656,441.8502130723463,3.737279834022938
1.5093761642473353e-05,0.08242848569713944,277.6667893879701,441.8502130723463,3.737279834022938
1.5181673664853431e-05,0.08290858171634327,278.11386626244365,441.8502130723463,3.737279834022938
1.5234420878281479e-05,0.08319663932786557,278.3816277751584,441.8502130723463,3.737279834022938
1.527661864902392e-05,0.08342708541708342,278.5955767502934,441.8502130723463,3.737279834022938
1.529771753439514e-05,0.08354230846169235,278.7024647982693,441.8502130723463,3.737279834022938
1.5403211961251236e-05,0.08411842368473695,279.23604504641867,441.8502130723463,3.737279834022938
1.5427827327517658e-05,0.08425285057011403,279.3603418046257,441.8502130723463,3.737279834022938
1.5550904158849772e-05,0.08492498499699941,279.9806692110816,441.8502130723463,3.737279834022938
1.562475025764904e-05,0.08532826565313063,280.351946650598,441.8502130723463,3.737279834022938
1.5673980990181886e-05,0.08559711942388479,280.59908482146193,441.8502130723463,3.737279834022938
1.5723211722714727e-05,0.08586597319463893,280.84592044292253,441.8502130723463,3.737279834022938
1.577947541703798e-05,0.08617323464692939,281.12764951502396,441.8502130723463,3.737279834022938
1.583222263046603e-05,0.0864612922584517,281.39141492247967,441.8502130723463,3.737279834022938
1.5958815942693346e-05,0.08715263052610522,282.0230575112947,441.8502130723463,3.737279834022938
1.5976398347169362e-05,0.08724864972994599,282.11063084888394,441.8502130723463,3.737279834022938
1.6036178522387818e-05,0.08757511502300461,282.4080994505565,441.8502130723463,3.737279834022938
1.6141672949243913e-05,0.08815123024604922,282.9319911903038,441.8502130723463,3.737279834022938
1.6197936643567164e-05,0.08845849169833968,283.21085404004276,441.8502130723463,3.737279834022938
1.622606849072879e-05,0.08861212242448491,283.3501437841217,441.8502130723463,3.737279834022938
1.6285848665947244e-05,0.08893858771754351,283.64582216345366,441.8502130723463,3.737279834022938
1.631398051310887e-05,0.08909221844368874,283.78481843819327,441.8502130723463,3.737279834022938
1.6349145322060902e-05,0.08928425685137027,283.95843239951785,441.8502130723463,3.737279834022938
1.6384310131012936e-05,0.08947629525905182,284.131900787879,441.8502130723463,3.737279834022938
1.6524969366821066e-05,0.09024444888977796,284.8243272605648,441.8502130723463,3.737279834022938
1.659178250382993e-05,0.09060932186437289,285.15242426518614,441.8502130723463,3.737279834022938
1.663046379367716e-05,0.09082056411282256,285.34213965039044,441.8502130723463,3.737279834022938
1.6732441739638058e-05,0.09137747549509903,285.8414753054704,441.8502130723463,3.737279834022938
1.6760573586799682e-05,0.09153110622124426,285.9790140257005,441.8502130723463,3.737279834022938
1.6774639510380496e-05,0.09160792158431687,286.047749621567,441.8502130723463,3.737279834022938
1.682738672380854e-05,0.09189597919583917,286.30530815583404,441.8502130723463,3.737279834022938
1.6869584494550982e-05,0.09212642528505702,286.5111283533237,441.8502130723463,3.737279834022938
1.6936397631559842e-05,0.09249129825965194,286.8366001699242,441.8502130723463,3.737279834022938
1.6971562440511876e-05,0.09268333666733347,287.007699974978,441.8502130723463,3.737279834022938
1.7017276692149515e-05,0.09293298659731947,287.2299231636687,441.8502130723463,3.737279834022938
1.7024309653939922e-05,0.09297139427885577,287.2640906713177,441.8502130723463,3.737279834022938
1.707705686736797e-05,0.09325945189037808,287.5201717431382,441.8502130723463,3.737279834022938
1.711925463811041e-05,0.09348989797959592,287.7248145640524,441.8502130723463,3.737279834022938
1.7210683141385694e-05,0.09398919783956791,288.16753367641013,441.8502130723463,3.737279834022938
1.7312661087346588e-05,0.09454610922184438,288.66025510077185,441.8502130723463,3.737279834022938
1.7361891819879432e-05,0.09481496299259852,288.89771539227274,441.8502130723463,3.737279834022938
1.7397056628831466e-05,0.09500700140028007,289.0671691390057,441.8502130723463,3.737279834022938
1.7453320323154717e-05,0.09531426285257052,289.3380175480398,441.8502130723463,3.737279834022938
1.7537715864639595e-05,0.09577515503100621,289.74365256387694,441.8502130723463,3.737279834022938
1.7593979558962846e-05,0.09608241648329667,290.01365305363026,441.8502130723463,3.737279834022938
1.760804548254366e-05,0.09615923184636928,290.0811005348956,441.8502130723463,3.737279834022938
1.769947398581894e-05,0.09665853170634127,290.51899809096426,441.8502130723463,3.737279834022938
1.7833100259836664e-05,0.09738827765553111,291.1574186593954,441.8502130723463,3.737279834022938
1.788936395415992e-05,0.09769553910782157,291.42566885744594,441.8502130723463,3.737279834022938
1.7970243014749592e-05,0.0981372274454891,291.8107027872272,441.8502130723463,3.737279834022938
1.802299022817764e-05,0.09842528505701141,292.061447814402,441.8502130723463,3.737279834022938
1.806870447981528e-05,0.0986749349869974,292.2785287572021,441.8502130723463,3.737279834022938
1.8128484655033737e-05,0.09900140028005601,292.56208091670766,441.8502130723463,3.737279834022938
1.8146067059509755e-05,0.09909741948389679,292.6454091806,441.8502130723463,3.737279834022938
1.8195297792042596e-05,0.09936627325465093,292.87856096714273,441.8502130723463,3.737279834022938
1.8244528524575444e-05,0.09963512702540508,293.11146685738174,441.8502130723463,3.737279834022938