File: datasets/aisi_316_L/data/M1/valid_23.csv
Time(s),Strain(%),Stress(MPa),Temp(C),Log_SR(s-1)
0.0,0.0,0.0,399.0221027080113,-3.47874706785187
0.03854402261775615,1.28e-05,2.1677648,399.0221027080113,-3.47874706785187
0.08190604806273181,2.7199999999999997e-05,4.606500199999999,399.0221027080113,-3.47874706785187
0.10358706078521965,3.4399999999999996e-05,5.8258678999999995,399.0221027080113,-3.47874706785187
0.12045007068048796,3.9999999999999996e-05,6.774265,399.0221027080113,-3.47874706785187
0.18067510602073195,5.9999999999999995e-05,10.1613975,399.0221027080113,-3.47874706785187
0.2192191286384881,7.28e-05,12.329162299999998,399.0221027080113,-3.47874706785187
0.4239842487953177,0.0001408,23.845412800000002,399.0221027080113,-3.47874706785187
0.4962542912036105,0.0001648,27.909971799999997,399.0221027080113,-3.47874706785187
0.5540703251302447,0.000184,31.161619,399.0221027080113,-3.47874706785187
0.5637063307846837,0.0001872,31.7035602,399.0221027080113,-3.47874706785187
0.5926143477480008,0.00019679999999999999,33.329383799999995,399.0221027080113,-3.47874706785187
0.6721113943971229,0.00022319999999999998,37.800398699999995,399.0221027080113,-3.47874706785187
0.7058374141876594,0.00023439999999999998,39.6971929,399.0221027080113,-3.47874706785187
0.7251094254965377,0.0002408,40.7810753,399.0221027080113,-3.47874706785187
0.7540174424598548,0.0002504,42.4068989,399.0221027080113,-3.47874706785187
0.8166514792137084,0.0002712,45.92951669999999,399.0221027080113,-3.47874706785187
0.951555558375855,0.000316,53.516693499999995,399.0221027080113,-3.47874706785187
0.9563735612030745,0.00031759999999999997,53.78766409999999,399.0221027080113,-3.47874706785187
0.9756455725119525,0.00032399999999999996,54.871546499999994,399.0221027080113,-3.47874706785187
1.031052605024977,0.0003424,57.987708399999995,399.0221027080113,-3.47874706785187
1.0888686389516113,0.0003616,61.2393556,399.0221027080113,-3.47874706785187
1.141866670051026,0.0003792,64.2200322,399.0221027080113,-3.47874706785187
1.2767707492131726,0.000424,71.807209,399.0221027080113,-3.47874706785187
1.2888157562812215,0.000428,72.4846355,399.0221027080113,-3.47874706785187
1.4189018326161482,0.00047119999999999996,79.80084169999999,399.0221027080113,-3.47874706785187
1.4983988792652703,0.0004976,84.27185659999999,399.0221027080113,-3.47874706785187
1.5104438863333192,0.0005015999999999999,84.94928309999999,399.0221027080113,-3.47874706785187
1.5321248990558072,0.0005088,86.1686508,399.0221027080113,-3.47874706785187
1.5538059117782947,0.000516,87.3880185,399.0221027080113,-3.47874706785187
1.5706689216735632,0.0005216,88.3364156,399.0221027080113,-3.47874706785187
1.5851229301552219,0.0005264,89.1493274,399.0221027080113,-3.47874706785187
1.7055730008357097,0.0005664,95.9235924,399.0221027080113,-3.47874706785187
1.7176180079037586,0.0005704,96.6010189,399.0221027080113,-3.47874706785187
1.7537530291079049,0.0005824,98.63329839999999,399.0221027080113,-3.47874706785187
1.7971150545528807,0.0005968,101.0720338,399.0221027080113,-3.47874706785187
1.8356590771706367,0.0006096,103.2397986,399.0221027080113,-3.47874706785187
1.90311111675171,0.000632,107.03338699999999,399.0221027080113,-3.47874706785187
1.9801991619872221,0.0006575999999999999,111.36891659999999,399.0221027080113,-3.47874706785187
2.042833198741076,0.0006784,114.8915344,399.0221027080113,-3.47874706785187
2.071741215704393,0.0006879999999999999,116.51735799999999,399.0221027080113,-3.47874706785187
2.093422228426881,0.0006952,117.7367257,399.0221027080113,-3.47874706785187
2.115103241149369,0.0007023999999999999,118.95609339999999,399.0221027080113,-3.47874706785187
2.141602256699076,0.0007111999999999999,120.44643169999999,399.0221027080113,-3.47874706785187
2.1584652665943445,0.0007168,121.3948288,399.0221027080113,-3.47874706785187
2.2909603443428814,0.0007608,128.84652029999998,399.0221027080113,-3.47874706785187
2.295778347170101,0.0007624,129.1174909,399.0221027080113,-3.47874706785187
2.3198683613061983,0.0007704,130.4723439,399.0221027080113,-3.47874706785187
2.334322369787857,0.0007752,131.2852557,399.0221027080113,-3.47874706785187
2.360821385337564,0.000784,132.77559399999998,399.0221027080113,-3.47874706785187
2.4764534531908327,0.0008223999999999999,139.2788884,399.0221027080113,-3.47874706785187
2.5198154786358082,0.0008368,141.71762379999998,399.0221027080113,-3.47874706785187
2.565586505494394,0.000852,143.6499020298583,399.0221027080113,-3.47874706785187
2.642674550729906,0.0008776,143.77707374523337,399.0221027080113,-3.47874706785187
2.7293986016198573,0.0009063999999999999,143.91842494674313,399.0221027080113,-3.47874706785187
2.765533622824004,0.0009184,143.97680302144198,399.0221027080113,-3.47874706785187
2.80166864402815,0.0009304,144.03488435866137,399.0221027080113,-3.47874706785187
2.8185316539234186,0.000936,144.06188893189898,399.0221027080113,-3.47874706785187
2.9173007118814187,0.0009687999999999999,144.2188113536393,399.0221027080113,-3.47874706785187
2.924527716122248,0.0009712,144.23021147325682,399.0221027080113,-3.47874706785187
2.9799347486352725,0.0009896,144.3172503090195,399.0221027080113,-3.47874706785187
3.054613792457175,0.0010144,144.43357137189653,399.0221027080113,-3.47874706785187
3.1292928362790775,0.0010391999999999999,144.54878848812638,399.0221027080113,-3.47874706785187
3.1895178716193215,0.0010592,144.64092630401726,399.0221027080113,-3.47874706785187
3.2256528928234682,0.0010712,144.69588335526385,399.0221027080113,-3.47874706785187
3.293104932404541,0.0010936,144.79783167373625,399.0221027080113,-3.47874706785187
3.3340579564359074,0.0011072,144.85933162375002,399.0221027080113,-3.47874706785187
3.3918739903625417,0.0011264,144.9456558715923,399.0221027080113,-3.47874706785187
3.574958097796883,0.0011872,145.21530501068474,399.0221027080113,-3.47874706785187
3.6351831331371267,0.0012071999999999999,145.302820877778,399.0221027080113,-3.47874706785187
3.7026351727182005,0.0012296,145.40017007168336,399.0221027080113,-3.47874706785187
3.7821322193673224,0.001256,145.5140195253776,399.0221027080113,-3.47874706785187
3.866447268843664,0.001284,145.63375378456763,399.0221027080113,-3.47874706785187
3.895355285806981,0.0012936,145.67457054237568,399.0221027080113,-3.47874706785187
3.948353316906396,0.0013112,145.74909575623158,399.0221027080113,-3.47874706785187
3.979670335283323,0.0013216,145.792950013872,399.0221027080113,-3.47874706785187
4.035077367796347,0.00134,145.8702100295986,399.0221027080113,-3.47874706785187
4.051940377691616,0.0013456,145.89364167901246,399.0221027080113,-3.47874706785187
4.138664428581567,0.0013744,146.0135517874138,399.0221027080113,-3.47874706785187
4.20129846533542,0.0013951999999999999,146.09954490212635,399.0221027080113,-3.47874706785187
4.227797480885128,0.0014039999999999999,146.1357759261201,399.0221027080113,-3.47874706785187
4.2326154837123475,0.0014056,146.14235385878948,399.0221027080113,-3.47874706785187
4.256705497848444,0.0014135999999999999,146.17519982095578,399.0221027080113,-3.47874706785187
4.302476524707031,0.0014288,146.23740811122548,399.0221027080113,-3.47874706785187
4.345838550152006,0.0014432,146.2961046280201,399.0221027080113,-3.47874706785187
4.386791574183372,0.0014567999999999998,146.35133084989,399.0221027080113,-3.47874706785187
4.487969633554982,0.0014904,146.48691702564022,399.0221027080113,-3.47874706785187
4.536149661827177,0.0015064,146.55106240175138,399.0221027080113,-3.47874706785187
4.659008733921275,0.0015471999999999999,146.7134419064701,399.0221027080113,-3.47874706785187
4.671053740989324,0.0015512,146.72927104278656,399.0221027080113,-3.47874706785187
4.7409147819840065,0.0015743999999999999,146.82076805289094,399.0221027080113,-3.47874706785187
4.798730815910641,0.0015936,146.89609272220287,399.0221027080113,-3.47874706785187
4.875818861146153,0.0016192,146.99597733681355,399.0221027080113,-3.47874706785187
4.90713587952308,0.0016296,147.0363793086664,399.0221027080113,-3.47874706785187
4.938452897900007,0.00164,147.0766808460814,399.0221027080113,-3.47874706785187
4.976996920517763,0.0016527999999999998,147.12614616985098,399.0221027080113,-3.47874706785187
4.991450928999422,0.0016576,147.14465712022206,399.0221027080113,-3.47874706785187
5.025176948789959,0.0016688,147.1877682301865,399.0221027080113,-3.47874706785187
5.1384000152296165,0.0017063999999999998,147.3316801232403,399.0221027080113,-3.47874706785187
5.196216049156251,0.0017255999999999999,147.4046896946626,399.0221027080113,-3.47874706785187
5.263668088737325,0.001748,147.4894683076154,399.0221027080113,-3.47874706785187
5.350392139627275,0.0017767999999999998,147.59784937939415,399.0221027080113,-3.47874706785187
5.444343194758057,0.001808,147.7144919345065,399.0221027080113,-3.47874706785187
5.473251211721373,0.0018176,147.7502236718501,399.0221027080113,-3.47874706785187
5.516613237166349,0.0018319999999999999,147.80368358263283,399.0221027080113,-3.47874706785187
5.559975262611325,0.0018464,147.85697986086487,399.0221027080113,-3.47874706785187
5.593701282401861,0.0018575999999999998,147.89832052803848,399.0221027080113,-3.47874706785187
5.60574628946991,0.0018616,147.91306147894952,399.0221027080113,-3.47874706785187
5.668380326223764,0.0018824,147.98951620730364,399.0221027080113,-3.47874706785187
5.731014362977618,0.0019031999999999999,148.06564216316121,399.0221027080113,-3.47874706785187
5.80569340679952,0.0019279999999999998,148.15598495864018,399.0221027080113,-3.47874706785187
5.853873435071716,0.001944,148.21403020353972,399.0221027080113,-3.47874706785187
5.880372450621423,0.0019528,148.24587566071088,399.0221027080113,-3.47874706785187
5.950233491616106,0.001976,148.3295647352085,399.0221027080113,-3.47874706785187
6.01045852695635,0.001996,148.4014033861562,399.0221027080113,-3.47874706785187
6.049002549574106,0.0020088,148.44723283423312,399.0221027080113,-3.47874706785187
6.075501565123814,0.0020176,148.47867453592684,399.0221027080113,-3.47874706785187
6.114045587741569,0.0020304,148.52431261396708,399.0221027080113,-3.47874706785187
6.174270623081814,0.0020504,148.59539811818036,399.0221027080113,-3.47874706785187
6.234495658422058,0.0020704,148.66621371208217,399.0221027080113,-3.47874706785187
6.2537676697309355,0.0020767999999999997,148.6888182902259,399.0221027080113,-3.47874706785187
6.313992705071179,0.0020968,148.75928312803657,399.0221027080113,-3.47874706785187
6.354945729102544,0.0021103999999999997,148.8070495562898,399.0221027080113,-3.47874706785187
6.362172733343375,0.0021127999999999997,148.8154664490227,399.0221027080113,-3.47874706785187
6.405534758788351,0.0021272,148.8658897230977,399.0221027080113,-3.47874706785187
6.477804801196643,0.0021512,148.94963368767336,399.0221027080113,-3.47874706785187
6.50912181957357,0.0021616,148.9858094935305,399.0221027080113,-3.47874706785187
6.578982860568253,0.0021847999999999998,149.06626565415382,399.0221027080113,-3.47874706785187
6.603072874704351,0.0021928,149.09393181067844,399.0221027080113,-3.47874706785187
6.71147793831679,0.0022288,149.21794557691175,399.0221027080113,-3.47874706785187
6.737976953866497,0.0022375999999999997,149.2481409316321,399.0221027080113,-3.47874706785187
6.817474000515619,0.002264,149.33845033347296,399.0221027080113,-3.47874706785187
6.822292003342839,0.0022656,149.34391039361492,399.0221027080113,-3.47874706785187
6.846382017478936,0.0022735999999999998,149.37118816943473,399.0221027080113,-3.47874706785187
6.884926040096693,0.0022864,149.41475488008933,399.0221027080113,-3.47874706785187
6.921061061300839,0.0022984,149.45551236174921,399.0221027080113,-3.47874706785187
6.957196082504985,0.0023103999999999998,149.4961869370473,399.0221027080113,-3.47874706785187
6.995740105122742,0.0023232,149.5394824430389,399.0221027080113,-3.47874706785187
7.053556139049375,0.0023423999999999997,149.6042516751944,399.0221027080113,-3.47874706785187
7.075237151771863,0.0023496,149.62848671562935,399.0221027080113,-3.47874706785187
7.092100161667132,0.0023552,149.64731617318304,399.0221027080113,-3.47874706785187
7.104145168735181,0.0023592,149.66075509705547,399.0221027080113,-3.47874706785187
7.152325197007376,0.0023752,149.71442216669428,399.0221027080113,-3.47874706785187
7.1812332139706925,0.0023848,149.74655473668972,399.0221027080113,-3.47874706785187
7.217368235174839,0.0023967999999999997,149.78664959745302,399.0221027080113,-3.47874706785187
7.2462762521381565,0.0024064,149.8186691463727,399.0221027080113,-3.47874706785187
7.3570903171642055,0.0024432,149.94095199602907,399.0221027080113,-3.47874706785187
7.373953327059473,0.0024487999999999997,149.95949709454447,399.0221027080113,-3.47874706785187
7.446223369467766,0.0024728,150.0387894818459,399.0221027080113,-3.47874706785187
7.484767392085522,0.0024855999999999997,150.0809560061312,399.0221027080113,-3.47874706785187
7.564264438734645,0.002512,150.1676579472529,399.0221027080113,-3.47874706785187
7.646170486797376,0.0025391999999999997,150.25661634309776,399.0221027080113,-3.47874706785187
7.691941513655962,0.0025544,150.30616649978703,399.0221027080113,-3.47874706785187
7.759393553237035,0.0025767999999999998,150.3789787008503,399.0221027080113,-3.47874706785187
7.7762565631323035,0.0025824,150.3971431291031,399.0221027080113,-3.47874706785187
7.836481598472548,0.0026024,150.46189105744548,399.0221027080113,-3.47874706785187
7.9207966479488885,0.0026303999999999998,150.55221307352133,399.0221027080113,-3.47874706785187
7.966567674807474,0.0026455999999999997,150.6010879674548,399.0221027080113,-3.47874706785187
8.026792710147719,0.0026655999999999997,150.66523051393054,399.0221027080113,-3.47874706785187
8.062927731351865,0.0026776,150.70362595555878,399.0221027080113,-3.47874706785187
8.077381739833523,0.0026823999999999997,150.71896533470218,399.0221027080113,-3.47874706785187
8.156878786482645,0.0027088,150.80314134276458,399.0221027080113,-3.47874706785187
8.183377802032352,0.0027175999999999997,150.8311288328625,399.0221027080113,-3.47874706785187
8.212285818995671,0.0027272,150.86162036047008,399.0221027080113,-3.47874706785187
8.241193835958986,0.0027367999999999997,150.89207005680936,399.0221027080113,-3.47874706785187
8.289373864231182,0.0027527999999999997,150.942727145151,399.0221027080113,-3.47874706785187
8.354416902398645,0.0027743999999999998,151.01093244326654,399.0221027080113,-3.47874706785187
8.40259693067084,0.0027903999999999997,151.06132144559578,399.0221027080113,-3.47874706785187
8.41464193773889,0.0027944,151.0739010741858,399.0221027080113,-3.47874706785187
8.450776958943036,0.0028063999999999997,151.11159789125801,399.0221027080113,-3.47874706785187
8.518228998524108,0.0028288,151.1817975141501,399.0221027080113,-3.47874706785187
8.665178084754304,0.0028775999999999997,151.33398614522042,399.0221027080113,-3.47874706785187
8.727812121508158,0.0028983999999999998,151.39854711167578,399.0221027080113,-3.47874706785187
8.8121271709845,0.0029264,151.4851714882752,399.0221027080113,-3.47874706785187
8.833808183706987,0.0029335999999999997,151.5073940062724,399.0221027080113,-3.47874706785187
8.959076257214695,0.0029752,151.63537672556285,399.0221027080113,-3.47874706785187
9.01689229114133,0.0029944,151.6942101023024,399.0221027080113,-3.47874706785187
9.069890322240745,0.003012,151.74801158296998,399.0221027080113,-3.47874706785187
9.101207340617671,0.0030223999999999997,151.77974573807512,399.0221027080113,-3.47874706785187
9.151796370303476,0.0030391999999999997,151.83091879101218,399.0221027080113,-3.47874706785187
9.233702418366208,0.0030664,151.91353712021643,399.0221027080113,-3.47874706785187
9.277064443811184,0.0030808,151.95716050146794,399.0221027080113,-3.47874706785187
9.320426469256159,0.0030951999999999998,152.00070443361102,399.0221027080113,-3.47874706785187
9.590234627580452,0.0031848,152.2698904638334,399.0221027080113,-3.47874706785187
9.628778650198209,0.0031975999999999997,152.30810311248942,399.0221027080113,-3.47874706785187
9.734774712397037,0.0032327999999999996,152.41288152272702,399.0221027080113,-3.47874706785187
9.773318735014794,0.0032456,152.4508723261312,399.0221027080113,-3.47874706785187
9.850406780250307,0.0032711999999999997,152.52667908676813,399.0221027080113,-3.47874706785187
9.862451787318355,0.0032752,152.5385029608826,399.0221027080113,-3.47874706785187
9.956402842449135,0.0033063999999999997,152.63053668121037,399.0221027080113,-3.47874706785187
9.987719860826063,0.0033168,152.66113924050464,399.0221027080113,-3.47874706785187
10.00940087354855,0.0033239999999999997,152.68230370904448,399.0221027080113,-3.47874706785187
10.02626388344382,0.0033296,152.6987526040117,399.0221027080113,-3.47874706785187
10.064807906061574,0.0033423999999999997,152.73630961667294,399.0221027080113,-3.47874706785187
10.096124924438502,0.0033528,152.76678340374903,399.0221027080113,-3.47874706785187
10.173212969674013,0.0033783999999999997,152.84163916669067,399.0221027080113,-3.47874706785187
10.221392997946209,0.0033943999999999997,152.8883116989842,399.0221027080113,-3.47874706785187
10.235847006427868,0.0033992,152.90229671760187,399.0221027080113,-3.47874706785187
10.284027034700063,0.0034151999999999997,152.9488579221721,399.0221027080113,-3.47874706785187
10.296072041768111,0.0034192,152.960484921103,399.0221027080113,-3.47874706785187
10.382796092658063,0.0034479999999999997,153.04404327536207,399.0221027080113,-3.47874706785187
10.40929510820777,0.0034568,153.06952064491622,399.0221027080113,-3.47874706785187
10.435794123757477,0.0034655999999999997,153.09497273240206,399.0221027080113,-3.47874706785187
10.479156149202455,0.00348,153.13656730175526,399.0221027080113,-3.47874706785187
10.498428160511331,0.0034863999999999997,153.15503222511447,399.0221027080113,-3.47874706785187
10.61165122695099,0.003524,153.26324787287086,399.0221027080113,-3.47874706785187
10.633332239673479,0.0035312,153.2839185488799,399.0221027080113,-3.47874706785187
10.71042028490899,0.0035567999999999997,153.3572815369609,399.0221027080113,-3.47874706785187
10.744146304699528,0.003568,153.38931305759704,399.0221027080113,-3.47874706785187
10.840506361243918,0.0036,153.48061632567877,399.0221027080113,-3.47874706785187
10.847733365484748,0.0036024,153.487451284537,399.0221027080113,-3.47874706785187
10.958547430510796,0.0036392,153.59203261091386,399.0221027080113,-3.47874706785187
11.004318457369381,0.0036544,153.63510879083256,399.0221027080113,-3.47874706785187
11.050089484227966,0.0036696,153.67811515095272,399.0221027080113,-3.47874706785187
11.059725489882407,0.0036728,153.6871602625857,399.0221027080113,-3.47874706785187
11.071770496950455,0.0036768,153.69846233120674,399.0221027080113,-3.47874706785187
11.12235952663626,0.0036936,153.7458787504414,399.0221027080113,-3.47874706785187
11.158494547840405,0.0037056,153.77969613931006,399.0221027080113,-3.47874706785187
11.168130553494846,0.0037088,153.78870689307712,399.0221027080113,-3.47874706785187
11.194629569044553,0.0037175999999999997,153.81347084526334,399.0221027080113,-3.47874706785187
11.242809597316747,0.0037335999999999997,153.85843772147084,399.0221027080113,-3.47874706785187
11.33194264962031,0.0037632,153.94142881617535,399.0221027080113,-3.47874706785187
11.358441665170016,0.0037719999999999997,153.9660526992985,399.0221027080113,-3.47874706785187
11.382531679306114,0.00378,153.98841861272416,399.0221027080113,-3.47874706785187
11.435529710405529,0.0037976,154.0375587433814,399.0221027080113,-3.47874706785187
11.452392720300796,0.0038031999999999996,154.0531756027875,399.0221027080113,-3.47874706785187
11.531889766949918,0.0038296,154.12667748544771,399.0221027080113,-3.47874706785187
11.568024788154064,0.0038415999999999997,154.16002207946133,399.0221027080113,-3.47874706785187
11.661975843284846,0.0038728,154.2465284671133,399.0221027080113,-3.47874706785187
11.690883860248162,0.0038824,154.2730910806319,399.0221027080113,-3.47874706785187
11.760744901242846,0.0039056,154.3371785313608,399.0221027080113,-3.47874706785187
11.775198909724503,0.0039104,154.35041944821896,399.0221027080113,-3.47874706785187
11.792061919619774,0.003916,154.365859175768,399.0221027080113,-3.47874706785187
11.840241947891968,0.003932,154.4099253065574,399.0221027080113,-3.47874706785187
11.852286954960014,0.003935999999999999,154.42093090557879,399.0221027080113,-3.47874706785187
11.890830977577773,0.0039488,154.45611954607594,399.0221027080113,-3.47874706785187
11.922147995954699,0.0039591999999999995,154.4846775724725,399.0221027080113,-3.47874706785187
12.00646304543104,0.0039872,154.56141952328187,399.0221027080113,-3.47874706785187
12.023326055326308,0.0039927999999999995,154.576742660824,399.0221027080113,-3.47874706785187
12.218489866388369,0.004057611522304461,154.7534792604854,399.0221027080113,-3.47874706785187
12.854593460300128,0.004268853770754151,155.3220272918329,399.0221027080113,-3.47874706785187
13.259386656425793,0.0044032806561312265,155.67812338266705,399.0221027080113,-3.47874706785187
13.953317849784076,0.00463372674534907,156.27886267143657,399.0221027080113,-3.47874706785187
15.109869838714546,0.005017803560712143,157.25481484747527,399.0221027080113,-3.47874706785187
15.9772838304124,0.0053058611722344474,157.9677589429662,399.0221027080113,-3.47874706785187
17.827767012701152,0.005920384076815363,159.440088714948,399.0221027080113,-3.47874706785187
18.521698206059433,0.006150830166033207,159.97667745148493,399.0221027080113,-3.47874706785187
18.81083620329205,0.006246849369873975,160.19793519406105,399.0221027080113,-3.47874706785187
19.215629399417715,0.00638127625525105,160.50548056567877,399.0221027080113,-3.47874706785187
21.181767780599518,0.007034206841368274,161.96474620727045,399.0221027080113,-3.47874706785187
21.58656097672518,0.007168633726745349,162.2585139457909,399.0221027080113,-3.47874706785187
23.55269935790698,0.007821564312862572,163.6559032515108,399.0221027080113,-3.47874706785187
24.246630551265262,0.008052010402080416,164.13813438464814,399.0221027080113,-3.47874706785187
25.114044542963118,0.00834006801360272,164.73341944879715,399.0221027080113,-3.47874706785187
26.44407933023316,0.008781756351270254,165.630844766068,399.0221027080113,-3.47874706785187
28.12107971418234,0.00933866773354671,166.73766806389102,399.0221027080113,-3.47874706785187
30.665494089829373,0.010183636727345468,168.36902122673956,399.0221027080113,-3.47874706785187
32.22683927488551,0.010702140428085618,169.34395492227773,399.0221027080113,-3.47874706785187
33.96166725828122,0.011278255651130227,170.40585400261472,399.0221027080113,-3.47874706785187
35.81215044056997,0.011892778555711142,171.51548287601995,399.0221027080113,-3.47874706785187
36.91087483005391,0.01225765153030606,172.16374513277097,399.0221027080113,-3.47874706785187
38.00959921953786,0.01262252450490098,172.8045238415853,399.0221027080113,-3.47874706785187
39.74442720293357,0.013198639727945589,173.8017624852562,399.0221027080113,-3.47874706785187
40.38053079684533,0.013409881976395279,174.16314400870488,399.0221027080113,-3.47874706785187
41.479255186329276,0.013774754950990198,174.78216213773277,399.0221027080113,-3.47874706785187
42.924945172492365,0.01425485097019404,175.58700254486988,399.0221027080113,-3.47874706785187
45.12239395146026,0.014984596919383877,176.79039960174975,399.0221027080113,-3.47874706785187
46.105463142051164,0.01531106221244249,177.32133783121475,399.0221027080113,-3.47874706785187
47.95594632433991,0.015925585117023404,178.30892382697064,399.0221027080113,-3.47874706785187
48.88118791548429,0.016232846569313862,178.79713469910638,399.0221027080113,-3.47874706785187
51.714740288363934,0.01717383476695339,180.27033262410131,399.0221027080113,-3.47874706785187
52.408671481722216,0.017404280856171232,180.6262747178,399.0221027080113,-3.47874706785187
53.39174067231313,0.017730746149229846,181.12739556803317,399.0221027080113,-3.47874706785187
54.316982263457504,0.018038007601520304,181.59576147027437,399.0221027080113,-3.47874706785187
54.43263746235055,0.01807641528305661,181.65408763937546,399.0221027080113,-3.47874706785187
56.05181024685321,0.018614122824564913,182.4656450451987,399.0221027080113,-3.47874706785187
58.01794862803501,0.019267053410682137,183.43891721555073,399.0221027080113,-3.47874706785187
58.42274182416067,0.01940148029605921,183.6376904419578,399.0221027080113,-3.47874706785187
59.52146621364462,0.01976635327065413,184.1745285769062,399.0221027080113,-3.47874706785187
60.562363003682044,0.020112022404480897,184.67955804698462,399.0221027080113,-3.47874706785187
62.008052989845126,0.020592118423684736,185.37540750637888,399.0221027080113,-3.47874706785187
62.528501384863844,0.02076495299059812,185.6243606753378,399.0221027080113,-3.47874706785187
63.68505337379432,0.021149029805961193,186.1747147484887,399.0221027080113,-3.47874706785187
64.43681216659913,0.02139867973594719,186.53035578573332,399.0221027080113,-3.47874706785187
64.78377776327827,0.02151390278055611,186.69395167870582,399.0221027080113,-3.47874706785187
65.70901935442264,0.02182116423284657,187.12854539087164,399.0221027080113,-3.47874706785187
67.96429573283706,0.022570114022804563,188.1779877045319,399.0221027080113,-3.47874706785187
68.48474412785576,0.022742948589717944,188.41822743140102,399.0221027080113,-3.47874706785187
69.23650292066058,0.022992598519703943,188.76398714215932,399.0221027080113,-3.47874706785187
70.85567570516324,0.023530306061212244,189.50376629803412,399.0221027080113,-3.47874706785187
72.59050368855894,0.02410642128425685,190.28910775487114,399.0221027080113,-3.47874706785187
74.9614352658664,0.02489377875575115,191.35067058507673,399.0221027080113,-3.47874706785187
75.42405606143859,0.02504740948189638,191.55626924328354,399.0221027080113,-3.47874706785187
76.06015965535035,0.02525865173034607,191.83816616385388,399.0221027080113,-3.47874706785187
77.21671164428082,0.02564272854570914,192.34836161145392,399.0221027080113,-3.47874706785187
78.02629803653215,0.025911582316463292,192.70372659833907,399.0221027080113,-3.47874706785187
78.54674643155087,0.026084416883376677,192.93141638405277,399.0221027080113,-3.47874706785187
80.57071241217919,0.026756551310262052,193.81133938850905,399.0221027080113,-3.47874706785187
81.61160920221661,0.027102220444088818,194.2605117085363,399.0221027080113,-3.47874706785187
83.17295438727275,0.027620724144828968,194.93010343016985,399.0221027080113,-3.47874706785187
84.56081677398932,0.028081616323264655,195.52119145745436,399.0221027080113,-3.47874706785187
85.19692036790107,0.028292858571714343,195.79084115333205,399.0221027080113,-3.47874706785187
86.58478275461763,0.02875375075015003,196.3764573022459,399.0221027080113,-3.47874706785187
88.2039555391203,0.029291458291658332,197.05506907257475,399.0221027080113,-3.47874706785187
89.01354193137162,0.029560312062412483,197.3925517723495,399.0221027080113,-3.47874706785187
89.36050752805076,0.029675535107021405,197.53682052628508,399.0221027080113,-3.47874706785187
89.99661112196252,0.029886777355471093,197.80074711923064,399.0221027080113,-3.47874706785187
91.61578390646518,0.030424484896979395,198.46929827641222,399.0221027080113,-3.47874706785187
92.94581869373522,0.03086617323464693,199.01502469720796,399.0221027080113,-3.47874706785187
94.73847427657746,0.031461492298459695,199.74577434620772,399.0221027080113,-3.47874706785187
95.95285386495445,0.03186477295459092,200.23773690536356,399.0221027080113,-3.47874706785187
96.47330225997315,0.0320376075215043,200.44783399172448,399.0221027080113,-3.47874706785187
96.58895745886622,0.03207601520304061,200.49446215015945,399.0221027080113,-3.47874706785187
97.57202664945711,0.03240248049609922,200.88992618679188,399.0221027080113,-3.47874706785187
98.49726824060149,0.03270974194838968,201.2607104993918,399.0221027080113,-3.47874706785187
100.00078582621111,0.03320904180836168,201.8603509118901,399.0221027080113,-3.47874706785187
100.86819981790894,0.03349709941988398,202.2046978288513,399.0221027080113,-3.47874706785187
101.50430341182071,0.03370834166833367,202.4564853604908,399.0221027080113,-3.47874706785187
102.89216579853728,0.034169233846769356,203.0037138040915,399.0221027080113,-3.47874706785187
103.18130379576989,0.03426525305061012,203.1173565458556,399.0221027080113,-3.47874706785187
104.10654538691426,0.03457251450290058,203.4801815414552,399.0221027080113,-3.47874706785187
105.26309737584474,0.034956591318263654,203.9319491397866,399.0221027080113,-3.47874706785187
105.78354577086344,0.035129425885177035,204.13461256900194,399.0221027080113,-3.47874706785187
106.41964936477521,0.035340668133626726,204.3817849967896,399.0221027080113,-3.47874706785187
109.02189133986876,0.03620484096819364,205.38700237626435,399.0221027080113,-3.47874706785187
109.77365013267357,0.036454490898179634,205.6756507047957,399.0221027080113,-3.47874706785187
110.40975372658534,0.036665733146629326,205.91928995812563,399.0221027080113,-3.47874706785187
111.10368491994363,0.036896179235847176,206.18445473509945,399.0221027080113,-3.47874706785187
112.95416810223239,0.03751070214042809,206.88842193173696,399.0221027080113,-3.47874706785187
113.87940969337676,0.03781796359271855,207.23871779262456,399.0221027080113,-3.47874706785187
114.51551328728848,0.03802920584116823,207.4789025870064,399.0221027080113,-3.47874706785187
115.72989287566547,0.03843248649729945,207.9359972393051,399.0221027080113,-3.47874706785187
116.36599646957724,0.038643728745749145,208.17468102025447,399.0221027080113,-3.47874706785187
119.08389364356387,0.039546309261852375,209.18883268698826,399.0221027080113,-3.47874706785187
119.83565243636868,0.03979595919183837,209.46774380023686,399.0221027080113,-3.47874706785187
122.20658401367612,0.04058331666333266,210.34294983691711,399.0221027080113,-3.47874706785187
123.18965320426703,0.04090978195639128,210.70389506482215,399.0221027080113,-3.47874706785187
124.1148947954114,0.041217043408681736,211.04258340488286,399.0221027080113,-3.47874706785187
125.44492958268144,0.041658731746349265,211.52772784950824,399.0221027080113,-3.47874706785187
126.42799877327235,0.04198519703940788,211.88502452179705,399.0221027080113,-3.47874706785187
127.06410236718412,0.04219643928785757,212.1156392489105,399.0221027080113,-3.47874706785187
128.79893035057984,0.042772554510902186,212.74231133556015,399.0221027080113,-3.47874706785187
128.9724131489194,0.04283016603320665,212.8047969433819,399.0221027080113,-3.47874706785187
131.45899992511988,0.04365593118623724,213.69685239866834,399.0221027080113,-3.47874706785187
131.92162072069206,0.04380956191238247,213.86208763024558,399.0221027080113,-3.47874706785187
132.73120711294342,0.044078415683136626,214.15070654320286,399.0221027080113,-3.47874706785187
134.4082074968926,0.04463532706541308,214.74638510441423,399.0221027080113,-3.47874706785187
134.9864834913578,0.04482736547309461,214.951118501183,399.0221027080113,-3.47874706785187
135.6804146847161,0.045057811562312464,215.1963476162512,399.0221027080113,-3.47874706785187
136.08520788084178,0.045192238447689534,215.339172045936,399.0221027080113,-3.47874706785187
136.8947942730931,0.04546109221844369,215.62432481277983,399.0221027080113,-3.47874706785187
137.12610467087922,0.04553790758151631,215.705676134883,399.0221027080113,-3.47874706785187
139.38138104929362,0.046286857371474296,216.49606672833397,399.0221027080113,-3.47874706785187
140.19096744154496,0.04655571114222845,216.7785780487153,399.0221027080113,-3.47874706785187
141.63665742770803,0.04703580716143228,217.28148505547975,399.0221027080113,-3.47874706785187
141.92579542494065,0.04713182636527305,217.38182579015816,399.0221027080113,-3.47874706785187
142.15710582272675,0.04720864172834567,217.46204098899395,399.0221027080113,-3.47874706785187
142.6775542177455,0.04738147629525906,217.64233930426116,399.0221027080113,-3.47874706785187
143.4293130105503,0.047631126225245055,217.9023180398043,399.0221027080113,-3.47874706785187
144.52803740003424,0.047995999199839975,218.2813330592046,399.0221027080113,-3.47874706785187
145.45327899117856,0.04830326065213042,218.59963281791516,399.0221027080113,-3.47874706785187
148.11334856571867,0.04918663732746549,219.51037547987437,399.0221027080113,-3.47874706785187
148.46031416239782,0.049301860372074416,219.62869593499028,399.0221027080113,-3.47874706785187
149.50121095243523,0.04964752950590118,219.9830119186358,399.0221027080113,-3.47874706785187
150.54210774247264,0.04999319863972794,220.33636710227364,399.0221027080113,-3.47874706785187
151.46734933361702,0.0503004600920184,220.64966145979776,399.0221027080113,-3.47874706785187
151.98779772863574,0.050473294658931786,220.82556152505893,399.0221027080113,-3.47874706785187
153.26000491645928,0.05089577915583117,221.2545534360534,399.0221027080113,-3.47874706785187
153.95393610981753,0.051126225245049006,221.48796357735145,399.0221027080113,-3.47874706785187
155.2839708970876,0.05156791358271655,221.9341893322942,399.0221027080113,-3.47874706785187
156.15138488878546,0.05185597119423885,222.2244032999842,399.0221027080113,-3.47874706785187
157.77055767328812,0.05239367873574716,222.76445937609435,399.0221027080113,-3.47874706785187
159.10059246055815,0.052835367073414685,223.20646165465055,399.0221027080113,-3.47874706785187
161.4136964384191,0.05360352070414083,223.9717441588354,399.0221027080113,-3.47874706785187
163.20635202126132,0.05419883976795359,224.56190004414574,399.0221027080113,-3.47874706785187
164.4207316096383,0.05460212042408481,224.9602474078528,399.0221027080113,-3.47874706785187
164.825524805764,0.0547365473094619,225.0927746630957,399.0221027080113,-3.47874706785187
166.56035278915968,0.055312662532506496,225.65931691620068,399.0221027080113,-3.47874706785187
168.1216979742158,0.055831166233246646,226.16724030039103,399.0221027080113,-3.47874706785187
169.39390516203935,0.05625365073014603,226.57974496969894,399.0221027080113,-3.47874706785187
169.68304315927196,0.056349669933986796,226.67332731889897,399.0221027080113,-3.47874706785187
170.7817675487559,0.05671454290858172,227.02837450357563,399.0221027080113,-3.47874706785187
172.40094033325857,0.057252250450090025,227.54998249203257,399.0221027080113,-3.47874706785187
172.7479059299377,0.05736747349469894,227.6615066666688,399.0221027080113,-3.47874706785187
173.38400952384944,0.05757871574314863,227.86574102713703,399.0221027080113,-3.47874706785187
175.35014790503124,0.05823164632926585,228.4951711861313,399.0221027080113,-3.47874706785187
176.79583789119434,0.058711742348469695,228.9562328725955,399.0221027080113,-3.47874706785187
178.6463210734831,0.05932626525305061,229.54425191417948,399.0221027080113,-3.47874706785187
179.22459706794834,0.059518303660732144,229.727520081715,399.0221027080113,-3.47874706785187
179.45590746573444,0.059595119023804766,229.8007627589221,399.0221027080113,-3.47874706785187
181.3642182474697,0.06022884576915383,230.4036163850502,399.0221027080113,-3.47874706785187
182.46294263695364,0.06059371874374875,230.74959168691387,399.0221027080113,-3.47874706785187
183.67732222533064,0.06099699939987997,231.13104152832057,399.0221027080113,-3.47874706785187
185.0073570126007,0.061438687737547515,231.54769316791516,399.0221027080113,-3.47874706785187
187.32046099046164,0.06220684136827366,232.2695329287767,399.0221027080113,-3.47874706785187
187.89873698492687,0.06239887977595519,232.449448667893,399.0221027080113,-3.47874706785187
188.24570258160603,0.06251410282056412,232.55729446026965,399.0221027080113,-3.47874706785187
189.80704776666212,0.06303260652130425,233.04164437834103,399.0221027080113,-3.47874706785187
189.98053056500171,0.06309021804360872,233.09536494708155,399.0221027080113,-3.47874706785187
191.1370825539322,0.0634742948589718,233.45301440668365,399.0221027080113,-3.47874706785187
191.83101374729046,0.06370474094818963,233.66719898438578,399.0221027080113,-3.47874706785187
192.69842773898833,0.06399279855971195,233.93450525682354,399.0221027080113,-3.47874706785187
195.5898077113145,0.06495299059811963,234.82215629119503,399.0221027080113,-3.47874706785187
196.39939410356584,0.06522184436887378,235.06977960804718,399.0221027080113,-3.47874706785187
198.07639448751502,0.06577875575115023,235.58145084385418,399.0221027080113,-3.47874706785187
198.94380847921286,0.06606681336267253,235.84544527367794,399.0221027080113,-3.47874706785187
199.63773967257117,0.06629725945189038,236.05631774846557,399.0221027080113,-3.47874706785187
201.4882228548599,0.0669117823564713,236.61725146607634,399.0221027080113,-3.47874706785187
202.52911964489732,0.06725745149029806,236.93189368524554,399.0221027080113,-3.47874706785187
202.81825764212994,0.06735347069413883,237.0191822966909,399.0221027080113,-3.47874706785187
204.4952580260791,0.06791038207641528,237.52450249356812,399.0221027080113,-3.47874706785187
204.9000512222048,0.06804480896179237,237.64623388775013,399.0221027080113,-3.47874706785187
205.2470168188839,0.06816003200640128,237.75050045221386,399.0221027080113,-3.47874706785187
205.6518100150096,0.06829445889177836,237.87205793566693,399.0221027080113,-3.47874706785187
207.21315520006576,0.06881296259251851,238.34005101101056,399.0221027080113,-3.47874706785187
207.73360359508445,0.06898579715943189,238.49574282482362,399.0221027080113,-3.47874706785187
208.77450038512188,0.06933146629325866,238.806670826951,399.0221027080113,-3.47874706785187
209.5262591779267,0.06958111622324466,239.03085406525736,399.0221027080113,-3.47874706785187
210.22019037128496,0.0698115623124625,239.23751416991797,399.0221027080113,-3.47874706785187
212.4754667496994,0.0705605121024205,239.9073295593409,399.0221027080113,-3.47874706785187
213.74767393752288,0.07098299659931986,240.28395081294673,399.0221027080113,-3.47874706785187
214.4994327303277,0.07123264652930586,240.50608882272473,399.0221027080113,-3.47874706785187
215.82946751759775,0.0716743348669734,240.89835986054408,399.0221027080113,-3.47874706785187
216.46557111150952,0.0718855771154231,241.08563438633948,399.0221027080113,-3.47874706785187
217.27515750376082,0.07215443088617723,241.3236736655163,399.0221027080113,-3.47874706785187
218.48953709213785,0.07255771154230847,241.6800850250252,399.0221027080113,-3.47874706785187
219.3569510838357,0.07284576915383077,241.93419172572956,399.0221027080113,-3.47874706785187
221.8435378600362,0.07367153430686138,242.6604680747428,399.0221027080113,-3.47874706785187
223.34705544564582,0.07417083416683337,243.09807188774954,399.0221027080113,-3.47874706785187
224.27229703679018,0.07447809561912383,243.36679556320198,399.0221027080113,-3.47874706785187
224.50360743457625,0.07455491098219644,243.4339088824842,399.0221027080113,-3.47874706785187
225.66015942350674,0.07493898779755952,243.76907181331885,399.0221027080113,-3.47874706785187
225.89146982129282,0.07501580316063212,243.83602393501366,399.0221027080113,-3.47874706785187
226.52757341520459,0.07522704540908182,244.0200045450857,399.0221027080113,-3.47874706785187
227.33715980745592,0.07549589917983597,244.25387054294384,399.0221027080113,-3.47874706785187
229.36112578808425,0.07616803360672135,244.83711898878613,399.0221027080113,-3.47874706785187
230.6333329759078,0.07659051810362073,245.20270511054778,399.0221027080113,-3.47874706785187
230.9224709731404,0.0766865373074615,245.28568308118295,399.0221027080113,-3.47874706785187
231.55857456705218,0.07689777955591119,245.46809212106226,399.0221027080113,-3.47874706785187
233.00426455321522,0.07737787557511502,245.88193289766522,399.0221027080113,-3.47874706785187
233.69819574657353,0.07760832166433287,246.08022066898033,399.0221027080113,-3.47874706785187
234.854747735504,0.07799239847969594,246.41019076805335,399.0221027080113,-3.47874706785187
236.64740331834625,0.07858771754350871,246.92039476950288,399.0221027080113,-3.47874706785187
238.0930933045093,0.07906781356271254,247.33075253599276,399.0221027080113,-3.47874706785187
238.72919689842107,0.07927905581116224,247.51100198036764,399.0221027080113,-3.47874706785187
242.37233566355204,0.08048889777955591,248.53975400923244,399.0221027080113,-3.47874706785187
243.18192205580337,0.08075775155031006,248.76754453115257,399.0221027080113,-3.47874706785187
244.56978444251993,0.08121864372874575,249.15735568559,399.0221027080113,-3.47874706785187
245.4371984342178,0.08150670134026806,249.40054961562265,399.0221027080113,-3.47874706785187
246.82506082093437,0.08196759351870375,249.78896384947083,399.0221027080113,-3.47874706785187
248.15509560820442,0.08240928185637128,250.16039567747367,399.0221027080113,-3.47874706785187
248.84902680156267,0.08263972794558912,250.3538779412051,399.0221027080113,-3.47874706785187
249.54295799492098,0.08287017403480697,250.54714989937,399.0221027080113,-3.47874706785187
251.9138895722284,0.08365753150630126,251.20591999583323,399.0221027080113,-3.47874706785187
252.8391311633728,0.08396479295859172,251.4623445251478,399.0221027080113,-3.47874706785187
253.59088995617762,0.08421444288857773,251.67042009372335,399.0221027080113,-3.47874706785187
253.9956831523033,0.0843488697739548,251.78236113695078,399.0221027080113,-3.47874706785187
254.34264874898244,0.08446409281856372,251.8782552369264,399.0221027080113,-3.47874706785187
257.00271832352246,0.08534746949389878,252.61175595027498,399.0221027080113,-3.47874706785187
257.69664951688077,0.08557791558311663,252.80261626415069,399.0221027080113,-3.47874706785187
259.9519258952952,0.08632686537307462,253.42153257291193,399.0221027080113,-3.47874706785187
260.588029489207,0.08653810762152431,253.59571963337282,399.0221027080113,-3.47874706785187
260.8771674864396,0.08663412682536507,253.67484074351498,399.0221027080113,-3.47874706785187
263.2480990637471,0.08742148429685938,254.32234884417096,399.0221027080113,-3.47874706785187
263.5950646604262,0.0875367073414683,254.41691500873776,399.0221027080113,-3.47874706785187
263.94203025710533,0.08765193038607721,254.5114326401853,399.0221027080113,-3.47874706785187
264.23116825433794,0.08774794958991798,254.5901603231188,399.0221027080113,-3.47874706785187
264.92509944769625,0.08797839567913583,254.77896980873126,399.0221027080113,-3.47874706785187
266.54427223219886,0.08851610322064413,255.21877678642835,399.0221027080113,-3.47874706785187
266.65992743109194,0.08855451090218044,255.25015164251968,399.0221027080113,-3.47874706785187
267.0647206272176,0.08868893778755751,255.35992187027378,399.0221027080113,-3.47874706785187
269.14651420729246,0.08938027605521105,255.92343277095503,399.0221027080113,-3.47874706785187
270.534376594009,0.08984116823364674,256.29816262097467,399.0221027080113,-3.47874706785187
272.0378941796186,0.09034046809361873,256.703274913446,399.0221027080113,-3.47874706785187
272.61617017408383,0.09053250650130026,256.85885470529905,399.0221027080113,-3.47874706785187
274.06186016024697,0.09101260252050411,257.2472421523911,399.0221027080113,-3.47874706785187
275.6232053453031,0.09153110622124426,257.6658042309091,399.0221027080113,-3.47874706785187
276.20148133976835,0.09172314462892579,257.8205924266903,399.0221027080113,-3.47874706785187
277.06889533146614,0.09201120224044809,258.0525379509169,399.0221027080113,-3.47874706785187
278.51458531762927,0.09249129825965194,258.4384854862156,399.0221027080113,-3.47874706785187
279.2085165109875,0.09272174434886978,258.623462716959,399.0221027080113,-3.47874706785187
279.5554821076667,0.0928369673934787,258.71588409015334,399.0221027080113,-3.47874706785187
281.8107584860811,0.09358591718343669,259.3155362752677,399.0221027080113,-3.47874706785187
282.38903448054634,0.09377795559111823,259.4689914137206,399.0221027080113,-3.47874706785187
283.8347244667094,0.09425805161032207,259.85209405291283,399.0221027080113,-3.47874706785187
284.58648325951424,0.09450770154030806,260.0510066319615,399.0221027080113,-3.47874706785187
285.2804144528725,0.09473814762952591,260.23443643522006,399.0221027080113,-3.47874706785187
286.72610443903557,0.09521824364872974,260.6160239106325,399.0221027080113,-3.47874706785187
287.9404840274126,0.09562152430486098,260.9359778666388,399.0221027080113,-3.47874706785187
288.5187600218778,0.09581356271254252,261.0881518876031,399.0221027080113,-3.47874706785187
290.02227760748747,0.09631286257251451,261.48324869516324,399.0221027080113,-3.47874706785187
290.195760405827,0.09637047409481897,261.5287853279968,399.0221027080113,-3.47874706785187
292.3353815853484,0.09708101620324065,262.0895336979209,399.0221027080113,-3.47874706785187
292.9714851792601,0.09729225845169034,262.25593371016737,399.0221027080113,-3.47874706785187
294.0702095687441,0.09765713142628527,262.54302041633616,399.0221027080113,-3.47874706785187
294.3015199665302,0.09773394678935787,262.6034063840361,399.0221027080113,-3.47874706785187
295.2845891571211,0.09806041208241649,262.85984052155806,399.0221027080113,-3.47874706785187
297.3085551377494,0.09873254650930187,263.3867471392033,399.0221027080113,-3.47874706785187
298.63858992501946,0.0991742348469694,263.7322385424099,399.0221027080113,-3.47874706785187
300.43124550786166,0.09976955391078215,264.1969528809969,399.0221027080113,-3.47874706785187
301.12517670121997,0.1,264.3765518125906,399.0221027080113,-3.47874706785187