File: datasets/aisi_316_L/data/M1/valid_12.csv
Time(s),Strain(%),Stress(MPa),Temp(C),Log_SR(s-1)
0.0,0.0,0.0,58.548623270331575,-3.2147708516589644
0.020988471952821917,1.28e-05,2.4953594,58.548623270331575,-3.2147708516589644
0.04460050289974657,2.7199999999999997e-05,5.3026387249999996,58.548623270331575,-3.2147708516589644
0.08001854932013357,4.88e-05,9.5135577125,58.548623270331575,-3.2147708516589644
0.09969524177590411,6.08e-05,11.85295715,58.548623270331575,-3.2147708516589644
0.1259308317169315,7.68e-05,14.9721564,58.548623270331575,-3.2147708516589644
0.17184311411372946,0.0001048,20.4307550875,58.548623270331575,-3.2147708516589644
0.20201404254591093,0.00012319999999999999,24.017834224999998,58.548623270331575,-3.2147708516589644
0.2479263249427089,0.0001512,29.476432912499998,58.548623270331575,-3.2147708516589644
0.2597323404161712,0.0001584,30.880072575,58.548623270331575,-3.2147708516589644
0.27153835588963354,0.0001656,32.2837122375,58.548623270331575,-3.2147708516589644
0.3017092843218151,0.000184,35.870791375,58.548623270331575,-3.2147708516589644
0.31351529979527737,0.00019119999999999999,37.274431037499994,58.548623270331575,-3.2147708516589644
0.32007419728053427,0.0001952,38.05423085,58.548623270331575,-3.2147708516589644
0.34106266923335615,0.000208,40.549590249999994,58.548623270331575,-3.2147708516589644
0.36861003867143494,0.0002248,43.824749462499994,58.548623270331575,-3.2147708516589644
0.4000927466006678,0.000244,47.5677885625,58.548623270331575,-3.2147708516589644
0.4315754545299007,0.0002632,51.3108276625,58.548623270331575,-3.2147708516589644
0.4420696905063116,0.0002696,52.5585073625,58.548623270331575,-3.2147708516589644
0.4551874854768253,0.00027759999999999997,54.11810698749999,58.548623270331575,-3.2147708516589644
0.46830528044733905,0.0002856,55.6777066125,58.548623270331575,-3.2147708516589644
0.5220882398264451,0.0003184,62.072065075,58.548623270331575,-3.2147708516589644
0.5247117988205479,0.00031999999999999997,62.383984999999996,58.548623270331575,-3.2147708516589644
0.6126010251229898,0.0003736,72.83330248749999,58.548623270331575,-3.2147708516589644
0.6204717021052979,0.0003784,73.7690622625,58.548623270331575,-3.2147708516589644
0.6401483945610685,0.0003904,76.1084617,58.548623270331575,-3.2147708516589644
0.6663839845020958,0.00040639999999999996,79.22766094999999,58.548623270331575,-3.2147708516589644
0.6808135589696609,0.00041519999999999995,80.9432205375,58.548623270331575,-3.2147708516589644
0.6886842359519691,0.00041999999999999996,81.87898031249999,58.548623270331575,-3.2147708516589644
0.7070491489106883,0.00043119999999999996,84.06241978749999,58.548623270331575,-3.2147708516589644
0.7201669438812021,0.0004392,85.6220194125,58.548623270331575,-3.2147708516589644
0.741155415834024,0.000452,88.1173788125,58.548623270331575,-3.2147708516589644
0.7595203287927431,0.0004632,90.3008182875,58.548623270331575,-3.2147708516589644
0.7883794777278733,0.0004808,93.7319374625,58.548623270331575,-3.2147708516589644
0.8080561701836437,0.0004927999999999999,96.07133689999999,58.548623270331575,-3.2147708516589644
0.8395388781128766,0.000512,99.814376,58.548623270331575,-3.2147708516589644
0.8500331140892877,0.0005184,101.0620557,58.548623270331575,-3.2147708516589644
0.8723333655391611,0.000532,103.7133750625,58.548623270331575,-3.2147708516589644
0.9103749709536506,0.0005551999999999999,108.23621397499998,58.548623270331575,-3.2147708516589644
0.9379223403917295,0.000572,111.5113731875,58.548623270331575,-3.2147708516589644
1.0008877562501952,0.0006104,118.99745138749999,58.548623270331575,-3.2147708516589644
1.0179408897118631,0.0006208,121.0249309,58.548623270331575,-3.2147708516589644
1.0323704641794282,0.0006296,122.7404904875,58.548623270331575,-3.2147708516589644
1.071723849090969,0.0006536,127.4192893625,58.548623270331575,-3.2147708516589644
1.1045183365172535,0.0006736,131.318288425,58.548623270331575,-3.2147708516589644
1.174042649860976,0.000716,139.5841664375,58.548623270331575,-3.2147708516589644
1.1937193423167465,0.0007279999999999999,141.92356587499998,58.548623270331575,-3.2147708516589644
1.2081489167843118,0.0007368,143.6391254625,58.548623270331575,-3.2147708516589644
1.2448787427017498,0.0007591999999999999,148.00600441249998,58.548623270331575,-3.2147708516589644
1.2593083171693151,0.000768,149.721564,58.548623270331575,-3.2147708516589644
1.2776732301280342,0.0007792,151.905003475,58.548623270331575,-3.2147708516589644
1.2934145840926508,0.0007888,153.776523025,58.548623270331575,-3.2147708516589644
1.2973499225838048,0.0007911999999999999,154.2444029125,58.548623270331575,-3.2147708516589644
1.3065323790631644,0.0007968,155.33612265,58.548623270331575,-3.2147708516589644
1.3367033074953458,0.0008152,158.9232017875,58.548623270331575,-3.2147708516589644
1.3537564409570138,0.0008256,160.9506813,58.548623270331575,-3.2147708516589644
1.4429574467565067,0.0008799999999999999,171.55595874999997,58.548623270331575,-3.2147708516589644
1.4691930366975343,0.000896,174.675158,58.548623270331575,-3.2147708516589644
1.511169980603178,0.0009216,179.66587679999998,58.548623270331575,-3.2147708516589644
1.5623293809881815,0.0009528,185.7483153375,58.548623270331575,-3.2147708516589644
1.5715118374675412,0.0009584,186.840035075,58.548623270331575,-3.2147708516589644
1.6121770018761337,0.0009832,191.6747939125,58.548623270331575,-3.2147708516589644
1.6344772533260068,0.0009968,194.32611327499998,58.548623270331575,-3.2147708516589644
1.6528421662847261,0.001008,196.50955275,58.548623270331575,-3.2147708516589644
1.692195551196267,0.001032,201.188351625,58.548623270331575,-3.2147708516589644
1.7197429206343458,0.0010488,204.46351083749997,58.548623270331575,-3.2147708516589644
1.7263018181196028,0.0010528,205.24331065,58.548623270331575,-3.2147708516589644
1.7394196130901165,0.0010608,206.802910275,58.548623270331575,-3.2147708516589644
1.7656552030311439,0.0010768,209.922109525,58.548623270331575,-3.2147708516589644
1.8181263829131984,0.0011087999999999998,216.16050802499996,58.548623270331575,-3.2147708516589644
1.8810917987716642,0.0011472,223.646586225,58.548623270331575,-3.2147708516589644
1.9283158606655137,0.001176,229.26114487499999,58.548623270331575,-3.2147708516589644
1.9335629786537192,0.0011792,229.884984725,58.548623270331575,-3.2147708516589644
1.9597985685947465,0.0011952,233.004183975,58.548623270331575,-3.2147708516589644
1.9794752610505169,0.0012071999999999999,235.34358341249998,58.548623270331575,-3.2147708516589644
1.9873459380328253,0.001212,236.2793431875,58.548623270331575,-3.2147708516589644
2.0135815279738525,0.001228,239.3985424375,58.548623270331575,-3.2147708516589644
2.025387543447315,0.0012351999999999999,240.80218209999998,58.548623270331575,-3.2147708516589644
2.050311353891291,0.0012504,243.7654213875,58.548623270331575,-3.2147708516589644
2.089664738802832,0.0012744,248.44422026249998,58.548623270331575,-3.2147708516589644
2.096223636288089,0.0012783999999999998,249.22402007499997,58.548623270331575,-3.2147708516589644
2.1132767697497568,0.0012887999999999999,251.25149958749998,58.548623270331575,-3.2147708516589644
2.1408241391878353,0.0013055999999999999,253.7558453913391,58.548623270331575,-3.2147708516589644
2.2339604834784828,0.0013624,254.17077569577486,58.548623270331575,-3.2147708516589644
2.277249206881178,0.0013888,254.36132852448355,58.548623270331575,-3.2147708516589644
2.2864316633605375,0.0013943999999999998,254.40156661537588,58.548623270331575,-3.2147708516589644
2.3179143712897705,0.0014135999999999999,254.5390498357795,58.548623270331575,-3.2147708516589644
2.33627928424849,0.0014248,254.61891206597392,58.548623270331575,-3.2147708516589644
2.3572677562013116,0.0014376,254.70988400085798,58.548623270331575,-3.2147708516589644
2.4162978335686236,0.0014736,254.9640643128217,58.548623270331575,-3.2147708516589644
2.439909864515548,0.001488,255.0650569299771,58.548623270331575,-3.2147708516589644
2.464833674959524,0.0015032,255.17124760425318,58.548623270331575,-3.2147708516589644
2.4792632494270888,0.0015119999999999999,255.23253500761223,58.548623270331575,-3.2147708516589644
2.4845103674152944,0.0015152,255.25478682519574,58.548623270331575,-3.2147708516589644
2.5238637523268355,0.0015392,255.4210951782033,58.548623270331575,-3.2147708516589644
2.536981547297349,0.0015471999999999999,255.47630615009444,58.548623270331575,-3.2147708516589644
2.58551738868825,0.0015768,255.6796258395099,58.548623270331575,-3.2147708516589644
2.6078176401381232,0.0015903999999999998,255.77254337770395,58.548623270331575,-3.2147708516589644
2.6314296710850478,0.0016048,255.87058952980874,58.548623270331575,-3.2147708516589644
2.6943950869435134,0.0016431999999999998,256.13038284072087,58.548623270331575,-3.2147708516589644
2.7298131333639004,0.0016648,256.2754758146467,58.548623270331575,-3.2147708516589644
2.7468662668255686,0.0016752,256.34507338862016,58.548623270331575,-3.2147708516589644
2.7678547387783903,0.0016879999999999998,256.4305010447455,58.548623270331575,-3.2147708516589644
2.8006492262046745,0.0017079999999999999,256.5634777181859,58.548623270331575,-3.2147708516589644
2.808519903186983,0.0017128,256.59530159038036,58.548623270331575,-3.2147708516589644
2.826884816145702,0.0017239999999999998,256.66942233638133,58.548623270331575,-3.2147708516589644
2.8439379496073696,0.0017343999999999999,256.7380807652228,58.548623270331575,-3.2147708516589644
2.851808626589678,0.0017392,256.7697150989205,58.548623270331575,-3.2147708516589644
2.858367524074935,0.0017431999999999999,256.7960510417991,58.548623270331575,-3.2147708516589644
2.870173539548397,0.0017503999999999998,256.84339642401216,58.548623270331575,-3.2147708516589644
2.8806677755248082,0.0017568,256.88541748373086,58.548623270331575,-3.2147708516589644
2.9318271759098113,0.0017879999999999999,257.0894213320458,58.548623270331575,-3.2147708516589644
2.9593745453478904,0.0018047999999999999,257.1986943044792,58.548623270331575,-3.2147708516589644
2.9961043712653286,0.0018272,257.3437765059459,58.548623270331575,-3.2147708516589644
3.018404622715202,0.0018407999999999999,257.43152375580496,58.548623270331575,-3.2147708516589644
3.032834197182767,0.0018495999999999999,257.48816669185396,58.548623270331575,-3.2147708516589644
3.078746479579565,0.0018775999999999999,257.66769895163736,58.548623270331575,-3.2147708516589644
3.099734951532387,0.0018904,257.74942277516794,58.548623270331575,-3.2147708516589644
3.1653239263849553,0.0019303999999999999,258.00342973506923,58.548623270331575,-3.2147708516589644
3.202053752302394,0.0019528,258.1447768087185,58.548623270331575,-3.2147708516589644
3.211236208781753,0.0019584,258.1800146018443,58.548623270331575,-3.2147708516589644
3.238783578219832,0.0019752,258.28549295121155,58.548623270331575,-3.2147708516589644
3.2728898451431676,0.001996,258.41560167850804,58.548623270331575,-3.2147708516589644
3.295190096593041,0.0020096,258.5003869682639,58.548623270331575,-3.2147708516589644
3.3188021275399655,0.0020239999999999998,258.58991608351965,58.548623270331575,-3.2147708516589644
3.3384788199957365,0.002036,258.6643340741372,58.548623270331575,-3.2147708516589644
3.368649748427918,0.0020544,258.7781102850857,58.548623270331575,-3.2147708516589644
3.373896866416123,0.0020575999999999997,258.79785681531166,58.548623270331575,-3.2147708516589644
3.384391102392534,0.002064,258.83731398177537,58.548623270331575,-3.2147708516589644
3.4066913538424073,0.0020775999999999998,258.9210023800295,58.548623270331575,-3.2147708516589644
3.448668297748051,0.0021032,259.0779561591602,58.548623270331575,-3.2147708516589644
3.4958923596419003,0.0021319999999999998,259.25364127749543,58.548623270331575,-3.2147708516589644
3.5208161700858764,0.0021471999999999997,259.34599069883683,58.548623270331575,-3.2147708516589644
3.5247515085770305,0.0021495999999999998,259.3605488476088,58.548623270331575,-3.2147708516589644
3.5391810830445958,0.0021584,259.4138745787322,58.548623270331575,-3.2147708516589644
3.5444282010328014,0.0021616,259.4332447224134,58.548623270331575,-3.2147708516589644
3.561481334494469,0.002172,259.4961205954136,58.548623270331575,-3.2147708516589644
3.5745991294649833,0.00218,259.5444067874617,58.548623270331575,-3.2147708516589644
3.606081837394216,0.0021992,259.6600125605603,58.548623270331575,-3.2147708516589644
3.6546176787851166,0.0022288,259.8374699136144,58.548623270331575,-3.2147708516589644
3.713647756152428,0.0022648,260.0520624942938,58.548623270331575,-3.2147708516589644
3.750377582069867,0.0022872,260.1849155638794,58.548623270331575,-3.2147708516589644
3.7779249515079454,0.002304,260.28422261550935,58.548623270331575,-3.2147708516589644
3.813342997928332,0.0023255999999999997,260.4114891317012,58.548623270331575,-3.2147708516589644
3.8382668083723086,0.0023408,260.5007708504331,58.548623270331575,-3.2147708516589644
3.8448257058575646,0.0023447999999999997,260.5242284242266,58.548623270331575,-3.2147708516589644
3.865814177810387,0.0023576,260.5991880020932,58.548623270331575,-3.2147708516589644
3.902544003727825,0.0023799999999999997,260.72998646097693,58.548623270331575,-3.2147708516589644
3.909102901213082,0.002384,260.7532927183976,58.548623270331575,-3.2147708516589644
3.918285357692442,0.0023896,260.7858958738652,58.548623270331575,-3.2147708516589644
3.947144506627572,0.0024072,260.88816948046866,58.548623270331575,-3.2147708516589644
3.95501518360988,0.002412,260.9160116163911,58.548623270331575,-3.2147708516589644
3.982562553047959,0.0024288,261.0132893790203,58.548623270331575,-3.2147708516589644
4.024539496953603,0.0024544,261.16101906941884,58.548623270331575,-3.2147708516589644
4.041592630415271,0.0024648,261.2208624571661,58.548623270331575,-3.2147708516589644
4.087504912812069,0.0024928,261.38149180946806,58.548623270331575,-3.2147708516589644
4.104558046273736,0.0025031999999999997,261.44097472749155,58.548623270331575,-3.2147708516589644
4.12685829772361,0.0025168,261.51861485684276,58.548623270331575,-3.2147708516589644
4.143911431185277,0.0025272,261.5778763690381,58.548623270331575,-3.2147708516589644
4.166211682635151,0.0025407999999999997,261.65522888037054,58.548623270331575,-3.2147708516589644
4.1872001545879725,0.0025536,261.7278838682533,58.548623270331575,-3.2147708516589644
4.191135493079126,0.0025559999999999997,261.7414908518652,58.548623270331575,-3.2147708516589644
4.222618201008359,0.0025751999999999997,261.850167915112,58.548623270331575,-3.2147708516589644
4.244918452458233,0.0025888,261.92695639193664,58.548623270331575,-3.2147708516589644
4.260659806422849,0.0025984,261.98106532913954,58.548623270331575,-3.2147708516589644
4.2803364988786194,0.0026103999999999997,262.048591987986,58.548623270331575,-3.2147708516589644
4.33805479674888,0.0026455999999999997,262.2459752572544,58.548623270331575,-3.2147708516589644
4.352484371216445,0.0026544,262.295160712424,58.548623270331575,-3.2147708516589644
4.378719961157472,0.0026704,262.38442619423176,58.548623270331575,-3.2147708516589644
4.399708433110294,0.0026831999999999997,262.4556884866626,58.548623270331575,-3.2147708516589644
4.43381470003363,0.002704,262.57120759149956,58.548623270331575,-3.2147708516589644
4.4364382590277325,0.0027056,262.5800792962448,58.548623270331575,-3.2147708516589644
4.446932495004144,0.002712,262.6155456733191,58.548623270331575,-3.2147708516589644
4.466609187459914,0.002724,262.6819572752522,58.548623270331575,-3.2147708516589644
4.495468336395044,0.0027416,262.7791549373326,58.548623270331575,-3.2147708516589644
4.525639264827226,0.00276,262.8805108412359,58.548623270331575,-3.2147708516589644
4.597787137165051,0.002804,263.12182102848067,58.548623270331575,-3.2147708516589644
4.618775609117873,0.0028168,263.19174247512274,58.548623270331575,-3.2147708516589644
4.633205183585438,0.0028255999999999997,263.23974160466304,58.548623270331575,-3.2147708516589644
4.6450111990589,0.0028328,263.27897027085265,58.548623270331575,-3.2147708516589644
4.676493906988133,0.002852,263.38339040714567,58.548623270331575,-3.2147708516589644
4.686988142964544,0.0028583999999999997,263.41813614829687,58.548623270331575,-3.2147708516589644
4.697482378940955,0.0028648,263.45285156213123,58.548623270331575,-3.2147708516589644
4.71060017391147,0.0028728,263.49620332499416,58.548623270331575,-3.2147708516589644
4.730276866367239,0.0028848,263.561142794886,58.548623270331575,-3.2147708516589644
4.753888897314164,0.0028991999999999998,263.63893126102937,58.548623270331575,-3.2147708516589644
4.808983636190321,0.0029327999999999997,263.81985404107394,58.548623270331575,-3.2147708516589644
4.8273485491490415,0.002944,263.8799817579537,58.548623270331575,-3.2147708516589644
4.8339074466342975,0.0029479999999999997,263.90143431399235,58.548623270331575,-3.2147708516589644
4.860143036575326,0.002964,263.9871312605029,58.548623270331575,-3.2147708516589644
4.892937524001609,0.0029839999999999997,264.09399915881767,58.548623270331575,-3.2147708516589644
4.898184641989815,0.0029871999999999998,264.1110720653313,58.548623270331575,-3.2147708516589644
4.957214719357126,0.0030231999999999998,264.30265335633527,58.548623270331575,-3.2147708516589644
4.965085396339435,0.003028,264.32813013874244,58.548623270331575,-3.2147708516589644
4.987385647789308,0.0030415999999999998,264.4002289627799,58.548623270331575,-3.2147708516589644
4.993944545274565,0.0030456,264.4214105577422,58.548623270331575,-3.2147708516589644
5.001815222256873,0.0030504,264.44681415573797,58.548623270331575,-3.2147708516589644
5.024115473706747,0.003064,264.5187064934819,58.548623270331575,-3.2147708516589644
5.072651315097647,0.0030935999999999997,264.67474926189533,58.548623270331575,-3.2147708516589644
5.1067575820209825,0.0031144,264.78405277300425,58.548623270331575,-3.2147708516589644
5.110692920512137,0.0031168,264.79664637000724,58.548623270331575,-3.2147708516589644
5.134304951459061,0.0031311999999999998,264.8721286840877,58.548623270331575,-3.2147708516589644
5.14217562844137,0.003136,264.8972593546966,58.548623270331575,-3.2147708516589644
5.172346556873551,0.0031544,264.99345493965495,58.548623270331575,-3.2147708516589644
5.2235059572585545,0.0031856,265.15607055141777,58.548623270331575,-3.2147708516589644
5.244494429211376,0.0031983999999999997,265.2226048232824,58.548623270331575,-3.2147708516589644
5.273353578146507,0.0032159999999999997,265.31392013619063,58.548623270331575,-3.2147708516589644
5.2864713731170205,0.003224,265.3553626473284,58.548623270331575,-3.2147708516589644
5.314018742555099,0.0032408,265.4422616042985,58.548623270331575,-3.2147708516589644
5.382231276401771,0.0032824,265.6566872661888,58.548623270331575,-3.2147708516589644
5.4110904253369005,0.0033,265.74708646607996,58.548623270331575,-3.2147708516589644
5.432078897289722,0.0033128,265.812713279775,58.548623270331575,-3.2147708516589644
5.471432282201264,0.0033368,265.9354976262577,58.548623270331575,-3.2147708516589644
5.52521524158037,0.0033696,266.10274734618537,58.548623270331575,-3.2147708516589644
5.539644816047935,0.0033783999999999997,266.1475110448604,58.548623270331575,-3.2147708516589644
5.576374641965373,0.0034008,266.2612502938013,58.548623270331575,-3.2147708516589644
5.6288458218474275,0.0034327999999999997,266.42322940673256,58.548623270331575,-3.2147708516589644
5.638028278326788,0.0034384,266.45151510124566,58.548623270331575,-3.2147708516589644
5.6445871758120445,0.0034424,266.4717081699849,58.548623270331575,-3.2147708516589644
5.660328529776661,0.0034519999999999998,266.52013423567075,58.548623270331575,-3.2147708516589644
5.685252340220637,0.0034671999999999997,266.5967015626977,58.548623270331575,-3.2147708516589644
5.7455941970849995,0.0035039999999999997,266.7815349719284,58.548623270331575,-3.2147708516589644
5.778388684511284,0.003524,266.88167032499166,58.548623270331575,-3.2147708516589644
5.80331249495526,0.0035391999999999997,266.9576250309436,58.548623270331575,-3.2147708516589644
5.819053848919877,0.0035488,267.00553088224837,58.548623270331575,-3.2147708516589644
5.838730541375647,0.0035608,267.0653421828426,58.548623270331575,-3.2147708516589644
5.891201721257702,0.0035927999999999997,267.2244559113245,58.548623270331575,-3.2147708516589644
5.918749090695781,0.0036095999999999997,267.3077693147845,58.548623270331575,-3.2147708516589644
5.929243326672192,0.003616,267.33946795854536,58.548623270331575,-3.2147708516589644
5.975155609068989,0.0036439999999999997,267.4778930555465,58.548623270331575,-3.2147708516589644
5.993520522027709,0.0036552,267.5331468701118,58.548623270331575,-3.2147708516589644
6.0105736554893765,0.0036655999999999998,267.58439489008293,58.548623270331575,-3.2147708516589644
6.0420563634186095,0.0036848,267.6788578871169,58.548623270331575,-3.2147708516589644
6.045991701909764,0.0036872,267.690652249628,58.548623270331575,-3.2147708516589644
6.064356614868482,0.0036983999999999997,267.74565306922517,58.548623270331575,-3.2147708516589644
6.086656866318356,0.003712,267.81235252651294,58.548623270331575,-3.2147708516589644
6.133880928212205,0.0037408,267.9532846466053,58.548623270331575,-3.2147708516589644
6.162740077147335,0.0037584,268.03920153942914,58.548623270331575,-3.2147708516589644
6.169298974632593,0.0037624,268.0587062060012,58.548623270331575,-3.2147708516589644
6.207340580047082,0.0037855999999999996,268.17167420118454,58.548623270331575,-3.2147708516589644
6.23357616998811,0.0038016,268.24942589576415,58.548623270331575,-3.2147708516589644
6.258499980432085,0.0038168,268.32317188011797,58.548623270331575,-3.2147708516589644
6.29129446785837,0.0038368,268.42003180333217,58.548623270331575,-3.2147708516589644
6.301788703834781,0.0038431999999999997,268.45098536505253,58.548623270331575,-3.2147708516589644
6.322777175787603,0.0038559999999999996,268.51283224527793,58.548623270331575,-3.2147708516589644
6.356883442710938,0.0038767999999999997,268.6131629306809,58.548623270331575,-3.2147708516589644
6.367377678687349,0.0038832,268.6439916463976,58.548623270331575,-3.2147708516589644
6.4001721661136335,0.0039032,268.74020391190555,58.548623270331575,-3.2147708516589644
6.405419284101839,0.0039064,268.7555800142233,58.548623270331575,-3.2147708516589644
6.4618258024750475,0.0039407999999999995,268.920564063629,58.548623270331575,-3.2147708516589644
6.498555628392486,0.0039632,269.0276936760632,58.548623270331575,-3.2147708516589644
6.653364502447986,0.004057611522304461,269.4766527974184,58.548623270331575,-3.2147708516589644
8.511215840540345,0.005190638127625526,274.5804162801735,58.548623270331575,-3.2147708516589644
8.70014987492262,0.0053058611722344474,275.0737698000786,58.548623270331575,-3.2147708516589644
8.857594903574514,0.005401880376075216,275.4817138342218,58.548623270331575,-3.2147708516589644
9.140995955147924,0.0055747149429885975,276.20895667367256,58.548623270331575,-3.2147708516589644
9.329929989530196,0.005689937987597519,276.68890558156806,58.548623270331575,-3.2147708516589644
10.022688115598534,0.006112422484496899,278.41718804321744,58.548623270331575,-3.2147708516589644
11.471182379195966,0.006995799159831967,281.88698334460054,58.548623270331575,-3.2147708516589644
12.195429510994682,0.0074374874974994995,283.55738823236817,58.548623270331575,-3.2147708516589644
12.951165648523776,0.007898379675935187,285.25966448727615,58.548623270331575,-3.2147708516589644
14.179236872008556,0.008647329465893179,287.94542549407,58.548623270331575,-3.2147708516589644
16.068577215831294,0.009799559911982397,291.9064189881717,58.548623270331575,-3.2147708516589644
16.5094232960566,0.010068413682736548,292.80398195886676,58.548623270331575,-3.2147708516589644
17.957917559654028,0.010951790358071613,295.68939754599455,58.548623270331575,-3.2147708516589644
18.997054748756536,0.011585517103420685,297.70369118897776,58.548623270331575,-3.2147708516589644
19.31194480606033,0.011777555511102222,298.3055374504299,58.548623270331575,-3.2147708516589644
20.66597205246662,0.012603320664132826,300.851041870428,58.548623270331575,-3.2147708516589644
21.106818132691927,0.012872174434886977,301.66566020227197,58.548623270331575,-3.2147708516589644
21.2957521670742,0.012987397479495899,302.01274797147306,58.548623270331575,-3.2147708516589644
22.019999298872914,0.013429085817163433,303.3322715532559,58.548623270331575,-3.2147708516589644
23.059136487975422,0.014062812562512503,305.1963086413994,58.548623270331575,-3.2147708516589644
23.468493562470346,0.0143124624924985,305.9215947481636,58.548623270331575,-3.2147708516589644
23.814872625504517,0.01452370474094819,306.5314527857296,58.548623270331575,-3.2147708516589644
25.420811917753845,0.015503100620124026,309.31496401279963,58.548623270331575,-3.2147708516589644
25.483789929214602,0.015541508301660333,309.4227010529941,58.548623270331575,-3.2147708516589644
25.73570197505763,0.01569513902780556,309.8526148812056,58.548623270331575,-3.2147708516589644
26.585905129777867,0.01621364272854571,311.2916080712688,58.548623270331575,-3.2147708516589644
26.869306181351273,0.01638647729545909,311.76726926845754,58.548623270331575,-3.2147708516589644
27.40461927876771,0.0167129425885177,312.6604356942563,58.548623270331575,-3.2147708516589644
27.467597290228476,0.016751350270054012,312.76506486971886,58.548623270331575,-3.2147708516589644
27.97142138191454,0.01705861172234447,313.59875641486343,58.548623270331575,-3.2147708516589644
28.632690502252494,0.017461892378475695,314.6841423004791,58.548623270331575,-3.2147708516589644
29.0735365824778,0.017730746149229846,315.4023064349322,58.548623270331575,-3.2147708516589644
29.860761725737277,0.01821084216843369,316.67426708713793,58.548623270331575,-3.2147708516589644
30.396074823153718,0.0185373074614923,317.5317387614795,58.548623270331575,-3.2147708516589644
30.773942891918264,0.018767753550710142,318.13347049983497,58.548623270331575,-3.2147708516589644
31.183299966413188,0.019017403480696138,318.7821040146361,58.548623270331575,-3.2147708516589644
31.52967902944736,0.01922864572914583,319.3283581226928,58.548623270331575,-3.2147708516589644
32.00201411540305,0.019516703340668136,320.0694932407629,58.548623270331575,-3.2147708516589644
33.32455235607896,0.020323264652930585,322.1223118331543,58.548623270331575,-3.2147708516589644
33.51348639046123,0.020438487697539507,322.41295663083423,58.548623270331575,-3.2147708516589644
34.42666755664222,0.020995399079815964,323.8088298459294,58.548623270331575,-3.2147708516589644
34.86751363686753,0.021264252850570115,324.4775249086452,58.548623270331575,-3.2147708516589644
35.40282673428397,0.021590718143628725,325.2850951895784,58.548623270331575,-3.2147708516589644
36.03260684889155,0.021974794958991798,326.22910594055605,58.548623270331575,-3.2147708516589644
36.28451889473458,0.022128425685137027,326.60490582656956,58.548623270331575,-3.2147708516589644
37.67003514687126,0.022973394678935787,328.6538982982544,58.548623270331575,-3.2147708516589644
38.42577128440035,0.023434286857371475,329.7591333803902,58.548623270331575,-3.2147708516589644
38.67768333024338,0.023587917583516704,330.1256568941996,58.548623270331575,-3.2147708516589644
39.27597443912058,0.02395279055811162,330.9924389463333,58.548623270331575,-3.2147708516589644
39.46490847350285,0.024068013602720543,331.26508775164785,58.548623270331575,-3.2147708516589644
40.47255665687498,0.02468253650730146,332.71070659447315,58.548623270331575,-3.2147708516589644
40.692979696987635,0.024816963392678536,333.0250567017563,58.548623270331575,-3.2147708516589644
41.7950948975509,0.025489097819563912,334.5869549091668,58.548623270331575,-3.2147708516589644
43.086144132496436,0.026276455291058213,336.39632163794374,58.548623270331575,-3.2147708516589644
43.684435241373635,0.02664132826565313,337.22762669904876,58.548623270331575,-3.2147708516589644
44.408682373172354,0.027083016603320666,338.2280259274809,58.548623270331575,-3.2147708516589644
44.975484476319174,0.02742868573714743,339.0065152894887,58.548623270331575,-3.2147708516589644
45.9831326596913,0.028043208641728348,340.3811139771141,58.548623270331575,-3.2147708516589644
46.32951172272547,0.028254450890178036,340.85091245437917,58.548623270331575,-3.2147708516589644
46.801846808681155,0.028542508501700342,341.4893450976122,58.548623270331575,-3.2147708516589644
48.02991803216593,0.029291458291658332,343.1376191617585,58.548623270331575,-3.2147708516589644
48.75416516396464,0.029733146629325864,344.1019736998492,58.548623270331575,-3.2147708516589644
49.28947826138109,0.030059611922384478,344.8111704565995,58.548623270331575,-3.2147708516589644
49.95074738171905,0.030462892578515702,345.6831033250543,58.548623270331575,-3.2147708516589644
50.45457147340511,0.03077015403080616,346.3444148357196,58.548623270331575,-3.2147708516589644
51.30477462812534,0.03128865773154631,347.454567627476,58.548623270331575,-3.2147708516589644
52.784757897453154,0.03219123824764953,349.3700901838517,58.548623270331575,-3.2147708516589644
53.03666994329618,0.03234486897379476,349.6940392487745,58.548623270331575,-3.2147708516589644
53.131136960487325,0.03240248049609922,349.81536536839565,58.548623270331575,-3.2147708516589644
53.25709298340884,0.032479295859171836,349.97700274042114,58.548623270331575,-3.2147708516589644
54.516653212624,0.03324744948989798,351.58526000297525,58.548623270331575,-3.2147708516589644
54.98898829857968,0.03353550710142028,352.18461204392975,58.548623270331575,-3.2147708516589644
55.524301395996126,0.0338619723944789,352.8614557836303,58.548623270331575,-3.2147708516589644
55.965147476221425,0.034130826165233046,353.41694765916077,58.548623270331575,-3.2147708516589644
56.46897156790749,0.034438087617523504,354.04971016206036,58.548623270331575,-3.2147708516589644
57.224707705436586,0.03489897979595919,354.994741134446,58.548623270331575,-3.2147708516589644
57.948954837235306,0.035340668133626726,355.8958388327465,58.548623270331575,-3.2147708516589644
59.08255904352893,0.03603200640128025,357.2974847408518,58.548623270331575,-3.2147708516589644
59.77531716959728,0.036454490898179634,358.1488841395726,58.548623270331575,-3.2147708516589644
59.90127319251881,0.036531306261252255,358.30326969902734,58.548623270331575,-3.2147708516589644
60.34211927274409,0.036800160032006396,358.84262495975594,58.548623270331575,-3.2147708516589644
60.53105330712637,0.03691538307661532,359.0733065353121,58.548623270331575,-3.2147708516589644
60.908921375890934,0.03714582916583317,359.53382898635664,58.548623270331575,-3.2147708516589644
62.07401458791495,0.037856371274254855,360.94680888562345,58.548623270331575,-3.2147708516589644
62.48337166240987,0.03810602120424085,361.4408008773628,58.548623270331575,-3.2147708516589644
63.14464078274783,0.038509301860372075,362.2361299962079,58.548623270331575,-3.2147708516589644
64.40420101196298,0.03927745549109822,363.74211347458413,58.548623270331575,-3.2147708516589644
64.71909106926677,0.03946949389877975,364.11680914530154,58.548623270331575,-3.2147708516589644
64.97100311510981,0.03962312462492498,364.41605401453774,58.548623270331575,-3.2147708516589644
66.48247539016799,0.04054490898179636,366.2021119611255,58.548623270331575,-3.2147708516589644
67.01778848758444,0.040871374274854974,366.8308674015555,58.548623270331575,-3.2147708516589644
67.36416755061862,0.041082616523304666,367.2366656836291,58.548623270331575,-3.2147708516589644
68.05692567668693,0.041505101020204035,368.0458291695093,58.548623270331575,-3.2147708516589644
68.40330473972111,0.04171634326865373,368.449205852957,58.548623270331575,-3.2147708516589644
68.49777175691224,0.04177395479095819,368.5590793199905,58.548623270331575,-3.2147708516589644
69.06457386005906,0.04211962392478495,369.2170833750166,58.548623270331575,-3.2147708516589644
69.78882099185779,0.042561312262452494,370.05480957765855,58.548623270331575,-3.2147708516589644
70.29264508354386,0.04286857371474295,370.6355770143206,58.548623270331575,-3.2147708516589644
70.5130681236565,0.04300300060012002,370.88915202957213,58.548623270331575,-3.2147708516589644
70.92242519815143,0.04325265053010602,371.3592583966659,58.548623270331575,-3.2147708516589644
71.89858437579319,0.04384796959391879,372.47603122919577,58.548623270331575,-3.2147708516589644
72.93772156489568,0.04448169633926785,373.6583756061651,58.548623270331575,-3.2147708516589644
73.78792471961592,0.045000200040008,374.62086945249166,58.548623270331575,-3.2147708516589644
73.94536974826781,0.04509621924384877,374.7986334105632,58.548623270331575,-3.2147708516589644
74.76408389725765,0.04559551910382076,375.72063723797106,58.548623270331575,-3.2147708516589644
75.51982003478675,0.046056411282256446,376.56822875870944,58.548623270331575,-3.2147708516589644
77.22022634422721,0.047093418683736746,378.4633073136099,58.548623270331575,-3.2147708516589644
77.34618236714874,0.04717023404680937,378.6030327111803,58.548623270331575,-3.2147708516589644
77.535116401531,0.04728545709141828,378.8124545352067,58.548623270331575,-3.2147708516589644
78.19638552186898,0.04768873774754952,379.5438687730316,58.548623270331575,-3.2147708516589644
80.52657194591701,0.04910982196439288,382.10222436531996,58.548623270331575,-3.2147708516589644
81.53422012928914,0.0497243448689738,383.19957981308164,58.548623270331575,-3.2147708516589644
82.38442328400937,0.05024284856971395,384.12136557327244,58.548623270331575,-3.2147708516589644
82.63633532985241,0.05039647929585918,384.39377382848187,58.548623270331575,-3.2147708516589644
82.7937803585043,0.050492498499699945,384.5638645362309,58.548623270331575,-3.2147708516589644
83.01420339861694,0.050626925385077015,384.8017797533199,58.548623270331575,-3.2147708516589644
83.42356047311188,0.05087657531506301,385.2429696835458,58.548623270331575,-3.2147708516589644
84.24227462210172,0.051375875175035,386.1228247330671,58.548623270331575,-3.2147708516589644
84.55716467940553,0.05156791358271655,386.4603417536603,58.548623270331575,-3.2147708516589644
85.12396678255234,0.05191358271654331,387.06663968980837,58.548623270331575,-3.2147708516589644
85.34438982266498,0.05204800960192038,387.3019967689269,58.548623270331575,-3.2147708516589644
85.56481286277766,0.052182436487297465,387.53711689857,58.548623270331575,-3.2147708516589644
87.04479613210546,0.05308501700340068,389.10970735915555,58.548623270331575,-3.2147708516589644
88.74520244154593,0.05412202440488098,390.9036970371443,58.548623270331575,-3.2147708516589644
88.99711448738896,0.05427565513102621,391.16832873998646,58.548623270331575,-3.2147708516589644
89.62689460199653,0.054659731946389276,391.8286331240325,58.548623270331575,-3.2147708516589644
89.97327366503069,0.05487097419483897,392.1910291569044,58.548623270331575,-3.2147708516589644
90.50858676244715,0.055197439487897584,392.7500273583355,58.548623270331575,-3.2147708516589644
90.94943284267244,0.055466293258651725,393.2094112835389,58.548623270331575,-3.2147708516589644
91.39027892289775,0.05573514702940588,393.6679276098444,58.548623270331575,-3.2147708516589644
92.24048207761798,0.05625365073014603,394.5497804501876,58.548623270331575,-3.2147708516589644
92.5238831291914,0.05642648529705942,394.8430262026194,58.548623270331575,-3.2147708516589644
92.90175119795593,0.056656931386277254,395.2334762046326,58.548623270331575,-3.2147708516589644
93.21664125525972,0.05684896979395879,395.5583783059406,58.548623270331575,-3.2147708516589644
93.59450932402427,0.05707941588317664,395.94769636402316,58.548623270331575,-3.2147708516589644
93.90939938132806,0.05727145429085817,396.2716600381725,58.548623270331575,-3.2147708516589644
94.53917949593566,0.05765553110622125,396.9183192191986,58.548623270331575,-3.2147708516589644
95.70427270795967,0.05836607321464293,398.1102269529117,58.548623270331575,-3.2147708516589644
96.49149785121914,0.058846169233846765,398.9123681221168,58.548623270331575,-3.2147708516589644
96.96383293717483,0.05913422684536908,399.39242782434536,58.548623270331575,-3.2147708516589644
98.3493491893115,0.05997919583916783,400.79536937024193,58.548623270331575,-3.2147708516589644
98.47530521223302,0.06005601120224045,400.9225260664056,58.548623270331575,-3.2147708516589644
98.88466228672795,0.06030566113222645,401.3353479563913,58.548623270331575,-3.2147708516589644
99.70337643571779,0.06080496099219844,402.1589976535905,58.548623270331575,-3.2147708516589644
100.80549163628106,0.06147709541908382,403.2636035664119,58.548623270331575,-3.2147708516589644
101.40378274515827,0.06184196839367874,403.8612739818716,58.548623270331575,-3.2147708516589644
101.84462882538358,0.062110822164432894,404.3007830700297,58.548623270331575,-3.2147708516589644
103.54503513482402,0.06314782956591318,405.9891274380421,58.548623270331575,-3.2147708516589644
104.20630425516198,0.0635511102220444,406.64278129731366,58.548623270331575,-3.2147708516589644
104.30077127235312,0.06360872174434887,406.73602819331893,58.548623270331575,-3.2147708516589644
104.74161735257843,0.06387757551510302,407.1707456118414,58.548623270331575,-3.2147708516589644
104.9305513869607,0.06399279855971195,407.3568345711853,58.548623270331575,-3.2147708516589644
105.87522155887206,0.06456891378275655,408.28532642920266,58.548623270331575,-3.2147708516589644
106.06415559325434,0.06468413682736547,408.47063647724417,58.548623270331575,-3.2147708516589644
108.36285301157201,0.06608601720344069,410.7150279076806,58.548623270331575,-3.2147708516589644
108.58327605168465,0.06622044408881776,410.9292632261296,58.548623270331575,-3.2147708516589644
109.08710014337072,0.06652770554110822,411.418308072989,58.548623270331575,-3.2147708516589644
109.15007815483149,0.06656611322264454,411.4793766813307,58.548623270331575,-3.2147708516589644
110.34666037258587,0.06729585917183437,412.63708204897637,58.548623270331575,-3.2147708516589644
110.85048446427194,0.06760312062412482,413.1230710122938,58.548623270331575,-3.2147708516589644
111.88962165337446,0.0682368473694739,414.1227110477568,58.548623270331575,-3.2147708516589644
112.29897872786938,0.0684864972994599,414.51551372588585,58.548623270331575,-3.2147708516589644
113.02322585966809,0.06892818563712742,415.2091070695905,58.548623270331575,-3.2147708516589644
113.30662691124151,0.06910102020404081,415.4800410547253,58.548623270331575,-3.2147708516589644
113.55853895708454,0.06925465093018604,415.72064947334866,58.548623270331575,-3.2147708516589644
113.96789603157946,0.06950430086017204,416.1111946559483,58.548623270331575,-3.2147708516589644
114.15683006596174,0.06961952390478096,416.29126172216303,58.548623270331575,-3.2147708516589644
114.5032091289959,0.06983076615323065,416.62108309915595,58.548623270331575,-3.2147708516589644
114.84958819203008,0.07004200840168034,416.95051559041303,58.548623270331575,-3.2147708516589644
115.16447824933387,0.07023404680936188,417.2496635817931,58.548623270331575,-3.2147708516589644
115.63681333528955,0.07052210442088418,417.6977881389419,58.548623270331575,-3.2147708516589644
115.69979134675032,0.0705605121024205,417.7574840976507,58.548623270331575,-3.2147708516589644
116.07765941551486,0.07079095819163833,418.115394088321,58.548623270331575,-3.2147708516589644
116.70743953012244,0.07117503500700141,418.71090263105845,58.548623270331575,-3.2147708516589644
117.30573063899962,0.07153990798159632,419.27547597910836,58.548623270331575,-3.2147708516589644
117.6521097020338,0.07175115023004601,419.60182095059537,58.548623270331575,-3.2147708516589644
118.50231285675403,0.07226965393078616,420.40126492286316,58.548623270331575,-3.2147708516589644
118.97464794270974,0.07255771154230847,420.84443381538097,58.548623270331575,-3.2147708516589644
119.10060396563124,0.07263452690538108,420.96249623398427,58.548623270331575,-3.2147708516589644
119.35251601147426,0.07278815763152631,421.1984750888035,58.548623270331575,-3.2147708516589644
119.66740606877805,0.07298019603920784,421.4931756758276,58.548623270331575,-3.2147708516589644
120.07676314327297,0.07322984596919384,421.87583469839376,58.548623270331575,-3.2147708516589644
120.86398828653246,0.07370994198839768,422.6102904868842,58.548623270331575,-3.2147708516589644
120.98994430945396,0.07378675735147029,422.727630060059,58.548623270331575,-3.2147708516589644
121.30483436675777,0.07397879575915184,423.02077075742653,58.548623270331575,-3.2147708516589644
121.99759249282609,0.07440128025605121,423.66463768651073,58.548623270331575,-3.2147708516589644
122.50141658451216,0.07470854170834167,424.1320092781143,58.548623270331575,-3.2147708516589644
123.72948780799695,0.07545749149829967,425.2680979164588,58.548623270331575,-3.2147708516589644
124.57969096271718,0.07597599519903982,426.05204594898373,58.548623270331575,-3.2147708516589644
125.68180616328044,0.0766481296259252,427.06517638499827,58.548623270331575,-3.2147708516589644
125.96520721485385,0.07682096419283857,427.32513486973727,58.548623270331575,-3.2147708516589644
126.05967423204498,0.07687857571514303,427.4117369967608,58.548623270331575,-3.2147708516589644
126.4690313065399,0.07712822564512903,427.78672078652426,58.548623270331575,-3.2147708516589644
126.84689937530446,0.07735867173434688,428.13243973968446,58.548623270331575,-3.2147708516589644
127.3822124727209,0.07768513702740548,428.62152150159267,58.548623270331575,-3.2147708516589644
128.1064596045196,0.07812682536507302,429.2819464033058,58.548623270331575,-3.2147708516589644
128.92517375350948,0.07862612522504502,430.0267627736453,58.548623270331575,-3.2147708516589644
129.303041822274,0.07885657131426285,430.3699018053184,58.548623270331575,-3.2147708516589644
131.31833818901825,0.08008561712342468,432.1934138516312,58.548623270331575,-3.2147708516589644
131.79067327497395,0.080373674734947,432.6192168209107,58.548623270331575,-3.2147708516589644
132.57789841823342,0.08085377075415083,433.3275682215847,58.548623270331575,-3.2147708516589644
133.01874449845874,0.08112262452490498,433.72352845270973,58.548623270331575,-3.2147708516589644
134.0893706932916,0.0817755551110222,434.6830214670451,58.548623270331575,-3.2147708516589644
135.0025518594726,0.08233246649329866,435.499053907146,58.548623270331575,-3.2147708516589644
135.1599968881245,0.08242848569713944,435.63953130152504,58.548623270331575,-3.2147708516589644
135.44339793969792,0.08260132026405281,435.892229892669,58.548623270331575,-3.2147708516589644
135.6323319740802,0.08271654330866174,436.06058106829335,58.548623270331575,-3.2147708516589644
136.51402413453079,0.08325425085017003,436.84501377103237,58.548623270331575,-3.2147708516589644
136.70295816891306,0.08336947389477896,437.01284914553827,58.548623270331575,-3.2147708516589644
136.8289141918346,0.08344628925785158,437.124689139702,58.548623270331575,-3.2147708516589644
137.7106063522852,0.08398399679935988,437.90644792128626,58.548623270331575,-3.2147708516589644
139.15910061588264,0.08486737347469495,439.1865414900666,58.548623270331575,-3.2147708516589644
139.2220786273434,0.08490578115623125,439.2420795468664,58.548623270331575,-3.2147708516589644
139.41101266172566,0.08502100420084018,439.4086349592479,58.548623270331575,-3.2147708516589644
139.72590271902945,0.08521304260852171,439.6860318217719,58.548623270331575,-3.2147708516589644
140.32419382790664,0.08557791558311663,440.2124150929404,58.548623270331575,-3.2147708516589644
140.89099593105345,0.08592358471694339,440.7102871750817,58.548623270331575,-3.2147708516589644
141.86715510869524,0.08651890378075616,441.5659063160933,58.548623270331575,-3.2147708516589644
142.55991323476354,0.08694138827765553,442.1717275412083,58.548623270331575,-3.2147708516589644
142.96927030925846,0.08719103820764153,442.52917315204144,58.548623270331575,-3.2147708516589644
144.16585252701287,0.08792078415683137,443.5717326412913,58.548623270331575,-3.2147708516589644
144.95307767027236,0.08840088017603522,444.25578711196005,58.548623270331575,-3.2147708516589644
145.173500710385,0.08853530706141229,444.4470625315747,58.548623270331575,-3.2147708516589644
145.23647872184577,0.08857371474294859,444.50169184350085,58.548623270331575,-3.2147708516589644
146.18114889375713,0.0891498299659932,445.32002609669485,58.548623270331575,-3.2147708516589644
146.87390701982548,0.08957231446289259,445.9188276757673,58.548623270331575,-3.2147708516589644
147.06284105420775,0.08968753750750151,446.0819458994457,58.548623270331575,-3.2147708516589644
147.66113216308494,0.09005241048209642,446.5979485874196,58.548623270331575,-3.2147708516589644
148.66878034645705,0.09066693338667733,447.465166464313,58.548623270331575,-3.2147708516589644
149.17260443814314,0.09097419483896779,447.8979155514374,58.548623270331575,-3.2147708516589644
149.70791753555957,0.09130066013202641,448.35708735371173,58.548623270331575,-3.2147708516589644
150.18025262151525,0.09158871774354871,448.7617074490312,58.548623270331575,-3.2147708516589644
151.3138568278089,0.09228005601120225,449.7307760972319,58.548623270331575,-3.2147708516589644
151.84916992522534,0.09260652130426085,450.18740725765497,58.548623270331575,-3.2147708516589644
153.07724114871013,0.09335547109421885,451.2326072768743,58.548623270331575,-3.2147708516589644
153.73851026904808,0.09375875175035008,451.7940525435484,58.548623270331575,-3.2147708516589644
155.09253751545438,0.09458451690338068,452.94074846935507,58.548623270331575,-3.2147708516589644
156.60400979051258,0.09550630126025206,454.21617931322794,58.548623270331575,-3.2147708516589644
157.64314697961507,0.09614002800560112,455.09025445988107,58.548623270331575,-3.2147708516589644
158.30441609995304,0.09654330866173236,455.6453143492155,58.548623270331575,-3.2147708516589644
158.6822841687176,0.0967737547509502,455.9620854310735,58.548623270331575,-3.2147708516589644
159.12313024894289,0.09704260852170435,456.331280115333,58.548623270331575,-3.2147708516589644
159.62695434062894,0.09734986997399481,456.75272878987874,58.548623270331575,-3.2147708516589644
161.42182766726054,0.09844448889777956,458.249941873957,58.548623270331575,-3.2147708516589644
161.61076170164282,0.09855971194238848,458.4071646367944,58.548623270331575,-3.2147708516589644
162.20905281052003,0.0989245849169834,458.90456446764796,58.548623270331575,-3.2147708516589644
162.8388329251276,0.09930866173234647,459.42737088548483,58.548623270331575,-3.2147708516589644
163.5630800569263,0.09975035007001401,460.02762439788034,58.548623270331575,-3.2147708516589644
163.81499210276937,0.09990398079615924,460.236165134547,58.548623270331575,-3.2147708516589644