File: datasets/aisi_316_L/data/M1/valid_14.csv
Time(s),Strain(%),Stress(MPa),Temp(C),Log_SR(s-1)
0.0,0.0,0.0,193.85572948183662,-3.4834923863807044
0.03166108004077564,1.0399999999999999e-05,1.9386550624999999,193.85572948183662,-3.4834923863807044
0.13882165864032395,4.56e-05,8.5002568125,193.85572948183662,-3.4834923863807044
0.1583054002038782,5.2e-05,9.693275312499999,193.85572948183662,-3.4834923863807044
0.2313694310672066,7.599999999999999e-05,14.167094687499999,193.85572948183662,-3.4834923863807044
0.26303051110798226,8.64e-05,16.10574975,193.85572948183662,-3.4834923863807044
0.33122360658042205,0.00010879999999999999,20.281314499999997,193.85572948183662,-3.4834923863807044
0.3507073481439763,0.0001152,21.474332999999998,193.85572948183662,-3.4834923863807044
0.42864231439819334,0.0001408,26.246407,193.85572948183662,-3.4834923863807044
0.443255120570859,0.0001456,27.141170874999997,193.85572948183662,-3.4834923863807044
0.46760979752530174,0.0001536,28.632444,193.85572948183662,-3.4834923863807044
0.5358028929977416,0.000176,32.80800875,193.85572948183662,-3.4834923863807044
0.5698994407339616,0.0001872,34.895791125,193.85572948183662,-3.4834923863807044
0.5991250530792929,0.00019679999999999999,36.685318875,193.85572948183662,-3.4834923863807044
0.6551408100745113,0.0002152,40.115247062499996,193.85572948183662,-3.4834923863807044
0.7062856316788413,0.000232,43.246920625,193.85572948183662,-3.4834923863807044
0.7793496625421696,0.000256,47.72074,193.85572948183662,-3.4834923863807044
0.8353654195373881,0.0002744,51.1506681875,193.85572948183662,-3.4834923863807044
0.9327841273551591,0.00030639999999999997,57.11576068749999,193.85572948183662,-3.4834923863807044
0.9522678689187134,0.00031279999999999996,58.308779187499994,193.85572948183662,-3.4834923863807044
1.0155900290002648,0.0003336,62.186089312499995,193.85572948183662,-3.4834923863807044
1.1276215429907017,0.0003704,69.0459456875,193.85572948183662,-3.4834923863807044
1.2737496047173584,0.0004184,77.99358443749999,193.85572948183662,-3.4834923863807044
1.3005397493672455,0.0004272,79.633984875,193.85572948183662,-3.4834923863807044
1.322458958626244,0.0004344,80.9761306875,193.85572948183662,-3.4834923863807044
1.366297377144241,0.00044879999999999996,83.66042231249999,193.85572948183662,-3.4834923863807044
1.4247486018349038,0.000468,87.2394778125,193.85572948183662,-3.4834923863807044
1.4685870203529008,0.00048239999999999996,89.9237694375,193.85572948183662,-3.4834923863807044
1.5002481003936763,0.0004927999999999999,91.86242449999999,193.85572948183662,-3.4834923863807044
1.5343446481298966,0.000504,93.950206875,193.85572948183662,-3.4834923863807044
1.5489574543025622,0.0005088,94.84497075,193.85572948183662,-3.4834923863807044
1.5538283896934506,0.0005103999999999999,95.14322537499999,193.85572948183662,-3.4834923863807044
1.6536825652066662,0.0005432,101.2574451875,193.85572948183662,-3.4834923863807044
1.6829081775519976,0.0005528,103.0469729375,193.85572948183662,-3.4834923863807044
1.6926500483337745,0.000556,103.6434821875,193.85572948183662,-3.4834923863807044
1.7511012730244373,0.0005752,107.2225376875,193.85572948183662,-3.4834923863807044
1.7949396915424345,0.0005896,109.90682931250001,193.85572948183662,-3.4834923863807044
1.902100270141983,0.0006248,116.4684310625,193.85572948183662,-3.4834923863807044
1.92889041479187,0.0006336,118.10883150000001,193.85572948183662,-3.4834923863807044
1.9727288333098667,0.0006479999999999999,120.79312312499998,193.85572948183662,-3.4834923863807044
2.001954445655198,0.0006575999999999999,122.58265087499998,193.85572948183662,-3.4834923863807044
2.0238736549141967,0.0006648,123.9247966875,193.85572948183662,-3.4834923863807044
2.123727830427412,0.0006975999999999999,130.03901649999997,193.85572948183662,-3.4834923863807044
2.191920925899852,0.0007199999999999999,134.21458124999998,193.85572948183662,-3.4834923863807044
2.272291359849513,0.0007463999999999999,139.1357825625,193.85572948183662,-3.4834923863807044
2.328307116844732,0.0007647999999999999,142.56571075,193.85572948183662,-3.4834923863807044
2.394064744621727,0.0007863999999999999,146.5921481875,193.85572948183662,-3.4834923863807044
2.398935680012616,0.000788,146.89040281249999,193.85572948183662,-3.4834923863807044
2.41841942157617,0.0007944,148.0834213125,193.85572948183662,-3.4834923863807044
2.4987898555258314,0.0008208,153.004622625,193.85572948183662,-3.4834923863807044
2.5401928063483843,0.0008344,155.5397869375,193.85572948183662,-3.4834923863807044
2.5767248217800485,0.0008464,157.776696625,193.85572948183662,-3.4834923863807044
2.5889021602572697,0.0008504,158.52233318749998,193.85572948183662,-3.4834923863807044
2.6303051110798226,0.000864,161.05749749999998,193.85572948183662,-3.4834923863807044
2.6741435295978198,0.0008784,163.741789125,193.85572948183662,-3.4834923863807044
2.705804609638595,0.0008887999999999999,165.68044418749997,193.85572948183662,-3.4834923863807044
2.7520784958520363,0.000904,168.513863125,193.85572948183662,-3.4834923863807044
2.825142526715365,0.000928,172.9876825,193.85572948183662,-3.4834923863807044
2.888464686796916,0.0009488,176.86499262499999,193.85572948183662,-3.4834923863807044
2.893335622187805,0.0009504,177.16324725,193.85572948183662,-3.4834923863807044
2.9542223145739115,0.0009704,180.89143006249998,193.85572948183662,-3.4834923863807044
3.049205554696239,0.0010016,186.70739525000002,193.85572948183662,-3.4834923863807044
3.075995699346126,0.0010104,188.34779568750002,193.85572948183662,-3.4834923863807044
3.158801600991231,0.0010375999999999999,193.41812431249997,193.85572948183662,-3.4834923863807044
3.173414407163897,0.0010424,194.3128881875,193.85572948183662,-3.4834923863807044
3.202640019509228,0.001052,195.07883524838056,193.85572948183662,-3.4834923863807044
3.2221237610727824,0.0010584,195.11852123492446,193.85572948183662,-3.4834923863807044
3.2951877919361108,0.0010823999999999999,195.2665174488956,193.85572948183662,-3.4834923863807044
3.319542468890554,0.0010904,195.31556438975184,193.85572948183662,-3.4834923863807044
3.409654773621992,0.00112,195.49583055382314,193.85572948183662,-3.4834923863807044
3.443751321358212,0.0011312,195.5635536199145,193.85572948183662,-3.4834923863807044
3.482718804485321,0.001144,195.64063201889212,193.85572948183662,-3.4834923863807044
3.5874439153894246,0.0011784,195.84613149680013,193.85572948183662,-3.4834923863807044
3.6020567215620902,0.0011832,195.87461871461713,193.85572948183662,-3.4834923863807044
3.6483306077755313,0.0011983999999999999,195.96453232886105,193.85572948183662,-3.4834923863807044
3.6653788816436417,0.001204,195.997546140963,193.85572948183662,-3.4834923863807044
3.792023201806744,0.0012456,196.24094393625282,193.85572948183662,-3.4834923863807044
3.8407325557156295,0.0012615999999999999,196.33371167876808,193.85572948183662,-3.4834923863807044
3.879700038842738,0.0012744,196.4075959291721,193.85572948183662,-3.4834923863807044
3.933280328142512,0.001292,196.5087159446717,193.85572948183662,-3.4834923863807044
3.9600704727923994,0.0013008,196.55907439029144,193.85572948183662,-3.4834923863807044
3.9966024882240636,0.0013128,196.62753140009954,193.85572948183662,-3.4834923863807044
4.062360116001059,0.0013344,196.75014217550702,193.85572948183662,-3.4834923863807044
4.1086340022145,0.0013495999999999998,196.8359602520469,193.85572948183662,-3.4834923863807044
4.115940405300833,0.001352,196.8494759405357,193.85572948183662,-3.4834923863807044
4.152472420732497,0.001364,196.91691453540597,193.85572948183662,-3.4834923863807044
4.171956162296052,0.0013704,196.95278715570586,193.85572948183662,-3.4834923863807044
4.19387537155505,0.0013775999999999999,196.9930658469851,193.85572948183662,-3.4834923863807044
4.21092364542316,0.0013832,197.02433698374188,193.85572948183662,-3.4834923863807044
4.264503934722934,0.0014008,197.12229778876272,193.85572948183662,-3.4834923863807044
4.325390627109041,0.0014207999999999998,197.2330360888201,193.85572948183662,-3.4834923863807044
4.361922642540706,0.0014328,197.29918729110534,193.85572948183662,-3.4834923863807044
4.391148254886037,0.0014424,197.35195281282844,193.85572948183662,-3.4834923863807044
4.437422141099478,0.0014575999999999999,197.4352189765661,193.85572948183662,-3.4834923863807044
4.449599479576699,0.0014616,197.45707475467304,193.85572948183662,-3.4834923863807044
4.568937396653469,0.0015007999999999998,197.67004111313904,193.85572948183662,-3.4834923863807044
4.583550202826135,0.0015056,197.69596870665566,193.85572948183662,-3.4834923863807044
4.651743298298575,0.0015279999999999998,197.81654044547466,193.85572948183662,-3.4834923863807044
4.668791572166685,0.0015336,197.84657542723417,193.85572948183662,-3.4834923863807044
4.749162006116346,0.00156,197.98759677853963,193.85572948183662,-3.4834923863807044
4.80274229541612,0.0015776,198.0810942696238,193.85572948183662,-3.4834923863807044
4.912338341711113,0.0016136,198.27108155390863,193.85572948183662,-3.4834923863807044
4.929386615579222,0.0016192,198.3004858987681,193.85572948183662,-3.4834923863807044
4.997579711051663,0.0016416,198.41770882437856,193.85572948183662,-3.4834923863807044
5.046289064960548,0.0016576,198.50105787241932,193.85572948183662,-3.4834923863807044
5.090127483478545,0.0016719999999999999,198.57580412618012,193.85572948183662,-3.4834923863807044
5.16075604664643,0.0016952,198.69570271763715,193.85572948183662,-3.4834923863807044
5.211900868250759,0.001712,198.78212669923195,193.85572948183662,-3.4834923863807044
5.355593462281972,0.0017591999999999998,199.02318456383992,193.85572948183662,-3.4834923863807044
5.3969964131045245,0.0017728,199.09217208313962,193.85572948183662,-3.4834923863807044
5.491979653226851,0.0018039999999999998,199.2496623696119,193.85572948183662,-3.4834923863807044
5.528511668658515,0.001816,199.30995225304227,193.85572948183662,-3.4834923863807044
5.577221022567401,0.0018319999999999999,199.3900976276826,193.85572948183662,-3.4834923863807044
5.677075198080617,0.0018648,199.55354724929614,193.85572948183662,-3.4834923863807044
5.718478148903169,0.0018784,199.6209897636799,193.85572948183662,-3.4834923863807044
5.737961890466724,0.0018847999999999998,199.65266149830882,193.85572948183662,-3.4834923863807044
5.764752035116611,0.0018935999999999998,199.69614173511698,193.85572948183662,-3.4834923863807044
5.801284050548275,0.0019056,199.75530618161255,193.85572948183662,-3.4834923863807044
5.845122469066272,0.0019199999999999998,199.82611206240432,193.85572948183662,-3.4834923863807044
5.862170742934382,0.0019256,199.85359171367958,193.85572948183662,-3.4834923863807044
5.959589450752153,0.0019576,200.01002448759834,193.85572948183662,-3.4834923863807044
5.974202256924819,0.0019624,200.03340310585386,193.85572948183662,-3.4834923863807044
6.134943124824142,0.0020152,200.2891131073924,193.85572948183662,-3.4834923863807044
6.154426866387695,0.0020215999999999997,200.3199297031254,193.85572948183662,-3.4834923863807044
6.183652478733027,0.0020312,200.36608335238904,193.85572948183662,-3.4834923863807044
6.266458380378132,0.0020583999999999997,200.4963922961997,193.85572948183662,-3.4834923863807044
6.2932485250280195,0.0020672,200.53840706557114,193.85572948183662,-3.4834923863807044
6.359006152805016,0.0020888,200.64123958122647,193.85572948183662,-3.4834923863807044
6.461295796013675,0.0021224,200.80038076947412,193.85572948183662,-3.4834923863807044
6.536795294572447,0.0021471999999999997,200.91721258085494,193.85572948183662,-3.4834923863807044
6.558714503831446,0.0021544,200.9510327680157,193.85572948183662,-3.4834923863807044
6.583069180785889,0.0021624,200.9885590967993,193.85572948183662,-3.4834923863807044
6.687794291689993,0.0021968,201.14930923152411,193.85572948183662,-3.4834923863807044
6.807132208766762,0.0022359999999999997,201.3312976586702,193.85572948183662,-3.4834923863807044
6.83392235341665,0.0022448,201.3719806862094,193.85572948183662,-3.4834923863807044
6.894809045802757,0.0022648,201.4642115016515,193.85572948183662,-3.4834923863807044
6.909421851975423,0.0022696,201.48629956593882,193.85572948183662,-3.4834923863807044
6.98248588283875,0.0022936,201.59646778531467,193.85572948183662,-3.4834923863807044
7.026324301356747,0.0023079999999999997,201.6623529337466,193.85572948183662,-3.4834923863807044
7.060420849092968,0.0023192,201.71348616480122,193.85572948183662,-3.4834923863807044
7.114001138392743,0.0023368,201.793644239792,193.85572948183662,-3.4834923863807044
7.155404089215295,0.0023504,201.855423412598,193.85572948183662,-3.4834923863807044
7.179758766169738,0.0023584,201.8916989800072,193.85572948183662,-3.4834923863807044
7.194371572342403,0.0023631999999999998,201.91344128594434,193.85572948183662,-3.4834923863807044
7.228468120078624,0.0023744,201.9641064647041,193.85572948183662,-3.4834923863807044
7.2674356032057315,0.0023872,202.02189553769873,193.85572948183662,-3.4834923863807044
7.294225747855618,0.0023959999999999997,202.06155544398356,193.85572948183662,-3.4834923863807044
7.313709489419173,0.0024024,202.09036333984022,193.85572948183662,-3.4834923863807044
7.321015892505506,0.0024048,202.1011585824358,193.85572948183662,-3.4834923863807044
7.355112440241725,0.0024159999999999997,202.1514809295759,193.85572948183662,-3.4834923863807044
7.411128197236944,0.0024343999999999998,202.23395629540488,193.85572948183662,-3.4834923863807044
7.4574020834503845,0.0024495999999999997,202.30190490461231,193.85572948183662,-3.4834923863807044
7.4939340988820495,0.0024616,202.3554324610194,193.85572948183662,-3.4834923863807044
7.540207985095491,0.0024768,202.42308816636947,193.85572948183662,-3.4834923863807044
7.598659209786154,0.002496,202.5083169981961,193.85572948183662,-3.4834923863807044
7.637626692913262,0.0025088,202.5649942145572,193.85572948183662,-3.4834923863807044
7.654674966781372,0.0025144,202.58975502194866,193.85572948183662,-3.4834923863807044
7.703384320690258,0.0025304,202.66038195457529,193.85572948183662,-3.4834923863807044
7.717997126862924,0.0025352,202.6815360438926,193.85572948183662,-3.4834923863807044
7.730174465340144,0.0025391999999999997,202.69915252217584,193.85572948183662,-3.4834923863807044
7.798367560812585,0.0025616,202.79760552105714,193.85572948183662,-3.4834923863807044
7.812980366985251,0.0025664,202.8186588441202,193.85572948183662,-3.4834923863807044
7.849512382416914,0.0025784,202.87122507706738,193.85572948183662,-3.4834923863807044
7.907963607107577,0.0025976,202.955133027635,193.85572948183662,-3.4834923863807044
8.056527136529677,0.0026463999999999997,203.1673176387999,193.85572948183662,-3.4834923863807044
8.112542893524896,0.0026647999999999997,203.24692482391816,193.85572948183662,-3.4834923863807044
8.144203973565673,0.0026752,203.29182535804787,193.85572948183662,-3.4834923863807044
8.190477859779113,0.0026904,203.35732695341756,193.85572948183662,-3.4834923863807044
8.229445342906223,0.0027032,203.4123743258083,193.85572948183662,-3.4834923863807044
8.246493616774332,0.0027088,203.43642557517526,193.85572948183662,-3.4834923863807044
8.273283761424219,0.0027175999999999997,203.4741812538412,193.85572948183662,-3.4834923863807044
8.30738030916044,0.0027288,203.52216504737888,193.85572948183662,-3.4834923863807044
8.353654195373881,0.002744,203.58716323765285,193.85572948183662,-3.4834923863807044
8.392621678500989,0.0027568,203.64178971659425,193.85572948183662,-3.4834923863807044
8.499782257100536,0.0027919999999999998,203.79150485431256,193.85572948183662,-3.4834923863807044
8.570410820268421,0.0028152,203.88977844122155,193.85572948183662,-3.4834923863807044
8.623991109568196,0.0028328,203.9641202682172,193.85572948183662,-3.4834923863807044
8.665394060390748,0.0028464,204.02144291686704,193.85572948183662,-3.4834923863807044
8.743329026644966,0.002872,204.1290554350329,193.85572948183662,-3.4834923863807044
8.792038380553851,0.002888,204.19612332240234,193.85572948183662,-3.4834923863807044
8.828570395985516,0.0029,204.24632918120992,193.85572948183662,-3.4834923863807044
8.874844282198955,0.0029151999999999997,204.30980711027675,193.85572948183662,-3.4834923863807044
8.94547284536684,0.0029384,204.40644617636647,193.85572948183662,-3.4834923863807044
8.972262990016729,0.0029472,204.44302447316892,193.85572948183662,-3.4834923863807044
8.999053134666614,0.002956,204.47956019943922,193.85572948183662,-3.4834923863807044
9.035585150098278,0.0029679999999999997,204.5293133568631,193.85572948183662,-3.4834923863807044
9.125697454829718,0.0029976,204.6517035656918,193.85572948183662,-3.4834923863807044
9.237728968820155,0.0030344,204.80320909002342,193.85572948183662,-3.4834923863807044
9.279131919642706,0.003048,204.85901869811025,193.85572948183662,-3.4834923863807044
9.31566393507437,0.00306,204.9081818689946,193.85572948183662,-3.4834923863807044
9.361937821287812,0.0030751999999999997,204.97034741258528,193.85572948183662,-3.4834923863807044
9.420389045978474,0.0030943999999999998,205.0487012886078,193.85572948183662,-3.4834923863807044
9.452050126019252,0.0031048,205.09106379589002,193.85572948183662,-3.4834923863807044
9.495888544537248,0.0031192,205.14962832744715,193.85572948183662,-3.4834923863807044
9.50319494762358,0.0031216,205.1593788222162,193.85572948183662,-3.4834923863807044
9.595742720050463,0.003152,205.28263311459278,193.85572948183662,-3.4834923863807044
9.63471020317757,0.0031647999999999997,205.3343908612895,193.85572948183662,-3.4834923863807044
9.722387040213567,0.0031936,205.4505482238536,193.85572948183662,-3.4834923863807044
9.788144667990561,0.0032151999999999997,205.53739833648876,193.85572948183662,-3.4834923863807044
9.812499344945005,0.0032232,205.56950726067248,193.85572948183662,-3.4834923863807044
9.87338603733111,0.0032432,205.64964389155674,193.85572948183662,-3.4834923863807044
9.887998843503777,0.003248,205.66884797666657,193.85572948183662,-3.4834923863807044
9.961062874367105,0.0032719999999999997,205.76470287711626,193.85572948183662,-3.4834923863807044
10.058481582184875,0.0033039999999999996,205.89208395313625,193.85572948183662,-3.4834923863807044
10.11206187148465,0.0033215999999999996,205.96193842620562,193.85572948183662,-3.4834923863807044
10.138852016134537,0.0033304,205.99681151988628,193.85572948183662,-3.4834923863807044
10.216786982388756,0.003356,206.09805676402584,193.85572948183662,-3.4834923863807044
10.294721948642971,0.0033816,206.19900125068946,193.85572948183662,-3.4834923863807044
10.35073770563819,0.0034,206.27137110110306,193.85572948183662,-3.4834923863807044
10.392140656460743,0.0034135999999999997,206.32476372778873,193.85572948183662,-3.4834923863807044
10.40188252724252,0.0034168,206.3373146345351,193.85572948183662,-3.4834923863807044
10.455462816542294,0.0034343999999999998,206.40626285226602,193.85572948183662,-3.4834923863807044
10.496865767364847,0.0034479999999999997,206.4594466818507,193.85572948183662,-3.4834923863807044
10.511478573537513,0.0034528,206.4781979042104,193.85572948183662,-3.4834923863807044
10.52122044431929,0.003456,206.4906930714752,193.85572948183662,-3.4834923863807044
10.560187927446398,0.0034687999999999997,206.54062868516993,193.85572948183662,-3.4834923863807044
10.591849007487173,0.0034792,206.58114847749752,193.85572948183662,-3.4834923863807044
10.611332749050728,0.0034855999999999997,206.60606025653482,193.85572948183662,-3.4834923863807044
10.650300232177838,0.0034984,206.65583036198694,193.85572948183662,-3.4834923863807044
10.681961312218613,0.0035088,206.69621630005756,193.85572948183662,-3.4834923863807044
10.735541601518387,0.0035264,206.76445554424996,193.85572948183662,-3.4834923863807044
10.793992826209049,0.0035456,206.83874704800044,193.85572948183662,-3.4834923863807044
10.81104110007716,0.0035512,206.8603858274304,193.85572948183662,-3.4834923863807044
10.828089373945268,0.0035567999999999997,206.88201130302267,193.85572948183662,-3.4834923863807044
10.876798727854155,0.0035727999999999997,206.94372532849604,193.85572948183662,-3.4834923863807044
10.966911032585593,0.0036024,207.05761287159154,193.85572948183662,-3.4834923863807044
10.991265709540036,0.0036103999999999997,207.08833056685188,193.85572948183662,-3.4834923863807044
11.008313983408145,0.003616,207.1098171610201,193.85572948183662,-3.4834923863807044
11.035104128058032,0.0036247999999999996,207.14355560774234,193.85572948183662,-3.4834923863807044
11.088684417357806,0.0036423999999999996,207.21093682207766,193.85572948183662,-3.4834923863807044
11.166619383612025,0.003668,207.3087196315297,193.85572948183662,-3.4834923863807044
11.190974060566468,0.003676,207.3392221291842,193.85572948183662,-3.4834923863807044
11.225070608302687,0.0036872,207.38188216837332,193.85572948183662,-3.4834923863807044
11.273779962211572,0.0037032,207.4427375201891,193.85572948183662,-3.4834923863807044
11.341973057684012,0.0037256,207.5277630221761,193.85572948183662,-3.4834923863807044
11.400424282374676,0.0037448,207.60048346139303,193.85572948183662,-3.4834923863807044
11.456440039369893,0.0037632,207.6700375565524,193.85572948183662,-3.4834923863807044
11.490536587106114,0.0037744,207.71230989906772,193.85572948183662,-3.4834923863807044
11.510020328669668,0.0037808,207.73644355879367,193.85572948183662,-3.4834923863807044
11.556294214883108,0.003796,207.7936972358621,193.85572948183662,-3.4834923863807044
11.605003568791995,0.003812,207.8538677564696,193.85572948183662,-3.4834923863807044
11.62448731035555,0.0038184,207.87790837637294,193.85572948183662,-3.4834923863807044
11.692680405827987,0.0038407999999999997,207.96192707171326,193.85572948183662,-3.4834923863807044
11.760873501300429,0.0038632,208.04575488021246,193.85572948183662,-3.4834923863807044
11.792534581341203,0.0038735999999999996,208.08461047713487,193.85572948183662,-3.4834923863807044
11.894824224549863,0.0039071999999999996,208.2098668006244,193.85572948183662,-3.4834923863807044
11.933791707676972,0.00392,208.25747290844978,193.85572948183662,-3.4834923863807044
11.992242932367633,0.0039391999999999995,208.3287685562512,193.85572948183662,-3.4834923863807044
12.099403510967182,0.0039743999999999995,208.45912624516444,193.85572948183662,-3.4834923863807044
12.145677397180624,0.003989599999999999,208.51527778266473,193.85572948183662,-3.4834923863807044
12.170032074135067,0.0039976,208.54479770820183,193.85572948183662,-3.4834923863807044
12.820430567236695,0.00421124224844969,209.3248125909452,193.85572948183662,-3.4834923863807044
14.398929333637868,0.004729745949189838,211.15629493937746,193.85572948183662,-3.4834923863807044
14.866632671830809,0.004883376675335067,211.6836827249998,193.85572948183662,-3.4834923863807044
15.80203934821669,0.005190638127625526,212.71943213637925,193.85572948183662,-3.4834923863807044
16.854371859150806,0.005536307261452291,213.85646967942677,193.85572948183662,-3.4834923863807044
18.082093121907274,0.005939587917583517,215.14857589426165,193.85572948183662,-3.4834923863807044
19.952906474679036,0.006554110822164433,217.0535220119117,193.85572948183662,-3.4834923863807044
20.362146895597856,0.0066885377075415085,217.460788894791,193.85572948183662,-3.4834923863807044
20.946776068339034,0.006880576115223045,218.03710397837176,193.85572948183662,-3.4834923863807044
22.057571496547265,0.007245449089817963,219.11510507135543,193.85572948183662,-3.4834923863807044
22.759126503836676,0.007475895179035807,219.78504915294022,193.85572948183662,-3.4834923863807044
23.10990400748138,0.007591118223644729,220.1169972266832,193.85572948183662,-3.4834923863807044
24.629939856608438,0.008090418083616723,221.53330875614304,193.85572948183662,-3.4834923863807044
27.319234051217844,0.00897379475895179,223.95822450032955,193.85572948183662,-3.4834923863807044
28.079251975781375,0.009223444688937788,224.62640807404895,193.85572948183662,-3.4834923863807044
28.780806983070786,0.009453890778155631,225.2369585961744,193.85572948183662,-3.4834923863807044
30.53469450129431,0.01003000600120024,226.73847198168332,193.85572948183662,-3.4834923863807044
30.8270090876649,0.010126025205041009,226.98541692748952,193.85572948183662,-3.4834923863807044
31.996267433147253,0.010510102020404082,227.9641985323202,193.85572948183662,-3.4834923863807044
32.46397077134019,0.01066373274654931,228.35179288957187,193.85572948183662,-3.4834923863807044
32.63935952316254,0.01072134426885377,228.49657854149635,193.85572948183662,-3.4834923863807044
34.159395372289595,0.011220644128825764,229.73892647801816,193.85572948183662,-3.4834923863807044
35.5040424695943,0.0116623324664933,230.82006111508704,193.85572948183662,-3.4834923863807044
36.55637498052842,0.012008001600320064,231.65506475469715,193.85572948183662,-3.4834923863807044
36.67330081507665,0.01204640928185637,231.74726060172793,193.85572948183662,-3.4834923863807044
38.13487374692959,0.012526505301060212,232.89020234031736,193.85572948183662,-3.4834923863807044
39.01181750604135,0.012814562912582516,233.5677686711295,193.85572948183662,-3.4834923863807044
41.1749454451837,0.013525105021004201,235.21418428595408,193.85572948183662,-3.4834923863807044
42.28574087339194,0.01388997799559912,236.0465071542601,193.85572948183662,-3.4834923863807044
43.33807338432605,0.014235647129425886,236.82719206687833,193.85572948183662,-3.4834923863807044
44.039628391615466,0.01446609321864373,237.34354514599366,193.85572948183662,-3.4834923863807044
45.5012013234684,0.01494618923784757,238.40908933793744,193.85572948183662,-3.4834923863807044
45.96890466166134,0.0150998199639928,238.74723309069736,193.85572948183662,-3.4834923863807044
46.611996751676635,0.01531106221244249,239.20999805035703,193.85572948183662,-3.4834923863807044
49.71053136720486,0.01632886577315463,241.40569225120885,193.85572948183662,-3.4834923863807044
49.94438303630133,0.016405681136227243,241.5692062512619,193.85572948183662,-3.4834923863807044
51.05517846450957,0.016770554110822164,242.34185656148952,193.85572948183662,-3.4834923863807044
51.873659306347214,0.017039407881576315,242.9069890780583,193.85572948183662,-3.4834923863807044
53.39369515547427,0.01753870774154831,243.9473792001445,193.85572948183662,-3.4834923863807044
54.21217599731192,0.01780756151230246,244.50280175892144,193.85572948183662,-3.4834923863807044
55.43989726006839,0.01821084216843369,245.32984245404143,193.85572948183662,-3.4834923863807044
55.849137680987205,0.018345269053810762,245.60393131132955,193.85572948183662,-3.4834923863807044
58.36304312377426,0.019171034206841367,247.27075191452053,193.85572948183662,-3.4834923863807044
58.94767229651544,0.019363072614522907,247.6543430076773,193.85572948183662,-3.4834923863807044
59.8246160556272,0.01965113022604521,248.22695934699627,193.85572948183662,-3.4834923863807044
60.11693064199778,0.019747149429885976,248.41710277191697,193.85572948183662,-3.4834923863807044
60.701559814738964,0.019939187837567512,248.7963113274735,193.85572948183662,-3.4834923863807044
61.57850357385073,0.02022724544908982,249.36246432114936,193.85572948183662,-3.4834923863807044
61.75389232567308,0.020284856971394278,249.47531663677734,193.85572948183662,-3.4834923863807044
63.50777984389661,0.020860972194438887,250.59704857258436,193.85572948183662,-3.4834923863807044
63.68316859571896,0.02091858371674335,250.70855313699778,193.85572948183662,-3.4834923863807044
66.66477737669895,0.021897979595919183,252.58618009628321,193.85572948183662,-3.4834923863807044
67.95096155672954,0.022320464092818564,253.38599247599382,193.85572948183662,-3.4834923863807044
69.17868281948601,0.02272374474894979,254.14395974147305,193.85572948183662,-3.4834923863807044
70.17255241314601,0.023050210042008402,254.75371693552609,193.85572948183662,-3.4834923863807044
71.4587365931766,0.023472694538907782,255.53783789427231,193.85572948183662,-3.4834923863807044
72.56953202138482,0.0238375675135027,256.2106139907785,193.85572948183662,-3.4834923863807044
73.8557162014154,0.02426005201040208,256.98462068525316,193.85572948183662,-3.4834923863807044
74.55727120870482,0.024490498099619923,257.4045897639111,193.85572948183662,-3.4834923863807044
76.77886206512129,0.02522024404880976,258.72443698548466,193.85572948183662,-3.4834923863807044
78.12350916242599,0.025661932386477296,259.51605812575514,193.85572948183662,-3.4834923863807044
79.29276750790835,0.02604600920184037,260.2001147281688,193.85572948183662,-3.4834923863807044
79.93585959792364,0.026257251450290058,260.5746686190625,193.85572948183662,-3.4834923863807044
81.22204377795423,0.026679735947189438,261.3202692883545,193.85572948183662,-3.4834923863807044
81.98206170251775,0.026929385877175437,261.75868722994585,193.85572948183662,-3.4834923863807044
84.90520756622364,0.02788957791558312,263.43034060358457,193.85572948183662,-3.4834923863807044
85.37291090441657,0.028043208641728348,263.6957080044607,193.85572948183662,-3.4834923863807044
87.53603884355891,0.02875375075015003,264.9157317610593,193.85572948183662,-3.4834923863807044
88.4714455199448,0.02906101220244049,265.439661661864,193.85572948183662,-3.4834923863807044
90.51764762453891,0.029733146629325864,266.5782849121733,193.85572948183662,-3.4834923863807044
91.97922055639185,0.030213242648529707,267.38544959208537,193.85572948183662,-3.4834923863807044
93.09001598460009,0.030578115623124624,267.99555363081936,193.85572948183662,-3.4834923863807044
94.37620016463067,0.031000600120024004,268.6984540284434,193.85572948183662,-3.4834923863807044
96.36393935195066,0.03165353070614123,269.7774504330647,193.85572948183662,-3.4834923863807044
97.82551228380362,0.032133626725345074,270.56530030754254,193.85572948183662,-3.4834923863807044
98.58553020836715,0.03238327665533107,270.973167219673,193.85572948183662,-3.4834923863807044
99.40401105020479,0.03265213042608522,271.4110395126322,193.85572948183662,-3.4834923863807044
99.87171438839772,0.032805761152230446,271.66062091694795,193.85572948183662,-3.4834923863807044
101.39175023752479,0.033305061012202444,272.4686304677301,193.85572948183662,-3.4834923863807044
102.03484232754006,0.03351630326065213,272.8090569217699,193.85572948183662,-3.4834923863807044
103.43795234211889,0.033977195439087816,273.5489144888444,193.85572948183662,-3.4834923863807044
103.73026692848948,0.03407321464292859,273.7025576722665,193.85572948183662,-3.4834923863807044
104.66567360487537,0.03438047609521905,274.19308499199866,193.85572948183662,-3.4834923863807044
105.1918398603424,0.03455331066213242,274.46825521047845,193.85572948183662,-3.4834923863807044
105.95185778490595,0.034802960592118425,274.864777521988,193.85572948183662,-3.4834923863807044
106.41956112309889,0.034956591318263654,275.108239948923,193.85572948183662,-3.4834923863807044
108.23191155859654,0.03555191038207642,276.04774153433533,193.85572948183662,-3.4834923863807044
108.64115197951534,0.03568633726745349,276.2590355643822,193.85572948183662,-3.4834923863807044
108.87500364861184,0.03576315263052611,276.37963564016644,193.85572948183662,-3.4834923863807044
109.40116990407887,0.035935987197439484,276.65061705405014,193.85572948183662,-3.4834923863807044
109.92733615954594,0.03610882176435287,276.9210906595173,193.85572948183662,-3.4834923863807044
111.68122367776948,0.036684936987397485,277.8190448917854,193.85572948183662,-3.4834923863807044
111.97353826414006,0.03678095619123825,277.9681676162168,193.85572948183662,-3.4834923863807044
113.49357411326712,0.03728025605121024,278.7411719322225,193.85572948183662,-3.4834923863807044
113.96127745146005,0.03743388677735547,278.9782057216031,193.85572948183662,-3.4834923863807044
115.36438746603888,0.03789477895579116,279.6870411388183,193.85572948183662,-3.4834923863807044
115.83209080423181,0.03804840968193639,279.92257139822124,193.85572948183662,-3.4834923863807044
117.05981206698827,0.03845169033806761,280.53908038233425,193.85572948183662,-3.4834923863807044
117.35212665335885,0.03854770954190838,280.68549593405714,193.85572948183662,-3.4834923863807044
118.63831083338945,0.03897019403880776,281.32804199376227,193.85572948183662,-3.4834923863807044
119.51525459250121,0.03925825165033006,281.76458472700415,193.85572948183662,-3.4834923863807044
121.32760502799887,0.03985357071414283,282.6628342183107,193.85572948183662,-3.4834923863807044
124.89384298172004,0.0410250050010002,284.41522197393715,193.85572948183662,-3.4834923863807044
126.94004508631416,0.04169713942788558,285.4118781097144,193.85572948183662,-3.4834923863807044
127.81698884542591,0.04198519703940788,285.8370962157076,193.85572948183662,-3.4834923863807044
128.40161801816708,0.042177235447089415,286.11994302318584,193.85572948183662,-3.4834923863807044
132.1432447237106,0.04340628125625125,287.9184127117167,193.85572948183662,-3.4834923863807044
133.25404015191884,0.04377115423084617,288.4484957396072,193.85572948183662,-3.4834923863807044
133.83866932466,0.0439631926385277,288.7267944739606,193.85572948183662,-3.4834923863807044
134.4817614146753,0.04417443488697739,289.03237606476233,193.85572948183662,-3.4834923863807044
135.18331642196472,0.04440488097619524,289.3650885603773,193.85572948183662,-3.4834923863807044
136.1187230983506,0.0447121424284857,289.80765960096085,193.85572948183662,-3.4834923863807044
137.4633701956553,0.04515383076615323,290.44178307425597,193.85572948183662,-3.4834923863807044
138.63262854113768,0.04553790758151631,290.99123094137343,193.85572948183662,-3.4834923863807044
139.86034980389414,0.045941188237647534,291.5662096145152,193.85572948183662,-3.4834923863807044
140.67883064573175,0.046210042008401675,291.94843553196466,193.85572948183662,-3.4834923863807044
141.32192273574705,0.04642128425685137,292.2481478005092,193.85572948183662,-3.4834923863807044
143.13427317124473,0.04701660332066414,293.0899431418338,193.85572948183662,-3.4834923863807044
144.12814276490468,0.04734306861372274,293.5498076495909,193.85572948183662,-3.4834923863807044
144.94662360674235,0.047611922384476896,293.9275916970314,193.85572948183662,-3.4834923863807044
145.94049320040236,0.04793838767753551,294.38521282358556,193.85572948183662,-3.4834923863807044
146.8174369595141,0.04822644528905781,294.78798778715674,193.85572948183662,-3.4834923863807044
148.1620840568188,0.04866813362672534,295.40375854364953,193.85572948183662,-3.4834923863807044
150.5006007477835,0.049436287257451486,296.46949803045726,193.85572948183662,-3.4834923863807044
151.31908158962116,0.04970514102820564,296.8409785233917,193.85572948183662,-3.4834923863807044
153.77452411513408,0.05051170234046809,297.95074641976623,193.85572948183662,-3.4834923863807044
154.47607912242353,0.05074214842968594,298.26655080115125,193.85572948183662,-3.4834923863807044
156.46381830974352,0.05139507901580316,299.15830659799013,193.85572948183662,-3.4834923863807044
156.75613289611408,0.05149109821964393,299.2890735503022,193.85572948183662,-3.4834923863807044
157.5161508206776,0.05174074814962992,299.6286233248548,193.85572948183662,-3.4834923863807044
158.4515574970635,0.05204800960192038,300.04565487258594,193.85572948183662,-3.4834923863807044
159.27003833890114,0.052316863372674535,300.40977048910986,193.85572948183662,-3.4834923863807044
162.54396170625174,0.05339227845569114,301.8589940985943,193.85572948183662,-3.4834923863807044
163.01166504444467,0.05354590918183637,302.0650929038,193.85572948183662,-3.4834923863807044
165.4671075699576,0.05435247049409882,303.1433513502469,193.85572948183662,-3.4834923863807044
166.57790299816583,0.05471734346869374,303.6290830671347,193.85572948183662,-3.4834923863807044
169.20873427550112,0.05558151630326065,304.77448900255615,193.85572948183662,-3.4834923863807044
170.49491845553172,0.056004000800160034,305.3319357620708,193.85572948183662,-3.4834923863807044
170.7872330419023,0.0561000200040008,305.458399197352,193.85572948183662,-3.4834923863807044
171.89802847011055,0.05646489297859572,305.93819233643495,193.85572948183662,-3.4834923863807044
172.65804639467407,0.05671454290858172,306.26577538045194,193.85572948183662,-3.4834923863807044
174.11961932652702,0.05719463892778556,306.894166451985,193.85572948183662,-3.4834923863807044
175.4642664238317,0.05763632726545309,307.47047174040284,193.85572948183662,-3.4834923863807044
176.107358513847,0.05784756951390278,307.7454869193275,193.85572948183662,-3.4834923863807044
177.15969102478113,0.058193238647729545,308.19466842705026,193.85572948183662,-3.4834923863807044
177.51046852842583,0.05830846169233847,308.3441641995086,193.85572948183662,-3.4834923863807044
178.27048645298936,0.058558111622324466,308.66767703500375,193.85572948183662,-3.4834923863807044
179.7905223021164,0.05905741148229646,309.3130935136058,193.85572948183662,-3.4834923863807044
180.5505402266799,0.05930706141228245,309.63500346233855,193.85572948183662,-3.4834923863807044
181.19363231669521,0.059518303660732144,309.9069762442698,193.85572948183662,-3.4834923863807044
183.0059827521929,0.060113622724544916,310.67142698141464,193.85572948183662,-3.4834923863807044
184.87679610496465,0.06072814562912583,311.45744688022126,193.85572948183662,-3.4834923863807044
185.92912861589875,0.061073814762952594,311.8982197531778,193.85572948183662,-3.4834923863807044
187.68301613412228,0.06164992998599721,312.63068524972965,193.85572948183662,-3.4834923863807044
187.91686780321874,0.061726745349069814,312.72814522967815,193.85572948183662,-3.4834923863807044
188.3845711414117,0.06188037607521504,312.9229234041704,193.85572948183662,-3.4834923863807044
189.55382948689405,0.06226445289057812,313.4090455536086,193.85572948183662,-3.4834923863807044
191.7169574260364,0.0629749949989998,314.3052996352766,193.85572948183662,-3.4834923863807044
192.47697535059993,0.0632246449289858,314.61926232890363,193.85572948183662,-3.4834923863807044
196.8032312288846,0.06464572914582917,316.39731039491716,193.85572948183662,-3.4834923863807044
198.32326707801167,0.06514502900580116,317.0184025794551,193.85572948183662,-3.4834923863807044
198.73250749893052,0.06527945589117824,317.18530215287285,193.85572948183662,-3.4834923863807044
199.0832850025752,0.06539467893578715,317.3282522746298,193.85572948183662,-3.4834923863807044
200.01869167896106,0.06570194038807761,317.70897317766793,193.85572948183662,-3.4834923863807044
201.01256127262107,0.06602840568113623,318.11272908853687,193.85572948183662,-3.4834923863807044
201.48026461081403,0.06618203640728146,318.30246240597324,193.85572948183662,-3.4834923863807044
202.24028253537753,0.06643168633726745,318.61041310557073,193.85572948183662,-3.4834923863807044
203.52646671540813,0.06685417083416684,319.1305342312067,193.85572948183662,-3.4834923863807044
204.3449475572458,0.06712302460492099,319.4608530792275,193.85572948183662,-3.4834923863807044
206.56653841366227,0.06785277055411083,320.3548420283952,193.85572948183662,-3.4834923863807044
207.6188709245964,0.0681984396879376,320.77700100121865,193.85572948183662,-3.4834923863807044
208.2619630146117,0.06840968193638729,321.0345762583229,193.85572948183662,-3.4834923863807044
209.48968427736816,0.06881296259251851,321.5254511103147,193.85572948183662,-3.4834923863807044
210.42509095375402,0.06912022404480897,321.89869831414404,193.85572948183662,-3.4834923863807044
211.53588638196226,0.06948509701940389,322.34108995920855,193.85572948183662,-3.4834923863807044
213.7574772383787,0.07021484296859372,323.22316462216963,193.85572948183662,-3.4834923863807044
214.22518057657163,0.07036847369473895,323.40840815861037,193.85572948183662,-3.4834923863807044
215.0436614184093,0.0706373274654931,323.7322052637433,193.85572948183662,-3.4834923863807044
216.85601185390692,0.07123264652930586,324.4474790346153,193.85572948183662,-3.4834923863807044
219.13606562759753,0.07198159631926386,325.34403677316914,193.85572948183662,-3.4834923863807044
219.42838021396813,0.07207761552310463,325.45871638759144,193.85572948183662,-3.4834923863807044
220.363786890354,0.07238487697539508,325.8252914147656,193.85572948183662,-3.4834923863807044
220.83149022854695,0.07253850770154031,326.00835132039526,193.85572948183662,-3.4834923863807044
221.53304523583634,0.07276895379075815,326.28265792429744,193.85572948183662,-3.4834923863807044
222.23460024312575,0.072999399879976,326.556625951719,193.85572948183662,-3.4834923863807044
223.22846983678573,0.0733258651730346,326.9441706391496,193.85572948183662,-3.4834923863807044
224.92389443773519,0.07388277655531107,327.6037267918879,193.85572948183662,-3.4834923863807044
225.50852361047635,0.0740748149629926,327.8307100068925,193.85572948183662,-3.4834923863807044
227.55472571507048,0.07474694938987798,328.6233502814681,193.85572948183662,-3.4834923863807044
228.54859530873043,0.07507341468293659,329.00734361320673,193.85572948183662,-3.4834923863807044
228.89937281237516,0.07518863772754551,329.1427151146259,193.85572948183662,-3.4834923863807044
229.48400198511632,0.07538067613522705,329.36815463185167,193.85572948183662,-3.4834923863807044
230.88711199969515,0.07584156831366273,329.9082975630421,193.85572948183662,-3.4834923863807044
231.35481533788808,0.07599519903980796,330.0880605280881,193.85572948183662,-3.4834923863807044
233.57640619430455,0.0767249449889978,330.9400066523366,193.85572948183662,-3.4834923863807044
234.4533499534163,0.0770130026005201,331.2754305350007,193.85572948183662,-3.4834923863807044
235.68107121617282,0.07741628325665134,331.7442031138762,193.85572948183662,-3.4834923863807044
237.49342165167045,0.0780116023204641,332.4344638798159,193.85572948183662,-3.4834923863807044
238.89653166624927,0.07847249449889979,332.96744939547773,193.85572948183662,-3.4834923863807044
240.88427085356926,0.079125425085017,333.7204270860995,193.85572948183662,-3.4834923863807044
242.05352919905164,0.07950950190038009,334.1622232029334,193.85572948183662,-3.4834923863807044
242.22891795087395,0.07956711342268454,334.2284207645082,193.85572948183662,-3.4834923863807044
246.08747049096573,0.08083456691338269,335.6800714215297,193.85572948183662,-3.4834923863807044
247.13980300189985,0.08118023604720945,336.074432056889,193.85572948183662,-3.4834923863807044
248.19213551283394,0.08152590518103621,336.46813834320733,193.85572948183662,-3.4834923863807044
250.12141178287985,0.08215963192638528,337.1882464725552,193.85572948183662,-3.4834923863807044
250.82296679016923,0.08239007801560312,337.4495664737561,193.85572948183662,-3.4834923863807044
251.29067012836217,0.08254370874174835,337.6236214606979,193.85572948183662,-3.4834923863807044
253.27840931568215,0.08319663932786557,338.36195010139147,193.85572948183662,-3.4834923863807044
254.73998224753512,0.08367673534706942,338.90339789732116,193.85572948183662,-3.4834923863807044
255.79231475846922,0.08402240448089618,339.2924903904298,193.85572948183662,-3.4834923863807044
256.14309226211395,0.0841376275255051,339.42204909287284,193.85572948183662,-3.4834923863807044
256.669258517581,0.08431046209241849,339.6162574799417,193.85572948183662,-3.4834923863807044
257.66312811124095,0.0846369273854771,339.98267243783476,193.85572948183662,-3.4834923863807044
260.0016448022057,0.08540508101620324,340.8426578209026,193.85572948183662,-3.4834923863807044
261.22936606496216,0.08580836167233447,341.29294227438413,193.85572948183662,-3.4834923863807044
262.8078648313633,0.08632686537307462,341.8706685508287,193.85572948183662,-3.4834923863807044
263.7432715077492,0.08663412682536507,342.21238629183625,193.85572948183662,-3.4834923863807044
264.56175234958687,0.08690298059611923,342.5110017718235,193.85572948183662,-3.4834923863807044
264.73714110140924,0.08696059211842369,342.57494390355527,193.85572948183662,-3.4834923863807044
265.90639944689156,0.08734466893378676,343.00080336312135,193.85572948183662,-3.4834923863807044
269.23878573151626,0.08843928785757152,344.2105145057048,193.85572948183662,-3.4834923863807044
270.3495811597245,0.08880416083216644,344.6124520716856,193.85572948183662,-3.4834923863807044
271.2265249188363,0.08909221844368874,344.9293164327311,193.85572948183662,-3.4834923863807044
271.8111540915774,0.08928425685137027,345.1403373933747,193.85572948183662,-3.4834923863807044
272.5127090988669,0.08951470294058812,345.3933290341663,193.85572948183662,-3.4834923863807044
275.0266145416539,0.09034046809361873,346.29780399026566,193.85572948183662,-3.4834923863807044
276.3712616389586,0.09078215643128626,346.78026910997926,193.85572948183662,-3.4834923863807044
276.83896497715153,0.09093578715743149,346.9478683610074,193.85572948183662,-3.4834923863807044
279.8790366754057,0.09193438687737548,348.0345841998745,193.85572948183662,-3.4834923863807044
280.522128765421,0.09214562912582518,348.2638753810944,193.85572948183662,-3.4834923863807044
281.16522085543625,0.09235687137427485,348.4929616517615,193.85572948183662,-3.4834923863807044
282.7437196218374,0.092875375075015,349.05439965432146,193.85572948183662,-3.4834923863807044
283.44527462912686,0.09310582116423285,349.30353513821234,193.85572948183662,-3.4834923863807044
284.029903801868,0.09329785957191439,349.5109643890033,193.85572948183662,-3.4834923863807044
285.78379132009155,0.093873974794959,350.1322553547027,193.85572948183662,-3.4834923863807044
290.22697303292443,0.09533346669333867,351.69957374582503,193.85572948183662,-3.4834923863807044
291.16237970931036,0.09564072814562913,352.0283399456855,193.85572948183662,-3.4834923863807044
293.1501188966303,0.09629365873174635,352.72560353769205,193.85572948183662,-3.4834923863807044
293.7347480693715,0.0964856971394279,352.9303298388426,193.85572948183662,-3.4834923863807044
294.3193772421127,0.09667773554710943,353.1348972870735,193.85572948183662,-3.4834923863807044
296.1901905948845,0.09729225845169034,353.78845072338663,193.85572948183662,-3.4834923863807044
296.89174560217384,0.09752270454090818,354.03311795367875,193.85572948183662,-3.4834923863807044
297.7686893612856,0.0978107621524305,354.3386351455241,193.85572948183662,-3.4834923863807044
298.0610039476562,0.09790678135627126,354.44039620374554,193.85572948183662,-3.4834923863807044
299.6979656313315,0.09844448889777956,355.00954049283934,193.85572948183662,-3.4834923863807044
300.80876105953973,0.09880936187237448,355.3950552434731,193.85572948183662,-3.4834923863807044
302.38725982594093,0.09932786557311463,355.94193829807267,193.85572948183662,-3.4834923863807044
303.26420358505266,0.09961592318463693,356.2452811021804,193.85572948183662,-3.4834923863807044
303.6149810886974,0.09973114622924585,356.366522413672,193.85572948183662,-3.4834923863807044