File: datasets/aisi_316_L/data/M1/valid_1.csv
Time(s),Strain(%),Stress(MPa),Temp(C),Log_SR(s-1)
0.0,0.0,0.0,408.3412280350117,2.2807619830735035
8.80130960801857e-08,1.68e-05,2.8320145875,408.3412280350117,2.2807619830735035
1.8859949160039796e-07,3.6e-05,6.0686026875,408.3412280350117,2.2807619830735035
3.81390083014138e-07,7.28e-05,12.272063212499999,408.3412280350117,2.2807619830735035
5.029319776010612e-07,9.6e-05,16.1829405,408.3412280350117,2.2807619830735035
5.783717742412203e-07,0.0001104,18.610381575,408.3412280350117,2.2807619830735035
7.376335671482231e-07,0.0001408,23.7349794,408.3412280350117,2.2807619830735035
8.005000643483557e-07,0.0001528,25.7578469625,408.3412280350117,2.2807619830735035
8.172644636017244e-07,0.000156,26.297278312499998,408.3412280350117,2.2807619830735035
8.927042602418835e-07,0.0001704,28.7247193875,408.3412280350117,2.2807619830735035
9.346152583753054e-07,0.0001784,30.0732977625,408.3412280350117,2.2807619830735035
1.119023650162361e-06,0.0002136,36.0070426125,408.3412280350117,2.2807619830735035
1.236374444935942e-06,0.000236,39.7830620625,408.3412280350117,2.2807619830735035
1.3621074393362073e-06,0.00026,43.828797187499994,408.3412280350117,2.2807619830735035
1.5339425316832363e-06,0.00029279999999999996,49.357968525,408.3412280350117,2.2807619830735035
1.5842357294433427e-06,0.0003024,50.976262575,408.3412280350117,2.2807619830735035
1.684822124963555e-06,0.0003216,54.212850675,408.3412280350117,2.2807619830735035
1.7770263208570829e-06,0.0003392,57.179723100000004,408.3412280350117,2.2807619830735035
1.8734216165639526e-06,0.00035759999999999996,60.281453362499995,408.3412280350117,2.2807619830735035
1.9153326146973746e-06,0.0003656,61.6300317375,408.3412280350117,2.2807619830735035
2.0829766072310614e-06,0.00039759999999999996,67.0243452375,408.3412280350117,2.2807619830735035
2.1961363021913005e-06,0.0004192,70.66550685,408.3412280350117,2.2807619830735035
2.2715760988314593e-06,0.00043359999999999997,73.09294792499999,408.3412280350117,2.2807619830735035
2.309295997151539e-06,0.0004408,74.3066684625,408.3412280350117,2.2807619830735035
2.4685577900585418e-06,0.00047119999999999996,79.4312662875,408.3412280350117,2.2807619830735035
2.506277688378621e-06,0.0004784,80.64498682499999,408.3412280350117,2.2807619830735035
2.7367881781124414e-06,0.0005224,88.0621678875,408.3412280350117,2.2807619830735035
2.7870813758725475e-06,0.000532,89.6804619375,408.3412280350117,2.2807619830735035
2.84994787307268e-06,0.000544,91.7033295,408.3412280350117,2.2807619830735035
2.8667122723260485e-06,0.0005472,92.24276085,408.3412280350117,2.2807619830735035
2.9966363665396564e-06,0.000572,96.42335381250001,408.3412280350117,2.2807619830735035
3.046929564299762e-06,0.0005815999999999999,98.04164786249999,408.3412280350117,2.2807619830735035
3.0804583628065e-06,0.000588,99.1205105625,408.3412280350117,2.2807619830735035
3.227146856273476e-06,0.000616,103.840534875,408.3412280350117,2.2807619830735035
3.3151599523536617e-06,0.0006328,106.6725494625,408.3412280350117,2.2807619830735035
3.3738353497404516e-06,0.0006439999999999999,108.56055918749999,408.3412280350117,2.2807619830735035
3.4576573460072955e-06,0.00066,111.2577159375,408.3412280350117,2.2807619830735035
3.5330971426474547e-06,0.0006744,113.6851570125,408.3412280350117,2.2807619830735035
3.541479342274139e-06,0.000676,113.95487268749999,408.3412280350117,2.2807619830735035
3.7175055344345105e-06,0.0007096,119.6189018625,408.3412280350117,2.2807619830735035
3.805518630514696e-06,0.0007264,122.45091645,408.3412280350117,2.2807619830735035
3.8432385288347754e-06,0.0007335999999999999,123.66463698749999,408.3412280350117,2.2807619830735035
3.897722826408224e-06,0.000744,125.417788875,408.3412280350117,2.2807619830735035
3.994118122115094e-06,0.0007624,128.5195191375,408.3412280350117,2.2807619830735035
4.08213121819528e-06,0.0007792,131.351533725,408.3412280350117,2.2807619830735035
4.128233316142044e-06,0.000788,132.8349699375,408.3412280350117,2.2807619830735035
4.308450608115757e-06,0.0008223999999999999,138.63385695,408.3412280350117,2.2807619830735035
4.417419203262654e-06,0.0008432,142.140160725,408.3412280350117,2.2807619830735035
4.450948001769391e-06,0.0008495999999999999,143.219023425,408.3412280350117,2.2807619830735035
4.6605029924365e-06,0.0008895999999999999,149.9619153,408.3412280350117,2.2807619830735035
4.857484683663583e-06,0.0009272,156.3002336625,408.3412280350117,2.2807619830735035
4.962262178997136e-06,0.0009471999999999999,159.67167959999998,408.3412280350117,2.2807619830735035
4.991599877690532e-06,0.0009528,160.61568446249998,408.3412280350117,2.2807619830735035
5.0209375763839274e-06,0.0009584,161.559689325,408.3412280350117,2.2807619830735035
5.125715071717482e-06,0.0009784,162.86607613123755,408.3412280350117,2.2807619830735035
5.167626069850903e-06,0.0009864,162.9087644336011,408.3412280350117,2.2807619830735035
5.264021365557773e-06,0.0010048,163.00643838824894,408.3412280350117,2.2807619830735035
5.3310789625712486e-06,0.0010176,163.07397445938014,408.3412280350117,2.2807619830735035
5.523869553984989e-06,0.0010544,163.2663193247582,408.3412280350117,2.2807619830735035
5.549016152865042e-06,0.0010592,163.2912133399627,408.3412280350117,2.2807619830735035
5.569971651931753e-06,0.0010632,163.31192476165265,408.3412280350117,2.2807619830735035
5.641220348758569e-06,0.0010768,163.38211739316648,408.3412280350117,2.2807619830735035
5.766953343158834e-06,0.0011007999999999999,163.50514907163753,408.3412280350117,2.2807619830735035
5.9806994336392856e-06,0.0011416,163.71192855901103,408.3412280350117,2.2807619830735035
6.085476928972841e-06,0.0011616,163.81223666105643,408.3412280350117,2.2807619830735035
6.190254424306394e-06,0.0011815999999999999,163.9118734234948,408.3412280350117,2.2807619830735035
6.295031919639949e-06,0.0012016,164.01085459070828,408.3412280350117,2.2807619830735035
6.424956013853556e-06,0.0012263999999999999,164.13270337244276,408.3412280350117,2.2807619830735035
6.445911512920267e-06,0.0012304,164.15226604901443,408.3412280350117,2.2807619830735035
6.521351309560426e-06,0.0012448,164.222487242648,408.3412280350117,2.2807619830735035
6.596791106200586e-06,0.0012592,164.2923923337527,408.3412280350117,2.2807619830735035
6.743479599667561e-06,0.0012871999999999998,164.42743275832368,408.3412280350117,2.2807619830735035
6.969798989588039e-06,0.0013304,164.633554858172,408.3412280350117,2.2807619830735035
7.036856586601514e-06,0.0013432,164.69412459171897,408.3412280350117,2.2807619830735035
7.141634081935068e-06,0.0013632,164.78831608178703,408.3412280350117,2.2807619830735035
7.18354508006849e-06,0.0013712,164.82584158527573,408.3412280350117,2.2807619830735035
7.263175976521991e-06,0.0013863999999999999,164.8969056406472,408.3412280350117,2.2807619830735035
7.346997972788836e-06,0.0014024,164.97138242256406,408.3412280350117,2.2807619830735035
7.4098644699889675e-06,0.0014144,165.02702272940078,408.3412280350117,2.2807619830735035
7.443393268495704e-06,0.0014207999999999998,165.0566222674812,408.3412280350117,2.2807619830735035
7.682285957856209e-06,0.0014663999999999999,165.2660340219251,408.3412280350117,2.2807619830735035
7.745152455056342e-06,0.0014784,165.32071830675565,408.3412280350117,2.2807619830735035
7.766107954123053e-06,0.0014824,165.33890789749438,408.3412280350117,2.2807619830735035
7.808018952256475e-06,0.0014904,165.37522975530666,408.3412280350117,2.2807619830735035
7.845738850576554e-06,0.0014976,165.40785446799816,408.3412280350117,2.2807619830735035
7.875076549269949e-06,0.0015032,165.4331869718021,408.3412280350117,2.2807619830735035
7.93375194665674e-06,0.0015144,165.4837418320667,408.3412280350117,2.2807619830735035
8.210364534337323e-06,0.0015672,165.7201350988889,408.3412280350117,2.2807619830735035
8.24389333284406e-06,0.0015735999999999999,165.74857622772433,408.3412280350117,2.2807619830735035
8.269039931724114e-06,0.0015784,165.76987747872002,408.3412280350117,2.2807619830735035
8.302568730230851e-06,0.0015848,165.79823988952862,408.3412280350117,2.2807619830735035
8.361244127617642e-06,0.001596,165.84776685626068,408.3412280350117,2.2807619830735035
8.461830523137855e-06,0.0016152,165.93235602668204,408.3412280350117,2.2807619830735035
8.482786022204565e-06,0.0016192,165.9499293095669,408.3412280350117,2.2807619830735035
8.51212372089796e-06,0.0016248,165.97450348854542,408.3412280350117,2.2807619830735035
8.528888120151328e-06,0.0016279999999999999,165.9885310457428,408.3412280350117,2.2807619830735035
8.692341012871674e-06,0.0016592,166.1247408415173,408.3412280350117,2.2807619830735035
8.952189201298888e-06,0.0017088,166.339240931011,408.3412280350117,2.2807619830735035
8.989909099618967e-06,0.0017159999999999999,166.37017502059507,408.3412280350117,2.2807619830735035
9.056966696632442e-06,0.0017288,166.42504426117478,408.3412280350117,2.2807619830735035
9.12821539345926e-06,0.0017423999999999999,166.48316951401458,408.3412280350117,2.2807619830735035
9.312623785246316e-06,0.0017775999999999998,166.63279561240458,408.3412280350117,2.2807619830735035
9.362916983006421e-06,0.0017871999999999999,166.67340161185987,408.3412280350117,2.2807619830735035
9.568280873860188e-06,0.0018264,166.8383341936358,408.3412280350117,2.2807619830735035
9.652102870127032e-06,0.0018424,166.90525616984075,408.3412280350117,2.2807619830735035
9.735924866393876e-06,0.0018583999999999999,166.9719518689015,408.3412280350117,2.2807619830735035
9.773644764713955e-06,0.0018655999999999998,167.0018918328961,408.3412280350117,2.2807619830735035
9.790409163967323e-06,0.0018687999999999999,167.0151840150624,408.3412280350117,2.2807619830735035
9.89937775911422e-06,0.0018896,167.1013678410227,408.3412280350117,2.2807619830735035
1.00167285538878e-05,0.0019119999999999999,167.1937684599122,408.3412280350117,2.2807619830735035
1.007121285146125e-05,0.0019223999999999999,167.2365251461243,408.3412280350117,2.2807619830735035
1.0184372546421488e-05,0.001944,167.325040321383,408.3412280350117,2.2807619830735035
1.0272385642501674e-05,0.0019608,167.39362054248951,408.3412280350117,2.2807619830735035
1.0293341141568386e-05,0.0019648,167.40991534410236,408.3412280350117,2.2807619830735035
1.0331061039888464e-05,0.001972,167.4392134215846,408.3412280350117,2.2807619830735035
1.038135423764857e-05,0.0019816,167.4782127118274,408.3412280350117,2.2807619830735035
1.0460985134102073e-05,0.0019968,167.53981123066814,408.3412280350117,2.2807619830735035
1.0511278331862178e-05,0.0020063999999999998,167.57862135367265,408.3412280350117,2.2807619830735035
1.0582527028688995e-05,0.00202,167.63347861990383,408.3412280350117,2.2807619830735035
1.0641202426075787e-05,0.0020312,167.67854711832712,408.3412280350117,2.2807619830735035
1.0670540124769181e-05,0.0020368,167.701045015937,408.3412280350117,2.2807619830735035
1.0733406621969313e-05,0.0020488,167.74917372444133,408.3412280350117,2.2807619830735035
1.0888477315062973e-05,0.0020783999999999998,167.86742354256046,408.3412280350117,2.2807619830735035
1.0901050614503e-05,0.0020808,167.8769824847232,408.3412280350117,2.2807619830735035
1.0951343812263108e-05,0.0020904,167.91517533306234,408.3412280350117,2.2807619830735035
1.1010019209649897e-05,0.0021016,167.95964730722767,408.3412280350117,2.2807619830735035
1.1089650106103399e-05,0.0021168,168.01985456879828,408.3412280350117,2.2807619830735035
1.1144134403676848e-05,0.0021272,168.06095189631375,408.3412280350117,2.2807619830735035
1.1257294098637085e-05,0.0021487999999999998,168.14605834203988,408.3412280350117,2.2807619830735035
1.132435169565056e-05,0.0021616,168.19633435906331,408.3412280350117,2.2807619830735035
1.1374644893410666e-05,0.0021712,168.23396521163164,408.3412280350117,2.2807619830735035
1.15171422870643e-05,0.0021984,168.34023518482334,408.3412280350117,2.2807619830735035
1.174765277679812e-05,0.0022424,168.51106318545524,408.3412280350117,2.2807619830735035
1.1814710373811594e-05,0.0022551999999999997,168.56051248763234,408.3412280350117,2.2807619830735035
1.1831474773064964e-05,0.0022584,168.57285769541713,408.3412280350117,2.2807619830735035
1.1852430272131675e-05,0.0022624,168.58827961592033,408.3412280350117,2.2807619830735035
1.1860812471758359e-05,0.002264,168.59444540618424,408.3412280350117,2.2807619830735035
1.1953016667651887e-05,0.0022816,168.6621573193116,408.3412280350117,2.2807619830735035
1.2007500965225334e-05,0.0022919999999999998,168.70207315765788,408.3412280350117,2.2807619830735035
1.2108087360745547e-05,0.0023112,168.7755788503878,408.3412280350117,2.2807619830735035
1.214999835887897e-05,0.0023192,168.80613589077953,408.3412280350117,2.2807619830735035
1.2158380558505654e-05,0.0023208,168.81224236288725,408.3412280350117,2.2807619830735035
1.2250584754399182e-05,0.0023384,168.87930555212407,408.3412280350117,2.2807619830735035
1.24014643476795e-05,0.0023672,168.98862225078884,408.3412280350117,2.2807619830735035
1.2531388441893108e-05,0.002392,169.08234109118558,408.3412280350117,2.2807619830735035
1.259425493909324e-05,0.002404,169.1275528098511,408.3412280350117,2.2807619830735035
1.2648739236666687e-05,0.0024143999999999997,169.16666515109426,408.3412280350117,2.2807619830735035
1.2833147628453743e-05,0.0024495999999999997,169.29856054538135,408.3412280350117,2.2807619830735035
1.2937925123787298e-05,0.0024695999999999997,169.3731717754324,408.3412280350117,2.2807619830735035
1.2954689523040666e-05,0.0024728,169.385087669128,408.3412280350117,2.2807619830735035
1.3067849218000906e-05,0.0024944,169.4653632309443,408.3412280350117,2.2807619830735035
1.3084613617254275e-05,0.0024976,169.47723280986366,408.3412280350117,2.2807619830735035
1.3147480114454406e-05,0.0025096,169.5216910070966,408.3412280350117,2.2807619830735035
1.3260639809414647e-05,0.0025312,169.601507397319,408.3412280350117,2.2807619830735035
1.338218170400157e-05,0.0025544,169.68694080844665,408.3412280350117,2.2807619830735035
1.3411519402694963e-05,0.0025599999999999998,169.7075172630896,408.3412280350117,2.2807619830735035
1.3520487997841861e-05,0.0025808,169.78379089101873,408.3412280350117,2.2807619830735035
1.3625265493175415e-05,0.0026008,169.85690514756726,408.3412280350117,2.2807619830735035
1.3683940890562205e-05,0.0026119999999999997,169.8977533445912,408.3412280350117,2.2807619830735035
1.3813864984775814e-05,0.0026368,169.98796061673053,408.3412280350117,2.2807619830735035
1.3893495881229314e-05,0.002652,170.04308541696582,408.3412280350117,2.2807619830735035
1.4040184374696291e-05,0.00268,170.14430961888246,408.3412280350117,2.2807619830735035
1.4082095372829712e-05,0.002688,170.17315495468614,408.3412280350117,2.2807619830735035
1.4224592766483347e-05,0.0027152,170.27097962532142,408.3412280350117,2.2807619830735035
1.427069486443011e-05,0.002724,170.30254685838435,408.3412280350117,2.2807619830735035
1.4316796962376875e-05,0.0027328,170.33407434447633,408.3412280350117,2.2807619830735035
1.4362899060323638e-05,0.0027416,170.36556226139362,408.3412280350117,2.2807619830735035
1.4467676555657193e-05,0.0027616,170.4369794830995,408.3412280350117,2.2807619830735035
1.4509587553790614e-05,0.0027695999999999997,170.46548985750695,408.3412280350117,2.2807619830735035
1.4643702747817565e-05,0.0027952,170.5565079794385,408.3412280350117,2.2807619830735035
1.4664658246884275e-05,0.0027992,170.57070014089572,408.3412280350117,2.2807619830735035
1.4710760344831038e-05,0.0028079999999999997,170.60189508510854,408.3412280350117,2.2807619830735035
1.4828111139604619e-05,0.0028304,170.68112884158188,408.3412280350117,2.2807619830735035
1.48658310379247e-05,0.0028376,170.70654484875314,408.3412280350117,2.2807619830735035
1.4932888634938174e-05,0.0028504,170.75166684779495,408.3412280350117,2.2807619830735035
1.4958035233818228e-05,0.0028552,170.76856721545448,408.3412280350117,2.2807619830735035
1.502090173101836e-05,0.0028672,170.81076972907678,408.3412280350117,2.2807619830735035
1.509634152765852e-05,0.0028816,170.86132192588857,408.3412280350117,2.2807619830735035
1.52136923224321e-05,0.002904,170.93976328892944,408.3412280350117,2.2807619830735035
1.527655881963223e-05,0.0029159999999999998,170.98168836426544,408.3412280350117,2.2807619830735035
1.5314278717952312e-05,0.0029232,171.0068111128493,408.3412280350117,2.2807619830735035
1.542324731309921e-05,0.002944,171.0792527376883,408.3412280350117,2.2807619830735035
1.5515451508992737e-05,0.0029616,171.1403937251125,408.3412280350117,2.2807619830735035
1.5586700205819554e-05,0.0029752,171.1875420289796,408.3412280350117,2.2807619830735035
1.561603790451295e-05,0.0029808,171.2069315970993,408.3412280350117,2.2807619830735035
1.5628611203952975e-05,0.0029831999999999997,171.21523706249923,408.3412280350117,2.2807619830735035
1.5838166194620084e-05,0.0030231999999999998,171.35328012211832,408.3412280350117,2.2807619830735035
1.5955516989393667e-05,0.0030456,171.4302730532932,408.3412280350117,2.2807619830735035
1.6106396582673983e-05,0.0030743999999999997,171.52894023080881,408.3412280350117,2.2807619830735035
1.613992538118072e-05,0.0030808,171.5508172412125,408.3412280350117,2.2807619830735035
1.6278231675021014e-05,0.0031072,171.6408731939044,408.3412280350117,2.2807619830735035
1.6353671471661172e-05,0.0031216,171.68986882927723,408.3412280350117,2.2807619830735035
1.639139136998125e-05,0.0031287999999999997,171.71433358619245,408.3412280350117,2.2807619830735035
1.648778666568812e-05,0.0031471999999999997,171.77675508875967,408.3412280350117,2.2807619830735035
1.652131546419486e-05,0.0031536,171.79843353223805,408.3412280350117,2.2807619830735035
1.6554844262701597e-05,0.00316,171.820094824514,408.3412280350117,2.2807619830735035
1.6655430658221807e-05,0.0031791999999999996,171.88497627561298,408.3412280350117,2.2807619830735035
1.667638615728852e-05,0.0031831999999999997,171.89847398991887,408.3412280350117,2.2807619830735035
1.6743443754301997e-05,0.003196,171.9416222914776,408.3412280350117,2.2807619830735035
1.6839839050008867e-05,0.0032144,172.00353008828895,408.3412280350117,2.2807619830735035
1.68733678485156e-05,0.0032208,172.02503081883668,408.3412280350117,2.2807619830735035
1.6919469946462365e-05,0.0032296,172.0545671368771,408.3412280350117,2.2807619830735035
1.702005634198258e-05,0.0032488,172.11890128431236,408.3412280350117,2.2807619830735035
1.7149980436196186e-05,0.0032735999999999998,172.20178052308185,408.3412280350117,2.2807619830735035
1.7204464733769635e-05,0.003284,172.23646341649211,408.3412280350117,2.2807619830735035
1.7288286730036478e-05,0.0033,172.28973818687354,408.3412280350117,2.2807619830735035
1.731762442872987e-05,0.0033055999999999997,172.30836054490587,408.3412280350117,2.2807619830735035
1.735534432704995e-05,0.0033128,172.3322855077112,408.3412280350117,2.2807619830735035
1.746850402201019e-05,0.0033344,172.40393901571298,408.3412280350117,2.2807619830735035
1.7489459521076902e-05,0.0033384,172.4171882947314,408.3412280350117,2.2807619830735035
1.7598428116223797e-05,0.0033591999999999997,172.4859849977228,408.3412280350117,2.2807619830735035
1.775349880931746e-05,0.0033888,172.58360225248447,408.3412280350117,2.2807619830735035
1.7837320805584302e-05,0.0034048,172.63622985838774,408.3412280350117,2.2807619830735035
1.7879231803717723e-05,0.0034127999999999997,172.66250748590554,408.3412280350117,2.2807619830735035
1.8189373189905046e-05,0.003472,172.8562207649331,408.3412280350117,2.2807619830735035
1.827319518617189e-05,0.0034879999999999998,172.90835403769267,408.3412280350117,2.2807619830735035
1.8289959585425257e-05,0.0034912,172.91876949128695,408.3412280350117,2.2807619830735035
1.8415692579825523e-05,0.0035152,172.99676706318186,408.3412280350117,2.2807619830735035
1.850789677571905e-05,0.0035328,173.05383335016626,408.3412280350117,2.2807619830735035
1.8541425574225787e-05,0.0035391999999999997,173.07455722357096,408.3412280350117,2.2807619830735035
1.8570763272919183e-05,0.0035448,173.09267862657788,408.3412280350117,2.2807619830735035
1.862105647067929e-05,0.0035543999999999997,173.1237179350627,408.3412280350117,2.2807619830735035
1.8683922967879422e-05,0.0035664,173.16247113178738,408.3412280350117,2.2807619830735035
1.8826420361533057e-05,0.0035935999999999997,173.25012393190522,408.3412280350117,2.2807619830735035
1.8847375860599766e-05,0.0035976,173.2629921932643,408.3412280350117,2.2807619830735035
1.89102423577999e-05,0.0036095999999999997,173.3015635392104,408.3412280350117,2.2807619830735035
1.8943771156306636e-05,0.003616,173.3221144739622,408.3412280350117,2.2807619830735035
1.914494394734706e-05,0.0036544,173.44512350081268,408.3412280350117,2.2807619830735035
1.9216192644173878e-05,0.003668,173.4885681806738,408.3412280350117,2.2807619830735035
1.927905914137401e-05,0.0036799999999999997,173.52684957836803,408.3412280350117,2.2807619830735035
1.9371263337267538e-05,0.0036975999999999997,173.5829076821233,408.3412280350117,2.2807619830735035
1.9417365435214303e-05,0.0037064,173.61089770352095,408.3412280350117,2.2807619830735035
1.9576627228121306e-05,0.0037367999999999998,173.70739171521825,408.3412280350117,2.2807619830735035
1.964368482513478e-05,0.0037495999999999996,173.74792912604374,408.3412280350117,2.2807619830735035
1.9673022523828176e-05,0.0037551999999999998,173.76564726868673,408.3412280350117,2.2807619830735035
1.9819711017295152e-05,0.0037832,173.85408388060733,408.3412280350117,2.2807619830735035
1.9907724113375338e-05,0.0038,173.90702332733207,408.3412280350117,2.2807619830735035
1.997478171038881e-05,0.0038128,173.94729690017522,408.3412280350117,2.2807619830735035
2.006698590628234e-05,0.0038304,174.00258707222505,408.3412280350117,2.2807619830735035
2.008375030553571e-05,0.0038336,174.01262917691253,408.3412280350117,2.2807619830735035
2.0289114196389478e-05,0.0038728,174.13538083911232,408.3412280350117,2.2807619830735035
2.043580268985645e-05,0.0039008,174.22276410844657,408.3412280350117,2.2807619830735035
2.0561535684256717e-05,0.0039248,174.29746953190963,408.3412280350117,2.2807619830735035
2.05699178838834e-05,0.0039264,174.30244354966564,408.3412280350117,2.2807619830735035
2.0616019981830166e-05,0.0039352,174.3297865303931,408.3412280350117,2.2807619830735035
2.0657930979963587e-05,0.0039432,174.3546230993305,408.3412280350117,2.2807619830735035
2.0779472874550513e-05,0.0039664,174.42653826115583,408.3412280350117,2.2807619830735035
2.0842339371750643e-05,0.0039784,174.46367137597986,408.3412280350117,2.2807619830735035
2.0938734667457513e-05,0.0039968,174.52052409203907,408.3412280350117,2.2807619830735035
2.4376120638712502e-05,0.004652930586117224,176.48568415658116,408.3412280350117,2.2807619830735035
2.5482792323771846e-05,0.004864172834566914,177.09493431606342,408.3412280350117,2.2807619830735035
2.5684005357419e-05,0.004902580516103221,177.20458933537228,408.3412280350117,2.2807619830735035
2.9406446479891344e-05,0.005613122624524905,179.17639778784792,408.3412280350117,2.2807619830735035
3.1116757265892156e-05,0.005939587917583517,180.04943759408363,408.3412280350117,2.2807619830735035
3.403434625377589e-05,0.006496499299859972,181.4967109848617,408.3412280350117,2.2807619830735035
3.514101793883523e-05,0.006707741548309662,182.03290873485037,408.3412280350117,2.2807619830735035
3.584526355660027e-05,0.006842168433686738,182.37069905597428,408.3412280350117,2.2807619830735035
3.644890265754174e-05,0.006957391478295659,182.6581786633453,408.3412280350117,2.2807619830735035
3.6851328724836045e-05,0.007034206841368274,182.8488008359067,408.3412280350117,2.2807619830735035
3.9970130746366924e-05,0.007629525905181036,184.29954734762285,408.3412280350117,2.2807619830735035
4.077498288095554e-05,0.007783156631326265,184.66667903804432,408.3412280350117,2.2807619830735035
4.5302276138016507e-05,0.008647329465893179,186.68141438613083,408.3412280350117,2.2807619830735035
4.88235042268417e-05,0.009319463892778556,188.19455734676453,408.3412280350117,2.2807619830735035
4.9628356361430314e-05,0.009473094618923785,188.53436926217563,408.3412280350117,2.2807619830735035
5.073502804648966e-05,0.009684336867373475,188.998121924417,408.3412280350117,2.2807619830735035
5.184169973154901e-05,0.009895579115823165,189.45794581357688,408.3412280350117,2.2807619830735035
5.224412579884332e-05,0.00997239447889578,189.62420328957833,408.3412280350117,2.2807619830735035
5.3250190967079085e-05,0.010164432886577316,190.03767667465664,408.3412280350117,2.2807619830735035
5.4055043101667705e-05,0.010318063612722545,190.36626593654293,408.3412280350117,2.2807619830735035
5.53629278203742e-05,0.01056771354270854,190.89618276119424,408.3412280350117,2.2807619830735035
5.6972632089551425e-05,0.010874974994998999,191.54173239147696,408.3412280350117,2.2807619830735035
5.727445164002217e-05,0.010932586517303462,191.66197690129812,408.3412280350117,2.2807619830735035
5.8381123325081506e-05,0.01114382876575315,192.10077490245942,408.3412280350117,2.2807619830735035
6.260659703167174e-05,0.011950390078015603,193.74715987508216,408.3412280350117,2.2807619830735035
6.331084264943677e-05,0.012084816963392678,194.01728756102835,408.3412280350117,2.2807619830735035
6.552418601955546e-05,0.012507301460292058,194.85872986935428,408.3412280350117,2.2807619830735035
6.592661208684978e-05,0.012584116823364673,195.0105208707685,408.3412280350117,2.2807619830735035
6.703328377190912e-05,0.012795359071814363,195.42609420185738,408.3412280350117,2.2807619830735035
6.723449680555628e-05,0.01283376675335067,195.5013646329809,408.3412280350117,2.2807619830735035
6.864298804108635e-05,0.013102620524104821,196.02581941908218,408.3412280350117,2.2807619830735035
7.085633141120505e-05,0.013525105021004201,196.84156132016824,408.3412280350117,2.2807619830735035
7.306967478132374e-05,0.013947589517903581,197.64742386322987,408.3412280350117,2.2807619830735035
7.407573994955951e-05,0.014139627925585117,198.01057209514755,408.3412280350117,2.2807619830735035
7.518241163461886e-05,0.014350870174034807,198.4078206491342,408.3412280350117,2.2807619830735035
7.799939410567902e-05,0.01488857771554311,199.40884311971325,408.3412280350117,2.2807619830735035
8.001152444215056e-05,0.015272654530906182,200.11524478838788,408.3412280350117,2.2807619830735035
8.101758961038633e-05,0.015464692938587718,200.46584497263626,408.3412280350117,2.2807619830735035
8.182244174497494e-05,0.015618323664732947,200.74510412284553,408.3412280350117,2.2807619830735035
8.33315394973286e-05,0.015906381276255252,201.26584435526212,408.3412280350117,2.2807619830735035
8.494124376650583e-05,0.01621364272854571,201.81726305103024,408.3412280350117,2.2807619830735035
8.695337410297736e-05,0.016597719543908783,202.50083842604548,408.3412280350117,2.2807619830735035
8.836186533850742e-05,0.01686657331466293,202.975675065987,408.3412280350117,2.2807619830735035
8.85630783721546e-05,0.01690498099619924,203.0432671187856,408.3412280350117,2.2807619830735035
9.037399567497897e-05,0.017250650130026003,203.64892409026328,408.3412280350117,2.2807619830735035
9.19836999441562e-05,0.01755791158231646,204.18332349857445,408.3412280350117,2.2807619830735035
9.33921911796863e-05,0.017826765353070616,204.6479381045595,408.3412280350117,2.2807619830735035
9.439825634792204e-05,0.01801880376075215,204.97813408952285,408.3412280350117,2.2807619830735035
9.600796061709928e-05,0.018326065213042607,205.5036071723088,408.3412280350117,2.2807619830735035
9.671220623486433e-05,0.018460492098419684,205.73241996203325,408.3412280350117,2.2807619830735035
9.852312353768871e-05,0.01880616123224645,206.31783170091717,408.3412280350117,2.2807619830735035
9.973040173957163e-05,0.019036607321464293,206.70577644165004,408.3412280350117,2.2807619830735035
0.00010194374510969033,0.019459091818363673,207.41228453922005,408.3412280350117,2.2807619830735035
0.00010455951454710333,0.019958391678335668,208.23958158691636,408.3412280350117,2.2807619830735035
0.00010496194061439764,0.020035207041408282,208.36613805500986,408.3412280350117,2.2807619830735035
0.00010697407095086919,0.020419283856771355,208.99610389888326,408.3412280350117,2.2807619830735035
0.00011130015117428298,0.02124504900980196,210.3350905322695,408.3412280350117,2.2807619830735035
0.00011290985544346021,0.021552310462092418,210.82811660221014,408.3412280350117,2.2807619830735035
0.00011622987049863826,0.02218603720744149,211.8364086727581,408.3412280350117,2.2807619830735035
0.00011884563993605127,0.022685337067413484,212.62293026746894,408.3412280350117,2.2807619830735035
0.00012005291813793419,0.022915783156631328,212.98366029732998,408.3412280350117,2.2807619830735035
0.00012236686802487645,0.02335747149429886,213.67112941241544,408.3412280350117,2.2807619830735035
0.00012327232667628865,0.023530306061212244,213.93875663004016,408.3412280350117,2.2807619830735035
0.00012377535926040654,0.02362632526505301,214.08710711983647,408.3412280350117,2.2807619830735035
0.0001247814244286423,0.023818363672734547,214.3831045745447,408.3412280350117,2.2807619830735035
0.00012790022645017317,0.02441368273654731,215.29483668897115,408.3412280350117,2.2807619830735035
0.00013101902847170407,0.025009001800360073,216.19793830024662,408.3412280350117,2.2807619830735035
0.00013152206105582196,0.02510502100420084,216.34281099340296,408.3412280350117,2.2807619830735035
0.00013373540442594063,0.02552750550110022,216.97770082060987,408.3412280350117,2.2807619830735035
0.0001352445021782943,0.025815563112622526,217.40823246993364,408.3412280350117,2.2807619830735035
0.00013574753476241217,0.025911582316463292,217.55132613874355,408.3412280350117,2.2807619830735035
0.00013755845206523656,0.026257251450290058,218.0647598577865,408.3412280350117,2.2807619830735035
0.00013826269768300162,0.026391678335667135,218.2637157801379,408.3412280350117,2.2807619830735035
0.0001399730084690024,0.026718143628725745,218.7452561626211,408.3412280350117,2.2807619830735035
0.00014289059745688617,0.027275055011002202,219.56144460310523,408.3412280350117,2.2807619830735035
0.0001449027277933577,0.027659131826365275,220.12055009702354,408.3412280350117,2.2807619830735035
0.00014902759498312435,0.028446489297859572,221.25733840417894,408.3412280350117,2.2807619830735035
0.000150536692735478,0.028734546909381875,221.67016195565083,408.3412280350117,2.2807619830735035
0.00015194518397100806,0.029003400680136026,222.0540101148487,408.3412280350117,2.2807619830735035
0.0001543597403747739,0.029464292858571713,222.70882260388566,408.3412280350117,2.2807619830735035
0.0001566736902617162,0.02990598119623925,223.332612844752,408.3412280350117,2.2807619830735035
0.00015918885318230561,0.030386077215443088,224.0065843763916,408.3412280350117,2.2807619830735035
0.00016059734441783568,0.03065493098619724,224.38219410619783,408.3412280350117,2.2807619830735035
0.0001615028030692479,0.030827765553110623,224.62297924839646,408.3412280350117,2.2807619830735035
0.00016331372037207227,0.03117343468693739,225.10297587603822,408.3412280350117,2.2807619830735035
0.00016391735947301372,0.03128865773154631,225.2625128818189,408.3412280350117,2.2807619830735035
0.0001654264572253674,0.03157671534306861,225.6603562271794,408.3412280350117,2.2807619830735035
0.0001666337354272503,0.03180716143228646,225.9776127298292,408.3412280350117,2.2807619830735035
0.00017025557003289907,0.03249849969993999,226.92404675304226,408.3412280350117,2.2807619830735035
0.0001727707329534885,0.03297859571914383,227.57667782845445,408.3412280350117,2.2807619830735035
0.00017367619160490072,0.033151430286057215,227.8107165872044,408.3412280350117,2.2807619830735035
0.0001761913545254901,0.03363152630526105,228.45834058805434,408.3412280350117,2.2807619830735035
0.0001769962066600787,0.03378515703140628,228.66481745921422,408.3412280350117,2.2807619830735035
0.00017931015654702102,0.03422684536907382,229.25640854465522,408.3412280350117,2.2807619830735035
0.0001893708082293787,0.036147229445889176,231.7946841355865,408.3412280350117,2.2807619830735035
0.00019178536463314454,0.03660812162432486,232.39597691491926,408.3412280350117,2.2807619830735035
0.00019440113407055752,0.037107421484296854,233.04405540921283,408.3412280350117,2.2807619830735035
0.0001958096253060876,0.03737627525505101,233.39161171225152,408.3412280350117,2.2807619830735035
0.00019812357519302992,0.03781796359271855,233.9604878376384,408.3412280350117,2.2807619830735035
0.00019973327946220715,0.03812522504500901,234.35470041939402,408.3412280350117,2.2807619830735035
0.0002011417706977372,0.03839407881576315,234.69862112660073,408.3412280350117,2.2807619830735035
0.00020214783586597294,0.03858611722344468,234.94370398018714,408.3412280350117,2.2807619830735035
0.00020355632710150303,0.03885497099419884,235.2860223011766,408.3412280350117,2.2807619830735035
0.000207379374740799,0.03958471694338868,236.2105469781871,408.3412280350117,2.2807619830735035
0.0002095927181109177,0.04000720144028806,236.74275986507806,408.3412280350117,2.2807619830735035
0.00021100120934644772,0.0402760552110422,237.08029985430764,408.3412280350117,2.2807619830735035
0.00021180606148103634,0.04042968593718743,237.27278530157125,408.3412280350117,2.2807619830735035
0.00021532728956986154,0.04110182036407281,238.1115772991699,408.3412280350117,2.2807619830735035
0.00022247035226433554,0.04246529305861173,239.7968705752775,408.3412280350117,2.2807619830735035
0.00022790310417280865,0.043502300460092014,241.0645499040972,408.3412280350117,2.2807619830735035
0.00022830553024010298,0.043579115823164635,241.1579805997162,408.3412280350117,2.2807619830735035
0.00023414070821587045,0.04469293858771754,242.50558890552153,408.3412280350117,2.2807619830735035
0.00023625344506916554,0.04509621924384877,242.99027801889432,408.3412280350117,2.2807619830735035
0.00023896982102340213,0.04561472294458892,243.61097305319532,408.3412280350117,2.2807619830735035
0.00024389954034775743,0.04655571114222845,244.73043653830206,408.3412280350117,2.2807619830735035
0.00024470439248234604,0.04670934186837368,244.91236481487883,408.3412280350117,2.2807619830735035
0.00024550924461693466,0.04686297259451891,245.09405987372298,408.3412280350117,2.2807619830735035
0.0002477225879870533,0.04728545709141828,245.59252739776773,408.3412280350117,2.2807619830735035
0.00024903047270575986,0.04753510702140429,245.88625998787762,408.3412280350117,2.2807619830735035
0.0002506401769749371,0.047842368473694746,246.2469524098133,408.3412280350117,2.2807619830735035
0.00025194806169364357,0.04809201840368074,246.53935023526086,408.3412280350117,2.2807619830735035
0.0002538595855132915,0.04845689137827565,246.96563831095654,408.3412280350117,2.2807619830735035
0.00025436261809740947,0.04855291058211643,247.07761108840296,408.3412280350117,2.2807619830735035
0.0002555698962992923,0.048783356671334266,247.34599398571476,408.3412280350117,2.2807619830735035
0.0002567771745011753,0.049013802760552116,247.6138828920179,408.3412280350117,2.2807619830735035
0.0002588899113544704,0.04941708341668334,248.08150949338034,408.3412280350117,2.2807619830735035
0.00025999658303952976,0.04962832566513303,248.32586265702957,408.3412280350117,2.2807619830735035
0.00026140507427505977,0.04989717943588717,248.63627173149607,408.3412280350117,2.2807619830735035
0.00026190810685917763,0.04999319863972794,248.7469739472377,408.3412280350117,2.2807619830735035
0.0002636184176451785,0.05031966393278656,249.12274277744862,408.3412280350117,2.2807619830735035
0.00026462448281341423,0.05051170234046809,249.3433391350054,408.3412280350117,2.2807619830735035
0.00026774328483494515,0.05110702140428086,250.0251183900545,408.3412280350117,2.2807619830735035
0.0002690511695536517,0.05135667133426686,250.31010324645027,408.3412280350117,2.2807619830735035
0.0002717675455078882,0.05187517503500701,250.90027431019416,408.3412280350117,2.2807619830735035
0.000274685134495772,0.05243208641728346,251.53160506137354,408.3412280350117,2.2807619830735035
0.00027891060820236217,0.05323864772954591,252.44132923037103,408.3412280350117,2.2807619830735035
0.00027951424730330367,0.053353870774154835,252.57084968887304,408.3412280350117,2.2807619830735035
0.0002824318362911874,0.05391078215643129,253.19533390827428,408.3412280350117,2.2807619830735035
0.0002827336558416581,0.05396839367873575,253.25979179950326,408.3412280350117,2.2807619830735035
0.0002838403275267175,0.05417963592718544,253.49590815739592,408.3412280350117,2.2807619830735035
0.0002850476057286004,0.05441008201640328,253.75308053907628,408.3412280350117,2.2807619830735035
0.00028565124482954183,0.054525305061012205,253.88150740692151,408.3412280350117,2.2807619830735035
0.00028766337516601334,0.05490938187637527,254.30883459804897,408.3412280350117,2.2807619830735035
0.00028917247291836704,0.055197439487897584,254.6285654013823,408.3412280350117,2.2807619830735035
0.0002915870293221329,0.05565833166633327,255.13878446242822,408.3412280350117,2.2807619830735035
0.0002950076508941345,0.05631126225245049,255.85878315899785,408.3412280350117,2.2807619830735035
0.0002958125030287231,0.05646489297859572,256.0277205636614,408.3412280350117,2.2807619830735035
0.00030365981134096215,0.05796279255851171,257.66557270047355,408.3412280350117,2.2807619830735035
0.00030506830257649216,0.05823164632926585,257.95779036206005,408.3412280350117,2.2807619830735035
0.000306778613362493,0.058558111622324466,258.3119196705171,408.3412280350117,2.2807619830735035
0.00030919316976625886,0.05901900380076015,258.81055890973784,408.3412280350117,2.2807619830735035
0.0003110040870690832,0.059364672934586915,259.1835423302133,408.3412280350117,2.2807619830735035
0.0003115071196532011,0.05946069213842768,259.28699839567537,408.3412280350117,2.2807619830735035
0.000312010152237319,0.05955671134226845,259.39038932647287,408.3412280350117,2.2807619830735035
0.0003143241021242613,0.05999839967993599,259.86515279421036,408.3412280350117,2.2807619830735035
0.0003162356259439093,0.06036327265453091,260.2563214588538,408.3412280350117,2.2807619830735035
0.00031754351066261576,0.06061292258451691,260.52343201347077,408.3412280350117,2.2807619830735035
0.00031834836279720437,0.060766553310662136,260.6875944912084,408.3412280350117,2.2807619830735035
0.00032307686908791247,0.06166913382676535,261.6488002421402,408.3412280350117,2.2807619830735035
0.0003232780821215596,0.061707541508301655,261.6895804658618,408.3412280350117,2.2807619830735035
0.00032579324504214906,0.0621876375275055,262.1985008871505,408.3412280350117,2.2807619830735035
0.00033001871874873925,0.06299419883976795,263.0500511834156,408.3412280350117,2.2807619830735035
0.0003321314556020344,0.06339747949589918,263.4742309861562,408.3412280350117,2.2807619830735035
0.00033615571627497746,0.06416563312662532,264.27929260323083,408.3412280350117,2.2807619830735035
0.0003385702726787433,0.06462652530506101,264.7605255677247,408.3412280350117,2.2807619830735035
0.00034118604211615637,0.06512582516503301,265.28035335023816,408.3412280350117,2.2807619830735035
0.0003434999920030986,0.06556751350270054,265.7389067701862,408.3412280350117,2.2807619830735035
0.0003461157614405116,0.06606681336267253,266.25582332414183,408.3412280350117,2.2807619830735035
0.00034802728526015956,0.06643168633726745,266.63260703835635,408.3412280350117,2.2807619830735035
0.00035205154593310263,0.0671998399679936,267.4232079390218,408.3412280350117,2.2807619830735035
0.00035346003716863275,0.06746869373874775,267.69908456122465,408.3412280350117,2.2807619830735035
0.00035557277402192784,0.06787197439487898,268.1120969689661,408.3412280350117,2.2807619830735035
0.0003558745935723986,0.06792958591718344,268.1710205190211,408.3412280350117,2.2807619830735035
0.0003578867239088701,0.0683136627325465,268.56334730483707,408.3412280350117,2.2807619830735035
0.00035949642817804733,0.06862092418483696,268.87658970894444,408.3412280350117,2.2807619830735035
0.00036181037806498964,0.06906261252250451,269.3259190240936,408.3412280350117,2.2807619830735035
0.0003642249344687555,0.0695235047009402,269.79359114484606,408.3412280350117,2.2807619830735035
0.0003706637515454644,0.07075255051010203,271.0348429785205,408.3412280350117,2.2807619830735035
0.00037569407738664325,0.0717127425485097,271.9987291426481,408.3412280350117,2.2807619830735035
0.00037871227289135054,0.07228885777155432,272.5746451207267,408.3412280350117,2.2807619830735035
0.00038012076412688065,0.07255771154230847,272.84279306185294,408.3412280350117,2.2807619830735035
0.0003823341074969993,0.07298019603920784,273.26338681802,408.3412280350117,2.2807619830735035
0.00038303835311476436,0.07311462292458493,273.39701282612754,408.3412280350117,2.2807619830735035
0.00038605654861947165,0.07369073814762953,273.96861386714187,408.3412280350117,2.2807619830735035
0.00038907474412417894,0.07426685337067414,274.53847471513774,408.3412280350117,2.2807619830735035
0.0003921935461457098,0.0748621724344869,275.1255226542136,408.3412280350117,2.2807619830735035
0.00039239475917935703,0.07490058011602321,275.1633340761784,408.3412280350117,2.2807619830735035
0.00039460810254947565,0.07532306461292258,275.5787618758636,408.3412280350117,2.2807619830735035
0.0003977269045710066,0.07591838367673535,276.1625982893731,408.3412280350117,2.2807619830735035
0.0003998396414243017,0.07632166433286658,276.5570862862374,408.3412280350117,2.2807619830735035
0.0004020529847944204,0.07674414882976596,276.9694884922063,408.3412280350117,2.2807619830735035
0.00040497057378230416,0.07730106021204242,277.51175928488215,408.3412280350117,2.2807619830735035
0.00040698270411877567,0.07768513702740548,277.884851731741,408.3412280350117,2.2807619830735035
0.00040849180187112937,0.0779731946389278,278.164199153699,408.3412280350117,2.2807619830735035
0.0004109063582748952,0.07843408681736348,278.6103193290213,408.3412280350117,2.2807619830735035
0.00041533304501513256,0.07927905581116224,279.42555997888144,408.3412280350117,2.2807619830735035
0.0004184518470366634,0.079874374874975,279.99790050731366,408.3412280350117,2.2807619830735035
0.00041925669917125205,0.08002800560112022,280.14533092636117,408.3412280350117,2.2807619830735035
0.00042106761647407644,0.080373674734947,280.4766463928806,408.3412280350117,2.2807619830735035
0.0004273052205171382,0.08156431286257251,281.61361455092424,408.3412280350117,2.2807619830735035
0.00042851249871902114,0.08179475895179036,281.8329232975986,408.3412280350117,2.2807619830735035
0.00042931735085360975,0.08194838967793559,281.9789952712014,408.3412280350117,2.2807619830735035
0.00043072584208913987,0.08221724344868975,282.2343644995165,408.3412280350117,2.2807619830735035
0.00043132948119008126,0.08233246649329866,282.3437087347725,408.3412280350117,2.2807619830735035
0.00043545434837984797,0.08311982396479296,283.08930351473714,408.3412280350117,2.2807619830735035
0.00043887496995184954,0.08377275455091018,283.7055146998734,408.3412280350117,2.2807619830735035
0.00044219498500702763,0.08440648129625926,284.3018132727505,408.3412280350117,2.2807619830735035
0.0004443077218603227,0.08480976195239048,284.6803670792748,408.3412280350117,2.2807619830735035
0.00044511257399491134,0.08496339267853571,284.82439331198185,408.3412280350117,2.2807619830735035
0.0004469234912977357,0.08530906181236247,285.1480814998698,408.3412280350117,2.2807619830735035
0.0004490362281510308,0.0857123424684937,285.52507193315023,408.3412280350117,2.2807619830735035
0.0004516519975884439,0.0862116423284657,285.9908649306764,408.3412280350117,2.2807619830735035
0.0004530604888239739,0.08648049609921984,286.2412407183758,408.3412280350117,2.2807619830735035
0.0004538653409585625,0.08663412682536507,286.3841762998989,408.3412280350117,2.2807619830735035
0.0004559780778118576,0.0870374074814963,286.7589126611422,408.3412280350117,2.2807619830735035
0.00045909687983338853,0.08763272654530907,287.3108596569795,408.3412280350117,2.2807619830735035
0.0004593986993838593,0.08769033806761353,287.3641961586773,408.3412280350117,2.2807619830735035
0.0004602035515184479,0.08784396879375876,287.50636005990657,408.3412280350117,2.2807619830735035
0.0004606059775857422,0.08792078415683137,287.5774056458775,408.3412280350117,2.2807619830735035
0.0004610084036530365,0.08799759951990399,287.64842702800576,408.3412280350117,2.2807619830735035
0.0004613102232035072,0.08805521104220844,287.7016771984963,408.3412280350117,2.2807619830735035
0.0004639259926409202,0.08855451090218044,288.1626109010814,408.3412280350117,2.2807619830735035
0.0004658375164605682,0.08891938387677537,288.4988063411094,408.3412280350117,2.2807619830735035
0.0004661393360110389,0.08897699539907981,288.55184060990547,408.3412280350117,2.2807619830735035
0.00046805085983068687,0.08934186837367473,288.88741385056477,408.3412280350117,2.2807619830735035
0.0004692581380325698,0.08957231446289259,289.0990794838376,408.3412280350117,2.2807619830735035
0.0004713708748858649,0.08997559511902381,289.4689840173996,408.3412280350117,2.2807619830735035
0.0004758981681429259,0.09083976795359072,290.25946628359014,408.3412280350117,2.2807619830735035
0.00048334305038787054,0.09226085217043409,291.55302323624994,408.3412280350117,2.2807619830735035
0.00048485214814022423,0.0925489097819564,291.8142809605112,408.3412280350117,2.2807619830735035
0.0004854557872411657,0.09266413282656531,291.9186952298732,408.3412280350117,2.2807619830735035
0.00048646185240940146,0.09285617123424686,292.09260655997633,408.3412280350117,2.2807619830735035
0.0004893794413972852,0.09341308261652331,292.5961579388783,408.3412280350117,2.2807619830735035
0.0004902849000486974,0.09358591718343669,292.7521942668553,408.3412280350117,2.2807619830735035
0.0004914921782505804,0.09381636327265454,292.96006799480546,408.3412280350117,2.2807619830735035
0.0004939067346543462,0.09427725545109022,293.3752189985373,408.3412280350117,2.2807619830735035
0.0004945103737552877,0.09439247849569915,293.47888298161087,408.3412280350117,2.2807619830735035
0.0004952146193730526,0.09452690538107622,293.5997619419313,408.3412280350117,2.2807619830735035
0.0004959188649908177,0.09466133226645329,293.72057387895813,408.3412280350117,2.2807619830735035
0.000497025536675877,0.09487257451490298,293.9102861121304,408.3412280350117,2.2807619830735035
0.0005009491908319966,0.09562152430486098,294.5815788011148,408.3412280350117,2.2807619830735035
0.0005066837622909404,0.09671614322864573,295.5590220045084,408.3412280350117,2.2807619830735035
0.0005090983186947063,0.09717703540708142,295.9692852163435,408.3412280350117,2.2807619830735035
0.0005100037773461184,0.09734986997399481,296.1229381884221,408.3412280350117,2.2807619830735035
0.0005130219728508257,0.0979259851970394,296.6343481243884,408.3412280350117,2.2807619830735035
0.0005133237924012965,0.09798359671934387,296.6854244965663,408.3412280350117,2.2807619830735035
0.000515335922737768,0.09836767353470695,297.0256348263917,408.3412280350117,2.2807619830735035
0.0005186559377929461,0.09900140028005601,297.5858514520334,408.3412280350117,2.2807619830735035
0.0005200644290284761,0.09927025405081016,297.8230963934789,408.3412280350117,2.2807619830735035
0.0005218753463313005,0.09961592318463693,298.12775771993654,408.3412280350117,2.2807619830735035
0.0005229820180163598,0.09982716543308662,298.31373668291496,408.3412280350117,2.2807619830735035
0.0005235856571173014,0.09994238847769554,298.41511506025057,408.3412280350117,2.2807619830735035