File: datasets/aisi_316_L/data/M1/valid_16.csv
Time(s),Strain(%),Stress(MPa),Temp(C),Log_SR(s-1)
0.0,0.0,0.0,190.66177379336332,5.125391168190024
1.0189379558348e-10,1.3599999999999999e-05,2.5386000125,190.66177379336332,5.125391168190024
1.9180008580419767e-10,2.56e-05,4.778541199999999,190.66177379336332,5.125391168190024
4.0158142965253884e-10,5.3599999999999995e-05,10.0050706375,190.66177379336332,5.125391168190024
5.094689779174e-10,6.8e-05,12.6930000625,190.66177379336332,5.125391168190024
6.713003003146918e-10,8.96e-05,16.724894199999998,190.66177379336332,5.125391168190024
7.851816012609342e-10,0.0001048,19.5621530375,190.66177379336332,5.125391168190024
8.690941388002708e-10,0.000116,21.6527648125,190.66177379336332,5.125391168190024
1.0249317085161814e-09,0.0001368,25.535329537499997,190.66177379336332,5.125391168190024
1.1028504933741366e-09,0.0001472,27.4766119,190.66177379336332,5.125391168190024
1.2826630738155718e-09,0.0001712,31.956494274999997,190.66177379336332,5.125391168190024
1.3485943533107647e-09,0.00017999999999999998,33.5991178125,190.66177379336332,5.125391168190024
1.4684694069383883e-09,0.000196,36.5857060625,190.66177379336332,5.125391168190024
1.864057083909546e-09,0.0002488,46.4414472875,190.66177379336332,5.125391168190024
1.9479696214488823e-09,0.00026,48.5320590625,190.66177379336332,5.125391168190024
2.133775954571699e-09,0.0002848,53.161270849999994,190.66177379336332,5.125391168190024
2.199707234066892e-09,0.0002936,54.803894387499994,190.66177379336332,5.125391168190024
2.277626018924847e-09,0.00030399999999999996,56.74517674999999,190.66177379336332,5.125391168190024
2.39150731987109e-09,0.0003192,59.5824355875,190.66177379336332,5.125391168190024
2.4094885779152335e-09,0.0003216,60.030423825,190.66177379336332,5.125391168190024
2.505388620817332e-09,0.0003344,62.419694424999996,190.66177379336332,5.125391168190024
2.6192699217635746e-09,0.0003496,65.25695326249999,190.66177379336332,5.125391168190024
2.715169964665673e-09,0.00036239999999999997,67.6462238625,190.66177379336332,5.125391168190024
2.811070007567772e-09,0.00037519999999999996,70.0354944625,190.66177379336332,5.125391168190024
2.9249513085140144e-09,0.0003904,72.8727533,190.66177379336332,5.125391168190024
2.942932566558158e-09,0.0003928,73.3207415375,190.66177379336332,5.125391168190024
2.9669075772836824e-09,0.000396,73.91805918749999,190.66177379336332,5.125391168190024
3.30855148012241e-09,0.0004416,82.4298357,190.66177379336332,5.125391168190024
3.3924640176617463e-09,0.0004528,84.520447475,190.66177379336332,5.125391168190024
3.506345318607989e-09,0.000468,87.3577063125,190.66177379336332,5.125391168190024
3.5782703507845626e-09,0.00047759999999999995,89.1496592625,190.66177379336332,5.125391168190024
3.632214124916993e-09,0.00048479999999999997,90.49362397499999,190.66177379336332,5.125391168190024
3.740101673181854e-09,0.0004992,93.1815534,190.66177379336332,5.125391168190024
3.782057941951523e-09,0.0005048,94.2268592875,190.66177379336332,5.125391168190024
3.913920500941909e-09,0.0005224,97.5121063625,190.66177379336332,5.125391168190024
4.129695597471631e-09,0.0005512,102.88796521249999,190.66177379336332,5.125391168190024
4.345470694001354e-09,0.00058,108.2638240625,190.66177379336332,5.125391168190024
4.573233295893838e-09,0.0006104,113.9383417375,190.66177379336332,5.125391168190024
4.68711459684008e-09,0.0006255999999999999,116.77560057499998,190.66177379336332,5.125391168190024
4.872920929962897e-09,0.0006504,121.4048123625,190.66177379336332,5.125391168190024
4.914877198732565e-09,0.000656,122.45011825,190.66177379336332,5.125391168190024
5.14263980062505e-09,0.0006864,128.124635925,190.66177379336332,5.125391168190024
5.202577327438862e-09,0.0006944,129.61793004999998,190.66177379336332,5.125391168190024
5.2685086069340545e-09,0.0007032,131.2605535875,190.66177379336332,5.125391168190024
5.2804961122968175e-09,0.0007048,131.5592124125,190.66177379336332,5.125391168190024
5.352421144473391e-09,0.0007144,133.3511653625,190.66177379336332,5.125391168190024
5.8019525955769795e-09,0.0007744,144.55087129999998,190.66177379336332,5.125391168190024
5.873877627753553e-09,0.000784,146.34282425,190.66177379336332,5.125391168190024
5.975771423337034e-09,0.0007976,148.8814242625,190.66177379336332,5.125391168190024
6.023721444788083e-09,0.0008039999999999999,150.07605956249998,190.66177379336332,5.125391168190024
6.071671466239132e-09,0.0008104,151.2706948625,190.66177379336332,5.125391168190024
6.1256152403715626e-09,0.0008175999999999999,152.614659575,190.66177379336332,5.125391168190024
6.2394965413178055e-09,0.0008328,155.4519184125,190.66177379336332,5.125391168190024
6.317415326175761e-09,0.0008432,157.393200775,190.66177379336332,5.125391168190024
6.635084218288963e-09,0.0008856,165.3076596375,190.66177379336332,5.125391168190024
6.766946777279349e-09,0.0009031999999999999,168.5929067125,190.66177379336332,5.125391168190024
6.838871809455923e-09,0.0009128,170.3848596625,190.66177379336332,5.125391168190024
7.03067189526012e-09,0.0009383999999999999,175.1634008625,190.66177379336332,5.125391168190024
7.1925032176574125e-09,0.0009599999999999999,179.195295,190.66177379336332,5.125391168190024
7.264428249833986e-09,0.0009695999999999999,180.98724794999998,190.66177379336332,5.125391168190024
7.28240950787813e-09,0.000972,181.4352361875,190.66177379336332,5.125391168190024
7.372315798098847e-09,0.0009839999999999998,183.67517737499998,190.66177379336332,5.125391168190024
7.486197099045091e-09,0.0009992,186.5124362125,190.66177379336332,5.125391168190024
7.642034668761e-09,0.0010199999999999999,190.3950009375,190.66177379336332,5.125391168190024
7.7379347116631e-09,0.0010328,192.7842715375,190.66177379336332,5.125391168190024
7.863803517972104e-09,0.0010496,195.92018919999998,190.66177379336332,5.125391168190024
7.905759786741771e-09,0.0010551999999999998,196.96549508749996,190.66177379336332,5.125391168190024
7.94771605551144e-09,0.0010608,198.010800975,190.66177379336332,5.125391168190024
7.983678571599727e-09,0.0010655999999999999,198.90677744999996,190.66177379336332,5.125391168190024
8.127528635952876e-09,0.0010848,202.49068334999998,190.66177379336332,5.125391168190024
8.157497399359782e-09,0.0010888,203.2373304125,190.66177379336332,5.125391168190024
8.211441173492213e-09,0.001096,204.581295125,190.66177379336332,5.125391168190024
8.283366205668788e-09,0.0011056,206.373248075,190.66177379336332,5.125391168190024
8.319328721757074e-09,0.0011103999999999999,207.26922455,190.66177379336332,5.125391168190024
8.481160044154366e-09,0.001132,211.3011186875,190.66177379336332,5.125391168190024
8.631003861188895e-09,0.001152,215.034354,190.66177379336332,5.125391168190024
8.888735226488286e-09,0.0011864,221.4555187375,190.66177379336332,5.125391168190024
8.930691495257954e-09,0.001192,222.50082462499998,190.66177379336332,5.125391168190024
9.020597785478672e-09,0.001204,224.7407658125,190.66177379336332,5.125391168190024
9.146466591787676e-09,0.0012208,227.876683475,190.66177379336332,5.125391168190024
9.302304161503587e-09,0.0012416,231.7592482,190.66177379336332,5.125391168190024
9.584010537528501e-09,0.0012791999999999999,238.77773058749997,190.66177379336332,5.125391168190024
9.76981687065132e-09,0.001304,240.13137658645064,190.66177379336332,5.125391168190024
9.859723160872036e-09,0.001316,240.21492132446016,190.66177379336332,5.125391168190024
9.955623203774136e-09,0.0013288,240.30370890435114,190.66177379336332,5.125391168190024
1.0189379558348e-08,0.0013599999999999999,240.51874263946897,190.66177379336332,5.125391168190024
1.0327235870019768e-08,0.0013784,240.64465557374947,190.66177379336332,5.125391168190024
1.0531023461186728e-08,0.0014056,240.82959358601812,190.66177379336332,5.125391168190024
1.0554998471912254e-08,0.0014088,240.8512588554473,190.66177379336332,5.125391168190024
1.0710836041628162e-08,0.0014295999999999998,240.99161818165385,190.66177379336332,5.125391168190024
1.0740804805035069e-08,0.0014336,241.01851881136795,190.66177379336332,5.125391168190024
1.0872667364025456e-08,0.0014512,241.13653553063182,190.66177379336332,5.125391168190024
1.0920617385476505e-08,0.0014575999999999999,241.1793121336945,190.66177379336332,5.125391168190024
1.1172354998094515e-08,0.0014912,241.40269879331092,190.66177379336332,5.125391168190024
1.1400117599986999e-08,0.0015216,241.60312462600265,190.66177379336332,5.125391168190024
1.1657848965286389e-08,0.0015559999999999999,241.8280482816586,190.66177379336332,5.125391168190024
1.1921574083267161e-08,0.0015911999999999999,242.056204134675,190.66177379336332,5.125391168190024
1.1939555341311304e-08,0.0015936,242.0716881558184,190.66177379336332,5.125391168190024
1.2053436642257546e-08,0.0016087999999999999,242.16954327106163,190.66177379336332,5.125391168190024
1.2305174254875557e-08,0.0016424,242.384584120372,190.66177379336332,5.125391168190024
1.2407068050459036e-08,0.001656,242.47113586289402,190.66177379336332,5.125391168190024
1.2461011824591466e-08,0.0016631999999999999,242.51684512205085,190.66177379336332,5.125391168190024
1.257489312553771e-08,0.0016784,242.61308979374866,190.66177379336332,5.125391168190024
1.2670793168439809e-08,0.0016912,242.69387456794652,190.66177379336332,5.125391168190024
1.2844611996199862e-08,0.0017143999999999998,242.83969179099654,190.66177379336332,5.125391168190024
1.3018430823959916e-08,0.0017376,242.98474144132237,190.66177379336332,5.125391168190024
1.3054393340048203e-08,0.0017423999999999999,243.01465719459424,190.66177379336332,5.125391168190024
1.319224965171997e-08,0.0017607999999999999,243.12903772807684,190.66177379336332,5.125391168190024
1.3228212167808259e-08,0.0017656,243.1587993456971,190.66177379336332,5.125391168190024
1.3318118458028975e-08,0.0017775999999999998,243.23306566863846,190.66177379336332,5.125391168190024
1.3372062232161406e-08,0.0017848,243.27753161569458,190.66177379336332,5.125391168190024
1.3408024748249693e-08,0.0017896,243.30713672132273,190.66177379336332,5.125391168190024
1.3485943533107649e-08,0.0018,243.3711750874026,190.66177379336332,5.125391168190024
1.3545881059921461e-08,0.001808,243.42033722630373,190.66177379336332,5.125391168190024
1.370171862963737e-08,0.0018288,243.5477633820173,190.66177379336332,5.125391168190024
1.3881531210078806e-08,0.0018528,243.6940933139469,190.66177379336332,5.125391168190024
1.4121281317334053e-08,0.0018847999999999998,243.88805510702088,190.66177379336332,5.125391168190024
1.420519385487339e-08,0.001896,243.95563776343187,190.66177379336332,5.125391168190024
1.441497519872173e-08,0.001924,244.12391677943916,190.66177379336332,5.125391168190024
1.4600781531844547e-08,0.0019487999999999999,244.2721679218186,190.66177379336332,5.125391168190024
1.4768606606923219e-08,0.0019711999999999998,244.40544095111085,190.66177379336332,5.125391168190024
1.4822550381055652e-08,0.0019784,244.44815310259682,190.66177379336332,5.125391168190024
1.523012556338957e-08,0.0020328,244.76893043366022,190.66177379336332,5.125391168190024
1.543391315455653e-08,0.0020599999999999998,244.92806230467238,190.66177379336332,5.125391168190024
1.5649688251086255e-08,0.0020888,245.0956642826504,190.66177379336332,5.125391168190024
1.5703632025218684e-08,0.0020959999999999998,245.13742365982577,190.66177379336332,5.125391168190024
1.5961363390518075e-08,0.0021303999999999997,245.3361736175241,190.66177379336332,5.125391168190024
1.603928217537603e-08,0.0021408,245.39601390121157,190.66177379336332,5.125391168190024
1.6171144734366417e-08,0.0021584,245.497024437792,190.66177379336332,5.125391168190024
1.6374932325533374e-08,0.0021855999999999998,245.65250208137905,190.66177379336332,5.125391168190024
1.6422882346984426e-08,0.002192,245.68897516851482,190.66177379336332,5.125391168190024
1.669859497032796e-08,0.0022288,245.89789503289094,190.66177379336332,5.125391168190024
1.6872413798088015e-08,0.002252,246.02891422115337,190.66177379336332,5.125391168190024
1.6974307593671495e-08,0.0022656,246.10547384089395,190.66177379336332,5.125391168190024
1.701626386244116e-08,0.0022711999999999997,246.13694627009778,190.66177379336332,5.125391168190024
1.7118157658024644e-08,0.0022848,246.21325358025203,190.66177379336332,5.125391168190024
1.722005145360812e-08,0.0022984,246.2893839526413,190.66177379336332,5.125391168190024
1.7375889023324032e-08,0.0023192,246.40547969858667,190.66177379336332,5.125391168190024
1.740585778673094e-08,0.0023232,246.42775917389932,190.66177379336332,5.125391168190024
1.7699551668118614e-08,0.0023623999999999997,246.64531209400877,190.66177379336332,5.125391168190024
1.7777470452976573e-08,0.0023728,246.7027933325069,190.66177379336332,5.125391168190024
1.7843401732471763e-08,0.0023815999999999998,246.75135459989045,190.66177379336332,5.125391168190024
1.8185045635310492e-08,0.0024272,247.00187816775477,190.66177379336332,5.125391168190024
1.8418801989884356e-08,0.0024584,247.17223232894867,190.66177379336332,5.125391168190024
1.847873951669817e-08,0.0024664,247.21577680538573,190.66177379336332,5.125391168190024
1.852668953814922e-08,0.0024728,247.25057273927214,190.66177379336332,5.125391168190024
1.858662706496303e-08,0.0024808,247.2940183053904,190.66177379336332,5.125391168190024
1.8700508365909272e-08,0.002496,247.37641464451232,190.66177379336332,5.125391168190024
1.8772433398085845e-08,0.0025055999999999998,247.42835362498755,190.66177379336332,5.125391168190024
1.8856345935625183e-08,0.0025168,247.48885111371516,190.66177379336332,5.125391168190024
1.9012183505341094e-08,0.0025376,247.6009257628706,190.66177379336332,5.125391168190024
1.909010229019905e-08,0.002548,247.65682869429003,190.66177379336332,5.125391168190024
1.9227958601870816e-08,0.0025664,247.75551637374917,190.66177379336332,5.125391168190024
1.941376493499363e-08,0.0025911999999999997,247.88809470174218,190.66177379336332,5.125391168190024
1.9737427579788216e-08,0.0026344,248.11786181126388,190.66177379336332,5.125391168190024
1.9845315128053076e-08,0.0026487999999999998,248.19412368460777,190.66177379336332,5.125391168190024
1.9923233912911035e-08,0.0026592,248.2491011823344,190.66177379336332,5.125391168190024
2.0031121461175894e-08,0.0026736,248.32508563657748,190.66177379336332,5.125391168190024
2.0480652912279483e-08,0.0027336,248.6399846998822,190.66177379336332,5.125391168190024
2.0648477987358153e-08,0.0027559999999999998,248.7568545088749,190.66177379336332,5.125391168190024
2.0726396772216112e-08,0.0027664,248.81098950983016,190.66177379336332,5.125391168190024
2.10800281804176e-08,0.0028136,249.05568840277382,190.66177379336332,5.125391168190024
2.113996570723141e-08,0.0028216,249.09700361248878,190.66177379336332,5.125391168190024
2.12718282662218e-08,0.0028392,249.1877366053758,190.66177379336332,5.125391168190024
2.1355740803761134e-08,0.0028504,249.2453615915174,190.66177379336332,5.125391168190024
2.148760336275152e-08,0.002868,249.33573704892478,190.66177379336332,5.125391168190024
2.155353464224671e-08,0.0028767999999999997,249.3808436480128,190.66177379336332,5.125391168190024
2.1577509652972235e-08,0.0028799999999999997,249.39723270181935,190.66177379336332,5.125391168190024
2.169738470659986e-08,0.0028959999999999997,249.47907168365194,190.66177379336332,5.125391168190024
2.185921602899715e-08,0.0029176,249.5892751414278,190.66177379336332,5.125391168190024
2.1889184792404058e-08,0.0029216,249.6096482236936,190.66177379336332,5.125391168190024
2.2116947394296542e-08,0.0029519999999999998,249.76412972001566,190.66177379336332,5.125391168190024
2.2224834942561405e-08,0.0029663999999999997,249.83708850246722,190.66177379336332,5.125391168190024
2.240464752300284e-08,0.0029904,249.958380273432,190.66177379336332,5.125391168190024
2.2470578802498034e-08,0.0029992,250.00275872478602,190.66177379336332,5.125391168190024
2.2632410124895324e-08,0.0030207999999999997,250.11147289630995,190.66177379336332,5.125391168190024
2.271032890975328e-08,0.0030312,250.16370859553018,190.66177379336332,5.125391168190024
2.274629142584157e-08,0.003036,250.18779380104277,190.66177379336332,5.125391168190024
2.2842191468743667e-08,0.0030488,250.25194852180243,190.66177379336332,5.125391168190024
2.299802903845958e-08,0.0030696,250.35597635591972,190.66177379336332,5.125391168190024
2.307594782331753e-08,0.00308,250.40788715436335,190.66177379336332,5.125391168190024
2.3147872855494107e-08,0.0030896,250.45574417201806,190.66177379336332,5.125391168190024
2.3333679188616922e-08,0.0031144,250.57910715035095,190.66177379336332,5.125391168190024
2.3357654199342446e-08,0.0031176,250.59499700121515,190.66177379336332,5.125391168190024
2.3507498016376978e-08,0.0031376,250.6941648436721,190.66177379336332,5.125391168190024
2.3531473027102503e-08,0.0031408,250.7100087921563,190.66177379336332,5.125391168190024
2.362137931732322e-08,0.0031528,250.76936761244315,190.66177379336332,5.125391168190024
2.3741254370950842e-08,0.0031688,250.8483758247143,190.66177379336332,5.125391168190024
2.3789204392401894e-08,0.0031752,250.87993552802504,190.66177379336332,5.125391168190024
2.3921066951392278e-08,0.0031928,250.96659705001892,190.66177379336332,5.125391168190024
2.3998985736250233e-08,0.0032032,251.01771856097585,190.66177379336332,5.125391168190024
2.4154823305966145e-08,0.003224,251.11976780085104,190.66177379336332,5.125391168190024
2.4232742090824097e-08,0.0032343999999999997,251.17069610917258,190.66177379336332,5.125391168190024
2.4256717101549625e-08,0.0032375999999999998,251.18635350408098,190.66177379336332,5.125391168190024
2.444252343467244e-08,0.0032624,251.307494343533,190.66177379336332,5.125391168190024
2.4640317273158017e-08,0.0032887999999999997,251.436056741772,190.66177379336332,5.125391168190024
2.476019232678564e-08,0.0033047999999999997,251.51377748350615,190.66177379336332,5.125391168190024
2.4832117358962218e-08,0.0033144,251.5603394919281,190.66177379336332,5.125391168190024
2.490404239113879e-08,0.0033239999999999997,251.60684893275842,190.66177379336332,5.125391168190024
2.49639799179526e-08,0.003332,251.64556679652367,190.66177379336332,5.125391168190024
2.509584247694299e-08,0.0033496,251.73061871056728,190.66177379336332,5.125391168190024
2.516776750911956e-08,0.0033591999999999997,251.77693719703592,190.66177379336332,5.125391168190024
2.519773627252647e-08,0.0033632,251.7962213267628,190.66177379336332,5.125391168190024
2.5227705035933376e-08,0.0033672,251.81549651373427,190.66177379336332,5.125391168190024
2.5287642562747183e-08,0.0033751999999999996,251.85402011842152,190.66177379336332,5.125391168190024
2.5623292712904533e-08,0.00342,252.0690978168609,190.66177379336332,5.125391168190024
2.5689223992399723e-08,0.0034287999999999996,252.11121580558853,190.66177379336332,5.125391168190024
2.580310529334597e-08,0.003444,252.183865897887,190.66177379336332,5.125391168190024
2.6036861647919833e-08,0.0034752,252.33259917015482,190.66177379336332,5.125391168190024
2.6258630497130937e-08,0.0035047999999999998,252.47322442993843,190.66177379336332,5.125391168190024
2.6336549281988893e-08,0.0035152,252.52252324577,190.66177379336332,5.125391168190024
2.6546330625837232e-08,0.0035432,252.65496890852037,190.66177379336332,5.125391168190024
2.6654218174102095e-08,0.0035575999999999997,252.72292483689284,190.66177379336332,5.125391168190024
2.6708161948234526e-08,0.0035648,252.75686256702127,190.66177379336332,5.125391168190024
2.6774093227729717e-08,0.0035735999999999997,252.79830573293108,190.66177379336332,5.125391168190024
2.6863999517950438e-08,0.0035856,252.85475505610037,190.66177379336332,5.125391168190024
2.6911949539401483e-08,0.0035919999999999997,252.88483123315544,190.66177379336332,5.125391168190024
2.6965893313533914e-08,0.0035992,252.91864196243256,190.66177379336332,5.125391168190024
2.7211637173470544e-08,0.003632,253.07233604301157,190.66177379336332,5.125391168190024
2.7259587194921595e-08,0.0036384,253.10226191412545,190.66177379336332,5.125391168190024
2.7583249839716177e-08,0.0036815999999999997,253.3037272479306,190.66177379336332,5.125391168190024
2.7727099904069326e-08,0.0037007999999999997,253.39297123745826,190.66177379336332,5.125391168190024
2.7787037430883137e-08,0.0037088,253.43010291846008,190.66177379336332,5.125391168190024
2.7828993699652803e-08,0.0037143999999999996,253.4560765115303,190.66177379336332,5.125391168190024
2.8080731312270815e-08,0.003748,253.61159856582643,190.66177379336332,5.125391168190024
2.8176631355172915e-08,0.0037608,253.67070191754178,190.66177379336332,5.125391168190024
2.8242562634668105e-08,0.0037695999999999997,253.71128997100712,190.66177379336332,5.125391168190024
2.8326475172207444e-08,0.0037808,253.76289408910665,190.66177379336332,5.125391168190024
2.8470325236560593e-08,0.0038,253.85121980192895,190.66177379336332,5.125391168190024
2.8656131569683408e-08,0.0038247999999999997,253.96505001106095,190.66177379336332,5.125391168190024
2.8686100333090315e-08,0.0038288,253.98338273045863,190.66177379336332,5.125391168190024
2.8805975386717937e-08,0.0038447999999999998,254.05663903689197,190.66177379336332,5.125391168190024
2.8895881676938654e-08,0.0038567999999999996,254.11150326876532,190.66177379336332,5.125391168190024
2.9045725493973183e-08,0.0038767999999999997,254.20279594294414,190.66177379336332,5.125391168190024
2.9153613042238046e-08,0.0038912,254.26841297279753,190.66177379336332,5.125391168190024
2.927948184854705e-08,0.003908,254.34484660132105,190.66177379336332,5.125391168190024
2.938736939681191e-08,0.0039223999999999995,254.41025920273526,190.66177379336332,5.125391168190024
2.9441313170944344e-08,0.0039296,254.44293037757873,190.66177379336332,5.125391168190024
2.9507244450439534e-08,0.0039384,254.48283012625384,190.66177379336332,5.125391168190024
2.9555194471890586e-08,0.0039448,254.51182628997117,190.66177379336332,5.125391168190024
2.9621125751385776e-08,0.0039536,254.55166607610167,190.66177379336332,5.125391168190024
2.984289460059688e-08,0.0039832,254.68541955058475,190.66177379336332,5.125391168190024
3.2702461369208164e-08,0.004364872974594919,256.3767536134545,190.66177379336332,5.125391168190024
3.342185556981403e-08,0.004460892178435687,256.7930415807495,190.66177379336332,5.125391168190024
3.975252453514562e-08,0.0053058611722344474,260.3168087923923,190.66177379336332,5.125391168190024
4.291785901781141e-08,0.005728345669133827,261.99589823360407,190.66177379336332,5.125391168190024
4.593931466035603e-08,0.006131626325265053,263.5541394448948,190.66177379336332,5.125391168190024
5.212610478556645e-08,0.006957391478295659,266.6252378618078,190.66177379336332,5.125391168190024
5.5723075788595757e-08,0.0074374874974994995,268.34530412624764,190.66177379336332,5.125391168190024
5.9176167951503903e-08,0.007898379675935187,269.956257881245,190.66177379336332,5.125391168190024
6.07588351928368e-08,0.008109621924384877,270.68231480980205,190.66177379336332,5.125391168190024
6.219762359404853e-08,0.008301660332066413,271.3359906359255,190.66177379336332,5.125391168190024
6.579459459707784e-08,0.008781756351270254,272.94489227170726,190.66177379336332,5.125391168190024
6.723338299828957e-08,0.00897379475895179,273.57880124763375,190.66177379336332,5.125391168190024
7.154974820192474e-08,0.0095499099819964,275.449517822515,190.66177379336332,5.125391168190024
7.22691424025306e-08,0.009645929185837168,275.75697373442637,190.66177379336332,5.125391168190024
7.313241544325764e-08,0.00976115223044609,276.12434973072743,190.66177379336332,5.125391168190024
7.428344616422702e-08,0.009914782956591319,276.61156423862826,190.66177379336332,5.125391168190024
7.615387108580226e-08,0.010164432886577316,277.39705452484924,190.66177379336332,5.125391168190024
7.888756904810452e-08,0.010529305861172233,278.5316766240643,190.66177379336332,5.125391168190024
8.133350933016447e-08,0.010855771154230847,279.5339298888794,190.66177379336332,5.125391168190024
8.421108613258793e-08,0.01123984796959392,280.6981231384907,190.66177379336332,5.125391168190024
8.608151105416315e-08,0.011489497899579915,281.446536983252,190.66177379336332,5.125391168190024
9.341933190034296e-08,0.01246889377875575,284.32333871427215,190.66177379336332,5.125391168190024
9.457036262131233e-08,0.01262252450490098,284.7664769845324,190.66177379336332,5.125391168190024
9.644078754288757e-08,0.012872174434886977,285.4821164634476,190.66177379336332,5.125391168190024
1.0162042578724978e-07,0.013563512702540508,287.4361753167164,190.66177379336332,5.125391168190024
1.0406636606930972e-07,0.01388997799559912,288.3453849932555,190.66177379336332,5.125391168190024
1.0665618519149082e-07,0.014235647129425886,289.299039823404,190.66177379336332,5.125391168190024
1.0795109475258138e-07,0.014408481696339268,289.77247735015095,190.66177379336332,5.125391168190024
1.0953376199391428e-07,0.014619723944788958,290.3481260402948,190.66177379336332,5.125391168190024
1.1600830979936704e-07,0.015483896779355872,292.67004033177625,190.66177379336332,5.125391168190024
1.2075631152336574e-07,0.016117623524704944,294.3407702252691,190.66177379336332,5.125391168190024
1.2377776716591037e-07,0.01652090418083617,295.3906341175702,190.66177379336332,5.125391168190024
1.2536043440724324e-07,0.016732146429285857,295.9365712300794,190.66177379336332,5.125391168190024
1.282380112096667e-07,0.01711622324464893,296.9223465832747,190.66177379336332,5.125391168190024
1.4104322798045107e-07,0.018825365073014605,301.2084091686953,190.66177379336332,5.125391168190024
1.4521571434396506e-07,0.01938227645529106,302.5718314194255,190.66177379336332,5.125391168190024
1.4838104882663086e-07,0.01980476095219044,303.5959832032556,190.66177379336332,5.125391168190024
1.5226577750990249e-07,0.020323264652930585,304.8413242679551,190.66177379336332,5.125391168190024
1.5428008127159892e-07,0.020592118423684736,305.48217454976134,190.66177379336332,5.125391168190024
1.5543111199256829e-07,0.020745749149829965,305.84690952767414,190.66177379336332,5.125391168190024
1.6161790211777871e-07,0.021571514302860573,307.7896025343706,190.66177379336332,5.125391168190024
1.6420772123995983e-07,0.02191718343668734,308.59418547328033,190.66177379336332,5.125391168190024
1.6492711544056568e-07,0.022013202640528105,308.81680049480553,190.66177379336332,5.125391168190024
1.6521487312080802e-07,0.022051610322064413,308.90574042914955,190.66177379336332,5.125391168190024
1.6838020760347382e-07,0.022474094818963793,309.88012552299847,190.66177379336332,5.125391168190024
1.7097002672565492e-07,0.022819763952790558,310.6720469379964,190.66177379336332,5.125391168190024
1.7298433048735135e-07,0.02308861772354471,311.2847557691071,190.66177379336332,5.125391168190024
1.7730069569098652e-07,0.023664732946589318,312.5884113744475,190.66177379336332,5.125391168190024
1.8046603017365231e-07,0.024087217443488698,313.5365718548436,190.66177379336332,5.125391168190024
1.8132930321437936e-07,0.02420244048809762,313.79403258443637,190.66177379336332,5.125391168190024
1.8348748581619692e-07,0.024490498099619923,314.4356018197764,190.66177379336332,5.125391168190024
1.842068800168028e-07,0.024586517303460693,314.64880334671005,190.66177379336332,5.125391168190024
1.8794772985995328e-07,0.025085817163432687,315.75225996084157,190.66177379336332,5.125391168190024
1.8866712406055913e-07,0.025181836367273454,315.9634776177482,190.66177379336332,5.125391168190024
1.9197633738334612e-07,0.02562352470494099,316.9310616940012,190.66177379336332,5.125391168190024
1.9614882374686012e-07,0.026180436087217443,318.1418371490124,190.66177379336332,5.125391168190024
2.000335524301318e-07,0.026698939787957593,319.2601118607384,190.66177379336332,5.125391168190024
2.0492543299425164e-07,0.027351870374074817,320.6563336596789,190.66177379336332,5.125391168190024
2.0607646371522103e-07,0.027505501100220046,320.9829600558421,190.66177379336332,5.125391168190024
2.1024895007873502e-07,0.0280624124824965,322.1610628231942,190.66177379336332,5.125391168190024
2.1255101152067377e-07,0.028369673934786958,322.807146243227,190.66177379336332,5.125391168190024
2.141336787620067e-07,0.02858091618323665,323.2497463843106,190.66177379336332,5.125391168190024
2.160041036835819e-07,0.028830566113222645,323.77117781996003,190.66177379336332,5.125391168190024
2.1859392280576303e-07,0.02917623524704941,324.49026203033435,190.66177379336332,5.125391168190024
2.2219089380879234e-07,0.02965633126625325,325.48350228821306,190.66177379336332,5.125391168190024
2.2406131873036758e-07,0.02990598119623925,325.9975077917514,190.66177379336332,5.125391168190024
2.2564398597170048e-07,0.030117223444688937,326.4311298071365,190.66177379336332,5.125391168190024
2.2780216857351806e-07,0.030405281056211243,327.02052581840064,190.66177379336332,5.125391168190024
2.2996035117533564e-07,0.030693338667733546,327.6077480886189,190.66177379336332,5.125391168190024
2.362910201406672e-07,0.0315383076615323,329.3179923418064,190.66177379336332,5.125391168190024
2.407512641844236e-07,0.032133626725345074,330.5122224579638,190.66177379336332,5.125391168190024
2.41902294905393e-07,0.0322872574514903,330.8190062678993,190.66177379336332,5.125391168190024
2.4535538706830115e-07,0.03274814962992599,331.73595994829714,190.66177379336332,5.125391168190024
2.462186601090282e-07,0.03286337267453491,331.9644102621174,190.66177379336332,5.125391168190024
2.508227829929057e-07,0.033477895579115825,333.1775764768588,190.66177379336332,5.125391168190024
2.515421771935115e-07,0.03357391478295659,333.3663463216807,190.66177379336332,5.125391168190024
2.526932079144809e-07,0.03372754550910182,333.66794072179545,190.66177379336332,5.125391168190024
2.547075116761773e-07,0.03399639927985597,334.1944448853413,190.66177379336332,5.125391168190024
2.590238768798125e-07,0.03457251450290058,335.31723097048354,190.66177379336332,5.125391168190024
2.5988714992053954e-07,0.034687737547509506,335.5409099664979,190.66177379336332,5.125391168190024
2.6132593832175124e-07,0.03487977595519104,335.91306543381353,190.66177379336332,5.125391168190024
2.6305248440320534e-07,0.03511022204440888,336.3585988378157,190.66177379336332,5.125391168190024
2.647790304846594e-07,0.035340668133626726,336.80299322893006,190.66177379336332,5.125391168190024
2.675127284469617e-07,0.03570554110822165,337.50431337232504,190.66177379336332,5.125391168190024
2.6851988032780986e-07,0.03583996799359872,337.76198920202745,190.66177379336332,5.125391168190024
2.7168521481047566e-07,0.0362624524904981,338.56938450939475,190.66177379336332,5.125391168190024
2.729801243715663e-07,0.03643528705741149,338.8986242187066,190.66177379336332,5.125391168190024
2.820444912992001e-07,0.03764512902580516,341.18648354326217,190.66177379336332,5.125391168190024
2.834832797004118e-07,0.037837167433486696,341.54698190492263,190.66177379336332,5.125391168190024
2.846343104213812e-07,0.037990798159631925,341.8348670876044,190.66177379336332,5.125391168190024
2.879435237441681e-07,0.03843248649729945,342.66001870636643,190.66177379336332,5.125391168190024
2.921160101076822e-07,0.03898939787957592,343.6951747040681,190.66177379336332,5.125391168190024
2.9398643502925746e-07,0.03923904780956192,344.1573366153119,190.66177379336332,5.125391168190024
2.9556910227059036e-07,0.03945029005801161,344.5475017001866,190.66177379336332,5.125391168190024
2.993099521137408e-07,0.0399495899179836,345.466485365291,190.66177379336332,5.125391168190024
2.9988546747422547e-07,0.04002640528105621,345.60746890002935,190.66177379336332,5.125391168190024
3.0175589239580065e-07,0.0402760552110422,346.0649383650533,190.66177379336332,5.125391168190024
3.027630442766489e-07,0.04041048209641929,346.31080996125235,190.66177379336332,5.125391168190024
3.0765492484076877e-07,0.04106341268253651,347.50053571550063,190.66177379336332,5.125391168190024
3.106763804833134e-07,0.04146669333866773,348.23168157789735,190.66177379336332,5.125391168190024
3.17870322489372e-07,0.04242688537707541,349.9614325195471,190.66177379336332,5.125391168190024
3.1988462625106843e-07,0.042695739147829564,350.4430181357716,190.66177379336332,5.125391168190024
3.249203856553095e-07,0.043367873574714944,351.64183663620275,190.66177379336332,5.125391168190024
3.260714163762789e-07,0.04352150430086017,351.91483229041455,190.66177379336332,5.125391168190024
3.2851735665833886e-07,0.04384796959391879,352.49370331351747,190.66177379336332,5.125391168190024
3.298122662194293e-07,0.044020804160832164,352.79948383205067,190.66177379336332,5.125391168190024
3.3441638910330687e-07,0.04463532706541308,353.8829318346316,190.66177379336332,5.125391168190024
3.364306928650033e-07,0.044904180836167235,354.3551093334559,190.66177379336332,5.125391168190024
3.4060317922851727e-07,0.04546109221844369,355.3296983439696,190.66177379336332,5.125391168190024
3.417542099494867e-07,0.04561472294458892,355.59772965747294,190.66177379336332,5.125391168190024
3.421858464698502e-07,0.04567233446689338,355.6981506041888,190.66177379336332,5.125391168190024
3.447756655920313e-07,0.04601800360072014,356.2996421133425,190.66177379336332,5.125391168190024
3.4578281747287956e-07,0.046152430486097226,356.533079288323,190.66177379336332,5.125391168190024
3.490920307956665e-07,0.046594118823764755,357.29822690801177,190.66177379336332,5.125391168190024
3.509624557172417e-07,0.04684376875375075,357.7294502788566,190.66177379336332,5.125391168190024
3.5283288063881693e-07,0.047093418683736746,358.1597782896464,190.66177379336332,5.125391168190024
3.535522748394228e-07,0.04718943788757751,358.3250520512229,190.66177379336332,5.125391168190024
3.564298516418463e-07,0.04757351470294059,358.98483976592564,190.66177379336332,5.125391168190024
3.5844415540354276e-07,0.047842368473694746,359.4454556563861,190.66177379336332,5.125391168190024
3.6146561104608736e-07,0.04824564912982597,360.1344911866803,190.66177379336332,5.125391168190024
3.649187032089955e-07,0.04870654130826166,360.9192158215844,190.66177379336332,5.125391168190024
3.6621361277008595e-07,0.04887937587517503,361.2127402674532,190.66177379336332,5.125391168190024
3.7009834145335763e-07,0.04939787957591518,362.09089452426736,190.66177379336332,5.125391168190024
3.7153712985456934e-07,0.049589917983596715,362.4152236354235,190.66177379336332,5.125391168190024
3.739830701366293e-07,0.04991638327665533,362.9654612153601,190.66177379336332,5.125391168190024
3.782994353402645e-07,0.050492498499699945,363.93305717844146,190.66177379336332,5.125391168190024
3.808892544624456e-07,0.05083816763352671,364.51154822783485,190.66177379336332,5.125391168190024
3.8189640634329376e-07,0.05097259451890378,364.73610243798447,190.66177379336332,5.125391168190024
3.850617408259596e-07,0.05139507901580316,365.44034533650176,190.66177379336332,5.125391168190024
3.865005292271713e-07,0.051587117423484694,365.75970902090006,190.66177379336332,5.125391168190024
3.8707604458765605e-07,0.051663932786557315,365.88732463035444,190.66177379336332,5.125391168190024
3.919679251517759e-07,0.052316863372674535,366.96908576075316,190.66177379336332,5.125391168190024
3.9297507703262405e-07,0.052451290258051605,367.19114626086446,190.66177379336332,5.125391168190024
3.941261077535934e-07,0.052604920984196835,367.4446580887649,190.66177379336332,5.125391168190024
3.9542101731468403e-07,0.05277775555111022,367.72951400871295,190.66177379336332,5.125391168190024
4.0304659584110613e-07,0.053795559111822364,369.3996782307057,190.66177379336332,5.125391168190024
4.0606805148365074e-07,0.05419883976795359,370.0580269481066,190.66177379336332,5.125391168190024
4.098089013268012e-07,0.05469813962792558,370.8704844067617,190.66177379336332,5.125391168190024
4.1326199348970936e-07,0.05515903180636127,371.6178816360721,190.66177379336332,5.125391168190024
4.1585181261189053e-07,0.05550470094018804,372.17683226249636,190.66177379336332,5.125391168190024
4.1714672217298104e-07,0.05567753550710142,372.4557983607238,190.66177379336332,5.125391168190024
4.21319208536495e-07,0.05623444688937787,373.3524004202194,190.66177379336332,5.125391168190024
4.243406641790397e-07,0.05663772754550911,373.9995036091834,190.66177379336332,5.125391168190024
4.249161795395244e-07,0.05671454290858172,374.1225573595214,190.66177379336332,5.125391168190024
4.296641812635231e-07,0.05734826965393079,375.1352825052699,190.66177379336332,5.125391168190024
4.308152119844925e-07,0.05750190038007602,375.3801332046085,190.66177379336332,5.125391168190024
4.3139072734497713e-07,0.05757871574314863,375.5024628710111,190.66177379336332,5.125391168190024
4.3282951574618884e-07,0.05777075415083016,375.8080089083943,190.66177379336332,5.125391168190024
4.368581232695817e-07,0.05830846169233847,376.6614376480778,190.66177379336332,5.125391168190024
4.400234577522475e-07,0.058730946189237854,377.3298374292576,190.66177379336332,5.125391168190024
4.414622461534592e-07,0.05892298459691939,377.6330353540869,190.66177379336332,5.125391168190024
4.4635412671757906e-07,0.05957591518303661,378.66103782004757,190.66177379336332,5.125391168190024
4.505266130810931e-07,0.06013282656531306,379.5343959986426,190.66177379336332,5.125391168190024
4.5326031104339534e-07,0.06049769953990798,380.1048863131,190.66177379336332,5.125391168190024
4.5469909944460704e-07,0.060689737947589514,380.40460530676785,190.66177379336332,5.125391168190024
4.567134032063035e-07,0.06095859171834367,380.82359125782546,190.66177379336332,5.125391168190024
4.616052837704233e-07,0.06161152230446089,381.8381394294368,190.66177379336332,5.125391168190024
4.6764819505551263e-07,0.06241808361672335,383.08563407439254,190.66177379336332,5.125391168190024
4.6951861997708787e-07,0.06266773354670935,383.47048717817717,190.66177379336332,5.125391168190024
4.712451660585419e-07,0.06289817963592718,383.8252058292127,190.66177379336332,5.125391168190024
4.7469825822145006e-07,0.06335907181436287,384.5331262296444,190.66177379336332,5.125391168190024
4.7642480430290415e-07,0.06358951790358072,384.8863330930443,190.66177379336332,5.125391168190024
4.800217753059334e-07,0.06406961392278455,385.6205814105327,190.66177379336332,5.125391168190024
4.86352444271265e-07,0.06491458291658332,386.9076679728317,190.66177379336332,5.125391168190024
4.870718384718709e-07,0.06501060212042409,387.05351321091115,190.66177379336332,5.125391168190024
4.903810517946578e-07,0.06545229045809162,387.7233222231141,190.66177379336332,5.125391168190024
4.932586285970813e-07,0.0658363672734547,388.3043332199966,190.66177379336332,5.125391168190024
4.955606900390201e-07,0.06614362872574515,388.76819080678035,190.66177379336332,5.125391168190024
4.965678419198683e-07,0.06627805561112222,388.97086416359787,190.66177379336332,5.125391168190024
4.975749938007165e-07,0.0664124824964993,389.1733772673865,190.66177379336332,5.125391168190024
4.985821456815648e-07,0.06654690938187638,389.3757305688454,190.66177379336332,5.125391168190024
4.997331764025341e-07,0.06670054010802161,389.6067963837432,190.66177379336332,5.125391168190024
5.03042389725321e-07,0.06714222844568914,390.2699572344867,190.66177379336332,5.125391168190024
5.049128146468963e-07,0.06739187837567515,390.64403464543074,190.66177379336332,5.125391168190024
5.060638453678657e-07,0.06754550910182038,390.87396752273594,190.66177379336332,5.125391168190024
5.076465126091986e-07,0.06775675135027005,391.1897924774706,190.66177379336332,5.125391168190024
5.098046952110162e-07,0.06804480896179237,391.6198447148012,190.66177379336332,5.125391168190024
5.161353641763478e-07,0.06888977795559112,392.87725402560255,190.66177379336332,5.125391168190024
5.172863948973172e-07,0.06904340868173635,393.105226203192,190.66177379336332,5.125391168190024
5.216027601009523e-07,0.06961952390478096,393.95836563563563,190.66177379336332,5.125391168190024
5.226099119818005e-07,0.06975395079015803,394.15703479719946,190.66177379336332,5.125391168190024
5.328253096304038e-07,0.07111742348469695,396.16374095714104,190.66177379336332,5.125391168190024
5.372855536741601e-07,0.0717127425485097,397.03519648814483,190.66177379336332,5.125391168190024
5.449111322005823e-07,0.07273054610922185,398.51859717784527,190.66177379336332,5.125391168190024
5.495152550844597e-07,0.07334506901380276,399.41031612099204,190.66177379336332,5.125391168190024
5.533999837677314e-07,0.07386357271454291,400.1604398327816,190.66177379336332,5.125391168190024
5.53831620288095e-07,0.07392118423684738,400.24365995180176,190.66177379336332,5.125391168190024
5.558459240497914e-07,0.07419003800760153,400.631686544719,190.66177379336332,5.125391168190024
5.574285912911242e-07,0.07440128025605121,400.93617999598183,190.66177379336332,5.125391168190024
5.610255622941536e-07,0.07488137627525505,401.62695942848467,190.66177379336332,5.125391168190024
5.662052005385158e-07,0.07557271454290859,402.6186550623488,190.66177379336332,5.125391168190024
5.67212352419364e-07,0.07570714142828566,402.8110732293675,190.66177379336332,5.125391168190024
5.687950196606969e-07,0.07591838367673535,403.1131756391205,190.66177379336332,5.125391168190024
5.699460503816663e-07,0.07607201440288058,403.3326806100553,190.66177379336332,5.125391168190024
5.722481118236051e-07,0.07637927585517104,403.7711725789135,190.66177379336332,5.125391168190024
5.757012039865132e-07,0.07684016803360673,404.4276228243435,190.66177379336332,5.125391168190024
5.777155077482096e-07,0.07710902180436088,404.8098429918423,190.66177379336332,5.125391168190024
5.790104173093001e-07,0.07728185637127426,405.0552815280481,190.66177379336332,5.125391168190024
5.818879941117236e-07,0.07766593318663734,405.5999353665577,190.66177379336332,5.125391168190024
5.843339343937835e-07,0.07799239847969594,406.06206572711784,190.66177379336332,5.125391168190024
5.87211511196207e-07,0.07837647529505902,406.60478375027753,190.66177379336332,5.125391168190024
5.93110543641175e-07,0.07916383276655331,407.71412384455056,190.66177379336332,5.125391168190024
5.946932108825079e-07,0.079375075015003,408.0110185144402,190.66177379336332,5.125391168190024
5.977146665250525e-07,0.07977835567113423,408.5769631360596,190.66177379336332,5.125391168190024
6.008800010077184e-07,0.08020084016803361,409.16866211244087,190.66177379336332,5.125391168190024
6.043330931706265e-07,0.0806617323464693,409.8127672188301,190.66177379336332,5.125391168190024
6.05628002731717e-07,0.08083456691338269,410.0539363852968,190.66177379336332,5.125391168190024
6.0721066997305e-07,0.08104580916183238,410.34842576978235,190.66177379336332,5.125391168190024
6.083617006940194e-07,0.0811994398879776,410.5624118772996,190.66177379336332,5.125391168190024
6.125341870575333e-07,0.08175635127025406,411.336791411589,190.66177379336332,5.125391168190024
6.165627945809262e-07,0.08229405881176236,412.0825185189945,190.66177379336332,5.125391168190024
6.198720079037131e-07,0.08273574714942988,412.693659514824,190.66177379336332,5.125391168190024
6.234689789067425e-07,0.08321584316863373,413.3565018153749,190.66177379336332,5.125391168190024
6.269220710696506e-07,0.08367673534706942,413.99142872452325,190.66177379336332,5.125391168190024
6.277853441103776e-07,0.08379195839167834,414.1499471625426,190.66177379336332,5.125391168190024
6.310945574331645e-07,0.08423364672934587,414.75681525880344,190.66177379336332,5.125391168190024
6.344037707559516e-07,0.08467533506701341,415.36244356649803,190.66177379336332,5.125391168190024
6.378568629188597e-07,0.0851362272454491,415.9930914353272,190.66177379336332,5.125391168190024
6.390078936398291e-07,0.08528985797159433,416.2030113225916,190.66177379336332,5.125391168190024
6.449069260847971e-07,0.08607721544308862,417.2765449158263,190.66177379336332,5.125391168190024
6.483600182477053e-07,0.08653810762152431,417.9031778389945,190.66177379336332,5.125391168190024
6.490794124483112e-07,0.08663412682536507,418.03356238732357,190.66177379336332,5.125391168190024
6.523886257710982e-07,0.08707581516303262,418.6326069057636,190.66177379336332,5.125391168190024
6.535396564920675e-07,0.08722944588917785,418.84069228021565,190.66177379336332,5.125391168190024
6.574243851753391e-07,0.08774794958991798,419.5419275979339,190.66177379336332,5.125391168190024
6.659132367424883e-07,0.08888097619523905,421.06865726800714,190.66177379336332,5.125391168190024
6.695102077455176e-07,0.0893610722144429,421.7132849648528,190.66177379336332,5.125391168190024
6.705173596263658e-07,0.08949549909981996,421.89353849669,190.66177379336332,5.125391168190024
6.718122691874564e-07,0.08966833366673335,422.12513795737823,190.66177379336332,5.125391168190024
6.775674227923034e-07,0.0904364872974595,423.15236975752936,190.66177379336332,5.125391168190024
6.787184535132727e-07,0.09059011802360473,423.357407168111,190.66177379336332,5.125391168190024
6.810205149552114e-07,0.09089737947589518,423.76707560942157,190.66177379336332,5.125391168190024
6.919553068044205e-07,0.09235687137427485,425.7056730318302,190.66177379336332,5.125391168190024
6.941134894062381e-07,0.09264492898579717,426.0868752016246,190.66177379336332,5.125391168190024
6.952645201272075e-07,0.0927985597119424,426.2899940036187,190.66177379336332,5.125391168190024
6.978543392493886e-07,0.09314422884576916,426.7465324224608,190.66177379336332,5.125391168190024
7.008757948919332e-07,0.09354750950190038,427.2783262854114,190.66177379336332,5.125391168190024
7.03177856333872e-07,0.09385477095419084,427.68290266193395,190.66177379336332,5.125391168190024
7.050482812554472e-07,0.09410442088417684,428.01124074759997,190.66177379336332,5.125391168190024
7.089330099387189e-07,0.09462292458491699,428.69209022466896,190.66177379336332,5.125391168190024
7.10659556020173e-07,0.09485337067413484,428.9942227851767,190.66177379336332,5.125391168190024
7.139687693429599e-07,0.09529505901180237,429.5725112241202,190.66177379336332,5.125391168190024
7.142565270232023e-07,0.09533346669333867,429.62274772161794,190.66177379336332,5.125391168190024
7.16558588465141e-07,0.09564072814562913,430.02435593694133,190.66177379336332,5.125391168190024
7.179973768663528e-07,0.09583276655331066,430.27510556222484,190.66177379336332,5.125391168190024
7.202994383082915e-07,0.09614002800560112,430.67589774050555,190.66177379336332,5.125391168190024
7.223137420699879e-07,0.09640888177635527,431.0261812799403,190.66177379336332,5.125391168190024
7.259107130730173e-07,0.09688897779555912,431.6507415229298,190.66177379336332,5.125391168190024
7.293638052359254e-07,0.09734986997399481,432.24918483581376,190.66177379336332,5.125391168190024
7.296515629161677e-07,0.09738827765553111,432.2990051802615,190.66177379336332,5.125391168190024
7.313781089976217e-07,0.09761872374474895,432.59776648907956,190.66177379336332,5.125391168190024
7.342556858000453e-07,0.09800280056011203,433.09509148758434,190.66177379336332,5.125391168190024
7.37421020282711e-07,0.09842528505701141,433.64127186940436,190.66177379336332,5.125391168190024
7.402985970851345e-07,0.09880936187237448,434.13700657687997,190.66177379336332,5.125391168190024
7.417373854863462e-07,0.09900140028005601,434.3845920742734,190.66177379336332,5.125391168190024
7.43176173887558e-07,0.09919343868773756,434.6319903428768,190.66177379336332,5.125391168190024
7.450465988091332e-07,0.09944308861772355,434.9533290129861,190.66177379336332,5.125391168190024
7.470609025708296e-07,0.0997119423884777,435.2990343938902,190.66177379336332,5.125391168190024
7.487874486522837e-07,0.09994238847769554,435.5950640520903,190.66177379336332,5.125391168190024