File: datasets/aisi_316_L/data/M1/valid_3.csv
Time(s),Strain(%),Stress(MPa),Temp(C),Log_SR(s-1)
0.0,0.0,0.0,219.87218666073008,5.713204692732111
2.322611399860033e-11,1.2e-05,2.211805125,219.87218666073008,5.713204692732111
3.096815199813377e-11,1.6e-05,2.9490735,219.87218666073008,5.713204692732111
4.954904319701403e-11,2.56e-05,4.7185176,219.87218666073008,5.713204692732111
7.277515719561436e-11,3.76e-05,6.930322725,219.87218666073008,5.713204692732111
1.1613056999300164e-10,5.9999999999999995e-05,11.059025624999999,219.87218666073008,5.713204692732111
1.5948598279038892e-10,8.24e-05,15.187728524999999,219.87218666073008,5.713204692732111
1.7342165118954912e-10,8.96e-05,16.514811599999998,219.87218666073008,5.713204692732111
2.167770639869364e-10,0.000112,20.6435145,219.87218666073008,5.713204692732111
2.369063627857233e-10,0.0001224,22.560412274999997,219.87218666073008,5.713204692732111
2.4464840078525676e-10,0.00012639999999999998,23.297680649999997,219.87218666073008,5.713204692732111
2.849069983828307e-10,0.0001472,27.1314762,219.87218666073008,5.713204692732111
3.1587515038096445e-10,0.00016319999999999998,30.080549699999995,219.87218666073008,5.713204692732111
3.344560415798447e-10,0.0001728,31.8499938,219.87218666073008,5.713204692732111
3.793598619771387e-10,0.000196,36.126150375,219.87218666073008,5.713204692732111
4.0723119877545906e-10,0.0002104,38.780316524999996,219.87218666073008,5.713204692732111
4.258120899743393e-10,0.00021999999999999998,40.549760625,219.87218666073008,5.713204692732111
4.428445735733129e-10,0.00022879999999999998,42.17175105,219.87218666073008,5.713204692732111
4.707159103716333e-10,0.0002432,44.8259172,219.87218666073008,5.713204692732111
5.202649535686473e-10,0.0002688,49.5444348,219.87218666073008,5.713204692732111
5.744592195653815e-10,0.0002968,54.705313425,219.87218666073008,5.713204692732111
6.751057135593162e-10,0.00034879999999999997,64.28980229999999,219.87218666073008,5.713204692732111
7.323967947558636e-10,0.0003784,69.745588275,219.87218666073008,5.713204692732111
7.664617619538108e-10,0.000396,72.98956912499999,219.87218666073008,5.713204692732111
7.726553923534376e-10,0.0003992,73.579383825,219.87218666073008,5.713204692732111
8.05171951951478e-10,0.000416,76.675911,219.87218666073008,5.713204692732111
8.144623975509181e-10,0.0004208,77.56063304999999,219.87218666073008,5.713204692732111
8.733018863473723e-10,0.00045119999999999996,83.1638727,219.87218666073008,5.713204692732111
8.965280003459726e-10,0.0004632,85.375677825,219.87218666073008,5.713204692732111
9.367865979435465e-10,0.000484,89.209473375,219.87218666073008,5.713204692732111
9.60012711942147e-10,0.000496,91.4212785,219.87218666073008,5.713204692732111
1.0049165323394408e-09,0.0005191999999999999,95.69743507499999,219.87218666073008,5.713204692732111
1.0606592059360816e-09,0.000548,101.00576737499999,219.87218666073008,5.713204692732111
1.0885305427344022e-09,0.0005624,103.659933525,219.87218666073008,5.713204692732111
1.1148534719328157e-09,0.000576,106.166646,219.87218666073008,5.713204692732111
1.1597572923301095e-09,0.0005991999999999999,110.44280257499999,219.87218666073008,5.713204692732111
1.1891770367283368e-09,0.0006144,113.24442239999999,219.87218666073008,5.713204692732111
1.2495649331246975e-09,0.0006456,118.99511572499999,219.87218666073008,5.713204692732111
1.2650490091237645e-09,0.0006536,120.46965247499999,219.87218666073008,5.713204692732111
1.2758878623231113e-09,0.0006592,121.50182819999999,219.87218666073008,5.713204692732111
1.2836299003226447e-09,0.0006632,122.23909657499999,219.87218666073008,5.713204692732111
1.2944687535219915e-09,0.0006688,123.27127229999999,219.87218666073008,5.713204692732111
1.3053076067213386e-09,0.0006744,124.30344802500001,219.87218666073008,5.713204692732111
1.3471146119188191e-09,0.000696,128.28469725,219.87218666073008,5.713204692732111
1.3734375411172327e-09,0.0007096,130.791409725,219.87218666073008,5.713204692732111
1.4291802147138735e-09,0.0007384,136.09974202499998,219.87218666073008,5.713204692732111
1.4678904047115406e-09,0.0007584,139.7860839,219.87218666073008,5.713204692732111
1.4802776655107942e-09,0.0007647999999999999,140.96571329999998,219.87218666073008,5.713204692732111
1.5251814859080882e-09,0.000788,145.241869875,219.87218666073008,5.713204692732111
1.5576980455061286e-09,0.0008047999999999999,148.33839705,219.87218666073008,5.713204692732111
1.5685368987054755e-09,0.0008104,149.370572775,219.87218666073008,5.713204692732111
1.5886661975042624e-09,0.0008208,151.28747055,219.87218666073008,5.713204692732111
1.6041502735033294e-09,0.0008288,152.7620073,219.87218666073008,5.713204692732111
1.6382152407012763e-09,0.0008464,156.00598815,219.87218666073008,5.713204692732111
1.7016999522974507e-09,0.0008792,162.051588825,219.87218666073008,5.713204692732111
1.729571289095771e-09,0.0008935999999999999,164.705754975,219.87218666073008,5.713204692732111
1.7822171474925984e-09,0.0009207999999999999,169.719179925,219.87218666073008,5.713204692732111
1.839508228689146e-09,0.0009504,175.1749659,219.87218666073008,5.713204692732111
1.887508864286253e-09,0.0009752,179.746029825,219.87218666073008,5.713204692732111
1.8983477174856e-09,0.0009808,180.77820555,219.87218666073008,5.713204692732111
1.977316505080841e-09,0.0010216,188.29834297499997,219.87218666073008,5.713204692732111
2.0005426190794413e-09,0.0010336,190.51014809999998,219.87218666073008,5.713204692732111
2.019123510278322e-09,0.0010432,192.2795922,219.87218666073008,5.713204692732111
2.0438980318768286e-09,0.0010559999999999999,194.638851,219.87218666073008,5.713204692732111
2.0609305154758023e-09,0.0010647999999999999,196.26084142499997,219.87218666073008,5.713204692732111
2.096543890273656e-09,0.0010831999999999999,199.65227595,219.87218666073008,5.713204692732111
2.1584801942699237e-09,0.0011152,205.55042295,219.87218666073008,5.713204692732111
2.1770610854688043e-09,0.0011248,207.31986705,219.87218666073008,5.713204692732111
2.226610128665818e-09,0.0011504,212.03838465,219.87218666073008,5.713204692732111
2.2746107642629253e-09,0.0011752,216.609448575,219.87218666073008,5.713204692732111
2.291643247861899e-09,0.001184,218.231439,219.87218666073008,5.713204692732111
2.3055789162610592e-09,0.0011912,219.55852207499998,219.87218666073008,5.713204692732111
2.3086757314608727e-09,0.0011928,219.853429425,219.87218666073008,5.713204692732111
2.3288050302596594e-09,0.0012032,221.7703272,219.87218666073008,5.713204692732111
2.3675152202573267e-09,0.0012232,225.456669075,219.87218666073008,5.713204692732111
2.3891929266560203e-09,0.0012343999999999999,227.52102052499998,219.87218666073008,5.713204692732111
2.4077738178549005e-09,0.0012439999999999999,229.29046462499997,219.87218666073008,5.713204692732111
2.5223559802479956e-09,0.0013032,232.39988673375012,219.87218666073008,5.713204692732111
2.534743241047249e-09,0.0013096,232.44305657324733,219.87218666073008,5.713204692732111
2.6864871858381044e-09,0.001388,232.96538011419818,219.87218666073008,5.713204692732111
2.709713299836705e-09,0.0014,233.0443005405454,219.87218666073008,5.713204692732111
2.773198011432879e-09,0.0014328,233.25868165683022,219.87218666073008,5.713204692732111
2.82894068502952e-09,0.0014616,233.44534548503745,219.87218666073008,5.713204692732111
2.83823113062896e-09,0.0014663999999999999,233.47631613034432,219.87218666073008,5.713204692732111
2.8661024674272804e-09,0.0014808,233.56899171006145,219.87218666073008,5.713204692732111
2.8769413206266272e-09,0.0014864,233.60493721069813,219.87218666073008,5.713204692732111
2.892425396625694e-09,0.0014944,233.65619644244134,219.87218666073008,5.713204692732111
2.9094578802246677e-09,0.0015032,233.71245814947466,219.87218666073008,5.713204692732111
2.932683994223268e-09,0.0015152,233.78897208614143,219.87218666073008,5.713204692732111
2.9388776246228943e-09,0.0015183999999999998,233.8093358432703,219.87218666073008,5.713204692732111
2.971394184220935e-09,0.0015352,233.91597221550637,219.87218666073008,5.713204692732111
2.989975075419816e-09,0.0015448,233.97670294035518,219.87218666073008,5.713204692732111
3.0039107438189756e-09,0.001552,234.022154438908,219.87218666073008,5.713204692732111
3.0286852654174827e-09,0.0015647999999999999,234.10275457526916,219.87218666073008,5.713204692732111
3.036427303417016e-09,0.0015688,234.12788933264005,219.87218666073008,5.713204692732111
3.1386222050108574e-09,0.0016216,234.4573599557232,219.87218666073008,5.713204692732111
3.1448158354104843e-09,0.0016248,234.47719233661547,219.87218666073008,5.713204692732111
3.161848319009458e-09,0.0016336,234.53165299324957,219.87218666073008,5.713204692732111
3.1773323950085248e-09,0.0016416,234.58106347622984,219.87218666073008,5.713204692732111
3.220687807805912e-09,0.001664,234.7189157180101,219.87218666073008,5.713204692732111
3.2532043674039525e-09,0.0016807999999999999,234.8218304485344,219.87218666073008,5.713204692732111
3.2779788890024596e-09,0.0016936,234.89997262526276,219.87218666073008,5.713204692732111
3.3073986334006866e-09,0.0017088,234.99246793408258,219.87218666073008,5.713204692732111
3.339915192998727e-09,0.0017255999999999999,235.0943270750155,219.87218666073008,5.713204692732111
3.3430120081985405e-09,0.0017272,235.1040077305278,219.87218666073008,5.713204692732111
3.3848190133960213e-09,0.0017488,235.23435615516743,219.87218666073008,5.713204692732111
3.3972062741952746e-09,0.0017552,235.27285713096308,219.87218666073008,5.713204692732111
3.415787165394155e-09,0.0017648,235.3305060961476,219.87218666073008,5.713204692732111
3.428174426193408e-09,0.0017712,235.36887080903617,219.87218666073008,5.713204692732111
3.483917099790049e-09,0.0018,235.54084732331293,219.87218666073008,5.713204692732111
3.493207545389489e-09,0.0018047999999999999,235.5694054212603,219.87218666073008,5.713204692732111
3.5117884365883693e-09,0.0018143999999999999,235.62643290790817,219.87218666073008,5.713204692732111
3.5427565885865032e-09,0.0018303999999999998,235.72121791015618,219.87218666073008,5.713204692732111
3.5721763329847302e-09,0.0018456,235.8109648073323,219.87218666073008,5.713204692732111
3.5954024469833304e-09,0.0018575999999999998,235.88161416090378,219.87218666073008,5.713204692732111
3.6015960773829573e-09,0.0018608,235.90042389931176,219.87218666073008,5.713204692732111
3.6310158217811843e-09,0.0018759999999999998,235.98959844878152,219.87218666073008,5.713204692732111
3.637209452180811e-09,0.0018792,236.00833608221245,219.87218666073008,5.713204692732111
3.700694163776985e-09,0.0019119999999999999,236.19968477486037,219.87218666073008,5.713204692732111
3.730113908175213e-09,0.0019272,236.28792405276647,219.87218666073008,5.713204692732111
3.8261151793694275e-09,0.0019768,236.57399306399657,219.87218666073008,5.713204692732111
3.843147662968401e-09,0.0019856,236.62445347141457,219.87218666073008,5.713204692732111
3.852438108567841e-09,0.0019904,236.65194056606268,219.87218666073008,5.713204692732111
3.8895998909656014e-09,0.0020096,236.76163140700334,219.87218666073008,5.713204692732111
3.894245113765321e-09,0.002012,236.77531396587247,219.87218666073008,5.713204692732111
3.901987151764855e-09,0.002016,236.79810409415327,219.87218666073008,5.713204692732111
3.923664858163549e-09,0.0020272,236.86182282486996,219.87218666073008,5.713204692732111
3.939148934162616e-09,0.0020352,236.9072521748104,219.87218666073008,5.713204692732111
3.9453425645622425e-09,0.0020384,236.92540440805885,219.87218666073008,5.713204692732111
3.97940753176019e-09,0.002056,237.02504374250978,219.87218666073008,5.713204692732111
3.99798842295907e-09,0.0020656,237.07925224344945,219.87218666073008,5.713204692732111
4.0088272761584165e-09,0.0020712,237.11082849433961,219.87218666073008,5.713204692732111
4.041343835756457e-09,0.002088,237.20535807428354,219.87218666073008,5.713204692732111
4.061473134555244e-09,0.0020984,237.2637277566283,219.87218666073008,5.713204692732111
4.095538101753191e-09,0.002116,237.3622508497977,219.87218666073008,5.713204692732111
4.1296030689511376e-09,0.0021336,237.4604548616176,219.87218666073008,5.713204692732111
4.149732367749925e-09,0.002144,237.51833600937042,219.87218666073008,5.713204692732111
4.174506889348433e-09,0.0021568,237.5894242458679,219.87218666073008,5.713204692732111
4.197733003347032e-09,0.0021688,237.6559201811438,219.87218666073008,5.713204692732111
4.26895975294274e-09,0.0022056,237.85895195702753,219.87218666073008,5.713204692732111
4.315411980939941e-09,0.0022296,237.99065259210485,219.87218666073008,5.713204692732111
4.337089687338634e-09,0.0022408,238.05192356958878,219.87218666073008,5.713204692732111
4.3711546545365815e-09,0.0022584,238.14796577661772,219.87218666073008,5.713204692732111
4.414510067333969e-09,0.0022808,238.2697801875891,219.87218666073008,5.713204692732111
4.4253489205333156e-09,0.0022864,238.30016077761795,219.87218666073008,5.713204692732111
4.437736181332569e-09,0.0022928,238.33484593997892,219.87218666073008,5.713204692732111
4.447026626932009e-09,0.0022976,238.36083503775816,219.87218666073008,5.713204692732111
4.4872852245295835e-09,0.0023184,238.47321065740664,219.87218666073008,5.713204692732111
4.504317708128556e-09,0.0023271999999999998,238.52063574434706,219.87218666073008,5.713204692732111
4.532189044926878e-09,0.0023416,238.5980898493296,219.87218666073008,5.713204692732111
4.536834267726597e-09,0.0023439999999999997,238.61098078524958,219.87218666073008,5.713204692732111
4.578641272924078e-09,0.0023656,238.72676848798832,219.87218666073008,5.713204692732111
4.618899870521651e-09,0.0023864,238.83787868256155,219.87218666073008,5.713204692732111
4.649868022519786e-09,0.0024024,238.92309124745225,219.87218666073008,5.713204692732111
4.6730941365183855e-09,0.0024143999999999997,238.9868554980461,219.87218666073008,5.713204692732111
4.705610696116426e-09,0.0024311999999999997,239.07591819346143,219.87218666073008,5.713204692732111
4.7412240709142794e-09,0.0024495999999999997,239.17318810386533,219.87218666073008,5.713204692732111
4.767547000112694e-09,0.0024632,239.24490021303788,219.87218666073008,5.713204692732111
4.7938699293111075e-09,0.0024768,239.31645806997344,219.87218666073008,5.713204692732111
4.821741266109428e-09,0.0024912,239.39205838977063,219.87218666073008,5.713204692732111
4.889871200505322e-09,0.0025264,239.57614524138285,219.87218666073008,5.713204692732111
4.911548906904016e-09,0.0025376,239.6345082004003,219.87218666073008,5.713204692732111
4.96109795010103e-09,0.0025632,239.76753331702045,219.87218666073008,5.713204692732111
4.9703883957004704e-09,0.002568,239.7924177365154,219.87218666073008,5.713204692732111
5.088067373293378e-09,0.0026287999999999997,240.10606647060845,219.87218666073008,5.713204692732111
5.097357818892818e-09,0.0026336,240.130707065914,219.87218666073008,5.713204692732111
5.129874378490859e-09,0.0026504,240.21681155868907,219.87218666073008,5.713204692732111
5.1469068620898326e-09,0.0026592,240.26182894806004,219.87218666073008,5.713204692732111
5.1561973076892725e-09,0.0026639999999999997,240.2863593979662,219.87218666073008,5.713204692732111
5.170132976088433e-09,0.0026712,240.3231227770973,219.87218666073008,5.713204692732111
5.2103915736860066e-09,0.002692,240.42911163146232,219.87218666073008,5.713204692732111
5.354393480477329e-09,0.0027664,240.80563884137172,219.87218666073008,5.713204692732111
5.3869100400753695e-09,0.0027832,240.8901120936975,219.87218666073008,5.713204692732111
5.459685197270984e-09,0.0028208,241.07845400434562,219.87218666073008,5.713204692732111
5.46587882767061e-09,0.0028239999999999997,241.09443775451265,219.87218666073008,5.713204692732111
5.489104941669211e-09,0.002836,241.15431401155678,219.87218666073008,5.713204692732111
5.527815131666878e-09,0.002856,241.2538886647087,219.87218666073008,5.713204692732111
5.554138060865292e-09,0.0028696,241.3214441421974,219.87218666073008,5.713204692732111
5.588203028063239e-09,0.0028872,241.40868381321351,219.87218666073008,5.713204692732111
5.643945701659879e-09,0.0029159999999999998,241.55099359218136,219.87218666073008,5.713204692732111
5.673365446058106e-09,0.0029311999999999997,241.62588048009053,219.87218666073008,5.713204692732111
5.682655891657547e-09,0.002936,241.64949748638628,219.87218666073008,5.713204692732111
5.6950431524568004e-09,0.0029424,241.68096341752062,219.87218666073008,5.713204692732111
5.730656527254654e-09,0.0029608,241.77127962864552,219.87218666073008,5.713204692732111
5.766269902052508e-09,0.0029792,241.86137720651683,219.87218666073008,5.713204692732111
5.775560347651947e-09,0.0029839999999999997,241.88484519877304,219.87218666073008,5.713204692732111
5.791044423651015e-09,0.002992,241.92392582889633,219.87218666073008,5.713204692732111
5.8158189452495216e-09,0.0030047999999999997,241.98637017870774,219.87218666073008,5.713204692732111
5.823560983249055e-09,0.0030088,242.00586275169337,219.87218666073008,5.713204692732111
5.851432320047376e-09,0.0030231999999999998,242.07595248794803,219.87218666073008,5.713204692732111
5.904078178444203e-09,0.0030504,242.20798999261802,219.87218666073008,5.713204692732111
5.9288527000427105e-09,0.0030632,242.26996633377078,219.87218666073008,5.713204692732111
5.9334979228424305e-09,0.0030656,242.28157564495098,219.87218666073008,5.713204692732111
5.993885819238791e-09,0.0030968,242.43217557654842,219.87218666073008,5.713204692732111
6.024853971236925e-09,0.0031127999999999998,242.50917669955805,219.87218666073008,5.713204692732111
6.043434862435806e-09,0.0031224,242.55530328474657,219.87218666073008,5.713204692732111
6.065112568834498e-09,0.0031336,242.60904778756623,219.87218666073008,5.713204692732111
6.077499829633752e-09,0.00314,242.63972529591243,219.87218666073008,5.713204692732111
6.105371166432073e-09,0.0031544,242.7086606697945,219.87218666073008,5.713204692732111
6.1162100196314195e-09,0.00316,242.73543571253106,219.87218666073008,5.713204692732111
6.14408135642974e-09,0.0031744,242.80420098779777,219.87218666073008,5.713204692732111
6.1765979160277805e-09,0.0031912,242.8842735711679,219.87218666073008,5.713204692732111
6.212211290825634e-09,0.0032096,242.97178371884308,219.87218666073008,5.713204692732111
6.229243774424608e-09,0.0032183999999999997,243.01356721606123,219.87218666073008,5.713204692732111
6.2369858124241414e-09,0.0032224,243.0325449830054,219.87218666073008,5.713204692732111
6.3004705240203154e-09,0.0032551999999999998,243.1878176349145,219.87218666073008,5.713204692732111
6.340729121617889e-09,0.003276,243.28596713669393,219.87218666073008,5.713204692732111
6.348471159617423e-09,0.00328,243.30481414609878,219.87218666073008,5.713204692732111
6.3670520508163024e-09,0.0032895999999999997,243.3500104338369,219.87218666073008,5.713204692732111
6.379439311615556e-09,0.003296,243.38011271825962,219.87218666073008,5.713204692732111
6.399568610414343e-09,0.0033063999999999997,243.42898035670098,219.87218666073008,5.713204692732111
6.447569246011451e-09,0.0033312,243.54526959834826,219.87218666073008,5.713204692732111
6.467698544810238e-09,0.0033415999999999997,243.59393551435957,219.87218666073008,5.713204692732111
6.507957142407811e-09,0.0033623999999999998,243.69109049740973,219.87218666073008,5.713204692732111
6.517247588007252e-09,0.0033672,243.71347755823808,219.87218666073008,5.713204692732111
6.554409370405012e-09,0.0033864,243.80290162059498,219.87218666073008,5.713204692732111
6.582280707203333e-09,0.0034008,243.86983996185785,219.87218666073008,5.713204692732111
6.636474973200066e-09,0.0034287999999999996,243.99968225174044,219.87218666073008,5.713204692732111
6.684475608797174e-09,0.0034536,244.11434048757576,219.87218666073008,5.713204692732111
6.732476244394282e-09,0.0034784,244.2286780625382,219.87218666073008,5.713204692732111
6.757250765992789e-09,0.0034912,244.2875665865003,219.87218666073008,5.713204692732111
6.764992803992322e-09,0.0034952,244.30595197408212,219.87218666073008,5.713204692732111
6.802154586390083e-09,0.0035144,244.39408786338782,219.87218666073008,5.713204692732111
6.8439615915875625e-09,0.0035359999999999996,244.4930165820374,219.87218666073008,5.713204692732111
6.88731700438495e-09,0.0035583999999999998,244.59536070943938,219.87218666073008,5.713204692732111
6.922930379182804e-09,0.0035767999999999998,244.6792412682259,219.87218666073008,5.713204692732111
6.980221460379351e-09,0.0036063999999999996,244.81382730467337,219.87218666073008,5.713204692732111
7.105642475971793e-09,0.0036712,245.10696681351106,219.87218666073008,5.713204692732111
7.130416997570301e-09,0.0036839999999999998,245.16463149116143,219.87218666073008,5.713204692732111
7.190804893966661e-09,0.0037151999999999997,245.30486275967863,219.87218666073008,5.713204692732111
7.2527411979629295e-09,0.0037472,245.44821342244032,219.87218666073008,5.713204692732111
7.283709349961063e-09,0.0037632,245.51970966101206,219.87218666073008,5.713204692732111
7.34564565395733e-09,0.0037952,245.66234747078994,219.87218666073008,5.713204692732111
7.3750653983555575e-09,0.0038104,245.72993604996853,219.87218666073008,5.713204692732111
7.440098517551638e-09,0.0038439999999999998,245.87897037787747,219.87218666073008,5.713204692732111
7.488099153148746e-09,0.0038688,245.98864622792834,219.87218666073008,5.713204692732111
7.531454565946133e-09,0.0038912,246.08747283920576,219.87218666073008,5.713204692732111
7.590294054742588e-09,0.0039216,246.2212405182475,219.87218666073008,5.713204692732111
7.613520168741188e-09,0.0039336,246.27393214916702,219.87218666073008,5.713204692732111
7.653778766338761e-09,0.003954399999999999,246.3651160455035,219.87218666073008,5.713204692732111
7.678553287937268e-09,0.0039672,246.4211362471105,219.87218666073008,5.713204692732111
7.726553923534376e-09,0.003992,246.52947519623643,219.87218666073008,5.713204692732111
7.890714864497477e-09,0.004076815363072615,246.89802372153872,219.87218666073008,5.713204692732111
8.74560683804068e-09,0.004518503700740148,248.77098627363972,219.87218666073008,5.713204692732111
9.34031429789682e-09,0.0048257651530306065,250.0319699800529,219.87218666073008,5.713204692732111
1.019520627144002e-08,0.00526745349069814,251.7910726213613,219.87218666073008,5.713204692732111
1.0864252163778176e-08,0.005613122624524905,253.12790701725226,219.87218666073008,5.713204692732111
1.1384621191152298e-08,0.005881976395279056,254.14558240415008,219.87218666073008,5.713204692732111
1.186782100228541e-08,0.006131626325265053,255.07443639585884,219.87218666073008,5.713204692732111
1.2834220624551639e-08,0.006630926185237048,256.8890222559984,219.87218666073008,5.713204692732111
1.3726281814335846e-08,0.007091818363672734,258.51724293390396,219.87218666073008,5.713204692732111
1.4060804760504925e-08,0.007264652930586117,259.1171159368354,219.87218666073008,5.713204692732111
1.4729850652843082e-08,0.007610322064412882,260.30041763993637,219.87218666073008,5.713204692732111
1.5956434788796372e-08,0.008244048809761952,262.41672274641473,219.87218666073008,5.713204692732111
1.655114224865251e-08,0.00855131026205241,263.4198800019521,219.87218666073008,5.713204692732111
1.7294526573472687e-08,0.008935387077415483,264.6542706276897,219.87218666073008,5.713204692732111
1.7554711087159748e-08,0.009069813962792559,265.08139538316254,219.87218666073008,5.713204692732111
1.8558279925666982e-08,0.009588317663532707,266.7062526679246,219.87218666073008,5.713204692732111
2.0379571521476406e-08,0.010529305861172233,269.57007991950553,219.87218666073008,5.713204692732111
2.0565417602681455e-08,0.010625325065013003,269.8565784589262,219.87218666073008,5.713204692732111
2.0825602116368513e-08,0.010759751950390077,270.2559858500895,219.87218666073008,5.713204692732111
2.11972942787786e-08,0.010951790358071613,270.8232083278796,219.87218666073008,5.713204692732111
2.179200173863474e-08,0.011259051810362072,271.72276153954454,219.87218666073008,5.713204692732111
2.2312370766008863e-08,0.011527905581116223,272.50204516649825,219.87218666073008,5.713204692732111
2.2609724495936934e-08,0.011681536307261452,272.9441672423896,219.87218666073008,5.713204692732111
2.391064706437224e-08,0.012353670734146829,274.8523843979465,219.87218666073008,5.713204692732111
2.4245170010541316e-08,0.012526505301060212,275.3364690171934,219.87218666073008,5.713204692732111
2.4914215902879474e-08,0.012872174434886977,276.2968933494449,219.87218666073008,5.713204692732111
2.591778474138671e-08,0.013390678135627125,277.7188797649163,219.87218666073008,5.713204692732111
2.6289476903796798e-08,0.013582716543308662,278.24007066972416,219.87218666073008,5.713204692732111
2.6884184363652936e-08,0.01388997799559912,279.0680378589905,219.87218666073008,5.713204692732111
2.7553230255991094e-08,0.014235647129425886,279.99100939276593,219.87218666073008,5.713204692732111
2.79992608508832e-08,0.01446609321864373,280.6014723153839,219.87218666073008,5.713204692732111
2.825944536457026e-08,0.014600520104020805,280.955824224136,219.87218666073008,5.713204692732111
2.8705475959462367e-08,0.014830966193238648,281.56033858432545,219.87218666073008,5.713204692732111
2.9039998905631444e-08,0.015003800760152031,282.01132319152487,219.87218666073008,5.713204692732111
2.996922931165666e-08,0.015483896779355872,283.25354989611094,219.87218666073008,5.713204692732111
3.082412128519986e-08,0.015925585117023404,284.3831939499665,219.87218666073008,5.713204692732111
3.145599796129701e-08,0.016252050410082017,285.21031024455766,219.87218666073008,5.713204692732111
3.2162213069876174e-08,0.016616923384676935,286.1271038300126,219.87218666073008,5.713204692732111
3.2979935827178367e-08,0.017039407881576315,287.1789023336351,219.87218666073008,5.713204692732111
3.394633544944459e-08,0.01753870774154831,288.408912612028,219.87218666073008,5.713204692732111
3.5210088801638894e-08,0.018191638327665533,289.99697379707237,219.87218666073008,5.713204692732111
3.6064980775182086e-08,0.018633326665333065,291.0586637163316,219.87218666073008,5.713204692732111
3.654818058631521e-08,0.018882976595319064,291.65440678930776,219.87218666073008,5.713204692732111
3.677119588376126e-08,0.018998199639927986,291.92832833385773,219.87218666073008,5.713204692732111
3.699421118120731e-08,0.019113422684536908,292.2016027248351,219.87218666073008,5.713204692732111
3.7180057262412357e-08,0.019209441888377678,292.4288409406291,219.87218666073008,5.713204692732111
3.7663257073545466e-08,0.019459091818363673,293.017596755371,219.87218666073008,5.713204692732111
3.8220795317160594e-08,0.019747149429885976,293.69328221352964,219.87218666073008,5.713204692732111
3.8443810614606646e-08,0.019862372474494898,293.9624787478457,219.87218666073008,5.713204692732111
3.937304102063187e-08,0.02034246849369874,295.0776376978985,219.87218666073008,5.713204692732111
3.970756396680095e-08,0.02051530306061212,295.4765760727295,219.87218666073008,5.713204692732111
4.0339440642898096e-08,0.020841768353670735,296.2265681562639,219.87218666073008,5.713204692732111
4.0896978886513224e-08,0.021129825965193038,296.88452923132945,219.87218666073008,5.713204692732111
4.1082824967718276e-08,0.021225845169033808,297.1030709835107,219.87218666073008,5.713204692732111
4.138017869764634e-08,0.021379475895179037,297.45193752896876,219.87218666073008,5.713204692732111
4.238374753615358e-08,0.021897979595919183,298.6222101719212,219.87218666073008,5.713204692732111
4.353599323962485e-08,0.022493298659731948,299.95261065393703,219.87218666073008,5.713204692732111
4.401919305075796e-08,0.022742948589717944,300.50642539534056,219.87218666073008,5.713204692732111
4.584048464656739e-08,0.02368393678735747,302.5729082362542,219.87218666073008,5.713204692732111
4.6398022890182516e-08,0.023971994398879776,303.19907037534483,219.87218666073008,5.713204692732111
4.6621038187628574e-08,0.024087217443488698,303.448712753326,219.87218666073008,5.713204692732111
4.7624607026135806e-08,0.024605721144228845,304.56638947465177,219.87218666073008,5.713204692732111
4.873968351336607e-08,0.025181836367273454,305.79753421734324,219.87218666073008,5.713204692732111
4.9074206459535146e-08,0.02535467093418684,306.16472913149954,219.87218666073008,5.713204692732111
5.026362137924743e-08,0.025969193838767755,307.46247837027977,219.87218666073008,5.713204692732111
5.126719021775466e-08,0.0264876975395079,308.5481645996814,219.87218666073008,5.713204692732111
5.2010574542574834e-08,0.026871774354870974,309.34704039137216,219.87218666073008,5.713204692732111
5.286546651611804e-08,0.02731346269253851,310.26026285998853,219.87218666073008,5.713204692732111
5.327432789476913e-08,0.027524704940988198,310.6949838888918,219.87218666073008,5.713204692732111
5.4500912030722426e-08,0.02815843168633727,311.9914062376482,219.87218666073008,5.713204692732111
5.550448086922966e-08,0.028676935387077416,313.04367208516356,219.87218666073008,5.713204692732111
5.572749616667571e-08,0.028792158431686338,313.2764982251553,219.87218666073008,5.713204692732111
5.617352676156782e-08,0.02902260452090418,313.74106322098874,219.87218666073008,5.713204692732111
5.658238814021891e-08,0.02923384676935387,314.16565223915603,219.87218666073008,5.713204692732111
5.818066443858229e-08,0.030059611922384478,315.81405429263634,219.87218666073008,5.713204692732111
5.9035556412125486e-08,0.03050130026005201,316.688503543958,219.87218666073008,5.713204692732111
5.985327916942768e-08,0.03092378475695139,317.52032365168395,219.87218666073008,5.713204692732111
6.003912525063272e-08,0.03101980396079216,317.7087541702423,219.87218666073008,5.713204692732111
6.063383271048887e-08,0.03132706541308262,318.3102089047273,219.87218666073008,5.713204692732111
6.100552487289896e-08,0.03151910382076416,318.68495002986447,219.87218666073008,5.713204692732111
6.182324763020115e-08,0.031941588317663534,319.50626033559115,219.87218666073008,5.713204692732111
6.25294627387803e-08,0.03230646129225845,320.2121701383064,219.87218666073008,5.713204692732111
6.323567784735947e-08,0.03267133426685337,320.9149773750991,219.87218666073008,5.713204692732111
6.498263101068689e-08,0.03357391478295659,322.6404756170735,219.87218666073008,5.713204692732111
6.565167690302504e-08,0.03391958391678336,323.29650169465896,219.87218666073008,5.713204692732111
6.602336906543513e-08,0.034111622324464894,323.65983386405736,219.87218666073008,5.713204692732111
6.643223044408623e-08,0.034322864572914585,324.0585791200692,219.87218666073008,5.713204692732111
6.710127633642438e-08,0.03466853370674135,324.7090130480934,219.87218666073008,5.713204692732111
6.784466066124455e-08,0.03505261052210442,325.4287582116545,219.87218666073008,5.713204692732111
6.884822949975177e-08,0.03557111422284456,326.39555425421054,219.87218666073008,5.713204692732111
6.89597371484748e-08,0.035628725745149026,326.50263569098126,219.87218666073008,5.713204692732111
6.921992166216189e-08,0.03576315263052611,326.75223010980267,219.87218666073008,5.713204692732111
6.955444460833095e-08,0.035935987197439484,327.0726002452496,219.87218666073008,5.713204692732111
6.988896755450003e-08,0.03610882176435287,327.39237001977557,219.87218666073008,5.713204692732111
7.081819796052527e-08,0.03658891778355672,328.2775025299963,219.87218666073008,5.713204692732111
7.15244130691044e-08,0.036953790758151625,328.947177151504,219.87218666073008,5.713204692732111
7.241647425888862e-08,0.03741468293658731,329.78940736383305,219.87218666073008,5.713204692732111
7.308552015122679e-08,0.03776035207041409,330.41842720073726,219.87218666073008,5.713204692732111
7.330853544867283e-08,0.037875575115023,330.6276009086094,219.87218666073008,5.713204692732111
7.375456604356494e-08,0.03810602120424085,331.0452052951253,219.87218666073008,5.713204692732111
7.434927350342109e-08,0.03841328265653131,331.6004822470618,219.87218666073008,5.713204692732111
7.460945801710813e-08,0.03854770954190838,331.84287092460505,219.87218666073008,5.713204692732111
7.490681174703621e-08,0.03870134026805361,332.1194832587029,219.87218666073008,5.713204692732111
7.512982704448226e-08,0.03881656331266253,332.32666156378616,219.87218666073008,5.713204692732111
7.609622666674849e-08,0.039315863172634524,333.2216768748219,219.87218666073008,5.713204692732111
7.735998001894277e-08,0.039968793758751744,334.3854210905335,219.87218666073008,5.713204692732111
7.925561004723423e-08,0.04094818963792758,336.11723081628423,219.87218666073008,5.713204692732111
7.981314829084938e-08,0.041236247249449895,336.62350237412977,219.87218666073008,5.713204692732111
8.074237869687458e-08,0.04171634326865373,337.4642339667781,219.87218666073008,5.713204692732111
8.156010145417677e-08,0.04213882776555311,338.20096126438483,219.87218666073008,5.713204692732111
8.222914734651492e-08,0.04248449689937987,338.80159781006046,219.87218666073008,5.713204692732111
8.248933186020201e-08,0.04261892378475696,339.0346635980349,219.87218666073008,5.713204692732111
8.393893129360134e-08,0.043367873574714944,340.3279625283135,219.87218666073008,5.713204692732111
8.471948483466251e-08,0.04377115423084617,341.02074502133456,219.87218666073008,5.713204692732111
8.497966934834957e-08,0.04390558111622324,341.25111875125805,219.87218666073008,5.713204692732111
8.590889975437479e-08,0.044385677135427085,342.0716459652802,219.87218666073008,5.713204692732111
8.654077643047195e-08,0.0447121424284857,342.6276283278897,219.87218666073008,5.713204692732111
8.691246859288203e-08,0.044904180836167235,342.95393723505805,219.87218666073008,5.713204692732111
8.750717605273817e-08,0.04521144228845769,343.47490173456316,219.87218666073008,5.713204692732111
8.914262156734254e-08,0.046056411282256446,344.90048244261806,219.87218666073008,5.713204692732111
8.955148294599364e-08,0.04626765353070614,345.2552793282653,219.87218666073008,5.713204692732111
9.007185197336777e-08,0.04653650730146029,345.70592664175825,219.87218666073008,5.713204692732111
9.100108237939301e-08,0.04701660332066414,346.50813661624005,219.87218666073008,5.713204692732111
9.222766651534627e-08,0.0476503300660132,347.56217902296754,219.87218666073008,5.713204692732111
9.304538927264848e-08,0.04807281456291258,348.26183823717685,219.87218666073008,5.713204692732111
9.337991221881756e-08,0.04824564912982597,348.5473707968781,219.87218666073008,5.713204692732111
9.390028124619166e-08,0.04851450290058011,348.99074090866094,219.87218666073008,5.713204692732111
9.419763497611973e-08,0.04866813362672534,349.2436650167118,219.87218666073008,5.713204692732111
9.464366557101186e-08,0.04889857971594319,349.6224681282067,219.87218666073008,5.713204692732111
9.549855754455504e-08,0.04934026805361072,350.346567021874,219.87218666073008,5.713204692732111
9.61304342206522e-08,0.04966673334666934,350.88014681004347,219.87218666073008,5.713204692732111
9.642778795058027e-08,0.049820364072814566,351.1307697211247,219.87218666073008,5.713204692732111
9.687381854547236e-08,0.0500508101620324,351.50613968642415,219.87218666073008,5.713204692732111
9.717117227540043e-08,0.05020444088817763,351.7560119350136,219.87218666073008,5.713204692732111
9.769154130277456e-08,0.050473294658931786,352.1925719950547,219.87218666073008,5.713204692732111
9.813757189766668e-08,0.05070374074814964,352.5660449993684,219.87218666073008,5.713204692732111
9.865794092504078e-08,0.05097259451890378,353.0009278493738,219.87218666073008,5.713204692732111
9.947566368234299e-08,0.05139507901580316,353.682512137154,219.87218666073008,5.713204692732111
1.0070224781829628e-07,0.052028805761152236,354.7008057251654,219.87218666073008,5.713204692732111
1.0122261684567038e-07,0.052297659531906376,355.13134638300176,219.87218666073008,5.713204692732111
1.021518472516956e-07,0.05277775555111022,355.8980281222536,219.87218666073008,5.713204692732111
1.0311824687396183e-07,0.053277055411082214,356.69249738217957,219.87218666073008,5.713204692732111
1.0497670768601226e-07,0.05423724744948989,358.21220844641505,219.87218666073008,5.713204692732111
1.054599074971454e-07,0.0544868973794759,358.6056100674912,219.87218666073008,5.713204692732111
1.0742987595791886e-07,0.05550470094018804,360.2022564657966,219.87218666073008,5.713204692732111
1.0824759871522103e-07,0.05592718543708741,360.8616569668567,219.87218666073008,5.713204692732111
1.1047775168968157e-07,0.05707941588317664,362.6502213108874,219.87218666073008,5.713204692732111
1.1125830523074274e-07,0.05748269653930786,363.272884959313,219.87218666073008,5.713204692732111
1.1241055093421401e-07,0.05807801560312062,364.1889503583786,219.87218666073008,5.713204692732111
1.1426901174626447e-07,0.05903820764152831,365.6587959530983,219.87218666073008,5.713204692732111
1.1579294961214581e-07,0.0598255651130226,366.85712474856643,219.87218666073008,5.713204692732111
1.1631331863951994e-07,0.06009441888377676,367.2648994232359,219.87218666073008,5.713204692732111
1.1683368766689407e-07,0.06036327265453091,367.67196322861247,219.87218666073008,5.713204692732111
1.1716821061306313e-07,0.060536107221444285,367.9332737684812,219.87218666073008,5.713204692732111
1.1757707199171422e-07,0.06074734946989398,368.2522585174916,219.87218666073008,5.713204692732111
1.1880365612766752e-07,0.06138107621524305,369.2066272154941,219.87218666073008,5.713204692732111
1.1928685593880063e-07,0.06163072614522905,369.5815346003495,219.87218666073008,5.713204692732111
1.1995590183113877e-07,0.06197639527905581,370.09966082687583,219.87218666073008,5.713204692732111
1.2118248596709208e-07,0.06261012202440489,371.0466411900345,219.87218666073008,5.713204692732111
1.2155417812950217e-07,0.06280216043208642,371.33286594358077,219.87218666073008,5.713204692732111
1.2281793148169646e-07,0.06345509101820364,372.303487033566,219.87218666073008,5.713204692732111
1.2389583875268571e-07,0.06401200240048009,373.12829570989226,219.87218666073008,5.713204692732111
1.2586580721345917e-07,0.06502980596119223,374.6285095408722,219.87218666073008,5.713204692732111
1.2876500608025785e-07,0.06652770554110822,376.8198220222733,219.87218666073008,5.713204692732111
1.2909952902642695e-07,0.06670054010802161,377.071421503353,219.87218666073008,5.713204692732111
1.2961989805380106e-07,0.06696939387877576,377.4622936864771,219.87218666073008,5.713204692732111
1.306234668923083e-07,0.06748789757951591,378.2143947001312,219.87218666073008,5.713204692732111
1.313296820008875e-07,0.06785277055411083,378.7423006647851,219.87218666073008,5.713204692732111
1.3177571259577956e-07,0.06808321664332867,379.07514460243414,219.87218666073008,5.713204692732111
1.3255626613684076e-07,0.0684864972994599,379.65656618263256,219.87218666073008,5.713204692732111
1.3285361986676882e-07,0.06864012802560512,379.87770870811016,219.87218666073008,5.713204692732111
1.33485496542866e-07,0.06896659331866374,380.3469966613645,219.87218666073008,5.713204692732111
1.3482358832754227e-07,0.06965793158631726,381.33793259048053,219.87218666073008,5.713204692732111
1.3538112657115743e-07,0.06994598919783958,381.74968967685624,219.87218666073008,5.713204692732111
1.3590149559853152e-07,0.07021484296859372,382.133400019914,219.87218666073008,5.713204692732111
1.361245108959776e-07,0.07033006601320264,382.29767185422656,219.87218666073008,5.713204692732111
1.3694223365327978e-07,0.07075255051010203,382.899106014707,219.87218666073008,5.713204692732111
1.3816881778923306e-07,0.07138627725545109,383.79863773292874,219.87218666073008,5.713204692732111
1.3861484838412519e-07,0.07161672334466894,384.12496733056764,219.87218666073008,5.713204692732111
1.387635252490892e-07,0.07169353870774155,384.2336528250438,219.87218666073008,5.713204692732111
1.404733091961756e-07,0.07257691538307662,385.48028933968106,219.87218666073008,5.713204692732111
1.4069632449362167e-07,0.07269213842768554,385.64245671554136,219.87218666073008,5.713204692732111
1.4196007784581597e-07,0.07334506901380276,386.55951862427594,219.87218666073008,5.713204692732111
1.426291237381541e-07,0.07369073814762953,387.04373272823307,219.87218666073008,5.713204692732111
1.4300081590056423e-07,0.07388277655531107,387.3123577776904,219.87218666073008,5.713204692732111
1.4363269257666135e-07,0.07420924184836968,387.7683962622228,219.87218666073008,5.713204692732111
1.4445041533396354e-07,0.07463172634526906,388.35740393662815,219.87218666073008,5.713204692732111
1.4571416868615784e-07,0.07528465693138628,389.265137178467,219.87218666073008,5.713204692732111
1.4638321457849598e-07,0.07563032606521304,389.7444585761576,219.87218666073008,5.713204692732111
1.4775847557941333e-07,0.07634086817363474,390.7270555227065,219.87218666073008,5.713204692732111
1.4790715244437736e-07,0.07641768353670735,390.83306814319695,219.87218666073008,5.713204692732111
1.4816733695806442e-07,0.07655211042208442,391.01849027957616,219.87218666073008,5.713204692732111
1.4876204441792054e-07,0.07685937187437487,391.441836121363,219.87218666073008,5.713204692732111
1.5043465914876598e-07,0.0777235447089418,392.6289721409115,219.87218666073008,5.713204692732111
1.5088068974365805e-07,0.07795399079815964,392.944670946314,219.87218666073008,5.713204692732111
1.5259047369074448e-07,0.07883736747349471,394.15149282686656,219.87218666073008,5.713204692732111
1.5303650428563655e-07,0.07906781356271254,394.46544714996145,219.87218666073008,5.713204692732111
1.543745960703129e-07,0.07975915183036608,395.4051759077919,219.87218666073008,5.713204692732111
1.5548967255754313e-07,0.08033526705341068,396.1858590007818,219.87218666073008,5.713204692732111
1.557870262874712e-07,0.08048889777955591,396.39367201426353,219.87218666073008,5.713204692732111
1.5690210277470148e-07,0.08106501300260052,397.17159689934283,219.87218666073008,5.713204692732111
1.5734813336959358e-07,0.08129545909181837,397.4821627732011,219.87218666073008,5.713204692732111
1.577569947482447e-07,0.08150670134026806,397.7665466782422,219.87218666073008,5.713204692732111
1.5861188672178788e-07,0.08194838967793559,398.360240394719,219.87218666073008,5.713204692732111
1.5883490201923394e-07,0.08206361272254452,398.51491161069936,219.87218666073008,5.713204692732111
1.5894640966795697e-07,0.08212122424484898,398.5922154560532,219.87218666073008,5.713204692732111
1.5980130164150016e-07,0.08256291258251651,399.1841772190668,219.87218666073008,5.713204692732111
1.612880702911405e-07,0.08333106621324265,400.21074260301083,219.87218666073008,5.713204692732111
1.6147391637234554e-07,0.08342708541708342,400.3388032775667,219.87218666073008,5.713204692732111
1.6229163912964773e-07,0.0838495699139828,400.90158874735147,219.87218666073008,5.713204692732111
1.625518236433348e-07,0.08398399679935988,401.08042478953195,219.87218666073008,5.713204692732111
1.6277483894078085e-07,0.0840992198439688,401.2336239898025,219.87218666073008,5.713204692732111
1.6400142307673413e-07,0.08473294658931786,402.0747609051572,219.87218666073008,5.713204692732111
1.6426160759042121e-07,0.08486737347469495,402.2528680699951,219.87218666073008,5.713204692732111
1.650793303477234e-07,0.08528985797159433,402.81191850362234,219.87218666073008,5.713204692732111
1.6526517642892845e-07,0.0853858771754351,402.9388246766774,219.87218666073008,5.713204692732111
1.6608289918623062e-07,0.08580836167233447,403.4965519459717,219.87218666073008,5.713204692732111
1.67718344700835e-07,0.08665333066613323,404.60880399270076,219.87218666073008,5.713204692732111
1.6835022137693218e-07,0.08697979595919185,405.03740390496995,219.87218666073008,5.713204692732111
1.6868474432310122e-07,0.08715263052610522,405.2640557245789,219.87218666073008,5.713204692732111
1.6913077491799335e-07,0.08738307661532307,405.56598565541753,219.87218666073008,5.713204692732111
1.693537902154394e-07,0.08749829965993199,405.71683415826425,219.87218666073008,5.713204692732111
1.6957680551288546e-07,0.08761352270454091,405.8676052088718,219.87218666073008,5.713204692732111
1.7121225102748984e-07,0.08845849169833968,406.9709063731176,219.87218666073008,5.713204692732111
1.7169545083862296e-07,0.08870814162832567,407.296094142283,219.87218666073008,5.713204692732111
1.7210431221727405e-07,0.08891938387677537,407.57097434544727,219.87218666073008,5.713204692732111
1.7247600437968414e-07,0.0891114222844569,407.8206445171901,219.87218666073008,5.713204692732111
1.7277335810961221e-07,0.08926505301060213,408.02022960378616,219.87218666073008,5.713204692732111
1.7333089635322732e-07,0.08955311062212443,408.39409093762,219.87218666073008,5.713204692732111
1.7418578832677054e-07,0.08999479895979197,408.9664353692291,219.87218666073008,5.713204692732111
1.7481766500286768e-07,0.09032126425285057,409.38876869609595,219.87218666073008,5.713204692732111
1.7611858757130297e-07,0.09099339867973595,410.25640850133357,219.87218666073008,5.713204692732111
1.7727083327477423e-07,0.09158871774354871,411.02280431661114,219.87218666073008,5.713204692732111
1.783859097620045e-07,0.09216483296659332,411.7626300410011,219.87218666073008,5.713204692732111
1.796496631141988e-07,0.09281776355271054,412.59892232977575,219.87218666073008,5.713204692732111
1.808762472501521e-07,0.09345149029805962,413.40842644705936,219.87218666073008,5.713204692732111
1.8195415452114135e-07,0.09400840168033607,414.11804311673734,219.87218666073008,5.713204692732111
1.8306923100837162e-07,0.09458451690338068,414.85040620646885,219.87218666073008,5.713204692732111
1.834037539545407e-07,0.09475735147029406,415.0697756186565,219.87218666073008,5.713204692732111
1.8373827690070977e-07,0.09493018603720745,415.2889890381709,219.87218666073008,5.713204692732111
1.8396129219815583e-07,0.09504540908181637,415.4350448502013,219.87218666073008,5.713204692732111
1.851878763341091e-07,0.09567913582716543,416.23712086638847,219.87218666073008,5.713204692732111
1.860055990914113e-07,0.09610162032406482,416.770687467668,219.87218666073008,5.713204692732111
1.8656313733502646e-07,0.09638967793558713,417.13395847938256,219.87218666073008,5.713204692732111
1.868233218487135e-07,0.0965241048209642,417.30334003415084,219.87218666073008,5.713204692732111
1.8741802930856965e-07,0.09683136627325466,417.6901527892606,219.87218666073008,5.713204692732111
1.8775255225473872e-07,0.09700420084016805,417.90752459531916,219.87218666073008,5.713204692732111
1.884959365795589e-07,0.09738827765553111,418.39003300458916,219.87218666073008,5.713204692732111
1.8949950541806613e-07,0.09790678135627126,419.04024380204567,219.87218666073008,5.713204692732111
1.897596899317532e-07,0.09804120824164833,419.2085975804955,219.87218666073008,5.713204692732111
1.9005704366168124e-07,0.09819483896779356,419.4008917029858,219.87218666073008,5.713204692732111
1.902057205266453e-07,0.09827165433086618,419.4969947618338,219.87218666073008,5.713204692732111
1.9080042798650145e-07,0.09857891578315664,419.8811143905343,219.87218666073008,5.713204692732111
1.914694738788396e-07,0.0989245849169834,420.31269127972234,219.87218666073008,5.713204692732111
1.918783352574907e-07,0.0991358271654331,420.57614319571553,219.87218666073008,5.713204692732111
1.9210135055493674e-07,0.09925105021004202,420.7197519591021,219.87218666073008,5.713204692732111
1.9299341174472094e-07,0.0997119423884777,421.2935380015102,219.87218666073008,5.713204692732111
1.93179257825926e-07,0.09980796159231847,421.4129464652651,219.87218666073008,5.713204692732111
1.9347661155585407e-07,0.0999615923184637,421.60390686249394,219.87218666073008,5.713204692732111