File: datasets/aisi_316_L/data/M1/valid_2.csv
Time(s),Strain(%),Stress(MPa),Temp(C),Log_SR(s-1)
0.0,0.0,0.0,317.60234163369523,-3.0125659817965165
0.013999253896745154,1.3599999999999999e-05,2.3962696374999997,317.60234163369523,-3.0125659817965165
0.016469710466759005,1.6e-05,2.81914075,317.60234163369523,-3.0125659817965165
0.02552805122347646,2.48e-05,4.3696681625,317.60234163369523,-3.0125659817965165
0.033762906456855965,3.28e-05,5.7792385374999995,317.60234163369523,-3.0125659817965165
0.05105610244695292,4.96e-05,8.739336325,317.60234163369523,-3.0125659817965165
0.06505535634369806,6.319999999999999e-05,11.135605962499998,317.60234163369523,-3.0125659817965165
0.07329021157707757,7.12e-05,12.5451763375,317.60234163369523,-3.0125659817965165
0.08564249442714683,8.319999999999999e-05,14.659531899999998,317.60234163369523,-3.0125659817965165
0.10211220489390584,9.92e-05,17.47867265,317.60234163369523,-3.0125659817965165
0.1078766035572715,0.0001048,18.4653719125,317.60234163369523,-3.0125659817965165
0.11528797326731305,0.000112,19.73398525,317.60234163369523,-3.0125659817965165
0.13669859687409977,0.0001328,23.398868225,317.60234163369523,-3.0125659817965165
0.18775469932105265,0.0001824,32.13820455,317.60234163369523,-3.0125659817965165
0.2001069821711219,0.00019439999999999998,34.2525601125,317.60234163369523,-3.0125659817965165
0.21492972159120502,0.00020879999999999998,36.7897867875,317.60234163369523,-3.0125659817965165
0.2272820044412743,0.0002208,38.90414235,317.60234163369523,-3.0125659817965165
0.23139943205796404,0.0002248,39.6089275375,317.60234163369523,-3.0125659817965165
0.24951611357139894,0.00024239999999999998,42.7099823625,317.60234163369523,-3.0125659817965165
0.2593979398514544,0.000252,44.4014668125,317.60234163369523,-3.0125659817965165
0.2635153674681441,0.000256,45.106252,317.60234163369523,-3.0125659817965165
0.31539495543843493,0.00030639999999999997,53.986545362499996,317.60234163369523,-3.0125659817965165
0.33351163695186986,0.00032399999999999996,57.087600187499994,317.60234163369523,-3.0125659817965165
0.33845255009189756,0.00032879999999999997,57.9333424125,317.60234163369523,-3.0125659817965165
0.3540987750353186,0.00034399999999999996,60.61152612499999,317.60234163369523,-3.0125659817965165
0.3878616814921746,0.0003768,66.3907646625,317.60234163369523,-3.0125659817965165
0.39939047881890594,0.000388,68.3641631875,317.60234163369523,-3.0125659817965165
0.4191541313790167,0.0004072,71.74713208749999,317.60234163369523,-3.0125659817965165
0.4389177839391275,0.00042639999999999996,75.13010098749999,317.60234163369523,-3.0125659817965165
0.4949147995261081,0.0004808,84.71517953749999,317.60234163369523,-3.0125659817965165
0.5047966258061636,0.0004904,86.4066639875,317.60234163369523,-3.0125659817965165
0.5229133073195985,0.000508,89.5077188125,317.60234163369523,-3.0125659817965165
0.5517353006364267,0.000536,94.441215125,317.60234163369523,-3.0125659817965165
0.5583231848231303,0.0005424,95.568871425,317.60234163369523,-3.0125659817965165
0.5887921491866345,0.000572,100.7842818125,317.60234163369523,-3.0125659817965165
0.6036148886067175,0.0005863999999999999,103.32150848749998,317.60234163369523,-3.0125659817965165
0.6069088307000694,0.0005896,103.8853366375,317.60234163369523,-3.0125659817965165
0.6365543095402356,0.0006184,108.95978998749999,317.60234163369523,-3.0125659817965165
0.6472596213436289,0.0006288,110.792231475,317.60234163369523,-3.0125659817965165
0.6736111580904434,0.0006544,115.302856675,317.60234163369523,-3.0125659817965165
0.6900808685572023,0.0006703999999999999,118.12199742499999,317.60234163369523,-3.0125659817965165
0.7106680066406511,0.0006904,121.6459233625,317.60234163369523,-3.0125659817965165
0.7329021157707758,0.000712,125.451763375,317.60234163369523,-3.0125659817965165
0.7444309130975071,0.0007232,127.4251619,317.60234163369523,-3.0125659817965165
0.7691354787976455,0.0007472,131.653873025,317.60234163369523,-3.0125659817965165
0.7732529064143353,0.0007511999999999999,132.3586582125,317.60234163369523,-3.0125659817965165
0.7987809576378119,0.000776,136.728326375,317.60234163369523,-3.0125659817965165
0.8028983852545015,0.00078,137.4331115625,317.60234163369523,-3.0125659817965165
0.810309754964543,0.0007871999999999999,138.7017249,317.60234163369523,-3.0125659817965165
0.8218385522912744,0.0007984,140.675123425,317.60234163369523,-3.0125659817965165
0.8308968930479919,0.0008072,142.2256508375,317.60234163369523,-3.0125659817965165
0.8432491758980611,0.0008192,144.3400064,317.60234163369523,-3.0125659817965165
0.86383631398151,0.0008392,147.8639323375,317.60234163369523,-3.0125659817965165
0.8696007126448755,0.0008447999999999999,148.85063159999999,317.60234163369523,-3.0125659817965165
0.8819529954949449,0.0008568,150.9649871625,317.60234163369523,-3.0125659817965165
0.8992461914850417,0.0008736,153.92508494999998,317.60234163369523,-3.0125659817965165
0.9338325834652356,0.0009071999999999999,159.845280525,317.60234163369523,-3.0125659817965165
0.9643015478287399,0.0009368,163.7820831123363,317.60234163369523,-3.0125659817965165
0.9725364030621193,0.0009448,163.82580224124627,317.60234163369523,-3.0125659817965165
0.9857121714355265,0.0009576,163.89545374258415,317.60234163369523,-3.0125659817965165
1.0038288529489614,0.0009752,163.9906345701419,317.60234163369523,-3.0125659817965165
1.0211220489390584,0.000992,164.0808659658268,317.60234163369523,-3.0125659817965165
1.0557084409192523,0.0010256,164.2595603632559,317.60234163369523,-3.0125659817965165
1.0738251224326871,0.0010432,164.35225012000578,317.60234163369523,-3.0125659817965165
1.108411514412881,0.0010768,164.5275269868993,317.60234163369523,-3.0125659817965165
1.111705456506233,0.00108,164.54410798486765,317.60234163369523,-3.0125659817965165
1.162761558953186,0.0011296,164.7987121925499,317.60234163369523,-3.0125659817965165
1.1882896101766622,0.0011543999999999999,164.92437630868906,317.60234163369523,-3.0125659817965165
1.2047593206434213,0.0011704,165.00489151517505,317.60234163369523,-3.0125659817965165
1.2228760021568563,0.001188,165.09296404957308,317.60234163369523,-3.0125659817965165
1.2360517705302634,0.0012008,165.1566974999239,317.60234163369523,-3.0125659817965165
1.2599328507070642,0.001224,165.27154311538365,317.60234163369523,-3.0125659817965165
1.2681677059404435,0.001232,165.31094779443413,317.60234163369523,-3.0125659817965165
1.274755590127147,0.0012384,165.3423997353571,317.60234163369523,-3.0125659817965165
1.2871078729772165,0.0012504,165.40120179139058,317.60234163369523,-3.0125659817965165
1.292872271640582,0.001256,165.4285673946612,317.60234163369523,-3.0125659817965165
1.3142828952473689,0.0012768,165.52979712591318,317.60234163369523,-3.0125659817965165
1.3406344319941832,0.0013024,165.65350892589294,317.60234163369523,-3.0125659817965165
1.359574599030956,0.0013208,165.74184171810646,317.60234163369523,-3.0125659817965165
1.3678094542643355,0.0013288,165.78009744641216,317.60234163369523,-3.0125659817965165
1.374397338451039,0.0013352,165.81063739538186,317.60234163369523,-3.0125659817965165
1.3966314475811639,0.0013568,165.91329082376024,317.60234163369523,-3.0125659817965165
1.4007488751978534,0.0013608,165.93223057064603,317.60234163369523,-3.0125659817965165
1.4221594988046402,0.0013816,166.0303694360501,317.60234163369523,-3.0125659817965165
1.4328648106080335,0.001392,166.07922266238367,317.60234163369523,-3.0125659817965165
1.453451948691482,0.0014119999999999998,166.17277292713692,317.60234163369523,-3.0125659817965165
1.4641572604948756,0.0014223999999999999,166.22121474984013,317.60234163369523,-3.0125659817965165
1.4979201669517317,0.0014552,166.37309577814565,317.60234163369523,-3.0125659817965165
1.5168603339885045,0.0014736,166.457712624474,317.60234163369523,-3.0125659817965165
1.5325065589319256,0.0014888,166.5273031363443,317.60234163369523,-3.0125659817965165
1.539094443118629,0.0014952,166.55652144467567,317.60234163369523,-3.0125659817965165
1.5481527838753466,0.001504,166.59661710275705,317.60234163369523,-3.0125659817965165
1.572033864052147,0.0015271999999999998,166.70188768987964,317.60234163369523,-3.0125659817965165
1.5777982627155127,0.0015328,166.72720416599637,317.60234163369523,-3.0125659817965165
1.5827391758555405,0.0015375999999999999,166.74887530573196,317.60234163369523,-3.0125659817965165
1.6000323718456373,0.0015543999999999998,166.8245173911188,317.60234163369523,-3.0125659817965165
1.6280308796391276,0.0015815999999999998,166.94631300466364,317.60234163369523,-3.0125659817965165
1.642853619059211,0.001596,167.01046217620924,317.60234163369523,-3.0125659817965165
1.6642642426659975,0.0016167999999999998,167.1027250106666,317.60234163369523,-3.0125659817965165
1.7004976056928673,0.0016519999999999998,167.25781444435037,317.60234163369523,-3.0125659817965165
1.726025656916344,0.0016768,167.36630904042622,317.60234163369523,-3.0125659817965165
1.7367309687197372,0.0016872,167.41162032054987,317.60234163369523,-3.0125659817965165
1.7811991869799866,0.0017304,167.59868215509852,317.60234163369523,-3.0125659817965165
1.7877870711666901,0.0017368,167.62623933628015,317.60234163369523,-3.0125659817965165
1.8042567816334492,0.0017527999999999999,167.69495959048515,317.60234163369523,-3.0125659817965165
1.822373463146884,0.0017703999999999999,167.77026992100886,317.60234163369523,-3.0125659817965165
1.838843173613643,0.0017863999999999998,167.8384808627513,317.60234163369523,-3.0125659817965165
1.8701356235004851,0.0018168,167.96742878998813,317.60234163369523,-3.0125659817965165
1.891546247107272,0.0018376,168.05517185211258,317.60234163369523,-3.0125659817965165
1.8948401892006237,0.0018407999999999999,168.06863632848555,317.60234163369523,-3.0125659817965165
1.8989576168173135,0.0018448,168.0854540939803,317.60234163369523,-3.0125659817965165
1.9154273272840725,0.0018608,168.152583427759,317.60234163369523,-3.0125659817965165
1.9491902337409284,0.0018935999999999998,168.2894988847069,317.60234163369523,-3.0125659817965165
1.9598955455443217,0.0019039999999999999,168.3327175639598,317.60234163369523,-3.0125659817965165
1.9648364586843494,0.0019088,168.35263358527453,317.60234163369523,-3.0125659817965165
1.9755417704877427,0.0019191999999999998,168.3957180824849,317.60234163369523,-3.0125659817965165
1.989541024384488,0.0019328,168.45192220884235,317.60234163369523,-3.0125659817965165
2.009304676944599,0.001952,168.53100734385754,317.60234163369523,-3.0125659817965165
2.039773641308103,0.0019816,168.65233846464602,317.60234163369523,-3.0125659817965165
2.057890322821538,0.0019992,168.7241462359131,317.60234163369523,-3.0125659817965165
2.0924767148017316,0.0020328,168.86055285687496,317.60234163369523,-3.0125659817965165
2.1081229397451526,0.002048,168.92197145702767,317.60234163369523,-3.0125659817965165
2.1204752225952217,0.0020599999999999998,168.97033433799942,317.60234163369523,-3.0125659817965165
2.1418858462020087,0.0020808,169.05390386004234,317.60234163369523,-3.0125659817965165
2.1575320711454298,0.0020959999999999998,169.1147680049498,317.60234163369523,-3.0125659817965165
2.1608260132387818,0.0020992,169.12755954728237,317.60234163369523,-3.0125659817965165
2.1937654341722994,0.0021311999999999998,169.25505946869148,317.60234163369523,-3.0125659817965165
2.1954124052189754,0.0021328,169.26141479324977,317.60234163369523,-3.0125659817965165
2.202823774929017,0.00214,169.28999077501643,317.60234163369523,-3.0125659817965165
2.2151760577790864,0.002152,169.33753422764133,317.60234163369523,-3.0125659817965165
2.232469253769183,0.0021688,169.40392172596353,317.60234163369523,-3.0125659817965165
2.237410166909211,0.0021736,169.4228527063605,317.60234163369523,-3.0125659817965165
2.246468507665928,0.0021823999999999997,169.4575172123332,317.60234163369523,-3.0125659817965165
2.2596442760393356,0.0021952,169.5078411583941,317.60234163369523,-3.0125659817965165
2.2802314141227846,0.0022152,169.58624382664982,317.60234163369523,-3.0125659817965165
2.284348841739474,0.0022191999999999997,169.60189117957867,317.60234163369523,-3.0125659817965165
2.3065829508695987,0.0022408,169.6861975765639,317.60234163369523,-3.0125659817965165
2.3304640310463993,0.002264,169.77639663988992,317.60234163369523,-3.0125659817965165
2.3559920822698754,0.0022887999999999997,169.87241861931412,317.60234163369523,-3.0125659817965165
2.3806966479700145,0.0023128,169.96495751330497,317.60234163369523,-3.0125659817965165
2.39057847425007,0.0023224,170.00186811692978,317.60234163369523,-3.0125659817965165
2.396342872913435,0.0023279999999999998,170.02337182302378,317.60234163369523,-3.0125659817965165
2.405401213670153,0.0023368,170.05712264726003,317.60234163369523,-3.0125659817965165
2.415283039950208,0.0023464,170.093885245284,317.60234163369523,-3.0125659817965165
2.4235178951835876,0.0023544,170.1244759555933,317.60234163369523,-3.0125659817965165
2.4819853673405823,0.0024112,170.3405161222879,317.60234163369523,-3.0125659817965165
2.486102794957272,0.0024151999999999997,170.3556549894793,317.60234163369523,-3.0125659817965165
2.4951611357139893,0.002424,170.38892612027465,317.60234163369523,-3.0125659817965165
2.4992785633306793,0.002428,170.40403378581334,317.60234163369523,-3.0125659817965165
2.5198657014141284,0.002448,170.4794270013743,317.60234163369523,-3.0125659817965165
2.533864955310873,0.0024616,170.53055722345277,317.60234163369523,-3.0125659817965165
2.538805868450901,0.0024664,170.54857686528717,317.60234163369523,-3.0125659817965165
2.5470407236842805,0.0024744,170.57857923824653,317.60234163369523,-3.0125659817965165
2.5577460354876735,0.0024847999999999997,170.61752582758982,317.60234163369523,-3.0125659817965165
2.576686202524446,0.0025031999999999997,170.68627595321348,317.60234163369523,-3.0125659817965165
2.5898619708978536,0.002516,170.73398593182858,317.60234163369523,-3.0125659817965165
2.593979398514543,0.0025199999999999997,170.7488758748996,317.60234163369523,-3.0125659817965165
2.598920311654571,0.0025248,170.76673164492047,317.60234163369523,-3.0125659817965165
2.631036247064751,0.0025559999999999997,170.88247311850745,317.60234163369523,-3.0125659817965165
2.657387783811566,0.0025816,170.9770295077486,317.60234163369523,-3.0125659817965165
2.6722105232316484,0.002596,171.03005676138474,317.60234163369523,-3.0125659817965165
2.6829158350350424,0.0026064,171.0682829052285,317.60234163369523,-3.0125659817965165
2.7232666256786016,0.0026455999999999997,171.2118345146012,317.60234163369523,-3.0125659817965165
2.733971937481995,0.002656,171.2497800975718,317.60234163369523,-3.0125659817965165
2.7784401557422442,0.0026991999999999997,171.40678392215287,317.60234163369523,-3.0125659817965165
2.7949098662090037,0.0027152,171.46468439980296,317.60234163369523,-3.0125659817965165
2.804791692489059,0.0027248,171.49936081840278,317.60234163369523,-3.0125659817965165
2.850906881795984,0.0027695999999999997,171.6605582689004,317.60234163369523,-3.0125659817965165
2.866553106739405,0.0027848,171.71501879658115,317.60234163369523,-3.0125659817965165
2.8912576724395436,0.0028087999999999998,171.8007736616796,317.60234163369523,-3.0125659817965165
2.904433440812951,0.0028216,171.8463927201581,317.60234163369523,-3.0125659817965165
2.9365493762231307,0.0028528,171.95725235751928,317.60234163369523,-3.0125659817965165
2.9538425722132278,0.0028696,172.01675011125965,317.60234163369523,-3.0125659817965165
2.9777236523900283,0.0028928,172.0986908258102,317.60234163369523,-3.0125659817965165
2.986781993146746,0.0029016,172.12970469216455,317.60234163369523,-3.0125659817965165
3.0246623272202915,0.0029384,172.25900358882748,317.60234163369523,-3.0125659817965165
3.051837349490444,0.0029648,172.35137275862922,317.60234163369523,-3.0125659817965165
3.0576017481538096,0.0029703999999999998,172.3709249178352,317.60234163369523,-3.0125659817965165
3.072424487573892,0.0029847999999999997,172.42113600179422,317.60234163369523,-3.0125659817965165
3.083129799377286,0.0029952,172.45734082647726,317.60234163369523,-3.0125659817965165
3.1037169374607347,0.0030152,172.52682798713337,317.60234163369523,-3.0125659817965165
3.115245734787466,0.0030264,172.56566227472226,317.60234163369523,-3.0125659817965165
3.1835950332245155,0.0030927999999999997,172.79475338638696,317.60234163369523,-3.0125659817965165
3.2066526278779786,0.0031152,172.8716033764304,317.60234163369523,-3.0125659817965165
3.2371215922414827,0.0031447999999999997,172.9728254083407,317.60234163369523,-3.0125659817965165
3.247826904044876,0.0031552,173.00830160751764,317.60234163369523,-3.0125659817965165
3.2700610131750008,0.0031768,173.0818375574413,317.60234163369523,-3.0125659817965165
3.2741784407916903,0.0031807999999999997,173.09543390041895,317.60234163369523,-3.0125659817965165
3.2766488973617043,0.0031831999999999997,173.10358850549505,317.60234163369523,-3.0125659817965165
3.281589810501732,0.003188,173.1198905257828,317.60234163369523,-3.0125659817965165
3.301353463061843,0.0032072,173.185003108763,317.60234163369523,-3.0125659817965165
3.315352716958588,0.0032208,173.23103257598072,317.60234163369523,-3.0125659817965165
3.3235875721919674,0.0032288,173.25807332488745,317.60234163369523,-3.0125659817965165
3.3268815142853194,0.003232,173.26888230666293,317.60234163369523,-3.0125659817965165
3.329351970855333,0.0032343999999999997,173.2769863041754,317.60234163369523,-3.0125659817965165
3.3367633405653745,0.0032416,173.30128423715868,317.60234163369523,-3.0125659817965165
3.3664088194055406,0.0032703999999999997,173.3982662279898,317.60234163369523,-3.0125659817965165
3.391113385105679,0.0032944,173.47883037882355,317.60234163369523,-3.0125659817965165
3.411700523189128,0.0033144,173.54579246724742,317.60234163369523,-3.0125659817965165
3.41499446528248,0.0033176,173.5564917601826,317.60234163369523,-3.0125659817965165
3.4421694875526323,0.0033439999999999998,173.6446078791438,317.60234163369523,-3.0125659817965165
3.4561687414493774,0.0033575999999999996,173.68989512465973,317.60234163369523,-3.0125659817965165
3.4578157124960534,0.0033591999999999997,173.695218328476,317.60234163369523,-3.0125659817965165
3.462756625636081,0.003364,173.71118201010918,317.60234163369523,-3.0125659817965165
3.480873307149516,0.0033816,173.76963966101158,317.60234163369523,-3.0125659817965165
3.496519532092937,0.0033967999999999997,173.82003038897867,317.60234163369523,-3.0125659817965165
3.5327528951198066,0.0034319999999999997,173.93638828110792,317.60234163369523,-3.0125659817965165
3.5533400332032556,0.0034519999999999998,174.00229335380305,317.60234163369523,-3.0125659817965165
3.576397627856718,0.0034744,174.07593049669433,317.60234163369523,-3.0125659817965165
3.6060431066968843,0.0035031999999999997,174.17033533262196,317.60234163369523,-3.0125659817965165
3.614277961930264,0.0035112,174.19650511942817,317.60234163369523,-3.0125659817965165
3.624983273733657,0.0035215999999999997,174.2304911038137,317.60234163369523,-3.0125659817965165
3.641452984200416,0.0035375999999999997,174.2827008999129,317.60234163369523,-3.0125659817965165
3.647217382863782,0.0035432,174.30095256102115,317.60234163369523,-3.0125659817965165
3.6727454340872585,0.003568,174.3816464938218,317.60234163369523,-3.0125659817965165
3.6900386300773556,0.0035848,174.43618588414958,317.60234163369523,-3.0125659817965165
3.722978051010873,0.0036168,174.53979546036857,317.60234163369523,-3.0125659817965165
3.7559174719443913,0.0036488,174.6430481356546,317.60234163369523,-3.0125659817965165
3.7707402113644743,0.0036631999999999997,174.68939656118303,317.60234163369523,-3.0125659817965165
3.7748576389811643,0.0036672,174.70225850662078,317.60234163369523,-3.0125659817965165
3.7888568928779094,0.0036807999999999997,174.74594825342018,317.60234163369523,-3.0125659817965165
3.797915233634627,0.0036896,174.77418454565264,317.60234163369523,-3.0125659817965165
3.813561458578048,0.0037048,174.8228945378186,317.60234163369523,-3.0125659817965165
3.8209728282880895,0.003712,174.84594048299687,317.60234163369523,-3.0125659817965165
3.8489713360815796,0.0037392,174.93284606121824,317.60234163369523,-3.0125659817965165
3.8572061913149596,0.0037472,174.95835955906355,317.60234163369523,-3.0125659817965165
3.8621471044549867,0.0037519999999999997,174.97365746129148,317.60234163369523,-3.0125659817965165
3.8860281846317877,0.0037752,175.04748999333913,317.60234163369523,-3.0125659817965165
3.8967334964351807,0.0037855999999999996,175.0805298719895,317.60234163369523,-3.0125659817965165
3.9066153227152363,0.0037952,175.11099681521873,317.60234163369523,-3.0125659817965165
3.9230850331819953,0.0038112,175.16170834787496,317.60234163369523,-3.0125659817965165
3.962612338302217,0.0038496,175.2830784603305,317.60234163369523,-3.0125659817965165
3.968376736965583,0.0038552,175.30073873956337,317.60234163369523,-3.0125659817965165
3.97331765010561,0.0038599999999999997,175.3158681603398,317.60234163369523,-3.0125659817965165
3.988963875049031,0.0038751999999999997,175.36372965848423,317.60234163369523,-3.0125659817965165
3.993081302665721,0.0038791999999999997,175.37631261386113,317.60234163369523,-3.0125659817965165
4.0021396434224386,0.003888,175.4039773176659,317.60234163369523,-3.0125659817965165
4.032608607785943,0.0039176,175.49685262716926,317.60234163369523,-3.0125659817965165
4.059783630056095,0.003944,175.57945671773146,317.60234163369523,-3.0125659817965165
4.110839732503048,0.0039936,175.7340714488259,317.60234163369523,-3.0125659817965165
4.116604131166413,0.0039992,175.7514807729076,317.60234163369523,-3.0125659817965165
4.710455799129564,0.004576115223044609,177.49717751850835,317.60234163369523,-3.0125659817965165
5.224413557244068,0.005075415083016604,178.93969306180463,317.60234163369523,-3.0125659817965165
5.501160042382647,0.005344268853770755,179.69343979310972,317.60234163369523,-3.0125659817965165
5.995350194415823,0.005824364872974595,181.00360810719644,317.60234163369523,-3.0125659817965165
6.390702316042365,0.0062084416883376676,182.02164011299294,317.60234163369523,-3.0125659817965165
6.884892468075543,0.0066885377075415085,183.26026167656227,317.60234163369523,-3.0125659817965165
7.062800922807486,0.006861372274454891,183.6976107823541,317.60234163369523,-3.0125659817965165
7.339547407946064,0.007130226045209041,184.36948630026245,317.60234163369523,-3.0125659817965165
7.418617832271372,0.007207041408281656,184.55962642553487,317.60234163369523,-3.0125659817965165
7.7151319234912785,0.00749509901980396,185.2657203131366,317.60234163369523,-3.0125659817965165
8.011646014711184,0.007783156631326265,185.9613065602471,317.60234163369523,-3.0125659817965165
8.446533348500381,0.008205641128225645,186.96360364677102,317.60234163369523,-3.0125659817965165
9.237237591753464,0.00897379475895179,188.73583157286063,317.60234163369523,-3.0125659817965165
9.889568592437257,0.00960752150430086,190.15376004865124,317.60234163369523,-3.0125659817965165
9.968639016762566,0.009684336867373475,190.32311553757214,317.60234163369523,-3.0125659817965165
10.186082683657164,0.009895579115823165,190.7861630763118,317.60234163369523,-3.0125659817965165
10.798878472178302,0.010490898179635926,192.07081733179365,317.60234163369523,-3.0125659817965165
10.957019320828918,0.010644528905781155,192.39768525837079,317.60234163369523,-3.0125659817965165
11.312836230292806,0.01099019803960792,193.12648467882045,317.60234163369523,-3.0125659817965165
11.62911792759404,0.011297459491898379,193.76683386745012,317.60234163369523,-3.0125659817965165
11.82679398840731,0.011489497899579915,194.16360463088103,317.60234163369523,-3.0125659817965165
12.004702443139255,0.0116623324664933,194.5184923458364,317.60234163369523,-3.0125659817965165
12.22214611003385,0.011873574714942988,194.94947057007596,317.60234163369523,-3.0125659817965165
12.30121653435916,0.011950390078015603,195.10544717861472,317.60234163369523,-3.0125659817965165
12.617498231660393,0.01225765153030606,195.72548272331133,317.60234163369523,-3.0125659817965165
13.30936444450684,0.012929785957191438,197.0610592820108,317.60234163369523,-3.0125659817965165
13.447737687076131,0.013064212842568514,197.32489472151357,317.60234163369523,-3.0125659817965165
13.98146305127196,0.013582716543308662,198.33277924166057,317.60234163369523,-3.0125659817965165
14.515188415467792,0.01410122024404881,199.3257654536742,317.60234163369523,-3.0125659817965165
14.890772931013007,0.01446609321864373,200.0160139754724,317.60234163369523,-3.0125659817965165
15.06868138574495,0.014638927785557112,200.34060085022253,317.60234163369523,-3.0125659817965165
15.167519416151586,0.01473494698939788,200.52028099516605,317.60234163369523,-3.0125659817965165
15.721012386428745,0.015272654530906182,201.5181763018853,317.60234163369523,-3.0125659817965165
16.65008987225112,0.016175235047009403,203.16294204246853,317.60234163369523,-3.0125659817965165
16.986139175633674,0.016501700340068013,203.7489901561132,317.60234163369523,-3.0125659817965165
17.539632145910833,0.017039407881576315,204.70448308291373,317.60234163369523,-3.0125659817965165
17.934984267537377,0.017423484696939388,205.37979162782273,317.60234163369523,-3.0125659817965165
18.25126596483861,0.017730746149229846,205.9158675052625,317.60234163369523,-3.0125659817965165
18.64661808646515,0.01811482296459292,206.58089440480163,317.60234163369523,-3.0125659817965165
18.883829359441076,0.018345269053810762,206.97727139527004,317.60234163369523,-3.0125659817965165
19.53616036012487,0.018978995799159834,208.05741925490523,317.60234163369523,-3.0125659817965165
20.08965333040203,0.019516703340668136,208.9629213800255,317.60234163369523,-3.0125659817965165
20.583843482435206,0.019996799359871975,209.76321544088586,317.60234163369523,-3.0125659817965165
21.038498422305725,0.020438487697539507,210.492892109751,317.60234163369523,-3.0125659817965165
21.29547730136298,0.020688137627525506,210.90259718889396,317.60234163369523,-3.0125659817965165
21.512920968257575,0.020899379875975194,211.2477668989468,317.60234163369523,-3.0125659817965165
22.007111120290755,0.021379475895179037,212.02722281854454,317.60234163369523,-3.0125659817965165
22.22455478718535,0.021590718143628725,212.36801759505283,317.60234163369523,-3.0125659817965165
22.44199845407995,0.021801960392078417,212.70751444182773,317.60234163369523,-3.0125659817965165
22.679209727055877,0.02203240648129626,213.07641484641286,317.60234163369523,-3.0125659817965165
23.054794242601087,0.022397279455891178,213.65744441120327,317.60234163369523,-3.0125659817965165
23.351308333820995,0.022685337067413484,214.11354838444365,317.60234163369523,-3.0125659817965165
23.548984394634267,0.02287737547509502,214.41636347424938,317.60234163369523,-3.0125659817965165
24.06294215274877,0.023376675335067015,215.19907919710474,317.60234163369523,-3.0125659817965165
24.26061821356204,0.02356871374274855,215.49838418734726,317.60234163369523,-3.0125659817965165
24.45829427437531,0.023760752150430085,215.79673956456932,317.60234163369523,-3.0125659817965165
24.5966675169446,0.023895179035807162,216.0050290210485,317.60234163369523,-3.0125659817965165
24.95248442640849,0.024240848169633927,216.5385428515851,317.60234163369523,-3.0125659817965165
25.3280689419537,0.024605721144228845,217.09848744183262,317.60234163369523,-3.0125659817965165
25.980399942637497,0.025239447889577916,218.06338639060854,317.60234163369523,-3.0125659817965165
26.355984458182707,0.025604320864172834,218.6146476260586,317.60234163369523,-3.0125659817965165
27.02808306494783,0.026257251450290058,219.5935285625958,317.60234163369523,-3.0125659817965165
27.30482955008641,0.02652610522104421,219.9938324158931,317.60234163369523,-3.0125659817965165
27.581576035224987,0.02679495899179836,220.39255703030767,317.60234163369523,-3.0125659817965165
28.332745066315418,0.027524704940988198,221.4670212770039,317.60234163369523,-3.0125659817965165
29.103681703487176,0.02827365473094619,222.55827029817712,317.60234163369523,-3.0125659817965165
29.222287339975136,0.028388877775555113,222.72514885252087,317.60234163369523,-3.0125659817965165
30.25020285620414,0.0293874774954991,224.1605294134244,317.60234163369523,-3.0125659817965165
30.42811131093609,0.029560312062412483,224.4070170048554,317.60234163369523,-3.0125659817965165
30.724625402155993,0.029848369673934786,224.81658429376415,317.60234163369523,-3.0125659817965165
30.764160614318644,0.029886777355471093,224.87107656194803,317.60234163369523,-3.0125659817965165
31.060674705538553,0.0301748349669934,225.27890160038694,317.60234163369523,-3.0125659817965165
31.39672400892111,0.03050130026005201,225.73927224275292,317.60234163369523,-3.0125659817965165
32.02928740352358,0.031115823164632926,226.6006722609294,317.60234163369523,-3.0125659817965165
32.38510431298747,0.031461492298459695,227.0822935206433,317.60234163369523,-3.0125659817965165
33.41301982921647,0.03246009201840368,228.46218499949086,317.60234163369523,-3.0125659817965165
34.480470557608136,0.03349709941988398,229.8777368077822,317.60234163369523,-3.0125659817965165
34.95489310355999,0.033957991598319665,230.50137381209254,317.60234163369523,-3.0125659817965165
35.25140719477989,0.034246049209841964,230.8894710632355,317.60234163369523,-3.0125659817965165
35.44908325559316,0.034438087617523504,231.1474955020587,317.60234163369523,-3.0125659817965165
35.52815367991847,0.03451490298059612,231.25054808396757,317.60234163369523,-3.0125659817965165
35.88397058938236,0.03486057211442288,231.71318224679192,317.60234163369523,-3.0125659817965165
36.43746355965952,0.03539827965593119,232.4292951018039,317.60234163369523,-3.0125659817965165
37.08979456034331,0.03603200640128025,233.2678614797607,317.60234163369523,-3.0125659817965165
37.56421710629515,0.03649289857971594,233.87411933610827,317.60234163369523,-3.0125659817965165
37.781660773189756,0.03670414082816563,234.15098881912297,317.60234163369523,-3.0125659817965165
38.31538613738559,0.03722264452890578,234.8279558723337,317.60234163369523,-3.0125659817965165
38.94794953198805,0.037837167433486696,235.62554319651954,317.60234163369523,-3.0125659817965165
39.22469601712664,0.03810602120424085,235.97289729970078,317.60234163369523,-3.0125659817965165
39.56074532050919,0.03843248649729945,236.39340212905995,317.60234163369523,-3.0125659817965165
39.89679462389175,0.03875895179035807,236.81251616963223,317.60234163369523,-3.0125659817965165
40.41075238200625,0.03925825165033006,237.45086086871805,317.60234163369523,-3.0125659817965165
40.647963654982185,0.03948869773954791,237.7444128209527,317.60234163369523,-3.0125659817965165
40.70726647322617,0.039546309261852375,237.81769632399372,317.60234163369523,-3.0125659817965165
40.904942534039435,0.03973834766953391,238.0616745167901,317.60234163369523,-3.0125659817965165
41.04331577660872,0.03987277455491098,238.23218572818723,317.60234163369523,-3.0125659817965165
41.69564677729252,0.04050650130026005,239.03302384015674,317.60234163369523,-3.0125659817965165
42.051463686756406,0.040852170434086815,239.46778452173322,317.60234163369523,-3.0125659817965165
42.1898369293257,0.0409865973194639,239.63647037137133,317.60234163369523,-3.0125659817965165
42.664259475277554,0.04144748949789959,240.21319082348356,317.60234163369523,-3.0125659817965165
42.86193553609082,0.04163952790558112,240.45275221246953,317.60234163369523,-3.0125659817965165
43.02007638474144,0.04179315863172635,240.64409123012626,317.60234163369523,-3.0125659817965165
43.178217233392054,0.04194678935787158,240.83515613396352,317.60234163369523,-3.0125659817965165
43.435196112449304,0.04219643928785757,241.14505555824027,317.60234163369523,-3.0125659817965165
43.81078062799452,0.042561312262452494,241.5967023196086,317.60234163369523,-3.0125659817965165
44.384041204353004,0.04311822364472895,242.2831574156967,317.60234163369523,-3.0125659817965165
44.42357641651565,0.04315663132626525,242.3303712965281,317.60234163369523,-3.0125659817965165
44.85846375030485,0.043579115823164635,242.84864705080298,317.60234163369523,-3.0125659817965165
45.1154426293621,0.04382876575315063,243.15397987116154,317.60234163369523,-3.0125659817965165
45.35265390233802,0.04405921184236847,243.4352240686386,317.60234163369523,-3.0125659817965165
45.49102714490732,0.04419363872774555,243.5990182502858,317.60234163369523,-3.0125659817965165
45.96544969085917,0.04465453090618124,244.1591290379459,317.60234163369523,-3.0125659817965165
46.08405532734714,0.044769753950790164,244.29880389284907,317.60234163369523,-3.0125659817965165
46.242196175997755,0.04492338467693539,244.48481914471392,317.60234163369523,-3.0125659817965165
46.47940744897367,0.04515383076615323,244.76337751973668,317.60234163369523,-3.0125659817965165
46.93406238884419,0.04559551910382076,245.2957362011165,317.60234163369523,-3.0125659817965165
47.329414510470734,0.04597959591918384,245.75702405602513,317.60234163369523,-3.0125659817965165
48.04104832939851,0.04667093418683736,246.5835729519334,317.60234163369523,-3.0125659817965165
48.59454129967567,0.04720864172834567,247.22314743875546,317.60234163369523,-3.0125659817965165
49.167801876034154,0.047765553110622125,247.8825759249692,317.60234163369523,-3.0125659817965165
49.642224421986,0.04822644528905781,248.4260452449579,317.60234163369523,-3.0125659817965165
50.25502021050713,0.04882176435287057,249.12503785353266,317.60234163369523,-3.0125659817965165
50.393393453076435,0.048956191238247654,249.28241392196946,317.60234163369523,-3.0125659817965165
51.085259665922884,0.04962832566513303,250.06678039024064,317.60234163369523,-3.0125659817965165
51.2434005145735,0.04978195639127826,250.2454811587591,317.60234163369523,-3.0125659817965165
51.44107657538677,0.049973994798959795,250.4685549543324,317.60234163369523,-3.0125659817965165
51.856196303094634,0.05037727545509102,250.93592465767728,317.60234163369523,-3.0125659817965165
52.17247800039587,0.05068453690738148,251.2910371350828,317.60234163369523,-3.0125659817965165
52.42945687945312,0.05093418683736747,251.57894821657868,317.60234163369523,-3.0125659817965165
52.923647031486304,0.05141428285657132,252.13108120151608,317.60234163369523,-3.0125659817965165
53.062020274055584,0.05154870974194839,252.28531764581507,317.60234163369523,-3.0125659817965165
53.37830197135682,0.05185597119423885,252.6372702641101,317.60234163369523,-3.0125659817965165
53.971330153796636,0.05243208641728346,253.29499702960834,317.60234163369523,-3.0125659817965165
54.03063297204062,0.05248969793958792,253.36061430675838,317.60234163369523,-3.0125659817965165
54.228309032853886,0.052681736347269456,253.57913599091717,317.60234163369523,-3.0125659817965165
55.1178513065136,0.05354590918183637,254.55866434701178,317.60234163369523,-3.0125659817965165
55.88878794368535,0.054294858971794355,255.40261234862334,317.60234163369523,-3.0125659817965165
56.52135133828782,0.05490938187637527,256.091696661335,317.60234163369523,-3.0125659817965165
56.7190273991011,0.05510142028405682,256.3064178433274,317.60234163369523,-3.0125659817965165
56.7980978234264,0.055178235647129426,256.39222457342237,317.60234163369523,-3.0125659817965165
57.13414712680897,0.05550470094018804,256.7563846645916,317.60234163369523,-3.0125659817965165
57.2329851572156,0.05560072014402881,256.8633314746268,317.60234163369523,-3.0125659817965165
57.64810488492347,0.056004000800160034,257.3117237840975,317.60234163369523,-3.0125659817965165
58.300435885607264,0.05663772754550911,258.0138044307878,317.60234163369523,-3.0125659817965165
58.359738703851235,0.05669533906781356,258.0774776377445,317.60234163369523,-3.0125659817965165
58.95276688629105,0.05727145429085817,258.7128279651456,317.60234163369523,-3.0125659817965165
59.52602746264954,0.057828365673134624,259.3246348418107,317.60234163369523,-3.0125659817965165
59.703935917381486,0.05800120024004801,259.5140381535644,317.60234163369523,-3.0125659817965165
60.5934781910412,0.058865373074614924,260.4577729914022,317.60234163369523,-3.0125659817965165
60.98883031266774,0.05924944988997799,260.87547469075645,317.60234163369523,-3.0125659817965165
61.186506373481016,0.05944148829765954,261.0839294438339,317.60234163369523,-3.0125659817965165
61.52255567686357,0.05976795359071814,261.43770075337005,317.60234163369523,-3.0125659817965165
62.53070358701125,0.06074734946989398,262.4945203542885,317.60234163369523,-3.0125659817965165
62.74814725390585,0.06095859171834367,262.7215882620604,317.60234163369523,-3.0125659817965165
62.886520496475136,0.06109301860372074,262.86592625636155,317.60234163369523,-3.0125659817965165
63.26210501202035,0.06145789157831566,263.2570777983292,317.60234163369523,-3.0125659817965165
63.49931628499628,0.06168833766753351,263.5036543054103,317.60234163369523,-3.0125659817965165
64.23071771000538,0.06239887977595519,264.26168014760975,317.60234163369523,-3.0125659817965165
64.40862616473733,0.06257171434286858,264.44555489026465,317.60234163369523,-3.0125659817965165
65.08072477150245,0.0632246449289858,265.1384124738774,317.60234163369523,-3.0125659817965165
65.65398534786094,0.06378155631126226,265.727176924953,317.60234163369523,-3.0125659817965165
66.24701353030075,0.06435767153430687,266.33413763168227,317.60234163369523,-3.0125659817965165
66.48422480327667,0.0645881176235247,266.57632814412926,317.60234163369523,-3.0125659817965165
66.95864734922851,0.06504900980196039,267.05970051277166,317.60234163369523,-3.0125659817965165
67.03771777355384,0.06512582516503301,267.1401325390767,317.60234163369523,-3.0125659817965165
67.27492904652975,0.06535627125425085,267.3812069178289,317.60234163369523,-3.0125659817965165
67.59121074383098,0.06566353270654131,267.70212437227593,317.60234163369523,-3.0125659817965165
67.69004877423762,0.06575955191038207,267.8022909020789,317.60234163369523,-3.0125659817965165
68.30284456275876,0.06635487097419485,268.42205504912135,317.60234163369523,-3.0125659817965165
68.52028822965336,0.06656611322264454,268.64144960633257,317.60234163369523,-3.0125659817965165
68.71796429046664,0.06675815163032607,268.84066369232664,317.60234163369523,-3.0125659817965165
69.19238683641848,0.06721904380876176,269.3178678411724,317.60234163369523,-3.0125659817965165
69.48890092763838,0.06750710142028406,269.6154725185049,317.60234163369523,-3.0125659817965165
69.60750656412635,0.06762232446489298,269.7343756669421,317.60234163369523,-3.0125659817965165
70.04239389791555,0.06804480896179237,270.1696795059038,317.60234163369523,-3.0125659817965165
70.12146432224085,0.06812162432486497,270.24871228043537,317.60234163369523,-3.0125659817965165
71.28775308103916,0.06925465093018604,271.410438128219,317.60234163369523,-3.0125659817965165
71.72264041482835,0.06967713542708542,271.84172373109266,317.60234163369523,-3.0125659817965165
72.13776014253622,0.07008041608321665,272.2524550405922,317.60234163369523,-3.0125659817965165
72.31566859726817,0.07025325065013004,272.4282004490425,317.60234163369523,-3.0125659817965165
72.86916156754532,0.07079095819163833,272.97388869527225,317.60234163369523,-3.0125659817965165
73.06683762835858,0.07098299659931986,273.16838529075653,317.60234163369523,-3.0125659817965165
73.60056299255442,0.07150150030006001,273.6925037594384,317.60234163369523,-3.0125659817965165
73.89707708377433,0.07178955791158233,273.9830401396861,317.60234163369523,-3.0125659817965165
74.35173202364486,0.07223124624924986,274.4276477719478,317.60234163369523,-3.0125659817965165
74.74708414527139,0.07261532306461292,274.8134019310352,317.60234163369523,-3.0125659817965165
75.2610419033859,0.07311462292458493,275.31369481302676,317.60234163369523,-3.0125659817965165
75.47848557028048,0.0733258651730346,275.5249558758149,317.60234163369523,-3.0125659817965165
75.59709120676845,0.07344108821764353,275.64008913387187,317.60234163369523,-3.0125659817965165
76.17035178312693,0.07399799959991998,276.1955764909699,317.60234163369523,-3.0125659817965165
76.36802784394021,0.07419003800760153,276.3867454993799,317.60234163369523,-3.0125659817965165
76.5064010865095,0.0743244648929786,276.5204489954535,317.60234163369523,-3.0125659817965165
76.58547151083481,0.07440128025605121,276.5968086492676,317.60234163369523,-3.0125659817965165
76.88198560205471,0.07468933786757352,276.882883929103,317.60234163369523,-3.0125659817965165
77.98897154260904,0.07576475295059013,277.9471176615535,317.60234163369523,-3.0125659817965165
78.66107014937415,0.07641768353670735,278.5903857694072,317.60234163369523,-3.0125659817965165
79.0564222710007,0.07680176035207043,278.96777749787003,317.60234163369523,-3.0125659817965165
80.3017814541243,0.0780116023204641,280.1517788588417,317.60234163369523,-3.0125659817965165
80.42038709061227,0.07812682536507302,280.26416609677045,317.60234163369523,-3.0125659817965165
81.01341527305206,0.07870294058811762,280.8251355594113,317.60234163369523,-3.0125659817965165
81.34946457643463,0.07902940588117624,281.1423073400389,317.60234163369523,-3.0125659817965165
81.66574627373586,0.0793366673334667,281.4403554975422,317.60234163369523,-3.0125659817965165
82.39714769874497,0.08004720944188838,282.1278729738597,317.60234163369523,-3.0125659817965165
82.85180263861548,0.08048889777955591,282.55404929693583,317.60234163369523,-3.0125659817965165
83.06924630551008,0.0807001400280056,282.7575502536545,317.60234163369523,-3.0125659817965165
83.46459842713664,0.08108421684336868,283.1270205425914,317.60234163369523,-3.0125659817965165
84.01809139741378,0.08162192438487698,283.6431343408637,317.60234163369523,-3.0125659817965165
84.70995761026023,0.08229405881176236,284.28641566757307,317.60234163369523,-3.0125659817965165
85.0460069136428,0.08262052410482097,284.59812699911555,317.60234163369523,-3.0125659817965165
85.54019706567597,0.0831006201240248,285.0556548088934,317.60234163369523,-3.0125659817965165
85.65880270216394,0.08321584316863373,285.16530794926945,317.60234163369523,-3.0125659817965165
85.91578158122118,0.08346549309861973,285.40268682550794,317.60234163369523,-3.0125659817965165
86.42973933933568,0.08396479295859172,285.8766154916301,317.60234163369523,-3.0125659817965165
86.60764779406763,0.0841376275255051,286.0404114768886,317.60234163369523,-3.0125659817965165
87.0227675217755,0.08454090818163633,286.4220926489812,317.60234163369523,-3.0125659817965165
87.14137315826346,0.08465613122624525,286.5310139051256,317.60234163369523,-3.0125659817965165
87.4576548555647,0.08496339267853571,286.8211882968552,317.60234163369523,-3.0125659817965165
88.22859149273646,0.0857123424684937,287.5267791080945,317.60234163369523,-3.0125659817965165
88.50533797787503,0.08598119623924785,287.7794810850678,317.60234163369523,-3.0125659817965165
88.623943614363,0.08609641928385678,287.88768757488094,317.60234163369523,-3.0125659817965165
89.03906334207086,0.086499699939988,288.26596633553385,317.60234163369523,-3.0125659817965165
89.47395067586007,0.08692218443688739,288.66152139260043,317.60234163369523,-3.0125659817965165
89.73092955491731,0.08717183436687338,288.89490603805314,317.60234163369523,-3.0125659817965165
90.71930985898366,0.08813202640528106,289.79012042457674,317.60234163369523,-3.0125659817965165
91.13442958669154,0.08853530706141229,290.16497525275787,317.60234163369523,-3.0125659817965165
91.29257043534216,0.08868893778755751,290.3076018571854,317.60234163369523,-3.0125659817965165
91.92513382994461,0.08930346069213843,290.87714736048815,317.60234163369523,-3.0125659817965165
92.53792961846575,0.08989877975595119,291.4274387736656,317.60234163369523,-3.0125659817965165
92.7158380731977,0.09007161432286458,291.58693436317554,317.60234163369523,-3.0125659817965165
92.99258455833628,0.09034046809361873,291.83480157417534,317.60234163369523,-3.0125659817965165
93.17049301306821,0.0905133026605321,291.9939928790353,317.60234163369523,-3.0125659817965165
93.6646831651014,0.09099339867973595,292.43557013165054,317.60234163369523,-3.0125659817965165
94.0995704988906,0.09141588317663533,292.8234070399429,317.60234163369523,-3.0125659817965165
94.51469022659846,0.09181916383276656,293.1929634175839,317.60234163369523,-3.0125659817965165
94.910042348225,0.09220324064812963,293.5443337925271,317.60234163369523,-3.0125659817965165
95.00888037863164,0.0922992598519704,293.63208713830875,317.60234163369523,-3.0125659817965165
95.28562686377022,0.09256811362272455,293.87760730024087,317.60234163369523,-3.0125659817965165
95.79958462188472,0.09306741348269654,294.3328367539054,317.60234163369523,-3.0125659817965165
96.09609871310464,0.09335547109421885,294.59503585858414,317.60234163369523,-3.0125659817965165
97.04494380500833,0.09427725545109022,295.4319605548714,317.60234163369523,-3.0125659817965165
97.44029592663486,0.09466133226645329,295.77973658639246,317.60234163369523,-3.0125659817965165
97.57866916920416,0.09479575915183037,295.90132812976594,317.60234163369523,-3.0125659817965165
98.1914649577253,0.09539107821564313,296.43899867942736,317.60234163369523,-3.0125659817965165
98.31007059421327,0.09550630126025206,296.54291262294436,317.60234163369523,-3.0125659817965165
98.52751426110787,0.09571754350870175,296.73329462257186,317.60234163369523,-3.0125659817965165
99.41705653476758,0.09658171634326866,297.51042983251085,317.60234163369523,-3.0125659817965165
99.6542678077435,0.0968121624324865,297.71720728873476,317.60234163369523,-3.0125659817965165
100.02985232328872,0.09717703540708142,298.0442127796902,317.60234163369523,-3.0125659817965165
100.06938753545137,0.09721544308861772,298.0786065318815,317.60234163369523,-3.0125659817965165
100.84032417262313,0.09796439287857572,298.7482291331993,317.60234163369523,-3.0125659817965165
101.09730305168038,0.09821404280856172,298.97099260126174,317.60234163369523,-3.0125659817965165
101.17637347600568,0.09829085817163433,299.03949076439346,317.60234163369523,-3.0125659817965165
101.255443900331,0.09836767353470695,299.10796805320393,317.60234163369523,-3.0125659817965165
101.41358474898162,0.09852130426085218,299.2448600984371,317.60234163369523,-3.0125659817965165
101.63102841587622,0.09873254650930187,299.43295080498683,317.60234163369523,-3.0125659817965165
101.86823968885213,0.0989629925985197,299.63796176013017,317.60234163369523,-3.0125659817965165
102.16475378007205,0.09925105021004202,299.89396382434984,317.60234163369523,-3.0125659817965165
102.24382420439734,0.09932786557311463,299.9621820820594,317.60234163369523,-3.0125659817965165
102.56010590169858,0.09963512702540508,300.23484961350727,317.60234163369523,-3.0125659817965165
102.77754956859319,0.09984636927385478,300.4221183400968,317.60234163369523,-3.0125659817965165