File: datasets/aisi_316_L/data/M1/valid_32.csv
Time(s),Strain(%),Stress(MPa),Temp(C),Log_SR(s-1)
0.0,0.0,0.0,250.59513496469975,5.253021153103479
1.5189649439291536e-10,2.7199999999999997e-05,4.94474155,250.59513496469975,5.253021153103479
2.0997456577844183e-10,3.76e-05,6.835378025,250.59513496469975,5.253021153103479
3.127280766912963e-10,5.6e-05,10.18035025,250.59513496469975,5.253021153103479
4.422868513205477e-10,7.92e-05,14.397923925,250.59513496469975,5.253021153103479
6.254561533825926e-10,0.000112,20.3607005,250.59513496469975,5.253021153103479
6.477938731462567e-10,0.000116,21.087868375,250.59513496469975,5.253021153103479
7.326772082481799e-10,0.0001312,23.851106299999998,250.59513496469975,5.253021153103479
8.845737026410954e-10,0.0001584,28.79584785,250.59513496469975,5.253021153103479
9.203140542629577e-10,0.0001648,29.95931645,250.59513496469975,5.253021153103479
9.783921256484842e-10,0.0001752,31.849952925,250.59513496469975,5.253021153103479
1.0498728288922091e-09,0.000188,34.176890125,250.59513496469975,5.253021153103479
1.1258210760886668e-09,0.0002016,36.6492609,250.59513496469975,5.253021153103479
1.2241070430487885e-09,0.0002192,39.848799549999995,250.59513496469975,5.253021153103479
1.282185114434315e-09,0.0002296,41.739436024999996,250.59513496469975,5.253021153103479
1.411743889063566e-09,0.00025279999999999996,45.95700969999999,250.59513496469975,5.253021153103479
1.5457702076455506e-09,0.0002768,50.32001695,250.59513496469975,5.253021153103479
1.670861438322069e-09,0.0002992,54.39215705,250.59513496469975,5.253021153103479
1.8048877569040531e-09,0.0003232,58.7551643,250.59513496469975,5.253021153103479
1.8808360041005108e-09,0.0003368,61.227535075,250.59513496469975,5.253021153103479
1.9969921468715636e-09,0.00035759999999999996,65.008808025,250.59513496469975,5.253021153103479
2.037200042446159e-09,0.0003648,66.3177102,250.59513496469975,5.253021153103479
2.104213201737151e-09,0.0003768,68.499213825,250.59513496469975,5.253021153103479
2.171226361028143e-09,0.00038879999999999996,70.68071744999999,250.59513496469975,5.253021153103479
2.242707064271868e-09,0.0004016,73.00765465,250.59513496469975,5.253021153103479
2.327590399373791e-09,0.0004168,75.770892575,250.59513496469975,5.253021153103479
2.399071102617516e-09,0.0004296,78.097829775,250.59513496469975,5.253021153103479
2.488421981672172e-09,0.0004456,81.006501275,250.59513496469975,5.253021153103479
2.5688377728213627e-09,0.00045999999999999996,83.62430562499999,250.59513496469975,5.253021153103479
2.653721107923286e-09,0.0004752,86.38754355,250.59513496469975,5.253021153103479
2.9351763769454526e-09,0.0005256,95.54985877499999,250.59513496469975,5.253021153103479
3.0066570801891773e-09,0.0005384,97.876795975,250.59513496469975,5.253021153103479
3.069202695527437e-09,0.0005496,99.912866025,250.59513496469975,5.253021153103479
3.198761470156688e-09,0.0005727999999999999,104.13043969999998,250.59513496469975,5.253021153103479
3.2836448052586112e-09,0.000588,106.893677625,250.59513496469975,5.253021153103479
3.435541299651527e-09,0.0006152,111.838419175,250.59513496469975,5.253021153103479
3.457879019415191e-09,0.0006192,112.56558704999999,250.59513496469975,5.253021153103479
3.614243057760839e-09,0.0006472,117.655762175,250.59513496469975,5.253021153103479
3.784009727964686e-09,0.0006776,123.182238025,250.59513496469975,5.253021153103479
3.8108149916810826e-09,0.0006824,124.054839475,250.59513496469975,5.253021153103479
3.958243942121265e-09,0.0007088,128.85414745,250.59513496469975,5.253021153103479
4.159283419994241e-09,0.0007448,135.398658325,250.59513496469975,5.253021153103479
4.2620369309070954e-09,0.0007632,138.74363055,250.59513496469975,5.253021153103479
4.480946584591003e-09,0.0008024,145.86987572499999,250.59513496469975,5.253021153103479
4.570297463645659e-09,0.0008183999999999999,148.77854722499998,250.59513496469975,5.253021153103479
4.628375535031186e-09,0.0008288,150.6691837,250.59513496469975,5.253021153103479
4.664115886653048e-09,0.0008351999999999999,151.83265229999998,250.59513496469975,5.253021153103479
4.673050974558514e-09,0.0008368,152.12351945,250.59513496469975,5.253021153103479
4.8606878205732915e-09,0.0008703999999999999,158.2317296,250.59513496469975,5.253021153103479
5.039389578682603e-09,0.0009023999999999999,164.0490726,250.59513496469975,5.253021153103479
5.235961512602847e-09,0.0009375999999999999,170.44814989999998,250.59513496469975,5.253021153103479
5.3521176553739004e-09,0.0009584,174.22942285,250.59513496469975,5.253021153103479
5.4682737981449525e-09,0.0009792,178.01069579999998,250.59513496469975,5.253021153103479
5.566559765105075e-09,0.0009968,181.21023445,250.59513496469975,5.253021153103479
5.6827159078761275e-09,0.0010176,184.9915074,250.59513496469975,5.253021153103479
5.7318588913561886e-09,0.0010264,186.591276725,250.59513496469975,5.253021153103479
5.848015034127241e-09,0.0010471999999999999,190.372549675,250.59513496469975,5.253021153103479
5.932898369229165e-09,0.0010624,193.13578760000001,250.59513496469975,5.253021153103479
5.964171176898294e-09,0.001068,194.15382262499998,250.59513496469975,5.253021153103479
5.986508896661959e-09,0.001072,194.8809905,250.59513496469975,5.253021153103479
6.089262407574813e-09,0.0010904,198.22596272500002,250.59513496469975,5.253021153103479
6.276899253589591e-09,0.001124,204.334172875,250.59513496469975,5.253021153103479
6.317107149164186e-09,0.0011312,205.64307505,250.59513496469975,5.253021153103479
6.370717676596979e-09,0.0011408,207.38827795,250.59513496469975,5.253021153103479
6.661108033524612e-09,0.0011928,216.84146032499999,250.59513496469975,5.253021153103479
6.808536983964794e-09,0.0012192,219.3765109412783,250.59513496469975,5.253021153103479
6.942563302546778e-09,0.0012431999999999999,219.5332892116135,250.59513496469975,5.253021153103479
6.964901022310442e-09,0.0012472,219.55930373628064,250.59513496469975,5.253021153103479
7.076589621128763e-09,0.0012672,219.68889145041055,250.59513496469975,5.253021153103479
7.143602780419754e-09,0.0012791999999999999,219.76626125284247,250.59513496469975,5.253021153103479
7.201680851805281e-09,0.0012896,219.83308639983886,250.59513496469975,5.253021153103479
7.250823835285342e-09,0.0012984,219.88946675588454,250.59513496469975,5.253021153103479
7.2865641869072035e-09,0.0013047999999999998,219.9303770900243,250.59513496469975,5.253021153103479
7.433993137347386e-09,0.0013311999999999998,220.09831158356576,250.59513496469975,5.253021153103479
7.51887647244931e-09,0.0013464,220.19441189256028,250.59513496469975,5.253021153103479
7.630565071267631e-09,0.0013664,220.3202174857667,250.59513496469975,5.253021153103479
7.679708054747691e-09,0.0013752,220.37534421618994,250.59513496469975,5.253021153103479
7.751188757991416e-09,0.001388,220.4552835935295,250.59513496469975,5.253021153103479
7.894150164478865e-09,0.0014135999999999999,220.61430500570978,250.59513496469975,5.253021153103479
7.992436131438987e-09,0.0014311999999999999,220.72298128113601,250.59513496469975,5.253021153103479
8.12199490606824e-09,0.0014544,220.86544332977036,250.59513496469975,5.253021153103479
8.18900806535923e-09,0.0014663999999999999,220.9387826622857,250.59513496469975,5.253021153103479
8.291761576272085e-09,0.0014847999999999999,221.05078333526845,250.59513496469975,5.253021153103479
8.434722982759535e-09,0.0015103999999999999,221.2057140461712,250.59513496469975,5.253021153103479
8.50620368600326e-09,0.0015232,221.2827951063804,250.59513496469975,5.253021153103479
8.684905444112572e-09,0.0015551999999999999,221.47440070870852,250.59513496469975,5.253021153103479
8.747451059450831e-09,0.0015664,221.54109860772877,250.59513496469975,5.253021153103479
8.805529130836359e-09,0.0015768,221.60286602427067,250.59513496469975,5.253021153103479
8.845737026410953e-09,0.001584,221.64553503931884,250.59513496469975,5.253021153103479
8.930620361512876e-09,0.0015991999999999998,221.7353664678078,250.59513496469975,5.253021153103479
9.140594927291318e-09,0.0016367999999999999,221.9561621504121,250.59513496469975,5.253021153103479
9.185270366818647e-09,0.0016447999999999999,222.00288373608782,250.59513496469975,5.253021153103479
9.301426509589699e-09,0.0016656,222.12394696526508,250.59513496469975,5.253021153103479
9.372907212833425e-09,0.0016784,222.19815440603864,250.59513496469975,5.253021153103479
9.439920372124415e-09,0.0016903999999999999,222.2675236816238,250.59513496469975,5.253021153103479
9.497998443509943e-09,0.0017008,222.3274885155651,250.59513496469975,5.253021153103479
9.609687042328262e-09,0.0017208,222.4424050943989,250.59513496469975,5.253021153103479
9.721375641146583e-09,0.0017407999999999998,222.55680194699292,250.59513496469975,5.253021153103479
9.752648448815713e-09,0.0017464,222.5887410642452,250.59513496469975,5.253021153103479
9.766051080673912e-09,0.0017488,222.60241702740538,250.59513496469975,5.253021153103479
9.783921256484842e-09,0.0017519999999999999,222.6206402641956,250.59513496469975,5.253021153103479
9.81072652020124e-09,0.0017568,222.6479507990552,250.59513496469975,5.253021153103479
9.877739679492231e-09,0.0017687999999999998,222.71610012590148,250.59513496469975,5.253021153103479
9.944752838783223e-09,0.0017808,222.78406937574442,250.59513496469975,5.253021153103479
1.0002830910168749e-08,0.0017912,222.8428316993785,250.59513496469975,5.253021153103479
1.006537652550701e-08,0.0018024,222.90596559119214,250.59513496469975,5.253021153103479
1.0266416003379985e-08,0.0018384,223.10786745633501,250.59513496469975,5.253021153103479
1.033789670662371e-08,0.0018512,223.17928242909935,250.59513496469975,5.253021153103479
1.0436182673583832e-08,0.0018687999999999999,223.27716436584998,250.59513496469975,5.253021153103479
1.0489793201016625e-08,0.0018784,223.33040295823835,250.59513496469975,5.253021153103479
1.0605949343787679e-08,0.0018992,223.44539056915536,250.59513496469975,5.253021153103479
1.0672962503078669e-08,0.0019111999999999998,223.5115061576416,250.59513496469975,5.253021153103479
1.0789118645849723e-08,0.001932,223.6257242689022,250.59513496469975,5.253021153103479
1.0874001980951646e-08,0.0019471999999999998,223.70888829347174,250.59513496469975,5.253021153103479
1.0932080052337172e-08,0.0019576,223.7656441709,250.59513496469975,5.253021153103479
1.0985690579769967e-08,0.0019672,223.8179299260916,250.59513496469975,5.253021153103479
1.1025898475344561e-08,0.0019744,223.85707896344485,250.59513496469975,5.253021153103479
1.1061638826966425e-08,0.0019808,223.89183139014327,250.59513496469975,5.253021153103479
1.1155457249973814e-08,0.0019976,223.98284879359935,250.59513496469975,5.253021153103479
1.1347561639941323e-08,0.002032,224.16829156148782,250.59513496469975,5.253021153103479
1.1535198485956102e-08,0.0020656,224.3482433392095,250.59513496469975,5.253021153103479
1.1593276557341626e-08,0.0020759999999999997,224.40371086089627,250.59513496469975,5.253021153103479
1.1620081821058024e-08,0.0020808,224.42927469459312,250.59513496469975,5.253021153103479
1.1731770419876344e-08,0.0021008,224.5355440576832,250.59513496469975,5.253021153103479
1.1843459018694665e-08,0.0021208,224.64141958078793,250.59513496469975,5.253021153103479
1.1986420425182113e-08,0.0021463999999999997,224.77637376758955,250.59513496469975,5.253021153103479
1.2093641480047701e-08,0.0021655999999999997,224.87717783305246,250.59513496469975,5.253021153103479
1.2348291485353473e-08,0.0022112,225.11520073334486,250.59513496469975,5.253021153103479
1.2379564293022603e-08,0.0022168,225.14429905065163,250.59513496469975,5.253021153103479
1.2446577452313593e-08,0.0022288,225.20655622945714,250.59513496469975,5.253021153103479
1.2500187979746387e-08,0.0022383999999999998,225.25626790071766,250.59513496469975,5.253021153103479
1.2594006402753776e-08,0.0022551999999999997,225.3430637114934,250.59513496469975,5.253021153103479
1.266101956204477e-08,0.0022672,225.404906402266,250.59513496469975,5.253021153103479
1.271463008947756e-08,0.0022768,225.45428869126027,250.59513496469975,5.253021153103479
1.2759305529004891e-08,0.0022848,225.49537859786014,250.59513496469975,5.253021153103479
1.2857591495965012e-08,0.0023024,225.58557940138724,250.59513496469975,5.253021153103479
1.290226693549234e-08,0.0023103999999999998,225.6264908309856,250.59513496469975,5.253021153103479
1.3005020446405194e-08,0.0023288,225.72037803099352,250.59513496469975,5.253021153103479
1.3040760798027057e-08,0.0023352,225.7529665760145,250.59513496469975,5.253021153103479
1.3223930100089101e-08,0.002368,225.91943929088433,250.59513496469975,5.253021153103479
1.3255202907758232e-08,0.0023736,225.94777134871367,250.59513496469975,5.253021153103479
1.3416034490056613e-08,0.0024024,226.09306933150495,250.59513496469975,5.253021153103479
1.3518788000969466e-08,0.0024208,226.18554306517458,250.59513496469975,5.253021153103479
1.3639411687693253e-08,0.0024424,226.29375013798153,250.59513496469975,5.253021153103479
1.387619151718809e-08,0.0024847999999999997,226.50507735907192,250.59513496469975,5.253021153103479
1.3952139764384549e-08,0.0024984,226.57256305193366,250.59513496469975,5.253021153103479
1.3978945028100945e-08,0.0025031999999999997,226.59634730597392,250.59513496469975,5.253021153103479
1.4037023099486472e-08,0.0025136,226.64781892334116,250.59513496469975,5.253021153103479
1.4072763451108334e-08,0.0025199999999999997,226.67945248544132,250.59513496469975,5.253021153103479
1.4135309066446594e-08,0.0025312,226.7347359293509,250.59513496469975,5.253021153103479
1.4193387137832119e-08,0.0025415999999999998,226.78598519419495,250.59513496469975,5.253021153103479
1.424253012131218e-08,0.0025504,226.829286108804,250.59513496469975,5.253021153103479
1.4452504687090624e-08,0.002588,227.0136465827317,250.59513496469975,5.253021153103479
1.4488245038712485e-08,0.0025943999999999997,227.04492276426922,250.59513496469975,5.253021153103479
1.4506115214523417e-08,0.0025976,227.06054957028098,250.59513496469975,5.253021153103479
1.4573128373814407e-08,0.0026095999999999997,227.11908334718981,250.59513496469975,5.253021153103479
1.4613336269389003e-08,0.0026168,227.15415322830643,250.59513496469975,5.253021153103479
1.4720557324254591e-08,0.002636,227.2474894185014,250.59513496469975,5.253021153103479
1.4774167851687384e-08,0.0026455999999999997,227.29405806005047,250.59513496469975,5.253021153103479
1.4850116098883843e-08,0.0026592,227.35991764733694,250.59513496469975,5.253021153103479
1.4894791538411169e-08,0.0026671999999999998,227.39859721904315,250.59513496469975,5.253021153103479
1.4917129258174834e-08,0.0026712,227.41792003574471,250.59513496469975,5.253021153103479
1.497520732956036e-08,0.0026815999999999997,227.4681066208114,250.59513496469975,5.253021153103479
1.5010947681182223e-08,0.002688,227.49895294577553,250.59513496469975,5.253021153103479
1.507349329652048e-08,0.0026991999999999997,227.5528651809744,250.59513496469975,5.253021153103479
1.5140506455811475e-08,0.0027112,227.61053156734235,250.59513496469975,5.253021153103479
1.5261130142535262e-08,0.0027328,227.71408084121643,250.59513496469975,5.253021153103479
1.5457702076455506e-08,0.002768,227.88214648413327,250.59513496469975,5.253021153103479
1.5555988043415627e-08,0.0027856,227.96586658130127,250.59513496469975,5.253021153103479
1.5618533658753884e-08,0.0027968,228.019035614538,250.59513496469975,5.253021153103479
1.578830032895773e-08,0.0028271999999999998,228.16293462676998,250.59513496469975,5.253021153103479
1.584637840034326e-08,0.0028376,228.21202453714614,250.59513496469975,5.253021153103479
1.5891053839870586e-08,0.0028455999999999998,228.24973827453448,250.59513496469975,5.253021153103479
1.596253454311431e-08,0.0028583999999999997,228.30999435940828,250.59513496469975,5.253021153103479
1.6034015246358035e-08,0.0028712,228.3701453025713,250.59513496469975,5.253021153103479
1.6154638933081822e-08,0.0028928,228.47141341321486,250.59513496469975,5.253021153103479
1.6181444196798216e-08,0.0028975999999999997,228.49387734015988,250.59513496469975,5.253021153103479
1.6221652092372814e-08,0.0029048,228.52754603815694,250.59513496469975,5.253021153103479
1.624845735608921e-08,0.0029096,228.549973757115,250.59513496469975,5.253021153103479
1.627973016375834e-08,0.0029151999999999997,228.5761211998558,250.59513496469975,5.253021153103479
1.637801613071846e-08,0.0029327999999999997,228.65817163822084,250.59513496469975,5.253021153103479
1.647183455372585e-08,0.0029495999999999997,228.7363135586858,250.59513496469975,5.253021153103479
1.658352315254417e-08,0.0029695999999999998,228.8291136967706,250.59513496469975,5.253021153103479
1.66281985920715e-08,0.0029776,228.86616546342873,250.59513496469975,5.253021153103479
1.6963264388526458e-08,0.0030375999999999997,229.1428267428152,250.59513496469975,5.253021153103479
1.6990069652242856e-08,0.0030424,229.16486715033963,250.59513496469975,5.253021153103479
1.703027754781745e-08,0.0030496,229.1979023508171,250.59513496469975,5.253021153103479
1.719110913011583e-08,0.0030784,229.3297401042158,250.59513496469975,5.253021153103479
1.734747316846148e-08,0.0031064,229.45745530264142,250.59513496469975,5.253021153103479
1.7436824047516136e-08,0.0031224,229.5302338336341,250.59513496469975,5.253021153103479
1.7508304750759862e-08,0.0031352,229.58835199236586,250.59513496469975,5.253021153103479
1.7575317910050854e-08,0.0031471999999999997,229.64275377935923,250.59513496469975,5.253021153103479
1.766913633305824e-08,0.0031639999999999997,229.71878056975422,250.59513496469975,5.253021153103479
1.7896981074647616e-08,0.0032048,229.9027645710075,250.59513496469975,5.253021153103479
1.7990799497655005e-08,0.0032216,229.978256909797,250.59513496469975,5.253021153103479
1.8039942481135065e-08,0.0032304,230.01773923302767,250.59513496469975,5.253021153103479
1.809802055252059e-08,0.0032408,230.06434612196986,250.59513496469975,5.253021153103479
1.8325865294109964e-08,0.0032816,230.24662802561716,250.59513496469975,5.253021153103479
1.844202143688102e-08,0.0033024,230.33921575856016,250.59513496469975,5.253021153103479
1.848222933245561e-08,0.0033095999999999998,230.37121233319826,250.59513496469975,5.253021153103479
1.863412582684853e-08,0.0033368,230.4918440727107,250.59513496469975,5.253021153103479
1.8714541617997718e-08,0.0033512,230.55555264685154,250.59513496469975,5.253021153103479
1.8803892497052376e-08,0.0033672,230.62621486647313,250.59513496469975,5.253021153103479
1.8933451271681625e-08,0.0033904,230.72844292998673,250.59513496469975,5.253021153103479
1.9013867062830818e-08,0.0034048,230.79175762914835,250.59513496469975,5.253021153103479
1.903173723864175e-08,0.003408,230.8058133700152,250.59513496469975,5.253021153103479
1.9058542502358143e-08,0.0034127999999999997,230.82688733422899,250.59513496469975,5.253021153103479
1.9192568820940127e-08,0.0034368,230.9320842593636,250.59513496469975,5.253021153103479
1.9246179348372922e-08,0.0034463999999999996,230.97408276251196,250.59513496469975,5.253021153103479
1.9326595139522114e-08,0.0034608,231.0369950714997,250.59513496469975,5.253021153103479
1.9599115320638812e-08,0.0035096,231.24944275319763,250.59513496469975,5.253021153103479
1.973760918317353e-08,0.0035344,231.35696624910884,250.59513496469975,5.253021153103479
1.9759946902937193e-08,0.0035383999999999997,231.37428115442492,250.59513496469975,5.253021153103479
1.982696006222819e-08,0.0035504,231.42618012584452,250.59513496469975,5.253021153103479
1.9885038133613715e-08,0.0035608,231.47110392213762,250.59513496469975,5.253021153103479
1.992524602918831e-08,0.003568,231.50217504032247,250.59513496469975,5.253021153103479
1.9952051292904703e-08,0.0035727999999999997,231.52287553531085,250.59513496469975,5.253021153103479
2.0010129364290233e-08,0.0035832,231.56768943597237,250.59513496469975,5.253021153103479
2.0032467084053895e-08,0.0035872,231.58491204086246,250.59513496469975,5.253021153103479
2.0099480243344887e-08,0.0035992,231.63653497306984,250.59513496469975,5.253021153103479
2.0162025858683148e-08,0.0036103999999999997,231.68465584804304,250.59513496469975,5.253021153103479
2.0175428490541345e-08,0.0036127999999999998,231.6949598857865,250.59513496469975,5.253021153103479
2.0215636386115943e-08,0.00362,231.7258559935888,250.59513496469975,5.253021153103479
2.0304987265170597e-08,0.003636,231.79442833692616,250.59513496469975,5.253021153103479
2.035859779260339e-08,0.0036455999999999997,231.83551525788138,250.59513496469975,5.253021153103479
2.038987060027252e-08,0.0036512,231.85946314221374,250.59513496469975,5.253021153103479
2.0474753935374444e-08,0.0036663999999999998,231.92439244387018,250.59513496469975,5.253021153103479
2.0546234638618167e-08,0.0036791999999999997,231.97898836601368,250.59513496469975,5.253021153103479
2.05775074462873e-08,0.0036848,232.00285078296665,250.59513496469975,5.253021153103479
2.0631117973720094e-08,0.0036944,232.04372490470985,250.59513496469975,5.253021153103479
2.0707066220916548e-08,0.003708,232.1015590738839,250.59513496469975,5.253021153103479
2.0854495171356732e-08,0.0037343999999999997,232.21358978738039,250.59513496469975,5.253021153103479
2.093044341855319e-08,0.003748,232.2711820091737,250.59513496469975,5.253021153103479
2.097511885808052e-08,0.003756,232.3050217153965,250.59513496469975,5.253021153103479
2.1015326753655113e-08,0.0037632,232.33545342482714,250.59513496469975,5.253021153103479
2.1153820616189828e-08,0.0037879999999999997,232.4401003878088,250.59513496469975,5.253021153103479
2.1211898687575358e-08,0.0037984,232.48390503933405,250.59513496469975,5.253021153103479
2.122976886338629e-08,0.0038016,232.4973739799669,250.59513496469975,5.253021153103479
2.1314652198488213e-08,0.0038168,232.56129116318766,250.59513496469975,5.253021153103479
2.132805483034641e-08,0.0038192,232.571374268224,250.59513496469975,5.253021153103479
2.1466548692881124e-08,0.0038439999999999998,232.6754220638659,250.59513496469975,5.253021153103479
2.1698860978423232e-08,0.0038856,232.84936787858143,250.59513496469975,5.253021153103479
2.182841975305248e-08,0.0039088,232.9460606121039,250.59513496469975,5.253021153103479
2.192223817605987e-08,0.0039256,233.01593982062738,250.59513496469975,5.253021153103479
2.1989251335350862e-08,0.0039375999999999994,233.06578215291702,250.59513496469975,5.253021153103479
2.2007121511161794e-08,0.0039407999999999995,233.07906343218193,250.59513496469975,5.253021153103479
2.2069667126500054e-08,0.003952,233.1255148236322,250.59513496469975,5.253021153103479
2.2199225901129307e-08,0.0039752,233.2215725598294,250.59513496469975,5.253021153103479
2.2275174148325764e-08,0.0039888,233.2777806189386,250.59513496469975,5.253021153103479
2.2659447273762807e-08,0.004057611522304461,233.56103713957816,250.59513496469975,5.253021153103479
2.534050985791932e-08,0.004537707541508302,235.487626838424,250.59513496469975,5.253021153103479
2.9630209992569746e-08,0.0053058611722344474,238.4121752198616,250.59513496469975,5.253021153103479
3.0809877529598615e-08,0.0055171034206841375,239.1868179565549,250.59513496469975,5.253021153103479
3.3383697610388865e-08,0.005977995599119824,240.83787944915045,250.59513496469975,5.253021153103479
3.8638580275335634e-08,0.006918983796759352,244.06194522561145,250.59513496469975,5.253021153103479
4.0139975322463275e-08,0.007187837567513502,244.95105168513115,250.59513496469975,5.253021153103479
4.1426885362858404e-08,0.007418283656731346,245.70286714797777,250.59513496469975,5.253021153103479
4.2499310396521006e-08,0.007610322064412882,246.3224465463356,250.59513496469975,5.253021153103479
4.44296754571137e-08,0.007955991198239648,247.42253665450247,250.59513496469975,5.253021153103479
4.475140296721248e-08,0.008013602720544109,247.60405729097204,250.59513496469975,5.253021153103479
4.5394857987410045e-08,0.00812882576515303,247.9655788827866,250.59513496469975,5.253021153103479
4.818316307493282e-08,0.008628125625125025,249.50962758014936,250.59513496469975,5.253021153103479
4.839764808166534e-08,0.008666533306661332,249.6269371275448,250.59513496469975,5.253021153103479
5.418874326344342e-08,0.009703540708141629,252.72153727814404,250.59513496469975,5.253021153103479
5.55828958072048e-08,0.009953190638127626,253.44692320362208,250.59513496469975,5.253021153103479
5.697704835096619e-08,0.010202840568113623,254.16524701728306,250.59513496469975,5.253021153103479
5.762050337116376e-08,0.010318063612722545,254.49446587678702,250.59513496469975,5.253021153103479
6.040880845868653e-08,0.01081736347269454,255.90482528686073,250.59513496469975,5.253021153103479
6.18029610024479e-08,0.011067013402680535,256.6004659770112,250.59513496469975,5.253021153103479
6.201744600918043e-08,0.011105421084216843,256.7069419814671,250.59513496469975,5.253021153103479
6.405505357313938e-08,0.011470294058811763,257.71140166710995,250.59513496469975,5.253021153103479
6.619990364046459e-08,0.011854370874174834,258.75535593826,250.59513496469975,5.253021153103479
7.006063376164997e-08,0.012545709141828365,260.6018175068966,250.59513496469975,5.253021153103479
7.038236127174875e-08,0.012603320664132826,260.7538747210273,250.59513496469975,5.253021153103479
7.08113312852138e-08,0.01268013602720544,260.9561966648893,250.59513496469975,5.253021153103479
7.649518396362562e-08,0.013697939587917584,263.59336807074646,250.59513496469975,5.253021153103479
7.885451903768335e-08,0.014120424084816964,264.6654581231772,250.59513496469975,5.253021153103479
8.08921266016423e-08,0.014485297059411883,265.5813246879854,250.59513496469975,5.253021153103479
8.228627914540368e-08,0.01473494698939788,266.20279211391795,250.59513496469975,5.253021153103479
8.49673417295602e-08,0.015215043008601721,267.38649917173484,250.59513496469975,5.253021153103479
8.582528175649029e-08,0.01536867373474695,267.76219694871594,250.59513496469975,5.253021153103479
8.76484043137167e-08,0.01569513902780556,268.5557258515791,250.59513496469975,5.253021153103479
8.807737432718174e-08,0.015771954390878175,268.74149987643995,250.59513496469975,5.253021153103479
8.957876937430941e-08,0.01604080816163233,269.3889482573602,250.59513496469975,5.253021153103479
9.676401709984884e-08,0.017327465493098618,272.4306867042038,250.59513496469975,5.253021153103479
1.0244786977826067e-07,0.018345269053810762,274.77483711919047,250.59513496469975,5.253021153103479
1.0362753731528952e-07,0.01855651130226045,275.25494006094,250.59513496469975,5.253021153103479
1.0609411489271353e-07,0.018998199639927986,276.25195803890745,250.59513496469975,5.253021153103479
1.0963311750380012e-07,0.019631926385277054,277.6668137847656,250.59513496469975,5.253021153103479
1.10812785040829e-07,0.019843168633726746,278.134459131946,250.59513496469975,5.253021153103479
1.1435178765191558e-07,0.020476895379075814,279.5258822403308,250.59513496469975,5.253021153103479
1.205718528471587e-07,0.021590718143628725,281.93137850661384,250.59513496469975,5.253021153103479
1.2239497540438514e-07,0.02191718343668734,282.6272009102638,250.59513496469975,5.253021153103479
1.237891279481465e-07,0.022166833366673334,283.1565763754045,250.59513496469975,5.253021153103479
1.2571949300873921e-07,0.0225125025005001,283.88573511910573,250.59513496469975,5.253021153103479
1.2968746563329086e-07,0.023223044608921786,285.3709901552203,250.59513496469975,5.253021153103479
1.3537131831170266e-07,0.024240848169633927,287.4680028438661,250.59513496469975,5.253021153103479
1.4202035352041083e-07,0.025431486297259453,289.87801041376497,250.59513496469975,5.253021153103479
1.4255656603724212e-07,0.02552750550110022,290.0704271623494,250.59513496469975,5.253021153103479
1.4727523618535758e-07,0.02637247449489898,291.751694300955,250.59513496469975,5.253021153103479
1.5006354127288036e-07,0.026871774354870974,292.7352960550153,250.59513496469975,5.253021153103479
1.5370978638733322e-07,0.027524704940988198,294.0108558221707,250.59513496469975,5.253021153103479
1.5435324140753077e-07,0.02763992798559712,294.23472411451917,250.59513496469975,5.253021153103479
1.556401514479259e-07,0.027870374074814963,294.6813717843981,250.59513496469975,5.253021153103479
1.5767775901188487e-07,0.028235247049409884,295.38562951849366,250.59513496469975,5.253021153103479
1.597153665758438e-07,0.0286001200240048,296.0863467344508,250.59513496469975,5.253021153103479
1.6046606409940762e-07,0.028734546909381875,296.3436257479008,250.59513496469975,5.253021153103479
1.61431246629704e-07,0.02890738147629526,296.6737243592081,250.59513496469975,5.253021153103479
1.6293264167683162e-07,0.02917623524704941,297.1856852701852,250.59513496469975,5.253021153103479
1.6346885419366293e-07,0.029272254450890177,297.3680821381013,250.59513496469975,5.253021153103479
1.646485217306918e-07,0.02948349669933987,297.76853591468455,250.59513496469975,5.253021153103479
1.6700785680474953e-07,0.02990598119623925,298.56610224071187,250.59513496469975,5.253021153103479
1.6840200934851092e-07,0.030155631126225244,299.0353260665246,250.59513496469975,5.253021153103479
1.6947443438217352e-07,0.03034766953390678,299.39523730635534,250.59513496469975,5.253021153103479
1.7011788940237107e-07,0.030462892578515702,299.61075772647087,250.59513496469975,5.253021153103479
1.7290619448989386e-07,0.030962192438487697,300.5410297116435,250.59513496469975,5.253021153103479
1.7387137702019022e-07,0.03113502700540108,300.86168139485727,250.59513496469975,5.253021153103479
1.763379545976142e-07,0.03157671534306861,301.6779866173617,250.59513496469975,5.253021153103479
1.7698140961781174e-07,0.03169193838767753,301.89020191146864,250.59513496469975,5.253021153103479
1.8137835225582847e-07,0.032479295859171836,303.3323699344867,250.59513496469975,5.253021153103479
1.8609702240394393e-07,0.033324264852970596,304.8649766830791,250.59513496469975,5.253021153103479
1.89421540008298e-07,0.03391958391678336,305.93567993216305,250.59513496469975,5.253021153103479
1.903867225385943e-07,0.034092418483696735,306.24515327391447,250.59513496469975,5.253021153103479
1.9274605761265207e-07,0.03451490298059612,306.99907895755456,250.59513496469975,5.253021153103479
1.962850602237387e-07,0.035148629725945194,308.12325388533804,250.59513496469975,5.253021153103479
1.9821542528433137e-07,0.035494298859771956,308.7331073622715,250.59513496469975,5.253021153103479
2.005747603583891e-07,0.03591678335667134,309.475347293925,250.59513496469975,5.253021153103479
2.01754427895418e-07,0.03612802560512103,309.8451897993479,250.59513496469975,5.253021153103479
2.0422100547284196e-07,0.03656971394278856,310.61578266051714,250.59513496469975,5.253021153103479
2.0582964302333582e-07,0.03685777155431086,311.11638841520704,250.59513496469975,5.253021153103479
2.07116553063731e-07,0.03708821764352871,311.5157752775476,250.59513496469975,5.253021153103479
2.0904691812432368e-07,0.03743388677735547,312.11304569790246,250.59513496469975,5.253021153103479
2.1226419322531152e-07,0.038010002000400084,313.1037385003733,250.59513496469975,5.253021153103479
2.128004057421428e-07,0.03810602120424085,313.26828295191495,250.59513496469975,5.253021153103479
2.1344386076234038e-07,0.038221244248849776,313.4655230029217,250.59513496469975,5.253021153103479
2.1440904329263667e-07,0.03839407881576315,313.76094883083437,250.59513496469975,5.253021153103479
2.1676837836669443e-07,0.03881656331266253,314.4809258131926,250.59513496469975,5.253021153103479
2.1912771344075218e-07,0.03923904780956192,315.1978530351767,250.59513496469975,5.253021153103479
2.2341741357540262e-07,0.04000720144028806,316.4936913882802,250.59513496469975,5.253021153103479
2.257767486494603e-07,0.04042968593718743,317.2022651458093,250.59513496469975,5.253021153103479
2.2749262870332045e-07,0.04073694738947789,317.7157789917044,250.59513496469975,5.253021153103479
2.2877953874371563e-07,0.04096739347869574,318.0999236582868,250.59513496469975,5.253021153103479
2.2953023626727942e-07,0.04110182036407281,318.3236188707479,250.59513496469975,5.253021153103479
2.312461163211396e-07,0.04140908181636327,318.83385353055064,250.59513496469975,5.253021153103479
2.3210405634806968e-07,0.0415627125425085,319.0884170016112,250.59513496469975,5.253021153103479
2.3306923887836604e-07,0.041735547109421886,319.3743626667899,250.59513496469975,5.253021153103479
2.386458490534116e-07,0.04273414682936587,321.0175395614155,250.59513496469975,5.253021153103479
2.408979416241031e-07,0.04313742748549711,321.6768769976638,250.59513496469975,5.253021153103479
2.4325727669816075e-07,0.043559911982396476,322.36503824582303,250.59513496469975,5.253021153103479
2.4904837187993884e-07,0.044596919383876776,324.04321697175914,250.59513496469975,5.253021153103479
2.5001355441023524e-07,0.044769753950790164,324.3214271574588,250.59513496469975,5.253021153103479
2.53230829511223e-07,0.04534586917383476,325.2457840289263,250.59513496469975,5.253021153103479
2.5548292208191446e-07,0.04574914982996599,325.8901105511243,250.59513496469975,5.253021153103479
2.5977262221656487e-07,0.04651730346069213,327.1113040098576,250.59513496469975,5.253021153103479
2.6020159223002997e-07,0.046594118823764755,327.2329891969245,250.59513496469975,5.253021153103479
2.6116677476032637e-07,0.04676695339067814,327.5064951733364,250.59513496469975,5.253021153103479
2.634188673310178e-07,0.04717023404680937,328.14314734229924,250.59513496469975,5.253021153103479
2.641695648545816e-07,0.04730466093218644,328.35489253887977,250.59513496469975,5.253021153103479
2.658854449084418e-07,0.047611922384476896,328.83800231605716,250.59513496469975,5.253021153103479
2.6685062743873817e-07,0.047784756951390284,329.10921719940427,250.59513496469975,5.253021153103479
2.682447799824995e-07,0.04803440688137628,329.5002975919614,250.59513496469975,5.253021153103479
2.685665074925983e-07,0.04809201840368074,329.59043424557,250.59513496469975,5.253021153103479
2.6931720501616213e-07,0.04822644528905781,329.800589495586,250.59513496469975,5.253021153103479
2.73821390157545e-07,0.04903300660132026,331.05675664192376,250.59513496469975,5.253021153103479
2.7446484517774265e-07,0.04914822964592919,331.2355490367605,250.59513496469975,5.253021153103479
2.763952102383353e-07,0.04949389877975595,331.77094795349234,250.59513496469975,5.253021153103479
2.8004145535278816e-07,0.05014682936587317,332.7782948772818,250.59513496469975,5.253021153103479
2.820790629167471e-07,0.05051170234046809,333.3389957559523,250.59513496469975,5.253021153103479
2.851890955143686e-07,0.051068613722744544,334.19176651386283,250.59513496469975,5.253021153103479
2.875484305884264e-07,0.05149109821964393,334.83627887085106,250.59513496469975,5.253021153103479
2.885136131187228e-07,0.051663932786557315,335.09934819486693,250.59513496469975,5.253021153103479
2.8969328065575166e-07,0.05187517503500701,335.420411724612,250.59513496469975,5.253021153103479
2.923743432399081e-07,0.05235527105421084,336.1482113022533,250.59513496469975,5.253021153103479
2.933395257702045e-07,0.05252810562112423,336.40958138113996,250.59513496469975,5.253021153103479
2.946264358105996e-07,0.052758551710342064,336.75755368853356,250.59513496469975,5.253021153103479
2.9548437583752965e-07,0.05291218243648729,336.9892059679708,250.59513496469975,5.253021153103479
2.975219834014886e-07,0.053277055411082214,337.5383313500333,250.59513496469975,5.253021153103479
2.982726809250525e-07,0.0534114822964593,337.7402707332926,250.59513496469975,5.253021153103479
2.987016509385175e-07,0.053488297659531905,337.85557567110004,250.59513496469975,5.253021153103479
3.0106098601257526e-07,0.05391078215643129,338.4886022135902,250.59513496469975,5.253021153103479
3.0170444103277284e-07,0.054026005201040214,338.6609096597566,250.59513496469975,5.253021153103479
3.0352756358999923e-07,0.05435247049409882,339.14833751355036,250.59513496469975,5.253021153103479
3.0492171613376057e-07,0.05460212042408481,339.5203064308113,250.59513496469975,5.253021153103479
3.0867520375157974e-07,0.05527425485097019,340.5184791060947,250.59513496469975,5.253021153103479
3.1360835890642773e-07,0.05615763152630526,341.82319348957947,250.59513496469975,5.253021153103479
3.209008491353334e-07,0.0574634926985397,343.73733439682775,250.59513496469975,5.253021153103479
3.212225766454322e-07,0.057521104220844166,343.82138883411585,250.59513496469975,5.253021153103479
3.224022441824611e-07,0.05773234646929386,344.12930793659217,250.59513496469975,5.253021153103479
3.2358191171948994e-07,0.05794358871774355,344.43678794847364,250.59513496469975,5.253021153103479
3.26477459310379e-07,0.0584620924184837,345.1896639684631,250.59513496469975,5.253021153103479
3.2958749190800056e-07,0.05901900380076015,345.9954137828301,250.59513496469975,5.253021153103479
3.320540694854245e-07,0.05946069213842768,346.63235022689895,250.59513496469975,5.253021153103479
3.325902820022558e-07,0.05955671134226845,346.7705701976504,250.59513496469975,5.253021153103479
3.3430616205611597e-07,0.059863972794558906,347.21229121801525,250.59513496469975,5.253021153103479
3.3548582959314483e-07,0.0600752150430086,347.51546163920773,250.59513496469975,5.253021153103479
3.368799821369062e-07,0.060324864972994593,347.87321846551595,250.59513496469975,5.253021153103479
3.3966828722442906e-07,0.0608241648329666,348.5870045686686,250.59513496469975,5.253021153103479
3.4202762229848674e-07,0.06124664932986597,349.1891943525642,250.59513496469975,5.253021153103479
3.4245659231195184e-07,0.06132346469293859,349.29850912808166,250.59513496469975,5.253021153103479
3.436362598489807e-07,0.06153470694138828,349.5988497482227,250.59513496469975,5.253021153103479
3.454593824062071e-07,0.061861172234446885,350.0622228187297,250.59513496469975,5.253021153103479
3.4803320248699735e-07,0.06232206441288257,350.7147762425554,250.59513496469975,5.253021153103479
3.485694150038287e-07,0.06241808361672335,350.85048767632645,250.59513496469975,5.253021153103479
3.506070225677876e-07,0.06278295659131826,351.36545027699503,250.59513496469975,5.253021153103479
3.526446301317466e-07,0.06314782956591318,351.8792470051413,250.59513496469975,5.253021153103479
3.551112077091706e-07,0.06358951790358072,352.49966496896695,250.59513496469975,5.253021153103479
3.56505360252932e-07,0.06383916783356672,352.84959252538533,250.59513496469975,5.253021153103479
3.5822124030679214e-07,0.06414642928585718,353.27954082021427,250.59513496469975,5.253021153103479
3.605805753808498e-07,0.06456891378275655,353.8694105769646,250.59513496469975,5.253021153103479
3.621892129313438e-07,0.06485697139427886,354.27073173612524,250.59513496469975,5.253021153103479
3.660499430525291e-07,0.06554830966193238,355.2310768570621,250.59513496469975,5.253021153103479
3.679803081131219e-07,0.06589397879575916,355.70976749477455,250.59513496469975,5.253021153103479
3.7001791567708074e-07,0.06625885177035407,356.21399081469997,250.59513496469975,5.253021153103479
3.720555232410398e-07,0.066623724744949,356.71713239764983,250.59513496469975,5.253021153103479
3.7291346326796987e-07,0.06677735547109423,356.9286598528719,250.59513496469975,5.253021153103479
3.735569182881674e-07,0.06689257851570314,357.08718091521024,250.59513496469975,5.253021153103479
3.7484382832856255e-07,0.06712302460492099,357.4039039282803,250.59513496469975,5.253021153103479
3.760234958655914e-07,0.06733426685337068,357.69386101851205,250.59513496469975,5.253021153103479
3.843884111281597e-07,0.06883216643328666,359.7398386333881,250.59513496469975,5.253021153103479
3.858898061752874e-07,0.06910102020404081,360.1052198480691,250.59513496469975,5.253021153103479
3.864260186921187e-07,0.06919703940788158,360.2355787219406,250.59513496469975,5.253021153103479
3.892143237796414e-07,0.06969633926785357,360.91231101969015,250.59513496469975,5.253021153103479
3.9189538636379795e-07,0.07017643528705741,361.5612343339888,250.59513496469975,5.253021153103479
3.9328953890755934e-07,0.07042608521704341,361.8979900804249,250.59513496469975,5.253021153103479
3.9468369145132073e-07,0.0706757351470294,362.2342805853694,250.59513496469975,5.253021153103479
4.0358481923072037e-07,0.07226965393078616,364.3705472473314,250.59513496469975,5.253021153103479
4.0755279185527196e-07,0.07298019603920784,365.31692907773794,250.59513496469975,5.253021153103479
4.105555819495273e-07,0.07351790358071615,366.0307231452641,250.59513496469975,5.253021153103479
4.1559597960774155e-07,0.07442048409681937,367.2243171412323,250.59513496469975,5.253021153103479
4.163466771313053e-07,0.07455491098219644,367.4016022465758,250.59513496469975,5.253021153103479
4.17848072178433e-07,0.07482376475295059,367.7557989032576,250.59513496469975,5.253021153103479
4.192422247221944e-07,0.07507341468293659,368.08425162275154,250.59513496469975,5.253021153103479
4.217088022996184e-07,0.07551510302060413,368.66431867660776,250.59513496469975,5.253021153103479
4.2471159239387366e-07,0.07605281056211242,369.36870439127415,250.59513496469975,5.253021153103479
4.254622899174376e-07,0.07618723744748951,369.54449701395885,250.59513496469975,5.253021153103479
4.2846508001169283e-07,0.0767249449889978,370.24646119711707,250.59513496469975,5.253021153103479
4.309316575891168e-07,0.07716663332666533,370.82164045607993,250.59513496469975,5.253021153103479
4.338272051800058e-07,0.07768513702740548,371.4952151254234,250.59513496469975,5.253021153103479
4.348996302136684e-07,0.07787717543508701,371.7442419886696,250.59513496469975,5.253021153103479
4.359720552473311e-07,0.07806921384276856,371.9930294760179,250.59513496469975,5.253021153103479
4.362937827574299e-07,0.07812682536507302,372.06761916635116,250.59513496469975,5.253021153103479
4.3736620779109247e-07,0.07831886377275456,372.31609668734444,250.59513496469975,5.253021153103479
4.390820878449526e-07,0.07862612522504502,372.71316705381804,250.59513496469975,5.253021153103479
4.420848779392079e-07,0.07916383276655331,373.4065870911986,250.59513496469975,5.253021153103479
4.4444421301326566e-07,0.0795863172634527,373.9501293227771,250.59513496469975,5.253021153103479
4.453021530401957e-07,0.07973994798959792,374.14750189340356,250.59513496469975,5.253021153103479
4.4744700310752097e-07,0.080124024804961,374.6402855981649,250.59513496469975,5.253021153103479
4.5066427820850875e-07,0.0807001400280056,375.37773733036437,250.59513496469975,5.253021153103479
4.5366706830276406e-07,0.08123784756951391,376.0641753138278,250.59513496469975,5.253021153103479
4.5506122084652545e-07,0.0814874974994999,376.38227611789955,250.59513496469975,5.253021153103479
4.5999437600137343e-07,0.08237087417483498,377.50482446628314,250.59513496469975,5.253021153103479
4.618174985585998e-07,0.08269733946789358,377.91848984965543,250.59513496469975,5.253021153103479
4.634261361090938e-07,0.08298539707941589,378.28296011024514,250.59513496469975,5.253021153103479
4.643913186393901e-07,0.08315823164632927,378.5014054393412,250.59513496469975,5.253021153103479
4.652492586663202e-07,0.0833118623724745,378.695430462261,250.59513496469975,5.253021153103479
4.6589271368651776e-07,0.08342708541708342,378.8408576707288,250.59513496469975,5.253021153103479
4.6685789621681415e-07,0.08359991998399681,379.0588516962184,250.59513496469975,5.253021153103479
4.690027462841393e-07,0.08398399679935988,379.542654567157,250.59513496469975,5.253021153103479
4.7222002138512714e-07,0.08456011202240449,380.2667440987752,250.59513496469975,5.253021153103479
4.739359014389873e-07,0.08486737347469495,380.65213837013715,250.59513496469975,5.253021153103479
4.761879940096788e-07,0.08527065413082617,381.15714353788377,250.59513496469975,5.253021153103479
4.781183590702715e-07,0.08561632326465293,381.5892641859551,250.59513496469975,5.253021153103479
4.786545715871027e-07,0.0857123424684937,381.7091768784308,250.59513496469975,5.253021153103479
4.816573616813581e-07,0.08625005001000201,382.37972231147944,250.59513496469975,5.253021153103479
4.819790891914568e-07,0.08630766153230647,382.4514696349675,250.59513496469975,5.253021153103479
4.833732417352183e-07,0.08655731146229247,382.76215911894997,250.59513496469975,5.253021153103479
4.892715794203626e-07,0.08761352270454091,384.0727663650629,250.59513496469975,5.253021153103479
4.897005494338276e-07,0.08769033806761353,384.16784220526233,250.59513496469975,5.253021153103479
4.91094701977589e-07,0.08793998799759953,384.4766146058615,250.59513496469975,5.253021153103479
4.951699171055068e-07,0.08866973394678936,385.3772259656112,250.59513496469975,5.253021153103479
4.996741022468898e-07,0.08947629525905182,386.3692821030445,250.59513496469975,5.253021153103479
5.020334373209475e-07,0.08989877975595119,386.8875383334809,250.59513496469975,5.253021153103479
5.051434699185692e-07,0.09045569113822766,387.56924529148705,250.59513496469975,5.253021153103479
5.106128375902484e-07,0.09143508701740348,388.76415199860554,250.59513496469975,5.253021153103479
5.120069901340098e-07,0.09168473694738949,389.0679364101802,250.59513496469975,5.253021153103479
5.136156276845037e-07,0.09197279455891179,389.41805631084384,250.59513496469975,5.253021153103479
5.147952952215326e-07,0.09218403680736148,389.6745391616865,250.59513496469975,5.253021153103479
5.179053278191541e-07,0.09274094818963793,390.3496248848,250.59513496469975,5.253021153103479
5.218733004437058e-07,0.09345149029805962,391.2086501765453,250.59513496469975,5.253021153103479
5.238036655042985e-07,0.09379715943188638,391.62563303159254,250.59513496469975,5.253021153103479
5.249833330413273e-07,0.09400840168033607,391.8801608708805,250.59513496469975,5.253021153103479
5.284150931490476e-07,0.09462292458491699,392.61934027288765,250.59513496469975,5.253021153103479
5.315251257466692e-07,0.09517983596719344,393.28760602069065,250.59513496469975,5.253021153103479
5.319540957601343e-07,0.09525665133026606,393.37966078813145,250.59513496469975,5.253021153103479
5.344206733375582e-07,0.09569833966793359,393.90841495291244,250.59513496469975,5.253021153103479
5.371017359217148e-07,0.09617843568713744,394.4820693999574,250.59513496469975,5.253021153103479
5.388176159755749e-07,0.0964856971394279,394.8486222435996,250.59513496469975,5.253021153103479
5.398900410092375e-07,0.09667773554710943,395.0774866065086,250.59513496469975,5.253021153103479
5.404262535260689e-07,0.0967737547509502,395.1918522962546,250.59513496469975,5.253021153103479
5.421421335799291e-07,0.09708101620324065,395.5575254684766,250.59513496469975,5.253021153103479
5.449304386674517e-07,0.09758031606321264,396.15078315953315,250.59513496469975,5.253021153103479
5.476115012516083e-07,0.09806041208241649,396.7201077994467,250.59513496469975,5.253021153103479
5.490056537953697e-07,0.09831006201240249,397.01572694189866,250.59513496469975,5.253021153103479
5.501853213323985e-07,0.09852130426085218,397.26563761329993,250.59513496469975,5.253021153103479
5.505070488424974e-07,0.09857891578315664,397.3337587892143,250.59513496469975,5.253021153103479
5.517939588828925e-07,0.09880936187237448,397.60608837203216,250.59513496469975,5.253021153103479
5.54903991480514e-07,0.09936627325465093,398.26319758698156,250.59513496469975,5.253021153103479
5.551184764872466e-07,0.09940468093618725,398.3084624497479,250.59513496469975,5.253021153103479
5.564053865276416e-07,0.09963512702540508,398.5799085277795,250.59513496469975,5.253021153103479
5.575850540646705e-07,0.09984636927385478,398.8285190805192,250.59513496469975,5.253021153103479
5.584429940916006e-07,0.1,399.0091979308459,250.59513496469975,5.253021153103479