File: datasets/aisi_316_L/data/M1/valid_26.csv
Time(s),Strain(%),Stress(MPa),Temp(C),Log_SR(s-1)
0.0,0.0,0.0,415.20173154264637,4.5572151024516
9.091985642866833e-10,3.28e-05,5.510221649999999,415.20173154264637,4.5572151024516
1.6409925306637699e-09,5.9199999999999996e-05,9.9452781,415.20173154264637,4.5572151024516
1.907099427528165e-09,6.879999999999999e-05,11.558025899999999,415.20173154264637,4.5572151024516
2.2619086233473586e-09,8.159999999999999e-05,13.708356299999998,415.20173154264637,4.5572151024516
2.3727864970408566e-09,8.56e-05,14.380334549999999,415.20173154264637,4.5572151024516
2.74977126759875e-09,9.92e-05,16.6650606,415.20173154264637,4.5572151024516
3.060229313940544e-09,0.0001104,18.5465997,415.20173154264637,4.5572151024516
3.3041606360662395e-09,0.0001192,20.02495185,415.20173154264637,4.5572151024516
3.991603452965927e-09,0.000144,24.191217,415.20173154264637,4.5572151024516
5.100382189900907e-09,0.000184,30.9109995,415.20173154264637,4.5572151024516
5.2112600635944045e-09,0.000188,31.582977749999998,415.20173154264637,4.5572151024516
5.7656494320618945e-09,0.000208,34.942868999999995,415.20173154264637,4.5572151024516
6.4974433984389804e-09,0.00023439999999999998,39.37792545,415.20173154264637,4.5572151024516
6.697023571087278e-09,0.0002416,40.5874863,415.20173154264637,4.5572151024516
6.8744281689968745e-09,0.000248,41.6626515,415.20173154264637,4.5572151024516
7.450993112203063e-09,0.0002688,45.156938399999994,415.20173154264637,4.5572151024516
7.739275583806159e-09,0.0002792,46.904081850000004,415.20173154264637,4.5572151024516
7.916680181715756e-09,0.0002856,47.97924705,415.20173154264637,4.5572151024516
8.315840527012347e-09,0.0003,50.398368749999996,415.20173154264637,4.5572151024516
8.448893975444546e-09,0.0003048,51.20474265,415.20173154264637,4.5572151024516
8.71500087230894e-09,0.0003144,52.81749045,415.20173154264637,4.5572151024516
9.24721466603773e-09,0.0003336,56.042986049999996,415.20173154264637,4.5572151024516
9.757252885027821e-09,0.000352,59.134085999999996,415.20173154264637,4.5572151024516
1.0577749150359707e-08,0.0003816,64.10672505,415.20173154264637,4.5572151024516
1.1442596565168992e-08,0.0004128,69.3481554,415.20173154264637,4.5572151024516
1.1597825588339888e-08,0.0004184,70.28892495,415.20173154264637,4.5572151024516
1.2085688232591278e-08,0.00043599999999999997,73.24562925,415.20173154264637,4.5572151024516
1.2329619554716973e-08,0.00044479999999999997,74.7239814,415.20173154264637,4.5572151024516
1.2484848577887871e-08,0.0004504,75.66475095,415.20173154264637,4.5572151024516
1.3039237946355362e-08,0.0004704,79.0246422,415.20173154264637,4.5572151024516
1.3327520417958456e-08,0.0004808,80.77178565,415.20173154264637,4.5572151024516
1.463587932754173e-08,0.0005279999999999999,88.701129,415.20173154264637,4.5572151024516
1.4702406051757831e-08,0.0005304,89.10431595,415.20173154264637,4.5572151024516
1.6409925306637698e-08,0.000592,99.452781,415.20173154264637,4.5572151024516
1.7097368123537385e-08,0.0006167999999999999,103.61904614999999,415.20173154264637,4.5572151024516
1.740782616987918e-08,0.000628,105.50058525,415.20173154264637,4.5572151024516
1.7829162089914475e-08,0.0006432,108.05410260000001,415.20173154264637,4.5572151024516
1.791786438886927e-08,0.0006464,108.5916852,415.20173154264637,4.5572151024516
1.805091783730147e-08,0.0006512,109.3980591,415.20173154264637,4.5572151024516
1.849442933207546e-08,0.0006672,112.08597209999999,415.20173154264637,4.5572151024516
1.869400950472376e-08,0.0006744,113.29553295000001,415.20173154264637,4.5572151024516
1.8893589677372054e-08,0.0006816,114.5050938,415.20173154264637,4.5572151024516
1.9115345424759048e-08,0.0006896,115.84905029999999,415.20173154264637,4.5572151024516
1.9204047723713847e-08,0.0006927999999999999,116.38663289999998,415.20173154264637,4.5572151024516
1.960320806901044e-08,0.0007072,118.80575459999999,415.20173154264637,4.5572151024516
2.009107071326183e-08,0.0007247999999999999,121.76245889999998,415.20173154264637,4.5572151024516
2.1044620427025912e-08,0.0007591999999999999,127.54147184999998,415.20173154264637,4.5572151024516
2.1222025024935513e-08,0.0007656,128.61663704999998,415.20173154264637,4.5572151024516
2.1443780772322507e-08,0.0007735999999999999,129.96059355,415.20173154264637,4.5572151024516
2.1909467841835197e-08,0.0007903999999999999,132.7829022,415.20173154264637,4.5572151024516
2.2242101462915692e-08,0.0008024,134.79883695,415.20173154264637,4.5572151024516
2.239733048608659e-08,0.000808,135.7396065,415.20173154264637,4.5572151024516
2.2707788532428383e-08,0.0008192,137.6211456,415.20173154264637,4.5572151024516
2.3217826751418476e-08,0.0008376,140.71224555,415.20173154264637,4.5572151024516
2.3971796292534262e-08,0.0008648,145.28169764999998,415.20173154264637,4.5572151024516
2.4792292557866145e-08,0.0008944,150.25433669999998,415.20173154264637,4.5572151024516
2.5280155202117538e-08,0.0009119999999999999,153.211041,415.20173154264637,4.5572151024516
2.5368857501072333e-08,0.0009151999999999999,153.74862359999997,415.20173154264637,4.5572151024516
2.5967598019017225e-08,0.0009368,157.37730615,415.20173154264637,4.5572151024516
2.6677216410655612e-08,0.0009624,161.67796694999998,415.20173154264637,4.5572151024516
2.6987674456997405e-08,0.0009735999999999999,163.55950604999998,415.20173154264637,4.5572151024516
2.7253781353861805e-08,0.0009832,165.17225385,415.20173154264637,4.5572151024516
2.8140804343409786e-08,0.0010152,169.4998085428724,415.20173154264637,4.5572151024516
2.849561353922898e-08,0.001028,169.56973167646242,415.20173154264637,4.5572151024516
2.8628666987661176e-08,0.0010328,169.59586520710062,415.20173154264637,4.5572151024516
2.8916949459264272e-08,0.0010432,169.65232590918805,415.20173154264637,4.5572151024516
2.9227407505606068e-08,0.0010544,169.71288480037384,415.20173154264637,4.5572151024516
2.944916325299306e-08,0.0010624,169.75598765477258,415.20173154264637,4.5572151024516
2.964874342564136e-08,0.0010696,169.79467211596054,415.20173154264637,4.5572151024516
3.022530836884755e-08,0.0010904,169.90586080944797,415.20173154264637,4.5572151024516
3.044706411623454e-08,0.0010984,169.9484050481194,415.20173154264637,4.5572151024516
3.1910652048988715e-08,0.0011512,170.22622606120234,415.20173154264637,4.5572151024516
3.215458337111441e-08,0.00116,170.27204206658982,415.20173154264637,4.5572151024516
3.2642446015365805e-08,0.0011776,170.3632694316326,415.20173154264637,4.5572151024516
3.3551644579652486e-08,0.0012104,170.53187754837336,415.20173154264637,4.5572151024516
3.372904917756208e-08,0.0012167999999999999,170.5645679076374,415.20173154264637,4.5572151024516
3.4394316419723075e-08,0.0012408,170.6865640878924,415.20173154264637,4.5572151024516
3.4527369868155266e-08,0.0012456,170.71085251051875,415.20173154264637,4.5572151024516
3.4593896592371365e-08,0.001248,170.72298303131345,415.20173154264637,4.5572151024516
3.4704774466064864e-08,0.0012519999999999999,170.7431803679836,415.20173154264637,4.5572151024516
3.486000348923576e-08,0.0012576,170.77141441161913,415.20173154264637,4.5572151024516
3.5347866133487155e-08,0.0012752,170.8598324405068,415.20173154264637,4.5572151024516
3.572485090404504e-08,0.0012887999999999999,170.9278298864776,415.20173154264637,4.5572151024516
3.6345766996728635e-08,0.0013112,171.03921879325173,415.20173154264637,4.5572151024516
3.6456644870422133e-08,0.0013151999999999999,171.05903132427332,415.20173154264637,4.5572151024516
3.656752274411563e-08,0.0013192,171.07882036891849,415.20173154264637,4.5572151024516
3.7121912112583124e-08,0.0013392,171.17741673417208,415.20173154264637,4.5572151024516
3.7321492285231415e-08,0.0013464,171.21277062991385,415.20173154264637,4.5572151024516
3.767630148105061e-08,0.0013591999999999999,171.27544048119393,415.20173154264637,4.5572151024516
3.780935492948281e-08,0.001364,171.29888228116113,415.20173154264637,4.5572151024516
3.79202328031763e-08,0.0013679999999999999,171.31839254852045,415.20173154264637,4.5572151024516
3.854114889585989e-08,0.0013904,171.4272416622221,415.20173154264637,4.5572151024516
3.874072906850819e-08,0.0013976,171.46208335078688,415.20173154264637,4.5572151024516
3.9073362689588685e-08,0.0014096,171.5199976720535,415.20173154264637,4.5572151024516
3.967210320753357e-08,0.0014311999999999999,171.62376121187452,415.20173154264637,4.5572151024516
4.018214142652366e-08,0.0014495999999999999,171.71167154543764,415.20173154264637,4.5572151024516
4.0803057519207255e-08,0.001472,171.81810761938596,415.20173154264637,4.5572151024516
4.106916441607165e-08,0.0014816,171.86352949974562,415.20173154264637,4.5572151024516
4.142397361189084e-08,0.0014944,171.9239138601338,415.20173154264637,4.5572151024516
4.1667904934016536e-08,0.0015032,171.96531114820442,415.20173154264637,4.5572151024516
4.202271412983573e-08,0.001516,172.02535706180572,415.20173154264637,4.5572151024516
4.2510576774087125e-08,0.0015336,172.10759834319373,415.20173154264637,4.5572151024516
4.328672188994161e-08,0.0015616,172.23768215648968,415.20173154264637,4.5572151024516
4.494988999534408e-08,0.0016216,172.5134088914769,415.20173154264637,4.5572151024516
4.510511901851497e-08,0.0016271999999999999,172.5389386554192,415.20173154264637,4.5572151024516
4.5282523616424574e-08,0.0016336,172.56807360817848,415.20173154264637,4.5572151024516
4.596996643332426e-08,0.0016584,172.68055357816928,415.20173154264637,4.5572151024516
4.643565350283695e-08,0.0016752,172.75637721907898,415.20173154264637,4.5572151024516
4.674611154917875e-08,0.0016864,172.8067616225387,415.20173154264637,4.5572151024516
4.685698942287224e-08,0.0016903999999999999,172.8247244037648,415.20173154264637,4.5572151024516
4.692351614708834e-08,0.0016928,172.8354941156665,415.20173154264637,4.5572151024516
4.7278325342907534e-08,0.0017055999999999998,172.892832320219,415.20173154264637,4.5572151024516
4.745572994081713e-08,0.001712,172.921438472611,415.20173154264637,4.5572151024516
4.758878338924933e-08,0.0017167999999999999,172.94286572527614,415.20173154264637,4.5572151024516
4.854233310301341e-08,0.0017511999999999998,173.09574973876434,415.20173154264637,4.5572151024516
4.8786264425139107e-08,0.0017599999999999998,173.13467090666373,415.20173154264637,4.5572151024516
4.92297759199131e-08,0.001776,173.20524277618478,415.20173154264637,4.5572151024516
4.9806340863119286e-08,0.0017967999999999999,173.29661661817818,415.20173154264637,4.5572151024516
5.0626837128451175e-08,0.0018264,173.42594056382984,415.20173154264637,4.5572151024516
5.115905092217997e-08,0.0018456,173.50938951365583,415.20173154264637,4.5572151024516
5.266699000441154e-08,0.0019,173.74400919956537,415.20173154264637,4.5572151024516
5.2711341153888933e-08,0.0019015999999999998,173.75086982489822,415.20173154264637,4.5572151024516
5.302179920023073e-08,0.0019127999999999999,173.79883132368212,415.20173154264637,4.5572151024516
5.3687066442391714e-08,0.0019367999999999998,173.90123871353953,415.20173154264637,4.5572151024516
5.388664661504002e-08,0.001944,173.9318642676998,415.20173154264637,4.5572151024516
5.4241455810859206e-08,0.0019568,173.9862006940367,415.20173154264637,4.5572151024516
5.49288986277589e-08,0.0019816,174.09108466515596,415.20173154264637,4.5572151024516
5.563851701939728e-08,0.0020071999999999998,174.1988164155371,415.20173154264637,4.5572151024516
5.612637966364867e-08,0.0020247999999999998,174.27257134087947,415.20173154264637,4.5572151024516
5.628160868681957e-08,0.0020304,174.29598632835084,415.20173154264637,4.5572151024516
5.670294460685486e-08,0.0020456,174.3594146794709,415.20173154264637,4.5572151024516
5.6902524779503163e-08,0.0020528,174.38939550866885,415.20173154264637,4.5572151024516
5.736821184901585e-08,0.0020696,174.45919174416807,415.20173154264637,4.5572151024516
5.763431874588024e-08,0.0020792,174.4989760958033,415.20173154264637,4.5572151024516
5.8011303516438135e-08,0.0020927999999999997,174.55521484653423,415.20173154264637,4.5572151024516
5.854351731016692e-08,0.0021119999999999997,174.63436868481742,415.20173154264637,4.5572151024516
5.896485323020223e-08,0.0021272,174.6968332879853,415.20173154264637,4.5572151024516
5.927531127654402e-08,0.0021384,174.74274850695176,415.20173154264637,4.5572151024516
5.951924259866971e-08,0.0021471999999999997,174.77875898750528,415.20173154264637,4.5572151024516
5.97631739207954e-08,0.002156,174.81471195610578,415.20173154264637,4.5572151024516
5.996275409344371e-08,0.0021632,174.84408547174726,415.20173154264637,4.5572151024516
6.02066854155694e-08,0.002172,174.87993470624266,415.20173154264637,4.5572151024516
6.04284411629564e-08,0.00218,174.91247579430674,415.20173154264637,4.5572151024516
6.153721989989137e-08,0.0022199999999999998,175.07448784039434,415.20173154264637,4.5572151024516
6.184767794623318e-08,0.0022312,175.1196466843079,415.20173154264637,4.5572151024516
6.213596041783627e-08,0.0022416,175.16150080004812,415.20173154264637,4.5572151024516
6.255729633787155e-08,0.0022567999999999998,175.22253622952869,415.20173154264637,4.5572151024516
6.271252536104246e-08,0.0022624,175.24498252598966,415.20173154264637,4.5572151024516
6.315603685581644e-08,0.0022784,175.30899571456473,415.20173154264637,4.5572151024516
6.382130409797743e-08,0.0023024,175.40468775525218,415.20173154264637,4.5572151024516
6.424264001801273e-08,0.0023176,175.465091554932,415.20173154264637,4.5572151024516
6.453092248961582e-08,0.0023279999999999998,175.50633147788918,415.20173154264637,4.5572151024516
6.49744339843898e-08,0.0023439999999999997,175.56963748963037,415.20173154264637,4.5572151024516
6.58392813991991e-08,0.0023752,175.6926015671671,415.20173154264637,4.5572151024516
6.601668599710869e-08,0.0023815999999999998,175.7177469269302,415.20173154264637,4.5572151024516
6.612756387080219e-08,0.0023856,175.73344939504193,415.20173154264637,4.5572151024516
6.661542651505358e-08,0.0024032,175.802418628862,415.20173154264637,4.5572151024516
6.721416703299848e-08,0.0024248,175.88679404368358,415.20173154264637,4.5572151024516
6.787943427515945e-08,0.0024487999999999997,175.98020145921322,415.20173154264637,4.5572151024516
6.801248772359165e-08,0.0024536,175.9988400245914,415.20173154264637,4.5572151024516
6.889951071313963e-08,0.0024855999999999997,176.1227357044206,415.20173154264637,4.5572151024516
6.945390008160713e-08,0.0025055999999999998,176.1998546890322,415.20173154264637,4.5572151024516
6.996393830059721e-08,0.0025239999999999998,176.27059238663136,415.20173154264637,4.5572151024516
7.10283658880548e-08,0.0025624,176.41757432759002,415.20173154264637,4.5572151024516
7.12944727849192e-08,0.002572,176.4541852780448,415.20173154264637,4.5572151024516
7.193756445234148e-08,0.0025951999999999998,176.54244241530515,415.20173154264637,4.5572151024516
7.235890037237677e-08,0.0026103999999999997,176.60009926765656,415.20173154264637,4.5572151024516
7.251412939554767e-08,0.002616,176.62130824151689,415.20173154264637,4.5572151024516
7.291328974084427e-08,0.0026303999999999998,176.67576445728517,415.20173154264637,4.5572151024516
7.331245008614085e-08,0.0026447999999999997,176.73010453038057,415.20173154264637,4.5572151024516
7.360073255774395e-08,0.0026552,176.7692784039782,415.20173154264637,4.5572151024516
7.380031273039224e-08,0.0026623999999999997,176.7963637304765,415.20173154264637,4.5572151024516
7.402206847777924e-08,0.0026704,176.82642505597903,415.20173154264637,4.5572151024516
7.446557997255323e-08,0.0026864,176.88644254623858,415.20173154264637,4.5572151024516
7.559653428422692e-08,0.0027272,177.03885954459307,415.20173154264637,4.5572151024516
7.61730992274331e-08,0.002748,177.11621991177367,415.20173154264637,4.5572151024516
7.64392061242975e-08,0.0027576,177.15184764183763,415.20173154264637,4.5572151024516
7.686054204433279e-08,0.0027727999999999997,177.20815944688357,415.20173154264637,4.5572151024516
7.783626733283557e-08,0.0028079999999999997,177.33810553854943,415.20173154264637,4.5572151024516
7.827977882760957e-08,0.0028239999999999997,177.3969617744546,415.20173154264637,4.5572151024516
7.859023687395136e-08,0.0028352,177.43808378368263,415.20173154264637,4.5572151024516
7.927767969085105e-08,0.0028599999999999997,177.5289148764496,415.20173154264637,4.5572151024516
8.014252710566034e-08,0.0028912,177.64275112145384,415.20173154264637,4.5572151024516
8.027558055409253e-08,0.0028959999999999997,177.66022177571014,415.20173154264637,4.5572151024516
8.065256532465043e-08,0.0029096,177.709660740359,415.20173154264637,4.5572151024516
8.165046618789191e-08,0.0029456,177.84009549458403,415.20173154264637,4.5572151024516
8.18722219352789e-08,0.0029536,177.86899639401,415.20173154264637,4.5572151024516
8.20052753837111e-08,0.0029584,177.88632228005898,415.20173154264637,4.5572151024516
8.20496265331885e-08,0.00296,177.89209513865146,415.20173154264637,4.5572151024516
8.231573343005289e-08,0.0029695999999999998,177.9267067682356,415.20173154264637,4.5572151024516
8.236008457953029e-08,0.0029712,177.9324711280048,415.20173154264637,4.5572151024516
8.260401590165599e-08,0.00298,177.96415349362758,415.20173154264637,4.5572151024516
8.326928314381697e-08,0.0030039999999999997,178.05037503277453,415.20173154264637,4.5572151024516
8.408977940914886e-08,0.0030336,178.15634582453418,415.20173154264637,4.5572151024516
8.464416877761636e-08,0.0030536,178.22771951990657,415.20173154264637,4.5572151024516
8.548684061768694e-08,0.003084,178.33585935824848,415.20173154264637,4.5572151024516
8.579729866402873e-08,0.0030951999999999998,178.37559545364948,415.20173154264637,4.5572151024516
8.68173751020089e-08,0.003132,178.5057638660071,415.20173154264637,4.5572151024516
8.76600469420795e-08,0.0031623999999999997,178.61284499054534,415.20173154264637,4.5572151024516
8.792615383894389e-08,0.003172,178.64657657959165,415.20173154264637,4.5572151024516
8.80813828621148e-08,0.0031776,178.6662349534758,415.20173154264637,4.5572151024516
8.832531418424048e-08,0.0031864,178.6970994073561,415.20173154264637,4.5572151024516
8.861359665584357e-08,0.0031967999999999996,178.73353275380444,415.20173154264637,4.5572151024516
8.887970355270797e-08,0.0032064,178.7671225277828,415.20173154264637,4.5572151024516
8.916798602431106e-08,0.0032167999999999997,178.80346721997068,415.20173154264637,4.5572151024516
8.994413114016556e-08,0.0032448,178.90109125572116,415.20173154264637,4.5572151024516
9.107508545183923e-08,0.0032856,179.0427573092178,415.20173154264637,4.5572151024516
9.120813890027143e-08,0.0032903999999999997,179.05937867744606,415.20173154264637,4.5572151024516
9.147424579713583e-08,0.0033,179.0925930720202,415.20173154264637,4.5572151024516
9.174035269400021e-08,0.0033095999999999998,179.12576980465911,415.20173154264637,4.5572151024516
9.205081074034202e-08,0.0033208,179.16442859464706,415.20173154264637,4.5572151024516
9.23612687866838e-08,0.003332,179.20303656827457,415.20173154264637,4.5572151024516
9.28491314309352e-08,0.0033496,179.26360414137588,415.20173154264637,4.5572151024516
9.30487116035835e-08,0.0033568,179.28834599717106,415.20173154264637,4.5572151024516
9.313741390253829e-08,0.0033599999999999997,179.29933573320392,415.20173154264637,4.5572151024516
9.384703229417668e-08,0.0033856,179.38710715202475,415.20173154264637,4.5572151024516
9.413531476577977e-08,0.0033959999999999997,179.42269031105735,415.20173154264637,4.5572151024516
9.440142166264418e-08,0.0034056,179.4554986016859,415.20173154264637,4.5572151024516
9.473405528372466e-08,0.0034176,179.49645828821696,415.20173154264637,4.5572151024516
9.522191792797606e-08,0.0034352,179.55643118145954,415.20173154264637,4.5572151024516
9.606458976804663e-08,0.0034655999999999997,179.65973923515514,415.20173154264637,4.5572151024516
9.697378833233333e-08,0.0034984,179.77080760895555,415.20173154264637,4.5572151024516
9.737294867762992e-08,0.0035128,179.8194409667077,415.20173154264637,4.5572151024516
9.783863574714261e-08,0.0035296,179.87608172419655,415.20173154264637,4.5572151024516
9.83043228166553e-08,0.0035464,179.9326174364448,415.20173154264637,4.5572151024516
9.934657482937419e-08,0.003584,180.05877262991766,415.20173154264637,4.5572151024516
9.961268172623857e-08,0.0035935999999999997,180.09089961794214,415.20173154264637,4.5572151024516
9.990096419784167e-08,0.003604,180.12566610673193,415.20173154264637,4.5572151024516
1.0027794896839956e-07,0.0036176,180.17107099658406,415.20173154264637,4.5572151024516
1.0036665126735436e-07,0.0036208,180.1817448195801,415.20173154264637,4.5572151024516
1.0081016276212836e-07,0.0036368,180.23505884916494,415.20173154264637,4.5572151024516
1.0132020098111844e-07,0.0036552,180.29625702707978,415.20173154264637,4.5572151024516
1.0156413230324413e-07,0.0036639999999999997,180.32548323944033,415.20173154264637,4.5572151024516
1.0222939954540512e-07,0.003688,180.40505228192575,415.20173154264637,4.5572151024516
1.0265073546544042e-07,0.0037032,180.45534157586795,415.20173154264637,4.5572151024516
1.0333817828234011e-07,0.003728,180.53722005059367,415.20173154264637,4.5572151024516
1.0400344552450109e-07,0.0037519999999999997,180.61625526556924,415.20173154264637,4.5572151024516
1.0477959064035558e-07,0.00378,180.70821425046455,415.20173154264637,4.5572151024516
1.0493481966352647e-07,0.0037855999999999996,180.72657412665697,415.20173154264637,4.5572151024516
1.0553356018147136e-07,0.0038071999999999997,180.79729179298042,415.20173154264637,4.5572151024516
1.0604359840046146e-07,0.0038255999999999997,180.85740943709294,415.20173154264637,4.5572151024516
1.0673104121736114e-07,0.0038504,180.9382594456225,415.20173154264637,4.5572151024516
1.0746283518373823e-07,0.0038767999999999997,181.0241027371453,415.20173154264637,4.5572151024516
1.0775111765534133e-07,0.0038872,181.05785715875882,415.20173154264637,4.5572151024516
1.0834985817328621e-07,0.0039088,181.12785016625435,415.20173154264637,4.5572151024516
1.0854943834593452e-07,0.003916,181.15114762654449,415.20173154264637,4.5572151024516
1.0897077426596982e-07,0.0039312,181.20027636475845,415.20173154264637,4.5572151024516
1.0925905673757291e-07,0.0039416,181.2338480875849,415.20173154264637,4.5572151024516
1.0965821708286948e-07,0.0039559999999999994,181.2802750357698,415.20173154264637,4.5572151024516
1.1039001104924657e-07,0.0039824,181.3652202890649,415.20173154264637,4.5572151024516
1.1076699581980446e-07,0.0039959999999999996,181.40889423925384,415.20173154264637,4.5572151024516
1.1833035730242283e-07,0.004268853770754151,182.2732283280281,415.20173154264637,4.5572151024516
1.2365355988022628e-07,0.004460892178435687,182.86868076671885,415.20173154264637,4.5572151024516
1.2525052065356733e-07,0.004518503700740148,183.045355809965,415.20173154264637,4.5572151024516
1.5665741586260776e-07,0.005651530306061212,186.35898721767242,415.20173154264637,4.5572151024516
1.6836846153377538e-07,0.006074014802960592,187.5266850448947,415.20173154264637,4.5572151024516
1.7156238308045746e-07,0.006189237847569514,187.8395934389461,415.20173154264637,4.5572151024516
1.790148666893823e-07,0.006458091618323665,188.561008057128,415.20173154264637,4.5572151024516
1.949844744227927e-07,0.007034206841368274,190.06857997713783,415.20173154264637,4.5572151024516
2.0350159854727822e-07,0.007341468293658731,190.85287887797986,415.20173154264637,4.5572151024516
2.0616319983617997e-07,0.0074374874974994995,191.09533285418098,415.20173154264637,4.5572151024516
2.0882480112508168e-07,0.007533506701340268,191.33656911082497,415.20173154264637,4.5572151024516
2.157449644762262e-07,0.007783156631326265,191.95823704282333,415.20173154264637,4.5572151024516
2.2479440885849208e-07,0.008109621924384877,192.7595760050412,415.20173154264637,4.5572151024516
2.3224689246741693e-07,0.008378475695139028,193.41009602659014,415.20173154264637,4.5572151024516
2.593952256142146e-07,0.009357871574314863,195.71393242508168,415.20173154264637,4.5572151024516
2.63121467418677e-07,0.009492298459691939,196.02263893806293,415.20173154264637,4.5572151024516
2.6897699025426087e-07,0.009703540708141629,196.5043264420101,415.20173154264637,4.5572151024516
2.8068803592542847e-07,0.010126025205041009,197.45560357544196,415.20173154264637,4.5572151024516
2.918667613388157e-07,0.010529305861172233,198.34930083169084,415.20173154264637,4.5572151024516
3.248706173211972e-07,0.011719943988797759,200.91301669339495,415.20173154264637,4.5572151024516
3.3551702247680414e-07,0.012104020804160832,201.71806776491718,415.20173154264637,4.5572151024516
3.5521287201467697e-07,0.012814562912582516,203.18162004856845,415.20173154264637,4.5572151024516
3.6692391768584456e-07,0.013237047409481896,204.03683686213265,415.20173154264637,4.5572151024516
3.834258456770353e-07,0.013832366473294659,205.22406077520301,415.20173154264637,4.5572151024516
3.882167279970584e-07,0.014005201040208042,205.56498395794682,415.20173154264637,4.5572151024516
3.924752900593012e-07,0.014158831766353271,205.8666517044463,415.20173154264637,4.5572151024516
4.0471865598824915e-07,0.014600520104020805,206.72691611802458,415.20173154264637,4.5572151024516
4.1004185856605264e-07,0.014792558511702341,207.09777168949583,415.20173154264637,4.5572151024516
4.24414505526122e-07,0.01531106221244249,208.08981997906164,415.20173154264637,4.5572151024516
4.3080234861948614e-07,0.015541508301660333,208.52651528129724,415.20173154264637,4.5572151024516
4.361255511972897e-07,0.01573354670934187,208.88850225297043,415.20173154264637,4.5572151024516
4.419810740328734e-07,0.01594478895779156,209.28470348686199,415.20173154264637,4.5572151024516
4.5315979944626066e-07,0.016348069613922784,210.03544874178772,415.20173154264637,4.5572151024516
4.632738843440872e-07,0.0167129425885177,210.7084932675611,415.20173154264637,4.5572151024516
4.6966172743745133e-07,0.016943388677735545,211.13062281935711,415.20173154264637,4.5572151024516
4.808404528508387e-07,0.017346669333866773,211.86400073757096,415.20173154264637,4.5572151024516
4.96810060584249e-07,0.017922784556911382,212.90025166299324,415.20173154264637,4.5572151024516
5.021332631620525e-07,0.01811482296459292,213.24277093002738,415.20173154264637,4.5572151024516
5.106503872865381e-07,0.018422084416883377,213.787870795147,415.20173154264637,4.5572151024516
5.441865635266999e-07,0.019631926385277054,215.90059480376993,415.20173154264637,4.5572151024516
5.50574406620064e-07,0.019862372474494898,216.2971949550065,415.20173154264637,4.5572151024516
5.553652889400872e-07,0.020035207041408282,216.59346845253594,415.20173154264637,4.5572151024516
5.606884915178906e-07,0.02022724544908982,216.92149464087046,415.20173154264637,4.5572151024516
5.654793738379137e-07,0.0204000800160032,217.21568119635077,415.20173154264637,4.5572151024516
5.825136220868848e-07,0.021014602920584116,218.2538958111963,415.20173154264637,4.5572151024516
5.87304504406908e-07,0.0211874374874975,218.54375150451264,415.20173154264637,4.5572151024516
5.942246677580524e-07,0.021437087417483496,218.9608092450212,415.20173154264637,4.5572151024516
5.979509095625149e-07,0.021571514302860573,219.18459403221038,415.20173154264637,4.5572151024516
6.064680336870005e-07,0.02187877575515103,219.69406977644624,415.20173154264637,4.5572151024516
6.16582118584827e-07,0.02224364872974595,220.29546204888481,415.20173154264637,4.5572151024516
6.373426086382606e-07,0.022992598519703943,221.51797738144074,415.20173154264637,4.5572151024516
6.437304517316247e-07,0.023223044608921786,221.89099833158815,415.20173154264637,4.5572151024516
6.538445366294512e-07,0.023587917583516704,222.478675943387,415.20173154264637,4.5572151024516
6.591677392072547e-07,0.02377995599119824,222.78655535007078,415.20173154264637,4.5572151024516
6.756696671984454e-07,0.024375275055011,223.73487652960824,415.20173154264637,4.5572151024516
6.788635887451275e-07,0.024490498099619923,223.9173746177643,415.20173154264637,4.5572151024516
6.927039154474165e-07,0.024989797959591917,224.7043614455458,415.20173154264637,4.5572151024516
6.974947977674397e-07,0.025162632526505302,224.97534804437913,415.20173154264637,4.5572151024516
7.203845688519945e-07,0.025988397679535907,226.2601736563452,415.20173154264637,4.5572151024516
7.368864968431853e-07,0.02658371674334867,227.17658575661875,415.20173154264637,4.5572151024516
7.592439476699599e-07,0.027390278055611124,228.40550907979778,415.20173154264637,4.5572151024516
7.688257123100061e-07,0.02773594718943789,228.92786081422815,415.20173154264637,4.5572151024516
7.757458756611505e-07,0.027985597119423885,229.30353713884153,415.20173154264637,4.5572151024516
7.842629997856361e-07,0.028292858571714343,229.7641185626894,415.20173154264637,4.5572151024516
7.874569213323182e-07,0.028408081616323265,229.9363331453842,415.20173154264637,4.5572151024516
8.039588493235088e-07,0.029003400680136026,230.82180570948674,415.20173154264637,4.5572151024516
8.07152770870191e-07,0.029118623724744948,230.99236572687582,415.20173154264637,4.5572151024516
8.092820519013123e-07,0.029195439087817562,231.10592619784126,415.20173154264637,4.5572151024516
8.156698949946765e-07,0.029425885177035406,231.44591050487193,415.20173154264637,4.5572151024516
8.188638165413586e-07,0.029541108221644328,231.61551314518385,415.20173154264637,4.5572151024516
8.337687837592082e-07,0.03007881576315263,232.4036058054627,415.20173154264637,4.5572151024516
8.385596660792315e-07,0.030251650330066014,232.6557518959065,415.20173154264637,4.5572151024516
8.774190448971967e-07,0.03165353070614123,234.68058004502322,415.20173154264637,4.5572151024516
8.875331297950233e-07,0.03201840368073615,235.20181539892224,415.20173154264637,4.5572151024516
9.061643388173356e-07,0.03269053810762153,236.15596157601723,415.20173154264637,4.5572151024516
9.136168224262603e-07,0.032959391878375675,236.53547403879324,415.20173154264637,4.5572151024516
9.168107439729422e-07,0.033074614922984594,236.69775243203625,415.20173154264637,4.5572151024516
9.295864301596705e-07,0.03353550710142028,237.34467327475875,415.20173154264637,4.5572151024516
9.375712340263758e-07,0.03382356471294259,237.74723845931175,415.20173154264637,4.5572151024516
9.423621163463989e-07,0.03399639927985597,237.98813581376137,415.20173154264637,4.5572151024516
9.492822796975433e-07,0.034246049209841964,238.3352571395795,415.20173154264637,4.5572151024516
9.609933253687111e-07,0.03466853370674135,238.9204533792084,415.20173154264637,4.5572151024516
9.68445808977636e-07,0.0349373874774955,239.29140333312534,415.20173154264637,4.5572151024516
9.822861356799249e-07,0.03543668733746749,239.9773701120709,415.20173154264637,4.5572151024516
9.908032598044104e-07,0.03574394878975795,240.3976303472343,415.20173154264637,4.5572151024516
9.92932540835532e-07,0.03582076415283057,240.50247497089362,415.20173154264637,4.5572151024516
9.961264623822138e-07,0.035935987197439484,240.65957764756436,415.20173154264637,4.5572151024516
1.0062405472800405e-06,0.036300860172034405,241.15577836637934,415.20173154264637,4.5572151024516
1.0104991093422832e-06,0.036454490898179634,241.3641226301597,415.20173154264637,4.5572151024516
1.0179515929512082e-06,0.03672334466893379,241.72790299121615,415.20173154264637,4.5572151024516
1.0440352855824453e-06,0.03766433286657332,242.9930345285467,415.20173154264637,4.5572151024516
1.0568109717691735e-06,0.03812522504500901,243.60818838323277,415.20173154264637,4.5572151024516
1.0642634553780982e-06,0.03839407881576315,243.96568878872998,415.20173154264637,4.5572151024516
1.0754421807914854e-06,0.038797359471894374,244.50011422018778,415.20173154264637,4.5572151024516
1.083959304915971e-06,0.03910462092418483,244.90584260442046,415.20173154264637,4.5572151024516
1.0876855467204336e-06,0.03923904780956192,245.0829576051396,415.20173154264637,4.5572151024516
1.105252115227185e-06,0.03987277455491098,245.9147616519119,415.20173154264637,4.5572151024516
1.117495481156133e-06,0.04031446289257852,246.49145732250943,415.20173154264637,4.5572151024516
1.1260126052806186e-06,0.04062172434486898,246.89118442142,415.20173154264637,4.5572151024516
1.1371913306940058e-06,0.0410250050010002,247.41404131194554,415.20173154264637,4.5572151024516
1.146773095334052e-06,0.041370674134826965,247.86061093490824,415.20173154264637,4.5572151024516
1.1504993371385143e-06,0.041505101020204035,248.0338836140825,415.20173154264637,4.5572151024516
1.163807343583023e-06,0.04198519703940788,248.65093591256579,415.20173154264637,4.5572151024516
1.188294075440919e-06,0.04286857371474295,249.77916956659325,415.20173154264637,4.5572151024516
1.194681918534283e-06,0.04309901980396079,250.07199559722045,415.20173154264637,4.5572151024516
1.2010697616276473e-06,0.04332946589317864,250.3642116332755,415.20173154264637,4.5572151024516
1.2058606439476702e-06,0.043502300460092014,250.58297606347782,415.20173154264637,4.5572151024516
1.2154424085877167e-06,0.04384796959391879,251.019490663451,415.20173154264637,4.5572151024516
1.2308796960633468e-06,0.04440488097619524,251.71995183110306,415.20173154264637,4.5572151024516
1.2463169835389767e-06,0.0449617923584717,252.41699512561812,415.20173154264637,4.5572151024516
1.2596249899834852e-06,0.04544188837767553,253.01519627612575,415.20173154264637,4.5572151024516
1.2750622774591157e-06,0.045998799759952,253.70603037645395,415.20173154264637,4.5572151024516
1.2793208395213584e-06,0.046152430486097226,253.8960302732721,415.20173154264637,4.5572151024516
1.2873056433880635e-06,0.046440488097619526,254.25161657301322,415.20173154264637,4.5572151024516
1.2931611662236473e-06,0.04665173034606922,254.51183340289586,415.20173154264637,4.5572151024516
1.3027429308636934e-06,0.04699739947989598,254.93665373227958,415.20173154264637,4.5572151024516
1.3144539765348613e-06,0.04741988397679536,255.4542273057817,415.20173154264637,4.5572151024516
1.326165022206029e-06,0.047842368473694746,255.97000556888537,415.20173154264637,4.5572151024516
1.3501194338061444e-06,0.04870654130826166,257.019506659403,415.20173154264637,4.5572151024516
1.3660890415395546e-06,0.04928265653130626,257.71514230006585,415.20173154264637,4.5572151024516
1.3682183225706762e-06,0.04935947189437888,257.8076535136854,415.20173154264637,4.5572151024516
1.3751384859218206e-06,0.049609121824364874,258.1079279282908,415.20173154264637,4.5572151024516
1.3847202505618666e-06,0.049954790958191636,258.5227214147897,415.20173154264637,4.5572151024516
1.3873818518507683e-06,0.0500508101620324,258.6377429782556,415.20173154264637,4.5572151024516
1.4214503483487105e-06,0.051279855971194235,260.1024997330085,415.20173154264637,4.5572151024516
1.4304997927309767e-06,0.05160632126425285,260.48926617655076,415.20173154264637,4.5572151024516
1.434226034535439e-06,0.05174074814962992,260.6482454596971,415.20173154264637,4.5572151024516
1.4390169168554623e-06,0.05191358271654331,260.85241089771733,415.20173154264637,4.5572151024516
1.45072796252663e-06,0.052336067213442694,261.35036915906477,415.20173154264637,4.5572151024516
1.4608420474244565e-06,0.052700940188037615,261.7791637266372,415.20173154264637,4.5572151024516
1.468294531033381e-06,0.052969793958791755,262.09437711814155,415.20173154264637,4.5572151024516
1.4720207728378437e-06,0.05310422084416884,262.25174978448575,415.20173154264637,4.5572151024516
1.4869257400556934e-06,0.053641928385677135,262.87969300350244,415.20173154264637,4.5572151024516
1.4917166223757165e-06,0.05381476295259052,263.08100992128004,415.20173154264637,4.5572151024516
1.5188649555225143e-06,0.05479415883176636,264.2170784619835,415.20173154264637,4.5572151024516
1.5284467201625604e-06,0.05513982796559312,264.616149429823,415.20173154264637,4.5572151024516
1.535366883513705e-06,0.05538947789557912,264.90376080761547,415.20173154264637,4.5572151024516
1.5412224063492888e-06,0.05560072014402881,265.14672962271,415.20173154264637,4.5572151024516
1.5422870468648493e-06,0.05563912782556511,265.19086706495096,415.20173154264637,4.5572151024516
1.5476102494426527e-06,0.055831166233246646,265.4113762894518,415.20173154264637,4.5572151024516
1.5518688115048953e-06,0.055984796959391875,265.58757076535613,415.20173154264637,4.5572151024516
1.55878897485604e-06,0.05623444688937787,265.87348514451133,415.20173154264637,4.5572151024516
1.5689030597538666e-06,0.05659931986397279,266.29047115038924,415.20173154264637,4.5572151024516
1.5699677002694276e-06,0.05663772754550911,266.3343033417544,415.20173154264637,4.5572151024516
1.584872667487277e-06,0.057175435087017404,266.9467419319989,415.20173154264637,4.5572151024516
1.5955190726428842e-06,0.057559511902380484,267.38282358728776,415.20173154264637,4.5572151024516
1.601906915736248e-06,0.05778995799159832,267.64392789096723,415.20173154264637,4.5572151024516
1.6216027652741209e-06,0.05850050010002,268.44645499695565,415.20173154264637,4.5572151024516
1.6375723730075314e-06,0.059076615323064616,269.0943654952682,415.20173154264637,4.5572151024516
1.6434278958431153e-06,0.05928785757151431,269.33131466384003,415.20173154264637,4.5572151024516
1.6583328630609647e-06,0.0598255651130226,269.9329770601049,415.20173154264637,4.5572151024516
1.6774963923410575e-06,0.06051690338067614,270.70345308880553,415.20173154264637,4.5572151024516
1.6822872746610804e-06,0.060689737947589514,270.8955347925903,415.20173154264637,4.5572151024516
1.6892074380122247e-06,0.06093938787757551,271.17260993939635,415.20173154264637,4.5572151024516
1.693998320332248e-06,0.0611122224444889,271.3641719251971,415.20173154264637,4.5572151024516
1.7019831241989532e-06,0.0614002800560112,271.6829730377748,415.20173154264637,4.5572151024516
1.708903287550098e-06,0.06164992998599721,271.9587958018874,415.20173154264637,4.5572151024516
1.7211466534790457e-06,0.062091618323664735,272.44572518894904,415.20173154264637,4.5572151024516
1.7238082547679474e-06,0.0621876375275055,272.55140043537324,415.20173154264637,4.5572151024516
1.725937535799069e-06,0.06226445289057812,272.6358948229698,415.20173154264637,4.5572151024516
1.7472303461102826e-06,0.06303260652130425,273.47861469707976,415.20173154264637,4.5572151024516
1.756812110750329e-06,0.06337827565513103,273.8565309509544,415.20173154264637,4.5572151024516
1.7669261956481556e-06,0.06374314862972595,274.25457150710196,415.20173154264637,4.5572151024516
1.7717170779681785e-06,0.06391598319663933,274.44280680180395,415.20173154264637,4.5572151024516
1.778637241319323e-06,0.06416563312662532,274.7143521468176,415.20173154264637,4.5572151024516
1.7903482869904908e-06,0.0645881176235247,275.17295363440485,415.20173154264637,4.5572151024516
1.7951391693105139e-06,0.06476095219043809,275.3602259589739,415.20173154264637,4.5572151024516
1.818561260652849e-06,0.06560592118423685,276.2729885030385,415.20173154264637,4.5572151024516
1.8409187114796235e-06,0.0664124824964993,277.13999434068245,415.20173154264637,4.5572151024516
1.8648731230797394e-06,0.06727665533106622,278.0643846378249,415.20173154264637,4.5572151024516
1.8670024041108606e-06,0.06735347069413883,278.146327897942,415.20173154264637,4.5572151024516
1.8701963256575428e-06,0.06746869373874775,278.26917448254864,415.20173154264637,4.5572151024516
1.88137505107093e-06,0.06787197439487898,278.69849467219984,415.20173154264637,4.5572151024516
1.890424495453196e-06,0.0681984396879376,279.04531138249064,415.20173154264637,4.5572151024516
1.9016032208665833e-06,0.06860172034406882,279.47283939150975,415.20173154264637,4.5572151024516
1.913314266537751e-06,0.0690242048409682,279.91967591600417,415.20173154264637,4.5572151024516
1.933542436333404e-06,0.06975395079015803,280.68898021763596,415.20173154264637,4.5572151024516
1.9393979591689876e-06,0.06996519303860772,280.9110869283194,415.20173154264637,4.5572151024516
1.950576684582375e-06,0.07036847369473895,281.33438393855494,415.20173154264637,4.5572151024516
1.9553675669023982e-06,0.07054130826165234,281.51550720234684,415.20173154264637,4.5572151024516
1.9638846910268836e-06,0.0708485697139428,281.83707735809753,415.20173154264637,4.5572151024516
1.990500703915901e-06,0.07180876175235047,282.8384962894912,415.20173154264637,4.5572151024516
2.00380871036041e-06,0.07228885777155432,283.33724639716144,415.20173154264637,4.5572151024516
2.0128581547426754e-06,0.07261532306461292,283.67565880341726,415.20173154264637,4.5572151024516
2.0362802460850108e-06,0.07346029205841169,284.5488058509978,415.20173154264637,4.5572151024516
2.0453296904672764e-06,0.07378675735147029,284.8851080077936,415.20173154264637,4.5572151024516
2.0501205727873e-06,0.07395959191838368,285.0629153703347,415.20173154264637,4.5572151024516
2.0527821740762016e-06,0.07405561112222445,285.1616272147483,415.20173154264637,4.5572151024516
2.068751781809612e-06,0.07463172634526906,285.75285345703895,415.20173154264637,4.5572151024516
2.0820597882541207e-06,0.0751118223644729,286.2441835419623,415.20173154264637,4.5572151024516
2.0884476313474845e-06,0.07534226845369074,286.4795868115278,415.20173154264637,4.5572151024516
2.092173873151947e-06,0.07547669533906781,286.61677570788873,415.20173154264637,4.5572151024516
2.0969647554719703e-06,0.0756495299059812,286.7930214922457,415.20173154264637,4.5572151024516
2.116128284752063e-06,0.07634086817363474,287.4964398945757,415.20173154264637,4.5572151024516
2.124113088618768e-06,0.07662892578515704,287.78879716268295,415.20173154264637,4.5572151024516
2.137421095063277e-06,0.07710902180436088,288.2751085995557,415.20173154264637,4.5572151024516
2.1768127941390223e-06,0.07853010602120425,289.7077166136389,415.20173154264637,4.5572151024516
2.1970409639346754e-06,0.07925985197039408,290.439448866394,415.20173154264637,4.5572151024516
2.205025767801381e-06,0.07954790958191639,290.7275666918972,415.20173154264637,4.5572151024516
2.222060016050352e-06,0.0801624324864973,291.34086163875435,415.20173154264637,4.5572151024516
2.2236569768236927e-06,0.08022004400880177,291.3982638702161,415.20173154264637,4.5572151024516
2.225786257854814e-06,0.08029685937187438,291.4747751755831,415.20173154264637,4.5572151024516
2.24974066945493e-06,0.08116103220644129,292.3335696324025,415.20173154264637,4.5572151024516
2.254531551774953e-06,0.08133386677335468,292.50489977287737,415.20173154264637,4.5572151024516
2.2752920418283862e-06,0.08208281656331266,293.24569564051313,415.20173154264637,4.5572151024516
2.277953643117288e-06,0.08217883576715343,293.3404784586956,415.20173154264637,4.5572151024516
2.29605253188182e-06,0.08283176635327066,293.98386003881205,415.20173154264637,4.5572151024516
2.300843414201843e-06,0.08300460092018404,294.1538354702583,415.20173154264637,4.5572151024516
2.3157483814196927e-06,0.08354230846169235,294.681767349437,415.20173154264637,4.5572151024516
2.3189423029663747e-06,0.08365753150630126,294.79472300939045,415.20173154264637,4.5572151024516
2.3311856688953226e-06,0.0840992198439688,295.22715878671335,415.20173154264637,4.5572151024516
2.333314949926444e-06,0.08417603520704141,295.30227450280086,415.20173154264637,4.5572151024516
2.3359765512153458e-06,0.08427205441088217,295.39613156464657,415.20173154264637,4.5572151024516
2.3524784792065366e-06,0.08486737347469495,295.97711720473734,415.20173154264637,4.5572151024516
2.3572693615265597e-06,0.08504020804160832,296.14549246772646,415.20173154264637,4.5572151024516
2.3721743287444094e-06,0.08557791558311663,296.6684751652177,415.20173154264637,4.5572151024516
2.3939994593134036e-06,0.08636527305461093,297.4319649864006,415.20173154264637,4.5572151024516
2.4120983480779356e-06,0.08701820364072815,298.06304609589773,415.20173154264637,4.5572151024516
2.427003315295785e-06,0.08755591118223645,298.581374460317,415.20173154264637,4.5572151024516
2.428600276069126e-06,0.08761352270454091,298.63683591091063,415.20173154264637,4.5572151024516
2.4339234786469294e-06,0.08780556111222244,298.8216047766355,415.20173154264637,4.5572151024516
2.4397790014825135e-06,0.08801680336067214,299.02466859541494,415.20173154264637,4.5572151024516
2.44989308638034e-06,0.08838167633526706,299.37496807715263,415.20173154264637,4.5572151024516
2.462136452309288e-06,0.08882336467293458,299.7982611139137,415.20173154264637,4.5572151024516
2.471185896691554e-06,0.0891498299659932,300.11060245710934,415.20173154264637,4.5572151024516
2.491414066487207e-06,0.08987957591518304,300.8071687529375,415.20173154264637,4.5572151024516
2.512706876798421e-06,0.09064772954590919,301.5380177973913,415.20173154264637,4.5572151024516
2.5398552099452185e-06,0.09162712542508503,302.46635677380146,415.20173154264637,4.5572151024516
2.551566255616386e-06,0.0920496099219844,302.8656210758599,415.20173154264637,4.5572151024516
2.5648742620608947e-06,0.09252970594118824,303.31846401905017,415.20173154264637,4.5572151024516
2.569665144380918e-06,0.09270254050810163,303.4812630384825,415.20173154264637,4.5572151024516
2.5755206672165015e-06,0.09291378275655131,303.680078952454,415.20173154264637,4.5572151024516
2.583505471083207e-06,0.09320184036807362,303.9509077002765,415.20173154264637,4.5572151024516
2.5930872357232532e-06,0.09354750950190038,304.2754716679297,415.20173154264637,4.5572151024516
2.6053306016522008e-06,0.09398919783956791,304.6895124445998,415.20173154264637,4.5572151024516
2.6181062878389294e-06,0.0944500900180036,305.1207467694287,415.20173154264637,4.5572151024516
2.6234294904167328e-06,0.09464212842568515,305.3001854333649,415.20173154264637,4.5572151024516
2.6356728563456807e-06,0.09508381676335267,305.71235634477944,415.20173154264637,4.5572151024516
2.6383344576345824e-06,0.09517983596719344,305.80185983131895,415.20173154264637,4.5572151024516
2.654304065367993e-06,0.09575595119023805,306.33814311957667,415.20173154264637,4.5572151024516
2.6718706338747448e-06,0.09638967793558713,306.92660343554064,415.20173154264637,4.5572151024516
2.6899695226392764e-06,0.09704260852170435,307.5313198820747,415.20173154264637,4.5572151024516
2.699018967021542e-06,0.09736907381476295,307.8330829072841,415.20173154264637,4.5572151024516
2.710197692434929e-06,0.09777235447089418,308.2053047699321,415.20173154264637,4.5572151024516
2.7219087381060967e-06,0.09819483896779356,308.5946098406584,415.20173154264637,4.5572151024516
2.7304258622305824e-06,0.09850210042008402,308.877330617957,415.20173154264637,4.5572151024516
2.74213690790175e-06,0.0989245849169834,309.26551073811095,415.20173154264637,4.5572151024516
2.761832757439623e-06,0.09963512702540508,309.9169042026195,415.20173154264637,4.5572151024516
2.7682206005329872e-06,0.09986557311462294,310.1277775469127,415.20173154264637,4.5572151024516