File: datasets/aisi_316_L/data/M1/valid_27.csv
Time(s),Strain(%),Stress(MPa),Temp(C),Log_SR(s-1)
0.0,0.0,0.0,426.92119414890095,-1.2116963979009219
0.00015630311416591584,9.6e-06,1.6032661499999998,426.92119414890095,-1.2116963979009219
0.0006252124566636634,3.84e-05,6.413064599999999,426.92119414890095,-1.2116963979009219
0.0006773134947189686,4.1599999999999995e-05,6.947486649999999,426.92119414890095,-1.2116963979009219
0.0010810965396475848,6.64e-05,11.0892575375,426.92119414890095,-1.2116963979009219
0.001302525951382632,7.999999999999999e-05,13.360551249999999,426.92119414890095,-1.2116963979009219
0.0014718543250623745,9.04e-05,15.0974229125,426.92119414890095,-1.2116963979009219
0.0015369806226315059,9.439999999999999e-05,15.765450474999998,426.92119414890095,-1.2116963979009219
0.0016672332177697692,0.0001024,17.1015056,426.92119414890095,-1.2116963979009219
0.0020840415222122114,0.000128,21.376882,426.92119414890095,-1.2116963979009219
0.002305470933947259,0.0001416,23.6481757125,426.92119414890095,-1.2116963979009219
0.0025269003456823065,0.0001552,25.919469425,426.92119414890095,-1.2116963979009219
0.0026441276813067432,0.0001624,27.1219190375,426.92119414890095,-1.2116963979009219
0.0028004307954726587,0.00017199999999999998,28.725185187499996,426.92119414890095,-1.2116963979009219
0.002878582352555617,0.0001768,29.526818262499997,426.92119414890095,-1.2116963979009219
0.002969759169152401,0.0001824,30.46205685,426.92119414890095,-1.2116963979009219
0.0031000117642906643,0.0001904,31.798111974999998,426.92119414890095,-1.2116963979009219
0.0033084159165118854,0.00020319999999999998,33.935800175,426.92119414890095,-1.2116963979009219
0.0033474916950533644,0.00020559999999999998,34.336616712499996,426.92119414890095,-1.2116963979009219
0.0034777442901916277,0.0002136,35.6726718375,426.92119414890095,-1.2116963979009219
0.003555895847274586,0.0002184,36.4743049125,426.92119414890095,-1.2116963979009219
0.003855476816092591,0.00023679999999999998,39.5472317,426.92119414890095,-1.2116963979009219
0.004337411418104164,0.00026639999999999997,44.4906356625,426.92119414890095,-1.2116963979009219
0.00438951245615947,0.0002696,45.0250577125,426.92119414890095,-1.2116963979009219
0.004962623874767829,0.0003048,50.903700262499996,426.92119414890095,-1.2116963979009219
0.005118926988933744,0.0003144,52.5069664125,426.92119414890095,-1.2116963979009219
0.0052752301030996596,0.00032399999999999996,54.110232562499995,426.92119414890095,-1.2116963979009219
0.0056399373694867964,0.00034639999999999996,57.85118691249999,426.92119414890095,-1.2116963979009219
0.0057441394455974085,0.0003528,58.920031012500004,426.92119414890095,-1.2116963979009219
0.005822291002680365,0.00035759999999999996,59.721664087499995,426.92119414890095,-1.2116963979009219
0.005874392040735671,0.0003608,60.2560861375,426.92119414890095,-1.2116963979009219
0.0060827961929568915,0.0003736,62.3937743375,426.92119414890095,-1.2116963979009219
0.006421452940316376,0.0003944,65.86751766249999,426.92119414890095,-1.2116963979009219
0.006473553978371681,0.00039759999999999996,66.4019397125,426.92119414890095,-1.2116963979009219
0.0065777560544822925,0.000404,67.4707838125,426.92119414890095,-1.2116963979009219
0.006734059168648208,0.00041359999999999997,69.0740499625,426.92119414890095,-1.2116963979009219
0.0070075896184385615,0.0004304,71.879765725,426.92119414890095,-1.2116963979009219
0.007124816954062997,0.00043759999999999996,73.08221533749999,426.92119414890095,-1.2116963979009219
0.0073853221443395236,0.00045359999999999997,75.75432558749999,426.92119414890095,-1.2116963979009219
0.00743742318239483,0.0004568,76.2887476375,426.92119414890095,-1.2116963979009219
0.00754162525850544,0.0004632,77.3575917375,426.92119414890095,-1.2116963979009219
0.007971458822461709,0.0004896,81.76657365,426.92119414890095,-1.2116963979009219
0.0083622166078765,0.0005136,85.774739025,426.92119414890095,-1.2116963979009219
0.008648772317180678,0.0005312,88.7140603,426.92119414890095,-1.2116963979009219
0.009039530102595466,0.0005551999999999999,92.72222567499999,426.92119414890095,-1.2116963979009219
0.009339111071413471,0.0005736,95.7951524625,426.92119414890095,-1.2116963979009219
0.009651717299745304,0.0005928,99.00168476249999,426.92119414890095,-1.2116963979009219
0.009716843597314435,0.0005968,99.66971232499999,426.92119414890095,-1.2116963979009219
0.010368106573005752,0.0006368,106.34998795,426.92119414890095,-1.2116963979009219
0.010615586503768452,0.000652,108.8884926875,426.92119414890095,-1.2116963979009219
0.010771889617934367,0.0006615999999999999,110.49175883749999,426.92119414890095,-1.2116963979009219
0.011019369548697068,0.0006768,113.03026357499999,426.92119414890095,-1.2116963979009219
0.011175672662862984,0.0006864,114.633529725,426.92119414890095,-1.2116963979009219
0.011566430448277772,0.0007103999999999999,118.64169509999999,426.92119414890095,-1.2116963979009219
0.012230718683482916,0.0007511999999999999,125.45557623749998,426.92119414890095,-1.2116963979009219
0.012400047057162657,0.0007616,127.19244789999999,426.92119414890095,-1.2116963979009219
0.012999208994798669,0.0007984,133.338301475,426.92119414890095,-1.2116963979009219
0.013233663666047541,0.0008127999999999999,135.7432007,426.92119414890095,-1.2116963979009219
0.013416017299241112,0.000824,137.613677875,426.92119414890095,-1.2116963979009219
0.013611396191948505,0.0008359999999999999,139.6177605625,426.92119414890095,-1.2116963979009219
0.013871901382225032,0.000852,142.2898708125,426.92119414890095,-1.2116963979009219
0.013924002420280338,0.0008552,142.8242928625,426.92119414890095,-1.2116963979009219
0.014119381312987732,0.0008671999999999999,144.82837554999998,426.92119414890095,-1.2116963979009219
0.014288709686667475,0.0008776,145.9526129107235,426.92119414890095,-1.2116963979009219
0.014796694807706701,0.0009088,146.1079795897623,426.92119414890095,-1.2116963979009219
0.014992073700414095,0.0009207999999999999,146.1671803181422,426.92119414890095,-1.2116963979009219
0.015487033561939496,0.0009511999999999999,146.31582441556583,426.92119414890095,-1.2116963979009219
0.01565636193561924,0.0009616,146.36624947106299,426.92119414890095,-1.2116963979009219
0.01579963979027133,0.0009704,146.4087509188051,426.92119414890095,-1.2116963979009219
0.015851740828326633,0.0009735999999999999,146.42416868864822,426.92119414890095,-1.2116963979009219
0.015955942904437245,0.00098,146.45494506670065,426.92119414890095,-1.2116963979009219
0.016424852246934993,0.0010088,146.59248005618628,426.92119414890095,-1.2116963979009219
0.01654207958255943,0.001016,146.62662347271797,426.92119414890095,-1.2116963979009219
0.016737458475266823,0.001028,146.6833202098295,426.92119414890095,-1.2116963979009219
0.016789559513322127,0.0010312,146.69839567292064,426.92119414890095,-1.2116963979009219
0.016984938406029524,0.0010432,146.7547669012089,426.92119414890095,-1.2116963979009219
0.01710216574165396,0.0010504,146.78846826136603,426.92119414890095,-1.2116963979009219
0.01719334255825074,0.0010559999999999999,146.8146181828715,426.92119414890095,-1.2116963979009219
0.017818555014914406,0.0010944,146.9924970051101,426.92119414890095,-1.2116963979009219
0.01807906020519093,0.0011103999999999999,147.06589278274305,426.92119414890095,-1.2116963979009219
0.018417716952550418,0.0011312,147.16069359595383,426.92119414890095,-1.2116963979009219
0.019003853630672602,0.0011672,147.32318079568944,426.92119414890095,-1.2116963979009219
0.01934251037803209,0.001188,147.41617129326775,426.92119414890095,-1.2116963979009219
0.019629066087336267,0.0012056,147.49436065893588,426.92119414890095,-1.2116963979009219
0.01968116712539157,0.0012088,147.50852894985567,426.92119414890095,-1.2116963979009219
0.019915621796640446,0.0012232,147.57210610494096,426.92119414890095,-1.2116963979009219
0.020228228024972275,0.0012423999999999998,147.65642342627535,426.92119414890095,-1.2116963979009219
0.02039755639865202,0.0012527999999999999,147.70188306134716,426.92119414890095,-1.2116963979009219
0.02052780899379028,0.0012607999999999999,147.7367519330256,426.92119414890095,-1.2116963979009219
0.021126970931426292,0.0012975999999999999,147.89605027619322,426.92119414890095,-1.2116963979009219
0.021439577159758125,0.0013168,147.9784624304256,426.92119414890095,-1.2116963979009219
0.021687057090520823,0.0013319999999999999,148.04337349321077,426.92119414890095,-1.2116963979009219
0.021960587540311178,0.0013488,148.11478212569622,426.92119414890095,-1.2116963979009219
0.02211689065447709,0.0013583999999999998,148.1554313075098,426.92119414890095,-1.2116963979009219
0.022273193768643007,0.0013679999999999999,148.19596860585273,426.92119414890095,-1.2116963979009219
0.022455547401836577,0.0013792,148.24312216531405,426.92119414890095,-1.2116963979009219
0.02285933044676519,0.0014039999999999999,148.3470054060712,426.92119414890095,-1.2116963979009219
0.022924456744334326,0.001408,148.36369351448846,426.92119414890095,-1.2116963979009219
0.02318496193461085,0.001424,148.43026187840786,426.92119414890095,-1.2116963979009219
0.02379714913176069,0.0014616,148.58555972449247,426.92119414890095,-1.2116963979009219
0.024109755360092522,0.0014808,148.664259274123,426.92119414890095,-1.2116963979009219
0.024279083733772265,0.0014912,148.70672199324753,426.92119414890095,-1.2116963979009219
0.024305134252799915,0.0014927999999999999,148.71324445392958,426.92119414890095,-1.2116963979009219
0.0243963110693967,0.0014984,148.7360516267495,426.92119414890095,-1.2116963979009219
0.024839169892866796,0.0015256,148.84635992814245,426.92119414890095,-1.2116963979009219
0.025360180273419845,0.0015576,148.9751571687076,426.92119414890095,-1.2116963979009219
0.025581609685154896,0.0015712,149.02958303141693,426.92119414890095,-1.2116963979009219
0.02584211487543142,0.0015872,149.09337879262264,426.92119414890095,-1.2116963979009219
0.026089594806194123,0.0016024,149.15375285059451,426.92119414890095,-1.2116963979009219
0.02624589792036004,0.001612,149.19176878150407,426.92119414890095,-1.2116963979009219
0.026532453629664218,0.0016296,149.26123612071063,426.92119414890095,-1.2116963979009219
0.026779933560426916,0.0016447999999999999,149.32099549937843,426.92119414890095,-1.2116963979009219
0.02698833771264814,0.0016576,149.3711523201793,426.92119414890095,-1.2116963979009219
0.027457247055145885,0.0016864,149.48345615045284,426.92119414890095,-1.2116963979009219
0.02790010587861598,0.0017136,149.58883601910503,426.92119414890095,-1.2116963979009219
0.028095484771323374,0.0017255999999999999,149.63511953479068,426.92119414890095,-1.2116963979009219
0.02829086366403077,0.0017376,149.68127769380632,426.92119414890095,-1.2116963979009219
0.028785823525556167,0.0017679999999999998,149.79765873256903,426.92119414890095,-1.2116963979009219
0.02907237923486035,0.0017855999999999998,149.86468050586987,426.92119414890095,-1.2116963979009219
0.029358934944164528,0.0018031999999999998,149.93144513129891,426.92119414890095,-1.2116963979009219
0.029684566432010184,0.0018231999999999999,150.00700630217693,426.92119414890095,-1.2116963979009219
0.029997172660342016,0.0018424,150.07924147936737,426.92119414890095,-1.2116963979009219
0.030244652591104718,0.0018575999999999998,150.13621966200682,426.92119414890095,-1.2116963979009219
0.030817764009713075,0.0018927999999999998,150.26747557440962,426.92119414890095,-1.2116963979009219
0.03123457231415552,0.0019184,150.362337223979,426.92119414890095,-1.2116963979009219
0.03140390068783526,0.0019287999999999998,150.40073359532647,426.92119414890095,-1.2116963979009219
0.031794658473250054,0.0019528,150.48903376805796,426.92119414890095,-1.2116963979009219
0.032081214182554225,0.0019703999999999998,150.55351847014913,426.92119414890095,-1.2116963979009219
0.03228961833477545,0.0019832,150.60027542641873,426.92119414890095,-1.2116963979009219
0.03261524982262111,0.0020032,150.6730982405553,426.92119414890095,-1.2116963979009219
0.032771552936787025,0.0020128,150.70795242522064,426.92119414890095,-1.2116963979009219
0.03343584117199217,0.0020536,150.8553652236912,426.92119414890095,-1.2116963979009219
0.03386567473594843,0.00208,150.95014167592055,426.92119414890095,-1.2116963979009219
0.03400895259060053,0.0020888,150.98162942012786,426.92119414890095,-1.2116963979009219
0.03420433148330792,0.0021008,151.02448400420332,426.92119414890095,-1.2116963979009219
0.03442576089504296,0.0021144,151.0729372906891,426.92119414890095,-1.2116963979009219
0.03462113978775037,0.0021264,151.1155893433622,426.92119414890095,-1.2116963979009219
0.034738367123374796,0.0021336,151.14113551819557,426.92119414890095,-1.2116963979009219
0.03485559445899924,0.0021408,151.16664809411708,426.92119414890095,-1.2116963979009219
0.035103074389761936,0.002156,151.2203983442756,426.92119414890095,-1.2116963979009219
0.03531147854198315,0.0021688,151.265547182297,426.92119414890095,-1.2116963979009219
0.03550685743469056,0.0021808,151.3077799287518,426.92119414890095,-1.2116963979009219
0.03632744878406161,0.0022312,151.48417677889216,426.92119414890095,-1.2116963979009219
0.036600979233851964,0.002248,151.54262949169706,426.92119414890095,-1.2116963979009219
0.0367703076075317,0.0022584,151.57872913956223,426.92119414890095,-1.2116963979009219
0.036874509683642316,0.0022648,151.60091208490866,426.92119414890095,-1.2116963979009219
0.03704383805732205,0.0022752,151.63690730039332,426.92119414890095,-1.2116963979009219
0.0374606463617645,0.0023008,151.72523860859195,426.92119414890095,-1.2116963979009219
0.03765602525447189,0.0023128,151.76651188545387,426.92119414890095,-1.2116963979009219
0.03805980829940051,0.0023376,151.85154627358978,426.92119414890095,-1.2116963979009219
0.038515692382384434,0.0023656,151.9471311081702,426.92119414890095,-1.2116963979009219
0.03868502075606418,0.002376,151.98252153713577,426.92119414890095,-1.2116963979009219
0.03880224809168861,0.0023832,152.006987220943,426.92119414890095,-1.2116963979009219
0.039258132174672535,0.0024112,152.10185877652953,426.92119414890095,-1.2116963979009219
0.03937535951029697,0.0024184,152.12618475092816,426.92119414890095,-1.2116963979009219
0.03960981418154584,0.0024327999999999997,152.17475213061437,426.92119414890095,-1.2116963979009219
0.0397400667766841,0.0024408,152.20168555995113,426.92119414890095,-1.2116963979009219
0.040235026638209506,0.0024712,152.30372013077897,426.92119414890095,-1.2116963979009219
0.04057368338556899,0.002492,152.37325136631281,426.92119414890095,-1.2116963979009219
0.040625784423624293,0.0024952,152.38392835699128,426.92119414890095,-1.2116963979009219
0.04097746643049761,0.0025168,152.4558588738332,426.92119414890095,-1.2116963979009219
0.04121192110174648,0.0025312,152.5036788418791,426.92119414890095,-1.2116963979009219
0.04148545155153684,0.002548,152.55933491407842,426.92119414890095,-1.2116963979009219
0.041824108298896316,0.0025688,152.62804454349185,426.92119414890095,-1.2116963979009219
0.04209763874868667,0.0025856,152.68338251655675,426.92119414890095,-1.2116963979009219
0.042253941862852584,0.0025951999999999998,152.71494125401233,426.92119414890095,-1.2116963979009219
0.042527472312642936,0.0026119999999999997,152.77005971015265,426.92119414890095,-1.2116963979009219
0.04263167438875355,0.0026184,152.7910208278078,426.92119414890095,-1.2116963979009219
0.04267075016729503,0.0026208,152.79887609431398,426.92119414890095,-1.2116963979009219
0.04273587646486416,0.0026248,152.81196197369275,426.92119414890095,-1.2116963979009219
0.043178735288334255,0.002652,152.9007405987306,426.92119414890095,-1.2116963979009219
0.043374114181041645,0.0026639999999999997,152.9397946706791,426.92119414890095,-1.2116963979009219
0.04353041729520757,0.0026736,152.9709885527226,426.92119414890095,-1.2116963979009219
0.04412957923284358,0.0027104,153.0901626023037,426.92119414890095,-1.2116963979009219
0.044351008644578624,0.002724,153.134045272381,426.92119414890095,-1.2116963979009219
0.044754791689507245,0.0027488,153.21384727069199,426.92119414890095,-1.2116963979009219
0.04526277681054647,0.00278,153.3138456164431,426.92119414890095,-1.2116963979009219
0.04548420622228151,0.0027936,153.35729755894417,426.92119414890095,-1.2116963979009219
0.04554933251985065,0.0027976,153.37006183140565,426.92119414890095,-1.2116963979009219
0.045757736672071864,0.0028104,153.4108597556632,426.92119414890095,-1.2116963979009219
0.04595311556477927,0.0028224,153.44904204375442,426.92119414890095,-1.2116963979009219
0.04663042905949823,0.002864,153.58091989353414,426.92119414890095,-1.2116963979009219
0.0471644646995651,0.0028967999999999997,153.6843745016088,426.92119414890095,-1.2116963979009219
0.04746404566838311,0.0029151999999999997,153.74220996842314,426.92119414890095,-1.2116963979009219
0.047646399301576686,0.0029264,153.77734446814614,426.92119414890095,-1.2116963979009219
0.0481022833845606,0.0029544,153.86495205871208,426.92119414890095,-1.2116963979009219
0.04837581383435095,0.0029712,153.91736119505944,426.92119414890095,-1.2116963979009219
0.04850606642948922,0.0029792,153.94227729535208,426.92119414890095,-1.2116963979009219
0.04866236954365513,0.0029888,153.97214219860157,426.92119414890095,-1.2116963979009219
0.04875354636025192,0.0029944,153.9895461156116,426.92119414890095,-1.2116963979009219
0.04888379895539018,0.0030023999999999997,154.01438685060714,426.92119414890095,-1.2116963979009219
0.04943085985497089,0.003036,154.11843730351254,426.92119414890095,-1.2116963979009219
0.04945691037399854,0.0030375999999999997,154.1233808541595,426.92119414890095,-1.2116963979009219
0.04965228926670594,0.0030496,154.16042516852235,426.92119414890095,-1.2116963979009219
0.0499779207545516,0.0030696,154.22203961018602,426.92119414890095,-1.2116963979009219
0.05005607231163455,0.0030743999999999997,154.2368037553223,426.92119414890095,-1.2116963979009219
0.05019935016628664,0.0030832,154.26384802717163,426.92119414890095,-1.2116963979009219
0.05034262802093873,0.0030919999999999997,154.29086221195155,426.92119414890095,-1.2116963979009219
0.05066825950878439,0.0031119999999999997,154.35214682113244,426.92119414890095,-1.2116963979009219
0.050876663661005614,0.0031248,154.39128837308564,426.92119414890095,-1.2116963979009219
0.05098086573711622,0.0031311999999999998,154.4108356966409,426.92119414890095,-1.2116963979009219
0.05109809307274066,0.0031384,154.43280781997933,426.92119414890095,-1.2116963979009219
0.05141069930107249,0.0031576,154.4913042508018,426.92119414890095,-1.2116963979009219
0.05159305293426606,0.0031688,154.52536310773465,426.92119414890095,-1.2116963979009219
0.05193170968162554,0.0031896,154.58849097400338,426.92119414890095,-1.2116963979009219
0.052035911757736156,0.003196,154.60788260603442,426.92119414890095,-1.2116963979009219
0.05219221487190207,0.0032056,154.6369416825315,426.92119414890095,-1.2116963979009219
0.05279137680953808,0.0032424,154.74802180521797,426.92119414890095,-1.2116963979009219
0.05315608407592522,0.0032648,154.81539509871223,426.92119414890095,-1.2116963979009219
0.05333843770911879,0.003276,154.84901412368094,426.92119414890095,-1.2116963979009219
0.05352079134231235,0.0032871999999999997,154.8825883530491,426.92119414890095,-1.2116963979009219
0.05367709445647827,0.0032968,154.91133077104843,426.92119414890095,-1.2116963979009219
0.053820372311130356,0.0033055999999999997,154.93764932614283,426.92119414890095,-1.2116963979009219
0.05402877646335158,0.0033184,154.97588213495763,426.92119414890095,-1.2116963979009219
0.054185079577517496,0.003328,155.00451900871138,426.92119414890095,-1.2116963979009219
0.054237180615572804,0.0033312,155.01405747171944,426.92119414890095,-1.2116963979009219
0.054510711065363156,0.003348,155.06407589649768,426.92119414890095,-1.2116963979009219
0.05510987300299917,0.0033848,155.17329929304074,426.92119414890095,-1.2116963979009219
0.05556575708598308,0.0034127999999999997,155.25609408634492,426.92119414890095,-1.2116963979009219
0.0559695401309117,0.0034376,155.3292056373472,426.92119414890095,-1.2116963979009219
0.056047691687994665,0.0034424,155.34333246935788,426.92119414890095,-1.2116963979009219
0.05617794428313292,0.0034503999999999997,155.3668601296504,426.92119414890095,-1.2116963979009219
0.05626912109972971,0.003456,155.3833168350298,426.92119414890095,-1.2116963979009219
0.056399373694867964,0.0034639999999999996,155.4068083852909,426.92119414890095,-1.2116963979009219
0.05681618199931041,0.0034896,155.48183955682254,426.92119414890095,-1.2116963979009219
0.05703761141104546,0.0035031999999999997,155.52161253758823,426.92119414890095,-1.2116963979009219
0.05744139445597408,0.003528,155.59398505811617,426.92119414890095,-1.2116963979009219
0.05823593528631748,0.0035767999999999998,155.7358187684821,426.92119414890095,-1.2116963979009219
0.05854854151464931,0.003596,155.7914150728275,426.92119414890095,-1.2116963979009219
0.05891324878103645,0.0036184,155.8561313202633,426.92119414890095,-1.2116963979009219
0.0595775370162416,0.0036592,155.97360728513334,426.92119414890095,-1.2116963979009219
0.06000737058019786,0.0036856,156.0493490218475,426.92119414890095,-1.2116963979009219
0.06009854739679465,0.0036912,156.06538821588234,426.92119414890095,-1.2116963979009219
0.060541406220264736,0.0037183999999999997,156.1431582859414,426.92119414890095,-1.2116963979009219
0.06089308822713805,0.00374,156.2047589343669,426.92119414890095,-1.2116963979009219
0.06098426504373484,0.0037456,156.22070680425412,426.92119414890095,-1.2116963979009219
0.06134897231012197,0.0037679999999999996,156.28440551386922,426.92119414890095,-1.2116963979009219
0.06145317438623258,0.0037744,156.3025779976,426.92119414890095,-1.2116963979009219
0.061791831133592066,0.0037952,156.36155574804405,426.92119414890095,-1.2116963979009219
0.061987210026299464,0.0038071999999999997,156.39552402984017,426.92119414890095,-1.2116963979009219
0.06205233632386859,0.0038112,156.4068375080974,426.92119414890095,-1.2116963979009219
0.06233889203317277,0.0038288,156.45656190008364,426.92119414890095,-1.2116963979009219
0.06263847300199078,0.0038472,156.50845127355555,426.92119414890095,-1.2116963979009219
0.06283385189469817,0.0038591999999999997,156.54224003346948,426.92119414890095,-1.2116963979009219
0.06306830656594704,0.0038735999999999996,156.5827325063538,426.92119414890095,-1.2116963979009219
0.06338091279427888,0.0038927999999999996,156.63663126704083,426.92119414890095,-1.2116963979009219
0.06384982213677663,0.0039216,156.71728542048646,426.92119414890095,-1.2116963979009219
0.06396704947240106,0.0039288,156.73741282375758,426.92119414890095,-1.2116963979009219
0.0644359588148988,0.0039575999999999995,156.81777899787303,426.92119414890095,-1.2116963979009219
0.0645792366695509,0.0039664,156.84228979264682,426.92119414890095,-1.2116963979009219
0.06481369134079977,0.0039808,156.88235266843085,426.92119414890095,-1.2116963979009219
0.06486579237885508,0.003984,156.8912478496166,426.92119414890095,-1.2116963979009219
0.06490486815739656,0.0039864,156.89791740701924,426.92119414890095,-1.2116963979009219
0.0676276476658056,0.004153630726145229,157.3588649424561,426.92119414890095,-1.2116963979009219
0.07388102290749057,0.004537707541508302,158.39094643969094,426.92119414890095,-1.2116963979009219
0.08232307948376529,0.00505621124224845,159.73170677081347,426.92119414890095,-1.2116963979009219
0.09357915491879823,0.00574754950990198,161.4386547634015,426.92119414890095,-1.2116963979009219
0.10014519892256744,0.006150830166033207,162.39733825848808,426.92119414890095,-1.2116963979009219
0.10139587397090444,0.006227645529105821,162.57713110912286,426.92119414890095,-1.2116963979009219
0.10327188654340994,0.006342868573714743,162.84520713293102,426.92119414890095,-1.2116963979009219
0.10483523035383117,0.006438887777555511,163.0671560455817,426.92119414890095,-1.2116963979009219
0.10577323664008392,0.006496499299859972,163.19970587319338,426.92119414890095,-1.2116963979009219
0.11046326807134765,0.006784556911382277,163.85570024424834,426.92119414890095,-1.2116963979009219
0.11390262445427439,0.006995799159831967,164.32987829443803,426.92119414890095,-1.2116963979009219
0.11515329950261138,0.007072614522904581,164.5009178942949,426.92119414890095,-1.2116963979009219
0.12203201226846484,0.00749509901980396,165.42899521902794,426.92119414890095,-1.2116963979009219
0.12766004998598132,0.007840768153630726,166.17324257992647,426.92119414890095,-1.2116963979009219
0.1326627501793293,0.008148029605921184,166.8241173262896,426.92119414890095,-1.2116963979009219
0.13797811913476152,0.008474494898979796,167.5052682460824,426.92119414890095,-1.2116963979009219
0.14892152580771023,0.009146629325865173,168.87622314065936,426.92119414890095,-1.2116963979009219
0.15236088219063695,0.009357871574314863,169.29890220153058,426.92119414890095,-1.2116963979009219
0.16049027000482743,0.009857171434286858,170.28343645266293,426.92119414890095,-1.2116963979009219
0.1642422951498384,0.010087617523504702,170.7312570990407,426.92119414890095,-1.2116963979009219
0.1673689827706809,0.010279655931186238,171.10140114786492,426.92119414890095,-1.2116963979009219
0.1717463454398604,0.010548509701940389,171.61510377491388,426.92119414890095,-1.2116963979009219
0.17674904563320837,0.010855771154230847,172.19598044037016,426.92119414890095,-1.2116963979009219
0.17737438315737686,0.010894178835767154,172.26813644986888,426.92119414890095,-1.2116963979009219
0.18300242087489332,0.01123984796959392,172.9131363080624,426.92119414890095,-1.2116963979009219
0.18831778983032554,0.01156631326265253,173.51523504994847,426.92119414890095,-1.2116963979009219
0.196447177644516,0.012065613122624524,174.42342631294918,426.92119414890095,-1.2116963979009219
0.2061399092691277,0.012660932186437287,175.48732877117646,426.92119414890095,-1.2116963979009219
0.21239328451081269,0.01304500900180036,176.16337562912935,426.92119414890095,-1.2116963979009219
0.21645797841790793,0.013294658931786357,176.59864687013913,426.92119414890095,-1.2116963979009219
0.22552537251835114,0.013851570314062813,177.55831023647954,426.92119414890095,-1.2116963979009219
0.2311534102358676,0.014197239447889578,178.14639908727898,426.92119414890095,-1.2116963979009219
0.23459276661879433,0.014408481696339268,178.50303847471952,426.92119414890095,-1.2116963979009219
0.23865746052588957,0.014658131626325266,178.9219029509399,426.92119414890095,-1.2116963979009219
0.2427221544329848,0.014907781556311263,179.3379942703846,426.92119414890095,-1.2116963979009219
0.250538873485091,0.015387877575515104,180.1306098722094,426.92119414890095,-1.2116963979009219
0.25929359882344993,0.015925585117023404,181.006976007594,426.92119414890095,-1.2116963979009219
0.26335829273054523,0.016175235047009403,181.4099300778422,426.92119414890095,-1.2116963979009219
0.26617231158930343,0.016348069613922784,181.6874785294206,426.92119414890095,-1.2116963979009219
0.26836099292389315,0.016482496499299858,181.9025591319618,426.92119414890095,-1.2116963979009219
0.27774105578642067,0.01705861172234447,182.81669080101827,426.92119414890095,-1.2116963979009219
0.2836817622660214,0.017423484696939388,183.38941769615073,426.92119414890095,-1.2116963979009219
0.28493243731435836,0.017500300060012002,183.5093935873236,426.92119414890095,-1.2116963979009219
0.29399983141480157,0.01805721144228846,184.37315839499303,426.92119414890095,-1.2116963979009219
0.2993152003702338,0.01838367673534707,184.87467289072805,426.92119414890095,-1.2116963979009219
0.30525590684983456,0.01874854970994199,185.43109658470794,426.92119414890095,-1.2116963979009219
0.3171373198090359,0.019478295659131825,186.5314325542648,426.92119414890095,-1.2116963979009219
0.33777345810659637,0.020745749149829965,188.40506578829527,426.92119414890095,-1.2116963979009219
0.3484041960174608,0.02139867973594719,189.35280921307003,426.92119414890095,-1.2116963979009219
0.35934760269040955,0.022070814162832568,190.31671935565566,426.92119414890095,-1.2116963979009219
0.3668516529804315,0.022531706341268255,190.97107880243163,426.92119414890095,-1.2116963979009219
0.3734176969842007,0.02293498699739948,191.53937281300483,426.92119414890095,-1.2116963979009219
0.37560637831879046,0.023069413882776557,191.72793635553495,426.92119414890095,-1.2116963979009219
0.3812344160363069,0.023415083016603323,192.21085682460597,426.92119414890095,-1.2116963979009219
0.38873846632632886,0.023875975195039006,192.85044769766216,426.92119414890095,-1.2116963979009219
0.3984311979509406,0.02447129425885177,193.6695038824026,426.92119414890095,-1.2116963979009219
0.40499724195470976,0.024874574914982996,194.21993783385219,426.92119414890095,-1.2116963979009219
0.40843659833763657,0.025085817163432687,194.50687078249666,426.92119414890095,-1.2116963979009219
0.41406463605515303,0.025431486297259453,194.97437312489458,426.92119414890095,-1.2116963979009219
0.4181293299622482,0.02568113622724545,195.31047382390554,426.92119414890095,-1.2116963979009219
0.422819361393512,0.025969193838767755,195.69670300346937,426.92119414890095,-1.2116963979009219
0.424070036441849,0.02604600920184037,195.79941481102662,426.92119414890095,-1.2116963979009219
0.42907273663519696,0.026353270654130827,196.20908613858091,426.92119414890095,-1.2116963979009219
0.43282476178020796,0.02658371674334867,196.51511825408753,426.92119414890095,-1.2116963979009219
0.43688945568730314,0.026833366673334667,196.8454878361198,426.92119414890095,-1.2116963979009219
0.43876546825980867,0.02694858971794359,196.9975615910493,426.92119414890095,-1.2116963979009219
0.4459568497877464,0.027390278055611124,197.5781768055461,426.92119414890095,-1.2116963979009219
0.45346090007776835,0.02785117023404681,198.18015632058166,426.92119414890095,-1.2116963979009219
0.46096495036779034,0.0283120624124825,198.778263035027,426.92119414890095,-1.2116963979009219
0.4700323444682335,0.028868973794758952,199.49593262363425,426.92119414890095,-1.2116963979009219
0.4728463633269917,0.029041808361672333,199.71755713571793,426.92119414890095,-1.2116963979009219
0.4759730509478342,0.02923384676935387,199.9632041803001,426.92119414890095,-1.2116963979009219
0.4772237259961712,0.029310662132426484,200.06128668892708,426.92119414890095,-1.2116963979009219
0.4919191578141309,0.030213242648529707,201.20634694495712,426.92119414890095,-1.2116963979009219
0.49473317667288913,0.030386077215443088,201.424083585377,426.92119414890095,-1.2116963979009219
0.4962965204833104,0.030482096419283858,201.5448396657669,426.92119414890095,-1.2116963979009219
0.5012992206766583,0.030789357871574316,201.93026600259304,426.92119414890095,-1.2116963979009219
0.5141186399221126,0.03157671534306861,202.9111357648098,426.92119414890095,-1.2116963979009219
0.518496002591292,0.03184556911382276,203.2438761527709,426.92119414890095,-1.2116963979009219
0.532253428122999,0.03269053810762153,204.2825697065336,426.92119414890095,-1.2116963979009219
0.5331914344092518,0.03274814962992599,204.35300606739304,426.92119414890095,-1.2116963979009219
0.5381941346025998,0.03305541108221645,204.72785362532937,426.92119414890095,-1.2116963979009219
0.5428841660338635,0.03334346869373875,205.07804094456068,426.92119414890095,-1.2116963979009219
0.5485122037513799,0.03368913782756551,205.4967121359843,426.92119414890095,-1.2116963979009219
0.549762878799717,0.03376595319063813,205.58952227175337,426.92119414890095,-1.2116963979009219
0.5525768976584751,0.033938787757551506,205.7980445374761,426.92119414890095,-1.2116963979009219
0.5566415915655704,0.03418843768753751,206.09851370716154,426.92119414890095,-1.2116963979009219
0.5663343231901821,0.03478375675135027,206.8115848338104,426.92119414890095,-1.2116963979009219
0.5703990170972774,0.03503340668133627,207.10919633293054,426.92119414890095,-1.2116963979009219
0.5804044174839733,0.035647929585917185,207.83827636310548,426.92119414890095,-1.2116963979009219
0.5922858304431747,0.036377675535107026,208.69772284682492,426.92119414890095,-1.2116963979009219
0.604167243402376,0.037107421484296854,209.5504711457386,426.92119414890095,-1.2116963979009219
0.6057305872127975,0.037203440688137634,209.66218596424645,426.92119414890095,-1.2116963979009219
0.6129219687407351,0.03764512902580516,210.17463271842877,426.92119414890095,-1.2116963979009219
0.6198006815065886,0.038067613522704546,210.66260944876308,426.92119414890095,-1.2116963979009219
0.6244907129378523,0.038355671134226846,210.99411049634688,426.92119414890095,-1.2116963979009219
0.6319947632278743,0.03881656331266253,211.52249969786638,426.92119414890095,-1.2116963979009219
0.6394988135178963,0.03927745549109822,212.0484476743932,426.92119414890095,-1.2116963979009219
0.6523182327633505,0.040064812962592525,212.94140773229142,426.92119414890095,-1.2116963979009219
0.6532562390496031,0.040122424484896974,213.00647631365842,426.92119414890095,-1.2116963979009219
0.6604476205775409,0.040564112822564516,213.50413054718672,426.92119414890095,-1.2116963979009219
0.6660756582950573,0.04090978195639128,213.8921264294909,426.92119414890095,-1.2116963979009219
0.6688896771538156,0.041082616523304666,214.08564475384793,426.92119414890095,-1.2116963979009219
0.6735797085850793,0.041370674134826965,214.40747120210102,426.92119414890095,-1.2116963979009219
0.6773317337300904,0.041601120224044816,214.664303579647,426.92119414890095,-1.2116963979009219
0.6823344339234384,0.041908381676335274,215.00588530430437,426.92119414890095,-1.2116963979009219
0.6854611215442808,0.04210042008401681,215.21887796968574,426.92119414890095,-1.2116963979009219
0.7048465847935043,0.043291058211642336,216.53107412988308,426.92119414890095,-1.2116963979009219
0.7057845910797569,0.043348669733946785,216.59420804505592,426.92119414890095,-1.2116963979009219
0.7073479348901781,0.04344468893778755,216.69935856655067,426.92119414890095,-1.2116963979009219
0.7204800228977167,0.044251250250050014,217.5790730102925,426.92119414890095,-1.2116963979009219
0.7323614358569179,0.04498099619923984,218.36963116000885,426.92119414890095,-1.2116963979009219
0.7436175112919511,0.04567233446689338,219.11397950317803,426.92119414890095,-1.2116963979009219
0.7504962240578046,0.046094818963792764,219.5666962837192,426.92119414890095,-1.2116963979009219
0.7592509493961634,0.04663252650530106,220.14054763634115,426.92119414890095,-1.2116963979009219
0.7620649682549218,0.046805361072214446,220.3244510457394,426.92119414890095,-1.2116963979009219
0.7742590499762073,0.04755431086217243,221.1183248760743,426.92119414890095,-1.2116963979009219
0.7801997564558081,0.047919183836767354,221.5033162384798,426.92119414890095,-1.2116963979009219
0.7808250939799766,0.04795759151830366,221.54377502753894,426.92119414890095,-1.2116963979009219
0.7986472134187788,0.04905221044208842,222.69159260774836,426.92119414890095,-1.2116963979009219
0.8064639324708849,0.04953230646129225,223.19186513365395,426.92119414890095,-1.2116963979009219
0.8095906200917276,0.0497243448689738,223.39144420933647,426.92119414890095,-1.2116963979009219
0.8124046389504856,0.04989717943588717,223.57080850557136,426.92119414890095,-1.2116963979009219
0.8170946703817495,0.05018523704740949,223.8692114885997,426.92119414890095,-1.2116963979009219
0.8214720330509289,0.05045409081816363,224.14711882608304,426.92119414890095,-1.2116963979009219
0.8258493957201084,0.05072294458891778,224.42444921695466,426.92119414890095,-1.2116963979009219
0.8311647646755407,0.0510494098819764,224.76043802116104,426.92119414890095,-1.2116963979009219
0.8349167898205515,0.051279855971194235,224.99710224528158,426.92119414890095,-1.2116963979009219
0.8405448275380681,0.05162552510502101,225.3513223491775,426.92119414890095,-1.2116963979009219
0.8427335088726579,0.05175995199039808,225.4888246605917,426.92119414890095,-1.2116963979009219
0.846798202779753,0.05200960192038408,225.7438171627208,426.92119414890095,-1.2116963979009219
0.8480488778280901,0.0520864172834567,225.82218030036307,426.92119414890095,-1.2116963979009219
0.8499248904005955,0.05220164032806561,225.93964055123863,426.92119414890095,-1.2116963979009219
0.861806303359797,0.05293138627725545,226.68122108882216,426.92119414890095,-1.2116963979009219
0.8674343410773134,0.053277055411082214,227.0311034171173,426.92119414890095,-1.2116963979009219
0.8708736974602401,0.053488297659531905,227.24448459956412,426.92119414890095,-1.2116963979009219
0.8765017351777565,0.05383396679335867,227.59294625133668,426.92119414890095,-1.2116963979009219
0.8793157540365149,0.054006801360272055,227.76684976720495,426.92119414890095,-1.2116963979009219
0.8886958168990424,0.05458291658331667,228.34496694741506,426.92119414890095,-1.2116963979009219
0.8990138860478225,0.05521664332866573,228.97815414421623,426.92119414890095,-1.2116963979009219
0.9015152361444965,0.05537027405481096,229.1312264805443,426.92119414890095,-1.2116963979009219
0.9062052675757604,0.05565833166633327,229.4177914033129,426.92119414890095,-1.2116963979009219
0.9165233367245404,0.05629205841168233,230.04620608135582,426.92119414890095,-1.2116963979009219
0.9221513744420571,0.05663772754550911,230.38781458049095,426.92119414890095,-1.2116963979009219
0.9302807622562475,0.0571370274054811,230.87981708184367,426.92119414890095,-1.2116963979009219
0.9355961312116795,0.0574634926985397,231.20060468878285,426.92119414890095,-1.2116963979009219
0.9431001815017015,0.05792438487697539,231.65227392068527,426.92119414890095,-1.2116963979009219
0.9571702757954926,0.0587885577115423,232.4953938579626,426.92119414890095,-1.2116963979009219
0.962485644750925,0.05911502300460092,232.81264617728814,426.92119414890095,-1.2116963979009219
0.9743670577101265,0.05984476895379076,233.51933806874115,426.92119414890095,-1.2116963979009219
0.9806204329518113,0.06022884576915383,233.8899308457579,426.92119414890095,-1.2116963979009219
0.9884371520039177,0.06070894178835767,234.35187827118702,426.92119414890095,-1.2116963979009219
1.0056339339185512,0.06176515303060612,235.36317701174485,426.92119414890095,-1.2116963979009219
1.0147013280189945,0.06232206441288257,235.89369040419916,426.92119414890095,-1.2116963979009219
1.0234560533573536,0.06285977195439088,236.40415867491217,426.92119414890095,-1.2116963979009219
1.0347121287923864,0.0635511102220444,237.05797964501622,426.92119414890095,-1.2116963979009219
1.038151485175313,0.0637623524704941,237.25720422314953,426.92119414890095,-1.2116963979009219
1.0450301979411667,0.06418483696739348,237.6548828289031,426.92119414890095,-1.2116963979009219
1.0494075606103461,0.06445369073814763,237.9074195892503,426.92119414890095,-1.2116963979009219
1.0600382985212107,0.06510662132426485,238.51901884859805,426.92119414890095,-1.2116963979009219
1.06441566119039,0.06537547509501901,238.77015801750642,426.92119414890095,-1.2116963979009219
1.0697310301458223,0.06570194038807761,239.07457186707032,426.92119414890095,-1.2116963979009219
1.0737957240529175,0.06595159031806361,239.30696105898286,426.92119414890095,-1.2116963979009219
1.0781730867220969,0.06622044408881776,239.5568430026496,426.92119414890095,-1.2116963979009219
1.0834884556775293,0.06654690938187638,239.85973978772844,426.92119414890095,-1.2116963979009219
1.08942916215713,0.0669117823564713,240.19758652496918,426.92119414890095,-1.2116963979009219
1.0988092250196575,0.06748789757951591,240.72956955134936,426.92119414890095,-1.2116963979009219
1.1025612501646684,0.06771834366873375,240.94186649562,426.92119414890095,-1.2116963979009219
1.1066259440717636,0.06796799359871974,241.17153715123814,426.92119414890095,-1.2116963979009219
1.11444266312387,0.06844808961792359,241.61228888727354,426.92119414890095,-1.2116963979009219
1.1200707008413864,0.06879375875175035,241.92888392807208,426.92119414890095,-1.2116963979009219
1.1269494136072398,0.06921624324864974,242.31499214204047,426.92119414890095,-1.2116963979009219
1.1344534638972619,0.06967713542708542,242.7351543471398,426.92119414890095,-1.2116963979009219
1.141019507901031,0.07008041608321665,243.1019079360966,426.92119414890095,-1.2116963979009219
1.1444588642839577,0.07029165833166634,243.2936884179717,426.92119414890095,-1.2116963979009219
1.1513375770498113,0.07071414282856572,243.67657638866578,426.92119414890095,-1.2116963979009219
1.1569656147673277,0.07105981196239249,243.9891852127054,426.92119414890095,-1.2116963979009219
1.1669710151540238,0.0716743348669734,244.54347380762303,426.92119414890095,-1.2116963979009219
1.1797904343994778,0.07246169233846769,245.2509549128141,426.92119414890095,-1.2116963979009219
1.1835424595444888,0.07269213842768554,245.4574545727224,426.92119414890095,-1.2116963979009219
1.1882324909757525,0.07298019603920784,245.7152204721399,426.92119414890095,-1.2116963979009219
1.1938605286932689,0.0733258651730346,246.0240163763914,426.92119414890095,-1.2116963979009219
1.200113903934954,0.07370994198839768,246.36645785374478,426.92119414890095,-1.2116963979009219
1.2085559605112288,0.07422844568913783,246.82765202938117,426.92119414890095,-1.2116963979009219
1.2201247047083459,0.07493898779755952,247.45762346658714,426.92119414890095,-1.2116963979009219
1.2257527424258623,0.07528465693138628,247.763253401859,426.92119414890095,-1.2116963979009219
1.2354454740504741,0.07587997599519905,248.2883362573273,426.92119414890095,-1.2116963979009219
1.2426368555784117,0.07632166433286658,248.67687625934917,426.92119414890095,-1.2116963979009219
1.2495155683442654,0.07674414882976596,249.04770346800967,426.92119414890095,-1.2116963979009219
1.255456274823866,0.07710902180436088,249.36732307810516,426.92119414890095,-1.2116963979009219
1.2573322873963715,0.0772242448489698,249.46813297249702,426.92119414890095,-1.2116963979009219
1.2588956312067927,0.07732026405281056,249.5520964147843,426.92119414890095,-1.2116963979009219
1.2667123502588988,0.07780036007201441,249.971305198705,426.92119414890095,-1.2116963979009219
1.2685883628314045,0.07791558311662333,250.07176503865202,426.92119414890095,-1.2116963979009219
1.2745290693110052,0.07828045609121825,250.38950630346196,426.92119414890095,-1.2116963979009219
1.276717750645595,0.07841488297659532,250.5064232083266,426.92119414890095,-1.2116963979009219
1.28078244455269,0.07866453290658132,250.72334742838783,426.92119414890095,-1.2116963979009219
1.2829711258872798,0.07879895979195839,250.84004156276043,426.92119414890095,-1.2116963979009219
1.2854724759839538,0.07895259051810362,250.97331126201823,426.92119414890095,-1.2116963979009219
1.2889118323668804,0.07916383276655331,251.15639207987212,426.92119414890095,-1.2116963979009219
1.2986045639914923,0.07975915183036608,251.6713248582902,426.92119414890095,-1.2116963979009219
1.3014185828502505,0.07993198639727946,251.82054043043644,426.92119414890095,-1.2116963979009219
1.3129873270473675,0.08064252850570114,252.4326648745063,426.92119414890095,-1.2116963979009219
1.3208040460994739,0.08112262452490498,252.84507215765075,426.92119414890095,-1.2116963979009219
1.3342488028690966,0.08194838967793559,253.55219298997113,426.92119414890095,-1.2116963979009219
1.345817547066214,0.08265893178635728,254.15842435075064,426.92119414890095,-1.2116963979009219
1.352383591069983,0.0830622124424885,254.50159745918515,426.92119414890095,-1.2116963979009219
1.3567609537391625,0.08333106621324265,254.73001859972638,426.92119414890095,-1.2116963979009219
1.3655156790775214,0.08386877375475095,255.18600045813605,426.92119414890095,-1.2116963979009219
1.372394391843375,0.08429125825165033,255.54347256114383,426.92119414890095,-1.2116963979009219
1.3739577356537962,0.0843872774554911,255.62461868842905,426.92119414890095,-1.2116963979009219
1.3767717545125544,0.08456011202240449,255.77059103267092,426.92119414890095,-1.2116963979009219
1.3883404987096717,0.08527065413082617,256.3694811389716,426.92119414890095,-1.2116963979009219
1.3992839053826205,0.08594278855771155,256.9342100153754,426.92119414890095,-1.2116963979009219
1.4024105930034627,0.08613482696539308,257.09524441275204,426.92119414890095,-1.2116963979009219
1.4061626181484739,0.08636527305461093,257.28830098039805,426.92119414890095,-1.2116963979009219
1.4133539996764115,0.08680696139227846,257.65776545110083,426.92119414890095,-1.2116963979009219
1.4217960562526863,0.08732546509301861,258.0905504105482,426.92119414890095,-1.2116963979009219
1.432739462925635,0.08799759951990399,258.650079283105,426.92119414890095,-1.2116963979009219
1.4343028067360561,0.08809361872374476,258.72987570636553,426.92119414890095,-1.2116963979009219
1.442744863312331,0.08861212242448491,259.16019166854215,426.92119414890095,-1.2116963979009219
1.4502489136023529,0.0890730146029206,259.54187103934083,426.92119414890095,-1.2116963979009219
1.458065632654459,0.08955311062212443,259.93863558967763,426.92119414890095,-1.2116963979009219
1.4649443454203126,0.08997559511902381,260.287102695718,426.92119414890095,-1.2116963979009219
1.4746370770449242,0.09057091418283657,260.77704335746483,426.92119414890095,-1.2116963979009219
1.4780764334278509,0.09078215643128626,260.95059116587544,426.92119414890095,-1.2116963979009219
1.4858931524799572,0.0912622524504901,261.3444333475436,426.92119414890095,-1.2116963979009219
1.4912085214353894,0.09158871774354871,261.6117846000428,426.92119414890095,-1.2116963979009219
1.4933972027699791,0.09172314462892579,261.7217623551312,426.92119414890095,-1.2116963979009219
1.4980872342012428,0.09201120224044809,261.95721752494364,426.92119414890095,-1.2116963979009219
1.5040279406808437,0.09237607521504301,262.2550484530684,426.92119414890095,-1.2116963979009219
1.5162220224021292,0.093125025005001,262.8649520956437,426.92119414890095,-1.2116963979009219
1.5249767477404883,0.09366273254650931,263.30165249470053,426.92119414890095,-1.2116963979009219
1.5281034353613308,0.09385477095419084,263.4573798276676,426.92119414890095,-1.2116963979009219
1.5343568106030159,0.09423884776955392,263.7684621888113,426.92119414890095,-1.2116963979009219
1.5362328231755211,0.09435407081416283,263.8616904271421,426.92119414890095,-1.2116963979009219
1.5465508923243014,0.09498779755951191,264.3736542746422,426.92119414890095,-1.2116963979009219
1.556243623948913,0.09558311662332467,264.85337790047447,426.92119414890095,-1.2116963979009219
1.5606209866180927,0.09585197039407882,265.0696451833706,426.92119414890095,-1.2116963979009219
1.5787557748189789,0.09696579315863173,265.9631009748344,426.92119414890095,-1.2116963979009219
1.5793811123431476,0.09700420084016805,265.99383819821134,426.92119414890095,-1.2116963979009219
1.5803191186294,0.0970618123624725,266.03993513543395,426.92119414890095,-1.2116963979009219
1.591262525302349,0.09773394678935787,266.57694667594603,426.92119414890095,-1.2116963979009219
1.5965778942577813,0.09806041208241649,266.8372610044819,426.92119414890095,-1.2116963979009219
1.601267925689045,0.09834846969393879,267.0666695634874,426.92119414890095,-1.2116963979009219
1.6134620074103307,0.09909741948389679,267.66190876524007,426.92119414890095,-1.2116963979009219
1.6187773763657627,0.09942388477695539,267.92082266271467,426.92119414890095,-1.2116963979009219
1.626594095417869,0.09990398079615924,268.3009768876143,426.92119414890095,-1.2116963979009219