File: datasets/aisi_316_L/data/M1/valid_17.csv
Time(s),Strain(%),Stress(MPa),Temp(C),Log_SR(s-1)
0.0,0.0,0.0,152.2238253104562,5.840472643835401
2.0791692727118908e-11,1.44e-05,2.730162825,152.2238253104562,5.840472643835401
2.541206888870089e-11,1.76e-05,3.3368656750000003,152.2238253104562,5.840472643835401
4.3893573535028806e-11,3.04e-05,5.763677075,152.2238253104562,5.840472643835401
5.1979231817797276e-11,3.6e-05,6.8254070625,152.2238253104562,5.840472643835401
6.468526626214771e-11,4.48e-05,8.4938399,152.2238253104562,5.840472643835401
7.277092454491618e-11,5.04e-05,9.555569887499999,152.2238253104562,5.840472643835401
8.547695898926661e-11,5.9199999999999996e-05,11.224002724999998,152.2238253104562,5.840472643835401
1.2012978020113145e-10,8.319999999999999e-05,15.774274099999998,152.2238253104562,5.840472643835401
1.339909086858774e-10,9.279999999999999e-05,17.59438265,152.2238253104562,5.840472643835401
1.4438675504943686e-10,9.999999999999999e-05,18.959464062499997,152.2238253104562,5.840472643835401
1.617131656553693e-10,0.000112,21.23459975,152.2238253104562,5.840472643835401
2.044516451500026e-10,0.0001416,26.8466011125,152.2238253104562,5.840472643835401
2.3217390211949449e-10,0.0001608,30.4868182125,152.2238253104562,5.840472643835401
2.5874106504859083e-10,0.0001792,33.9753596,152.2238253104562,5.840472643835401
2.7491238161412777e-10,0.0001904,36.098819575,152.2238253104562,5.840472643835401
3.234263313107386e-10,0.000224,42.4691995,152.2238253104562,5.840472643835401
3.2804670747232056e-10,0.0002272,43.07590235,152.2238253104562,5.840472643835401
3.3151198959350706e-10,0.0002296,43.530929487499996,152.2238253104562,5.840472643835401
3.5230368232062597e-10,0.000244,46.2610923125,152.2238253104562,5.840472643835401
3.9273197373446826e-10,0.000272,51.56974225,152.2238253104562,5.840472643835401
4.019727260576322e-10,0.0002784,52.78314795,152.2238253104562,5.840472643835401
4.054380081788187e-10,0.0002808,53.2381750875,152.2238253104562,5.840472643835401
4.2969498302712406e-10,0.00029759999999999997,56.423365049999994,152.2238253104562,5.840472643835401
4.470213936330565e-10,0.0003096,58.6985007375,152.2238253104562,5.840472643835401
4.6550289827938444e-10,0.0003224,61.125312137499996,152.2238253104562,5.840472643835401
4.678130863601754e-10,0.00032399999999999996,61.42866356249999,152.2238253104562,5.840472643835401
4.712783684813619e-10,0.00032639999999999996,61.883690699999995,152.2238253104562,5.840472643835401
4.932251552488763e-10,0.0003416,64.7655292375,152.2238253104562,5.840472643835401
5.047760956528313e-10,0.0003496,66.2822863625,152.2238253104562,5.840472643835401
5.232576002991591e-10,0.00036239999999999997,68.7090977625,152.2238253104562,5.840472643835401
5.452043870666736e-10,0.00037759999999999996,71.5909363,152.2238253104562,5.840472643835401
5.636858917130015e-10,0.0003904,74.0177477,152.2238253104562,5.840472643835401
5.78702114238143e-10,0.0004008,75.9895319625,152.2238253104562,5.840472643835401
5.948734308036799e-10,0.000412,78.1129919375,152.2238253104562,5.840472643835401
6.456975685810817e-10,0.0004472,84.7867232875,152.2238253104562,5.840472643835401
6.65334167267805e-10,0.0004608,87.3652104,152.2238253104562,5.840472643835401
6.734198255505735e-10,0.00046639999999999995,88.4269403875,152.2238253104562,5.840472643835401
7.138481169644159e-10,0.0004944,93.73559032499999,152.2238253104562,5.840472643835401
7.404152798935123e-10,0.0005128,97.2241317125,152.2238253104562,5.840472643835401
7.635171607014221e-10,0.0005288,100.25764596249999,152.2238253104562,5.840472643835401
8.074107342364508e-10,0.0005591999999999999,106.02132303749998,152.2238253104562,5.840472643835401
8.686307183774122e-10,0.0006016,114.0601358,152.2238253104562,5.840472643835401
8.963529753469041e-10,0.0006208,117.7003529,152.2238253104562,5.840472643835401
9.03283539589277e-10,0.0006255999999999999,118.61040717499999,152.2238253104562,5.840472643835401
9.252303263567914e-10,0.0006408,121.4922457125,152.2238253104562,5.840472643835401
9.506423952454923e-10,0.0006584,124.82911138749999,152.2238253104562,5.840472643835401
9.783646522149843e-10,0.0006776,128.4693284875,152.2238253104562,5.840472643835401
1.0141725674672444e-09,0.0007023999999999999,133.17127557499998,152.2238253104562,5.840472643835401
1.0187929436288265e-09,0.0007056,133.77797842500001,152.2238253104562,5.840472643835401
1.0430499184771318e-09,0.0007224,136.9631683875,152.2238253104562,5.840472643835401
1.0777027396889968e-09,0.0007463999999999999,141.51343976249998,152.2238253104562,5.840472643835401
1.0938740562545336e-09,0.0007576,143.6368997375,152.2238253104562,5.840472643835401
1.1088902787796752e-09,0.000768,145.608684,152.2238253104562,5.840472643835401
1.1400778178703535e-09,0.0007896,149.7039282375,152.2238253104562,5.840472643835401
1.1516287582743084e-09,0.0007976,151.2206853625,152.2238253104562,5.840472643835401
1.1920570496881508e-09,0.0008256,156.5293353,152.2238253104562,5.840472643835401
1.2105385543344787e-09,0.0008384,158.9561467,152.2238253104562,5.840472643835401
1.2243996828192247e-09,0.000848,160.77625525,152.2238253104562,5.840472643835401
1.2786891027178127e-09,0.0008856,167.90501373749998,152.2238253104562,5.840472643835401
1.2960155133237452e-09,0.0008975999999999999,170.180149425,152.2238253104562,5.840472643835401
1.3144970179700733e-09,0.0009104,172.60696082500002,152.2238253104562,5.840472643835401
1.342219274939565e-09,0.0009295999999999999,176.247177925,152.2238253104562,5.840472643835401
1.3641660617070794e-09,0.0009448,179.1290164625,152.2238253104562,5.840472643835401
1.37687209615143e-09,0.0009536,180.79744929999998,152.2238253104562,5.840472643835401
1.3999739769593397e-09,0.0009695999999999999,183.83096354999998,152.2238253104562,5.840472643835401
1.4149901994844813e-09,0.00098,185.8027478125,152.2238253104562,5.840472643835401
1.4450226445347642e-09,0.0010008,189.74631633750002,152.2238253104562,5.840472643835401
1.451953208777137e-09,0.0010056,190.65637061249998,152.2238253104562,5.840472643835401
1.4854509359486062e-09,0.0010287999999999999,195.05496627499997,152.2238253104562,5.840472643835401
1.5154833809988892e-09,0.0010496,198.9985348,152.2238253104562,5.840472643835401
1.5224139452412623e-09,0.0010544,199.908589075,152.2238253104562,5.840472643835401
1.5443607320087767e-09,0.0010696,202.7904276125,152.2238253104562,5.840472643835401
1.559376954533918e-09,0.00108,204.762211875,152.2238253104562,5.840472643835401
1.573238083018664e-09,0.0010896,206.582320425,152.2238253104562,5.840472643835401
1.5928746817053874e-09,0.0011032,209.16080753749998,152.2238253104562,5.840472643835401
1.6587150420079308e-09,0.0011488,217.80632315,152.2238253104562,5.840472643835401
1.6841271108966315e-09,0.0011664,221.14318882499998,152.2238253104562,5.840472643835401
1.699143333421773e-09,0.0011768,223.1149730875,152.2238253104562,5.840472643835401
1.7349512486740333e-09,0.0012016,227.81692017499998,152.2238253104562,5.840472643835401
1.7430369069568016e-09,0.0012071999999999999,228.87865016249998,152.2238253104562,5.840472643835401
1.7568980354415476e-09,0.0012167999999999999,230.69875871249997,152.2238253104562,5.840472643835401
1.8007916089765765e-09,0.0012472,236.4624357875,152.2238253104562,5.840472643835401
1.8227383957440908e-09,0.0012624,239.344274325,152.2238253104562,5.840472643835401
1.8423749944308145e-09,0.001276,241.92276143750001,152.2238253104562,5.840472643835401
1.907060260692962e-09,0.0013208,250.4166013375,152.2238253104562,5.840472643835401
1.9243866712988945e-09,0.0013327999999999999,252.69173702499998,152.2238253104562,5.840472643835401
1.946333458066409e-09,0.001348,255.5735755625,152.2238253104562,5.840472643835401
1.9705904329147144e-09,0.0013648,258.758765525,152.2238253104562,5.840472643835401
1.9740557150359006e-09,0.0013671999999999998,259.2137926625,152.2238253104562,5.840472643835401
1.991382125641833e-09,0.0013792,259.70913505974056,152.2238253104562,5.840472643835401
2.0121738183689518e-09,0.0013935999999999998,259.8149631613487,152.2238253104562,5.840472643835401
2.028345134934489e-09,0.0014047999999999999,259.8969793380563,152.2238253104562,5.840472643835401
2.041051169378839e-09,0.0014135999999999999,259.9612418528506,152.2238253104562,5.840472643835401
2.0572224859443762e-09,0.0014248,260.0428053086421,152.2238253104562,5.840472643835401
2.0860998369542637e-09,0.0014448,260.18783511190315,152.2238253104562,5.840472643835401
2.1011160594794053e-09,0.0014552,260.2629410565259,152.2238253104562,5.840472643835401
2.1750420780647168e-09,0.0015064,260.6296842657177,152.2238253104562,5.840472643835401
2.195833770791836e-09,0.0015207999999999999,260.73195068104104,152.2238253104562,5.840472643835401
2.2050745231149996e-09,0.0015271999999999998,260.7772811278172,152.2238253104562,5.840472643835401
2.2189356515997454e-09,0.0015367999999999998,260.8451381331436,152.2238253104562,5.840472643835401
2.227021309882514e-09,0.0015424,260.88464504327476,152.2238253104562,5.840472643835401
2.2431926264480512e-09,0.0015536,260.96349144035247,152.2238253104562,5.840472643835401
2.2558986608924016e-09,0.0015624,261.0252867720785,152.2238253104562,5.840472643835401
2.273225071498334e-09,0.0015743999999999999,261.1093348226579,152.2238253104562,5.840472643835401
2.2847760119022886e-09,0.0015823999999999999,261.16522809934565,152.2238253104562,5.840472643835401
2.319428833114154e-09,0.0016064,261.33225041964016,152.2238253104562,5.840472643835401
2.3356001496796906e-09,0.0016175999999999999,261.4098608552838,152.2238253104562,5.840472643835401
2.3563918424068097e-09,0.001632,261.50933845259516,152.2238253104562,5.840472643835401
2.3898895695782788e-09,0.0016552,261.6688908878915,152.2238253104562,5.840472643835401
2.4314729550325166e-09,0.001684,261.8657477445934,152.2238253104562,5.840472643835401
2.455729929880822e-09,0.0017008,261.9799745580226,152.2238253104562,5.840472643835401
2.4753665285675452e-09,0.0017143999999999998,262.07212192352875,152.2238253104562,5.840472643835401
2.488072563011896e-09,0.0017231999999999998,262.1315948123554,152.2238253104562,5.840472643835401
2.5308110425065293e-09,0.0017527999999999999,262.33077637489026,152.2238253104562,5.840472643835401
2.5596883935164167e-09,0.0017728,262.4646164161102,152.2238253104562,5.840472643835401
2.5643087696779988e-09,0.001776,262.4859760548754,152.2238253104562,5.840472643835401
2.5781698981627446e-09,0.0017855999999999998,262.5499650957205,152.2238253104562,5.840472643835401
2.5989615908898637e-09,0.0018,262.6456976607931,152.2238253104562,5.840472643835401
2.634769506142124e-09,0.0018248,262.80987319056004,152.2238253104562,5.840472643835401
2.6590264809904294e-09,0.0018415999999999999,262.92059476539015,152.2238253104562,5.840472643835401
2.668267233313593e-09,0.0018479999999999998,262.9626707084378,152.2238253104562,5.840472643835401
2.68443854987913e-09,0.0018591999999999999,263.0361671178032,152.2238253104562,5.840472643835401
2.7364177816969275e-09,0.0018951999999999999,263.2712445756194,152.2238253104562,5.840472643835401
2.7583645684644416e-09,0.0019103999999999998,263.36997588072205,152.2238253104562,5.840472643835401
2.798792859878284e-09,0.0019383999999999998,263.5510510550227,152.2238253104562,5.840472643835401
2.8299803989689627e-09,0.00196,263.6900415009699,152.2238253104562,5.840472643835401
2.84846190361529e-09,0.0019728,263.7721243358859,152.2238253104562,5.840472643835401
2.8704086903828047e-09,0.0019879999999999997,263.86932842111764,152.2238253104562,5.840472643835401
2.8923554771503196e-09,0.0020032,263.9662430826882,152.2238253104562,5.840472643835401
2.9050615115946696e-09,0.002012,264.02222048585105,152.2238253104562,5.840472643835401
2.927008298362184e-09,0.0020272,264.1186843471449,152.2238253104562,5.840472643835401
2.9397143328065345e-09,0.002036,264.1744029151369,152.2238253104562,5.840472643835401
2.9628162136144445e-09,0.002052,264.27546936851024,152.2238253104562,5.840472643835401
2.972056965937608e-09,0.0020583999999999997,264.3158098393788,152.2238253104562,5.840472643835401
2.9778324361395857e-09,0.0020624,264.34099779484984,152.2238253104562,5.840472643835401
2.9882282825031452e-09,0.0020696,264.38628815575913,152.2238253104562,5.840472643835401
3.002089410987891e-09,0.0020792,264.4465798317114,152.2238253104562,5.840472643835401
3.0136403513918464e-09,0.0020872,264.49674000684985,152.2238253104562,5.840472643835401
3.047138078563315e-09,0.0021103999999999997,264.6417822345676,152.2238253104562,5.840472643835401
3.06908486533083e-09,0.0021256,264.73647285454314,152.2238253104562,5.840472643835401
3.0864112759367625e-09,0.0021376,264.8110421979442,152.2238253104562,5.840472643835401
3.1383905077545594e-09,0.0021736,265.03377677327626,152.2238253104562,5.840472643835401
3.164957670683656e-09,0.002192,265.1470629893836,152.2238253104562,5.840472643835401
3.1984553978551255e-09,0.0022152,265.2893749113655,152.2238253104562,5.840472643835401
3.2215572786630355e-09,0.0022312,265.3871825676384,152.2238253104562,5.840472643835401
3.2469693475517363e-09,0.0022488,265.4944555947112,152.2238253104562,5.840472643835401
3.260830476036482e-09,0.0022584,265.55283012989156,152.2238253104562,5.840472643835401
3.3047240495715107e-09,0.0022887999999999997,265.73704761257176,152.2238253104562,5.840472643835401
3.313964801894675e-09,0.0022952,265.77570836845,152.2238253104562,5.840472643835401
3.3324463065410023e-09,0.0023079999999999997,265.85290398169514,152.2238253104562,5.840472643835401
3.3543930933085173e-09,0.0023232,265.9443572476094,152.2238253104562,5.840472643835401
3.3763398800760318e-09,0.0023384,266.0355774520186,152.2238253104562,5.840472643835401
3.386735726439591e-09,0.0023455999999999998,266.0787062834716,152.2238253104562,5.840472643835401
3.426008923813038e-09,0.0023728,266.2411735753527,152.2238253104562,5.840472643835401
3.4571964629037166e-09,0.0023944,266.3696748777544,152.2238253104562,5.840472643835401
3.5149511649234906e-09,0.0024343999999999998,266.60645272994594,152.2238253104562,5.840472643835401
3.526502105327446e-09,0.0024424,266.65362569252176,152.2238253104562,5.840472643835401
3.586566995428012e-09,0.002484,266.897960446282,152.2238253104562,5.840472643835401
3.601583217953153e-09,0.0024944,266.9587941391988,152.2238253104562,5.840472643835401
3.6258401928014583e-09,0.0025112,267.05685540982216,152.2238253104562,5.840472643835401
3.6466318855285774e-09,0.0025256,267.1407044634551,152.2238253104562,5.840472643835401
3.6535624497709503e-09,0.0025304,267.16861268778405,152.2238253104562,5.840472643835401
3.6859050829020244e-09,0.0025528,267.29857904943196,152.2238253104562,5.840472643835401
3.702076399467561e-09,0.002564,267.36339538976364,152.2238253104562,5.840472643835401
3.715937527952307e-09,0.0025735999999999997,267.41886441647335,152.2238253104562,5.840472643835401
3.749435255123776e-09,0.0025968,267.5525824703026,152.2238253104562,5.840472643835401
3.764451477648918e-09,0.0026072,267.6123737215095,152.2238253104562,5.840472643835401
3.7806227942144546e-09,0.0026184,267.676660370348,152.2238253104562,5.840472643835401
3.818740897547506e-09,0.0026447999999999997,267.82777035150735,152.2238253104562,5.840472643835401
3.85108353067858e-09,0.0026671999999999998,267.9555241312601,152.2238253104562,5.840472643835401
3.854548812799766e-09,0.0026696,267.96918717239333,152.2238253104562,5.840472643835401
3.871875223405699e-09,0.0026815999999999997,268.0374306531588,152.2238253104562,5.840472643835401
3.935405395627451e-09,0.0027256,268.2866442387226,152.2238253104562,5.840472643835401
3.941180865829429e-09,0.0027296,268.309221930305,152.2238253104562,5.840472643835401
3.948111430071801e-09,0.0027343999999999997,268.3362981348469,152.2238253104562,5.840472643835401
3.985074439364457e-09,0.00276,268.48039269923197,152.2238253104562,5.840472643835401
3.998935567849203e-09,0.0027695999999999997,268.53429365794005,152.2238253104562,5.840472643835401
4.013951790374345e-09,0.00278,268.5926042041054,152.2238253104562,5.840472643835401
4.033588389061068e-09,0.0027936,268.6687282511356,152.2238253104562,5.840472643835401
4.04860461158621e-09,0.002804,268.7268432772017,152.2238253104562,5.840472643835401
4.0624657400709555e-09,0.0028136,268.7804133478154,152.2238253104562,5.840472643835401
4.075171774515306e-09,0.0028224,268.829456657611,152.2238253104562,5.840472643835401
4.090187997040447e-09,0.0028328,268.8873401134616,152.2238253104562,5.840472643835401
4.1005838434040075e-09,0.00284,268.92736473493653,152.2238253104562,5.840472643835401
4.125995912292708e-09,0.0028576,269.02503646201694,152.2238253104562,5.840472643835401
4.142167228858245e-09,0.0028688,269.0870690649845,152.2238253104562,5.840472643835401
4.201077024918415e-09,0.0029096,269.31225063487295,152.2238253104562,5.840472643835401
4.208007589160788e-09,0.0029143999999999997,269.33866137786947,152.2238253104562,5.840472643835401
4.212627965322369e-09,0.0029176,269.3562591158526,152.2238253104562,5.840472643835401
4.226489093807116e-09,0.0029272,269.4090072207814,152.2238253104562,5.840472643835401
4.2334196580494885e-09,0.0029319999999999997,269.43535597011214,152.2238253104562,5.840472643835401
4.2484358805746305e-09,0.0029424,269.49238728430373,152.2238253104562,5.840472643835401
4.257676632897794e-09,0.0029487999999999997,269.5274444046226,152.2238253104562,5.840472643835401
4.266917385220958e-09,0.0029552,269.5624718635092,152.2238253104562,5.840472643835401
4.298104924311637e-09,0.0029768,269.68047172942875,152.2238253104562,5.840472643835401
4.323516993200337e-09,0.0029944,269.7763730672759,152.2238253104562,5.840472643835401
4.332757745523501e-09,0.0030007999999999996,269.81119174490306,152.2238253104562,5.840472643835401
4.335067933604292e-09,0.0030023999999999997,269.81989188761446,152.2238253104562,5.840472643835401
4.369720754816157e-09,0.0030264,269.9501778152642,152.2238253104562,5.840472643835401
4.385892071381694e-09,0.0030375999999999997,270.0108399597802,152.2238253104562,5.840472643835401
4.403218481987627e-09,0.0030496,270.07573839622376,152.2238253104562,5.840472643835401
4.418234704512768e-09,0.00306,270.13190318858716,152.2238253104562,5.840472643835401
4.443646773401469e-09,0.0030775999999999998,270.22678199919073,152.2238253104562,5.840472643835401
4.455197713805424e-09,0.0030856,270.26983875452487,152.2238253104562,5.840472643835401
4.48176487673452e-09,0.003104,270.3687044099867,152.2238253104562,5.840472643835401
4.495626005219266e-09,0.0031136,270.42019574249076,152.2238253104562,5.840472643835401
4.516417697946385e-09,0.0031279999999999997,270.4973167998058,152.2238253104562,5.840472643835401
4.556845989360228e-09,0.003156,270.64687918739224,152.2238253104562,5.840472643835401
4.589188622491302e-09,0.0031784,270.76615683298246,152.2238253104562,5.840472643835401
4.600739562895256e-09,0.0031864,270.8086764828826,152.2238253104562,5.840472643835401
4.65618407683424e-09,0.0032248,271.0121940878744,152.2238253104562,5.840472643835401
4.682751239763336e-09,0.0032432,271.10937780902384,152.2238253104562,5.840472643835401
4.700077650369268e-09,0.0032551999999999998,271.1726426697201,152.2238253104562,5.840472643835401
4.737040659661925e-09,0.0032808,271.307304514039,152.2238253104562,5.840472643835401
4.7797791391565575e-09,0.0033104,271.46249748218213,152.2238253104562,5.840472643835401
4.8144319603684225e-09,0.0033344,271.5879327019824,152.2238253104562,5.840472643835401
4.828293088853168e-09,0.0033439999999999998,271.63800813983306,152.2238253104562,5.840472643835401
4.879117226630571e-09,0.0033791999999999997,271.82114036611836,152.2238253104562,5.840472643835401
4.901064013398084e-09,0.0033943999999999997,271.8999900307013,152.2238253104562,5.840472643835401
4.924165894205994e-09,0.0034103999999999996,271.9828410574798,152.2238253104562,5.840472643835401
4.947267775013905e-09,0.0034264,272.0655406298864,152.2238253104562,5.840472643835401
4.987696066427747e-09,0.0034544,272.2099033925441,152.2238253104562,5.840472643835401
5.035054922083962e-09,0.0034871999999999998,272.37843492498376,152.2238253104562,5.840472643835401
5.0616220850130585e-09,0.0035055999999999998,272.47270630199137,152.2238253104562,5.840472643835401
5.074328119457409e-09,0.0035144,272.5177243798573,152.2238253104562,5.840472643835401
5.095119812184528e-09,0.0035288,272.5912956130862,152.2238253104562,5.840472643835401
5.1136013168308555e-09,0.0035415999999999998,272.6565940269803,152.2238253104562,5.840472643835401
5.13554810359837e-09,0.0035567999999999997,272.73401647035234,152.2238253104562,5.840472643835401
5.1459439499619296e-09,0.003564,272.7706452118386,152.2238253104562,5.840472643835401
5.160960172487071e-09,0.0035743999999999997,272.8235024865396,152.2238253104562,5.840472643835401
5.1725111128910266e-09,0.0035824,272.86412112487875,152.2238253104562,5.840472643835401
5.190992617537354e-09,0.0035952,272.9290374421468,152.2238253104562,5.840472643835401
5.214094498345264e-09,0.0036111999999999997,273.01005622264626,152.2238253104562,5.840472643835401
5.231420908951197e-09,0.0036232,273.0707284669402,152.2238253104562,5.840472643835401
5.284555234809388e-09,0.0036599999999999996,273.2563031964999,152.2238253104562,5.840472643835401
5.289175610970971e-09,0.0036631999999999997,273.27240566004696,152.2238253104562,5.840472643835401
5.292640893092157e-09,0.0036655999999999998,273.2844789078472,152.2238253104562,5.840472643835401
5.311122397738485e-09,0.0036783999999999996,273.348817571507,152.2238253104562,5.840472643835401
5.319208056021254e-09,0.0036839999999999998,273.3769382741544,152.2238253104562,5.840472643835401
5.334224278546395e-09,0.0036944,273.4291182470167,152.2238253104562,5.840472643835401
5.351550689152328e-09,0.0037064,273.4892547758858,152.2238253104562,5.840472643835401
5.3723423818794465e-09,0.0037208,273.56131847168206,152.2238253104562,5.840472643835401
5.382738228243006e-09,0.003728,273.59730952514604,152.2238253104562,5.840472643835401
5.390823886525775e-09,0.0037335999999999997,273.6252838279275,152.2238253104562,5.840472643835401
5.424321613697244e-09,0.0037568,273.7410034736043,152.2238253104562,5.840472643835401
5.4335623660204084e-09,0.0037632,273.7728770453032,152.2238253104562,5.840472643835401
5.458974434909109e-09,0.0037808,273.86042054700704,152.2238253104562,5.840472643835401
5.513263854807697e-09,0.0038184,274.04691461502495,152.2238253104562,5.840472643835401
5.5201944190500695e-09,0.0038231999999999997,274.07067071058026,152.2238253104562,5.840472643835401
5.5432962998579794e-09,0.0038391999999999996,274.14977382122555,152.2238253104562,5.840472643835401
5.556002334302331e-09,0.003848,274.1932257262061,152.2238253104562,5.840472643835401
5.5756389329890535e-09,0.0038615999999999998,274.260302520449,152.2238253104562,5.840472643835401
5.588344967433405e-09,0.0038704,274.3036560630427,152.2238253104562,5.840472643835401
5.596430625716173e-09,0.0038759999999999997,274.3312246665312,152.2238253104562,5.840472643835401
5.620687600564478e-09,0.0038927999999999996,274.41383742356845,152.2238253104562,5.840472643835401
5.666891362180298e-09,0.0039248,274.5708114072949,152.2238253104562,5.840472643835401
5.6807524906650445e-09,0.0039344,274.617806166277,152.2238253104562,5.840472643835401
5.70500946551335e-09,0.0039512,274.69993952779026,152.2238253104562,5.840472643835401
5.735041910563632e-09,0.003972,274.8014399975042,152.2238253104562,5.840472643835401
5.740817380765609e-09,0.0039759999999999995,274.820935531011,152.2238253104562,5.840472643835401
5.756988697331147e-09,0.0039872,274.87548237338933,152.2238253104562,5.840472643835401
5.775470201977475e-09,0.004,274.9377485042749,152.2238253104562,5.840472643835401
5.914109214627464e-09,0.004096019203840768,275.4023850987883,152.2238253104562,5.840472643835401
7.300499341127358e-09,0.00505621124224845,279.836142150347,152.2238253104562,5.840472643835401
7.550049563897339e-09,0.005229045809161833,280.59796407351814,152.2238253104562,5.840472643835401
8.354155837267277e-09,0.0057859571914382875,282.98846092576224,152.2238253104562,5.840472643835401
8.492794849917267e-09,0.005881976395279056,283.39137163042676,152.2238253104562,5.840472643835401
8.71461727015725e-09,0.006035607121424285,284.0307337363463,152.2238253104562,5.840472643835401
8.908711887867235e-09,0.00617003400680136,284.5849866071816,152.2238253104562,5.840472643835401
9.740545963767172e-09,0.006746149229845969,286.90890473673124,152.2238253104562,5.840472643835401
1.0711019052317096e-08,0.007418283656731346,289.52439176118315,152.2238253104562,5.840472643835401
1.1210119497857059e-08,0.007763952790558111,290.83337983836066,152.2238253104562,5.840472643835401
1.2568781821826955e-08,0.00870494098819764,294.2863194956023,152.2238253104562,5.840472643835401
1.276287643953694e-08,0.008839367873574715,294.76743680810773,152.2238253104562,5.840472643835401
1.32897046876069e-08,0.009204240848169634,296.05915360379737,152.2238253104562,5.840472643835401
1.3594710515436877e-08,0.009415483096619324,296.79786016639883,152.2238253104562,5.840472643835401
1.4038355355916842e-08,0.009722744548909782,297.8609065455863,152.2238253104562,5.840472643835401
1.4814733826756782e-08,0.010260452090418083,299.6902316654256,152.2238253104562,5.840472643835401
1.520292306217675e-08,0.010529305861172233,300.5908423677757,152.2238253104562,5.840472643835401
1.559111229759672e-08,0.010798159631926384,301.4825279591271,152.2238253104562,5.840472643835401
1.58961181254267e-08,0.011009401880376076,302.1770777420307,152.2238253104562,5.840472643835401
1.7005230226626616e-08,0.011777555511102222,304.6600433891272,152.2238253104562,5.840472643835401
1.7310236054456592e-08,0.01198879775955191,305.3316797124332,152.2238253104562,5.840472643835401
1.7504330672166577e-08,0.012123224644928985,305.75668264313373,152.2238253104562,5.840472643835401
1.8058886722766533e-08,0.012507301460292058,306.96096571974897,152.2238253104562,5.840472643835401
1.877980958854648e-08,0.013006601320264053,308.5051857165013,152.2238253104562,5.840472643835401
1.9112543218906454e-08,0.013237047409481896,309.21008750359937,152.2238253104562,5.840472643835401
1.972255487456641e-08,0.013659531906381276,310.49010025984035,152.2238253104562,5.840472643835401
2.0138471912516376e-08,0.013947589517903581,311.35399549075714,152.2238253104562,5.840472643835401
2.0277110925166365e-08,0.01404360872174435,311.6404105634792,152.2238253104562,5.840472643835401
2.0803939173236326e-08,0.014408481696339268,312.721892595514,152.2238253104562,5.840472643835401
2.11089450010663e-08,0.014619723944788958,313.34313153959215,152.2238253104562,5.840472643835401
2.2911252165516164e-08,0.015867973594718945,316.9450539365344,152.2238253104562,5.840472643835401
2.3909453056596083e-08,0.016559311862372472,318.89233657126226,152.2238253104562,5.840472643835401
2.440855350213605e-08,0.01690498099619924,319.8540676081741,152.2238253104562,5.840472643835401
2.5517665603335966e-08,0.017673134626925387,321.96420448759415,152.2238253104562,5.840472643835401
2.5628576813455957e-08,0.017749949989998,322.1732314325797,152.2238253104562,5.840472643835401
2.5767215826105944e-08,0.017845969193838768,322.4340196653499,152.2238253104562,5.840472643835401
2.659904990200588e-08,0.018422084416883377,323.9874095893914,152.2238253104562,5.840472643835401
2.734770057031582e-08,0.018940588117623523,325.36933407412505,152.2238253104562,5.840472643835401
2.7624978595615804e-08,0.019132626525305063,325.87740361459583,152.2238253104562,5.840472643835401
2.859545168416573e-08,0.01980476095219044,327.64019316090696,152.2238253104562,5.840472643835401
2.8734090696815717e-08,0.019900780156031205,327.89010226732137,152.2238253104562,5.840472643835401
2.9122279932235688e-08,0.020169633926785356,328.5873583193045,152.2238253104562,5.840472643835401
2.9565924772715653e-08,0.020476895379075814,329.37979917181434,152.2238253104562,5.840472643835401
3.012048082331561e-08,0.020860972194438887,330.3638588118189,152.2238253104562,5.840472643835401
3.02591198359656e-08,0.020956991398279657,330.6087665301035,152.2238253104562,5.840472643835401
3.056412566379558e-08,0.021168233646729345,331.146028357397,152.2238253104562,5.840472643835401
3.1700965567525494e-08,0.021955591118223646,333.13039074487057,152.2238253104562,5.840472643835401
3.2089154802945464e-08,0.022224444888977797,333.8015956281119,152.2238253104562,5.840472643835401
3.2255521618125454e-08,0.02233966793358672,334.08828463720357,152.2238253104562,5.840472643835401
3.256052744595542e-08,0.022550910182036407,334.61238783662736,152.2238253104562,5.840472643835401
3.2754622063665415e-08,0.022685337067413484,334.94491138695315,152.2238253104562,5.840472643835401
3.3142811299085385e-08,0.022954190838167635,335.6076619961702,152.2238253104562,5.840472643835401
3.3336905916795364e-08,0.02308861772354471,335.93790152340296,152.2238253104562,5.840472643835401
3.4224195597755295e-08,0.023703140628125625,337.43811989065296,152.2238253104562,5.840472643835401
3.525012429136522e-08,0.02441368273654731,339.1539656900732,152.2238253104562,5.840472643835401
3.5333307698955215e-08,0.02447129425885177,339.29222891472887,152.2238253104562,5.840472643835401
3.605423056473516e-08,0.024970594118823766,340.4852388614893,152.2238253104562,5.840472643835401
3.691379244316509e-08,0.025565913182636527,341.89558231250567,152.2238253104562,5.840472643835401
3.719107046846507e-08,0.025757951590318063,342.3477919213544,152.2238253104562,5.840472643835401
3.863291620002496e-08,0.026756551310262052,344.67841695659587,152.2238253104562,5.840472643835401
3.921520005315492e-08,0.02715983196639328,345.6099841397799,152.2238253104562,5.840472643835401
3.94092946708649e-08,0.027294258851770354,345.9193056799498,152.2238253104562,5.840472643835401
4.140569645302475e-08,0.028676935387077416,349.0671558137277,152.2238253104562,5.840472643835401
4.234844173904468e-08,0.02932986597319464,350.53301041627395,152.2238253104562,5.840472643835401
4.356846505036458e-08,0.0301748349669934,352.4112430214341,152.2238253104562,5.840472643835401
4.46498493490345e-08,0.03092378475695139,354.0589578184947,152.2238253104562,5.840472643835401
4.4843943966744484e-08,0.031058211642328467,354.35304658799305,152.2238253104562,5.840472643835401
4.5786689252764414e-08,0.03171114222844569,355.7744762058868,152.2238253104562,5.840472643835401
4.642442871095436e-08,0.03215283056611322,356.72956485562605,152.2238253104562,5.840472643835401
4.659079552613435e-08,0.032268053610722144,356.97787516697053,152.2238253104562,5.840472643835401
4.6757162341314347e-08,0.03238327665533107,357.22583991735405,152.2238253104562,5.840472643835401
4.706216816914432e-08,0.03259451890378076,357.67955011902495,152.2238253104562,5.840472643835401
4.761672421974427e-08,0.03297859571914383,358.5015505764164,152.2238253104562,5.840472643835401
4.85040139007042e-08,0.033593118623724744,359.80902772499815,152.2238253104562,5.840472643835401
4.891993093865417e-08,0.03388117623524705,360.4186934782894,152.2238253104562,5.840472643835401
5.0029043039854086e-08,0.034649329865973195,362.03466599170406,152.2238253104562,5.840472643835401
5.0361776670214064e-08,0.03487977595519104,362.51672529647226,152.2238253104562,5.840472643835401
5.1609527784063964e-08,0.03574394878975795,364.31349092886194,152.2238253104562,5.840472643835401
5.172043899418397e-08,0.03582076415283057,364.47237897944416,152.2238253104562,5.840472643835401
5.194226141442395e-08,0.0359743948789758,364.789756993126,152.2238253104562,5.840472643835401
5.244136185996391e-08,0.036320064012802564,365.501931185792,152.2238253104562,5.840472643835401
5.3661385171283807e-08,0.03716503300660132,367.2317632098721,152.2238253104562,5.840472643835401
5.4077302209233786e-08,0.03745309061812363,367.8179639220434,152.2238253104562,5.840472643835401
5.418821341935377e-08,0.03752990598119624,367.97398681550334,152.2238253104562,5.840472643835401
5.438230803706376e-08,0.03766433286657332,368.24672752649207,152.2238253104562,5.840472643835401
5.5103230902843704e-08,0.03816363272654531,369.2564577731047,152.2238253104562,5.840472643835401
5.52695977180237e-08,0.03827885577115424,369.48873923212915,152.2238253104562,5.840472643835401
5.6018248386333625e-08,0.038797359471894374,370.5306496382728,152.2238253104562,5.840472643835401
5.679462685717357e-08,0.03933506701340268,371.60542935626586,152.2238253104562,5.840472643835401
5.721054389512353e-08,0.03962312462492498,372.17884648290357,152.2238253104562,5.840472643835401
5.812556137861347e-08,0.04025685137027406,373.4346722879656,152.2238253104562,5.840472643835401
5.8596934021623425e-08,0.04058331666333266,374.0786024002256,152.2238253104562,5.840472643835401
5.940104029499338e-08,0.04114022804560913,375.17242828887737,152.2238253104562,5.840472643835401
5.984468513547335e-08,0.04144748949789959,375.7734460123246,152.2238253104562,5.840472643835401
6.006650755571333e-08,0.041601120224044816,376.0733030750762,152.2238253104562,5.840472643835401
6.062106360631328e-08,0.04198519703940788,376.8210624796525,152.2238253104562,5.840472643835401
6.17579035100432e-08,0.042772554510902186,378.34568050653326,152.2238253104562,5.840472643835401
6.18410869176332e-08,0.04283016603320665,378.45680630781266,152.2238253104562,5.840472643835401
6.206290933787318e-08,0.04298379675935188,378.75285714496556,152.2238253104562,5.840472643835401
6.331066045172308e-08,0.04384796959391879,380.4105173694729,152.2238253104562,5.840472643835401
6.358793847702306e-08,0.04404000800160032,380.77715030650273,152.2238253104562,5.840472643835401
6.403158331750302e-08,0.04434726945389078,381.3624687862468,152.2238253104562,5.840472643835401
6.4253405737743e-08,0.04450090018003601,381.6545347704145,152.2238253104562,5.840472643835401
6.4419772552923e-08,0.044616123224644935,381.8733262665312,152.2238253104562,5.840472643835401
6.577843487689288e-08,0.045557111422284455,383.6519490630242,152.2238253104562,5.840472643835401
6.644390213761284e-08,0.04601800360072014,384.51787910191854,152.2238253104562,5.840472643835401
6.672118016291281e-08,0.046210042008401675,384.8776842576312,152.2238253104562,5.840472643835401
6.694300258315279e-08,0.046363672734546904,385.16510868825833,152.2238253104562,5.840472643835401
6.722028060845278e-08,0.04655571114222845,385.52386742528796,152.2238253104562,5.840472643835401
6.819075369700271e-08,0.04722784556911383,386.7750031682485,152.2238253104562,5.840472643835401
6.857894293242267e-08,0.04749669933986797,387.2735107298636,152.2238253104562,5.840472643835401
6.979896624374258e-08,0.04834166833366674,388.8331319721544,152.2238253104562,5.840472643835401
7.021488328169254e-08,0.04862972594518904,389.36238624134097,152.2238253104562,5.840472643835401
7.08248949373525e-08,0.04905221044208842,390.1364195280467,152.2238253104562,5.840472643835401
7.157354560566245e-08,0.04957071414282857,391.0828250398352,152.2238253104562,5.840472643835401
7.312630254734233e-08,0.050646129225845174,393.03352039251155,152.2238253104562,5.840472643835401
7.351449178276228e-08,0.050914982996599314,393.5186618516059,152.2238253104562,5.840472643835401
7.393040882071226e-08,0.05120304060812163,394.0373489183486,152.2238253104562,5.840472643835401
7.417995904348223e-08,0.051375875175035,394.3480149316921,152.2238253104562,5.840472643835401
7.484542630420218e-08,0.05183676735347069,395.17447139117803,152.2238253104562,5.840472643835401
7.589908280034211e-08,0.05256651330266053,396.47719049244034,152.2238253104562,5.840472643835401
7.631499983829209e-08,0.052854570914182844,396.9894778279859,152.2238253104562,5.840472643835401
7.695273929648203e-08,0.05329625925185037,397.77287531767166,152.2238253104562,5.840472643835401
7.759047875467198e-08,0.0537379475895179,398.5537448469531,152.2238253104562,5.840472643835401
7.786775677997195e-08,0.053929985997199434,398.8924721635529,152.2238253104562,5.840472643835401
7.808957920021193e-08,0.05408361672334466,399.16311544741836,152.2238253104562,5.840472643835401
7.85332240406919e-08,0.05439087817563512,399.70350420276964,152.2238253104562,5.840472643835401
7.903232448623188e-08,0.0547365473094619,400.3100204767664,152.2238253104562,5.840472643835401
7.925414690647186e-08,0.054890178035607126,400.57910358526277,152.2238253104562,5.840472643835401
7.98087029570718e-08,0.05527425485097019,401.25052951563265,152.2238253104562,5.840472643835401
7.99750697722518e-08,0.05538947789557912,401.4516021668303,152.2238253104562,5.840472643835401
8.041871461273177e-08,0.055696739347869575,401.9869999856548,152.2238253104562,5.840472643835401
8.105645407092171e-08,0.056138427685537104,402.75462065438967,152.2238253104562,5.840472643835401
8.111190967598172e-08,0.05617683536707342,402.82125876282026,152.2238253104562,5.840472643835401
8.127827649116169e-08,0.05629205841168233,403.0210665594233,152.2238253104562,5.840472643835401
8.147237110887168e-08,0.05642648529705942,403.2539741732876,152.2238253104562,5.840472643835401
8.183283254176165e-08,0.05667613522704541,403.68594357748464,152.2238253104562,5.840472643835401
8.197147155441165e-08,0.05677215443088618,403.851887982783,152.2238253104562,5.840472643835401
8.235966078983162e-08,0.057041008201640334,404.31595100827263,152.2238253104562,5.840472643835401
8.299740024802156e-08,0.05748269653930786,405.07649265785875,152.2238253104562,5.840472643835401
8.407878454669148e-08,0.05823164632926585,406.36091848468794,152.2238253104562,5.840472643835401
8.474425180741142e-08,0.058692538507701536,407.14813271981444,152.2238253104562,5.840472643835401
8.52433522529514e-08,0.05903820764152831,407.73696223093077,152.2238253104562,5.840472643835401
8.552063027825138e-08,0.059230246049209845,408.0635087130034,152.2238253104562,5.840472643835401
8.601973072379133e-08,0.05957591518303661,408.6502537512474,152.2238253104562,5.840472643835401
8.660201457692128e-08,0.05997919583916783,409.3331141826016,152.2238253104562,5.840472643835401
8.679610919463129e-08,0.060113622724544916,409.5603361043843,152.2238253104562,5.840472643835401
8.793294909836118e-08,0.060900980196039206,410.8872494673539,152.2238253104562,5.840472643835401
8.837659393884114e-08,0.061208241648329664,411.40325233417764,152.2238253104562,5.840472643835401
9.012344549823103e-08,0.06241808361672335,413.425269402433,152.2238253104562,5.840472643835401
9.15375634272609e-08,0.06339747949589918,415.0509676420623,152.2238253104562,5.840472643835401
9.203666387280088e-08,0.06374314862972595,415.6224011219793,152.2238253104562,5.840472643835401
9.259121992340083e-08,0.06412722544508902,416.25591168261803,152.2238253104562,5.840472643835401
9.267440333099082e-08,0.06418483696739348,416.35081048407613,152.2238253104562,5.840472643835401
9.408852126002072e-08,0.06516423284656932,417.95904181672586,152.2238253104562,5.840472643835401
9.483717192833067e-08,0.06568273654730947,418.8066406182109,152.2238253104562,5.840472643835401
9.605719523965056e-08,0.06652770554110822,420.18234277473516,152.2238253104562,5.840472643835401
9.730494635350049e-08,0.06739187837567515,421.58228056230894,152.2238253104562,5.840472643835401
9.744358536615048e-08,0.06748789757951591,421.73739582849237,152.2238253104562,5.840472643835401
9.810905262687042e-08,0.0679487897579516,422.4807543330899,152.2238253104562,5.840472643835401
9.930134813566031e-08,0.0687745549109822,423.8077057676262,152.2238253104562,5.840472643835401
9.974499297614028e-08,0.06908181636327265,424.29986710418746,152.2238253104562,5.840472643835401
9.982817638373028e-08,0.06913942788557711,424.39205223461863,152.2238253104562,5.840472643835401
1.0043818803939023e-07,0.0695619123824765,425.0671635273944,152.2238253104562,5.840472643835401
1.0143638893047017e-07,0.07025325065013004,426.16845196023695,152.2238253104562,5.840472643835401
1.0176912256083013e-07,0.07048369673934787,426.53460780082196,152.2238253104562,5.840472643835401
1.0224049520384011e-07,0.07081016203240649,427.0525303665965,152.2238253104562,5.840472643835401
1.0243458982155009e-07,0.07094458891778356,427.26552182458676,152.2238253104562,5.840472643835401
1.0359915752780999e-07,0.07175115023004601,428.54018088151633,152.2238253104562,5.840472643835401
1.0456963061635992e-07,0.07242328465693139,429.5981336048408,152.2238253104562,5.840472643835401
1.047914530365999e-07,0.07257691538307662,429.83941290290204,152.2238253104562,5.840472643835401
1.0545692029731984e-07,0.0730378075615123,430.5620584927618,152.2238253104562,5.840472643835401
1.0570647052008984e-07,0.0732106421284257,430.83259180685997,152.2238253104562,5.840472643835401
1.0731468306682971e-07,0.0743244648929786,432.5700918241935,152.2238253104562,5.840472643835401
1.0803560593260965e-07,0.07482376475295059,433.3456716644178,152.2238253104562,5.840472643835401
1.0836833956296963e-07,0.07505421084216844,433.7029505687225,152.2238253104562,5.840472643835401
1.088119844034496e-07,0.0753614722944589,434.17865764709643,152.2238253104562,5.840472643835401
1.0928335704645956e-07,0.0756879375875175,434.6832683596425,152.2238253104562,5.840472643835401
1.0975472968946952e-07,0.07601440288057612,435.18703093170086,152.2238253104562,5.840472643835401
1.1011519112235949e-07,0.07626405281056212,435.57169200680755,152.2238253104562,5.840472643835401
1.1078065838307945e-07,0.0767249449889978,436.2805478182149,152.2238253104562,5.840472643835401
1.1164022026150937e-07,0.07732026405281056,437.19370022411124,152.2238253104562,5.840472643835401
1.1236114312728933e-07,0.07781956391278257,437.95745765638526,152.2238253104562,5.840472643835401
1.1313752159812926e-07,0.07835727145429086,438.77783148946503,152.2238253104562,5.840472643835401
1.1330388841330926e-07,0.07847249449889979,438.953339903993,152.2238253104562,5.840472643835401
1.1347025522848925e-07,0.07858771754350871,439.12874784299635,152.2238253104562,5.840472643835401
1.1377526105631921e-07,0.07879895979195839,439.4500687861027,152.2238253104562,5.840472643835401
1.1593802965365905e-07,0.08029685937187438,441.7189666493048,152.2238253104562,5.840472643835401
1.1624303548148902e-07,0.08050810162032407,442.03760625377777,152.2238253104562,5.840472643835401
1.1699168614979897e-07,0.08102660532106422,442.8183423735244,152.2238253104562,5.840472643835401
1.1774033681810891e-07,0.08154510902180437,443.5971324395912,152.2238253104562,5.840472643835401
1.1868308210412884e-07,0.08219803960792159,444.5750893090802,152.2238253104562,5.840472643835401
1.1887717672183882e-07,0.08233246649329866,444.77605676804626,152.2238253104562,5.840472643835401
1.1901581573448882e-07,0.08242848569713944,444.9195266125302,152.2238253104562,5.840472643835401
1.1979219420532876e-07,0.08296619323864773,445.7217564898105,152.2238253104562,5.840472643835401
1.2026356684833874e-07,0.08329265853170635,446.2078354173027,152.2238253104562,5.840472643835401
1.216499569748386e-07,0.08425285057011403,447.63319122172874,152.2238253104562,5.840472643835401
1.2212132961784856e-07,0.08457931586317263,448.11636719142757,152.2238253104562,5.840472643835401
1.2273134127350854e-07,0.08500180036007202,448.7405754174741,152.2238253104562,5.840472643835401
1.230363471013385e-07,0.08521304260852171,449.0522257055781,152.2238253104562,5.840472643835401
1.2353544754687847e-07,0.08555871174234847,449.5615497681232,152.2238253104562,5.840472643835401
1.243395538202484e-07,0.08611562312462492,450.3804426562769,152.2238253104562,5.840472643835401
1.2489410987084837e-07,0.086499699939988,450.94399340282416,152.2238253104562,5.840472643835401
1.2522684350120832e-07,0.08673014602920584,451.28165544225106,152.2238253104562,5.840472643835401
1.258645829593983e-07,0.08717183436687338,451.9278645988206,152.2238253104562,5.840472643835401
1.2630822779987825e-07,0.08747909581916384,452.3766484655645,152.2238253104562,5.840472643835401
1.269182394555382e-07,0.08790158031606321,452.99272378959324,152.2238253104562,5.840472643835401
1.2733415649348818e-07,0.08818963792758552,453.4121131862197,152.2238253104562,5.840472643835401
1.2755597891372817e-07,0.08834326865373075,453.6355690671339,152.2238253104562,5.840472643835401
1.2777780133396814e-07,0.08849689937987598,453.858873447567,152.2238253104562,5.840472643835401
1.2863736321239807e-07,0.08909221844368874,454.722753692106,152.2238253104562,5.840472643835401
1.2874827442251808e-07,0.08916903380676136,454.83405789688805,152.2238253104562,5.840472643835401
1.2913646365793804e-07,0.0894378875775155,455.22332847295377,152.2238253104562,5.840472643835401
1.29691019708538e-07,0.08982196439287858,455.7786385786585,152.2238253104562,5.840472643835401
1.3002375333889797e-07,0.09005241048209642,456.11138015414133,152.2238253104562,5.840472643835401
1.3041194257431795e-07,0.09032126425285057,456.49915923537077,152.2238253104562,5.840472643835401
1.311051376375679e-07,0.09080136027205442,457.1905040575793,152.2238253104562,5.840472643835401
1.3135468786033785e-07,0.09097419483896779,457.4390390204401,152.2238253104562,5.840472643835401
1.3243607215900778e-07,0.09172314462892579,458.51390293684796,152.2238253104562,5.840472643835401
1.3285198919695776e-07,0.09201120224044809,458.92640004028283,152.2238253104562,5.840472643835401
1.3321245062984772e-07,0.09226085217043409,459.28349030661906,152.2238253104562,5.840472643835401
1.3459884075634762e-07,0.09322104420884177,460.6534167359385,152.2238253104562,5.840472643835401
1.350147577942976e-07,0.09350910182036408,461.06332012238715,152.2238253104562,5.840472643835401
1.360129586853775e-07,0.0942004400880176,462.0450842077675,152.2238253104562,5.840472643835401
1.362070533030875e-07,0.09433486697339469,462.23565603324084,152.2238253104562,5.840472643835401
1.3659524253850746e-07,0.09460372074414883,462.61648225153135,152.2238253104562,5.840472643835401
1.375934434295874e-07,0.09529505901180237,463.5938165883392,152.2238253104562,5.840472643835401
1.3775981024476739e-07,0.09541028205641129,463.756436430391,152.2238253104562,5.840472643835401
1.3814799948018734e-07,0.09567913582716543,464.1355851633302,152.2238253104562,5.840472643835401
1.3903528916114727e-07,0.09629365873174635,465.00065403878017,152.2238253104562,5.840472643835401
1.4036622368258718e-07,0.09721544308861772,466.2942312828504,152.2238253104562,5.840472643835401
1.412535133635471e-07,0.09782996599319864,467.1539595701381,152.2238253104562,5.840472643835401
1.414198801787271e-07,0.09794518903780756,467.31492388054255,152.2238253104562,5.840472643835401
1.4180806941414708e-07,0.09821404280856172,467.69022035120605,152.2238253104562,5.840472643835401
1.4191898062426706e-07,0.09829085817163433,467.797374295239,152.2238253104562,5.840472643835401
1.4239035326727701e-07,0.09861732346469294,468.2524146846907,152.2238253104562,5.840472643835401
1.4366583218365692e-07,0.09950070014002801,469.48076443288267,152.2238253104562,5.840472643835401
1.4380447119630692e-07,0.09959671934386878,469.6140239396677,152.2238253104562,5.840472643835401