File: datasets/aisi_316_L/data/M1/valid_10.csv
Time(s),Strain(%),Stress(MPa),Temp(C),Log_SR(s-1)
0.0,0.0,0.0,403.8374771215529,-1.1287662247120465
0.0001506552419913714,1.12e-05,1.892255925,403.8374771215529,-1.1287662247120465
0.00048424899211512237,3.6e-05,6.0822511875,403.8374771215529,-1.1287662247120465
0.0006779485889611713,5.04e-05,8.5151516625,403.8374771215529,-1.1287662247120465
0.000979259072943914,7.28e-05,12.299663512499999,403.8374771215529,-1.1287662247120465
0.0015173135086273834,0.00011279999999999999,19.057720387499998,403.8374771215529,-1.1287662247120465
0.001646446573191416,0.0001224,20.6796540375,403.8374771215529,-1.1287662247120465
0.0017755796377554485,0.00013199999999999998,22.301587687499996,403.8374771215529,-1.1287662247120465
0.0019692792346014975,0.00014639999999999998,24.734488162499996,403.8374771215529,-1.1287662247120465
0.0020230846781698446,0.0001504,25.41029385,403.8374771215529,-1.1287662247120465
0.0021845010088748854,0.0001624,27.4377109125,403.8374771215529,-1.1287662247120465
0.0023889616944346033,0.00017759999999999998,30.005772524999998,403.8374771215529,-1.1287662247120465
0.002485811492857628,0.0001848,31.2222227625,403.8374771215529,-1.1287662247120465
0.002604183468707991,0.0001936,32.708995275,403.8374771215529,-1.1287662247120465
0.002840927420408718,0.00021119999999999998,35.6825403,403.8374771215529,-1.1287662247120465
0.0030238659285410975,0.0002248,37.9802796375,403.8374771215529,-1.1287662247120465
0.003077671372109444,0.00022879999999999998,38.656085325,403.8374771215529,-1.1287662247120465
0.0032283266141008155,0.00023999999999999998,40.54834124999999,403.8374771215529,-1.1287662247120465
0.0034973538319425504,0.00026,43.9273696875,403.8374771215529,-1.1287662247120465
0.0036049647190792445,0.000268,45.2789810625,403.8374771215529,-1.1287662247120465
0.003917036291775656,0.0002912,49.198654049999995,403.8374771215529,-1.1287662247120465
0.004315196574181424,0.0003208,54.1996161375,403.8374771215529,-1.1287662247120465
0.00472411794530086,0.00035119999999999997,59.33573936249999,403.8374771215529,-1.1287662247120465
0.0049285786308605785,0.00036639999999999996,61.903800974999996,403.8374771215529,-1.1287662247120465
0.005014667340569934,0.0003728,62.985090075,403.8374771215529,-1.1287662247120465
0.005165322582561306,0.000384,64.877346,403.8374771215529,-1.1287662247120465
0.005208366937415982,0.0003872,65.41799055,403.8374771215529,-1.1287662247120465
0.005359022179407354,0.0003984,67.310246475,403.8374771215529,-1.1287662247120465
0.005617288308535419,0.00041759999999999996,70.55411377499999,403.8374771215529,-1.1287662247120465
0.005800226816667799,0.00043119999999999996,72.8518531125,403.8374771215529,-1.1287662247120465
0.005886315526377153,0.00043759999999999996,73.93314221249999,403.8374771215529,-1.1287662247120465
0.005983165324800178,0.00044479999999999997,75.14959245,403.8374771215529,-1.1287662247120465
0.00630599798621026,0.00046879999999999996,79.204426575,403.8374771215529,-1.1287662247120465
0.006499697583056309,0.0004832,81.63732705,403.8374771215529,-1.1287662247120465
0.006714919357329697,0.0004992,84.3405498,403.8374771215529,-1.1287662247120465
0.006962424397744093,0.0005176,87.4492559625,403.8374771215529,-1.1287662247120465
0.007199168349444819,0.0005352,90.4228009875,403.8374771215529,-1.1287662247120465
0.007242212704299497,0.0005384,90.9634455375,403.8374771215529,-1.1287662247120465
0.007747983873841958,0.000576,97.316019,403.8374771215529,-1.1287662247120465
0.0078017893174103055,0.00058,97.9918246875,403.8374771215529,-1.1287662247120465
0.007984727825542685,0.0005936,100.289564025,403.8374771215529,-1.1287662247120465
0.008372127019234782,0.0006224,105.155364975,403.8374771215529,-1.1287662247120465
0.008512021172512485,0.0006328,106.91245976249999,403.8374771215529,-1.1287662247120465
0.00893170363234559,0.000664,112.183744125,403.8374771215529,-1.1287662247120465
0.009007031253341277,0.0006696,113.1298720875,403.8374771215529,-1.1287662247120465
0.009222253027614664,0.0006856,115.8330948375,403.8374771215529,-1.1287662247120465
0.009308341737324019,0.000692,116.9143839375,403.8374771215529,-1.1287662247120465
0.00944823589060172,0.0007023999999999999,118.67147872499999,403.8374771215529,-1.1287662247120465
0.009566607866452083,0.0007111999999999999,120.1582512375,403.8374771215529,-1.1287662247120465
0.009771068552011802,0.0007264,122.72631285,403.8374771215529,-1.1287662247120465
0.009867918350434827,0.0007335999999999999,123.94276308749998,403.8374771215529,-1.1287662247120465
0.010061617947280875,0.000748,126.3756635625,403.8374771215529,-1.1287662247120465
0.010244556455413256,0.0007616,128.67340289999999,403.8374771215529,-1.1287662247120465
0.010416733874831965,0.0007744,130.8359811,403.8374771215529,-1.1287662247120465
0.01051358367325499,0.0007815999999999999,132.0524313375,403.8374771215529,-1.1287662247120465
0.011137726818647813,0.000828,139.89177731249998,403.8374771215529,-1.1287662247120465
0.011847958673749994,0.0008807999999999999,148.8124123875,403.8374771215529,-1.1287662247120465
0.011998613915741366,0.000892,150.7046683125,403.8374771215529,-1.1287662247120465
0.012181552423873745,0.0009056,151.32926993356642,403.8374771215529,-1.1287662247120465
0.012246118956155762,0.0009104,151.35387051827678,403.8374771215529,-1.1287662247120465
0.012375252020719794,0.0009199999999999999,151.40292045675022,403.8374771215529,-1.1287662247120465
0.01262275706113419,0.0009383999999999999,151.49637845618307,403.8374771215529,-1.1287662247120465
0.01331146673880903,0.0009896,151.75274715293153,403.8374771215529,-1.1287662247120465
0.01349440524694141,0.0010031999999999999,151.81996877449342,403.8374771215529,-1.1287662247120465
0.013752671376069475,0.0010224,151.91426795380644,403.8374771215529,-1.1287662247120465
0.013871043351919838,0.0010312,151.9572573461398,403.8374771215529,-1.1287662247120465
0.013924848795488186,0.0010352,151.97675065761936,403.8374771215529,-1.1287662247120465
0.014043220771338549,0.001044,152.01953283937416,403.8374771215529,-1.1287662247120465
0.014161592747188912,0.0010528,152.06217460978382,403.8374771215529,-1.1287662247120465
0.014279964723039275,0.0010616,152.10467759760525,403.8374771215529,-1.1287662247120465
0.014312247989180285,0.001064,152.11624544599135,403.8374771215529,-1.1287662247120465
0.014462903231171654,0.0010752,152.17009475731837,403.8374771215529,-1.1287662247120465
0.01471040827158605,0.0010936,152.2580889756874,403.8374771215529,-1.1287662247120465
0.01503324093299613,0.0011175999999999998,152.37200112118572,403.8374771215529,-1.1287662247120465
0.015097807465278149,0.0011224,152.39466862971028,403.8374771215529,-1.1287662247120465
0.01526998488469686,0.0011352,152.454931248385,403.8374771215529,-1.1287662247120465
0.015463684481542908,0.0011496,152.52241082575858,403.8374771215529,-1.1287662247120465
0.015721950610670974,0.0011688,152.61187302159803,403.8374771215529,-1.1287662247120465
0.01593717238494436,0.0011848,152.68598785859413,403.8374771215529,-1.1287662247120465
0.01610934980436307,0.0011976,152.74499906241684,403.8374771215529,-1.1287662247120465
0.016399899199632143,0.0012192,152.84402571643844,403.8374771215529,-1.1287662247120465
0.016507510086768838,0.0012272,152.88052831576377,403.8374771215529,-1.1287662247120465
0.016927192546601945,0.0012584,153.02201047865807,403.8374771215529,-1.1287662247120465
0.017067086699879646,0.0012688,153.06886631046717,403.8374771215529,-1.1287662247120465
0.017206980853157347,0.0012791999999999999,153.11557259439772,403.8374771215529,-1.1287662247120465
0.01732535282900771,0.0012879999999999999,153.15497774085085,403.8374771215529,-1.1287662247120465
0.017476008070999083,0.0012992,153.20497821864006,403.8374771215529,-1.1287662247120465
0.017626663312990454,0.0013104,153.25481087116873,403.8374771215529,-1.1287662247120465
0.017917212708259526,0.0013319999999999999,153.35045009255785,403.8374771215529,-1.1287662247120465
0.01824004536966961,0.001356,153.45600928378522,403.8374771215529,-1.1287662247120465
0.018509072587511343,0.0013759999999999998,153.5434198080124,403.8374771215529,-1.1287662247120465
0.018692011095643724,0.0013896,153.60257612148615,403.8374771215529,-1.1287662247120465
0.01874581653921207,0.0013935999999999998,153.6199320098322,403.8374771215529,-1.1287662247120465
0.018993321579626465,0.0014119999999999998,153.69952018817418,403.8374771215529,-1.1287662247120465
0.019133215732904166,0.0014223999999999999,153.74432587309698,403.8374771215529,-1.1287662247120465
0.019176260087758846,0.0014256,153.75808650986104,403.8374771215529,-1.1287662247120465
0.019326915329750217,0.0014368,153.80615416035295,403.8374771215529,-1.1287662247120465
0.01944528730560058,0.0014456,153.84381916089845,403.8374771215529,-1.1287662247120465
0.019574420370164613,0.0014552,153.88480641491523,403.8374771215529,-1.1287662247120465
0.01980040323315167,0.001472,153.95628126233512,403.8374771215529,-1.1287662247120465
0.01996181956385671,0.0014839999999999999,154.00714008031483,403.8374771215529,-1.1287662247120465
0.020263130047839455,0.0015064,154.10164945649987,403.8374771215529,-1.1287662247120465
0.020973361902941634,0.0015592,154.32227897689444,403.8374771215529,-1.1287662247120465
0.021059450612650986,0.0015655999999999999,154.34882250010972,403.8374771215529,-1.1287662247120465
0.0212316280320697,0.0015784,154.4017829331807,403.8374771215529,-1.1287662247120465
0.02125315020949704,0.00158,154.40839118994165,403.8374771215529,-1.1287662247120465
0.021425327628915747,0.0015928,154.46116361524278,403.8374771215529,-1.1287662247120465
0.021522177427338772,0.0015999999999999999,154.49077541640654,403.8374771215529,-1.1287662247120465
0.022189364927586275,0.0016496,154.69337392904066,403.8374771215529,-1.1287662247120465
0.022469153234141677,0.0016703999999999998,154.77762590978287,403.8374771215529,-1.1287662247120465
0.022695136097128737,0.0016872,154.8453772777555,403.8374771215529,-1.1287662247120465
0.022888835693974784,0.0017016,154.90324073546535,403.8374771215529,-1.1287662247120465
0.0229534022262568,0.0017063999999999998,154.92248607484277,403.8374771215529,-1.1287662247120465
0.02298568549239781,0.0017088,154.93210082632146,403.8374771215529,-1.1287662247120465
0.02316862400053019,0.0017224,154.9864852673551,403.8374771215529,-1.1287662247120465
0.02346993448451293,0.0017448,155.0756959750951,403.8374771215529,-1.1287662247120465
0.023599067549076962,0.0017544,155.11379227588745,403.8374771215529,-1.1287662247120465
0.02421244960575612,0.0018,155.29365101373915,403.8374771215529,-1.1287662247120465
0.02432006049289281,0.001808,155.32502107241132,403.8374771215529,-1.1287662247120465
0.024395388113888496,0.0018135999999999998,155.34694791154274,403.8374771215529,-1.1287662247120465
0.024470715734884185,0.0018192,155.3688483614568,403.8374771215529,-1.1287662247120465
0.024621370976875553,0.0018303999999999998,155.41257054419296,403.8374771215529,-1.1287662247120465
0.024804309485007933,0.001844,155.46552174759535,403.8374771215529,-1.1287662247120465
0.025331602831977735,0.0018832,155.61730024632118,403.8374771215529,-1.1287662247120465
0.02540693045297342,0.0018888,155.63888187688772,403.8374771215529,-1.1287662247120465
0.025740524203097172,0.0019136,155.73415927854512,403.8374771215529,-1.1287662247120465
0.025966507066084228,0.0019303999999999999,155.79842858461106,403.8374771215529,-1.1287662247120465
0.02614944557421661,0.001944,155.85029649493697,403.8374771215529,-1.1287662247120465
0.026536844767908702,0.0019728,155.95966957993835,403.8374771215529,-1.1287662247120465
0.026859677429318787,0.0019968,156.05033893823347,403.8374771215529,-1.1287662247120465
0.026945766139028146,0.0020032,156.07444552787743,403.8374771215529,-1.1287662247120465
0.027150226824587863,0.0020184,156.13157861425387,403.8374771215529,-1.1287662247120465
0.02729012097786556,0.0020288,156.17057302624175,403.8374771215529,-1.1287662247120465
0.02734392642143391,0.0020328,156.18555010929296,403.8374771215529,-1.1287662247120465
0.027580670373134636,0.0020504,156.25131320360333,403.8374771215529,-1.1287662247120465
0.027838936502262702,0.0020696,156.32280418582798,403.8374771215529,-1.1287662247120465
0.028075680453963428,0.0020872,156.3881106856864,403.8374771215529,-1.1287662247120465
0.028312424405664154,0.0021048,156.45320276724948,403.8374771215529,-1.1287662247120465
0.0286137348896469,0.0021272,156.5357410460138,403.8374771215529,-1.1287662247120465
0.028667540333215242,0.0021311999999999998,156.5504442846694,403.8374771215529,-1.1287662247120465
0.028979611905911657,0.0021544,156.6355117896383,403.8374771215529,-1.1287662247120465
0.029054939526907343,0.00216,156.65599170849524,403.8374771215529,-1.1287662247120465
0.02935625001089008,0.0021823999999999997,156.73770515483466,403.8374771215529,-1.1287662247120465
0.029592993962590807,0.0021999999999999997,156.80167933251388,403.8374771215529,-1.1287662247120465
0.030023437511137587,0.002232,156.9174869742989,403.8374771215529,-1.1287662247120465
0.03062605847910307,0.0022768,157.0785356679879,403.8374771215529,-1.1287662247120465
0.030776713721094445,0.002288,157.11860414838154,403.8374771215529,-1.1287662247120465
0.031034979850222504,0.0023071999999999997,157.18711546094266,403.8374771215529,-1.1287662247120465
0.03135781251163259,0.0023312,157.27244271944713,403.8374771215529,-1.1287662247120465
0.03146542339876929,0.0023392,157.30080891608588,403.8374771215529,-1.1287662247120465
0.03193891130217074,0.0023744,157.4251734040904,403.8374771215529,-1.1287662247120465
0.03221869960872614,0.0023952,157.49832355301604,403.8374771215529,-1.1287662247120465
0.032541532270136224,0.0024192,157.5824204299084,403.8374771215529,-1.1287662247120465
0.03278903731055062,0.0024376,157.6466745377376,403.8374771215529,-1.1287662247120465
0.03302578126225134,0.0024552,157.7079582213803,403.8374771215529,-1.1287662247120465
0.03316567541552905,0.0024656,157.74409077729587,403.8374771215529,-1.1287662247120465
0.0332517641252384,0.002472,157.76629665453245,403.8374771215529,-1.1287662247120465
0.033434702633370776,0.0024855999999999997,157.8134098349383,403.8374771215529,-1.1287662247120465
0.03376829638349453,0.0025104,157.89906410086516,403.8374771215529,-1.1287662247120465
0.03383286291577655,0.0025152,157.91560416091912,403.8374771215529,-1.1287662247120465
0.034101890133618286,0.0025352,157.98438898890873,403.8374771215529,-1.1287662247120465
0.034435483883742034,0.0025599999999999998,158.06938896934574,403.8374771215529,-1.1287662247120465
0.034736794367724776,0.0025824,158.14588751465178,403.8374771215529,-1.1287662247120465
0.0350811492065622,0.002608,158.23299825287123,403.8374771215529,-1.1287662247120465
0.03530713206954926,0.0026248,158.2899835045118,403.8374771215529,-1.1287662247120465
0.03532865424697659,0.0026264,158.2954032419254,403.8374771215529,-1.1287662247120465
0.03538245969054494,0.0026303999999999998,158.30894695498844,403.8374771215529,-1.1287662247120465
0.035651486908386675,0.0026504,158.37654540922583,403.8374771215529,-1.1287662247120465
0.0357483367068097,0.0026576,158.40083211488317,403.8374771215529,-1.1287662247120465
0.03612497481178813,0.0026856,158.49503748242788,403.8374771215529,-1.1287662247120465
0.0365231350941939,0.0027152,158.59421045481434,403.8374771215529,-1.1287662247120465
0.036630745981330586,0.0027232,158.62094146810267,403.8374771215529,-1.1287662247120465
0.03670607360232628,0.0027288,158.63963495790205,403.8374771215529,-1.1287662247120465
0.036932056465313334,0.0027456,158.69562586494706,403.8374771215529,-1.1287662247120465
0.037039667352450026,0.0027535999999999997,158.7222412256679,403.8374771215529,-1.1287662247120465
0.03717956150572773,0.002764,158.75679615371348,403.8374771215529,-1.1287662247120465
0.03726565021543708,0.0027703999999999997,158.77803552277237,403.8374771215529,-1.1287662247120465
0.0375777217881335,0.0027936,158.8548683451942,403.8374771215529,-1.1287662247120465
0.038083492957675956,0.0028312,158.9788641330861,403.8374771215529,-1.1287662247120465
0.038298714731949346,0.0028472,159.0314333198402,403.8374771215529,-1.1287662247120465
0.03848165324008172,0.0028607999999999997,159.07602660649712,403.8374771215529,-1.1287662247120465
0.038696875014355106,0.0028767999999999997,159.1283835855997,403.8374771215529,-1.1287662247120465
0.03890133569991483,0.002892,159.17801762481403,403.8374771215529,-1.1287662247120465
0.039062752030619874,0.002904,159.21713056326962,403.8374771215529,-1.1287662247120465
0.03962232864373068,0.0029456,159.35223674059088,403.8374771215529,-1.1287662247120465
0.040085055458418464,0.00298,159.463397947394,403.8374771215529,-1.1287662247120465
0.04037560485368753,0.0030015999999999997,159.53294113395674,403.8374771215529,-1.1287662247120465
0.040633870982815595,0.0030207999999999997,159.59459361833973,403.8374771215529,-1.1287662247120465
0.04077376513609331,0.0030312,159.62792489696082,403.8374771215529,-1.1287662247120465
0.04092442037808467,0.0030424,159.66377028125146,403.8374771215529,-1.1287662247120465
0.04110735888621705,0.0030559999999999997,159.70722770703986,403.8374771215529,-1.1287662247120465
0.041322580660490445,0.003072,159.75825764406645,403.8374771215529,-1.1287662247120465
0.0415485635234775,0.0030888,159.81172764575095,403.8374771215529,-1.1287662247120465
0.04167769658804153,0.0030984,159.84223100744953,403.8374771215529,-1.1287662247120465
0.04183911291874657,0.0031103999999999997,159.8803084260579,403.8374771215529,-1.1287662247120465
0.042323361910861695,0.0031463999999999997,159.99419840448698,403.8374771215529,-1.1287662247120465
0.04272152219326746,0.003176,160.08746104355058,403.8374771215529,-1.1287662247120465
0.04297978832239553,0.0031952,160.14777452522637,403.8374771215529,-1.1287662247120465
0.04311968247567323,0.0032056,160.18038530471836,403.8374771215529,-1.1287662247120465
0.04325957662895093,0.0032159999999999997,160.21295484826243,403.8374771215529,-1.1287662247120465
0.043388709693514965,0.0032256,160.242982602572,403.8374771215529,-1.1287662247120465
0.04360393146778835,0.0032416,160.2929515229617,403.8374771215529,-1.1287662247120465
0.04370078126621138,0.0032488,160.31540614614656,403.8374771215529,-1.1287662247120465
0.04374382562106605,0.0032519999999999997,160.32537974809262,403.8374771215529,-1.1287662247120465
0.04396980848405311,0.0032687999999999997,160.37767849657493,403.8374771215529,-1.1287662247120465
0.044002091750194115,0.0032711999999999997,160.3851411800635,403.8374771215529,-1.1287662247120465
0.04422807461318117,0.0032879999999999997,160.4373203055156,403.8374771215529,-1.1287662247120465
0.044583190540732266,0.0033144,160.51910648797022,403.8374771215529,-1.1287662247120465
0.04483069558114666,0.0033328,160.5759587972642,403.8374771215529,-1.1287662247120465
0.045110483887702064,0.0033536,160.64007942922376,403.8374771215529,-1.1287662247120465
0.045218094774838756,0.0033615999999999997,160.66469988842445,403.8374771215529,-1.1287662247120465
0.045497883081394165,0.0033824,160.72860637717332,403.8374771215529,-1.1287662247120465
0.04557321070238985,0.003388,160.74578576022395,403.8374771215529,-1.1287662247120465
0.04571310485566755,0.0033983999999999998,160.77766097661302,403.8374771215529,-1.1287662247120465
0.0462942036462057,0.0034416,160.90966055063325,403.8374771215529,-1.1287662247120465
0.04635877017848771,0.0034463999999999996,160.92428717235777,403.8374771215529,-1.1287662247120465
0.046563230864047435,0.0034616,160.97055248134336,403.8374771215529,-1.1287662247120465
0.04664931957375679,0.0034679999999999997,160.99000890077025,403.8374771215529,-1.1287662247120465
0.04686454134803017,0.0034839999999999997,161.03858878551154,403.8374771215529,-1.1287662247120465
0.04693986896902586,0.0034896,161.05557117928717,403.8374771215529,-1.1287662247120465
0.04714432965458558,0.0035047999999999998,161.10161275613513,403.8374771215529,-1.1287662247120465
0.04727346271914961,0.0035144,161.13065152721654,403.8374771215529,-1.1287662247120465
0.04740259578371364,0.003524,161.15965937881555,403.8374771215529,-1.1287662247120465
0.04761781755798703,0.0035399999999999997,161.20793740566916,403.8374771215529,-1.1287662247120465
0.04763933973541437,0.0035415999999999998,161.21276052313303,403.8374771215529,-1.1287662247120465
0.04788684477582877,0.00356,161.26816543432244,403.8374771215529,-1.1287662247120465
0.04827424396952086,0.0035887999999999996,161.35466248403293,403.8374771215529,-1.1287662247120465
0.04848946574379426,0.0036048,161.4025994146477,403.8374771215529,-1.1287662247120465
0.048650882074499295,0.0036168,161.43849767593164,403.8374771215529,-1.1287662247120465
0.04881229840520433,0.0036287999999999997,161.4743495161853,403.8374771215529,-1.1287662247120465
0.04898447582462305,0.0036416,161.51254055306111,403.8374771215529,-1.1287662247120465
0.049371875018315144,0.0036704,161.5982794876473,403.8374771215529,-1.1287662247120465
0.04942568046188349,0.0036744,161.6101668885703,403.8374771215529,-1.1287662247120465
0.049866885099143936,0.0037072,161.70745393480328,403.8374771215529,-1.1287662247120465
0.05042646171225474,0.0037487999999999996,161.83036085852356,403.8374771215529,-1.1287662247120465
0.050717011107523816,0.0037703999999999997,161.89396805203913,403.8374771215529,-1.1287662247120465
0.050867666349515187,0.0037816,161.92689360168217,403.8374771215529,-1.1287662247120465
0.05099679941407922,0.0037911999999999998,161.95508524314306,403.8374771215529,-1.1287662247120465
0.05137343751905765,0.0038192,162.03715227777943,403.8374771215529,-1.1287662247120465
0.05166398691432672,0.0038407999999999997,162.10030090883865,403.8374771215529,-1.1287662247120465
0.05185768651117277,0.0038552,162.14232306707405,403.8374771215529,-1.1287662247120465
0.05221280243872386,0.0038816,162.21920504479772,403.8374771215529,-1.1287662247120465
0.05282618449540301,0.0039272,162.35152257965285,403.8374771215529,-1.1287662247120465
0.05322434477780878,0.0039568,162.43709231354327,403.8374771215529,-1.1287662247120465
0.055097032531779944,0.004096019203840768,162.83625530815968,403.8374771215529,-1.1287662247120465
0.05897179942207899,0.004384076815363073,163.64573777676617,403.8374771215529,-1.1287662247120465
0.06413815527581104,0.004768153630726146,164.6934712679909,403.8374771215529,-1.1287662247120465
0.06827123995879668,0.005075415083016604,165.50813037390887,403.8374771215529,-1.1287662247120465
0.07162937126372251,0.005325065013002601,166.15596228668454,403.8374771215529,-1.1287662247120465
0.07472918477596174,0.005555511102220444,166.74352172400876,403.8374771215529,-1.1287662247120465
0.07576245594670815,0.005632326465293058,166.93725224005453,403.8374771215529,-1.1287662247120465
0.08144544738581341,0.0060548109621924385,167.98489929420518,403.8374771215529,-1.1287662247120465
0.08454526089805264,0.006285257051410282,168.54430678773858,403.8374771215529,-1.1287662247120465
0.08583684986148565,0.00638127625525105,168.77502555507704,403.8374771215529,-1.1287662247120465
0.08919498116641149,0.006630926185237048,169.3686450771938,403.8374771215529,-1.1287662247120465
0.09513629039820334,0.007072614522904581,170.3979665181427,403.8374771215529,-1.1287662247120465
0.09591124377626314,0.007130226045209041,170.5303527318272,403.8374771215529,-1.1287662247120465
0.10546900210566744,0.007840768153630726,172.13024089957094,403.8374771215529,-1.1287662247120465
0.10650227327641386,0.00791758351670334,172.2997444931458,403.8374771215529,-1.1287662247120465
0.1201931162888038,0.008935387077415483,174.4883251003075,403.8374771215529,-1.1287662247120465
0.12535947214253584,0.009319463892778556,175.28863286028127,403.8374771215529,-1.1287662247120465
0.1307841457889545,0.009722744548909782,176.1152308364318,403.8374771215529,-1.1287662247120465
0.13259237033776072,0.009857171434286858,176.3877774949574,403.8374771215529,-1.1287662247120465
0.13620881943537316,0.010126025205041009,176.92856045316472,403.8374771215529,-1.1287662247120465
0.142150128667165,0.01056771354270854,177.80498738228476,403.8374771215529,-1.1287662247120465
0.14447498880134446,0.010740548109621925,178.14403332875264,403.8374771215529,-1.1287662247120465
0.14783312010627025,0.01099019803960792,178.63003371664865,403.8374771215529,-1.1287662247120465
0.15222452258194252,0.011316663332666534,179.25912478239223,403.8374771215529,-1.1287662247120465
0.16281555208209322,0.012104020804160832,180.74790839453055,403.8374771215529,-1.1287662247120465
0.1695318146919449,0.012603320664132826,181.6724669497081,403.8374771215529,-1.1287662247120465
0.17598975950910994,0.013083416683336667,182.54808442950798,403.8374771215529,-1.1287662247120465
0.17805630185060278,0.013237047409481896,182.82562344016546,403.8374771215529,-1.1287662247120465
0.1793478908140358,0.013333066613322665,182.99844752957515,403.8374771215529,-1.1287662247120465
0.1899389203141865,0.014120424084816964,184.39774574799398,403.8374771215529,-1.1287662247120465
0.19433032278985873,0.014446889377875576,184.96897728143594,403.8374771215529,-1.1287662247120465
0.19613854733866495,0.014581316263252651,185.20272436482318,403.8374771215529,-1.1287662247120465
0.2015632209850836,0.014984596919383877,185.89897432485483,403.8374771215529,-1.1287662247120465
0.2072462124241889,0.015407081416283257,186.62058530172988,403.8374771215529,-1.1287662247120465
0.21163761489986116,0.01573354670934187,187.17292054319955,403.8374771215529,-1.1287662247120465
0.21447911061941374,0.01594478895779156,187.52793358255056,403.8374771215529,-1.1287662247120465
0.218870513095086,0.016271254250850173,188.07300321516047,403.8374771215529,-1.1287662247120465
0.221453691021952,0.016463292658531706,188.39164011925848,403.8374771215529,-1.1287662247120465
0.22894490700986345,0.01702020404080816,189.3075906810413,403.8374771215529,-1.1287662247120465
0.2366944407904616,0.017596319263852772,190.24290756308793,403.8374771215529,-1.1287662247120465
0.24857705925404527,0.018479695939187836,191.65418799057866,403.8374771215529,-1.1287662247120465
0.2534850973150907,0.018844568913782757,192.22940000976942,403.8374771215529,-1.1287662247120465
0.26123463109568884,0.019420684136827366,193.1288635286293,403.8374771215529,-1.1287662247120465
0.26304285564449503,0.01955511102220444,193.33723375165658,403.8374771215529,-1.1287662247120465
0.2702757538397199,0.02009281856371274,194.16518819715105,403.8374771215529,-1.1287662247120465
0.27750865203494474,0.020630526105221043,194.9845451148431,403.8374771215529,-1.1287662247120465
0.2798335121691242,0.020803360672134428,195.2461354369169,403.8374771215529,-1.1287662247120465
0.28654977477897586,0.021302660532106422,195.99712139998408,403.8374771215529,-1.1287662247120465
0.29507426193763375,0.02193638727745549,196.9404823079504,403.8374771215529,-1.1287662247120465
0.2976574398644998,0.022128425685137027,197.22424290272107,403.8374771215529,-1.1287662247120465
0.3010155711694256,0.022378075615123026,197.59169999404025,403.8374771215529,-1.1287662247120465
0.30359874909629164,0.022570114022804563,197.8732724378173,403.8374771215529,-1.1287662247120465
0.3085067871573371,0.02293498699739948,198.40569920995182,403.8374771215529,-1.1287662247120465
0.31341482521838254,0.0232998599719944,198.93483259391968,403.8374771215529,-1.1287662247120465
0.318322863279428,0.023664732946589318,199.46074406506517,403.8374771215529,-1.1287662247120465
0.3271056682307725,0.024317663532706542,200.39402291148247,403.8374771215529,-1.1287662247120465
0.33459688421868394,0.024874574914982996,201.18235744699314,403.8374771215529,-1.1287662247120465
0.34467127813346143,0.02562352470494099,202.23176254314612,403.8374771215529,-1.1287662247120465
0.35681221438973176,0.02652610522104421,203.48066588204915,403.8374771215529,-1.1287662247120465
0.3581038033531648,0.02662212442488498,203.61254520015058,403.8374771215529,-1.1287662247120465
0.3601703456946576,0.026775755151030207,203.8231669132955,403.8374771215529,-1.1287662247120465
0.3668866083045093,0.027275055011002202,204.50445536738775,403.8374771215529,-1.1287662247120465
0.3715363285728681,0.027620724144828968,204.97326989665214,403.8374771215529,-1.1287662247120465
0.38238567586570543,0.02842728545709142,206.05836082985803,403.8374771215529,-1.1287662247120465
0.38781034951212406,0.028830566113222645,206.59639860235333,403.8374771215529,-1.1287662247120465
0.3903935274389901,0.02902260452090418,206.851574723436,403.8374771215529,-1.1287662247120465
0.3991763323903346,0.029675535107021405,207.71428997248486,403.8374771215529,-1.1287662247120465
0.3999512857683944,0.029733146629325864,207.79005469171338,403.8374771215529,-1.1287662247120465
0.40201782810988723,0.029886777355471093,207.99181456112856,403.8374771215529,-1.1287662247120465
0.40356773486600683,0.030002000400080015,208.14286912934128,403.8374771215529,-1.1287662247120465
0.4095090440977987,0.03044368873774755,208.71982772083854,403.8374771215529,-1.1287662247120465
0.4110589508539183,0.030558911782356472,208.8698005995504,403.8374771215529,-1.1287662247120465
0.41415876436615756,0.030789357871574316,209.16908638418508,403.8374771215529,-1.1287662247120465
0.41725857787839676,0.03101980396079216,209.46749981925598,403.8374771215529,-1.1287662247120465
0.4206167091833226,0.031269453890778155,209.7898070473822,403.8374771215529,-1.1287662247120465
0.42242493373212886,0.03140388077615523,209.96294134962778,403.8374771215529,-1.1287662247120465
0.42965783192735374,0.031941588317663534,210.6526076182169,403.8374771215529,-1.1287662247120465
0.4355991411591456,0.03238327665533107,211.2157382028061,403.8374771215529,-1.1287662247120465
0.4415404503909374,0.0328249649929986,211.77588113311757,403.8374771215529,-1.1287662247120465
0.4591060602936264,0.034130826165233046,213.41501210664987,403.8374771215529,-1.1287662247120465
0.4681471830376575,0.034802960592118425,214.2491357573867,403.8374771215529,-1.1287662247120465
0.4751217634401957,0.03532146429285857,214.88831707283757,403.8374771215529,-1.1287662247120465
0.4787382125378082,0.03559031806361272,215.21830315026142,403.8374771215529,-1.1287662247120465
0.479513165915868,0.035647929585917185,215.28888780831045,403.8374771215529,-1.1287662247120465
0.483387932806167,0.035935987197439484,215.64114596617048,403.8374771215529,-1.1287662247120465
0.49372064451363107,0.03670414082816563,216.57515848800372,403.8374771215529,-1.1287662247120465
0.5030200850503489,0.03739547909581917,217.40927146454916,403.8374771215529,-1.1287662247120465
0.510769618830947,0.03797159431886378,218.09978134479243,403.8374771215529,-1.1287662247120465
0.5136111145504995,0.03818283656731346,218.351943008782,403.8374771215529,-1.1287662247120465
0.515935974684679,0.038355671134226846,218.5578526618587,403.8374771215529,-1.1287662247120465
0.5213606483310976,0.03875895179035807,219.03690639974104,403.8374771215529,-1.1287662247120465
0.527560275355576,0.03921984396879376,219.58202244027396,403.8374771215529,-1.1287662247120465
0.5327266312093082,0.03960392078415684,220.03437996937686,403.8374771215529,-1.1287662247120465
0.5371180336849803,0.03993038607721544,220.41754028372722,403.8374771215529,-1.1287662247120465
0.5386679404411,0.040045609121824366,220.55248138829026,403.8374771215529,-1.1287662247120465
0.5466757920143847,0.040640928185637124,221.24727945785233,403.8374771215529,-1.1287662247120465
0.547192427599758,0.04067933586717344,221.29196835877505,403.8374771215529,-1.1287662247120465
0.5510671944900569,0.04096739347869574,221.6266121810944,403.8374771215529,-1.1287662247120465
0.5536503724169229,0.04115943188637727,221.84919838576408,403.8374771215529,-1.1287662247120465
0.5629498129536407,0.04185077015403081,222.64717679785988,403.8374771215529,-1.1287662247120465
0.5694077577708057,0.042330866173234644,223.19830635998815,403.8374771215529,-1.1287662247120465
0.5794821516855833,0.043079815963192644,224.05322554601884,403.8374771215529,-1.1287662247120465
0.5838735541612554,0.04340628125625125,224.4240664382298,403.8374771215529,-1.1287662247120465
0.5864567320881214,0.04359831966393278,224.6417000248101,403.8374771215529,-1.1287662247120465
0.5934313124906597,0.04411682336467293,225.22745130209523,403.8374771215529,-1.1287662247120465
0.6040223419908105,0.044904180836167235,226.11181732595207,403.8374771215529,-1.1287662247120465
0.6084137444664828,0.04523064612922585,226.476729627672,403.8374771215529,-1.1287662247120465
0.6128051469421549,0.045557111422284455,226.840616157665,403.8374771215529,-1.1287662247120465
0.6156466426617075,0.045768353670734147,227.07553034736318,403.8374771215529,-1.1287662247120465
0.6190047739666333,0.04601800360072014,227.35261174129744,403.8374771215529,-1.1287662247120465
0.6202963629300664,0.04611402280456091,227.4590253319147,403.8374771215529,-1.1287662247120465
0.6215879518934994,0.046210042008401675,227.56535254300036,403.8374771215529,-1.1287662247120465
0.624429447613052,0.04642128425685137,227.7989695785858,403.8374771215529,-1.1287662247120465
0.6288208500887243,0.046747749549909984,228.159200240412,403.8374771215529,-1.1287662247120465
0.6334705703570831,0.047093418683736746,228.53955320261562,403.8374771215529,-1.1287662247120465
0.6378619728327555,0.04741988397679536,228.89777692036466,403.8374771215529,-1.1287662247120465
0.6456115066133535,0.047995999199839975,229.52759890456483,403.8374771215529,-1.1287662247120465
0.6487113201255927,0.04822644528905781,229.77870131070185,403.8374771215529,-1.1287662247120465
0.65956066741843,0.04903300660132026,230.653898216675,403.8374771215529,-1.1287662247120465
0.6652436588575352,0.049455491098219645,231.11009292825366,403.8374771215529,-1.1287662247120465
0.6678268367844012,0.04964752950590118,231.3169514673237,403.8374771215529,-1.1287662247120465
0.683584222138284,0.05081896379275855,232.5720969819612,403.8374771215529,-1.1287662247120465
0.6884922601993295,0.05118383676735347,232.96073258082592,403.8374771215529,-1.1287662247120465
0.6910754381261954,0.051375875175035,233.16484356752773,403.8374771215529,-1.1287662247120465
0.7060578701020186,0.05248969793958792,234.3428719854411,403.8374771215529,-1.1287662247120465
0.710965908163064,0.052854570914182844,234.7266525780547,403.8374771215529,-1.1287662247120465
0.720007030907095,0.05352670534106821,235.43092288422878,403.8374771215529,-1.1287662247120465
0.7254317045535136,0.053929985997199434,235.85182973062447,403.8374771215529,-1.1287662247120465
0.7357644162609777,0.05469813962792558,236.65017665332059,403.8374771215529,-1.1287662247120465
0.7396391831512769,0.05498619723944789,236.9484279385888,403.8374771215529,-1.1287662247120465
0.7442889034196356,0.055331866373274655,237.30552633355992,403.8374771215529,-1.1287662247120465
0.7463554457611284,0.055485497099419884,237.4639573501094,403.8374771215529,-1.1287662247120465
0.7502302126514274,0.05577355471094218,237.76055515156423,403.8374771215529,-1.1287662247120465
0.7546216151270998,0.0561000200040008,238.0959780582735,403.8374771215529,-1.1287662247120465
0.7569464752612792,0.05627285457091419,238.27324665816562,403.8374771215529,-1.1287662247120465
0.7621128311150112,0.056656931386277254,238.66641842686008,403.8374771215529,-1.1287662247120465
0.7652126446272506,0.056887377475495104,238.90182257235395,403.8374771215529,-1.1287662247120465
0.76676255138337,0.057002600520104016,239.01938515971798,403.8374771215529,-1.1287662247120465
0.7685707759321764,0.0571370274054811,239.1564244407862,403.8374771215529,-1.1287662247120465
0.7711539538590423,0.05732906581316263,239.35197692098652,403.8374771215529,-1.1287662247120465
0.7801950766030734,0.05800120024004801,240.03440782557092,403.8374771215529,-1.1287662247120465
0.7845864790787456,0.058327665533106615,240.36476086088337,403.8374771215529,-1.1287662247120465
0.7863947036275519,0.0584620924184837,240.50057889181727,403.8374771215529,-1.1287662247120465
0.7879446103836716,0.058577315463092625,240.61689743567396,403.8374771215529,-1.1287662247120465
0.7923360128593437,0.05890378075615123,240.9459830529239,403.8374771215529,-1.1287662247120465
0.798019004298449,0.05932626525305061,241.37080457501105,403.8374771215529,-1.1287662247120465
0.8026687245668078,0.05967193438687737,241.71750891440402,403.8374771215529,-1.1287662247120465
0.8047352669083007,0.0598255651130226,241.87134821845788,403.8374771215529,-1.1287662247120465
0.8065434914571069,0.059959991998399687,242.0058312668119,403.8374771215529,-1.1287662247120465
0.8119681651035257,0.06036327265453091,242.40857666095872,403.8374771215529,-1.1287662247120465
0.8173928387499443,0.060766553310662136,242.81027403891025,403.8374771215529,-1.1287662247120465
0.822042559018303,0.0611122224444889,243.15375926490853,403.8374771215529,-1.1287662247120465
0.8285005038354681,0.061592318463692744,243.62956772022318,403.8374771215529,-1.1287662247120465
0.8318586351403939,0.06184196839367874,243.8764163606857,403.8374771215529,-1.1287662247120465
0.8414163934697982,0.06255251050210042,244.57686737243446,403.8374771215529,-1.1287662247120465
0.844774524774724,0.06280216043208642,244.82223422852775,403.8374771215529,-1.1287662247120465
0.8483909738723365,0.06307101420284057,245.08605043181922,403.8374771215529,-1.1287662247120465
0.8512324695918893,0.06328225645129026,245.2930270363733,403.8374771215529,-1.1287662247120465
0.8551072364821882,0.06357031406281256,245.5748341416446,403.8374771215529,-1.1287662247120465
0.8569154610309944,0.06370474094818963,245.7061736520287,403.8374771215529,-1.1287662247120465
0.865698265982339,0.06435767153430687,246.3425773226399,403.8374771215529,-1.1287662247120465
0.8677648083238317,0.0645113022604521,246.4919528226424,403.8374771215529,-1.1287662247120465
0.8711229396287576,0.06476095219043809,246.73439245478428,403.8374771215529,-1.1287662247120465
0.8734477997629368,0.06493378675735147,246.90202180154117,403.8374771215529,-1.1287662247120465
0.8747393887263699,0.06502980596119223,246.99507402459474,403.8374771215529,-1.1287662247120465
0.877322566653236,0.06522184436887378,247.18101787396566,403.8374771215529,-1.1287662247120465
0.8835221936777146,0.06568273654730947,247.6264140994897,403.8374771215529,-1.1287662247120465
0.8863636893972672,0.06589397879575916,247.83014652426786,403.8374771215529,-1.1287662247120465
0.8938549053851786,0.06645089017803561,248.3660420290429,403.8374771215529,-1.1287662247120465
0.8969547188974177,0.06668133626725345,248.58727920755098,403.8374771215529,-1.1287662247120465
0.9008294857877169,0.06696939387877576,248.86340680490352,403.8374771215529,-1.1287662247120465
0.9028960281292098,0.06712302460492099,249.01048543794136,403.8374771215529,-1.1287662247120465
0.9054792060560757,0.06731506301260252,249.1941492383301,403.8374771215529,-1.1287662247120465
0.9101289263244345,0.06766073214642929,249.5242299577273,403.8374771215529,-1.1287662247120465
0.9129704220439872,0.06787197439487898,249.72562221550996,403.8374771215529,-1.1287662247120465
0.91503696438548,0.06802560512102421,249.8719358031211,403.8374771215529,-1.1287662247120465
0.9220115447880183,0.06854410882176436,250.3647955021247,403.8374771215529,-1.1287662247120465
0.9274362184344369,0.06894738947789558,250.74712626775477,403.8374771215529,-1.1287662247120465
0.9362190233857813,0.0696003200640128,251.36429403401849,403.8374771215529,-1.1287662247120465
0.9367356589711547,0.06963872774554912,251.4005275421777,403.8374771215529,-1.1287662247120465
0.9416436970322,0.07000360072014403,251.74435804355164,403.8374771215529,-1.1287662247120465
0.9437102393736928,0.07015723144628926,251.88891960399314,403.8374771215529,-1.1287662247120465
0.9524930443250375,0.07081016203240649,252.50193399678255,403.8374771215529,-1.1287662247120465
0.9543012688738436,0.07094458891778356,252.62786875010477,403.8374771215529,-1.1287662247120465
0.9623091204471282,0.07153990798159632,253.18446490686685,403.8374771215529,-1.1287662247120465
0.9685087474716066,0.072000800160032,253.6141383944196,403.8374771215529,-1.1287662247120465
0.9811663193132503,0.07294178835767154,254.48807208589776,403.8374771215529,-1.1287662247120465
0.9927906199841474,0.07380596119223845,255.286798786503,403.8374771215529,-1.1287662247120465
1.0013151071428052,0.07443968793758753,255.87021552849214,403.8374771215529,-1.1287662247120465
1.0026066961062383,0.07453570714142829,255.95844273759374,403.8374771215529,-1.1287662247120465
1.0062231452038508,0.07480456091218245,256.2052434193913,403.8374771215529,-1.1287662247120465
1.00854800533803,0.07497739547909582,256.3637183428695,403.8374771215529,-1.1287662247120465
1.0173308102893746,0.07563032606521304,256.96112000304424,403.8374771215529,-1.1287662247120465
1.0183640814601211,0.07570714142828566,257.0312700675662,403.8374771215529,-1.1287662247120465
1.021722212765047,0.07595679135827166,257.2590663068543,403.8374771215529,-1.1287662247120465
1.0227554839357933,0.07603360672134428,257.3290986884211,403.8374771215529,-1.1287662247120465
1.0248220262772862,0.07618723744748951,257.46908072618976,403.8374771215529,-1.1287662247120465
1.0274052042041522,0.07637927585517104,257.6439035615425,403.8374771215529,-1.1287662247120465
1.0310216533017647,0.0766481296259252,257.88836781090487,403.8374771215529,-1.1287662247120465
1.0416126828019152,0.07743548709741949,258.6023823480857,403.8374771215529,-1.1287662247120465
1.0478123098263938,0.07789637927585517,259.0190282957395,403.8374771215529,-1.1287662247120465
1.053495301265499,0.07831886377275456,259.40010994138237,403.8374771215529,-1.1287662247120465
1.0550452080216186,0.07843408681736348,259.5039020494296,403.8374771215529,-1.1287662247120465
1.0565951147777382,0.0785493098619724,259.6076347092063,403.8374771215529,-1.1287662247120465
1.070285957790128,0.07956711342268454,260.52137687457514,403.8374771215529,-1.1287662247120465
1.0744190424731137,0.079874374874975,260.7963262892941,403.8374771215529,-1.1287662247120465
1.078810444948786,0.08020084016803361,261.0880084588003,403.8374771215529,-1.1287662247120465
1.0816519406683387,0.0804120824164833,261.2764972622886,403.8374771215529,-1.1287662247120465
1.0865599787293843,0.08077695539107822,261.601614614628,403.8374771215529,-1.1287662247120465
1.088626521070877,0.08093058611722345,261.7383347277306,403.8374771215529,-1.1287662247120465
1.0919846523758028,0.08118023604720945,261.96028922833904,403.8374771215529,-1.1287662247120465
1.1061921309735658,0.08223644728945789,262.89639716947556,403.8374771215529,-1.1287662247120465
1.107483719936999,0.08233246649329866,262.9812647005894,403.8374771215529,-1.1287662247120465
1.1116168046199846,0.08263972794558912,263.252581771184,403.8374771215529,-1.1287662247120465
1.1216911985347622,0.08338867773554712,263.9122741457504,403.8374771215529,-1.1287662247120465
1.1265992365958075,0.08375355071014204,264.2328253170741,403.8374771215529,-1.1287662247120465
1.13021568569342,0.08402240448089618,264.46867252500505,403.8374771215529,-1.1287662247120465
1.141839986364317,0.08488657731546309,265.22476717372865,403.8374771215529,-1.1287662247120465
1.1439065287058099,0.08504020804160832,265.35886912416333,403.8374771215529,-1.1287662247120465
1.151656062486408,0.08561632326465293,265.8609121738049,403.8374771215529,-1.1287662247120465
1.159405596267006,0.08619243848769755,266.3616394154689,403.8374771215529,-1.1287662247120465
1.1627637275719318,0.08644208841768354,266.5782156711097,403.8374771215529,-1.1287662247120465
1.1674134478402907,0.0867877575515103,266.8776882030712,403.8374771215529,-1.1287662247120465
1.173096439279396,0.08721024204840969,267.2430792032417,403.8374771215529,-1.1287662247120465
1.1785211129258146,0.08761352270454091,267.59121807256173,403.8374771215529,-1.1287662247120465
1.180845973059994,0.0877863572714543,267.7402290684758,403.8374771215529,-1.1287662247120465
1.1818792442307404,0.0878631726345269,267.8064194471418,403.8374771215529,-1.1287662247120465
1.1873039178771592,0.08826645329065813,268.1535493710438,403.8374771215529,-1.1287662247120465
1.1914370025601446,0.08857371474294859,268.4176143066414,403.8374771215529,-1.1287662247120465
1.204352892194475,0.08953390678135628,269.2405239691637,403.8374771215529,-1.1287662247120465
1.2164938284507452,0.0904364872974595,270.01092636037447,403.8374771215529,-1.1287662247120465
1.2177854174141782,0.09053250650130026,270.09270720319927,403.8374771215529,-1.1287662247120465
1.219335324170298,0.09064772954590919,270.1907995759132,403.8374771215529,-1.1287662247120465
1.22372672664597,0.09097419483896779,270.468464240542,403.8374771215529,-1.1287662247120465
1.2268265401582095,0.09120464092818564,270.66422890878073,403.8374771215529,-1.1287662247120465
1.2356093451095538,0.09185757151430286,271.21785062099707,403.8374771215529,-1.1287662247120465
1.248525234743884,0.09281776355271054,272.02922032871226,403.8374771215529,-1.1287662247120465
1.2573080396952285,0.09347069413882778,272.57908279200063,403.8374771215529,-1.1287662247120465
1.2604078532074676,0.09370114022804561,272.772793980381,403.8374771215529,-1.1287662247120465
1.2671241158173192,0.0942004400880176,273.19186530991016,403.8374771215529,-1.1287662247120465
1.2689323403661257,0.09433486697339469,273.30454408143277,403.8374771215529,-1.1287662247120465
1.2748736495979174,0.09477655531106222,273.6743342128064,403.8374771215529,-1.1287662247120465
1.2792650520735898,0.09510302060412083,273.94722552666707,403.8374771215529,-1.1287662247120465
1.2867562680615012,0.09565993198639729,274.411904319012,403.8374771215529,-1.1287662247120465
1.2960557085982187,0.09635127025405081,274.9872817753844,403.8374771215529,-1.1287662247120465
1.299930475488518,0.09663932786557312,275.2265469223049,403.8374771215529,-1.1287662247120465
1.3084549626471758,0.09727305461092219,275.75195336155355,403.8374771215529,-1.1287662247120465
1.316204496427774,0.0978491698339668,276.22843828371805,403.8374771215529,-1.1287662247120465
1.3174960853912068,0.09794518903780756,276.3077459442817,403.8374771215529,-1.1287662247120465
1.3195626277326997,0.0980988197639528,276.43457516108685,403.8374771215529,-1.1287662247120465
1.3249873013791182,0.09850210042008402,276.76713384318566,403.8374771215529,-1.1287662247120465
1.3275704793059844,0.09869413882776555,276.9253084508187,403.8374771215529,-1.1287662247120465
1.3317035639889698,0.09900140028005601,277.17813838512944,403.8374771215529,-1.1287662247120465
1.3329951529524031,0.09909741948389679,277.2570849560185,403.8374771215529,-1.1287662247120465
1.3360949664646422,0.09932786557311463,277.4464351077891,403.8374771215529,-1.1287662247120465
1.3404863689403146,0.09965433086617324,277.71438813917405,403.8374771215529,-1.1287662247120465
1.3410030045256878,0.09969273854770955,277.7458895023078,403.8374771215529,-1.1287662247120465