File: datasets/aisi_316_L/data/M1/valid_8.csv
Time(s),Strain(%),Stress(MPa),Temp(C),Log_SR(s-1)
0.0,0.0,0.0,431.51994844196565,4.934266373502794
2.3268244687257667e-10,1.9999999999999998e-05,3.3323809374999995,431.51994844196565,4.934266373502794
3.6298461712121964e-10,3.12e-05,5.1985142625,431.51994844196565,4.934266373502794
5.398232767443778e-10,4.6399999999999996e-05,7.7311237749999995,431.51994844196565,4.934266373502794
6.9804734061773e-10,5.9999999999999995e-05,9.9971428125,431.51994844196565,4.934266373502794
8.935005959906944e-10,7.68e-05,12.7963428,431.51994844196565,4.934266373502794
1.1354903407381742e-09,9.76e-05,16.262018975,431.51994844196565,4.934266373502794
1.1727195322377864e-09,0.0001008,16.795199925,431.51994844196565,4.934266373502794
1.2378706173621079e-09,0.0001064,17.7282665875,431.51994844196565,4.934266373502794
1.4519384684848786e-09,0.0001248,20.79405705,431.51994844196565,4.934266373502794
1.8893814686053227e-09,0.0001624,27.058933212499998,431.51994844196565,4.934266373502794
1.9824544473543535e-09,0.0001704,28.3918855875,431.51994844196565,4.934266373502794
2.1406785112277055e-09,0.000184,30.657904625,431.51994844196565,4.934266373502794
2.3919755538500882e-09,0.00020559999999999998,34.2568760375,431.51994844196565,4.934266373502794
2.4292047453497003e-09,0.00020879999999999998,34.790056987499995,431.51994844196565,4.934266373502794
2.4664339368493128e-09,0.000212,35.323237937500004,431.51994844196565,4.934266373502794
2.5967361070979556e-09,0.00022319999999999998,37.189371262499996,431.51994844196565,4.934266373502794
2.8201112560956293e-09,0.00024239999999999998,40.388456962499994,431.51994844196565,4.934266373502794
3.0434864050933025e-09,0.00026159999999999996,43.58754266249999,431.51994844196565,4.934266373502794
3.257554256216073e-09,0.00028,46.653333124999996,431.51994844196565,4.934266373502794
3.536773192463165e-09,0.00030399999999999996,50.65219025,431.51994844196565,4.934266373502794
3.592616979712584e-09,0.00030879999999999997,51.45196167499999,431.51994844196565,4.934266373502794
3.927679703209094e-09,0.00033759999999999997,56.250590224999996,431.51994844196565,4.934266373502794
4.132440256456962e-09,0.00035519999999999996,59.18308544999999,431.51994844196565,4.934266373502794
4.420966490578957e-09,0.00037999999999999997,63.315237812499994,431.51994844196565,4.934266373502794
4.765336511950371e-09,0.0004096,68.2471616,431.51994844196565,4.934266373502794
4.970097065198238e-09,0.0004272,71.179656825,431.51994844196565,4.934266373502794
5.1003992354468805e-09,0.0004384,73.04579015,431.51994844196565,4.934266373502794
5.240008703570427e-09,0.0004504,75.0452187125,431.51994844196565,4.934266373502794
5.454076554693197e-09,0.00046879999999999996,78.11100917499999,431.51994844196565,4.934266373502794
5.70537359731558e-09,0.0004904,81.7099805875,431.51994844196565,4.934266373502794
6.003207129312478e-09,0.000516,85.9754281875,431.51994844196565,4.934266373502794
6.059050916561897e-09,0.0005208,86.77519961249999,431.51994844196565,4.934266373502794
6.291733363434474e-09,0.0005408,90.10758055000001,431.51994844196565,4.934266373502794
6.8408639380537545e-09,0.000588,97.9719995625,431.51994844196565,4.934266373502794
6.9618588104274944e-09,0.0005984,99.70483765,431.51994844196565,4.934266373502794
7.585447768046e-09,0.000652,108.6356185625,431.51994844196565,4.934266373502794
7.706442640419739e-09,0.0006624,110.36845664999998,431.51994844196565,4.934266373502794
8.181114832039796e-09,0.0007032,117.16651376249999,431.51994844196565,4.934266373502794
8.302109704413535e-09,0.0007136,118.89935185,431.51994844196565,4.934266373502794
8.609250534285338e-09,0.00074,123.2980946875,431.51994844196565,4.934266373502794
8.693016215159465e-09,0.0007472,124.497751825,431.51994844196565,4.934266373502794
8.804703789658302e-09,0.0007568,126.097294675,431.51994844196565,4.934266373502794
8.879162172657527e-09,0.0007632,127.163656575,431.51994844196565,4.934266373502794
8.944313257781848e-09,0.0007687999999999999,128.0967232375,431.51994844196565,4.934266373502794
9.028078938655975e-09,0.000776,129.296380375,431.51994844196565,4.934266373502794
9.409678151527e-09,0.0008087999999999999,134.7614851125,431.51994844196565,4.934266373502794
9.754048172898415e-09,0.0008384,139.6934089,431.51994844196565,4.934266373502794
1.025664225814318e-08,0.0008816,146.891351725,431.51994844196565,4.934266373502794
1.0489324705015757e-08,0.0009015999999999999,150.2237326625,431.51994844196565,4.934266373502794
1.068477796038872e-08,0.0009184,153.02293265,431.51994844196565,4.934266373502794
1.1057069875384844e-08,0.0009504,158.35474215,431.51994844196565,4.934266373502794
1.1122220960509165e-08,0.0009559999999999999,159.28780881249997,431.51994844196565,4.934266373502794
1.1271137726507613e-08,0.0009687999999999999,161.42053261249998,431.51994844196565,4.934266373502794
1.1550356662754708e-08,0.0009928,165.4193897375,431.51994844196565,4.934266373502794
1.1643429641503738e-08,0.0010008,166.7523421125,431.51994844196565,4.934266373502794
1.1801653705377088e-08,0.0010144,166.8506763515343,431.51994844196565,4.934266373502794
1.1838882896876702e-08,0.0010176,166.86792124174528,431.51994844196565,4.934266373502794
1.1876112088376313e-08,0.0010207999999999999,166.8851449954846,431.51994844196565,4.934266373502794
1.2164638322498309e-08,0.0010456,167.0179224450014,431.51994844196565,4.934266373502794
1.2499701045994819e-08,0.0010743999999999999,167.17058388215096,431.51994844196565,4.934266373502794
1.2983680535489779e-08,0.001116,167.38830670183754,431.51994844196565,4.934266373502794
1.3095368109988617e-08,0.0011256,167.43809816508428,431.51994844196565,4.934266373502794
1.3355972450485902e-08,0.001148,167.55363858620967,431.51994844196565,4.934266373502794
1.3495581918609447e-08,0.00116,167.6151734077759,431.51994844196565,4.934266373502794
1.383995193998086e-08,0.0011895999999999999,167.7659072978344,431.51994844196565,4.934266373502794
1.3914410322980086e-08,0.001196,167.79830526677875,431.51994844196565,4.934266373502794
1.4100556280478146e-08,0.001212,167.87900577865216,431.51994844196565,4.934266373502794
1.4221551152851887e-08,0.0012224,167.93123839756578,431.51994844196565,4.934266373502794
1.4268087642226401e-08,0.0012263999999999999,167.9512816827168,431.51994844196565,4.934266373502794
1.4370467918850335e-08,0.0012351999999999999,167.99528738514917,431.51994844196565,4.934266373502794
1.4528691982723688e-08,0.0012488,168.06305646149298,431.51994844196565,4.934266373502794
1.4798603621095877e-08,0.001272,168.17800195230046,431.51994844196565,4.934266373502794
1.54687290680889e-08,0.0013296,168.4599041874723,431.51994844196565,4.934266373502794
1.5729333408586183e-08,0.001352,168.56824141070237,431.51994844196565,4.934266373502794
1.593409396183405e-08,0.0013696,168.65287318302643,431.51994844196565,4.934266373502794
1.6036474238457984e-08,0.0013784,168.69502993600685,431.51994844196565,4.934266373502794
1.632500047257998e-08,0.0014031999999999998,168.81327430778836,431.51994844196565,4.934266373502794
1.6511146430078042e-08,0.0014192,168.8891286779234,431.51994844196565,4.934266373502794
1.6771750770575326e-08,0.0014416,168.9947668560821,431.51994844196565,4.934266373502794
1.7041662408947513e-08,0.0014647999999999998,169.10350514321806,431.51994844196565,4.934266373502794
1.7134735387696548e-08,0.0014728,169.14084509418825,431.51994844196565,4.934266373502794
1.7581485685691894e-08,0.0015111999999999999,169.31898728374514,431.51994844196565,4.934266373502794
1.7646636770816217e-08,0.0015168,169.34481809072415,431.51994844196565,4.934266373502794
1.772109515381544e-08,0.0015232,169.3742935141659,431.51994844196565,4.934266373502794
1.8018928685812337e-08,0.0015488,169.49171539172744,431.51994844196565,4.934266373502794
1.8195767345435496e-08,0.0015639999999999999,169.56107652034441,431.51994844196565,4.934266373502794
1.8372606005058655e-08,0.0015792,169.63017524344372,431.51994844196565,4.934266373502794
1.8530830068932006e-08,0.0015928,169.6917808577562,431.51994844196565,4.934266373502794
1.8577366558306523e-08,0.0015968,169.70986107018376,431.51994844196565,4.934266373502794
1.8679746834930455e-08,0.0016056,169.74957547843917,431.51994844196565,4.934266373502794
1.8810049005179097e-08,0.0016167999999999998,169.79999852871325,431.51994844196565,4.934266373502794
1.8856585494553614e-08,0.0016208,169.81797372366023,431.51994844196565,4.934266373502794
1.9042731452051674e-08,0.0016367999999999999,169.88970216716922,431.51994844196565,4.934266373502794
1.9266106601049348e-08,0.001656,169.97541634774802,431.51994844196565,4.934266373502794
1.929402849467406e-08,0.0016584,169.98610330189288,431.51994844196565,4.934266373502794
1.933125768617367e-08,0.0016615999999999998,170.00034319616228,431.51994844196565,4.934266373502794
1.960116932454586e-08,0.0016848,170.103264460185,431.51994844196565,4.934266373502794
1.966632040967018e-08,0.0016903999999999999,170.12802453358327,431.51994844196565,4.934266373502794
1.9750086090544307e-08,0.0016975999999999998,170.15981195866104,431.51994844196565,4.934266373502794
1.9889695558667853e-08,0.0017096,170.21267440542383,431.51994844196565,4.934266373502794
2.0075841516165916e-08,0.0017255999999999999,170.28293311127,431.51994844196565,4.934266373502794
2.0168914494914945e-08,0.0017335999999999999,170.31796715657387,431.51994844196565,4.934266373502794
2.0476055324786745e-08,0.0017599999999999998,170.43313473370776,431.51994844196565,4.934266373502794
2.051328451628636e-08,0.0017632,170.44704851163027,431.51994844196565,4.934266373502794
2.067150858015971e-08,0.0017767999999999998,170.50607253609473,431.51994844196565,4.934266373502794
2.0839039941907968e-08,0.0017912,170.56837683938903,431.51994844196565,4.934266373502794
2.0922805622782095e-08,0.0017984,170.59945571475353,431.51994844196565,4.934266373502794
2.1025185899406027e-08,0.0018072,170.63737518539074,431.51994844196565,4.934266373502794
2.1136873473904864e-08,0.0018168,170.6786598458593,431.51994844196565,4.934266373502794
2.1285790239903314e-08,0.0018296,170.73357395918998,431.51994844196565,4.934266373502794
2.1444014303776665e-08,0.0018432,170.79175628927143,431.51994844196565,4.934266373502794
2.15463945804006e-08,0.001852,170.82931448294022,431.51994844196565,4.934266373502794
2.1713925942148855e-08,0.0018663999999999998,170.89062356328876,431.51994844196565,4.934266373502794
2.1983837580521046e-08,0.0018896,170.98901269024526,431.51994844196565,4.934266373502794
2.2300285708267748e-08,0.0019168,171.1037674966555,431.51994844196565,4.934266373502794
2.236543679339207e-08,0.0019223999999999999,171.12731445554968,431.51994844196565,4.934266373502794
2.2877338176511742e-08,0.0019664,171.31140446304678,431.51994844196565,4.934266373502794
2.3044869538259994e-08,0.0019808,171.37130226083647,431.51994844196565,4.934266373502794
2.321240090000825e-08,0.0019952,171.43103047403935,431.51994844196565,4.934266373502794
2.348231253838044e-08,0.0020184,171.5269068487773,431.51994844196565,4.934266373502794
2.364053660225379e-08,0.002032,171.58291042578117,431.51994844196565,4.934266373502794
2.3994213921500105e-08,0.0020624,171.70756899691546,431.51994844196565,4.934266373502794
2.4217589070497778e-08,0.0020816,171.7859316213299,431.51994844196565,4.934266373502794
2.425481826199739e-08,0.0020848,171.79896460432587,431.51994844196565,4.934266373502794
2.479464153874177e-08,0.0021311999999999998,171.98707469867156,431.51994844196565,4.934266373502794
2.48877145174908e-08,0.0021392,172.0193453692647,431.51994844196565,4.934266373502794
2.5139011560113187e-08,0.0021608,172.10624194165328,431.51994844196565,4.934266373502794
2.525069913461202e-08,0.0021704,172.14475383013834,431.51994844196565,4.934266373502794
2.542753779423518e-08,0.0021855999999999998,172.20559539820385,431.51994844196565,4.934266373502794
2.559506915598343e-08,0.0021999999999999997,172.26308273645125,431.51994844196565,4.934266373502794
2.5809137007106203e-08,0.0022183999999999997,172.3363256723283,431.51994844196565,4.934266373502794
2.6023204858228972e-08,0.0022367999999999997,172.4093320641554,431.51994844196565,4.934266373502794
2.652579894347374e-08,0.00228,172.57982402401896,431.51994844196565,4.934266373502794
2.6739866794596513e-08,0.0022984,172.65205786412534,431.51994844196565,4.934266373502794
2.682363247547064e-08,0.0023056,172.68026184568978,431.51994844196565,4.934266373502794
2.698185653934399e-08,0.0023192,172.73344249031203,431.51994844196565,4.934266373502794
2.7056314922343214e-08,0.0023255999999999997,172.75842657905545,431.51994844196565,4.934266373502794
2.7279690071340887e-08,0.0023447999999999997,172.83321845116242,431.51994844196565,4.934266373502794
2.7437914135214245e-08,0.0023584,172.88605158775863,431.51994844196565,4.934266373502794
2.752167981608837e-08,0.0023656,172.91397396134752,431.51994844196565,4.934266373502794
2.7549601709713078e-08,0.002368,172.92327405126267,431.51994844196565,4.934266373502794
2.763336739058721e-08,0.0023752,172.95115228974117,431.51994844196565,4.934266373502794
2.794981551833391e-08,0.0024024,173.05617396988856,431.51994844196565,4.934266373502794
2.8629248263201834e-08,0.0024608,173.2801076810437,431.51994844196565,4.934266373502794
2.885262341219951e-08,0.00248,173.35327573205745,431.51994844196565,4.934266373502794
2.9159764242071308e-08,0.0025063999999999998,173.45352210193826,431.51994844196565,4.934266373502794
2.9485519667692917e-08,0.0025344,173.55939506129386,431.51994844196565,4.934266373502794
2.988573347631375e-08,0.0025688,173.68884511005862,431.51994844196565,4.934266373502794
3.002534294443729e-08,0.0025808,173.73384281858236,431.51994844196565,4.934266373502794
3.022079619981026e-08,0.0025976,173.79670276632226,431.51994844196565,4.934266373502794
3.037902026368361e-08,0.0026111999999999997,173.84747334135784,431.51994844196565,4.934266373502794
3.051862973180716e-08,0.0026232,173.89218532739625,431.51994844196565,4.934266373502794
3.057447351905657e-08,0.0026279999999999997,173.9100477777432,431.51994844196565,4.934266373502794
3.077923407230444e-08,0.0026455999999999997,173.97543485195618,431.51994844196565,4.934266373502794
3.0844385157428764e-08,0.0026512,173.99620422463465,431.51994844196565,4.934266373502794
3.09746873276774e-08,0.0026623999999999997,174.03769171311694,431.51994844196565,4.934266373502794
3.134697924267353e-08,0.0026944,174.15585399321435,431.51994844196565,4.934266373502794
3.140282302992295e-08,0.0026991999999999997,174.17353101773287,431.51994844196565,4.934266373502794
3.1477281412922174e-08,0.0027056,174.19708132493685,431.51994844196565,4.934266373502794
3.166342737042023e-08,0.0027216,174.25586224154603,431.51994844196565,4.934266373502794
3.220325064716461e-08,0.002768,174.42556953732563,431.51994844196565,4.934266373502794
3.225909443441403e-08,0.0027727999999999997,174.44306190528954,431.51994844196565,4.934266373502794
3.244524039191209e-08,0.0027887999999999997,174.50128469456354,431.51994844196565,4.934266373502794
3.328289720065337e-08,0.0028607999999999997,174.7616916435585,431.51994844196565,4.934266373502794
3.352488694540085e-08,0.0028816,174.83644281627227,431.51994844196565,4.934266373502794
3.359934532840007e-08,0.002888,174.85940080296768,431.51994844196565,4.934266373502794
3.362726722202478e-08,0.0028904,174.86800493143812,431.51994844196565,4.934266373502794
3.375756939227342e-08,0.0029016,174.90812074795136,431.51994844196565,4.934266373502794
3.378549128589813e-08,0.002904,174.91670913242353,431.51994844196565,4.934266373502794
3.389717886039697e-08,0.0029135999999999997,174.95103502493092,431.51994844196565,4.934266373502794
3.393440805189658e-08,0.0029167999999999998,174.96246718339876,431.51994844196565,4.934266373502794
3.433462186051741e-08,0.0029511999999999997,175.0850555483631,431.51994844196565,4.934266373502794
3.435323645626722e-08,0.0029527999999999998,175.09074373073463,431.51994844196565,4.934266373502794
3.457661160526489e-08,0.002972,175.15890842676814,431.51994844196565,4.934266373502794
3.465106998826412e-08,0.0029784,175.18159179897793,431.51994844196565,4.934266373502794
3.512574217988417e-08,0.0030191999999999997,175.32575398440434,431.51994844196565,4.934266373502794
3.518158596713359e-08,0.0030239999999999998,175.3426641455946,431.51994844196565,4.934266373502794
3.546080490338069e-08,0.003048,175.42705843674327,431.51994844196565,4.934266373502794
3.551664869063011e-08,0.0030528,175.44390615211825,431.51994844196565,4.934266373502794
3.583309681837681e-08,0.00308,175.53918211481587,431.51994844196565,4.934266373502794
3.600062818012506e-08,0.0030943999999999998,175.58948945442123,431.51994844196565,4.934266373502794
3.635430549937138e-08,0.0031248,175.69539498970616,431.51994844196565,4.934266373502794
3.6540451456869445e-08,0.0031408,175.75097330797692,431.51994844196565,4.934266373502794
3.658698794624395e-08,0.0031447999999999997,175.76485062089085,431.51994844196565,4.934266373502794
3.67265974143675e-08,0.0031568,175.80644131479482,431.51994844196565,4.934266373502794
3.708027473361382e-08,0.0031872,175.91152939282009,431.51994844196565,4.934266373502794
3.7247806095362074e-08,0.0032015999999999998,175.96117144992178,431.51994844196565,4.934266373502794
3.7620098010358194e-08,0.0032335999999999997,176.07117643135794,431.51994844196565,4.934266373502794
3.775970747848174e-08,0.0032456,176.11231873856275,431.51994844196565,4.934266373502794
3.787139505298058e-08,0.0032551999999999998,176.14518988622066,431.51994844196565,4.934266373502794
3.810407749985316e-08,0.0032752,176.21355026346734,431.51994844196565,4.934266373502794
3.8252994265851604e-08,0.0032879999999999997,176.25721548042603,431.51994844196565,4.934266373502794
3.859736428722302e-08,0.0033176,176.35793817034704,431.51994844196565,4.934266373502794
3.862528618084773e-08,0.00332,176.3660894825875,431.51994844196565,4.934266373502794
3.889519781921992e-08,0.0033431999999999997,176.44476738121176,431.51994844196565,4.934266373502794
3.897896350009405e-08,0.0033504,176.46914132692788,431.51994844196565,4.934266373502794
3.918372405334191e-08,0.003368,176.52863624287744,431.51994844196565,4.934266373502794
3.922095324484152e-08,0.0033712,176.5394404607934,431.51994844196565,4.934266373502794
3.935125541509017e-08,0.0033824,176.5772237665334,431.51994844196565,4.934266373502794
3.9407099202339586e-08,0.0033872,176.59340167174696,431.51994844196565,4.934266373502794
3.9481557585338806e-08,0.0033935999999999997,176.61495831064806,431.51994844196565,4.934266373502794
3.9602552457712554e-08,0.003404,176.64995406405492,431.51994844196565,4.934266373502794
3.9667703542836876e-08,0.0034096,176.6687806585614,431.51994844196565,4.934266373502794
3.972354733008629e-08,0.0034143999999999997,176.6849081433995,431.51994844196565,4.934266373502794
3.983523490458513e-08,0.003424,176.7171366111175,431.51994844196565,4.934266373502794
3.9974844372708674e-08,0.003436,176.75737268190716,431.51994844196565,4.934266373502794
3.999345896845848e-08,0.0034376,176.7627333476444,431.51994844196565,4.934266373502794
4.015168303233183e-08,0.0034511999999999998,176.80825978531072,431.51994844196565,4.934266373502794
4.0430901968578924e-08,0.0034752,176.8884302431319,431.51994844196565,4.934266373502794
4.0803193883575044e-08,0.0035072,176.9949891023519,431.51994844196565,4.934266373502794
4.101726173469781e-08,0.0035256,177.05608874497423,431.51994844196565,4.934266373502794
4.112894930919665e-08,0.0035351999999999996,177.08791744368335,431.51994844196565,4.934266373502794
4.121271499007078e-08,0.0035424,177.11176685117664,431.51994844196565,4.934266373502794
4.1380246351819035e-08,0.0035567999999999997,177.1594090267949,431.51994844196565,4.934266373502794
4.1594314202941804e-08,0.0035751999999999997,177.22017581272382,431.51994844196565,4.934266373502794
4.1696694479565743e-08,0.003584,177.24919506252206,431.51994844196565,4.934266373502794
4.1864225841314e-08,0.0035984,177.29662123900212,431.51994844196565,4.934266373502794
4.1966606117937924e-08,0.0036071999999999996,177.3255674667531,431.51994844196565,4.934266373502794
4.221790316056031e-08,0.0036287999999999997,177.3965007832249,431.51994844196565,4.934266373502794
4.228305424568463e-08,0.0036344,177.41486399875947,431.51994844196565,4.934266373502794
4.244127830955798e-08,0.0036479999999999998,177.45941449861712,431.51994844196565,4.934266373502794
4.2469200203182695e-08,0.0036504,177.46726962289293,431.51994844196565,4.934266373502794
4.2599502373431334e-08,0.0036615999999999997,177.50390027127992,431.51994844196565,4.934266373502794
4.286941401180353e-08,0.0036848,177.57963932869896,431.51994844196565,4.934266373502794
4.3018330777801974e-08,0.0036975999999999997,177.6213467785974,431.51994844196565,4.934266373502794
4.307417456505139e-08,0.0037024,177.63697255069272,431.51994844196565,4.934266373502794
4.3278935118299264e-08,0.0037199999999999998,177.69419957874877,431.51994844196565,4.934266373502794
4.3595383246045966e-08,0.0037472,177.78243409147723,431.51994844196565,4.934266373502794
4.380945109716874e-08,0.0037656,177.8419805514983,431.51994844196565,4.934266373502794
4.388390948016796e-08,0.0037719999999999997,177.86266575038445,431.51994844196565,4.934266373502794
4.3986289756791894e-08,0.0037808,177.89108556325368,431.51994844196565,4.934266373502794
4.420035760791467e-08,0.0037992,177.95042558028004,431.51994844196565,4.934266373502794
4.4321352480288404e-08,0.0038096,177.9839160091772,431.51994844196565,4.934266373502794
4.4460961948411946e-08,0.0038215999999999997,178.02251453691298,431.51994844196565,4.934266373502794
4.455403492716098e-08,0.0038296,178.04822063179643,431.51994844196565,4.934266373502794
4.467502979953472e-08,0.0038399999999999997,178.08160726727212,431.51994844196565,4.934266373502794
4.4721566288909236e-08,0.0038439999999999998,178.09443888862617,431.51994844196565,4.934266373502794
4.505662901240575e-08,0.0038728,178.18667332781686,431.51994844196565,4.934266373502794
4.514970199115478e-08,0.0038808,178.212246482661,431.51994844196565,4.934266373502794
4.536376984227755e-08,0.0038992,178.27098684244294,431.51994844196565,4.934266373502794
4.5531301204025805e-08,0.0039136,178.31688218463322,431.51994844196565,4.934266373502794
4.558714499127522e-08,0.0039184,178.33216599040358,431.51994844196565,4.934266373502794
4.5736061757273676e-08,0.0039312,178.37288715042303,431.51994844196565,4.934266373502794
4.58291347360227e-08,0.0039391999999999995,178.39831161853243,431.51994844196565,4.934266373502794
4.5968744204146253e-08,0.0039512,178.4364105961452,431.51994844196565,4.934266373502794
4.638757260851689e-08,0.0039872,178.55043768813647,431.51994844196565,4.934266373502794
5.48030231941932e-08,0.004710542108421685,180.76275729710156,431.51994844196565,4.934266373502794
6.619743467537078e-08,0.005689937987597519,183.55695495438707,431.51994844196565,4.934266373502794
6.798479333908492e-08,0.0058435687137427484,183.9776047800741,431.51994844196565,4.934266373502794
7.044241150169184e-08,0.0060548109621924385,184.54902223481284,431.51994844196565,4.934266373502794
7.178293049947745e-08,0.00617003400680136,184.85742518556432,431.51994844196565,4.934266373502794
7.357028916319158e-08,0.006323664732946589,185.26515748627358,431.51994844196565,4.934266373502794
7.848552548840545e-08,0.006746149229845969,186.36696905466374,431.51994844196565,4.934266373502794
8.27305023147265e-08,0.007111022204440888,187.29704073635108,431.51994844196565,4.934266373502794
9.367807412997556e-08,0.008052010402080416,189.61352597618017,431.51994844196565,4.934266373502794
9.859331045518942e-08,0.008474494898979796,190.61894344864157,431.51994844196565,4.934266373502794
1.0172118811668916e-07,0.008743348669733947,191.248586749633,431.51994844196565,4.934266373502794
1.0797694343968862e-07,0.009281056211242249,192.4856613717423,431.51994844196565,4.934266373502794
1.1155166076711689e-07,0.009588317663532707,193.1800037391723,431.51994844196565,4.934266373502794
1.1289217976490248e-07,0.009703540708141629,193.43813788921798,431.51994844196565,4.934266373502794
1.1467953842861661e-07,0.009857171434286858,193.7804648372286,431.51994844196565,4.934266373502794
1.1847767558900913e-07,0.010183636727345468,194.50107617981044,431.51994844196565,4.934266373502794
1.2160555325050886e-07,0.010452490498099619,195.0877793007581,431.51994844196565,4.934266373502794
1.2719104907461554e-07,0.010932586517303462,196.12102895406787,431.51994844196565,4.934266373502794
1.3456390356243631e-07,0.01156631326265253,197.45821205380173,431.51994844196565,4.934266373502794
1.3679810189207898e-07,0.011758351670334066,197.8577364901227,431.51994844196565,4.934266373502794
1.40149399386543e-07,0.01204640928185637,198.45228433923725,431.51994844196565,4.934266373502794
1.4707541420843525e-07,0.012641728345669134,199.66372672505196,431.51994844196565,4.934266373502794
1.5556536786107737e-07,0.013371474294858972,201.11877563588814,431.51994844196565,4.934266373502794
1.6025718435332697e-07,0.013774754950990198,201.9095816150303,431.51994844196565,4.934266373502794
1.6450216117964804e-07,0.014139627925585117,202.61732541286835,431.51994844196565,4.934266373502794
1.6695977934225496e-07,0.014350870174034807,203.02381602941094,431.51994844196565,4.934266373502794
1.7768393132453975e-07,0.015272654530906182,204.77096371339778,431.51994844196565,4.934266373502794
1.8617388497718188e-07,0.01600240048009602,206.12511257960858,431.51994844196565,4.934266373502794
1.9019544197053866e-07,0.016348069613922784,206.75812502951476,431.51994844196565,4.934266373502794
1.9153596096832427e-07,0.016463292658531706,206.96796633089528,431.51994844196565,4.934266373502794
1.933233196320384e-07,0.016616923384676935,207.24686592399448,431.51994844196565,4.934266373502794
1.973448766253952e-07,0.0169625925185037,207.87073913007228,431.51994844196565,4.934266373502794
2.027069526165376e-07,0.017423484696939388,208.69491095376011,431.51994844196565,4.934266373502794
2.067285096098944e-07,0.017769153830766153,209.3074711545199,431.51994844196565,4.934266373502794
2.1566530292846506e-07,0.0185373074614923,210.65231707039516,431.51994844196565,4.934266373502794
2.1924002025589333e-07,0.018844568913782757,211.18414789448545,431.51994844196565,4.934266373502794
2.2504893591296424e-07,0.01934386877375475,212.0412159673054,431.51994844196565,4.934266373502794
2.2705971440964267e-07,0.019516703340668136,212.33587747069382,431.51994844196565,4.934266373502794
2.319749507348565e-07,0.019939187837567512,213.05190917861933,431.51994844196565,4.934266373502794
2.3554966806228477e-07,0.02024644928985797,213.56894822367067,431.51994844196565,4.934266373502794
2.400180647215701e-07,0.020630526105221043,214.21096362252223,431.51994844196565,4.934266373502794
2.440396217149269e-07,0.02097619523904781,214.78480273961952,431.51994844196565,4.934266373502794
2.578916513587114e-07,0.022166833366673334,216.7337277822158,431.51994844196565,4.934266373502794
2.5900875052353275e-07,0.022262852570514104,216.88909748020885,431.51994844196565,4.934266373502794
2.6124294885317545e-07,0.02245489097819564,217.19905506552726,431.51994844196565,4.934266373502794
2.674987041761749e-07,0.022992598519703943,218.0614840879708,431.51994844196565,4.934266373502794
2.8179757348588794e-07,0.024221644328865772,220.00374149720045,431.51994844196565,4.934266373502794
2.8313809248367354e-07,0.024336867373474694,220.1838344326236,431.51994844196565,4.934266373502794
2.8626597014517327e-07,0.024605721144228845,220.6027630360664,431.51994844196565,4.934266373502794
3.0034141962192204e-07,0.025815563112622526,222.46627601595915,431.51994844196565,4.934266373502794
3.02799037784529e-07,0.026026805361072214,222.78812708058655,431.51994844196565,4.934266373502794
3.0503323611417164e-07,0.02621884376875375,223.079835979854,431.51994844196565,4.934266373502794
3.1709790709424203e-07,0.027255851170234047,224.64089518277163,431.51994844196565,4.934266373502794
3.2022578475574176e-07,0.027524704940988198,225.0418111649187,431.51994844196565,4.934266373502794
3.233536624172415e-07,0.02779355871174235,225.44120276885505,431.51994844196565,4.934266373502794
3.3318413506766924e-07,0.02863852770554111,226.6867350598957,431.51994844196565,4.934266373502794
3.3832279122584735e-07,0.02908021604320864,227.3320998291351,431.51994844196565,4.934266373502794
3.414506688873471e-07,0.02934906981396279,227.72305921138562,431.51994844196565,4.934266373502794
3.434614473840255e-07,0.029521904380876176,227.97365286591142,431.51994844196565,4.934266373502794
3.4658932504552524e-07,0.029790758151630327,228.36233094437344,431.51994844196565,4.934266373502794
3.5105772170481057e-07,0.0301748349669934,228.91522060968242,431.51994844196565,4.934266373502794
3.671439496782377e-07,0.03155751150230046,230.883292223318,431.51994844196565,4.934266373502794
3.6937814800788037e-07,0.031749549909981994,231.15395137700548,431.51994844196565,4.934266373502794
3.73176285168273e-07,0.03207601520304061,231.61261122841915,431.51994844196565,4.934266373502794
3.760807429968084e-07,0.03232566513302661,231.96212374508977,431.51994844196565,4.934266373502794
3.863580553131647e-07,0.03320904180836168,233.19049552187687,431.51994844196565,4.934266373502794
3.872517346450217e-07,0.033285857171434285,233.29670451547477,431.51994844196565,4.934266373502794
3.9239039080319986e-07,0.03372754550910182,233.90556135371406,431.51994844196565,4.934266373502794
4.035613824514132e-07,0.034687737547509506,235.21853712727105,431.51994844196565,4.934266373502794
4.093702981084841e-07,0.0351870374074815,235.89567808857947,431.51994844196565,4.934266373502794
4.1160449643812674e-07,0.03537907581516303,236.1551178119262,431.51994844196565,4.934266373502794
4.140621146007337e-07,0.03559031806361272,236.43986798988672,431.51994844196565,4.934266373502794
4.185305112600191e-07,0.0359743948789758,236.95591259316024,431.51994844196565,4.934266373502794
4.221052285874473e-07,0.03628165633126626,237.3672028711152,431.51994844196565,4.934266373502794
4.2277548808634e-07,0.03633926785357071,237.444168334307,431.51994844196565,4.934266373502794
4.263502054137683e-07,0.03664652930586117,237.85384989584338,431.51994844196565,4.934266373502794
4.297015029082324e-07,0.03693458691738348,238.23671137624416,431.51994844196565,4.934266373502794
4.3506357889937475e-07,0.03739547909581917,238.84687636890243,431.51994844196565,4.934266373502794
4.357338383982676e-07,0.03745309061812363,238.9229402374591,431.51994844196565,4.934266373502794
4.390851358927315e-07,0.03774114822964593,239.30257725458176,431.51994844196565,4.934266373502794
4.542776845343016e-07,0.03904700940188037,241.009619244659,431.51994844196565,4.934266373502794
4.5852266136062266e-07,0.03941188237647529,241.48258827275777,431.51994844196565,4.934266373502794
4.6232079852101527e-07,0.03973834766953391,241.9043254986636,431.51994844196565,4.934266373502794
4.650018365165864e-07,0.039968793758751744,242.20120919708256,431.51994844196565,4.934266373502794
4.705873323406931e-07,0.04044888977795559,242.8175813337904,431.51994844196565,4.934266373502794
4.7148101167255025e-07,0.04052570514102821,242.91593548610774,431.51994844196565,4.934266373502794
4.786304463274068e-07,0.04114022804560913,243.70016816743592,431.51994844196565,4.934266373502794
4.79747545492228e-07,0.041236247249449895,243.8222906168422,431.51994844196565,4.934266373502794
4.813114843229779e-07,0.041370674134826965,243.99307589536315,431.51994844196565,4.934266373502794
4.857798809822633e-07,0.041754750950190045,244.47984535157343,431.51994844196565,4.934266373502794
4.915887966393342e-07,0.042254050810162036,245.11004298029653,431.51994844196565,4.934266373502794
4.944932544678696e-07,0.04250370074014803,245.42405221103846,431.51994844196565,4.934266373502794
4.978445519623336e-07,0.04279175835167033,245.78547813514956,431.51994844196565,4.934266373502794
5.016426891227261e-07,0.04311822364472895,246.19394908186712,431.51994844196565,4.934266373502794
5.061110857820114e-07,0.043502300460092014,246.67296213837903,431.51994844196565,4.934266373502794
5.083452841116542e-07,0.04369433886777356,246.91184994770674,431.51994844196565,4.934266373502794
5.19069436093939e-07,0.044616123224644935,248.05285999896273,431.51994844196565,4.934266373502794
5.215270542565458e-07,0.04482736547309461,248.31304220882572,431.51994844196565,4.934266373502794
5.219738939224745e-07,0.04486577315463093,248.36029664713874,431.51994844196565,4.934266373502794
5.251017715839741e-07,0.04513462692538507,248.69063709487045,431.51994844196565,4.934266373502794
5.380601218959016e-07,0.04624844968993799,250.05109425143485,431.51994844196565,4.934266373502794
5.40964579724437e-07,0.04649809961992399,250.35426424107655,431.51994844196565,4.934266373502794
5.445392970518654e-07,0.046805361072214446,250.72652647880557,431.51994844196565,4.934266373502794
5.586147465286141e-07,0.04801520304060812,252.18313768947203,431.51994844196565,4.934266373502794
5.615192043571495e-07,0.048264852970594116,252.48191880514298,431.51994844196565,4.934266373502794
5.755946538338985e-07,0.049474694938987804,253.92140609206308,431.51994844196565,4.934266373502794
5.776054323305767e-07,0.04964752950590118,254.12592083570013,431.51994844196565,4.934266373502794
5.809567298250408e-07,0.04993558711742349,254.46616278489347,431.51994844196565,4.934266373502794
5.840846074865404e-07,0.05020444088817763,254.7830319729677,431.51994844196565,4.934266373502794
5.85425126484326e-07,0.05031966393278656,254.91863038923861,431.51994844196565,4.934266373502794
5.92797980972147e-07,0.05095339067813563,255.66226834881618,431.51994844196565,4.934266373502794
5.983834767962535e-07,0.051433486697339464,256.2232314483579,431.51994844196565,4.934266373502794
5.992771561281106e-07,0.051510302060412086,256.31279569026725,431.51994844196565,4.934266373502794
6.028518734555389e-07,0.051817563512702544,256.6705329860477,431.51994844196565,4.934266373502794
6.064265907829671e-07,0.052124824964993,257.02744393781916,431.51994844196565,4.934266373502794
6.093310486115026e-07,0.052374474894979,257.3168302974864,431.51994844196565,4.934266373502794
6.102247279433596e-07,0.052451290258051605,257.4057639594229,431.51994844196565,4.934266373502794
6.15586803934502e-07,0.05291218243648729,257.93830313506845,431.51994844196565,4.934266373502794
6.287685740793937e-07,0.05404520904180836,259.23982929282073,431.51994844196565,4.934266373502794
6.325667112397863e-07,0.054371674334866976,259.61286480507493,431.51994844196565,4.934266373502794
6.368116880661075e-07,0.0547365473094619,260.02875465619576,431.51994844196565,4.934266373502794
6.392693062287144e-07,0.05494778955791159,260.26903880950937,431.51994844196565,4.934266373502794
6.42397183890214e-07,0.05521664332866573,260.57433460342236,431.51994844196565,4.934266373502794
6.444079623868925e-07,0.05538947789557912,260.770290091287,431.51994844196565,4.934266373502794
6.475358400483922e-07,0.05565833166633327,261.07463641904377,431.51994844196565,4.934266373502794
6.52451076373606e-07,0.05608081616323264,261.55173909476673,431.51994844196565,4.934266373502794
6.560257937010342e-07,0.0563880776155231,261.8978428641635,431.51994844196565,4.934266373502794
6.604941903603196e-07,0.05677215443088618,262.32943999914534,431.51994844196565,4.934266373502794
6.640689076877479e-07,0.05707941588317664,262.67389837341534,431.51994844196565,4.934266373502794
6.680904646811046e-07,0.0574250850170034,263.06055082118047,431.51994844196565,4.934266373502794
6.7255886134039e-07,0.05780916183236648,263.4891016299204,431.51994844196565,4.934266373502794
6.776975174985681e-07,0.05825085017003401,263.9805646949628,431.51994844196565,4.934266373502794
6.801551356611751e-07,0.0584620924184837,264.21509830867535,431.51994844196565,4.934266373502794
6.88421669480853e-07,0.05917263452690538,265.0015698107859,431.51994844196565,4.934266373502794
6.890919289797457e-07,0.059230246049209845,265.06517589768504,431.51994844196565,4.934266373502794
6.93560325639031e-07,0.05961432286457291,265.4886015466929,431.51994844196565,4.934266373502794
7.000395007949947e-07,0.060171234246849364,266.10068382662854,431.51994844196565,4.934266373502794
7.029439586235303e-07,0.060420884176835374,266.37434793267096,431.51994844196565,4.934266373502794
7.038376379553873e-07,0.06049769953990798,266.4584635072426,431.51994844196565,4.934266373502794
7.058484164520658e-07,0.06067053410682137,266.647571404287,431.51994844196565,4.934266373502794
7.136681106058151e-07,0.06134266853370675,267.38100241969016,431.51994844196565,4.934266373502794
7.197004460958501e-07,0.061861172234446885,267.94465266681397,431.51994844196565,4.934266373502794
7.210409650936358e-07,0.06197639527905581,268.06965771223065,431.51994844196565,4.934266373502794
7.237220030892071e-07,0.06220684136827366,268.31939622426364,431.51994844196565,4.934266373502794
7.257327815858854e-07,0.062379675935187034,268.50646339417955,431.51994844196565,4.934266373502794
7.293074989133136e-07,0.06268693738747749,268.8385289090877,431.51994844196565,4.934266373502794
7.331056360737062e-07,0.06301340268053611,269.1906537537324,431.51994844196565,4.934266373502794
7.335524757396347e-07,0.06305181036207241,269.2320333782906,431.51994844196565,4.934266373502794
7.348929947374204e-07,0.06316703340668134,269.35611330975314,431.51994844196565,4.934266373502794
7.360100939022417e-07,0.0632630526105221,269.4594458383206,431.51994844196565,4.934266373502794
7.407019103944913e-07,0.06366633326665333,269.8927762205752,431.51994844196565,4.934266373502794
7.467342458845264e-07,0.06418483696739348,270.44834556309985,431.51994844196565,4.934266373502794
7.53883680539383e-07,0.0647993598719744,271.1045366565855,431.51994844196565,4.934266373502794
7.59022336697561e-07,0.06524104820964192,271.57467583204317,431.51994844196565,4.934266373502794
7.628204738579537e-07,0.06556751350270054,271.9213725721778,431.51994844196565,4.934266373502794
7.652780920205606e-07,0.06577875575115023,272.1453470672888,431.51994844196565,4.934266373502794
7.675122903502032e-07,0.06597079415883177,272.3487169403404,431.51994844196565,4.934266373502794
7.710870076776315e-07,0.06627805561112222,272.67362916440527,431.51994844196565,4.934266373502794
7.818111596599163e-07,0.0671998399679936,273.6448593254773,431.51994844196565,4.934266373502794
7.833750984906663e-07,0.06733426685337068,273.7860617461888,431.51994844196565,4.934266373502794
7.847156174884517e-07,0.0674494898979796,273.9070049114829,431.51994844196565,4.934266373502794
7.878434951499515e-07,0.06771834366873375,274.1888927127097,431.51994844196565,4.934266373502794
7.896308538136656e-07,0.06787197439487898,274.3497754886735,431.51994844196565,4.934266373502794
7.992379066311291e-07,0.06869773954790959,275.2120992894319,431.51994844196565,4.934266373502794
8.037063032904144e-07,0.06908181636327265,275.6118018541949,431.51994844196565,4.934266373502794
8.061639214530214e-07,0.06929305861172234,275.8312688158751,431.51994844196565,4.934266373502794
8.130899362749137e-07,0.06988837767553512,276.44836718427786,431.51994844196565,4.934266373502794
8.168880734353061e-07,0.07021484296859372,276.78590549065,431.51994844196565,4.934266373502794
8.213564700945915e-07,0.0705989197839568,277.18222677441946,431.51994844196565,4.934266373502794
8.298464237472338e-07,0.07132866573314664,277.9329282597139,431.51994844196565,4.934266373502794
8.316337824109478e-07,0.07148229645929187,278.09058833463774,431.51994844196565,4.934266373502794
8.352084997383761e-07,0.07178955791158233,278.40551259497084,431.51994844196565,4.934266373502794
8.401237360635899e-07,0.0722120424084817,278.8376764721995,431.51994844196565,4.934266373502794
8.430281938921253e-07,0.07246169233846769,279.09258254833685,431.51994844196565,4.934266373502794
8.497307888810534e-07,0.0730378075615123,279.6795237319795,431.51994844196565,4.934266373502794
8.512947277118031e-07,0.07317223444688938,279.81621653942636,431.51994844196565,4.934266373502794
8.54422605373303e-07,0.07344108821764353,280.08930869558367,431.51994844196565,4.934266373502794
8.635828185248379e-07,0.07422844568913783,280.886844553619,431.51994844196565,4.934266373502794
8.725196118434086e-07,0.07499659931986398,281.66175490033805,431.51994844196565,4.934266373502794
8.743069705071227e-07,0.07515023004600921,281.81636484414065,431.51994844196565,4.934266373502794
8.774348481686225e-07,0.07541908381676336,282.08663596069215,431.51994844196565,4.934266373502794
8.794456266653008e-07,0.07559191838367674,282.2601832799675,431.51994844196565,4.934266373502794
8.803393059971579e-07,0.07566873374674936,282.33726574110096,431.51994844196565,4.934266373502794
8.84584282823479e-07,0.07603360672134428,282.70299148937835,431.51994844196565,4.934266373502794
8.874887406520144e-07,0.07628325665133028,282.95283060926533,431.51994844196565,4.934266373502794
8.915102976453712e-07,0.07662892578515704,283.2982359040104,431.51994844196565,4.934266373502794
8.928508166431568e-07,0.07674414882976596,283.4132358967933,431.51994844196565,4.934266373502794
8.964255339705851e-07,0.07705141028205642,283.71957381591136,431.51994844196565,4.934266373502794
9.017876099617275e-07,0.07751230246049211,284.1781889143175,431.51994844196565,4.934266373502794
9.062560066210128e-07,0.07789637927585517,284.55955632339993,431.51994844196565,4.934266373502794
9.075965256187984e-07,0.0780116023204641,284.6738234520784,431.51994844196565,4.934266373502794
9.151927999395834e-07,0.07866453290658132,285.320098198307,431.51994844196565,4.934266373502794
9.207782957636902e-07,0.07914462892578517,285.7939663352299,431.51994844196565,4.934266373502794
9.239061734251898e-07,0.0794134826965393,286.05884278455306,431.51994844196565,4.934266373502794
9.26587211420761e-07,0.07964392878575716,286.28560150735626,431.51994844196565,4.934266373502794
9.281511502515109e-07,0.07977835567113423,286.4177592603014,431.51994844196565,4.934266373502794
9.379816229019387e-07,0.080623324664933,287.24648530525576,431.51994844196565,4.934266373502794
9.435671187260452e-07,0.08110342068413683,287.71584320633025,431.51994844196565,4.934266373502794
9.440139583919738e-07,0.08114182836567314,287.75334496383437,431.51994844196565,4.934266373502794
9.455778972227237e-07,0.08127625525105021,287.8845466319648,431.51994844196565,4.934266373502794
9.511633930468304e-07,0.08175635127025406,288.35243473625854,431.51994844196565,4.934266373502794
9.569723087039014e-07,0.08225565113022605,288.83790307842816,431.51994844196565,4.934266373502794
9.636749036928292e-07,0.08283176635327066,289.39663306687737,431.51994844196565,4.934266373502794
9.69260399516936e-07,0.0833118623724745,289.8610845942761,431.51994844196565,4.934266373502794
9.746224755080784e-07,0.08377275455091018,290.30597702504315,431.51994844196565,4.934266373502794
9.779737730025424e-07,0.0840608121624325,290.58355009716155,431.51994844196565,4.934266373502794
9.799845514992206e-07,0.08423364672934587,290.7499158850177,431.51994844196565,4.934266373502794
9.89591604316684e-07,0.08505941188237648,291.54294442810925,431.51994844196565,4.934266373502794
9.947302604748622e-07,0.08550110022004401,291.9658897117483,431.51994844196565,4.934266373502794
1.0000923364660046e-06,0.0859619923984797,292.4063164423643,431.51994844196565,4.934266373502794
1.00456073312529e-06,0.08634606921384277,292.7726356631439,431.51994844196565,4.934266373502794
1.0059012521230757e-06,0.0864612922584517,292.88240743982135,431.51994844196565,4.934266373502794
1.0108164884482894e-06,0.08688377675535107,293.28441676826145,431.51994844196565,4.934266373502794
1.0123804272790394e-06,0.08701820364072815,293.4121688531552,431.51994844196565,4.934266373502794
1.0166254041053605e-06,0.08738307661532307,293.7585371234045,431.51994844196565,4.934266373502794
1.020423541265753e-06,0.08770954190838168,294.0679677522668,431.51994844196565,4.934266373502794
1.023998258593181e-06,0.08801680336067214,294.3587865130665,431.51994844196565,4.934266373502794
1.0318179527469305e-06,0.08868893778755751,294.99357574855685,431.51994844196565,4.934266373502794
1.0351692502413945e-06,0.08897699539907981,295.26505362171065,431.51994844196565,4.934266373502794
1.03963764690068e-06,0.0893610722144429,295.6264915251996,431.51994844196565,4.934266373502794
1.0405313262325368e-06,0.0894378875775155,295.698706348373,431.51994844196565,4.934266373502794
1.0441060435599651e-06,0.08974514902980596,295.9873240798962,431.51994844196565,4.934266373502794
1.0458934022236792e-06,0.08989877975595119,296.1314884113133,431.51994844196565,4.934266373502794
1.048127600553322e-06,0.09009081816363274,296.3115587804574,431.51994844196565,4.934266373502794
1.0510320583818575e-06,0.09034046809361873,296.5454266216135,431.51994844196565,4.934266373502794
1.0552770352081786e-06,0.09070534106821365,296.8867805879322,431.51994844196565,4.934266373502794
1.0575112335378213e-06,0.09089737947589518,297.066225449237,431.51994844196565,4.934266373502794
1.0619796301971064e-06,0.09128145629125825,297.4246722257891,431.51994844196565,4.934266373502794
1.0655543475245348e-06,0.09158871774354871,297.7110063243643,431.51994844196565,4.934266373502794
1.069129064851963e-06,0.09189597919583917,297.99696603601575,431.51994844196565,4.934266373502794
1.0762784995068194e-06,0.09251050210042008,298.56776924016174,431.51994844196565,4.934266373502794
1.0834279341616761e-06,0.093125025005001,299.13709558398494,431.51994844196565,4.934266373502794
1.0863323919902115e-06,0.093374674934987,299.3679656610342,431.51994844196565,4.934266373502794
1.0870026514891043e-06,0.09343228645729146,299.42120916948915,431.51994844196565,4.934266373502794
1.0896836894846756e-06,0.09366273254650931,299.6340552888554,431.51994844196565,4.934266373502794
1.091694467981354e-06,0.09383556711342268,299.7935558743152,431.51994844196565,4.934266373502794
1.1019717802977102e-06,0.09471894378875775,300.60699861982926,431.51994844196565,4.934266373502794
1.1073338562888526e-06,0.09517983596719344,301.03022869721246,431.51994844196565,4.934266373502794
1.1091212149525667e-06,0.09533346669333867,301.17112767491585,431.51994844196565,4.934266373502794
1.1138130314448164e-06,0.0957367473494699,301.54056681291036,431.51994844196565,4.934266373502794
1.1189516876029945e-06,0.09617843568713744,301.944494945949,431.51994844196565,4.934266373502794
1.1220795652644942e-06,0.09644728945789158,302.1900100636642,431.51994844196565,4.934266373502794
1.1278884809215652e-06,0.09694658931786358,302.64525974038685,431.51994844196565,4.934266373502794
1.1316866180819577e-06,0.09727305461092219,302.9424286708485,431.51994844196565,4.934266373502794
1.1339208164116002e-06,0.09746509301860372,303.1170522291175,431.51994844196565,4.934266373502794
1.1379423734049572e-06,0.0978107621524305,303.4310368618548,431.51994844196565,4.934266373502794
1.1406234114005283e-06,0.09804120824164833,303.6401195622687,431.51994844196565,4.934266373502794
1.1435278692290637e-06,0.09829085817163433,303.86640965059036,431.51994844196565,4.934266373502794
1.151124143549849e-06,0.09894378875775156,304.4571880327646,431.51994844196565,4.934266373502794
1.1526880823805988e-06,0.09907821564312863,304.5786299208279,431.51994844196565,4.934266373502794
1.1560393798750626e-06,0.09936627325465093,304.8386463645255,431.51994844196565,4.934266373502794
1.157156479039884e-06,0.0994622924584917,304.9252531637178,431.51994844196565,4.934266373502794
1.1591672575365623e-06,0.09963512702540508,305.08106327642355,431.51994844196565,4.934266373502794
1.1618482955321336e-06,0.09986557311462294,305.28864622275927,431.51994844196565,4.934266373502794