File: datasets/aisi_316_L/data/M1/valid_13.csv
Time(s),Strain(%),Stress(MPa),Temp(C),Log_SR(s-1)
0.0,0.0,0.0,416.6781810480269,5.101787075725445
5.0628247936281755e-11,6.4e-06,1.0743692999999999,416.6781810480269,5.101787075725445
7.594237190442264e-11,9.6e-06,1.61155395,416.6781810480269,5.101787075725445
1.4555621281681007e-10,1.84e-05,3.0888117375,416.6781810480269,5.101787075725445
1.7087033678495094e-10,2.16e-05,3.6259963875,416.6781810480269,5.101787075725445
2.0251299174512702e-10,2.56e-05,4.297477199999999,416.6781810480269,5.101787075725445
3.16426549601761e-10,3.9999999999999996e-05,6.714808124999999,416.6781810480269,5.101787075725445
3.670547975380427e-10,4.6399999999999996e-05,7.789177424999999,416.6781810480269,5.101787075725445
4.2401157646635967e-10,5.3599999999999995e-05,8.9978428875,416.6781810480269,5.101787075725445
8.290375599566138e-10,0.0001048,17.5927972875,416.6781810480269,5.101787075725445
1.2340635434468678e-09,0.000156,26.1877516875,416.6781810480269,5.101787075725445
1.3543056322955369e-09,0.0001712,28.739378775,416.6781810480269,5.101787075725445
1.4049338802318185e-09,0.00017759999999999998,29.813748074999996,416.6781810480269,5.101787075725445
1.563147155032699e-09,0.00019759999999999998,33.171152137499995,416.6781810480269,5.101787075725445
1.727688960825615e-09,0.0002184,36.6628523625,416.6781810480269,5.101787075725445
1.847931049674284e-09,0.00023359999999999999,39.21447945,416.6781810480269,5.101787075725445
1.987158731499059e-09,0.0002512,42.168995024999994,416.6781810480269,5.101787075725445
2.0631011034034818e-09,0.0002608,43.780548975,416.6781810480269,5.101787075725445
2.107400820347728e-09,0.00026639999999999997,44.720622112499996,416.6781810480269,5.101787075725445
2.398513245981348e-09,0.0003032,50.8982455875,416.6781810480269,5.101787075725445
2.7275968575671796e-09,0.0003448,57.8816460375,416.6781810480269,5.101787075725445
2.828853353439743e-09,0.00035759999999999996,60.03038463749999,416.6781810480269,5.101787075725445
2.911124256336201e-09,0.000368,61.77623475,416.6781810480269,5.101787075725445
3.126294310065398e-09,0.00039519999999999996,66.34230427499999,416.6781810480269,5.101787075725445
3.227550805937962e-09,0.000408,68.491042875,416.6781810480269,5.101787075725445
3.2781790538742436e-09,0.0004144,69.56541217499999,416.6781810480269,5.101787075725445
3.430063797683089e-09,0.00043359999999999997,72.788520075,416.6781810480269,5.101787075725445
3.575620010499899e-09,0.000452,75.8773318125,416.6781810480269,5.101787075725445
3.6135911964521104e-09,0.0004568,76.6831087875,416.6781810480269,5.101787075725445
3.6705479753804275e-09,0.000464,77.89177425,416.6781810480269,5.101787075725445
3.721176223316709e-09,0.0004704,78.96614355,416.6781810480269,5.101787075725445
3.847746843157413e-09,0.0004864,81.6520668,416.6781810480269,5.101787075725445
4.138859268791033e-09,0.0005231999999999999,87.82969027499999,416.6781810480269,5.101787075725445
4.271758419623773e-09,0.00054,90.6499096875,416.6781810480269,5.101787075725445
4.32871519855209e-09,0.0005472,91.85857515,416.6781810480269,5.101787075725445
4.35402932252023e-09,0.0005503999999999999,92.3957598,416.6781810480269,5.101787075725445
4.613499093193675e-09,0.0005832,97.90190246249999,416.6781810480269,5.101787075725445
4.714755589066238e-09,0.000596,100.05064106249999,416.6781810480269,5.101787075725445
4.816012084938802e-09,0.0006087999999999999,102.1993796625,416.6781810480269,5.101787075725445
4.87296886386712e-09,0.000616,103.408045125,416.6781810480269,5.101787075725445
5.138767165532598e-09,0.0006496,109.04848394999999,416.6781810480269,5.101787075725445
5.208381006444985e-09,0.0006584,110.5257417375,416.6781810480269,5.101787075725445
5.315966033309584e-09,0.000672,112.8087765,416.6781810480269,5.101787075725445
5.410893998190112e-09,0.0006839999999999999,114.82321893749999,416.6781810480269,5.101787075725445
5.46785077711843e-09,0.0006912,116.0318844,416.6781810480269,5.101787075725445
5.512150494062675e-09,0.0006967999999999999,116.97195753749999,416.6781810480269,5.101787075725445
5.645049644895416e-09,0.0007136,119.79217695,416.6781810480269,5.101787075725445
5.77162026473612e-09,0.0007296,122.47810019999999,416.6781810480269,5.101787075725445
6.271574213106902e-09,0.0007928,133.0874970375,416.6781810480269,5.101787075725445
6.3158739300511495e-09,0.0007984,134.027570175,416.6781810480269,5.101787075725445
6.398144832947607e-09,0.0008087999999999999,135.7734202875,416.6781810480269,5.101787075725445
6.429787487907783e-09,0.0008127999999999999,136.44490109999998,416.6781810480269,5.101787075725445
6.581672231716628e-09,0.000832,139.66800899999998,416.6781810480269,5.101787075725445
6.663943134613086e-09,0.0008424,141.4138591125,416.6781810480269,5.101787075725445
6.803170816437861e-09,0.00086,144.3683746875,416.6781810480269,5.101787075725445
6.9487270292546714e-09,0.0008784,147.457186425,416.6781810480269,5.101787075725445
7.100611773063516e-09,0.0008975999999999999,150.68029432499998,416.6781810480269,5.101787075725445
7.328438888776784e-09,0.0009264,155.51495617499998,416.6781810480269,5.101787075725445
7.3474244817528895e-09,0.0009287999999999999,155.9178446625,416.6781810480269,5.101787075725445
7.379067136713066e-09,0.0009327999999999999,156.58932547499998,416.6781810480269,5.101787075725445
7.619551314410405e-09,0.0009632,161.69257965,416.6781810480269,5.101787075725445
7.65119396937058e-09,0.0009672,162.3640604625,416.6781810480269,5.101787075725445
7.720807810282968e-09,0.000976,163.84131825,416.6781810480269,5.101787075725445
7.78409312020332e-09,0.0009839999999999998,165.184279875,416.6781810480269,5.101787075725445
7.847378430123674e-09,0.000992,166.5272415,416.6781810480269,5.101787075725445
8.005591704924552e-09,0.0010119999999999999,169.88464556249997,416.6781810480269,5.101787075725445
8.201776165677645e-09,0.0010368,171.17795961381105,416.6781810480269,5.101787075725445
8.372646502462596e-09,0.0010584,171.29587962517923,416.6781810480269,5.101787075725445
8.461245936351088e-09,0.0010696,171.35665360908078,416.6781810480269,5.101787075725445
8.4992171223033e-09,0.0010743999999999999,171.3826235702055,416.6781810480269,5.101787075725445
8.600473618175863e-09,0.0010872,171.45165653032754,416.6781810480269,5.101787075725445
8.859943388849307e-09,0.00112,171.62712204779734,416.6781810480269,5.101787075725445
8.98651400869001e-09,0.0011359999999999999,171.71198677885667,416.6781810480269,5.101787075725445
9.144727283490892e-09,0.001156,171.81741498434337,416.6781810480269,5.101787075725445
9.340911744243983e-09,0.0011807999999999999,171.94716315053614,416.6781810480269,5.101787075725445
9.454825302100618e-09,0.0011952,172.02201307274,416.6781810480269,5.101787075725445
9.581395921941322e-09,0.0012112,172.10476836905283,416.6781810480269,5.101787075725445
9.714295072774061e-09,0.001228,172.19120387585892,416.6781810480269,5.101787075725445
9.83453716162273e-09,0.0012431999999999999,172.269010849489,416.6781810480269,5.101787075725445
9.897822471543083e-09,0.0012511999999999998,172.3098128204583,416.6781810480269,5.101787075725445
1.0037050153367859e-08,0.0012688,172.39922072182443,416.6781810480269,5.101787075725445
1.0252220207097055e-08,0.0012959999999999998,172.536451011608,416.6781810480269,5.101787075725445
1.0321834048009442e-08,0.0013047999999999998,172.5806079484065,416.6781810480269,5.101787075725445
1.0486375853802358e-08,0.0013256,172.68451973652765,416.6781810480269,5.101787075725445
1.0581303818682888e-08,0.0013376,172.74417957837235,416.6781810480269,5.101787075725445
1.0707874438523591e-08,0.0013536,172.823402338609,416.6781810480269,5.101787075725445
1.0758502686459873e-08,0.0013599999999999999,172.85498908172048,416.6781810480269,5.101787075725445
1.080280240340412e-08,0.0013656,172.88257995812143,416.6781810480269,5.101787075725445
1.0961015678205e-08,0.0013855999999999999,172.9807606200788,416.6781810480269,5.101787075725445
1.1055943643085529e-08,0.0013976,173.0394037556513,416.6781810480269,5.101787075725445
1.1302756351774903e-08,0.0014288,173.1909641728784,416.6781810480269,5.101787075725445
1.1422998440623571e-08,0.001444,173.2643332596746,416.6781810480269,5.101787075725445
1.1511597874512066e-08,0.0014552,173.31820210290567,416.6781810480269,5.101787075725445
1.167613968030498e-08,0.0014759999999999999,173.41781718899406,416.6781810480269,5.101787075725445
1.2024208884866917e-08,0.0015199999999999999,173.62675515611386,416.6781810480269,5.101787075725445
1.2106479787763375e-08,0.0015304,173.6757942205887,416.6781810480269,5.101787075725445
1.2296335717524431e-08,0.0015543999999999998,173.78846793516038,416.6781810480269,5.101787075725445
1.2327978372484607e-08,0.0015584,173.80718072806465,416.6781810480269,5.101787075725445
1.2511505771253629e-08,0.0015815999999999998,173.91534780515912,416.6781810480269,5.101787075725445
1.2555805488197876e-08,0.0015872,173.94136417490412,416.6781810480269,5.101787075725445
1.2581119612166016e-08,0.0015903999999999998,173.95621459877387,416.6781810480269,5.101787075725445
1.3011459719624411e-08,0.0016447999999999999,174.20691560852725,416.6781810480269,5.101787075725445
1.3093730622520869e-08,0.0016552,174.25447330628936,416.6781810480269,5.101787075725445
1.3213972711369538e-08,0.0016703999999999998,174.3237716146589,416.6781810480269,5.101787075725445
1.3346871862202279e-08,0.0016872,174.40007898743073,416.6781810480269,5.101787075725445
1.3600013101883687e-08,0.0017192,174.54461153909872,416.6781810480269,5.101787075725445
1.3675955473788109e-08,0.0017288,174.5877662127799,416.6781810480269,5.101787075725445
1.371392665974032e-08,0.0017335999999999999,174.60930849541845,416.6781810480269,5.101787075725445
1.3770883438668636e-08,0.0017407999999999998,174.64157835433141,416.6781810480269,5.101787075725445
1.3948082306445623e-08,0.0017632,174.7416421917532,416.6781810480269,5.101787075725445
1.4049338802318188e-08,0.001776,174.79859891837887,416.6781810480269,5.101787075725445
1.4264508856047384e-08,0.0018031999999999998,174.91910311541855,416.6781810480269,5.101787075725445
1.4327794165967738e-08,0.0018112,174.95441034048517,416.6781810480269,5.101787075725445
1.4410065068864194e-08,0.0018215999999999998,175.00021893955608,416.6781810480269,5.101787075725445
1.4593592467633216e-08,0.0018448,175.10204139055213,416.6781810480269,5.101787075725445
1.4675863370529674e-08,0.0018552,175.14752369982372,416.6781810480269,5.101787075725445
1.4745477211442062e-08,0.001864,175.18593111711172,416.6781810480269,5.101787075725445
1.4878376362274802e-08,0.0018808,175.25905856828834,416.6781810480269,5.101787075725445
1.496064726517126e-08,0.0018912,175.30420029953785,416.6781810480269,5.101787075725445
1.5118860539972138e-08,0.0019111999999999998,175.39074013573105,416.6781810480269,5.101787075725445
1.5163160256916385e-08,0.0019168,175.41490790626028,416.6781810480269,5.101787075725445
1.5226445566836738e-08,0.0019248,175.44938557967652,416.6781810480269,5.101787075725445
1.5308716469733196e-08,0.0019352,175.49412312026234,416.6781810480269,5.101787075725445
1.538465884163762e-08,0.0019448,175.53533615833985,416.6781810480269,5.101787075725445
1.5454272682550006e-08,0.0019535999999999998,175.57304513153045,416.6781810480269,5.101787075725445
1.5523886523462395e-08,0.0019624,175.61068791711497,416.6781810480269,5.101787075725445
1.563147155032699e-08,0.001976,175.668733900804,416.6781810480269,5.101787075725445
1.5745385108183624e-08,0.0019904,175.7300247869826,416.6781810480269,5.101787075725445
1.5865627197032293e-08,0.0020055999999999997,175.79453340659296,416.6781810480269,5.101787075725445
1.5922583975960612e-08,0.0020128,175.82502354656245,416.6781810480269,5.101787075725445
1.596688369290486e-08,0.0020184,175.84870870194067,416.6781810480269,5.101787075725445
1.6068140188777423e-08,0.0020312,175.9027501729351,416.6781810480269,5.101787075725445
1.6302295835482724e-08,0.0020608,176.0272149313736,416.6781810480269,5.101787075725445
1.6498480296235818e-08,0.0020856,176.13096033107388,416.6781810480269,5.101787075725445
1.657442266814024e-08,0.0020951999999999998,176.17099053540818,416.6781810480269,5.101787075725445
1.6593408261116345e-08,0.0020976,176.1809869018392,416.6781810480269,5.101787075725445
1.6833892438813686e-08,0.002128,176.30722390469546,416.6781810480269,5.101787075725445
1.702374836857474e-08,0.002152,176.40638856663807,416.6781810480269,5.101787075725445
1.7087033678495093e-08,0.00216,176.43934748409615,416.6781810480269,5.101787075725445
1.7156647519407478e-08,0.0021688,176.47554735578902,416.6781810480269,5.101787075725445
1.7226261360319867e-08,0.0021776,176.511689988401,416.6781810480269,5.101787075725445
1.7428774352064994e-08,0.0022031999999999998,176.61650970930936,416.6781810480269,5.101787075725445
1.753003084793756e-08,0.002216,176.66874136619853,416.6781810480269,5.101787075725445
1.761863028182605e-08,0.0022272,176.7143476216723,416.6781810480269,5.101787075725445
1.782747180456321e-08,0.0022535999999999997,176.82149564184806,416.6781810480269,5.101787075725445
1.797302801738002e-08,0.0022719999999999997,176.89588525445546,416.6781810480269,5.101787075725445
1.8067955982260552e-08,0.002284,176.94427366974867,416.6781810480269,5.101787075725445
1.830844015995789e-08,0.0023144,177.06641599894164,416.6781810480269,5.101787075725445
1.8359068407894173e-08,0.0023208,177.09205026411124,416.6781810480269,5.101787075725445
1.8447667841782664e-08,0.002332,177.1368439881403,416.6781810480269,5.101787075725445
1.849196755872691e-08,0.0023376,177.15920938136085,416.6781810480269,5.101787075725445
1.8643852302535758e-08,0.0023568,177.23573259130183,416.6781810480269,5.101787075725445
1.8852693825272917e-08,0.0023832,177.34055620340092,416.6781810480269,5.101787075725445
1.896660738312955e-08,0.0023975999999999997,177.39754180711196,416.6781810480269,5.101787075725445
1.908052094098619e-08,0.002412,177.4543940862795,416.6781810480269,5.101787075725445
1.9118492126938397e-08,0.0024167999999999998,177.47331540978826,416.6781810480269,5.101787075725445
1.9137477719914502e-08,0.0024192,177.482770575125,416.6781810480269,5.101787075725445
1.9371633366619807e-08,0.0024487999999999997,177.59908510502711,416.6781810480269,5.101787075725445
1.9713374040189708e-08,0.002492,177.76786213482393,416.6781810480269,5.101787075725445
1.9732359633165813e-08,0.0024944,177.77720503710373,416.6781810480269,5.101787075725445
1.9865258783998554e-08,0.0025112,177.842507469526,416.6781810480269,5.101787075725445
1.99095585009428e-08,0.0025168,177.86423705546454,416.6781810480269,5.101787075725445
1.9998157934831292e-08,0.002528,177.90763974120551,416.6781810480269,5.101787075725445
2.0074100306735717e-08,0.0025376,177.9447823886203,416.6781810480269,5.101787075725445
2.0143714147648103e-08,0.0025464,177.97878170293527,416.6781810480269,5.101787075725445
2.023864211252863e-08,0.0025583999999999997,178.0250706484677,416.6781810480269,5.101787075725445
2.0485454821218007e-08,0.0025896,178.1450273555445,416.6781810480269,5.101787075725445
2.074492459189145e-08,0.0026224,178.27052951802858,416.6781810480269,5.101787075725445
2.075758165387552e-08,0.002624,178.27663586630388,416.6781810480269,5.101787075725445
2.0820866963795872e-08,0.002632,178.30714585304506,416.6781810480269,5.101787075725445
2.1111979389429493e-08,0.0026688,178.44702857889996,416.6781810480269,5.101787075725445
2.1187921761333915e-08,0.0026784,178.48339575525526,416.6781810480269,5.101787075725445
2.1308163850182583e-08,0.0026936,178.54087332414008,416.6781810480269,5.101787075725445
2.1529662434903816e-08,0.0027216,178.6464230124229,416.6781810480269,5.101787075725445
2.1554976558871957e-08,0.0027248,178.65845880802289,416.6781810480269,5.101787075725445
2.1599276275816204e-08,0.0027304,178.67950819412073,416.6781810480269,5.101787075725445
2.1770146612601153e-08,0.0027519999999999997,178.76054145391123,416.6781810480269,5.101787075725445
2.1903045763433898e-08,0.0027688,178.8233959558728,416.6781810480269,5.101787075725445
2.2111887286171057e-08,0.0027952,178.92186763941888,416.6781810480269,5.101787075725445
2.2130872879147163e-08,0.0027976,178.93080158610053,416.6781810480269,5.101787075725445
2.2181501127083446e-08,0.002804,178.9546108428796,416.6781810480269,5.101787075725445
2.2428313835772817e-08,0.0028352,179.07037883505825,416.6781810480269,5.101787075725445
2.2478942083709097e-08,0.0028415999999999997,179.0940645856741,416.6781810480269,5.101787075725445
2.2592855641565736e-08,0.002856,179.14728158829635,416.6781810480269,5.101787075725445
2.267512654446219e-08,0.0028664,179.1856510314363,416.6781810480269,5.101787075725445
2.2725754792398474e-08,0.0028728,179.20923601200147,416.6781810480269,5.101787075725445
2.278271157132679e-08,0.0028799999999999997,179.2357446351045,416.6781810480269,5.101787075725445
2.2883968067199354e-08,0.0028928,179.28280734745672,416.6781810480269,5.101787075725445
2.3118123713904658e-08,0.0029224,179.391329910447,416.6781810480269,5.101787075725445
2.3200394616801113e-08,0.0029327999999999997,179.42935758047753,416.6781810480269,5.101787075725445
2.3434550263506418e-08,0.0029624,179.53730339268427,416.6781810480269,5.101787075725445
2.3611749131283403e-08,0.0029847999999999997,179.61871272877409,416.6781810480269,5.101787075725445
2.3649720317235614e-08,0.0029896,179.6361265474195,416.6781810480269,5.101787075725445
2.3706677096163933e-08,0.0029968,179.6622268443243,416.6781810480269,5.101787075725445
2.3852233308980744e-08,0.0030152,179.72881673801905,416.6781810480269,5.101787075725445
2.4073731893701976e-08,0.0030432,179.82984591182998,416.6781810480269,5.101787075725445
2.4200302513542678e-08,0.0030591999999999998,179.8874140946201,416.6781810480269,5.101787075725445
2.4244602230486925e-08,0.0030648,179.90753520154317,416.6781810480269,5.101787075725445
2.437117285032763e-08,0.0030808,179.96494522253417,416.6781810480269,5.101787075725445
2.4485086408184262e-08,0.0030951999999999998,180.01651489741522,416.6781810480269,5.101787075725445
2.4567357311080724e-08,0.0031056,180.05370148843684,416.6781810480269,5.101787075725445
2.470025646191346e-08,0.0031224,180.11366970618104,416.6781810480269,5.101787075725445
2.4801512957786025e-08,0.0031352,180.159275353293,416.6781810480269,5.101787075725445
2.4839484143738236e-08,0.00314,180.17635874257454,416.6781810480269,5.101787075725445
2.5060982728459468e-08,0.003168,180.27580961047144,416.6781810480269,5.101787075725445
2.5130596569371857e-08,0.0031768,180.30699472061755,416.6781810480269,5.101787075725445
2.5155910693339995e-08,0.0031799999999999997,180.31832640539045,416.6781810480269,5.101787075725445
2.5181224817308137e-08,0.0031831999999999997,180.32965364388323,416.6781810480269,5.101787075725445
2.5333109561116983e-08,0.0032023999999999998,180.39752404977378,416.6781810480269,5.101787075725445
2.53900663400453e-08,0.0032096,180.42293451437152,416.6781810480269,5.101787075725445
2.5687507296670957e-08,0.0032472,180.5552741532576,416.6781810480269,5.101787075725445
2.5858377633455906e-08,0.0032687999999999997,180.63102876782807,416.6781810480269,5.101787075725445
2.5927991474368295e-08,0.0032776,180.6618357589371,416.6781810480269,5.101787075725445
2.606721915619307e-08,0.0032952,180.72335313689842,416.6781810480269,5.101787075725445
2.6282389209922265e-08,0.0033223999999999997,180.8181739984494,416.6781810480269,5.101787075725445
2.6440602484723144e-08,0.0033423999999999997,180.88770218492624,416.6781810480269,5.101787075725445
2.6560844573571813e-08,0.0033575999999999996,180.94043514457826,416.6781810480269,5.101787075725445
2.6813985813253227e-08,0.0033896,181.05114854591537,416.6781810480269,5.101787075725445
2.692789937110986e-08,0.003404,181.10083651078574,416.6781810480269,5.101787075725445
2.700384174301428e-08,0.0034135999999999997,181.13391628596884,416.6781810480269,5.101787075725445
2.7041812928966492e-08,0.0034184,181.15044256656665,416.6781810480269,5.101787075725445
2.7313939761624007e-08,0.0034528,181.2686171951822,416.6781810480269,5.101787075725445
2.7396210664520465e-08,0.0034632,181.30425389789428,416.6781810480269,5.101787075725445
2.7421524788488604e-08,0.0034663999999999997,181.31521063728292,416.6781810480269,5.101787075725445
2.7598723656265592e-08,0.0034888,181.39179766275504,416.6781810480269,5.101787075725445
2.766833749717798e-08,0.0034976,181.4218329244369,416.6781810480269,5.101787075725445
2.7769593993050544e-08,0.0035104,181.4654680202869,416.6781810480269,5.101787075725445
2.8016406701739915e-08,0.0035415999999999998,181.57156941523453,416.6781810480269,5.101787075725445
2.8193605569516903e-08,0.003564,181.64752009122049,416.6781810480269,5.101787075725445
2.834549031332575e-08,0.0035832,181.7124726145009,416.6781810480269,5.101787075725445
2.8560660367054946e-08,0.0036103999999999997,181.80425681808293,416.6781810480269,5.101787075725445
2.8756844827808036e-08,0.0036352,181.88770765033567,416.6781810480269,5.101787075725445
2.8921386633600952e-08,0.003656,181.95752760620576,416.6781810480269,5.101787075725445
2.90922569703859e-08,0.0036775999999999996,182.029869172311,416.6781810480269,5.101787075725445
2.9142885218322184e-08,0.0036839999999999998,182.051271862723,416.6781810480269,5.101787075725445
2.9231484652210682e-08,0.0036952,182.0886917111001,416.6781810480269,5.101787075725445
2.9351726741059347e-08,0.0037104,182.13940511780538,416.6781810480269,5.101787075725445
2.94150120509797e-08,0.0037183999999999997,182.16606383715907,416.6781810480269,5.101787075725445
2.9528925608836332e-08,0.0037327999999999997,182.2139932316781,416.6781810480269,5.101787075725445
2.9668153290661107e-08,0.0037503999999999997,182.2724757879586,416.6781810480269,5.101787075725445
2.9731438600581463e-08,0.0037584,182.29902337492837,416.6781810480269,5.101787075725445
2.991496599935048e-08,0.0037816,182.37588703514703,416.6781810480269,5.101787075725445
3.0041536619191186e-08,0.0037976,182.42878933762208,416.6781810480269,5.101787075725445
3.013013605307968e-08,0.0038087999999999998,182.46576924042992,416.6781810480269,5.101787075725445
3.021240695597614e-08,0.0038192,182.50006976606528,416.6781810480269,5.101787075725445
3.0351634637800915e-08,0.0038368,182.5580339404815,416.6781810480269,5.101787075725445
3.038327729276109e-08,0.0038407999999999997,182.57119314371008,416.6781810480269,5.101787075725445
3.055414762954604e-08,0.0038623999999999998,182.64216069690923,416.6781810480269,5.101787075725445
3.0864245648155765e-08,0.0039016,182.77055957882007,416.6781810480269,5.101787075725445
3.0902216834107976e-08,0.0039064,182.7862472420782,416.6781810480269,5.101787075725445
3.112371541882921e-08,0.0039344,182.87760922461123,416.6781810480269,5.101787075725445
3.1351542534542477e-08,0.0039632,182.97131739045759,416.6781810480269,5.101787075725445
3.151608434033539e-08,0.003984,183.03883042333766,416.6781810480269,5.101787075725445
3.1592026712239814e-08,0.0039936,183.06994390697002,416.6781810480269,5.101787075725445
3.162366936719999e-08,0.0039976,183.08289924804643,416.6781810480269,5.101787075725445
3.4377127243191916e-08,0.0043456691338267656,184.19161505386833,416.6781810480269,5.101787075725445
3.711159952620774e-08,0.004691338267653531,185.2588891345662,416.6781810480269,5.101787075725445
4.0757562570228826e-08,0.005152230446089218,186.63534868101422,416.6781810480269,5.101787075725445
4.303628947274201e-08,0.005440288057611523,187.47127155875643,416.6781810480269,5.101787075725445
4.577076175575782e-08,0.0057859571914382875,188.45192121635586,416.6781810480269,5.101787075725445
4.683416764359731e-08,0.005920384076815363,188.82707953459303,416.6781810480269,5.101787075725445
4.9112894546110494e-08,0.0062084416883376676,189.61998188862276,416.6781810480269,5.101787075725445
5.108779119495525e-08,0.006458091618323665,190.29562552915434,416.6781810480269,5.101787075725445
5.6100990380484246e-08,0.007091818363672734,191.96648630884783,416.6781810480269,5.101787075725445
5.731631139515794e-08,0.007245449089817963,192.36264412423824,416.6781810480269,5.101787075725445
5.974695342450533e-08,0.007552710542108421,193.14526516941186,416.6781810480269,5.101787075725445
6.081035931234482e-08,0.007687137427485497,193.4837461511403,416.6781810480269,5.101787075725445
6.369674672219486e-08,0.008052010402080416,194.39103932964582,416.6781810480269,5.101787075725445
6.870994590772386e-08,0.008685737147429486,195.92963324325166,416.6781810480269,5.101787075725445
7.493846610792656e-08,0.009473094618923785,197.7814969492398,416.6781810480269,5.101787075725445
7.569804174209762e-08,0.009569113822764553,198.0031516140495,416.6781810480269,5.101787075725445
7.979975016662134e-08,0.010087617523504702,199.18542330716085,416.6781810480269,5.101787075725445
8.466103422531613e-08,0.010702140428085618,200.55636385138035,416.6781810480269,5.101787075725445
8.526869473265298e-08,0.010778955791158232,200.7255458330615,416.6781810480269,5.101787075725445
9.028189391818196e-08,0.0114126825365073,202.10379494740303,416.6781810480269,5.101787075725445
9.210487544019251e-08,0.011643128625725144,202.59753281163958,416.6781810480269,5.101787075725445
1.0167552843074788e-07,0.012852970594118824,205.1296521520083,416.6781810480269,5.101787075725445
1.0228318893808474e-07,0.012929785957191438,205.2872090857532,416.6781810480269,5.101787075725445
1.0668872761627689e-07,0.013486697339467894,206.4187748934087,416.6781810480269,5.101787075725445
1.0896745451879007e-07,0.013774754950990198,206.9969070966505,416.6781810480269,5.101787075725445
1.0957511502612691e-07,0.013851570314062813,207.1502769152638,416.6781810480269,5.101787075725445
1.1261341756281116e-07,0.014235647129425886,207.912206014587,416.6781810480269,5.101787075725445
1.168670411141691e-07,0.014773354670934187,208.9655721563151,416.6781810480269,5.101787075725445
1.1823427725567701e-07,0.01494618923784757,209.300964410293,416.6781810480269,5.101787075725445
1.2036108903135598e-07,0.015215043008601721,209.81969473623562,416.6781810480269,5.101787075725445
1.2248790080703495e-07,0.015483896779355872,210.33486235177986,416.6781810480269,5.101787075725445
1.2446279745587972e-07,0.01573354670934187,210.81011716926128,416.6781810480269,5.101787075725445
1.2856450588040344e-07,0.016252050410082017,211.78788886705888,416.6781810480269,5.101787075725445
1.3631217734894824e-07,0.01723144628925785,213.60221505818765,416.6781810480269,5.101787075725445
1.4102154628080884e-07,0.017826765353070616,214.6853950518161,416.6781810480269,5.101787075725445
1.4512325470533256e-07,0.018345269053810762,215.6173652152811,416.6781810480269,5.101787075725445
1.4755389673467995e-07,0.01865253050610122,216.16479663022753,416.6781810480269,5.101787075725445
1.5044028414452996e-07,0.019017403480696138,216.81032437609446,416.6781810480269,5.101787075725445
1.5256709592020896e-07,0.019286257251450292,217.2828897376332,416.6781810480269,5.101787075725445
1.557573135837274e-07,0.019689537907581517,217.9869487762653,416.6781810480269,5.101787075725445
1.572764648520695e-07,0.019881576315263053,218.32023627317182,416.6781810480269,5.101787075725445
1.609224278960906e-07,0.02034246849369874,219.11504491661097,416.6781810480269,5.101787075725445
1.6547988170111698e-07,0.02091858371674335,220.09874750665745,416.6781810480269,5.101787075725445
1.6623945733528804e-07,0.021014602920584116,220.26166520590178,416.6781810480269,5.101787075725445
1.6791052373046437e-07,0.021225845169033808,220.61906571877992,416.6781810480269,5.101787075725445
1.7079691114031438e-07,0.021590718143628725,221.2331436256637,416.6781810480269,5.101787075725445
1.7489861956483813e-07,0.022109221844368875,222.09886349851004,416.6781810480269,5.101787075725445
1.7808883722835658e-07,0.0225125025005001,222.76673828773158,416.6781810480269,5.101787075725445
1.8021564900403556e-07,0.02278135627125425,223.20939770618614,416.6781810480269,5.101787075725445
1.8370969692122245e-07,0.023223044608921786,223.93222629572128,416.6781810480269,5.101787075725445
1.867479994579067e-07,0.02360712142428486,224.556425541244,416.6781810480269,5.101787075725445
1.9145736838976724e-07,0.02420244048809762,225.51616344343424,416.6781810480269,5.101787075725445
1.9252077427760672e-07,0.024336867373474694,225.73159904384272,416.6781810480269,5.101787075725445
1.9403992554594884e-07,0.02452890578115623,226.03856087029087,416.6781810480269,5.101787075725445
1.957109919411252e-07,0.024740148029605922,226.3751383749348,416.6781810480269,5.101787075725445
1.9753397346313573e-07,0.024970594118823766,226.74103813049194,416.6781810480269,5.101787075725445
1.9935695498514627e-07,0.02520104020804161,227.10562328726357,416.6781810480269,5.101787075725445
2.0193951214132787e-07,0.02552750550110022,227.61990103368439,416.6781810480269,5.101787075725445
2.0664888107318847e-07,0.026122824564912984,228.5511461832477,416.6781810480269,5.101787075725445
2.0999101386354113e-07,0.026545309061812364,229.20701523709982,416.6781810480269,5.101787075725445
2.1151016513188325e-07,0.0267373474694939,229.50379046486796,416.6781810480269,5.101787075725445
2.13485061780728e-07,0.026986997399479896,229.88835841375771,416.6781810480269,5.101787075725445
2.1773868533208595e-07,0.027524704940988198,230.71197763850432,416.6781810480269,5.101787075725445
2.1940975172726228e-07,0.02773594718943789,231.03382254668594,416.6781810480269,5.101787075725445
2.221442240102781e-07,0.028081616323264655,231.55842340279503,416.6781810480269,5.101787075725445
2.2563827192746497e-07,0.028523304660932187,232.2250961745315,416.6781810480269,5.101787075725445
2.2624593243480183e-07,0.0286001200240048,232.34062706916518,416.6781810480269,5.101787075725445
2.273093383226413e-07,0.028734546909381875,232.54251536281998,416.6781810480269,5.101787075725445
2.3217062238133609e-07,0.02934906981396279,233.46078256563158,416.6781810480269,5.101787075725445
2.3277828288867294e-07,0.029425885177035406,233.5750363741458,416.6781810480269,5.101787075725445
2.3520892491802033e-07,0.029733146629325864,234.03089319246516,416.6781810480269,5.101787075725445
2.3703190644003087e-07,0.029963592718543708,234.37158110012285,416.6781810480269,5.101787075725445
2.431085115133994e-07,0.030731746349269853,235.49989858862907,416.6781810480269,5.101787075725445
2.4584298379641516e-07,0.03107741548309662,236.00404739758557,416.6781810480269,5.101787075725445
2.4766596531842575e-07,0.031307861572314466,236.3389321588257,416.6781810480269,5.101787075725445
2.531349098844573e-07,0.03199919983996799,237.33786540243415,416.6781810480269,5.101787075725445
2.57844278816318e-07,0.03259451890378076,238.19133182753657,416.6781810480269,5.101787075725445
2.5875576957732323e-07,0.03270974194838968,238.3558143686257,416.6781810480269,5.101787075725445
2.6027492084566535e-07,0.03290178035607122,238.6294506739794,416.6781810480269,5.101787075725445
2.631613082555154e-07,0.033266653330666134,239.14764969392968,416.6781810480269,5.101787075725445
2.658957805385312e-07,0.0336123224644929,239.6365341513274,416.6781810480269,5.101787075725445
2.7060514947039174e-07,0.03420764152830566,240.47393018068578,416.6781810480269,5.101787075725445
2.7273196124607075e-07,0.034476495299059814,240.85024407163627,416.6781810480269,5.101787075725445
2.7622600916325756e-07,0.03491818363672734,241.4659989275315,416.6781810480269,5.101787075725445
2.798719722072787e-07,0.03537907581516303,242.1052958017468,416.6781810480269,5.101787075725445
2.8442942601230505e-07,0.03595519103820764,242.89986759108763,416.6781810480269,5.101787075725445
2.8929071007099984e-07,0.03656971394278856,243.74195742855227,416.6781810480269,5.101787075725445
2.9263284286135255e-07,0.03699219843968794,244.31769547145245,416.6781810480269,5.101787075725445
2.9567114539803674e-07,0.03737627525505101,244.8388721933986,416.6781810480269,5.101787075725445
2.9825370255421837e-07,0.037702740548109626,245.28023227068107,416.6781810480269,5.101787075725445
3.026592412324105e-07,0.03825965193038608,246.02971609791084,416.6781810480269,5.101787075725445
3.066090345301e-07,0.03875895179035807,246.698057435422,416.6781810480269,5.101787075725445
3.08735846305779e-07,0.039027805561112225,247.0565423793484,416.6781810480269,5.101787075725445
3.101030824472869e-07,0.0392006401280256,247.28648850352621,416.6781810480269,5.101787075725445
3.1253372447663424e-07,0.03950790158031606,247.69430771375397,416.6781810480269,5.101787075725445
3.1496436650598166e-07,0.039815163032606515,248.1008918210285,416.6781810480269,5.101787075725445
3.1557202701331854e-07,0.03989197839567914,248.20234641866583,416.6781810480269,5.101787075725445
3.225601228476923e-07,0.04077535507101421,249.36365078872134,416.6781810480269,5.101787075725445
3.248388497502055e-07,0.04106341268253651,249.74021004689007,416.6781810480269,5.101787075725445
3.269656615258845e-07,0.04133226645329066,250.09073694451513,416.6781810480269,5.101787075725445
3.2894055817472923e-07,0.04158191638327666,250.41543081688238,416.6781810480269,5.101787075725445
3.33042266599253e-07,0.04210042008401681,251.08737580029756,416.6781810480269,5.101787075725445
3.347133329944293e-07,0.0423116623324665,251.36020494257173,416.6781810480269,5.101787075725445
3.35928654009103e-07,0.04246529305861173,251.5582925899789,416.6781810480269,5.101787075725445
3.365363145164398e-07,0.042542108421684335,251.65723159095407,416.6781810480269,5.101787075725445
3.4139759857513457e-07,0.04315663132626525,252.4462508292214,416.6781810480269,5.101787075725445
3.4246100446297413e-07,0.043291058211642336,252.6182633019301,416.6781810480269,5.101787075725445
3.5051250618518736e-07,0.04430886177235448,253.9139510333751,416.6781810480269,5.101787075725445
3.533988935950373e-07,0.044673734746949384,254.37560960983822,416.6781810480269,5.101787075725445
3.5598145075121897e-07,0.045000200040008,254.78742752861734,416.6781810480269,5.101787075725445
3.5810826252689797e-07,0.045269053810762155,255.12569751626822,416.6781810480269,5.101787075725445
3.600831591757427e-07,0.04551870374074815,255.43910447318152,416.6781810480269,5.101787075725445
3.6327337683926117e-07,0.045921984396879376,255.9439648474302,416.6781810480269,5.101787075725445
3.652482734881059e-07,0.04617163432686537,256.2556310769543,416.6781810480269,5.101787075725445
3.6783083064428754e-07,0.04649809961992399,256.66220474453553,416.6781810480269,5.101787075725445
3.6874232140529283e-07,0.046613322664532914,256.80543533496876,416.6781810480269,5.101787075725445
3.7390743571765603e-07,0.047266253250650134,257.6144822477727,416.6781810480269,5.101787075725445
3.811993618056982e-07,0.04818803760752151,258.7492847776894,416.6781810480269,5.101787075725445
3.8378191896187974e-07,0.04851450290058011,259.1491597474829,416.6781810480269,5.101787075725445
3.878836273864035e-07,0.04903300660132026,259.7821050582029,416.6781810480269,5.101787075725445
3.916815055572588e-07,0.04951310262052411,260.3658419862353,416.6781810480269,5.101787075725445
3.9502363834761154e-07,0.04993558711742349,260.87770692158506,416.6781810480269,5.101787075725445
3.9927726189896944e-07,0.050473294658931786,261.5267352485747,416.6781810480269,5.101787075725445
4.032270551966589e-07,0.05097259451890378,262.1269939828847,416.6781810480269,5.101787075725445
4.0520195184550367e-07,0.05122224444888977,262.4262631100513,416.6781810480269,5.101787075725445
4.1006323590419845e-07,0.05183676735347069,263.160512289799,416.6781810480269,5.101787075725445
4.1492451996289323e-07,0.052451290258051605,263.8913744571132,416.6781810480269,5.101787075725445
4.162917561044012e-07,0.05262412482496499,264.09632676230393,416.6781810480269,5.101787075725445
4.1796282249957753e-07,0.052835367073414685,264.34646786261067,416.6781810480269,5.101787075725445
4.184185678800802e-07,0.05289297859571915,264.41462043180104,416.6781810480269,5.101787075725445
4.21912615797267e-07,0.053334666933386676,264.9361650809017,416.6781810480269,5.101787075725445
4.249509183339513e-07,0.053718743748749756,265.38831444964234,416.6781810480269,5.101787075725445
4.258624090949565e-07,0.05383396679335867,265.5237131798236,416.6781810480269,5.101787075725445
4.285968813779724e-07,0.05417963592718544,265.929232861286,416.6781810480269,5.101787075725445
4.298122023926461e-07,0.05433326665333067,266.10913981654153,416.6781810480269,5.101787075725445
4.336100805635013e-07,0.054813362672534505,266.67007459329034,416.6781810480269,5.101787075725445
4.358888074660146e-07,0.05510142028405682,267.00571579961456,416.6781810480269,5.101787075725445
4.366483831001856e-07,0.055197439487897584,267.1174440406201,416.6781810480269,5.101787075725445
4.4652286634440934e-07,0.05644568913782756,268.5630815527029,416.6781810480269,5.101787075725445
4.472824419785804e-07,0.05654170834166833,268.6737653262002,416.6781810480269,5.101787075725445
4.484977629932541e-07,0.05669533906781356,268.8507070101793,416.6781810480269,5.101787075725445
4.5624543446179895e-07,0.057674734946989395,269.97434610990257,416.6781810480269,5.101787075725445
4.5685309496913584e-07,0.057751550310062016,270.0621587015058,416.6781810480269,5.101787075725445
4.579165008569753e-07,0.05788597719543909,270.2157212066819,416.6781810480269,5.101787075725445
4.63385445423007e-07,0.058577315463092625,271.0032850591297,416.6781810480269,5.101787075725445
4.661199177060228e-07,0.05892298459691939,271.3957069901792,416.6781810480269,5.101787075725445
4.687024748622043e-07,0.05924944988997799,271.765504119947,416.6781810480269,5.101787075725445
4.732599286672307e-07,0.0598255651130226,272.4161545903326,416.6781810480269,5.101787075725445
4.7584248582341234e-07,0.06015203040608122,272.78377175253445,416.6781810480269,5.101787075725445
4.823748362772835e-07,0.06097779555911183,273.710170542615,416.6781810480269,5.101787075725445
4.845016480529623e-07,0.06124664932986597,274.0107312493362,416.6781810480269,5.101787075725445
4.848054783066309e-07,0.061285057011402286,274.053626451415,416.6781810480269,5.101787075725445
4.878437808433151e-07,0.06166913382676535,274.48200341074477,416.6781810480269,5.101787075725445
4.92097404394673e-07,0.06220684136827366,275.0799872309216,416.6781810480269,5.101787075725445
4.974144338338705e-07,0.06287897579515904,275.8246397385462,416.6781810480269,5.101787075725445
4.987816699753783e-07,0.06305181036207241,276.01561924339967,416.6781810480269,5.101787075725445
5.0425061454141e-07,0.06374314862972595,276.7775044104686,416.6781810480269,5.101787075725445
5.091118986001048e-07,0.06435767153430687,277.4520343992694,416.6781810480269,5.101787075725445
5.109348801221153e-07,0.0645881176235247,277.7043349529579,416.6781810480269,5.101787075725445
5.130616918977943e-07,0.06485697139427886,277.9982423088409,416.6781810480269,5.101787075725445
5.165557398149811e-07,0.06529865973194639,278.4800606842183,416.6781810480269,5.101787075725445
5.194421272248312e-07,0.06566353270654131,278.87712660706524,416.6781810480269,5.101787075725445
5.22936175142018e-07,0.06610522104420884,279.3566359264963,416.6781810480269,5.101787075725445
5.265821381860392e-07,0.06656611322264454,279.85566319073064,416.6781810480269,5.101787075725445
5.284051197080497e-07,0.06679655931186237,280.104671372119,416.6781810480269,5.101787075725445
5.318991676252367e-07,0.06723824764952992,280.58100257004907,416.6781810480269,5.101787075725445
5.469387651818236e-07,0.06913942788557711,282.6175220393414,416.6781810480269,5.101787075725445
5.504328130990105e-07,0.06958111622324466,283.08751240409,416.6781810480269,5.101787075725445
5.566613332992131e-07,0.07036847369473895,283.9224457170205,416.6781810480269,5.101787075725445
5.574209089333842e-07,0.07046449289857971,284.02401700536893,416.6781810480269,5.101787075725445
5.598515509627317e-07,0.07077175435087017,284.3486829890916,416.6781810480269,5.101787075725445
5.616745324847422e-07,0.07100220044008802,284.5918218394852,416.6781810480269,5.101787075725445
5.666877316702712e-07,0.0716359271854371,285.25887192678545,416.6781810480269,5.101787075725445
5.688145434459501e-07,0.07190478095619124,285.5411671417773,416.6781810480269,5.101787075725445
5.72308591363137e-07,0.07234646929385878,286.0040458366078,416.6781810480269,5.101787075725445
5.748911485193186e-07,0.07267293458691738,286.3454655249057,416.6781810480269,5.101787075725445
5.809677535926871e-07,0.07344108821764353,287.14645509675455,416.6781810480269,5.101787075725445
5.821830746073608e-07,0.07359471894378876,287.3062601997257,416.6781810480269,5.101787075725445
5.840060561293715e-07,0.07382516503300661,287.5457241281782,416.6781810480269,5.101787075725445
5.893230855685689e-07,0.07449729945989199,288.2425010737207,416.6781810480269,5.101787075725445
5.919056427247504e-07,0.07482376475295059,288.5800506098205,416.6781810480269,5.101787075725445
5.94488199880932e-07,0.07515023004600921,288.91702625179346,416.6781810480269,5.101787075725445
5.961592662761084e-07,0.0753614722944589,289.13476513163715,416.6781810480269,5.101787075725445
5.979822477981189e-07,0.07559191838367674,289.3720271625665,416.6781810480269,5.101787075725445
6.036031074909847e-07,0.07630246049209842,290.1018155444155,416.6781810480269,5.101787075725445
6.046665133788242e-07,0.0764368873774755,290.2395849654355,416.6781810480269,5.101787075725445
6.099835428180217e-07,0.07710902180436088,290.9270197517043,416.6781810480269,5.101787075725445
6.104392881985242e-07,0.07716663332666533,290.9858337765678,416.6781810480269,5.101787075725445
6.140852512425454e-07,0.07762752550510102,291.4557310599064,416.6781810480269,5.101787075725445
6.169716386523954e-07,0.07799239847969594,291.8269618720504,416.6781810480269,5.101787075725445
6.210733470769191e-07,0.07851090218043609,292.35333735842295,416.6781810480269,5.101787075725445
6.256308008819455e-07,0.0790870174034807,292.93661149327534,416.6781810480269,5.101787075725445
6.292767639259666e-07,0.07954790958191639,293.4020385881796,416.6781810480269,5.101787075725445
6.336823026041588e-07,0.08010482096419284,293.9630288532281,416.6781810480269,5.101787075725445
6.368725202676772e-07,0.08050810162032407,294.36831408562875,416.6781810480269,5.101787075725445
6.399108228043615e-07,0.08089217843568715,294.7535645523031,416.6781810480269,5.101787075725445
6.429491253410457e-07,0.08127625525105021,295.13810229847036,416.6781810480269,5.101787075725445
6.497853060485852e-07,0.08214042808561713,296.0007304847822,416.6781810480269,5.101787075725445
6.519121178242642e-07,0.08240928185637128,296.2683808803411,416.6781810480269,5.101787075725445
6.540389295999433e-07,0.08267813562712543,296.53569094830686,416.6781810480269,5.101787075725445
6.607231951806485e-07,0.08352310462092419,297.37360978870817,416.6781810480269,5.101787075725445
6.61786601068488e-07,0.08365753150630126,297.5066096420623,416.6781810480269,5.101787075725445
6.66040224619846e-07,0.08419523904780957,298.03777768687104,416.6781810480269,5.101787075725445
6.669517153808512e-07,0.08431046209241849,298.15142710104334,416.6781810480269,5.101787075725445
6.687746969028617e-07,0.08454090818163633,298.3785443691562,416.6781810480269,5.101787075725445
6.702938481712038e-07,0.08473294658931786,298.5676243815089,416.6781810480269,5.101787075725445
6.731802355810539e-07,0.08509781956391278,298.9264166075319,416.6781810480269,5.101787075725445
6.745474717225618e-07,0.08527065413082617,299.09616136710434,416.6781810480269,5.101787075725445
6.824470583179407e-07,0.08626925385077015,300.07429430199346,416.6781810480269,5.101787075725445
6.89738984405983e-07,0.08719103820764153,300.9732741226085,416.6781810480269,5.101787075725445
6.923215415621647e-07,0.08751750350070014,301.29077298289684,416.6781810480269,5.101787075725445
6.938406928305067e-07,0.08770954190838168,301.477321254503,416.6781810480269,5.101787075725445
7.015883642990516e-07,0.08868893778755751,302.426250923335,416.6781810480269,5.101787075725445
7.035632609478963e-07,0.08893858771754351,302.6674802210697,416.6781810480269,5.101787075725445
7.05538157596741e-07,0.0891882376475295,302.9084455826618,416.6781810480269,5.101787075725445
7.06905393738249e-07,0.0893610722144429,303.0751136824463,416.6781810480269,5.101787075725445
7.09032205513928e-07,0.08962992598519705,303.3341255041743,416.6781810480269,5.101787075725445
7.100956114017675e-07,0.08976435287057412,303.4635177762094,416.6781810480269,5.101787075725445
7.14045404699457e-07,0.09026365273054611,303.94345744641515,416.6781810480269,5.101787075725445
7.16172216475136e-07,0.09053250650130026,304.2014575977514,416.6781810480269,5.101787075725445
7.22704566929007e-07,0.09135827165433087,304.9920246762579,416.6781810480269,5.101787075725445
7.233122274363438e-07,0.09143508701740348,305.0654238318464,416.6781810480269,5.101787075725445
7.331867106805677e-07,0.09268333666733347,306.25480993480977,416.6781810480269,5.101787075725445
7.34098201441573e-07,0.0927985597119424,306.3642835086495,416.6781810480269,5.101787075725445
7.388075703734335e-07,0.09339387877575515,306.92905468741384,416.6781810480269,5.101787075725445
7.395671460076046e-07,0.09348989797959592,307.0200151616996,416.6781810480269,5.101787075725445
7.410862972759466e-07,0.09368193638727745,307.20182688109793,416.6781810480269,5.101787075725445
7.44124599812631e-07,0.09406601320264053,307.5650148530718,416.6781810480269,5.101787075725445
7.489858838713257e-07,0.09468053610722145,308.144914978397,416.6781810480269,5.101787075725445
7.518722712811758e-07,0.09504540908181637,308.4885361779973,416.6781810480269,5.101787075725445
7.533914225495179e-07,0.0952374474894979,308.6691827804649,416.6781810480269,5.101787075725445
7.565816402130363e-07,0.09564072814562913,309.04807889244324,416.6781810480269,5.101787075725445
7.579488763545443e-07,0.09581356271254252,309.21027214279434,416.6781810480269,5.101787075725445
7.640254814279128e-07,0.09658171634326866,309.92975495384616,416.6781810480269,5.101787075725445
7.647850570620838e-07,0.09667773554710943,310.019533124205,416.6781810480269,5.101787075725445
7.66304208330426e-07,0.09686977395479096,310.1989852080824,416.6781810480269,5.101787075725445
7.72076983150126e-07,0.0975995199039808,310.8796415118139,416.6781810480269,5.101787075725445
7.725327285306286e-07,0.09765713142628527,310.93329285610196,416.6781810480269,5.101787075725445
7.735961344184681e-07,0.09779155831166234,311.0584313452472,416.6781810480269,5.101787075725445
7.740518797989708e-07,0.0978491698339668,311.1120415874088,416.6781810480269,5.101787075725445
7.781535882234945e-07,0.09836767353470695,311.5939810771036,416.6781810480269,5.101787075725445
7.811918907601787e-07,0.09875175035007001,311.95033479705376,416.6781810480269,5.101787075725445
7.831667874090234e-07,0.09900140028005601,312.1816748926603,416.6781810480269,5.101787075725445
7.860531748188735e-07,0.09936627325465093,312.5193785072413,416.6781810480269,5.101787075725445
7.893953076092262e-07,0.09978875775155031,312.9098001493976,416.6781810480269,5.101787075725445
7.896991378628946e-07,0.09982716543308662,312.9452610288878,416.6781810480269,5.101787075725445