File: datasets/aisi_316_L/data/M1/valid_31.csv
Time(s),Strain(%),Stress(MPa),Temp(C),Log_SR(s-1)
0.0,0.0,0.0,352.62058705165936,-3.2598244057412824
0.002910344423299209,1.6e-06,0.27721097499999997,352.62058705165936,-3.2598244057412824
0.017462066539795255,9.6e-06,1.66326585,352.62058705165936,-3.2598244057412824
0.059662060677633785,3.28e-05,5.682824987499999,352.62058705165936,-3.2598244057412824
0.08003447164072824,4.4e-05,7.623301812499999,352.62058705165936,-3.2598244057412824
0.125144810201866,6.879999999999999e-05,11.920071924999998,352.62058705165936,-3.2598244057412824
0.14988273779990927,8.24e-05,14.2763652125,352.62058705165936,-3.2598244057412824
0.18335169866785017,0.0001008,17.464291425,352.62058705165936,-3.2598244057412824
0.1920827319377478,0.00010559999999999999,18.29592435,352.62058705165936,-3.2598244057412824
0.21827583174744067,0.00011999999999999999,20.790823125,352.62058705165936,-3.2598244057412824
0.2270068650173383,0.0001248,21.62245605,352.62058705165936,-3.2598244057412824
0.2619309980969288,0.000144,24.94898775,352.62058705165936,-3.2598244057412824
0.2924896145415705,0.0001608,27.8597029875,352.62058705165936,-3.2598244057412824
0.3317792642561098,0.0001824,31.602051149999998,352.62058705165936,-3.2598244057412824
0.3870758082987948,0.0002128,36.869059675,352.62058705165936,-3.2598244057412824
0.4118137358968381,0.0002264,39.2253529625,352.62058705165936,-3.2598244057412824
0.452558557823027,0.0002488,43.1063066125,352.62058705165936,-3.2598244057412824
0.4641999355162238,0.00025519999999999997,44.215150512499996,352.62058705165936,-3.2598244057412824
0.5034895852307631,0.0002768,47.957498675000004,352.62058705165936,-3.2598244057412824
0.5253171684055072,0.00028879999999999997,50.036580987499995,352.62058705165936,-3.2598244057412824
0.5442344071569521,0.0002992,51.838452325,352.62058705165936,-3.2598244057412824
0.5602413014850978,0.000308,53.3631126875,352.62058705165936,-3.2598244057412824
0.5966206067763379,0.000328,56.828249875,352.62058705165936,-3.2598244057412824
0.6038964678345858,0.000332,57.5212773125,352.62058705165936,-3.2598244057412824
0.6213585343743812,0.0003416,59.1845431625,352.62058705165936,-3.2598244057412824
0.6490068063957236,0.0003568,61.818047425,352.62058705165936,-3.2598244057412824
0.6606481840889205,0.0003632,62.926891325,352.62058705165936,-3.2598244057412824
0.6853861116869637,0.0003768,65.2831846125,352.62058705165936,-3.2598244057412824
0.6970274893801606,0.0003832,66.3920285125,352.62058705165936,-3.2598244057412824
0.7043033504384085,0.0003872,67.08505595,352.62058705165936,-3.2598244057412824
0.7406826557296486,0.0004072,70.5501931375,352.62058705165936,-3.2598244057412824
0.7785171332325385,0.000428,74.1539358125,352.62058705165936,-3.2598244057412824
0.8061654052538809,0.0004432,76.78744007499999,352.62058705165936,-3.2598244057412824
0.8294481606402746,0.00045599999999999997,79.005127875,352.62058705165936,-3.2598244057412824
0.8629171215082155,0.0004744,82.1930540875,352.62058705165936,-3.2598244057412824
0.8847447046829596,0.0004864,84.27213640000001,352.62058705165936,-3.2598244057412824
0.9094826322810029,0.0005,86.6284296875,352.62058705165936,-3.2598244057412824
0.9327653876673965,0.0005128,88.8461174875,352.62058705165936,-3.2598244057412824
0.9429515931489438,0.0005184,89.8163559,352.62058705165936,-3.2598244057412824
0.9589584874770894,0.0005272,91.3410162625,352.62058705165936,-3.2598244057412824
0.9676895207469871,0.000532,92.1726491875,352.62058705165936,-3.2598244057412824
1.0462688201760657,0.0005752,99.6573455125,352.62058705165936,-3.2598244057412824
1.0549998534459633,0.00058,100.4889784375,352.62058705165936,-3.2598244057412824
1.059365370080912,0.0005824,100.9047949,352.62058705165936,-3.2598244057412824
1.0899239865255537,0.0005991999999999999,103.81551013749998,352.62058705165936,-3.2598244057412824
1.1306688084517427,0.0006215999999999999,107.6964637875,352.62058705165936,-3.2598244057412824
1.1539515638381366,0.0006344,109.9141515875,352.62058705165936,-3.2598244057412824
1.1888756969177268,0.0006536,113.24068328749999,352.62058705165936,-3.2598244057412824
1.217979141150719,0.0006696,116.0127930375,352.62058705165936,-3.2598244057412824
1.2310756910555654,0.0006768,117.260242425,352.62058705165936,-3.2598244057412824
1.2485377575953607,0.0006864,118.923508275,352.62058705165936,-3.2598244057412824
1.2689101685584552,0.0006975999999999999,120.8639851,352.62058705165936,-3.2598244057412824
1.2980136127914472,0.0007136,123.63609485,352.62058705165936,-3.2598244057412824
1.3285722292360889,0.0007304,126.54681008749999,352.62058705165936,-3.2598244057412824
1.3605860178923803,0.000748,129.5961308125,352.62058705165936,-3.2598244057412824
1.3780480844321754,0.0007576,131.2593966625,352.62058705165936,-3.2598244057412824
1.3896894621253721,0.0007639999999999999,132.36824056249998,352.62058705165936,-3.2598244057412824
1.442075661744758,0.0007928,137.3580381125,352.62058705165936,-3.2598244057412824
1.5148342723272383,0.0008328,144.2883124875,352.62058705165936,-3.2598244057412824
1.5774066774281712,0.0008671999999999999,150.24834844999998,352.62058705165936,-3.2598244057412824
1.5905032273330177,0.0008744,151.4957978375,352.62058705165936,-3.2598244057412824
1.6108756382961122,0.0008856,153.43627466249998,352.62058705165936,-3.2598244057412824
1.6166963271427106,0.0008887999999999999,153.9906966125,352.62058705165936,-3.2598244057412824
1.6399790825291043,0.0009015999999999999,154.62898930833464,352.62058705165936,-3.2598244057412824
1.6792687322436437,0.0009232,154.74190942544905,352.62058705165936,-3.2598244057412824
1.7171032097465333,0.000944,154.84967742073644,352.62058705165936,-3.2598244057412824
1.752027342826124,0.0009632,154.94833641855104,352.62058705165936,-3.2598244057412824
1.781130787059116,0.0009792,155.02996769564027,352.62058705165936,-3.2598244057412824
1.7942273369639623,0.0009864,155.06653188452887,352.62058705165936,-3.2598244057412824
1.8553445698532456,0.0010199999999999999,155.23580713965336,352.62058705165936,-3.2598244057412824
1.865530775334793,0.0010256,155.26380689709168,352.62058705165936,-3.2598244057412824
1.894634219567785,0.0010416,155.34347953317203,352.62058705165936,-3.2598244057412824
1.9091859416842811,0.0010496,155.38313675765806,352.62058705165936,-3.2598244057412824
1.9397445581289228,0.0010664,155.46603525785588,352.62058705165936,-3.2598244057412824
1.957206624668718,0.001076,155.51317713041647,352.62058705165936,-3.2598244057412824
1.9688480023619148,0.0010823999999999999,155.54451394819532,352.62058705165936,-3.2598244057412824
1.9848548966900603,0.0010911999999999999,155.5874843374917,352.62058705165936,-3.2598244057412824
1.9921307577483085,0.0010952,155.60697163422554,352.62058705165936,-3.2598244057412824
2.0066824798648044,0.0011032,155.6458631539944,352.62058705165936,-3.2598244057412824
2.0590686794841906,0.001132,155.78497100375816,352.62058705165936,-3.2598244057412824
2.0677997127540877,0.0011367999999999999,155.80802079076372,352.62058705165936,-3.2598244057412824
2.0765307460239857,0.0011416,155.83103265214808,352.62058705165936,-3.2598244057412824
2.0969031569870804,0.0011528,155.88458074678684,352.62058705165936,-3.2598244057412824
2.123096256796773,0.0011672,155.9531311031039,352.62058705165936,-3.2598244057412824
2.185668661897706,0.0012016,156.11556874317088,352.62058705165936,-3.2598244057412824
2.219137622765647,0.00122,156.20170900275946,352.62058705165936,-3.2598244057412824
2.238054861517092,0.0012304,156.25017282346403,352.62058705165936,-3.2598244057412824
2.277344511231631,0.0012519999999999999,156.35032093434464,352.62058705165936,-3.2598244057412824
2.2933514055597763,0.0012607999999999999,156.39092855937042,352.62058705165936,-3.2598244057412824
2.339916916332564,0.0012864,156.5084360001378,352.62058705165936,-3.2598244057412824
2.3602893272956584,0.0012975999999999999,156.55955833821685,352.62058705165936,-3.2598244057412824
2.373385877200505,0.0013047999999999998,156.592331847295,352.62058705165936,-3.2598244057412824
2.3864824271053515,0.001312,156.62503490142467,352.62058705165936,-3.2598244057412824
2.431592765666489,0.0013368,156.73714686835396,352.62058705165936,-3.2598244057412824
2.4592410376878315,0.001352,156.80545982052985,352.62058705165936,-3.2598244057412824
2.4796134486509263,0.0013632,156.85560417045141,352.62058705165936,-3.2598244057412824
2.523268615000414,0.0013871999999999999,156.9625184887673,352.62058705165936,-3.2598244057412824
2.5625582647149536,0.0014088,157.0581261346157,352.62058705165936,-3.2598244057412824
2.5916617089479455,0.0014248,157.1285784431699,352.62058705165936,-3.2598244057412824
2.619309980969288,0.0014399999999999999,157.19522288566807,352.62058705165936,-3.2598244057412824
2.6294961864508353,0.0014456,157.2197068710316,352.62058705165936,-3.2598244057412824
2.638227219720733,0.0014504,157.24066371763803,352.62058705165936,-3.2598244057412824
2.6833375582818704,0.0014751999999999999,157.34851286050312,352.62058705165936,-3.2598244057412824
2.7400892745362055,0.0015064,157.483194892312,352.62058705165936,-3.2598244057412824
2.7837444408856933,0.0015304,157.58605747039294,352.62058705165936,-3.2598244057412824
2.8244892628118827,0.0015528,157.68149637682058,352.62058705165936,-3.2598244057412824
2.8303099516584806,0.0015559999999999999,157.69508654594128,352.62058705165936,-3.2598244057412824
2.891427184547764,0.0015895999999999998,157.83713137154106,352.62058705165936,-3.2598244057412824
2.903068562240961,0.001596,157.864054255204,352.62058705165936,-3.2598244057412824
2.9161651121458076,0.0016032,157.8942922215602,352.62058705165936,-3.2598244057412824
2.9278064898390044,0.0016095999999999999,157.92112598068627,352.62058705165936,-3.2598244057412824
2.9307168342623036,0.0016112,157.9278279147961,352.62058705165936,-3.2598244057412824
2.9598202784952954,0.0016271999999999999,157.99470511388233,352.62058705165936,-3.2598244057412824
2.977282345035091,0.0016367999999999999,158.03470834218766,352.62058705165936,-3.2598244057412824
3.01802716696128,0.0016592,158.12769504497558,352.62058705165936,-3.2598244057412824
3.0456754389826224,0.0016744,158.1905145008705,352.62058705165936,-3.2598244057412824
3.0529513000408706,0.0016784,158.20700892248468,352.62058705165936,-3.2598244057412824
3.099516810813658,0.001704,158.31221249874136,352.62058705165936,-3.2598244057412824
3.1242547384117008,0.0017176,158.36785109349398,352.62058705165936,-3.2598244057412824
3.1577236992796416,0.001736,158.44285413406794,352.62058705165936,-3.2598244057412824
3.166454732549539,0.0017407999999999998,158.46236907551315,352.62058705165936,-3.2598244057412824
3.198468521205831,0.0017584,158.53374502009723,352.62058705165936,-3.2598244057412824
3.2144754155339768,0.0017672,158.5693284705845,352.62058705165936,-3.2598244057412824
3.2464892041902678,0.0017848,158.64028873167567,352.62058705165936,-3.2598244057412824
3.268316787365012,0.0017967999999999999,158.6885143330086,352.62058705165936,-3.2598244057412824
3.3061512648679017,0.0018176,158.77180887375536,352.62058705165936,-3.2598244057412824
3.3207029869843976,0.0018256,158.80374614655,352.62058705165936,-3.2598244057412824
3.3439857423707915,0.0018384,158.85473248729045,352.62058705165936,-3.2598244057412824
3.362902981122236,0.0018487999999999998,158.89605702151053,352.62058705165936,-3.2598244057412824
3.406558147471724,0.0018728,158.99107686705418,352.62058705165936,-3.2598244057412824
3.4240202140115197,0.0018824,159.0289516905969,352.62058705165936,-3.2598244057412824
3.4749512414192556,0.0019103999999999998,159.13899200415418,352.62058705165936,-3.2598244057412824
3.5055098578638972,0.0019272,159.2047143074775,352.62058705165936,-3.2598244057412824
3.5709926073881295,0.0019632,159.34480011165664,352.62058705165936,-3.2598244057412824
3.5768132962347283,0.0019664,159.35720349529205,352.62058705165936,-3.2598244057412824
3.591365018351224,0.0019744,159.38817756430737,352.62058705165936,-3.2598244057412824
3.616102945949267,0.0019879999999999997,159.44072138567356,352.62058705165936,-3.2598244057412824
3.6277443236424642,0.0019944,159.46539936518138,352.62058705165936,-3.2598244057412824
3.6335650124890626,0.0019976,159.4777267718362,352.62058705165936,-3.2598244057412824
3.7048684508598932,0.0020368,159.62811782684494,352.62058705165936,-3.2598244057412824
3.7383374117278345,0.0020552,159.69831986959346,352.62058705165936,-3.2598244057412824
3.75288913384433,0.0020632,159.72876599536275,352.62058705165936,-3.2598244057412824
3.757254650479279,0.0020656,159.73789085057078,352.62058705165936,-3.2598244057412824
3.7921787835588696,0.0020848,159.81074143045484,352.62058705165936,-3.2598244057412824
3.8125511945219634,0.0020959999999999998,159.853116767751,352.62058705165936,-3.2598244057412824
3.853296016448153,0.0021184,159.93760344105266,352.62058705165936,-3.2598244057412824
3.990082204343216,0.0021936,160.21872301731273,352.62058705165936,-3.2598244057412824
4.013364959729609,0.0022064,160.2661963569888,352.62058705165936,-3.2598244057412824
4.0381028873276525,0.0022199999999999998,160.3165192440941,352.62058705165936,-3.2598244057412824
4.059930470502397,0.002232,160.36082203105204,352.62058705165936,-3.2598244057412824
4.08321322588879,0.0022448,160.407976072085,352.62058705165936,-3.2598244057412824
4.118137358968381,0.002264,160.47851099372937,352.62058705165936,-3.2598244057412824
4.129778736661578,0.0022704,160.5019707419003,352.62058705165936,-3.2598244057412824
4.141420114354775,0.0022768,160.5254047133584,352.62058705165936,-3.2598244057412824
4.16033735310622,0.0022872,160.56343019922875,352.62058705165936,-3.2598244057412824
4.1836201084926135,0.0023,160.6101383537768,352.62058705165936,-3.2598244057412824
4.195261486185809,0.0023063999999999997,160.6334544067872,352.62058705165936,-3.2598244057412824
4.215633897148904,0.0023176,160.6741968742899,352.62058705165936,-3.2598244057412824
4.2432821691702465,0.0023328,160.72936761479392,352.62058705165936,-3.2598244057412824
4.30294422984788,0.0023656,160.84794484118504,352.62058705165936,-3.2598244057412824
4.320406296387676,0.0023752,160.88252884603875,352.62058705165936,-3.2598244057412824
4.337868362927471,0.0023848,160.91705837929527,352.62058705165936,-3.2598244057412824
4.359695946102215,0.0023967999999999997,160.9601441588747,352.62058705165936,-3.2598244057412824
4.372792496007062,0.002404,160.98595524632069,352.62058705165936,-3.2598244057412824
4.390254562546857,0.0024135999999999997,161.0203231804906,352.62058705165936,-3.2598244057412824
4.413537317933251,0.0024264,161.06606427790112,352.62058705165936,-3.2598244057412824
4.435364901107994,0.0024384,161.10886116345736,352.62058705165936,-3.2598244057412824
4.442640762166243,0.0024424,161.12310852843518,352.62058705165936,-3.2598244057412824
4.454282139859439,0.0024487999999999997,161.14588539899262,352.62058705165936,-3.2598244057412824
4.48775110072738,0.0024671999999999997,161.21123993995744,352.62058705165936,-3.2598244057412824
4.503757995055526,0.002476,161.2424292402848,352.62058705165936,-3.2598244057412824
4.528495922653569,0.0024896,161.29054598677067,352.62058705165936,-3.2598244057412824
4.538682128135116,0.0024952,161.31032895645436,352.62058705165936,-3.2598244057412824
4.5605097113098605,0.0025072,161.35266282106966,352.62058705165936,-3.2598244057412824
4.579426950061306,0.0025176,161.3892882913531,352.62058705165936,-3.2598244057412824
4.623082116410793,0.0025415999999999998,161.4735841484442,352.62058705165936,-3.2598244057412824
4.630357977469042,0.0025456,161.48760322172063,352.62058705165936,-3.2598244057412824
4.660916593913683,0.0025624,161.5463897599358,352.62058705165936,-3.2598244057412824
4.690020038146675,0.0025784,161.60223734694281,352.62058705165936,-3.2598244057412824
4.767144165364105,0.0026208,161.74958365167686,352.62058705165936,-3.2598244057412824
4.7918820929621475,0.0026344,161.7966483621029,352.62058705165936,-3.2598244057412824
4.825351053830088,0.0026528,161.8601735980698,352.62058705165936,-3.2598244057412824
4.89228897556597,0.0026896,161.98671088270666,352.62058705165936,-3.2598244057412824
4.901020008835868,0.0026944,162.0031658235548,352.62058705165936,-3.2598244057412824
4.965047586148451,0.0027296,162.12348799676917,352.62058705165936,-3.2598244057412824
4.986875169323195,0.0027416,162.16436840756725,352.62058705165936,-3.2598244057412824
5.050902746635777,0.0027768,162.28388360901133,352.62058705165936,-3.2598244057412824
5.122206185006608,0.002816,162.41628684476305,352.62058705165936,-3.2598244057412824
5.129482046064856,0.00282,162.42975683726627,352.62058705165936,-3.2598244057412824
5.148399284816301,0.0028304,162.4647439910332,352.62058705165936,-3.2598244057412824
5.193509623377439,0.0028552,162.5479731864493,352.62058705165936,-3.2598244057412824
5.213882034340533,0.0028664,162.58546810181954,352.62058705165936,-3.2598244057412824
5.250261339631773,0.0028864,162.652281502826,352.62058705165936,-3.2598244057412824
5.283730300499714,0.0029048,162.71359054145972,352.62058705165936,-3.2598244057412824
5.29682685040456,0.0029119999999999997,162.7375397834395,352.62058705165936,-3.2598244057412824
5.330295811272501,0.0029303999999999997,162.79863871796775,352.62058705165936,-3.2598244057412824
5.384137183103537,0.00296,162.89661529478272,352.62058705165936,-3.2598244057412824
5.433613038299623,0.0029871999999999998,162.98631145660647,352.62058705165936,-3.2598244057412824
5.469992343590863,0.0030072,163.0520614371543,352.62058705165936,-3.2598244057412824
5.512192337728702,0.0030304,163.12811814095065,352.62058705165936,-3.2598244057412824
5.5209233709986,0.0030352,163.14382562110353,352.62058705165936,-3.2598244057412824
5.5543923318665405,0.0030536,163.20394809489537,352.62058705165936,-3.2598244057412824
5.669350936586859,0.0031168,163.40938810490738,352.62058705165936,-3.2598244057412824
5.696999208608202,0.003132,163.4585545901774,352.62058705165936,-3.2598244057412824
5.772668163613981,0.0031736,163.59264192619457,352.62058705165936,-3.2598244057412824
5.784309541307177,0.0031799999999999997,163.61320974754668,352.62058705165936,-3.2598244057412824
5.800316435635324,0.0031888,163.64146416162825,352.62058705165936,-3.2598244057412824
5.92255090141389,0.0032559999999999998,163.85623132587338,352.62058705165936,-3.2598244057412824
5.96038537891678,0.0032768,163.9223556137864,352.62058705165936,-3.2598244057412824
5.99530951199637,0.003296,163.983248271204,352.62058705165936,-3.2598244057412824
6.022957784017713,0.0033112,164.03135690410315,352.62058705165936,-3.2598244057412824
6.0389646783458595,0.00332,164.05916990429031,352.62058705165936,-3.2598244057412824
6.066612950367201,0.0033352,164.10714291622878,352.62058705165936,-3.2598244057412824
6.100081911235143,0.0033536,164.16510157738531,352.62058705165936,-3.2598244057412824
6.117543977774937,0.0033632,164.1952916388666,352.62058705165936,-3.2598244057412824
6.14082673316133,0.0033759999999999997,164.23549282651172,352.62058705165936,-3.2598244057412824
6.162654316336075,0.003388,164.2731274861603,352.62058705165936,-3.2598244057412824
6.191757760569067,0.003404,164.32322626420276,352.62058705165936,-3.2598244057412824
6.226681893648658,0.0034232,164.38322373485101,352.62058705165936,-3.2598244057412824
6.236868099130205,0.0034287999999999996,164.4006982571347,352.62058705165936,-3.2598244057412824
6.2528749934583505,0.0034376,164.42813574936727,352.62058705165936,-3.2598244057412824
6.274702576633095,0.0034495999999999997,164.4655064070517,352.62058705165936,-3.2598244057412824
6.295074987596189,0.0034608,164.5003399709041,352.62058705165936,-3.2598244057412824
6.305261193077736,0.0034663999999999997,164.51774026409527,352.62058705165936,-3.2598244057412824
6.335819809522378,0.0034831999999999997,164.56987548434134,352.62058705165936,-3.2598244057412824
6.351826703850524,0.003492,164.59714526609773,352.62058705165936,-3.2598244057412824
6.369288770390319,0.0035015999999999997,164.62686357044706,352.62058705165936,-3.2598244057412824
6.395481870200012,0.003516,164.67138151725925,352.62058705165936,-3.2598244057412824
6.410033592316508,0.003524,164.6960829831801,352.62058705165936,-3.2598244057412824
6.446412897607748,0.003544,164.7577411609812,352.62058705165936,-3.2598244057412824
6.463874964147543,0.0035535999999999996,164.7872888717225,352.62058705165936,-3.2598244057412824
6.498799097227134,0.0035727999999999997,164.84629106612772,352.62058705165936,-3.2598244057412824
6.523537024825178,0.0035864,164.88800949301458,352.62058705165936,-3.2598244057412824
6.542454263576622,0.0035968,164.91987020264466,352.62058705165936,-3.2598244057412824
6.603571496465905,0.0036303999999999998,165.02256012460188,352.62058705165936,-3.2598244057412824
6.615212874159102,0.0036368,165.04207801421208,352.62058705165936,-3.2598244057412824
6.663233557143539,0.0036631999999999997,165.1224481221263,352.62058705165936,-3.2598244057412824
6.673419762625087,0.0036688,165.1394672506824,352.62058705165936,-3.2598244057412824
6.6937921735881805,0.0036799999999999997,165.1734751443234,352.62058705165936,-3.2598244057412824
6.701068034646429,0.0036839999999999998,165.18561103500193,352.62058705165936,-3.2598244057412824
6.703978379069728,0.0036856,165.19046395223006,352.62058705165936,-3.2598244057412824
6.718530101186224,0.0036936,165.21471622478106,352.62058705165936,-3.2598244057412824
6.743268028784267,0.0037072,165.25589812549572,352.62058705165936,-3.2598244057412824
6.747633545419216,0.0037096,165.2631593992651,352.62058705165936,-3.2598244057412824
6.80729560609685,0.0037424,165.36221390168225,352.62058705165936,-3.2598244057412824
6.813116294943448,0.0037456,165.37185959248748,352.62058705165936,-3.2598244057412824
6.848040428023039,0.0037648,165.42966639070724,352.62058705165936,-3.2598244057412824
6.894605938795826,0.0037903999999999998,165.50656358888614,352.62058705165936,-3.2598244057412824
6.909157660912323,0.0037984,165.53055239009862,352.62058705165936,-3.2598244057412824
6.941171449568614,0.003816,165.58325850278212,352.62058705165936,-3.2598244057412824
6.957178343896759,0.0038247999999999997,165.60957600126352,352.62058705165936,-3.2598244057412824
6.977550754859854,0.003836,165.6430368709725,352.62058705165936,-3.2598244057412824
7.000833510246247,0.0038488,165.68123124558218,352.62058705165936,-3.2598244057412824
7.009564543516145,0.0038536,165.69554136021415,352.62058705165936,-3.2598244057412824
7.063405915347181,0.0038832,165.7836339500181,352.62058705165936,-3.2598244057412824
7.1012403928500705,0.003904,165.8453802478631,352.62058705165936,-3.2598244057412824
7.109971426119968,0.0039088,165.85961115757678,352.62058705165936,-3.2598244057412824
7.195826586607294,0.0039559999999999994,165.9991873164357,352.62058705165936,-3.2598244057412824
7.243847269591731,0.0039824,166.07697207823944,352.62058705165936,-3.2598244057412824
7.264219680554826,0.0039936,166.10991088938636,352.62058705165936,-3.2598244057412824
7.380654416158377,0.004057611522304461,166.29747976737383,352.62058705165936,-3.2598244057412824
8.04434568292395,0.00442248449689938,167.34539008266557,352.62058705165936,-3.2598244057412824
8.952554784813682,0.004921784356871375,168.72624147490134,352.62058705165936,-3.2598244057412824
9.616246051579255,0.005286657331466294,169.7009700282768,352.62058705165936,-3.2598244057412824
11.188146420234558,0.006150830166033207,171.91030798706552,352.62058705165936,-3.2598244057412824
11.712113209786326,0.006438887777555511,172.61936260156418,352.62058705165936,-3.2598244057412824
12.236079999338093,0.006726945389077816,173.31614843657857,352.62058705165936,-3.2598244057412824
12.969633504710568,0.007130226045209041,174.27240311208956,352.62058705165936,-3.2598244057412824
13.598393652172689,0.007475895179035807,175.07537436632688,352.62058705165936,-3.2598244057412824
13.738118129386494,0.007552710542108421,175.2518305369754,352.62058705165936,-3.2598244057412824
14.611396111972775,0.008032806561312262,176.33923247605892,352.62058705165936,-3.2598244057412824
16.18329648062808,0.008896979395879176,178.23469367349756,352.62058705165936,-3.2598244057412824
17.58054125276613,0.009665133026605321,179.86000539732171,352.62058705165936,-3.2598244057412824
18.80313042838692,0.010337267453490697,181.2412305078013,352.62058705165936,-3.2598244057412824
19.536683933759395,0.010740548109621925,182.05315529431638,352.62058705165936,-3.2598244057412824
19.78120176888355,0.010874974994998999,182.3211431034257,352.62058705165936,-3.2598244057412824
20.34009967773877,0.011182236447289457,182.9288819315517,352.62058705165936,-3.2598244057412824
20.479824154952574,0.011259051810362072,183.07979468337768,352.62058705165936,-3.2598244057412824
21.283239898931956,0.011700740148029607,183.93987494816724,352.62058705165936,-3.2598244057412824
22.435966835945845,0.012334466893378675,185.15210397791432,352.62058705165936,-3.2598244057412824
23.099658102711416,0.012699339867973595,185.83903095307983,352.62058705165936,-3.2598244057412824
23.798280488780442,0.013083416683336667,186.55384714454695,352.62058705165936,-3.2598244057412824
25.125663022311585,0.013813162632526505,187.88984192705934,352.62058705165936,-3.2598244057412824
25.544836453953,0.01404360872174435,188.3059776991952,352.62058705165936,-3.2598244057412824
25.719492050470258,0.014139627925585117,188.47858062161393,352.62058705165936,-3.2598244057412824
26.69756339096689,0.01467733546709342,189.43683985853465,352.62058705165936,-3.2598244057412824
27.675634731463525,0.015215043008601721,190.3815014723855,352.62058705165936,-3.2598244057412824
28.12973928240839,0.015464692938587718,190.81565960730288,352.62058705165936,-3.2598244057412824
28.583843833353257,0.015714342868573716,191.2470927908291,352.62058705165936,-3.2598244057412824
29.247535100118828,0.016079215843168633,191.8728712749331,352.62058705165936,-3.2598244057412824
29.631777412456792,0.016290458091618325,192.2326326485594,352.62058705165936,-3.2598244057412824
30.57491763364997,0.01680896179235847,193.10805487313294,352.62058705165936,-3.2598244057412824
31.168746661808648,0.017135427085417085,193.65384686152416,352.62058705165936,-3.2598244057412824
31.4132644969328,0.01726985397079416,193.87740421993874,352.62058705165936,-3.2598244057412824
31.937231286484568,0.01755791158231646,194.3541831752439,352.62058705165936,-3.2598244057412824
32.635853672553594,0.017941988397679534,194.98516976809594,352.62058705165936,-3.2598244057412824
33.020095984891555,0.018153230646129226,195.32996621069196,352.62058705165936,-3.2598244057412824
34.347478518422704,0.018882976595319064,196.50922363277218,352.62058705165936,-3.2598244057412824
35.08103202379518,0.019286257251450292,197.15328841990458,352.62058705165936,-3.2598244057412824
35.36048097822279,0.01943988797759552,197.39726214792563,352.62058705165936,-3.2598244057412824
36.68786351175393,0.020169633926785356,198.5460218590903,352.62058705165936,-3.2598244057412824
37.59607261364366,0.02066893378675735,199.32269062641146,352.62058705165936,-3.2598244057412824
37.770728210160925,0.02076495299059812,199.4712074407022,352.62058705165936,-3.2598244057412824
38.22483276110579,0.021014602920584116,199.85610307660772,352.62058705165936,-3.2598244057412824
38.99331738578171,0.021437087417483496,200.50342698151056,352.62058705165936,-3.2598244057412824
39.27276634020932,0.021590718143628725,200.73758143560923,352.62058705165936,-3.2598244057412824
40.530286635133564,0.022282056411282256,201.7833372281046,352.62058705165936,-3.2598244057412824
40.600148873740466,0.022320464092818564,201.8410609042305,352.62058705165936,-3.2598244057412824
41.7179446914509,0.02293498699739948,202.75943513016284,352.62058705165936,-3.2598244057412824
41.892600287968165,0.02303100620124025,202.90205958775772,352.62058705165936,-3.2598244057412824
42.8706716284648,0.02356871374274855,203.69651200274492,352.62058705165936,-3.2598244057412824
43.39463841801656,0.023856771354270855,204.1192022572486,352.62058705165936,-3.2598244057412824
45.07133214458222,0.02477855571114223,205.45862676021898,352.62058705165936,-3.2598244057412824
45.45557445692018,0.024989797959591917,205.76282432856596,352.62058705165936,-3.2598244057412824
48.110339523982475,0.026449289857971594,207.83780923642308,352.62058705165936,-3.2598244057412824
48.42471959771354,0.02662212442488498,208.0805380822775,352.62058705165936,-3.2598244057412824
48.634306313534246,0.0267373474694939,208.2420159710562,352.62058705165936,-3.2598244057412824
49.19320422238947,0.02704460892178436,208.6713023552082,352.62058705165936,-3.2598244057412824
49.64730877333433,0.027294258851770354,209.0186986447362,352.62058705165936,-3.2598244057412824
51.00962242616893,0.028043208641728348,210.0535271875975,352.62058705165936,-3.2598244057412824
51.39386473850689,0.028254450890178036,210.3434458204612,352.62058705165936,-3.2598244057412824
52.30207384039662,0.02875375075015003,211.0253681601546,352.62058705165936,-3.2598244057412824
52.93083398785874,0.029099419883976796,211.4947652952071,352.62058705165936,-3.2598244057412824
53.73424973183812,0.029541108221644328,212.0913979438374,352.62058705165936,-3.2598244057412824
55.55066793561758,0.030539707941588317,213.42762830846067,352.62058705165936,-3.2598244057412824
55.79518577074174,0.030674134826965394,213.6061952216993,352.62058705165936,-3.2598244057412824
55.93491024795555,0.03075095019003801,213.70809642842312,352.62058705165936,-3.2598244057412824
56.07463472516935,0.030827765553110623,213.80989840983094,352.62058705165936,-3.2598244057412824
56.947912707755634,0.031307861572314466,214.44393395643897,352.62058705165936,-3.2598244057412824
57.681466213128104,0.03171114222844569,214.97359877441897,352.62058705165936,-3.2598244057412824
58.13557076407297,0.031960792158431686,215.30017031984954,352.62058705165936,-3.2598244057412824
58.83419315014199,0.03234486897379476,215.80065216433252,352.62058705165936,-3.2598244057412824
59.46295329760412,0.03269053810762153,216.24910759769693,352.62058705165936,-3.2598244057412824
59.74240225203173,0.03284416883376676,216.44782710178995,352.62058705165936,-3.2598244057412824
60.09171344506624,0.03303620724144829,216.695717433935,352.62058705165936,-3.2598244057412824
61.7684071716319,0.033957991598319665,217.8778557176804,352.62058705165936,-3.2598244057412824
62.432098438397475,0.034322864572914585,218.3423199239609,352.62058705165936,-3.2598244057412824
63.514963136804454,0.03491818363672734,219.0960171214747,352.62058705165936,-3.2598244057412824
64.14372328426657,0.035263852770554105,219.53134798024172,352.62058705165936,-3.2598244057412824
64.42317223869418,0.035417483496699334,219.72429383046537,352.62058705165936,-3.2598244057412824
64.66769007381835,0.03555191038207642,219.8928538513661,352.62058705165936,-3.2598244057412824
65.261519101977,0.03587837567513502,220.30118238802677,352.62058705165936,-3.2598244057412824
66.58890163550815,0.03660812162432486,221.2087132905705,352.62058705165936,-3.2598244057412824
66.83341947063234,0.03674254850970195,221.37511765067543,352.62058705165936,-3.2598244057412824
67.49711073739788,0.037107421484296854,221.82559406336657,352.62058705165936,-3.2598244057412824
68.02107752694967,0.03739547909581917,222.1800142321775,352.62058705165936,-3.2598244057412824
68.37038871998418,0.0375875175035007,222.41570300300202,352.62058705165936,-3.2598244057412824
69.45325341839116,0.03818283656731346,223.14337138664948,352.62058705165936,-3.2598244057412824
69.80256461142568,0.038374874974995005,223.377157484541,352.62058705165936,-3.2598244057412824
69.94228908863947,0.03845169033806761,223.47054411396567,352.62058705165936,-3.2598244057412824
70.57104923610159,0.038797359471894374,223.889886813766,352.62058705165936,-3.2598244057412824
70.8504981905292,0.0389509901980396,224.07579336890805,352.62058705165936,-3.2598244057412824
71.86350065032929,0.03950790158031606,224.74732063635827,352.62058705165936,-3.2598244057412824
72.10801848545346,0.03964232846569314,224.90885909162603,352.62058705165936,-3.2598244057412824
72.4223985591845,0.039815163032606515,225.116237829356,352.62058705165936,-3.2598244057412824
73.26074542246732,0.0402760552110422,225.66753854140077,352.62058705165936,-3.2598244057412824
73.5751254961984,0.04044888977795559,225.87364129158271,352.62058705165936,-3.2598244057412824
73.78471221201912,0.040564112822564516,226.01085234818567,352.62058705165936,-3.2598244057412824
74.8675769104261,0.04115943188637727,226.7173691476334,352.62058705165936,-3.2598244057412824
75.21688810346059,0.041351470294058806,226.94442615773764,352.62058705165936,-3.2598244057412824
76.12509720535034,0.04185077015403081,227.53285808130255,352.62058705165936,-3.2598244057412824
78.11617100564705,0.04294538907781556,228.81338527862923,352.62058705165936,-3.2598244057412824
79.19903570405405,0.04354070814162833,229.5044657477051,352.62058705165936,-3.2598244057412824
79.93258920942652,0.043943988797759556,229.97052457270576,352.62058705165936,-3.2598244057412824
80.49148711828174,0.044251250250050014,230.32449825749887,352.62058705165936,-3.2598244057412824
81.53942069738527,0.04482736547309461,230.9856259823178,352.62058705165936,-3.2598244057412824
82.27297420275777,0.04523064612922585,231.4464450985392,352.62058705165936,-3.2598244057412824
83.94966792932343,0.046152430486097226,232.49377065384562,352.62058705165936,-3.2598244057412824
84.19418576444757,0.046286857371474296,232.6458212669344,352.62058705165936,-3.2598244057412824
85.3818438207649,0.04693978795759152,233.38191707204254,352.62058705165936,-3.2598244057412824
85.87087949101323,0.04720864172834567,233.68385340576287,352.62058705165936,-3.2598244057412824
86.6742952349926,0.0476503300660132,234.17843987270012,352.62058705165936,-3.2598244057412824
86.9537441894202,0.04780396079215843,234.3500504230587,352.62058705165936,-3.2598244057412824
87.75715993339959,0.04824564912982597,234.8422367024885,352.62058705165936,-3.2598244057412824
88.49071343877208,0.048648929785957196,235.2900915718585,352.62058705165936,-3.2598244057412824
88.87495575111004,0.04886017203440689,235.52410424714333,352.62058705165936,-3.2598244057412824
89.85302709160666,0.04939787957591518,236.1179993604256,352.62058705165936,-3.2598244057412824
90.65644283558602,0.04983956791358271,236.60395794479416,352.62058705165936,-3.2598244057412824
90.9009606707102,0.049973994798959795,236.75152462493918,352.62058705165936,-3.2598244057412824
91.84410089190338,0.050492498499699945,237.31926613343177,352.62058705165936,-3.2598244057412824
92.57765439727586,0.05089577915583117,237.75927235560633,352.62058705165936,-3.2598244057412824
92.78724111309657,0.051011002200440095,237.88473840418183,352.62058705165936,-3.2598244057412824
94.0447614080208,0.05170234046809362,238.63522670236569,352.62058705165936,-3.2598244057412824
94.81324603269674,0.052124824964993,239.09193212124438,352.62058705165936,-3.2598244057412824
95.44200618015886,0.052470494098819764,239.4645273417653,352.62058705165936,-3.2598244057412824
97.04883766811761,0.053353870774154835,240.41239188420272,352.62058705165936,-3.2598244057412824
98.76046251398671,0.054294858971794355,241.4153660037435,352.62058705165936,-3.2598244057412824
99.28442930353849,0.05458291658331667,241.72104060439963,352.62058705165936,-3.2598244057412824
99.9131894510006,0.05492858571714343,242.08702091539905,352.62058705165936,-3.2598244057412824
100.61181183706962,0.055312662532506496,242.49261385603805,352.62058705165936,-3.2598244057412824
100.71660519497998,0.05537027405481096,242.55335793144152,352.62058705165936,-3.2598244057412824
100.9261919108007,0.055485497099419884,242.67477218550692,352.62058705165936,-3.2598244057412824
102.28850556363528,0.05623444688937787,243.46158154420687,352.62058705165936,-3.2598244057412824
103.19671466552502,0.056733746749349875,243.9838518396752,352.62058705165936,-3.2598244057412824
103.26657690413192,0.05677215443088618,244.0239520759243,352.62058705165936,-3.2598244057412824
104.10492376741476,0.057233046609321866,244.5043325947766,352.62058705165936,-3.2598244057412824
104.55902831835962,0.05748269653930786,244.76390868238045,352.62058705165936,-3.2598244057412824
105.18778846582173,0.057828365673134624,245.12259705733706,352.62058705165936,-3.2598244057412824
105.5720307781597,0.058039607921584316,245.34138390361798,352.62058705165936,-3.2598244057412824
106.16585980631838,0.05836607321464293,245.67889917222794,352.62058705165936,-3.2598244057412824
106.89941331169085,0.05876935387077416,246.09481501114047,352.62058705165936,-3.2598244057412824
107.14393114681499,0.05890378075615123,246.23320607839764,352.62058705165936,-3.2598244057412824
108.47131368034616,0.05963352670534107,246.9823335683498,352.62058705165936,-3.2598244057412824
108.82062487338065,0.0598255651130226,247.17887708986515,352.62058705165936,-3.2598244057412824
109.34459166293244,0.060113622724544916,247.47323165664258,352.62058705165936,-3.2598244057412824
111.09114762810499,0.061073814762952594,248.45046466049845,352.62058705165936,-3.2598244057412824
111.5103210597464,0.06130426085217043,248.68410675812163,352.62058705165936,-3.2598244057412824
112.6630479967603,0.061937987597519506,249.3248630087566,352.62058705165936,-3.2598244057412824
114.33974172332596,0.06285977195439088,250.2523265654762,352.62058705165936,-3.2598244057412824
115.14315746730533,0.06330146029205841,250.6948551518845,352.62058705165936,-3.2598244057412824
115.45753754103639,0.0634742948589718,250.86769050652836,352.62058705165936,-3.2598244057412824
116.29588440431922,0.06393518703740748,251.32768983315677,352.62058705165936,-3.2598244057412824
117.06436902899516,0.06435767153430687,251.74822107096796,352.62058705165936,-3.2598244057412824
117.76299141506416,0.06474174834966993,252.12958884568383,352.62058705165936,-3.2598244057412824
118.28695820461593,0.06502980596119223,252.41503590158766,352.62058705165936,-3.2598244057412824
118.5314760397401,0.06516423284656932,252.54807573001142,352.62058705165936,-3.2598244057412824
119.33489178371947,0.06560592118423685,252.98445492725648,352.62058705165936,-3.2598244057412824
119.47461626093329,0.06568273654730947,253.06022985251985,352.62058705165936,-3.2598244057412824
120.41775648212648,0.06620124024804962,253.57080961908719,352.62058705165936,-3.2598244057412824
120.5225498400368,0.06625885177035407,253.62744426829292,352.62058705165936,-3.2598244057412824
121.46569006123002,0.06677735547109423,254.1362948084827,352.62058705165936,-3.2598244057412824
121.57048341914034,0.06683496699339868,254.19273847861243,352.62058705165936,-3.2598244057412824
122.30403692451284,0.06723824764952992,254.58731422264376,352.62058705165936,-3.2598244057412824
122.65334811754735,0.06743028605721145,254.77488294131732,352.62058705165936,-3.2598244057412824
123.63141945804398,0.06796799359871974,255.29897025400518,352.62058705165936,-3.2598244057412824
125.09852646878892,0.0687745549109822,256.0820794926075,352.62058705165936,-3.2598244057412824
125.6224932583407,0.06906261252250451,256.36089227539213,352.62058705165936,-3.2598244057412824
126.60056459883732,0.0696003200640128,256.8801323408422,352.62058705165936,-3.2598244057412824
127.01973803047875,0.06983076615323065,257.102184616444,352.62058705165936,-3.2598244057412824
128.66150063774094,0.07073334666933387,257.96915160491704,352.62058705165936,-3.2598244057412824
129.25532966589964,0.07105981196239249,258.2816715177106,352.62058705165936,-3.2598244057412824
131.2813345854998,0.0721736347269454,259.343726882109,352.62058705165936,-3.2598244057412824
131.7703702557481,0.07244248849769955,259.59912504885114,352.62058705165936,-3.2598244057412824
132.08475032947916,0.07261532306461292,259.76311440133287,352.62058705165936,-3.2598244057412824
133.62171957883103,0.07346029205841169,260.5626591961403,352.62058705165936,-3.2598244057412824
134.04089301047242,0.07369073814762953,260.78009335651694,352.62058705165936,-3.2598244057412824
134.73951539654146,0.0740748149629926,261.1418952491912,352.62058705165936,-3.2598244057412824
135.54293114052084,0.07451650330066013,261.55706419945017,352.62058705165936,-3.2598244057412824
136.4162091231071,0.07499659931986398,262.00724775551214,352.62058705165936,-3.2598244057412824
136.90524479335545,0.07526545309061813,262.2588595823672,352.62058705165936,-3.2598244057412824
137.25455598638996,0.07545749149829967,262.4383677577331,352.62058705165936,-3.2598244057412824
137.95317837245895,0.07584156831366273,262.79685049102204,352.62058705165936,-3.2598244057412824
138.82645635504525,0.07632166433286658,263.2439598176213,352.62058705165936,-3.2598244057412824
139.73466545693498,0.07682096419283857,263.7077915002631,352.62058705165936,-3.2598244057412824
139.80452769554188,0.07685937187437487,263.7434220877882,352.62058705165936,-3.2598244057412824
140.18877000787984,0.07707061412282457,263.93926633661056,352.62058705165936,-3.2598244057412824
140.60794343952128,0.07730106021204242,264.1526760030171,352.62058705165936,-3.2598244057412824
140.95725463255576,0.07749309861972395,264.33032792148396,352.62058705165936,-3.2598244057412824
141.97025709235587,0.0780500100020004,264.8445501214748,352.62058705165936,-3.2598244057412824
142.84353507494214,0.07853010602120425,265.2866976711893,352.62058705165936,-3.2598244057412824
143.78667529613534,0.0790486097219444,265.763034614051,352.62058705165936,-3.2598244057412824
144.27571096638363,0.07931746349269854,266.0095443259288,352.62058705165936,-3.2598244057412824
144.76474663663194,0.0795863172634527,266.2557283811763,352.62058705165936,-3.2598244057412824
144.86953999454232,0.07964392878575716,266.30843988568677,352.62058705165936,-3.2598244057412824
145.5332312613079,0.08000880176035208,266.6419347514786,352.62058705165936,-3.2598244057412824
145.7428179771286,0.080124024804961,266.74712562212113,352.62058705165936,-3.2598244057412824
146.0222669315562,0.08027765553110623,266.8872883915026,352.62058705165936,-3.2598244057412824
146.2318536473769,0.08039287857571514,266.99234182740736,352.62058705165936,-3.2598244057412824
146.51130260180452,0.08054650930186037,267.13232177650946,352.62058705165936,-3.2598244057412824
146.86061379483903,0.08073854770954192,267.3071503714541,352.62058705165936,-3.2598244057412824
147.59416730021152,0.08114182836567314,267.6737634227039,352.62058705165936,-3.2598244057412824
149.09620543025991,0.08196759351870375,268.42223748618,352.62058705165936,-3.2598244057412824
151.01741699194972,0.0830238047609522,269.3753156346499,352.62058705165936,-3.2598244057412824
152.3098684061774,0.08373434686937388,270.0138181334764,352.62058705165936,-3.2598244057412824
152.76397295712226,0.08398399679935988,270.23765475496606,352.62058705165936,-3.2598244057412824
153.88176877483272,0.08459851970394079,270.78753451591876,352.62058705165936,-3.2598244057412824
154.5454600415983,0.08496339267853571,271.1132885978374,352.62058705165936,-3.2598244057412824
155.6981869786122,0.08559711942388479,271.67777826035433,352.62058705165936,-3.2598244057412824
156.3968093646812,0.08598119623924785,272.0191000226999,352.62058705165936,-3.2598244057412824
156.60639608050192,0.08609641928385678,272.1213805322922,352.62058705165936,-3.2598244057412824
156.85091391562608,0.08623084616923385,272.2406403464855,352.62058705165936,-3.2598244057412824
157.37488070517784,0.08651890378075616,272.49595320884913,352.62058705165936,-3.2598244057412824
158.21322756846067,0.08697979595919185,272.9037653152895,352.62058705165936,-3.2598244057412824
158.87691883522623,0.08734466893378676,273.22601918641925,352.62058705165936,-3.2598244057412824
159.2611611475642,0.08755591118223645,273.4123472532082,352.62058705165936,-3.2598244057412824
159.5406101019918,0.08770954190838168,273.5477484725977,352.62058705165936,-3.2598244057412824
160.48375032318498,0.08822804560912183,274.0040462584481,352.62058705165936,-3.2598244057412824
162.1255129304472,0.08913062612522504,274.79585547123907,352.62058705165936,-3.2598244057412824
164.5008290430819,0.0904364872974595,275.9359389664924,352.62058705165936,-3.2598244057412824
164.95493359402676,0.09068613722744549,276.15316316124336,352.62058705165936,-3.2598244057412824
165.68848709939923,0.09108941788357672,276.50357177540417,352.62058705165936,-3.2598244057412824
166.77135179780623,0.09168473694738949,277.01973786252677,352.62058705165936,-3.2598244057412824
167.40011194526835,0.09203040608121625,277.31884738164695,352.62058705165936,-3.2598244057412824
167.64462978039248,0.09216483296659332,277.4350493829463,352.62058705165936,-3.2598244057412824
167.92407873482009,0.09231846369273855,277.5677707625934,352.62058705165936,-3.2598244057412824
169.00694343322706,0.09291378275655131,278.08125456755556,352.62058705165936,-3.2598244057412824
170.08980813163407,0.09350910182036408,278.5934568623547,352.62058705165936,-3.2598244057412824
170.85829275631002,0.09393158631726346,278.9561840377659,352.62058705165936,-3.2598244057412824
172.25553752844806,0.09469973994798961,279.61406205682187,352.62058705165936,-3.2598244057412824
173.05895327242743,0.09514142828565714,279.99139951222895,352.62058705165936,-3.2598244057412824
173.68771341988955,0.0954870974194839,280.28623073967583,352.62058705165936,-3.2598244057412824
174.70071587968962,0.09604400880176035,280.7603625776023,352.62058705165936,-3.2598244057412824
175.74864945879318,0.09662012402480497,281.24971685478545,352.62058705165936,-3.2598244057412824
176.69178967998636,0.09713862772554512,281.68916359816944,352.62058705165936,-3.2598244057412824
177.9493099749106,0.09782996599319864,282.2736721911316,352.62058705165936,-3.2598244057412824
178.26369004864165,0.09800280056011203,282.4195473604082,352.62058705165936,-3.2598244057412824
179.90545265590384,0.09890538107621524,283.17971598152803,352.62058705165936,-3.2598244057412824
180.21983272963493,0.09907821564312863,283.3249710417289,352.62058705165936,-3.2598244057412824
181.3026974280419,0.09967353470694139,283.8245393662288,352.62058705165936,-3.2598244057412824
181.72187085968332,0.09990398079615924,284.01760807535624,352.62058705165936,-3.2598244057412824
181.89652645620058,0.1,284.0980021006116,352.62058705165936,-3.2598244057412824