File: datasets/aisi_316_L/data/M1/valid_21.csv
Time(s),Strain(%),Stress(MPa),Temp(C),Log_SR(s-1)
0.0,0.0,0.0,20.106687167319755,-1.725214252036893
0.0012747513886798838,2.4e-05,4.6933957500000005,20.106687167319755,-1.725214252036893
0.0022095690737117986,4.1599999999999995e-05,8.1352193,20.106687167319755,-1.725214252036893
0.002591994490315764,4.88e-05,9.543238025,20.106687167319755,-1.725214252036893
0.003611795601259671,6.8e-05,13.297954625,20.106687167319755,-1.725214252036893
0.0037392707401276595,7.04e-05,13.7672942,20.106687167319755,-1.725214252036893
0.0045891049992475815,8.64e-05,16.8962247,20.106687167319755,-1.725214252036893
0.004971530415851547,9.36e-05,18.304243425,20.106687167319755,-1.725214252036893
0.005311464119499515,9.999999999999999e-05,19.555815624999997,20.106687167319755,-1.725214252036893
0.006288773517487426,0.00011839999999999999,23.1540857,20.106687167319755,-1.725214252036893
0.0067136906470473875,0.00012639999999999998,24.718550949999997,20.106687167319755,-1.725214252036893
0.007181099489563346,0.0001352,26.439462725000002,20.106687167319755,-1.725214252036893
0.007436049767299321,0.00014,27.378141874999997,20.106687167319755,-1.725214252036893
0.008285884026419246,0.000156,30.507072375,20.106687167319755,-1.725214252036893
0.008710801155979206,0.000164,32.071537625,20.106687167319755,-1.725214252036893
0.008965751433715183,0.00016879999999999998,33.010216774999996,20.106687167319755,-1.725214252036893
0.009305685137363153,0.0001752,34.261788975,20.106687167319755,-1.725214252036893
0.010325486248307059,0.00019439999999999998,38.016505575,20.106687167319755,-1.725214252036893
0.011005353655602996,0.0002072,40.519649975,20.106687167319755,-1.725214252036893
0.012110138192458896,0.00022799999999999999,44.587259624999994,20.106687167319755,-1.725214252036893
0.014532165830950674,0.0002736,53.504711549999996,20.106687167319755,-1.725214252036893
0.015127049812334621,0.0002848,55.6949629,20.106687167319755,-1.725214252036893
0.01674173490466247,0.00031519999999999996,61.63993084999999,20.106687167319755,-1.725214252036893
0.017506585737870405,0.0003296,64.4559683,20.106687167319755,-1.725214252036893
0.018271436571078332,0.00034399999999999996,67.27200574999999,20.106687167319755,-1.725214252036893
0.019036287404286263,0.0003584,70.0880432,20.106687167319755,-1.725214252036893
0.019418712820890232,0.0003656,71.49606192499999,20.106687167319755,-1.725214252036893
0.02052349735774613,0.00038639999999999996,75.56367157499999,20.106687167319755,-1.725214252036893
0.02073595592252611,0.0003904,76.3459042,20.106687167319755,-1.725214252036893
0.02137333161686605,0.00040239999999999997,78.692602075,20.106687167319755,-1.725214252036893
0.021925723885294002,0.0004128,80.7264069,20.106687167319755,-1.725214252036893
0.022053199024161987,0.00041519999999999995,81.19574647499999,20.106687167319755,-1.725214252036893
0.022308149301897964,0.00041999999999999996,82.13442562499999,20.106687167319755,-1.725214252036893
0.023540408977621854,0.0004432,86.67137484999999,20.106687167319755,-1.725214252036893
0.023880342681269824,0.0004496,87.92294704999999,20.106687167319755,-1.725214252036893
0.024432734949697773,0.00045999999999999996,89.956751875,20.106687167319755,-1.725214252036893
0.02468768522743375,0.00046479999999999997,90.895431025,20.106687167319755,-1.725214252036893
0.024900143792213728,0.00046879999999999996,91.67766364999999,20.106687167319755,-1.725214252036893
0.0263448620327176,0.000496,96.9968455,20.106687167319755,-1.725214252036893
0.026684795736365566,0.0005024,98.24841769999999,20.106687167319755,-1.725214252036893
0.027449646569573497,0.0005168,101.06445515,20.106687167319755,-1.725214252036893
0.029106823374857347,0.000548,107.165869625,20.106687167319755,-1.725214252036893
0.02931928193963733,0.000552,107.94810224999999,20.106687167319755,-1.725214252036893
0.029744199069197286,0.00056,109.51256749999999,20.106687167319755,-1.725214252036893
0.03050904990240522,0.0005744,112.32860495,20.106687167319755,-1.725214252036893
0.031316392448569146,0.0005896,115.301088925,20.106687167319755,-1.725214252036893
0.03195376814290909,0.0006016,117.64778679999999,20.106687167319755,-1.725214252036893
0.03276111068907301,0.0006167999999999999,120.62027077499998,20.106687167319755,-1.725214252036893
0.03390838693888491,0.0006384,124.84432695,20.106687167319755,-1.725214252036893
0.03514064661460879,0.0006615999999999999,129.38127617499998,20.106687167319755,-1.725214252036893
0.03667034828102466,0.0006904,135.013351075,20.106687167319755,-1.725214252036893
0.03701028198467262,0.0006967999999999999,136.26492327499997,20.106687167319755,-1.725214252036893
0.03773264110492456,0.0007103999999999999,138.92451419999998,20.106687167319755,-1.725214252036893
0.03849749193813249,0.0007247999999999999,141.74055165,20.106687167319755,-1.725214252036893
0.038837425641780464,0.0007312,142.99212384999998,20.106687167319755,-1.725214252036893
0.039177359345428424,0.0007375999999999999,144.24369604999998,20.106687167319755,-1.725214252036893
0.0395172930490764,0.000744,145.49526825,20.106687167319755,-1.725214252036893
0.04002719360454835,0.0007536,147.37262655,20.106687167319755,-1.725214252036893
0.04185433726165618,0.000788,154.099827125,20.106687167319755,-1.725214252036893
0.042279254391216145,0.0007959999999999999,155.664292375,20.106687167319755,-1.725214252036893
0.043256563789204054,0.0008144,159.26256245,20.106687167319755,-1.725214252036893
0.04363898920580802,0.0008215999999999999,160.670581175,20.106687167319755,-1.725214252036893
0.04431885661310396,0.0008344,163.173725575,20.106687167319755,-1.725214252036893
0.044871248881531905,0.0008447999999999999,165.2075304,20.106687167319755,-1.725214252036893
0.0460185251313438,0.0008663999999999999,169.43158657499998,20.106687167319755,-1.725214252036893
0.04648593397385976,0.0008751999999999999,171.15249834999997,20.106687167319755,-1.725214252036893
0.04776068536253965,0.0008992,175.84589409999998,20.106687167319755,-1.725214252036893
0.048228094205055604,0.000908,177.566805875,20.106687167319755,-1.725214252036893
0.04852553619574758,0.0009136,178.66193155,20.106687167319755,-1.725214252036893
0.05026769642694342,0.0009463999999999999,185.076239075,20.106687167319755,-1.725214252036893
0.05166992295449129,0.0009728,190.2389744,20.106687167319755,-1.725214252036893
0.05315713290795116,0.0010008,195.714602775,20.106687167319755,-1.725214252036893
0.05383700031524709,0.0010136,198.21774717499997,20.106687167319755,-1.725214252036893
0.05455935943549903,0.0010272,200.8773381,20.106687167319755,-1.725214252036893
0.054771818000279006,0.0010312,201.65957072499998,20.106687167319755,-1.725214252036893
0.056471486518518854,0.0010632,207.917431725,20.106687167319755,-1.725214252036893
0.056641453370342834,0.0010664,208.54321782499997,20.106687167319755,-1.725214252036893
0.057236337351726785,0.0010776,210.73346917499998,20.106687167319755,-1.725214252036893
0.05838361360153868,0.0010992,214.95752535,20.106687167319755,-1.725214252036893
0.05872354730518665,0.0011056,216.20909755,20.106687167319755,-1.725214252036893
0.05910597272179061,0.0011128,217.617116275,20.106687167319755,-1.725214252036893
0.060635674388206474,0.0011416,223.249191175,20.106687167319755,-1.725214252036893
0.06182544235097436,0.0011639999999999999,227.629693875,20.106687167319755,-1.725214252036893
0.062335342906446316,0.0011736,229.50705217499998,20.106687167319755,-1.725214252036893
0.0625902931841823,0.0011784,230.445731325,20.106687167319755,-1.725214252036893
0.06344012744330221,0.0011944,233.574661825,20.106687167319755,-1.725214252036893
0.06369507772103819,0.0011991999999999999,234.51334097499998,20.106687167319755,-1.725214252036893
0.06399251971173017,0.0012048,235.60846665,20.106687167319755,-1.725214252036893
0.0647998622578941,0.00122,238.58095062499999,20.106687167319755,-1.725214252036893
0.06730687332229787,0.0012672,247.8112956,20.106687167319755,-1.725214252036893
0.06887906670166971,0.0012967999999999999,253.59981702499996,20.106687167319755,-1.725214252036893
0.06943145897009767,0.0013072,255.63362184999997,20.106687167319755,-1.725214252036893
0.06960142582192166,0.0013104,256.25940794999997,20.106687167319755,-1.725214252036893
0.07062122693286557,0.0013296,260.01412455,20.106687167319755,-1.725214252036893
0.07202345346041344,0.001356,265.176859875,20.106687167319755,-1.725214252036893
0.07210843688632543,0.0013576,265.489752925,20.106687167319755,-1.725214252036893
0.07257584572884139,0.0013664,267.2106647,20.106687167319755,-1.725214252036893
0.07440298938594922,0.0014008,273.937865275,20.106687167319755,-1.725214252036893
0.07491288994142117,0.0014104,275.815223575,20.106687167319755,-1.725214252036893
0.07678252531148501,0.0014456,282.698870675,20.106687167319755,-1.725214252036893
0.07703747558922097,0.0014504,283.637549825,20.106687167319755,-1.725214252036893
0.07818475183903288,0.001472,287.861606,20.106687167319755,-1.725214252036893
0.0790770778111088,0.0014888,291.146983025,20.106687167319755,-1.725214252036893
0.07975694521840472,0.0015015999999999999,293.650127425,20.106687167319755,-1.725214252036893
0.08018186234796469,0.0015095999999999998,295.21459267499995,20.106687167319755,-1.725214252036893
0.08124415517186459,0.0015295999999999999,299.1257558,20.106687167319755,-1.725214252036893
0.0822639562828085,0.0015488,302.8804724,20.106687167319755,-1.725214252036893
0.08298631540306044,0.0015624,305.540063325,20.106687167319755,-1.725214252036893
0.08413359165287233,0.001584,309.7641195,20.106687167319755,-1.725214252036893
0.08723548669866005,0.0016424,312.8424754932124,20.106687167319755,-1.725214252036893
0.08761791211526401,0.0016496,312.90166144098345,20.106687167319755,-1.725214252036893
0.08834027123551594,0.0016631999999999999,313.0131829634362,20.106687167319755,-1.725214252036893
0.0899974480407998,0.0016944,313.26769125995924,20.106687167319755,-1.725214252036893
0.09050734859627176,0.001704,313.34563293731514,20.106687167319755,-1.725214252036893
0.09088977401287572,0.0017112,313.40397686070696,20.106687167319755,-1.725214252036893
0.09173960827199563,0.0017272,313.5332883435275,20.106687167319755,-1.725214252036893
0.09284439280885154,0.001748,313.70069698497076,20.106687167319755,-1.725214252036893
0.09365173535501546,0.0017632,313.8225431617288,20.106687167319755,-1.725214252036893
0.0954363872991673,0.0017967999999999999,314.0904430474946,20.106687167319755,-1.725214252036893
0.09577632100281526,0.0018031999999999998,314.1412493251708,20.106687167319755,-1.725214252036893
0.09730602266923112,0.0018319999999999999,314.3690128444511,20.106687167319755,-1.725214252036893
0.09951559174294293,0.0018736,314.6955545833321,20.106687167319755,-1.725214252036893
0.10053539285388684,0.0018927999999999998,314.845311259061,20.106687167319755,-1.725214252036893
0.1009178182704908,0.0019,314.90131712482105,20.106687167319755,-1.725214252036893
0.10164017739074273,0.0019136,315.00688066784426,20.106687167319755,-1.725214252036893
0.10219256965917069,0.001924,315.0874084238419,20.106687167319755,-1.725214252036893
0.1044021387328825,0.0019656,315.4078361934235,20.106687167319755,-1.725214252036893
0.10499702271426643,0.0019768,315.49365192842845,20.106687167319755,-1.725214252036893
0.10571938183451836,0.0019904,315.59760224759515,20.106687167319755,-1.725214252036893
0.10678167465841826,0.0020104,315.7499685621095,20.106687167319755,-1.725214252036893
0.10733406692684623,0.0020208,315.828965355069,20.106687167319755,-1.725214252036893
0.10877878516735008,0.002048,316.03482633638754,20.106687167319755,-1.725214252036893
0.109756094565338,0.0020664,316.17348094942827,20.106687167319755,-1.725214252036893
0.11013851998194198,0.0020736,316.22760592792866,20.106687167319755,-1.725214252036893
0.11069091225036991,0.002084,316.30565723586693,20.106687167319755,-1.725214252036893
0.1119231719260938,0.0021072,316.47922635989147,20.106687167319755,-1.725214252036893
0.11251805590747774,0.0021184,316.5627514751106,20.106687167319755,-1.725214252036893
0.11336789016659767,0.0021344,316.6817749317423,20.106687167319755,-1.725214252036893
0.11430270785162958,0.002152,316.8122995502624,20.106687167319755,-1.725214252036893
0.11561995095326547,0.0021768,316.99551618012833,20.106687167319755,-1.725214252036893
0.11604486808282541,0.0021847999999999998,317.0544444239506,20.106687167319755,-1.725214252036893
0.11685221062898933,0.0021999999999999997,317.16617676453166,20.106687167319755,-1.725214252036893
0.11727712775854932,0.002208,317.22486231093666,20.106687167319755,-1.725214252036893
0.11791450345288924,0.0022199999999999998,317.3127353851321,20.106687167319755,-1.725214252036893
0.1184668957213172,0.0022304,317.38874231316805,20.106687167319755,-1.725214252036893
0.11897679627678914,0.00224,317.4587799653019,20.106687167319755,-1.725214252036893
0.11931672998043713,0.0022464,317.5054067095733,20.106687167319755,-1.725214252036893
0.12131384048936894,0.002284,317.7782998056665,20.106687167319755,-1.725214252036893
0.12178124933188489,0.0022928,317.8419147157166,20.106687167319755,-1.725214252036893
0.12203619960962088,0.0022976,317.87657361994576,20.106687167319755,-1.725214252036893
0.12241862502622484,0.0023048,317.9285090756237,20.106687167319755,-1.725214252036893
0.12301350900760878,0.002316,318.0091719717822,20.106687167319755,-1.725214252036893
0.12352340956308074,0.0023255999999999997,318.0781905880796,20.106687167319755,-1.725214252036893
0.1239058349796847,0.0023328,318.12988165567083,20.106687167319755,-1.725214252036893
0.1251805863683646,0.0023568,318.30173760127,20.106687167319755,-1.725214252036893
0.12547802835905655,0.0023623999999999997,318.3417389530278,20.106687167319755,-1.725214252036893
0.12798503942346035,0.0024096,318.67743631057476,20.106687167319755,-1.725214252036893
0.12900484053440425,0.0024288,318.81325621210783,20.106687167319755,-1.725214252036893
0.1296422162287442,0.0024408,318.8979310466121,20.106687167319755,-1.725214252036893
0.13002464164534816,0.002448,318.9486580199672,20.106687167319755,-1.725214252036893
0.13036457534899612,0.0024544,318.9936998352935,20.106687167319755,-1.725214252036893
0.13214922729314796,0.0024879999999999998,319.2294220800682,20.106687167319755,-1.725214252036893
0.1327866029874879,0.0025,319.3133072936152,20.106687167319755,-1.725214252036893
0.13295656983931187,0.0025031999999999997,319.335650144251,20.106687167319755,-1.725214252036893
0.1338064040984318,0.0025192,319.4471977439004,20.106687167319755,-1.725214252036893
0.13448627150572776,0.002532,319.5362370150274,20.106687167319755,-1.725214252036893
0.13682331571830753,0.0025759999999999997,319.8409794941588,20.106687167319755,-1.725214252036893
0.1370357742830875,0.00258,319.8685823003013,20.106687167319755,-1.725214252036893
0.13746069141264747,0.002588,319.9237378933807,20.106687167319755,-1.725214252036893
0.1383530173847234,0.0026048,320.0393486716332,20.106687167319755,-1.725214252036893
0.1392878350697553,0.0026224,320.16015325496386,20.106687167319755,-1.725214252036893
0.13975524391227126,0.0026311999999999998,320.2204369418916,20.106687167319755,-1.725214252036893
0.13992521076409525,0.0026344,320.2423387807963,20.106687167319755,-1.725214252036893
0.1403926196066112,0.0026432,320.3025154037982,20.106687167319755,-1.725214252036893
0.14086002844912715,0.002652,320.36261394243115,20.106687167319755,-1.725214252036893
0.14136992900459913,0.0026616,320.4280873525288,20.106687167319755,-1.725214252036893
0.14200730469893905,0.0026736,320.5097997446506,20.106687167319755,-1.725214252036893
0.142559696967367,0.0026839999999999998,320.5805015218202,20.106687167319755,-1.725214252036893
0.14332454780057494,0.0026983999999999997,320.6782201585507,20.106687167319755,-1.725214252036893
0.14430185719856284,0.0027167999999999997,320.8027874081211,20.106687167319755,-1.725214252036893
0.1446842826151668,0.002724,320.8514414968494,20.106687167319755,-1.725214252036893
0.1448967411799468,0.002728,320.87844987383005,20.106687167319755,-1.725214252036893
0.14549162516133074,0.0027392,320.9539912873724,20.106687167319755,-1.725214252036893
0.1459590340038467,0.002748,321.01326078140545,20.106687167319755,-1.725214252036893
0.14646893455931864,0.0027576,321.0778340531689,20.106687167319755,-1.725214252036893
0.14668139312409864,0.0027616,321.1047137010516,20.106687167319755,-1.725214252036893
0.14740375224435057,0.0027752,321.1959911415888,20.106687167319755,-1.725214252036893
0.14821109479051447,0.0027903999999999997,321.29780091225194,20.106687167319755,-1.725214252036893
0.1491884041885024,0.0028087999999999998,321.4207553955653,20.106687167319755,-1.725214252036893
0.14991076330875436,0.0028224,321.5114329963376,20.106687167319755,-1.725214252036893
0.15042066386422628,0.002832,321.5753381458222,20.106687167319755,-1.725214252036893
0.15186538210473013,0.0028591999999999997,321.7559455515665,20.106687167319755,-1.725214252036893
0.153480067197058,0.0028896,321.9570097874346,20.106687167319755,-1.725214252036893
0.15543468599303384,0.0029264,322.1993029335918,20.106687167319755,-1.725214252036893
0.1556896362707698,0.0029311999999999997,322.23081855182653,20.106687167319755,-1.725214252036893
0.1566244539558017,0.0029487999999999997,322.346204020115,20.106687167319755,-1.725214252036893
0.15717684622422967,0.0029592,322.4142600994201,20.106687167319755,-1.725214252036893
0.15857907275177754,0.0029855999999999997,322.5866002343563,20.106687167319755,-1.725214252036893
0.1593014318720295,0.0029992,322.6751495084906,20.106687167319755,-1.725214252036893
0.16049119983479737,0.0030215999999999997,322.82065476331525,20.106687167319755,-1.725214252036893
0.16108608381618134,0.0030328,322.8932495909931,20.106687167319755,-1.725214252036893
0.16176595122347726,0.0030456,322.97608720488535,20.106687167319755,-1.725214252036893
0.16202090150121323,0.0030504,323.00711629085947,20.106687167319755,-1.725214252036893
0.1635930948805851,0.00308,323.19804324474705,20.106687167319755,-1.725214252036893
0.164230470574925,0.0030919999999999997,323.2752420432856,20.106687167319755,-1.725214252036893
0.16516528825995694,0.0031095999999999997,323.38825592076506,20.106687167319755,-1.725214252036893
0.1667799733522848,0.00314,323.58287589037695,20.106687167319755,-1.725214252036893
0.16762980761140472,0.003156,323.6850122207826,20.106687167319755,-1.725214252036893
0.16805472474096467,0.0031639999999999997,323.7360046432356,20.106687167319755,-1.725214252036893
0.16839465844461265,0.0031704,323.77676238655283,20.106687167319755,-1.725214252036893
0.16877708386121662,0.0031776,323.82257651231305,20.106687167319755,-1.725214252036893
0.1697968849721605,0.0031967999999999996,323.94455001839657,20.106687167319755,-1.725214252036893
0.1708591777960604,0.0032167999999999997,324.07130233411453,20.106687167319755,-1.725214252036893
0.17124160321266438,0.003224,324.1168578818706,20.106687167319755,-1.725214252036893
0.17204894575882831,0.0032392,324.2129006121651,20.106687167319755,-1.725214252036893
0.1741735314066281,0.0032792,324.4648084793183,20.106687167319755,-1.725214252036893
0.17506585737870403,0.003296,324.5702520964124,20.106687167319755,-1.725214252036893
0.17697798446172386,0.003332,324.7954994712894,20.106687167319755,-1.725214252036893
0.17825273585040377,0.003356,324.94513732095754,20.106687167319755,-1.725214252036893
0.1799099126556876,0.0033872,325.1390440734259,20.106687167319755,-1.725214252036893
0.18071725520185153,0.0034024,325.2332590198736,20.106687167319755,-1.725214252036893
0.18131213918323547,0.0034135999999999997,325.302575555108,20.106687167319755,-1.725214252036893
0.18143961432210345,0.0034159999999999998,325.31741755235345,20.106687167319755,-1.725214252036893
0.18165207288688345,0.00342,325.34214518034435,20.106687167319755,-1.725214252036893
0.18233194029417937,0.0034327999999999997,325.4211979006347,20.106687167319755,-1.725214252036893
0.18356419996990328,0.003456,325.564188566974,20.106687167319755,-1.725214252036893
0.1841165922383312,0.0034663999999999997,325.62816625962824,20.106687167319755,-1.725214252036893
0.1843715425160672,0.0034712,325.6576691727928,20.106687167319755,-1.725214252036893
0.18454150936789118,0.0034744,325.6773289427478,20.106687167319755,-1.725214252036893
0.186368653024999,0.0035088,325.8882273996681,20.106687167319755,-1.725214252036893
0.18670858672864699,0.0035152,325.92737519464697,20.106687167319755,-1.725214252036893
0.18785586297845885,0.0035367999999999997,326.05929426302845,20.106687167319755,-1.725214252036893
0.18819579668210684,0.0035432,326.09832100439615,20.106687167319755,-1.725214252036893
0.19015041547808267,0.00358,326.32219353929315,20.106687167319755,-1.725214252036893
0.1912127083019826,0.0036,326.4434868978528,20.106687167319755,-1.725214252036893
0.19240247626475046,0.0036224,326.5790238923307,20.106687167319755,-1.725214252036893
0.19261493482953043,0.0036263999999999997,326.60319249112024,20.106687167319755,-1.725214252036893
0.1932098188109144,0.0036376,326.67080931932776,20.106687167319755,-1.725214252036893
0.19388968621821032,0.0036504,326.74798635321815,20.106687167319755,-1.725214252036893
0.19486699561619825,0.0036688,326.8587436929889,20.106687167319755,-1.725214252036893
0.1952494210328022,0.003676,326.90202452480526,20.106687167319755,-1.725214252036893
0.19580181330123014,0.0036864,326.9644829604949,20.106687167319755,-1.725214252036893
0.19686410612513006,0.0037064,327.084402525448,20.106687167319755,-1.725214252036893
0.1986912497822379,0.0037408,327.2900755136053,20.106687167319755,-1.725214252036893
0.20009347630978574,0.0037671999999999996,327.44741770837334,20.106687167319755,-1.725214252036893
0.2006883602911697,0.0037784,327.51403896037544,20.106687167319755,-1.725214252036893
0.20226055367054155,0.0038079999999999998,327.689739714502,20.106687167319755,-1.725214252036893
0.20357779677217744,0.0038328,327.83653875077505,20.106687167319755,-1.725214252036893
0.2039602221887814,0.0038399999999999997,327.87908837934623,20.106687167319755,-1.725214252036893
0.2040876973276494,0.0038423999999999997,327.8932646730763,20.106687167319755,-1.725214252036893
0.20481005644790132,0.0038559999999999996,327.97353187080034,20.106687167319755,-1.725214252036893
0.20570238241997726,0.0038728,328.0725331975936,20.106687167319755,-1.725214252036893
0.20684965866978913,0.0038943999999999997,328.1995748573499,20.106687167319755,-1.725214252036893
0.20774198464186508,0.0039112,328.298195144881,20.106687167319755,-1.725214252036893
0.2102065039933128,0.0039575999999999995,328.569720432225,20.106687167319755,-1.725214252036893
0.21135378024312473,0.0039792,328.6956963631267,20.106687167319755,-1.725214252036893
0.21207613936337666,0.0039927999999999995,328.77487773724124,20.106687167319755,-1.725214252036893
0.22265861589964364,0.0041920384076815365,329.9230779684866,20.106687167319755,-1.725214252036893
0.23693868746717187,0.004460892178435687,331.43927494026224,20.106687167319755,-1.725214252036893
0.2624388152663294,0.004940988197639528,334.0609087521465,20.106687167319755,-1.725214252036893
0.26753884082616086,0.0050370074014802965,334.5730975774733,20.106687167319755,-1.725214252036893
0.2756988817218913,0.005190638127625526,335.3847492387277,20.106687167319755,-1.725214252036893
0.2889589481774532,0.005440288057611523,336.683977971157,20.106687167319755,-1.725214252036893
0.305279029968914,0.00574754950990198,338.2515299064705,20.106687167319755,-1.725214252036893
0.3654593315749257,0.006880576115223045,343.7688729614588,20.106687167319755,-1.725214252036893
0.3756593826945887,0.007072614522904581,344.66768340154835,20.106687167319755,-1.725214252036893
0.3858594338142517,0.007264652930586117,345.5570247823468,20.106687167319755,-1.725214252036893
0.3889194491501506,0.007322264452890578,345.8220330626047,20.106687167319755,-1.725214252036893
0.4042195258296451,0.007610322064412882,347.1350688048926,20.106687167319755,-1.725214252036893
0.4195196025091396,0.007898379675935187,348.42885861301994,20.106687167319755,-1.725214252036893
0.46133981209975794,0.008685737147429486,351.8745446930673,20.106687167319755,-1.725214252036893
0.48479992967498287,0.00912742548509702,353.75406193571223,20.106687167319755,-1.725214252036893
0.5174400932579045,0.009741948389677936,356.31105495043926,20.106687167319755,-1.725214252036893
0.5480402466168935,0.010318063612722545,358.65165826852297,20.106687167319755,-1.725214252036893
0.5531402721767249,0.010414082816563312,359.0367488818511,20.106687167319755,-1.725214252036893
0.5806804101998151,0.010932586517303462,361.09278870652327,20.106687167319755,-1.725214252036893
0.5919004664314443,0.01114382876575315,361.91948785927053,20.106687167319755,-1.725214252036893
0.6010805124391412,0.011316663332666534,362.5913414920818,20.106687167319755,-1.725214252036893
0.6204606095665007,0.011681536307261452,363.99669710343306,20.106687167319755,-1.725214252036893
0.6357606862459952,0.011969593918783756,365.0941305454012,20.106687167319755,-1.725214252036893
0.665340834493018,0.012526505301060212,367.18705633807446,20.106687167319755,-1.725214252036893
0.6786009009485799,0.012776155231046209,368.11345028701777,20.106687167319755,-1.725214252036893
0.6979809980759396,0.013141028205641128,369.45481070515797,20.106687167319755,-1.725214252036893
0.7010410134118386,0.013198639727945589,369.66526935419216,20.106687167319755,-1.725214252036893
0.7122610696434678,0.013409881976395279,370.43390481734866,20.106687167319755,-1.725214252036893
0.7224611207631308,0.013601920384076815,371.12857625818907,20.106687167319755,-1.725214252036893
0.7520412690101536,0.014158831766353271,373.12181336476897,20.106687167319755,-1.725214252036893
0.7765213916973448,0.014619723944788958,374.74836460784104,20.106687167319755,-1.725214252036893
0.8418017188631879,0.01584876975395079,378.9908985600072,20.106687167319755,-1.725214252036893
0.8693418568862781,0.01636727345469094,380.7419912001722,20.106687167319755,-1.725214252036893
0.8734218773341433,0.016444088817763554,380.9995604987584,20.106687167319755,-1.725214252036893
0.8958619897974017,0.01686657331466293,382.4078919258499,20.106687167319755,-1.725214252036893
0.8989220051333008,0.016924184836967393,382.5988656093303,20.106687167319755,-1.725214252036893
0.9489022556196494,0.01786517303460692,385.683076345972,20.106687167319755,-1.725214252036893
0.9754223885307733,0.018364472894578918,387.2938301183869,20.106687167319755,-1.725214252036893
0.9988825061059983,0.01880616123224645,388.7045433489042,20.106687167319755,-1.725214252036893
1.0274426492410547,0.01934386877375475,390.4046108808076,20.106687167319755,-1.725214252036893
1.042742725920549,0.019631926385277054,391.3077750706672,20.106687167319755,-1.725214252036893
1.0672228486077402,0.02009281856371274,392.74216107509886,20.106687167319755,-1.725214252036893
1.0713028690556055,0.020169633926785356,392.97997232599647,20.106687167319755,-1.725214252036893
1.0855829406231337,0.020438487697539507,393.8095443071006,20.106687167319755,-1.725214252036893
1.117203099094089,0.02103380676135227,395.63145668355065,20.106687167319755,-1.725214252036893
1.1263831451017856,0.021206641328265653,396.1566175981055,20.106687167319755,-1.725214252036893
1.191663472267629,0.022435687137427485,399.84410348774327,20.106687167319755,-1.725214252036893
1.2141035847308876,0.022858171634326865,401.0933671580816,20.106687167319755,-1.725214252036893
1.219203610290719,0.022954190838167635,401.3760310142126,20.106687167319755,-1.725214252036893
1.2467437483138093,0.023472694538907782,402.8945208363978,20.106687167319755,-1.725214252036893
1.2681638556651014,0.023875975195039006,404.06654200930706,20.106687167319755,-1.725214252036893
1.283463932344596,0.024164032806561313,404.8989779509012,20.106687167319755,-1.725214252036893
1.3018240243599895,0.024509701940388078,405.89280980715023,20.106687167319755,-1.725214252036893
1.3048840396958883,0.024567313462692537,406.0579155516683,20.106687167319755,-1.725214252036893
1.3477242543984729,0.02537387477495499,408.3537677049392,20.106687167319755,-1.725214252036893
1.39260447932499,0.02621884376875375,410.72862256410514,20.106687167319755,-1.725214252036893
1.4262646480198782,0.026852570514102822,412.4902222667337,20.106687167319755,-1.725214252036893
1.4323846786916759,0.026967793558711744,412.80876345449195,20.106687167319755,-1.725214252036893
1.510925072313081,0.028446489297859572,416.850700581534,20.106687167319755,-1.725214252036893
1.5170451029848788,0.028561712342468494,417.16217271576903,20.106687167319755,-1.725214252036893
1.5292851643284744,0.028792158431686338,417.783650723042,20.106687167319755,-1.725214252036893
1.5598853176874634,0.029368273654730947,419.32891826549775,20.106687167319755,-1.725214252036893
1.5700853688071263,0.029560312062412483,419.84137431072907,20.106687167319755,-1.725214252036893
1.6068055528379133,0.030251650330066014,421.67556191554615,20.106687167319755,-1.725214252036893
1.629245665301172,0.030674134826965394,422.7884089587037,20.106687167319755,-1.725214252036893
1.6843259413473521,0.03171114222844569,425.49489587430463,20.106687167319755,-1.725214252036893
1.7016660282507792,0.0320376075215043,426.33976482431285,20.106687167319755,-1.725214252036893
1.71798611004224,0.03234486897379476,427.13187361496676,20.106687167319755,-1.725214252036893
1.7271661560499365,0.03251770354070814,427.57614507297006,20.106687167319755,-1.725214252036893
1.732266181609768,0.032613722744548906,427.8225645951304,20.106687167319755,-1.725214252036893
1.7465462531772964,0.03288257651530306,428.51103854270497,20.106687167319755,-1.725214252036893
1.7659263503046563,0.03324744948989798,429.44189487211094,20.106687167319755,-1.725214252036893
1.796526503663645,0.03382356471294259,430.90359707098014,20.106687167319755,-1.725214252036893
1.8240666416867353,0.03434206841368274,432.210847675036,20.106687167319755,-1.725214252036893
1.8495667694858926,0.034822164432886576,433.4144179142209,20.106687167319755,-1.725214252036893
1.870986876837185,0.0352254450890178,434.42042387039885,20.106687167319755,-1.725214252036893
1.9281071631072977,0.036300860172034405,437.0813853651091,20.106687167319755,-1.725214252036893
1.94952727045859,0.03670414082816563,438.07129676301406,20.106687167319755,-1.725214252036893
1.9811474289295457,0.0372994598919784,439.52487687475866,20.106687167319755,-1.725214252036893
1.99644750560904,0.0375875175035007,440.2249714830285,20.106687167319755,-1.725214252036893
2.0097075720646016,0.037837167433486696,440.8300292864658,20.106687167319755,-1.725214252036893
2.0199076231842645,0.03802920584116823,441.29439951245746,20.106687167319755,-1.725214252036893
2.0494877714312874,0.03858611722344468,442.63592931077125,20.106687167319755,-1.725214252036893
2.0739678941184785,0.03904700940188037,443.74045956353416,20.106687167319755,-1.725214252036893
2.1066080577014,0.039661532306461286,445.20528945491884,20.106687167319755,-1.725214252036893
2.110688078149266,0.03973834766953391,445.38776876874624,20.106687167319755,-1.725214252036893
2.129048170164659,0.04008401680336067,446.207229227748,20.106687167319755,-1.725214252036893
2.143328241732187,0.040352870574114824,446.8426834578107,20.106687167319755,-1.725214252036893
2.165768354195446,0.04077535507101421,447.83792850438834,20.106687167319755,-1.725214252036893
2.168828369531345,0.04083296659331867,447.97333147462564,20.106687167319755,-1.725214252036893
2.1861684564347716,0.04115943188637727,448.73921229553224,20.106687167319755,-1.725214252036893
2.2157486046817945,0.04171634326865373,450.0402693909276,20.106687167319755,-1.725214252036893
2.2443087478168513,0.042254050810162036,451.2900499846947,20.106687167319755,-1.725214252036893
2.26674886028011,0.04267653530706142,452.2676743019321,20.106687167319755,-1.725214252036893
2.282048936959604,0.04296459291858372,452.93207323420296,20.106687167319755,-1.725214252036893
2.300409028974997,0.04331026205241048,453.72706317467083,20.106687167319755,-1.725214252036893
2.3034690443108965,0.043367873574714944,453.8593205482799,20.106687167319755,-1.725214252036893
2.323869146550222,0.04375195039007801,454.73929179879275,20.106687167319755,-1.725214252036893
2.3442692487895482,0.04413602720544109,455.61625546920976,20.106687167319755,-1.725214252036893
2.35752931524511,0.044385677135427085,456.1846862751329,20.106687167319755,-1.725214252036893
2.363649345916908,0.04450090018003601,456.4466182731932,20.106687167319755,-1.725214252036893
2.3820094379323016,0.04484656931386277,457.23083186170385,20.106687167319755,-1.725214252036893
2.386089458380167,0.04492338467693539,457.40478099936536,20.106687167319755,-1.725214252036893
2.430969683306684,0.045768353670734147,459.31062794502606,20.106687167319755,-1.725214252036893
2.4595298264417407,0.046306061212242455,460.5162981352084,20.106687167319755,-1.725214252036893
2.4972700155844936,0.04701660332066414,462.1011634799583,20.106687167319755,-1.725214252036893
2.5125700922639878,0.04730466093218644,462.74101208419825,20.106687167319755,-1.725214252036893
2.5319501893913476,0.04766953390678136,463.54930977707295,20.106687167319755,-1.725214252036893
2.550310281406741,0.04801520304060812,464.31284262933104,20.106687167319755,-1.725214252036893
2.577850419429831,0.04853370674134827,465.4541346239339,20.106687167319755,-1.725214252036893
2.6043705523409546,0.04903300660132026,466.548670681545,20.106687167319755,-1.725214252036893
2.628850675028146,0.04949389877975595,467.5551597512878,20.106687167319755,-1.725214252036893
2.634970705699944,0.049609121824364874,467.8062100640215,20.106687167319755,-1.725214252036893
2.647210767043539,0.04983956791358271,468.3076295094723,20.106687167319755,-1.725214252036893
2.6625108437230343,0.050127625525105024,468.93313411413084,20.106687167319755,-1.725214252036893
2.6716908897307303,0.0503004600920184,469.30776403010765,20.106687167319755,-1.725214252036893
2.684950956186293,0.05055011002200441,469.8480110555065,20.106687167319755,-1.725214252036893
2.7175911197692146,0.051164632926585324,471.17343569056067,20.106687167319755,-1.725214252036893
2.7308511862247764,0.05141428285657132,471.7101142866856,20.106687167319755,-1.725214252036893
2.7369712168965736,0.05152950590118023,471.9574692293372,20.106687167319755,-1.725214252036893
2.7502312833521363,0.05177915583116624,472.4926661495088,20.106687167319755,-1.725214252036893
2.7553313089119675,0.05187517503500701,472.6982430352154,20.106687167319755,-1.725214252036893
2.7594113293598324,0.051951990398079614,472.8625977150955,20.106687167319755,-1.725214252036893
2.7706313855914617,0.052163232646529306,473.3140851274841,20.106687167319755,-1.725214252036893
2.7961315133906197,0.05264332866573315,474.337549381737,20.106687167319755,-1.725214252036893
2.856311814996631,0.053776355271054205,476.7385996055085,20.106687167319755,-1.725214252036893
2.871611891676126,0.05406441288257652,477.3458803778212,20.106687167319755,-1.725214252036893
2.889971983691519,0.05441008201640328,478.07295414631324,20.106687167319755,-1.725214252036893
2.9073120705949465,0.0547365473094619,478.75798257554754,20.106687167319755,-1.725214252036893
2.9134321012667437,0.05485177035407081,478.9993766379194,20.106687167319755,-1.725214252036893
2.9358722137300024,0.05527425485097019,479.88280130855196,20.106687167319755,-1.725214252036893
2.9766724182086546,0.05604240848169634,481.4823105022454,20.106687167319755,-1.725214252036893
3.0582728271659585,0.05757871574314863,484.65590526180574,20.106687167319755,-1.725214252036893
3.081732944741184,0.05802040408081617,485.56217920653353,20.106687167319755,-1.725214252036893
3.0888729805249477,0.05815483096619324,485.837467127099,20.106687167319755,-1.725214252036893
3.100093036756577,0.05836607321464293,486.269561554366,20.106687167319755,-1.725214252036893
3.120493138995903,0.058750150030006,487.0536284464622,20.106687167319755,-1.725214252036893
3.13783322589933,0.059076615323064616,487.71851481794835,20.106687167319755,-1.725214252036893
3.15721332302669,0.05944148829765954,488.45992969004607,20.106687167319755,-1.725214252036893
3.191893496833544,0.06009441888377676,489.7822573118563,20.106687167319755,-1.725214252036893
3.216373619520735,0.060555311062212444,490.7122935851982,20.106687167319755,-1.725214252036893
3.2337137064241626,0.06088177635527106,491.3693997361272,20.106687167319755,-1.725214252036893
3.2541138086634884,0.06126585317063413,492.14070903607325,20.106687167319755,-1.725214252036893
3.261253844447252,0.0614002800560112,492.4102214754036,20.106687167319755,-1.725214252036893
3.3071540744857364,0.06226445289057812,494.13733901261986,20.106687167319755,-1.725214252036893
3.318374130717365,0.0624756951390278,494.5580982984198,20.106687167319755,-1.725214252036893
3.3255141665011294,0.06261012202440489,494.8255653492483,20.106687167319755,-1.725214252036893
3.3295941869489942,0.06268693738747749,494.97830310831773,20.106687167319755,-1.725214252036893
3.3316341971729275,0.06272534506901381,495.05464461418984,20.106687167319755,-1.725214252036893
3.3765144220994445,0.06357031406281256,496.72957321534756,20.106687167319755,-1.725214252036893
3.382634452771242,0.06368553710742149,496.9572980037243,20.106687167319755,-1.725214252036893
3.3897744885550063,0.06381996399279856,497.22277393622505,20.106687167319755,-1.725214252036893
3.4346547134815237,0.06466493298659733,498.8865137639165,20.106687167319755,-1.725214252036893
3.4774949281841083,0.06547149429885978,500.4667375173851,20.106687167319755,-1.725214252036893
3.5315551991183223,0.06648929785957192,502.45003581246306,20.106687167319755,-1.725214252036893
3.544815265573884,0.06673894778955791,502.9346925790749,20.106687167319755,-1.725214252036893
3.5641953627012435,0.06710382076415283,503.64176716546586,20.106687167319755,-1.725214252036893
3.582555454716637,0.0674494898979796,504.31024545003163,20.106687167319755,-1.725214252036893
3.5907154956123675,0.06760312062412482,504.6069179049308,20.106687167319755,-1.725214252036893
3.6049955671798957,0.06787197439487898,505.12546278459075,20.106687167319755,-1.725214252036893
3.6141756131875926,0.06804480896179237,505.4583900930052,20.106687167319755,-1.725214252036893
3.6274356796431544,0.06829445889177836,505.9387034471746,20.106687167319755,-1.725214252036893
3.6376357307628173,0.0684864972994599,506.30770944955015,20.106687167319755,-1.725214252036893
3.6529358074423115,0.0687745549109822,506.8604627274279,20.106687167319755,-1.725214252036893
3.688635986361132,0.06944668933786757,508.1467209142832,20.106687167319755,-1.725214252036893
3.7008760477047282,0.06967713542708542,508.5866048644552,20.106687167319755,-1.725214252036893
3.728416185727818,0.07019563912782557,509.5742745186394,20.106687167319755,-1.725214252036893
3.7447362675192792,0.07050290058011603,510.1582176854364,20.106687167319755,-1.725214252036893
3.7651363697586047,0.0708869773954791,510.8867528041773,20.106687167319755,-1.725214252036893
3.795736523117594,0.07146309261852371,511.9766756384802,20.106687167319755,-1.725214252036893
3.8089965895731557,0.0717127425485097,512.4479107367689,20.106687167319755,-1.725214252036893
3.8416367531560773,0.07232726545309062,513.6051565553181,20.106687167319755,-1.725214252036893
3.8712169014031,0.07288417683536708,514.6506025399175,20.106687167319755,-1.725214252036893
3.908957090545853,0.07359471894378876,515.9799353563503,20.106687167319755,-1.725214252036893
3.919157141665516,0.07378675735147029,516.338354077336,20.106687167319755,-1.725214252036893
3.93751723368091,0.07413242648529707,516.9825923397091,20.106687167319755,-1.725214252036893
3.9497572950245052,0.0743628725745149,517.4114337706986,20.106687167319755,-1.725214252036893
3.9732174125997304,0.07480456091218245,518.2319339197587,20.106687167319755,-1.725214252036893
4.0078975864065844,0.07545749149829967,519.4413946601658,20.106687167319755,-1.725214252036893
4.018097637526248,0.0756495299059812,519.7963407554499,20.106687167319755,-1.725214252036893
4.032377709093776,0.07591838367673535,520.2926754955831,20.106687167319755,-1.725214252036893
4.0609378522288315,0.07645609121824365,521.2832932433265,20.106687167319755,-1.725214252036893
4.10581807715535,0.07730106021204242,522.8345062444818,20.106687167319755,-1.725214252036893
4.13335821517844,0.07781956391278257,523.7831134773108,20.106687167319755,-1.725214252036893
4.172118409433159,0.0785493098619724,525.1140249907298,20.106687167319755,-1.725214252036893
4.182318460552822,0.07874134826965394,525.4634622955372,20.106687167319755,-1.725214252036893
4.205778578128046,0.07918303660732147,526.2659092042891,20.106687167319755,-1.725214252036893
4.234338721263103,0.07972074414882976,527.2404487833637,20.106687167319755,-1.725214252036893
4.246578782606699,0.07995119023804761,527.6573234750203,20.106687167319755,-1.725214252036893
4.274118920629789,0.08046969393878776,528.5935819715244,20.106687167319755,-1.725214252036893
4.292479012645182,0.08081536307261453,529.2164475411822,20.106687167319755,-1.725214252036893
4.361839360258891,0.08212122424484898,531.5601772442299,20.106687167319755,-1.725214252036893
4.378159442050352,0.08242848569713944,532.1095253018913,20.106687167319755,-1.725214252036893
4.391419508505914,0.08267813562712543,532.5552827842772,20.106687167319755,-1.725214252036893
4.398559544289678,0.0828125625125025,532.7950886034806,20.106687167319755,-1.725214252036893
4.423039666976869,0.08327345469093819,533.6161298918154,20.106687167319755,-1.725214252036893
4.469959902127319,0.08415683136627326,535.1848555773895,20.106687167319755,-1.725214252036893
4.4872999890307455,0.08448329665933187,535.762975132013,20.106687167319755,-1.725214252036893
4.528100193509397,0.08525145029005801,537.119830479941,20.106687167319755,-1.725214252036893
4.532180213957263,0.08532826565313063,537.2552532426624,20.106687167319755,-1.725214252036893
4.5566603366444545,0.08578915783156632,538.0667936091947,20.106687167319755,-1.725214252036893
4.578080443995747,0.08619243848769755,538.7754976207029,20.106687167319755,-1.725214252036893
4.583180469555578,0.08628845769153831,538.9440459210992,20.106687167319755,-1.725214252036893
4.6025605666829374,0.08665333066613323,539.5838634702309,20.106687167319755,-1.725214252036893
4.647440791609455,0.08749829965993199,541.0615258237843,20.106687167319755,-1.725214252036893
4.658660847841084,0.08770954190838168,541.4300705601285,20.106687167319755,-1.725214252036893
4.680080955192376,0.0881128225645129,542.1326961241426,20.106687167319755,-1.725214252036893
4.697421042095804,0.08843928785757152,542.7005701050206,20.106687167319755,-1.725214252036893
4.704561077879568,0.08857371474294859,542.9341628756472,20.106687167319755,-1.725214252036893
4.737201241462489,0.0891882376475295,544.0002597297516,20.106687167319755,-1.725214252036893
4.751481313030017,0.08945709141828366,544.4657758515335,20.106687167319755,-1.725214252036893
4.811661614636029,0.09059011802360473,546.4216289064236,20.106687167319755,-1.725214252036893
4.830021706651422,0.09093578715743149,547.0164275098567,20.106687167319755,-1.725214252036893
4.85552183445058,0.09141588317663533,547.8410759291884,20.106687167319755,-1.725214252036893
4.875921936689906,0.0917999599919984,548.4995792041365,20.106687167319755,-1.725214252036893
4.881021962249737,0.09189597919583917,548.6640370280196,20.106687167319755,-1.725214252036893
4.884081977585637,0.09195359071814363,548.7626795548248,20.106687167319755,-1.725214252036893
4.903462074712996,0.09231846369273855,549.3868567675781,20.106687167319755,-1.725214252036893
4.908562100272827,0.09241448289657932,549.550953928223,20.106687167319755,-1.725214252036893
4.928962202512154,0.0927985597119424,550.2066787211569,20.106687167319755,-1.725214252036893
4.942222268967716,0.09304820964192839,550.6323323281308,20.106687167319755,-1.725214252036893
4.967722396766873,0.09352830566113222,551.4496471941876,20.106687167319755,-1.725214252036893
4.975882437662603,0.09368193638727745,551.7108421698532,20.106687167319755,-1.725214252036893
4.986082488782267,0.093873974794959,552.0371010921124,20.106687167319755,-1.725214252036893
4.998322550125862,0.09410442088417684,552.4282684079594,20.106687167319755,-1.725214252036893
5.006482591021593,0.09425805161032207,552.6888390931571,20.106687167319755,-1.725214252036893
5.021782667701087,0.09454610922184438,553.1769631281992,20.106687167319755,-1.725214252036893
5.033002723932716,0.09475735147029406,553.5345522092912,20.106687167319755,-1.725214252036893
5.049322805724176,0.09506461292258452,554.054127292452,20.106687167319755,-1.725214252036893
5.063602877291705,0.09533346669333867,554.5082184710211,20.106687167319755,-1.725214252036893
5.077882948859234,0.09560232046409282,554.9618104889911,20.106687167319755,-1.725214252036893
5.103383076658392,0.09608241648329667,555.7705608134945,20.106687167319755,-1.725214252036893
5.113583127778054,0.0962744548909782,556.093619471972,20.106687167319755,-1.725214252036893
5.120723163561818,0.09640888177635527,556.3196110155146,20.106687167319755,-1.725214252036893
5.147243296472942,0.09690818163632726,557.1579344120678,20.106687167319755,-1.725214252036893
5.1513233169208075,0.09698499699939989,557.2867575761028,20.106687167319755,-1.725214252036893
5.16152336804047,0.09717703540708142,557.6086415162192,20.106687167319755,-1.725214252036893
5.173763429384066,0.09740748149629927,557.9945749670737,20.106687167319755,-1.725214252036893
5.207423598078954,0.09804120824164833,559.0540602435871,20.106687167319755,-1.725214252036893
5.217623649198616,0.09823324664932986,559.3745886427167,20.106687167319755,-1.725214252036893
5.242103771885808,0.09869413882776555,560.1428613811562,20.106687167319755,-1.725214252036893
5.251283817893505,0.09886697339467894,560.4306027598521,20.106687167319755,-1.725214252036893
5.2635238792371,0.09909741948389679,560.8139529545531,20.106687167319755,-1.725214252036893
5.309424109275584,0.0999615923184637,562.2484302717047,20.106687167319755,-1.725214252036893