File: datasets/aisi_316_L/data/M1/valid_6.csv
Time(s),Strain(%),Stress(MPa),Temp(C),Log_SR(s-1)
0.0,0.0,0.0,442.88932703492054,1.6813971769219238
7.997128003047897e-07,3.84e-05,6.361319399999999,442.88932703492054,1.6813971769219238
1.0829444170794027e-06,5.2e-05,8.6142866875,442.88932703492054,1.6813971769219238
1.4161580838730652e-06,6.8e-05,11.2648364375,442.88932703492054,1.6813971769219238
1.7327110673270443e-06,8.319999999999999e-05,13.782858699999998,442.88932703492054,1.6813971769219238
2.249192250857221e-06,0.000108,17.8912108125,442.88932703492054,1.6813971769219238
2.415799084254052e-06,0.000116,19.2164856875,442.88932703492054,1.6813971769219238
3.36545803461599e-06,0.0001616,26.770552475,442.88932703492054,1.6813971769219238
3.5820469180318704e-06,0.00017199999999999998,28.493409812499998,442.88932703492054,1.6813971769219238
3.682011018069969e-06,0.0001768,29.2885747375,442.88932703492054,1.6813971769219238
4.38175971833666e-06,0.0002104,34.8547292125,442.88932703492054,1.6813971769219238
5.064847735263668e-06,0.0002432,40.2883562,442.88932703492054,1.6813971769219238
5.314757985358914e-06,0.00025519999999999997,42.276268512499996,442.88932703492054,1.6813971769219238
5.697953702171626e-06,0.0002736,45.324400725,442.88932703492054,1.6813971769219238
6.331059669079584e-06,0.00030399999999999996,50.36044524999999,442.88932703492054,1.6813971769219238
7.114111786044692e-06,0.0003416,56.5892371625,442.88932703492054,1.6813971769219238
7.314039986120889e-06,0.00035119999999999997,58.179567012499994,442.88932703492054,1.6813971769219238
8.047110053066946e-06,0.00038639999999999996,64.01077646249999,442.88932703492054,1.6813971769219238
8.347002353181242e-06,0.0004008,66.3962712375,442.88932703492054,1.6813971769219238
8.813501486692369e-06,0.0004232,70.10704088749999,442.88932703492054,1.6813971769219238
9.796481803733675e-06,0.0004704,77.92616265,442.88932703492054,1.6813971769219238
1.0212998887225751e-05,0.0004904,81.2393498375,442.88932703492054,1.6813971769219238
1.0362945037282899e-05,0.0004976,82.43209722499999,442.88932703492054,1.6813971769219238
1.0696158704076564e-05,0.0005136,85.082646975,442.88932703492054,1.6813971769219238
1.1129336470908323e-05,0.0005344,88.52836165,442.88932703492054,1.6813971769219238
1.1162657837587691e-05,0.000536,88.793416625,442.88932703492054,1.6813971769219238
1.1462550137701985e-05,0.0005503999999999999,91.17891139999999,442.88932703492054,1.6813971769219238
1.1679139021117866e-05,0.0005608,92.90176873749999,442.88932703492054,1.6813971769219238
1.191238858787343e-05,0.000572,94.75715356250001,442.88932703492054,1.6813971769219238
1.212897747128931e-05,0.0005824,96.4800109,442.88932703492054,1.6813971769219238
1.2245602254667092e-05,0.000588,97.40770331249999,442.88932703492054,1.6813971769219238
1.2795404804876635e-05,0.0006144,101.78111039999999,442.88932703492054,1.6813971769219238
1.3528474871822693e-05,0.0006496,107.61231984999999,442.88932703492054,1.6813971769219238
1.3778385121917939e-05,0.0006615999999999999,109.60023216249999,442.88932703492054,1.6813971769219238
1.3961652638654452e-05,0.0006703999999999999,111.05803452499998,442.88932703492054,1.6813971769219238
1.4178241522070334e-05,0.0006808,112.7808918625,442.88932703492054,1.6813971769219238
1.5477774822565616e-05,0.0007432,123.1180358875,442.88932703492054,1.6813971769219238
1.5611060289283084e-05,0.0007496,124.1782557875,442.88932703492054,1.6813971769219238
1.5877631222718013e-05,0.0007624,126.29869558749999,442.88932703492054,1.6813971769219238
1.66773440230228e-05,0.0008008,132.6600149875,442.88932703492054,1.6813971769219238
1.6910593589778366e-05,0.000812,134.5153998125,442.88932703492054,1.6813971769219238
1.731044998993076e-05,0.0008311999999999999,137.6960595125,442.88932703492054,1.6813971769219238
1.7543699556686323e-05,0.0008424,139.5514443375,442.88932703492054,1.6813971769219238
1.7826931173460938e-05,0.000856,141.804411625,442.88932703492054,1.6813971769219238
1.8243448256953015e-05,0.0008759999999999999,145.11759881249998,442.88932703492054,1.6813971769219238
1.8510019190387944e-05,0.0008887999999999999,147.2380386125,442.88932703492054,1.6813971769219238
1.9043161057257805e-05,0.0009144,151.4789182125,442.88932703492054,1.6813971769219238
1.9143125157295904e-05,0.0009192,152.2740831375,442.88932703492054,1.6813971769219238
1.929307130735305e-05,0.0009264,152.643114099331,442.88932703492054,1.6813971769219238
1.955964224078798e-05,0.0009392,152.70854775443655,442.88932703492054,1.6813971769219238
1.982621317422291e-05,0.0009519999999999999,152.77363452892266,442.88932703492054,1.6813971769219238
2.019274820769594e-05,0.0009695999999999999,152.86257429545157,442.88932703492054,1.6813971769219238
2.094247895798168e-05,0.0010056,153.04255908662395,442.88932703492054,1.6813971769219238
2.104244305801978e-05,0.0010104,153.06636576175939,442.88932703492054,1.6813971769219238
2.132567467479439e-05,0.001024,153.1335796590796,442.88932703492054,1.6813971769219238
2.137565672481344e-05,0.0010264,153.1454047049962,442.88932703492054,1.6813971769219238
2.1558924241549958e-05,0.0010352,153.1886712543874,442.88932703492054,1.6813971769219238
2.2175369525118228e-05,0.0010647999999999999,153.3331628456969,442.88932703492054,1.6813971769219238
2.2325315675175382e-05,0.001072,153.36807154138336,442.88932703492054,1.6813971769219238
2.2491922508572213e-05,0.00108,153.4067519129031,442.88932703492054,1.6813971769219238
2.3791455809067495e-05,0.0011424,153.70471567916124,442.88932703492054,1.6813971769219238
2.4024705375823055e-05,0.0011535999999999999,153.75751745309293,442.88932703492054,1.6813971769219238
2.517429252626119e-05,0.0012088,154.01488942945602,442.88932703492054,1.6813971769219238
2.5240935259619925e-05,0.001212,154.02966739546721,442.88932703492054,1.6813971769219238
2.59573446432263e-05,0.0012464,154.18758124629693,442.88932703492054,1.6813971769219238
2.6673754026832672e-05,0.0012808,154.34380420402616,442.88932703492054,1.6813971769219238
2.6890342910248555e-05,0.0012912,154.39071112177842,442.88932703492054,1.6813971769219238
2.699030701028665e-05,0.0012959999999999998,154.4123107493563,442.88932703492054,1.6813971769219238
2.730685999374063e-05,0.0013112,154.48050464768818,442.88932703492054,1.6813971769219238
2.7523448877156515e-05,0.0013216,154.5269860877005,442.88932703492054,1.6813971769219238
2.837314372748035e-05,0.0013624,154.7079752804904,442.88932703492054,1.6813971769219238
2.858973261089623e-05,0.0013728,154.75377014242252,442.88932703492054,1.6813971769219238
2.8806321494312114e-05,0.0013832,154.79942989949416,442.88932703492054,1.6813971769219238
2.9222838577804187e-05,0.0014031999999999998,154.88686255297634,442.88932703492054,1.6813971769219238
2.9339463361181972e-05,0.0014088,154.91125642836013,442.88932703492054,1.6813971769219238
2.9572712927937538e-05,0.00142,154.95993102424362,442.88932703492054,1.6813971769219238
2.9672677027975633e-05,0.0014248,154.9807457053878,442.88932703492054,1.6813971769219238
2.982262317803278e-05,0.001432,155.01191652348953,442.88932703492054,1.6813971769219238
2.998923001142961e-05,0.0014399999999999999,155.04647916710317,442.88932703492054,1.6813971769219238
3.0155836844826442e-05,0.0014479999999999999,155.08096700559727,442.88932703492054,1.6813971769219238
3.083892486175345e-05,0.0014808,155.22159713218693,442.88932703492054,1.6813971769219238
3.112215647852806e-05,0.0014944,155.279550278015,442.88932703492054,1.6813971769219238
3.1372066728623316e-05,0.0015064,155.33051480704944,442.88932703492054,1.6813971769219238
3.155533424535983e-05,0.0015152,155.36778822143586,442.88932703492054,1.6813971769219238
3.180524449545507e-05,0.0015271999999999998,155.41847983159533,442.88932703492054,1.6813971769219238
3.203849406221064e-05,0.0015383999999999999,155.46565202798774,442.88932703492054,1.6813971769219238
3.213845816224874e-05,0.0015432,155.48582766151392,442.88932703492054,1.6813971769219238
3.222176157894715e-05,0.0015471999999999999,155.50262200060172,442.88932703492054,1.6813971769219238
3.2455011145702715e-05,0.0015584,155.54955630358845,442.88932703492054,1.6813971769219238
3.2571635929080496e-05,0.0015639999999999999,155.572974110186,442.88932703492054,1.6813971769219238
3.2721582079137644e-05,0.0015712,155.60303472421057,442.88932703492054,1.6813971769219238
3.282154617917574e-05,0.001576,155.62304529269107,442.88932703492054,1.6813971769219238
3.297149232923289e-05,0.0015831999999999999,155.6530166364442,442.88932703492054,1.6813971769219238
3.3321366679366234e-05,0.0015999999999999999,155.72274380583218,442.88932703492054,1.6813971769219238
3.347131282942339e-05,0.0016072,155.7525394053959,442.88932703492054,1.6813971769219238
3.390449059625515e-05,0.0016279999999999999,155.83832455368986,442.88932703492054,1.6813971769219238
3.4104418796331345e-05,0.0016376,155.87777342652484,442.88932703492054,1.6813971769219238
3.4370989729766274e-05,0.0016504,155.93023191230725,442.88932703492054,1.6813971769219238
3.4437632463125006e-05,0.0016535999999999999,155.94332171172593,442.88932703492054,1.6813971769219238
3.523734526342979e-05,0.001692,156.09963651898858,442.88932703492054,1.6813971769219238
3.538729141348694e-05,0.0016991999999999999,156.12879087397977,442.88932703492054,1.6813971769219238
3.555389824688377e-05,0.0017071999999999999,156.16112815448307,442.88932703492054,1.6813971769219238
3.568718371360124e-05,0.0017136,156.18695544849052,442.88932703492054,1.6813971769219238
3.5870451230337756e-05,0.0017224,156.22240663627127,442.88932703492054,1.6813971769219238
3.5970415330375855e-05,0.0017272,156.24171387189546,442.88932703492054,1.6813971769219238
3.6686824713982226e-05,0.0017615999999999999,156.37947515542282,442.88932703492054,1.6813971769219238
3.692007428073779e-05,0.0017728,156.42410073667781,442.88932703492054,1.6813971769219238
3.708668111413462e-05,0.0017808,156.45590885999425,442.88932703492054,1.6813971769219238
3.758650161432511e-05,0.0018047999999999999,156.5510005298899,442.88932703492054,1.6813971769219238
3.811964348119497e-05,0.0018303999999999998,156.6518896796803,442.88932703492054,1.6813971769219238
3.830291099793149e-05,0.0018391999999999998,156.68644303179704,442.88932703492054,1.6813971769219238
3.880273149812198e-05,0.0018632,156.78035327832748,442.88932703492054,1.6813971769219238
3.9302551998312474e-05,0.0018872,156.87379292340586,442.88932703492054,1.6813971769219238
3.971906908180456e-05,0.0019072,156.95130580170627,442.88932703492054,1.6813971769219238
3.988567591520139e-05,0.0019152,156.98222211209972,442.88932703492054,1.6813971769219238
4.028553231535378e-05,0.0019344,157.05621648778097,442.88932703492054,1.6813971769219238
4.061874598214744e-05,0.0019504,157.117659919041,442.88932703492054,1.6813971769219238
4.078535281554427e-05,0.0019584,157.1483078949534,442.88932703492054,1.6813971769219238
4.103526306563952e-05,0.0019703999999999998,157.19418846809853,442.88932703492054,1.6813971769219238
4.153508356583001e-05,0.0019944,157.28562399463087,442.88932703492054,1.6813971769219238
4.180165449926494e-05,0.0020071999999999998,157.3342140987602,442.88932703492054,1.6813971769219238
4.2068225432699876e-05,0.00202,157.3826835062085,442.88932703492054,1.6813971769219238
4.226815363277607e-05,0.0020296,157.4189569939332,442.88932703492054,1.6813971769219238
4.2717992082947515e-05,0.0020512,157.50032857809626,442.88932703492054,1.6813971769219238
4.3117848483099916e-05,0.0020704,157.5723787454207,442.88932703492054,1.6813971769219238
4.335109804985547e-05,0.0020816,157.6142876718099,442.88932703492054,1.6813971769219238
4.356768693327136e-05,0.002092,157.65312442842014,442.88932703492054,1.6813971769219238
4.380093650002692e-05,0.0021032,157.6948645156832,442.88932703492054,1.6813971769219238
4.405084675012216e-05,0.0021152,157.73948995755893,442.88932703492054,1.6813971769219238
4.4250774950198364e-05,0.0021248,157.77511926180898,442.88932703492054,1.6813971769219238
4.440072110025551e-05,0.0021319999999999998,157.80180005487003,442.88932703492054,1.6813971769219238
4.455066725031266e-05,0.0021392,157.82844573042584,442.88932703492054,1.6813971769219238
4.461730998367139e-05,0.0021424,157.8402770235995,442.88932703492054,1.6813971769219238
4.531705868393809e-05,0.002176,157.96409232703414,442.88932703492054,1.6813971769219238
4.538370141729682e-05,0.0021792,157.9758452375834,442.88932703492054,1.6813971769219238
4.555030825069364e-05,0.0021872,158.0051981053572,442.88932703492054,1.6813971769219238
4.576689713410953e-05,0.0021976,158.04329431201444,442.88932703492054,1.6813971769219238
4.605012875088414e-05,0.0022112,158.0930065045762,442.88932703492054,1.6813971769219238
4.6266717634300015e-05,0.0022216,158.13094129363338,442.88932703492054,1.6813971769219238
4.6599931301093676e-05,0.0022375999999999997,158.1891675500295,442.88932703492054,1.6813971769219238
4.686650223452862e-05,0.0022504,158.2356317292299,442.88932703492054,1.6813971769219238
4.7049769751265125e-05,0.0022592,158.2675160804704,442.88932703492054,1.6813971769219238
4.741630478473815e-05,0.0022768,158.3311398450246,442.88932703492054,1.6813971769219238
4.7932785968268334e-05,0.0023016,158.42046691069254,442.88932703492054,1.6813971769219238
4.8082732118325475e-05,0.0023087999999999997,158.44633016244265,442.88932703492054,1.6813971769219238
4.828266031840168e-05,0.0023184,158.48076562077557,442.88932703492054,1.6813971769219238
4.889910560196995e-05,0.002348,158.58659321314167,442.88932703492054,1.6813971769219238
4.969881840227474e-05,0.0023864,158.72311094612527,442.88932703492054,1.6813971769219238
5.006535343574777e-05,0.002404,158.78539498906468,442.88932703492054,1.6813971769219238
5.1281583319544644e-05,0.0024624,158.99080237073474,442.88932703492054,1.6813971769219238
5.139820810292242e-05,0.0024679999999999997,159.010398605284,442.88932703492054,1.6813971769219238
5.17147610863764e-05,0.0024832,159.06350116625103,442.88932703492054,1.6813971769219238
5.216459953654784e-05,0.0025047999999999997,159.1387451472594,442.88932703492054,1.6813971769219238
5.229788500326531e-05,0.0025112,159.16099100694746,442.88932703492054,1.6813971769219238
5.2531134570020867e-05,0.0025223999999999997,159.19986812964274,442.88932703492054,1.6813971769219238
5.2831026870135175e-05,0.0025368,159.24975422135583,442.88932703492054,1.6813971769219238
5.3247543953627245e-05,0.0025567999999999997,159.31885763567558,442.88932703492054,1.6813971769219238
5.369738240379869e-05,0.0025784,159.39325296414233,442.88932703492054,1.6813971769219238
5.4197202903989186e-05,0.0026024,159.47562995296235,442.88932703492054,1.6813971769219238
5.4397131104065376e-05,0.0026119999999999997,159.50849772482647,442.88932703492054,1.6813971769219238
5.486363023757651e-05,0.0026344,159.58500652292443,442.88932703492054,1.6813971769219238
5.5113540487671755e-05,0.0026463999999999997,159.6258889950782,442.88932703492054,1.6813971769219238
5.5680003721220986e-05,0.0026736,159.7182892107284,442.88932703492054,1.6813971769219238
5.596323533799559e-05,0.0026872,159.76435178512415,442.88932703492054,1.6813971769219238
5.604653875469401e-05,0.0026912,159.77788228670502,442.88932703492054,1.6813971769219238
5.631310968812894e-05,0.002704,159.82112728040704,442.88932703492054,1.6813971769219238
5.652969857154482e-05,0.0027144,159.85620508149762,442.88932703492054,1.6813971769219238
5.659634130490355e-05,0.0027175999999999997,159.86698770091581,442.88932703492054,1.6813971769219238
5.692955497169722e-05,0.0027336,159.92082670119643,442.88932703492054,1.6813971769219238
5.717946522179246e-05,0.0027456,159.96112533621823,442.88932703492054,1.6813971769219238
5.777924982202105e-05,0.0027743999999999998,160.05756282818209,442.88932703492054,1.6813971769219238
5.801249938877662e-05,0.0027856,160.09496076166423,442.88932703492054,1.6813971769219238
5.8312391688890916e-05,0.0028,160.14295776355834,442.88932703492054,1.6813971769219238
5.8895515605779824e-05,0.002828,160.23601057509134,442.88932703492054,1.6813971769219238
5.969522840608461e-05,0.0028664,160.3630436737705,442.88932703492054,1.6813971769219238
6.026169163963384e-05,0.0028936,160.4526241985191,442.88932703492054,1.6813971769219238
6.051160188972909e-05,0.0029056,160.49204055271613,442.88932703492054,1.6813971769219238
6.067820872312591e-05,0.0029135999999999997,160.51828285731705,442.88932703492054,1.6813971769219238
6.0878136923202115e-05,0.0029232,160.54973655831532,442.88932703492054,1.6813971769219238
6.117802922331641e-05,0.0029376,160.5968416798998,442.88932703492054,1.6813971769219238
6.154456425678944e-05,0.0029552,160.65429248853704,442.88932703492054,1.6813971769219238
6.1777813823545e-05,0.0029663999999999997,160.69078262758381,442.88932703492054,1.6813971769219238
6.214434885701803e-05,0.0029839999999999997,160.74801590286603,442.88932703492054,1.6813971769219238
6.259418730718947e-05,0.0030055999999999998,160.81807712410549,442.88932703492054,1.6813971769219238
6.272747277390695e-05,0.003012,160.83879825798616,442.88932703492054,1.6813971769219238
6.302736507402123e-05,0.0030264,160.88535812961905,442.88932703492054,1.6813971769219238
6.384373855766571e-05,0.0030656,161.01166876635548,442.88932703492054,1.6813971769219238
6.431023769117684e-05,0.003088,161.0835634401464,442.88932703492054,1.6813971769219238
6.441020179121494e-05,0.0030927999999999997,161.09894294747124,442.88932703492054,1.6813971769219238
6.489336160806575e-05,0.003116,161.17314640348346,442.88932703492054,1.6813971769219238
6.502664707478321e-05,0.0031224,161.19357836453128,442.88932703492054,1.6813971769219238
6.569307440837053e-05,0.0031544,161.2954941970434,442.88932703492054,1.6813971769219238
6.584302055842768e-05,0.0031615999999999997,161.31836959782575,442.88932703492054,1.6813971769219238
6.604294875850388e-05,0.0031712,161.34883855311884,442.88932703492054,1.6813971769219238
6.645946584199597e-05,0.0031912,161.4122002496261,442.88932703492054,1.6813971769219238
6.664273335873247e-05,0.0031999999999999997,161.4400303132375,442.88932703492054,1.6813971769219238
6.680934019212931e-05,0.003208,161.46530448098312,442.88932703492054,1.6813971769219238
6.735914274233884e-05,0.0032343999999999997,161.54853537888306,442.88932703492054,1.6813971769219238
6.8192176909323e-05,0.0032744,161.67413973554883,442.88932703492054,1.6813971769219238
6.837544442605952e-05,0.0032832,161.70169222310048,442.88932703492054,1.6813971769219238
6.85920333094754e-05,0.0032936,161.7342171494148,442.88932703492054,1.6813971769219238
6.955835294317702e-05,0.0033399999999999997,161.87884311537894,442.88932703492054,1.6813971769219238
6.990822729331038e-05,0.0033568,161.93101419956358,442.88932703492054,1.6813971769219238
7.012481617672624e-05,0.0033672,161.96325955882236,442.88932703492054,1.6813971769219238
7.029142301012307e-05,0.0033751999999999996,161.98803725785785,442.88932703492054,1.6813971769219238
7.047469052685959e-05,0.003384,162.01526628748255,442.88932703492054,1.6813971769219238
7.084122556033261e-05,0.0034016,162.0696416423061,442.88932703492054,1.6813971769219238
7.095785034371041e-05,0.0034072,162.08691986709934,442.88932703492054,1.6813971769219238
7.162427767729773e-05,0.0034392,162.185440942162,442.88932703492054,1.6813971769219238
7.16575990439771e-05,0.0034408,162.1903575898084,442.88932703492054,1.6813971769219238
7.177422382735487e-05,0.0034463999999999996,162.20755883924429,442.88932703492054,1.6813971769219238
7.190750929407234e-05,0.0034528,162.2272040681157,442.88932703492054,1.6813971769219238
7.215741954416758e-05,0.0034647999999999997,162.26400063761855,442.88932703492054,1.6813971769219238
7.275720414439618e-05,0.0034936,162.3521102091575,442.88932703492054,1.6813971769219238
7.327368532792635e-05,0.0035183999999999997,162.42775559099277,442.88932703492054,1.6813971769219238
7.344029216132318e-05,0.0035264,162.4521129304466,442.88932703492054,1.6813971769219238
7.384014856147558e-05,0.0035456,162.51048278770892,442.88932703492054,1.6813971769219238
7.397343402819306e-05,0.003552,162.5299119960233,442.88932703492054,1.6813971769219238
7.448991521172322e-05,0.0035767999999999998,162.60507157513098,442.88932703492054,1.6813971769219238
7.465652204512006e-05,0.0035848,162.6292732099757,442.88932703492054,1.6813971769219238
7.475648614515815e-05,0.0035895999999999996,162.64378408052536,442.88932703492054,1.6813971769219238
7.505637844527246e-05,0.003604,162.6872713550232,442.88932703492054,1.6813971769219238
7.535627074538675e-05,0.0036184,162.7306909172225,442.88932703492054,1.6813971769219238
7.563950236216136e-05,0.003632,162.771636444766,442.88932703492054,1.6813971769219238
7.578944851221851e-05,0.0036392,162.79328927900877,442.88932703492054,1.6813971769219238
7.633925106242805e-05,0.0036655999999999998,162.8725404672402,442.88932703492054,1.6813971769219238
7.695569634599632e-05,0.0036952,162.961133624723,442.88932703492054,1.6813971769219238
7.72722493294503e-05,0.0037104,163.0065198272873,442.88932703492054,1.6813971769219238
7.773874846296143e-05,0.0037327999999999997,163.07327281165666,442.88932703492054,1.6813971769219238
7.850513989658685e-05,0.0037695999999999997,163.18260027470814,442.88932703492054,1.6813971769219238
7.907160313013609e-05,0.0037968,163.263140191586,442.88932703492054,1.6813971769219238
7.950478089696785e-05,0.0038176,163.3245777999656,442.88932703492054,1.6813971769219238
7.960474499700593e-05,0.0038223999999999997,163.33873715379977,442.88932703492054,1.6813971769219238
7.993795866379959e-05,0.0038383999999999996,163.38588499769716,442.88932703492054,1.6813971769219238
8.007124413051707e-05,0.0038447999999999998,163.40472266658108,442.88932703492054,1.6813971769219238
8.012122618053612e-05,0.0038472,163.41178363907508,442.88932703492054,1.6813971769219238
8.047110053066946e-05,0.003864,163.46116243462404,442.88932703492054,1.6813971769219238
8.107088513089805e-05,0.0038927999999999996,163.54561744288458,442.88932703492054,1.6813971769219238
8.167066973112665e-05,0.0039216,163.62982911941197,442.88932703492054,1.6813971769219238
8.190391929788222e-05,0.0039328,163.6625129249857,442.88932703492054,1.6813971769219238
8.217049023131714e-05,0.0039456,163.6998214289309,442.88932703492054,1.6813971769219238
8.258700731480921e-05,0.0039656,163.75802160736896,442.88932703492054,1.6813971769219238
8.272029278152668e-05,0.003972,163.7766214726811,442.88932703492054,1.6813971769219238
8.305350644832035e-05,0.003988,163.82307007352526,442.88932703492054,1.6813971769219238
8.33034166984156e-05,0.004,163.85785884435245,442.88932703492054,1.6813971769219238
8.73027805727144e-05,0.0041920384076815365,164.40916822588957,442.88932703492054,1.6813971769219238
8.890252612243393e-05,0.004268853770754151,164.62692296270018,442.88932703492054,1.6813971769219238
9.650131748360167e-05,0.00463372674534907,165.64107959632454,442.88932703492054,1.6813971769219238
0.00010889934549392798,0.005229045809161833,167.23124357896717,442.88932703492054,1.6813971769219238
0.00011729800962995546,0.005632326465293058,168.26847358464934,442.88932703492054,1.6813971769219238
0.00012849622847799214,0.00617003400680136,169.6074359319067,442.88932703492054,1.6813971769219238
0.00013289552873972082,0.00638127625525105,170.1209020052918,442.88932703492054,1.6813971769219238
0.00013889457455116904,0.006669333866773355,170.81052391176846,442.88932703492054,1.6813971769219238
0.0001412941928757483,0.006784556911382277,171.0831077712316,442.88932703492054,1.6813971769219238
0.0001496928570117758,0.007187837567513502,172.02324890193043,442.88932703492054,1.6813971769219238
0.00016569031250897103,0.007955991198239648,173.75891352193807,442.88932703492054,1.6813971769219238
0.00019008643214219378,0.00912742548509702,176.28476139803593,442.88932703492054,1.6813971769219238
0.00019448573240392247,0.00933866773354671,176.72644192159473,442.88932703492054,1.6813971769219238
0.00020128465099023045,0.009665133026605321,177.4014506796657,442.88932703492054,1.6813971769219238
0.00020408420570223963,0.009799559911982397,177.67680383165802,442.88932703492054,1.6813971769219238
0.00021488248816284642,0.010318063612722545,178.72535980764607,442.88932703492054,1.6813971769219238
0.00022528083423602332,0.01081736347269454,179.71582139648694,442.88932703492054,1.6813971769219238
0.00022728051617317268,0.010913382676535306,179.90423330524249,442.88932703492054,1.6813971769219238
0.00024247809889550815,0.011643128625725144,181.31561771523332,442.88932703492054,1.6813971769219238
0.00024607752638237707,0.011815963192638527,181.6447874982469,442.88932703492054,1.6813971769219238
0.00025127669941896555,0.012065613122624524,182.11695899040433,442.88932703492054,1.6813971769219238
0.0002776725009893377,0.013333066613322665,184.4577469735888,442.88932703492054,1.6813971769219238
0.0002792722465390572,0.013409881976395279,184.5967567613015,442.88932703492054,1.6813971769219238
0.00028247173763849625,0.013563512702540508,184.8738481703305,442.88932703492054,1.6813971769219238
0.0002864711015127951,0.013755551110222045,185.21849712052546,442.88932703492054,1.6813971769219238
0.00029247014732424327,0.01404360872174435,185.73197271786282,442.88932703492054,1.6813971769219238
0.00030006893868541104,0.014408481696339268,186.37651618674593,442.88932703492054,1.6813971769219238
0.00030566804810942935,0.01467733546709342,186.8473768186376,442.88932703492054,1.6813971769219238
0.00030766773004657877,0.014773354670934187,187.0147245670835,442.88932703492054,1.6813971769219238
0.0003128669030831672,0.015023004600920185,187.44785544529535,442.88932703492054,1.6813971769219238
0.00031806607611975567,0.015272654530906182,187.87818814349174,442.88932703492054,1.6813971769219238
0.00033126397690494175,0.015906381276255252,188.9584284926546,442.88932703492054,1.6813971769219238
0.00033806289549124965,0.016232846569313862,189.50835649831265,442.88932703492054,1.6813971769219238
0.0003420622593655485,0.0164248849769954,189.82982875506892,442.88932703492054,1.6813971769219238
0.0003492611143392863,0.016770554110822164,190.4048089226621,442.88932703492054,1.6813971769219238
0.00036005939679989316,0.017289057811562314,191.25868739674263,442.88932703492054,1.6813971769219238
0.00037165755203535965,0.017845969193838768,192.16476590925666,442.88932703492054,1.6813971769219238
0.0003760568522970884,0.01805721144228846,192.50555751672832,442.88932703492054,1.6813971769219238
0.00038165596172110667,0.018326065213042607,192.9370519138263,442.88932703492054,1.6813971769219238
0.0003896546894697043,0.01871014202840568,193.54921419457898,442.88932703492054,1.6813971769219238
0.0004116511907783478,0.01976635327065413,195.20789456832077,442.88932703492054,1.6813971769219238
0.00041605049104007644,0.01997759551910382,195.535442443065,442.88932703492054,1.6813971769219238
0.00042524902795096375,0.020419283856771355,196.21598230106267,442.88932703492054,1.6813971769219238
0.00043204794653727165,0.020745749149829965,196.7153057651184,442.88932703492054,1.6813971769219238
0.00044124648344815896,0.0211874374874975,197.38601040282634,442.88932703492054,1.6813971769219238
0.0004468455928721773,0.02145629125825165,197.79159622588784,442.88932703492054,1.6813971769219238
0.00045204476590876574,0.021705941188237647,198.1664404577295,442.88932703492054,1.6813971769219238
0.0004528446386836255,0.021744348869773954,198.2239592249059,442.88932703492054,1.6813971769219238
0.00045884368449507375,0.02203240648129626,198.65409409761781,442.88932703492054,1.6813971769219238
0.00046564260308138165,0.02235887177435487,199.13893767587382,442.88932703492054,1.6813971769219238
0.0004676422850185311,0.02245489097819564,199.28101226941598,442.88932703492054,1.6813971769219238
0.00047484113999226896,0.022800560112022406,199.7905306224282,442.88932703492054,1.6813971769219238
0.00048363974051572633,0.023223044608921786,200.40920229223758,442.88932703492054,1.6813971769219238
0.0004964377049134825,0.0238375675135027,201.3013092044799,442.88932703492054,1.6813971769219238
0.0005052363054369399,0.02426005201040208,201.9094360830033,442.88932703492054,1.6813971769219238
0.0005208338245467053,0.025009001800360073,202.97742418955258,442.88932703492054,1.6813971769219238
0.000531632107007312,0.02552750550110022,203.70950419506624,442.88932703492054,1.6813971769219238
0.0005372312164313303,0.02579635927185437,204.08681674706912,442.88932703492054,1.6813971769219238
0.0005388309619810498,0.025873174634926985,204.19433824196483,442.88932703492054,1.6813971769219238
0.0005472296261170774,0.026276455291058213,204.7567965669785,442.88932703492054,1.6813971769219238
0.0005536286083159555,0.02658371674334867,205.1830794096559,442.88932703492054,1.6813971769219238
0.0005560282266405348,0.026698939787957593,205.3424395240076,442.88932703492054,1.6813971769219238
0.0005636270180017025,0.02706381276255251,205.8453194652335,442.88932703492054,1.6813971769219238
0.0005684262546508611,0.027294258851770354,206.16156591811287,442.88932703492054,1.6813971769219238
0.0005744253004623093,0.02758231646329266,206.55541342256154,442.88932703492054,1.6813971769219238
0.000575225173237169,0.027620724144828968,206.60780495875701,442.88932703492054,1.6813971769219238
0.0005776247915617483,0.02773594718943789,206.76480935782308,442.88932703492054,1.6813971769219238
0.0005832239009857667,0.02800480096019204,207.13016704298838,442.88932703492054,1.6813971769219238
0.000588823010409785,0.02827365473094619,207.4941593225396,442.88932703492054,1.6813971769219238
0.0006016209748075411,0.028888177635527104,208.321110378415,442.88932703492054,1.6813971769219238
0.0006060202750692699,0.029099419883976796,208.60378654855668,442.88932703492054,1.6813971769219238
0.0006112194481058583,0.02934906981396279,208.9368286756221,442.88932703492054,1.6813971769219238
0.0006228176033413248,0.02990598119623925,209.6758130495948,442.88932703492054,1.6813971769219238
0.0006272169036030535,0.030117223444688937,209.95471103641668,442.88932703492054,1.6813971769219238
0.0006380151860636604,0.030635727145429087,210.6360638191498,442.88932703492054,1.6813971769219238
0.0006484135321368372,0.03113502700540108,211.28794323434389,442.88932703492054,1.6813971769219238
0.0006540126415608556,0.03140388077615523,211.6372659557175,442.88932703492054,1.6813971769219238
0.0006680104151209014,0.03207601520304061,212.50550839660497,442.88932703492054,1.6813971769219238
0.0006800085067437978,0.03265213042608522,213.24408358979275,442.88932703492054,1.6813971769219238
0.0006816082522935173,0.03272894578915783,213.34217487574045,442.88932703492054,1.6813971769219238
0.0006900069164295448,0.033132226445289056,213.8556884945411,442.88932703492054,1.6813971769219238
0.0007008051988901516,0.033650730146029206,214.51235250848043,442.88932703492054,1.6813971769219238
0.0007044046263770205,0.03382356471294259,214.73036204745455,442.88932703492054,1.6813971769219238
0.00070640430831417,0.03391958391678336,214.85129071665222,442.88932703492054,1.6813971769219238
0.0007184023999370664,0.034495699139827966,215.57407883575127,442.88932703492054,1.6813971769219238
0.0007220018274239353,0.03466853370674135,215.7899952366409,442.88932703492054,1.6813971769219238
0.0007284008096228134,0.034975795159031806,216.1728129183285,442.88932703492054,1.6813971769219238
0.0007479976926068777,0.03591678335667134,217.3371142124628,442.88932703492054,1.6813971769219238
0.0007491975017691673,0.0359743948789758,217.40800902905434,442.88932703492054,1.6813971769219238
0.0007603957206172039,0.0365121024204841,218.06757251388512,442.88932703492054,1.6813971769219238
0.0007779929216641188,0.037357071414282864,219.0964267131397,442.88932703492054,1.6813971769219238
0.0007803925399886978,0.037472294458891775,219.23601851913017,442.88932703492054,1.6813971769219238
0.0007819922855384175,0.037549109821964397,219.32898673500264,442.88932703492054,1.6813971769219238
0.0007915907588367347,0.038010002000400084,219.88524633651983,442.88932703492054,1.6813971769219238
0.0008183864967945367,0.03929665933186638,221.42438505428277,442.88932703492054,1.6813971769219238
0.0008275850337054239,0.03973834766953391,221.94819790159917,442.88932703492054,1.6813971769219238
0.000833584079516872,0.04002640528105621,222.28859210763503,442.88932703492054,1.6813971769219238
0.0008391831889408904,0.04029525905181036,222.60543240388122,442.88932703492054,1.6813971769219238
0.0008443823619774788,0.04054490898179636,222.89890381715884,442.88932703492054,1.6813971769219238
0.0008491815986266375,0.04077535507101421,223.16917561142753,442.88932703492054,1.6813971769219238
0.000857180326375235,0.04115943188637727,223.61830854068444,442.88932703492054,1.6813971769219238
0.0008631793721866833,0.04144748949789959,223.95408636724903,442.88932703492054,1.6813971769219238
0.0008735777182598602,0.04194678935787158,224.5339532445972,442.88932703492054,1.6813971769219238
0.0008859757462701864,0.042542108421684335,225.22182657003154,442.88932703492054,1.6813971769219238
0.0008927746648564944,0.04286857371474295,225.59745324708067,442.88932703492054,1.6813971769219238
0.0008979738378930829,0.04311822364472895,225.88394490407882,442.88932703492054,1.6813971769219238
0.0009055726292542507,0.04348309661932387,226.30150253545037,442.88932703492054,1.6813971769219238
0.0009175707208771469,0.04405921184236847,226.9580326084604,442.88932703492054,1.6813971769219238
0.000921170148364016,0.044232046409281855,227.15433764502873,442.88932703492054,1.6813971769219238
0.0009255694486257446,0.04444328865773155,227.39386024040712,442.88932703492054,1.6813971769219238
0.0009455662679972387,0.045403480696139226,228.47705166302626,442.88932703492054,1.6813971769219238
0.0009487657590966777,0.045557111422284455,228.64952978238364,442.88932703492054,1.6813971769219238
0.0009655630873687326,0.046363672734546904,229.5513451847046,442.88932703492054,1.6813971769219238
0.0009735618151173304,0.046747749549909984,229.97862875771474,442.88932703492054,1.6813971769219238
0.0009771612426041994,0.04692058411682337,230.1704594707974,442.88932703492054,1.6813971769219238
0.0009867597159025166,0.04738147629525906,230.6806655230185,442.88932703492054,1.6813971769219238
0.0009919588889391049,0.047631126225245055,230.95621883644378,442.88932703492054,1.6813971769219238
0.000998357871137983,0.04793838767753551,231.29458935670831,442.88932703492054,1.6813971769219238
0.0010039569805620012,0.04820724144828965,231.58997032352687,442.88932703492054,1.6813971769219238
0.0010163550085723278,0.048802560512102425,232.2417514318923,442.88932703492054,1.6813971769219238
0.0010191545632843367,0.048936987397479495,232.3884978045861,442.88932703492054,1.6813971769219238
0.0010259534818706448,0.04926345269053811,232.7442288786937,442.88932703492054,1.6813971769219238
0.0010287530365826539,0.04939787957591518,232.89043901442935,442.88932703492054,1.6813971769219238
0.0010323524640695229,0.04957071414282857,233.07819566592366,442.88932703492054,1.6813971769219238
0.0010415510009804101,0.0500124024804961,233.55686198229276,442.88932703492054,1.6813971769219238
0.0010447504920798492,0.05016603320664133,233.7229677877066,442.88932703492054,1.6813971769219238
0.0010539490289907362,0.050607721544308856,234.19942046974373,442.88932703492054,1.6813971769219238
0.001058748265639895,0.05083816763352671,234.44736052847733,442.88932703492054,1.6813971769219238
0.001061547820351904,0.05097259451890378,234.59178981232608,442.88932703492054,1.6813971769219238
0.0010643473750639133,0.05110702140428086,234.73607062349728,442.88932703492054,1.6813971769219238
0.0010699464844879315,0.051375875175035,235.0241889946338,442.88932703492054,1.6813971769219238
0.0010707463572627914,0.05141428285657132,235.06530070933988,442.88932703492054,1.6813971769219238
0.0010871437491474165,0.05220164032806561,235.9054693648214,442.88932703492054,1.6813971769219238
0.0010967422224457337,0.0526625325065013,236.3949822238483,442.88932703492054,1.6813971769219238
0.001102741268257182,0.05295059011802361,236.70007945362255,442.88932703492054,1.6813971769219238
0.0011095401868434897,0.053277055411082214,237.045074876458,442.88932703492054,1.6813971769219238
0.0011115398687806392,0.05337307461492298,237.14638708487274,442.88932703492054,1.6813971769219238
0.0011247377695658253,0.054006801360272055,237.81327379731766,442.88932703492054,1.6813971769219238
0.0011351361156390022,0.054506101220244046,238.3365525829772,442.88932703492054,1.6813971769219238
0.00114273490700017,0.05487097419483897,238.71776713094823,442.88932703492054,1.6813971769219238
0.0011547329986230665,0.05544708941788358,239.31767813339752,442.88932703492054,1.6813971769219238
0.0011595322352722249,0.05567753550710142,239.5569612642809,442.88932703492054,1.6813971769219238
0.0011683308357956822,0.0561000200040008,239.99464623329274,442.88932703492054,1.6813971769219238
0.0011751297543819905,0.05642648529705942,240.33197746755863,442.88932703492054,1.6813971769219238
0.001183128482130588,0.05681056211242248,240.72786480014804,442.88932703492054,1.6813971769219238
0.0011943267009786246,0.05734826965393079,241.28035792570594,442.88932703492054,1.6813971769219238
0.001199125937627783,0.05757871574314863,241.51652182230794,442.88932703492054,1.6813971769219238
0.0012039251742769418,0.05780916183236648,241.75231737968744,442.88932703492054,1.6813971769219238
0.0012095242837009599,0.05807801560312062,242.02694937646174,442.88932703492054,1.6813971769219238
0.0012143235203501187,0.05830846169233847,242.2619538359805,442.88932703492054,1.6813971769219238
0.001227121484747875,0.05892298459691939,242.88686824205845,442.88932703492054,1.6813971769219238
0.0012483181132816586,0.05994078815763153,243.9163202983617,442.88932703492054,1.6813971769219238
0.0012511176679936675,0.0600752150430086,244.05177419558498,442.88932703492054,1.6813971769219238
0.0012651154415537133,0.06074734946989398,244.72727863455393,442.88932703492054,1.6813971769219238
0.0012683149326531524,0.060900980196039206,244.8812696344571,442.88932703492054,1.6813971769219238
0.0012751138512394607,0.06122744548909782,245.2079983863553,442.88932703492054,1.6813971769219238
0.0012815128334383386,0.06153470694138828,245.51488769834754,442.88932703492054,1.6813971769219238
0.0012867120064749271,0.06178435687137428,245.76379544638732,442.88932703492054,1.6813971769219238
0.0012911113067366558,0.06199559911982397,245.97410347917517,442.88932703492054,1.6813971769219238
0.0012987100980978235,0.06236047209441889,246.33670573320313,442.88932703492054,1.6813971769219238
0.001303909271134412,0.06261012202440489,246.58432540371174,442.88932703492054,1.6813971769219238
0.0013087085077835704,0.06284056811362272,246.81255584764068,442.88932703492054,1.6813971769219238
0.0013171071719195978,0.06324384876975395,247.2111752489445,442.88932703492054,1.6813971769219238
0.0013227062813436163,0.0635127025405081,247.47637092478476,442.88932703492054,1.6813971769219238
0.0013271055816053451,0.06372394478895779,247.68443194161233,442.88932703492054,1.6813971769219238
0.001330305072704784,0.06387757551510302,247.8355801315782,442.88932703492054,1.6813971769219238
0.0013327046910293634,0.06399279855971195,247.94884825236562,442.88932703492054,1.6813971769219238
0.0013427031007151103,0.06447289457891578,248.41994515676427,442.88932703492054,1.6813971769219238
0.0013491020829139884,0.06478015603120624,248.72072932921668,442.88932703492054,1.6813971769219238
0.0013543012559505767,0.06502980596119223,248.96470698631674,442.88932703492054,1.6813971769219238
0.0013619000473117445,0.06539467893578715,249.32063365942977,442.88932703492054,1.6813971769219238
0.0013726983297723515,0.0659131826365273,249.82509475618505,442.88932703492054,1.6813971769219238
0.0013806970575209491,0.06629725945189038,250.19777242425099,442.88932703492054,1.6813971769219238
0.0013970944494055744,0.06708461692338469,250.95913960291358,442.88932703492054,1.6813971769219238
0.0014018936860547327,0.06731506301260252,251.18131846486784,442.88932703492054,1.6813971769219238
0.0014098924138033306,0.0676991398279656,251.55095850869503,442.88932703492054,1.6813971769219238
0.001415091586839919,0.0679487897579516,251.79078604002828,442.88932703492054,1.6813971769219238
0.0014286894240125348,0.06860172034406882,252.41640817308337,442.88932703492054,1.6813971769219238
0.0014446868795097302,0.06936987397479497,253.14946884273445,442.88932703492054,1.6813971769219238
0.0014478863706091692,0.0695235047009402,253.2957003381732,442.88932703492054,1.6813971769219238
0.0014558850983577667,0.06990758151630326,253.66072880401867,442.88932703492054,1.6813971769219238
0.0014606843350069253,0.07013802760552111,253.87937047431302,442.88932703492054,1.6813971769219238
0.0014698828719178125,0.07057971594318864,254.2976521644367,442.88932703492054,1.6813971769219238
0.0014746821085669711,0.07081016203240649,254.51548076107588,442.88932703492054,1.6813971769219238
0.001475881917729261,0.07086777355471095,254.56989468978904,442.88932703492054,1.6813971769219238
0.0014774816632789802,0.07094458891778356,254.64241976617174,442.88932703492054,1.6813971769219238
0.0014834807090904284,0.07123264652930586,254.91411647806208,442.88932703492054,1.6813971769219238
0.0014890798185144467,0.07150150030006001,255.16731373029015,442.88932703492054,1.6813971769219238
0.0015062770831739318,0.07232726545309062,255.9426794443681,442.88932703492054,1.6813971769219238
0.001518675111184258,0.07292258451690338,256.4995239269221,442.88932703492054,1.6813971769219238
0.0015298733300322946,0.07346029205841169,257.0009582298998,442.88932703492054,1.6813971769219238
0.0015366722486186025,0.07378675735147029,257.3047021739056,442.88932703492054,1.6813971769219238
0.0015534695768906577,0.07459331866373275,258.0528900353429,442.88932703492054,1.6813971769219238
0.0015606684318643955,0.07493898779755952,258.3725753894426,442.88932703492054,1.6813971769219238
0.001571866650712432,0.07547669533906781,258.86872299953944,442.88932703492054,1.6813971769219238
0.0015774657601364504,0.07574554910982197,259.1162797267867,442.88932703492054,1.6813971769219238
0.001589863788146777,0.07634086817363474,259.66322480116514,442.88932703492054,1.6813971769219238
0.0015982624522828043,0.07674414882976596,260.032791224734,442.88932703492054,1.6813971769219238
0.0016214587627537374,0.07785797159431887,261.04958456767076,442.88932703492054,1.6813971769219238
0.0016254581266280362,0.0780500100020004,261.2243188382152,442.88932703492054,1.6813971769219238
0.0016290575541149052,0.07822284456891379,261.38143637531425,442.88932703492054,1.6813971769219238
0.0016330569179892039,0.07841488297659532,261.555852712181,442.88932703492054,1.6813971769219238
0.0016354565363137833,0.07853010602120425,261.6604225543278,442.88932703492054,1.6813971769219238
0.001639855836575512,0.07874134826965394,261.85197865230026,442.88932703492054,1.6813971769219238
0.0016490543734863992,0.07918303660732147,262.25185861712623,442.88932703492054,1.6813971769219238
0.0016774498569939206,0.08054650930186037,263.4808183280846,442.88932703492054,1.6813971769219238
0.0016842487755802287,0.08087297459491899,263.7738691525702,442.88932703492054,1.6813971769219238
0.0017098447043757412,0.08210202040408082,264.8730058616496,442.88932703492054,1.6813971769219238
0.0017190432412866282,0.08254370874174835,265.2664382625553,442.88932703492054,1.6813971769219238
0.0017222427323860673,0.08269733946789358,265.403091747555,442.88932703492054,1.6813971769219238
0.0017398399334329821,0.08354230846169235,266.15292359140346,442.88932703492054,1.6813971769219238
0.0017446391700821407,0.08377275455091018,266.35690911251334,442.88932703492054,1.6813971769219238
0.0017522379614433085,0.0841376275255051,266.67943919654215,442.88932703492054,1.6813971769219238
0.0017566372617050371,0.0843488697739548,266.865917815889,442.88932703492054,1.6813971769219238
0.0017614364983541955,0.08457931586317263,267.0691414349574,442.88932703492054,1.6813971769219238
0.001767035607778214,0.08484816963392679,267.3059629280486,442.88932703492054,1.6813971769219238
0.0017694352261027934,0.08496339267853571,267.4073682447884,442.88932703492054,1.6813971769219238
0.0017790336994011106,0.0854242848569714,267.8124543299188,442.88932703492054,1.6813971769219238
0.0017830330632754093,0.08561632326465293,267.98098852722586,442.88932703492054,1.6813971769219238
0.0018026299462594734,0.08655731146229247,268.80468450895916,442.88932703492054,1.6813971769219238
0.001811028610395501,0.08696059211842369,269.156627175949,442.88932703492054,1.6813971769219238
0.0018150279742697997,0.08715263052610522,269.3239951471133,442.88932703492054,1.6813971769219238
0.0018242265111806867,0.08759431886377275,269.7083966080094,442.88932703492054,1.6813971769219238
0.001840623903065312,0.08838167633526706,270.3917643785961,442.88932703492054,1.6813971769219238
0.0018502223763636292,0.08884256851370274,270.7906828741995,442.88932703492054,1.6813971769219238
0.0018546216766253578,0.08905381076215244,270.9732507051855,442.88932703492054,1.6813971769219238
0.0018586210404996568,0.08924584916983397,271.1390749517244,442.88932703492054,1.6813971769219238
0.0018802176054208703,0.09028285657131427,272.0321326859543,442.88932703492054,1.6813971769219238
0.0018990146156300746,0.09118543708741748,272.80617236091626,442.88932703492054,1.6813971769219238
0.0019170117530644191,0.0920496099219844,273.5444789466046,442.88932703492054,1.6813971769219238
0.0019194113713889985,0.09216483296659332,273.64271518392974,442.88932703492054,1.6813971769219238
0.0019294097810747457,0.09264492898579717,274.05151834698296,442.88932703492054,1.6813971769219238
0.001935008890498764,0.09291378275655131,274.28008721632324,442.88932703492054,1.6813971769219238
0.0019378084452107733,0.09304820964192839,274.3942749133684,442.88932703492054,1.6813971769219238
0.001942207745472502,0.09325945189037808,274.5735828218404,442.88932703492054,1.6813971769219238
0.001945407236571941,0.09341308261652331,274.7038890986745,442.88932703492054,1.6813971769219238
0.001955405646257688,0.09389317863572715,275.11055855888895,442.88932703492054,1.6813971769219238
0.0019570053918074076,0.09396999399879977,275.175550340348,442.88932703492054,1.6813971769219238
0.0019602048829068467,0.094123624724945,275.30547177779937,442.88932703492054,1.6813971769219238
0.0019662039287182947,0.0944116823364673,275.54885177875127,442.88932703492054,1.6813971769219238
0.0019706032289800233,0.09462292458491699,275.7271464271669,442.88932703492054,1.6813971769219238
0.001971403101754883,0.09466133226645329,275.75954695105474,442.88932703492054,1.6813971769219238
0.0019806016386657707,0.09510302060412083,276.1317852281123,442.88932703492054,1.6813971769219238
0.001998598776100115,0.09596719343868775,276.85813321671,442.88932703492054,1.6813971769219238
0.0020041978855241333,0.0962360472094419,277.0835873102347,442.88932703492054,1.6813971769219238
0.0020105968677230114,0.09654330866173236,277.3409485651639,442.88932703492054,1.6813971769219238
0.0020153961043721702,0.0967737547509502,277.5337599242492,442.88932703492054,1.6813971769219238
0.0020177957226967494,0.09688897779555912,277.6300984487798,442.88932703492054,1.6813971769219238
0.0020209952137961885,0.09704260852170435,277.7584803388199,442.88932703492054,1.6813971769219238
0.0020317934962567953,0.0975611122224445,278.1911852119162,442.88932703492054,1.6813971769219238
0.0020505905064659995,0.09846369273854771,278.9422788369603,442.88932703492054,1.6813971769219238
0.002051790315628289,0.09852130426085218,278.9901296165166,442.88932703492054,1.6813971769219238
0.002063788407251186,0.09909741948389679,279.46803873943674,442.88932703492054,1.6813971769219238
0.0020709872622249235,0.09944308861772355,279.754264126719,442.88932703492054,1.6813971769219238
0.002079385926360951,0.09984636927385478,280.08770378813216,442.88932703492054,1.6813971769219238
0.0020805857355232407,0.09990398079615924,280.1352951137364,442.88932703492054,1.6813971769219238