File: datasets/aisi_316_L/data/M1/valid_15.csv
Time(s),Strain(%),Stress(MPa),Temp(C),Log_SR(s-1)
0.0,0.0,0.0,428.2457508635193,4.051575446656331
1.2077122229681845e-09,1.3599999999999999e-05,2.2697747624999995,428.2457508635193,4.051575446656331
2.202298759530219e-09,2.48e-05,4.1390010375,428.2457508635193,4.051575446656331
3.4100109824984036e-09,3.84e-05,6.4087758,428.2457508635193,4.051575446656331
5.257100264685038e-09,5.9199999999999996e-05,9.880196025,428.2457508635193,4.051575446656331
6.535854383121941e-09,7.36e-05,12.28348695,428.2457508635193,4.051575446656331
9.448572097339327e-09,0.0001064,17.7576496125,428.2457508635193,4.051575446656331
9.661697783745476e-09,0.00010879999999999999,18.158198099999996,428.2457508635193,4.051575446656331
1.200608033421313e-08,0.0001352,22.5642314625,428.2457508635193,4.051575446656331
1.4492546675618215e-08,0.00016319999999999998,27.237297149999996,428.2457508635193,4.051575446656331
1.6055468375929985e-08,0.0001808,30.174652725,428.2457508635193,4.051575446656331
1.6623803539679717e-08,0.0001872,31.242782025,428.2457508635193,4.051575446656331
1.8328809030928922e-08,0.0002064,34.447169925,428.2457508635193,4.051575446656331
1.8897144194678655e-08,0.0002128,35.515299225,428.2457508635193,4.051575446656331
2.2307155177177057e-08,0.0002512,41.92407502499999,428.2457508635193,4.051575446656331
2.358590929561396e-08,0.0002656,44.32736595,428.2457508635193,4.051575446656331
2.4083202563894975e-08,0.0002712,45.261979087499995,428.2457508635193,4.051575446656331
2.5006747204988295e-08,0.0002816,46.9976892,428.2457508635193,4.051575446656331
2.536195668233188e-08,0.0002856,47.6652700125,428.2457508635193,4.051575446656331
2.7138004069049797e-08,0.0003056,51.003174075,428.2457508635193,4.051575446656331
2.8843009560298995e-08,0.0003248,54.207561975,428.2457508635193,4.051575446656331
3.083218263342306e-08,0.0003472,57.946014524999995,428.2457508635193,4.051575446656331
3.1329475901704085e-08,0.0003528,58.880627662500004,428.2457508635193,4.051575446656331
3.303448139295328e-08,0.000372,62.0850155625,428.2457508635193,4.051575446656331
3.381594224310917e-08,0.0003808,63.553693349999996,428.2457508635193,4.051575446656331
3.4810528779671204e-08,0.000392,65.42291962499999,428.2457508635193,4.051575446656331
3.566303152529581e-08,0.0004016,67.025113575,428.2457508635193,4.051575446656331
3.658657616638912e-08,0.000412,68.7608236875,428.2457508635193,4.051575446656331
3.7225953225607576e-08,0.0004192,69.96246915,428.2457508635193,4.051575446656331
3.836262355310704e-08,0.000432,72.09872775,428.2457508635193,4.051575446656331
4.035179662623111e-08,0.0004544,75.8371803,428.2457508635193,4.051575446656331
4.0849089894512124e-08,0.00045999999999999996,76.7717934375,428.2457508635193,4.051575446656331
4.1985760222011596e-08,0.0004728,78.9080520375,428.2457508635193,4.051575446656331
4.560889689091615e-08,0.0005136,85.717376325,428.2457508635193,4.051575446656331
4.816640512778995e-08,0.0005424,90.52395817499999,428.2457508635193,4.051575446656331
5.0794955260132475e-08,0.000572,95.4640561875,428.2457508635193,4.051575446656331
5.377871486981857e-08,0.0006056,101.0717350125,428.2457508635193,4.051575446656331
5.413392434716216e-08,0.0006096,101.73931582499999,428.2457508635193,4.051575446656331
5.541267846559906e-08,0.000624,104.14260675,428.2457508635193,4.051575446656331
5.5838929838411365e-08,0.0006288,104.943703725,428.2457508635193,4.051575446656331
5.626518121122366e-08,0.0006336,105.7448007,428.2457508635193,4.051575446656331
5.89647732390349e-08,0.000664,110.818414875,428.2457508635193,4.051575446656331
5.931998271637848e-08,0.000668,111.4859956875,428.2457508635193,4.051575446656331
6.031456925294051e-08,0.0006791999999999999,113.35522196249998,428.2457508635193,4.051575446656331
6.074082062575281e-08,0.0006839999999999999,114.15631893749999,428.2457508635193,4.051575446656331
6.301416128075176e-08,0.0007096,118.4288361375,428.2457508635193,4.051575446656331
6.61400046813753e-08,0.0007448,124.3035472875,428.2457508635193,4.051575446656331
6.720563311340604e-08,0.0007568,126.306289725,428.2457508635193,4.051575446656331
6.812917775449936e-08,0.0007672,128.0419998375,428.2457508635193,4.051575446656331
7.260481716902851e-08,0.0008175999999999999,136.45351807499998,428.2457508635193,4.051575446656331
7.288898475090338e-08,0.0008208,136.987582725,428.2457508635193,4.051575446656331
7.587274436058947e-08,0.0008544,142.59526155,428.2457508635193,4.051575446656331
7.93537972385566e-08,0.0008935999999999999,149.13755351249998,428.2457508635193,4.051575446656331
8.10588027298058e-08,0.0009128,152.3419414125,428.2457508635193,4.051575446656331
8.283485011652371e-08,0.0009327999999999999,155.67984547499998,428.2457508635193,4.051575446656331
8.546340024886624e-08,0.0009624,160.6199434875,428.2457508635193,4.051575446656331
8.660007057636571e-08,0.0009752,162.7562020875,428.2457508635193,4.051575446656331
8.759465711292774e-08,0.0009864,164.43296043763883,428.2457508635193,4.051575446656331
8.837611796308362e-08,0.0009952,164.48019980114182,428.2457508635193,4.051575446656331
9.143091946823844e-08,0.0010295999999999999,164.6633205546761,428.2457508635193,4.051575446656331
9.363321822776868e-08,0.0010544,164.79386065977442,428.2457508635193,4.051575446656331
9.555134940542401e-08,0.001076,164.9065842373984,428.2457508635193,4.051575446656331
9.67590616283922e-08,0.0010896,164.97710577456317,428.2457508635193,4.051575446656331
9.75405224785481e-08,0.0010984,165.0225544972234,428.2457508635193,4.051575446656331
9.825094143323526e-08,0.0011064,165.06374843838734,428.2457508635193,4.051575446656331
9.867719280604755e-08,0.0011112,165.0884090473661,428.2457508635193,4.051575446656331
1.0187407810213981e-07,0.0011472,165.27205736897392,428.2457508635193,4.051575446656331
1.0414741875713874e-07,0.0011727999999999999,165.40128674814721,428.2457508635193,4.051575446656331
1.0535513098010693e-07,0.0011864,165.46949215203074,428.2457508635193,4.051575446656331
1.0762847163510586e-07,0.001212,165.5970572405484,428.2457508635193,4.051575446656331
1.0919139333541763e-07,0.0012296,165.68414928272816,428.2457508635193,4.051575446656331
1.0975972849916736e-07,0.001236,165.71569840235932,428.2457508635193,4.051575446656331
1.1061223124479197e-07,0.0012456,165.762902886368,428.2457508635193,4.051575446656331
1.1125160830401041e-07,0.0012527999999999999,165.7982131924663,428.2457508635193,4.051575446656331
1.1245932052697861e-07,0.0012664,165.86469524945042,428.2457508635193,4.051575446656331
1.1515891255478983e-07,0.0012967999999999999,166.01230354294512,428.2457508635193,4.051575446656331
1.170770437324452e-07,0.0013184,166.11636414707544,428.2457508635193,4.051575446656331
1.1807163026900723e-07,0.0013296,166.17005960382878,428.2457508635193,4.051575446656331
1.1856892353728824e-07,0.0013352,166.19684116116665,428.2457508635193,4.051575446656331
1.1984767765572513e-07,0.0013495999999999998,166.26550764250297,428.2457508635193,4.051575446656331
1.234708143246297e-07,0.0013904,166.458527936775,428.2457508635193,4.051575446656331
1.256020711886912e-07,0.0014144,166.57103743896488,428.2457508635193,4.051575446656331
1.280885375300963e-07,0.0014424,166.70136176665918,428.2457508635193,4.051575446656331
1.295093754394706e-07,0.0014583999999999999,166.77538977555133,428.2457508635193,4.051575446656331
1.3121438093071983e-07,0.0014776,166.86380659242366,428.2457508635193,4.051575446656331
1.3384293106306235e-07,0.0015072,166.99924300974342,428.2457508635193,4.051575446656331
1.3490855949509308e-07,0.0015191999999999998,167.05385366955957,428.2457508635193,4.051575446656331
1.3597418792712384e-07,0.0015312,167.1082963542602,428.2457508635193,4.051575446656331
1.370398163591546e-07,0.0015432,167.1625728909123,428.2457508635193,4.051575446656331
1.383896123730602e-07,0.0015584,167.2310874554629,428.2457508635193,4.051575446656331
1.3945524080509097e-07,0.0015704,167.28499397702979,428.2457508635193,4.051575446656331
1.3988149217790327e-07,0.0015752,167.30651157525315,428.2457508635193,4.051575446656331
1.4194170714649605e-07,0.0015983999999999998,167.4101549528504,428.2457508635193,4.051575446656331
1.4371775453321396e-07,0.0016183999999999999,167.4990326836712,428.2457508635193,4.051575446656331
1.4513859244258828e-07,0.0016343999999999998,167.56982683665302,428.2457508635193,4.051575446656331
1.4627526277008776e-07,0.0016472,167.62626774501854,428.2457508635193,4.051575446656331
1.4933006427524258e-07,0.0016816,167.77711147327432,428.2457508635193,4.051575446656331
1.497563156480549e-07,0.0016864,167.79806335499143,428.2457508635193,4.051575446656331
1.502536089163359e-07,0.001692,167.82247784444968,428.2457508635193,4.051575446656331
1.5416091316711534e-07,0.001736,168.0132214787292,428.2457508635193,4.051575446656331
1.5664737950852042e-07,0.001764,168.1336226839452,428.2457508635193,4.051575446656331
1.5813925931336346e-07,0.0017808,168.2055056873604,428.2457508635193,4.051575446656331
1.5977322290914396e-07,0.0017992,168.2839319118217,428.2457508635193,4.051575446656331
1.6154927029586187e-07,0.0018192,168.36882387151084,428.2457508635193,4.051575446656331
1.633963595780485e-07,0.0018399999999999998,168.45672629204935,428.2457508635193,4.051575446656331
1.6609595160585973e-07,0.0018704,168.58450513797422,428.2457508635193,4.051575446656331
1.6638011918773463e-07,0.0018736,168.59790825650256,428.2457508635193,4.051575446656331
1.6666428676960947e-07,0.0018767999999999999,168.61130245021667,428.2457508635193,4.051575446656331
1.6829825036538997e-07,0.0018951999999999999,168.68814692184404,428.2457508635193,4.051575446656331
1.6957700448382689e-07,0.0019096,168.74808329618688,428.2457508635193,4.051575446656331
1.714951356614822e-07,0.0019311999999999999,168.83765840837864,428.2457508635193,4.051575446656331
1.7199242892976322e-07,0.0019367999999999998,168.86081769707843,428.2457508635193,4.051575446656331
1.7256076409351296e-07,0.0019432,168.88725350189142,428.2457508635193,4.051575446656331
1.7419472768929346e-07,0.0019616,168.96306795268117,428.2457508635193,4.051575446656331
1.7497618853944933e-07,0.0019703999999999998,168.99922895243034,428.2457508635193,4.051575446656331
1.7582869128507394e-07,0.00198,169.03860555799355,428.2457508635193,4.051575446656331
1.77320571089917e-07,0.0019968,169.10733592268124,428.2457508635193,4.051575446656331
1.795939117449159e-07,0.0020223999999999997,169.21163583304192,428.2457508635193,4.051575446656331
1.8051745638600926e-07,0.0020328,169.25386044214355,428.2457508635193,4.051575446656331
1.829328808319456e-07,0.0020599999999999998,169.36389762472416,428.2457508635193,4.051575446656331
1.8492205390506969e-07,0.0020824,169.45409163591054,428.2457508635193,4.051575446656331
1.8563247285975686e-07,0.0020904,169.48621198139602,428.2457508635193,4.051575446656331
1.8648497560538144e-07,0.0021,169.52469318348545,428.2457508635193,4.051575446656331
1.8691122697819375e-07,0.0021048,169.54390805272624,428.2457508635193,4.051575446656331
1.884031067830368e-07,0.0021216,169.6110259276538,428.2457508635193,4.051575446656331
1.8953977711053626e-07,0.0021344,169.6620243242425,428.2457508635193,4.051575446656331
1.9017915416975472e-07,0.0021416,169.6906585032011,428.2457508635193,4.051575446656331
1.904633217516296e-07,0.0021448,169.7033727511755,428.2457508635193,4.051575446656331
1.9138686639272292e-07,0.0021552,169.74464305822443,428.2457508635193,4.051575446656331
1.9159999207912907e-07,0.0021576,169.75415593669118,428.2457508635193,4.051575446656331
1.9749646940303253e-07,0.002224,170.01573149219604,428.2457508635193,4.051575446656331
1.9913043299881303e-07,0.0022424,170.087675039559,428.2457508635193,4.051575446656331
2.016879412356868e-07,0.0022711999999999997,170.19982184767332,428.2457508635193,4.051575446656331
2.0261148587678016e-07,0.0022816,170.24018283016898,428.2457508635193,4.051575446656331
2.0403232378615448e-07,0.0022976,170.302136828804,428.2457508635193,4.051575446656331
2.0566628738193498e-07,0.002316,170.37317629673512,428.2457508635193,4.051575446656331
2.075133766641216e-07,0.0023368,170.4532172657753,428.2457508635193,4.051575446656331
2.1078130385568258e-07,0.0023736,170.59415085260275,428.2457508635193,4.051575446656331
2.1127859712396358e-07,0.0023791999999999997,170.61552233217873,428.2457508635193,4.051575446656331
2.1227318366052562e-07,0.0023904,170.6582065280362,428.2457508635193,4.051575446656331
2.1355193777896254e-07,0.0024048,170.71297177517263,428.2457508635193,4.051575446656331
2.1568319464302403e-07,0.0024288,170.80396382775194,428.2457508635193,4.051575446656331
2.164646554931799e-07,0.0024376,170.83723963392873,428.2457508635193,4.051575446656331
2.1909320562552241e-07,0.0024671999999999997,170.94882510746663,428.2457508635193,4.051575446656331
2.215086300714588e-07,0.0024944,171.05090364282725,428.2457508635193,4.051575446656331
2.2292946798083313e-07,0.0025104,171.11074706060654,428.2457508635193,4.051575446656331
2.2342676124911418e-07,0.002516,171.13165709062818,428.2457508635193,4.051575446656331
2.2392405451739514e-07,0.0025215999999999997,171.15254897767068,428.2457508635193,4.051575446656331
2.244923896811449e-07,0.002528,171.17640327591207,428.2457508635193,4.051575446656331
2.2548697621770693e-07,0.0025391999999999997,171.21809170260207,428.2457508635193,4.051575446656331
2.2839969393192434e-07,0.002572,171.33976866722898,428.2457508635193,4.051575446656331
2.3038886700504838e-07,0.0025943999999999997,171.4225175719388,428.2457508635193,4.051575446656331
2.3266220766004733e-07,0.00262,171.51674732350853,428.2457508635193,4.051575446656331
2.3521971589692113e-07,0.0026487999999999998,171.62232763058995,428.2457508635193,4.051575446656331
2.362853443289519e-07,0.0026608,171.66618718059357,428.2457508635193,4.051575446656331
2.3784826602926368e-07,0.0026784,171.73037523458046,428.2457508635193,4.051575446656331
2.401926485797313e-07,0.0027048,171.82634974347397,428.2457508635193,4.051575446656331
2.4140036080269947e-07,0.0027183999999999997,171.87564853708977,428.2457508635193,4.051575446656331
2.4168452838457434e-07,0.0027216,171.8872342629982,428.2457508635193,4.051575446656331
2.4381578524863586e-07,0.0027456,171.973958500827,428.2457508635193,4.051575446656331
2.4843350845410244e-07,0.0027976,172.16085321203087,428.2457508635193,4.051575446656331
2.491439274087896e-07,0.0028055999999999997,172.18948554971035,428.2457508635193,4.051575446656331
2.5013851394535166e-07,0.0028168,172.22951738754338,428.2457508635193,4.051575446656331
2.5077789100457006e-07,0.0028239999999999997,172.25521936365323,428.2457508635193,4.051575446656331
2.533353992414439e-07,0.0028528,172.35777273098674,428.2457508635193,4.051575446656331
2.5432998577800593e-07,0.002864,172.3975454546315,428.2457508635193,4.051575446656331
2.558929074783177e-07,0.0028816,172.45992311244524,428.2457508635193,4.051575446656331
2.5639020074659873e-07,0.0028872,172.47973936618763,428.2457508635193,4.051575446656331
2.5873458329706636e-07,0.0029135999999999997,172.5729576902268,428.2457508635193,4.051575446656331
2.6079479826565916e-07,0.0029368,172.65460522233997,428.2457508635193,4.051575446656331
2.620735523840961e-07,0.0029511999999999997,172.70515649726204,428.2457508635193,4.051575446656331
2.64346893039095e-07,0.0029768,172.7947885473662,428.2457508635193,4.051575446656331
2.6711752696237496e-07,0.003008,172.90362218094882,428.2457508635193,4.051575446656331
2.6811211349893695e-07,0.0030191999999999997,172.94258316360398,428.2457508635193,4.051575446656331
2.685383648717493e-07,0.0030239999999999998,172.95926346807437,428.2457508635193,4.051575446656331
2.693198257219052e-07,0.0030328,172.98981723229463,428.2457508635193,4.051575446656331
2.6974607709471745e-07,0.0030375999999999997,173.0064683480587,428.2457508635193,4.051575446656331
2.7010128657206103e-07,0.0030415999999999998,173.0203364405319,428.2457508635193,4.051575446656331
2.7138004069049795e-07,0.0030559999999999997,173.07020278773302,428.2457508635193,4.051575446656331
2.7351129755455947e-07,0.00308,173.15311020457958,428.2457508635193,4.051575446656331
2.7805797886455733e-07,0.0031311999999999998,173.32914195430607,428.2457508635193,4.051575446656331
2.7891048161018194e-07,0.0031408,173.36202255889253,428.2457508635193,4.051575446656331
2.84664875143148e-07,0.0032056,173.58295028549176,428.2457508635193,4.051575446656331
2.8523321030689774e-07,0.003212,173.60467537179986,428.2457508635193,4.051575446656331
2.8587258736611614e-07,0.0032191999999999998,173.62909592446877,428.2457508635193,4.051575446656331
2.8686717390267824e-07,0.0032304,173.66704115409792,428.2457508635193,4.051575446656331
2.872934252754905e-07,0.0032351999999999997,173.68328768507504,428.2457508635193,4.051575446656331
2.876486347528341e-07,0.0032392,173.69681928096588,428.2457508635193,4.051575446656331
2.880748861256464e-07,0.003244,173.7130485968817,428.2457508635193,4.051575446656331
2.889984307667397e-07,0.0032543999999999997,173.74818002115222,428.2457508635193,4.051575446656331
2.910586457353325e-07,0.0032776,173.82639272503258,428.2457508635193,4.051575446656331
2.9262156743564424e-07,0.0032952,173.88558255810386,428.2457508635193,4.051575446656331
2.9354511207673757e-07,0.0033055999999999997,173.9205004166798,428.2457508635193,4.051575446656331
2.9425553103142474e-07,0.0033136,173.94733116137354,428.2457508635193,4.051575446656331
2.968130392682985e-07,0.0033423999999999997,174.04371336667478,428.2457508635193,4.051575446656331
2.9759450011845446e-07,0.0033512,174.073098811143,428.2457508635193,4.051575446656331
2.9858908665501645e-07,0.0033623999999999998,174.11045498005674,428.2457508635193,4.051575446656331
3.0022305025079695e-07,0.0033807999999999998,174.17172065016948,428.2457508635193,4.051575446656331
3.019990976375149e-07,0.0034008,174.23816646314373,428.2457508635193,4.051575446656331
3.035620193378266e-07,0.0034184,174.29651281693992,428.2457508635193,4.051575446656331
3.055511924109507e-07,0.0034408,174.37060264959644,428.2457508635193,4.051575446656331
3.05977443783763e-07,0.0034456,174.38645454177293,428.2457508635193,4.051575446656331
3.068299465293876e-07,0.0034552,174.41813251270264,428.2457508635193,4.051575446656331
3.09742664243605e-07,0.0034879999999999998,174.5261075281527,428.2457508635193,4.051575446656331
3.1336580091250956e-07,0.0035288,174.65986685374003,428.2457508635193,4.051575446656331
3.1443142934454027e-07,0.0035407999999999998,174.6990928695998,428.2457508635193,4.051575446656331
3.158522672539146e-07,0.0035567999999999997,174.7513136692786,428.2457508635193,4.051575446656331
3.162785186267269e-07,0.0035616,174.76696203374064,428.2457508635193,4.051575446656331
3.1755727274516384e-07,0.0035759999999999998,174.81385785225285,428.2457508635193,4.051575446656331
3.178414403270387e-07,0.0035792,174.82426913693433,428.2457508635193,4.051575446656331
3.191201944454756e-07,0.0035935999999999997,174.871075066819,428.2457508635193,4.051575446656331
3.2004373908656895e-07,0.003604,174.90483387020032,428.2457508635193,4.051575446656331
3.214645769959433e-07,0.00362,174.9566963986956,428.2457508635193,4.051575446656331
3.221749959506304e-07,0.0036279999999999997,174.9825941330411,428.2457508635193,4.051575446656331
3.2267228921891144e-07,0.0036336,175.00070929717944,428.2457508635193,4.051575446656331
3.2395104333734835e-07,0.0036479999999999998,175.04724122174053,428.2457508635193,4.051575446656331
3.2601125830594116e-07,0.0036712,175.1220589295024,428.2457508635193,4.051575446656331
3.2778730569265904e-07,0.0036912,175.1864090766852,428.2457508635193,4.051575446656331
3.292081436020334e-07,0.0037072,175.237791342306,428.2457508635193,4.051575446656331
3.296343949748457e-07,0.003712,175.2531891475424,428.2457508635193,4.051575446656331
3.3062898151140774e-07,0.0037232,175.28908719315658,428.2457508635193,4.051575446656331
3.314814842570323e-07,0.0037327999999999997,175.31982343935226,428.2457508635193,4.051575446656331
3.3375482491203125e-07,0.0037584,175.40163641890047,428.2457508635193,4.051575446656331
3.360281655670302e-07,0.003784,175.48323235280318,428.2457508635193,4.051575446656331
3.371648358945297e-07,0.0037968,175.5239495659221,428.2457508635193,4.051575446656331
3.3773317105827937e-07,0.0038031999999999996,175.54428809448416,428.2457508635193,4.051575446656331
3.39580260340466e-07,0.0038239999999999997,175.61029631928363,428.2457508635193,4.051575446656331
3.414273496226527e-07,0.0038447999999999998,175.6761646658601,428.2457508635193,4.051575446656331
3.4213776857733985e-07,0.0038528,175.7014616224683,428.2457508635193,4.051575446656331
3.449084025006198e-07,0.003884,175.79992463669237,428.2457508635193,4.051575446656331
3.4512152818702593e-07,0.0038864,175.80748591385733,428.2457508635193,4.051575446656331
3.454767376643695e-07,0.0038904,175.82008399693095,428.2457508635193,4.051575446656331
3.462581985145254e-07,0.0038992,175.84778201153154,428.2457508635193,4.051575446656331
3.4675549178280643e-07,0.0039048,175.86539532824372,428.2457508635193,4.051575446656331
3.482473715876495e-07,0.0039216,175.91817626521615,428.2457508635193,4.051575446656331
3.497392513924925e-07,0.0039384,175.97086909191916,428.2457508635193,4.051575446656331
3.5016550276530486e-07,0.0039432,175.98590807492684,428.2457508635193,4.051575446656331
3.5130217309280424e-07,0.0039559999999999994,176.02597716578572,428.2457508635193,4.051575446656331
3.544280164934278e-07,0.0039911999999999994,176.1359072970374,428.2457508635193,4.051575446656331
3.5862017046470636e-07,0.004038407681536307,176.2827458410798,428.2457508635193,4.051575446656331
4.080752207209845e-07,0.004595319063812763,177.9673159663417,428.2457508635193,4.051575446656331
4.2512868632659763e-07,0.004787357471494299,178.52946819242786,428.2457508635193,4.051575446656331
4.5241423129557867e-07,0.005094618923784757,179.41095084392057,428.2457508635193,4.051575446656331
5.189227471574698e-07,0.0058435687137427484,181.47683093807706,428.2457508635193,4.051575446656331
5.751991836559933e-07,0.0064772954590918185,183.14527909519205,428.2457508635193,4.051575446656331
6.110114614277809e-07,0.006880576115223045,184.17391685667963,428.2457508635193,4.051575446656331
6.348863132756392e-07,0.007149429885977195,184.84663758153502,428.2457508635193,4.051575446656331
6.45118392639007e-07,0.007264652930586117,185.13191785877814,428.2457508635193,4.051575446656331
7.013948291375305e-07,0.007898379675935187,186.6705006879917,428.2457508635193,4.051575446656331
7.099215619403371e-07,0.007994398879775955,186.899349376159,428.2457508635193,4.051575446656331
7.184482947431437e-07,0.008090418083616723,187.1271285637983,428.2457508635193,4.051575446656331
7.440284931515633e-07,0.008378475695139028,187.80422271585402,428.2457508635193,4.051575446656331
8.258851280585064e-07,0.009300260052010402,189.91230216205423,428.2457508635193,4.051575446656331
8.44643940224681e-07,0.009511502300460092,190.3837298215076,428.2457508635193,4.051575446656331
8.651080989514167e-07,0.009741948389677936,190.89338148691337,428.2457508635193,4.051575446656331
9.179738423288173e-07,0.010337267453490697,192.1886800689559,428.2457508635193,4.051575446656331
9.64018199463973e-07,0.010855771154230847,193.29331003911614,428.2457508635193,4.051575446656331
9.776609719484634e-07,0.011009401880376076,193.61663051628867,428.2457508635193,4.051575446656331
1.0168839428413736e-06,0.011451090218043608,194.53651739320645,428.2457508635193,4.051575446656331
1.0731603793398969e-06,0.012084816963392678,195.83253903287462,428.2457508635193,4.051575446656331
1.0868031518243875e-06,0.012238447689537907,196.14270057699983,428.2457508635193,4.051575446656331
1.0919191915060714e-06,0.012296059211842368,196.2586192060098,428.2457508635193,4.051575446656331
1.1805972126552598e-06,0.013294658931786357,198.23538804251555,428.2457508635193,4.051575446656331
1.1891239454580664e-06,0.013390678135627125,198.42235681954583,428.2457508635193,4.051575446656331
1.2078827576242408e-06,0.013601920384076815,198.83185745725393,428.2457508635193,4.051575446656331
1.2317576094720992e-06,0.013870774154830966,199.3494705206891,428.2457508635193,4.051575446656331
1.2590431544410803e-06,0.014178035607121425,199.9362609020615,428.2457508635193,4.051575446656331
1.301676818455113e-06,0.014658131626325266,200.84328781333505,428.2457508635193,4.051575446656331
1.3647746411958817e-06,0.01536867373474695,202.16470534863555,428.2457508635193,4.051575446656331
1.3852387999226176e-06,0.015599119823964794,202.58812727286116,428.2457508635193,4.051575446656331
1.393765532725424e-06,0.01569513902780556,202.76383225549938,428.2457508635193,4.051575446656331
1.4244617708155279e-06,0.01604080816163233,203.39292838659696,428.2457508635193,4.051575446656331
1.4415152364211408e-06,0.016232846569313862,203.74014103426438,428.2457508635193,4.051575446656331
1.4636847417084377e-06,0.016482496499299858,204.18913187917713,428.2457508635193,4.051575446656331
1.4875595935562965e-06,0.016751350270054012,204.669704572084,428.2457508635193,4.051575446656331
1.5029077126013481e-06,0.016924184836967393,204.97705640758468,428.2457508635193,4.051575446656331
1.5489520697365038e-06,0.017442688537707543,205.89184978713223,428.2457508635193,4.051575446656331
1.5847643475082911e-06,0.017845969193838768,206.59604268436024,428.2457508635193,4.051575446656331
1.5932910803110977e-06,0.017941988397679534,206.76278960232852,428.2457508635193,4.051575446656331
1.615460585598395e-06,0.018191638327665533,207.19471092516022,428.2457508635193,4.051575446656331
1.681969101460286e-06,0.018940588117623523,208.47681302465102,428.2457508635193,4.051575446656331
1.709254646429267e-06,0.01924784956991398,208.99706532644183,428.2457508635193,4.051575446656331
1.7757631622911585e-06,0.019996799359871975,210.25179292300015,428.2457508635193,4.051575446656331
1.8098700935023848e-06,0.020380876175235048,210.88812432983124,428.2457508635193,4.051575446656331
1.8286289056685592e-06,0.020592118423684736,211.23611255400405,428.2457508635193,4.051575446656331
1.8525037575164176e-06,0.020860972194438887,211.6769996766911,428.2457508635193,4.051575446656331
1.8627358368797853e-06,0.02097619523904781,211.8652723055114,428.2457508635193,4.051575446656331
1.8951374215304505e-06,0.02134106821364273,212.45882542115467,428.2457508635193,4.051575446656331
1.908780194014941e-06,0.02149469893978796,212.70755696340333,428.2457508635193,4.051575446656331
1.958235244271219e-06,0.022051610322064413,213.60345444064723,428.2457508635193,4.051575446656331
1.9906368289218842e-06,0.022416483296659333,214.18564109875476,428.2457508635193,4.051575446656331
2.040091879178162e-06,0.022973394678935787,215.06716646626327,428.2457508635193,4.051575446656331
2.077609503510511e-06,0.023395879175835167,215.73036116877748,428.2457508635193,4.051575446656331
2.1014843553583693e-06,0.023664732946589318,216.14996339962937,428.2457508635193,4.051575446656331
2.1475287124935248e-06,0.024183236647329465,216.95398279806525,428.2457508635193,4.051575446656331
2.1662875246596993e-06,0.024394478895779156,217.27961540658285,428.2457508635193,4.051575446656331
2.2208586145976616e-06,0.025009001800360073,218.22071488187572,428.2457508635193,4.051575446656331
2.241322773324397e-06,0.025239447889577916,218.57129651221922,428.2457508635193,4.051575446656331
2.246438813006081e-06,0.025297059411882376,218.65874658871368,428.2457508635193,4.051575446656331
2.2703136648539393e-06,0.025565913182636527,219.0658243517201,428.2457508635193,4.051575446656331
2.30953663574685e-06,0.026007601520304062,219.7309890846054,428.2457508635193,4.051575446656331
2.3351168341552694e-06,0.026295659131826365,220.1624198945962,428.2457508635193,4.051575446656331
2.391393270653793e-06,0.026929385877175437,221.1051321943066,428.2457508635193,4.051575446656331
2.4272055484255803e-06,0.02733266653330666,221.70053772280153,428.2457508635193,4.051575446656331
2.4715445590001744e-06,0.027831966393278656,222.43298067085212,428.2457508635193,4.051575446656331
2.4885980246057876e-06,0.028024004800960192,222.7133227190801,428.2457508635193,4.051575446656331
2.515883569574769e-06,0.02833126625325065,223.16031662527175,428.2457508635193,4.051575446656331
2.5534011939071176e-06,0.02875375075015003,223.77185839079743,428.2457508635193,4.051575446656331
2.5960348579211504e-06,0.02923384676935387,224.46255437084665,428.2457508635193,4.051575446656331
2.654016640980235e-06,0.029886777355471093,225.39484305816632,428.2457508635193,4.051575446656331
2.6949449584337068e-06,0.03034766953390678,226.0481525120471,428.2457508635193,4.051575446656331
2.7137037705998813e-06,0.030558911782356472,226.34629168009846,428.2457508635193,4.051575446656331
2.7307572362054945e-06,0.03075095019003801,226.6166305401457,428.2457508635193,4.051575446656331
2.771685553658966e-06,0.031211842368473696,227.26277147351615,428.2457508635193,4.051575446656331
2.8535421885659095e-06,0.032133626725345074,228.54399647542053,428.2457508635193,4.051575446656331
2.9012918922616255e-06,0.03267133426685337,229.28475803791045,428.2457508635193,4.051575446656331
2.9763271409263237e-06,0.03351630326065213,230.43927685006875,428.2457508635193,4.051575446656331
3.0155501118192337e-06,0.033957991598319665,231.03825431616133,428.2457508635193,4.051575446656331
3.02407684462204e-06,0.03405401080216043,231.16806386446703,428.2457508635193,4.051575446656331
3.065005162075512e-06,0.03451490298059612,231.78917355403837,428.2457508635193,4.051575446656331
3.076942587999441e-06,0.034649329865973195,231.9697201494708,428.2457508635193,4.051575446656331
3.0991120932867383e-06,0.03489897979595919,232.30429786937793,428.2457508635193,4.051575446656331
3.12810298481628e-06,0.0352254450890178,232.74041752965945,428.2457508635193,4.051575446656331
3.1400404107402105e-06,0.035359871974394885,232.9195377039817,428.2457508635193,4.051575446656331
3.1570938763458233e-06,0.03555191038207642,233.1749636651844,428.2457508635193,4.051575446656331
3.1724419953908742e-06,0.03572474494898979,233.40438733034654,428.2457508635193,4.051575446656331
3.201432886920417e-06,0.03605121024204841,233.8365655297923,428.2457508635193,4.051575446656331
3.2150756594049074e-06,0.03620484096819364,234.03941512354686,428.2457508635193,4.051575446656331
3.2372451646922047e-06,0.036454490898179634,234.36833119517883,428.2457508635193,4.051575446656331
3.284994868387922e-06,0.03699219843968794,235.07379687740573,428.2457508635193,4.051575446656331
3.2969322943118506e-06,0.03712662532506501,235.24953701899727,428.2457508635193,4.051575446656331
3.3293338789625156e-06,0.037491498299659934,235.72529948658985,428.2457508635193,4.051575446656331
3.3600301170526193e-06,0.037837167433486696,236.1743588426508,428.2457508635193,4.051575446656331
3.4452974450806848e-06,0.038797359471894374,237.41342798747712,428.2457508635193,4.051575446656331
3.470877643489105e-06,0.03908541708341669,237.78280899783198,428.2457508635193,4.051575446656331
3.5015738815792084e-06,0.03943108621724345,238.2246677077118,428.2457508635193,4.051575446656331
3.5169220006242607e-06,0.03960392078415684,238.44503037412957,428.2457508635193,4.051575446656331
3.5339754662298734e-06,0.03979595919183837,238.68943837276552,428.2457508635193,4.051575446656331
3.591957249288958e-06,0.04044888977795559,239.51700648120215,428.2457508635193,4.051575446656331
3.6107160614551325e-06,0.04066013202640528,239.7836315021694,428.2457508635193,4.051575446656331
3.617537447697377e-06,0.04073694738947789,239.88045204443918,428.2457508635193,4.051575446656331
3.6550550720297267e-06,0.04115943188637727,240.41169773074546,428.2457508635193,4.051575446656331
3.6823406169987076e-06,0.04146669333866773,240.79672338680584,428.2457508635193,4.051575446656331
3.7266796275733013e-06,0.04196599319863972,241.42002542847186,428.2457508635193,4.051575446656331
3.735206360376109e-06,0.0420620124024805,241.5395589182732,428.2457508635193,4.051575446656331
3.7641972519056508e-06,0.042388477695539106,241.94517912769874,428.2457508635193,4.051575446656331
3.7812507175112635e-06,0.04258051610322064,242.18321013813687,428.2457508635193,4.051575446656331
3.8324111143281035e-06,0.04315663132626525,242.89480373240121,428.2457508635193,4.051575446656331
3.842643193691472e-06,0.04327185437087418,243.03667683056435,428.2457508635193,4.051575446656331
3.851169926494278e-06,0.043367873574714944,243.15479190188205,428.2457508635193,4.051575446656331
3.893803590508311e-06,0.04384796959391879,243.7438442928946,428.2457508635193,4.051575446656331
3.912562402674484e-06,0.04405921184236847,244.00222991179083,428.2457508635193,4.051575446656331
3.926205175158975e-06,0.0442128425685137,244.1898433617498,428.2457508635193,4.051575446656331
3.9620174529307636e-06,0.044616123224644935,244.68112296358007,428.2457508635193,4.051575446656331
3.98418695821806e-06,0.04486577315463093,244.9843806817785,428.2457508635193,4.051575446656331
4.018293889429286e-06,0.045249849969994,245.44964912596276,428.2457508635193,4.051575446656331
4.06092755344332e-06,0.04572994598919784,246.02907447714944,428.2457508635193,4.051575446656331
4.07457032592781e-06,0.04588357671534307,246.2139888995032,428.2457508635193,4.051575446656331
4.098445177775669e-06,0.046152430486097226,246.53700916190718,428.2457508635193,4.051575446656331
4.139373495229141e-06,0.046613322664532914,247.08905601968556,428.2457508635193,4.051575446656331
4.1598376539558755e-06,0.04684376875375075,247.36428085978994,428.2457508635193,4.051575446656331
4.182007159243172e-06,0.047093418683736746,247.6618459018626,428.2457508635193,4.051575446656331
4.195649931727663e-06,0.047247049409881975,247.84465709610518,428.2457508635193,4.051575446656331
4.205882011091031e-06,0.0473622724544909,247.9816133918697,428.2457508635193,4.051575446656331
4.277506566634606e-06,0.04816883376675335,248.9366951231806,428.2457508635193,4.051575446656331
4.299676071921903e-06,0.048418483696739345,249.2310489584771,428.2457508635193,4.051575446656331
4.309908151285271e-06,0.04853370674134827,249.3667048803371,428.2457508635193,4.051575446656331
4.35936320154155e-06,0.049090618123624724,250.02061274848745,428.2457508635193,4.051575446656331
4.4139342914795115e-06,0.04970514102820564,250.73881784655154,428.2457508635193,4.051575446656331
4.441219836448492e-06,0.0500124024804961,251.09662116781772,428.2457508635193,4.051575446656331
4.552067362884978e-06,0.05126065213042609,252.54146736279026,428.2457508635193,4.051575446656331
4.601522413141256e-06,0.051817563512702544,253.1816575021526,428.2457508635193,4.051575446656331
4.6168705321863075e-06,0.05199039807961592,253.37979085313665,428.2457508635193,4.051575446656331
4.6492721168369725e-06,0.05235527105421084,253.79723077341893,428.2457508635193,4.051575446656331
4.695316473972128e-06,0.05287377475495099,254.38848838593722,428.2457508635193,4.051575446656331
4.743066177667846e-06,0.0534114822964593,254.9992608935827,428.2457508635193,4.051575446656331
4.758414296712897e-06,0.05358431686337267,255.19507073401186,428.2457508635193,4.051575446656331
4.773762415757949e-06,0.05375715143028606,255.3906344131284,428.2457508635193,4.051575446656331
4.836860238498717e-06,0.05446769353870774,256.1920556034343,428.2457508635193,4.051575446656331
4.898252714678924e-06,0.05515903180636127,256.96791240947124,428.2457508635193,4.051575446656331
4.942591725253519e-06,0.05565833166633327,257.5258967648555,428.2457508635193,4.051575446656331
5.007394894554848e-06,0.0563880776155231,258.3379135157351,428.2457508635193,4.051575446656331
5.021037667039339e-06,0.05654170834166833,258.50834101355025,428.2457508635193,4.051575446656331
5.041501825766075e-06,0.05677215443088618,258.76364403001196,428.2457508635193,4.051575446656331
5.072198063856179e-06,0.05711782356471294,259.1458420591242,428.2457508635193,4.051575446656331
5.111421034749089e-06,0.057559511902380484,259.63289602253866,428.2457508635193,4.051575446656331
5.148938659081438e-06,0.05798199639927985,260.09741161638425,428.2457508635193,4.051575446656331
5.206920442140522e-06,0.05863492698539707,260.81271133832917,428.2457508635193,4.051575446656331
5.239322026791187e-06,0.058999799959991994,261.21108446992224,428.2457508635193,4.051575446656331
5.2631968786390455e-06,0.05926865373074615,261.50400801758394,428.2457508635193,4.051575446656331
5.283661037365783e-06,0.059499099819964,261.75467312682457,428.2457508635193,4.051575446656331
5.312651928895324e-06,0.0598255651130226,262.1091348570549,428.2457508635193,4.051575446656331
5.33311608762206e-06,0.06005601120224045,262.3588890929532,428.2457508635193,4.051575446656331
5.367223018833286e-06,0.06044008801760352,262.77431717848276,428.2457508635193,4.051575446656331
5.396213910362829e-06,0.060766553310662136,263.12662219611525,428.2457508635193,4.051575446656331
5.4252048018923705e-06,0.06109301860372074,263.4781898132203,428.2457508635193,4.051575446656331
5.4371422278163e-06,0.06122744548909782,263.6227398996547,428.2457508635193,4.051575446656331
5.474659852148649e-06,0.06164992998599721,264.07623648194294,428.2457508635193,4.051575446656331
5.515588169602121e-06,0.062110822164432894,264.56957992950277,428.2457508635193,4.051575446656331
5.539463021449978e-06,0.062379675935187034,264.85670427884605,428.2457508635193,4.051575446656331
5.588918071706256e-06,0.06293658731746349,265.44993112671006,428.2457508635193,4.051575446656331
5.597444804509063e-06,0.06303260652130425,265.5520043562386,428.2457508635193,4.051575446656331
5.64519450820478e-06,0.06357031406281256,266.12249773956137,428.2457508635193,4.051575446656331
5.68441747909769e-06,0.06401200240048009,266.5897107661105,428.2457508635193,4.051575446656331
5.694649558461058e-06,0.06412722544508902,266.71138543896336,428.2457508635193,4.051575446656331
5.713408370627233e-06,0.06433846769353871,266.9342344557222,428.2457508635193,4.051575446656331
5.727051143111724e-06,0.06449209841968394,267.09612727681804,428.2457508635193,4.051575446656331
5.754336688080705e-06,0.0647993598719744,267.4194624078585,428.2457508635193,4.051575446656331
5.791854312413054e-06,0.06522184436887378,267.86307359363036,428.2457508635193,4.051575446656331
5.844720055790454e-06,0.06581716343268654,268.4862646276075,428.2457508635193,4.051575446656331
5.8515414420327e-06,0.06589397879575916,268.56651594095615,428.2457508635193,4.051575446656331
5.875416293880557e-06,0.0661628325665133,268.8471086673235,428.2457508635193,4.051575446656331
5.933398076939643e-06,0.06681576315263053,269.5267032505828,428.2457508635193,4.051575446656331
5.95556758222694e-06,0.06706541308261653,269.7858631492015,428.2457508635193,4.051575446656331
6.015254711846586e-06,0.06773754750950191,270.48173804155806,428.2457508635193,4.051575446656331
6.0766471880267926e-06,0.06842888577715543,271.1946913903991,428.2457508635193,4.051575446656331
6.083468574269039e-06,0.06850570114022805,271.27373464208455,428.2457508635193,4.051575446656331
6.115870158919704e-06,0.06887057411482297,271.6487190634847,428.2457508635193,4.051575446656331
6.168735902297104e-06,0.06946589317863573,272.2588766845484,428.2457508635193,4.051575446656331
6.21648560599282e-06,0.07000360072014403,272.8082361882024,428.2457508635193,4.051575446656331
6.247181844082925e-06,0.0703492698539708,273.1605270365811,428.2457508635193,4.051575446656331
6.259119270006854e-06,0.07048369673934787,273.2973466355518,428.2457508635193,4.051575446656331
6.323922439308184e-06,0.07121344268853771,274.03831342005674,428.2457508635193,4.051575446656331
6.337565211792675e-06,0.07136707341468294,274.1939284306229,428.2457508635193,4.051575446656331
6.3819042223672685e-06,0.07186637327465493,274.69877733407316,428.2457508635193,4.051575446656331
6.445002045108037e-06,0.07257691538307662,275.4148640632768,428.2457508635193,4.051575446656331
6.508099867848805e-06,0.0732874574914983,276.128221808546,428.2457508635193,4.051575446656331
6.555849571544523e-06,0.07382516503300661,276.666268549394,428.2457508635193,4.051575446656331
6.589956502755749e-06,0.07420924184836968,277.0496523377008,428.2457508635193,4.051575446656331
6.607009968361361e-06,0.07440128025605121,277.2410539810655,428.2457508635193,4.051575446656331
6.683750563586622e-06,0.07526545309061813,278.09998816662886,428.2457508635193,4.051575446656331
6.7332056138428995e-06,0.07582236447289459,278.65148620429454,428.2457508635193,4.051575446656331
6.784366010659738e-06,0.07639847969593919,279.22034153575794,428.2457508635193,4.051575446656331
6.813356902189281e-06,0.0767249449889978,279.5419502351418,428.2457508635193,4.051575446656331
6.896918883656786e-06,0.07766593318663734,280.4659673686806,428.2457508635193,4.051575446656331
6.924204428625767e-06,0.0779731946389278,280.76674028947207,428.2457508635193,4.051575446656331
6.9685434392003606e-06,0.07847249449889979,281.254512291754,428.2457508635193,4.051575446656331
6.978775518563729e-06,0.07858771754350871,281.36690299448173,428.2457508635193,4.051575446656331
6.997534330729902e-06,0.07879895979195839,281.5727858456346,428.2457508635193,4.051575446656331
7.041873341304497e-06,0.0792982596519304,282.0585642612704,428.2457508635193,4.051575446656331
7.075980272515723e-06,0.07968233646729346,282.43142868052223,428.2457508635193,4.051575446656331
7.205586611118384e-06,0.08114182836567314,283.84196651702325,428.2457508635193,4.051575446656331
7.241398888890171e-06,0.08154510902180437,284.229971152756,428.2457508635193,4.051575446656331
7.369299880932269e-06,0.08298539707941589,285.60963437174286,428.2457508635193,4.051575446656331
7.38294265341676e-06,0.08313902780556112,285.7562451450368,428.2457508635193,4.051575446656331
7.403406812143496e-06,0.08336947389477896,285.9759633515313,428.2457508635193,4.051575446656331
7.410228198385741e-06,0.08344628925785158,286.04915010138257,428.2457508635193,4.051575446656331
7.4255763174307926e-06,0.08361912382476495,286.21372428996756,428.2457508635193,4.051575446656331
7.4341030502335985e-06,0.08371514302860572,286.30509706969644,428.2457508635193,4.051575446656331
7.459683248642019e-06,0.08400320064012803,286.578970486283,428.2457508635193,4.051575446656331
7.47332602112651e-06,0.08415683136627326,286.72488653478223,428.2457508635193,4.051575446656331
7.478442060808194e-06,0.08421444288857773,286.77957826526637,428.2457508635193,4.051575446656331
7.502316912656051e-06,0.08448329665933187,287.03461365425414,428.2457508635193,4.051575446656331
7.580762854441872e-06,0.08536667333466694,287.87036730658264,428.2457508635193,4.051575446656331
7.587584240684118e-06,0.08544348869773956,287.9428817603005,428.2457508635193,4.051575446656331
7.611459092531976e-06,0.0857123424684937,288.1964823708033,428.2457508635193,4.051575446656331
7.650682063424887e-06,0.08615403080616124,288.6124394925637,428.2457508635193,4.051575446656331
7.684788994636113e-06,0.08653810762152431,288.9734657702396,428.2457508635193,4.051575446656331
7.691610380878358e-06,0.08661492298459693,289.04559597852955,428.2457508635193,4.051575446656331
7.705253153362849e-06,0.08676855371074216,289.1897815945108,428.2457508635193,4.051575446656331
7.73424404489239e-06,0.08709501900380076,289.49584586314603,428.2457508635193,4.051575446656331
7.742770777695197e-06,0.08719103820764153,289.5857795731901,428.2457508635193,4.051575446656331
7.776877708906423e-06,0.08757511502300461,289.94512883144716,428.2457508635193,4.051575446656331
7.81098464011765e-06,0.08795919183836767,290.3038639756474,428.2457508635193,4.051575446656331
7.834859491965507e-06,0.08822804560912183,290.5546151745951,428.2457508635193,4.051575446656331
7.86385038349505e-06,0.08855451090218044,290.8586985030932,428.2457508635193,4.051575446656331
7.887725235342908e-06,0.08882336467293458,291.10879192326433,428.2457508635193,4.051575446656331
7.918421473433012e-06,0.08916903380676136,291.4299072321627,428.2457508635193,4.051575446656331
7.954233751204801e-06,0.08957231446289259,291.8039288100987,428.2457508635193,4.051575446656331
7.976403256492097e-06,0.08982196439287858,292.0351368883026,428.2457508635193,4.051575446656331
8.000278108339956e-06,0.09009081816363274,292.28385010273365,428.2457508635193,4.051575446656331
8.019036920506131e-06,0.09030206041208243,292.4790646161097,428.2457508635193,4.051575446656331
8.032679692990622e-06,0.09045569113822766,292.6209269621183,428.2457508635193,4.051575446656331
8.078724050125775e-06,0.09097419483896779,293.0990201624666,428.2457508635193,4.051575446656331
8.087250782928584e-06,0.09107021404280857,293.1874391985078,428.2457508635193,4.051575446656331
8.106009595094757e-06,0.09128145629125825,293.3818332011375,428.2457508635193,4.051575446656331
8.165696724714403e-06,0.09195359071814363,293.99919558659434,428.2457508635193,4.051575446656331
8.230499894015733e-06,0.09268333666733347,294.66748548205754,428.2457508635193,4.051575446656331
8.235615933697417e-06,0.09274094818963793,294.7201576513075,428.2457508635193,4.051575446656331
8.244142666500224e-06,0.0928369673934787,294.80791625121986,428.2457508635193,4.051575446656331
8.281660290832572e-06,0.09325945189037808,295.193634318195,428.2457508635193,4.051575446656331
8.31917791516492e-06,0.09368193638727745,295.57867150500044,428.2457508635193,4.051575446656331
8.353284846376147e-06,0.09406601320264053,295.92811805404125,428.2457508635193,4.051575446656331
8.366927618860638e-06,0.09421964392878576,296.06774081294526,428.2457508635193,4.051575446656331
8.372043658542322e-06,0.09427725545109022,296.1200764531742,428.2457508635193,4.051575446656331
8.40956128287467e-06,0.09469973994798961,296.50349076120744,428.2457508635193,4.051575446656331
8.477775145297123e-06,0.09546789357871575,297.19890292343274,428.2457508635193,4.051575446656331
8.530640888674524e-06,0.09606321264252851,297.73634747490064,428.2457508635193,4.051575446656331
8.557926433643506e-06,0.09637047409481897,298.01322989272836,428.2457508635193,4.051575446656331
8.62955098918708e-06,0.09717703540708142,298.7384130985239,428.2457508635193,4.051575446656331
8.646604454792693e-06,0.09736907381476295,298.910729322421,428.2457508635193,4.051575446656331
8.673889999761675e-06,0.09767633526705341,299.18615984716246,428.2457508635193,4.051575446656331
8.697764851609532e-06,0.09794518903780756,299.42688448714665,428.2457508635193,4.051575446656331
8.721639703457391e-06,0.09821404280856172,299.6673515624043,428.2457508635193,4.051575446656331
8.735282475941882e-06,0.09836767353470695,299.80464605561053,428.2457508635193,4.051575446656331
8.755746634668617e-06,0.09859811962392478,300.0104311002212,428.2457508635193,4.051575446656331
8.781326833077037e-06,0.0988861772354471,300.26739881726036,428.2457508635193,4.051575446656331
8.801790991803773e-06,0.09911662332466493,300.472762859686,428.2457508635193,4.051575446656331
8.835897923014999e-06,0.09950070014002801,300.81462293876285,428.2457508635193,4.051575446656331
8.858067428302297e-06,0.09975035007001401,301.03655604800736,428.2457508635193,4.051575446656331
8.859772774862858e-06,0.09976955391078215,301.05361884787646,428.2457508635193,4.051575446656331