File: datasets/aisi_316_L/data/M1/valid_22.csv
Time(s),Strain(%),Stress(MPa),Temp(C),Log_SR(s-1)
0.0,0.0,0.0,387.2615054558039,-3.083804906464464
0.014554126739810212,1.2e-05,2.0441499375,387.2615054558039,-3.083804906464464
0.030078528595607768,2.48e-05,4.2245765375,387.2615054558039,-3.083804906464464
0.051424581147329416,4.24e-05,7.2226631125,387.2615054558039,-3.083804906464464
0.06985980835108901,5.76e-05,9.811919699999999,387.2615054558039,-3.083804906464464
0.07665173416300043,6.319999999999999e-05,10.765856337499999,387.2615054558039,-3.083804906464464
0.08247338485892453,6.8e-05,11.5835163125,387.2615054558039,-3.083804906464464
0.0902355857868233,7.439999999999999e-05,12.673729612499999,387.2615054558039,-3.083804906464464
0.10964108810657026,9.04e-05,15.3992628625,387.2615054558039,-3.083804906464464
0.12807631531032984,0.00010559999999999999,17.98851945,387.2615054558039,-3.083804906464464
0.13680879135421598,0.00011279999999999999,19.2150094125,387.2615054558039,-3.083804906464464
0.1494223678620515,0.00012319999999999999,20.986606024999997,387.2615054558039,-3.083804906464464
0.16979814529778578,0.00014,23.848415937499997,387.2615054558039,-3.083804906464464
0.184352272037596,0.00015199999999999998,25.892565874999995,387.2615054558039,-3.083804906464464
0.20763887482129234,0.0001712,29.163205774999998,387.2615054558039,-3.083804906464464
0.2154010757491911,0.00017759999999999998,30.253419074999996,387.2615054558039,-3.083804906464464
0.2396579536488748,0.00019759999999999998,33.6603356375,387.2615054558039,-3.083804906464464
0.25518235550467233,0.0002104,35.8407622375,387.2615054558039,-3.083804906464464
0.2658553817805332,0.0002192,37.339805524999996,387.2615054558039,-3.083804906464464
0.2833203338683054,0.00023359999999999999,39.79278545,387.2615054558039,-3.083804906464464
0.30078528595607773,0.000248,42.245765375000005,387.2615054558039,-3.083804906464464
0.3085474868839765,0.0002544,43.335978675,387.2615054558039,-3.083804906464464
0.31825023804384994,0.0002624,44.6987453,387.2615054558039,-3.083804906464464
0.3201907882758246,0.00026399999999999997,44.971298624999996,387.2615054558039,-3.083804906464464
0.33474491501563486,0.000276,47.0154485625,387.2615054558039,-3.083804906464464
0.33959629059557156,0.00028,47.696831874999994,387.2615054558039,-3.083804906464464
0.34929904175544507,0.000288,49.0595985,387.2615054558039,-3.083804906464464
0.38034784546704015,0.0003136,53.420451699999994,387.2615054558039,-3.083804906464464
0.40266417313474917,0.000332,56.5548149375,387.2615054558039,-3.083804906464464
0.4259507759184455,0.00035119999999999997,59.8254548375,387.2615054558039,-3.083804906464464
0.4657320556739268,0.000384,65.412798,387.2615054558039,-3.083804906464464
0.47446453171781283,0.00039119999999999997,66.63928796249999,387.2615054558039,-3.083804906464464
0.49484030915354715,0.000408,69.501097875,387.2615054558039,-3.083804906464464
0.5016322349654586,0.00041359999999999997,70.45503451249999,387.2615054558039,-3.083804906464464
0.5685812179685855,0.00046879999999999996,79.858124225,387.2615054558039,-3.083804906464464
0.5908975456362945,0.00048719999999999997,82.9924874625,387.2615054558039,-3.083804906464464
0.6073922226080796,0.0005008,85.30919072500001,387.2615054558039,-3.083804906464464
0.6335896507397378,0.0005224,88.9886606125,387.2615054558039,-3.083804906464464
0.6413518516676365,0.0005288,90.07887391249999,387.2615054558039,-3.083804906464464
0.6471735023635606,0.0005336,90.8965338875,387.2615054558039,-3.083804906464464
0.6762817558431812,0.0005576,94.9848337625,387.2615054558039,-3.083804906464464
0.6850142318870672,0.0005648,96.211323725,387.2615054558039,-3.083804906464464
0.6937467079309534,0.000572,97.43781368750001,387.2615054558039,-3.083804906464464
0.7160630355986624,0.0005903999999999999,100.572176925,387.2615054558039,-3.083804906464464
0.7442010139622954,0.0006136,104.52420013749999,387.2615054558039,-3.083804906464464
0.7801011932538273,0.0006432,109.56643665,387.2615054558039,-3.083804906464464
0.7985364204575869,0.0006584,112.15569323749999,387.2615054558039,-3.083804906464464
0.8121202720814098,0.0006696,114.0635665125,387.2615054558039,-3.083804906464464
0.8276446739372073,0.0006824,116.2439931125,387.2615054558039,-3.083804906464464
0.8616043029967644,0.0007103999999999999,121.01367629999999,387.2615054558039,-3.083804906464464
0.9110883339121192,0.0007511999999999999,127.96378608749998,387.2615054558039,-3.083804906464464
0.9450479629716764,0.0007792,132.733469275,387.2615054558039,-3.083804906464464
0.963483190175436,0.0007944,135.3227258625,387.2615054558039,-3.083804906464464
0.9848292427271577,0.000812,138.3208124375,387.2615054558039,-3.083804906464464
1.0013239196989425,0.0008256,140.6375157,387.2615054558039,-3.083804906464464
1.0149077713227654,0.0008368,142.54538897499998,387.2615054558039,-3.083804906464464
1.0323727234105375,0.0008512,144.9983689,387.2615054558039,-3.083804906464464
1.0401349243384364,0.0008575999999999999,146.0885822,387.2615054558039,-3.083804906464464
1.044986299918373,0.0008615999999999999,146.7699655125,387.2615054558039,-3.083804906464464
1.0857378547898417,0.0008952,147.75843929429513,387.2615054558039,-3.083804906464464
1.0944703308337278,0.0009023999999999999,147.79462564480426,387.2615054558039,-3.083804906464464
1.119697483849399,0.0009232,147.8985368033743,387.2615054558039,-3.083804906464464
1.128429959893285,0.0009304,147.93429279222227,387.2615054558039,-3.083804906464464
1.1517165626769814,0.0009496,148.02911841704656,387.2615054558039,-3.083804906464464
1.1633598640688296,0.0009592,148.07625060621447,387.2615054558039,-3.083804906464464
1.1944086677804244,0.0009847999999999999,148.20104560508665,387.2615054558039,-3.083804906464464
1.2138141701001717,0.0010008,148.27840030315207,387.2615054558039,-3.083804906464464
1.2303088470719565,0.0010144,148.34377332612902,387.2615054558039,-3.083804906464464
1.2458332489277542,0.0010272,148.40498932052552,387.2615054558039,-3.083804906464464
1.2623279258995388,0.0010408,148.4697062419541,387.2615054558039,-3.083804906464464
1.3176336075108177,0.0010864,148.68433088367445,387.2615054558039,-3.083804906464464
1.3350985595985898,0.0011007999999999999,148.75137329586116,387.2615054558039,-3.083804906464464
1.3836123153979574,0.0011408,148.9358309894273,387.2615054558039,-3.083804906464464
1.4068989181816538,0.00116,149.02347316612642,387.2615054558039,-3.083804906464464
1.4117502937615904,0.0011639999999999999,149.04166053905897,387.2615054558039,-3.083804906464464
1.4292152458493628,0.0011784,149.10693422155643,387.2615054558039,-3.083804906464464
1.4525018486330592,0.0011976,149.1934839348672,387.2615054558039,-3.083804906464464
1.4689965256048438,0.0012112,149.25446286808108,387.2615054558039,-3.083804906464464
1.504896704896376,0.0012408,149.38626620348364,387.2615054558039,-3.083804906464464
1.5184805565201984,0.0012519999999999999,149.43581723132434,387.2615054558039,-3.083804906464464
1.5456482597678445,0.0012744,149.53440368212526,387.2615054558039,-3.083804906464464
1.5553510109277178,0.0012824,149.56944904719816,387.2615054558039,-3.083804906464464
1.6125972427709714,0.0013296,149.77450728864247,387.2615054558039,-3.083804906464464
1.6349135704386804,0.001348,149.85367367217344,387.2615054558039,-3.083804906464464
1.6387946709026295,0.0013511999999999999,149.86739860763058,387.2615054558039,-3.083804906464464
1.6446163215985539,0.001356,149.88796226600982,387.2615054558039,-3.083804906464464
1.6756651253101489,0.0013816,149.9971593528723,387.2615054558039,-3.083804906464464
1.6970111778618706,0.0013992,150.07177501343148,387.2615054558039,-3.083804906464464
1.712535579717668,0.0014119999999999998,150.1258112327513,387.2615054558039,-3.083804906464464
1.729030256689453,0.0014256,150.18301581311297,387.2615054558039,-3.083804906464464
1.7338816322693895,0.0014295999999999998,150.19980013394658,387.2615054558039,-3.083804906464464
1.7620196106330228,0.0014528,150.2967904384054,387.2615054558039,-3.083804906464464
1.7930684143446178,0.0014784,150.40311587749207,387.2615054558039,-3.083804906464464
1.8367307945640485,0.0015144,150.5514290860194,387.2615054558039,-3.083804906464464
1.8483740959558967,0.001524,150.59074623770852,387.2615054558039,-3.083804906464464
1.8677795982756438,0.00154,150.65606085533082,387.2615054558039,-3.083804906464464
1.8871851005953906,0.0015559999999999999,150.721111351302,387.2615054558039,-3.083804906464464
1.9027095024511882,0.0015688,150.77296411547024,387.2615054558039,-3.083804906464464
1.9483124329025936,0.0016064,150.9243357765936,387.2615054558039,-3.083804906464464
1.9618962845264163,0.0016175999999999999,150.9691572765426,387.2615054558039,-3.083804906464464
1.9851828873101127,0.0016367999999999999,151.04571356745578,387.2615054558039,-3.083804906464464
2.00070728916591,0.0016496,151.09655661251315,387.2615054558039,-3.083804906464464
2.0375777435734292,0.0016799999999999999,151.21669613541417,387.2615054558039,-3.083804906464464
2.08124012379286,0.0017159999999999999,151.35787557946196,387.2615054558039,-3.083804906464464
2.101615901228594,0.0017327999999999998,151.4233635665663,387.2615054558039,-3.083804906464464
2.1151997528524173,0.0017439999999999999,151.46688470990563,387.2615054558039,-3.083804906464464
2.1413971809840757,0.0017656,151.55051174852227,387.2615054558039,-3.083804906464464
2.1569215828398733,0.0017783999999999999,151.59988024331741,387.2615054558039,-3.083804906464464
2.164683783767772,0.0017848,151.62451250986672,387.2615054558039,-3.083804906464464
2.187970386551468,0.0018039999999999998,151.6982034495712,387.2615054558039,-3.083804906464464
2.2093164391031896,0.0018215999999999998,151.765485216601,387.2615054558039,-3.083804906464464
2.2180489151470764,0.0018288,151.79293644758604,387.2615054558039,-3.083804906464464
2.2238705658430002,0.0018336,151.81121385552893,387.2615054558039,-3.083804906464464
2.232603041886886,0.0018407999999999999,151.83859501856887,387.2615054558039,-3.083804906464464
2.236484142350836,0.001844,151.85075101409748,387.2615054558039,-3.083804906464464
2.253949094438608,0.0018583999999999999,151.90535150368507,387.2615054558039,-3.083804906464464
2.27141404652638,0.0018728,151.95978724017795,387.2615054558039,-3.083804906464464
2.281116797686254,0.0018808,151.98995877489642,387.2615054558039,-3.083804906464464
2.320898077441735,0.0019136,152.11314238143572,387.2615054558039,-3.083804906464464
2.3538874313853047,0.0019408,152.21467127787517,387.2615054558039,-3.083804906464464
2.3616496323132035,0.0019471999999999998,152.23847960017974,387.2615054558039,-3.083804906464464
2.406282287648622,0.001984,152.37478981609527,387.2615054558039,-3.083804906464464
2.4227769646204065,0.0019976,152.42491533068684,387.2615054558039,-3.083804906464464
2.428598615316331,0.0020024,152.44257488952468,387.2615054558039,-3.083804906464464
2.446063567404103,0.0020168,152.49545477399622,387.2615054558039,-3.083804906464464
2.460617694143913,0.0020288,152.53940895550093,387.2615054558039,-3.083804906464464
2.4848745720435965,0.0020488,152.61244127439593,387.2615054558039,-3.083804906464464
2.498458423667419,0.0020599999999999998,152.6532179124444,387.2615054558039,-3.083804906464464
2.5110720001752553,0.0020704,152.69100458212526,387.2615054558039,-3.083804906464464
2.5236855766830906,0.0020808,152.72871729823444,387.2615054558039,-3.083804906464464
2.540180253654875,0.0020943999999999997,152.77792319337559,387.2615054558039,-3.083804906464464
2.552793830162711,0.0021048,152.81546719625106,387.2615054558039,-3.083804906464464
2.558615480858635,0.0021096,152.8327707894834,387.2615054558039,-3.083804906464464
2.5663776817865336,0.002116,152.85581838094404,387.2615054558039,-3.083804906464464
2.580931808526344,0.002128,152.8989594711869,387.2615054558039,-3.083804906464464
2.594515660150167,0.0021392,152.939138966413,387.2615054558039,-3.083804906464464
2.6216833633978127,0.0021616,153.0192526736793,387.2615054558039,-3.083804906464464
2.6323563896736735,0.0021704,153.05063725158521,387.2615054558039,-3.083804906464464
2.667286293849218,0.0021992,153.15300517390645,387.2615054558039,-3.083804906464464
2.6857215210529777,0.0022144,153.20682183472664,387.2615054558039,-3.083804906464464
2.6925134468648886,0.0022199999999999998,153.22661268461795,387.2615054558039,-3.083804906464464
2.698335097560813,0.0022248,153.24356077879207,387.2615054558039,-3.083804906464464
2.7099783989526616,0.0022344,153.27741424613572,387.2615054558039,-3.083804906464464
2.726473075924446,0.002248,153.32527638304032,387.2615054558039,-3.083804906464464
2.733265001736357,0.0022535999999999997,153.34495148305464,387.2615054558039,-3.083804906464464
2.7720760063758516,0.0022856,153.45701698663746,387.2615054558039,-3.083804906464464
2.790511233579611,0.0023008,153.5100335923608,387.2615054558039,-3.083804906464464
2.8011842598554715,0.0023095999999999998,153.54066498282205,387.2615054558039,-3.083804906464464
2.8137978363633076,0.00232,153.57680709562595,387.2615054558039,-3.083804906464464
2.8720143433225482,0.002368,153.7428048216402,387.2615054558039,-3.083804906464464
2.8758954437864976,0.0023712,153.75382445092814,387.2615054558039,-3.083804906464464
2.8826873695984094,0.0023768,153.7730948566021,387.2615054558039,-3.083804906464464
2.897241496338219,0.0023888,153.81432905808276,387.2615054558039,-3.083804906464464
2.9050036972661184,0.0023952,153.83628759703905,387.2615054558039,-3.083804906464464
2.9224686493538905,0.0024096,153.8856108174201,387.2615054558039,-3.083804906464464
2.9292605751658014,0.0024151999999999997,153.9047610079676,387.2615054558039,-3.083804906464464
2.9467255272535744,0.0024296,153.9539250078174,387.2615054558039,-3.083804906464464
2.968071579805296,0.0024472,154.01386028290727,387.2615054558039,-3.083804906464464
2.971952680269245,0.0024503999999999997,154.02473952036533,387.2615054558039,-3.083804906464464
2.9971798332849158,0.0024712,154.09531998714826,387.2615054558039,-3.083804906464464
3.0068825844447895,0.0024792,154.12240458105484,387.2615054558039,-3.083804906464464
3.036961113040397,0.0025039999999999997,154.20615102239452,387.2615054558039,-3.083804906464464
3.0456935890842836,0.0025112,154.230403834934,387.2615054558039,-3.083804906464464
3.0631585411720557,0.0025256,154.27882825520643,387.2615054558039,-3.083804906464464
3.074801842563904,0.0025352,154.31105139452035,387.2615054558039,-3.083804906464464
3.097118170231613,0.0025536,154.37267970893794,387.2615054558039,-3.083804906464464
3.1019695458115493,0.0025575999999999997,154.38605422408244,387.2615054558039,-3.083804906464464
3.114583122319385,0.002568,154.42078984098706,387.2615054558039,-3.083804906464464
3.1368994499870944,0.0025864,154.48211106423702,387.2615054558039,-3.083804906464464
3.1630968781187527,0.002608,154.5538801775032,387.2615054558039,-3.083804906464464
3.2164620094980565,0.002652,154.6993634075512,387.2615054558039,-3.083804906464464
3.232956686469841,0.0026655999999999997,154.7441400998019,387.2615054558039,-3.083804906464464
3.2494513634416267,0.0026792,154.7888277836953,387.2615054558039,-3.083804906464464
3.293113743661057,0.0027152,154.90669373721695,387.2615054558039,-3.083804906464464
3.298935394356981,0.0027199999999999998,154.92236302165705,387.2615054558039,-3.083804906464464
3.3561816262002346,0.0027672,155.07587421465365,387.2615054558039,-3.083804906464464
3.362973552012146,0.0027727999999999997,155.0940193917662,387.2615054558039,-3.083804906464464
3.3920818054917663,0.0027968,155.17162311547506,387.2615054558039,-3.083804906464464
3.40178455665164,0.0028048,155.1974332520947,387.2615054558039,-3.083804906464464
3.425071159435336,0.0028239999999999997,155.25926072119995,387.2615054558039,-3.083804906464464
3.4483577622190325,0.0028431999999999997,155.3209244668301,387.2615054558039,-3.083804906464464
3.4900795922064884,0.0028775999999999997,155.43100072947638,387.2615054558039,-3.083804906464464
3.5133661949901844,0.0028967999999999997,155.49221545944528,387.2615054558039,-3.083804906464464
3.5347122475419064,0.0029143999999999997,155.54819009952868,387.2615054558039,-3.083804906464464
3.5774043526453494,0.0029495999999999997,155.6597454449041,387.2615054558039,-3.083804906464464
3.597780130081084,0.0029663999999999997,155.71280462888078,387.2615054558039,-3.083804906464464
3.635620859604591,0.0029976,155.8110332263451,387.2615054558039,-3.083804906464464
3.660848012620262,0.0030184,155.87629752931397,387.2615054558039,-3.083804906464464
3.6812237900559963,0.0030352,155.92888305084992,387.2615054558039,-3.083804906464464
3.699659017259756,0.0030504,155.97636269531816,387.2615054558039,-3.083804906464464
3.7093617684196287,0.0030583999999999997,156.0013149160411,387.2615054558039,-3.083804906464464
3.721975344927465,0.0030688,156.033714781224,387.2615054558039,-3.083804906464464
3.732648371203325,0.0030775999999999998,156.0610966185181,387.2615054558039,-3.083804906464464
3.7501133232910973,0.0030919999999999997,156.10583748859392,387.2615054558039,-3.083804906464464
3.759816074450971,0.0031,156.13065841207342,387.2615054558039,-3.083804906464464
3.7656377251468953,0.0031048,156.14553897554242,387.2615054558039,-3.083804906464464
3.7860135025826294,0.0031216,156.1975504401494,387.2615054558039,-3.083804906464464
3.8102703804823133,0.0031416,156.2593267267819,387.2615054558039,-3.083804906464464
3.8471408348898324,0.003172,156.3529337406878,387.2615054558039,-3.083804906464464
3.8519922104697693,0.003176,156.3652243541854,387.2615054558039,-3.083804906464464
3.878189638601427,0.0031975999999999997,156.43148964083628,387.2615054558039,-3.083804906464464
3.8956545906891997,0.003212,156.4755695388638,387.2615054558039,-3.083804906464464
3.9364061455606683,0.0032456,156.57812399782998,387.2615054558039,-3.083804906464464
3.9480494469525165,0.0032551999999999998,156.60734911206842,387.2615054558039,-3.083804906464464
3.9558116478804153,0.0032616,156.62681384957824,387.2615054558039,-3.083804906464464
3.9752171502001623,0.0032776,156.67541063789778,387.2615054558039,-3.083804906464464
4.004325403679783,0.0033016,156.74813270449772,387.2615054558039,-3.083804906464464
4.0324633820434155,0.0033247999999999997,156.8182349833136,387.2615054558039,-3.083804906464464
4.060601360407048,0.003348,156.88814674562502,387.2615054558039,-3.083804906464464
4.062541910639023,0.0033496,156.89296127063517,387.2615054558039,-3.083804906464464
4.082917688074757,0.0033664,156.94345975131537,387.2615054558039,-3.083804906464464
4.112996216670366,0.0033912,157.01782586641372,387.2615054558039,-3.083804906464464
4.123669242946226,0.0034,157.04416282057096,387.2615054558039,-3.083804906464464
4.135312544338075,0.0034096,157.07286374195297,387.2615054558039,-3.083804906464464
4.146955845729923,0.0034192,157.10153316478872,387.2615054558039,-3.083804906464464
4.151807221309859,0.0034232,157.11346949043,387.2615054558039,-3.083804906464464
4.159569422237758,0.0034295999999999997,157.13255630343673,387.2615054558039,-3.083804906464464
4.188677675717378,0.0034536,157.2040084729615,387.2615054558039,-3.083804906464464
4.226518405240885,0.0034847999999999997,157.29660745239968,387.2615054558039,-3.083804906464464
4.250775283140569,0.0035047999999999998,157.355795752056,387.2615054558039,-3.083804906464464
4.262418584532417,0.0035144,157.38415933484703,387.2615054558039,-3.083804906464464
4.27212133569229,0.0035223999999999997,157.40777257910358,387.2615054558039,-3.083804906464464
4.2992890389399365,0.0035448,157.47377865073585,387.2615054558039,-3.083804906464464
4.313843165679747,0.0035567999999999997,157.5090721232199,387.2615054558039,-3.083804906464464
4.3254864670715945,0.0035664,157.53727347676804,387.2615054558039,-3.083804906464464
4.350713620087266,0.0035872,157.59827504569964,387.2615054558039,-3.083804906464464
4.357505545899177,0.0035927999999999997,157.61467495591464,387.2615054558039,-3.083804906464464
4.360416371247139,0.0035952,157.6217004367301,387.2615054558039,-3.083804906464464
4.3866137993787975,0.0036168,157.68484766981481,387.2615054558039,-3.083804906464464
4.420573428438354,0.0036447999999999997,157.7664867234644,387.2615054558039,-3.083804906464464
4.4293059044822405,0.003652,157.7874400429414,387.2615054558039,-3.083804906464464
4.440949205874088,0.0036615999999999997,157.81535275810958,387.2615054558039,-3.083804906464464
4.483641310977532,0.0036967999999999997,157.91745610804762,387.2615054558039,-3.083804906464464
4.487522411441481,0.0036999999999999997,157.92671938879764,387.2615054558039,-3.083804906464464
4.500135987949317,0.0037104,157.95680349585348,387.2615054558039,-3.083804906464464
4.51760094003709,0.0037248,157.99840417843512,387.2615054558039,-3.083804906464464
4.563203870488495,0.0037624,158.10673354605717,387.2615054558039,-3.083804906464464
4.590371573736141,0.0037847999999999996,158.1710695128808,387.2615054558039,-3.083804906464464
4.597163499548052,0.0037903999999999998,158.1871302805908,387.2615054558039,-3.083804906464464
4.622390652563723,0.0038112,158.24670371342756,387.2615054558039,-3.083804906464464
4.667023307899141,0.003848,158.35179317025927,387.2615054558039,-3.083804906464464
4.678666609290989,0.0038575999999999997,158.379143258193,387.2615054558039,-3.083804906464464
4.692250460914812,0.0038688,158.41101816726626,387.2615054558039,-3.083804906464464
4.7388236664822045,0.0039071999999999996,158.52003139427333,387.2615054558039,-3.083804906464464
4.744645317178128,0.003912,158.53362860723203,387.2615054558039,-3.083804906464464
4.762110269265901,0.0039264,158.57438125986602,387.2615054558039,-3.083804906464464
4.770842745309787,0.0039336,158.5947357247438,387.2615054558039,-3.083804906464464
4.790248247629535,0.0039496,158.63991592011183,387.2615054558039,-3.083804906464464
4.81353485041323,0.0039688,158.69403804161993,387.2615054558039,-3.083804906464464
4.827118702037054,0.00398,158.72556212308385,387.2615054558039,-3.083804906464464
4.849435029704763,0.0039984,158.77727668143962,387.2615054558039,-3.083804906464464
4.921249363044447,0.004057611522304461,158.9430686425172,387.2615054558039,-3.083804906464464
5.13087071236758,0.004230446089217844,159.42169107297474,387.2615054558039,-3.083804906464464
5.363783322726615,0.00442248449689938,159.9446357222325,387.2615054558039,-3.083804906464464
6.528346374521791,0.005382676535307062,162.4369930159597,387.2615054558039,-3.083804906464464
7.71620068735287,0.006362072414482897,164.80582748543122,387.2615054558039,-3.083804906464464
8.461521040501783,0.006976595319063813,166.21956739525396,387.2615054558039,-3.083804906464464
8.577977345681301,0.007072614522904581,166.43599748801043,387.2615054558039,-3.083804906464464
9.858996702655993,0.00812882576515303,168.74565427535353,387.2615054558039,-3.083804906464464
10.37140444544587,0.00855131026205241,169.63633093026334,387.2615054558039,-3.083804906464464
10.604317055804906,0.008743348669733947,170.03549294554114,387.2615054558039,-3.083804906464464
11.209889842738399,0.009242648529705941,171.05763011391488,387.2615054558039,-3.083804906464464
11.629132541384662,0.009588317663532707,171.75267917672429,387.2615054558039,-3.083804906464464
11.722297585528276,0.009665133026605321,171.90579931758322,387.2615054558039,-3.083804906464464
12.21141406728225,0.010068413682736548,172.70202416487925,387.2615054558039,-3.083804906464464
14.004841167046822,0.011547109421884378,175.5207060842008,387.2615054558039,-3.083804906464464
14.237753777405857,0.011739147829565914,175.8761440692901,387.2615054558039,-3.083804906464464
14.493957648800793,0.011950390078015603,176.26451684994998,387.2615054558039,-3.083804906464464
15.006365391590672,0.012372874574914983,177.0333215718828,387.2615054558039,-3.083804906464464
15.239278001949707,0.012564912982596519,177.37938665842265,387.2615054558039,-3.083804906464464
15.821559527847294,0.01304500900180036,178.23564463348242,387.2615054558039,-3.083804906464464
16.287384748565366,0.013429085817163433,178.91183357997272,387.2615054558039,-3.083804906464464
17.591695366575962,0.014504500900180036,180.76616283927046,387.2615054558039,-3.083804906464464
18.080811848329937,0.014907781556311263,181.44760738095394,387.2615054558039,-3.083804906464464
18.919297245622463,0.015599119823964794,182.59930228804254,387.2615054558039,-3.083804906464464
19.54816129359186,0.016117623524704944,183.45005188430622,387.2615054558039,-3.083804906464464
19.664617598771375,0.01621364272854571,183.60641976173912,387.2615054558039,-3.083804906464464
20.75930686745884,0.01711622324464893,185.0590383541621,387.2615054558039,-3.083804906464464
21.318297132320524,0.017577115423084617,185.78925585772893,387.2615054558039,-3.083804906464464
21.877287397182208,0.018038007601520304,186.51204301504808,387.2615054558039,-3.083804906464464
22.04032622443353,0.018172434486897378,186.7214944968992,387.2615054558039,-3.083804906464464
22.436277662043892,0.01849889977995599,187.22766247032217,387.2615054558039,-3.083804906464464
22.529442706187506,0.018575715143028606,187.34625308381933,387.2615054558039,-3.083804906464464
22.971976665869672,0.018940588117623523,187.9069672738692,387.2615054558039,-3.083804906464464
23.46109314762365,0.01934386877375475,188.52182541339437,387.2615054558039,-3.083804906464464
23.670714496946783,0.019516703340668136,188.7838033701064,387.2615054558039,-3.083804906464464
23.787170802126298,0.019612722544508902,188.92895567421417,387.2615054558039,-3.083804906464464
24.06666593455714,0.019843168633726746,189.27619508402623,387.2615054558039,-3.083804906464464
24.509199894239305,0.020208041608321663,189.82279153262715,387.2615054558039,-3.083804906464464
24.718821243562438,0.020380876175235048,190.08036098579262,387.2615054558039,-3.083804906464464
24.905151331849666,0.020534506901380277,190.3085973323508,387.2615054558039,-3.083804906464464
25.53401537981906,0.021053010602120423,191.0740253310915,387.2615054558039,-3.083804906464464
25.720345468106288,0.021206641328265653,191.29940225524723,387.2615054558039,-3.083804906464464
26.162879427788457,0.021571514302860573,191.8321356269008,387.2615054558039,-3.083804906464464
26.25604447193207,0.021648329665933188,191.9438409112558,387.2615054558039,-3.083804906464464
26.97807356404508,0.02224364872974595,192.80437633103972,387.2615054558039,-3.083804906464464
27.653520134086286,0.022800560112022406,193.60129655731924,387.2615054558039,-3.083804906464464
27.839850222373514,0.022954190838167635,193.81979601435702,387.2615054558039,-3.083804906464464
28.119345354804356,0.02318463692738548,194.14647885026872,387.2615054558039,-3.083804906464464
28.63175309759423,0.02360712142428486,194.74212710867184,387.2615054558039,-3.083804906464464
29.563403539030368,0.024375275055011,195.81457979929218,387.2615054558039,-3.083804906464464
30.005937498712537,0.024740148029605922,196.31936991069418,387.2615054558039,-3.083804906464464
30.28543263114338,0.024970594118823766,196.63668925051707,387.2615054558039,-3.083804906464464
30.63480154668193,0.02525865173034607,197.03173691825154,387.2615054558039,-3.083804906464464
31.054044245328196,0.025604320864172834,197.5034823341055,387.2615054558039,-3.083804906464464
31.240374333615424,0.025757951590318063,197.7123490014947,387.2615054558039,-3.083804906464464
31.449995682938557,0.025930786157231447,197.94674413239085,387.2615054558039,-3.083804906464464
31.706199554333494,0.026142028405681136,198.232401263122,387.2615054558039,-3.083804906464464
32.28848108023109,0.02662212442488498,198.87829505202154,387.2615054558039,-3.083804906464464
32.54468495162602,0.026833366673334667,199.16104747859805,387.2615054558039,-3.083804906464464
32.87076260612867,0.027102220444088818,199.5196618167689,387.2615054558039,-3.083804906464464
33.0803839554518,0.027275055011002202,199.74946717565138,387.2615054558039,-3.083804906464464
33.429752870990356,0.027563112622524505,200.13121805513134,387.2615054558039,-3.083804906464464
33.80241304756481,0.027870374074814963,200.53670799213046,387.2615054558039,-3.083804906464464
33.98874313585204,0.028024004800960192,200.73879889309532,387.2615054558039,-3.083804906464464
34.198364485175176,0.028196839367873577,200.9656354037326,387.2615054558039,-3.083804906464464
34.407985834498305,0.028369673934786958,201.19193029773785,387.2615054558039,-3.083804906464464
34.96697609935999,0.028830566113222645,201.7927700748249,387.2615054558039,-3.083804906464464
35.502675103185766,0.029272254450890177,202.36506940635041,387.2615054558039,-3.083804906464464
36.22470419529878,0.02986757351470294,203.13112889620734,387.2615054558039,-3.083804906464464
36.92344202637588,0.03044368873774755,203.86682677075703,387.2615054558039,-3.083804906464464
37.412558508129855,0.030846969393878775,204.3785878711809,387.2615054558039,-3.083804906464464
37.94825751195563,0.03128865773154631,204.9361034407917,387.2615054558039,-3.083804906464464
38.11129633920696,0.031423084616923384,205.10517175068026,387.2615054558039,-3.083804906464464
39.159403085822625,0.0322872574514903,206.18538103883313,387.2615054558039,-3.083804906464464
39.7416846117202,0.032767353470694136,206.78062327857276,387.2615054558039,-3.083804906464464
40.53358748694093,0.03342028405681136,207.58472279624772,387.2615054558039,-3.083804906464464
40.97612144662309,0.03378515703140628,208.0314033816921,387.2615054558039,-3.083804906464464
41.185742795946226,0.033957991598319665,208.24233190702802,387.2615054558039,-3.083804906464464
41.46523792837707,0.03418843768753751,208.52291980333973,387.2615054558039,-3.083804906464464
41.83789810495153,0.034495699139827966,208.8958922964392,387.2615054558039,-3.083804906464464
42.42017963084911,0.034975795159031806,209.47607842597643,387.2615054558039,-3.083804906464464
42.932587373638995,0.03539827965593119,209.98407781709787,387.2615054558039,-3.083804906464464
43.18879124503393,0.03560952190438088,210.2371903882224,387.2615054558039,-3.083804906464464
44.14373294750597,0.03639687937587517,211.17549503270976,387.2615054558039,-3.083804906464464
44.49310186304453,0.036684936987397485,211.51679502462835,387.2615054558039,-3.083804906464464
44.9356358227267,0.037049809961992405,211.94761165063096,387.2615054558039,-3.083804906464464
45.261713477229335,0.037318663732746546,212.26399741831628,387.2615054558039,-3.083804906464464
46.40298526798862,0.03825965193038608,213.36441444223917,387.2615054558039,-3.083804906464464
46.845519227670785,0.038624524904981,213.78826046857404,387.2615054558039,-3.083804906464464
46.9852667938862,0.03873974794958991,213.92178178692555,387.2615054558039,-3.083804906464464
47.38121823149656,0.03906621324264853,214.29925369905692,387.2615054558039,-3.083804906464464
47.56754831978379,0.03921984396879376,214.47646167415095,387.2615054558039,-3.083804906464464
47.68400462496331,0.039315863172634524,214.58707919484164,387.2615054558039,-3.083804906464464
48.9417327209021,0.040352870574114824,215.77511128270152,387.2615054558039,-3.083804906464464
49.058189026081614,0.04044888977795559,215.88450842769072,387.2615054558039,-3.083804906464464
50.57212099341535,0.04169713942788558,217.29757851281016,387.2615054558039,-3.083804906464464
50.73515982066667,0.04183156631326265,217.44876474623283,387.2615054558039,-3.083804906464464
51.13111125827704,0.04215803160632127,217.8151446273894,387.2615054558039,-3.083804906464464
51.20098504138475,0.04221564312862573,217.87968487183826,387.2615054558039,-3.083804906464464
51.34073260760016,0.042330866173234644,218.00866240210624,387.2615054558039,-3.083804906464464
51.387315129671975,0.04236927385477096,218.05162447649636,387.2615054558039,-3.083804906464464
51.736684045210524,0.04265733146629326,218.37335730035383,387.2615054558039,-3.083804906464464
51.899722872461844,0.04279175835167033,218.52320921083037,387.2615054558039,-3.083804906464464
52.29567431007221,0.04311822364472895,218.88637298610035,387.2615054558039,-3.083804906464464
52.59846070353895,0.043367873574714944,219.1633633568105,387.2615054558039,-3.083804906464464
52.738208269754374,0.04348309661932387,219.29099526008443,387.2615054558039,-3.083804906464464
52.901247097005694,0.04361752350470094,219.43973256099358,387.2615054558039,-3.083804906464464
53.18074222943655,0.04384796959391879,219.6942955346134,387.2615054558039,-3.083804906464464
53.879480060513636,0.04442408481696339,220.32843081184552,387.2615054558039,-3.083804906464464
54.01922762672906,0.044539307861572314,220.45487210940453,387.2615054558039,-3.083804906464464
54.43847032537532,0.044884976995399076,220.83343279106347,387.2615054558039,-3.083804906464464
55.02075185127292,0.04536507301460292,221.35733069654825,387.2615054558039,-3.083804906464464
55.09062563438063,0.045422684536907385,221.42005280900716,387.2615054558039,-3.083804906464464
55.463285810955085,0.04572994598919784,221.75404821029946,387.2615054558039,-3.083804906464464
55.696198421314115,0.045921984396879376,221.96235095424194,387.2615054558039,-3.083804906464464
56.162023642032196,0.046306061212242455,222.37794005863879,387.2615054558039,-3.083804906464464
56.744305167929774,0.04678615723144629,222.89554079225863,387.2615054558039,-3.083804906464464
56.95392651725291,0.046958991798359676,223.08136943649885,387.2615054558039,-3.083804906464464
57.81570317558134,0.04766953390678136,223.84254594516855,387.2615054558039,-3.083804906464464
57.95545074179677,0.047784756951390284,223.96556181136202,387.2615054558039,-3.083804906464464
58.09519830801217,0.047899979995999195,224.0884620471593,387.2615054558039,-3.083804906464464
58.2815283962994,0.048053610722144424,224.25214982632772,387.2615054558039,-3.083804906464464
58.654188572873856,0.04836087217443488,224.5789143821684,387.2615054558039,-3.083804906464464
59.073431271520136,0.04870654130826166,224.94555823115996,387.2615054558039,-3.083804906464464
59.37621766498688,0.048956191238247654,225.20972573830514,387.2615054558039,-3.083804906464464
59.67900405845362,0.04920584116823365,225.473368391718,387.2615054558039,-3.083804906464464
60.37774188953073,0.04978195639127826,226.0797915598469,387.2615054558039,-3.083804906464464
61.332683592002766,0.05056931386277255,226.90416198055445,387.2615054558039,-3.083804906464464
62.52053790483385,0.05154870974194839,227.92264524765125,387.2615054558039,-3.083804906464464
62.77674177622879,0.05175995199039808,228.141325502514,387.2615054558039,-3.083804906464464
63.102819430731444,0.052028805761152236,228.4191430835794,387.2615054558039,-3.083804906464464
63.63851843455722,0.052470494098819764,228.87434529959384,387.2615054558039,-3.083804906464464
64.38383878770613,0.05308501700340068,229.50519194978114,387.2615054558039,-3.083804906464464
64.73320770324467,0.05337307461492298,229.7999202989317,387.2615054558039,-3.083804906464464
65.03599409671142,0.053622724544908976,230.05485009087144,387.2615054558039,-3.083804906464464
65.99093579918348,0.05441008201640328,230.85584412821711,387.2615054558039,-3.083804906464464
66.8760037185478,0.05513982796559312,231.59420163914587,387.2615054558039,-3.083804906464464
67.22537263408636,0.05542788557711542,231.88460826855655,387.2615054558039,-3.083804906464464
67.29524641719406,0.055485497099419884,231.94261889743717,387.2615054558039,-3.083804906464464
67.50486776651721,0.05565833166633327,232.11651000174112,387.2615054558039,-3.083804906464464
67.64461533273261,0.05577355471094218,232.23232042349747,387.2615054558039,-3.083804906464464
67.69119785480444,0.0558119623924785,232.27090315720775,387.2615054558039,-3.083804906464464
67.87752794309166,0.05596559311862373,232.4251306552129,387.2615054558039,-3.083804906464464
67.92411046516347,0.056004000800160034,232.46366171986116,387.2615054558039,-3.083804906464464
68.25018811966612,0.05627285457091419,232.73309120174352,387.2615054558039,-3.083804906464464
68.59955703520467,0.05656091218243649,233.02120915444735,387.2615054558039,-3.083804906464464
69.04209099488683,0.05692578515703141,233.3853383672327,387.2615054558039,-3.083804906464464
69.5312074766408,0.05732906581316263,233.7867396165794,387.2615054558039,-3.083804906464464
70.34640161289744,0.05800120024004801,234.45330313633278,387.2615054558039,-3.083804906464464
70.53273170118466,0.05815483096619324,234.60523673216517,387.2615054558039,-3.083804906464464
71.4643821426208,0.05892298459691939,235.36256929651765,387.2615054558039,-3.083804906464464
71.72058601401575,0.05913422684536908,235.57015946278912,387.2615054558039,-3.083804906464464
72.04666366851838,0.05940308061612322,235.83394732843004,387.2615054558039,-3.083804906464464
73.07147915409814,0.060248049609921986,236.65997981615223,387.2615054558039,-3.083804906464464
73.63046941895983,0.06070894178835767,237.10863819202154,387.2615054558039,-3.083804906464464
73.93325581242658,0.06095859171834367,237.3511067513618,387.2615054558039,-3.083804906464464
74.7018674266114,0.061592318463692744,237.9648709996243,387.2615054558039,-3.083804906464464
75.19098390836537,0.06199559911982397,238.35416625970296,387.2615054558039,-3.083804906464464
75.30744021354488,0.062091618323664735,238.44670988936096,387.2615054558039,-3.083804906464464
76.0760518277297,0.06272534506901381,239.05610405441644,387.2615054558039,-3.083804906464464
76.19250813290923,0.06282136427285458,239.1482266139882,387.2615054558039,-3.083804906464464
76.7514983977709,0.06328225645129026,239.58965277502594,387.2615054558039,-3.083804906464464
77.03099353020174,0.0635127025405081,239.809895539463,387.2615054558039,-3.083804906464464
77.4036537067762,0.06381996399279856,240.10306837330654,387.2615054558039,-3.083804906464464
77.63656631713523,0.06401200240048009,240.28602188270446,387.2615054558039,-3.083804906464464
77.93935271060197,0.06426165233046609,240.52354174741808,387.2615054558039,-3.083804906464464
78.28872162614053,0.0645497099419884,240.79715641628047,387.2615054558039,-3.083804906464464
78.82442062996631,0.06499139827965593,241.21577583865124,387.2615054558039,-3.083804906464464
79.12720702343306,0.06524104820964192,241.45189599271959,387.2615054558039,-3.083804906464464
79.52315846104342,0.06556751350270054,241.76013749198142,387.2615054558039,-3.083804906464464
79.73277981036655,0.06574034806961393,241.92308181803392,387.2615054558039,-3.083804906464464
80.0355662038333,0.06598999799959993,242.15815120110486,387.2615054558039,-3.083804906464464
80.1287312479769,0.06606681336267253,242.23041043272275,387.2615054558039,-3.083804906464464
80.7110127738745,0.06654690938187638,242.68129053503435,387.2615054558039,-3.083804906464464
81.15354673355667,0.0669117823564713,243.0231114770115,387.2615054558039,-3.083804906464464
81.54949817116703,0.06723824764952992,243.32833556232066,387.2615054558039,-3.083804906464464
81.85228456463378,0.06748789757951591,243.5613523985556,387.2615054558039,-3.083804906464464
82.03861465292101,0.06764152830566114,243.7045802949582,387.2615054558039,-3.083804906464464
82.50443987363907,0.06802560512102421,244.06209610033477,387.2615054558039,-3.083804906464464
82.87710005021353,0.06833286657331467,244.34754225851555,387.2615054558039,-3.083804906464464
83.04013887746484,0.06846729345869174,244.472267499253,387.2615054558039,-3.083804906464464
83.17988644368027,0.06858251650330066,244.57909885417538,387.2615054558039,-3.083804906464464
83.59912914232653,0.06892818563712742,244.8991737164416,387.2615054558039,-3.083804906464464
83.73887670854195,0.06904340868173635,245.00572614447964,387.2615054558039,-3.083804906464464
83.83204175268558,0.06912022404480897,245.07672257144347,387.2615054558039,-3.083804906464464
84.6239446279063,0.06977315463092619,245.67895485341882,387.2615054558039,-3.083804906464464
85.55559506934243,0.07054130826165234,246.38465671898564,387.2615054558039,-3.083804906464464
85.69534263555786,0.07065653130626126,246.4902529422102,387.2615054558039,-3.083804906464464
86.06800281213232,0.07096379275855172,246.771515057567,387.2615054558039,-3.083804906464464
86.65028433802989,0.07144388877775555,247.21003815345884,387.2615054558039,-3.083804906464464
86.99965325356845,0.07173194638927786,247.47260039669212,387.2615054558039,-3.083804906464464
87.74497360671737,0.07234646929385878,248.03136277958473,387.2615054558039,-3.083804906464464
88.11763378329182,0.07265373074614924,248.31004961458711,387.2615054558039,-3.083804906464464
88.37383765468675,0.07286497299459892,248.50138023427706,387.2615054558039,-3.083804906464464
89.00270170265615,0.07338347669533907,248.97009508161116,387.2615054558039,-3.083804906464464
89.25890557405108,0.07359471894378876,249.16068247913822,387.2615054558039,-3.083804906464464
89.72473079476917,0.07397879575915184,249.5066593181029,387.2615054558039,-3.083804906464464
90.14397349341543,0.0743244648929786,249.81743998512653,387.2615054558039,-3.083804906464464
90.72625501931303,0.07480456091218245,250.24814627482505,387.2615054558039,-3.083804906464464
91.05233267381566,0.07507341468293659,250.48887086822532,387.2615054558039,-3.083804906464464
91.79765302696457,0.0756879375875175,251.03783955111655,387.2615054558039,-3.083804906464464
92.21689572561085,0.07603360672134428,251.3458704821923,387.2615054558039,-3.083804906464464
92.75259472943662,0.07647529505901181,251.73867193796002,387.2615054558039,-3.083804906464464
93.82399273708819,0.07735867173434688,252.52163054284802,387.2615054558039,-3.083804906464464
94.05690534744723,0.07755071014202841,252.6913766402086,387.2615054558039,-3.083804906464464
94.19665291366265,0.07766593318663734,252.7931456125489,387.2615054558039,-3.083804906464464
94.68576939541661,0.07806921384276856,253.14887424142833,387.2615054558039,-3.083804906464464
95.1283033550988,0.07843408681736348,253.470106904293,387.2615054558039,-3.083804906464464
95.38450722649371,0.07864532906581316,253.6558173305925,387.2615054558039,-3.083804906464464
96.40932271207348,0.07949029805961193,254.39672186555518,387.2615054558039,-3.083804906464464
96.71210910554022,0.07973994798959792,254.6150368408018,387.2615054558039,-3.083804906464464
97.2943906314378,0.08022004400880177,255.03412556440892,387.2615054558039,-3.083804906464464
97.50401198076094,0.08039287857571514,255.1847579016993,387.2615054558039,-3.083804906464464
97.71363333008408,0.08056571314262853,255.33526399398778,387.2615054558039,-3.083804906464464
98.08629350665854,0.08087297459491899,255.6025198330675,387.2615054558039,-3.083804906464464
98.5288274663407,0.08123784756951391,255.919372353089,387.2615054558039,-3.083804906464464
99.97288565056672,0.08242848569713944,256.94947301837516,387.2615054558039,-3.083804906464464
101.62656518411586,0.08379195839167834,258.1220034068138,387.2615054558039,-3.083804906464464
101.7663127503313,0.08390718143628727,258.22074821995903,387.2615054558039,-3.083804906464464
102.32530301519297,0.08436807361472295,258.61519978609385,387.2615054558039,-3.083804906464464
103.07062336834188,0.08498259651930387,259.139830419287,387.2615054558039,-3.083804906464464
104.25847768117295,0.0859619923984797,259.9729127502309,387.2615054558039,-3.083804906464464
104.95721551225006,0.08653810762152431,260.461232055981,387.2615054558039,-3.083804906464464
105.44633199400404,0.08694138827765553,260.80230147135023,387.2615054558039,-3.083804906464464
106.23823486922475,0.08759431886377275,261.35320384320875,387.2615054558039,-3.083804906464464
106.37798243544017,0.08770954190838168,261.4502554296451,387.2615054558039,-3.083804906464464
106.77393387305054,0.0880360072014403,261.72496526917047,387.2615054558039,-3.083804906464464
107.42608918205583,0.08857371474294859,262.1765640361755,387.2615054558039,-3.083804906464464
107.72887557552258,0.08882336467293458,262.38587132753395,387.2615054558039,-3.083804906464464
108.38103088452789,0.0893610722144429,262.83590937094664,387.2615054558039,-3.083804906464464
108.59065223385102,0.08953390678135628,262.98034000441646,387.2615054558039,-3.083804906464464
109.38255510907173,0.0901868373674735,263.5249883425786,387.2615054558039,-3.083804906464464
109.52230267528716,0.09030206041208243,263.62094290367287,387.2615054558039,-3.083804906464464
110.19774924532837,0.09085897179435888,264.084051828979,387.2615054558039,-3.083804906464464
111.36231229712354,0.09181916383276656,264.8799241022422,387.2615054558039,-3.083804906464464
111.734972473698,0.09212642528505702,265.13391683087656,387.2615054558039,-3.083804906464464
112.89953552549316,0.0930866173234647,265.92552304942024,387.2615054558039,-3.083804906464464
113.99422479418062,0.09398919783956791,266.6667341901654,387.2615054558039,-3.083804906464464
114.90258397458086,0.09473814762952591,267.27967662586445,387.2615054558039,-3.083804906464464
115.7177781108375,0.09541028205641129,267.82814604009025,387.2615054558039,-3.083804906464464
115.83423441601701,0.09550630126025206,267.90637562726886,387.2615054558039,-3.083804906464464
116.50968098605821,0.09606321264252851,268.359503819699,387.2615054558039,-3.083804906464464
117.86057412614062,0.09717703540708142,269.26269832662086,387.2615054558039,-3.083804906464464
118.16336051960735,0.09742668533706741,269.4645835448046,387.2615054558039,-3.083804906464464
119.25804978829483,0.09832926585317064,270.1927990158557,387.2615054558039,-3.083804906464464
119.35121483243844,0.09840608121624325,270.2546541726374,387.2615054558039,-3.083804906464464
120.23628275180278,0.0991358271654331,270.8413419973979,387.2615054558039,-3.083804906464464
120.51577788423361,0.09936627325465093,271.0262616021295,387.2615054558039,-3.083804906464464
121.0514768880594,0.09980796159231847,271.38022401479077,387.2615054558039,-3.083804906464464
121.16793319323892,0.09990398079615924,271.4570914673687,387.2615054558039,-3.083804906464464