File: datasets/aisi_316_L/data/M1/valid_24.csv
Time(s),Strain(%),Stress(MPa),Temp(C),Log_SR(s-1)
0.0,0.0,0.0,434.22374620356436,-2.177395909741907
0.002888664727562909,1.92e-05,3.194706,434.22374620356436,-2.177395909741907
0.003249747818508273,2.16e-05,3.59404425,434.22374620356436,-2.177395909741907
0.00493480224291997,3.28e-05,5.45762275,434.22374620356436,-2.177395909741907
0.005175524303550213,3.4399999999999996e-05,5.72384825,434.22374620356436,-2.177395909741907
0.00782346697048288,5.2e-05,8.652328749999999,434.22374620356436,-2.177395909741907
0.011073214788991153,7.36e-05,12.246373,434.22374620356436,-2.177395909741907
0.01179538097088188,7.84e-05,13.0450495,434.22374620356436,-2.177395909741907
0.01275826921340285,8.48e-05,14.109951500000001,434.22374620356436,-2.177395909741907
0.013721157455923819,9.12e-05,15.1748535,434.22374620356436,-2.177395909741907
0.018294876607898428,0.0001216,20.233138,434.22374620356436,-2.177395909741907
0.020220653092940365,0.0001344,22.362941999999997,434.22374620356436,-2.177395909741907
0.025997982548066186,0.0001728,28.752354,434.22374620356436,-2.177395909741907
0.02864592521499885,0.0001904,31.6808345,434.22374620356436,-2.177395909741907
0.030692062730355914,0.000204,33.94375125,434.22374620356436,-2.177395909741907
0.03478433776107003,0.00023119999999999998,38.469584749999996,434.22374620356436,-2.177395909741907
0.040922750307141216,0.000272,45.258335,434.22374620356436,-2.177395909741907
0.044052137095334364,0.00029279999999999996,48.719266499999996,434.22374620356436,-2.177395909741907
0.04549646945911582,0.0003024,50.316619499999995,434.22374620356436,-2.177395909741907
0.047903690065418246,0.0003184,52.978874499999996,434.22374620356436,-2.177395909741907
0.051875604065817246,0.0003448,57.37159525,434.22374620356436,-2.177395909741907
0.05283849230833822,0.00035119999999999997,58.436497249999995,434.22374620356436,-2.177395909741907
0.053560658490228945,0.000356,59.235173749999994,434.22374620356436,-2.177395909741907
0.05572715703590113,0.0003704,61.63120325,434.22374620356436,-2.177395909741907
0.056569684248106974,0.000376,62.56299249999999,434.22374620356436,-2.177395909741907
0.059097265884724526,0.0003928,65.35836025,434.22374620356436,-2.177395909741907
0.06030087618787573,0.0004008,66.68948775,434.22374620356436,-2.177395909741907
0.0657171225520562,0.0004368,72.6795615,434.22374620356436,-2.177395909741907
0.06956867552214006,0.00046239999999999996,76.93916949999999,434.22374620356436,-2.177395909741907
0.06980939758277031,0.000464,77.205395,434.22374620356436,-2.177395909741907
0.0708926468556064,0.00047119999999999996,78.40340975,434.22374620356436,-2.177395909741907
0.0725777012800181,0.00048239999999999996,80.26698825,434.22374620356436,-2.177395909741907
0.07426275570442979,0.0004936,82.13056675,434.22374620356436,-2.177395909741907
0.0759478101288415,0.0005048,83.99414525,434.22374620356436,-2.177395909741907
0.07967900206861026,0.0005296,88.1206405,434.22374620356436,-2.177395909741907
0.08076225134144634,0.0005367999999999999,89.31865524999999,434.22374620356436,-2.177395909741907
0.08208622267491267,0.0005455999999999999,90.78289549999998,434.22374620356436,-2.177395909741907
0.08449344328121511,0.0005616,93.4451505,434.22374620356436,-2.177395909741907
0.08605813667531169,0.000572,95.17561625,434.22374620356436,-2.177395909741907
0.08810427419066873,0.0005855999999999999,97.43853299999999,434.22374620356436,-2.177395909741907
0.0901504117060258,0.0005991999999999999,99.70144975,434.22374620356436,-2.177395909741907
0.09087257788791651,0.0006039999999999999,100.50012625,434.22374620356436,-2.177395909741907
0.09219654922138286,0.0006127999999999999,101.96436649999998,434.22374620356436,-2.177395909741907
0.10002001619186575,0.0006648,110.61669525,434.22374620356436,-2.177395909741907
0.10278831988911354,0.0006832,113.67828850000001,434.22374620356436,-2.177395909741907
0.1049548184347857,0.0006975999999999999,116.07431799999999,434.22374620356436,-2.177395909741907
0.10615842873793693,0.0007056,117.4054455,434.22374620356436,-2.177395909741907
0.10856564934423935,0.0007216,120.0677005,434.22374620356436,-2.177395909741907
0.11097286995054176,0.0007375999999999999,122.72995549999999,434.22374620356436,-2.177395909741907
0.11205611922337787,0.0007448,123.92797025,434.22374620356436,-2.177395909741907
0.11313936849621395,0.000752,125.12598499999999,434.22374620356436,-2.177395909741907
0.11542622807220126,0.0007672,127.65512725,434.22374620356436,-2.177395909741907
0.11687056043598272,0.0007768,129.25248025,434.22374620356436,-2.177395909741907
0.1219257237092178,0.0008104,134.84321574999998,434.22374620356436,-2.177395909741907
0.12794377522497385,0.0008504,140.9833564341465,434.22374620356436,-2.177395909741907
0.13119352304348214,0.0008719999999999999,141.08884250782017,434.22374620356436,-2.177395909741907
0.13239713334663333,0.0008799999999999999,141.12765218025325,434.22374620356436,-2.177395909741907
0.13612832528640212,0.0009048,141.24709685761889,434.22374620356436,-2.177395909741907
0.13757265765018356,0.0009144,141.29298985495603,434.22374620356436,-2.177395909741907
0.13985951722617085,0.0009295999999999999,141.36527132363227,434.22374620356436,-2.177395909741907
0.14070204443837672,0.0009352,141.39178495849393,434.22374620356436,-2.177395909741907
0.14142421062026744,0.00094,141.41446168720174,434.22374620356436,-2.177395909741907
0.14359070916593963,0.0009544,141.48222244807155,434.22374620356436,-2.177395909741907
0.14948839965138055,0.0009935999999999999,141.6646917199103,434.22374620356436,-2.177395909741907
0.1506920099545318,0.0010016,141.70158297064503,434.22374620356436,-2.177395909741907
0.15177525922736787,0.0010088,141.73468695788966,434.22374620356436,-2.177395909741907
0.15394175777304003,0.0010232,141.80061978377418,434.22374620356436,-2.177395909741907
0.16128378062226245,0.001072,142.02141550090295,434.22374620356436,-2.177395909741907
0.16357064019824974,0.0010872,142.08938260784782,434.22374620356436,-2.177395909741907
0.16417244534982534,0.0010911999999999999,142.10720696683242,434.22374620356436,-2.177395909741907
0.16910724759274534,0.001124,142.25241775115046,434.22374620356436,-2.177395909741907
0.1693479696533756,0.0011256,142.2594586224508,434.22374620356436,-2.177395909741907
0.17043121892621166,0.0011328,142.2910943647803,434.22374620356436,-2.177395909741907
0.17211627335062338,0.001144,142.3401500944204,434.22374620356436,-2.177395909741907
0.17271807850219895,0.001148,142.35762455922642,434.22374620356436,-2.177395909741907
0.17368096674471992,0.0011543999999999999,142.38553439275165,434.22374620356436,-2.177395909741907
0.1769307145632282,0.001176,142.4792877244363,434.22374620356436,-2.177395909741907
0.17933793516953062,0.001192,142.54830223041824,434.22374620356436,-2.177395909741907
0.1804211844423667,0.0011991999999999999,142.57924079227345,434.22374620356436,-2.177395909741907
0.18306912710929937,0.0012167999999999999,142.65456497343555,434.22374620356436,-2.177395909741907
0.18511526462465644,0.0012304,142.7124793653907,434.22374620356436,-2.177395909741907
0.18631887492780766,0.0012384,142.74643003672492,434.22374620356436,-2.177395909741907
0.1881242903825345,0.0012504,142.79719610514434,434.22374620356436,-2.177395909741907
0.19005006686757642,0.0012632,142.8511375969977,434.22374620356436,-2.177395909741907
0.19197584335261836,0.001276,142.90486633549347,434.22374620356436,-2.177395909741907
0.19438306395892077,0.001292,142.97173257815564,434.22374620356436,-2.177395909741907
0.19991967135341637,0.0013288,143.12431124437862,434.22374620356436,-2.177395909741907
0.20208616989908854,0.0013432,143.1835662285571,434.22374620356436,-2.177395909741907
0.2024472529900339,0.0013456,143.1934179229205,434.22374620356436,-2.177395909741907
0.20437302947507582,0.0013583999999999998,143.2458450080971,434.22374620356436,-2.177395909741907
0.20894674862705045,0.0013888,143.36959314014118,434.22374620356436,-2.177395909741907
0.20930783171799583,0.0013912,143.37931750560585,434.22374620356436,-2.177395909741907
0.21002999789988652,0.0013959999999999999,143.3987466311032,434.22374620356436,-2.177395909741907
0.21123360820303774,0.0014039999999999999,143.43107070915926,434.22374620356436,-2.177395909741907
0.21219649644555874,0.0014104,143.4568782829639,434.22374620356436,-2.177395909741907
0.2138815508699704,0.0014215999999999999,143.50193190807752,434.22374620356436,-2.177395909741907
0.21749238177942407,0.0014456,143.59801187557784,434.22374620356436,-2.177395909741907
0.22254754505265914,0.0014792,143.73148518228334,434.22374620356436,-2.177395909741907
0.2262787369924279,0.001504,143.8292439548304,434.22374620356436,-2.177395909741907
0.23061173408377228,0.0015328,143.94198477095637,434.22374620356436,-2.177395909741907
0.23289859365975957,0.001548,144.0011536371971,434.22374620356436,-2.177395909741907
0.23518545323574686,0.0015631999999999998,144.0600963477476,434.22374620356436,-2.177395909741907
0.23602798044795273,0.0015688,144.08175568383928,434.22374620356436,-2.177395909741907
0.23711122972078882,0.001576,144.10955914683575,434.22374620356436,-2.177395909741907
0.2438514474184356,0.0016208,144.28145846753992,434.22374620356436,-2.177395909741907
0.24445325257001121,0.0016248,144.29671593578482,434.22374620356436,-2.177395909741907
0.2461383069944229,0.0016359999999999999,144.33935911092036,434.22374620356436,-2.177395909741907
0.24674011214599853,0.00164,144.35456120455848,434.22374620356436,-2.177395909741907
0.251193470267658,0.0016695999999999998,144.46661069180385,434.22374620356436,-2.177395909741907
0.2568504386924687,0.0017071999999999999,144.60783293303155,434.22374620356436,-2.177395909741907
0.25949838135940134,0.0017247999999999999,144.67351967666417,434.22374620356436,-2.177395909741907
0.26948834687555645,0.0017912,144.91901910733486,434.22374620356436,-2.177395909741907
0.271053040269653,0.0018016,144.95714695180342,434.22374620356436,-2.177395909741907
0.27189556748185884,0.0018072,144.97764177120655,434.22374620356436,-2.177395909741907
0.2721362895424891,0.0018088,144.98349288275213,434.22374620356436,-2.177395909741907
0.2756267594216276,0.0018319999999999999,145.06810845369193,434.22374620356436,-2.177395909741907
0.27863578517950566,0.001852,145.1407180415237,434.22374620356436,-2.177395909741907
0.283931670513371,0.0018872,145.26777250352242,434.22374620356436,-2.177395909741907
0.28682033524093387,0.0019064,145.336685257531,434.22374620356436,-2.177395909741907
0.2887461117259758,0.0019191999999999998,145.38247677679726,434.22374620356436,-2.177395909741907
0.29007008305944215,0.0019279999999999998,145.4138893773077,434.22374620356436,-2.177395909741907
0.2921162205747992,0.0019416,145.46232636158237,434.22374620356436,-2.177395909741907
0.2952456073629924,0.0019624,145.53615130028538,434.22374620356436,-2.177395909741907
0.2968103007570889,0.0019728,145.57294928455153,434.22374620356436,-2.177395909741907
0.30018040960591236,0.0019952,145.65195050340844,434.22374620356436,-2.177395909741907
0.3065595442126138,0.0020376,145.80054785151293,434.22374620356436,-2.177395909741907
0.3089667648189162,0.0020536,145.85630830246453,434.22374620356436,-2.177395909741907
0.309809292031122,0.0020591999999999997,145.87578439866604,434.22374620356436,-2.177395909741907
0.31149434645553375,0.0020704,145.9146747322216,434.22374620356436,-2.177395909741907
0.3158273435468781,0.0020992,146.0143035594005,434.22374620356436,-2.177395909741907
0.3173920369409747,0.0021096,146.0501494452952,434.22374620356436,-2.177395909741907
0.3193178134260166,0.0021224,146.09417298848066,434.22374620356436,-2.177395909741907
0.32076214578979806,0.0021319999999999998,146.12712272603545,434.22374620356436,-2.177395909741907
0.32172503403231906,0.0021384,146.14905707743688,434.22374620356436,-2.177395909741907
0.32232683918389465,0.0021424,146.16275304666362,434.22374620356436,-2.177395909741907
0.3255765870024029,0.0021639999999999997,146.2365396650114,434.22374620356436,-2.177395909741907
0.32629875318429363,0.0021688,146.25289761916403,434.22374620356436,-2.177395909741907
0.33039102821500776,0.002196,146.34532737453364,434.22374620356436,-2.177395909741907
0.3329186098516253,0.0022128,146.40219333358897,434.22374620356436,-2.177395909741907
0.33809413415517553,0.0022472,146.5181104726408,434.22374620356436,-2.177395909741907
0.3398995496099023,0.0022592,146.5583836039514,434.22374620356436,-2.177395909741907
0.34146424300399897,0.0022696,146.59321954866525,434.22374620356436,-2.177395909741907
0.3421864091858896,0.0022743999999999998,146.6092766743607,434.22374620356436,-2.177395909741907
0.34242713124651986,0.002276,146.61462611195057,434.22374620356436,-2.177395909741907
0.343510380519356,0.0022832,146.638680454698,434.22374620356436,-2.177395909741907
0.3462786842166038,0.0023016,146.70001864696835,434.22374620356436,-2.177395909741907
0.34736193348943983,0.0023087999999999997,146.72396845337911,434.22374620356436,-2.177395909741907
0.34880626585322133,0.0023184,146.7558562673596,434.22374620356436,-2.177395909741907
0.3496487930654272,0.002324,146.77443371125526,434.22374620356436,-2.177395909741907
0.3524170967626749,0.0023423999999999997,146.83535133288544,434.22374620356436,-2.177395909741907
0.3548243173689774,0.0023584,146.88817163940024,434.22374620356436,-2.177395909741907
0.3566297328237042,0.0023704,146.92769520354813,434.22374620356436,-2.177395909741907
0.3613238130059939,0.0024016,147.03009299116576,434.22374620356436,-2.177395909741907
0.3637310336122963,0.0024176,147.08240334484134,434.22374620356436,-2.177395909741907
0.36529572700639296,0.002428,147.1163326872938,434.22374620356436,-2.177395909741907
0.36661969833985925,0.0024368,147.14499788397998,434.22374620356436,-2.177395909741907
0.36722150349143484,0.0024408,147.15801416985764,434.22374620356436,-2.177395909741907
0.3737209991284514,0.002484,147.29806403166964,434.22374620356436,-2.177395909741907
0.376248580765069,0.0025008,147.35227093289492,434.22374620356436,-2.177395909741907
0.3785354403410563,0.002516,147.401193019562,434.22374620356436,-2.177395909741907
0.3799797727048377,0.0025256,147.43203179869596,434.22374620356436,-2.177395909741907
0.38166482712924943,0.0025368,147.46795265392075,434.22374620356436,-2.177395909741907
0.38310915949303087,0.0025464,147.498692758292,434.22374620356436,-2.177395909741907
0.38599782422059375,0.0025656,147.56003770935726,434.22374620356436,-2.177395909741907
0.3870810734934299,0.0025728,147.58299587371636,434.22374620356436,-2.177395909741907
0.3910529874938289,0.0025992,147.6669622865047,434.22374620356436,-2.177395909741907
0.3935805691304464,0.002616,147.720222325873,434.22374620356436,-2.177395909741907
0.3959877897367488,0.002632,147.77082229208511,434.22374620356436,-2.177395909741907
0.3982746493127361,0.0026471999999999997,147.8187812590668,434.22374620356436,-2.177395909741907
0.4005615088887234,0.0026623999999999997,147.86663294872443,434.22374620356436,-2.177395909741907
0.40080223094935363,0.0026639999999999997,147.8716637629998,434.22374620356436,-2.177395909741907
0.4010429530099839,0.0026655999999999997,147.8766933990241,434.22374620356436,-2.177395909741907
0.4036908956769166,0.0026831999999999997,147.9319419108418,434.22374620356436,-2.177395909741907
0.4053759501013283,0.0026944,147.96702648030694,434.22374620356436,-2.177395909741907
0.40706100452573996,0.0027056,148.0020542186506,434.22374620356436,-2.177395909741907
0.41031075234424824,0.0027272,148.06944842965956,434.22374620356436,-2.177395909741907
0.41127364058676924,0.0027336,148.08937706470465,434.22374620356436,-2.177395909741907
0.41356050016275653,0.0027488,148.1366347864652,434.22374620356436,-2.177395909741907
0.4160880817993741,0.0027656,148.18874859272955,434.22374620356436,-2.177395909741907
0.418013858284416,0.0027784,148.2283715233619,434.22374620356436,-2.177395909741907
0.41909710755725216,0.0027856,148.25062813545233,434.22374620356436,-2.177395909741907
0.42005999579977304,0.0027919999999999998,148.27039296279472,434.22374620356436,-2.177395909741907
0.4221061333151301,0.0028055999999999997,148.3123346489344,434.22374620356436,-2.177395909741907
0.42367082670922673,0.002816,148.34435422432938,434.22374620356436,-2.177395909741907
0.42667985246710477,0.002836,148.40580100284964,434.22374620356436,-2.177395909741907
0.42800382380057106,0.0028447999999999998,148.43278402147814,434.22374620356436,-2.177395909741907
0.43017032234624325,0.0028591999999999997,148.4768679411487,434.22374620356436,-2.177395909741907
0.4304110444068735,0.0028607999999999997,148.4817608035915,434.22374620356436,-2.177395909741907
0.43450331943758763,0.002888,148.56477686906484,434.22374620356436,-2.177395909741907
0.4367901790135749,0.0029032,148.6110353737688,434.22374620356436,-2.177395909741907
0.43787342828641107,0.0029104,148.63291432100647,434.22374620356436,-2.177395909741907
0.43979920477145296,0.0029232,148.6717581772323,434.22374620356436,-2.177395909741907
0.4432896746505915,0.0029464,148.74199401261745,434.22374620356436,-2.177395909741907
0.450752058530129,0.002996,148.89143397446415,434.22374620356436,-2.177395909741907
0.4535203622273768,0.0030144,148.9466256204062,434.22374620356436,-2.177395909741907
0.4548443335608431,0.0030231999999999998,148.9729751663495,434.22374620356436,-2.177395909741907
0.4582144424096665,0.0030456,149.03991211681657,434.22374620356436,-2.177395909741907
0.4620659953797504,0.0030712,149.11617683238634,434.22374620356436,-2.177395909741907
0.4642324939254226,0.0030856,149.15896677563993,434.22374620356436,-2.177395909741907
0.4661582704104645,0.0030984,149.19693694305025,434.22374620356436,-2.177395909741907
0.4685654910167669,0.0031144,149.24431373383578,434.22374620356436,-2.177395909741907
0.4695283792592879,0.0031208,149.26323786003542,434.22374620356436,-2.177395909741907
0.4768704021085103,0.0031696,149.40703992845752,434.22374620356436,-2.177395909741907
0.4798794278663883,0.0031896,149.46572543895158,434.22374620356436,-2.177395909741907
0.4810830381695395,0.0031975999999999997,149.48915943861434,434.22374620356436,-2.177395909741907
0.48336989774552686,0.0032128,149.53362114022246,434.22374620356436,-2.177395909741907
0.48601784041245955,0.0032304,149.58500075023986,434.22374620356436,-2.177395909741907
0.48734181174592583,0.0032392,149.6106496073879,434.22374620356436,-2.177395909741907
0.4909526426553795,0.0032632,149.68046328433834,434.22374620356436,-2.177395909741907
0.4928784191404214,0.003276,149.71761535206772,434.22374620356436,-2.177395909741907
0.49624852798924485,0.0032984,149.78249553373684,434.22374620356436,-2.177395909741907
0.49672997211050535,0.0033016,149.7917500841263,434.22374620356436,-2.177395909741907
0.5003408030199589,0.0033255999999999997,149.86104805177794,434.22374620356436,-2.177395909741907
0.5010629692018497,0.0033304,149.87488421056207,434.22374620356436,-2.177395909741907
0.5057570493841393,0.0033615999999999997,149.96463041804134,434.22374620356436,-2.177395909741907
0.5102104075057989,0.0033912,150.04947443472687,434.22374620356436,-2.177395909741907
0.5115343788392652,0.0034,150.0746425715782,434.22374620356436,-2.177395909741907
0.5138212384152525,0.0034151999999999997,150.11805505183705,434.22374620356436,-2.177395909741907
0.5155062928396642,0.0034264,150.14999499247796,434.22374620356436,-2.177395909741907
0.518274596536912,0.0034448,150.20237950009178,434.22374620356436,-2.177395909741907
0.5189967627188027,0.0034495999999999997,150.21602706291682,434.22374620356436,-2.177395909741907
0.5227279546585715,0.0034744,150.28642183430506,434.22374620356436,-2.177395909741907
0.5236908429010925,0.0034808,150.30455638191646,434.22374620356436,-2.177395909741907
0.5248944532042437,0.0034888,150.32720629018516,434.22374620356436,-2.177395909741907
0.5256166193861344,0.0034936,150.34078651267086,434.22374620356436,-2.177395909741907
0.5293478113259031,0.0035183999999999997,150.41083540939613,434.22374620356436,-2.177395909741907
0.53115322678063,0.0035304,150.4446608847182,434.22374620356436,-2.177395909741907
0.5346436966597684,0.0035535999999999996,150.5099299272763,434.22374620356436,-2.177395909741907
0.5362083900538651,0.003564,150.5391344961585,434.22374620356436,-2.177395909741907
0.5383748885995372,0.0035784,150.57951678190892,434.22374620356436,-2.177395909741907
0.5427078856908816,0.0036071999999999996,150.6600917245701,434.22374620356436,-2.177395909741907
0.5482444930853771,0.0036439999999999997,150.76268442144374,434.22374620356436,-2.177395909741907
0.548966659267268,0.0036488,150.7760362254232,434.22374620356436,-2.177395909741907
0.5502906306007342,0.0036576,150.8004967551135,434.22374620356436,-2.177395909741907
0.5526978512070367,0.0036736,150.84491172428173,434.22374620356436,-2.177395909741907
0.5576326534499566,0.0037064,150.93572725168877,434.22374620356436,-2.177395909741907
0.5588362637531078,0.0037143999999999996,150.9578297680551,434.22374620356436,-2.177395909741907
0.5591973468440532,0.0037167999999999997,150.964456901674,434.22374620356436,-2.177395909741907
0.5614842064200405,0.0037319999999999996,151.00639005873393,434.22374620356436,-2.177395909741907
0.5660579255720152,0.0037624,151.09005708282345,434.22374620356436,-2.177395909741907
0.5718352550271409,0.0038008,151.19536585020887,434.22374620356436,-2.177395909741907
0.5731592263606072,0.0038096,151.21944057203365,434.22374620356436,-2.177395909741907
0.5753257249062794,0.0038239999999999997,151.25878884158118,434.22374620356436,-2.177395909741907
0.5791772778763633,0.0038496,151.32859893232086,434.22374620356436,-2.177395909741907
0.5833899139373926,0.0038775999999999997,151.40474673548275,434.22374620356436,-2.177395909741907
0.5884450772106277,0.0039112,151.49584161462477,434.22374620356436,-2.177395909741907
0.588685799271258,0.0039128,151.5001718370794,434.22374620356436,-2.177395909741907
0.5892876044228336,0.0039168,151.51099437307494,434.22374620356436,-2.177395909741907
0.5949445728476441,0.003954399999999999,151.6125163912299,434.22374620356436,-2.177395909741907
0.5973517934539466,0.0039704,151.65560298610092,434.22374620356436,-2.177395909741907
0.60072190230277,0.0039927999999999995,151.71581062932128,434.22374620356436,-2.177395909741907
0.6018051515756062,0.004,151.73513509128773,434.22374620356436,-2.177395909741907
0.6133621218799187,0.004076815363072615,151.94046652907724,434.22374620356436,-2.177395909741907
0.6278083347603093,0.004172834566913383,152.19502117952132,434.22374620356436,-2.177395909741907
0.6624792456732468,0.0044032806561312265,152.7968068138027,434.22374620356436,-2.177395909741907
0.7202640971948093,0.004787357471494299,153.77316534003774,434.22374620356436,-2.177395909741907
0.7780489487163719,0.005171434286857372,154.71940983019806,434.22374620356436,-2.177395909741907
0.7982736467489188,0.0053058611722344474,155.04406541879692,434.22374620356436,-2.177395909741907
0.8473907705422468,0.005632326465293058,155.8194385734313,434.22374620356436,-2.177395909741907
0.8647262259987155,0.00574754950990198,156.088887963581,434.22374620356436,-2.177395909741907
0.8791724388791061,0.0058435687137427484,156.31182354247676,434.22374620356436,-2.177395909741907
0.9254003200963562,0.006150830166033207,157.01580252983777,434.22374620356436,-2.177395909741907
1.0120775973787,0.006726945389077816,158.2998393569128,434.22374620356436,-2.177395909741907
1.0669732063241841,0.007091818363672734,159.0909068656168,434.22374620356436,-2.177395909741907
1.1160903301175125,0.007418283656731346,159.78534390094117,434.22374620356436,-2.177395909741907
1.15076124103045,0.0076487297459491895,160.268375336888,434.22374620356436,-2.177395909741907
1.1594289687586843,0.00770634126825365,160.388242205961,434.22374620356436,-2.177395909741907
1.2172138202802467,0.008090418083616723,161.1786063756836,434.22374620356436,-2.177395909741907
1.2952233698343563,0.008608921784356871,162.22276010816515,434.22374620356436,-2.177395909741907
1.3472297362037624,0.008954590918183637,162.90526353490364,434.22374620356436,-2.177395909741907
1.4743564095512,0.009799559911982397,164.53171072858834,434.22374620356436,-2.177395909741907
1.5090273204641376,0.01003000600120024,164.96567099075708,434.22374620356436,-2.177395909741907
1.5610336868335435,0.010375675135027004,165.60939010746134,434.22374620356436,-2.177395909741907
1.633264751235497,0.010855771154230847,166.48973653879324,434.22374620356436,-2.177395909741907
1.7170527859417624,0.0114126825365073,167.49213176426758,434.22374620356436,-2.177395909741907
1.8557364295935124,0.012334466893378675,169.11031418992945,434.22374620356436,-2.177395909741907
1.867293399897825,0.01241128225645129,169.2429957902533,434.22374620356436,-2.177395909741907
1.9048535533868405,0.012660932186437287,169.67201591054143,434.22374620356436,-2.177395909741907
1.9279674939954656,0.012814562912582516,169.9343889190514,434.22374620356436,-2.177395909741907
2.005977043549575,0.013333066613322665,170.81097820433735,434.22374620356436,-2.177395909741907
2.0666511376472156,0.013736347269453891,171.48360911295956,434.22374620356436,-2.177395909741907
2.1071005337123094,0.014005201040208042,171.92775568822626,434.22374620356436,-2.177395909741907
2.16777462780995,0.014408481696339268,172.58779078946918,434.22374620356436,-2.177395909741907
2.211113266451122,0.014696539307861573,173.05484058162926,434.22374620356436,-2.177395909741907
2.237116449635825,0.014869373874774956,173.33335700690378,434.22374620356436,-2.177395909741907
2.2891228160052313,0.015215043008601721,173.88663071193636,434.22374620356436,-2.177395909741907
2.3151259991899344,0.015387877575515104,174.16142759837248,434.22374620356436,-2.177395909741907
2.4278064596569813,0.016136827365473096,175.33856843093372,434.22374620356436,-2.177395909741907
2.4595881279938405,0.016348069613922784,175.66670461994826,434.22374620356436,-2.177395909741907
2.517372979515403,0.016732146429285857,176.25911028359153,434.22374620356436,-2.177395909741907
2.5375976775479496,0.01686657331466293,176.46519622751705,434.22374620356436,-2.177395909741907
2.624274954830294,0.017442688537707543,177.34126349022395,434.22374620356436,-2.177395909741907
2.656056623167153,0.01765393078615723,177.65965114024868,434.22374620356436,-2.177395909741907
2.670502836047544,0.017749949989998,177.80388127918013,434.22374620356436,-2.177395909741907
2.713841474688716,0.018038007601520304,178.2347569502386,434.22374620356436,-2.177395909741907
2.7802940539385124,0.018479695939187836,178.89025710088606,434.22374620356436,-2.177395909741907
2.8496358757643874,0.018940588117623523,179.56777535599866,434.22374620356436,-2.177395909741907
2.9189776975902624,0.01940148029605921,180.2388935613082,434.22374620356436,-2.177395909741907
3.0114334600247625,0.020016003200640127,181.1241241560826,434.22374620356436,-2.177395909741907
3.028768915481231,0.02013122624524905,181.28891818265183,434.22374620356436,-2.177395909741907
3.1732310442851372,0.02109141828365673,182.64818240039287,434.22374620356436,-2.177395909741907
3.202123470045919,0.021283456691338267,182.9171153940459,434.22374620356436,-2.177395909741907
3.2396836235349347,0.021533106621324266,183.26531770584538,434.22374620356436,-2.177395909741907
3.297468475056497,0.02191718343668734,183.79795489325278,434.22374620356436,-2.177395909741907
3.3841457523388407,0.022493298659731948,184.59013528101408,434.22374620356436,-2.177395909741907
3.4130381780996224,0.022685337067413484,184.8524317010929,434.22374620356436,-2.177395909741907
3.436152118708247,0.022838967793558713,185.06164587597016,434.22374620356436,-2.177395909741907
3.522829395990591,0.023415083016603323,185.8413583800584,434.22374620356436,-2.177395909741907
3.6557345544901843,0.024298459691938386,187.02253978785853,434.22374620356436,-2.177395909741907
3.7308548614682158,0.02479775955191038,187.6827530363108,434.22374620356436,-2.177395909741907
3.762636529805075,0.025009001800360073,187.96051100081178,434.22374620356436,-2.177395909741907
3.7944181981419343,0.02522024404880976,188.23735546945122,434.22374620356436,-2.177395909741907
3.820421381326638,0.025393078615723146,188.4631925463831,434.22374620356436,-2.177395909741907
3.8522030496634967,0.025604320864172834,188.73840317005633,434.22374620356436,-2.177395909741907
3.889763203152513,0.025853970794158833,189.06251303650197,434.22374620356436,-2.177395909741907
4.028446846804263,0.026775755151030207,190.24879714096642,434.22374620356436,-2.177395909741907
4.135348822119154,0.02748629725945189,191.1523852275161,434.22374620356436,-2.177395909741907
4.204690643945028,0.027947189437887578,191.73362907093139,434.22374620356436,-2.177395909741907
4.256697010314435,0.028292858571714343,192.16711174043118,434.22374620356436,-2.177395909741907
4.395380653966185,0.029214642928585718,193.313084602027,434.22374620356436,-2.177395909741907
4.461833233215981,0.02965633126625325,193.85719138005834,434.22374620356436,-2.177395909741907
4.487836416400684,0.029829165833166634,194.06924128474967,434.22374620356436,-2.177395909741907
4.508061114433231,0.029963592718543708,194.2338378833392,434.22374620356436,-2.177395909741907
4.55717823822656,0.03029005801160232,194.63237807812212,434.22374620356436,-2.177395909741907
4.701640367030466,0.03125025005001,195.7949581004901,434.22374620356436,-2.177395909741907
4.759425218552028,0.031634326865373076,196.25607900554473,434.22374620356436,-2.177395909741907
4.8114315849214355,0.031979995999199845,196.66922430629333,434.22374620356436,-2.177395909741907
4.967450684029654,0.03301700340068014,197.89833480123693,434.22374620356436,-2.177395909741907
4.990564624638279,0.03317063412682537,198.07913661515883,434.22374620356436,-2.177395909741907
5.074352659344544,0.03372754550910182,198.73182323268094,434.22374620356436,-2.177395909741907
5.218814788148451,0.034687737547509506,199.84735921151446,434.22374620356436,-2.177395909741907
5.224593273300607,0.03472614522904581,199.89172840187467,434.22374620356436,-2.177395909741907
5.302602822854716,0.03524464892978596,200.4888515861465,434.22374620356436,-2.177395909741907
5.325716763463341,0.03539827965593119,200.66511774862064,434.22374620356436,-2.177395909741907
5.409504798169607,0.03595519103820764,201.3015967299251,434.22374620356436,-2.177395909741907
5.473068134843326,0.036377675535107026,201.7818813433116,434.22374620356436,-2.177395909741907
5.533742228940966,0.03678095619123825,202.23830955597504,434.22374620356436,-2.177395909741907
5.600194808190762,0.03722264452890578,202.73597351465713,434.22374620356436,-2.177395909741907
5.6261979913754665,0.03739547909581917,202.9300840027634,434.22374620356436,-2.177395909741907
5.657979659712326,0.03760672134426886,203.16685565376324,434.22374620356436,-2.177395909741907
5.675315115168793,0.03772194438887777,203.29578518479514,434.22374620356436,-2.177395909741907
5.701318298353497,0.03789477895579116,203.48889187456413,434.22374620356436,-2.177395909741907
5.733099966690356,0.03810602120424085,203.7244453259977,434.22374620356436,-2.177395909741907
5.747546179570747,0.03820204040808162,203.83134667115363,434.22374620356436,-2.177395909741907
5.779327847907607,0.03841328265653131,204.06616146393335,434.22374620356436,-2.177395909741907
5.808220273668388,0.03860532106421284,204.27919281023156,434.22374620356436,-2.177395909741907
5.822666486548778,0.03870134026805361,204.38555347302758,434.22374620356436,-2.177395909741907
5.923789976711513,0.03937347469493899,205.127217550925,434.22374620356436,-2.177395909741907
5.981574828233076,0.03975755151030207,205.54880845948531,434.22374620356436,-2.177395909741907
5.996021041113466,0.03985357071414283,205.65395763423712,434.22374620356436,-2.177395909741907
6.045138164906794,0.040180036007201436,206.01072811257302,434.22374620356436,-2.177395909741907
6.076919833243653,0.04039127825565113,206.24097732229689,434.22374620356436,-2.177395909741907
6.1635971105259975,0.04096739347869574,206.86655506543536,434.22374620356436,-2.177395909741907
6.247385145232263,0.041524304860972194,207.46802698809233,434.22374620356436,-2.177395909741907
6.305169996753826,0.041908381676335274,207.8810034186573,434.22374620356436,-2.177395909741907
6.365844090851467,0.0423116623324665,208.313043193925,434.22374620356436,-2.177395909741907
6.371622576003622,0.0423500700140028,208.35410590156403,434.22374620356436,-2.177395909741907
6.536309402840074,0.04344468893778755,209.51835823115547,434.22374620356436,-2.177395909741907
6.5883157692094825,0.04379035807161433,209.88363260037457,434.22374620356436,-2.177395909741907
6.666325318763592,0.04430886177235448,210.42944272439715,434.22374620356436,-2.177395909741907
6.700996229676528,0.044539307861572314,210.67122483745166,434.22374620356436,-2.177395909741907
6.767448808926324,0.04498099619923984,211.1332812004469,434.22374620356436,-2.177395909741907
6.900353967425919,0.04586437287457491,212.05211935425407,434.22374620356436,-2.177395909741907
7.007255942740809,0.046574914982996596,212.78618608244733,434.22374620356436,-2.177395909741907
7.044816096229825,0.04682456491298259,213.04306287043212,434.22374620356436,-2.177395909741907
7.111268675479622,0.047266253250650134,213.49623254851187,434.22374620356436,-2.177395909741907
7.200835195338044,0.04786157231446289,214.1044219481815,434.22374620356436,-2.177395909741907
7.238395348827059,0.04811122224444889,214.35859026382985,434.22374620356436,-2.177395909741907
7.264398532011763,0.048284056811362275,214.53425171058365,434.22374620356436,-2.177395909741907
7.307737170652934,0.048572114422884574,214.82647681887744,434.22374620356436,-2.177395909741907
7.322183383533325,0.04866813362672534,214.92373488907268,434.22374620356436,-2.177395909741907
7.345297324141949,0.04882176435287057,215.07919228990826,434.22374620356436,-2.177395909741907
7.417528388543904,0.049301860372074416,215.56377154583868,434.22374620356436,-2.177395909741907
7.466645512337233,0.04962832566513303,215.89223471183973,434.22374620356436,-2.177395909741907
7.49842718067409,0.04983956791358271,216.10432075564106,434.22374620356436,-2.177395909741907
7.553322789619575,0.05020444088817763,216.4698273085089,434.22374620356436,-2.177395909741907
7.642889309477998,0.0507997599519904,217.06396382374967,434.22374620356436,-2.177395909741907
7.784462195705824,0.05174074814962992,217.99757431025859,434.22374620356436,-2.177395909741907
7.859582502683858,0.05224004800960193,218.49026924425277,434.22374620356436,-2.177395909741907
7.905810383901108,0.052547309461892386,218.79255342601544,434.22374620356436,-2.177395909741907
7.9578167502705135,0.05289297859571915,219.13180035678053,434.22374620356436,-2.177395909741907
7.97804144830306,0.05302740548109622,219.26349607283032,434.22374620356436,-2.177395909741907
8.02426932952031,0.053334666933386676,219.56402690211007,434.22374620356436,-2.177395909741907
8.108057364226575,0.05389157831566313,220.107023609327,434.22374620356436,-2.177395909741907
8.258297978182638,0.054890178035607126,221.07522422048098,434.22374620356436,-2.177395909741907
8.26985494848695,0.054966993398679734,221.1494154378999,434.22374620356436,-2.177395909741907
8.278522676215184,0.055024604920984196,221.2050323180713,434.22374620356436,-2.177395909741907
8.342086012888904,0.05544708941788358,221.61219777562079,434.22374620356436,-2.177395909741907
8.394092379258309,0.05579275855171034,221.94443393768387,434.22374620356436,-2.177395909741907
8.446098745627715,0.056138427685537104,222.27586828690403,434.22374620356436,-2.177395909741907
8.492326626844966,0.05644568913782756,222.569809013975,434.22374620356436,-2.177395909741907
8.642567240801029,0.05744428885777156,223.5208354292469,434.22374620356436,-2.177395909741907
8.688795122018279,0.057751550310062016,223.8121589035327,434.22374620356436,-2.177395909741907
8.82458952309395,0.05865413082616523,224.66444588801937,434.22374620356436,-2.177395909741907
8.859260434006888,0.05888457691538308,224.88122948067368,434.22374620356436,-2.177395909741907
8.977719379626091,0.05967193438687737,225.61942302877873,434.22374620356436,-2.177395909741907
9.009501047962951,0.059883176635327065,225.81682741504113,434.22374620356436,-2.177395909741907
9.038393473723731,0.0600752150430086,225.99605040617104,434.22374620356436,-2.177395909741907
9.061507414332356,0.06022884576915383,226.13926797827583,434.22374620356436,-2.177395909741907
9.078842869788826,0.06034406881376275,226.2465876778312,434.22374620356436,-2.177395909741907
9.127959993582154,0.06067053410682137,226.55022701921328,434.22374620356436,-2.177395909741907
9.214637270864497,0.06124664932986597,227.0845112788757,434.22374620356436,-2.177395909741907
9.298425305570763,0.061803560712142436,227.5991260521436,434.22374620356436,-2.177395909741907
9.353320914516246,0.06216843368673734,227.93530716428825,434.22374620356436,-2.177395909741907
9.38221334027703,0.06236047209441889,228.1119354664303,434.22374620356436,-2.177395909741907
9.422662736342122,0.06262932586517303,228.3588591257909,434.22374620356436,-2.177395909741907
9.45733364725506,0.06285977195439088,228.57017912848906,434.22374620356436,-2.177395909741907
9.48622607301584,0.06305181036207241,228.74604843190974,434.22374620356436,-2.177395909741907
9.564235622569951,0.06357031406281256,229.2198551866021,434.22374620356436,-2.177395909741907
9.743368662286795,0.06476095219043809,230.30218835623376,434.22374620356436,-2.177395909741907
9.789596543504045,0.06506821364272855,230.58023687539867,434.22374620356436,-2.177395909741907
9.821378211840905,0.06527945589117824,230.7710982646194,434.22374620356436,-2.177395909741907
9.867606093058155,0.0655867173434687,231.04828540611575,434.22374620356436,-2.177395909741907
9.887830791090702,0.06572114422884577,231.16939547886332,434.22374620356436,-2.177395909741907
9.922501702003638,0.06595159031806361,231.3767882195501,434.22374620356436,-2.177395909741907
9.928280187155796,0.06598999799959993,231.4113261810432,434.22374620356436,-2.177395909741907
9.945615642612262,0.06610522104420884,231.51489305779853,434.22374620356436,-2.177395909741907
9.9802865535252,0.06633566713342669,231.7218158451309,434.22374620356436,-2.177395909741907
10.147862622937732,0.0674494898979796,232.71801733669028,434.22374620356436,-2.177395909741907
10.283657024013404,0.06835207041408282,233.52058619305075,434.22374620356436,-2.177395909741907
10.329884905230655,0.06865933186637328,233.7928567192216,434.22374620356436,-2.177395909741907
10.410783697360841,0.06919703940788158,234.26818945817737,434.22374620356436,-2.177395909741907
10.503239459795342,0.0698115623124625,234.80966651545143,434.22374620356436,-2.177395909741907
10.61303067768631,0.07054130826165234,235.4502620671701,434.22374620356436,-2.177395909741907
10.699707954968655,0.07111742348469695,235.95417158981925,434.22374620356436,-2.177395909741907
10.734378865881592,0.07134786957391479,236.15528932846334,434.22374620356436,-2.177395909741907
10.80083144513139,0.07178955791158233,236.54005828600256,434.22374620356436,-2.177395909741907
10.8123884154357,0.07186637327465493,236.6068802723867,434.22374620356436,-2.177395909741907
10.85861629665295,0.0721736347269454,236.87389013657784,434.22374620356436,-2.177395909741907
10.919290390750591,0.07257691538307662,237.2236687730333,434.22374620356436,-2.177395909741907
10.942404331359217,0.07273054610922185,237.35671829292474,434.22374620356436,-2.177395909741907
11.101312673043513,0.07378675735147029,238.2684847668309,434.22374620356436,-2.177395909741907
11.130205098804295,0.07397879575915184,238.43371217289211,434.22374620356436,-2.177395909741907
11.196657678054091,0.07442048409681937,238.81310171224445,434.22374620356436,-2.177395909741907
11.263110257303888,0.0748621724344869,239.19161410149496,434.22374620356436,-2.177395909741907
11.294891925640748,0.07507341468293659,239.3723337979615,434.22374620356436,-2.177395909741907
11.303559653368982,0.07513102620524105,239.42158655509863,434.22374620356436,-2.177395909741907
11.33823056428192,0.0753614722944589,239.61845046829498,434.22374620356436,-2.177395909741907
11.410461628683873,0.07584156831366273,240.02783117150983,434.22374620356436,-2.177395909741907
11.439354054444655,0.07603360672134428,240.19130031311317,434.22374620356436,-2.177395909741907
11.479803450509747,0.07630246049209842,240.41988685498882,434.22374620356436,-2.177395909741907
11.505806633694451,0.07647529505901181,240.56666948963763,434.22374620356436,-2.177395909741907
11.635822549617966,0.07733946789357872,241.2986509685388,434.22374620356436,-2.177395909741907
11.667604217954826,0.07755071014202841,241.47709376200984,434.22374620356436,-2.177395909741907
11.69071815856345,0.07770434086817364,241.60675129546408,434.22374620356436,-2.177395909741907
11.728278312052467,0.07795399079815964,241.81723176137865,434.22374620356436,-2.177395909741907
11.820734074486968,0.07856851370274055,242.33422064356148,434.22374620356436,-2.177395909741907
11.875629683432452,0.07893338667733547,242.64043667113376,434.22374620356436,-2.177395909741907
11.89296513888892,0.0790486097219444,242.73702171384596,434.22374620356436,-2.177395909741907
11.965196203290873,0.07952870574114823,243.1388698167458,434.22374620356436,-2.177395909741907
12.043205752844983,0.08004720944188838,243.57180460264655,434.22374620356436,-2.177395909741907
12.069208936029685,0.08022004400880177,243.71587297621096,434.22374620356436,-2.177395909741907
12.135661515279482,0.0806617323464693,244.0834988139706,434.22374620356436,-2.177395909741907
12.158775455888108,0.08081536307261453,244.211184533536,434.22374620356436,-2.177395909741907
12.179000153920654,0.0809497899579916,244.32283190316298,434.22374620356436,-2.177395909741907
12.326351525300637,0.08192918583716743,245.13409141392145,434.22374620356436,-2.177395909741907
12.369690163941812,0.08221724344868975,245.37197621027448,434.22374620356436,-2.177395909741907
12.427475015463372,0.08260132026405281,245.68865092495972,434.22374620356436,-2.177395909741907
12.456367441224154,0.08279335867173435,245.84677289731036,434.22374620356436,-2.177395909741907
12.491038352137092,0.0830238047609522,246.03633058050988,434.22374620356436,-2.177395909741907
12.548823203658653,0.08340788157631526,246.35180469307963,434.22374620356436,-2.177395909741907
12.641278966093154,0.08402240448089618,246.85538739938153,434.22374620356436,-2.177395909741907
12.684617604734328,0.08431046209241849,247.0909471378734,434.22374620356436,-2.177395909741907
12.800187307777453,0.08507861572314464,247.7175769588452,434.22374620356436,-2.177395909741907
12.823301248386077,0.08523224644928987,247.8426377211048,434.22374620356436,-2.177395909741907
12.834858218690389,0.08530906181236247,247.90513513215828,434.22374620356436,-2.177395909741907
12.857972159299013,0.0854626925385077,248.0300641515832,434.22374620356436,-2.177395909741907
12.933092466277044,0.0859619923984797,248.43547992203656,434.22374620356436,-2.177395909741907
13.068886867352717,0.08686457291458292,249.16602396128133,434.22374620356436,-2.177395909741907
13.170010357515451,0.0875367073414683,249.70812448193956,434.22374620356436,-2.177395909741907
13.227795209037014,0.08792078415683137,250.01716733496343,434.22374620356436,-2.177395909741907
13.265355362526028,0.08817043408681736,250.21776288614012,434.22374620356436,-2.177395909741907
13.311583243743279,0.08847769553910782,250.46434589206595,434.22374620356436,-2.177395909741907
13.360700367536609,0.08880416083216644,250.72597469197112,434.22374620356436,-2.177395909741907
13.484937798307968,0.08962992598519705,251.38607283829674,434.22374620356436,-2.177395909741907
13.632289169687953,0.09060932186437289,252.1659130938889,434.22374620356436,-2.177395909741907
13.675627808329123,0.09089737947589518,252.39465134008492,434.22374620356436,-2.177395909741907
13.707409476665983,0.09110862172434488,252.56221308718165,434.22374620356436,-2.177395909741907
13.733412659850686,0.09128145629125825,252.69919639247195,434.22374620356436,-2.177395909741907
13.814311451980874,0.09181916383276656,253.12472122538355,434.22374620356436,-2.177395909741907
13.874985546078515,0.09222244448889778,253.4432273613956,434.22374620356436,-2.177395909741907
13.921213427295763,0.09252970594118824,253.6855342457721,434.22374620356436,-2.177395909741907
13.967441308513013,0.0928369673934787,253.92752752945026,434.22374620356436,-2.177395909741907
14.007890704578108,0.09310582116423285,254.1390155358094,434.22374620356436,-2.177395909741907
14.12634965019731,0.09389317863572715,254.75700745989204,434.22374620356436,-2.177395909741907
14.1407958630777,0.09398919783956791,254.8322338159326,434.22374620356436,-2.177395909741907
14.259254808696904,0.09477655531106222,255.44796345201402,434.22374620356436,-2.177395909741907
14.3257073879467,0.09521824364872974,255.7924992464802,434.22374620356436,-2.177395909741907
14.337264358251014,0.09529505901180237,255.85235483378366,434.22374620356436,-2.177395909741907
14.37193526916395,0.0955255051010202,256.0318087965004,434.22374620356436,-2.177395909741907
14.397938452348654,0.09569833966793359,256.16628849031235,434.22374620356436,-2.177395909741907
14.470169516750609,0.09617843568713744,256.53934711256346,434.22374620356436,-2.177395909741907
14.516397397967859,0.0964856971394279,256.77772354202517,434.22374620356436,-2.177395909741907
14.623299373282748,0.09719623924784958,257.32783800619063,434.22374620356436,-2.177395909741907
14.65219179904353,0.09738827765553111,257.4762480785609,434.22374620356436,-2.177395909741907
14.66663801192392,0.09748429685937188,257.5504103119392,434.22374620356436,-2.177395909741907
14.730201348597639,0.09790678135627126,257.8763862830659,434.22374620356436,-2.177395909741907
14.753315289206265,0.09806041208241649,257.99478692682715,434.22374620356436,-2.177395909741907
14.88333120512978,0.0989245849169834,258.65944748573474,434.22374620356436,-2.177395909741907
15.033571819085841,0.09992318463692738,259.4246859983941,434.22374620356436,-2.177395909741907
15.042239546814075,0.09998079615923185,259.46874315485013,434.22374620356436,-2.177395909741907