File: datasets/aisi_316_L/data/M1/valid_18.csv
Time(s),Strain(%),Stress(MPa),Temp(C),Log_SR(s-1)
0.0,0.0,0.0,213.93065029396695,5.409982541036847
6.53622119160532e-11,1.68e-05,3.1046318625,213.93065029396695,5.409982541036847
1.0271204729665503e-10,2.6399999999999998e-05,4.878707212499999,213.93065029396695,5.409982541036847
1.8052420433957551e-10,4.6399999999999996e-05,8.574697525,213.93065029396695,5.409982541036847
2.5833636138249604e-10,6.64e-05,12.2706878375,213.93065029396695,5.409982541036847
2.92573710481381e-10,7.52e-05,13.896923574999999,213.93065029396695,5.409982541036847
4.544229971306556e-10,0.00011679999999999999,21.584583424999998,213.93065029396695,5.409982541036847
5.944848798079126e-10,0.0001528,28.2373659875,213.93065029396695,5.409982541036847
6.19384770061647e-10,0.0001592,29.420082887499998,213.93065029396695,5.409982541036847
6.660720642873993e-10,0.0001712,31.637677075,213.93065029396695,5.409982541036847
7.345467624851693e-10,0.00018879999999999998,34.89014855,213.93065029396695,5.409982541036847
7.905715155560721e-10,0.00020319999999999998,37.551261575,213.93065029396695,5.409982541036847
8.061339469646562e-10,0.0002072,38.2904596375,213.93065029396695,5.409982541036847
8.62158700035559e-10,0.0002216,40.9515726625,213.93065029396695,5.409982541036847
9.244084256698954e-10,0.0002376,43.9083649125,213.93065029396695,5.409982541036847
9.337458845150457e-10,0.00023999999999999998,44.35188375,213.93065029396695,5.409982541036847
1.0706952809105857e-09,0.00027519999999999997,50.85682669999999,213.93065029396695,5.409982541036847
1.1391699791083558e-09,0.00029279999999999996,54.10929817499999,213.93065029396695,5.409982541036847
1.2200946224329931e-09,0.0003136,57.953128099999994,213.93065029396695,5.409982541036847
1.2356570538415773e-09,0.00031759999999999997,58.692326162499995,213.93065029396695,5.409982541036847
1.375718936518834e-09,0.0003536,65.34510872499999,213.93065029396695,5.409982541036847
1.397506340490852e-09,0.0003592,66.3799860125,213.93065029396695,5.409982541036847
1.431743689589737e-09,0.000368,68.00622175,213.93065029396695,5.409982541036847
1.4566435798434714e-09,0.0003744,69.18893865,213.93065029396695,5.409982541036847
1.5033308740692236e-09,0.00038639999999999996,71.4065328375,213.93065029396695,5.409982541036847
1.531343250604675e-09,0.00039359999999999997,72.73708934999999,213.93065029396695,5.409982541036847
1.6122678939293124e-09,0.0004144,76.580919275,213.93065029396695,5.409982541036847
1.6589551881550645e-09,0.00042639999999999996,78.7985134625,213.93065029396695,5.409982541036847
1.7305423726345515e-09,0.00044479999999999997,82.19882455,213.93065029396695,5.409982541036847
1.845704365058074e-09,0.0004744,87.6688902125,213.93065029396695,5.409982541036847
1.895504145565543e-09,0.00048719999999999997,90.0343240125,213.93065029396695,5.409982541036847
1.963978843763313e-09,0.0005048,93.2867954875,213.93065029396695,5.409982541036847
2.097815753877136e-09,0.0005392,99.643898825,213.93065029396695,5.409982541036847
2.222315205145809e-09,0.0005712,105.557483325,213.93065029396695,5.409982541036847
2.234765150272676e-09,0.0005744,106.148841775,213.93065029396695,5.409982541036847
2.290789903343579e-09,0.0005888,108.8099548,213.93065029396695,5.409982541036847
2.340589683851048e-09,0.0006016,111.17538859999999,213.93065029396695,5.409982541036847
2.4339642723025523e-09,0.0006255999999999999,115.61057697499999,213.93065029396695,5.409982541036847
2.449526703711137e-09,0.0006296,116.34977503750001,213.93065029396695,5.409982541036847
2.480651566528305e-09,0.0006376,117.8281711625,213.93065029396695,5.409982541036847
2.5615762098529422e-09,0.0006584,121.67200108749999,213.93065029396695,5.409982541036847
2.654950798304447e-09,0.0006824,126.1071894625,213.93065029396695,5.409982541036847
2.6954131199667653e-09,0.0006927999999999999,128.02910442499999,213.93065029396695,5.409982541036847
2.738987927910801e-09,0.000704,130.098859,213.93065029396695,5.409982541036847
2.785675222136553e-09,0.000716,132.3164531875,213.93065029396695,5.409982541036847
2.860374892897757e-09,0.0007352,135.8646038875,213.93065029396695,5.409982541036847
2.931962077377244e-09,0.0007536,139.264914975,213.93065029396695,5.409982541036847
2.963086940194412e-09,0.0007616,140.7433111,213.93065029396695,5.409982541036847
3.0564615286459165e-09,0.0007856,145.178499475,213.93065029396695,5.409982541036847
3.13116119940712e-09,0.0008047999999999999,148.72665017499997,213.93065029396695,5.409982541036847
3.168511034787722e-09,0.0008144,150.50072552499998,213.93065029396695,5.409982541036847
3.184073466196306e-09,0.0008183999999999999,151.2399235875,213.93065029396695,5.409982541036847
3.249435678112359e-09,0.0008351999999999999,154.34455544999997,213.93065029396695,5.409982541036847
3.289897999774678e-09,0.0008456,156.26647041249998,213.93065029396695,5.409982541036847
3.3272478351552796e-09,0.0008552,158.0405457625,213.93065029396695,5.409982541036847
3.3459227528455807e-09,0.00086,158.9275834375,213.93065029396695,5.409982541036847
3.358372697972448e-09,0.0008632,159.51894188749998,213.93065029396695,5.409982541036847
3.367710156817599e-09,0.0008656,159.962460725,213.93065029396695,5.409982541036847
3.4548597727056695e-09,0.000888,164.101969875,213.93065029396695,5.409982541036847
3.4828721492411208e-09,0.0008952,165.4325263875,213.93065029396695,5.409982541036847
3.6540588947355456e-09,0.0009392,173.563705075,213.93065029396695,5.409982541036847
3.6976337026795814e-09,0.0009504,175.63345965,213.93065029396695,5.409982541036847
3.800345749976236e-09,0.0009767999999999999,180.51216686249998,213.93065029396695,5.409982541036847
3.865707961892289e-09,0.0009935999999999999,183.61679872499997,213.93065029396695,5.409982541036847
3.884382879582591e-09,0.0009984,184.50383639999998,213.93065029396695,5.409982541036847
3.955970064062077e-09,0.0010168,187.9041474875,213.93065029396695,5.409982541036847
3.974644981752378e-09,0.0010216,188.79118516249997,213.93065029396695,5.409982541036847
4.030669734823281e-09,0.001036,191.4522981875,213.93065029396695,5.409982541036847
4.043119679950148e-09,0.0010391999999999999,192.0436566375,213.93065029396695,5.409982541036847
4.0835820016124665e-09,0.0010496,193.96557159999998,213.93065029396695,5.409982541036847
4.176956590063971e-09,0.0010735999999999999,198.40075997499997,213.93065029396695,5.409982541036847
4.292118582487494e-09,0.0011032,203.8708256375,213.93065029396695,5.409982541036847
4.410393061192733e-09,0.0011336,209.4887309125,213.93065029396695,5.409982541036847
4.497542677080804e-09,0.001156,213.62824006249997,213.93065029396695,5.409982541036847
4.544229971306556e-09,0.001168,215.84583425,213.93065029396695,5.409982541036847
4.572242347842007e-09,0.0011752,217.17639076249998,213.93065029396695,5.409982541036847
4.631379587194627e-09,0.0011903999999999999,219.98534339999998,213.93065029396695,5.409982541036847
4.668729422575229e-09,0.0012,221.75941874999998,213.93065029396695,5.409982541036847
4.724754175646132e-09,0.0012144,224.420531775,213.93065029396695,5.409982541036847
4.7403166070547155e-09,0.0012184,225.15972983749998,213.93065029396695,5.409982541036847
4.768328983590167e-09,0.0012255999999999999,226.49028634999996,213.93065029396695,5.409982541036847
4.805678818970769e-09,0.0012351999999999999,228.26436169999997,213.93065029396695,5.409982541036847
4.83369119550622e-09,0.0012423999999999998,229.59491821249998,213.93065029396695,5.409982541036847
4.930178270239442e-09,0.0012672,232.80648448642143,213.93065029396695,5.409982541036847
5.0266653449726636e-09,0.001292,232.97559960984594,213.93065029396695,5.409982541036847
5.1169274471424504e-09,0.0013151999999999999,233.13266150237996,213.93065029396695,5.409982541036847
5.179177172776787e-09,0.0013311999999999998,233.24035103856497,213.93065029396695,5.409982541036847
5.2663267886648584e-09,0.0013536,233.39027216039503,213.93065029396695,5.409982541036847
5.306789110327177e-09,0.001364,233.45954919436707,213.93065029396695,5.409982541036847
5.331689000580911e-09,0.0013704,233.50207883578156,213.93065029396695,5.409982541036847
5.415726130187266e-09,0.001392,233.64504791481332,213.93065029396695,5.409982541036847
5.456188451849585e-09,0.0014024,233.7135760745288,213.93065029396695,5.409982541036847
5.474863369539885e-09,0.0014072,233.74513758132375,213.93065029396695,5.409982541036847
5.555788012864523e-09,0.001428,233.8814217889842,213.93065029396695,5.409982541036847
5.624262711062292e-09,0.0014456,233.9961355732079,213.93065029396695,5.409982541036847
5.6553875738794605e-09,0.0014536,234.04809801211258,213.93065029396695,5.409982541036847
5.761212107457832e-09,0.0014808,234.22394197914625,213.93065029396695,5.409982541036847
5.826574319373886e-09,0.0014976,234.33192236645527,213.93065029396695,5.409982541036847
6.0537858179392135e-09,0.0015559999999999999,234.70366142395994,213.93065029396695,5.409982541036847
6.094248139601532e-09,0.0015664,234.7692866745019,213.93065029396695,5.409982541036847
6.122260516136983e-09,0.0015735999999999999,234.81462003039329,213.93065029396695,5.409982541036847
6.1720602966444525e-09,0.0015864,234.89501342757234,213.93065029396695,5.409982541036847
6.259209912532523e-09,0.0016087999999999999,235.03509578378848,213.93065029396695,5.409982541036847
6.274772343941107e-09,0.0016128,235.06003023712117,213.93065029396695,5.409982541036847
6.3152346656034265e-09,0.0016232,235.12474720392726,213.93065029396695,5.409982541036847
6.39927179520978e-09,0.0016447999999999999,235.2586449284018,213.93065029396695,5.409982541036847
6.464634007125833e-09,0.0016615999999999998,235.36231405067335,213.93065029396695,5.409982541036847
6.5704585407042055e-09,0.0016887999999999998,235.52929676743761,213.93065029396695,5.409982541036847
6.5984709172396576e-09,0.001696,235.57332208820773,213.93065029396695,5.409982541036847
6.645158211465409e-09,0.0017079999999999999,235.64653598764855,213.93065029396695,5.409982541036847
6.651383184028843e-09,0.0017096,235.65628266166203,213.93065029396695,5.409982541036847
6.6887330194094445e-09,0.0017192,235.71468817299152,213.93065029396695,5.409982541036847
6.744757772480347e-09,0.0017335999999999999,235.80205851774275,213.93065029396695,5.409982541036847
6.85991976490387e-09,0.0017632,235.98076925358998,213.93065029396695,5.409982541036847
6.953294353355374e-09,0.0017871999999999999,236.12481240798508,213.93065029396695,5.409982541036847
6.9719692710456755e-09,0.001792,236.15353029686173,213.93065029396695,5.409982541036847
6.984419216172542e-09,0.0017951999999999998,236.17265889127552,213.93065029396695,5.409982541036847
7.021769051553144e-09,0.0018047999999999999,236.2299650458029,213.93065029396695,5.409982541036847
7.049781428088596e-09,0.001812,236.27286667935806,213.93065029396695,5.409982541036847
7.084018777187481e-09,0.0018208,236.3252118297004,213.93065029396695,5.409982541036847
7.152493475385251e-09,0.0018384,236.42960707230952,213.93065029396695,5.409982541036847
7.242755577555039e-09,0.0018616,236.56662537550335,213.93065029396695,5.409982541036847
7.267655467808773e-09,0.0018679999999999999,236.60430612558602,213.93065029396695,5.409982541036847
7.276992926653924e-09,0.0018704,236.61842342215098,213.93065029396695,5.409982541036847
7.3330176797248255e-09,0.0018847999999999998,236.70297931907749,213.93065029396695,5.409982541036847
7.435729727021481e-09,0.0019111999999999998,236.85734698411594,213.93065029396695,5.409982541036847
7.479304534965517e-09,0.0019223999999999999,236.92258480360914,213.93065029396695,5.409982541036847
7.547779233163287e-09,0.0019399999999999999,237.02480268737747,213.93065029396695,5.409982541036847
7.63181636276964e-09,0.0019616,237.14975894618925,213.93065029396695,5.409982541036847
7.694066088403977e-09,0.0019776,237.24197344869282,213.93065029396695,5.409982541036847
7.715853492375996e-09,0.0019832,237.27417972384762,213.93065029396695,5.409982541036847
7.778103218010333e-09,0.0019992,237.3660028010519,213.93065029396695,5.409982541036847
7.90571515556072e-09,0.002032,237.55334895272685,213.93065029396695,5.409982541036847
7.992864771448793e-09,0.0020544,237.68061541904996,213.93065029396695,5.409982541036847
8.11113925015403e-09,0.0020848,237.85247194546062,213.93065029396695,5.409982541036847
8.139151626689483e-09,0.002092,237.8930313254479,213.93065029396695,5.409982541036847
8.176501462070084e-09,0.0021016,237.94702591411234,213.93065029396695,5.409982541036847
8.213851297450684e-09,0.0021111999999999997,238.0009243966598,213.93065029396695,5.409982541036847
8.248088646549571e-09,0.00212,238.0502474309034,213.93065029396695,5.409982541036847
8.266763564239873e-09,0.0021248,238.0771172471582,213.93065029396695,5.409982541036847
8.322788317310774e-09,0.0021392,238.15758501660545,213.93065029396695,5.409982541036847
8.34768820756451e-09,0.0021456,238.19328063208945,213.93065029396695,5.409982541036847
8.434837823452579e-09,0.002168,238.31788958788513,213.93065029396695,5.409982541036847
8.48463760396005e-09,0.0021808,238.38886925523587,213.93065029396695,5.409982541036847
8.500200035368633e-09,0.0021847999999999998,238.4110170564628,213.93065029396695,5.409982541036847
8.5126499804955e-09,0.002188,238.4287239134444,213.93065029396695,5.409982541036847
8.627811972919022e-09,0.0022175999999999997,238.59203634210982,213.93065029396695,5.409982541036847
8.683836725989927e-09,0.002232,238.67117805651526,213.93065029396695,5.409982541036847
8.733636506497395e-09,0.0022448,238.74135922907925,213.93065029396695,5.409982541036847
8.75853639675113e-09,0.0022512,238.77639127691924,213.93065029396695,5.409982541036847
8.774098828159713e-09,0.0022551999999999997,238.79826658379002,213.93065029396695,5.409982541036847
8.795886232131732e-09,0.0022608,238.82886660891984,213.93065029396695,5.409982541036847
8.833236067512334e-09,0.0022704,238.8812551107024,213.93065029396695,5.409982541036847
8.858135957766068e-09,0.0022768,238.91613279156985,213.93065029396695,5.409982541036847
8.879923361738085e-09,0.0022824,238.94661940927324,213.93065029396695,5.409982541036847
8.95462303249929e-09,0.0023016,239.05092419838908,213.93065029396695,5.409982541036847
9.035547675823926e-09,0.0023224,239.16353885237865,213.93065029396695,5.409982541036847
9.1600471270926e-09,0.0023544,239.33602710154094,213.93065029396695,5.409982541036847
9.181834531064617e-09,0.0023599999999999997,239.3661183014001,213.93065029396695,5.409982541036847
9.219184366445219e-09,0.0023696,239.417638508917,213.93065029396695,5.409982541036847
9.262759174389253e-09,0.0023807999999999998,239.47764264678713,213.93065029396695,5.409982541036847
9.32500890002359e-09,0.0023967999999999997,239.56317222610784,213.93065029396695,5.409982541036847
9.43394591988368e-09,0.0024248,239.71231510596238,213.93065029396695,5.409982541036847
9.5304329946169e-09,0.0024495999999999997,239.84385308708767,213.93065029396695,5.409982541036847
9.58957023396952e-09,0.0024648,239.92421646759564,213.93065029396695,5.409982541036847
9.645594987040423e-09,0.0024792,240.00017209484295,213.93065029396695,5.409982541036847
9.71718217151991e-09,0.0024976,240.0969765880506,213.93065029396695,5.409982541036847
9.74519454805536e-09,0.0025047999999999997,240.1347808466572,213.93065029396695,5.409982541036847
9.866581513042318e-09,0.002536,240.2981120023523,213.93065029396695,5.409982541036847
9.907043834704635e-09,0.0025464,240.3523813229768,213.93065029396695,5.409982541036847
9.928831238676654e-09,0.002552,240.38156745757465,213.93065029396695,5.409982541036847
9.941281183803522e-09,0.0025552,240.3982340343023,213.93065029396695,5.409982541036847
9.972406046620689e-09,0.0025632,240.43986490227945,213.93065029396695,5.409982541036847
1.0022205827128157e-08,0.0025759999999999997,240.5063690435919,213.93065029396695,5.409982541036847
1.0096905497889362e-08,0.0025951999999999998,240.6058841195509,213.93065029396695,5.409982541036847
1.0174717654932281e-08,0.0026152,240.70924080849647,213.93065029396695,5.409982541036847
1.0227629921721467e-08,0.0026287999999999997,240.7793473358999,213.93065029396695,5.409982541036847
1.026497975710207e-08,0.0026384,240.82874915801702,213.93065029396695,5.409982541036847
1.034279191414499e-08,0.0026584,240.93144503090826,213.93065029396695,5.409982541036847
1.0411266612342761e-08,0.002676,241.02156840635138,213.93065029396695,5.409982541036847
1.0473516337977097e-08,0.002692,241.1032983469417,213.93065029396695,5.409982541036847
1.0489078769385682e-08,0.002696,241.12370120385177,213.93065029396695,5.409982541036847
1.0545103522456583e-08,0.0027104,241.19705393898602,213.93065029396695,5.409982541036847
1.0573115898992034e-08,0.0027175999999999997,241.23367329967783,213.93065029396695,5.409982541036847
1.0622915679499505e-08,0.0027304,241.2986810964725,213.93065029396695,5.409982541036847
1.0660265514880105e-08,0.00274,241.34735897483085,213.93065029396695,5.409982541036847
1.0703840322824143e-08,0.0027512,241.40406584574293,213.93065029396695,5.409982541036847
1.0840789719219682e-08,0.0027864,241.58170412670012,213.93065029396695,5.409982541036847
1.0893701986008868e-08,0.0028,241.65010243798463,213.93065029396695,5.409982541036847
1.0927939335107751e-08,0.0028087999999999998,241.69429113709833,213.93065029396695,5.409982541036847
1.0977739115615221e-08,0.0028216,241.75846934634788,213.93065029396695,5.409982541036847
1.1124025970855912e-08,0.0028591999999999997,241.94633941273364,213.93065029396695,5.409982541036847
1.1152038347391363e-08,0.0028664,241.98220435174127,213.93065029396695,5.409982541036847
1.1201838127898831e-08,0.0028791999999999997,242.0458776127814,213.93065029396695,5.409982541036847
1.1267200339814885e-08,0.0028959999999999997,242.12928148270822,213.93065029396695,5.409982541036847
1.1382362332238408e-08,0.0029256,242.27577349140708,213.93065029396695,5.409982541036847
1.1397924763646992e-08,0.0029295999999999997,242.2955252815678,213.93065029396695,5.409982541036847
1.1466399461844762e-08,0.0029472,242.38230850837948,213.93065029396695,5.409982541036847
1.149752432466193e-08,0.0029552,242.42168859073718,213.93065029396695,5.409982541036847
1.1531761673760816e-08,0.002964,242.46495869214965,213.93065029396695,5.409982541036847
1.1618911289648886e-08,0.0029863999999999997,242.57487529601408,213.93065029396695,5.409982541036847
1.1650036152466055e-08,0.0029944,242.6140532424272,213.93065029396695,5.409982541036847
1.1793210521425028e-08,0.0030312,242.79374861588659,213.93065029396695,5.409982541036847
1.1808772952833613e-08,0.0030352,242.8132293191639,213.93065029396695,5.409982541036847
1.1824335384242196e-08,0.0030391999999999997,242.83270001252455,213.93065029396695,5.409982541036847
1.1833672843087347e-08,0.0030415999999999998,242.84437763139937,213.93065029396695,5.409982541036847
1.1899035055003399e-08,0.0030583999999999997,242.9260205785417,213.93065029396695,5.409982541036847
1.1920822458975418e-08,0.003064,242.95319600239503,213.93065029396695,5.409982541036847
1.2007972074863488e-08,0.0030864,243.0617045517686,213.93065029396695,5.409982541036847
1.2039096937680657e-08,0.0030943999999999998,243.1003831167668,213.93065029396695,5.409982541036847
1.2116909094723576e-08,0.0031144,243.19690930158623,213.93065029396695,5.409982541036847
1.222273362830195e-08,0.0031416,243.3277978486837,213.93065029396695,5.409982541036847
1.2322333189316888e-08,0.0031672,243.4505839202988,213.93065029396695,5.409982541036847
1.2412595291486675e-08,0.0031904,243.56152487252177,213.93065029396695,5.409982541036847
1.2512194852501612e-08,0.0032159999999999997,243.68357798014586,213.93065029396695,5.409982541036847
1.2540207229037065e-08,0.0032232,243.71783707059708,213.93065029396695,5.409982541036847
1.277053121388411e-08,0.0032824,243.99840021265084,213.93065029396695,5.409982541036847
1.2792318617856127e-08,0.0032879999999999997,244.0248373836091,213.93065029396695,5.409982541036847
1.2845230884645314e-08,0.0033016,244.08896893923136,213.93065029396695,5.409982541036847
1.2879468233744197e-08,0.0033104,244.13041093498683,213.93065029396695,5.409982541036847
1.2898143151434499e-08,0.0033152,244.15299755026996,213.93065029396695,5.409982541036847
1.294483044566025e-08,0.0033271999999999998,244.20940836135796,213.93065029396695,5.409982541036847
1.2979067794759138e-08,0.003336,244.25072587310268,213.93065029396695,5.409982541036847
1.3013305143858021e-08,0.0033447999999999998,244.29200090014106,213.93065029396695,5.409982541036847
1.324051664242335e-08,0.0034032,244.56485170364428,213.93065029396695,5.409982541036847
1.3380578525100606e-08,0.0034392,244.73213786576883,213.93065029396695,5.409982541036847
1.3396140956509191e-08,0.0034432,244.75068296534135,213.93065029396695,5.409982541036847
1.3430378305608074e-08,0.0034519999999999998,244.79145263451957,213.93065029396695,5.409982541036847
1.3452165709580093e-08,0.0034576,244.81737586666188,213.93065029396695,5.409982541036847
1.3557990243158464e-08,0.0034847999999999997,244.94305653437343,213.93065029396695,5.409982541036847
1.3607790023665935e-08,0.0034976,245.00206794397056,213.93065029396695,5.409982541036847
1.3679377208145422e-08,0.003516,245.08674950112,213.93065029396695,5.409982541036847
1.384745146735813e-08,0.0035591999999999998,245.28489072367262,213.93065029396695,5.409982541036847
1.3947051028373068e-08,0.0035848,245.40186517991532,213.93065029396695,5.409982541036847
1.3987513350035386e-08,0.0035952,245.44929294041842,213.93065029396695,5.409982541036847
1.4052875561951439e-08,0.0036119999999999998,245.52579414276278,213.93065029396695,5.409982541036847
1.4087112911050324e-08,0.0036208,245.56581081241436,213.93065029396695,5.409982541036847
1.4121350260149208e-08,0.0036295999999999998,245.60578956991836,213.93065029396695,5.409982541036847
1.4242737225136164e-08,0.0036607999999999996,245.74722884217343,213.93065029396695,5.409982541036847
1.4280087060516768e-08,0.0036704,245.79065393482804,213.93065029396695,5.409982541036847
1.4385911594095139e-08,0.0036975999999999997,245.91345180032286,213.93065029396695,5.409982541036847
1.4469948723701492e-08,0.0037191999999999998,246.01071697076748,213.93065029396695,5.409982541036847
1.4513523531645529e-08,0.0037304,246.0610640161378,213.93065029396695,5.409982541036847
1.4538423421899263e-08,0.0037367999999999998,246.08980728762964,213.93065029396695,5.409982541036847
1.46006731475336e-08,0.0037527999999999997,246.16158159797806,213.93065029396695,5.409982541036847
1.46193480652239e-08,0.0037576,246.18309060625464,213.93065029396695,5.409982541036847
1.4659810386886219e-08,0.0037679999999999996,246.2296567316066,213.93065029396695,5.409982541036847
1.4768747406746308e-08,0.003796,246.35477859568402,213.93065029396695,5.409982541036847
1.4824772159817211e-08,0.0038104,246.41898679493164,213.93065029396695,5.409982541036847
1.4852784536352662e-08,0.0038176,246.45105540184647,213.93065029396695,5.409982541036847
1.492437172083215e-08,0.003836,246.53290152876897,213.93065029396695,5.409982541036847
1.5027083768128804e-08,0.0038623999999999998,246.6500659991424,213.93065029396695,5.409982541036847
1.5067546089791124e-08,0.0038728,246.6961358956428,213.93065029396695,5.409982541036847
1.5123570842862027e-08,0.0038872,246.7598454086972,213.93065029396695,5.409982541036847
1.5201382999904945e-08,0.0039071999999999996,246.84817835876203,213.93065029396695,5.409982541036847
1.5260520239257564e-08,0.0039223999999999995,246.91519351450444,213.93065029396695,5.409982541036847
1.5328994937455335e-08,0.00394,246.99266361005635,213.93065029396695,5.409982541036847
1.5388132176807954e-08,0.0039552,247.0594610533762,213.93065029396695,5.409982541036847
1.544415692987886e-08,0.0039696,247.1226505521156,213.93065029396695,5.409982541036847
1.5543756490893797e-08,0.0039952,247.23476714699333,213.93065029396695,5.409982541036847
1.59360044770038e-08,0.004096019203840768,247.6736126361458,213.93065029396695,5.409982541036847
1.7056723682262906e-08,0.004384076815363073,248.90483382202962,213.93065029396695,5.409982541036847
1.8252157501205956e-08,0.004691338267653531,250.18384067300298,213.93065029396695,5.409982541036847
2.1539600503299335e-08,0.005536307261452291,253.5426432079347,213.93065029396695,5.409982541036847
2.1913173571719034e-08,0.005632326465293058,253.91122061607615,213.93065029396695,5.409982541036847
2.6694908847491224e-08,0.006861372274454891,258.43110525830446,213.93065029396695,5.409982541036847
2.736734037064669e-08,0.007034206841368274,259.04036504245266,213.93065029396695,5.409982541036847
2.796505728011821e-08,0.007187837567513502,259.57704478170837,213.93065029396695,5.409982541036847
3.072949798642401e-08,0.007898379675935187,262.00319855058126,213.93065029396695,5.409982541036847
3.1999646419051e-08,0.008224844968993799,263.08921047570396,213.93065029396695,5.409982541036847
3.3344509465361924e-08,0.008570514102820564,264.22093605068414,213.93065029396695,5.409982541036847
3.536180403482832e-08,0.009089017803560712,265.8856957123197,213.93065029396695,5.409982541036847
3.715495476324289e-08,0.0095499099819964,267.3346240429128,213.93065029396695,5.409982541036847
3.737909860429471e-08,0.00960752150430086,267.5138025426942,213.93065029396695,5.409982541036847
3.767795705903047e-08,0.009684336867373475,267.7520567366218,213.93065029396695,5.409982541036847
3.947110778744505e-08,0.010145229045809162,269.16640420874865,213.93065029396695,5.409982541036847
4.2609121562170536e-08,0.010951790358071613,271.5826230595617,213.93065029396695,5.409982541036847
4.365512615374571e-08,0.011220644128825764,272.37246904106024,213.93065029396695,5.409982541036847
4.4028699222165416e-08,0.011316663332666534,272.6527636540655,213.93065029396695,5.409982541036847
4.425284306321723e-08,0.011374274854970993,272.8204952491953,213.93065029396695,5.409982541036847
4.537356226847634e-08,0.0116623324664933,273.6542340208946,213.93065029396695,5.409982541036847
4.597127917794786e-08,0.011815963192638527,274.09560881899614,213.93065029396695,5.409982541036847
4.791385913373031e-08,0.012315263052610522,275.51486244571316,213.93065029396695,5.409982541036847
5.0080582930564586e-08,0.012872174434886977,277.0716568286276,213.93065029396695,5.409982541036847
5.1873733658979155e-08,0.013333066613322665,278.3402659357573,213.93065029396695,5.409982541036847
5.493703282002072e-08,0.014120424084816964,280.4685956756869,213.93065029396695,5.409982541036847
5.568417895686012e-08,0.0143124624924985,280.9806162878969,213.93065029396695,5.409982541036847
5.6506039707383465e-08,0.01452370474094819,281.54075421272853,213.93065029396695,5.409982541036847
5.844861966316592e-08,0.015023004600920185,282.8522346703138,213.93065029396695,5.409982541036847
5.867276350421774e-08,0.015080616123224646,283.00245749308385,213.93065029396695,5.409982541036847
6.278206725683446e-08,0.016136827365473096,285.7180743235263,213.93065029396695,5.409982541036847
6.494879105366874e-08,0.01669373874774955,287.12197554242863,213.93065029396695,5.409982541036847
6.674194178208331e-08,0.017154630926185237,288.270062064681,213.93065029396695,5.409982541036847
6.763851714629059e-08,0.01738507701540308,288.83958935738053,213.93065029396695,5.409982541036847
6.808680482839424e-08,0.017500300060012002,289.1232483590441,213.93065029396695,5.409982541036847
7.032824323891245e-08,0.01807641528305661,290.5307622520463,213.93065029396695,5.409982541036847
7.212139396732702e-08,0.0185373074614923,291.64421596852173,213.93065029396695,5.409982541036847
7.496054928731676e-08,0.019267053410682137,293.38535200554327,213.93065029396695,5.409982541036847
7.57824100378401e-08,0.019478295659131825,293.8845398968197,213.93065029396695,5.409982541036847
7.802384844835831e-08,0.020054410882176434,295.23534396764825,213.93065029396695,5.409982541036847
8.086300376834805e-08,0.020784156831366273,296.92482942263933,213.93065029396695,5.409982541036847
8.131129145045169e-08,0.020899379875975194,297.1894607150092,213.93065029396695,5.409982541036847
8.48228782935969e-08,0.021801960392078417,299.24307572555927,213.93065029396695,5.409982541036847
8.616774133990783e-08,0.022147629525905183,300.02075115184135,213.93065029396695,5.409982541036847
8.848389436410998e-08,0.022742948589717944,301.34907476730297,213.93065029396695,5.409982541036847
9.139776429778367e-08,0.023491898379675937,303.0010847021085,213.93065029396695,5.409982541036847
9.453577807250915e-08,0.024298459691938386,304.75736400420345,213.93065029396695,5.409982541036847
9.588064111882008e-08,0.024644128825765152,305.50307815405927,213.93065029396695,5.409982541036847
9.632892880092372e-08,0.024759351870374074,305.75074156284245,213.93065029396695,5.409982541036847
1.0178309559985139e-07,0.02616123224644929,308.72884664529886,213.93065029396695,5.409982541036847
1.04771680147209e-07,0.026929385877175437,310.3342608358045,213.93065029396695,5.409982541036847
1.0581768473878417e-07,0.027198239647929588,310.8919233202377,213.93065029396695,5.409982541036847
1.0693840394404327e-07,0.02748629725945189,311.4870384667708,213.93065029396695,5.409982541036847
1.0783497930825055e-07,0.027716743348669734,311.9613811283088,213.93065029396695,5.409982541036847
1.0843269621772207e-07,0.027870374074814963,312.27675535086166,213.93065029396695,5.409982541036847
1.0888098389982573e-07,0.027985597119423885,312.51284127611115,213.93065029396695,5.409982541036847
1.1074884924192425e-07,0.028465693138627728,313.4924798164007,213.93065029396695,5.409982541036847
1.1134656615139576e-07,0.028619323864772953,313.80460043910335,213.93065029396695,5.409982541036847
1.1261671458402275e-07,0.028945789157831567,314.4656954176373,213.93065029396695,5.409982541036847
1.1358800456191397e-07,0.029195439087817562,314.9692784202618,213.93065029396695,5.409982541036847
1.145592945398052e-07,0.02944508901780356,315.47118480358506,213.93065029396695,5.409982541036847
1.153064406766446e-07,0.029637127425485098,315.85613814765077,213.93065029396695,5.409982541036847
1.1575472835874824e-07,0.02975235047009402,316.0866432357287,213.93065029396695,5.409982541036847
1.1747316447347888e-07,0.03019403880776155,316.967039539929,213.93065029396695,5.409982541036847
1.1963988827031314e-07,0.03075095019003801,318.0699779956876,213.93065029396695,5.409982541036847
1.2038703440715256e-07,0.030942988597719545,318.44849172085554,213.93065029396695,5.409982541036847
1.215824682260956e-07,0.03125025005001,319.05221361929443,213.93065029396695,5.409982541036847
1.22329614362935e-07,0.031442288457691536,319.4283644373234,213.93065029396695,5.409982541036847
1.256170573650284e-07,0.0322872574514903,321.0728970085346,213.93065029396695,5.409982541036847
1.291286442081736e-07,0.03318983796759352,322.81112313073714,213.93065029396695,5.409982541036847
1.2980107573132906e-07,0.03336267253450691,323.141861413762,213.93065029396695,5.409982541036847
1.3249080182395091e-07,0.03405401080216043,324.45818654801303,213.93065029396695,5.409982541036847
1.3480695484815306e-07,0.034649329865973195,325.5833590312659,213.93065029396695,5.409982541036847
1.3555410098499248e-07,0.034841368273654735,325.9447062551549,213.93065029396695,5.409982541036847
1.36151817894464e-07,0.034994998999799964,326.23322508571965,213.93065029396695,5.409982541036847
1.3697367864498734e-07,0.03520624124824965,326.62913319774583,213.93065029396695,5.409982541036847
1.4033583626076469e-07,0.03607041408281657,328.2392028207688,213.93065029396695,5.409982541036847
1.4235313083023107e-07,0.03658891778355672,329.198024715079,213.93065029396695,5.409982541036847
1.4369799387654198e-07,0.03693458691738348,329.8342969615899,213.93065029396695,5.409982541036847
1.4399685233127772e-07,0.03701140228045609,329.9753749169276,213.93065029396695,5.409982541036847
1.4519228615022076e-07,0.037318663732746546,330.53854855439573,213.93065029396695,5.409982541036847
1.4579000305969229e-07,0.037472294458891775,330.81945702203905,213.93065029396695,5.409982541036847
1.4773258301547478e-07,0.03797159431886378,331.7293231694171,213.93065029396695,5.409982541036847
1.501981652670448e-07,0.03860532106421284,332.8774616811948,213.93065029396695,5.409982541036847
1.5072116756283236e-07,0.03873974794958991,333.1200585875663,213.93065029396695,5.409982541036847
1.5445689824702942e-07,0.039699939987997604,334.84344524431935,213.93065029396695,5.409982541036847
1.5587647590702428e-07,0.040064812962592525,335.4940600597169,213.93065029396695,5.409982541036847
1.572213389533352e-07,0.04041048209641929,336.1083036734238,213.93065029396695,5.409982541036847
1.5864091661333008e-07,0.04077535507101421,336.75445302518284,213.93065029396695,5.409982541036847
1.6103178425121617e-07,0.041389877975595124,337.83763055882844,213.93065029396695,5.409982541036847
1.616295011606877e-07,0.04154350870174035,338.1074426956637,213.93065029396695,5.409982541036847
1.627502203659468e-07,0.04183156631326265,338.61229392810793,213.93065029396695,5.409982541036847
1.6424451263962563e-07,0.04221564312862573,339.2833248829231,213.93065029396695,5.409982541036847
1.6491694416278105e-07,0.042388477695539106,339.58451159513197,213.93065029396695,5.409982541036847
1.651410880038329e-07,0.04244608921784357,339.68480068463896,213.93065029396695,5.409982541036847
1.6558937568593654e-07,0.042561312262452494,339.8852197440534,213.93065029396695,5.409982541036847
1.6723309718698324e-07,0.04298379675935188,340.61828619133627,213.93065029396695,5.409982541036847
1.6798024332382264e-07,0.04317583516703341,340.9505687341997,213.93065029396695,5.409982541036847
1.6969867943855326e-07,0.04361752350470094,341.71263887455973,213.93065029396695,5.409982541036847
1.7126768632591599e-07,0.044020804160832164,342.4058176552949,213.93065029396695,5.409982541036847
1.7365855396380208e-07,0.04463532706541308,343.45734668584004,213.93065029396695,5.409982541036847
1.745551293280094e-07,0.04486577315463093,343.85021252417016,213.93065029396695,5.409982541036847
1.7537699007853275e-07,0.04507701540308062,344.20964875534514,213.93065029396695,5.409982541036847
1.773942846479991e-07,0.04559551910382076,345.08912746127794,213.93065029396695,5.409982541036847
1.7888857692167794e-07,0.04597959591918384,345.7380805406269,213.93065029396695,5.409982541036847
1.7918743537641368e-07,0.046056411282256446,345.8676170872016,213.93065029396695,5.409982541036847
1.8120472994588006e-07,0.046574914982996596,346.73979532388165,213.93065029396695,5.409982541036847
1.8277373683324282e-07,0.04697819563912782,347.415540788193,213.93065029396695,5.409982541036847
1.830725952879786e-07,0.04705501100220044,347.54399730969766,213.93065029396695,5.409982541036847
1.8479103140270923e-07,0.04749669933986797,348.2810413800244,213.93065029396695,5.409982541036847
1.8538874831218075e-07,0.0476503300660132,348.5367773247719,213.93065029396695,5.409982541036847
1.8636003829007195e-07,0.047899979995999195,348.95166346501367,213.93065029396695,5.409982541036847
1.8718189904059532e-07,0.04811122224444889,349.30206270625644,213.93065029396695,5.409982541036847
1.884520474732223e-07,0.048437687537507504,349.8424109200153,213.93065029396695,5.409982541036847
1.908429151111084e-07,0.04905221044208842,350.85569941880453,213.93065029396695,5.409982541036847
1.928602096805748e-07,0.04957071414282857,351.7068164926067,213.93065029396695,5.409982541036847
1.9345792659004633e-07,0.0497243448689738,351.9583316299679,213.93065029396695,5.409982541036847
1.9652122575108787e-07,0.05051170234046809,353.24262065246256,213.93065029396695,5.409982541036847
1.9816494725213457e-07,0.05093418683736747,353.92853162561414,213.93065029396695,5.409982541036847
2.0070524411738853e-07,0.051587117423484694,354.9842275060793,213.93065029396695,5.409982541036847
2.0302139714159073e-07,0.052182436487297465,355.94224078961855,213.93065029396695,5.409982541036847
2.0638355475736803e-07,0.05304660932186438,357.32535514722423,213.93065029396695,5.409982541036847
2.0772841780367894e-07,0.05339227845569114,357.87613699305643,213.93065029396695,5.409982541036847
2.0802727625841467e-07,0.05346909381876375,357.9983438983413,213.93065029396695,5.409982541036847
2.0982042698682924e-07,0.053929985997199434,358.7301526044229,213.93065029396695,5.409982541036847
2.102687146689329e-07,0.05404520904180836,358.9127231705332,213.93065029396695,5.409982541036847
2.1116529003314024e-07,0.05427565513102621,359.2774095341232,213.93065029396695,5.409982541036847
2.1355615767102633e-07,0.054890178035607126,360.246966256021,213.93065029396695,5.409982541036847
2.1564816685417663e-07,0.05542788557711542,361.09186099111616,213.93065029396695,5.409982541036847
2.1609645453628029e-07,0.055543108621724346,361.272493295641,213.93065029396695,5.409982541036847
2.1803903449206272e-07,0.05604240848169634,362.05355061367044,213.93065029396695,5.409982541036847
2.187114660152182e-07,0.056215243048609725,362.3232836909279,213.93065029396695,5.409982541036847
2.1998161444784516e-07,0.05654170834166833,362.83189870884394,213.93065029396695,5.409982541036847
2.228207697678349e-07,0.05727145429085817,363.9646797298282,213.93065029396695,5.409982541036847
2.2334377206362254e-07,0.057405881176235254,364.17273449088896,213.93065029396695,5.409982541036847
2.2416563281414582e-07,0.05761712342468493,364.49929420522034,213.93065029396695,5.409982541036847
2.2498749356466918e-07,0.057828365673134624,364.8253873169755,213.93065029396695,5.409982541036847
2.255852104741407e-07,0.05798199639927985,365.06225422367214,213.93065029396695,5.409982541036847
2.2648178583834802e-07,0.058212442488497704,365.4170961617834,213.93065029396695,5.409982541036847
2.2857379502149832e-07,0.058750150030006,366.24293701334364,213.93065029396695,5.409982541036847
2.2954508499938955e-07,0.058999799959991994,366.6253605992939,213.93065029396695,5.409982541036847
2.3006808729517716e-07,0.05913422684536908,366.83101957279393,213.93065029396695,5.409982541036847
2.320106672509596e-07,0.05963352670534107,367.5933046819299,213.93065029396695,5.409982541036847
2.3455096411621355e-07,0.06028645729145829,368.58639374084197,213.93065029396695,5.409982541036847
2.3597054177620844e-07,0.06065133026605321,369.1395280492684,213.93065029396695,5.409982541036847
2.3746483404988727e-07,0.06103540708141629,369.72037450848484,213.93065029396695,5.409982541036847
2.388844117098821e-07,0.0614002800560112,370.2708597075287,213.93065029396695,5.409982541036847
2.401545601425091e-07,0.061726745349069814,370.76231860510904,213.93065029396695,5.409982541036847
2.409017062793485e-07,0.06191878375675135,371.0509385490115,213.93065029396695,5.409982541036847
2.4291900084881487e-07,0.0624372874574915,371.828473902859,213.93065029396695,5.409982541036847
2.441144346677579e-07,0.06274454890978196,372.2880473527346,213.93065029396695,5.409982541036847
2.4471215157722944e-07,0.06289817963592718,372.51750487602044,213.93065029396695,5.409982541036847
2.4530986848670096e-07,0.06305181036207241,372.74674392488583,213.93065029396695,5.409982541036847
2.4560872694143675e-07,0.06312862572514504,372.8612817527006,213.93065029396695,5.409982541036847
2.469535899877477e-07,0.0634742948589718,373.37603082326615,213.93065029396695,5.409982541036847
2.474018776698514e-07,0.06358951790358072,373.54737074901465,213.93065029396695,5.409982541036847
2.50390462217209e-07,0.06435767153430687,374.68655832286254,213.93065029396695,5.409982541036847
2.5315490292351474e-07,0.06506821364272855,375.73559455090515,213.93065029396695,5.409982541036847
2.5554577056140083e-07,0.06568273654730947,376.63927144535353,213.93065029396695,5.409982541036847
2.5629291669824025e-07,0.065874774954991,376.92099347345464,213.93065029396695,5.409982541036847
2.5704006283507966e-07,0.06606681336267253,377.20239538492166,213.93065029396695,5.409982541036847
2.57787208971919e-07,0.06625885177035407,377.48347847241024,213.93065029396695,5.409982541036847
2.5980450354138546e-07,0.06677735547109423,378.2408202990707,213.93065029396695,5.409982541036847
2.6167236888348395e-07,0.06725745149029806,378.9400203911197,213.93065029396695,5.409982541036847
2.6234480040663945e-07,0.06743028605721145,379.1912555738852,213.93065029396695,5.409982541036847
2.630919465434788e-07,0.06762232446489298,379.47011141237255,213.93065029396695,5.409982541036847
2.6510924111294525e-07,0.06814082816563313,380.2214837738852,213.93065029396695,5.409982541036847
2.6697710645504374e-07,0.06862092418483696,380.9152131770356,213.93065029396695,5.409982541036847
2.687702571834583e-07,0.06908181636327265,381.57941474993066,213.93065029396695,5.409982541036847
2.7004040561608527e-07,0.06940828165633127,382.0488456394179,213.93065029396695,5.409982541036847
2.715346978897641e-07,0.06979235847169435,382.60001623432095,213.93065029396695,5.409982541036847
2.720577001855517e-07,0.06992678535707142,382.7926463100026,213.93065029396695,5.409982541036847
2.7220712941291955e-07,0.06996519303860772,382.84765694117743,213.93065029396695,5.409982541036847
2.7250598786765534e-07,0.07004200840168034,382.9576428842603,213.93065029396695,5.409982541036847
2.783337277350027e-07,0.07153990798159632,385.0930554019622,213.93065029396695,5.409982541036847
2.7900615925815817e-07,0.0717127425485097,385.3383219692329,213.93065029396695,5.409982541036847
2.795291615539457e-07,0.07184716943388678,385.52892550774106,213.93065029396695,5.409982541036847
2.82966033783407e-07,0.07273054610922185,386.77802086150524,213.93065029396695,5.409982541036847
2.8378789453393035e-07,0.07294178835767154,387.07583926589956,213.93065029396695,5.409982541036847
2.8587990371708066e-07,0.07347949589917983,387.8324086171956,213.93065029396695,5.409982541036847
2.8901791749180617e-07,0.0742860572114423,388.9632266776872,213.93065029396695,5.409982541036847
2.902133513107492e-07,0.07459331866373275,389.39275371401135,213.93065029396695,5.409982541036847
2.904374951518011e-07,0.07465093018603722,389.47321315684826,213.93065029396695,5.409982541036847
2.916329289707441e-07,0.07495819163832768,389.901921884988,213.93065029396695,5.409982541036847
2.925295043349514e-07,0.07518863772754551,390.22300381135784,213.93065029396695,5.409982541036847
2.9559280349599297e-07,0.07597599519903982,391.3171495461532,213.93065029396695,5.409982541036847
2.977595272928272e-07,0.07653290658131627,392.0883889702026,213.93065029396695,5.409982541036847
2.9873081727071843e-07,0.07678255651130227,392.43340617975036,213.93065029396695,5.409982541036847
3.0000096570334545e-07,0.07710902180436088,392.8839231253464,213.93065029396695,5.409982541036847
3.008975410675527e-07,0.07733946789357872,393.2014873199593,213.93065029396695,5.409982541036847
3.0336312331912277e-07,0.0779731946389278,394.0728917067408,213.93065029396695,5.409982541036847
3.0508155943385337e-07,0.07841488297659532,394.67860144353904,213.93065029396695,5.409982541036847
3.073229978443716e-07,0.07899099819963994,395.4666617150999,213.93065029396695,5.409982541036847
3.0784600014015917e-07,0.079125425085017,395.65021952679473,213.93065029396695,5.409982541036847
3.090414339591022e-07,0.07943268653730746,396.0693241530264,213.93065029396695,5.409982541036847
3.1038629700541315e-07,0.07977835567113423,396.5400618452106,213.93065029396695,5.409982541036847
3.1277716464329924e-07,0.08039287857571514,397.3749694527995,213.93065029396695,5.409982541036847
3.144956007580299e-07,0.08083456691338269,397.97352265293915,213.93065029396695,5.409982541036847
3.165128953274963e-07,0.08135307061412284,398.6745469483972,213.93065029396695,5.409982541036847
3.1778304376012324e-07,0.08167953590718144,399.11503878136625,213.93065029396695,5.409982541036847
3.185301898969626e-07,0.08187157431486297,399.3738308824117,213.93065029396695,5.409982541036847
3.1905319219275026e-07,0.08200600120024006,399.55484451158355,213.93065029396695,5.409982541036847
3.2346135440010274e-07,0.08313902780556112,401.07595982153975,213.93065029396695,5.409982541036847
3.254039343558852e-07,0.08363832766553311,401.743713152824,213.93065029396695,5.409982541036847
3.28168375062191e-07,0.0843488697739548,402.691303308069,213.93065029396695,5.409982541036847
3.2884080658534644e-07,0.08452170434086818,402.92132687010564,213.93065029396695,5.409982541036847
3.3197882036007195e-07,0.08532826565313063,403.99235398585944,213.93065029396695,5.409982541036847
3.327259664969113e-07,0.08552030406081217,404.24677761908504,213.93065029396695,5.409982541036847
3.360134094990047e-07,0.08636527305461093,405.36360504528784,213.93065029396695,5.409982541036847
3.3668584102216016e-07,0.08653810762152431,405.5915211509376,213.93065029396695,5.409982541036847
3.3705941409057987e-07,0.08663412682536507,405.718064499004,213.93065029396695,5.409982541036847
3.390019940463624e-07,0.08713342668533708,406.3752102591079,213.93065029396695,5.409982541036847
3.408698593884608e-07,0.08761352270454091,407.0056976213026,213.93065029396695,5.409982541036847
3.4273772473055937e-07,0.08809361872374476,407.63483900980793,213.93065029396695,5.409982541036847
3.441573023905542e-07,0.08845849169833968,408.1120925497896,213.93065029396695,5.409982541036847
3.4475501930002575e-07,0.08861212242448491,408.3128116540042,213.93065029396695,5.409982541036847
3.4512859236844546e-07,0.08870814162832567,408.43819217722586,213.93065029396695,5.409982541036847
3.45726309277917e-07,0.0888617723544709,408.6386909794666,213.93065029396695,5.409982541036847
3.462493115737046e-07,0.08899619923984797,408.81401656089605,213.93065029396695,5.409982541036847
3.4766888923369944e-07,0.0893610722144429,409.2893804324007,213.93065029396695,5.409982541036847
3.5005975687158553e-07,0.08997559511902381,410.0882857614572,213.93065029396695,5.409982541036847
3.5230119528210373e-07,0.09055171034206842,410.83532901735583,213.93065029396695,5.409982541036847
3.529736268052592e-07,0.0907245449089818,411.0590802373336,213.93065029396695,5.409982541036847
3.531230560326271e-07,0.09076295259051811,411.1087801477232,213.93065029396695,5.409982541036847
3.546173483063059e-07,0.09114702940588118,411.6053289624902,213.93065029396695,5.409982541036847
3.5566335289788106e-07,0.09141588317663533,411.9524277128164,213.93065029396695,5.409982541036847
3.5611164057998474e-07,0.09153110622124426,412.10106242203756,213.93065029396695,5.409982541036847
3.6059451740102113e-07,0.09268333666733347,413.5834179509568,213.93065029396695,5.409982541036847
3.6253709735680354e-07,0.09318263652730546,414.2235381035344,213.93065029396695,5.409982541036847
3.6507739422205753e-07,0.09383556711342268,415.05860353846356,213.93065029396695,5.409982541036847
3.6530153806310934e-07,0.09389317863572715,415.1321768121781,213.93065029396695,5.409982541036847
3.668705449504721e-07,0.09429645929185837,415.6466976585533,213.93065029396695,5.409982541036847
3.678418349283634e-07,0.09454610922184438,415.96478053230146,213.93065029396695,5.409982541036847
3.709051340894049e-07,0.09533346669333867,416.9658260808686,213.93065029396695,5.409982541036847
3.729224286588713e-07,0.09585197039407882,417.62329087707985,213.93065029396695,5.409982541036847
3.753132962967574e-07,0.09646649329865974,418.40071501798343,213.93065029396695,5.409982541036847
3.790490269809544e-07,0.09742668533706741,419.6115847012155,213.93065029396695,5.409982541036847
3.843537645525142e-07,0.09879015803160633,421.3230532334237,213.93065029396695,5.409982541036847
3.85773342212509e-07,0.09915503100620124,421.77948622628355,213.93065029396695,5.409982541036847
3.8637105912198054e-07,0.09930866173234647,421.97147251798134,213.93065029396695,5.409982541036847
3.865204883493485e-07,0.09934706941388279,422.0194509879971,213.93065029396695,5.409982541036847