File: datasets/aisi_316_L/data/M1/valid_25.csv
Time(s),Strain(%),Stress(MPa),Temp(C),Log_SR(s-1)
0.0,0.0,0.0,217.37617104472926,5.479463625887668
4.243716308997751e-11,1.28e-05,2.3618566,217.37617104472926,5.479463625887668
6.365574463496626e-11,1.92e-05,3.5427849,217.37617104472926,5.479463625887668
1.0874523041806737e-10,3.28e-05,6.052257537499999,217.37617104472926,5.479463625887668
1.6444400697366288e-10,4.96e-05,9.152194325,217.37617104472926,5.479463625887668
2.1749046083613474e-10,6.56e-05,12.104515074999998,217.37617104472926,5.479463625887668
3.341926593335729e-10,0.0001008,18.599620725,217.37617104472926,5.479463625887668
3.766298224235504e-10,0.0001136,20.961477325,217.37617104472926,5.479463625887668
4.5354718052413467e-10,0.0001368,25.242342412499998,217.37617104472926,5.479463625887668
5.118982797728537e-10,0.00015439999999999999,28.489895237499997,217.37617104472926,5.479463625887668
5.463784747834605e-10,0.0001648,30.408903725,217.37617104472926,5.479463625887668
5.967726059528087e-10,0.00017999999999999998,33.2136084375,217.37617104472926,5.479463625887668
6.232958328840447e-10,0.000188,34.6897688125,217.37617104472926,5.479463625887668
7.187794498364941e-10,0.00021679999999999998,40.0039461625,217.37617104472926,5.479463625887668
7.346933859952356e-10,0.0002216,40.8896423875,217.37617104472926,5.479463625887668
7.479549994608536e-10,0.00022559999999999998,41.627722575,217.37617104472926,5.479463625887668
8.036537760164491e-10,0.00024239999999999998,44.7276593625,217.37617104472926,5.479463625887668
8.96485070275775e-10,0.0002704,49.894220675,217.37617104472926,5.479463625887668
9.54836169524494e-10,0.000288,53.1417735,217.37617104472926,5.479463625887668
1.0291012049319547e-09,0.0003104,57.27502255,217.37617104472926,5.479463625887668
1.0450151410906962e-09,0.00031519999999999996,58.16071877499999,217.37617104472926,5.479463625887668
1.0741906907150556e-09,0.00032399999999999996,59.78449518749999,217.37617104472926,5.479463625887668
1.0901046268737974e-09,0.00032879999999999997,60.670191412499996,217.37617104472926,5.479463625887668
1.2598532792337074e-09,0.00037999999999999997,70.1176178125,217.37617104472926,5.479463625887668
1.3447276054136624e-09,0.0004056,74.84133101249999,217.37617104472926,5.479463625887668
1.3632938642655274e-09,0.00041119999999999997,75.874643275,217.37617104472926,5.479463625887668
1.4296019315936174e-09,0.00043119999999999996,79.5650442125,217.37617104472926,5.479463625887668
1.5012146443079546e-09,0.0004528,83.550677225,217.37617104472926,5.479463625887668
1.55691342086355e-09,0.0004696,86.6506140125,217.37617104472926,5.479463625887668
1.692181878212853e-09,0.0005103999999999999,94.17903192499999,217.37617104472926,5.479463625887668
1.753185300154696e-09,0.0005288,97.57420078749999,217.37617104472926,5.479463625887668
1.7664469136203139e-09,0.0005327999999999999,98.312280975,217.37617104472926,5.479463625887668
1.7797085270859317e-09,0.0005367999999999999,99.05036116249998,217.37617104472926,5.479463625887668
1.877844466731505e-09,0.0005664,104.51215455,217.37617104472926,5.479463625887668
1.914976984435235e-09,0.0005775999999999999,106.57877907499999,217.37617104472926,5.479463625887668
1.9600664702183364e-09,0.0005912,109.0882517125,217.37617104472926,5.479463625887668
1.9918943425358195e-09,0.0006008,110.85964416249999,217.37617104472926,5.479463625887668
2.007808278694561e-09,0.0006056,111.7453403875,217.37617104472926,5.479463625887668
2.2014278352925836e-09,0.000664,122.521311125,217.37617104472926,5.479463625887668
2.2279510622238194e-09,0.000672,123.99747149999999,217.37617104472926,5.479463625887668
2.296911452245033e-09,0.0006927999999999999,127.83548847499999,217.37617104472926,5.479463625887668
2.360567196879999e-09,0.000712,131.378273375,217.37617104472926,5.479463625887668
2.421570618821842e-09,0.0007304,134.7734422375,217.37617104472926,5.479463625887668
2.453398491139325e-09,0.00074,136.54483468749999,217.37617104472926,5.479463625887668
2.5674483669436394e-09,0.0007744,142.89232429999998,217.37617104472926,5.479463625887668
2.654975015816718e-09,0.0008008,147.76365353749998,217.37617104472926,5.479463625887668
2.7053691469860664e-09,0.000816,150.56835825,217.37617104472926,5.479463625887668
2.8485945724147407e-09,0.0008592,158.539624275,217.37617104472926,5.479463625887668
2.904293348970336e-09,0.0008759999999999999,161.63956106249998,217.37617104472926,5.479463625887668
2.9255119305153247e-09,0.0008824,162.82048936249998,217.37617104472926,5.479463625887668
2.9812107070709203e-09,0.0008992,165.92042615,217.37617104472926,5.479463625887668
3.007733934002156e-09,0.0009071999999999999,167.39658652499998,217.37617104472926,5.479463625887668
3.034257160933392e-09,0.0009151999999999999,168.87274689999998,217.37617104472926,5.479463625887668
3.1058698736477294e-09,0.0009368,172.8583799125,217.37617104472926,5.479463625887668
3.1191314871133473e-09,0.0009408,173.5964601,217.37617104472926,5.479463625887668
3.1748302636689424e-09,0.0009576,176.6963968875,217.37617104472926,5.479463625887668
3.2093104586795496e-09,0.000968,178.615405375,217.37617104472926,5.479463625887668
3.2888801394732573e-09,0.000992,183.0438865,217.37617104472926,5.479463625887668
3.4161916287431896e-09,0.0010304,190.1294563,217.37617104472926,5.479463625887668
3.5116752456956393e-09,0.0010592,195.44363364999998,217.37617104472926,5.479463625887668
3.588592603796223e-09,0.0010823999999999999,199.72449873749997,217.37617104472926,5.479463625887668
3.6204204761137064e-09,0.0010919999999999999,201.49589118749998,217.37617104472926,5.479463625887668
3.6920331888280435e-09,0.0011136,205.4815242,217.37617104472926,5.479463625887668
3.7105994476799083e-09,0.0011191999999999999,206.51483646249997,217.37617104472926,5.479463625887668
3.750384288076763e-09,0.0011312,208.72907702499998,217.37617104472926,5.479463625887668
3.808735387325482e-09,0.0011488,211.97662985,217.37617104472926,5.479463625887668
3.82995396887047e-09,0.0011551999999999999,213.15755814999997,217.37617104472926,5.479463625887668
3.845867905029212e-09,0.00116,214.043254375,217.37617104472926,5.479463625887668
3.8989143588916836e-09,0.001176,216.995575125,217.37617104472926,5.479463625887668
3.986441007764763e-09,0.0012024,221.86690436249998,217.37617104472926,5.479463625887668
4.018268880082246e-09,0.001212,223.6382968125,217.37617104472926,5.479463625887668
4.039487461627234e-09,0.0012184,224.8192251125,217.37617104472926,5.479463625887668
4.06601068855847e-09,0.0012263999999999999,226.29538548749997,217.37617104472926,5.479463625887668
4.073967656637841e-09,0.0012288,226.7382336,217.37617104472926,5.479463625887668
4.166798950897167e-09,0.0012568,231.85303709756357,217.37617104472926,5.479463625887668
4.193322177828403e-09,0.0012648,231.9076977921085,217.37617104472926,5.479463625887668
4.211888436680268e-09,0.0012703999999999999,231.94588007846633,217.37617104472926,5.479463625887668
4.331242957870829e-09,0.0013063999999999999,232.18978870607873,217.37617104472926,5.479463625887668
4.418769606743908e-09,0.0013327999999999999,232.3669921407552,217.37617104472926,5.479463625887668
4.439988188288898e-09,0.0013392,232.4097437495386,217.37617104472926,5.479463625887668
4.4824253513788745e-09,0.001352,232.4950086732001,217.37617104472926,5.479463625887668
4.5301671598550995e-09,0.0013664,232.5905562907087,217.37617104472926,5.479463625887668
4.596475227183189e-09,0.0013863999999999999,232.7226123793606,217.37617104472926,5.479463625887668
4.67074026259065e-09,0.0014088,232.86963629746808,217.37617104472926,5.479463625887668
4.7078727802943805e-09,0.00142,232.9428061606636,217.37617104472926,5.479463625887668
4.731743684532493e-09,0.0014272,232.98972510340454,217.37617104472926,5.479463625887668
4.824574978791819e-09,0.0014552,233.17131682967425,217.37617104472926,5.479463625887668
4.843141237643684e-09,0.0014608,233.20747109319925,217.37617104472926,5.479463625887668
4.86966446457492e-09,0.0014688,233.25902641621627,217.37617104472926,5.479463625887668
4.925363241130515e-09,0.0014856,233.36693748794556,217.37617104472926,5.479463625887668
4.954538790754874e-09,0.0014944,233.42327233914193,217.37617104472926,5.479463625887668
5.057979375786695e-09,0.0015256,233.62197082359893,217.37617104472926,5.479463625887668
5.084502602717931e-09,0.0015336,233.67266308503116,217.37617104472926,5.479463625887668
5.140201379273526e-09,0.0015504,233.77878237176031,217.37617104472926,5.479463625887668
5.201204801215369e-09,0.0015688,233.89449501436172,217.37617104472926,5.479463625887668
5.243641964305346e-09,0.0015815999999999998,233.97467878499236,217.37617104472926,5.479463625887668
5.259555900464088e-09,0.0015864,234.0046824004162,217.37617104472926,5.479463625887668
5.3072977089403126e-09,0.0016007999999999999,234.09448153260763,217.37617104472926,5.479463625887668
5.376258098961526e-09,0.0016216,234.22363719912136,217.37617104472926,5.479463625887668
5.469089393220852e-09,0.0016496,234.3964849044612,217.37617104472926,5.479463625887668
5.5433544286283124e-09,0.0016719999999999999,234.53394062654417,217.37617104472926,5.479463625887668
5.686579854056987e-09,0.0017151999999999998,234.7970223523215,217.37617104472926,5.479463625887668
5.774106502930065e-09,0.0017415999999999998,234.95652273776972,217.37617104472926,5.479463625887668
5.8351099248719075e-09,0.0017599999999999998,235.0671324948537,217.37617104472926,5.479463625887668
5.8510238610306494e-09,0.0017648,235.09591292915258,217.37617104472926,5.479463625887668
5.869590119882514e-09,0.0017703999999999999,235.1294515461563,217.37617104472926,5.479463625887668
5.885504056041256e-09,0.0017752,235.15816601527706,217.37617104472926,5.479463625887668
5.959769091448717e-09,0.0017976,235.29176853399315,217.37617104472926,5.479463625887668
5.980987672993705e-09,0.0018039999999999998,235.3298212221242,217.37617104472926,5.479463625887668
6.079123612639278e-09,0.0018336,235.50513456154107,217.37617104472926,5.479463625887668
6.09503754879802e-09,0.0018384,235.53345941960626,217.37617104472926,5.479463625887668
6.129517743808627e-09,0.0018487999999999998,235.5947311887967,217.37617104472926,5.479463625887668
6.286004782702919e-09,0.001896,235.87113851367937,217.37617104472926,5.479463625887668
6.323137300406649e-09,0.0019072,235.93633116879712,217.37617104472926,5.479463625887668
6.347008204644761e-09,0.0019144,235.9781619019958,217.37617104472926,5.479463625887668
6.370879108882874e-09,0.0019215999999999999,236.0199313235946,217.37617104472926,5.479463625887668
6.43453485351784e-09,0.0019408,236.13101911991052,217.37617104472926,5.479463625887668
6.495538275459683e-09,0.0019592,236.23707676501692,217.37617104472926,5.479463625887668
6.50084292084593e-09,0.0019608,236.24628077123126,217.37617104472926,5.479463625887668
6.543280083935907e-09,0.0019736,236.31980766950628,217.37617104472926,5.479463625887668
6.606935828570874e-09,0.0019928,236.4297502660608,217.37617104472926,5.479463625887668
6.636111378195234e-09,0.0020016,236.48000248428684,217.37617104472926,5.479463625887668
6.728942672454559e-09,0.0020296,236.63932568035688,217.37617104472926,5.479463625887668
6.760770544772041e-09,0.0020391999999999997,236.69375313918383,217.37617104472926,5.479463625887668
6.7899460943964015e-09,0.002048,236.74355725532914,217.37617104472926,5.479463625887668
6.842992548258874e-09,0.002064,236.83389689324767,217.37617104472926,5.479463625887668
6.911952938280087e-09,0.0020848,236.95093115679614,217.37617104472926,5.479463625887668
6.938476165211322e-09,0.0020927999999999997,236.9958229690356,217.37617104472926,5.479463625887668
7.0153935233119076e-09,0.002116,237.1256323039252,217.37617104472926,5.479463625887668
7.041916750243144e-09,0.002124,237.1702652878849,217.37617104472926,5.479463625887668
7.116181785650603e-09,0.0021463999999999997,237.29489019313172,217.37617104472926,5.479463625887668
7.14270501258184e-09,0.0021544,237.33927602835752,217.37617104472926,5.479463625887668
7.211665402603053e-09,0.0021752,237.4543794114592,217.37617104472926,5.479463625887668
7.24614559761366e-09,0.0021855999999999998,237.51177007377294,217.37617104472926,5.479463625887668
7.2594072110792784e-09,0.0021896,237.53381503398126,217.37617104472926,5.479463625887668
7.291235083396762e-09,0.0021992,237.586658955969,217.37617104472926,5.479463625887668
7.3575431507248505e-09,0.0022191999999999997,237.6964623888436,217.37617104472926,5.479463625887668
7.503420898846648e-09,0.0022632,237.93668052889265,217.37617104472926,5.479463625887668
7.529944125777883e-09,0.0022711999999999997,237.98016016054035,217.37617104472926,5.479463625887668
7.545858061936625e-09,0.002276,238.00621927055326,217.37617104472926,5.479463625887668
7.601556838492221e-09,0.0022928,238.09725784635756,217.37617104472926,5.479463625887668
7.707649746217164e-09,0.0023247999999999997,238.26994816159203,217.37617104472926,5.479463625887668
7.72621600506903e-09,0.0023304,238.3000734081275,217.37617104472926,5.479463625887668
7.750086909307143e-09,0.0023376,238.3387644156929,217.37617104472926,5.479463625887668
7.795176395090244e-09,0.0023512,238.41172085879936,217.37617104472926,5.479463625887668
7.866789107804582e-09,0.0023728,238.52725549335852,217.37617104472926,5.479463625887668
7.901269302815187e-09,0.0023832,238.58273692859063,217.37617104472926,5.479463625887668
7.925140207053301e-09,0.0023904,238.62109185167654,217.37617104472926,5.479463625887668
7.956968079370783e-09,0.0024,238.67216173634836,217.37617104472926,5.479463625887668
7.967577370143278e-09,0.0024032,238.68916731891787,217.37617104472926,5.479463625887668
8.033885437471369e-09,0.0024232,238.7952528262946,217.37617104472926,5.479463625887668
8.089584214026963e-09,0.00244,238.884101019251,217.37617104472926,5.479463625887668
8.177110862900043e-09,0.0024664,239.0232390947048,217.37617104472926,5.479463625887668
8.246071252921255e-09,0.0024871999999999997,239.13245435934326,217.37617104472926,5.479463625887668
8.275246802545616e-09,0.002496,239.178553521338,217.37617104472926,5.479463625887668
8.291160738704358e-09,0.0025008,239.20367180072176,217.37617104472926,5.479463625887668
8.30177002947685e-09,0.0025039999999999997,239.22040687525742,217.37617104472926,5.479463625887668
8.373382742191187e-09,0.0025256,239.3331512572977,217.37617104472926,5.479463625887668
8.421124550667411e-09,0.0025399999999999997,239.4081053309271,217.37617104472926,5.479463625887668
8.452952422984895e-09,0.0025496,239.45798266455128,217.37617104472926,5.479463625887668
8.548436039937345e-09,0.0025784,239.60717704975542,217.37617104472926,5.479463625887668
8.704923078831637e-09,0.0026256,239.85029227884831,217.37617104472926,5.479463625887668
8.826929922715322e-09,0.0026623999999999997,240.03865915478346,217.37617104472926,5.479463625887668
8.856105472339681e-09,0.0026712,240.083552636321,217.37617104472926,5.479463625887668
8.933022830440267e-09,0.0026944,240.20163256013066,217.37617104472926,5.479463625887668
8.978112316223368e-09,0.002708,240.27066747758366,217.37617104472926,5.479463625887668
9.11338077357267e-09,0.0027488,240.47696547046928,217.37617104472926,5.479463625887668
9.184993486287007e-09,0.0027703999999999997,240.58569841294766,217.37617104472926,5.479463625887668
9.232735294763233e-09,0.0027848,240.65800341674304,217.37617104472926,5.479463625887668
9.301695684784445e-09,0.0028055999999999997,240.76218708240262,217.37617104472926,5.479463625887668
9.320261943636311e-09,0.0028112,240.7901850077858,217.37617104472926,5.479463625887668
9.357394461340042e-09,0.0028224,240.84611568977445,217.37617104472926,5.479463625887668
9.402483947123144e-09,0.002836,240.91391528383988,217.37617104472926,5.479463625887668
9.434311819440626e-09,0.0028455999999999998,240.96169749792622,217.37617104472926,5.479463625887668
9.455530400985615e-09,0.002852,240.99351738548773,217.37617104472926,5.479463625887668
9.495315241382468e-09,0.002864,241.0531047165024,217.37617104472926,5.479463625887668
9.535100081779323e-09,0.002876,241.11259475632986,217.37617104472926,5.479463625887668
9.566927954096805e-09,0.0028856,241.1601171176035,217.37617104472926,5.479463625887668
9.68893479798049e-09,0.0029224,241.34171780878515,217.37617104472926,5.479463625887668
9.787070737626063e-09,0.0029519999999999998,241.48714158459643,217.37617104472926,5.479463625887668
9.8135939645573e-09,0.00296,241.52634754645803,217.37617104472926,5.479463625887668
9.845421836874782e-09,0.0029695999999999998,241.5733401937118,217.37617104472926,5.479463625887668
9.935600808440985e-09,0.0029968,241.70616536265365,217.37617104472926,5.479463625887668
9.959471712679097e-09,0.0030039999999999997,241.74124616063077,217.37617104472926,5.479463625887668
1.004169371616593e-08,0.0030288,241.86182981526298,217.37617104472926,5.479463625887668
1.0187571464287725e-08,0.0030727999999999997,242.07482517452624,217.37617104472926,5.479463625887668
1.0222051659298334e-08,0.0030832,242.12499533303003,217.37617104472926,5.479463625887668
1.0259184177002063e-08,0.0030943999999999998,242.17895098143052,217.37617104472926,5.479463625887668
1.0304273662785164e-08,0.0031079999999999997,242.24436627074775,217.37617104472926,5.479463625887668
1.0317535276250782e-08,0.0031119999999999997,242.26358480392088,217.37617104472926,5.479463625887668
1.0325492244330154e-08,0.0031144,242.27511129957608,217.37617104472926,5.479463625887668
1.0336101535102648e-08,0.0031176,242.2904745731963,217.37617104472926,5.479463625887668
1.0381191020885748e-08,0.0031311999999999998,242.35569999416353,217.37617104472926,5.479463625887668
1.0439542120134467e-08,0.0031487999999999998,242.43994558784377,217.37617104472926,5.479463625887668
1.0535025737086919e-08,0.0031776,242.5774069643545,217.37617104472926,5.479463625887668
1.0601333804415006e-08,0.0031975999999999997,242.67258051560424,217.37617104472926,5.479463625887668
1.062520470865312e-08,0.0032048,242.70678612504992,217.37617104472926,5.479463625887668
1.065438025827748e-08,0.0032136,242.74855230758538,217.37617104472926,5.479463625887668
1.0731297616378063e-08,0.0032367999999999997,242.85844990055685,217.37617104472926,5.479463625887668
1.0752516197923052e-08,0.0032432,242.888712361374,217.37617104472926,5.479463625887668
1.0768430134081794e-08,0.003248,242.91139392510607,217.37617104472926,5.479463625887668
1.0779039424854287e-08,0.0032511999999999997,242.9265077054576,217.37617104472926,5.479463625887668
1.0866566073727367e-08,0.0032776,243.05097579864326,217.37617104472926,5.479463625887668
1.0954092722600445e-08,0.0033039999999999996,243.1750535057959,217.37617104472926,5.479463625887668
1.0983268272224805e-08,0.0033128,243.2163267396955,217.37617104472926,5.479463625887668
1.1028357758007906e-08,0.0033263999999999998,243.28002864322931,217.37617104472926,5.479463625887668
1.10389670487804e-08,0.0033296,243.2950025551907,217.37617104472926,5.479463625887668
1.120871570114031e-08,0.0033807999999999998,243.5338270380854,217.37617104472926,5.479463625887668
1.1259109832309659e-08,0.0033959999999999997,243.60445597097967,217.37617104472926,5.479463625887668
1.1325417899637748e-08,0.0034159999999999998,243.69720122707207,217.37617104472926,5.479463625887668
1.140763990312458e-08,0.0034408,243.81191175969596,217.37617104472926,5.479463625887668
1.1426206161976445e-08,0.0034463999999999996,243.8377694590804,217.37617104472926,5.479463625887668
1.154025603778076e-08,0.0034808,243.99625161736674,217.37617104472926,5.479463625887668
1.1558822296632625e-08,0.0034863999999999997,244.02199311463528,217.37617104472926,5.479463625887668
1.1582693200870737e-08,0.0034936,244.05506564345137,217.37617104472926,5.479463625887668
1.162247804126759e-08,0.0035055999999999998,244.1101275143965,217.37617104472926,5.479463625887668
1.1739180239765028e-08,0.0035407999999999998,244.27121985014472,217.37617104472926,5.479463625887668
1.1778965080161884e-08,0.0035528,244.32599477964723,217.37617104472926,5.479463625887668
1.1794879016320624e-08,0.0035575999999999997,244.347884542803,217.37617104472926,5.479463625887668
1.1882405665193704e-08,0.003584,244.4680729804565,217.37617104472926,5.479463625887668
1.1893014955966199e-08,0.0035872,244.4826177770037,217.37617104472926,5.479463625887668
1.1943409087135546e-08,0.0036024,244.55163657623794,217.37617104472926,5.479463625887668
1.1996455540998018e-08,0.0036184,244.62416535788756,217.37617104472926,5.479463625887668
1.2150290257199186e-08,0.0036647999999999997,244.83379484958928,217.37617104472926,5.479463625887668
1.22192506472204e-08,0.0036856,244.92743041767062,217.37617104472926,5.479463625887668
1.2272297101082871e-08,0.0037015999999999998,244.99931760680872,217.37617104472926,5.479463625887668
1.2301472650707233e-08,0.0037104,245.03880390287168,217.37617104472926,5.479463625887668
1.2357171427262827e-08,0.0037272,245.1140855587375,217.37617104472926,5.479463625887668
1.2394303944966556e-08,0.0037384,245.1641998221577,217.37617104472926,5.479463625887668
1.2452655044215275e-08,0.003756,245.2428326665021,217.37617104472926,5.479463625887668
1.2550790983860848e-08,0.0037855999999999996,245.37475551892337,217.37617104472926,5.479463625887668
1.2564052597326467e-08,0.0037895999999999997,245.3925520264275,217.37617104472926,5.479463625887668
1.2582618856178332e-08,0.0037952,245.41745483421417,217.37617104472926,5.479463625887668
1.2680754795823905e-08,0.0038247999999999997,245.54884665908597,217.37617104472926,5.479463625887668
1.2725844281607006e-08,0.0038383999999999996,245.60908285673278,217.37617104472926,5.479463625887668
1.2776238412776355e-08,0.0038536,245.67630725196136,217.37617104472926,5.479463625887668
1.2837241834718198e-08,0.003872,245.75754595111462,217.37617104472926,5.479463625887668
1.2932725451670647e-08,0.0039008,245.8844005698327,217.37617104472926,5.479463625887668
1.2972510292067501e-08,0.0039128,245.93714879612082,217.37617104472926,5.479463625887668
1.2988424228226243e-08,0.0039176,245.95823041669695,217.37617104472926,5.479463625887668
1.3065341586326825e-08,0.0039407999999999995,246.05998324647993,217.37617104472926,5.479463625887668
1.3115735717496174e-08,0.0039559999999999994,246.12652224642716,217.37617104472926,5.479463625887668
1.3182043784824264e-08,0.0039759999999999995,246.21392185148395,217.37617104472926,5.479463625887668
1.3195305398289883e-08,0.00398,246.23138117930085,217.37617104472926,5.479463625887668
1.3898298248924298e-08,0.0041920384076815365,247.147328680003,217.37617104472926,5.479463625887668
1.4089303683916195e-08,0.004249649929985997,247.39304965292905,217.37617104472926,5.479463625887668
1.4407646075569357e-08,0.0043456691338267656,247.79971699449624,217.37617104472926,5.479463625887668
1.4725988467222519e-08,0.004441688337667534,248.20289472083059,217.37617104472926,5.479463625887668
1.5107999337206313e-08,0.004556911382276456,248.6822483684557,217.37617104472926,5.479463625887668
1.6508705860480228e-08,0.004979395879175836,250.40082156664877,217.37617104472926,5.479463625887668
1.7718406948762243e-08,0.005344268853770755,251.83973277797818,217.37617104472926,5.479463625887668
1.854609716706046e-08,0.005593918783756751,252.80223486263242,217.37617104472926,5.479463625887668
1.981946673367311e-08,0.005977995599119824,254.25091258622857,217.37617104472926,5.479463625887668
2.013780912532627e-08,0.006074014802960592,254.60735212032176,217.37617104472926,5.479463625887668
2.1029167821955127e-08,0.006342868573714743,255.5938771222816,217.37617104472926,5.479463625887668
2.1729521083592083e-08,0.006554110822164433,256.35760644824967,217.37617104472926,5.479463625887668
2.268454825855157e-08,0.006842168433686738,257.383759512432,217.37617104472926,5.479463625887668
2.542229282676876e-08,0.007667933586717343,260.2358991277447,217.37617104472926,5.479463625887668
2.6631993915050776e-08,0.008032806561312262,261.4576777547836,217.37617104472926,5.479463625887668
2.8669385221631012e-08,0.008647329465893179,263.4675664156618,217.37617104472926,5.479463625887668
3.0324765658227453e-08,0.009146629325865173,265.05986504751115,217.37617104472926,5.479463625887668
3.102511891986441e-08,0.009357871574314863,265.72328144059105,217.37617104472926,5.479463625887668
3.2107483051485167e-08,0.009684336867373475,266.7371864751422,217.37617104472926,5.479463625887668
3.2871504791452755e-08,0.009914782956591319,267.4448730973126,217.37617104472926,5.479463625887668
3.420854283639603e-08,0.010318063612722545,268.6680780669287,217.37617104472926,5.479463625887668
3.5418243924678043e-08,0.010682936587317463,269.75881101286615,217.37617104472926,5.479463625887668
3.6818950447951956e-08,0.011105421084216843,271.00377405452303,217.37617104472926,5.479463625887668
3.7646640666250186e-08,0.011355071014202842,271.73075204474,217.37617104472926,5.479463625887668
3.917468414618536e-08,0.011815963192638527,273.0566943636492,217.37617104472926,5.479463625887668
3.9938705886152945e-08,0.01204640928185637,273.71208943357914,217.37617104472926,5.479463625887668
4.08300645827818e-08,0.012315263052610522,274.47056854224246,217.37617104472926,5.479463625887668
4.153041784441876e-08,0.012526505301060212,275.06199523422544,217.37617104472926,5.479463625887668
4.490484719594228e-08,0.013544308861772355,277.85879897220985,217.37617104472926,5.479463625887668
4.8279276547465796e-08,0.014562112422484497,280.574736402475,217.37617104472926,5.479463625887668
4.8533950460788326e-08,0.014638927785557112,280.77665740490914,217.37617104472926,5.479463625887668
4.9297972200755914e-08,0.014869373874774956,281.3799555249391,217.37617104472926,5.479463625887668
5.031666785404603e-08,0.015176635327065414,282.1787109343809,217.37617104472926,5.479463625887668
5.184471133398121e-08,0.0156375275055011,283.36511862058086,217.37617104472926,5.479463625887668
5.318174937892449e-08,0.01604080816163233,284.39208189233096,217.37617104472926,5.479463625887668
5.413677655388396e-08,0.01632886577315463,285.119471339914,217.37617104472926,5.479463625887668
5.483712981552093e-08,0.01654010802160432,285.6497135363458,217.37617104472926,5.479463625887668
5.623783633879484e-08,0.0169625925185037,286.7023402065478,217.37617104472926,5.479463625887668
5.789321677539128e-08,0.017461892378475695,287.933260336565,217.37617104472926,5.479463625887668
6.018528199529405e-08,0.018153230646129226,289.61518457500136,217.37617104472926,5.479463625887668
6.069462982193911e-08,0.018306861372274455,289.9855311508264,217.37617104472926,5.479463625887668
6.152232004023733e-08,0.01855651130226045,290.5847695737486,217.37617104472926,5.479463625887668
6.273202112851935e-08,0.01892138427685537,291.45495452798116,217.37617104472926,5.479463625887668
6.489674939176084e-08,0.019574314862972595,292.99596652692077,217.37617104472926,5.479463625887668
6.527876026174464e-08,0.019689537907581517,293.2658155989052,217.37617104472926,5.479463625887668
6.553343417506717e-08,0.01976635327065413,293.4453729096293,217.37617104472926,5.479463625887668
6.585177656672033e-08,0.019862372474494898,293.6694373142842,217.37617104472926,5.479463625887668
6.687047222001045e-08,0.020169633926785356,294.38362112512954,217.37617104472926,5.479463625887668
6.8334847221615e-08,0.02061132226445289,295.40287090846573,217.37617104472926,5.479463625887668
6.928987439657449e-08,0.020899379875975194,296.06301280129065,217.37617104472926,5.479463625887668
7.107259178983219e-08,0.021437087417483496,297.2858601251932,217.37617104472926,5.479463625887668
7.310998309641243e-08,0.022051610322064413,298.66884551809426,217.37617104472926,5.479463625887668
7.451068961968633e-08,0.022474094818963793,299.61094025115295,217.37617104472926,5.479463625887668
7.50200374463314e-08,0.02262772554510902,299.95180440420336,217.37617104472926,5.479463625887668
7.584772766462962e-08,0.02287737547509502,300.50378991437935,217.37617104472926,5.479463625887668
7.724843418790354e-08,0.0232998599719944,301.43259727764206,217.37617104472926,5.479463625887668
7.801245592787113e-08,0.023530306061212244,301.9364501638188,217.37617104472926,5.479463625887668
8.145055375772527e-08,0.024567313462692537,304.18038573085454,217.37617104472926,5.479463625887668
8.285126028099918e-08,0.024989797959591917,305.08395359221265,217.37617104472926,5.479463625887668
8.507965702257132e-08,0.025661932386477296,306.5092649929558,217.37617104472926,5.479463625887668
8.679870593749839e-08,0.026180436087217443,307.5988652081868,217.37617104472926,5.479463625887668
8.743539072080471e-08,0.02637247449489898,308.00028091203103,217.37617104472926,5.479463625887668
8.91544396357318e-08,0.02689097819563913,309.07844937969503,217.37617104472926,5.479463625887668
9.125549942064267e-08,0.027524704940988198,310.3852623765853,217.37617104472926,5.479463625887668
9.163751029062645e-08,0.02763992798559712,310.6215986113956,217.37617104472926,5.479463625887668
9.284721137890847e-08,0.02800480096019204,311.367474369694,217.37617104472926,5.479463625887668
9.32928907272229e-08,0.028139227845569114,311.64131409323153,217.37617104472926,5.479463625887668
9.437525485884365e-08,0.028465693138627728,312.3042379823665,217.37617104472926,5.479463625887668
9.634897768709326e-08,0.02906101220244049,313.50551554899107,217.37617104472926,5.479463625887668
9.736767334038337e-08,0.029368273654730947,314.12177234080036,217.37617104472926,5.479463625887668
1.0036009182192308e-07,0.030270854170834166,315.91764782419114,217.37617104472926,5.479463625887668
1.0163346138853573e-07,0.03065493098619724,316.6755020716118,217.37617104472926,5.479463625887668
1.0271582552015649e-07,0.030981396279255852,317.31677110009997,217.37617104472926,5.479463625887668
1.0341617878179345e-07,0.03119263852770554,317.7303060161662,217.37617104472926,5.479463625887668
1.0532623313171243e-07,0.03176875375075015,318.8526142021496,217.37617104472926,5.479463625887668
1.072362874816314e-07,0.03234486897379476,319.96701233524175,217.37617104472926,5.479463625887668
1.0793664074326835e-07,0.03255611122224445,320.3736819155005,217.37617104472926,5.479463625887668
1.113747385731225e-07,0.033593118623724744,322.3553244317683,217.37617104472926,5.479463625887668
1.1232976574808198e-07,0.03388117623524705,322.9015280746833,217.37617104472926,5.479463625887668
1.1532218422962171e-07,0.03478375675135027,324.6013544526838,217.37617104472926,5.479463625887668
1.1595886901292803e-07,0.034975795159031806,324.96079034109385,217.37617104472926,5.479463625887668
1.169138961878875e-07,0.035263852770554105,325.498504395975,217.37617104472926,5.479463625887668
1.1799626031950826e-07,0.03559031806361272,326.1058470976543,217.37617104472926,5.479463625887668
1.1901495597279838e-07,0.03589757951590318,326.67548201049107,217.37617104472926,5.479463625887668
1.206703364093948e-07,0.03639687937587517,327.5970997841217,217.37617104472926,5.479463625887668
1.2328074402095075e-07,0.037184236847369476,329.0404643564089,217.37617104472926,5.479463625887668
1.2359908641260392e-07,0.03728025605121024,329.2156653012203,217.37617104472926,5.479463625887668
1.2525446684920036e-07,0.03777955591118223,330.12388882563613,217.37617104472926,5.479463625887668
1.2678251032913554e-07,0.03824044808961792,330.9581026529568,217.37617104472926,5.479463625887668
1.272918581557806e-07,0.03839407881576315,331.2353013430505,217.37617104472926,5.479463625887668
1.2958392337568337e-07,0.03908541708341669,332.4773807305886,217.37617104472926,5.479463625887668
1.3187598859558613e-07,0.03977675535107021,333.71092086869936,217.37617104472926,5.479463625887668
1.3225799946556993e-07,0.03989197839567914,333.91569524990496,217.37617104472926,5.479463625887668
1.331493581621988e-07,0.04016083216643329,334.3926071803731,217.37617104472926,5.479463625887668
1.342317222938195e-07,0.040487297459491894,334.9700438552946,217.37617104472926,5.479463625887668
1.3512308099044837e-07,0.04075615123024605,335.44421768955476,217.37617104472926,5.479463625887668
1.3582343425208534e-07,0.04096739347869574,335.8159275804666,217.37617104472926,5.479463625887668
1.367147929487142e-07,0.041236247249449895,336.28793358274396,217.37617104472926,5.479463625887668
1.3735147773202052e-07,0.04142828565713143,336.6243462140648,217.37617104472926,5.479463625887668
1.380518309936575e-07,0.04163952790558112,336.99369844908347,217.37617104472926,5.479463625887668
1.3894318969028635e-07,0.041908381676335274,337.4627279277337,217.37617104472926,5.479463625887668
1.4047123317022153e-07,0.04236927385477096,338.2640574402445,217.37617104472926,5.479463625887668
1.4250862447680176e-07,0.04298379675935188,339.3272284366921,217.37617104472926,5.479463625887668
1.4448234730505134e-07,0.043579115823164635,340.3515367571749,217.37617104472926,5.479463625887668
1.4709275491660724e-07,0.044366473294658926,341.6979243285336,217.37617104472926,5.479463625887668
1.4741109730826047e-07,0.044462492498499706,341.8614780123275,217.37617104472926,5.479463625887668
1.4849346143988119e-07,0.04478895779155831,342.4165330681901,217.37617104472926,5.479463625887668
1.493211516581794e-07,0.045038607721544305,342.83992295121544,217.37617104472926,5.479463625887668
1.5046718426813082e-07,0.04538427685537108,343.42464718791757,217.37617104472926,5.479463625887668
1.5174055383474343e-07,0.045768353670734147,344.0723074903866,217.37617104472926,5.479463625887668
1.528865864446948e-07,0.04611402280456091,344.65339169635,217.37617104472926,5.479463625887668
1.5339593427133986e-07,0.04626765353070614,344.9111058050661,217.37617104472926,5.479463625887668
1.5511498318626695e-07,0.04678615723144629,345.7784375362633,217.37617104472926,5.479463625887668
1.5568799949124267e-07,0.046958991798359676,346.0667139998771,217.37617104472926,5.479463625887668
1.5638835275287961e-07,0.04717023404680937,346.41849056934615,217.37617104472926,5.479463625887668
1.57534385362831e-07,0.04751590318063613,346.9928025929979,217.37617104472926,5.479463625887668
1.5874408645111302e-07,0.04788077615523105,347.59725593200136,217.37617104472926,5.479463625887668
1.5976278210440314e-07,0.04818803760752151,348.10487720457803,217.37617104472926,5.479463625887668
1.601447929743869e-07,0.04830326065213042,348.2949095394324,217.37617104472926,5.479463625887668
1.6205484732430587e-07,0.04887937587517503,349.24243224561087,217.37617104472926,5.479463625887668
1.637102277609023e-07,0.04937867573514702,350.06010092002487,217.37617104472926,5.479463625887668
1.6428324406587802e-07,0.04955151030206041,350.3423879754783,217.37617104472926,5.479463625887668
1.6460158645753116e-07,0.04964752950590118,350.49904818565597,217.37617104472926,5.479463625887668
1.6485626037085373e-07,0.0497243448689738,350.6242912927817,217.37617104472926,5.479463625887668
1.6593862450247445e-07,0.0500508101620324,351.15573488810384,217.37617104472926,5.479463625887668
1.6632063537245825e-07,0.05016603320664133,351.34298021950553,217.37617104472926,5.479463625887668
1.6797601580905469e-07,0.05066533306661332,352.15244616456766,217.37617104472926,5.479463625887668
1.6867636907069166e-07,0.05087657531506301,352.49397529795687,217.37617104472926,5.479463625887668
1.6905837994067546e-07,0.050991798359671936,352.68003080178,217.37617104472926,5.479463625887668
1.7033174950728807e-07,0.051375875175035,353.29903503557256,217.37617104472926,5.479463625887668
1.7122310820391695e-07,0.051644728945789156,353.7312646140819,217.37617104472926,5.479463625887668
1.742155266854567e-07,0.052547309461892386,355.17594544567686,217.37617104472926,5.479463625887668
1.7485221146876302e-07,0.05273934786957392,355.4820720719196,217.37617104472926,5.479463625887668
1.7561623320873057e-07,0.052969793958791755,355.848850779287,217.37617104472926,5.479463625887668
1.770169397320045e-07,0.05339227845569114,356.51966618512273,217.37617104472926,5.479463625887668
1.7969101582189104e-07,0.05419883976795359,357.79459303588027,217.37617104472926,5.479463625887668
1.814737332151488e-07,0.0547365473094619,358.6404358444908,217.37617104472926,5.479463625887668
1.8312911365174522e-07,0.05523584716943389,359.4229642254107,217.37617104472926,5.479463625887668
1.844661516966885e-07,0.05563912782556511,360.0529943444312,217.37617104472926,5.479463625887668
1.8554851582830926e-07,0.05596559311862373,360.56171530602745,217.37617104472926,5.479463625887668
1.8828626039652647e-07,0.05679135827165434,361.84334110064043,217.37617104472926,5.479463625887668
1.8943229300647782e-07,0.0571370274054811,362.377675316292,217.37617104472926,5.479463625887668
1.9140601583472743e-07,0.05773234646929386,363.2949716658637,217.37617104472926,5.479463625887668
1.9433476583793652e-07,0.05861572314462893,364.6493518441518,217.37617104472926,5.479463625887668
1.9522612453456538e-07,0.05888457691538308,365.05997138880366,217.37617104472926,5.479463625887668
1.966904995361699e-07,0.05932626525305061,365.7329768817144,217.37617104472926,5.479463625887668
1.9713617888448433e-07,0.05946069213842768,365.93741640091963,217.37617104472926,5.479463625887668
1.975818582327988e-07,0.059595119023804766,366.1416757450832,217.37617104472926,5.479463625887668
1.9815487453777445e-07,0.05976795359071814,366.40403106325516,217.37617104472926,5.479463625887668
2.013382984543061e-07,0.06072814562912583,367.8562082411848,217.37617104472926,5.479463625887668
2.0172030932428986e-07,0.06084336867373474,368.02986570330046,217.37617104472926,5.479463625887668
2.0248433106425747e-07,0.061073814762952594,368.3767963323205,217.37617104472926,5.479463625887668
2.0388503758753138e-07,0.06149629925985198,369.011512751957,217.37617104472926,5.479463625887668
2.0503107019748276e-07,0.06184196839367874,369.52956221811496,217.37617104472926,5.479463625887668
2.0541308106746656e-07,0.061957191438287665,369.70199425518103,217.37617104472926,5.479463625887668
2.0802348867902246e-07,0.06274454890978196,370.87695056204126,217.37617104472926,5.479463625887668
2.0897851585398195e-07,0.06303260652130425,371.3053741278877,217.37617104472926,5.479463625887668
2.098698745506108e-07,0.06330146029205841,371.70454772157746,217.37617104472926,5.479463625887668
2.1101590716056218e-07,0.06364712942588517,372.216800708039,217.37617104472926,5.479463625887668
2.1139791803054599e-07,0.0637623524704941,372.387310441909,217.37617104472926,5.479463625887668
2.1228927672717484e-07,0.06403120624124825,372.78469985218175,217.37617104472926,5.479463625887668
2.1298962998881182e-07,0.06424244848969794,373.0964780592511,217.37617104472926,5.479463625887668
2.1426299955542443e-07,0.06462652530506101,373.6623251095445,217.37617104472926,5.479463625887668
2.151543582520533e-07,0.06489537907581516,374.0576379533481,217.37617104472926,5.479463625887668
2.1566370607869837e-07,0.06504900980196039,374.283244231614,217.37617104472926,5.479463625887668
2.171280810803029e-07,0.06549069813962792,374.9307076463108,217.37617104472926,5.479463625887668
2.1935647782187504e-07,0.0661628325665133,375.9127200298093,217.37617104472926,5.479463625887668
2.2082085282347962e-07,0.06660452090418084,376.5559247760188,217.37617104472926,5.479463625887668
2.210755267368021e-07,0.06668133626725345,376.6676164484064,217.37617104472926,5.479463625887668
2.2222155934675354e-07,0.06702700540108023,377.16960929426904,217.37617104472926,5.479463625887668
2.2260357021673728e-07,0.06714222844568914,377.336715742758,217.37617104472926,5.479463625887668
2.2413161369667246e-07,0.06760312062412482,378.0040261553495,217.37617104472926,5.479463625887668
2.2661468435156715e-07,0.06835207041408282,379.0846337473358,217.37617104472926,5.479463625887668
2.288430810931393e-07,0.0690242048409682,380.05048441127286,217.37617104472926,5.479463625887668
2.3158082566135646e-07,0.0698499699939988,381.2320940846672,217.37617104472926,5.479463625887668
2.3247218435798532e-07,0.07011882376475295,381.6156269465709,217.37617104472926,5.479463625887668
2.338092224029286e-07,0.07052210442088418,382.18985264080226,217.37617104472926,5.479463625887668
2.3533726588286378e-07,0.07098299659931986,382.8445447659233,217.37617104472926,5.479463625887668
2.3591028218783947e-07,0.07115583116623325,383.0896266325617,217.37617104472926,5.479463625887668
2.3661063544947645e-07,0.07136707341468294,383.38885607863756,217.37617104472926,5.479463625887668
2.375019941461053e-07,0.0716359271854371,383.7691944497782,217.37617104472926,5.479463625887668
2.3794767349441973e-07,0.07177035407081417,383.9591548443855,217.37617104472926,5.479463625887668
2.387116952343873e-07,0.072000800160032,384.2844787197807,217.37617104472926,5.479463625887668
2.3922104306103234e-07,0.07215443088617723,384.50113573185337,217.37617104472926,5.479463625887668
2.3953938545268557e-07,0.07225045009001801,384.636455008537,217.37617104472926,5.479463625887668
2.414494398026045e-07,0.07282656531306261,385.4469027029282,217.37617104472926,5.479463625887668
2.420224561075802e-07,0.072999399879976,385.6895489316447,217.37617104472926,5.479463625887668
2.4297748328253964e-07,0.0732874574914983,386.0934620111138,217.37617104472926,5.479463625887668
2.4488753763245867e-07,0.07386357271454291,386.89943547449786,217.37617104472926,5.479463625887668
2.46733923504047e-07,0.07442048409681937,387.67621592817625,217.37617104472926,5.479463625887668
2.4781628763566777e-07,0.07474694938987798,388.13051601410365,217.37617104472926,5.479463625887668
2.4998101589890926e-07,0.0753998799759952,389.03680130395475,217.37617104472926,5.479463625887668
2.5112704850886064e-07,0.07574554910982197,389.5153600192678,217.37617104472926,5.479463625887668
2.530371028587796e-07,0.07632166433286658,390.3110694679548,217.37617104472926,5.479463625887668
2.5437414090372285e-07,0.0767249449889978,390.86667286930697,217.37617104472926,5.479463625887668
2.5571117894866614e-07,0.07712822564512903,391.42113849238024,217.37617104472926,5.479463625887668
2.5647520068863375e-07,0.07735867173434688,391.7374683354281,217.37617104472926,5.479463625887668
2.579395756902383e-07,0.07780036007201441,392.34274185852854,217.37617104472926,5.479463625887668
2.5921294525685093e-07,0.07818443688737747,392.86797814721655,217.37617104472926,5.479463625887668
2.606136517801248e-07,0.07860692138427686,393.44457718650654,217.37617104472926,5.479463625887668
2.620780267817294e-07,0.0790486097219444,394.0460944939626,217.37617104472926,5.479463625887668
2.624600376517132e-07,0.07916383276655331,394.2027962992895,217.37617104472926,5.479463625887668
2.638607441749871e-07,0.0795863172634527,394.77661013922227,217.37617104472926,5.479463625887668
2.6481577134994655e-07,0.079874374874975,395.1671658945668,217.37617104472926,5.479463625887668
2.666621572215349e-07,0.08043128625725146,395.9206862568621,217.37617104472926,5.479463625887668
2.680628637448088e-07,0.08085377075415083,396.4909658289007,217.37617104472926,5.479463625887668
2.6927256483309085e-07,0.08121864372874575,396.982545400162,217.37617104472926,5.479463625887668
2.699729180947278e-07,0.08142988597719544,397.2667504383459,217.37617104472926,5.479463625887668
2.7175563548798557e-07,0.08196759351870375,397.98888701870663,217.37617104472926,5.479463625887668
2.73411015924582e-07,0.08246689337867574,398.6577898778522,217.37617104472926,5.479463625887668
2.737930267945658e-07,0.08258211642328467,398.81192755359547,217.37617104472926,5.479463625887668
2.7621242897112976e-07,0.0833118623724745,399.7861923028327,217.37617104472926,5.479463625887668
2.7767680397273436e-07,0.08375355071014204,400.37426217820416,217.37617104472926,5.479463625887668
2.7914117897433886e-07,0.08419523904780957,400.9611237888115,217.37617104472926,5.479463625887668
2.799688691926371e-07,0.08444488897779556,401.2922970423343,217.37617104472926,5.479463625887668
2.81369575715911e-07,0.08486737347469495,401.8518755432769,217.37617104472926,5.479463625887668
2.8283395071751556e-07,0.08530906181236247,402.4357290623085,217.37617104472926,5.479463625887668
2.8366164093581376e-07,0.08555871174234847,402.7652117120115,217.37617104472926,5.479463625887668
2.8397998332746693e-07,0.08565473094618924,402.8918359450167,217.37617104472926,5.479463625887668
2.845529996324426e-07,0.08582756551310262,403.1196201481044,217.37617104472926,5.479463625887668
2.8499867898075705e-07,0.0859619923984797,403.2966619835054,217.37617104472926,5.479463625887668
2.872270757223292e-07,0.08663412682536507,404.18025671062117,217.37617104472926,5.479463625887668
2.88818787680595e-07,0.08711422284456892,404.80975972827275,217.37617104472926,5.479463625887668
2.8920079855057883e-07,0.08722944588917785,404.9606389494178,217.37617104472926,5.479463625887668
2.8971014637722386e-07,0.08738307661532307,405.16169039179584,217.37617104472926,5.479463625887668
2.9085617898717524e-07,0.08772874574914984,405.613552789065,217.37617104472926,5.479463625887668
2.917475376838041e-07,0.08799759951990399,405.9645214365385,217.37617104472926,5.479463625887668
2.923205539887798e-07,0.08817043408681736,406.18992332588135,217.37617104472926,5.479463625887668
2.9403960290370685e-07,0.08868893778755751,406.86509735305697,217.37617104472926,5.479463625887668
2.960769942102871e-07,0.08930346069213843,407.66331340102073,217.37617104472926,5.479463625887668
2.964590050802709e-07,0.08941868373674736,407.81274012671935,217.37617104472926,5.479463625887668
2.979233800818754e-07,0.08986037207441488,408.3848482623817,217.37617104472926,5.479463625887668
2.9887840725683493e-07,0.0901484296859372,408.7573715070563,217.37617104472926,5.479463625887668
3.0129780943339894e-07,0.09087817563512703,409.699025325467,217.37617104472926,5.479463625887668
3.0231650508668906e-07,0.09118543708741748,410.09462838338084,217.37617104472926,5.479463625887668
3.0276218443500354e-07,0.09131986397279457,410.2675412055761,217.37617104472926,5.479463625887668
3.040992224799468e-07,0.09172314462892579,410.7856850402618,217.37617104472926,5.479463625887668
3.053725920465594e-07,0.09210722144428886,411.2783299673728,217.37617104472926,5.479463625887668
3.0626395074318827e-07,0.09237607521504301,411.6227048321671,217.37617104472926,5.479463625887668
3.076646572664622e-07,0.0927985597119424,412.1630766333333,217.37617104472926,5.479463625887668
3.093837061813893e-07,0.09331706341268255,412.82495066365806,217.37617104472926,5.479463625887668
3.0970204857304245e-07,0.09341308261652331,412.94736237254546,217.37617104472926,5.479463625887668
3.117394398796227e-07,0.09402760552110423,413.7296384820925,217.37617104472926,5.479463625887668
3.1352215727288035e-07,0.09456531306261252,414.41249589441975,217.37617104472926,5.479463625887668
3.1466818988283173e-07,0.09491098219643929,414.8506761528532,217.37617104472926,5.479463625887668
3.153685431444687e-07,0.09512222444488898,415.1181466016191,217.37617104472926,5.479463625887668
3.1715126053772645e-07,0.09565993198639729,415.7979372653704,217.37617104472926,5.479463625887668
3.1995267358427423e-07,0.09650490098019604,416.86317657786356,217.37617104472926,5.479463625887668
3.2090770075923375e-07,0.09679295859171835,417.2254941313,217.37617104472926,5.479463625887668
3.2275408663082207e-07,0.09734986997399481,417.9247845368546,217.37617104472926,5.479463625887668
3.242821301107573e-07,0.0978107621524305,418.5023285319512,217.37617104472926,5.479463625887668
3.2625585293900685e-07,0.09840608121624325,419.2467544418605,217.37617104472926,5.479463625887668
3.2924827142054655e-07,0.09930866173234647,420.3720588519548,217.37617104472926,5.479463625887668
3.2975761924719164e-07,0.0994622924584917,420.56320209362565,217.37617104472926,5.479463625887668
3.3026696707383667e-07,0.09961592318463693,420.75423022542316,217.37617104472926,5.479463625887668
3.3077631490048176e-07,0.09976955391078215,420.94514349403426,217.37617104472926,5.479463625887668
3.314129996837881e-07,0.0999615923184637,421.18362392778613,217.37617104472926,5.479463625887668