File: datasets/aisi_316_L/data/M1/valid_30.csv
Time(s),Strain(%),Stress(MPa),Temp(C),Log_SR(s-1)
0.0,0.0,0.0,413.94849221520576,3.4442055836561902
5.177938745146054e-09,1.44e-05,2.4206418,413.94849221520576,3.4442055836561902
1.0355877490292108e-08,2.88e-05,4.8412836,413.94849221520576,3.4442055836561902
2.099941824420344e-08,5.8399999999999997e-05,9.817047299999999,413.94849221520576,3.4442055836561902
3.2218285525353226e-08,8.96e-05,15.061771199999999,413.94849221520576,3.4442055836561902
3.279361205259167e-08,9.12e-05,15.3307314,413.94849221520576,3.4442055836561902
3.88345405885954e-08,0.000108,18.1548135,413.94849221520576,3.4442055836561902
4.3437152806503006e-08,0.0001208,20.3064951,413.94849221520576,3.4442055836561902
4.602612217907604e-08,0.000128,21.516816,413.94849221520576,3.4442055836561902
5.494368335127202e-08,0.0001528,25.6856991,413.94849221520576,3.4442055836561902
5.724498946022582e-08,0.0001592,26.7615399,413.94849221520576,3.4442055836561902
5.954629556917962e-08,0.0001656,27.837380699999997,413.94849221520576,3.4442055836561902
6.098461188727575e-08,0.0001696,28.5097812,413.94849221520576,3.4442055836561902
6.50118975779449e-08,0.0001808,30.3925026,413.94849221520576,3.4442055836561902
7.220347916842553e-08,0.0002008,33.7545051,413.94849221520576,3.4442055836561902
7.680609138633314e-08,0.0002136,35.9061867,413.94849221520576,3.4442055836561902
8.227169339509841e-08,0.00022879999999999998,38.461308599999995,413.94849221520576,3.4442055836561902
8.88879484583406e-08,0.0002472,41.554350899999996,413.94849221520576,3.4442055836561902
9.607953004882122e-08,0.0002672,44.9163534,413.94849221520576,3.4442055836561902
1.0010681573949038e-07,0.0002784,46.7990748,413.94849221520576,3.4442055836561902
1.0643540753911333e-07,0.000296,49.757636999999995,413.94849221520576,3.4442055836561902
1.199555809292169e-07,0.0003336,56.078201699999994,413.94849221520576,3.4442055836561902
1.2053090745645535e-07,0.00033519999999999996,56.347161899999996,413.94849221520576,3.4442055836561902
1.2916080536503214e-07,0.0003592,60.3815649,413.94849221520576,3.4442055836561902
1.323251012648436e-07,0.000368,61.860846,413.94849221520576,3.4442055836561902
1.3635238695551275e-07,0.0003792,63.7435674,413.94849221520576,3.4442055836561902
1.3894135632808577e-07,0.00038639999999999996,64.95388829999999,413.94849221520576,3.4442055836561902
1.4526994812770875e-07,0.000404,67.9124505,413.94849221520576,3.4442055836561902
1.495848970819971e-07,0.000416,69.92965199999999,413.94849221520576,3.4442055836561902
1.564888154088585e-07,0.00043519999999999995,73.15717439999999,413.94849221520576,3.4442055836561902
1.6080376436314688e-07,0.0004472,75.1743759,413.94849221520576,3.4442055836561902
1.6914599900810443e-07,0.0004704,79.0742988,413.94849221520576,3.4442055836561902
1.7317328469877358e-07,0.0004816,80.9570202,413.94849221520576,3.4442055836561902
1.7432393775325047e-07,0.00048479999999999997,81.49494059999999,413.94849221520576,3.4442055836561902
1.7950187649839653e-07,0.0004992,83.9155824,413.94849221520576,3.4442055836561902
1.8324149892544647e-07,0.0005096,85.66382370000001,413.94849221520576,3.4442055836561902
1.8784411114335408e-07,0.0005224,87.8155053,413.94849221520576,3.4442055836561902
1.950356927338347e-07,0.0005424,91.17750779999999,413.94849221520576,3.4442055836561902
2.0337792737879222e-07,0.0005656,95.0774307,413.94849221520576,3.4442055836561902
2.0682988654222294e-07,0.0005752,96.69119189999999,413.94849221520576,3.4442055836561902
2.1632277424165736e-07,0.0006016,101.1290352,413.94849221520576,3.4442055836561902
2.1833641708699196e-07,0.0006072,102.07039590000001,413.94849221520576,3.4442055836561902
2.2639098846833025e-07,0.0006296,105.8358387,413.94849221520576,3.4442055836561902
2.3243191700433397e-07,0.0006464,108.6599208,413.94849221520576,3.4442055836561902
2.3674686595862235e-07,0.0006584,110.6771223,413.94849221520576,3.4442055836561902
2.4681508018529526e-07,0.0006864,115.3839258,413.94849221520576,3.4442055836561902
2.4969171282148746e-07,0.0006944,116.72872679999999,413.94849221520576,3.4442055836561902
2.591846005209219e-07,0.0007208,121.16657009999999,413.94849221520576,3.4442055836561902
2.632118862115911e-07,0.000732,123.0492915,413.94849221520576,3.4442055836561902
2.773073861289331e-07,0.0007712,129.6388164,413.94849221520576,3.4442055836561902
2.8478663098303293e-07,0.000792,133.135299,413.94849221520576,3.4442055836561902
2.9025223299179823e-07,0.0008072,135.6904209,413.94849221520576,3.4442055836561902
2.9571783500056353e-07,0.0008223999999999999,138.24554279999998,413.94849221520576,3.4442055836561902
3.0290941659104414e-07,0.0008424,141.6075453,413.94849221520576,3.4442055836561902
3.054983859636172e-07,0.0008495999999999999,142.8178662,413.94849221520576,3.4442055836561902
3.1326529408133626e-07,0.0008711999999999999,146.4488289,413.94849221520576,3.4442055836561902
3.2131986546267455e-07,0.0008935999999999999,150.21427169999998,413.94849221520576,3.4442055836561902
3.273607939986783e-07,0.0009104,153.0383538,413.94849221520576,3.4442055836561902
3.371413449617319e-07,0.0009375999999999999,157.6106772,413.94849221520576,3.4442055836561902
3.428946102341165e-07,0.0009536,160.3002792,413.94849221520576,3.4442055836561902
3.4548357960668947e-07,0.0009607999999999999,161.51060009999998,413.94849221520576,3.4442055836561902
3.4749722245202405e-07,0.0009664,162.4519608,413.94849221520576,3.4442055836561902
3.4951086529735867e-07,0.000972,163.39332149999998,413.94849221520576,3.4442055836561902
3.561271203606008e-07,0.0009904,165.73401571679355,413.94849221520576,3.4442055836561902
3.6015440605127e-07,0.0010016,165.79448283443847,413.94849221520576,3.4442055836561902
3.621680488966045e-07,0.0010072,165.82461746442948,413.94849221520576,3.4442055836561902
3.774142018684235e-07,0.0010496,166.05069659449623,413.94849221520576,3.4442055836561902
3.8518110998614256e-07,0.0010712,166.16449751555575,413.94849221520576,3.4442055836561902
3.8892073241319254e-07,0.0010816,166.2189710634772,413.94849221520576,3.4442055836561902
3.926603548402424e-07,0.0010919999999999999,166.2732407143851,413.94849221520576,3.4442055836561902
3.94673997685577e-07,0.0010976,166.30237932648254,413.94849221520576,3.4442055836561902
4.010025894852e-07,0.0011152,166.39358262612893,413.94849221520576,3.4442055836561902
4.0675585475758443e-07,0.0011312,166.47600874522738,413.94849221520576,3.4442055836561902
4.096324873937767e-07,0.0011392,166.51705120592558,413.94849221520576,3.4442055836561902
4.153857526661612e-07,0.0011551999999999999,166.59880045515493,413.94849221520576,3.4442055836561902
4.1768705877511503e-07,0.0011616,166.6313763673201,413.94849221520576,3.4442055836561902
4.2775527300178784e-07,0.0011895999999999999,166.77308082333164,413.94849221520576,3.4442055836561902
4.323578852196955e-07,0.0012024,166.83742616023954,413.94849221520576,3.4442055836561902
4.375358239648415e-07,0.0012167999999999999,166.90949619555184,413.94849221520576,3.4442055836561902
4.389741402829377e-07,0.0012208,166.92945651967247,413.94849221520576,3.4442055836561902
4.412754463918915e-07,0.0012272,166.9613400670494,413.94849221520576,3.4442055836561902
4.473163749278952e-07,0.0012439999999999999,167.044727357128,413.94849221520576,3.4442055836561902
4.481793647187529e-07,0.0012464,167.0566038761983,413.94849221520576,3.4442055836561902
4.4875469124599135e-07,0.001248,167.06451660106092,413.94849221520576,3.4442055836561902
4.608365483179988e-07,0.0012816,167.22978081507497,413.94849221520576,3.4442055836561902
4.6169953810885647e-07,0.001284,167.2415203375343,413.94849221520576,3.4442055836561902
4.783840073987715e-07,0.0013304,167.46682910522551,413.94849221520576,3.4442055836561902
4.913288542616367e-07,0.0013664,167.63953268091487,413.94849221520576,3.4442055836561902
4.927671705797327e-07,0.0013704,167.6586117915141,413.94849221520576,3.4442055836561902
4.950684766886865e-07,0.0013767999999999999,167.6890932555764,413.94849221520576,3.4442055836561902
5.031230480700249e-07,0.0013992,167.7953459195331,413.94849221520576,3.4442055836561902
5.088763133424094e-07,0.0014152,167.8708349112202,413.94849221520576,3.4442055836561902
5.149172418784131e-07,0.001432,167.94974099366283,413.94849221520576,3.4442055836561902
5.362043233862359e-07,0.0014912,168.22495835058115,413.94849221520576,3.4442055836561902
5.419575886586204e-07,0.0015072,168.29860568153896,413.94849221520576,3.4442055836561902
5.45409547822051e-07,0.0015168,168.3426477366376,413.94849221520576,3.4442055836561902
5.459848743492894e-07,0.0015183999999999998,168.34997749715882,413.94849221520576,3.4442055836561902
5.514504763580548e-07,0.0015336,168.4194606375957,413.94849221520576,3.4442055836561902
5.549024355214855e-07,0.0015432,168.46320637535914,413.94849221520576,3.4442055836561902
5.6065570079387e-07,0.0015592,168.53588082169506,413.94849221520576,3.4442055836561902
5.635323334300622e-07,0.0015672,168.5721089349541,413.94849221520576,3.4442055836561902
5.721622313386389e-07,0.0015911999999999999,168.68036298931298,413.94849221520576,3.4442055836561902
5.79929139456358e-07,0.0016128,168.7772483813448,413.94849221520576,3.4442055836561902
5.830934353561695e-07,0.0016216,168.81657496793812,413.94849221520576,3.4442055836561902
5.902850169466501e-07,0.0016416,168.90564534153336,413.94849221520576,3.4442055836561902
5.917233332647462e-07,0.0016455999999999999,168.92340852100227,413.94849221520576,3.4442055836561902
6.012162209641807e-07,0.0016719999999999999,169.04022601547862,413.94849221520576,3.4442055836561902
6.017915474914191e-07,0.0016736,169.04728265560445,413.94849221520576,3.4442055836561902
6.158870474087612e-07,0.0017128,169.21935705000354,413.94849221520576,3.4442055836561902
6.230786289992418e-07,0.0017327999999999998,169.30655792987844,413.94849221520576,3.4442055836561902
6.256675983718148e-07,0.00174,169.33785404264495,413.94849221520576,3.4442055836561902
6.282565677443879e-07,0.0017472,169.36909969051933,413.94849221520576,3.4442055836561902
6.365988023893453e-07,0.0017703999999999999,169.46944022719143,413.94849221520576,3.4442055836561902
6.389001084982991e-07,0.0017767999999999998,169.49702996240427,413.94849221520576,3.4442055836561902
6.460916900887798e-07,0.0017967999999999999,169.58299913612151,413.94849221520576,3.4442055836561902
6.564475675790719e-07,0.0018256,169.70614199002233,413.94849221520576,3.4442055836561902
6.590365369516449e-07,0.0018327999999999999,169.7368090349347,413.94849221520576,3.4442055836561902
6.691047511783179e-07,0.0018608,169.85562578921474,413.94849221520576,3.4442055836561902
6.699677409691755e-07,0.0018632,169.86577752556195,413.94849221520576,3.4442055836561902
6.728443736053677e-07,0.0018712,169.89957987491448,413.94849221520576,3.4442055836561902
6.754333429779408e-07,0.0018784,169.92995383085145,413.94849221520576,3.4442055836561902
6.788853021413715e-07,0.001888,169.97038190189255,413.94849221520576,3.4442055836561902
6.832002510956599e-07,0.0019,170.0208044275546,413.94849221520576,3.4442055836561902
6.880905265771867e-07,0.0019136,170.07780005611184,413.94849221520576,3.4442055836561902
6.958574346949058e-07,0.0019352,170.1679988950396,413.94849221520576,3.4442055836561902
7.010353734400519e-07,0.0019496,170.22791341666533,413.94849221520576,3.4442055836561902
7.157061998846323e-07,0.0019904,170.39674111072213,413.94849221520576,3.4442055836561902
7.17719842729967e-07,0.001996,170.4198077544469,413.94849221520576,3.4442055836561902
7.220347916842553e-07,0.002008,170.46915145948165,413.94849221520576,3.4442055836561902
7.34404312019882e-07,0.0020423999999999998,170.609970029753,413.94849221520576,3.4442055836561902
7.36993281392455e-07,0.0020496,170.63932627913746,413.94849221520576,3.4442055836561902
7.401575772922664e-07,0.0020583999999999997,170.675151578396,413.94849221520576,3.4442055836561902
7.436095364556972e-07,0.002068,170.71416566763543,413.94849221520576,3.4442055836561902
7.487874752008432e-07,0.0020824,170.77255462584083,413.94849221520576,3.4442055836561902
7.577050363730393e-07,0.0021072,170.87274560045861,413.94849221520576,3.4442055836561902
7.614446588000891e-07,0.0021176,170.9146241875662,413.94849221520576,3.4442055836561902
7.634583016454238e-07,0.0021232,170.93714096842461,413.94849221520576,3.4442055836561902
7.712252097631429e-07,0.0021448,171.02377531023268,413.94849221520576,3.4442055836561902
7.758278219810505e-07,0.0021576,171.0749536219443,413.94849221520576,3.4442055836561902
7.84170056626008e-07,0.0021808,171.16741352007594,413.94849221520576,3.4442055836561902
7.881973423166771e-07,0.002192,171.21191196916982,413.94849221520576,3.4442055836561902
7.948135973799192e-07,0.0022104,171.28482454612393,413.94849221520576,3.4442055836561902
7.962519136980155e-07,0.0022144,171.3006437398999,413.94849221520576,3.4442055836561902
8.077584442427845e-07,0.0022464,171.42679856579284,413.94849221520576,3.4442055836561902
8.178266584694573e-07,0.0022743999999999998,171.53661021551318,413.94849221520576,3.4442055836561902
8.195526380511726e-07,0.0022792,171.5553820070501,413.94849221520576,3.4442055836561902
8.235799237418417e-07,0.0022903999999999997,171.59912299724317,413.94849221520576,3.4442055836561902
8.276072094325109e-07,0.0023016,171.64278064850672,413.94849221520576,3.4442055836561902
8.347987910229916e-07,0.0023216,171.72053521931775,413.94849221520576,3.4442055836561902
8.442916787224259e-07,0.002348,171.82277242007052,413.94849221520576,3.4442055836561902
8.471683113586183e-07,0.002356,171.8536647520069,413.94849221520576,3.4442055836561902
8.572365255852911e-07,0.002384,171.9614672170319,413.94849221520576,3.4442055836561902
8.589625051670065e-07,0.0023888,171.9798979479782,413.94849221520576,3.4442055836561902
8.624144643304371e-07,0.0023983999999999998,172.01671613692042,413.94849221520576,3.4442055836561902
8.675924030755833e-07,0.0024128,172.07183583850815,413.94849221520576,3.4442055836561902
8.779482805658754e-07,0.0024416,172.18169185453493,413.94849221520576,3.4442055836561902
8.805372499384483e-07,0.0024487999999999997,172.20907675182966,413.94849221520576,3.4442055836561902
8.845645356291176e-07,0.00246,172.2516131477272,413.94849221520576,3.4442055836561902
8.90317800901502e-07,0.002476,172.31224864314936,413.94849221520576,3.4442055836561902
9.026873212371287e-07,0.0025104,172.44209990668276,413.94849221520576,3.4442055836561902
9.075775967186555e-07,0.0025239999999999998,172.49324481785712,413.94849221520576,3.4442055836561902
9.164951578908516e-07,0.0025488,172.58623323266326,413.94849221520576,3.4442055836561902
9.199471170542822e-07,0.0025583999999999997,172.62213393116227,413.94849221520576,3.4442055836561902
9.280016884356205e-07,0.0025808,172.7056985344092,413.94849221520576,3.4442055836561902
9.317413108626704e-07,0.0025911999999999997,172.7444001879609,413.94849221520576,3.4442055836561902
9.37494576135055e-07,0.0026072,172.80382311193932,413.94849221520576,3.4442055836561902
9.458368107800124e-07,0.0026303999999999998,172.88973435267044,413.94849221520576,3.4442055836561902
9.50151759734301e-07,0.0026424,172.93405521351298,413.94849221520576,3.4442055836561902
9.524530658432546e-07,0.0026487999999999998,172.9576609060638,413.94849221520576,3.4442055836561902
9.610829637518314e-07,0.0026728,173.04598484225866,413.94849221520576,3.4442055836561902
9.653979127061199e-07,0.0026847999999999998,173.0900307815292,413.94849221520576,3.4442055836561902
9.671238922878352e-07,0.0026896,173.10762765122922,413.94849221520576,3.4442055836561902
9.685622086059314e-07,0.0026936,173.12228235541303,413.94849221520576,3.4442055836561902
9.826577085232735e-07,0.0027328,173.2654521346945,413.94849221520576,3.4442055836561902
9.875479840048002e-07,0.0027464,173.31493585057342,413.94849221520576,3.4442055836561902
9.944519023316617e-07,0.0027656,173.38463283013513,413.94849221520576,3.4442055836561902
1.0010681573949037e-06,0.002784,173.45124890547982,413.94849221520576,3.4442055836561902
1.002794136976619e-06,0.0027887999999999997,173.46859874501638,413.94849221520576,3.4442055836561902
1.0088350655126227e-06,0.0028055999999999997,173.52923168248725,413.94849221520576,3.4442055836561902
1.0197662695301534e-06,0.002836,173.6385897114163,413.94849221520576,3.4442055836561902
1.0223552389027264e-06,0.0028431999999999997,173.66442322096117,413.94849221520576,3.4442055836561902
1.024368881748061e-06,0.0028488,173.68449831561324,413.94849221520576,3.4442055836561902
1.029546820493207e-06,0.0028631999999999998,173.73604944546832,413.94849221520576,3.4442055836561902
1.0301221470204455e-06,0.0028648,173.74177110032164,413.94849221520576,3.4442055836561902
1.03961503471988e-06,0.0028912,173.83599921250703,413.94849221520576,3.4442055836561902
1.0488202591556952e-06,0.0029167999999999998,173.92705198932353,413.94849221520576,3.4442055836561902
1.0617651060185602e-06,0.0029527999999999998,174.05456940535373,413.94849221520576,3.4442055836561902
1.0663677182364677e-06,0.0029655999999999997,174.09976262839845,413.94849221520576,3.4442055836561902
1.0683813610818025e-06,0.0029712,174.11951073500205,413.94849221520576,3.4442055836561902
1.0747099528814254e-06,0.0029888,174.18148192174974,413.94849221520576,3.4442055836561902
1.090819095644102e-06,0.0030336,174.33858796345012,413.94849221520576,3.4442055836561902
1.0931204017530557e-06,0.0030399999999999997,174.36095759593928,413.94849221520576,3.4442055836561902
1.0954217078620095e-06,0.0030464,174.38330886930459,413.94849221520576,3.4442055836561902
1.1008873098707748e-06,0.0030616,174.43631987629988,413.94849221520576,3.4442055836561902
1.111243187361067e-06,0.0030903999999999997,174.53648114675303,413.94849221520576,3.4442055836561902
1.1169964526334516e-06,0.0031064,174.59196898065764,413.94849221520576,3.4442055836561902
1.1244756974875513e-06,0.0031271999999999997,174.66393681483387,413.94849221520576,3.4442055836561902
1.1273523301237435e-06,0.0031352,174.69156701185645,413.94849221520576,3.4442055836561902
1.1322426056052705e-06,0.0031487999999999998,174.73847532629213,413.94849221520576,3.4442055836561902
1.1351192382414627e-06,0.0031568,174.76603154300744,413.94849221520576,3.4442055836561902
1.140584840250228e-06,0.003172,174.81831343838294,413.94849221520576,3.4442055836561902
1.1538173503767123e-06,0.0032088,174.9444876693867,413.94849221520576,3.4442055836561902
1.1555433299584277e-06,0.0032136,174.96090347257945,413.94849221520576,3.4442055836561902
1.1612965952308123e-06,0.0032296,175.01555388454713,413.94849221520576,3.4442055836561902
1.1644608911306236e-06,0.0032384,175.04556659958007,413.94849221520576,3.4442055836561902
1.1733784523028196e-06,0.0032632,175.12997724088208,413.94849221520576,3.4442055836561902
1.1860356359020657e-06,0.0032984,175.24935758700684,413.94849221520576,3.4442055836561902
1.1900629215927347e-06,0.0033095999999999998,175.2872379093765,413.94849221520576,3.4442055836561902
1.1909259113835924e-06,0.003312,175.295348613219,413.94849221520576,3.4442055836561902
1.1935148807561654e-06,0.0033192,175.31966698297748,413.94849221520576,3.4442055836561902
1.1963915133923576e-06,0.0033271999999999998,175.34666327783486,413.94849221520576,3.4442055836561902
1.2004187990830269e-06,0.0033384,175.3844156000379,413.94849221520576,3.4442055836561902
1.211925329627796e-06,0.0033704,175.4920081562615,413.94849221520576,3.4442055836561902
1.2142266357367496e-06,0.0033767999999999997,175.5134787797388,413.94849221520576,3.4442055836561902
1.218541584691038e-06,0.0033888,175.55369347202313,413.94849221520576,3.4442055836561902
1.2240071866998032e-06,0.003404,175.60455244498144,413.94849221520576,3.4442055836561902
1.2291851254449493e-06,0.0034184,175.65265299157082,413.94849221520576,3.4442055836561902
1.2320617580811417e-06,0.0034264,175.67934137001473,413.94849221520576,3.4442055836561902
1.2401163294624798e-06,0.0034487999999999997,175.7539398533597,413.94849221520576,3.4442055836561902
1.2409793192533375e-06,0.0034511999999999998,175.76192132445775,413.94849221520576,3.4442055836561902
1.2498968804255335e-06,0.003476,175.84427016990765,413.94849221520576,3.4442055836561902
1.2507598702163914e-06,0.0034784,175.85222723334886,413.94849221520576,3.4442055836561902
1.254499492643441e-06,0.0034888,175.88668312894106,413.94849221520576,3.4442055836561902
1.2585267783341103e-06,0.0034999999999999996,175.92374471054453,413.94849221520576,3.4442055836561902
1.2599650946522065e-06,0.0035039999999999997,175.93696977674983,413.94849221520576,3.4442055836561902
1.2668690129790677e-06,0.0035231999999999998,176.00036831773363,413.94849221520576,3.4442055836561902
1.276074237414883e-06,0.0035488,176.08469050153025,413.94849221520576,3.4442055836561902
1.2783755435238367e-06,0.0035551999999999997,176.10573393971447,413.94849221520576,3.4442055836561902
1.2829781557417445e-06,0.003568,176.14777654657217,413.94849221520576,3.4442055836561902
1.2904574005958443e-06,0.0035887999999999996,176.2159705437306,413.94849221520576,3.4442055836561902
1.2947723495501327e-06,0.0036008,176.25524311671327,413.94849221520576,3.4442055836561902
1.2967859923954672e-06,0.0036063999999999996,176.2735528463345,413.94849221520576,3.4442055836561902
1.309155512731094e-06,0.0036408,176.38578460665218,413.94849221520576,3.4442055836561902
1.3172100841124322e-06,0.0036631999999999997,176.45864349379795,413.94849221520576,3.4442055836561902
1.3275659616027244e-06,0.003692,176.5520644017687,413.94849221520576,3.4442055836561902
1.3313055840297743e-06,0.0037024,176.5857298277851,413.94849221520576,3.4442055836561902
1.3390724921474934e-06,0.003724,176.65553271328184,413.94849221520576,3.4442055836561902
1.3517296757467393e-06,0.0037592,176.76894818631249,413.94849221520576,3.4442055836561902
1.3571952777555045e-06,0.0037744,176.8177949274457,413.94849221520576,3.4442055836561902
1.3669758287185584e-06,0.0038016,176.90501383995544,413.94849221520576,3.4442055836561902
1.3738797470454196e-06,0.0038207999999999996,176.96643366077075,413.94849221520576,3.4442055836561902
1.3750304000998964e-06,0.0038239999999999997,176.9766585836139,413.94849221520576,3.4442055836561902
1.3810713286359002e-06,0.0038407999999999997,177.03028477970653,413.94849221520576,3.4442055836561902
1.3862492673810463e-06,0.0038552,177.0761773202987,413.94849221520576,3.4442055836561902
1.3879752469627617e-06,0.0038599999999999997,177.09145997121863,413.94849221520576,3.4442055836561902
1.398618787716673e-06,0.0038896,177.18553973232915,413.94849221520576,3.4442055836561902
1.400057104034769e-06,0.0038935999999999997,177.1982317641338,413.94849221520576,3.4442055836561902
1.4210565222789725e-06,0.003952,177.38296016141206,413.94849221520576,3.4442055836561902
1.4236454916515455e-06,0.0039591999999999995,177.40566094514742,413.94849221520576,3.4442055836561902
1.4308370732420262e-06,0.0039792,177.4686343575445,413.94849221520576,3.4442055836561902
1.6869070960187213e-06,0.004691338267653531,179.63641107197435,413.94849221520576,3.4442055836561902
1.8871607782341452e-06,0.0052482496499299865,181.24319911802377,413.94849221520576,3.4442055836561902
2.2117098494108664e-06,0.006150830166033207,183.7125121083626,413.94849221520576,3.4442055836561902
2.453395327946723e-06,0.006822964592918584,185.4602981348241,413.94849221520576,3.4442055836561902
2.5915013156814976e-06,0.007207041408281656,186.42883863512407,413.94849221520576,3.4442055836561902
2.701986105869318e-06,0.007514302860572114,187.1892498380105,413.94849221520576,3.4442055836561902
2.812470896057138e-06,0.007821564312862572,187.9376268257353,413.94849221520576,3.4442055836561902
2.8539026923775704e-06,0.007936787357471494,188.21530073937794,413.94849221520576,3.4442055836561902
2.978198081338868e-06,0.00828245649129826,189.0390391851158,413.94849221520576,3.4442055836561902
3.268220655581896e-06,0.009089017803560712,190.9106199850987,413.94849221520576,3.4442055836561902
3.399421343929932e-06,0.009453890778155631,191.73587918064308,413.94849221520576,3.4442055836561902
3.489190235957536e-06,0.009703540708141629,192.2933850155964,413.94849221520576,3.4442055836561902
3.7861181095873017e-06,0.010529305861172233,194.09882297761243,413.94849221520576,3.4442055836561902
3.8620764028414285e-06,0.010740548109621925,194.5516990109118,413.94849221520576,3.4442055836561902
3.951845294869032e-06,0.01099019803960792,195.08246167199204,413.94849221520576,3.4442055836561902
4.179720174631412e-06,0.011623924784956993,196.40908491667798,413.94849221520576,3.4442055836561902
4.35235265929988e-06,0.012104020804160832,197.39539974336554,413.94849221520576,3.4442055836561902
4.511174545194871e-06,0.012545709141828365,198.28941438601987,413.94849221520576,3.4442055836561902
4.690712329250079e-06,0.01304500900180036,199.28538623461642,413.94849221520576,3.4442055836561902
4.79429182005116e-06,0.013333066613322665,199.85322111538682,413.94849221520576,3.4442055836561902
5.091219693680927e-06,0.014158831766353271,201.45508261751752,413.94849221520576,3.4442055836561902
5.250041579575918e-06,0.014600520104020805,202.29691220514366,413.94849221520576,3.4442055836561902
5.429579363631125e-06,0.0150998199639928,203.23667538355886,413.94849221520576,3.4442055836561902
5.450295261791342e-06,0.01515743148629726,203.34432409669455,413.94849221520576,3.4442055836561902
5.62983304584655e-06,0.015656731346269256,204.27068868742273,413.94849221520576,3.4442055836561902
5.671264842166982e-06,0.015771954390878175,204.48282034836404,413.94849221520576,3.4442055836561902
5.836992027448712e-06,0.016232846569313862,205.32537177684227,413.94849221520576,3.4442055836561902
5.857707925608928e-06,0.016290458091618325,205.4300307328169,413.94849221520576,3.4442055836561902
5.947476817636532e-06,0.01654010802160432,205.88189499757058,413.94849221520576,3.4442055836561902
6.161541098625434e-06,0.017135427085417085,206.9488159433437,413.94849221520576,3.4442055836561902
6.278931188199992e-06,0.017461892378475695,207.52776026634479,413.94849221520576,3.4442055836561902
6.320362984520425e-06,0.017577115423084617,207.731083689722,413.94849221520576,3.4442055836561902
6.686343852017579e-06,0.01859491898379676,209.50507889184664,413.94849221520576,3.4442055836561902
6.78992334281866e-06,0.018882976595319064,210.00022365591266,413.94849221520576,3.4442055836561902
6.8244498397523545e-06,0.018978995799159834,210.16461613159484,413.94849221520576,3.4442055836561902
6.879692234846265e-06,0.019132626525305063,210.42697102263506,413.94849221520576,3.4442055836561902
6.907313432393219e-06,0.019209441888377678,210.55784027749775,413.94849221520576,3.4442055836561902
6.997082324420822e-06,0.019459091818363673,210.98176273468124,413.94849221520576,3.4442055836561902
7.107567114608643e-06,0.01976635327065413,211.5006127783709,413.94849221520576,3.4442055836561902
7.1973360066362455e-06,0.020016003200640127,211.9198661282368,413.94849221520576,3.4442055836561902
7.432116185785364e-06,0.02066893378675735,213.00684434775815,413.94849221520576,3.4442055836561902
7.5356956765864455e-06,0.020956991398279657,213.4821272135091,413.94849221520576,3.4442055836561902
7.659991065547743e-06,0.021302660532106422,214.0491166451005,413.94849221520576,3.4442055836561902
7.853339448376428e-06,0.021840368073614724,214.92401967810005,413.94849221520576,3.4442055836561902
8.046687831205113e-06,0.022378075615123026,215.7905613002103,413.94849221520576,3.4442055836561902
8.170983220166411e-06,0.02272374474894979,216.34333842540593,413.94849221520576,3.4442055836561902
8.315994507287924e-06,0.023127025405081016,216.9841171494244,413.94849221520576,3.4442055836561902
8.4541004950227e-06,0.02351110222044409,217.5903431596027,413.94849221520576,3.4442055836561902
8.688880674171816e-06,0.024164032806561313,218.6121371979512,413.94849221520576,3.4442055836561902
8.882229057000502e-06,0.024701740348069615,219.44555325036276,413.94849221520576,3.4442055836561902
9.041050942895493e-06,0.025143428685737147,220.12486458208693,413.94849221520576,3.4442055836561902
9.11010393676288e-06,0.025335467093418683,220.41876396110314,413.94849221520576,3.4442055836561902
9.262020523271134e-06,0.025757951590318063,221.06230162400664,413.94849221520576,3.4442055836561902
9.55204309751416e-06,0.026564512902580516,222.2795554859331,413.94849221520576,3.4442055836561902
9.572758995674378e-06,0.02662212442488498,222.365946635563,413.94849221520576,3.4442055836561902
9.703959684022414e-06,0.026986997399479896,222.91140708869747,413.94849221520576,3.4442055836561902
9.862781569917405e-06,0.02742868573714743,223.56786814681143,413.94849221520576,3.4442055836561902
9.876592168690883e-06,0.02746709341868374,223.624756159637,413.94849221520576,3.4442055836561902
1.0021603455812395e-05,0.027870374074814963,224.2202191857351,413.94849221520576,3.4442055836561902
1.0097561749066524e-05,0.028081616323264655,224.530786770229,413.94849221520576,3.4442055836561902
1.0208046539254343e-05,0.028388877775555113,224.98089988366894,413.94849221520576,3.4442055836561902
1.0346152526989117e-05,0.028772954590918182,225.54087833142418,413.94849221520576,3.4442055836561902
1.0401394922083028e-05,0.02892658531706341,225.76405253272077,413.94849221520576,3.4442055836561902
1.04497320177902e-05,0.02906101220244049,225.95895103253434,413.94849221520576,3.4442055836561902
1.0546406209204542e-05,0.02932986597319464,226.34769642567073,413.94849221520576,3.4442055836561902
1.0864049980994525e-05,0.030213242648529707,227.6153282178122,413.94849221520576,3.4442055836561902
1.099525066934256e-05,0.030578115623124624,228.1346871853076,413.94849221520576,3.4442055836561902
1.1036682465662993e-05,0.030693338667733546,228.29819241052618,413.94849221520576,3.4442055836561902
1.1085019561370164e-05,0.030827765553110623,228.48864626232432,413.94849221520576,3.4442055836561902
1.1292178542972327e-05,0.03140388077615523,229.3012356665077,413.94849221520576,3.4442055836561902
1.1368136836226454e-05,0.031615123024604924,229.59772574735527,413.94849221520576,3.4442055836561902
1.1437189830093841e-05,0.03180716143228646,229.86659241631915,413.94849221520576,3.4442055836561902
1.1499337524574492e-05,0.031979995999199845,230.10803160940614,413.94849221520576,3.4442055836561902
1.1575295817828615e-05,0.03219123824764953,230.402433976716,413.94849221520576,3.4442055836561902
1.1644348811696004e-05,0.03238327665533107,230.6694193308551,413.94849221520576,3.4442055836561902
1.1727212404336867e-05,0.032613722744548906,230.9889880704793,413.94849221520576,3.4442055836561902
1.1823886595751212e-05,0.03288257651530306,231.36070736166172,413.94849221520576,3.4442055836561902
1.2003424379806417e-05,0.03338187637527505,232.04791357248075,413.94849221520576,3.4442055836561902
1.2058666774900327e-05,0.03353550710142028,232.2585536196465,413.94849221520576,3.4442055836561902
1.2334878750369877e-05,0.034303660732146427,233.30616103389937,413.94849221520576,3.4442055836561902
1.249370063626487e-05,0.03474534906981396,233.90439211732422,413.94849221520576,3.4442055836561902
1.2687049019093556e-05,0.035283056611322264,234.6286851911016,413.94849221520576,3.4442055836561902
1.2763007312347682e-05,0.035494298859771956,234.91204952483073,413.94849221520576,3.4442055836561902
1.2776817911121158e-05,0.03553270654130826,234.96349957243262,413.94849221520576,3.4442055836561902
1.2894208000695719e-05,0.035859171834366876,235.39995273730614,413.94849221520576,3.4442055836561902
1.3087556383524402e-05,0.03639687937587517,236.1154536592294,413.94849221520576,3.4442055836561902
1.3273999466966348e-05,0.03691538307661532,236.80150684412334,413.94849221520576,3.4442055836561902
1.3432821352861343e-05,0.037357071414282864,237.38296348031298,413.94849221520576,3.4442055836561902
1.3902381711159576e-05,0.038662932586517304,239.08657103222802,413.94849221520576,3.4442055836561902
1.4026677100120873e-05,0.039008601720344066,239.53375074019178,413.94849221520576,3.4442055836561902
1.4075014195828046e-05,0.03914302860572115,239.70723627137804,413.94849221520576,3.4442055836561902
1.4302889075590423e-05,0.03977675535107021,240.5219872943796,413.94849221520576,3.4442055836561902
1.4371942069457808e-05,0.039968793758751744,240.7678800033236,413.94849221520576,3.4442055836561902
1.4434089763938459e-05,0.04014162832566513,240.98878976893474,413.94849221520576,3.4442055836561902
1.4503142757805846e-05,0.040333666733346665,241.23381045902875,413.94849221520576,3.4442055836561902
1.4620532847380406e-05,0.04066013202640528,241.64930403137555,413.94849221520576,3.4442055836561902
1.476554413450192e-05,0.04106341268253651,242.16076887192017,413.94849221520576,3.4442055836561902
1.481388123020909e-05,0.04119783956791358,242.3308213292122,413.94849221520576,3.4442055836561902
1.5007229613037777e-05,0.041735547109421886,243.0088782532384,413.94849221520576,3.4442055836561902
1.52074832952532e-05,0.04229245849169834,243.70756946450018,413.94849221520576,3.4442055836561902
1.543535817501558e-05,0.042926185237047415,244.49828186432376,413.94849221520576,3.4442055836561902
1.5504411168882967e-05,0.04311822364472895,244.7369911429879,413.94849221520576,3.4442055836561902
1.5911823832700555e-05,0.044251250250050014,246.13702732803526,413.94849221520576,3.4442055836561902
1.5960160928407725e-05,0.044385677135427085,246.30220043597345,413.94849221520576,3.4442055836561902
1.6167319910009886e-05,0.0449617923584717,247.00788683395413,413.94849221520576,3.4442055836561902
1.619494110755684e-05,0.045038607721544305,247.10171119788723,413.94849221520576,3.4442055836561902
1.6312331197131402e-05,0.04536507301460292,247.49977051132706,413.94849221520576,3.4442055836561902
1.6402100089159003e-05,0.04561472294458892,247.80341545563186,413.94849221520576,3.4442055836561902
1.6844039249910285e-05,0.04684376875375075,249.2889357689503,413.94849221520576,3.4442055836561902
1.696833463887158e-05,0.04718943788757751,249.70398946905675,413.94849221520576,3.4442055836561902
1.7147872422926792e-05,0.04768873774754952,250.30142425823408,413.94849221520576,3.4442055836561902
1.719620951863396e-05,0.04782316463292659,250.46185464671098,413.94849221520576,3.4442055836561902
1.7465516194716772e-05,0.048572114422884574,251.35248228461015,413.94849221520576,3.4442055836561902
1.7506947991037204e-05,0.0486873374674935,251.48902509488295,413.94849221520576,3.4442055836561902
1.7569095685517856e-05,0.04886017203440689,251.69360325135415,413.94849221520576,3.4442055836561902
1.7748633469573062e-05,0.04935947189437888,252.28302742588446,413.94849221520576,3.4442055836561902
1.7776254667120014e-05,0.049436287257451486,252.37350126463278,413.94849221520576,3.4442055836561902
1.8017940145655872e-05,0.050108421684336865,253.1628223115131,413.94849221520576,3.4442055836561902
1.8114614337070215e-05,0.05037727545509102,253.4773932512103,413.94849221520576,3.4442055836561902
1.825272032480499e-05,0.050761352270454085,253.92564691709805,413.94849221520576,3.4442055836561902
1.8397731611926508e-05,0.051164632926585324,254.39489200119783,413.94849221520576,3.4442055836561902
1.842535280947346e-05,0.05124144828965793,254.48410824047755,413.94849221520576,3.4442055836561902
1.8577269395981714e-05,0.051663932786557315,254.9738683727279,413.94849221520576,3.4442055836561902
1.8853481371451262e-05,0.05243208641728346,255.86035820986967,413.94849221520576,3.4442055836561902
1.8991587359186036e-05,0.052816163232646526,256.3017026448227,413.94849221520576,3.4442055836561902
1.908826155060038e-05,0.05308501700340068,256.60989929715777,413.94849221520576,3.4442055836561902
1.9178030442627984e-05,0.053334666933386676,256.8955372702028,413.94849221520576,3.4442055836561902
1.920565164017494e-05,0.0534114822964593,256.9833209106765,413.94849221520576,3.4442055836561902
1.94128106217771e-05,0.053987597519503897,257.6401359763424,413.94849221520576,3.4442055836561902
1.9509484813191443e-05,0.05425645129025805,257.94571366892654,413.94849221520576,3.4442055836561902
1.9571632507672092e-05,0.05442928585717144,258.1418446734548,413.94849221520576,3.4442055836561902
1.9661401399699697e-05,0.054678935787157434,258.42471675232514,413.94849221520576,3.4442055836561902
1.981331798620795e-05,0.05510142028405682,258.9022785681654,413.94849221520576,3.4442055836561902
1.9903086878235555e-05,0.05535107021404281,259.18380296930815,413.94849221520576,3.4442055836561902
2.0124056458611196e-05,0.05596559311862373,259.87468459804404,413.94849221520576,3.4442055836561902
2.0151677656158148e-05,0.05604240848169634,259.96083629202735,413.94849221520576,3.4442055836561902
2.0275973045119443e-05,0.0563880776155231,260.3479504205868,413.94849221520576,3.4442055836561902
2.0372647236533785e-05,0.056656931386277254,260.6483996918716,413.94849221520576,3.4442055836561902
2.0434794931014438e-05,0.05682976595319064,260.841252073965,413.94849221520576,3.4442055836561902
2.0538374421815518e-05,0.05711782356471294,261.1621651732536,413.94849221520576,3.4442055836561902
2.0607427415682902e-05,0.057309861972394474,261.37575664915505,413.94849221520576,3.4442055836561902
2.0807681097898332e-05,0.05786677335467094,261.99359910034815,413.94849221520576,3.4442055836561902
2.101484007950049e-05,0.05844288857771554,262.6303110469388,413.94849221520576,3.4442055836561902
2.10700824745944e-05,0.05859651930386077,262.79968689001157,413.94849221520576,3.4442055836561902
2.118747256416896e-05,0.05892298459691939,263.1590365882235,413.94849221520576,3.4442055836561902
2.1339389150677215e-05,0.05934546909381877,263.62292683735353,413.94849221520576,3.4442055836561902
2.1546548132279373e-05,0.05992158431686337,264.25343413829563,413.94849221520576,3.4442055836561902
2.1850381305295883e-05,0.060766553310662136,265.1739183674957,413.94849221520576,3.4442055836561902
2.207135088567152e-05,0.06138107621524305,265.8402290026408,413.94849221520576,3.4442055836561902
2.236827875930129e-05,0.06220684136827366,266.7315014935356,413.94849221520576,3.4442055836561902
2.2485668848875843e-05,0.06253330666133226,267.08259087224474,413.94849221520576,3.4442055836561902
2.2603058938450407e-05,0.06285977195439088,267.43296613583556,413.94849221520576,3.4442055836561902
2.284474441698626e-05,0.06353190638127626,268.1521002430944,413.94849221520576,3.4442055836561902
2.296213450656082e-05,0.06385837167433486,268.5003228546628,413.94849221520576,3.4442055836561902
2.316238818877624e-05,0.06441528305661132,269.0927515215101,413.94849221520576,3.4442055836561902
2.3500747858726442e-05,0.06535627125425085,270.0892326451521,413.94849221520576,3.4442055836561902
2.356980085259383e-05,0.06554830966193238,270.2919069236267,413.94849221520576,3.4442055836561902
2.3604327349527523e-05,0.06564432886577315,270.39315721319423,413.94849221520576,3.4442055836561902
2.3811486331129684e-05,0.06622044408881776,270.99945043874584,413.94849221520576,3.4442055836561902
2.388053932499707e-05,0.0664124824964993,271.20109058107676,413.94849221520576,3.4442055836561902
2.3949592318864462e-05,0.06660452090418084,271.40250345668574,413.94849221520576,3.4442055836561902
2.4011740013345114e-05,0.06677735547109423,271.58358148419217,413.94849221520576,3.4442055836561902
2.4094603605985978e-05,0.06700780156031207,271.82473478417864,413.94849221520576,3.4442055836561902
2.4287951988814663e-05,0.06754550910182038,272.3861714700129,413.94849221520576,3.4442055836561902
2.441224737777596e-05,0.06789117823564714,272.74617481444807,413.94849221520576,3.4442055836561902
2.4536542766737256e-05,0.0682368473694739,273.1054640087493,413.94849221520576,3.4442055836561902
2.4667743455085295e-05,0.06860172034406882,273.48394449917026,413.94849221520576,3.4442055836561902
2.4812754742206808e-05,0.06900500100020004,273.9013528272856,413.94849221520576,3.4442055836561902
2.50613455201294e-05,0.06969633926785357,274.6147033103693,413.94849221520576,3.4442055836561902
2.5316841597438738e-05,0.07040688137627527,275.3449992862037,413.94849221520576,3.4442055836561902
2.5441136986400036e-05,0.07075255051010203,275.69923865002727,413.94849221520576,3.4442055836561902
2.5544716477201114e-05,0.07104060812162433,275.99392281776954,413.94849221520576,3.4442055836561902
2.558614827352155e-05,0.07115583116623325,276.111665958272,413.94849221520576,3.4442055836561902
2.5620674770455242e-05,0.07125185037007402,276.20972845140204,413.94849221520576,3.4442055836561902
2.585545494960436e-05,0.07190478095619124,276.87519189102767,413.94849221520576,3.4442055836561902
2.611785632630043e-05,0.07263452690538108,277.61616254609515,413.94849221520576,3.4442055836561902
2.6587416684598665e-05,0.07394038807761552,278.93490413897644,413.94849221520576,3.4442055836561902
2.678767036681409e-05,0.07449729945989199,279.49454222238364,413.94849221520576,3.4442055836561902
2.695339755209582e-05,0.07495819163832768,279.9564581352377,413.94849221520576,3.4442055836561902
2.7312473120206236e-05,0.07595679135827166,280.9534930849754,413.94849221520576,3.4442055836561902
2.7374620814686885e-05,0.07612962592518505,281.12553657076484,413.94849221520576,3.4442055836561902
2.7526537401195135e-05,0.07655211042208442,281.5454472855874,413.94849221520576,3.4442055836561902
2.756796919751557e-05,0.07666733346669334,281.65981140735465,413.94849221520576,3.4442055836561902
2.760249569444926e-05,0.07676335267053411,281.75506364606116,413.94849221520576,3.4442055836561902
2.7706075185250348e-05,0.07705141028205642,282.04054195087934,413.94849221520576,3.4442055836561902
2.7775128179117732e-05,0.07724344868973795,282.2306296148488,413.94849221520576,3.4442055836561902
2.7809654676051425e-05,0.07733946789357872,282.3256043248594,413.94849221520576,3.4442055836561902
2.812039314845467e-05,0.07820364072814563,283.17831728460186,413.94849221520576,3.4442055836561902
2.8223972639255748e-05,0.07849169833966793,283.4617372636615,413.94849221520576,3.4442055836561902
2.82861203337364e-05,0.07866453290658132,283.63159454603567,413.94849221520576,3.4442055836561902
2.8382794525150743e-05,0.07893338667733547,283.8955279768942,413.94849221520576,3.4442055836561902
2.8534711111658997e-05,0.07935587117423486,284.3095732569141,413.94849221520576,3.4442055836561902
2.872115419510094e-05,0.079874374874975,284.8165466297268,413.94849221520576,3.4442055836561902
2.878330188958159e-05,0.08004720944188838,284.9852523208045,413.94849221520576,3.4442055836561902
2.8852354883448977e-05,0.08023924784956991,285.1725365608894,413.94849221520576,3.4442055836561902
2.9045703266277665e-05,0.08077695539107822,285.6960047230453,413.94849221520576,3.4442055836561902
2.9128566858918525e-05,0.08100740148029606,285.91993201125035,413.94849221520576,3.4442055836561902
2.919761985278592e-05,0.0811994398879776,286.1063483698164,413.94849221520576,3.4442055836561902
2.9687896109244367e-05,0.08256291258251651,287.4249952837631,413.94849221520576,3.4442055836561902
2.977075970188523e-05,0.08279335867173435,287.6470235160964,413.94849221520576,3.4442055836561902
2.9805286198818923e-05,0.08288937787557511,287.73946413128505,413.94849221520576,3.4442055836561902
2.9853623294526096e-05,0.0830238047609522,287.8688108623949,413.94849221520576,3.4442055836561902
2.9908865689620007e-05,0.08317743548709743,288.0165357266448,413.94849221520576,3.4442055836561902
3.005387697674152e-05,0.08358071614322865,288.40380809052294,413.94849221520576,3.4442055836561902
3.023341476079673e-05,0.08408001600320064,288.88227995685855,413.94849221520576,3.4442055836561902
3.0309373054050854e-05,0.08429125825165033,289.0843766316988,413.94849221520576,3.4442055836561902
3.044057374239889e-05,0.08465613122624525,289.4329880800328,413.94849221520576,3.4442055836561902
3.09239446994706e-05,0.08600040008001601,290.712320715562,413.94849221520576,3.4442055836561902
3.102752419027169e-05,0.08628845769153831,290.9854460615835,413.94849221520576,3.4442055836561902
3.1186346076166675e-05,0.08673014602920584,291.40354863358823,413.94849221520576,3.4442055836561902
3.12623043694208e-05,0.08694138827765553,291.6032171144701,413.94849221520576,3.4442055836561902
3.137278915960862e-05,0.08724864972994599,291.89330657666176,413.94849221520576,3.4442055836561902
3.1669717033238385e-05,0.0880744148829766,292.6709545343607,413.94849221520576,3.4442055836561902
3.171114882955882e-05,0.08818963792758552,292.7792370519397,413.94849221520576,3.4442055836561902
3.178020182342621e-05,0.08838167633526706,292.9595853833808,413.94849221520576,3.4442055836561902
3.1987360805028375e-05,0.08895779155831167,293.49971563632437,413.94849221520576,3.4442055836561902
3.210475089460293e-05,0.08928425685137027,293.8051838529241,413.94849221520576,3.4442055836561902
3.212546679276314e-05,0.08934186837367473,293.8590447593781,413.94849221520576,3.4442055836561902
3.2263572780497924e-05,0.08972594518903781,294.2177719362464,413.94849221520576,3.4442055836561902
3.228428867865814e-05,0.08978355671134228,294.2715293166012,413.94849221520576,3.4442055836561902
3.24016787682327e-05,0.09011002200440088,294.5759007455258,413.94849221520576,3.4442055836561902
3.248454236087356e-05,0.09034046809361873,294.7904922896937,413.94849221520576,3.4442055836561902
3.253978475596747e-05,0.09049409881976396,294.9334347293878,413.94849221520576,3.4442055836561902
3.260883774983486e-05,0.09068613722744549,295.1119797588849,413.94849221520576,3.4442055836561902
3.275384903695637e-05,0.09108941788357672,295.4864450688809,413.94849221520576,3.4442055836561902
3.284361792898397e-05,0.09133906781356271,295.71793293502725,413.94849221520576,3.4442055836561902
3.2947197419785063e-05,0.09162712542508503,295.98472792166984,413.94849221520576,3.4442055836561902
3.299553451549223e-05,0.0917615523104621,296.10912028503486,413.94849221520576,3.4442055836561902
3.310601930568005e-05,0.09206881376275255,296.39317912198766,413.94849221520576,3.4442055836561902
3.314054580261374e-05,0.09216483296659332,296.48187165648926,413.94849221520576,3.4442055836561902
3.3188882898320915e-05,0.0922992598519704,296.6059806871643,413.94849221520576,3.4442055836561902
3.36860644541661e-05,0.09368193638727745,297.87846571610413,413.94849221520576,3.4442055836561902
3.3789643944967185e-05,0.09396999399879977,298.142642475147,413.94849221520576,3.4442055836561902
3.3810359843127406e-05,0.09402760552110423,298.1954399072585,413.94849221520576,3.4442055836561902
3.410038241737043e-05,0.09483416683336668,298.9332842688013,413.94849221520576,3.4442055836561902
3.4231583105718466e-05,0.0951990398079616,299.2662665946155,413.94849221520576,3.4442055836561902
3.4418026189160413e-05,0.09571754350870175,299.7385970716637,413.94849221520576,3.4442055836561902
3.4625185170762575e-05,0.09629365873174635,300.2622399331715,413.94849221520576,3.4442055836561902
3.475638585911061e-05,0.09665853170634127,300.5932485455853,413.94849221520576,3.4442055836561902
3.488758654745865e-05,0.09702340468093619,300.92377020506,413.94849221520576,3.4442055836561902
3.492901834377908e-05,0.09713862772554512,301.02804470699266,413.94849221520576,3.4442055836561902
3.501878723580668e-05,0.09738827765553111,301.25380745520584,413.94849221520576,3.4442055836561902
3.514308262476798e-05,0.09773394678935787,301.56602977115205,413.94849221520576,3.4442055836561902
3.535024160637014e-05,0.09831006201240249,302.0854449538353,413.94849221520576,3.4442055836561902
3.554358998919883e-05,0.09884776955391078,302.56916244412537,413.94849221520576,3.4442055836561902
3.557121118674579e-05,0.0989245849169834,302.6381810782094,413.94849221520576,3.4442055836561902
3.5730033072640775e-05,0.09936627325465093,303.0346333595174,413.94849221520576,3.4442055836561902
3.5757654270187734e-05,0.09944308861772355,303.1035113667241,413.94849221520576,3.4442055836561902
3.586123376098881e-05,0.09973114622924585,303.3616192981852,413.94849221520576,3.4442055836561902
3.59302867548562e-05,0.09992318463692738,303.53352974539854,413.94849221520576,3.4442055836561902
3.5937192054242936e-05,0.09994238847769554,303.5507137002732,413.94849221520576,3.4442055836561902