File: datasets/aisi_316_L/data/M1/valid_5.csv
Time(s),Strain(%),Stress(MPa),Temp(C),Log_SR(s-1)
0.0,0.0,0.0,427.5587761723612,-3.3021402149579147
0.014436858883785288,7.2e-06,1.2020626125,427.5587761723612,-3.3021402149579147
0.05133105380901436,2.56e-05,4.274000399999999,427.5587761723612,-3.3021402149579147
0.06897610355586305,3.4399999999999996e-05,5.7431880374999995,427.5587761723612,-3.3021402149579147
0.07699658071352154,3.84e-05,6.4110005999999995,427.5587761723612,-3.3021402149579147
0.09784982132343363,4.88e-05,8.1473132625,427.5587761723612,-3.3021402149579147
0.1299317299540676,6.48e-05,10.8185635125,427.5587761723612,-3.3021402149579147
0.18447097462614537,9.2e-05,15.3596889375,427.5587761723612,-3.3021402149579147
0.21174059696218422,0.00010559999999999999,17.630251649999998,427.5587761723612,-3.3021402149579147
0.2358020284351597,0.0001176,19.633689337499998,427.5587761723612,-3.3021402149579147
0.2454266010243499,0.0001224,20.435064412499997,427.5587761723612,-3.3021402149579147
0.29034127310723745,0.0001448,24.1748147625,427.5587761723612,-3.3021402149579147
0.31279860914868124,0.000156,26.0446899375,427.5587761723612,-3.3021402149579147
0.367337853820759,0.00018319999999999998,30.585815362499996,427.5587761723612,-3.3021402149579147
0.39460747615679787,0.00019679999999999999,32.856378074999995,427.5587761723612,-3.3021402149579147
0.4282934802189636,0.0002136,35.6611908375,427.5587761723612,-3.3021402149579147
0.43791805280815377,0.0002184,36.4625659125,427.5587761723612,-3.3021402149579147
0.4475426253973439,0.00022319999999999998,37.26394098749999,427.5587761723612,-3.3021402149579147
0.47641634316491455,0.0002376,39.6680662125,427.5587761723612,-3.3021402149579147
0.6111603594135773,0.0003048,50.8873172625,427.5587761723612,-3.3021402149579147
0.6288054091604259,0.0003136,52.3565049,427.5587761723612,-3.3021402149579147
0.6640955086541233,0.0003312,55.294880174999996,427.5587761723612,-3.3021402149579147
0.6801364629694403,0.0003392,56.6305053,427.5587761723612,-3.3021402149579147
0.7090101807370108,0.0003536,59.034630525,427.5587761723612,-3.3021402149579147
0.734675707641518,0.00036639999999999996,61.17163072499999,427.5587761723612,-3.3021402149579147
0.7507166619568351,0.0003744,62.50725585,427.5587761723612,-3.3021402149579147
0.7683617117036837,0.0003832,63.9764434875,427.5587761723612,-3.3021402149579147
0.8325255289649516,0.00041519999999999995,69.31894398749999,427.5587761723612,-3.3021402149579147
0.8533787695748638,0.0004256,71.05525665,427.5587761723612,-3.3021402149579147
0.8774402010478392,0.00043759999999999996,73.05869433749999,427.5587761723612,-3.3021402149579147
0.8886688690685611,0.0004432,73.993631925,427.5587761723612,-3.3021402149579147
0.9255630639937902,0.0004616,77.0655697125,427.5587761723612,-3.3021402149579147
0.9849145949604631,0.0004912,82.007382675,427.5587761723612,-3.3021402149579147
1.0137883127280336,0.0005055999999999999,84.41150789999999,427.5587761723612,-3.3021402149579147
1.0795562254208333,0.0005384,89.8875709125,427.5587761723612,-3.3021402149579147
1.1100340386199357,0.0005536,92.42525865,427.5587761723612,-3.3021402149579147
1.1340954700929111,0.0005656,94.4286963375,427.5587761723612,-3.3021402149579147
1.138907756387506,0.0005679999999999999,94.82938387499999,427.5587761723612,-3.3021402149579147
1.1806142376073303,0.0005888,98.3020092,427.5587761723612,-3.3021402149579147
1.1998633827857108,0.0005984,99.90475935,427.5587761723612,-3.3021402149579147
1.2239248142586863,0.0006104,101.9081970375,427.5587761723612,-3.3021402149579147
1.2560067228893201,0.0006263999999999999,104.57944728749999,427.5587761723612,-3.3021402149579147
1.2929009178145492,0.0006448,107.651385075,427.5587761723612,-3.3021402149579147
1.320170540150588,0.0006584,109.92194778749999,427.5587761723612,-3.3021402149579147
1.3731056893911342,0.0006848,114.32951069999999,427.5587761723612,-3.3021402149579147
1.4180203614740217,0.0007072,118.06926105,427.5587761723612,-3.3021402149579147
1.448498174673124,0.0007224,120.6069487875,427.5587761723612,-3.3021402149579147
1.4613309381253774,0.0007287999999999999,121.67544888749998,427.5587761723612,-3.3021402149579147
1.4821841787352896,0.0007392,123.41176155,427.5587761723612,-3.3021402149579147
1.5158701827974552,0.0007559999999999999,126.21657431249999,427.5587761723612,-3.3021402149579147
1.5270988508181773,0.0007616,127.15151189999999,427.5587761723612,-3.3021402149579147
1.539931614270431,0.000768,128.220012,427.5587761723612,-3.3021402149579147
1.5447439005650259,0.0007704,128.6206995375,427.5587761723612,-3.3021402149579147
1.5575766640172797,0.0007768,129.6891996375,427.5587761723612,-3.3021402149579147
1.5688053320380013,0.0007823999999999999,130.624137225,427.5587761723612,-3.3021402149579147
1.6040954315316986,0.0007999999999999999,133.5625125,427.5587761723612,-3.3021402149579147
1.6441978173199912,0.00082,136.9015753125,427.5587761723612,-3.3021402149579147
1.6586346762037765,0.0008271999999999999,138.103637925,427.5587761723612,-3.3021402149579147
1.714778016307386,0.0008552,138.49074319452413,427.5587761723612,-3.3021402149579147
1.7260066843281079,0.0008608,138.51764209923002,427.5587761723612,-3.3021402149579147
1.7693172609794638,0.0008824,138.62076194466036,427.5587761723612,-3.3021402149579147
1.7885664061578441,0.000892,138.66627648671383,427.5587761723612,-3.3021402149579147
1.8302728873776684,0.0009128,138.76424107032094,427.5587761723612,-3.3021402149579147
1.8559384142821753,0.0009256,138.82409437849904,427.5587761723612,-3.3021402149579147
1.8816039411866825,0.0009383999999999999,138.88362573900935,427.5587761723612,-3.3021402149579147
1.9361431858587603,0.0009655999999999999,139.00908845832993,427.5587761723612,-3.3021402149579147
1.9489759493110141,0.000972,139.03840787227247,427.5587761723612,-3.3021402149579147
1.9698291899209261,0.0009824,139.08589185030596,427.5587761723612,-3.3021402149579147
1.9826619533731797,0.0009888,139.11501533313938,427.5587761723612,-3.3021402149579147
2.019556148298409,0.0010072,139.1983386290082,427.5587761723612,-3.3021402149579147
2.0532421523605744,0.001024,139.27389938768113,427.5587761723612,-3.3021402149579147
2.0997609198749934,0.0010471999999999999,139.37745513466342,427.5587761723612,-3.3021402149579147
2.1222182559164375,0.0010584,139.42712699604485,427.5587761723612,-3.3021402149579147
2.1366551148002224,0.0010655999999999999,139.45895068928812,427.5587761723612,-3.3021402149579147
2.1591124508416666,0.0010768,139.50828803358613,427.5587761723612,-3.3021402149579147
2.1767575005885154,0.0010856,139.5469128262608,427.5587761723612,-3.3021402149579147
2.187986168609237,0.0010911999999999999,139.5714286760946,427.5587761723612,-3.3021402149579147
2.2505458904389735,0.0011224,139.70712922824464,427.5587761723612,-3.3021402149579147
2.261774558459695,0.0011279999999999999,139.7313292006942,427.5587761723612,-3.3021402149579147
2.2874400853642025,0.0011408,139.78646816284578,427.5587761723612,-3.3021402149579147
2.3082933259741147,0.0011512,139.8310911192336,427.5587761723612,-3.3021402149579147
2.3243342802894316,0.0011592,139.86530957061794,427.5587761723612,-3.3021402149579147
2.3516039026254703,0.0011727999999999999,139.9232703213501,427.5587761723612,-3.3021402149579147
2.369248952372319,0.0011815999999999999,139.96063470435868,427.5587761723612,-3.3021402149579147
2.3772694295299774,0.0011856,139.97758262274914,427.5587761723612,-3.3021402149579147
2.3836858112561043,0.0011887999999999998,139.99112490705258,427.5587761723612,-3.3021402149579147
2.406143147297548,0.0012,140.0384113514096,427.5587761723612,-3.3021402149579147
2.428600483338992,0.0012112,140.08552598301708,427.5587761723612,-3.3021402149579147
2.449453723948904,0.0012216,140.1291233689068,427.5587761723612,-3.3021402149579147
2.479931537148006,0.0012368,140.19258313786335,427.5587761723612,-3.3021402149579147
2.540887163546211,0.0012672,140.31859744993253,427.5587761723612,-3.3021402149579147
2.6371328894381127,0.0013151999999999999,140.5151929249283,427.5587761723612,-3.3021402149579147
2.6595902254795565,0.0013264,140.56066015197464,427.5587761723612,-3.3021402149579147
2.701296706699381,0.0013472,140.64470401248298,427.5587761723612,-3.3021402149579147
2.762252333097585,0.0013775999999999999,140.76663268741305,427.5587761723612,-3.3021402149579147
2.895392253914716,0.001444,141.029359551102,427.5587761723612,-3.3021402149579147
2.914641399093097,0.0014536,141.06695061064534,427.5587761723612,-3.3021402149579147
2.929078257976882,0.0014608,141.09508039845946,427.5587761723612,-3.3021402149579147
2.965972452902111,0.0014792,141.16672307344953,427.5587761723612,-3.3021402149579147
2.99324207523815,0.0014927999999999999,141.21945317261742,427.5587761723612,-3.3021402149579147
3.018907602142657,0.0015056,141.26891061398246,427.5587761723612,-3.3021402149579147
3.049385415341759,0.0015207999999999999,141.3274288467059,427.5587761723612,-3.3021402149579147
3.0750509422462664,0.0015336,141.37653065037705,427.5587761723612,-3.3021402149579147
3.0814673239723933,0.0015367999999999998,141.38878109579383,427.5587761723612,-3.3021402149579147
3.094300087424647,0.0015432,141.41325218251072,427.5587761723612,-3.3021402149579147
3.1231738051922173,0.0015576,141.46816787516946,427.5587761723612,-3.3021402149579147
3.2081908630633973,0.0015999999999999999,141.6287257273763,427.5587761723612,-3.3021402149579147
3.2113990539264607,0.0016016,141.63475180507,427.5587761723612,-3.3021402149579147
3.222627721947183,0.0016072,141.65582461284004,427.5587761723612,-3.3021402149579147
3.240272771694032,0.001616,141.68888126192073,427.5587761723612,-3.3021402149579147
3.2835833483453873,0.0016376,141.76972406257178,427.5587761723612,-3.3021402149579147
3.3188734478390844,0.0016552,141.83528893087052,427.5587761723612,-3.3021402149579147
3.3573717381958454,0.0016744,141.90650492169854,427.5587761723612,-3.3021402149579147
3.4151191737309867,0.0017032,142.01273463968022,427.5587761723612,-3.3021402149579147
3.4327642234778355,0.001712,142.0450536854358,427.5587761723612,-3.3021402149579147
3.43757650977243,0.0017143999999999998,142.05385671801344,427.5587761723612,-3.3021402149579147
3.4536174640877477,0.0017224,142.08316551079457,427.5587761723612,-3.3021402149579147
3.4728666092661276,0.0017319999999999998,142.11826607556787,427.5587761723612,-3.3021402149579147
3.5225935676436104,0.0017568,142.20859313806974,427.5587761723612,-3.3021402149579147
3.5274058539382054,0.0017591999999999998,142.21730799163578,427.5587761723612,-3.3021402149579147
3.5835491940418147,0.0017871999999999999,142.3186410520682,427.5587761723612,-3.3021402149579147
3.6300679615562346,0.0018104,142.40213451762688,427.5587761723612,-3.3021402149579147
3.671774442776058,0.0018311999999999998,142.47663662088146,427.5587761723612,-3.3021402149579147
3.700648160543629,0.0018456,142.52802177734682,427.5587761723612,-3.3021402149579147
3.7359382600373263,0.0018632,142.5906140055168,427.5587761723612,-3.3021402149579147
3.7680201686679604,0.0018792,142.64731621892346,427.5587761723612,-3.3021402149579147
3.925221520958067,0.0019576,142.92248069642974,427.5587761723612,-3.3021402149579147
3.931637902684194,0.0019608,142.93361967778725,427.5587761723612,-3.3021402149579147
3.9813648610616768,0.0019856,143.0197076924809,427.5587761723612,-3.3021402149579147
4.0054262925346515,0.0019976,143.06121255408354,427.5587761723612,-3.3021402149579147
4.047132773754476,0.0020184,143.1329247027142,427.5587761723612,-3.3021402149579147
4.063173728069793,0.0020264,143.16042948313228,427.5587761723612,-3.3021402149579147
4.087235159542769,0.0020384,143.20160738356182,427.5587761723612,-3.3021402149579147
4.11610887731034,0.0020528,143.25089627983328,427.5587761723612,-3.3021402149579147
4.1321498316256555,0.0020608,143.27822072953745,427.5587761723612,-3.3021402149579147
4.201125935181519,0.0020951999999999998,143.3952475923349,427.5587761723612,-3.3021402149579147
4.246040607264407,0.0021176,143.47104849745156,427.5587761723612,-3.3021402149579147
4.260477466148192,0.0021248,143.4953465782558,427.5587761723612,-3.3021402149579147
4.287747088484231,0.0021384,143.54115552156952,427.5587761723612,-3.3021402149579147
4.306996233662611,0.0021479999999999997,143.57342286194918,427.5587761723612,-3.3021402149579147
4.353515001177031,0.0021712,143.65117094974227,427.5587761723612,-3.3021402149579147
4.3663477646292845,0.0021776,143.6725615943054,427.5587761723612,-3.3021402149579147
4.388805100670727,0.0021888,143.7099363188658,427.5587761723612,-3.3021402149579147
4.403241959554514,0.002196,143.73392354760549,427.5587761723612,-3.3021402149579147
4.424095200164425,0.0022064,143.7685176881436,427.5587761723612,-3.3021402149579147
4.470613967678845,0.0022296,143.84546088926305,427.5587761723612,-3.3021402149579147
4.483446731131098,0.0022359999999999997,143.86663156972227,427.5587761723612,-3.3021402149579147
4.49467539915182,0.0022416,143.88513653675864,427.5587761723612,-3.3021402149579147
4.512320448898669,0.0022504,143.91417938551564,427.5587761723612,-3.3021402149579147
4.565255598139214,0.0022768,144.0010433361887,427.5587761723612,-3.3021402149579147
4.5893170296121895,0.0022887999999999997,144.04039700658862,427.5587761723612,-3.3021402149579147
4.618190747379761,0.0023032,144.08751535259705,427.5587761723612,-3.3021402149579147
4.683958660072561,0.002336,144.19441367504376,427.5587761723612,-3.3021402149579147
4.712832377840131,0.0023504,144.24115956220746,427.5587761723612,-3.3021402149579147
4.719248759566258,0.0023536,144.25153235342202,427.5587761723612,-3.3021402149579147
4.741706095607701,0.0023648,144.28779388815855,427.5587761723612,-3.3021402149579147
4.797849435711311,0.0023928,144.3781559208011,427.5587761723612,-3.3021402149579147
4.809078103732032,0.0023983999999999998,144.39617873874047,427.5587761723612,-3.3021402149579147
4.905323829623935,0.0024464,144.54999257298599,427.5587761723612,-3.3021402149579147
4.945426215412228,0.0024664,144.61373376708707,427.5587761723612,-3.3021402149579147
4.982320410337456,0.0024847999999999997,144.67219785433554,427.5587761723612,-3.3021402149579147
5.020818700694217,0.0025039999999999997,144.73302412995,427.5587761723612,-3.3021402149579147
5.1106480448599925,0.0025488,144.87424909259028,427.5587761723612,-3.3021402149579147
5.125084903743777,0.0025559999999999997,144.89685535482784,427.5587761723612,-3.3021402149579147
5.158770907805944,0.0025728,144.9495069395065,427.5587761723612,-3.3021402149579147
5.205289675320362,0.002596,145.02199636762145,427.5587761723612,-3.3021402149579147
5.2373715839509964,0.0026119999999999997,145.07184193738297,427.5587761723612,-3.3021402149579147
5.245392061108655,0.002616,145.08428470615507,427.5587761723612,-3.3021402149579147
5.251808442834782,0.0026192,145.0942335796069,427.5587761723612,-3.3021402149579147
5.263037110855504,0.0026248,145.11163270898206,427.5587761723612,-3.3021402149579147
5.26945349258163,0.0026279999999999997,145.12156856861426,427.5587761723612,-3.3021402149579147
5.288702637760011,0.0026376,145.15134787569616,427.5587761723612,-3.3021402149579147
5.412217985987951,0.0026991999999999997,145.34143568708987,427.5587761723612,-3.3021402149579147
5.425050749440205,0.0027056,145.36108755634862,427.5587761723612,-3.3021402149579147
5.473173612386156,0.0027296,145.4346211587159,427.5587761723612,-3.3021402149579147
5.497235043859131,0.0027416,145.47129337155008,427.5587761723612,-3.3021402149579147
5.538941525078956,0.0027624,145.5347105917644,427.5587761723612,-3.3021402149579147
5.553378383962741,0.0027695999999999997,145.55661928165276,427.5587761723612,-3.3021402149579147
5.559794765688868,0.0027727999999999997,145.56634934607467,427.5587761723612,-3.3021402149579147
5.5646070519834625,0.0027752,145.57364402069075,427.5587761723612,-3.3021402149579147
5.583856197161843,0.0027848,145.60279814984153,427.5587761723612,-3.3021402149579147
5.620750392087073,0.0028032,145.6585675721044,427.5587761723612,-3.3021402149579147
5.657644587012302,0.0028216,145.71419440982382,427.5587761723612,-3.3021402149579147
5.672081445896087,0.0028288,145.73592290084042,427.5587761723612,-3.3021402149579147
5.713787927115911,0.0028496,145.79857326800203,427.5587761723612,-3.3021402149579147
5.736245263157355,0.0028607999999999997,145.83223419862378,427.5587761723612,-3.3021402149579147
5.782764030671774,0.002884,145.90179735835758,427.5587761723612,-3.3021402149579147
5.82607460732313,0.0029056,145.96636713009346,427.5587761723612,-3.3021402149579147
5.850136038796105,0.0029176,146.00215832841766,427.5587761723612,-3.3021402149579147
5.867781088542954,0.0029264,146.028368729837,427.5587761723612,-3.3021402149579147
5.93034081037269,0.0029576,146.12104984492655,427.5587761723612,-3.3021402149579147
5.956006337277198,0.0029703999999999998,146.1589624693489,427.5587761723612,-3.3021402149579147
5.980067768750174,0.0029824,146.19444772952883,427.5587761723612,-3.3021402149579147
5.991296436770894,0.0029879999999999998,146.2109884573901,427.5587761723612,-3.3021402149579147
6.0089414865177435,0.0029968,146.2369566239916,427.5587761723612,-3.3021402149579147
6.0426274905799096,0.0030136,146.28644978177806,427.5587761723612,-3.3021402149579147
6.068293017484416,0.0030264,146.32408666329405,427.5587761723612,-3.3021402149579147
6.073105303779012,0.0030288,146.3311366618486,427.5587761723612,-3.3021402149579147
6.121228166724963,0.0030528,146.4015172322814,427.5587761723612,-3.3021402149579147
6.140477311903343,0.0030624,146.42960899958382,427.5587761723612,-3.3021402149579147
6.150101884492533,0.0030672,146.44364200267808,427.5587761723612,-3.3021402149579147
6.1725592205339765,0.0030784,146.4763524114954,427.5587761723612,-3.3021402149579147
6.182183793123167,0.0030832,146.49035694631627,427.5587761723612,-3.3021402149579147
6.243139419521372,0.0031136,146.57885568946548,427.5587761723612,-3.3021402149579147
6.294470473330386,0.0031392,146.65311987892153,427.5587761723612,-3.3021402149579147
6.312115523077234,0.0031479999999999998,146.67859359497163,427.5587761723612,-3.3021402149579147
6.3361769545502105,0.00316,146.71328576954133,427.5587761723612,-3.3021402149579147
6.357030195160122,0.0031704,146.74331078140574,427.5587761723612,-3.3021402149579147
6.368258863180844,0.003176,146.75946218418193,427.5587761723612,-3.3021402149579147
6.397132580948415,0.0031904,146.80094344568167,427.5587761723612,-3.3021402149579147
6.40194486724301,0.0031928,146.80784988408794,427.5587761723612,-3.3021402149579147
6.472525066230404,0.003228,146.90891283368418,427.5587761723612,-3.3021402149579147
6.52546021547095,0.0032543999999999997,146.9844282285465,427.5587761723612,-3.3021402149579147
6.547917551512395,0.0032656,147.01639284282908,427.5587761723612,-3.3021402149579147
6.570374887553838,0.0032768,147.04831473037652,427.5587761723612,-3.3021402149579147
6.599248605321408,0.0032911999999999998,147.08929470135934,427.5587761723612,-3.3021402149579147
6.634538704815106,0.0033087999999999998,147.13928649328167,427.5587761723612,-3.3021402149579147
6.697098426644842,0.0033399999999999997,147.2276541777343,427.5587761723612,-3.3021402149579147
6.764470434769174,0.0033736,147.32246011193178,427.5587761723612,-3.3021402149579147
6.79815643883134,0.0033904,147.36972493236198,427.5587761723612,-3.3021402149579147
6.844675206345758,0.0034135999999999997,147.43484551149962,427.5587761723612,-3.3021402149579147
6.8671325423872025,0.0034248,147.46622123613236,427.5587761723612,-3.3021402149579147
6.9168595007646845,0.0034495999999999997,147.53555399981641,427.5587761723612,-3.3021402149579147
6.9537536956899135,0.0034679999999999997,147.58686888585365,427.5587761723612,-3.3021402149579147
7.033958467266499,0.003508,147.69805809709493,427.5587761723612,-3.3021402149579147
7.051603517013348,0.0035168,147.7224532407432,427.5587761723612,-3.3021402149579147
7.112559143411552,0.0035472,147.80654480535128,427.5587761723612,-3.3021402149579147
7.125391906863806,0.0035535999999999996,147.82421242570626,427.5587761723612,-3.3021402149579147
7.162286101789035,0.0035719999999999997,147.8749378414713,427.5587761723612,-3.3021402149579147
7.1959721058512,0.0035887999999999996,147.9211634234415,427.5587761723612,-3.3021402149579147
7.215221251029581,0.0035984,147.94754015019205,427.5587761723612,-3.3021402149579147
7.264948209407064,0.0036232,148.01555331720937,427.5587761723612,-3.3021402149579147
7.316279263216078,0.0036488,148.0855702906929,427.5587761723612,-3.3021402149579147
7.340340694689053,0.0036607999999999996,148.11832477266162,427.5587761723612,-3.3021402149579147
7.364402126162029,0.0036728,148.15103740766773,427.5587761723612,-3.3021402149579147
7.377234889614282,0.0036791999999999997,148.1684671012182,427.5587761723612,-3.3021402149579147
7.40290041651879,0.003692,148.20329105550044,427.5587761723612,-3.3021402149579147
7.41252498910798,0.0036967999999999997,148.21633789502434,427.5587761723612,-3.3021402149579147
7.420545466265638,0.0037007999999999997,148.22720521527262,427.5587761723612,-3.3021402149579147
7.46866832921159,0.0037248,148.29231319787047,427.5587761723612,-3.3021402149579147
7.500750237842223,0.0037408,148.3356276489762,427.5587761723612,-3.3021402149579147
7.52641576474673,0.0037535999999999997,148.37022721067183,427.5587761723612,-3.3021402149579147
7.539248528198984,0.00376,148.38750973380408,427.5587761723612,-3.3021402149579147
7.563309959671959,0.0037719999999999997,148.41988357382473,427.5587761723612,-3.3021402149579147
7.593787772871061,0.0037871999999999997,148.46083283426222,427.5587761723612,-3.3021402149579147
7.6018082500287205,0.0037911999999999998,148.47159829595267,427.5587761723612,-3.3021402149579147
7.6451188266800765,0.0038128,148.5296554225484,427.5587761723612,-3.3021402149579147
7.651535208406203,0.003816,148.53824555673108,427.5587761723612,-3.3021402149579147
7.691637594194495,0.003836,148.5918703857961,427.5587761723612,-3.3021402149579147
7.736552266277383,0.0038583999999999997,148.65180091140894,427.5587761723612,-3.3021402149579147
7.747780934298105,0.003864,148.66676232212922,427.5587761723612,-3.3021402149579147
7.78948741551793,0.0038848,148.72225939451545,427.5587761723612,-3.3021402149579147
7.879316759683705,0.0039296,148.84139947713493,427.5587761723612,-3.3021402149579147
7.906586382019744,0.0039432,148.87746203456967,427.5587761723612,-3.3021402149579147
7.930647813492719,0.0039552,148.90924167435702,427.5587761723612,-3.3021402149579147
7.980374771870202,0.00398,148.97480068394904,427.5587761723612,-3.3021402149579147
7.99801982161705,0.0039888,148.99802523729903,427.5587761723612,-3.3021402149579147
8.015664871363898,0.0039976,149.02122981660568,427.5587761723612,-3.3021402149579147
9.714740786081654,0.00484496899379876,151.17042762762318,427.5587761723612,-3.3021402149579147
11.370498422949739,0.005670734146829366,153.12742391578234,427.5587761723612,-3.3021402149579147
11.986594287830888,0.005977995599119824,153.826774007592,427.5587761723612,-3.3021402149579147
12.44866618649175,0.0062084416883376676,154.3421205088141,427.5587761723612,-3.3021402149579147
12.795220110487396,0.00638127625525105,154.7237480007654,427.5587761723612,-3.3021402149579147
13.141774034483042,0.006554110822164433,155.10136499064853,427.5587761723612,-3.3021402149579147
13.565339941588832,0.006765353070614123,155.55766314644598,427.5587761723612,-3.3021402149579147
14.682013696685912,0.007322264452890578,156.73475050744102,427.5587761723612,-3.3021402149579147
14.797531671351127,0.007379875975195039,156.85449055452779,427.5587761723612,-3.3021402149579147
15.06707361223663,0.007514302860572114,157.13247517215405,427.5587761723612,-3.3021402149579147
16.76133724065979,0.008359271854370874,158.83736694159623,427.5587761723612,-3.3021402149579147
17.300421122430794,0.008628125625125025,159.36554989720273,427.5587761723612,-3.3021402149579147
17.608469054871367,0.008781756351270254,159.66448619960016,427.5587761723612,-3.3021402149579147
18.03203496197716,0.008992998599719944,160.07221444958213,427.5587761723612,-3.3021402149579147
18.417094877527877,0.00918503700740148,160.4396465177372,427.5587761723612,-3.3021402149579147
19.572274624180032,0.00976115223044609,161.5243724109259,427.5587761723612,-3.3021402149579147
19.995840531285822,0.00997239447889578,161.91581057186272,427.5587761723612,-3.3021402149579147
20.650442387722038,0.01029885977195439,162.51445872315466,427.5587761723612,-3.3021402149579147
21.497574201933617,0.01072134426885377,163.27830527225487,427.5587761723612,-3.3021402149579147
21.728610151264046,0.010836567313462692,163.48457797161947,427.5587761723612,-3.3021402149579147
22.383212007700273,0.011163032606521305,164.06442279714844,427.5587761723612,-3.3021402149579147
23.846439686792998,0.011892778555711142,165.33714772362413,427.5587761723612,-3.3021402149579147
25.078631416555293,0.012507301460292058,166.3854542113409,427.5587761723612,-3.3021402149579147
25.771739264546586,0.012852970594118824,166.96629319884988,427.5587761723612,-3.3021402149579147
26.61887107875817,0.013275455091018204,167.66799851118145,427.5587761723612,-3.3021402149579147
27.96658078318568,0.013947589517903581,168.766656824837,427.5587761723612,-3.3021402149579147
29.66084441160884,0.014792558511702341,170.11895319404223,427.5587761723612,-3.3021402149579147
30.04590432715956,0.014984596919383877,170.42205126287035,427.5587761723612,-3.3021402149579147
30.199928293379845,0.015061412282456492,170.54286585323803,427.5587761723612,-3.3021402149579147
30.77751816670592,0.015349469893978797,170.99379618684563,427.5587761723612,-3.3021402149579147
31.085566099146497,0.015503100620124026,171.2329422965347,427.5587761723612,-3.3021402149579147
33.280407617785585,0.016597719543908783,172.91087754849374,427.5587761723612,-3.3021402149579147
35.359731161759456,0.017634726945389076,174.46110339095551,427.5587761723612,-3.3021402149579147
36.28387495908118,0.018095619123824763,175.13863450264716,427.5587761723612,-3.3021402149579147
37.05399479018262,0.018479695939187836,175.698117588308,427.5587761723612,-3.3021402149579147
37.285030739513054,0.01859491898379676,175.86507577706283,427.5587761723612,-3.3021402149579147
37.97813858750434,0.018940588117623523,176.36354612524542,427.5587761723612,-3.3021402149579147
39.05630635104635,0.019478295659131825,177.13194948805508,427.5587761723612,-3.3021402149579147
39.402860275042,0.01965113022604521,177.37717345164518,427.5587761723612,-3.3021402149579147
41.13562989502023,0.02051530306061212,178.59089760138406,427.5587761723612,-3.3021402149579147
41.674713776791236,0.020784156831366273,178.96441202897546,427.5587761723612,-3.3021402149579147
42.44483360789267,0.021168233646729345,179.49475174908937,427.5587761723612,-3.3021402149579147
42.71437554877818,0.021302660532106422,179.6794823205069,427.5587761723612,-3.3021402149579147
42.983917489663675,0.021437087417483496,179.86375881982846,427.5587761723612,-3.3021402149579147
44.177603227870904,0.02203240648129626,180.67448286586242,427.5587761723612,-3.3021402149579147
45.717842890073776,0.022800560112022406,181.7080637863196,427.5587761723612,-3.3021402149579147
48.259238332708506,0.024068013602720543,183.38425959077486,427.5587761723612,-3.3021402149579147
48.91384018914473,0.024394478895779156,183.81038599867387,427.5587761723612,-3.3021402149579147
49.79947799491138,0.02483616723344669,184.38338666098448,427.5587761723612,-3.3021402149579147
50.261549893572244,0.025066613322664532,184.68076506108451,427.5587761723612,-3.3021402149579147
52.30236744599105,0.026084416883376677,185.98163592190787,427.5587761723612,-3.3021402149579147
53.61157115886349,0.0267373474694939,186.80574342615526,427.5587761723612,-3.3021402149579147
54.84376288862579,0.027351870374074817,187.57423278489088,427.5587761723612,-3.3021402149579147
55.69089470283737,0.027774354870974197,188.09866728522,427.5587761723612,-3.3021402149579147
56.615038500159095,0.028235247049409884,188.66724196774564,427.5587761723612,-3.3021402149579147
57.38515833126052,0.028619323864772953,189.13829442547032,427.5587761723612,-3.3021402149579147
57.53918229748081,0.028696139227845568,189.23220836220182,427.5587761723612,-3.3021402149579147
57.80872423836632,0.028830566113222645,189.39632217555086,427.5587761723612,-3.3021402149579147
58.07826617925181,0.02896499299859972,189.56013782862473,427.5587761723612,-3.3021402149579147
58.771374027243105,0.029310662132426484,189.98002236426888,427.5587761723612,-3.3021402149579147
59.42597588367933,0.029637127425485098,190.3748102145991,427.5587761723612,-3.3021402149579147
59.965059765450334,0.02990598119623925,190.69865770598824,427.5587761723612,-3.3021402149579147
60.6966736049967,0.030270854170834166,191.13635472352723,427.5587761723612,-3.3021402149579147
60.88920356277206,0.030366873374674936,191.2511955616287,427.5587761723612,-3.3021402149579147
61.2357574867677,0.030539707941588317,191.45755282826616,427.5587761723612,-3.3021402149579147
62.275419258754646,0.031058211642328467,192.07390903749172,427.5587761723612,-3.3021402149579147
63.161057064521295,0.031499899979996,192.5957944579734,427.5587761723612,-3.3021402149579147
64.04669487028795,0.031941588317663534,193.11483360545498,427.5587761723612,-3.3021402149579147
64.58577875205894,0.03221044208841768,193.42940023908534,427.5587761723612,-3.3021402149579147
65.70245250715602,0.032767353470694136,194.07776369593387,427.5587761723612,-3.3021402149579147
65.89498246493139,0.03286337267453491,194.18911473269722,427.5587761723612,-3.3021402149579147
66.47257233825748,0.033151430286057215,194.5224090241509,427.5587761723612,-3.3021402149579147
67.31970415246904,0.03357391478295659,195.00920482037705,427.5587761723612,-3.3021402149579147
67.58924609335455,0.03370834166833367,195.16359261775568,427.5587761723612,-3.3021402149579147
68.51338989067628,0.034169233846769356,195.69110878423248,427.5587761723612,-3.3021402149579147
69.24500373022265,0.03453410682136428,196.1067602655453,427.5587761723612,-3.3021402149579147
69.74558162043857,0.03478375675135027,196.39016704420607,427.5587761723612,-3.3021402149579147
70.16914752754437,0.034994998999799964,196.62935371658978,427.5587761723612,-3.3021402149579147
71.51685723197188,0.035667133426685343,197.38668300830994,427.5587761723612,-3.3021402149579147
71.74789318130229,0.035782356471294255,197.51595001103215,427.5587761723612,-3.3021402149579147
72.67203697862402,0.03624324864972994,198.0314028544181,427.5587761723612,-3.3021402149579147
74.05825267460662,0.03693458691738348,198.79981454397273,427.5587761723612,-3.3021402149579147
75.25193841281383,0.03752990598119624,199.45701822606833,427.5587761723612,-3.3021402149579147
75.94504626080511,0.037875575115023,199.83675458431844,427.5587761723612,-3.3021402149579147
76.36861216791091,0.03808681736347269,200.0681504042968,427.5587761723612,-3.3021402149579147
77.44677993145294,0.038624524904981,200.65491068903336,427.5587761723612,-3.3021402149579147
78.21689976255435,0.039008601720344066,201.07207638070926,427.5587761723612,-3.3021402149579147
78.60195967810506,0.0392006401280256,201.28005829697176,427.5587761723612,-3.3021402149579147
78.71747765277028,0.03925825165033006,201.34237533719104,427.5587761723612,-3.3021402149579147
80.37323528963837,0.04008401680336067,202.23170319216467,427.5587761723612,-3.3021402149579147
84.1468224620354,0.04196599319863972,204.23226531757123,427.5587761723612,-3.3021402149579147
84.993954276247,0.042388477695539106,204.67652560394416,427.5587761723612,-3.3021402149579147
85.61005014112814,0.042695739147829564,204.99854006128658,427.5587761723612,-3.3021402149579147
85.99511005667885,0.0428877775555111,205.1993402126989,427.5587761723612,-3.3021402149579147
86.34166398067451,0.043060612122424485,205.37976073519823,427.5587761723612,-3.3021402149579147
87.26580777799623,0.04352150430086017,205.85950671586104,427.5587761723612,-3.3021402149579147
88.18995157531795,0.04398239647929586,206.33727534199693,427.5587761723612,-3.3021402149579147
88.49799950775852,0.04413602720544109,206.49609712743052,427.5587761723612,-3.3021402149579147
88.69052946553388,0.044232046409281855,206.59525126416827,427.5587761723612,-3.3021402149579147
89.15260136419477,0.044462492498499706,206.83287932061512,427.5587761723612,-3.3021402149579147
89.22961334730489,0.04450090018003601,206.8724372517437,427.5587761723612,-3.3021402149579147
90.07674516151648,0.04492338467693539,207.3066993330291,427.5587761723612,-3.3021402149579147
90.80835900106283,0.0452882576515303,207.680463636341,427.5587761723612,-3.3021402149579147
91.46296085749906,0.04561472294458892,208.01389000892473,427.5587761723612,-3.3021402149579147
91.69399680682949,0.04572994598919784,208.1313475353805,427.5587761723612,-3.3021402149579147
92.0790567223802,0.045921984396879376,208.32685391346902,427.5587761723612,-3.3021402149579147
92.9261885365918,0.04634446889377876,208.75584908040892,427.5587761723612,-3.3021402149579147
94.5434401819048,0.04715103020604121,209.57062807525284,427.5587761723612,-3.3021402149579147
94.73597013968015,0.047247049409881975,209.6672621741204,427.5587761723612,-3.3021402149579147
95.35206600456131,0.04755431086217243,209.97597786334399,427.5587761723612,-3.3021402149579147
95.81413790322217,0.047784756951390284,210.20700437049481,427.5587761723612,-3.3021402149579147
96.19919781877289,0.04797679535907182,210.39919472458917,427.5587761723612,-3.3021402149579147
96.77678769209895,0.048264852970594116,210.68691867098136,427.5587761723612,-3.3021402149579147
97.1233416160946,0.048437687537507504,210.85923159353695,427.5587761723612,-3.3021402149579147
97.85495545564098,0.048802560512102425,211.22221784767376,427.5587761723612,-3.3021402149579147
98.66358127829749,0.04920584116823365,211.62218401625532,427.5587761723612,-3.3021402149579147
98.93312321918297,0.04934026805361072,211.75522170867137,427.5587761723612,-3.3021402149579147
99.66473705872934,0.04970514102820564,212.11561336291598,427.5587761723612,-3.3021402149579147
100.78141081382643,0.050262052410482094,212.66370197575375,427.5587761723612,-3.3021402149579147
100.93543478004672,0.050338867773554716,212.73911411153233,427.5587761723612,-3.3021402149579147
101.97509655203366,0.050857371474294866,213.24697723236983,427.5587761723612,-3.3021402149579147
102.62969840846986,0.05118383676735347,213.56570714988186,427.5587761723612,-3.3021402149579147
103.63085418890172,0.05168313662732546,214.05164713448053,427.5587761723612,-3.3021402149579147
103.93890212134231,0.05183676735347069,214.2007983359607,427.5587761723612,-3.3021402149579147
104.63200996933362,0.052182436487297465,214.5357596501936,427.5587761723612,-3.3021402149579147
105.5946597582104,0.0526625325065013,214.9995516548013,427.5587761723612,-3.3021402149579147
105.78718971598575,0.052758551710342064,215.09211185997393,427.5587761723612,-3.3021402149579147
106.59581553864228,0.0531618323664733,215.4801494767427,427.5587761723612,-3.3021402149579147
107.2119114035234,0.05346909381876375,215.77502712620438,427.5587761723612,-3.3021402149579147
108.21306718395529,0.05396839367873575,216.25279770776754,427.5587761723612,-3.3021402149579147
108.4441031332857,0.05408361672334466,216.36280727878776,427.5587761723612,-3.3021402149579147
108.63663309106109,0.05417963592718544,216.4544121157083,427.5587761723612,-3.3021402149579147
109.90733081237843,0.054813362672534505,217.0574239013867,427.5587761723612,-3.3021402149579147
110.48492068570452,0.05510142028405682,217.3306207185062,427.5587761723612,-3.3021402149579147
110.79296861814511,0.05525505101020205,217.47609790970637,427.5587761723612,-3.3021402149579147
111.21653452525086,0.055466293258651725,217.67587173694716,427.5587761723612,-3.3021402149579147
111.79412439857697,0.05575435087017404,217.9478130575731,427.5587761723612,-3.3021402149579147
112.29470228879289,0.056004000800160034,218.18305260826529,427.5587761723612,-3.3021402149579147
113.41137604388997,0.05656091218243649,218.70634902522747,427.5587761723612,-3.3021402149579147
113.79643595944069,0.05675295059011802,218.886329632844,427.5587761723612,-3.3021402149579147
114.7205797567624,0.05721384276855371,219.31731678460827,427.5587761723612,-3.3021402149579147
115.18265165542329,0.05744428885777156,219.53230244695166,427.5587761723612,-3.3021402149579147
115.45219359630877,0.05757871574314863,219.65755542075456,427.5587761723612,-3.3021402149579147
116.22231342741023,0.05796279255851171,220.01479419032222,427.5587761723612,-3.3021402149579147
116.45334937674063,0.05807801560312062,220.12178564367613,427.5587761723612,-3.3021402149579147
116.56886735140586,0.05813562712542508,220.17525032444848,427.5587761723612,-3.3021402149579147
117.10795123317686,0.05840448089617924,220.42447946536097,427.5587761723612,-3.3021402149579147
118.0320950304986,0.058865373074614924,220.85069094829478,427.5587761723612,-3.3021402149579147
118.45566093760438,0.059076615323064616,221.04560273640033,427.5587761723612,-3.3021402149579147
118.8022148616,0.05924944988997799,221.20487392334354,427.5587761723612,-3.3021402149579147
119.14876878559566,0.05942228445689138,221.3639640172184,427.5587761723612,-3.3021402149579147
119.26428676026089,0.05947989597919584,221.41695393222489,427.5587761723612,-3.3021402149579147
119.61084068425654,0.05965273054610923,221.57580370604967,427.5587761723612,-3.3021402149579147
120.11141857447247,0.059902380476095224,221.80493686067896,427.5587761723612,-3.3021402149579147
120.76602043090868,0.06022884576915383,222.1040113670014,427.5587761723612,-3.3021402149579147
121.34361030423477,0.06051690338067614,222.3673759972952,427.5587761723612,-3.3021402149579147
122.15223612689128,0.060920184036807365,222.73526659811995,427.5587761723612,-3.3021402149579147
122.96086194954778,0.06132346469293859,223.10220862154236,427.5587761723612,-3.3021402149579147
124.65512557797092,0.06216843368673734,223.86800181126165,427.5587761723612,-3.3021402149579147
126.1953652401738,0.06293658731746349,224.56066213307426,427.5587761723612,-3.3021402149579147
127.81261688548683,0.06374314862972595,225.28441630661553,427.5587761723612,-3.3021402149579147
128.04365283481724,0.06385837167433486,225.38751745191593,427.5587761723612,-3.3021402149579147
128.89078464902883,0.06428085617123425,225.76493585755549,427.5587761723612,-3.3021402149579147
129.27584456457953,0.06447289457891578,225.93616974593488,427.5587761723612,-3.3021402149579147
129.81492844635056,0.06474174834966993,226.17556339156462,427.5587761723612,-3.3021402149579147
132.12528793965487,0.06589397879575916,227.1971757178034,427.5587761723612,-3.3021402149579147
132.4718418636505,0.06606681336267253,227.34981455490427,427.5587761723612,-3.3021402149579147
132.97241975386643,0.06631646329265853,227.57001822902913,427.5587761723612,-3.3021402149579147
134.08909350896354,0.066873374674935,228.0600801374461,427.5587761723612,-3.3021402149579147
136.05289907827222,0.06785277055411083,228.91806969730197,427.5587761723612,-3.3021402149579147
137.32359679958955,0.0684864972994599,229.47066679873242,427.5587761723612,-3.3021402149579147
138.59429452090694,0.06912022404480897,230.02127325304016,427.5587761723612,-3.3021402149579147
139.82648625066923,0.06973474694938989,230.5533175308726,427.5587761723612,-3.3021402149579147
140.44258211555038,0.07004200840168034,230.81865374495493,427.5587761723612,-3.3021402149579147
140.5581000902156,0.07009961992398481,230.8683537070546,427.5587761723612,-3.3021402149579147
141.32821992131701,0.07048369673934787,231.1992806296738,427.5587761723612,-3.3021402149579147
142.56041165107933,0.07109821964392879,231.72730463748394,427.5587761723612,-3.3021402149579147
144.02363933017205,0.07182796559311863,232.35202693201646,427.5587761723612,-3.3021402149579147
144.52421722038798,0.07207761552310463,232.56517881819735,427.5587761723612,-3.3021402149579147
145.14031308526913,0.07238487697539508,232.8271247500541,427.5587761723612,-3.3021402149579147
146.5650347728068,0.07309541908381677,233.4312194420229,427.5587761723612,-3.3021402149579147
148.06676844345458,0.07384436887377475,234.06549393281477,427.5587761723612,-3.3021402149579147
148.60585232522558,0.07411322264452891,234.29256961356378,427.5587761723612,-3.3021402149579147
150.1075859958734,0.0748621724344869,234.92344983797054,427.5587761723612,-3.3021402149579147
151.37828371719075,0.07549589917983597,235.45535131202953,427.5587761723612,-3.3021402149579147
152.6874874300632,0.07614882976595319,236.00155292503442,427.5587761723612,-3.3021402149579147
152.91852337939363,0.07626405281056212,236.0977515373131,427.5587761723612,-3.3021402149579147
153.45760726116464,0.07653290658131627,236.32199480213077,427.5587761723612,-3.3021402149579147
154.49726903315158,0.07705141028205642,236.75359826479894,427.5587761723612,-3.3021402149579147
154.728304982482,0.07716663332666533,236.84935614792116,427.5587761723612,-3.3021402149579147
155.22888287269797,0.07741628325665134,237.05664047171462,427.5587761723612,-3.3021402149579147
157.3467124082269,0.07847249449889979,237.93074362487945,427.5587761723612,-3.3021402149579147
158.27085620554863,0.07893338667733547,238.3107311980721,427.5587761723612,-3.3021402149579147
158.9639640535399,0.07927905581116224,238.59515427672093,427.5587761723612,-3.3021402149579147
160.11914380019206,0.07985517103420685,239.06812031169287,427.5587761723612,-3.3021402149579147
160.50420371574276,0.08004720944188838,239.2254796868991,427.5587761723612,-3.3021402149579147
161.38984152150942,0.08048889777955591,239.5868485734413,427.5587761723612,-3.3021402149579147
161.5823714792848,0.08058491698339669,239.66530459440153,427.5587761723612,-3.3021402149579147
163.77721299792387,0.08167953590718144,240.55714163856618,427.5587761723612,-3.3021402149579147
165.5484886094572,0.08256291258251651,241.2734757704631,427.5587761723612,-3.3021402149579147
166.7806803392195,0.08317743548709743,241.77003320650638,427.5587761723612,-3.3021402149579147
168.01287206898178,0.08379195839167834,242.2651619268028,427.5587761723612,-3.3021402149579147
168.59046194230785,0.08408001600320064,242.49676582537867,427.5587761723612,-3.3021402149579147
170.0151836298455,0.08479055811162232,243.06673629451925,427.5587761723612,-3.3021402149579147
172.67209704714546,0.08611562312462492,244.12470277307384,427.5587761723612,-3.3021402149579147
173.1726749373614,0.08636527305461093,244.32331703595975,427.5587761723612,-3.3021402149579147
174.1353247262382,0.08684536907381477,244.70463934616083,427.5587761723612,-3.3021402149579147
175.63705839688598,0.08759431886377275,245.29786462788726,427.5587761723612,-3.3021402149579147
176.13763628710194,0.08784396879375876,245.49516636637102,427.5587761723612,-3.3021402149579147
176.83074413509323,0.08818963792758552,245.76799274957264,427.5587761723612,-3.3021402149579147
177.4853459915294,0.08851610322064413,246.02527941971616,427.5587761723612,-3.3021402149579147
178.10144185641056,0.08882336467293458,246.26709372112464,427.5587761723612,-3.3021402149579147
178.98707966217725,0.08926505301060213,246.61413101838187,427.5587761723612,-3.3021402149579147
179.41064556928302,0.08947629525905182,246.77986858827677,427.5587761723612,-3.3021402149579147
180.18076540038444,0.08986037207441488,247.08081919067536,427.5587761723612,-3.3021402149579147
180.33478936660475,0.0899371874374875,247.14094906660512,427.5587761723612,-3.3021402149579147
182.33710092746847,0.09093578715743149,247.92082369635511,427.5587761723612,-3.3021402149579147
183.8003286065612,0.09166553310662133,248.48862147018426,427.5587761723612,-3.3021402149579147
184.1083765390018,0.09181916383276656,248.6079329031544,427.5587761723612,-3.3021402149579147
184.57044843766263,0.0920496099219844,248.78675417685358,427.5587761723612,-3.3021402149579147
185.0325203363235,0.09228005601120225,248.96540094079123,427.5587761723612,-3.3021402149579147
186.64977198163652,0.0930866173234647,249.589299059101,427.5587761723612,-3.3021402149579147
188.6905895340553,0.09410442088417684,250.3735983950584,427.5587761723612,-3.3021402149579147
189.22967341582634,0.09437327465493099,250.58021856681395,427.5587761723612,-3.3021402149579147
190.15381721314805,0.09483416683336668,250.93389128460385,427.5587761723612,-3.3021402149579147
191.11646700202485,0.09531426285257052,251.30158827679165,427.5587761723612,-3.3021402149579147
191.34750295135527,0.09542948589717944,251.38972798951866,427.5587761723612,-3.3021402149579147
191.46302092602048,0.0954870974194839,251.4337822810815,427.5587761723612,-3.3021402149579147
192.0021048077915,0.09575595119023805,251.63923206785682,427.5587761723612,-3.3021402149579147
192.42567071489728,0.09596719343868775,251.80049912063186,427.5587761723612,-3.3021402149579147
192.84923662200308,0.09617843568713744,251.96162779055948,427.5587761723612,-3.3021402149579147
193.0802725713335,0.09629365873174635,252.04945798043315,427.5587761723612,-3.3021402149579147
193.73487442776974,0.09662012402480497,252.29808787846315,427.5587761723612,-3.3021402149579147
194.62051223353637,0.0970618123624725,252.63394864297743,427.5587761723612,-3.3021402149579147
194.81304219131175,0.09715783156631327,252.70688291833616,427.5587761723612,-3.3021402149579147
195.2751140899726,0.09738827765553111,252.88181058173055,427.5587761723612,-3.3021402149579147
195.66017400552332,0.09758031606321264,253.02746035379553,427.5587761723612,-3.3021402149579147
196.2377638788494,0.09786837367473496,253.2457255825433,427.5587761723612,-3.3021402149579147
196.73834176906533,0.09811802360472095,253.43468619668604,427.5587761723612,-3.3021402149579147
197.81650953260734,0.09865573114622925,253.8410426071241,427.5587761723612,-3.3021402149579147
198.35559341437835,0.0989245849169834,254.04389683472763,427.5587761723612,-3.3021402149579147
198.50961738059863,0.09900140028005601,254.10181567904357,427.5587761723612,-3.3021402149579147
199.54927915258557,0.09951990398079616,254.4923104686541,427.5587761723612,-3.3021402149579147