File: datasets/am_bench_2022/raw_data/90-XY.16-4/specimen.dat
MTS793|MPT|ENU|1|2|.|/|:|1|0|0|A

Operator Information						Time:	11.244873	Sec	11/3/2021 8:12:38 AM
Operator	Nick Derimow
Project	AM Bench 2022 mini-tensile challenge
Specimen ID	90-XY.16-4
Material	PBF-L Inconel 625
Specimen Width	2.54	mm
Specimen Thickness	1.51	mm
Notes
Operator Information End

Data Acquisition						Time:	1007.8193	Sec	11/3/2021 8:29:14 AM
Time	Axial Displacement	Axial Extensometer	Axial Force
Sec	mm	mm	N
11.358643	0.0012612761	0.00010995562	69.367661
12.259521	0.0022904433	0.000249387	84.772903
13.1604	0.0043968763	0.00017318907	96.220695
14.061279	0.0084901368	0.00027612425	108.59179
14.962158	0.0085757812	0.00030187494	119.44189
15.863037	0.012257826	0.00033578338	131.31712
16.763916	0.016442928	0.00040326625	147.33127
17.664795	0.017380919	0.00051419728	155.37854
18.565674	0.019374251	0.0004541284	172.66217
19.466553	0.02453023	0.00058028998	192.04916
20.367432	0.024703978	0.00065689359	207.27782
21.268311	0.031194054	0.00079536508	230.01228
22.169189	0.031583551	0.00072165963	242.13147
23.070068	0.033981595	0.00077712262	260.38394
23.970947	0.039208874	0.00084509212	269.76825
24.871826	0.038739879	0.00096196088	289.48355
25.772705	0.044911761	0.00095278176	307.38495
26.673584	0.044897009	0.0011165204	326.43094
27.574463	0.049381405	0.001307489	350.10565
28.475342	0.049955919	0.0014168536	370.79044
29.376221	0.055094533	0.0014229184	391.20801
30.2771	0.056645967	0.0015088292	406.23807
31.177979	0.060128447	0.0016017412	433.25827
32.078857	0.062147599	0.0016501117	447.48508
32.979736	0.063015103	0.0016883352	468.96515
33.880615	0.065814681	0.0018817175	491.98544
34.781494	0.071055792	0.0019570631	510.93042
35.682373	0.070180088	0.0020242878	534.16779
36.583252	0.074196316	0.0022165831	559.14948
37.484131	0.076823987	0.0021318218	576.28485
38.38501	0.078795396	0.0023012236	598.04584
39.285889	0.085370503	0.0025422459	627.7085
40.186768	0.08397074	0.0025722461	650.42908
41.087646	0.08286453	0.0026067898	668.56757
41.988525	0.090649471	0.002774159	690.80481
42.889404	0.094535381	0.002832307	714.89838
43.790283	0.095931299	0.0029794455	738.10211
44.691162	0.099118941	0.003135219	762.03705
45.592041	0.099301912	0.0032974607	794.37115
46.49292	0.10382728	0.0034155999	816.42981
47.393799	0.1067412	0.0034159401	843.9516
48.294678	0.11392831	0.0035766463	867.09216
49.195557	0.11123036	0.0037181429	886.51526
50.096436	0.11344866	0.0037574768	909.09222
50.997314	0.1180062	0.0039053375	936.39246
51.898193	0.11955021	0.0039666481	961.51086
52.799072	0.1224867	0.0041937144	985.55377
53.699951	0.12571	0.0042543816	1019.0486
54.60083	0.128123	0.0043750643	1048.6462
55.501709	0.13029684	0.0045042592	1065.0941
56.402588	0.13377051	0.0045913327	1091.7125
57.303467	0.13462859	0.0047459509	1116.875
58.204346	0.14099123	0.0048928466	1151.2721
59.105225	0.14104696	0.005058086	1170.5431
60.006104	0.14614598	0.0051169498	1200.9785
60.906982	0.14700407	0.0052261394	1223.8499
61.807861	0.15094411	0.0053247605	1237.3229
62.70874	0.15162496	0.0054387683	1262.2704
63.609619	0.15382524	0.005571356	1288.0906
64.510498	0.15746877	0.0057417457	1313.0377
65.411377	0.15957397	0.0058014304	1332.6987
66.312256	0.16429691	0.0059283949	1365.4456
67.213135	0.16489458	0.0061308211	1384.4515
68.114014	0.16906872	0.0061413976	1411.0209
69.014893	0.17111661	0.006357871	1439.9279
69.915771	0.17258911	0.0065253419	1465.8292
70.81665	0.17372768	0.0066552456	1494.8712
71.717529	0.17936173	0.0067392457	1520.5048
72.618408	0.18297492	0.006765353	1540.5277
73.519287	0.18643568	0.0069245226	1568.6155
74.420166	0.18469928	0.0070832167	1590.0176
75.321045	0.18882041	0.0071593872	1613.0356
76.221924	0.19111048	0.007384473	1639.7787
77.122803	0.19380659	0.0074351016	1659.6118
78.023682	0.20072463	0.0075170645	1682.5647
78.924561	0.19718683	0.0076768165	1702.314
79.825439	0.20467779	0.0078438446	1728.8597
80.726318	0.20626299	0.0079382258	1762.2438
81.627197	0.20757695	0.008065559	1780.2146
82.528076	0.20827399	0.008201913	1808.7529
83.428955	0.21347976	0.0083126137	1826.2965
84.329834	0.2175573	0.0085013378	1858.3893
85.230713	0.21929574	0.0085963188	1876.3352
86.131592	0.22301856	0.008770369	1903.9089
87.032471	0.2257161	0.0087562967	1924.5782
87.93335	0.22676678	0.0089686513	1945.568
88.834229	0.22895502	0.0091582062	1974.2347
89.735107	0.2328227	0.0091101229	1989.1305
90.635986	0.23675142	0.0093691349	2021.3633
91.536865	0.23830491	0.0095536988	2043.0085
92.437744	0.24153456	0.0097007798	2065.1853
93.338623	0.24457924	0.0097600212	2077.2012
94.239502	0.24438255	0.0098085552	2089.0471
95.140381	0.25121862	0.0098983543	2114.8123
96.04126	0.25309128	0.010023635	2127.5803
96.942139	0.25345474	0.010068842	2142.2996
97.843018	0.258165	0.010195429	2170.4324
98.743896	0.26007268	0.010406059	2194.4546
99.644775	0.26356992	0.010445181	2207.2788
100.54565	0.26496133	0.010641215	2230.1453
101.44653	0.26562434	0.01061514	2236.0234
102.34741	0.27146	0.010765475	2264.6177
103.24829	0.27415469	0.010893818	2276.0112
104.14917	0.278108	0.01096984	2292.9941
105.05005	0.27890155	0.011063891	2309.0837
105.95093	0.2836476	0.011261032	2319.2014
106.85181	0.2884762	0.011340753	2332.946
107.75269	0.28627834	0.011354399	2341.8567
108.65356	0.28786337	0.01147253	2357.75
109.55444	0.29515472	0.011620996	2379.8374
110.45532	0.29379916	0.011723015	2386.5249
111.3562	0.29794738	0.011810129	2394.272
112.25708	0.30184376	0.011982789	2413.3447
113.15796	0.30593476	0.012045046	2430.1863
114.05884	0.30678767	0.012164925	2443.7517
114.95972	0.31022921	0.012350395	2457.8142
115.8606	0.31249163	0.012368487	2467.1003
116.76147	0.31459457	0.012565266	2482.8789
117.66235	0.31511378	0.012672989	2487.8203
118.56323	0.3189128	0.012629962	2498.4453
119.46411	0.32246229	0.012735205	2514.3413
120.36499	0.32773572	0.012991574	2526.5386
121.26587	0.32835469	0.013017398	2535.0852
122.16675	0.33124873	0.01319543	2542.6243
123.06763	0.33584931	0.01331359	2563.8269
123.96851	0.33697149	0.013455892	2563.9165
124.86938	0.34046605	0.013633146	2583.1301
125.77026	0.34160239	0.013698624	2591.8862
126.67114	0.34557515	0.013763659	2595.9282
127.57202	0.35061482	0.013966979	2614.6379
128.4729	0.35242853	0.014003248	2616.1238
129.37378	0.35286227	0.014147777	2626.293
130.27466	0.35684422	0.014360299	2640.1606
131.17554	0.35729581	0.014556083	2647.3044
132.07642	0.36098257	0.014554387	2654.9578
132.97729	0.36261573	0.01482511	2671.6338
133.87817	0.36662444	0.014931976	2676.4668
134.77905	0.36839527	0.015103402	2684.4678
135.67993	0.37239817	0.015272509	2695.8035
136.58081	0.37530407	0.015502168	2701.1121
137.48169	0.37615582	0.015672997	2708.5576
138.38257	0.38052997	0.015739758	2714.0845
139.28345	0.38512993	0.015818935	2721.1807
140.18433	0.38598433	0.016031273	2733.8948
141.08521	0.38541451	0.016201252	2739.2429
141.98608	0.39563888	0.016446045	2755.0066
142.88696	0.3920337	0.016509438	2749.085
143.78784	0.39587533	0.016783968	2757.0713
144.68872	0.39730951	0.016923947	2767.5422
145.5896	0.40277433	0.017225504	2783.8032
146.49048	0.40407455	0.017363479	2780.9248
147.39136	0.4059442	0.017765217	2795.8381
148.29224	0.40947893	0.017992692	2804.3042
149.19312	0.41438738	0.01814086	2803.719
150.09399	0.41401613	0.018577177	2817.137
150.99487	0.4193185	0.018796666	2821.856
151.89575	0.4221226	0.0190522	2829.0918
152.79663	0.42313638	0.019330701	2832.6052
153.69751	0.42681187	0.019504029	2837.8574
154.59839	0.42811227	0.019713137	2850.2415
155.49927	0.43329969	0.020151382	2857.8955
156.40015	0.43367097	0.020452609	2864.6895
157.30103	0.43767074	0.020875061	2876.4539
158.2019	0.44022101	0.021193003	2873.9968
159.10278	0.44451508	0.021692799	2879.7441
160.00366	0.44571677	0.022015929	2883.5574
160.90454	0.45019582	0.022351209	2897.8958
161.80542	0.45004851	0.022772841	2899.7581
162.7063	0.45435911	0.023369305	2912.8535
163.60718	0.45551285	0.023865074	2913.3203
164.50806	0.46223158	0.02442383	2920.8867
165.40894	0.46267661	0.02472532	2928.2329
166.30981	0.46410629	0.025290107	2933.4026
167.21069	0.4641954	0.025831891	2932.7244
168.11157	0.46936229	0.026260985	2936.3804
169.01245	0.47493181	0.026761204	2945.2915
169.91333	0.47548193	0.02739374	2945.686
170.81421	0.47656518	0.027884912	2950.0022
171.71509	0.48188365	0.02834071	2955.8167
172.61597	0.48182157	0.028893227	2962.801
173.51685	0.48704156	0.029479969	2967.9114
174.41772	0.49011344	0.030139821	2973.9968
175.3186	0.49211538	0.030868361	2980.5354
176.21948	0.49532825	0.031686161	2981.0383
177.12036	0.49609166	0.032218747	2982.5464
178.02124	0.49951437	0.032886013	2989.7654
178.92212	0.50547493	0.033526536	2993.6262
179.823	0.50314742	0.034194805	3000.0415
180.72388	0.50674772	0.034915365	2999.6084
181.62476	0.51006955	0.035643045	3005.4531
182.52563	0.51361275	0.036400825	3011.1184
183.42651	0.51563478	0.037103288	3009.1409
184.32739	0.5182215	0.03792239	3017.7212
185.22827	0.51941884	0.038728558	3022.071
186.12915	0.52280664	0.039601669	3030.7129
187.03003	0.5290947	0.040456198	3033.6604
187.93091	0.52885437	0.041276161	3033.0105
188.83179	0.53275812	0.041993394	3038.9856
189.73267	0.53402007	0.042884056	3041.4587
190.63354	0.54097873	0.043749511	3046.2004
191.53442	0.54290891	0.044581469	3050.502
192.4353	0.53773588	0.045466423	3045.5396
193.33618	0.54563558	0.046321642	3047.1335
194.23706	0.5473212	0.047126777	3054.4749
195.13794	0.54851115	0.047914315	3049.0962
196.03882	0.55387419	0.048681322	3062.8145
196.9397	0.55831307	0.049594644	3073.6216
197.84058	0.56100881	0.050549459	3071.0173
198.74146	0.56165189	0.051396072	3063.1814
199.64233	0.56725651	0.05225607	3075.1367
200.54321	0.56487298	0.053045265	3070.7021
201.44409	0.56881422	0.053867407	3080.2625
202.34497	0.57385409	0.054668248	3087.9412
203.24585	0.57530874	0.055574611	3086.6021
204.14673	0.5767262	0.056584716	3085.6047
205.04761	0.57942277	0.057594072	3094.3721
205.94849	0.58336091	0.058639649	3098.1345
206.84937	0.58525836	0.059368629	3092.7795
207.75024	0.58995461	0.060165752	3100.812
208.65112	0.59304988	0.061075028	3103.1702
209.552	0.59714746	0.062152777	3110.9321
210.45288	0.5964914	0.0630254	3102.6602
211.35376	0.60225797	0.063897237	3110.875
212.25464	0.60058403	0.064738348	3106.9231
213.15552	0.60598922	0.065703481	3123.886
214.0564	0.60788614	0.066693753	3117.4109
214.95728	0.60942644	0.067591965	3114.7266
215.85815	0.61364037	0.068510525	3128.3652
216.75903	0.61839914	0.069389261	3121.2742
217.65991	0.61878431	0.070314646	3127.7813
218.56079	0.61996019	0.07122878	3129.6748
219.46167	0.62391388	0.07224153	3136.9114
220.36255	0.6242485	0.073215283	3132.4746
221.26343	0.62760454	0.074133426	3134.2793
222.16431	0.63277394	0.07509011	3143.166
223.06519	0.63526905	0.076210998	3147.3088
223.96606	0.63898879	0.077018037	3143.574
224.86694	0.64064121	0.078003265	3145.1819
225.76782	0.64181709	0.079071715	3151.8523
226.6687	0.64491028	0.080152251	3147.0151
227.56958	0.65137947	0.080987923	3157.7517
228.47046	0.65141898	0.081909753	3155.6382
229.37134	0.6549111	0.082892895	3159.05
230.27222	0.65555054	0.083872192	3159.3679
231.1731	0.66058099	0.08470951	3167.1785
232.07397	0.66142064	0.085584745	3165.0398
232.97485	0.66670465	0.086697012	3167.7505
233.87573	0.66512728	0.087866008	3168.835
234.77661	0.67102861	0.088946044	3173.1548
235.67749	0.6748392	0.089902468	3173.4773
236.57837	0.67871976	0.090873249	3181.6094
237.47925	0.67739147	0.091875374	3178.9028
238.38013	0.68363893	0.092710182	3177.6035
239.28101	0.68210679	0.09365119	3180.5952
240.18188	0.68714643	0.094831072	3190.688
241.08276	0.6890406	0.095978476	3191.6599
241.98364	0.69357848	0.096972764	3190.5664
242.88452	0.69659156	0.098081596	3192.731
243.7854	0.69675016	0.09899345	3193.1941
244.68628	0.69763875	0.099992357	3199.6262
245.58716	0.70265281	0.10083836	3191.9656
246.48804	0.70351064	0.10174801	3194.7161
247.38892	0.70853251	0.10273977	3200.5024
248.28979	0.71249014	0.10354231	3200.2512
249.19067	0.71324492	0.10444498	3206.0454
250.09155	0.71623242	0.10552309	3207.8247
250.99243	0.71999395	0.10658357	3217.1023
251.89331	0.72341722	0.1075204	3208.0354
252.79419	0.72519934	0.10848129	3210.1282
253.69507	0.72847599	0.1095436	3217.0806
254.59595	0.73109466	0.11039434	3218.186
255.49683	0.73165375	0.11155489	3223.0117
256.39771	0.73560953	0.1124612	3216.5503
257.29858	0.73828989	0.11350613	3227.5732
258.19946	0.740834	0.11457156	3226.324
259.10034	0.74302036	0.11593319	3225.8635
260.00122	0.74603981	0.11688981	3226.6428
260.9021	0.75043303	0.11778589	3227.9587
261.80298	0.75076842	0.11873138	3227.3943
262.70386	0.75492954	0.119591	3226.5012
263.60474	0.75839955	0.12036442	3233.0569
264.50562	0.76150584	0.12153075	3239.5615
265.40649	0.76189715	0.12246672	3242.032
266.30737	0.76508993	0.12361719	3238.5618
267.20825	0.76765352	0.12469941	3242.0186
268.10913	0.76850569	0.12582639	3244.2107
269.01001	0.77033716	0.12693794	3240.1702
269.91089	0.77563435	0.12816423	3250.8972
270.81177	0.77782458	0.12914741	3245.0928
271.71265	0.78208178	0.1300758	3253.1614
272.61353	0.78364468	0.13106	3253.6589
273.5144	0.7855987	0.13192348	3256.4058
274.41528	0.79025435	0.13297799	3256.5088
275.31616	0.79358482	0.1339553	3264.0771
276.21704	0.79113394	0.13513218	3257.5735
277.11792	0.79574913	0.13622527	3259.657
278.0188	0.79872262	0.13742849	3268.3738
278.91968	0.80282921	0.13844387	3265.4038
279.82056	0.80612606	0.13939895	3263.8464
280.72144	0.80912465	0.1403382	3270.8445
281.62231	0.81033301	0.14127323	3271.7524
282.52319	0.81081861	0.14224418	3265.7344
283.42407	0.81554931	0.14325903	3274.0908
284.32495	0.82063341	0.14439444	3282.4556
285.22583	0.82200575	0.14528726	3283.2439
286.12671	0.8267405	0.14614156	3279.3972
287.02759	0.82795835	0.14698955	3272.0205
287.92847	0.83156931	0.14800584	3284.3831
288.82935	0.83334059	0.14874259	3280.2937
289.73022	0.83481807	0.14978631	3288.6089
290.6311	0.83586586	0.15085952	3286.5469
291.53198	0.84106469	0.15173823	3284.2993
292.43286	0.84373146	0.15279606	3294.7424
293.33374	0.84887689	0.15370668	3292.4492
294.23462	0.84967905	0.15480176	3292.9258
295.1355	0.85059547	0.15587576	3294.4058
296.03638	0.85653442	0.15706512	3299.0105
296.93726	0.85754937	0.15799148	3294.0774
297.83813	0.8621707	0.15903014	3295.4004
298.73901	0.86016256	0.15989918	3296.0154
299.63989	0.86179614	0.16090116	3303.1389
300.54077	0.86821961	0.16193686	3301.0073
301.44165	0.87044162	0.16303639	3304.6938
302.34253	0.87196785	0.16420653	3307.8337
303.24341	0.8760255	0.16518956	3312.2151
304.14429	0.87930942	0.16634499	3313.418
305.04517	0.882402	0.16728556	3318.0681
305.94604	0.88160866	0.16831033	3309.6003
306.84692	0.88684869	0.16937912	3317.2769
307.7478	0.88812762	0.17022164	3313.9888
308.64868	0.8900159	0.17132547	3314.2361
309.54956	0.89414722	0.17212214	3319.0996
310.45044	0.89520508	0.17335829	3321.8186
311.35132	0.89778543	0.17455201	3322.5786
312.2522	0.90360618	0.17559575	3327.689
313.15308	0.90406263	0.17665616	3330.1438
314.05396	0.90823948	0.1779141	3335.8171
314.95483	0.91244131	0.17900835	3335.4836
315.85571	0.91127694	0.18004206	3332.2769
316.75659	0.91429847	0.18092796	3326.9971
317.65747	0.9194088	0.1818447	3333.9158
318.55835	0.9214648	0.18271147	3330.9822
319.45923	0.92815161	0.18376063	3338.0095
320.36011	0.92815059	0.18462467	3339.1252
321.26099	0.92912382	0.18572517	3340.2939
322.16187	0.93348402	0.1866646	3337.7334
323.06274	0.93601501	0.187796	3345.4924
323.96362	0.93886501	0.18875249	3343.5291
324.8645	0.94128352	0.18987001	3346.8601
325.76538	0.9438045	0.19091305	3342.3208
326.66626	0.9486267	0.19185178	3349.2026
327.56714	0.94629592	0.19301407	3353.623
328.46802	0.95069039	0.19430053	3355.8254
329.3689	0.95252079	0.19524151	3351.2676
330.26978	0.95671695	0.19638932	3362.1963
331.17065	0.9595772	0.19743535	3359.4692
332.07153	0.96468788	0.19845608	3360.063
332.97241	0.96662658	0.19931984	3356.6733
333.87329	0.96516281	0.20024353	3362.3159
334.77417	0.97085679	0.2013713	3358.5066
335.67505	0.97216779	0.20228878	3362.5105
336.57593	0.978984	0.20334102	3371.0864
337.47681	0.97532183	0.20448519	3369.0034
338.37769	0.98370653	0.20546708	3368.3726
339.27856	0.98517168	0.20654924	3370.2646
340.17944	0.98747075	0.20761384	3374.0098
341.08032	0.98983002	0.20866808	3377.0464
341.9812	0.99308652	0.20953877	3373.1414
342.88208	0.99578696	0.21044721	3379.2961
343.78296	0.99806446	0.21154165	3373.3948
344.68384	0.99906087	0.21255533	3375.5439
345.58472	1.0005293	0.2135216	3381.2368
346.4856	1.0032283	0.2144378	3380.469
347.38647	1.0094582	0.2155353	3382.175
348.28735	1.010934	0.21660209	3386.2747
349.18823	1.0131775	0.21768917	3386.7251
350.08911	1.0174632	0.21870151	3385.123
350.98999	1.0201929	0.21961142	3384.9585
351.89087	1.0213137	0.22061244	3392.072
352.79175	1.0253216	0.22171879	3392.3799
353.69263	1.0275574	0.22276551	3391.6821
354.59351	1.0275494	0.22374399	3388.3718
355.49438	1.0311173	0.22480662	3398.3557
356.39526	1.0341347	0.22597261	3393.157
357.29614	1.0383294	0.2270624	3399.8716
358.19702	1.0385755	0.22804613	3394.7197
359.0979	1.0444943	0.22892433	3399.8982
359.99878	1.0463464	0.22996084	3404.1702
360.89966	1.0492868	0.23104247	3400.2168
361.80054	1.051699	0.23204273	3401.4888
362.70142	1.0547752	0.23296903	3402.7537
363.60229	1.0587238	0.23401058	3409.8774
364.50317	1.0613583	0.23489816	3408.4497
365.40405	1.0643197	0.23579451	3409.3784
366.30493	1.0665141	0.23668504	3406.426
367.20581	1.066336	0.23789848	3417.8843
368.10669	1.0720201	0.23897523	3411.8452
369.00757	1.0720776	0.24007618	3413.3259
369.90845	1.0759543	0.24118912	3420.083
370.80933	1.0774848	0.24244562	3418.8245
371.71021	1.0810798	0.24376369	3418.9858
372.61108	1.0848488	0.24474038	3418.7512
373.51196	1.0850357	0.24582796	3420.8833
374.41284	1.085966	0.24690361	3423.54
375.31372	1.0904076	0.24797675	3421.3782
376.2146	1.092213	0.24892978	3424.6699
377.11548	1.0978628	0.24995339	3424.3284
378.01636	1.0987602	0.25077757	3423.3081
378.91724	1.105495	0.25179663	3431.6626
379.81812	1.1074702	0.25265071	3431.2654
380.71899	1.1090461	0.25371325	3434.9307
381.61987	1.1085116	0.25499123	3435.186
382.52075	1.1111259	0.25590041	3428.3906
383.42163	1.1161566	0.25696898	3432.3364
384.32251	1.1167296	0.25794682	3432.5051
385.22339	1.1225023	0.25900799	3437.8591
386.12427	1.1231539	0.25983706	3438.8574
387.02515	1.1263604	0.26097932	3439.1921
387.92603	1.1318659	0.26194614	3432.5413
388.8269	1.1324378	0.26293886	3447.7781
389.72778	1.1356674	0.26382554	3440.533
390.62866	1.1377814	0.26488936	3442.761
391.52954	1.1424435	0.2658453	3449.2898
392.43042	1.1458259	0.26675612	3439.728
393.3313	1.1448021	0.26768029	3451.9294
394.23218	1.1515074	0.26889297	3450.366
395.13306	1.1540465	0.26974744	3449.6304
396.03394	1.1551698	0.27089271	3460.8691
396.93481	1.1585792	0.27197766	3452.7739
397.83569	1.1571347	0.27303496	3458.0564
398.73657	1.1628118	0.27413386	3459.9238
399.63745	1.1661545	0.2752192	3461.5833
400.53833	1.1679991	0.27622613	3453.739
401.43921	1.1675811	0.27730054	3462.2102
402.34009	1.1728252	0.27831647	3455.8916
403.24097	1.1748103	0.27935436	3462.2556
404.14185	1.1791217	0.28059071	3470.4834
405.04272	1.1805252	0.28149828	3462.7603
405.9436	1.1851068	0.28284582	3470.489
406.84448	1.1862853	0.28393826	3465.2417
407.74536	1.1899288	0.28484321	3465.1692
408.64624	1.191471	0.28595981	3470.3193
409.54712	1.1940169	0.28677198	3471.3584
410.448	1.1950022	0.28787988	3470.0071
411.34888	1.1995149	0.28905535	3478.645
412.24976	1.2000564	0.29023573	3472.3154
413.15063	1.2027	0.29115847	3469.1733
414.05151	1.2089806	0.29231128	3477.2488
414.95239	1.2126397	0.29343393	3480.5164
415.85327	1.2128494	0.29438916	3473.9143
416.75415	1.2158839	0.29526007	3476.0205
417.65503	1.2196366	0.29618007	3482.6777
418.55591	1.2230713	0.29701993	3480.1445
419.45679	1.2227746	0.29815507	3484.5122
420.35767	1.2260166	0.29921776	3485.3032
421.25854	1.232788	0.30051029	3491.7952
422.15942	1.2328219	0.30149233	3484.0728
423.0603	1.2345643	0.30245388	3484.3357
423.96118	1.2387085	0.30348083	3487.9893
424.86206	1.2390119	0.30463597	3491.6677
425.76294	1.2452571	0.30578437	3494.9438
426.66382	1.2459594	0.30675301	3492.3044
427.5647	1.248608	0.30768782	3490.7021
428.46558	1.2524909	0.30867589	3497.2761
429.36646	1.2534858	0.30985785	3504.0259
430.26733	1.2581304	0.31063956	3496.9277
431.16821	1.2581142	0.31168914	3494.3542
432.06909	1.2613806	0.31234342	3488.6423
432.96997	1.2657455	0.31324366	3498.1135
433.87085	1.267383	0.31411085	3498.6606
434.77173	1.2694864	0.31513768	3504.8108
435.67261	1.2733358	0.31630835	3506.748
436.57349	1.2758894	0.31736723	3506.1484
437.47437	1.2783657	0.31842583	3504.1748
438.37524	1.2821324	0.31949461	3513.6145
439.27612	1.2849393	0.32064858	3508.0674
440.177	1.2883191	0.32148555	3505.8801
441.07788	1.2904707	0.32254437	3509.9277
441.97876	1.2913054	0.32360846	3507.105
442.87964	1.2946953	0.32484892	3521.0247
443.78052	1.2965909	0.32595512	3515.9783
444.6814	1.2995081	0.32708746	3512.821
445.58228	1.3056265	0.32824636	3515.5239
446.48315	1.3019058	0.32942063	3515.1985
447.38403	1.3075405	0.33051196	3517.0649
448.28491	1.3109938	0.33176622	3519.1814
449.18579	1.3151696	0.33260286	3511.9453
450.08667	1.3156602	0.33361694	3516.2803
450.98755	1.322883	0.3347162	3522.3665
451.88843	1.3227863	0.33540839	3515.3293
452.78931	1.3237021	0.33653796	3524.7832
453.69019	1.3295923	0.33746177	3521.9724
454.59106	1.331079	0.33856797	3526.3091
455.49194	1.3350631	0.33965886	3533.938
456.39282	1.3324168	0.34077689	3524.5405
457.2937	1.340453	0.34199202	3535.4771
458.19458	1.3412635	0.34312013	3527.1621
459.09546	1.3425186	0.34409636	3531.5698
459.99634	1.3470939	0.34529972	3533.2271
460.89722	1.3499726	0.34631488	3536.7844
461.7981	1.353617	0.34754205	3532.1062
462.69897	1.355472	0.34852609	3536.3362
463.59985	1.3571082	0.34955648	3529.6768
464.50073	1.3580928	0.35051522	3535.2847
465.40161	1.3641984	0.3515662	3539.2781
466.30249	1.3640757	0.35246935	3533.0791
467.20337	1.3668058	0.35357451	3537.4946
468.10425	1.3693671	0.35453779	3542.5781
469.00513	1.372025	0.35566139	3545.6052
469.90601	1.3754468	0.35697323	3542.2527
470.80688	1.3797255	0.35799462	3542.095
471.70776	1.3827691	0.35902104	3544.9714
472.60864	1.3841237	0.35997349	3540.5627
473.50952	1.385528	0.36081344	3550.5359
474.4104	1.389099	0.36201727	3550.5288
475.31128	1.3923458	0.36303642	3541.9368
476.21216	1.3955402	0.36422032	3551.6899
477.11304	1.3973944	0.36513588	3543.9951
478.01392	1.400812	0.36622477	3551.3772
478.91479	1.405169	0.3672266	3555.9939
479.81567	1.4058487	0.36846742	3560.5901
480.71655	1.4087481	0.36962384	3555.7766
481.61743	1.4106905	0.37076947	3555.3738
482.51831	1.4149743	0.37191355	3557.7126
483.41919	1.4158529	0.37307411	3559.4114
484.32007	1.4182683	0.37420517	3553.8569
485.22095	1.4225984	0.37519532	3558.2139
486.12183	1.4239635	0.376205	3561.9895
487.02271	1.4270539	0.37725174	3558.4753
487.92358	1.431535	0.37833628	3562.116
488.82446	1.4306991	0.3793458	3562.4534
489.72534	1.4353298	0.38051948	3564.6924
490.62622	1.4370228	0.38169101	3571.7141
491.5271	1.4394094	0.3828012	3566.0645
492.42798	1.4445184	0.38370442	3567.9712
493.32886	1.4452368	0.38480046	3565.0498
494.22974	1.4502543	0.38580447	3567.3923
495.13062	1.4519225	0.3869195	3572.408
496.03149	1.4535006	0.38801819	3576.0237
496.93237	1.4562292	0.38922888	3570.8459
497.83325	1.4604368	0.39039296	3569.9612
498.73413	1.4600958	0.39158121	3571.6753
499.63501	1.4665843	0.39255026	3572.2397
500.53589	1.4683617	0.39346051	3571.5903
501.43677	1.46989	0.39448485	3578.4749
502.33765	1.4724785	0.39546338	3570.3428
503.23853	1.4739554	0.39624929	3568.6724
504.1394	1.4782958	0.39736012	3581.1887
505.04028	1.4804196	0.39842218	3583.5278
505.94116	1.4846067	0.39958325	3580.665
506.84204	1.4865007	0.40077206	3576.9348
507.74292	1.4896753	0.40195221	3579.3306
508.6438	1.493468	0.40306887	3582.1177
509.54468	1.4945964	0.40421465	3586.7258
510.44556	1.4993657	0.40530574	3586.6162
511.34644	1.4994915	0.40642333	3589.0676
512.24731	1.5017421	0.4077352	3593.8062
513.14819	1.504994	0.40873185	3586.3997
514.04907	1.5076256	0.40970296	3580.5081
514.94995	1.5109671	0.41056383	3589.1904
515.85083	1.5146639	0.41154015	3590.0354
516.75171	1.5173725	0.41283914	3597.7554
517.65259	1.5179625	0.41408545	3597.3215
518.55347	1.5257527	0.41538149	3594.5337
519.45435	1.5262026	0.41650611	3595.2947
520.35522	1.5296873	0.41774768	3597.1941
521.2561	1.530737	0.41877627	3592.6541
522.15698	1.5337141	0.42000094	3601.4373
523.05786	1.5369459	0.42124557	3600.6616
523.95874	1.5386506	0.42237827	3598.8008
524.85962	1.5423329	0.42341173	3598.9968
525.7605	1.5415227	0.42435518	3590.6016
526.66138	1.5470402	0.425401	3595.6348
527.56226	1.5502216	0.4262549	3598.0073
528.46313	1.5542762	0.4273324	3609.2886
529.36401	1.5549768	0.42840752	3602.9746
530.26489	1.5574758	0.4296982	3606.7866
531.16577	1.5593709	0.43072596	3606.2532
532.06665	1.5604571	0.43185118	3609.1443
532.96753	1.5664431	0.43306592	3611.1348
533.86841	1.569611	0.4340978	3606.4802
534.76929	1.5704845	0.43521631	3603.0872
535.67017	1.5731844	0.43619737	3607.0095
536.57104	1.5752727	0.43729424	3603.9185
537.47192	1.5774209	0.43832022	3602.6521
538.3728	1.580808	0.43935487	3608.9722
539.27368	1.5843703	0.44041249	3614.2
540.17456	1.5859829	0.4417012	3612.5261
541.07544	1.5881722	0.44278535	3610.9065
541.97632	1.5901824	0.44379622	3610.8381
542.8772	1.5927918	0.44511929	3616.7961
543.77808	1.5993201	0.44625968	3619.2146
544.67896	1.5978483	0.44751373	3619.3521
545.57983	1.6012982	0.44870886	3616.2417
546.48071	1.608431	0.44971895	3616.8669
547.38159	1.6083617	0.45093304	3617.3037
548.28247	1.6106814	0.4520562	3618.2119
549.18335	1.612577	0.45325136	3618.366
550.08423	1.6161884	0.45423588	3619.2881
550.98511	1.6196865	0.45542786	3625.5281
551.88599	1.6197001	0.45663384	3623.1887
552.78687	1.6271992	0.45786342	3617.949
553.68774	1.6257097	0.45899525	3625.719
554.58862	1.6295656	0.46037397	3628.186
555.4895	1.6361811	0.46203175	3636.8733
556.39038	1.6376946	0.46326962	3625.3535
557.29126	1.6382439	0.46439844	3625.936
558.19214	1.6423954	0.46541396	3622.6189
559.09302	1.6419395	0.46661142	3626.7996
559.9939	1.6447618	0.4676958	3631.4661
560.89478	1.6509421	0.46890652	3635.1414
561.79565	1.6493578	0.47015238	3634.8125
562.69653	1.6534245	0.47117576	3625.3577
563.59741	1.6576635	0.47216237	3629.5796
564.49829	1.6591092	0.47306877	3630.3643
565.39917	1.663941	0.47415367	3635.1584
566.30005	1.6662936	0.47507495	3632.5283
567.20093	1.666689	0.47609702	3642.7954
568.10181	1.6692201	0.47752917	3644.8511
569.00269	1.6733665	0.47868118	3635.1636
569.90356	1.676546	0.47973537	3636.9719
570.80444	1.6769899	0.48106825	3635.4458
571.70532	1.6818895	0.48231721	3637.3132
572.6062	1.6820974	0.48326927	3630.3757
573.50708	1.6885731	0.48422694	3633.8655
574.40796	1.6894286	0.48521078	3639.0781
575.30884	1.6930946	0.48626134	3647.0979
576.20972	1.6949264	0.48745686	3640.0901
577.1106	1.6970947	0.48848641	3637.0759
578.01147	1.7011917	0.48960346	3649.4822
578.91235	1.7048839	0.49059212	3647.4536
579.81323	1.7053506	0.4917227	3645.2678
580.71411	1.707348	0.49278873	3639.1013
581.61499	1.7123331	0.49397713	3646.5879
582.51587	1.7124091	0.49512875	3649.8904
583.41675	1.7168494	0.4962568	3656.9844
584.31763	1.7162502	0.49759406	3648.3516
585.21851	1.7225791	0.49889416	3648.7122
586.11938	1.7254549	0.50026947	3649.0171
587.02026	1.7286274	0.50153798	3654.2695
587.92114	1.7283974	0.50287724	3653.2197
588.82202	1.7344694	0.50437212	3653.3943
589.7229	1.7343094	0.50552744	3651.7632
590.62378	1.7389367	0.50685769	3654.2532
591.52466	1.7389586	0.50802827	3655.6621
592.42554	1.7434251	0.50914139	3654.9651
593.32642	1.7474326	0.51009858	3653.7834
594.22729	1.7488055	0.51119465	3655.2683
595.12817	1.7536236	0.51237702	3665.5437
596.02905	1.7563108	0.51391387	3660.8826
596.92993	1.7586387	0.51511937	3658.2363
597.83081	1.7618079	0.51607144	3656.5605
598.73169	1.7597597	0.51713347	3656.9236
599.63257	1.7655212	0.51856965	3661.7903
600.53345	1.7690171	0.51969451	3661.5159
601.43433	1.7682781	0.52087444	3658.4189
602.33521	1.7734541	0.5220055	3661.1011
603.23608	1.7771093	0.52328175	3658.4502
604.13696	1.780201	0.52439898	3665.2219
605.03784	1.7812266	0.52556241	3658.5618
605.93872	1.781147	0.52671546	3662.0007
606.8396	1.7851509	0.52798659	3667.1904
607.74048	1.7889465	0.52904904	3663.1536
608.64136	1.7933625	0.53031808	3668.6636
609.54224	1.7918317	0.53160876	3664.0452
610.44312	1.7973192	0.53272337	3661.6133
611.34399	1.7993001	0.53383636	3667.781
612.24487	1.8045028	0.53486258	3662.3069
613.14575	1.8072689	0.53582889	3666.2515
614.04663	1.8087162	0.53706652	3671.2734
614.94751	1.8117104	0.53823376	3670.208
615.84839	1.8109238	0.5393768	3671.4368
616.74927	1.8162149	0.54082197	3674.3589
617.65015	1.8168527	0.54211569	3671.2893
618.55103	1.8242277	0.54343802	3674.9041
619.4519	1.8242155	0.54454547	3672.4348
620.35278	1.8281038	0.5460121	3672.8057
621.25366	1.8301646	0.54713738	3672.3779
622.15454	1.8343508	0.54836142	3672.4082
623.05542	1.8346094	0.54939932	3675.0686
623.9563	1.8377113	0.55046266	3669.312
624.85718	1.8385471	0.55181956	3672.7617
625.75806	1.8414637	0.55312282	3675.8855
626.65894	1.8472121	0.5545271	3678.113
627.55981	1.849902	0.5559392	3673.7598
628.46069	1.8495103	0.5571577	3680.532
629.36157	1.8527772	0.55848783	3674.0796
630.26245	1.8590302	0.55983365	3678.9524
631.16333	1.8603209	0.56103086	3678.0398
632.06421	1.8620046	0.56214619	3677.9324
632.96509	1.8645321	0.5633741	3678.4617
633.86597	1.8660008	0.56471914	3680.7961
634.76685	1.8723755	0.56617177	3682.7581
635.66772	1.8729391	0.56736523	3685.585
636.5686	1.8781725	0.56878334	3686.353
637.46948	1.8789743	0.57001567	3683.167
638.37036	1.8838861	0.57131898	3686.563
639.27124	1.8846755	0.57251757	3685.0784
640.17212	1.8860925	0.57374167	3682.1377
641.073	1.8893521	0.57492125	3687.5925
641.97388	1.892018	0.57630503	3686.906
642.87476	1.8939679	0.57759154	3688.709
643.77563	1.9006751	0.57915789	3691.4385
644.67651	1.8992712	0.58044994	3684.5791
645.57739	1.9004871	0.58178544	3682.7886
646.47827	1.906111	0.58307981	3683.4839
647.37915	1.9107054	0.58431476	3686.51
648.28003	1.9100047	0.58530092	3688.9141
649.18091	1.9140035	0.58646119	3691.2124
650.08179	1.9130576	0.58789432	3685.7195
650.98267	1.9184135	0.58904839	3690.4854
651.88354	1.9211226	0.59031636	3692.9453
652.78442	1.9249713	0.59150803	3688.3909
653.6853	1.9277219	0.59305871	3700.5466
654.58618	1.928696	0.59427589	3685.9668
655.48706	1.932258	0.59545225	3693.3823
656.38794	1.9355819	0.59674269	3695.3721
657.28882	1.938818	0.59802204	3694.3467
658.1897	1.9425861	0.59932154	3694.8208
659.09058	1.9384623	0.60063976	3692.9568
659.99146	1.9462218	0.6020534	3695.5972
660.89233	1.9490178	0.60330218	3697.7507
661.79321	1.9518108	0.60478753	3702.1157
662.69409	1.9547464	0.60610276	3697.9568
663.59497	1.9567184	0.6074881	3691.4231
664.49585	1.9602096	0.60878307	3693.6145
665.39673	1.9644006	0.61011279	3703.7346
666.29761	1.9640797	0.61151314	3697.9827
667.19849	1.9706312	0.61289692	3701.9094
668.09937	1.9676614	0.61420864	3698.5261
669.00024	1.9683133	0.61540896	3693.5361
669.90112	1.9761628	0.61676627	3702.1416
670.802	1.9795736	0.61818105	3702.1169
671.70288	1.9806888	0.61937833	3699.5088
672.60376	1.9844357	0.62061161	3705.2036
673.50464	1.9871337	0.62198895	3703.4155
674.40552	1.9914074	0.62338078	3705.0222
675.3064	1.9934517	0.62474245	3702.1213
676.20728	1.9943439	0.62590802	3692.8335
677.10815	1.996889	0.62711799	3706.8618
678.00903	1.9981408	0.62831658	3702.8142
678.90991	2.0027523	0.62951994	3704.0166
679.81079	2.0069313	0.63074499	3703.8225
680.71167	2.0089443	0.63221878	3706.709
681.61255	2.0088248	0.63379157	3706.6411
682.51343	2.014678	0.63514853	3704.1389
683.41431	2.0164726	0.63646573	3701.6597
684.31519	2.0187182	0.63767487	3700.4951
685.21606	2.0223134	0.63893378	3700.5247
686.11694	2.0243921	0.64018005	3706.8557
687.01782	2.0271027	0.64151365	3707.0974
687.9187	2.0296049	0.64282447	3711.7554
688.81958	2.0341256	0.64445531	3713.7981
689.72046	2.0367315	0.64583772	3708.2417
690.62134	2.0364389	0.64729071	3706.8984
691.52222	2.0402935	0.64868379	3712.1746
692.4231	2.0436347	0.65011871	3713.2905
693.32397	2.0453272	0.65176243	3712.1643
694.22485	2.0471668	0.65326899	3705.6621
695.12573	2.05529	0.6545828	3711.9023
696.02661	2.0529985	0.65601599	3707.1287
696.92749	2.0574636	0.65708816	3707.3032
697.82837	2.05967	0.65833861	3708.4941
698.72925	2.0631418	0.65985548	3709.7883
699.63013	2.0654974	0.66105694	3708.5215
700.53101	2.0677419	0.66250557	3711.2009
701.43188	2.0730371	0.66403389	3716.6025
702.33276	2.072623	0.66545397	3709.0452
703.23364	2.0770419	0.66679645	3710.1035
704.13452	2.0800817	0.66807306	3714.468
705.0354	2.082557	0.66950756	3718.8284
705.93628	2.0842969	0.6710031	3709.6724
706.83716	2.0840077	0.67237842	3711.1155
707.73804	2.0879264	0.67399567	3719.0095
708.63892	2.0952995	0.67545688	3720.5737
709.53979	2.0939622	0.67696714	3718.3462
710.44067	2.0959823	0.67842257	3715.9048
711.34155	2.1008475	0.67986554	3719.8965
712.24243	2.1018908	0.68149811	3720.9097
713.14331	2.1051278	0.68295842	3718.5415
714.04419	2.1081612	0.68405795	3711.7219
714.94507	2.1118102	0.68523759	3712.103
715.84595	2.1125121	0.68639863	3716.3975
716.74683	2.1193016	0.68761706	3716.8311
717.64771	2.1175306	0.68893242	3714.863
718.54858	2.1213422	0.69027555	3716.3276
719.44946	2.1249089	0.69192076	3727.1707
720.35034	2.1291354	0.69344181	3723.2754
721.25122	2.1302185	0.69489229	3716.812
722.1521	2.1314158	0.69631016	3711.3127
723.05298	2.1353581	0.69767451	3717.896
723.95386	2.1367435	0.69919229	3714.4939
724.85474	2.1393104	0.70069999	3716.6133
725.75562	2.1455457	0.70231497	3725.0769
726.65649	2.1475034	0.70363992	3715.8601
727.55737	2.1510863	0.70500326	3721.4973
728.45825	2.1500268	0.70647269	3719.7056
729.35913	2.1518629	0.70783871	3720.553
730.26001	2.1580155	0.70937592	3722.5503
731.16089	2.1598277	0.71091342	3721.1814
732.06177	2.1626847	0.71230763	3725.4229
732.96265	2.1651855	0.71385896	3723.5386
733.86353	2.1685824	0.71528554	3718.842
734.7644	2.1731396	0.71679544	3724.2996
735.66528	2.1729484	0.71814436	3718.3428
736.56616	2.1762106	0.71964473	3730.0583
737.46704	2.1808202	0.72124135	3724.9758
738.36792	2.1821406	0.72279626	3721.781
739.2688	2.1835835	0.7242617	3725.6775
740.16968	2.1873441	0.72573733	3724.552
741.07056	2.1876841	0.72729009	3724.6406
741.97144	2.1938882	0.72880834	3724.9534
742.87231	2.1948247	0.73064041	3728.8508
743.77319	2.1977911	0.73241812	3725.7073
744.67407	2.2019312	0.73379099	3718.8325
745.57495	2.2038469	0.73557109	3730.5271
746.47583	2.204463	0.73719627	3718.2922
747.37671	2.2105129	0.73881477	3726.311
748.27759	2.213444	0.74028146	3722.3962
749.17847	2.2106078	0.74166703	3715.1021
750.07935	2.2147274	0.74294662	3717.2085
750.98022	2.2198989	0.74448663	3724.584
751.8811	2.2241435	0.74606115	3723.5129
752.78198	2.2237282	0.74764919	3727.7144
753.68286	2.2251751	0.74904257	3722.8843
754.58374	2.2294509	0.75047797	3719.0864
755.48462	2.2334352	0.75196844	3723.3
756.3855	2.2351305	0.75359404	3728.1887
757.28638	2.2387297	0.75520819	3728.9727
758.18726	2.2409079	0.75666714	3720.168
759.08813	2.2430656	0.75798374	3717.125
759.98901	2.2445343	0.75952917	3724.4563
760.88989	2.2494338	0.76130599	3723.4036
761.79077	2.2523925	0.76327461	3730.0093
762.69165	2.2562132	0.76483405	3724.2932
763.59253	2.2582533	0.76644307	3725.9224
764.49341	2.2610142	0.76816827	3737.3835
765.39429	2.2644513	0.76991802	3728.5403
766.29517	2.2663963	0.77161968	3725.0793
767.19604	2.2698812	0.77305764	3721.5315
768.09692	2.2698565	0.77453858	3726.6948
768.9978	2.272836	0.77620035	3732.9929
769.89868	2.2750502	0.7780304	3731.5989
770.79956	2.2800202	0.77984858	3728.3279
771.70044	2.2835929	0.78139603	3725.5596
772.60132	2.2841408	0.78276545	3721.6958
773.5022	2.290019	0.78415239	3722.9717
774.40308	2.2883358	0.78550452	3723.6406
775.30396	2.2928648	0.78709501	3728.3389
776.20483	2.2946343	0.78876352	3732.2732
777.10571	2.2989984	0.79024136	3722.9324
778.00659	2.3046947	0.79189545	3733.3481
778.90747	2.3010275	0.79346192	3730.0996
779.80835	2.3054039	0.79516178	3730.3992
780.70923	2.3069558	0.79690433	3729.5999
781.61011	2.3104548	0.79857635	3725.7061
782.51099	2.3158517	0.80028337	3728.7949
783.41187	2.317332	0.80163264	3726.9404
784.31274	2.3213873	0.80323219	3728.1829
785.21362	2.3194959	0.80506748	3724.1201
786.1145	2.3226593	0.80686498	3730.6387
787.01538	2.3289733	0.80862164	3726.635
787.91626	2.3297856	0.81002223	3721.2224
788.81714	2.3301325	0.81152475	3725.7363
789.71802	2.3330915	0.81313801	3724.4607
790.6189	2.3377485	0.81498247	3728.2268
791.51978	2.3387787	0.81682616	3720.8804
792.42065	2.3434477	0.8185122	3726.1824
793.32153	2.3480797	0.82002652	3725.363
794.22241	2.349968	0.82150835	3728.1648
795.12329	2.3506889	0.8230316	3721.7178
796.02417	2.3539176	0.82499385	3730.4316
796.92505	2.3567595	0.82697272	3728.158
797.82593	2.3605461	0.82875764	3728.4304
798.72681	2.3629115	0.83037704	3730.1467
799.62769	2.3649781	0.83225596	3727.2766
800.52856	2.3691914	0.8340677	3732.1775
801.42944	2.3736253	0.83585393	3727.4199
802.33032	2.373724	0.83755374	3723.1294
803.2312	2.3756325	0.83943766	3728.687
804.13208	2.3803363	0.84125292	3730.1162
805.03296	2.3819714	0.84327185	3728.8008
805.93384	2.3869927	0.84512389	3727.5269
806.83472	2.3860095	0.84688926	3723.6904
807.7356	2.388468	0.84869641	3721.106
808.63647	2.3936036	0.85036021	3726.1934
809.53735	2.3963811	0.85187864	3724.7339
810.43823	2.3989451	0.85353392	3727.6196
811.33911	2.400682	0.8554197	3732.6064
812.23999	2.4035878	0.85743946	3724.2314
813.14087	2.4071293	0.85926265	3729.3767
814.04175	2.4088933	0.86098099	3723.2053
814.94263	2.4125035	0.86262327	3727.8374
815.84351	2.4138172	0.86460608	3732.0671
816.74438	2.4173431	0.86653233	3725.3416
817.64526	2.4184313	0.86830205	3724.4871
818.54614	2.420413	0.87007362	3724.2458
819.44702	2.425508	0.87201816	3723.9438
820.3479	2.4258296	0.87386358	3723.9983
821.24878	2.4286709	0.875947	3721.2517
822.14966	2.4312396	0.87786716	3719.3979
823.05054	2.4359725	0.87974948	3726.0974
823.95142	2.4372923	0.88160539	3722.4321
824.85229	2.440428	0.88353175	3723.9233
825.75317	2.4431541	0.8853035	3721.6838
826.65405	2.4461429	0.88712305	3720.354
827.55493	2.4509382	0.88899279	3727.6614
828.45581	2.4515388	0.89065665	3716.147
829.35669	2.4535363	0.89254606	3723.3562
830.25757	2.4573114	0.89443648	3726.5605
831.15845	2.461484	0.89647311	3723.4065
832.05933	2.4604023	0.89847827	3722.4216
832.96021	2.4636638	0.9004876	3720.0261
833.86108	2.4669192	0.90251398	3713.8884
834.76196	2.4692922	0.90418595	3715.7021
835.66284	2.4768407	0.90621644	3727.2273
836.56372	2.4772489	0.90822482	3720.1548
837.4646	2.4755764	0.91028708	3716.7732
838.36548	2.4828398	0.91234392	3728.0042
839.26636	2.4833057	0.91435724	3723.4365
840.16724	2.4858482	0.91633517	3720.5613
841.06812	2.4890711	0.91830605	3717.3801
841.96899	2.4936962	0.92041391	3722.6682
842.86987	2.4955549	0.92255419	3718.1655
843.77075	2.4986944	0.92458636	3722.3594
844.67163	2.5016167	0.92671305	3716.7676
845.57251	2.5040534	0.92849636	3714.9136
846.47339	2.5048375	0.93051082	3712.9116
847.37427	2.507591	0.93239361	3713.3044
848.27515	2.5079491	0.9341768	3716.0837
849.17603	2.5130801	0.93626642	3718.3303
850.0769	2.5140269	0.93825084	3716.4978
850.97778	2.5189395	0.94067115	3716.8335
851.87866	2.522747	0.94276601	3716.6008
852.77954	2.5228648	0.94464368	3709.1289
853.68042	2.5281827	0.94645727	3712.4675
854.5813	2.532639	0.94831383	3716.2197
855.48218	2.5340679	0.95047241	3721.0845
856.38306	2.533375	0.95290619	3722.9421
857.28394	2.5380981	0.95527107	3709.1399
858.18481	2.5410538	0.957322	3710.1299
859.08569	2.545531	0.9592979	3714.0386
859.98657	2.5430555	0.96114194	3708.1875
860.88745	2.5479083	0.9629057	3709.0171
861.78833	2.5534124	0.96479517	3712.0942
862.68921	2.5550916	0.96692944	3712.7292
863.59009	2.5585916	0.96877396	3705.5557
864.49097	2.5600398	0.97087657	3709.4441
865.39185	2.561723	0.97300941	3706.7485
866.29272	2.5637715	0.97504848	3706.7454
867.1936	2.5689883	0.97709841	3711.2305
868.09448	2.5695565	0.97937185	3710.2153
868.99536	2.5693419	0.98169374	3714.0747
869.89624	2.5776725	0.98417485	3704.9128
870.79712	2.5777361	0.9862622	3702.7432
871.698	2.5810933	0.98836893	3706.5603
872.59888	2.5843804	0.99083489	3710.02
873.49976	2.5854626	0.99277127	3701.8994
874.40063	2.5875003	0.99443901	3701.3821
875.30151	2.5924249	0.99623621	3698.0032
876.20239	2.596468	0.99811286	3709.137
877.10327	2.5976686	1.0010107	3707.8391
878.00415	2.6012244	1.0040175	3704.6309
878.90503	2.6025126	1.0066825	3701.8577
879.80591	2.6058164	1.0088758	3696.4392
880.70679	2.609534	1.0109234	3699.9915
881.60767	2.6117549	1.0134197	3703.1199
882.50854	2.6127663	1.0158986	3698.8501
883.40942	2.6184044	1.0180807	3696.0425
884.3103	2.6176064	1.0205107	3698.4189
885.21118	2.6224136	1.0231483	3694.4143
886.11206	2.6246994	1.0253028	3692.8135
887.01294	2.6256769	1.027738	3695.448
887.91382	2.6317563	1.0302106	3694.2578
888.8147	2.6343498	1.0324674	3691.0283
889.71558	2.637543	1.0344447	3688.9473
890.61646	2.6402519	1.0366107	3688.1663
891.51733	2.6413586	1.038886	3691.3164
892.41821	2.6443286	1.0412848	3693.7085
893.31909	2.6440554	1.0437574	3689.8113
894.21997	2.6491613	1.0463057	3690.9946
895.12085	2.6494181	1.0487883	3690.4121
896.02173	2.6589854	1.050954	3685.7263
896.92261	2.6562855	1.0531751	3685.821
897.82349	2.6589205	1.0554729	3689.8484
898.72437	2.6619675	1.0578921	3689.8057
899.62524	2.6681042	1.0603031	3686.8538
900.52612	2.6671665	1.0629909	3683.0291
901.427	2.6715567	1.0654044	3679.137
902.32788	2.6739798	1.0674911	3680.4302
903.22876	2.6746774	1.0698727	3679.0557
904.12964	2.6786151	1.0718852	3675.03
905.03052	2.6810479	1.0740553	3677.7495
905.9314	2.6855297	1.0772574	3679.0618
906.83228	2.6873384	1.0799298	3670.5818
907.73315	2.689996	1.0826446	3680.542
908.63403	2.6923935	1.0855303	3677.886
909.53491	2.6959839	1.0882514	3675.1594
910.43579	2.6974149	1.0906807	3664.3354
911.33667	2.7017837	1.0930834	3671.0471
912.23755	2.7018924	1.0956773	3674.5571
913.13843	2.7057216	1.0990345	3668.2324
914.03931	2.7087355	1.102139	3663.1162
914.94019	2.7114832	1.1048313	3663.4727
915.84106	2.7114825	1.1071116	3663.0735
916.74194	2.7163455	1.1099964	3663.6985
917.64282	2.7189231	1.1127325	3660.0596
918.5437	2.7209516	1.1153358	3660.9839
919.44458	2.7254565	1.1177752	3650.9246
920.34546	2.7279222	1.1196474	3647.5767
921.24634	2.7266841	1.1220963	3654.116
922.14722	2.7348077	1.1247636	3651.9795
923.0481	2.736151	1.1269971	3653.5535
923.94897	2.737906	1.1294978	3648.1272
924.84985	2.7415466	1.1319901	3651.3618
925.75073	2.7430701	1.1349374	3649.2769
926.65161	2.744751	1.1381016	3648.8259
927.55249	2.7515194	1.1412333	3654.9658
928.45337	2.752645	1.1443917	3648.1306
929.35425	2.7526839	1.1473125	3640.6472
930.25513	2.7561209	1.1500517	3638.8867
931.15601	2.7587318	1.1523572	3634.5737
932.05688	2.759136	1.1545268	3626.0291
932.95776	2.7662749	1.1567278	3632.1982
933.85864	2.7651515	1.159036	3633.6519
934.75952	2.7711029	1.1616335	3634.3745
935.6604	2.7726779	1.1648707	3634.3679
936.56128	2.7759273	1.1675345	3623.5837
937.46216	2.7784297	1.1704053	3626.1934
938.36304	2.7845471	1.1733187	3619.9473
939.26392	2.7850721	1.1760371	3628.4294
940.16479	2.7879179	1.1791729	3622.3237
941.06567	2.7878811	1.1819271	3615.802
941.96655	2.7952504	1.1851205	3619.0188
942.86743	2.7936993	1.1881689	3613.9753
943.76831	2.8004677	1.1911416	3609.1792
944.66919	2.7987344	1.1936688	3601.7144
945.57007	2.8033817	1.1959991	3609.3672
946.47095	2.8053737	1.199242	3611.8457
947.37183	2.8083837	1.2019758	3599.6934
948.27271	2.811553	1.2045684	3604.5562
949.17358	2.8151226	1.2073302	3600.7769
950.07446	2.8146493	1.2100896	3596.3591
950.97534	2.8216891	1.2125694	3589.5491
951.87622	2.8210611	1.2151068	3590.1702
952.7771	2.8265996	1.2178171	3588.9949
953.67798	2.8298514	1.2204554	3588.2253
954.57886	2.8315878	1.2236558	3584.4543
955.47974	2.8326287	1.2264555	3584.3633
956.38062	2.835525	1.2292622	3578.8875
957.28149	2.8381479	1.232391	3580.511
958.18237	2.8396733	1.2354023	3573.6445
959.08325	2.8388145	1.2381272	3566.6582
959.98413	2.8452611	1.2407367	3568.1611
960.88501	2.8499191	1.2436489	3575.1479
961.78589	2.8545091	1.2467009	3563.958
962.68677	2.85255	1.2494472	3565.9233
963.58765	2.8614106	1.2531725	3568.2622
964.48853	2.8611956	1.2565405	3558.2896
965.3894	2.8633094	1.2593358	3558.4055
966.29028	2.8666639	1.2624077	3556.6863
967.19116	2.8680649	1.2652012	3550.8633
968.09204	2.871758	1.2676489	3541.0637
968.99292	2.8763049	1.2700394	3544.696
969.8938	2.8786435	1.2728121	3548.0361
970.79468	2.8806024	1.275942	3541.7673
971.69556	2.8821042	1.2791609	3534.7605
972.59644	2.8852592	1.2818328	3529.7468
973.49731	2.883266	1.2844808	3524.2109
974.39819	2.8896656	1.2872752	3527.1699
975.29907	2.8947091	1.2909224	3527.1782
976.19995	2.8935869	1.2937365	3520.7229
977.10083	2.8993697	1.2971569	3519.1665
978.00171	2.9021571	1.3003846	3509.9304
978.90259	2.9062819	1.3031776	3501.158
979.80347	2.9035921	1.3056363	3503.7886
980.70435	2.9104459	1.3086942	3503.6355
981.60522	2.90874	1.3117138	3497.2705
982.5061	2.9169881	1.3146012	3496.6479
983.40698	2.9162519	1.3177333	3495.7263
984.30786	2.9210916	1.3213298	3487.2839
985.20874	2.9235203	1.3246948	3482.748
986.10962	2.9247942	1.3278898	3475.6091
987.0105	2.925669	1.3311456	3469.8735
987.91138	2.9308379	1.3344122	3471.9856
988.81226	2.9337149	1.3375304	3467.3235
989.71313	2.9375148	1.3403087	3464.3972
990.61401	2.9372563	1.3430637	3453.5691
991.51489	2.9429913	1.3461324	3451.8076
992.41577	2.9446628	1.3495359	3448.7742
993.31665	2.9458437	1.352856	3437.0852
994.21753	2.9476023	1.3557304	3432.4836
995.11841	2.9513855	1.3590431	3425.4226
996.01929	2.9535484	1.3619806	3424.2773
996.92017	2.9588208	1.3648503	3420.8977
997.82104	2.9599078	1.3677286	3414.5454
998.72192	2.9624836	1.3707364	3414.8628
999.6228	2.9645903	1.3735559	3403.6531
1000.5237	2.9710824	1.3769953	3403.6094
1001.4246	2.971734	1.3806188	3389.3379
1002.3254	2.9747171	1.3832477	3386.1216
1003.2263	2.9760807	1.3860587	3376.26
1004.1272	2.979851	1.3891995	3373.6067
1005.0281	2.9827213	1.3923258	3361.8926
1005.929	2.9846914	1.3957114	3357.4729
1006.8298	2.9892461	1.3991435	3344.2
1007.7307	2.9919195	1.406436	3287.7046