File: datasets/am_bench_2022/raw_data/45-XY.02-3/specimen.dat
MTS793|MPT|ENU|1|2|.|/|:|1|0|0|A

Operator Information						Time:	33.345459	Sec	10/19/2021 11:09:34 AM
Operator	Newell Moser
Project	AM Bench 2022 mini-tensile challenge
Specimen ID	45-XY.02-3
Material	PBF-L Inconel 625
Specimen Width	2.54	mm
Specimen Thickness	1.51	mm
Notes
Operator Information End

Data Acquisition						Time:	1034.3401	Sec	10/19/2021 11:26:15 AM
Time	Axial Displacement	Axial Extensometer	Axial Force
Sec	mm	mm	N
33.459961	0.00084614177	1.3815749e-05	34.923233
34.561035	0.00062752311	0.00016134851	50.055553
35.662109	0.004346448	0.00016599134	65.441185
36.763184	0.0062801577	0.00011519068	79.375206
37.864258	0.013523002	0.00018159994	95.846909
38.965332	0.01421246	0.00022022496	108.75051
40.066406	0.015136723	0.0002558268	125.85382
41.16748	0.018763242	0.00026677619	134.32091
42.268555	0.025418203	0.00030872453	152.00655
43.369629	0.025197741	0.00038269325	169.87044
44.470703	0.028319255	0.00053505733	194.8181
45.571777	0.03431467	0.00051289226	212.32237
46.672852	0.039239995	0.00063797203	234.29047
47.773926	0.041143022	0.00069141167	253.34004
48.875	0.041713644	0.00069986138	267.01062
49.976074	0.046339978	0.00091362925	297.54657
51.077148	0.050774381	0.00094737479	322.15668
52.178223	0.052107606	0.00093446259	338.96805
53.279297	0.05562374	0.0010544457	364.15128
54.380371	0.062269073	0.001225044	394.35687
55.481445	0.063540369	0.001416779	412.14725
56.58252	0.065708935	0.0014816505	444.3895
57.683594	0.067881189	0.0016406644	467.30914
58.784668	0.072285682	0.0016153286	485.97498
59.885742	0.075416155	0.0017294917	512.64807
60.986816	0.079485446	0.0019273652	539.19495
62.087891	0.083715372	0.0020024732	568.3952
63.188965	0.086702831	0.0021104333	594.91644
64.290039	0.089388698	0.0022863958	620.04327
65.391113	0.094293989	0.0024268269	646.7793
66.492188	0.098264314	0.0025092771	672.2934
67.593262	0.099306189	0.0025873652	702.47455
68.694336	0.10377169	0.0026857322	728.26044
69.79541	0.10555403	0.0028687471	767.51239
70.896484	0.10979194	0.0030106935	791.50146
71.997559	0.11315518	0.0031714446	829.79572
73.098633	0.11811636	0.0032270891	855.89105
74.199707	0.11894248	0.0033968433	888.69305
75.300781	0.12338979	0.0035066423	913.29401
76.401855	0.12479883	0.0036104431	938.39087
77.50293	0.1281721	0.0038130658	969.81476
78.604004	0.13125463	0.0039532348	1007.9146
79.705078	0.13569298	0.0041427356	1036.7542
80.806152	0.13645922	0.004192098	1061.0531
81.907227	0.14022875	0.0044220071	1090.6782
83.008301	0.14430603	0.0045045861	1134.2747
84.109375	0.14881794	0.0046132337	1158.8075
85.210449	0.15108459	0.0047099739	1193.4871
86.311523	0.1535504	0.0049281265	1219.7178
87.412598	0.15835977	0.0050762207	1254.5667
88.513672	0.16129236	0.0053089955	1285.2006
89.614746	0.16510943	0.0053303973	1312.0101
90.71582	0.16767052	0.0055068801	1346.1178
91.816895	0.17472999	0.0056944597	1381.8507
92.917969	0.1761255	0.0058326372	1419.0648
94.019043	0.17927729	0.0059901341	1452.4668
95.120117	0.17972907	0.0060226745	1473.988
96.221191	0.18394418	0.0061446535	1500.821
97.322266	0.18571956	0.006323759	1519.2789
98.42334	0.19044185	0.006444029	1559.623
99.524414	0.19700584	0.0066208928	1586.2449
100.62549	0.19715109	0.0066897226	1616.7115
101.72656	0.19911765	0.0067834677	1641.5795
102.82764	0.20440911	0.006981587	1673.8699
103.92871	0.20625558	0.0071495585	1710.1184
105.02979	0.21062109	0.0072533023	1738.9808
106.13086	0.21262965	0.007443029	1765.5513
107.23193	0.21703598	0.0075058723	1798.3678
108.33301	0.22155008	0.0076464131	1822.8181
109.43408	0.22407633	0.0077554467	1845.855
110.53516	0.22522967	0.0077579343	1871.2015
111.63623	0.22986655	0.0079659829	1906.4763
112.7373	0.23533028	0.0080296453	1930.5165
113.83838	0.2374949	0.0081379768	1954.8324
114.93945	0.24192505	0.0082952669	1982.7585
116.04053	0.24329905	0.0084018046	2002.6245
117.1416	0.24838844	0.008494677	2018.4791
118.24268	0.2537342	0.0086179124	2051.6331
119.34375	0.25643283	0.0086387703	2070.8909
120.44482	0.25983089	0.0086935125	2085.9443
121.5459	0.26093909	0.0089514833	2113.2434
122.64697	0.26407161	0.0089320894	2130.3013
123.74805	0.26752874	0.0089655761	2150.8035
124.84912	0.27273354	0.0091357287	2173.988
125.9502	0.27787906	0.0092167072	2193.7314
127.05127	0.27633792	0.0091246115	2201.7239
128.15234	0.27975628	0.009273991	2219.1345
129.25342	0.28402865	0.0093928715	2239.917
130.35449	0.28512847	0.0094428556	2248.6311
131.45557	0.29263392	0.0095276181	2270.356
132.55664	0.29751602	0.0096472735	2283.3284
133.65771	0.29576242	0.0096905865	2306.3538
134.75879	0.30190617	0.0097277043	2323.0552
135.85986	0.30448714	0.0098240515	2334.5107
136.96094	0.30735213	0.0098743113	2343.2639
138.06201	0.31026423	0.010005849	2356.5896
139.16309	0.31821814	0.010090169	2376.521
140.26416	0.31622276	0.010081486	2385.262
141.36523	0.31820402	0.010209885	2390.9756
142.46631	0.32514772	0.010403084	2408.022
143.56738	0.32698333	0.010330192	2427.5195
144.66846	0.32925367	0.010469804	2438.1658
145.76953	0.33253333	0.010535683	2451.0149
146.87061	0.34079817	0.010713157	2464.2703
147.97168	0.34079078	0.010754532	2477.4932
149.07275	0.34196395	0.010810873	2485.9326
150.17383	0.34705073	0.010872905	2489.981
151.2749	0.35138041	0.011004808	2507.8645
152.37598	0.35415486	0.011127888	2515.5737
153.47705	0.35806161	0.011260862	2534.6284
154.57813	0.36142734	0.011259747	2536.165
155.6792	0.36565092	0.011537933	2557.3738
156.78027	0.36564538	0.011666131	2559.958
157.88135	0.37134439	0.011732934	2568.1616
158.98242	0.37690508	0.01183561	2578.9141
160.0835	0.37653032	0.011942354	2595.1145
161.18457	0.38135895	0.012163027	2603.0366
162.28564	0.38508335	0.012145907	2610.7141
163.38672	0.38929078	0.012461295	2620.1833
164.48779	0.38856238	0.012515342	2623.5068
165.58887	0.39378256	0.012731175	2643.0557
166.68994	0.39561996	0.01289348	2640.708
167.79102	0.39669338	0.012991941	2649.0718
168.89209	0.4030841	0.013295303	2665.4373
169.99316	0.40623793	0.013379782	2674.8381
171.09424	0.41082662	0.013577861	2677.5581
172.19531	0.41368726	0.013785204	2689.3589
173.29639	0.41910902	0.014037565	2696.9521
174.39746	0.42067829	0.01419242	2699.9448
175.49854	0.42553124	0.014512076	2714.4739
176.59961	0.42687592	0.014668712	2720.2083
177.70068	0.43024617	0.014860013	2722.3418
178.80176	0.43523169	0.015293053	2739.6838
179.90283	0.43798727	0.015595341	2745.3325
181.00391	0.44188014	0.015921034	2754.5259
182.10498	0.44374016	0.016205475	2752.6299
183.20605	0.44608015	0.016580939	2769.8896
184.30713	0.45335984	0.016947368	2770.9905
185.4082	0.45416054	0.017320389	2775.2068
186.50928	0.45486167	0.017670844	2782.0771
187.61035	0.45907584	0.018059824	2792.4302
188.71143	0.46078339	0.018568145	2799.7708
189.8125	0.46840113	0.019021891	2803.0352
190.91357	0.47045967	0.019535257	2807.4365
192.01465	0.47695398	0.020125957	2818.613
193.11572	0.47540569	0.020645743	2823.2451
194.2168	0.48001912	0.021143004	2822.9355
195.31787	0.48464617	0.021693073	2827.5837
196.41895	0.48343873	0.022245137	2829.4697
197.52002	0.48891926	0.0227545	2837.9705
198.62109	0.49359277	0.023539407	2853.7754
199.72217	0.49698681	0.024139956	2846.5549
200.82324	0.49894229	0.02493253	2859.4666
201.92432	0.50138676	0.025698641	2866.0583
203.02539	0.50796878	0.026480256	2863.3826
204.12646	0.51115239	0.027358903	2881.4783
205.22754	0.5098505	0.028012514	2875.4351
206.32861	0.5154106	0.029005937	2884.0947
207.42969	0.52019531	0.029818915	2882.6479
208.53076	0.52152753	0.030722227	2889.8052
209.63184	0.5257169	0.031588115	2889.9146
210.73291	0.52784669	0.032602727	2896.97
211.83398	0.53549951	0.033615112	2902.6636
212.93506	0.53712881	0.034485191	2897.1958
214.03613	0.54131895	0.03544201	2911.8464
215.13721	0.54612786	0.036612175	2911.8125
216.23828	0.54751086	0.037603986	2917.1265
217.33936	0.54859185	0.038626324	2918.6113
218.44043	0.55111223	0.039641879	2917.1987
219.5415	0.55792332	0.040709715	2924.8206
220.64258	0.55979723	0.041731525	2921.5559
221.74365	0.5619086	0.04301304	2935.0659
222.84473	0.56488627	0.044255491	2934.3452
223.9458	0.56841201	0.045420889	2935.0969
225.04688	0.57087678	0.046615977	2936.457
226.14795	0.57681859	0.0476496	2942.2393
227.24902	0.58119214	0.048696835	2942.1563
228.3501	0.57930636	0.049852192	2951.7466
229.45117	0.58855784	0.051171627	2952.696
230.55225	0.58977163	0.052315842	2955.8604
231.65332	0.59354466	0.053351894	2954.427
232.75439	0.59466499	0.054432876	2955.3789
233.85547	0.60017687	0.055573743	2963.0352
234.95654	0.6015535	0.056684587	2960.8408
236.05762	0.60625738	0.057855375	2966.8276
237.15869	0.60753137	0.059100207	2970.8301
238.25977	0.61484218	0.060335472	2970.6929
239.36084	0.61746848	0.061458729	2978.2957
240.46191	0.62134558	0.062597252	2975.2861
241.56299	0.62094891	0.063615307	2978.446
242.66406	0.62516779	0.064751796	2975.719
243.76514	0.63038462	0.065943293	2982.5437
244.86621	0.63373148	0.067099191	2987.9744
245.96729	0.63431054	0.068514802	2986.9333
247.06836	0.63908154	0.069669031	2988.5332
248.16943	0.6420567	0.070906453	2997.3655
249.27051	0.64702588	0.0720893	2991.4182
250.37158	0.64835602	0.073411673	2998.2229
251.47266	0.65328282	0.074785315	3002.3838
252.57373	0.65756273	0.076393023	3011.1758
253.6748	0.65718985	0.077727415	2997.2002
254.77588	0.6626243	0.078932256	3008.468
255.87695	0.66577649	0.079996087	3003.0159
256.97803	0.66771942	0.081167087	3009.333
258.0791	0.67122841	0.082435586	3013.4639
259.18018	0.67489773	0.083680637	3011.7173
260.28125	0.67771101	0.084863	3017.6106
261.38232	0.68299079	0.086173616	3022.823
262.4834	0.68496102	0.087549277	3024.7026
263.58447	0.68746024	0.08895947	3030.947
264.68555	0.68851954	0.090308562	3022.5447
265.78662	0.69451457	0.091584943	3026.6987
266.8877	0.69909573	0.092809975	3031.1687
267.98877	0.69988966	0.094091579	3032.875
269.08984	0.7061637	0.09549313	3037.2146
270.19092	0.70813471	0.096497908	3031.5283
271.29199	0.70975357	0.097777203	3036.7507
272.39307	0.71860516	0.099028394	3040.1199
273.49414	0.71858221	0.10019147	3037.2832
274.59521	0.72256708	0.10129313	3039.345
275.69629	0.72403145	0.10234195	3037.0024
276.79736	0.7301439	0.10348482	3044.4236
277.89844	0.73054671	0.10474946	3050.0522
278.99951	0.73287219	0.10585925	3045.5042
280.10059	0.73650283	0.10716202	3046.6243
281.20166	0.74159223	0.10860563	3055.4319
282.30273	0.74225056	0.10980753	3058.2915
283.40381	0.75109619	0.11104541	3060.72
284.50488	0.75464487	0.11214348	3059.8833
285.60596	0.75488949	0.1134517	3063.1335
286.70703	0.75714391	0.11507796	3065.623
287.80811	0.7621237	0.11651468	3071.3984
288.90918	0.76618916	0.11787021	3067.4617
290.01025	0.7679202	0.11911698	3069.106
291.11133	0.7681753	0.12046459	3072.2917
292.2124	0.77294552	0.12179437	3075.1033
293.31348	0.77821118	0.12288402	3067.2
294.41455	0.78064609	0.12413917	3076.3567
295.51563	0.78300947	0.12543339	3080.4597
296.6167	0.78704107	0.12691981	3085.5745
297.71777	0.79332155	0.12802112	3084.8821
298.81885	0.79738837	0.12928851	3084.4243
299.91992	0.79571068	0.13039133	3086.7627
301.021	0.79693574	0.13172407	3080.8752
302.12207	0.80015785	0.13295683	3093.1226
303.22314	0.80919379	0.13436154	3088.905
304.32422	0.80767524	0.13550127	3089.7512
305.42529	0.81467372	0.13679519	3093.4917
306.52637	0.81698245	0.13814931	3093.5088
307.62744	0.82129288	0.13961238	3106.3765
308.72852	0.82448322	0.14073218	3094.687
309.82959	0.82595021	0.14173219	3098.4739
310.93066	0.82712752	0.14310516	3097.5837
312.03174	0.83589041	0.1441458	3100.8149
313.13281	0.83720475	0.14515357	3107.2617
314.23389	0.83755469	0.1463726	3107.1052
315.33496	0.84418368	0.14774045	3112.9583
316.43604	0.8449899	0.14889419	3110.877
317.53711	0.85084522	0.15010844	3113.4299
318.63818	0.85166967	0.15151967	3115.5149
319.73926	0.85700971	0.15256274	3113.2131
320.84033	0.86066329	0.15389259	3123.4063
321.94141	0.86195403	0.15530035	3122.5847
323.04248	0.86647332	0.15674743	3122.6609
324.14355	0.87165838	0.15801623	3118.6843
325.24463	0.87282383	0.15914169	3123.3037
326.3457	0.87733918	0.16033308	3119.0491
327.44678	0.88028485	0.16143313	3123.269
328.54785	0.88288116	0.16286062	3125.3828
329.64893	0.88571972	0.16410755	3131.1816
330.75	0.89034855	0.16544569	3134.8923
331.85107	0.89284468	0.16708519	3140.2683
332.95215	0.89631796	0.1686281	3137.8413
334.05322	0.89635217	0.16969688	3128.9856
335.1543	0.9017812	0.1709014	3137.6511
336.25537	0.90575105	0.17218381	3145.2585
337.35645	0.91109043	0.17372389	3144.2251
338.45752	0.91094828	0.17482194	3144.6069
339.55859	0.91477644	0.17603621	3144.2607
340.65967	0.9172492	0.17738485	3144.6587
341.76074	0.92400885	0.17861697	3154.4712
342.86182	0.92852998	0.17988768	3155.4451
343.96289	0.92989659	0.18131736	3149.2036
345.06396	0.93225646	0.18229033	3149.1001
346.16504	0.93656242	0.18373452	3158.4702
347.26611	0.9388572	0.18506303	3154.4187
348.36719	0.94054157	0.18598631	3146.5347
349.46826	0.94575351	0.18697436	3157.5808
350.56934	0.94880104	0.18816155	3153.6594
351.67041	0.95496041	0.1892973	3166.4182
352.77148	0.95685029	0.19070794	3171.0107
353.87256	0.95942694	0.19193442	3166.4399
354.97363	0.96389085	0.19340867	3173.7754
356.07471	0.96874839	0.19465186	3170.7529
357.17578	0.96915323	0.19567239	3162.5649
358.27686	0.9724437	0.19696125	3165.7632
359.37793	0.97809929	0.19792746	3171.0188
360.479	0.97845989	0.19920693	3180.7839
361.58008	0.98089093	0.20052882	3175.8896
362.68115	0.98657286	0.20212135	3191.4661
363.78223	0.98732704	0.20355888	3181.0095
364.8833	0.99224091	0.20488101	3178.6782
365.98438	0.99427402	0.20606115	3180.0095
367.08545	1.0000088	0.20727669	3182.0938
368.18652	1.0026906	0.20859155	3181.4028
369.2876	1.0059596	0.20977914	3189.1597
370.38867	1.0083579	0.21128531	3196.5195
371.48975	1.0111917	0.2125873	3188.1392
372.59082	1.0161544	0.21396643	3186.0059
373.69189	1.0193237	0.21508063	3187.8591
374.79297	1.024551	0.21633452	3192.8162
375.89404	1.0219004	0.21739615	3187.0803
376.99512	1.0304267	0.21860595	3202.3796
378.09619	1.0318944	0.21976024	3200.3689
379.19727	1.0355237	0.22087264	3195.0994
380.29834	1.0398875	0.22195932	3204.0203
381.39941	1.0375348	0.22332999	3201.3391
382.50049	1.0419819	0.22489463	3209.2219
383.60156	1.0469595	0.22632112	3208.3982
384.70264	1.0517445	0.22752626	3205.0442
385.80371	1.057211	0.22851309	3204.6592
386.90479	1.0594329	0.22961502	3210.3396
388.00586	1.0597011	0.2309709	3212.5945
389.10693	1.0663928	0.23218448	3211.7104
390.20801	1.0658021	0.2333803	3214.0027
391.30908	1.0713847	0.23450959	3219.8428
392.41016	1.0759646	0.23589496	3222.7075
393.51123	1.0775664	0.23735712	3225.9241
394.6123	1.0825562	0.23878501	3218.4021
395.71338	1.0847479	0.23994748	3219.604
396.81445	1.0868988	0.24110809	3223.1167
397.91553	1.0935643	0.24221978	3222.0244
399.0166	1.0940025	0.24333119	3228.541
400.11768	1.0984248	0.24452181	3225.4255
401.21875	1.1024243	0.24587849	3232.3105
402.31982	1.1058191	0.24708495	3231.9634
403.4209	1.1076313	0.24858917	3238.1482
404.52197	1.1125802	0.24988912	3244.0049
405.62305	1.1165469	0.25120994	3236.3772
406.72412	1.1172615	0.2522814	3237.2698
407.8252	1.1196665	0.25363013	3241.4512
408.92627	1.1254287	0.25492239	3240.5903
410.02734	1.1286013	0.25602058	3236.5688
411.12842	1.1328189	0.25718096	3238.4526
412.22949	1.1332936	0.25851735	3244.8606
413.33057	1.1388962	0.25957307	3242.853
414.43164	1.1430969	0.2608588	3248.0728
415.53271	1.144605	0.26210505	3251.0659
416.63379	1.1472424	0.26333761	3247.9238
417.73486	1.1514955	0.26457113	3252.9246
418.83594	1.1560913	0.26597846	3251.0725
419.93701	1.1567509	0.26715359	3255.6707
421.03809	1.1631476	0.26835433	3257.9033
422.13916	1.1632137	0.26953226	3252.7925
423.24023	1.1678317	0.27062288	3251.4695
424.34131	1.1693569	0.27196079	3256.98
425.44238	1.1733155	0.27346131	3266.0837
426.54346	1.1781193	0.27484423	3265.8135
427.64453	1.1823608	0.27603427	3265.7747
428.74561	1.1831238	0.27751717	3259.3843
429.84668	1.1851366	0.27860892	3261.2961
430.94775	1.1900483	0.27984801	3260.4866
432.04883	1.1933953	0.28088325	3266.8242
433.1499	1.1964616	0.2821773	3275.6704
434.25098	1.2033466	0.28355047	3275.5957
435.35205	1.2022516	0.28475976	3271.5925
436.45313	1.2058635	0.28611308	3271.354
437.5542	1.2105485	0.28726143	3277.5632
438.65527	1.2128556	0.28862628	3276.3127
439.75635	1.2173729	0.28997228	3272.7983
440.85742	1.219949	0.29124245	3281.1318
441.9585	1.2229642	0.29247615	3280.7019
443.05957	1.2265221	0.29348513	3280.5859
444.16064	1.227951	0.29463401	3278.5344
445.26172	1.2350591	0.29594836	3289.0171
446.36279	1.2376519	0.29717135	3287.2434
447.46387	1.2407138	0.29835522	3290.583
448.56494	1.244598	0.29966882	3293.3616
449.66602	1.2479149	0.30086288	3287.668
450.76709	1.2485595	0.30209985	3293.4312
451.86816	1.2527732	0.30349827	3292.1277
452.96924	1.2561433	0.30469602	3292.0349
454.07031	1.2590395	0.30590069	3299.6709
455.17139	1.2629111	0.30711463	3296.3596
456.27246	1.2659901	0.30841053	3293.47
457.37354	1.2736808	0.30939016	3300.647
458.47461	1.2737228	0.31056362	3300.2563
459.57568	1.2781838	0.31172267	3303.553
460.67676	1.2805259	0.31310081	3306.0261
461.77783	1.2830391	0.314457	3303.1077
462.87891	1.2817825	0.3156001	3300.0295
463.97998	1.2901022	0.3169001	3309.634
465.08105	1.2934279	0.31814572	3308.4446
466.18213	1.2987251	0.31936273	3307.4177
467.2832	1.302665	0.32058054	3316.5361
468.38428	1.3042548	0.32192546	3309.8503
469.48535	1.3044769	0.32296711	3306.8103
470.58643	1.3113527	0.32407305	3307.0779
471.6875	1.3121642	0.32523859	3310.0627
472.78857	1.317654	0.3264026	3314.8923
473.88965	1.3161348	0.32776564	3316.9189
474.99072	1.3206159	0.32940671	3319.0459
476.0918	1.3263096	0.33065179	3325.8438
477.19287	1.3299094	0.33209911	3322.3374
478.29395	1.3344389	0.33332607	3326.1531
479.39502	1.3382611	0.33464485	3327.2175
480.49609	1.338696	0.33602658	3323.5552
481.59717	1.3403254	0.33732206	3326.5066
482.69824	1.3484334	0.33855215	3321.0405
483.79932	1.3480328	0.33958599	3325.8037
484.90039	1.3524021	0.34063703	3326.7839
486.00146	1.3570732	0.34185725	3330.8877
487.10254	1.3605958	0.3431949	3340.3269
488.20361	1.3626475	0.3445563	3336.9434
489.30469	1.3660393	0.34585229	3332.2297
490.40576	1.3690804	0.34720299	3333.4382
491.50684	1.3708802	0.3485657	3336.916
492.60791	1.3751812	0.349722	3340.3237
493.70898	1.3786801	0.35075006	3335.4346
494.81006	1.3795992	0.35184774	3339.1946
495.91113	1.3887106	0.35308352	3344.1987
497.01221	1.3878448	0.35433495	3343.3154
498.11328	1.3881741	0.35593995	3351.0425
499.21436	1.3937726	0.35743847	3344.5664
500.31543	1.3962364	0.35880774	3347.5051
501.4165	1.4004624	0.36011723	3343.6609
502.51758	1.4040691	0.36131921	3356.0208
503.61865	1.4098191	0.3625043	3347.4253
504.71973	1.4095905	0.36369801	3350.1494
505.8208	1.4158237	0.36512506	3360.0808
506.92188	1.4176965	0.36630934	3354.041
508.02295	1.4225963	0.3675172	3358.9656
509.12402	1.4243215	0.36863163	3354.1584
510.2251	1.427999	0.37007448	3360.0688
511.32617	1.4280995	0.37139174	3360.5918
512.42725	1.4351277	0.37264606	3361.3042
513.52832	1.4368529	0.37375003	3356.8164
514.62939	1.4414572	0.37491366	3360.6729
515.73047	1.4415369	0.37620756	3363.9514
516.83154	1.4460773	0.37752125	3363.5981
517.93262	1.452176	0.37876093	3369.2681
519.03369	1.452271	0.38014629	3365.4988
520.13477	1.4578074	0.38142517	3367.645
521.23584	1.4600166	0.38252875	3366.8867
522.33691	1.4655641	0.38385394	3370.1042
523.43799	1.465691	0.38506752	3372.2998
524.53906	1.471489	0.38634735	3373.5684
525.64014	1.473567	0.387474	3371.9395
526.74121	1.4787335	0.38852218	3371.7817
527.84229	1.4826088	0.38981685	3380.9253
528.94336	1.484013	0.39097866	3369.9697
530.04443	1.4898496	0.39202008	3378.0649
531.14551	1.4926109	0.3935613	3388.8665
532.24658	1.4941342	0.3949019	3380.8171
533.34766	1.4976186	0.39602861	3384.1909
534.44873	1.4998	0.39741436	3386.7986
535.5498	1.5055526	0.39859131	3385.9541
536.65088	1.5096211	0.39994901	3389.3323
537.75195	1.5093839	0.40119255	3379.8745
538.85303	1.5145013	0.40243617	3392.7637
539.9541	1.5190629	0.4034104	3386.9321
541.05518	1.5189329	0.40457284	3389.4861
542.15625	1.5239246	0.40600517	3394.0464
543.25732	1.5270522	0.40736866	3390.3013
544.3584	1.5303086	0.40888655	3398.261
545.45947	1.5348552	0.4102926	3398.907
546.56055	1.5385729	0.41164815	3392.0681
547.66162	1.5418917	0.41283286	3395.4712
548.7627	1.5466187	0.41392902	3400.374
549.86377	1.5487807	0.41525409	3397.3767
550.96484	1.5536505	0.41648313	3399.6272
552.06592	1.5500522	0.41787353	3401.4656
553.16699	1.5583551	0.41927448	3409.5681
554.26807	1.5597019	0.4204562	3403.8645
555.36914	1.565408	0.42159086	3401.4248
556.47021	1.5666828	0.42306942	3409.5691
557.57129	1.571987	0.42435163	3408.259
558.67236	1.5776047	0.42577678	3413.1975
559.77344	1.5779146	0.42698818	3406.8054
560.87451	1.5807551	0.42815787	3410.3987
561.97559	1.5813828	0.42944074	3411.4583
563.07666	1.5864513	0.43063784	3406.6619
564.17773	1.5908494	0.43183163	3408.9609
565.27881	1.5962608	0.43317649	3418.908
566.37988	1.5978752	0.43433475	3412.9509
567.48096	1.6004599	0.4357172	3420.8206
568.58203	1.6009982	0.43726259	3417.5647
569.68311	1.6091714	0.43863493	3421.97
570.78418	1.6108835	0.43989804	3421.9182
571.88525	1.6108567	0.44103676	3412.2998
572.98633	1.6154424	0.44214806	3414.407
574.0874	1.6177788	0.44349906	3417.5161
575.18848	1.6238428	0.44452086	3421.7695
576.28955	1.62907	0.44581515	3427.3445
577.39063	1.6335769	0.44735062	3430.9744
578.4917	1.6317478	0.44848609	3422.1572
579.59277	1.638234	0.44978303	3432.3721
580.69385	1.6414413	0.45106846	3426.5442
581.79492	1.646001	0.45235363	3431.5913
582.896	1.6476413	0.45369172	3432.8787
583.99707	1.6489202	0.45481858	3429.082
585.09814	1.6539973	0.45619488	3436.8706
586.19922	1.653932	0.45742899	3428.3557
587.30029	1.6590632	0.45890856	3438.1641
588.40137	1.6603897	0.46042049	3439.8459
589.50244	1.6702981	0.46164441	3438.6187
590.60352	1.6709795	0.46287626	3436.9102
591.70459	1.6696057	0.46400371	3434.8384
592.80566	1.6773057	0.46536437	3447.6707
593.90674	1.6767293	0.46655068	3442.9463
595.00781	1.6817306	0.46792957	3442.4922
596.10889	1.6858741	0.46913654	3442.7737
597.20996	1.6923999	0.47037515	3443.3936
598.31104	1.6930912	0.47158548	3444.5024
599.41211	1.6969608	0.47269729	3443.3823
600.51318	1.7001764	0.47381684	3448.0647
601.61426	1.703723	0.47516811	3449.4116
602.71533	1.7066841	0.47650546	3456.0762
603.81641	1.7081763	0.47785753	3446.4192
604.91748	1.7132013	0.47918931	3454.3054
606.01855	1.7145591	0.4803963	3452.1921
607.11963	1.7186631	0.48158267	3446.5032
608.2207	1.7231011	0.48292813	3453.2415
609.32178	1.7265726	0.48414513	3454.5669
610.42285	1.7272002	0.48545206	3454.8975
611.52393	1.7314469	0.48694724	3458.2043
612.625	1.7350924	0.48833084	3457.9365
613.72607	1.7398469	0.48953098	3454.8289
614.82715	1.742609	0.49077797	3456.9131
615.92822	1.741596	0.49195421	3455.4502
617.0293	1.7457545	0.49318463	3458.7214
618.13037	1.7516267	0.49463332	3462.8237
619.23145	1.7560322	0.49597684	3467.0684
620.33252	1.7557642	0.49735928	3465.1348
621.43359	1.7643192	0.4989174	3467.9917
622.53467	1.7659874	0.50015908	3465.8142
623.63574	1.7653383	0.50151092	3463.021
624.73682	1.7704029	0.5028066	3461.9426
625.83789	1.7765621	0.50414306	3477.2185
626.93896	1.7795789	0.5055775	3468.3003
628.04004	1.7838818	0.50687855	3470.3608
629.14111	1.7837578	0.5081538	3468.1897
630.24219	1.7897719	0.50943589	3473.0632
631.34326	1.7930067	0.51077557	3475.0872
632.44434	1.7979056	0.51191729	3476.1445
633.54541	1.7992907	0.51325703	3477.7087
634.64648	1.803622	0.5144856	3481.8174
635.74756	1.804913	0.51575917	3477.6199
636.84863	1.8081207	0.51726961	3487.438
637.94971	1.8121611	0.51862347	3480.335
639.05078	1.8149664	0.51990092	3474.9148
640.15186	1.8222452	0.5211271	3481.4001
641.25293	1.8232542	0.52238309	3483.4548
642.354	1.8252546	0.52373832	3483.2478
643.45508	1.8296282	0.52512306	3485.1445
644.55615	1.8307829	0.52641034	3482.1016
645.65723	1.8367293	0.52775878	3493.1152
646.7583	1.8373832	0.52896667	3486.1909
647.85938	1.8406312	0.53029162	3490.5259
648.96045	1.844543	0.53168827	3492.7158
650.06152	1.846563	0.53297317	3487.0986
651.1626	1.8505869	0.53431648	3496.1777
652.26367	1.853237	0.53567314	3491.3464
653.36475	1.8579407	0.53717607	3497.5044
654.46582	1.8627967	0.53860837	3490.1423
655.56689	1.8665442	0.54004437	3496.5317
656.66797	1.8682044	0.54151088	3494.9036
657.76904	1.8721738	0.54303128	3494.2517
658.87012	1.8741938	0.54431278	3494.2297
659.97119	1.8786771	0.54546934	3498.2498
661.07227	1.8820691	0.54671216	3496.3425
662.17334	1.8862058	0.5480178	3503.5378
663.27441	1.8872377	0.54936659	3498.4985
664.37549	1.8916491	0.55066115	3496.2119
665.47656	1.8965763	0.55209333	3501.4954
666.57764	1.8976558	0.55345106	3500.8745
667.67871	1.9012367	0.55463058	3505.2249
668.77979	1.9010504	0.55597842	3500.2534
669.88086	1.9097939	0.55742741	3509.0483
670.98193	1.9121389	0.55871123	3509.1348
672.08301	1.9118789	0.55972624	3497.9968
673.18408	1.9189125	0.56083173	3505.7178
674.28516	1.9189652	0.56213707	3506.0234
675.38623	1.9238334	0.56331462	3508.0088
676.4873	1.9264312	0.56449842	3509.1387
677.58838	1.9318613	0.56610256	3516.2524
678.68945	1.9346007	0.56774509	3516.6135
679.79053	1.9370049	0.56909198	3505.1829
680.8916	1.9443934	0.57066721	3519.6924
681.99268	1.9444813	0.57186359	3504.637
683.09375	1.947174	0.57313842	3514.4595
684.19482	1.9504783	0.57445621	3514.3054
685.2959	1.9541124	0.5759421	3518.469
686.39697	1.9562865	0.57717937	3521.5212
687.49805	1.9618169	0.57845628	3517.4985
688.59912	1.9652486	0.57965815	3522.8535
689.7002	1.9695567	0.58114463	3526.5095
690.80127	1.9711602	0.58268011	3528.7114
691.90234	1.9744054	0.58395296	3520.8923
693.00342	1.9756496	0.5853231	3520.8779
694.10449	1.9797658	0.58680427	3525.7703
695.20557	1.9836323	0.58831096	3524.5615
696.30664	1.9871962	0.58972281	3529.9045
697.40771	1.9902261	0.59117246	3531.584
698.50879	1.9944669	0.59248161	3521.4211
699.60986	1.996295	0.59379596	3522.2891
700.71094	2.0056572	0.59496218	3529.4355
701.81201	2.0048954	0.59629792	3535.9983
702.91309	2.007988	0.59762025	3534.9429
704.01416	2.011409	0.59883803	3526.4656
705.11523	2.0147741	0.60028768	3536.2148
706.21631	2.0160863	0.60166526	3531.7871
707.31738	2.0208077	0.60326594	3539.6125
708.41846	2.0260515	0.60475326	3540.6045
709.51953	2.0245039	0.60607922	3531.6265
710.62061	2.0310531	0.60746831	3533.436
711.72168	2.0341866	0.6087386	3538.0806
712.82275	2.033078	0.61016315	3538.3103
713.92383	2.0397384	0.61142421	3538.2639
715.0249	2.0441599	0.61301285	3542.8987
716.12598	2.0461514	0.61417437	3532.2898
717.22705	2.0481336	0.61541951	3534.3918
718.32813	2.0508537	0.61670673	3541.3923
719.4292	2.0544205	0.61822104	3548.0925
720.53027	2.0582709	0.62006795	3542.6943
721.63135	2.0632505	0.62121791	3538.2036
722.73242	2.0658848	0.62270677	3546.2078
723.8335	2.0688338	0.62425542	3550.1758
724.93457	2.07253	0.6256519	3542.9724
726.03564	2.0741208	0.62709421	3544.5361
727.13672	2.0768335	0.62842649	3549.4021
728.23779	2.0846441	0.62999135	3558.9614
729.33887	2.0871842	0.63151181	3551.8401
730.43994	2.0858836	0.63274908	3545.292
731.54102	2.0919855	0.63413382	3548.582
732.64209	2.0957227	0.6355508	3552.1814
733.74316	2.0981212	0.63704932	3548.9666
734.84424	2.1035178	0.63826036	3552.553
735.94531	2.1054626	0.63975692	3551.6548
737.04639	2.1113188	0.64103299	3552.0066
738.14746	2.1133294	0.64233154	3559.5613
739.24854	2.1184778	0.64358163	3553.748
740.34961	2.1193433	0.64488274	3557.2944
741.45068	2.1220045	0.64604306	3551.3228
742.55176	2.1243713	0.64746869	3555.5071
743.65283	2.128284	0.64886713	3558.5732
744.75391	2.1338661	0.65024149	3562.4019
745.85498	2.1332972	0.65159309	3563.1963
746.95605	2.1404402	0.653081	3566.6262
748.05713	2.1422698	0.65453523	3557.718
749.1582	2.1452863	0.65591109	3559.6826
750.25928	2.1500444	0.65735251	3563.469
751.36035	2.1498191	0.6587103	3554.1213
752.46143	2.1562512	0.65986854	3559.9915
753.5625	2.1596215	0.66128105	3568.3838
754.66357	2.1610591	0.66278458	3565.5828
755.76465	2.164556	0.66435593	3565.5383
756.86572	2.1698258	0.66602111	3573.6267
757.9668	2.1722536	0.66753989	3568.2227
759.06787	2.1743267	0.66899949	3570.6133
760.16895	2.1786907	0.67045015	3573.907
761.27002	2.181129	0.67188621	3574.8149
762.37109	2.1841142	0.6732257	3567.5249
763.47217	2.1901133	0.67453015	3570.1233
764.57324	2.1946325	0.67597145	3573.6575
765.67432	2.195559	0.67724693	3572.9729
766.77539	2.1991708	0.67879939	3577.3611
767.87646	2.2023854	0.68045622	3579.4788
768.97754	2.2056079	0.6819573	3574.1436
770.07861	2.2078507	0.68342549	3575.1787
771.17969	2.2106287	0.68497777	3574.5229
772.28076	2.2122734	0.68633783	3573.3123
773.38184	2.2183506	0.68784809	3578.3787
774.48291	2.220448	0.68943894	3577.2817
775.58398	2.2276087	0.69106227	3581.4678
776.68506	2.2268043	0.69273418	3577.5142
777.78613	2.231564	0.69409734	3573.0581
778.88721	2.2335854	0.69556504	3581.9509
779.98828	2.2393584	0.69686085	3578.8132
781.08936	2.2401385	0.69806278	3574.1187
782.19043	2.2437539	0.69958496	3580.1968
783.2915	2.2497039	0.70103538	3580.7024
784.39258	2.2472084	0.70250148	3583.1331
785.49365	2.2567255	0.70407695	3589.7197
786.59473	2.2538335	0.70558935	3584.3662
787.6958	2.2605479	0.7072053	3585.6641
788.79688	2.2653196	0.70847666	3580.7349
789.89795	2.2685308	0.70985121	3582.9827
790.99902	2.267436	0.71098799	3578.7786
792.1001	2.2738776	0.71232748	3583.6106
793.20117	2.2790253	0.71403044	3599.1992
794.30225	2.2795045	0.71564603	3587.4028
795.40332	2.2850192	0.717278	3590.1206
796.50439	2.2873952	0.7190122	3590.3911
797.60547	2.2907443	0.7207464	3598.5474
798.70654	2.2940567	0.72200084	3585.5288
799.80762	2.2966397	0.72342199	3586.2429
800.90869	2.300617	0.7249651	3592.845
802.00977	2.3035586	0.72638041	3587.032
803.11084	2.3105292	0.72797757	3596.9153
804.21191	2.3101504	0.72948939	3595.9565
805.31299	2.3156276	0.73099232	3592.175
806.41406	2.3169947	0.7323336	3596.4116
807.51514	2.3196654	0.73378122	3597.0737
808.61621	2.3221278	0.73531967	3591.687
809.71729	2.3290696	0.73691696	3600.3757
810.81836	2.3345056	0.73834455	3596.3367
811.91943	2.3337419	0.7396754	3595.1047
813.02051	2.3346026	0.74109823	3597.3074
814.12158	2.3431776	0.74250549	3599.1177
815.22266	2.3417366	0.74396372	3596.0752
816.32373	2.3483601	0.74547845	3596.5818
817.4248	2.3482797	0.74678391	3599.1719
818.52588	2.3507156	0.74819779	3602.0405
819.62695	2.3588827	0.74958372	3600.8105
820.72803	2.3602026	0.75130123	3606.1106
821.8291	2.3638833	0.75275666	3604.2522
822.93018	2.3657634	0.75434512	3603.218
824.03125	2.3715837	0.75611365	3607.5005
825.13232	2.3730962	0.75772107	3603.1621
826.2334	2.3742328	0.75920844	3604.772
827.33447	2.3769181	0.76080531	3604.6541
828.43555	2.3816438	0.76230705	3603.313
829.53662	2.3890305	0.76395577	3612.269
830.6377	2.3914652	0.76558107	3608.6116
831.73877	2.3938615	0.76722056	3611.1553
832.83984	2.3977609	0.76918292	3613.8252
833.94092	2.3971996	0.77092063	3608.6365
835.04199	2.4028339	0.77244538	3605.7285
836.14307	2.4065797	0.77384192	3605.647
837.24414	2.4097118	0.77516645	3604.2686
838.34521	2.4131873	0.7765097	3604.3821
839.44629	2.4191754	0.7779603	3611.4832
840.54736	2.420198	0.77956522	3613.8186
841.64844	2.4243925	0.78127778	3618.5291
842.74951	2.4292481	0.78288311	3618.1963
843.85059	2.4292006	0.78467309	3613.8652
844.95166	2.4331682	0.78635561	3616.9089
846.05273	2.4347725	0.78808767	3610.1533
847.15381	2.4400854	0.78967005	3615.4004
848.25488	2.438741	0.7911483	3611.0286
849.35596	2.4465361	0.79261893	3610.6748
850.45703	2.4507177	0.79399359	3619.6228
851.55811	2.4531457	0.79556459	3619.115
852.65918	2.4541099	0.79718864	3615.8943
853.76025	2.4588232	0.79879475	3618.7844
854.86133	2.4646266	0.80035394	3617.7458
855.9624	2.4625258	0.80154407	3610.8843
857.06348	2.4674213	0.80315536	3617.4199
858.16455	2.4708579	0.80481535	3620.4656
859.26563	2.4778683	0.80655575	3625.3726
860.3667	2.4795003	0.80818427	3617.2705
861.46777	2.4827232	0.80986351	3616.6238
862.56885	2.4835339	0.81141621	3619.0886
863.66992	2.4874682	0.81310666	3618.7683
864.771	2.4909983	0.81464291	3620.6025
865.87207	2.4961274	0.81633061	3625.5571
866.97314	2.5000577	0.81796223	3625.4197
868.07422	2.5042546	0.8196277	3623.1848
869.17529	2.5026526	0.82126921	3626.948
870.27637	2.5089512	0.82294822	3628.8616
871.37744	2.5115719	0.82476711	3624.2681
872.47852	2.5150917	0.82639194	3623.6023
873.57959	2.5177419	0.82829064	3625.6106
874.68066	2.5190835	0.82994813	3620.0525
875.78174	2.5252216	0.83163065	3629.9497
876.88281	2.5309708	0.83316439	3626.0354
877.98389	2.5318141	0.83491069	3632.3186
879.08496	2.5325084	0.83649355	3622.3237
880.18604	2.5365229	0.83796722	3626.2458
881.28711	2.5416665	0.83938491	3626.2295
882.38818	2.5434277	0.84116387	3626.3691
883.48926	2.547586	0.84289038	3628.2886
884.59033	2.5532579	0.84454423	3624.0095
885.69141	2.5566144	0.84578806	3624.9265
886.79248	2.5551474	0.84722018	3628.2781
887.89355	2.5627306	0.84875488	3629.5894
888.99463	2.5629334	0.85036355	3632.6418
890.0957	2.5687795	0.85213834	3635.5842
891.19678	2.5718191	0.85390359	3631.9192
892.29785	2.5750291	0.85543984	3626.6873
893.39893	2.5784154	0.85686612	3631.8318
894.5	2.5837851	0.85867631	3636.4092
895.60107	2.5860372	0.86016989	3625.2278
896.70215	2.586746	0.86189616	3635.5459
897.80322	2.5897584	0.86397517	3635.5591
898.9043	2.5949037	0.86584747	3637.0554
900.00537	2.6003606	0.86747932	3636.2017
901.10645	2.5995436	0.86940014	3628.4021
902.20752	2.6059201	0.87130171	3640.9836
903.30859	2.6120303	0.87334442	3638.1602
904.40967	2.6125083	0.8750844	3635.4946
905.51074	2.6142588	0.87685984	3636.1819
906.61182	2.6185985	0.87841922	3636.8792
907.71289	2.6200724	0.88032538	3635.8601
908.81396	2.6260478	0.8819235	3637.9446
909.91504	2.6287439	0.88354421	3635.7375
911.01611	2.6301215	0.88522875	3636.4204
912.11719	2.6354496	0.88704497	3639.5657
913.21826	2.6348257	0.88889229	3636.4033
914.31934	2.6415417	0.89082158	3643.54
915.42041	2.6416581	0.89266413	3637.1323
916.52148	2.6479921	0.89449662	3641.5586
917.62256	2.652051	0.89629936	3632.9844
918.72363	2.6552379	0.89780343	3638.4329
919.82471	2.6593301	0.89943975	3635.5566
920.92578	2.6607018	0.90084928	3632.1299
922.02686	2.6654422	0.90231693	3636.9846
923.12793	2.668057	0.90411067	3647.1975
924.229	2.6686878	0.90599126	3640.5581
925.33008	2.6765888	0.90758657	3639.5549
926.43115	2.6774874	0.90924644	3641.6992
927.53223	2.6819694	0.91120279	3644.3186
928.6333	2.6841488	0.91333193	3646.4434
929.73438	2.6856766	0.9154219	3642.0569
930.83545	2.6898131	0.91708857	3637.0103
931.93652	2.6929467	0.91869324	3642.4084
933.0376	2.6954992	0.9206838	3652.2903
934.13867	2.6997542	0.92237222	3639.3372
935.23975	2.7060082	0.92418391	3644.8345
936.34082	2.7056973	0.92565006	3640.9377
937.44189	2.7096536	0.92754358	3647.3157
938.54297	2.7126279	0.92946625	3645.2461
939.64404	2.7167161	0.93159992	3649.8755
940.74512	2.7221797	0.93369114	3654.7283
941.84619	2.7257257	0.93584681	3650.3176
942.94727	2.7260122	0.93764275	3640.6321
944.04834	2.7309527	0.93930376	3637.4329
945.14941	2.7349226	0.94084829	3644.884
946.25049	2.7355745	0.94266647	3649.8801
947.35156	2.7406244	0.94442624	3645.3237
948.45264	2.7422302	0.94646263	3653.4502
949.55371	2.7450275	0.94873965	3650.5593
950.65479	2.7508337	0.95031315	3639.5178
951.75586	2.7529144	0.9520334	3646.0095
952.85693	2.7585845	0.95389545	3646.1257
953.95801	2.7617579	0.95590413	3651.9109
955.05908	2.7629392	0.95801508	3650.1069
956.16016	2.7669988	0.959975	3646.7791
957.26123	2.7693775	0.96174711	3646.1648
958.3623	2.7711453	0.96360236	3647.5454
959.46338	2.777575	0.96560746	3649.4634
960.56445	2.7822518	0.96728957	3647.6624
961.66553	2.7833302	0.9690519	3650.4558
962.7666	2.7853107	0.97096628	3650.6074
963.86768	2.7914703	0.97332168	3654.4502
964.96875	2.7917848	0.97502089	3645.3923
966.06982	2.7959561	0.97693408	3650.8149
967.1709	2.800735	0.97886372	3655.7815
968.27197	2.8037779	0.98087263	3654.3428
969.37305	2.8062747	0.98302299	3655.0129
970.47412	2.8073101	0.98520756	3656.7993
971.5752	2.810472	0.98740155	3650.0576
972.67627	2.8175578	0.98932487	3651.7898
973.77734	2.8207765	0.99146676	3651.8997
974.87842	2.8231838	0.99349546	3656.021
975.97949	2.8227303	0.99555266	3650.2607
977.08057	2.8291416	0.99731642	3650.7771
978.18164	2.8352368	0.99920905	3653.7751
979.28271	2.8357811	1.0013434	3648.0286
980.38379	2.8429577	1.003094	3654.5625
981.48486	2.8424687	1.0049374	3652.2817
982.58594	2.8442571	1.0066547	3648.9678
983.68701	2.8501031	1.0089161	3659.3433
984.78809	2.8535359	1.0106339	3649.5283
985.88916	2.8554344	1.0123743	3648.7148
986.99023	2.8603585	1.0144043	3656.0913
988.09131	2.8618727	1.0166775	3655.6584
989.19238	2.8668792	1.0189614	3652.335
990.29346	2.8710544	1.0209148	3654.0593
991.39453	2.8726604	1.0230011	3656.7534
992.49561	2.8773198	1.0251471	3657.2168
993.59668	2.8783314	1.0271857	3644.9497
994.69775	2.8831618	1.0291538	3650.4778
995.79883	2.8873963	1.0310318	3653.3306
996.8999	2.8871655	1.0332466	3655.6904
998.00098	2.8901074	1.0353664	3650.2708
999.10205	2.8957818	1.0373899	3655.0166
1000.2031	2.8998513	1.0392234	3654.7754
1001.3042	2.9014742	1.0414091	3652.9241
1002.4053	2.9079988	1.0437976	3656.6467
1003.5063	2.9084868	1.0460258	3655.3164
1004.6074	2.9101641	1.0481498	3651.4353
1005.7085	2.9122849	1.0503781	3655.9814
1006.8096	2.9183285	1.0525036	3648.304
1007.9106	2.9248209	1.0547328	3660.5388
1009.0117	2.9291196	1.057075	3661.5154
1010.1128	2.9271266	1.0593185	3653.7009
1011.2139	2.9319265	1.0615705	3657.239
1012.3149	2.9338567	1.0638237	3653.5981
1013.416	2.9378006	1.0659546	3658.8528
1014.5171	2.9417531	1.0685418	3655.6572
1015.6182	2.9458079	1.0705552	3653.2622
1016.7192	2.9492936	1.0729034	3658.3074
1017.8203	2.9493845	1.0751467	3650.7766
1018.9214	2.954319	1.0774727	3656.0452
1020.0225	2.9565072	1.0794694	3652.0378
1021.1235	2.961544	1.0817419	3654.814
1022.2246	2.9639552	1.0838569	3653.356
1023.3257	2.9679296	1.0858278	3656.6577
1024.4268	2.9708986	1.0882828	3654.5637
1025.5278	2.9746554	1.0909541	3657.2039
1026.6289	2.9764607	1.0934173	3654.2356
1027.73	2.9811344	1.0954857	3649.3279
1028.8311	2.9846234	1.0973978	3647.4509
1029.9321	2.9887974	1.0989568	3648.073
1031.0332	2.992312	1.1009012	3652.5134
1032.1343	2.9958165	1.1028622	3656.2197
1033.2354	2.9974041	1.1052972	3650.7603
1034.3364	3.0018616	1.1076891	3655.2854
1035.4375	3.0025835	1.1098654	3656.97
1036.5386	3.0096874	1.112303	3659.4897
1037.6396	3.0106633	1.1147095	3653.3867
1038.7407	3.0101328	1.1170149	3653.8899
1039.8418	3.0168374	1.1191453	3645.8499
1040.9429	3.0219767	1.1209164	3642.3474
1042.0439	3.0232339	1.1225673	3643.2249
1043.145	3.025842	1.1240715	3645.1082
1044.2461	3.0314934	1.1262512	3657.9409
1045.3472	3.0340235	1.1284375	3653.8599
1046.4482	3.0360198	1.1310024	3657.5632
1047.5493	3.038769	1.1336724	3658.7625
1048.6504	3.0429177	1.1358178	3645.5151
1049.7515	3.0475712	1.1379161	3656.0735
1050.8525	3.0541077	1.1402899	3657.5562
1051.9536	3.0544076	1.1429545	3659.636
1053.0547	3.0585792	1.1459423	3656.2007
1054.1558	3.0618501	1.1483024	3655.822
1055.2568	3.0623515	1.1508173	3652.0884
1056.3579	3.0643303	1.1533722	3651.6833
1057.459	3.0724626	1.1561103	3653.7109
1058.5601	3.0740449	1.1583108	3644.8413
1059.6611	3.0771141	1.1604838	3648.52
1060.7622	3.0806878	1.1625258	3645.9939
1061.8633	3.0826943	1.1647398	3653.7861
1062.9644	3.0872533	1.1672001	3652.1594
1064.0654	3.0891569	1.1700242	3652.447
1065.1665	3.0938647	1.1728302	3655.3105
1066.2676	3.1012938	1.1756358	3657.2976
1067.3687	3.1007931	1.1786104	3651.1001
1068.4697	3.1037939	1.1814479	3652.1919
1069.5708	3.1073711	1.1838937	3647.9917
1070.6719	3.1098135	1.1861348	3648.3477
1071.7729	3.1123579	1.1886276	3651.4199
1072.874	3.1127887	1.1910852	3643.9497
1073.9751	3.1178193	1.1934676	3642.5955
1075.0762	3.1240051	1.1961387	3651.9717
1076.1772	3.1285558	1.1989475	3652.9941
1077.2783	3.1313562	1.2012864	3645.835
1078.3794	3.1357548	1.2035707	3646.5674
1079.4805	3.1352551	1.2062739	3649.7036
1080.5815	3.1407425	1.2094249	3654.6357
1081.6826	3.1422203	1.2120548	3643.8
1082.7837	3.1484654	1.2146088	3647.925
1083.8848	3.1499925	1.2177079	3647.8579
1084.9858	3.1541913	1.2204673	3645.9258
1086.0869	3.1572711	1.223401	3648.2581
1087.188	3.1604886	1.2264191	3645.7156
1088.2891	3.1596518	1.228875	3635.8857
1089.3901	3.1664436	1.2315416	3643.4233
1090.4912	3.1677501	1.2343007	3640.0105
1091.5923	3.1734939	1.2370664	3640.4351
1092.6934	3.1771498	1.23944	3650.4202
1093.7944	3.1790447	1.2420011	3638.2629
1094.8955	3.1837533	1.2444584	3641.7068
1095.9966	3.1879427	1.2472073	3649.8552
1097.0977	3.1901214	1.2504935	3642.519
1098.1987	3.1946964	1.2533628	3641.3035
1099.2998	3.1950252	1.2558297	3635.6619
1100.4009	3.1980834	1.2584852	3641.9031
1101.502	3.2028327	1.2613963	3637.5442
1102.603	3.2054214	1.263782	3639.6487
1103.7041	3.2068961	1.2665031	3640.4651
1104.8052	3.2141631	1.2692122	3643.4221
1105.9063	3.2154701	1.2724061	3638.0364
1107.0073	3.217695	1.2758189	3638.4556
1108.1084	3.2233539	1.2787771	3638.1824
1109.2095	3.2256956	1.2817352	3630.1882
1110.3105	3.2301285	1.2848918	3635.3533
1111.4116	3.2337339	1.2875503	3632.0674
1112.5127	3.2341075	1.2907726	3639.6038
1113.6138	3.2399406	1.2939239	3632.9365
1114.7148	3.2410395	1.2963432	3623.2371
1115.8159	3.248296	1.2986368	3625.6628
1116.917	3.2505763	1.3010286	3631.2371
1118.0181	3.2505777	1.3036748	3634.7793
1119.1191	3.2570555	1.3068551	3638.3318
1120.2202	3.2598956	1.3107978	3637.3298
1121.3213	3.2609193	1.3144884	3629.624
1122.4224	3.2644794	1.3179321	3622.1316
1123.5234	3.2656579	1.3206884	3626.3323
1124.6245	3.2720282	1.323557	3626.0427
1125.7256	3.2728064	1.3264009	3624.6687
1126.8267	3.2790201	1.3294165	3629.4744
1127.9277	3.282048	1.3324653	3624.6763
1129.0288	3.2842078	1.3353473	3624.1494
1130.1299	3.2889066	1.338527	3624.0764
1131.231	3.2917397	1.3415084	3627.6973
1132.332	3.2934115	1.344777	3621.8123
1133.4331	3.29796	1.3475487	3621.9026
1134.5342	3.3004334	1.3504864	3619.6257
1135.6353	3.3041928	1.3534896	3622.9424
1136.7363	3.3076851	1.3566889	3619.6365
1137.8374	3.3115096	1.3597997	3619.7131
1138.9385	3.3168955	1.3628098	3622.4614
1140.0396	3.3184381	1.3658091	3616.384
1141.1406	3.3210516	1.3691291	3614.5076
1142.2417	3.3258016	1.3724812	3619.7847
1143.3428	3.3289158	1.3754389	3619.2141
1144.4438	3.3334231	1.3787895	3614.5437
1145.5449	3.3329527	1.3819021	3612.8855
1146.646	3.3379281	1.3850678	3616.9221
1147.7471	3.3404424	1.3882918	3609.0334
1148.8481	3.3446085	1.3914709	3613.3149
1149.9492	3.3459959	1.3948712	3609.4805
1151.0503	3.3491395	1.3987454	3609.29
1152.1514	3.3574781	1.4024922	3606.7026
1153.2524	3.3555012	1.4052348	3601.2063
1154.3535	3.3611815	1.4081494	3606.2427
1155.4546	3.362076	1.4114175	3600.2021
1156.5557	3.3673933	1.4150367	3601.7722
1157.6567	3.3721945	1.4184949	3600.0059
1158.7578	3.3758311	1.4216982	3597.6223
1159.8589	3.3783171	1.4248075	3598.5928
1160.96	3.3798969	1.4283273	3594.9409
1162.061	3.383842	1.4313802	3594.7263
1163.1621	3.3860755	1.4347316	3593.7505
1164.2632	3.3926296	1.4379011	3598.8494
1165.3643	3.3962901	1.4412431	3597.8342
1166.4653	3.398592	1.444935	3589.3169
1167.5664	3.4034472	1.4484887	3592.2957
1168.6675	3.4057629	1.45173	3583.6748
1169.7686	3.4090331	1.4548955	3589.3801
1170.8696	3.4123161	1.4578993	3581.6016
1171.9707	3.4149194	1.4614533	3583.4854
1173.0718	3.4175897	1.4652936	3582.7727
1174.1729	3.423851	1.4685981	3584.1836
1175.2739	3.4253793	1.4716021	3578.123
1176.375	3.429853	1.474789	3579.406
1177.4761	3.429024	1.4779075	3574.2161
1178.5771	3.4336104	1.4812958	3573.3677
1179.6782	3.4403865	1.4842762	3574.7871
1180.7793	3.4417617	1.4877887	3576.3359
1181.8804	3.4450076	1.4916402	3574.9656
1182.9814	3.4468572	1.4957169	3563.1829
1184.0825	3.4542782	1.4990973	3571.1025
1185.1836	3.453747	1.5022314	3563.635
1186.2847	3.4561462	1.5051821	3562.5352
1187.3857	3.4582281	1.5082599	3558.7429
1188.4868	3.4641676	1.5117049	3561.3782
1189.5879	3.4667213	1.5149989	3559.4058
1190.689	3.471267	1.5183251	3556.5466
1191.79	3.4732933	1.5218042	3552.5981
1192.8911	3.476959	1.525809	3553.177
1193.9922	3.4806163	1.5292492	3551.3445
1195.0933	3.4825418	1.5325445	3548.7566
1196.1943	3.4870884	1.5355499	3546.7441
1197.2954	3.4907923	1.5388701	3545.4229
1198.3965	3.4940794	1.5421374	3537.4238
1199.4976	3.4941132	1.5455352	3538.4836
1200.5986	3.4958339	1.5489641	3532.8962
1201.6997	3.5022426	1.5525926	3538.5586
1202.8008	3.508184	1.5567608	3533.311
1203.9019	3.5121949	1.5604979	3533.1941
1205.0029	3.5131381	1.5640445	3528.3252
1206.104	3.5152075	1.5671544	3517.175
1207.2051	3.5164828	1.5701181	3518.6084
1208.3062	3.5220604	1.573302	3516.2256
1209.4072	3.5252836	1.5766834	3517.0803
1210.5083	3.5286453	1.5808905	3514.7451
1211.6094	3.5330603	1.5842016	3509.8335
1212.7104	3.5323186	1.5877037	3500.5305
1213.8115	3.5398662	1.5910263	3504.6392
1214.9126	3.5433347	1.5942361	3509.2314
1216.0137	3.5471587	1.5983188	3502.073
1217.1147	3.5511494	1.6021277	3492.8101
1218.2158	3.552516	1.6056108	3492.2432
1219.3169	3.5576	1.6094452	3493.0344
1220.418	3.561424	1.6127455	3488.2209
1221.519	3.559041	1.6164107	3478.8992
1222.6201	3.5652306	1.6193967	3476.0742
1223.7212	3.5692635	1.622661	3479.395
1224.8223	3.5757272	1.6262349	3473.0632
1225.9233	3.5748594	1.6306841	3473.0217
1227.0244	3.5788965	1.6346836	3462.0552
1228.1255	3.5827515	1.638364	3459.7969
1229.2266	3.5861928	1.642457	3451.8535
1230.3276	3.5911028	1.6459975	3444.5869
1231.4287	3.5945811	1.6494612	3449.2246
1232.5298	3.5926597	1.6529731	3435.4407
1233.6309	3.6018586	1.6564156	3439.229
1234.7319	3.6024661	1.6598208	3436.8718
1235.833	3.6081371	1.6639223	3428.4824
1236.9341	3.6083593	1.6678789	3417.3364
1238.0352	3.6107733	1.6719419	3414.9167
1239.1362	3.615237	1.6761115	3402.0022
1240.2373	3.6198835	1.6802294	3396.1479
1241.3384	3.6230612	1.6839811	3389.2185
1242.4395	3.6249573	1.6881245	3389.542
1243.5405	3.629607	1.6922717	3375.9612
1244.6416	3.6309729	1.6954439	3362.6252
1245.7427	3.6361499	1.6988727	3363.6282
1246.8438	3.6381111	1.7026876	3357.24
1247.9448	3.6423826	1.7065855	3349.5225
1249.0459	3.6486709	1.7101054	3341.7974
1250.147	3.6511178	1.714262	3337.1072
1251.248	3.6526117	1.7191559	3316.2803
1252.3491	3.6557164	1.7242339	3299.958
1253.4502	3.6611209	1.7294434	3293.7471
1254.5513	3.6625783	1.734845	3263.689
1255.6523	3.6663141	1.742615	3228.6213
1256.7534	3.6699152	1.7495399	3189.4148
1257.8545	3.6738443	1.7620113	3103.1035
1258.9556	3.6820023	1.7745037	3013.2444
1259.2559	3.6795382	1.7811002	2962.7583