File: datasets/am_bench_2022/raw_data/TH3-C/specimen.dat
MTS793|MPT|ENU|1|2|.|/|:|1|0|0|A

Operator Information						Time:	11.715088	Sec	11/3/2021 1:05:01 PM
Operator	Nick Derimow
Project	AM Bench 2022 mini-tensile challenge
Specimen ID	TH3-C
Material	PBF-L Inconel 625
Specimen Width	2.57	mm
Specimen Thickness	1.52	mm
Notes
Operator Information End

Data Acquisition						Time:	1012.7102	Sec	11/3/2021 1:21:42 PM
Time	Axial Displacement	Axial Extensometer	Axial Force
Sec	mm	mm	N
11.830078	0.0022446064	-0.00027845142	70.979103
12.730957	0.0038579179	-0.0002989897	83.957176
13.631836	0.0081035662	-0.00012573902	95.51223
14.532715	0.0079455953	-2.9249721e-05	100.91205
15.433594	0.011225285	0.00015993226	115.08059
16.334473	0.016386436	0.00014898801	129.46342
17.235352	0.015062227	0.00032823585	138.99847
18.13623	0.019296248	0.00038656421	150.31577
19.037109	0.022360954	0.00020461898	163.16602
19.937988	0.02473769	0.00016229259	174.26669
20.838867	0.030249821	0.00026994949	193.19061
21.739746	0.030005591	0.00091249269	199.12328
22.640625	0.034318291	0.000640126	223.13007
23.541504	0.033231139	0.0009885144	230.13319
24.442383	0.035723381	0.0010233213	246.67905
25.343262	0.036866058	0.0011948375	262.18283
26.244141	0.042050771	0.0010566888	280.38855
27.14502	0.046866477	0.0011685747	297.24496
28.045898	0.045443304	0.0013679345	307.7316
28.946777	0.048864935	0.0014456456	325.97922
29.847656	0.053551406	0.0018407768	348.48941
30.748535	0.058613747	0.001706772	373.07297
31.649414	0.059317138	0.0021500853	383.45413
32.550293	0.060185671	0.0021781093	412.79953
33.451172	0.061811633	0.0023651656	431.20505
34.352051	0.06974373	0.0023859895	451.23032
35.25293	0.071193948	0.0022082815	471.69189
36.153809	0.07212697	0.002628685	488.52301
37.054688	0.076251172	0.0025749339	508.7818
37.955566	0.074109085	0.0031220154	529.50598
38.856445	0.078214437	0.0032052288	549.51654
39.757324	0.082100347	0.0032079045	575.95361
40.658203	0.086087681	0.0031297316	597.94611
41.559082	0.087649561	0.0034792838	620.79919
42.459961	0.09270335	0.0035491504	641.04919
43.36084	0.092420399	0.0036473989	667.41144
44.261719	0.096739247	0.0041025346	692.7572
45.162598	0.096282132	0.0044066631	722.09302
46.063477	0.10226034	0.0043756836	743.72064
46.964355	0.10291374	0.0045199865	766.4812
47.865234	0.10707753	0.0047071041	794.565
48.766113	0.10813825	0.0047835191	820.70587
49.666992	0.11054198	0.0049993605	847.79639
50.567871	0.11410171	0.005316664	867.302
51.46875	0.1168767	0.0053743683	890.16583
52.369629	0.11924585	0.0053838999	916.31775
53.270508	0.1240425	0.0057046078	933.77625
54.171387	0.12468606	0.0057295715	964.58978
55.072266	0.12897883	0.0058195954	987.1593
55.973145	0.12812163	0.0062724156	1012.3618
56.874023	0.13041143	0.0064216889	1034.9507
57.774902	0.13432424	0.0067068902	1053.5542
58.675781	0.14069296	0.0064454768	1076.7124
59.57666	0.14037457	0.0070010726	1107.4871
60.477539	0.1433692	0.0071089435	1136.88
61.378418	0.14696687	0.0074492306	1167.7432
62.279297	0.15075998	0.0073756347	1190.0736
63.180176	0.15336655	0.0077527151	1212.7291
64.081055	0.15488684	0.0080043804	1246.2153
64.981934	0.15495117	0.0081448397	1270.9995
65.882813	0.15766101	0.0084389942	1293.5719
66.783691	0.16033894	0.008478418	1317.245
67.68457	0.16454652	0.008719122	1351.2476
68.585449	0.16787779	0.0088677891	1376.0043
69.486328	0.16817981	0.0092245778	1401.637
70.387207	0.17341001	0.0094977971	1422.7
71.288086	0.17554969	0.0095048621	1445.3124
72.188965	0.18153219	0.0093981475	1469.9821
73.089844	0.18119904	0.0096231718	1493.54
73.990723	0.18452744	0.010237866	1516.2048
74.891602	0.18809009	0.0099393073	1538.9421
75.79248	0.18907659	0.010135775	1559.5607
76.693359	0.19005883	0.010380527	1585.0005
77.594238	0.19887929	0.010635503	1612.3339
78.495117	0.19886474	0.010710902	1641.2521
79.395996	0.20431623	0.010993041	1667.9764
80.296875	0.20269267	0.011130514	1697.6573
81.197754	0.20470326	0.011360255	1723.8236
82.098633	0.20861438	0.011512134	1739.9261
82.999512	0.21074027	0.011654807	1770.2919
83.900391	0.21214254	0.011739742	1785.5289
84.80127	0.21767578	0.01193012	1809.7086
85.702148	0.21869695	0.012166291	1833.2025
86.603027	0.22385211	0.012246718	1860.4988
87.503906	0.22731559	0.01250542	1888.4849
88.404785	0.23010144	0.012565078	1913.4915
89.305664	0.22954291	0.012727596	1929.1482
90.206543	0.23476942	0.012929529	1960.3732
91.107422	0.23567422	0.012961799	1967.0386
92.008301	0.23855063	0.013185251	1992.0658
92.90918	0.24202928	0.013404781	2022.0566
93.810059	0.24520421	0.01349619	2037.6365
94.710938	0.24986394	0.01370289	2057.9509
95.611816	0.24817017	0.01380104	2073.0874
96.512695	0.25169402	0.01392076	2094.3979
97.413574	0.25563121	0.014092343	2117.6145
98.314453	0.2598494	0.014196487	2128.7539
99.215332	0.26311469	0.014327702	2160.3943
100.11621	0.25969452	0.014434482	2163.9221
101.01709	0.26620957	0.014518155	2185.4524
101.91797	0.26742378	0.014687687	2204.5605
102.81885	0.27192968	0.014883971	2229.7681
103.71973	0.27575803	0.015035727	2247.1675
104.62061	0.27611986	0.015161427	2258.3569
105.52148	0.27916777	0.015347166	2277.9016
106.42236	0.28026721	0.015366889	2293.3787
107.32324	0.28434777	0.015572794	2318.4272
108.22412	0.28610593	0.015749576	2333.1995
109.125	0.29348701	0.015844362	2341.532
110.02588	0.29076076	0.015962115	2348.9353
110.92676	0.29631308	0.01613264	2367.252
111.82764	0.29841807	0.016239801	2386.354
112.72852	0.29921019	0.016426183	2401.8733
113.62939	0.30226916	0.016511971	2413.0955
114.53027	0.3073332	0.016826147	2434.3508
115.43115	0.31065914	0.016923035	2441.323
116.33203	0.31109905	0.017020062	2453.6621
117.23291	0.31951833	0.017145399	2465.3174
118.13379	0.31927449	0.017290507	2474.0256
119.03467	0.32267672	0.017460903	2489.0156
119.93555	0.32216203	0.017604662	2498.02
120.83643	0.32815191	0.017752074	2518.2012
121.7373	0.32691765	0.017845975	2517.5691
122.63818	0.33204868	0.01808795	2526.4841
123.53906	0.33210954	0.018194225	2540.9368
124.43994	0.3361254	0.018521285	2549.1565
125.34082	0.33560559	0.018550193	2558.5935
126.2417	0.34492409	0.018819248	2576.5566
127.14258	0.34488761	0.018912842	2582.6604
128.04346	0.34936529	0.019257294	2599.6875
128.94434	0.34990251	0.019324541	2598.7505
129.84521	0.35241875	0.019561954	2605.7437
130.74609	0.3549245	0.019793922	2615.6851
131.64697	0.3583906	0.019919034	2624.8025
132.54785	0.36504683	0.020194635	2642.4128
133.44873	0.36599365	0.020520944	2650.4983
134.34961	0.36850882	0.02076979	2656.0273
135.25049	0.37172085	0.021035936	2662.2085
136.15137	0.36986294	0.021286171	2671.5588
137.05225	0.37478191	0.021472644	2674.5752
137.95313	0.37692714	0.021731446	2684.5242
138.854	0.3812865	0.022021642	2689.6155
139.75488	0.38107052	0.02230899	2698.793
140.65576	0.39014614	0.02270066	2711.7134
141.55664	0.38764399	0.023023168	2712.9517
142.45752	0.3913658	0.023448003	2728.252
143.3584	0.39219213	0.023727262	2732.366
144.25928	0.39732209	0.02415582	2742.0249
145.16016	0.39817011	0.024475962	2753.4758
146.06104	0.40484685	0.024914732	2755.9409
146.96191	0.40590778	0.025377275	2764.7725
147.86279	0.40921488	0.025813483	2770.9009
148.76367	0.41125655	0.026290217	2773.9668
149.66455	0.41152477	0.026695423	2782.386
150.56543	0.41450286	0.027130524	2792.5332
151.46631	0.41676977	0.027718427	2798.5471
152.36719	0.42077202	0.028247589	2806.3369
153.26807	0.42600301	0.028803747	2813.2739
154.16895	0.42958575	0.029308276	2818.1587
155.06982	0.42795685	0.029814033	2822.9924
155.9707	0.43481466	0.03026812	2829.9475
156.87158	0.43433726	0.030942481	2837.9038
157.77246	0.43679985	0.031447057	2840.8186
158.67334	0.4389694	0.032030918	2837.665
159.57422	0.44243696	0.032600328	2848.7988
160.4751	0.44517303	0.033263914	2857.2959
161.37598	0.44772941	0.033687647	2855.2007
162.27686	0.45190379	0.034321666	2866.6985
163.17773	0.45539105	0.034927942	2869.7583
164.07861	0.45834225	0.035687651	2878.6287
164.97949	0.45856598	0.036462214	2879.8376
165.88037	0.4632057	0.037212871	2886.3164
166.78125	0.46300715	0.037825603	2887.2976
167.68213	0.46793002	0.038613357	2895.436
168.58301	0.46745753	0.039367411	2898.479
169.48389	0.47466141	0.040205531	2909.0715
170.38477	0.475977	0.040758274	2899.9341
171.28564	0.48013398	0.041439842	2912.2354
172.18652	0.4804858	0.042011186	2909.5869
173.0874	0.48499376	0.042818163	2921.6357
173.98828	0.4896906	0.043709058	2929.6362
174.88916	0.49192613	0.044462908	2925.9211
175.79004	0.49320465	0.04535336	2933.2957
176.69092	0.49472883	0.046229448	2938.0247
177.5918	0.49599323	0.047199659	2939.3794
178.49268	0.50504661	0.048043016	2950.9343
179.39355	0.50634456	0.049064305	2951.1477
180.29443	0.50663263	0.049877327	2952.823
181.19531	0.50857437	0.050631333	2958.2581
182.09619	0.51311862	0.051425122	2959.8459
182.99707	0.51583213	0.05213191	2958.2834
183.89795	0.51509881	0.05276211	2958.8928
184.79883	0.51995939	0.053489067	2964.3518
185.69971	0.52133548	0.054363687	2974.3569
186.60059	0.52397263	0.055411726	2978.7805
187.50146	0.52706599	0.056271624	2977.1475
188.40234	0.5313828	0.057097547	2983.7314
189.30322	0.53484112	0.058098454	2992.804
190.2041	0.53363901	0.059199154	2989.9258
191.10498	0.53667426	0.060203709	2986.2915
192.00586	0.54261005	0.061232347	3006.5269
192.90674	0.54434448	0.062073696	3000.709
193.80762	0.54547215	0.062990278	3003.5518
194.7085	0.54996234	0.063881934	3002.5503
195.60938	0.54955071	0.064705394	3004.5142
196.51025	0.55471325	0.065572828	3009.2834
197.41113	0.56032741	0.066636615	3017.0046
198.31201	0.55873907	0.067625962	3018.9023
199.21289	0.56433958	0.068739913	3022.0591
200.11377	0.56506091	0.069818787	3026.3987
201.01465	0.56796259	0.070908435	3027.3484
201.91553	0.57099146	0.071815491	3032.4153
202.81641	0.57576638	0.072750725	3031.2493
203.71729	0.57557607	0.073576212	3036.6074
204.61816	0.5802809	0.074275911	3035.5317
205.51904	0.5815748	0.075253606	3048.8215
206.41992	0.58544856	0.076132149	3041.001
207.3208	0.58843631	0.077176206	3043.6184
208.22168	0.58760852	0.078077167	3048.2122
209.12256	0.58977669	0.079234153	3047.7788
210.02344	0.59148443	0.079933017	3044.7517
210.92432	0.59596652	0.080929838	3057.3042
211.8252	0.60136539	0.081995972	3059.9302
212.72607	0.60424447	0.082937449	3059.4321
213.62695	0.60599339	0.083925903	3060.3323
214.52783	0.60898435	0.084774949	3064.959
215.42871	0.61273706	0.085694022	3066.6465
216.32959	0.61245573	0.086721674	3072.0281
217.23047	0.61376542	0.087601483	3067.8442
218.13135	0.6183275	0.088744357	3074.3374
219.03223	0.62221724	0.089509271	3076.9553
219.93311	0.62479579	0.090613425	3078.6401
220.83398	0.62687707	0.091713838	3085.8284
221.73486	0.62898684	0.092761502	3083.4609
222.63574	0.63230723	0.093840137	3092.0073
223.53662	0.63673323	0.095004722	3091.3953
224.4375	0.63474399	0.095956974	3092.2139
225.33838	0.64381111	0.096944891	3099.6294
226.23926	0.6439476	0.097933233	3098.3279
227.14014	0.6458317	0.098892488	3095.5579
228.04102	0.64756674	0.099760346	3102.7644
228.94189	0.65270877	0.1007463	3103.9324
229.84277	0.65557951	0.10174317	3108.2578
230.74365	0.65773988	0.10281237	3118.447
231.64453	0.65884835	0.10391788	3113.0386
232.54541	0.66218966	0.10498314	3114.3499
233.44629	0.66545415	0.10602205	3116.3464
234.34717	0.66723502	0.10685088	3118.4663
235.24805	0.67087448	0.1080824	3119.6345
236.14893	0.67248857	0.10908811	3125.0586
237.0498	0.67569017	0.10997091	3121.5955
237.95068	0.68135858	0.11090869	3125.7258
238.85156	0.67929041	0.11194608	3125.5183
239.75244	0.68696314	0.11302802	3133.8984
240.65332	0.68716615	0.11385906	3130.3555
241.5542	0.68979323	0.11477919	3135.5452
242.45508	0.69329089	0.11571286	3137.635
243.35596	0.69738603	0.11665054	3139.4678
244.25684	0.69662529	0.11751048	3136.3601
245.15771	0.69842178	0.11844582	3143.3328
246.05859	0.70240557	0.11953995	3140.1787
246.95947	0.70649368	0.12040505	3147.895
247.86035	0.71063554	0.12158605	3156.7607
248.76123	0.70848197	0.12275676	3153.8271
249.66211	0.71554345	0.12375184	3157.1824
250.56299	0.71467412	0.12467287	3161.0044
251.46387	0.71814775	0.12571646	3161.1736
252.36475	0.72389597	0.12711687	3165.7063
253.26563	0.72743005	0.12806986	3162.4495
254.1665	0.72860903	0.12891388	3164.9272
255.06738	0.73047119	0.12990321	3165.7607
255.96826	0.73283893	0.13102345	3167.9963
256.86914	0.73637468	0.13227145	3178.1448
257.77002	0.74012375	0.13336352	3175.3208
258.6709	0.74248487	0.13439901	3175.3916
259.57178	0.74643403	0.13540645	3175.6479
260.47266	0.74727207	0.1362918	3176.5913
261.37354	0.74936587	0.1373979	3181.4878
262.27441	0.75314641	0.13848515	3182.2466
263.17529	0.75501609	0.13963577	3188.3665
264.07617	0.7548005	0.14087282	3186.2476
264.97705	0.75911915	0.14185891	3186.5125
265.87793	0.76194209	0.14284725	3195.3481
266.77881	0.76574099	0.14392637	3196.4517
267.67969	0.76908785	0.14506213	3199.936
268.58057	0.77166325	0.1458431	3194.0962
269.48145	0.77021652	0.14683394	3191.2104
270.38232	0.77441859	0.1476291	3200.5542
271.2832	0.77706784	0.14883558	3207.4229
272.18408	0.78386581	0.14979774	3204.3389
273.08496	0.78576654	0.15097128	3207.1079
273.98584	0.78824878	0.15199403	3208.6729
274.88672	0.79046631	0.15283492	3209.4441
275.7876	0.7920841	0.15368086	3206.0205
276.68848	0.79685223	0.15465197	3214.6951
277.58936	0.79878908	0.15545307	3208.8398
278.49023	0.80037552	0.15630628	3209.7542
279.39111	0.80688608	0.15716286	3217.418
280.29199	0.80621099	0.15811688	3221.8074
281.19287	0.80651671	0.15905683	3221.9895
282.09375	0.80980289	0.16024183	3217.6768
282.99463	0.81660682	0.16133113	3233.8489
283.89551	0.81639451	0.16231729	3225.1707
284.79639	0.81634861	0.16343981	3229.7849
285.69727	0.81859976	0.16452652	3232.9409
286.59814	0.82360762	0.16555516	3229.5798
287.49902	0.82654291	0.166556	3233.8525
288.3999	0.83060008	0.16750039	3231.8665
289.30078	0.83253509	0.16837226	3231.2754
290.20166	0.83622223	0.16930176	3237.7632
291.10254	0.83660972	0.17031011	3244.7893
292.00342	0.84269708	0.17140572	3242.835
292.9043	0.84818667	0.17231663	3244.4565
293.80518	0.84484434	0.17325586	3241.3889
294.70605	0.84877288	0.17427649	3244.3931
295.60693	0.8500852	0.17526016	3244.281
296.50781	0.85514021	0.17637403	3253.9392
297.40869	0.85879648	0.1774864	3255.7329
298.30957	0.85895073	0.17870969	3254.592
299.21045	0.86218083	0.17995115	3253.75
300.11133	0.86383235	0.18098308	3258.1604
301.01221	0.87062877	0.18207397	3258.3042
301.91309	0.87232792	0.18286863	3255.8765
302.81396	0.8744936	0.18364206	3260.9131
303.71484	0.87591386	0.1845469	3261.8875
304.61572	0.87725061	0.18552527	3261.1985
305.5166	0.87997866	0.18656559	3262.7563
306.41748	0.88594484	0.18749629	3275.6045
307.31836	0.88661546	0.18871602	3272.1934
308.21924	0.88843054	0.18968655	3267.3027
309.12012	0.89365172	0.19081274	3273.9878
310.021	0.89281166	0.19164942	3270.5156
310.92188	0.89913636	0.19261873	3272.4702
311.82275	0.89838916	0.19358499	3275.0071
312.72363	0.90368426	0.19459604	3282.5588
313.62451	0.90251434	0.19558595	3281.7942
314.52539	0.90867347	0.19663256	3284.2678
315.42627	0.90869993	0.19755058	3279.9023
316.32715	0.91796827	0.19850251	3283.4519
317.22803	0.91786683	0.19947524	3287.3286
318.12891	0.91838908	0.20030753	3281.5361
319.02979	0.92142493	0.20123626	3288.0574
319.93066	0.92482507	0.20220214	3292.5183
320.83154	0.92740631	0.20344824	3296.8496
321.73242	0.92994279	0.20447221	3292.825
322.6333	0.93545753	0.20547441	3295.5483
323.53418	0.93575507	0.20655809	3298.1125
324.43506	0.94148743	0.20762858	3301.6406
325.33594	0.94276124	0.20848191	3301.4414
326.23682	0.94349414	0.20946366	3302.0593
327.1377	0.94355047	0.21039687	3305.082
328.03857	0.94758618	0.21147019	3302.8811
328.93945	0.95227772	0.21248135	3302.3542
329.84033	0.95590955	0.21363592	3309.0923
330.74121	0.95692134	0.21459396	3311.9419
331.64209	0.96201295	0.21569109	3316.345
332.54297	0.96113402	0.21673203	3309.8806
333.44385	0.9672274	0.21773164	3318.9648
334.34473	0.96870792	0.21887282	3319.9097
335.24561	0.96883106	0.21982186	3314.8604
336.14648	0.97315788	0.22084349	3317.6982
337.04736	0.97378141	0.22178616	3316.6492
337.94824	0.98003316	0.22266847	3323.6846
338.84912	0.97993177	0.22374637	3322.5918
339.75	0.98035342	0.22484316	3321.97
340.65088	0.98978293	0.22578798	3330.7224
341.55176	0.98842269	0.22664364	3324.2891
342.45264	0.99072343	0.22749083	3318.6123
343.35352	0.99567103	0.22833568	3329.7603
344.25439	0.99687707	0.2293238	3330.2327
345.15527	0.99979097	0.23055029	3332.3416
346.05615	1.0019654	0.23158497	3331.1145
346.95703	1.0075122	0.23254612	3339.7017
347.85791	1.0070926	0.23351996	3340.0974
348.75879	1.0141596	0.23422126	3333.1707
349.65967	1.0142213	0.2352739	3338.6699
350.56055	1.015968	0.23608267	3338.4861
351.46143	1.0200713	0.23706988	3344.2117
352.3623	1.023981	0.23808147	3349.2932
353.26318	1.0234544	0.23909411	3344.6885
354.16406	1.0277303	0.24015215	3349.6912
355.06494	1.0313872	0.24096309	3346.3542
355.96582	1.0314542	0.2419112	3347.5774
356.8667	1.0371616	0.24302207	3352.6567
357.76758	1.0366385	0.24407762	3347.3665
358.66846	1.0426129	0.24508138	3359.8633
359.56934	1.0436726	0.24626878	3361.427
360.47021	1.0433955	0.24719317	3351.6929
361.37109	1.0497737	0.24804763	3357.1851
362.27197	1.0510486	0.24914436	3360.5142
363.17285	1.0540588	0.25030437	3362.6338
364.07373	1.0571207	0.25159398	3361.668
364.97461	1.0600852	0.25282463	3375.2571
365.87549	1.063656	0.25384501	3371.1396
366.77637	1.0660136	0.25482684	3364.8184
367.67725	1.0688593	0.25562751	3368.2017
368.57813	1.0711231	0.25642353	3359.0649
369.479	1.0742785	0.25740999	3374.5566
370.37988	1.0763595	0.25833398	3374.4392
371.28076	1.0798842	0.25935856	3374.075
372.18164	1.0826571	0.26031244	3374.3662
373.08252	1.0845662	0.26135767	3376.4395
373.9834	1.0866016	0.26240388	3381.9185
374.88428	1.0911901	0.26343432	3382.7063
375.78516	1.0914313	0.26436749	3377.9456
376.68604	1.0921007	0.26527396	3376.9573
377.58691	1.0976886	0.26615694	3383.6519
378.48779	1.1009871	0.26718533	3386.8926
379.38867	1.1015846	0.26801857	3384.9043
380.28955	1.1044325	0.26907653	3387.7236
381.19043	1.1099702	0.27019471	3393.5122
382.09131	1.1106424	0.27114329	3389.4985
382.99219	1.1116518	0.2720204	3385.8418
383.89307	1.1194993	0.27307558	3400.6726
384.79395	1.1199454	0.2738837	3389.5427
385.69482	1.1222726	0.27492887	3396.356
386.5957	1.1263911	0.27591485	3393.2747
387.49658	1.1311779	0.2767306	3396.0176
388.39746	1.1317931	0.27786398	3402.7466
389.29834	1.1327659	0.27873868	3397.1736
390.19922	1.1351775	0.27968654	3400.4622
391.1001	1.136711	0.28061542	3397.3599
392.00098	1.1391644	0.28147519	3398.5364
392.90186	1.1441563	0.28241736	3408.907
393.80273	1.1455363	0.28332543	3404.0754
394.70361	1.1499634	0.28439599	3410.1797
395.60449	1.1531819	0.28525749	3412.8796
396.50537	1.1536902	0.28629181	3406.6313
397.40625	1.1575161	0.28752223	3417.2432
398.30713	1.1622207	0.28866962	3416.6035
399.20801	1.1640792	0.2894859	3409.5269
400.10889	1.1630819	0.29052645	3414.0479
401.00977	1.1687425	0.291448	3415.3267
401.91064	1.1701202	0.29236761	3415.2009
402.81152	1.1721802	0.29323635	3417.5393
403.7124	1.1731031	0.29429677	3421.2798
404.61328	1.1798905	0.29528418	3425.0161
405.51416	1.1820681	0.29629922	3423.4683
406.41504	1.1848379	0.29733276	3424.0042
407.31592	1.1880275	0.29830572	3419.3484
408.2168	1.1925014	0.29924873	3429.8201
409.11768	1.1942971	0.30032271	3428.5798
410.01855	1.1969012	0.30130678	3435.4387
410.91943	1.1979476	0.30252624	3427.0254
411.82031	1.2021054	0.3034907	3427.3428
412.72119	1.2020779	0.30434269	3432.949
413.62207	1.2066408	0.30517489	3430.6514
414.52295	1.2081444	0.30613738	3434.9883
415.42383	1.2105341	0.30729005	3436.052
416.32471	1.2130604	0.3083379	3437.0503
417.22559	1.2218981	0.30932996	3436.9119
418.12646	1.2195383	0.30996349	3437.4888
419.02734	1.2210443	0.31086275	3430.2869
419.92822	1.2245904	0.31174666	3440.5789
420.8291	1.2299581	0.31266958	3447.6724
421.72998	1.2285542	0.31340685	3436.0247
422.63086	1.2334096	0.31416252	3440.3323
423.53174	1.2345151	0.31522775	3444.855
424.43262	1.2383285	0.31602883	3442.5505
425.3335	1.2401017	0.31700197	3449.2502
426.23438	1.2427562	0.31803349	3450.1052
427.13525	1.2461101	0.31929627	3450.4043
428.03613	1.2489088	0.32039955	3453.7625
428.93701	1.251721	0.32157326	3457.3413
429.83789	1.2560407	0.32265335	3456.1716
430.73877	1.2566655	0.32358134	3456.1001
431.63965	1.2610044	0.32443723	3456
432.54053	1.2623533	0.32531363	3450.2844
433.44141	1.2651799	0.3262963	3462.4453
434.34229	1.2669122	0.32722586	3460.906
435.24316	1.2718611	0.32818416	3456.1135
436.14404	1.2741899	0.32920659	3457.7986
437.04492	1.2745652	0.33031556	3464.4441
437.9458	1.2790596	0.33129826	3465.5095
438.84668	1.2789356	0.33236372	3467.0212
439.74756	1.2865258	0.33348778	3466.4795
440.64844	1.2841592	0.3343983	3463.74
441.54932	1.2891845	0.33552229	3469.5354
442.4502	1.293806	0.3363905	3470.4995
443.35107	1.2972093	0.33731183	3468.948
444.25195	1.2987454	0.33824649	3475.6753
445.15283	1.3006958	0.3392241	3476.9419
446.05371	1.3028042	0.3403199	3473.0916
446.95459	1.3044939	0.34125006	3474.6873
447.85547	1.3083313	0.34224725	3476.6069
448.75635	1.3101394	0.34338573	3477.0769
449.65723	1.3142247	0.34434763	3480.531
450.55811	1.3172083	0.34537429	3479.6069
451.45898	1.3196074	0.34626621	3477.7341
452.35986	1.3239403	0.34716791	3480.7561
453.26074	1.3260121	0.34807205	3485.5447
454.16162	1.3296435	0.34903154	3489.0544
455.0625	1.330826	0.34998718	3482.7051
455.96338	1.334571	0.35091007	3486.7979
456.86426	1.333717	0.35176697	3484.1963
457.76514	1.3382423	0.35295674	3488.5771
458.66602	1.3429943	0.35398889	3496.7544
459.56689	1.3452084	0.35491717	3487.1697
460.46777	1.3465916	0.35623479	3500.5449
461.36865	1.3495463	0.35729343	3491.7922
462.26953	1.3494824	0.35843101	3487.3335
463.17041	1.3557997	0.35919991	3487.9453
464.07129	1.3571962	0.3601639	3490.1362
464.97217	1.3617297	0.36114019	3504.6018
465.87305	1.3622373	0.36198607	3497.0637
466.77393	1.3628737	0.36304796	3494.5376
467.6748	1.3684949	0.36403582	3498.4333
468.57568	1.3705626	0.36515889	3504.5659
469.47656	1.3732296	0.36605975	3501.0767
470.37744	1.373958	0.36688316	3499.3638
471.27832	1.3804808	0.36766621	3499.5281
472.1792	1.3821604	0.3686482	3504.4868
473.08008	1.3843403	0.36973953	3509.9587
473.98096	1.3870049	0.37085676	3510.8618
474.88184	1.3892803	0.37188867	3503.5483
475.78271	1.3934016	0.3730208	3513.8767
476.68359	1.39303	0.37398493	3512.5378
477.58447	1.3977326	0.37505627	3512.4609
478.48535	1.401354	0.37617153	3514.6099
479.38623	1.4034201	0.37719336	3520.7249
480.28711	1.4056946	0.37838238	3523.3376
481.18799	1.4070913	0.37934116	3514.7842
482.08887	1.4116144	0.38034612	3519.8481
482.98975	1.4135326	0.38130915	3513.7708
483.89063	1.4186397	0.38234538	3522.9563
484.7915	1.4197663	0.38309461	3515.2998
485.69238	1.4206477	0.38422322	3521.1333
486.59326	1.4249434	0.38500592	3525.2913
487.49414	1.4287568	0.38617474	3533.5396
488.39502	1.4320397	0.38726547	3527.0442
489.2959	1.432505	0.38831499	3523.3125
490.19678	1.4374163	0.38908681	3519.7639
491.09766	1.4364191	0.39008081	3521.1768
491.99854	1.4417412	0.39095843	3524.2983
492.89941	1.4417892	0.39200726	3525.4648
493.80029	1.4465452	0.39297289	3529.2803
494.70117	1.449627	0.39409745	3531.6897
495.60205	1.4522799	0.39503041	3531.4839
496.50293	1.45318	0.39582956	3528.3616
497.40381	1.4564918	0.3968285	3533.3101
498.30469	1.4609717	0.39786506	3538.2329
499.20557	1.4615109	0.39894959	3535.7546
500.10645	1.4654684	0.40002599	3535.2234
501.00732	1.4691484	0.40106127	3533.0454
501.9082	1.4713004	0.40206608	3537.6594
502.80908	1.4713471	0.40306121	3538.981
503.70996	1.4777648	0.40419725	3543.9021
504.61084	1.4797778	0.40512866	3542.1216
505.51172	1.4838436	0.40622041	3543.8521
506.4126	1.4874433	0.40723777	3546.3662
507.31348	1.486873	0.40809342	3540.1865
508.21436	1.489916	0.40901938	3547.0244
509.11523	1.4924877	0.41015759	3553.2537
510.01611	1.4967718	0.41144243	3556.53
510.91699	1.4970785	0.41256803	3549.0872
511.81787	1.5007242	0.41373089	3552.0596
512.71875	1.5015621	0.41463137	3548.052
513.61963	1.504011	0.41563454	3548.0017
514.52051	1.5092643	0.41676897	3557.4502
515.42139	1.5137728	0.41800514	3556.4797
516.32227	1.5151639	0.41877446	3549.0757
517.22314	1.5204915	0.41971242	3554.4148
518.12402	1.5190109	0.42053413	3549.6155
519.0249	1.5245763	0.42154971	3557.0532
519.92578	1.5286314	0.42267552	3565.7253
520.82666	1.5296223	0.42377308	3563.7993
521.72754	1.5321832	0.4246453	3557.6309
522.62842	1.5369684	0.4258579	3564.4126
523.5293	1.5358061	0.42681107	3563.4204
524.43018	1.5388523	0.42792332	3559.4727
525.33105	1.544613	0.42915517	3564.2375
526.23193	1.5444734	0.43009287	3567.8147
527.13281	1.5465615	0.43105662	3562.7693
528.03369	1.5507289	0.4319973	3562.0798
528.93457	1.5520627	0.43277732	3557.78
529.83545	1.5552915	0.43362772	3562.9016
530.73633	1.5583394	0.43479875	3571.5964
531.63721	1.560414	0.43577576	3567.075
532.53809	1.5621588	0.43675441	3565.9412
533.43896	1.5652143	0.43787649	3572.0623
534.33984	1.5693871	0.43888825	3575.9612
535.24072	1.5727541	0.43991765	3573.6682
536.1416	1.5743628	0.44111276	3575.7639
537.04248	1.5743136	0.44207567	3570.7166
537.94336	1.5795567	0.44315323	3575.7651
538.84424	1.5823981	0.44416869	3579.0906
539.74512	1.5819609	0.44522291	3576.7021
540.646	1.5873601	0.4461208	3572.1467
541.54688	1.5923504	0.44701535	3579.4507
542.44775	1.5945965	0.44798213	3576.2971
543.34863	1.5955169	0.44906029	3580.5898
544.24951	1.5978353	0.45026621	3583.6074
545.15039	1.6007311	0.4515695	3585.8347
546.05127	1.6043849	0.45271921	3582.2959
546.95215	1.6069235	0.4537434	3586.9827
547.85303	1.6108508	0.45487639	3588.4631
548.75391	1.6107781	0.45603573	3583.7969
549.65479	1.6149418	0.45696288	3583.8062
550.55566	1.6166395	0.45796144	3588.7632
551.45654	1.6223727	0.4589892	3589.095
552.35742	1.6219313	0.46015549	3593.9941
553.2583	1.6256266	0.46148083	3590.6582
554.15918	1.6282353	0.46250936	3592.4873
555.06006	1.6303334	0.46353537	3590.0037
555.96094	1.6309434	0.46430191	3588.0444
556.86182	1.6332406	0.46535617	3593.0391
557.7627	1.6368757	0.46639189	3591.6699
558.66357	1.6422451	0.46728832	3592.9363
559.56445	1.6438534	0.4681665	3591.3804
560.46533	1.6458418	0.4693566	3600.6089
561.36621	1.6492141	0.47044033	3595.5796
562.26709	1.6500804	0.47144902	3593.167
563.16797	1.6527464	0.47250837	3596.4065
564.06885	1.6582432	0.4734976	3602.0413
564.96973	1.6596187	0.47433296	3593.8716
565.87061	1.6630515	0.47529578	3600.0703
566.77148	1.6644435	0.47649834	3604.6575
567.67236	1.6689932	0.47754562	3597.7634
568.57324	1.6713558	0.47864327	3604.1882
569.47412	1.6723644	0.47981715	3604.126
570.375	1.6752793	0.48100552	3604.2585
571.27588	1.6797934	0.48218098	3604.6794
572.17676	1.682676	0.48325962	3603.1316
573.07764	1.6832436	0.4842236	3604.9114
573.97852	1.6860526	0.48517334	3604.3225
574.87939	1.6883464	0.48636138	3606.4465
575.78027	1.6921555	0.48719886	3600.7776
576.68115	1.6940089	0.48825425	3603.2156
577.58203	1.6998093	0.48919201	3609.6909
578.48291	1.6988178	0.49047291	3615.0928
579.38379	1.7031307	0.49176759	3616.5469
580.28467	1.7087194	0.49300557	3612.0171
581.18555	1.708848	0.4939962	3613.6919
582.08643	1.7119633	0.49517739	3617.958
582.9873	1.7151899	0.49625993	3617.7432
583.88818	1.7179321	0.49728709	3614.0767
584.78906	1.718496	0.49820793	3614.6189
585.68994	1.7221744	0.49933863	3612.1096
586.59082	1.7250565	0.50034416	3618.1509
587.4917	1.7278146	0.50157946	3617.968
588.39258	1.7306383	0.50273418	3620.2146
589.29346	1.7334119	0.50381857	3621.78
590.19434	1.7347561	0.50489205	3613.1677
591.09521	1.7378416	0.50614482	3619.0198
591.99609	1.7412277	0.50730276	3626.3513
592.89697	1.7437389	0.50849211	3620.116
593.79785	1.7469519	0.50971329	3623.1843
594.69873	1.7493504	0.5107224	3626.2212
595.59961	1.7500523	0.51181585	3620.3679
596.50049	1.7554954	0.51288319	3622.0571
597.40137	1.7573546	0.51364523	3616.3496
598.30225	1.7609973	0.51454049	3622.5349
599.20313	1.7645893	0.51556575	3626.8982
600.104	1.7671564	0.51667988	3629.6174
601.00488	1.7687978	0.51785952	3629.1904
601.90576	1.7705703	0.51903689	3629.2161
602.80664	1.7732582	0.52032596	3631.7876
603.70752	1.7782826	0.52158737	3632.2451
604.6084	1.7761115	0.52262634	3625.9932
605.50928	1.7818161	0.52398765	3630.8005
606.41016	1.7833788	0.52518463	3628.7607
607.31104	1.7900437	0.52640188	3637.1619
608.21191	1.7898985	0.52754474	3632.1909
609.11279	1.7929614	0.52862418	3629.4617
610.01367	1.7966012	0.52961236	3634.0862
610.91455	1.7955978	0.53066176	3633.769
611.81543	1.8031986	0.53177476	3640.8877
612.71631	1.8026028	0.53306043	3639.4512
613.61719	1.8071436	0.53426266	3639.4111
614.51807	1.8097999	0.53538626	3639.0378
615.41895	1.8139352	0.53644389	3637.1985
616.31982	1.8151994	0.53762305	3638.6655
617.2207	1.8195456	0.53875268	3641.0447
618.12158	1.8214744	0.5398255	3642.8892
619.02246	1.8212752	0.54109871	3639.4456
619.92334	1.8246592	0.54223156	3644.1687
620.82422	1.8286117	0.54332244	3643.6096
621.7251	1.8290435	0.54462701	3644.5825
622.62598	1.832117	0.54565203	3639.7581
623.52686	1.835171	0.54688382	3642.2439
624.42773	1.8369503	0.54790848	3643.3833
625.32861	1.8369259	0.54923898	3642.2419
626.22949	1.8455321	0.55059874	3647.5974
627.13037	1.8459315	0.55166209	3647.5151
628.03125	1.8487152	0.55282098	3647.0693
628.93213	1.8505932	0.55391759	3644.2207
629.83301	1.8558177	0.55501282	3649.7444
630.73389	1.857111	0.55607331	3646.6743
631.63477	1.8593959	0.55740267	3648.2778
632.53564	1.8648638	0.55858558	3650.8772
633.43652	1.8661038	0.55971825	3648.467
634.3374	1.865914	0.560781	3648.5542
635.23828	1.8731865	0.56187898	3653.2317
636.13916	1.8722682	0.56294185	3651.5515
637.04004	1.8744594	0.56398284	3653.178
637.94092	1.8777812	0.56503189	3649.3682
638.8418	1.8778396	0.56635112	3654.2874
639.74268	1.8826151	0.56750429	3653.4443
640.64355	1.887418	0.56870967	3655.3237
641.54443	1.8893569	0.56988913	3657.6152
642.44531	1.8931957	0.57103807	3656.394
643.34619	1.8970625	0.57230645	3660.7185
644.24707	1.8967518	0.5734815	3655.5269
645.14795	1.8996441	0.57479519	3658.8967
646.04883	1.9037557	0.57604051	3661.4646
646.94971	1.9065094	0.5772233	3662.1726
647.85059	1.9060193	0.57838804	3657.9146
648.75146	1.9130678	0.5797506	3665.4805
649.65234	1.9146267	0.58096731	3662.1157
650.55322	1.9184488	0.58208627	3659.1411
651.4541	1.92003	0.58319312	3663.28
652.35498	1.9222077	0.58454651	3664.9768
653.25586	1.9247177	0.58576041	3664.0371
654.15674	1.9243294	0.5869512	3660.8301
655.05762	1.9310369	0.58821368	3665.3091
655.9585	1.9329017	0.58943212	3663.9297
656.85938	1.935195	0.59050852	3662.0386
657.76025	1.9409028	0.59165728	3666.1206
658.66113	1.9415677	0.59277785	3667.9863
659.56201	1.9474336	0.59426284	3674.8684
660.46289	1.9463902	0.59566998	3666.7107
661.36377	1.9496144	0.59682834	3671.7007
662.26465	1.9516515	0.59788501	3664.1462
663.16553	1.9548041	0.59924102	3673.2839
664.06641	1.9568189	0.60052449	3666.6582
664.96729	1.9592534	0.6017822	3671.0496
665.86816	1.9620854	0.60300833	3668.144
666.76904	1.9634571	0.6040625	3667.3098
667.66992	1.9671341	0.60543412	3671.3135
668.5708	1.969695	0.60662568	3673.6047
669.47168	1.9759461	0.60794163	3668.8999
670.37256	1.974883	0.60905302	3668.0132
671.27344	1.9785801	0.61014807	3670.5002
672.17432	1.9801539	0.61134934	3673.2927
673.0752	1.9829912	0.61260045	3669.2852
673.97607	1.9869188	0.61369383	3668.2246
674.87695	1.9889772	0.61496568	3675.4773
675.77783	1.9947101	0.61620498	3675.6709
676.67871	1.9938616	0.61738408	3672.6311
677.57959	1.9979426	0.61872232	3681.6631
678.48047	2.0010355	0.61985093	3675.0869
679.38135	2.0053115	0.62127382	3680.0842
680.28223	2.0077083	0.62237245	3675.7151
681.18311	2.0103943	0.62370336	3684.1948
682.08398	2.011739	0.62482953	3686.8547
682.98486	2.015722	0.62623239	3686.7334
683.88574	2.0147381	0.62774122	3682.6831
684.78662	2.0202138	0.6289016	3674.8318
685.6875	2.0258944	0.63004333	3675.8721
686.58838	2.0277302	0.63122785	3679.2737
687.48926	2.0271111	0.63239503	3679.125
688.39014	2.0268941	0.63368696	3678.689
689.29102	2.0316532	0.63530606	3683.8376
690.19189	2.0342522	0.63658929	3677.9177
691.09277	2.0401335	0.63806361	3679.5552
691.99365	2.0419133	0.63940638	3682.8445
692.89453	2.0441327	0.64067739	3680.6216
693.79541	2.0470438	0.64200836	3684.292
694.69629	2.0514555	0.64310747	3680.8301
695.59717	2.0513937	0.64429522	3684.8567
696.49805	2.0554111	0.64561445	3685.9175
697.39893	2.0560646	0.64696807	3685.7419
698.2998	2.0588107	0.64834273	3684.771
699.20068	2.062691	0.64955634	3679.8901
700.10156	2.0660794	0.6511147	3688.7654
701.00244	2.0706162	0.65246707	3686.4385
701.90332	2.0707994	0.65407795	3689.6543
702.8042	2.0730898	0.65558696	3685.7439
703.70508	2.0764372	0.65681589	3684.6899
704.60596	2.0786104	0.65813792	3693.3069
705.50684	2.0823236	0.6592356	3685.4805
706.40771	2.0858464	0.66026366	3681.8276
707.30859	2.0843527	0.66149324	3685.4021
708.20947	2.0893223	0.66247874	3686.8662
709.11035	2.0916862	0.66401857	3693.8069
710.01123	2.0950923	0.66518909	3688.7942
710.91211	2.0984211	0.66662627	3692.196
711.81299	2.099256	0.66816235	3690.1003
712.71387	2.1033587	0.66958088	3688.228
713.61475	2.1054313	0.67103392	3693.9375
714.51563	2.1078806	0.6724605	3689.0085
715.4165	2.1107526	0.67376882	3688.303
716.31738	2.1114075	0.67501122	3684.7412
717.21826	2.1168034	0.676135	3686.9795
718.11914	2.1162322	0.67728084	3690.689
719.02002	2.1228344	0.67873615	3698.6963
719.9209	2.1228676	0.6801514	3696.9314
720.82178	2.1261981	0.68153149	3688.6907
721.72266	2.1281586	0.68290085	3688.1917
722.62354	2.1332519	0.68423504	3692.5623
723.52441	2.1362941	0.68569505	3694.5029
724.42529	2.1407185	0.6870479	3698.3274
725.32617	2.1435153	0.68862271	3701.4009
726.22705	2.1435113	0.69013286	3696.2405
727.12793	2.1452584	0.69160855	3698.499
728.02881	2.1487918	0.69330353	3692.9546
728.92969	2.1542351	0.69480723	3695.7979
729.83057	2.1560185	0.69619578	3694.9651
730.73145	2.1586733	0.69772267	3702.5337
731.63232	2.1602867	0.69916338	3693.5349
732.5332	2.161747	0.70067573	3691.7188
733.43408	2.1661744	0.70199013	3692.3164
734.33496	2.1697383	0.70326316	3696.5486
735.23584	2.1712911	0.70472407	3700.1787
736.13672	2.1724539	0.70609784	3700.8823
737.0376	2.1759689	0.70761567	3700.833
737.93848	2.1805663	0.70921797	3695.5964
738.83936	2.1811447	0.71060914	3698.3665
739.74023	2.1856248	0.71207207	3695.7576
740.64111	2.1886401	0.71350628	3698.3318
741.54199	2.1900773	0.71488488	3694.4536
742.44287	2.1914868	0.71636546	3701.3613
743.34375	2.1963358	0.71769691	3696.554
744.24463	2.1997361	0.71905494	3700.9788
745.14551	2.1982696	0.72045225	3700.3269
746.04639	2.2044218	0.72193092	3699.2488
746.94727	2.2065525	0.72338271	3701.802
747.84814	2.2100067	0.72480595	3699.1387
748.74902	2.2113452	0.72626317	3700.1963
749.6499	2.2156992	0.72768664	3703.3306
750.55078	2.2207601	0.72918248	3705.1824
751.45166	2.2192936	0.73092574	3710.261
752.35254	2.2208288	0.73249388	3704.0259
753.25342	2.2247097	0.73422122	3705.3962
754.1543	2.2281523	0.7357201	3701.8335
755.05518	2.2299802	0.73720807	3700.9121
755.95605	2.2330592	0.738397	3698.1521
756.85693	2.235424	0.73994511	3705.6604
757.75781	2.2403796	0.74137878	3701.8618
758.65869	2.2428608	0.74287027	3708.2893
759.55957	2.2424004	0.74461424	3704.9941
760.46045	2.2486823	0.74633396	3706.7036
761.36133	2.2500579	0.74778783	3704.0703
762.26221	2.2502086	0.74955267	3703.3896
763.16309	2.2568526	0.75104201	3704.1655
764.06396	2.25845	0.75252593	3703.988
764.96484	2.2609348	0.75384808	3701.5042
765.86572	2.2617693	0.75552309	3709.7754
766.7666	2.2658393	0.75715631	3702.6775
767.66748	2.2683606	0.75889516	3709.196
768.56836	2.2757611	0.76041573	3708.6289
769.46924	2.2763407	0.76189685	3706.4133
770.37012	2.2769017	0.76336575	3704.165
771.271	2.2807133	0.76483494	3705.3708
772.17188	2.281641	0.76642615	3705.936
773.07275	2.2857513	0.76810819	3706.2871
773.97363	2.2875679	0.76987678	3708.9326
774.87451	2.2910683	0.77175039	3705.4492
775.77539	2.2930284	0.7733295	3703.0645
776.67627	2.2944498	0.77489108	3701.0764
777.57715	2.2941339	0.77623034	3693.323
778.47803	2.2988877	0.77759022	3697.3296
779.37891	2.303328	0.77904952	3701.2964
780.27979	2.3046155	0.78062677	3704.3118
781.18066	2.3096216	0.78211486	3707.9128
782.08154	2.3137698	0.78368789	3707.0977
782.98242	2.3193822	0.7850607	3708.0649
783.8833	2.3163781	0.78674912	3710.8865
784.78418	2.3194973	0.78868484	3710.8999
785.68506	2.3216994	0.79043454	3706.1724
786.58594	2.3264515	0.79227906	3707.7278
787.48682	2.3276191	0.7940051	3709.3684
788.3877	2.3292441	0.79570282	3707.9827
789.28857	2.3334248	0.79727381	3707.2346
790.18945	2.3352637	0.79876882	3703.2747
791.09033	2.3407292	0.80042094	3702.0415
791.99121	2.3431182	0.80196959	3705.5569
792.89209	2.3437729	0.80349541	3706.3877
793.79297	2.3496249	0.80542344	3710.6099
794.69385	2.3495255	0.80721909	3704.2522
795.59473	2.3518209	0.80911434	3706.6492
796.49561	2.3551023	0.81081426	3704.3945
797.39648	2.3590004	0.81290263	3716.5049
798.29736	2.3593371	0.81506062	3702.9451
799.19824	2.3632097	0.81696445	3706.354
800.09912	2.3665025	0.81850296	3705.3525
801	2.3680606	0.82023859	3702.615
801.90088	2.3724134	0.82187384	3701.6108
802.80176	2.3730569	0.82351983	3703.8411
803.70264	2.3750682	0.8251875	3699.7305
804.60352	2.3795619	0.82722831	3705.3901
805.50439	2.3824887	0.82908142	3706.5957
806.40527	2.3834541	0.83103812	3702.2019
807.30615	2.3877676	0.8328194	3707.6799
808.20703	2.390043	0.83477944	3705.4146
809.10791	2.3934715	0.83675861	3709.1453
810.00879	2.3960919	0.83852541	3701.7756
810.90967	2.3997705	0.84011918	3709.2136
811.81055	2.4001815	0.84208238	3705.4104
812.71143	2.4061096	0.84423262	3706.2617
813.6123	2.4054825	0.84616315	3702.3748
814.51318	2.4090166	0.847821	3697.2112
815.41406	2.4110951	0.84939373	3701.2864
816.31494	2.4142048	0.85097605	3702.6694
817.21582	2.4156625	0.85285366	3703.4661
818.1167	2.4183443	0.85480487	3698.6792
819.01758	2.4244254	0.85638905	3697.4033
819.91846	2.4250116	0.85806644	3707.863
820.81934	2.4290965	0.86018324	3710.9714
821.72021	2.4302583	0.8624894	3704.3833
822.62109	2.4340906	0.86477506	3707.8267
823.52197	2.4345541	0.86696541	3700.311
824.42285	2.4376402	0.8688069	3695.552
825.32373	2.4414048	0.87060344	3697.9714
826.22461	2.4464347	0.87214017	3699.374
827.12549	2.4457953	0.87402987	3706.9634
828.02637	2.450439	0.876293	3706.4983
828.92725	2.4488931	0.87835026	3700.2715
829.82813	2.455507	0.88020456	3698.6208
830.729	2.4560156	0.88205391	3703.2034
831.62988	2.4599531	0.88428921	3702.2148
832.53076	2.4646487	0.88632125	3698.0833
833.43164	2.4658611	0.88809043	3697.9995
834.33252	2.4679735	0.89005834	3701.0232
835.2334	2.4738934	0.89212745	3707.4548
836.13428	2.4751894	0.89411247	3700.6536
837.03516	2.4791963	0.89610946	3698.9426
837.93604	2.4795916	0.89810854	3696.7637
838.83691	2.4810808	0.89986497	3695.1611
839.73779	2.4864309	0.90165764	3698.0862
840.63867	2.4870009	0.90363985	3697.4907
841.53955	2.4910624	0.90573829	3701.8977
842.44043	2.4934938	0.90769881	3697.4607
843.34131	2.4942286	0.91014677	3703.0405
844.24219	2.4956348	0.91291493	3694.0664
845.14307	2.5012028	0.91525358	3698.8237
846.04395	2.5032275	0.91753733	3697.2197
846.94482	2.5053761	0.91948223	3695.9019
847.8457	2.5096929	0.92143208	3698.2129
848.74658	2.5098798	0.92356402	3691.7202
849.64746	2.5138619	0.92523253	3689.3062
850.54834	2.5189586	0.92714453	3692.9744
851.44922	2.5213475	0.92877042	3685.9514
852.3501	2.522294	0.93065059	3691.9502
853.25098	2.5239074	0.93311483	3695.8894
854.15186	2.5276549	0.93545687	3693.5073
855.05273	2.5291195	0.93802452	3691.178
855.95361	2.5354197	0.93990225	3688.8206
856.85449	2.5335829	0.94212019	3687.8042
857.75537	2.5384481	0.94440615	3692.6394
858.65625	2.5423169	0.94637942	3684.459
859.55713	2.5443265	0.9482168	3684.6833
860.45801	2.5457647	0.95027131	3691.7095
861.35889	2.5480258	0.95289588	3696.5049
862.25977	2.550597	0.95572865	3690.1646
863.16064	2.5545521	0.95815986	3688.5833
864.06152	2.5595148	0.96021384	3687.3838
864.9624	2.5635791	0.96229547	3685.5337
865.86328	2.5633664	0.96467572	3687.239
866.76416	2.5654776	0.96706569	3684.8999
867.66504	2.5673804	0.96969336	3687.5767
868.56592	2.5704589	0.9724865	3683.5591
869.4668	2.571157	0.97496492	3684.3838
870.36768	2.5771449	0.97745329	3683.7156
871.26855	2.5793095	0.97985679	3680.5271
872.16943	2.5809565	0.9820286	3681.1626
873.07031	2.5849464	0.98408151	3682.8894
873.97119	2.5868144	0.98629528	3677.5503
874.87207	2.5902896	0.98855788	3678.3694
875.77295	2.5922618	0.99059296	3673.425
876.67383	2.5952175	0.99259931	3677.3711
877.57471	2.5984356	0.99495268	3680.1045
878.47559	2.6013067	0.99761838	3681.155
879.37646	2.602813	1.0004549	3682.5332
880.27734	2.6042824	1.0031163	3673.9282
881.17822	2.6053119	1.0064222	3674.8237
882.0791	2.6100202	1.0096776	3677.7949
882.97998	2.6141183	1.0122786	3671.4971
883.88086	2.6171546	1.0144588	3674.4644
884.78174	2.6231427	1.0167342	3671.0605
885.68262	2.6246331	1.0188787	3670.8311
886.5835	2.6270306	1.0208756	3665.1868
887.48438	2.6277521	1.0228556	3666.8188
888.38525	2.6314659	1.0253153	3674.3228
889.28613	2.6342258	1.0282604	3670.0181
890.18701	2.635129	1.0310544	3662.304
891.08789	2.638634	1.0335797	3664.1726
891.98877	2.6408498	1.0361971	3663.8525
892.88965	2.6442397	1.0387394	3667.3628
893.79053	2.6483474	1.0414842	3665.4045
894.69141	2.6486688	1.0440015	3658.0188
895.59229	2.6526866	1.0464385	3656.8037
896.49316	2.6554313	1.0488226	3659.4722
897.39404	2.6560082	1.0514057	3661.8225
898.29492	2.6603026	1.0539302	3654.7903
899.1958	2.6638396	1.0565223	3657.8086
900.09668	2.6659777	1.0591671	3654.5681
900.99756	2.6690686	1.0619899	3662.5308
901.89844	2.672332	1.0645598	3652.7327
902.79932	2.6742368	1.0673651	3655.187
903.7002	2.6776271	1.0708594	3655.9558
904.60107	2.6761556	1.0735614	3646.717
905.50195	2.6825254	1.0761099	3645.8181
906.40283	2.6853759	1.0785054	3643.1787
907.30371	2.6886191	1.0811411	3650.2344
908.20459	2.6891315	1.0838237	3643.6016
909.10547	2.6961577	1.0866576	3650.2827
910.00635	2.6958983	1.0893275	3648.3738
910.90723	2.6966219	1.092046	3639.0229
911.80811	2.7004261	1.0944598	3638.3479
912.70898	2.7042513	1.0972259	3648.2341
913.60986	2.7048275	1.1000115	3636.0315
914.51074	2.710176	1.102549	3636.4553
915.41162	2.7110784	1.105369	3635.4543
916.3125	2.7153175	1.1080955	3633.364
917.21338	2.7180612	1.111055	3633.1602
918.11426	2.7220759	1.1138818	3630.0171
919.01514	2.724051	1.1163344	3626.3088
919.91602	2.7245312	1.1188265	3622.3059
920.81689	2.7293415	1.1212401	3626.5745
921.71777	2.7303355	1.123648	3626.085
922.61865	2.7347372	1.1264119	3627.1323
923.51953	2.7380261	1.1295159	3622.6592
924.42041	2.7388909	1.1321495	3616.9324
925.32129	2.7403378	1.1345221	3618.9255
926.22217	2.7447097	1.1374904	3623.6272
927.12305	2.7485869	1.1400409	3609.7114
928.02393	2.7490592	1.1426324	3613.3706
928.9248	2.7498968	1.1461377	3614.3059
929.82568	2.7564969	1.1488354	3605.1558
930.72656	2.7588427	1.1515096	3613.9304
931.62744	2.759527	1.1542528	3603.3481
932.52832	2.764847	1.1566771	3604.4717
933.4292	2.7661104	1.1589988	3602.0115
934.33008	2.7699327	1.1619605	3605.7087
935.23096	2.7678876	1.1651598	3601.8982
936.13184	2.7735147	1.1682183	3598.4526
937.03271	2.7790976	1.1711298	3596.1838
937.93359	2.7799499	1.1740469	3598.7988
938.83447	2.782896	1.1769834	3588.8098
939.73535	2.7854846	1.1799282	3588.8186
940.63623	2.788945	1.18309	3589.9309
941.53711	2.7929568	1.1857307	3587.5046
942.43799	2.7926102	1.1884992	3582.9646
943.33887	2.7967904	1.1909457	3577.3218
944.23975	2.7982156	1.193395	3584.8665
945.14063	2.7990935	1.1965077	3583.9651
946.0415	2.8046629	1.1997755	3576.8411
946.94238	2.8065279	1.202904	3574.3347
947.84326	2.8088207	1.2056792	3569.0176
948.74414	2.8146279	1.2081707	3565.959
949.64502	2.8150091	1.2107285	3562.3052
950.5459	2.8168066	1.2136022	3570.4067
951.44678	2.8176293	1.2166396	3560.6279
952.34766	2.8216805	1.2198365	3567.3567
953.24854	2.8264651	1.2229704	3557.032
954.14941	2.827785	1.2256913	3555.7964
955.05029	2.8296854	1.2287821	3557.5386
955.95117	2.8335738	1.2319638	3550.5483
956.85205	2.8336711	1.2344943	3540.7546
957.75293	2.8403127	1.2368721	3548.9675
958.65381	2.840728	1.2396282	3551.1692
959.55469	2.8417871	1.2427328	3543.303
960.45557	2.8466802	1.2456274	3539.7925
961.35645	2.8510652	1.2485007	3537.041
962.25732	2.8518386	1.2507366	3535.2449
963.1582	2.8532987	1.253736	3541.5344
964.05908	2.8594944	1.2571486	3534.3718
964.95996	2.8585367	1.2601782	3527.0371
965.86084	2.8610969	1.2630632	3523.9534
966.76172	2.8652759	1.2664218	3524.9197
967.6626	2.8688321	1.2696193	3517.6494
968.56348	2.8737442	1.2722771	3511.8809
969.46436	2.8752012	1.2748753	3517.0046
970.36523	2.8745778	1.2779993	3513.709
971.26611	2.8790157	1.2809625	3506.1389
972.16699	2.8813968	1.2835202	3504.4937
973.06787	2.8844531	1.2863958	3508.9915
973.96875	2.8870826	1.2895927	3503.9578
974.86963	2.8893883	1.2934737	3498.9653
975.77051	2.8931234	1.2969791	3498.1292
976.67139	2.8947494	1.3000083	3486.9475
977.57227	2.897779	1.3027729	3487.7913
978.47314	2.8990896	1.3054082	3484.269
979.37402	2.908777	1.3082112	3487.3638
980.2749	2.9056685	1.3110929	3480.4211
981.17578	2.9098153	1.3140808	3482.0791
982.07666	2.9131877	1.3171091	3472.9558
982.97754	2.916842	1.3202654	3471.8782
983.87842	2.9162741	1.3234389	3465.6853
984.7793	2.9198084	1.3261935	3464.5422
985.68018	2.9228158	1.3289355	3465.9038
986.58105	2.9275112	1.3316551	3461.7593
987.48193	2.9278498	1.335147	3457.4543
988.38281	2.93292	1.3385733	3448.2576
989.28369	2.9328628	1.341719	3446.3311
990.18457	2.9371529	1.3448226	3445.9353
991.08545	2.9397132	1.3476615	3442.47
991.98633	2.9435065	1.3498044	3434.3093
992.88721	2.9414601	1.3517759	3430.5623
993.78809	2.949198	1.3542105	3435.1917
994.68896	2.9498827	1.3570076	3435.0662
995.58984	2.9515371	1.3603683	3428.5144
996.49072	2.9582391	1.3634973	3422.1809
997.3916	2.9573798	1.3660618	3413.8142
998.29248	2.9623554	1.3687986	3416.5488
999.19336	2.9629366	1.3718927	3417.5093
1000.0942	2.9663448	1.3753269	3413.6294
1000.9951	2.9686472	1.3785496	3402.0955
1001.896	2.9743345	1.3814232	3403.1116
1002.7969	2.9772105	1.3839114	3392.2915
1003.6978	2.9790215	1.3864005	3392.5857
1004.5986	2.9802518	1.3888432	3385.8008
1005.4995	2.9806292	1.3912197	3383.4624
1006.4004	2.9849072	1.393574	3386.5251
1007.3013	2.9884427	1.3958054	3380.8999
1008.2021	2.9906425	1.3981582	3383.676
1009.103	2.9937439	1.4009314	3381.0044
1010.0039	2.9960845	1.4037267	3372.9087
1010.9048	2.9982462	1.4072033	3371.6165
1011.8057	3.0004766	1.4107848	3369.1233
1012.7065	3.0046182	1.4140406	3361.8071
1013.6074	3.0090902	1.4173076	3353.6582
1014.5083	3.0100873	1.4206625	3354.5107
1015.4092	3.0107605	1.4237684	3345.3354
1016.3101	3.0131855	1.4264723	3340.1533
1017.2109	3.0164902	1.4291844	3340.1904
1018.1118	3.0191557	1.4324675	3340.2356
1019.0127	3.0240834	1.4357095	3327.0344
1019.9136	3.0257559	1.4387809	3329.6689
1020.8145	3.0301051	1.4422613	3321.0449
1021.7153	3.031883	1.4455042	3317.3083
1022.6162	3.0335462	1.4483058	3310.8977
1023.5171	3.0353653	1.4516654	3311.2539
1024.418	3.0429914	1.4550135	3306.5784
1025.3188	3.0419507	1.4580911	3295.4824
1026.2197	3.0419121	1.4611962	3285.8076
1027.1206	3.0494869	1.4638617	3289.6902
1028.0215	3.0494134	1.4664416	3280.7417
1028.9224	3.053781	1.469282	3286.0051
1029.8232	3.0547855	1.4723158	3275.1746
1030.7241	3.0587645	1.4754223	3276.2607
1031.625	3.0621777	1.4785399	3269.9333
1032.5259	3.0633097	1.4813775	3262.2463
1033.4268	3.0664334	1.4841914	3259.6653
1034.3276	3.0677307	1.486941	3255.5322
1035.2285	3.0731642	1.4904401	3256.062
1036.1294	3.0764749	1.4937011	3248.5781
1037.0303	3.0793905	1.4972531	3248.3115
1037.9312	3.0805302	1.5013769	3234.8152
1038.832	3.0838947	1.5050188	3230.7166
1039.7329	3.0820091	1.5082738	3217.8984
1040.6338	3.0870931	1.5114335	3213.2935
1041.5347	3.0900121	1.5144972	3210.8708
1042.4355	3.0931344	1.5175313	3203.7495
1043.3364	3.0944989	1.5211107	3203.699
1044.2373	3.1004429	1.5240469	3196.8589
1045.1382	3.1040597	1.5272115	3187.7681
1046.0391	3.1035628	1.5300523	3181.7422
1046.9399	3.1082542	1.5334568	3182.553
1047.8408	3.108407	1.5373974	3170.2905
1048.7417	3.1129487	1.5410883	3165.1929
1049.6426	3.1145105	1.5442352	3152.8306
1050.5435	3.1181016	1.5477006	3148.4004
1051.4443	3.1211042	1.5506467	3143.1697
1052.3452	3.1240644	1.5536124	3141.9309
1053.2461	3.1253018	1.5571086	3131.3496
1054.147	3.1295209	1.560472	3123.8711
1055.0479	3.1311898	1.563709	3120.7207
1055.9487	3.1354053	1.5667236	3113.5483
1056.8496	3.1361935	1.5699255	3107.9849
1057.7505	3.1388052	1.5731692	3099.4473
1058.6514	3.1435997	1.5766108	3096.2021
1059.5522	3.1447721	1.5795405	3082.4702
1060.4531	3.1474268	1.5825816	3075.8411
1061.354	3.1502361	1.5858662	3077.8677
1062.2549	3.1523273	1.5895166	3064.864
1063.1558	3.1568081	1.5929725	3060.8149
1064.0566	3.1599448	1.5958179	3056.3325
1064.9575	3.1622641	1.5990695	3047.1316
1065.8584	3.1622751	1.6026191	3036.3381
1066.7593	3.1677229	1.6058841	3026.104
1067.6602	3.1676731	1.6096312	3021.3252
1068.561	3.1723711	1.6133083	3008.6909
1069.4619	3.1749895	1.6163262	3001.9131
1070.3628	3.1759739	1.6195003	2995.0791
1071.2637	3.1798379	1.6227462	2983.4304
1072.1646	3.1826379	1.6256722	2981.2727
1073.0654	3.185684	1.6296949	2978.6836
1073.9663	3.1860242	1.63442	2950.5996
1074.8672	3.1922998	1.6376116	2939.9812
1075.7681	3.1925018	1.6409516	2932.8401
1076.6689	3.1970232	1.6446254	2919.0715
1077.5698	3.2002807	1.6480801	2914.2729
1078.4707	3.2014093	1.6520482	2893.4255
1079.3716	3.2048497	1.6563269	2878.7173
1080.2725	3.2095344	1.6617888	2854.5881
1081.1733	3.2103505	1.6679339	2813.4319
1082.0742	3.2151084	1.673808	2780.7839
1082.9751	3.2180667	1.6813823	2737.1321
1083.876	3.2250097	1.6979767	2575.5708
1084.2764	3.2251461	1.7062238	2499.1262