File: datasets/am_bench_2022/raw_data/0-X.11-3/specimen.dat
MTS793|MPT|ENU|1|2|.|/|:|1|0|0|A

Operator Information						Time:	30.537842	Sec	10/13/2021 8:29:54 AM
Operator	Jake Benzing
Project	AM Bench 2022 mini-tensile challenge
Specimen ID	O-X.11-3
Material	PBF-L Inconel 625
Specimen Width	2.55	mm
Specimen Thickness	1.52	mm
Notes
Operator Information End

Data Acquisition						Time:	1031.5313	Sec	10/13/2021 8:46:35 AM
Time	Axial Displacement	Axial Extensometer	Axial Force
Sec	mm	mm	N
30.651367	-5.8417387e-05	2.6517033e-05	34.443447
31.752441	0.0064672576	0.00025749268	58.713066
32.853516	0.0054008001	0.00048677079	74.5093
33.95459	0.010045627	0.00041850112	88.949615
35.055664	0.014706436	0.00031012404	101.65006
36.156738	0.015792767	0.00059057161	114.28566
37.257813	0.019098222	0.0006516322	131.51668
38.358887	0.022547919	0.00055757596	145.13708
39.459961	0.027398303	0.00079923874	162.49442
40.561035	0.028508557	0.0010020367	175.30351
41.662109	0.0345993	0.00078658469	194.22282
42.763184	0.035311859	0.00080422167	212.14926
43.864258	0.036971271	0.00099169789	231.47502
44.965332	0.042065218	0.0011761223	252.15208
46.066406	0.047295623	0.0011352394	269.5397
47.16748	0.050615218	0.001505001	295.91086
48.268555	0.053361166	0.0015022964	321.46005
49.369629	0.055494849	0.0013640176	344.74625
50.470703	0.061977699	0.0016771043	373.48279
51.571777	0.064868711	0.0017986353	395.64569
52.672852	0.066345975	0.0019130496	431.0596
53.773926	0.068119511	0.0019237449	444.66141
54.875	0.072471499	0.0020655929	471.59229
55.976074	0.074467547	0.0023932063	499.2995
57.077148	0.077465869	0.0022384163	523.58087
58.178223	0.085976526	0.0022248209	550.98108
59.279297	0.086438559	0.0026235131	579.81219
60.380371	0.088267207	0.0025712207	606.26343
61.481445	0.094338894	0.0027118528	636.5849
62.58252	0.09723109	0.0029191596	666.41125
63.683594	0.09862189	0.003149966	697.57501
64.784668	0.10259667	0.0031391152	719.64459
65.885742	0.10567515	0.0031530764	753.10394
66.986816	0.10806992	0.0034894224	786.0318
68.087891	0.11273355	0.0036795335	813.46503
69.188965	0.11622812	0.0037334156	845.68268
70.290039	0.11929984	0.0039167861	873.57147
71.391113	0.12173989	0.0041721966	906.81213
72.492188	0.12476628	0.0042649582	937.83319
73.593262	0.1283426	0.0044127563	964.6709
74.694336	0.13193798	0.0044729318	994.3844
75.79541	0.13781564	0.0046115313	1026.2577
76.896484	0.13785353	0.0048282915	1053.3275
77.997559	0.14334963	0.0049173762	1084.6844
79.098633	0.14517993	0.0049374513	1108.9679
80.199707	0.14969116	0.0052198246	1149.8396
81.300781	0.15336338	0.0055245347	1191.3712
82.401855	0.15514223	0.0055375695	1215.7211
83.50293	0.15612443	0.0058341995	1244.4215
84.604004	0.16171221	0.005758862	1274.6173
85.705078	0.16651149	0.0060630431	1312.0721
86.806152	0.16659324	0.0062594949	1330.8032
87.907227	0.16936372	0.0061522652	1357.4353
89.008301	0.17526458	0.0066020112	1394.0132
90.109375	0.17605868	0.0066551846	1423.8811
91.210449	0.18050189	0.0067146807	1457.4285
92.311523	0.18349572	0.007036671	1487.9979
93.412598	0.19032018	0.0071753347	1529.0326
94.513672	0.1909748	0.0073729791	1549.9814
95.614746	0.19762874	0.0074838893	1584.1091
96.71582	0.20192058	0.0075948532	1615.9065
97.816895	0.20094755	0.0079450067	1643.2651
98.917969	0.20483859	0.0079754619	1676.7926
100.01904	0.20746934	0.008169922	1705.8542
101.12012	0.21053958	0.0083097098	1728.7123
102.22119	0.21279871	0.008554453	1759.6715
103.32227	0.21788323	0.0087376321	1791.9063
104.42334	0.22064675	0.0089202486	1820.8013
105.52441	0.2229757	0.0090506151	1848.3439
106.62549	0.22715302	0.0091651399	1872.3296
107.72656	0.22880217	0.0092595033	1891.8088
108.82764	0.23524138	0.0095472159	1916.7122
109.92871	0.24094878	0.0097356439	1957.3584
111.02979	0.24271433	0.0099679995	1981.6868
112.13086	0.24685343	0.010004798	2003.3004
113.23193	0.24565589	0.010303443	2027.7402
114.33301	0.25026995	0.010434843	2052.7292
115.43408	0.25623164	0.010762828	2070.6099
116.53516	0.25906935	0.01092201	2103.1191
117.63623	0.2599493	0.011070473	2114.6548
118.7373	0.26590502	0.011325596	2140.2029
119.83838	0.26554891	0.011481779	2160.4336
120.93945	0.2702634	0.0117437	2183.6201
122.04053	0.27177796	0.012054118	2203.1599
123.1416	0.27986941	0.01226828	2229.3455
124.24268	0.27872878	0.012575195	2242.2239
125.34375	0.28662995	0.012847427	2260.4485
126.44482	0.28768632	0.012971131	2277.1094
127.5459	0.29267085	0.013550924	2301.0251
128.64697	0.29469967	0.013769819	2319.4277
129.74805	0.29616833	0.014159381	2327.459
130.84912	0.30033326	0.014509033	2343.1775
131.9502	0.30527538	0.014666563	2346.8301
133.05127	0.30725768	0.015281971	2372.5854
134.15234	0.31036624	0.015655963	2389.2842
135.25342	0.31535244	0.016294682	2401.2803
136.35449	0.31815651	0.01681646	2420.7761
137.45557	0.32215169	0.017305061	2422.8735
138.55664	0.32660371	0.018071497	2443.5476
139.65771	0.32725501	0.018651921	2445.0542
140.75879	0.33108497	0.019193685	2454.1113
141.85986	0.33210963	0.019796036	2467.3601
142.96094	0.33547232	0.020685742	2476.8687
144.06201	0.34114686	0.021452155	2482.9392
145.16309	0.34280834	0.022287875	2495.3367
146.26416	0.34882388	0.023147449	2509.2329
147.36523	0.34934327	0.023948444	2508.0793
148.46631	0.35434476	0.025021102	2516.1509
149.56738	0.35632935	0.026047705	2525.0835
150.66846	0.36059779	0.026948579	2523.2849
151.76953	0.36370596	0.027915826	2534.4001
152.87061	0.36829114	0.028827379	2546.8274
153.97168	0.37131262	0.02976938	2545.7056
155.07275	0.37756479	0.030954717	2555.1768
156.17383	0.37550896	0.031869613	2555.5039
157.2749	0.37915331	0.033074412	2557.7957
158.37598	0.38349369	0.034387942	2569.9717
159.47705	0.38794202	0.035692938	2572.3052
160.57813	0.38969609	0.037151434	2575.0068
161.6792	0.39533192	0.038398653	2576.5549
162.78027	0.3996858	0.039897762	2583.825
163.88135	0.40000421	0.041192245	2585.3645
164.98242	0.40731096	0.042580344	2590.5168
166.0835	0.40790921	0.043766402	2584.8691
167.18457	0.40831429	0.045108892	2596.2874
168.28564	0.41235203	0.046391882	2596.9109
169.38672	0.41548276	0.047981933	2601.5833
170.48779	0.41940287	0.049499698	2609.4958
171.58887	0.42330375	0.05138031	2613.1597
172.68994	0.4267897	0.052472804	2610.7581
173.79102	0.42958114	0.053871028	2608.2119
174.89209	0.43502724	0.055568732	2622.5701
175.99316	0.43913791	0.056964908	2625.4727
177.09424	0.44006321	0.058650136	2625.0815
178.19531	0.44381946	0.059837569	2619.8333
179.29639	0.44827494	0.061436009	2627.603
180.39746	0.44922584	0.063376509	2625.1431
181.49854	0.45678216	0.064815395	2630.0959
182.59961	0.45582634	0.066311039	2629.6616
183.70068	0.46045005	0.067830332	2638.3599
184.80176	0.46510345	0.069636367	2632.9216
185.90283	0.46853516	0.071221493	2640.5525
187.00391	0.47014767	0.072706163	2640.2922
188.10498	0.4706859	0.074257985	2640.0989
189.20605	0.47547451	0.075868197	2639.021
190.30713	0.48047072	0.077446632	2643.1123
191.4082	0.48311996	0.079229847	2650.876
192.50928	0.48520017	0.080860011	2646.5642
193.61035	0.49092498	0.082619846	2649.8921
194.71143	0.4897784	0.08429864	2650.5457
195.8125	0.49834767	0.085773386	2648.7842
196.91357	0.49754947	0.0872861	2649.2097
198.01465	0.50135094	0.088831507	2647.8774
199.11572	0.5035252	0.090445273	2653.8059
200.2168	0.50987905	0.091974996	2665.5027
201.31787	0.51288801	0.094012745	2662.6575
202.41895	0.51620066	0.09595158	2664.4058
203.52002	0.52135831	0.097715124	2661.1008
204.62109	0.52301913	0.099610016	2670.613
205.72217	0.52589577	0.10137487	2668.9937
206.82324	0.53038716	0.10336138	2668.1077
207.92432	0.5316968	0.10506179	2662.9153
209.02539	0.53695017	0.10671318	2664.1494
210.12646	0.54027039	0.10864342	2676.6172
211.22754	0.53963357	0.11049066	2670.3486
212.32861	0.54512107	0.11274427	2674.5579
213.42969	0.54830956	0.11480308	2675.7852
214.53076	0.55530953	0.11629061	2671.6008
215.63184	0.55677062	0.11799636	2678.6741
216.73291	0.55938768	0.11951832	2678.645
217.83398	0.56376964	0.12105118	2681.8127
218.93506	0.56493753	0.12266356	2676.9783
220.03613	0.56844747	0.12438021	2683.8398
221.13721	0.57210755	0.1260159	2677.5281
222.23828	0.57517558	0.1277452	2685.6265
223.33936	0.57783771	0.12970001	2680.1733
224.44043	0.58341968	0.131383	2693.2971
225.5415	0.58306909	0.13346176	2686.1338
226.64258	0.59151894	0.13525118	2687.0164
227.74365	0.59198958	0.13661894	2685.145
228.84473	0.59519774	0.13850343	2689.188
229.9458	0.60035902	0.14050671	2691.8843
231.04688	0.60147506	0.14231674	2698.3291
232.14795	0.60639322	0.14422946	2695.7681
233.24902	0.60713434	0.14592499	2700.0144
234.3501	0.6149078	0.14752397	2697.9697
235.45117	0.61462092	0.14917377	2704.2532
236.55225	0.62006235	0.15121421	2702.491
237.65332	0.61894822	0.15314148	2696.396
238.75439	0.62706363	0.15478653	2706.5171
239.85547	0.62862366	0.15695523	2709.3352
240.95654	0.63462669	0.15890279	2712.46
242.05762	0.63379568	0.16067283	2701.0278
243.15869	0.63994598	0.16274084	2711.7434
244.25977	0.64041805	0.16462061	2704.8862
245.36084	0.64491373	0.16658063	2707.9351
246.46191	0.64856571	0.16841383	2710.6296
247.56299	0.65061474	0.17020336	2709.9475
248.66406	0.65522391	0.17224081	2710.3318
249.76514	0.65814936	0.17390923	2716.0088
250.86621	0.66469449	0.17601041	2721.6978
251.96729	0.66722423	0.17795801	2712.4443
253.06836	0.66728222	0.17972173	2721.2649
254.16943	0.67151093	0.18172754	2722.2773
255.27051	0.6745277	0.18422771	2725.5618
256.37158	0.68056041	0.18626118	2723.2251
257.47266	0.68521208	0.18808852	2717.8555
258.57373	0.68385035	0.18971649	2719.8635
259.6748	0.68711752	0.19160159	2726.9355
260.77588	0.69256979	0.19337402	2719.324
261.87695	0.69617504	0.19532764	2727.5291
262.97803	0.69955021	0.19715983	2730.8718
264.0791	0.70143187	0.19893163	2726.5457
265.18018	0.70280403	0.2007734	2731.8945
266.28125	0.70728612	0.20265143	2729.2117
267.38232	0.70924199	0.20452413	2725.6621
268.4834	0.713485	0.20614159	2728.5237
269.58447	0.72204775	0.2076315	2736.0461
270.68555	0.72352499	0.20936868	2728.8604
271.78662	0.72451502	0.21131308	2736.9897
272.8877	0.72919655	0.21352506	2738.5603
273.98877	0.73148245	0.21568598	2739.5764
275.08984	0.73653519	0.21773121	2735.1672
276.19092	0.73779613	0.2198648	2738.8457
277.29199	0.74185169	0.22169949	2744.5693
278.39307	0.74432874	0.22375838	2738.241
279.49414	0.74596685	0.22583906	2741.1062
280.59521	0.75226164	0.22744051	2752.1409
281.69629	0.75520468	0.22982903	2750.2009
282.79736	0.75943172	0.2317896	2748.1748
283.89844	0.75964606	0.23376487	2747.1287
284.99951	0.76306093	0.23566496	2739.9387
286.10059	0.76503628	0.23755857	2744.95
287.20166	0.76790041	0.23979847	2753.363
288.30273	0.77323264	0.24161932	2747.9929
289.40381	0.77830607	0.2433162	2749.561
290.50488	0.77961636	0.24551764	2757.978
291.60596	0.78276628	0.24737673	2754.666
292.70703	0.78816158	0.24960952	2760.5232
293.80811	0.79120588	0.25158054	2755.6021
294.90918	0.79363662	0.2534757	2756.6506
296.01025	0.79891193	0.25517732	2759.7012
297.11133	0.80071652	0.25680301	2758.0376
298.2124	0.80418104	0.2586228	2764.4163
299.31348	0.81012386	0.26041272	2758.6052
300.41455	0.81138718	0.26245666	2767.4712
301.51563	0.81530666	0.2646654	2763.1772
302.6167	0.81759959	0.26655695	2759.7051
303.71777	0.82075489	0.26828766	2756.4226
304.81885	0.82489181	0.26989791	2769.5906
305.91992	0.82525504	0.27192992	2769.157
307.021	0.83148348	0.27422142	2769.2395
308.12207	0.8328712	0.27596563	2762.05
309.22314	0.83828634	0.27775323	2774.2324
310.32422	0.83682454	0.27971569	2770.2598
311.42529	0.84431177	0.28173843	2766.6174
312.52637	0.84867507	0.28337651	2776.489
313.62744	0.84824353	0.28527093	2773.7141
314.72852	0.85245341	0.28713351	2775.3157
315.82959	0.85593504	0.28914434	2779.825
316.93066	0.8577168	0.29112923	2772.7358
318.03174	0.86055779	0.29298639	2775.6997
319.13281	0.8635928	0.29486492	2779.3311
320.23389	0.87206167	0.29683807	2782.2898
321.33496	0.87756246	0.29866558	2782.4304
322.43604	0.875009	0.30083328	2784.6021
323.53711	0.88221467	0.30264109	2780.8511
324.63818	0.88533765	0.30459321	2787.3535
325.73926	0.88674051	0.30671906	2782.7578
326.84033	0.88538826	0.30863842	2780.9319
327.94141	0.89376736	0.31039968	2786.707
329.04248	0.89464444	0.31227565	2783.8396
330.14355	0.90012139	0.31428835	2791.7368
331.24463	0.9017908	0.31601197	2786.2139
332.3457	0.90839368	0.31790954	2790.7305
333.44678	0.90918911	0.3197636	2784.2739
334.54785	0.9151575	0.32177594	2794.325
335.64893	0.91594738	0.32393178	2794.9121
336.75	0.92104888	0.32593998	2797.6572
337.85107	0.92152584	0.32788834	2792.6145
338.95215	0.92513335	0.33002925	2798.8416
340.05322	0.92905265	0.33207196	2799.0947
341.1543	0.93139368	0.33404243	2789.7927
342.25537	0.93394315	0.33580273	2800.7686
343.35645	0.93920165	0.33806434	2804.1375
344.45752	0.94171494	0.34003511	2791.3403
345.55859	0.94716132	0.34205192	2807.5098
346.65967	0.94758379	0.34429756	2799.6184
347.76074	0.95323527	0.34647167	2806.2876
348.86182	0.95576996	0.34862107	2806.4236
349.96289	0.95790327	0.35066381	2801.0581
351.06396	0.96191061	0.35253051	2804.9333
352.16504	0.96539521	0.35443887	2804.167
353.26611	0.96973002	0.35627002	2805.543
354.36719	0.97198725	0.35778838	2810.2729
355.46826	0.97658068	0.35958311	2806.9854
356.56934	0.98017609	0.36161363	2812.8501
357.67041	0.9819389	0.36365756	2814.5422
358.77148	0.98582071	0.36562121	2814.5051
359.87256	0.98946857	0.36743432	2813.7158
360.97363	0.99340612	0.3691844	2813.3362
362.07471	0.99530953	0.37142137	2816.043
363.17578	0.9989143	0.37359324	2821.2881
364.27686	1.0004386	0.37585157	2819.949
365.37793	1.0043304	0.37746069	2810.0627
366.479	1.0087123	0.37917918	2819.4119
367.58008	1.0122962	0.38116443	2822.7727
368.68115	1.0144285	0.38290676	2813.2319
369.78223	1.0186105	0.38491148	2819.0291
370.8833	1.0230544	0.38703433	2824.2144
371.98438	1.0254556	0.3888247	2820.9438
373.08545	1.0266312	0.39076921	2819.3733
374.18652	1.0316467	0.3928484	2827.0981
375.2876	1.0360959	0.39518452	2832.2261
376.38867	1.0347791	0.39703983	2826.532
377.48975	1.0435481	0.39908591	2830.8945
378.59082	1.044053	0.4012737	2832.8435
379.69189	1.0463538	0.40309727	2822.4917
380.79297	1.0519024	0.4051441	2830.2434
381.89404	1.0556662	0.40713331	2833.9895
382.99512	1.0572857	0.40916088	2831.3293
384.09619	1.0644295	0.41115361	2836.0698
385.19727	1.0647314	0.41322616	2839.8928
386.29834	1.0680958	0.41534889	2834.3152
387.39941	1.0721372	0.41712344	2827.6917
388.50049	1.0728326	0.41905734	2834.9844
389.60156	1.0758132	0.42092639	2832.8652
390.70264	1.0823171	0.42297882	2840.8828
391.80371	1.0827949	0.42507389	2837.6863
392.90479	1.0873566	0.42678255	2839.2986
394.00586	1.093076	0.4286457	2844.7913
395.10693	1.0973523	0.4311702	2848.5798
396.20801	1.0991995	0.43296009	2839.9548
397.30908	1.1004707	0.43459991	2835.2285
398.41016	1.1052579	0.43637165	2843.3213
399.51123	1.1076168	0.43819502	2842.7529
400.6123	1.1108276	0.44034693	2846.084
401.71338	1.1140269	0.44234878	2853.0889
402.81445	1.1170386	0.44453561	2848.2776
403.91553	1.120628	0.44646427	2850.9822
405.0166	1.1244627	0.44844234	2850.0437
406.11768	1.1276567	0.4508011	2850.7488
407.21875	1.1315416	0.45266217	2845.9849
408.31982	1.1356087	0.45434013	2851.3
409.4209	1.1387693	0.45623735	2852.876
410.52197	1.1409805	0.45819181	2853.6392
411.62305	1.1442207	0.46006525	2854.9688
412.72412	1.1478251	0.46197438	2860.1565
413.8252	1.1503626	0.4641467	2854.8225
414.92627	1.1550069	0.46612537	2860.4946
416.02734	1.1566374	0.46822831	2859.1968
417.12842	1.1588621	0.47044593	2853.7986
418.22949	1.1613066	0.4723343	2852.7083
419.33057	1.1661539	0.4744871	2861.5525
420.43164	1.1707661	0.47644255	2861.262
421.53271	1.1734929	0.47905532	2868.97
422.63379	1.1781737	0.48110417	2858.8259
423.73486	1.1794485	0.48279917	2858.0273
424.83594	1.1832303	0.48445368	2861.5837
425.93701	1.1872004	0.48601636	2865.1309
427.03809	1.1885486	0.48785686	2862.0918
428.13916	1.1944572	0.49047494	2872.8772
429.24023	1.1950073	0.49225742	2858.6453
430.34131	1.2022381	0.49407598	2869.9038
431.44238	1.2025665	0.4957113	2863.4075
432.54346	1.207159	0.49771553	2875.7935
433.64453	1.2094016	0.50010985	2877.3003
434.74561	1.2113521	0.50199777	2871.3186
435.84668	1.2182837	0.50405115	2869.6328
436.94775	1.2203473	0.50630718	2873.3843
438.04883	1.2253722	0.50841624	2875.0039
439.1499	1.2251741	0.51031727	2872.6553
440.25098	1.2316706	0.51193178	2880.0073
441.35205	1.2366754	0.51420432	2880.0769
442.45313	1.235254	0.51632053	2873.2998
443.5542	1.2422069	0.51798826	2878.6572
444.65527	1.2437991	0.52020985	2882.0098
445.75635	1.2477927	0.52244222	2880.5969
446.85742	1.2497796	0.52475828	2879.5444
447.9585	1.2537991	0.52663541	2880.7361
449.05957	1.2561535	0.52824438	2878.2561
450.16064	1.26077	0.53034323	2881.0117
451.26172	1.2608092	0.53229731	2877.6804
452.36279	1.2671131	0.53428835	2887.446
453.46387	1.270673	0.53628427	2886.8315
454.56494	1.2731264	0.53841245	2889.7649
455.66602	1.2748092	0.54072201	2887.2559
456.76709	1.2791672	0.54290181	2893.9336
457.86816	1.2835776	0.54495651	2882.5796
458.96924	1.2872686	0.54672116	2885.0771
460.07031	1.2856156	0.54868227	2882.5889
461.17139	1.2902541	0.55044144	2894.5024
462.27246	1.2973285	0.55232513	2898.2927
463.37354	1.2993693	0.55424333	2889.5112
464.47461	1.3054318	0.55643791	2895.6069
465.57568	1.3072432	0.55845273	2893.3857
466.67676	1.3072191	0.56039065	2889.2339
467.77783	1.3103752	0.56217581	2893.4624
468.87891	1.3158067	0.56442434	2900.4355
469.97998	1.3177458	0.56670815	2896.8796
471.08105	1.3238556	0.56858391	2899.3137
472.18213	1.3253976	0.57017785	2895.3635
473.2832	1.3278458	0.5719285	2899.0242
474.38428	1.3312207	0.57356542	2891.9138
475.48535	1.3341869	0.57508951	2897.0215
476.58643	1.3389759	0.57694495	2901.011
477.6875	1.3447862	0.57916224	2908.8772
478.78857	1.346308	0.5812583	2907.1584
479.88965	1.3489764	0.58319801	2907.7336
480.99072	1.3532199	0.58546555	2903.3777
482.0918	1.3541336	0.58725774	2908.7336
483.19287	1.3578717	0.58952576	2902.6929
484.29395	1.3638314	0.59144789	2910.8972
485.39502	1.3644155	0.5936864	2906.1687
486.49609	1.3681298	0.59539241	2899.2158
487.59717	1.3725784	0.59733152	2911.2925
488.69824	1.3745742	0.59907186	2907.1514
489.79932	1.3789397	0.60085773	2909.5969
490.90039	1.3817928	0.60316586	2914.0547
492.00146	1.3880093	0.60546225	2914.927
493.10254	1.3888235	0.60747141	2917.8586
494.20361	1.3910738	0.60959339	2908.7319
495.30469	1.3952264	0.6113866	2907.7239
496.40576	1.3980913	0.61332506	2916.5491
497.50684	1.4024721	0.61505461	2908.5383
498.60791	1.4010279	0.61708909	2911.084
499.70898	1.4092031	0.6194213	2920.8984
500.81006	1.4145916	0.62127388	2921.4976
501.91113	1.417225	0.62337011	2924.4807
503.01221	1.4177427	0.62537706	2919.1594
504.11328	1.4207051	0.62737483	2915.9363
505.21436	1.4258231	0.62928963	2922.5784
506.31543	1.4302578	0.63130075	2921.6626
507.4165	1.4290702	0.63327307	2919.2537
508.51758	1.4342418	0.63477951	2920.833
509.61865	1.4394081	0.63675332	2920.0999
510.71973	1.4379758	0.63849211	2921.2678
511.8208	1.4436202	0.64034283	2921.4385
512.92188	1.449571	0.64251518	2926.9856
514.02295	1.4481913	0.64454746	2925.5027
515.12402	1.4545829	0.64669955	2926.5398
516.2251	1.458097	0.64873821	2924.0955
517.32617	1.4613599	0.65052944	2923.9324
518.42725	1.4656149	0.65263349	2927.9363
519.52832	1.4674067	0.6546579	2932.8042
520.62939	1.4702444	0.65685749	2922.8281
521.73047	1.4745815	0.65907443	2930.9976
522.83154	1.4771912	0.66112119	2936.272
523.93262	1.4796748	0.66347706	2930.0115
525.03369	1.4851233	0.66566962	2925.8376
526.13477	1.4883435	0.66751099	2929.6726
527.23584	1.4889812	0.66948748	2933.5222
528.33691	1.4954617	0.67176169	2940.3386
529.43799	1.4973038	0.67367065	2941.9707
530.53906	1.5023261	0.67586362	2943.9944
531.64014	1.5070568	0.67797416	2939.9324
532.74121	1.5110236	0.67980707	2934.7981
533.84229	1.5112797	0.68161839	2942.5718
534.94336	1.5143688	0.68315893	2933.1187
536.04443	1.5181509	0.68490279	2938.3386
537.14551	1.5198848	0.68715364	2947.6228
538.24658	1.5239964	0.68932891	2947.688
539.34766	1.5270942	0.69139171	2947.625
540.44873	1.5310686	0.6934436	2944.1868
541.5498	1.5341287	0.69544256	2948.2329
542.65088	1.5358884	0.69781137	2945.5518
543.75195	1.5397885	0.69973499	2941.5444
544.85303	1.542281	0.70156389	2942.1899
545.9541	1.5484369	0.70352274	2941.6704
547.05518	1.5503628	0.70485163	2943.8633
548.15625	1.5518138	0.7064513	2943.4675
549.25732	1.5581107	0.70867592	2950.821
550.3584	1.5613807	0.71059364	2951.1448
551.45947	1.5661019	0.71292859	2956.0886
552.56055	1.5669283	0.71522081	2952.1353
553.66162	1.5734615	0.71712029	2949.6123
554.7627	1.5722077	0.71893102	2944.9778
555.86377	1.5764724	0.72126609	2957.5244
556.96484	1.576679	0.72344548	2948.7722
558.06592	1.5844039	0.72498959	2945.4929
559.16699	1.5883393	0.72688866	2958.2778
560.26807	1.5915936	0.72899932	2958.4067
561.36914	1.5933474	0.73086965	2960.5403
562.47021	1.5962893	0.73260671	2955.0837
563.57129	1.5987086	0.73488474	2954.7004
564.67236	1.6028332	0.73714882	2955.429
565.77344	1.6057172	0.73944587	2960.7224
566.87451	1.609333	0.74147809	2959.219
567.97559	1.6127644	0.74393737	2962.7036
569.07666	1.6171604	0.74618661	2958.1357
570.17773	1.6193367	0.74797702	2954.77
571.27881	1.6231635	0.74993587	2966.6392
572.37988	1.6243587	0.7523101	2960.1555
573.48096	1.6291473	0.75450426	2962.2505
574.58203	1.6320761	0.75617909	2962.2317
575.68311	1.6351424	0.75845075	2964.2578
576.78418	1.6406603	0.76026094	2960.3723
577.88525	1.6430181	0.76204932	2966.7034
578.98633	1.6459938	0.763798	2962.6475
580.0874	1.6502432	0.76542419	2964.3835
581.18848	1.6521046	0.76720726	2962.4255
582.28955	1.6519915	0.76916218	2964.0439
583.39063	1.6586806	0.77077943	2958.6074
584.4917	1.6624502	0.77261478	2966.2305
585.59277	1.665861	0.77518654	2976.8008
586.69385	1.6708871	0.77758873	2976.3801
587.79492	1.6713241	0.7797389	2969.8203
588.896	1.6734843	0.78151166	2964.9478
589.99707	1.6785555	0.7837109	2971.6167
591.09814	1.6846845	0.78568244	2970.1064
592.19922	1.6854846	0.78765845	2971.6436
593.30029	1.6899824	0.78958803	2969.5623
594.40137	1.6930552	0.79185808	2976.3867
595.50244	1.6961163	0.79349893	2973.7539
596.60352	1.7005509	0.79571187	2977.4563
597.70459	1.702171	0.79758304	2976.6812
598.80566	1.7048936	0.79989743	2980.2664
599.90674	1.7087735	0.80193394	2983.2397
601.00781	1.7119426	0.80392814	2974.5718
602.10889	1.7173507	0.80581808	2975.3879
603.20996	1.7189069	0.807841	2983.8135
604.31104	1.7220528	0.80963314	2972.3206
605.41211	1.7253621	0.81169909	2982.7288
606.51318	1.7293712	0.81379974	2980.4045
607.61426	1.7331555	0.81562877	2976.1814
608.71533	1.7351829	0.81737733	2977.5647
609.81641	1.7387079	0.81942368	2977.2522
610.91748	1.7408553	0.82154375	2985.2976
612.01855	1.7478076	0.82428837	2990.2937
613.11963	1.7496334	0.82630748	2985.8606
614.2207	1.7524068	0.82823342	2983.1648
615.32178	1.7561196	0.83014804	2979.0005
616.42285	1.7594372	0.83184946	2986.3462
617.52393	1.7611703	0.83376497	2977.1262
618.625	1.7627504	0.83596885	2990.6094
619.72607	1.7684319	0.8379063	2983.5059
620.82715	1.7732526	0.83995759	2991.9243
621.92822	1.7725972	0.84178758	2985.2395
623.0293	1.7783147	0.84366411	2984.1616
624.13037	1.7819163	0.84541374	2980.5708
625.23145	1.7864501	0.84723896	2987.8806
626.33252	1.7895435	0.84949332	2992.1321
627.43359	1.7918663	0.85164493	2987.9158
628.53467	1.7929031	0.85360509	2988.7749
629.63574	1.7989503	0.85556084	2986.3955
630.73682	1.7989734	0.85748708	2993.2437
631.83789	1.805398	0.8594653	2994.126
632.93896	1.8079799	0.86181468	2997.6421
634.04004	1.8138132	0.8638379	2997.6934
635.14111	1.8149214	0.86616677	2991.5044
636.24219	1.8180016	0.86842501	2996.613
637.34326	1.8199981	0.87042189	2992.5349
638.44434	1.8267759	0.87244165	2994.0979
639.54541	1.8239771	0.8746202	2991.9238
640.64648	1.8324746	0.87689966	3003.5959
641.74756	1.8345054	0.87867415	2989.6555
642.84863	1.8360151	0.88067943	2993.4036
643.94971	1.8409314	0.88228869	2992.0273
645.05078	1.845081	0.88430196	2999.1406
646.15186	1.8465322	0.88638735	3003.8091
647.25293	1.8489676	0.88834697	2995.9333
648.354	1.8539796	0.8903327	3000.1382
649.45508	1.8549603	0.8924188	3001.167
650.55615	1.8575616	0.89452559	2996.1895
651.65723	1.862231	0.89618254	2995.1748
652.7583	1.8686568	0.89834493	3005.9924
653.85938	1.8695652	0.90035856	3000.0164
654.96045	1.8758347	0.90228516	3002.2749
656.06152	1.8773063	0.90460324	3007.8083
657.1626	1.8807073	0.9065457	3002.2952
658.26367	1.8828799	0.9089424	3000.1165
659.36475	1.8884975	0.91082674	3006.2708
660.46582	1.8917323	0.91266429	3009.7075
661.56689	1.8953482	0.91512907	3007.5959
662.66797	1.8962772	0.91728175	3013.7024
663.76904	1.9002557	0.91955763	3013.2876
664.87012	1.9050668	0.92203963	3008.9045
665.97119	1.906532	0.9238053	3003.5161
667.07227	1.9111744	0.92562854	3003.03
668.17334	1.9107747	0.92787266	3003.6411
669.27441	1.915499	0.92985737	3004.4661
670.37549	1.920568	0.9317497	3005.4634
671.47656	1.9239459	0.93367678	3013.481
672.57764	1.9282507	0.935893	3013.2859
673.67871	1.9329293	0.93831128	3015.8381
674.77979	1.9330182	0.94057709	3014.9758
675.88086	1.9344823	0.94270313	3009.0842
676.98193	1.9419746	0.94484103	3013.2417
678.08301	1.9454844	0.94692808	3012.4419
679.18408	1.944146	0.94872802	3006.6509
680.28516	1.9480631	0.95092845	3010.147
681.38623	1.9538001	0.95305711	3021.6584
682.4873	1.956288	0.9551205	3015.3518
683.58838	1.9578251	0.95695746	3012.1743
684.68945	1.9646059	0.95877987	3017.677
685.79053	1.9651392	0.96105093	3018.7346
686.8916	1.9675174	0.96314466	3015.7454
687.99268	1.9718007	0.9652968	3021.4941
689.09375	1.9754649	0.96729088	3013.3787
690.19482	1.9788226	0.96918595	3015.8894
691.2959	1.9819565	0.97108436	3015.1277
692.39697	1.9882041	0.9736315	3025.6965
693.49805	1.9918479	0.97543937	3016.4106
694.59912	1.9923685	0.97752738	3021.2952
695.7002	1.9947163	0.97933698	3016.6064
696.80127	2.0021763	0.98141915	3018.3103
697.90234	2.0014491	0.98338169	3019.7173
699.00342	2.0054581	0.98531574	3020.0925
700.10449	2.0067351	0.98760492	3021.2437
701.20557	2.0114515	0.98966706	3015.0005
702.30664	2.0142565	0.99123889	3015.0894
703.40771	2.018703	0.99329597	3026.2097
704.50879	2.0225546	0.99546409	3025.7671
705.60986	2.0250885	0.9975245	3018.9746
706.71094	2.0274882	0.99968857	3023.47
707.81201	2.0313914	1.001743	3023.6265
708.91309	2.0377135	1.0041604	3024.9753
710.01416	2.0392752	1.0063058	3027.0208
711.11523	2.0434625	1.0089077	3025.6892
712.21631	2.0460293	1.01125	3025.4758
713.31738	2.0506253	1.0132389	3024.9712
714.41846	2.0521932	1.0153418	3017.0659
715.51953	2.0572677	1.0174696	3032.2622
716.62061	2.0608695	1.01968	3025.8452
717.72168	2.0628228	1.0215212	3022.4641
718.82275	2.0658324	1.0233734	3030.1211
719.92383	2.0683258	1.0257444	3034.9363
721.0249	2.0737903	1.0279182	3030.4226
722.12598	2.076009	1.0298911	3026.6929
723.22705	2.0782359	1.0316526	3030.6396
724.32813	2.0817394	1.0337359	3024.8845
725.4292	2.0858073	1.0356156	3028.9409
726.53027	2.0902467	1.0375618	3032.2217
727.63135	2.0917675	1.0399348	3034.45
728.73242	2.0967567	1.0420253	3035.0117
729.8335	2.0969977	1.0440475	3032.3408
730.93457	2.0985489	1.0464792	3030.8447
732.03564	2.1056931	1.0487618	3033.8203
733.13672	2.1060174	1.0511041	3028.137
734.23779	2.1141443	1.0530219	3030.0332
735.33887	2.1133828	1.0549053	3029.7617
736.43994	2.1188607	1.0571474	3037.8503
737.54102	2.1211922	1.0591612	3037.4255
738.64209	2.1237714	1.0615001	3031.9644
739.74316	2.1281815	1.0635223	3033.6309
740.84424	2.1316626	1.0654881	3033.4875
741.94531	2.1375682	1.0679594	3045.3125
743.04639	2.1359174	1.0702752	3039.0867
744.14746	2.1431103	1.0724711	3035.2983
745.24854	2.1454623	1.0744429	3033.8491
746.34961	2.1481249	1.0766165	3041.0181
747.45068	2.1521983	1.0790137	3036.321
748.55176	2.155817	1.0810276	3043.426
749.65283	2.1586795	1.0832661	3036.4495
750.75391	2.1613421	1.0858519	3052.7183
751.85498	2.1649177	1.0881203	3034.6455
752.95605	2.16433	1.0899857	3032.2012
754.05713	2.1731422	1.0919031	3043.3958
755.1582	2.1752567	1.0940869	3043.1042
756.25928	2.1781423	1.0961868	3033.4929
757.36035	2.1831503	1.0982413	3038.4336
758.46143	2.1862934	1.1005516	3045.5522
759.5625	2.1883838	1.1025738	3040.6421
760.66357	2.194438	1.1045836	3039.074
761.76465	2.1954226	1.1063824	3043.4612
762.86572	2.1973426	1.1083887	3041.8752
763.9668	2.2013791	1.1104355	3043.2834
765.06787	2.203176	1.1127487	3045.6636
766.16895	2.2090878	1.1147927	3039.9248
767.27002	2.210639	1.117154	3045.24
768.37109	2.2151501	1.1193879	3040.3628
769.47217	2.2182112	1.1217126	3047.697
770.57324	2.2180963	1.1236521	3044.2864
771.67432	2.2245817	1.1257079	3044.3794
772.77539	2.226131	1.1282231	3045.7144
773.87646	2.2315755	1.1305926	3044.8584
774.97754	2.234946	1.1328458	3047.2908
776.07861	2.2378933	1.1347398	3046.4297
777.17969	2.2405844	1.1370556	3041.7124
778.28076	2.2454197	1.13893	3048.1489
779.38184	2.2474973	1.1410043	3050.3525
780.48291	2.2532332	1.1435637	3053.897
781.58398	2.2518356	1.1460513	3048.239
782.68506	2.2595181	1.1483047	3047.4282
783.78613	2.2599437	1.1504155	3055.1152
784.88721	2.2633862	1.1526444	3049.2747
785.98828	2.2655756	1.1547452	3045.3022
787.08936	2.2705808	1.1570578	3051.9597
788.19043	2.274451	1.1593626	3046.9458
789.2915	2.2776532	1.1617541	3055.6677
790.39258	2.2795563	1.1640528	3053.9983
791.49365	2.284523	1.166209	3046.9685
792.59473	2.2878108	1.168228	3045.7637
793.6958	2.2909725	1.1703218	3049.9148
794.79688	2.291647	1.1724442	3045.1663
795.89795	2.2977915	1.1750072	3058.5664
796.99902	2.3004434	1.1768993	3043.7686
798.1001	2.3013012	1.1788306	3045.0095
799.20117	2.3057063	1.1810175	3051.803
800.30225	2.3088281	1.1832266	3053.1145
801.40332	2.3125677	1.185184	3046.991
802.50439	2.3152409	1.1876757	3055.843
803.60547	2.3165371	1.1899159	3049.7578
804.70654	2.3238933	1.1920342	3049.4028
805.80762	2.3289239	1.1939638	3054.9014
806.90869	2.3300281	1.1960593	3047.8662
808.00977	2.3315182	1.1984775	3052.2817
809.11084	2.3350053	1.2007626	3048.1892
810.21191	2.3390114	1.203247	3050.0991
811.31299	2.3430164	1.2055644	3053.9309
812.41406	2.3458338	1.207888	3054.6895
813.51514	2.3500621	1.21076	3061.5688
814.61621	2.3517635	1.2127866	3047.2029
815.71729	2.3551233	1.215027	3049.1563
816.81836	2.3593609	1.2170128	3056.8374
817.91943	2.3662875	1.2190138	3062.2693
819.02051	2.3652551	1.2212212	3052.489
820.12158	2.3685539	1.2236534	3058.2534
821.22266	2.3743811	1.2259209	3063.8914
822.32373	2.375654	1.2282165	3057.3896
823.4248	2.3793168	1.2304345	3054.7368
824.52588	2.3815289	1.2329149	3066.6008
825.62695	2.3904085	1.235309	3064.7273
826.72803	2.3875167	1.2374862	3055.0933
827.8291	2.3928363	1.2398034	3061.3962
828.93018	2.3980193	1.2420062	3061.8838
830.03125	2.4014552	1.2442079	3055.1909
831.13232	2.4022989	1.2467052	3061.6147
832.2334	2.4071085	1.2489339	3056.6824
833.33447	2.4110701	1.2512517	3060.4211
834.43555	2.4145784	1.2532927	3059.3208
835.53662	2.4165404	1.2551074	3054.6521
836.6377	2.4217193	1.2573924	3062.188
837.73877	2.421001	1.2595729	3058.9121
838.83984	2.4258137	1.2619288	3064.0847
839.94092	2.4293878	1.2644291	3063.2393
841.04199	2.4317634	1.267109	3055.5659
842.14307	2.4341762	1.2693577	3056.9028
843.24414	2.4413409	1.2717502	3060.2466
844.34521	2.4410546	1.2741183	3057.1382
845.44629	2.4438386	1.2763489	3058.9604
846.54736	2.4489126	1.2789488	3055.5859
847.64844	2.4522271	1.2807627	3054.1936
848.74951	2.4554615	1.2829677	3062.8474
849.85059	2.4593167	1.2854729	3062.3828
850.95166	2.4611144	1.2882797	3060.5872
852.05273	2.4648547	1.2908703	3064.9517
853.15381	2.4683428	1.293149	3062.8152
854.25488	2.4717171	1.2952693	3055.2993
855.35596	2.4778898	1.2973139	3058.676
856.45703	2.4787643	1.2995164	3062.2214
857.55811	2.4819548	1.3018723	3059.1204
858.65918	2.4840789	1.3044055	3068.3572
859.76025	2.4885223	1.3066554	3053.364
860.86133	2.4927235	1.3091549	3067.9678
861.9624	2.4980228	1.3112677	3068.6494
863.06348	2.5019112	1.3137759	3065.429
864.16455	2.5026593	1.3160218	3062.3181
865.26563	2.5057001	1.3185666	3063.3733
866.3667	2.5076997	1.3206737	3056.2493
867.46777	2.5102408	1.3231775	3070.6201
868.56885	2.5141511	1.3258806	3062.094
869.66992	2.518003	1.3278834	3052.8364
870.771	2.5202756	1.3300505	3063.9163
871.87207	2.5279562	1.3324273	3065.1526
872.97314	2.5277536	1.3345593	3065.5195
874.07422	2.5303628	1.336892	3066.6479
875.17529	2.5361264	1.3392425	3067.7952
876.27637	2.5396543	1.3420072	3067.7261
877.37744	2.5393031	1.344426	3056.7666
878.47852	2.5426404	1.3467201	3065.2512
879.57959	2.5471275	1.349679	3061.4946
880.68066	2.5523624	1.3521147	3059.8853
881.78174	2.553144	1.3542829	3060.0061
882.88281	2.558424	1.356589	3071.4319
883.98389	2.5597687	1.3588703	3063.5627
885.08496	2.565094	1.3616576	3063.2993
886.18604	2.5650737	1.3641735	3067.1335
887.28711	2.5709808	1.3667806	3067.228
888.38818	2.5729392	1.3693538	3067.9546
889.48926	2.5786443	1.3715311	3062.0549
890.59033	2.5795977	1.3736805	3060.1531
891.69141	2.5847213	1.375875	3068.9219
892.79248	2.5868869	1.3784511	3063.9265
893.89355	2.5930295	1.3807009	3065.9453
894.99463	2.5945957	1.3833576	3067.0059
896.0957	2.596781	1.3860524	3066.9734
897.19678	2.6028941	1.3884745	3066.0728
898.29785	2.6050189	1.3913728	3067.4502
899.39893	2.6044536	1.3937606	3063.3213
900.5	2.6106868	1.3960664	3067.0549
901.60107	2.6126122	1.3984821	3064.9312
902.70215	2.6186793	1.4005601	3069.1458
903.80322	2.6204815	1.4027722	3069.376
904.9043	2.6216221	1.4048862	3065.4573
906.00537	2.6272981	1.4071571	3065.2654
907.10645	2.6330652	1.409652	3069.6482
908.20752	2.6334653	1.4122362	3065.292
909.30859	2.6356814	1.4148898	3068.2368
910.40967	2.6388099	1.4168468	3057.0344
911.51074	2.6459639	1.4191858	3063.8647
912.61182	2.6487114	1.4218552	3072.6702
913.71289	2.65258	1.4245368	3071.5791
914.81396	2.654675	1.4267409	3069.0581
915.91504	2.6553154	1.4291326	3070.7703
917.01611	2.6592448	1.4315774	3063.4304
918.11719	2.6615548	1.4341294	3062.626
919.21826	2.6685412	1.4363015	3066.1328
920.31934	2.6708515	1.4390637	3068.8447
921.42041	2.6742446	1.441722	3066.9258
922.52148	2.6779199	1.4443449	3069.8372
923.62256	2.6781273	1.4474516	3069.2349
924.72363	2.6826205	1.450197	3067.5754
925.82471	2.6876149	1.4526324	3062.5503
926.92578	2.6914084	1.4552661	3071.2678
928.02686	2.6929536	1.4579366	3071.4434
929.12793	2.6967909	1.4607553	3064.1423
930.229	2.7020392	1.4633952	3072.0515
931.33008	2.7044485	1.4661899	3067.6528
932.43115	2.7093415	1.4684895	3066.6841
933.53223	2.712127	1.4708805	3066.4299
934.6333	2.7129879	1.4734627	3064.1733
935.73438	2.7168326	1.4758679	3065.4597
936.83545	2.7185509	1.4782175	3065.5308
937.93652	2.7244785	1.4807583	3064.729
939.0376	2.7256808	1.4832343	3063.3174
940.13867	2.7304862	1.485563	3067.575
941.23975	2.7325463	1.4882426	3064.1506
942.34082	2.7373147	1.4910172	3068.1028
943.44189	2.7406087	1.4938809	3066.2603
944.54297	2.7466772	1.4964069	3066.9182
945.64404	2.7452192	1.4986415	3061.0676
946.74512	2.7508526	1.500941	3068.9697
947.84619	2.7531416	1.5032789	3065.6743
948.94727	2.7559721	1.5056534	3070.2263
950.04834	2.7557354	1.5085347	3066.8794
951.14941	2.7588065	1.5115588	3067.3677
952.25049	2.7656279	1.5143877	3062.2322
953.35156	2.7698724	1.5174987	3067.9866
954.45264	2.7728779	1.519941	3064.2603
955.55371	2.7770376	1.5223799	3062.7708
956.65479	2.7794676	1.5247227	3062.5051
957.75586	2.7844	1.5272144	3071.7036
958.85693	2.7873552	1.5301529	3062.9209
959.95801	2.7896111	1.5328231	3066.2761
961.05908	2.7935586	1.5356555	3067.3164
962.16016	2.7930627	1.5383962	3066.3899
963.26123	2.7967575	1.5415876	3066.6191
964.3623	2.8044026	1.5447744	3067.1704
965.46338	2.8071368	1.5472231	3062.6057
966.56445	2.8072526	1.5494153	3059.1555
967.66553	2.8106878	1.5519503	3063.2722
968.7666	2.8145781	1.5542797	3060.9124
969.86768	2.818444	1.5572298	3064.9629
970.96875	2.8220434	1.5601122	3057.6182
972.06982	2.8251939	1.5623624	3059.2407
973.1709	2.829879	1.5650133	3065.4434
974.27197	2.8342555	1.5678005	3067.8313
975.37305	2.8333945	1.5709078	3064.1421
976.47412	2.8385334	1.5734733	3069.0603
977.5752	2.8432665	1.5761104	3061.0205
978.67627	2.8442388	1.5787631	3063.4529
979.77734	2.8482001	1.58184	3067.5798
980.87842	2.8515279	1.5841936	3065.9885
981.97949	2.8563151	1.5867664	3066.6047
983.08057	2.8593779	1.5896677	3066.0852
984.18164	2.8588331	1.5928186	3063.23
985.28271	2.8652089	1.5958394	3063.458
986.38379	2.8688188	1.5983967	3056.6113
987.48486	2.8703294	1.6011031	3057.2461
988.58594	2.875149	1.6039438	3065.2708
989.68701	2.8765361	1.6064929	3053.991
990.78809	2.8817484	1.6090095	3062.4673
991.88916	2.8863502	1.6119938	3066.9424
992.99023	2.891753	1.6148741	3065.8091
994.09131	2.8925674	1.6177392	3061.3789
995.19238	2.8956573	1.6204604	3060.8501
996.29346	2.898191	1.622936	3062.6421
997.39453	2.9013908	1.6257079	3061.4585
998.49561	2.9066603	1.6283281	3063.6462
999.59668	2.9078457	1.6313963	3062.2737
1000.6978	2.9105089	1.6345571	3059.2373
1001.7988	2.9153819	1.6370295	3059.4092
1002.8999	2.9189272	1.6396766	3061.2327
1004.001	2.9194112	1.642644	3061.5325
1005.1021	2.9248593	1.6459763	3059.8506
1006.2031	2.9252682	1.6487627	3059.6929
1007.3042	2.9311402	1.651718	3059.2048
1008.4053	2.9382939	1.6541616	3062.6235
1009.5063	2.938273	1.6570395	3061.2227
1010.6074	2.9398468	1.6598595	3054.9863
1011.7085	2.9497862	1.6627918	3063.1365
1012.8096	2.9482553	1.6651349	3055.8591
1013.9106	2.9516568	1.6683148	3065.5996
1015.0117	2.9542723	1.6712953	3052.8918
1016.1128	2.9581959	1.674183	3057.4966
1017.2139	2.9628584	1.6772151	3059.1379
1018.3149	2.9632907	1.6809939	3063.5081
1019.416	2.966332	1.6842306	3051.0193
1020.5171	2.9719577	1.6871026	3057.3374
1021.6182	2.9769351	1.6897451	3057.3665
1022.7192	2.9767821	1.6926116	3055.0449
1023.8203	2.981926	1.6957854	3057.7263
1024.9214	2.9839041	1.6989121	3055.2283
1026.0225	2.9872952	1.7016122	3048.3931
1027.1235	2.991822	1.7045304	3056.4741
1028.2246	2.9938755	1.7071499	3053.7688
1029.3257	2.9988465	1.7098072	3057.124
1030.4268	3.0009882	1.7134377	3058.4375
1031.5278	3.0039856	1.7165112	3050.6917
1032.6289	3.0073059	1.719635	3056.2725
1033.73	3.0100369	1.7231019	3050.8538
1034.8311	3.0158956	1.725677	3045.9646
1035.9321	3.0157752	1.7283311	3047.9688
1037.0332	3.0195172	1.7310816	3050.7883
1038.1343	3.0237317	1.734553	3059.1204
1039.2354	3.02705	1.7380201	3044.9001
1040.3364	3.0299864	1.7407236	3043.9912
1041.4375	3.032414	1.7434974	3043.7109
1042.5386	3.0391109	1.7463796	3051.5251
1043.6396	3.0387456	1.7496485	3051.4548
1044.7407	3.0431042	1.7527788	3045.5264
1045.8418	3.04775	1.7555695	3042.0063
1046.9429	3.0477729	1.7584127	3040.1042
1048.0439	3.0538788	1.7611362	3041.9314
1049.145	3.0567861	1.7639139	3045.4326
1050.2461	3.0596054	1.7665867	3045.2705
1051.3472	3.061182	1.76996	3041.9553
1052.4482	3.0672345	1.7730631	3041.2349
1053.5493	3.0709398	1.776021	3042.4543
1054.6504	3.0754411	1.7791216	3043.4949
1055.7515	3.0753272	1.7822084	3036.5061
1056.8525	3.0798469	1.7847639	3038.8274
1057.9536	3.0850875	1.7878772	3047.4702
1059.0547	3.0854549	1.7902516	3041.1306
1060.1558	3.0913215	1.7928463	3043.5056
1061.2568	3.0923414	1.7954102	3035.792
1062.3579	3.0951159	1.7984214	3034.9644
1063.459	3.0990372	1.8013016	3033.2769
1064.5601	3.1033635	1.8040382	3039.4338
1065.6611	3.1069143	1.8074979	3046.8179
1066.7622	3.1112721	1.8106267	3038.7532
1067.8633	3.1125288	1.8135983	3033.2363
1068.9644	3.1171753	1.8168428	3033.4431
1070.0654	3.1211791	1.8207155	3043.186
1071.1665	3.1250861	1.8244163	3035.0603
1072.2676	3.1250169	1.8274691	3034.2693
1073.3687	3.1301723	1.8305026	3027.2097
1074.4697	3.1331568	1.8338751	3034.1436
1075.5708	3.1370218	1.8365413	3030.3918
1076.6719	3.1360629	1.8393185	3027.2837
1077.7729	3.1454191	1.842272	3032.8081
1078.874	3.1460166	1.8452015	3032.1355
1079.9751	3.1510623	1.8487236	3035.8152
1081.0762	3.1532342	1.8521619	3031.0366
1082.1772	3.1558425	1.8555661	3023.8743
1083.2783	3.1575258	1.8584679	3023.3884
1084.3794	3.1601734	1.8615685	3025.1443
1085.4805	3.1664426	1.864903	3022.1563
1086.5815	3.167897	1.8680089	3018.5496
1087.6826	3.1706672	1.8707992	3022.4287
1088.7837	3.1731732	1.8739997	3020.2842
1089.8848	3.1812456	1.8775786	3028.97
1090.9858	3.1850326	1.8805752	3020.46
1092.0869	3.1882074	1.8837266	3025.1819
1093.188	3.1895549	1.8871737	3019.4812
1094.2891	3.1919329	1.8907303	3023.5288
1095.3901	3.1943564	1.8939047	3017.1787
1096.4912	3.199086	1.8970387	3013.1938
1097.5923	3.2007222	1.9000856	3016.0642
1098.6934	3.2060058	1.9030633	3012.8706
1099.7944	3.208869	1.9062363	3014.4658
1100.8955	3.2128336	1.9095097	3014.3076
1101.9966	3.2167509	1.9129688	3012.4226
1103.0977	3.2206695	1.9161023	3015.0984
1104.1987	3.2206767	1.9199754	3011.2473
1105.2998	3.2244544	1.9231721	3000.3342
1106.4009	3.2284698	1.9263614	3008.7744
1107.502	3.2286835	1.9302299	3004.7703
1108.603	3.2355881	1.9338163	2998.6846
1109.7041	3.236582	1.9371051	3004.1206
1110.8052	3.2460978	1.9407357	3001.6777
1111.9063	3.2453337	1.943734	3001.4585
1113.0073	3.2502415	1.9470737	3000.7102
1114.1084	3.2505529	1.950579	2996.3408
1115.2095	3.2557452	1.953181	2994.9773
1116.3105	3.2601392	1.9566784	2999.6995
1117.4116	3.2598593	1.9600818	2986.1174
1118.5127	3.2692227	1.9628774	2992.9929
1119.6138	3.2694032	1.9653752	2994.6011
1120.7148	3.2744184	1.9683614	2996.9277
1121.8159	3.2753727	1.9719751	2994.9644
1122.917	3.2797761	1.9749448	2988.074
1124.0181	3.2835863	1.9781632	2995.5457
1125.1191	3.2862439	1.9817517	2990.0845
1126.2202	3.2852213	1.9848151	2984.0503
1127.3213	3.2916009	1.9885076	2987.7161
1128.4224	3.2921946	1.9923509	2984.2312
1129.5234	3.2983174	1.9958315	2985.0146
1130.6245	3.3020208	1.9991331	2982.9912
1131.7256	3.3056922	2.0024395	2974.0532
1132.8267	3.3078794	2.005511	2974.2896
1133.9277	3.3119464	2.0089896	2985.8376
1135.0288	3.3151269	2.0121298	2970.9241
1136.1299	3.314954	2.0149701	2970.9504
1137.231	3.3194053	2.0184216	2975.1604
1138.332	3.3241782	2.0224113	2972.7834
1139.4331	3.3257906	2.0266876	2968.2622
1140.5342	3.3351805	2.0301726	2968.1345
1141.6353	3.3312876	2.0330546	2963.0405
1142.7363	3.3392406	2.0363369	2964.0994
1143.8374	3.3396461	2.0403097	2963.72
1144.9385	3.3421257	2.0438347	2956.1287
1146.0396	3.348901	2.0472186	2958.6563
1147.1406	3.350714	2.0501173	2956.2825
1148.2417	3.3528841	2.052882	2961.3596
1149.3428	3.3572426	2.054862	2959.3784
1150.4438	3.3606734	2.0559258	2949.8687
1151.5449	3.3631921	2.0565786	2953.8914
1152.646	3.3664067	2.0570166	2947.0891
1153.7471	3.3738065	2.0570545	2955.7053
1154.8481	3.3745165	2.0576615	2943.6611
1155.9492	3.3770423	2.0575316	2948.1262
1157.0503	3.3816085	2.057601	2948.4133
1158.1514	3.384912	2.0579686	2941.2363
1159.2524	3.3854692	2.0579448	2944.4998
1160.3535	3.3931284	2.058013	2941.0376
1161.4546	3.3918884	2.0578973	2930.7483
1162.5557	3.3942659	2.0579805	2934.4238
1163.6567	3.3996265	2.0577292	2929.6016
1164.7578	3.4001491	2.0575006	2925.4927
1165.8589	3.4091394	2.0573392	2927.207
1166.96	3.4095926	2.057507	2919.9583
1168.061	3.4144812	2.0576041	2932.3618
1169.1621	3.4168797	2.0574243	2927.7285
1170.2632	3.4226241	2.0573063	2917.6414
1171.3643	3.4226358	2.0575588	2914.2986
1172.4653	3.4287055	2.0572813	2921.2629
1173.5664	3.4333777	2.0575342	2920.4778
1174.6675	3.432765	2.0576301	2903.5007
1175.7686	3.4394164	2.0576122	2916.8203
1176.8696	3.4394374	2.0576556	2911.2883
1177.9707	3.4416792	2.0574706	2905.606
1179.0718	3.4462261	2.0575945	2906.2161
1180.1729	3.4491105	2.0575068	2896.8975
1181.2739	3.4537652	2.0573721	2894.6023
1182.375	3.4557962	2.0575383	2896.8096
1183.4761	3.4634404	2.0574307	2898.4055
1184.5771	3.4647574	2.0574095	2892.5637
1185.6782	3.4626553	2.05755	2888.3877
1186.7793	3.4690108	2.057477	2886.7544
1187.8804	3.4719746	2.0576003	2876.8101
1188.9814	3.4795709	2.0573456	2883.7834
1190.0825	3.4810209	2.0576267	2877.6584
1191.1836	3.4856272	2.0575318	2888.6462
1192.2847	3.4872377	2.0574069	2879.4133
1193.3857	3.4898052	2.057745	2870.7129
1194.4868	3.496104	2.0578837	2871.2292
1195.5879	3.4970524	2.0577226	2869.7173
1196.689	3.5019157	2.0574975	2867.6392
1197.79	3.5035956	2.0573292	2861.4871
1198.8911	3.5065475	2.0578196	2853.7307
1199.9922	3.507396	2.0576549	2857.885
1201.0933	3.5128284	2.0578923	2848.144
1202.1943	3.5175664	2.0577986	2849.5195
1203.2954	3.5226045	2.0577068	2847.6204
1204.3965	3.5232167	2.0577943	2850.8879
1205.4976	3.5262408	2.0576191	2840.1843
1206.5986	3.5308232	2.0576608	2840.1499
1207.6997	3.5308359	2.0576892	2832.1733
1208.8008	3.5370259	2.057719	2838.6047
1209.9019	3.5376942	2.0577478	2824.4863
1211.0029	3.5413547	2.0579016	2817.8384
1212.104	3.5471232	2.0579429	2828.2141
1213.2051	3.5474882	2.0579941	2820.7571
1214.3062	3.5511546	2.0579917	2813.8098
1215.4072	3.555227	2.0577679	2811.0427
1216.5083	3.5603456	2.0578203	2808.8022
1217.6094	3.5618615	2.0579081	2803.9824
1218.7104	3.5655184	2.0578594	2803.4358
1219.8115	3.5685675	2.0578415	2799.5176
1220.9126	3.5718436	2.057966	2802.4956
1222.0137	3.57531	2.057688	2793.6196
1223.1147	3.5786345	2.0577004	2791.8416
1224.2158	3.5842552	2.057879	2784.0161
1225.3169	3.5870888	2.0579376	2784.8848
1226.418	3.5902655	2.0577989	2782.3545
1227.519	3.5917497	2.057533	2778.7358
1228.6201	3.5969844	2.0576839	2775.3672
1229.7212	3.5975544	2.0579147	2773.1787
1230.8223	3.6029236	2.0578072	2764.9504
1231.9233	3.6045475	2.0578728	2760.4285
1233.0244	3.6099794	2.0578001	2763.6697
1234.1255	3.6131463	2.0575421	2756.9429
1235.2266	3.6146307	2.0579321	2755.2915
1236.3276	3.6193252	2.0577135	2747.7971
1237.4287	3.6239684	2.0576689	2745.5774
1238.5298	3.6247368	2.05741	2740.1133
1239.6309	3.6289961	2.0576627	2735.6113
1240.7319	3.6356306	2.0577557	2730.1206
1241.833	3.6355205	2.0576997	2724.2432
1242.9341	3.6377609	2.0577884	2722.2146
1244.0352	3.6424208	2.0575445	2724.8782
1245.1362	3.6418207	2.0578198	2717.7
1246.2373	3.6507635	2.057821	2712.2334
1247.3384	3.6508033	2.0580468	2711.3662
1248.4395	3.6538916	2.0581183	2695.7493
1249.5405	3.659847	2.0579505	2698.7144
1250.6416	3.6601219	2.0582471	2685.7163
1251.7427	3.664917	2.0584505	2688.0005
1252.8438	3.6663003	2.0585418	2672.0854
1253.9448	3.6726334	2.0586007	2671.0122
1255.0459	3.6750062	2.0583231	2665.9778
1256.147	3.6786318	2.0583501	2667.2522
1257.248	3.6801867	2.0583644	2661.5439
1258.3491	3.6833141	2.0584197	2647.8408
1259.4502	3.6882722	2.0583224	2648.3606
1260.5513	3.6917689	2.0583968	2639.553
1261.6523	3.6974471	2.0581682	2638.7498
1262.7534	3.6996396	2.0583231	2616.0867
1263.8545	3.7016726	2.0583243	2606.8628
1264.9556	3.7045507	2.0584426	2598.8467
1266.0566	3.7081323	2.0581124	2583.5117
1267.1577	3.7082899	2.0582025	2562.364
1268.2588	3.7163723	2.0578918	2550.6699
1269.3599	3.7185562	2.057929	2523.2798
1270.4609	3.723819	2.0579753	2477.8647
1271.562	3.7276032	2.0576448	2402.708