File: datasets/am_bench_2022/raw_data/60-XY.09-4/specimen.dat
MTS793|MPT|ENU|1|2|.|/|:|1|0|0|A

Operator Information						Time:	11.379883	Sec	11/2/2021 8:52:28 AM
Operator	Nick Derimow
Project	AM Bench 2022 mini-tensile challenge
Specimen ID	60-XY.09-4
Material	PBF-L Inconel 625
Specimen Width	2.55	mm
Specimen Thickness	1.52	mm
Notes
Operator Information End

Data Acquisition						Time:	1012.3752	Sec	11/2/2021 9:09:09 AM
Time	Axial Displacement	Axial Extensometer	Axial Force
Sec	mm	mm	N
11.494385	-0.0014819672	-2.4488241e-05	53.510212
12.495361	0.00061688462	8.8322675e-05	63.460381
13.496338	0.003248248	4.388285e-05	73.311897
14.497314	0.0085116411	0.00023853542	90.268608
15.498291	0.0081911916	0.00023680204	105.85602
16.499268	0.012342026	0.00029148231	120.01109
17.500244	0.015504109	0.00034031909	133.62128
18.501221	0.019203518	0.00042439305	146.49086
19.502197	0.021231323	0.00048538909	156.85356
20.503174	0.023579374	0.00062990072	170.8037
21.50415	0.028923288	0.00070370553	191.04297
22.505127	0.03032879	0.0007847891	205.84749
23.506104	0.03346603	0.0008600076	227.50201
24.50708	0.03562599	0.00094551477	241.52113
25.508057	0.040866435	0.0009950574	266.0582
26.509033	0.042044353	0.0012369445	290.20395
27.51001	0.045007434	0.0013572718	306.35278
28.510986	0.050082736	0.0013177822	333.32001
29.511963	0.054081134	0.0015174003	352.13315
30.512939	0.055259872	0.0015906938	374.84933
31.513916	0.056548174	0.0017097457	391.8009
32.514893	0.061468169	0.0018547584	420.93909
33.515869	0.062205777	0.0019443552	443.71478
34.516846	0.063377343	0.0019948075	465.75992
35.517822	0.067941852	0.0022025895	490.42303
36.518799	0.074360982	0.0023726306	525.31018
37.519775	0.076891594	0.0024655436	546.70752
38.520752	0.079179406	0.0026063055	564.34503
39.521729	0.08359696	0.0027209779	598.80176
40.522705	0.081623912	0.0028109732	621.51532
41.523682	0.087530404	0.0029882428	648.47943
42.524658	0.091442794	0.0030330762	665.35431
43.525635	0.094588026	0.0032012495	695.28558
44.526611	0.096827641	0.003311987	719.2077
45.527588	0.097967036	0.003386054	748.70966
46.528564	0.10309827	0.0035477653	785.95337
47.529541	0.10573768	0.0038004993	809.77319
48.530518	0.10805802	0.0038740009	835.13477
49.531494	0.11307979	0.0039771134	860.67981
50.532471	0.11678566	0.004108008	891.09503
51.533447	0.11694875	0.0042515984	922.3692
52.534424	0.1207691	0.0044452627	954.06409
53.5354	0.12172491	0.0045383568	979.54431
54.536377	0.12573355	0.004636555	1001.3793
55.537354	0.128511	0.0047645699	1028.7643
56.53833	0.13053082	0.004917027	1050.0714
57.539307	0.13668133	0.0049967244	1072.9718
58.540283	0.13999663	0.0051233666	1107.2555
59.54126	0.14397356	0.0052789915	1132.2207
60.542236	0.14513816	0.0053561083	1161.8401
61.543213	0.14765191	0.0056009539	1187.8752
62.544189	0.14913286	0.0058292281	1221.0017
63.545166	0.15542169	0.0058988421	1252.4712
64.546143	0.16132188	0.0060877688	1287.4425
65.547119	0.1627178	0.0061532645	1306.1266
66.548096	0.16289872	0.006250856	1335.2496
67.549072	0.16525061	0.0063958685	1362.7988
68.550049	0.17177655	0.0066256179	1393.2893
69.551025	0.17239901	0.0066783978	1426.3616
70.552002	0.17541392	0.0068537281	1444.8467
71.552979	0.17518671	0.0068802368	1476.7217
72.553955	0.17891116	0.0071198004	1495.951
73.554932	0.18270302	0.0071985237	1536.905
74.555908	0.18803895	0.0073716422	1562.4838
75.556885	0.18949983	0.0075379214	1601.4995
76.557861	0.19290158	0.0077503547	1633.4102
77.558838	0.19505084	0.0078268275	1653.9767
78.559814	0.19900748	0.0078474805	1682.6704
79.560791	0.20109445	0.0080815647	1700.2028
80.561768	0.20450604	0.0081499768	1724.2235
81.562744	0.20529877	0.0083663361	1757.9749
82.563721	0.21167409	0.0084205074	1782.4639
83.564697	0.21343288	0.0084583666	1801.7393
84.565674	0.21578908	0.0087240459	1839.3455
85.56665	0.22166792	0.0088368952	1856.0256
86.567627	0.22121489	0.0089232018	1880.2458
87.568604	0.22480848	0.0090670874	1906.6022
88.56958	0.22759679	0.0092059895	1922.2567
89.570557	0.23251657	0.0093380446	1949.0128
90.571533	0.23582941	0.0093589593	1966.3717
91.57251	0.23960657	0.0095620854	1988.5413
92.573486	0.23973094	0.0095610246	2013.3181
93.574463	0.24299009	0.0096962592	2034.0011
94.575439	0.24555671	0.0098003624	2054.1797
95.576416	0.25080657	0.0098809628	2076.0837
96.577393	0.25295794	0.010011337	2097.3806
97.578369	0.25460583	0.010135729	2117.9619
98.579346	0.2576066	0.010240632	2130.7747
99.580322	0.26040584	0.010293932	2149.0518
100.5813	0.26346233	0.010379784	2172.7654
101.58228	0.26821944	0.010562724	2194.4033
102.58325	0.27147204	0.010698825	2215.4788
103.58423	0.2739881	0.010717728	2233.552
104.58521	0.27931499	0.010869487	2245.229
105.58618	0.27994874	0.010969023	2259.5193
106.58716	0.28319395	0.011062138	2280.636
107.58813	0.28460068	0.011193422	2293.2932
108.58911	0.28889945	0.011268743	2311.884
109.59009	0.28989974	0.011507545	2326.6013
110.59106	0.29706225	0.011501074	2341.0566
111.59204	0.29768363	0.0116088	2354.6072
112.59302	0.30060783	0.011692943	2370.3232
113.59399	0.30516231	0.011714236	2376.5537
114.59497	0.30577165	0.011893526	2392.1245
115.59595	0.30913776	0.011960593	2403.47
116.59692	0.31168368	0.012012837	2421.1768
117.5979	0.3154102	0.012120895	2431.3799
118.59888	0.32000816	0.01232401	2440.2056
119.59985	0.31951231	0.012438353	2452.6873
120.60083	0.32348755	0.012596045	2473.0408
121.60181	0.32928833	0.012618241	2477.4531
122.60278	0.32952601	0.012691316	2492.7996
123.60376	0.33391967	0.012851303	2501.3943
124.60474	0.33737838	0.012933762	2510.0266
125.60571	0.3426114	0.013130561	2523.6548
126.60669	0.344329	0.013236058	2535.1509
127.60767	0.349123	0.013355889	2550.6323
128.60864	0.35257044	0.013534188	2558.5803
129.60962	0.35482317	0.013635702	2563.2986
130.6106	0.3565973	0.013742658	2572.3455
131.61157	0.36005977	0.013920305	2582.053
132.61255	0.36112478	0.014013517	2589.5039
133.61353	0.36496887	0.014164642	2599.2566
134.6145	0.36854538	0.014400985	2615.9966
135.61548	0.37031463	0.01441872	2616.3662
136.61646	0.37373322	0.014701422	2633.7161
137.61743	0.37418255	0.014821717	2633.4016
138.61841	0.37938523	0.01510581	2642.4832
139.61938	0.38234955	0.015392982	2653.0774
140.62036	0.3865287	0.015464784	2660.3784
141.62134	0.38656476	0.015782677	2666.5095
142.62231	0.39267942	0.01603744	2686.9963
143.62329	0.39440748	0.016292861	2686.5015
144.62427	0.39922443	0.016717406	2702.2312
145.62524	0.40038821	0.016938392	2708.9363
146.62622	0.40302879	0.017319541	2707.8076
147.6272	0.40694481	0.017642459	2724.6865
148.62817	0.41089547	0.018015111	2724.7444
149.62915	0.41233361	0.018349681	2730.3921
150.63013	0.4153311	0.018734047	2740.218
151.6311	0.41853207	0.01911683	2746.7998
152.63208	0.42403722	0.019666351	2760.6543
153.63306	0.42495677	0.020101693	2767.176
154.63403	0.42519793	0.02067695	2769.4819
155.63501	0.42952046	0.021108285	2780.9595
156.63599	0.4327575	0.021600649	2778.9146
157.63696	0.43471646	0.022059694	2784.9534
158.63794	0.43894964	0.022482993	2783.302
159.63892	0.44570357	0.023218298	2803.4614
160.63989	0.4436326	0.023729114	2799.4023
161.64087	0.446132	0.024335789	2802.8953
162.64185	0.45310563	0.024845911	2812.3298
163.64282	0.45380944	0.025579061	2820.3101
164.6438	0.45651147	0.026140697	2814.3987
165.64478	0.46222824	0.026983347	2832.5637
166.64575	0.46367887	0.027671903	2827.7893
167.64673	0.46501291	0.028315382	2832.8413
168.64771	0.47037977	0.028966621	2837.0164
169.64868	0.47476685	0.029809376	2845.0027
170.64966	0.47618917	0.030462975	2850.3672
171.65063	0.47704643	0.031145653	2849.7952
172.65161	0.48136818	0.031890236	2849.0989
173.65259	0.48588407	0.032699272	2870.302
174.65356	0.48840505	0.033671748	2869.342
175.65454	0.49036601	0.034643095	2868.5051
176.65552	0.49324268	0.035572127	2875.0027
177.65649	0.49856326	0.036703017	2884.7163
178.65747	0.50083441	0.03748079	2878.1345
179.65845	0.50529075	0.038397931	2884.6379
180.65942	0.50415033	0.039308019	2885.9414
181.6604	0.50860608	0.040350132	2893.8164
182.66138	0.51050621	0.041359842	2894.5479
183.66235	0.51250792	0.042362142	2896.1416
184.66333	0.51799607	0.043370873	2900.2424
185.66431	0.52026302	0.044429488	2907.5291
186.66528	0.5219605	0.045252904	2902.603
187.66626	0.52590948	0.046397429	2915.0759
188.66724	0.53104377	0.04737813	2915.469
189.66821	0.5345667	0.048535053	2916.5583
190.66919	0.53525841	0.04952918	2918.8513
191.67017	0.53728575	0.050549977	2919.8225
192.67114	0.54041725	0.05138018	2913.7529
193.67212	0.54651004	0.052373108	2929.8625
194.6731	0.54688644	0.053346165	2931.5452
195.67407	0.55098134	0.054531351	2931.634
196.67505	0.55546308	0.055624701	2935.6335
197.67603	0.55614936	0.056767341	2942.1553
198.677	0.5601005	0.057809509	2937.1472
199.67798	0.56150383	0.05869839	2940.457
200.67896	0.56414562	0.059812315	2944.5662
201.67993	0.56717199	0.060901955	2946.8831
202.68091	0.571648	0.061890069	2949.396
203.68188	0.57494694	0.062899329	2956.8777
204.68286	0.57519406	0.064110942	2954.1577
205.68384	0.57939017	0.06538555	2954.3262
206.68481	0.58661616	0.066590391	2973.3071
207.68579	0.58582366	0.067829281	2960.6931
208.68677	0.58814585	0.069161445	2961.8171
209.68774	0.59386963	0.070532866	2975.1606
210.68872	0.59498423	0.071776085	2967.925
211.6897	0.59792376	0.072954364	2975.3328
212.69067	0.59941679	0.074080184	2976.9004
213.69165	0.60649937	0.075314082	2980.2478
214.69263	0.6065731	0.076481037	2983.5034
215.6936	0.61232007	0.077535324	2981.5935
216.69458	0.61481559	0.078465365	2986.0757
217.69556	0.61701465	0.079780869	2994.1318
218.69653	0.61910826	0.081139252	2988.3958
219.69751	0.62255156	0.082489282	2996.877
220.69849	0.627666	0.083520815	2996.3054
221.69946	0.62844479	0.084614359	2993.7556
222.70044	0.63269627	0.085933514	3006.8765
223.70142	0.63260812	0.087078542	2995.9915
224.70239	0.63910514	0.088428184	3007.3579
225.70337	0.63890928	0.089560382	2999.8694
226.70435	0.64245713	0.090812966	3011.3181
227.70532	0.64434206	0.091905192	3005.8992
228.7063	0.65109664	0.093047187	3015.3179
229.70728	0.6539557	0.094346687	3017.3499
230.70825	0.65386635	0.095444329	3012.1975
231.70923	0.6592375	0.096312299	3011.3687
232.71021	0.66229892	0.097364038	3012.512
233.71118	0.66285765	0.098711953	3022.1506
234.71216	0.66503519	0.10023923	3025.4717
235.71313	0.67005259	0.10140103	3017.8137
236.71411	0.67079115	0.10278501	3031.9541
237.71509	0.67705089	0.10410154	3029.6707
238.71606	0.67985868	0.10520078	3030.2173
239.71704	0.6820609	0.1063493	3036.6589
240.71802	0.68668175	0.1074248	3029.9211
241.71899	0.69043362	0.10857817	3039.6404
242.71997	0.6933738	0.10975949	3036.6047
243.72095	0.69630271	0.11120062	3039.166
244.72192	0.69839394	0.11254609	3043.3303
245.7229	0.70303488	0.11362007	3043.3076
246.72388	0.70288247	0.11452422	3040.5679
247.72485	0.7043066	0.11555006	3041.4988
248.72583	0.71266425	0.1167761	3058.7891
249.72681	0.71452236	0.11816006	3054.5696
250.72778	0.71634221	0.11951802	3057.4426
251.72876	0.72281814	0.12067014	3058.0364
252.72974	0.72045517	0.12185305	3058.5405
253.73071	0.72793764	0.12320396	3058.9648
254.73169	0.72606134	0.12446769	3060.4038
255.73267	0.73260808	0.12579463	3058.9458
256.73364	0.73433858	0.1267789	3058.0979
257.73462	0.73757994	0.12801278	3066.8586
258.7356	0.74259007	0.12952222	3070
259.73657	0.7431097	0.13059333	3065.9595
260.73755	0.74827147	0.13181946	3070.0518
261.73853	0.74525446	0.13287392	3071.8855
262.7395	0.74972391	0.13419789	3069.2039
263.74048	0.75403005	0.13552129	3080.0916
264.74146	0.75682145	0.13681522	3075.3638
265.74243	0.76004106	0.13821971	3079.6001
266.74341	0.76359117	0.13938187	3069.5356
267.74438	0.76578248	0.14080648	3085.4355
268.74536	0.76797205	0.14195934	3081.6775
269.74634	0.77249825	0.14306997	3082.9009
270.74731	0.77572304	0.14418374	3085.0129
271.74829	0.78191805	0.14530984	3089.4551
272.74927	0.78103226	0.14622611	3083.2668
273.75024	0.78580314	0.14746177	3094.0193
274.75122	0.78707772	0.14878744	3090.5557
275.7522	0.79086477	0.15005833	3096.834
276.75317	0.7922377	0.15122619	3092.5627
277.75415	0.79826671	0.15261963	3100.283
278.75513	0.80026746	0.15386121	3095.1355
279.7561	0.80290294	0.1550861	3096.8633
280.75708	0.80812001	0.15607668	3098.1289
281.75806	0.80656493	0.1573184	3105.5349
282.75903	0.81102902	0.15872025	3107.1077
283.76001	0.81459594	0.16001768	3105.7288
284.76099	0.82055902	0.16148449	3114.8298
285.76196	0.82159883	0.16259143	3106.4131
286.76294	0.82708675	0.16385913	3119.6409
287.76392	0.83081555	0.16510241	3117.9336
288.76489	0.82926065	0.16635486	3114.0928
289.76587	0.83083093	0.16746692	3122.0427
290.76685	0.83517593	0.16898984	3123.615
291.76782	0.8408764	0.17042175	3121.6104
292.7688	0.84418929	0.17142318	3122.6709
293.76978	0.84334779	0.17273553	3126.9729
294.77075	0.84944135	0.17414194	3128.1118
295.77173	0.85240543	0.17520259	3128.4766
296.77271	0.85434514	0.17632449	3126.6277
297.77368	0.85518807	0.17727439	3124.3337
298.77466	0.85888606	0.17841391	3122.4106
299.77563	0.86271566	0.17969185	3138.1172
300.77661	0.86854845	0.18109256	3137.3137
301.77759	0.8680141	0.18227005	3133.1514
302.77856	0.87201947	0.18371117	3144.0088
303.77954	0.87735844	0.18487352	3136.0591
304.78052	0.87797558	0.18608113	3138.3186
305.78149	0.88087678	0.18711284	3141.4192
306.78247	0.88397145	0.18812846	3138.6895
307.78345	0.88571644	0.18945335	3142.5173
308.78442	0.88914216	0.19050413	3141.9802
309.7854	0.89376181	0.19204843	3153.252
310.78638	0.89316642	0.19323681	3146.3062
311.78735	0.89787847	0.1943191	3145.4045
312.78833	0.90117389	0.19562699	3149.9668
313.78931	0.90576804	0.19678999	3154.9595
314.79028	0.90656281	0.19790365	3153.2896
315.79126	0.90904057	0.19923109	3147.1504
316.79224	0.91474181	0.20052828	3158.5017
317.79321	0.91857344	0.20175192	3160.8369
318.79419	0.91988897	0.20307519	3157.0388
319.79517	0.91974086	0.20427354	3156.6406
320.79614	0.92566544	0.20539641	3160.3521
321.79712	0.92907047	0.20657553	3166.8416
322.7981	0.93186539	0.20775758	3162.2478
323.79907	0.93679416	0.2088061	3163.8906
324.80005	0.94006664	0.21008645	3176.085
325.80103	0.94228679	0.21130113	3171.1677
326.802	0.94249517	0.21257906	3171.0574
327.80298	0.94918668	0.21388249	3179.8359
328.80396	0.95068848	0.21547551	3183.3242
329.80493	0.95504278	0.21695764	3180.7483
330.80591	0.95611453	0.21804711	3171.4624
331.80688	0.95862997	0.21924458	3178.5198
332.80786	0.96168995	0.22038545	3186.3611
333.80884	0.96489465	0.22162628	3184.5579
334.80981	0.96572912	0.22288974	3184.1704
335.81079	0.96841836	0.2241051	3180.7708
336.81177	0.97172749	0.22528023	3182.6345
337.81274	0.97462583	0.2264486	3177.3533
338.81372	0.98165107	0.22768736	3185.4207
339.8147	0.98364663	0.2287069	3186.3267
340.81567	0.9867382	0.2299317	3198.0281
341.81665	0.98990583	0.23118451	3188.2063
342.81763	0.99509567	0.23259936	3199.3147
343.8186	0.99523664	0.23367319	3195.7095
344.81958	0.99801487	0.23485613	3194.5596
345.82056	1.0031463	0.23617661	3197.9131
346.82153	1.0043937	0.23733334	3196.9358
347.82251	1.0086247	0.23848003	3200.5798
348.82349	1.0136366	0.23974387	3208.6887
349.82446	1.014654	0.240977	3205.6826
350.82544	1.0159413	0.24214576	3206.9006
351.82642	1.019865	0.24338511	3206.082
352.82739	1.0238142	0.24480134	3212.8845
353.82837	1.02425	0.24637069	3217.2559
354.82935	1.0276623	0.24757378	3212.0076
355.83032	1.0306178	0.24871276	3208.3113
356.8313	1.0348545	0.24987145	3212.2212
357.83228	1.0379001	0.25108048	3214.574
358.83325	1.0412128	0.25192031	3210.2712
359.83423	1.0408708	0.25304735	3209.0356
360.83521	1.0438488	0.25434121	3221.04
361.83618	1.0513154	0.2555806	3214.2227
362.83716	1.0521686	0.2569688	3226.2041
363.83813	1.0539372	0.25843084	3223.5767
364.83911	1.0583878	0.25965419	3217.1035
365.84009	1.0644166	0.26088783	3228.7268
366.84106	1.0645467	0.26220337	3231.2163
367.84204	1.0657645	0.26338452	3218.4832
368.84302	1.0692719	0.2643691	3222.4165
369.84399	1.0713017	0.2655395	3230.7761
370.84497	1.0762383	0.26675352	3227.731
371.84595	1.0783557	0.268047	3232.7178
372.84692	1.0843966	0.26934272	3240.3247
373.8479	1.0828552	0.27070704	3233.7305
374.84888	1.0855173	0.27190879	3233.8977
375.84985	1.090252	0.27319455	3243.9609
376.85083	1.0920012	0.2745218	3234.9048
377.85181	1.0978029	0.27576667	3237.0159
378.85278	1.0990174	0.27690586	3236.7734
379.85376	1.1040055	0.27816346	3247.0129
380.85474	1.1053143	0.2793991	3248.4268
381.85571	1.1075995	0.28062111	3242.1035
382.85669	1.1110268	0.28193811	3248.1011
383.85767	1.1165061	0.28308883	3246.9976
384.85864	1.1183343	0.28417021	3249.6868
385.85962	1.1227015	0.28531662	3253.0225
386.8606	1.1232508	0.28653643	3250.8933
387.86157	1.1263359	0.28767163	3254.7952
388.86255	1.1290852	0.28887326	3252.2102
389.86353	1.1350788	0.29015449	3259.3296
390.8645	1.1356854	0.29143822	3259.7183
391.86548	1.1362143	0.29271472	3256.2642
392.86646	1.139788	0.29381996	3259.1357
393.86743	1.1430601	0.2950685	3255.3796
394.86841	1.1503685	0.2961944	3267.1858
395.86938	1.1497812	0.29739314	3268.7405
396.87036	1.152885	0.29876253	3266.1265
397.87134	1.1559319	0.30007818	3261.2446
398.87231	1.161424	0.30127591	3264.6924
399.87329	1.1650105	0.3023496	3270.6829
400.87427	1.1660824	0.30356959	3270.7847
401.87524	1.1705689	0.30512443	3275.4951
402.87622	1.1723751	0.3063913	3272.3777
403.8772	1.1774729	0.30735821	3280.4783
404.87817	1.1801745	0.30869672	3277.8533
405.87915	1.180227	0.30987573	3280.3967
406.88013	1.1841884	0.31141624	3282.3704
407.8811	1.1859974	0.31242108	3272.2925
408.88208	1.1894397	0.31341538	3278.5496
409.88306	1.1941297	0.31479505	3284.9719
410.88403	1.1978279	0.31600824	3282.592
411.88501	1.199831	0.31695738	3274.365
412.88599	1.1995784	0.31806162	3281.6416
413.88696	1.2066952	0.31931841	3289.0745
414.88794	1.2098196	0.32063746	3287.9053
415.88892	1.2115666	0.32188526	3290.4199
416.88989	1.216342	0.32314679	3291.3787
417.89087	1.2159129	0.32434446	3283.9653
418.89185	1.2219467	0.32547483	3289.731
419.89282	1.2237054	0.32646999	3285.3408
420.8938	1.2251139	0.32755756	3287.2751
421.89478	1.2310929	0.3287949	3299.2634
422.89575	1.2337602	0.33022809	3300.4739
423.89673	1.2348713	0.33159405	3303.074
424.89771	1.2370669	0.33269218	3294.575
425.89868	1.2370874	0.33403426	3296.8794
426.89966	1.2423134	0.33522743	3296.2395
427.90063	1.2452493	0.33639482	3301.033
428.90161	1.2519469	0.3377462	3301.6648
429.90259	1.2524291	0.33893937	3301.4475
430.90356	1.2549559	0.34026739	3308.1091
431.90454	1.2601196	0.34176451	3309.1685
432.90552	1.2658242	0.34316152	3309.6008
433.90649	1.2660047	0.34425458	3303.4155
434.90747	1.2693819	0.3452974	3308.1814
435.90845	1.2719381	0.34640169	3312.3113
436.90942	1.2752612	0.34782949	3320.6086
437.9104	1.2762762	0.3490853	3311.2737
438.91138	1.2795118	0.35036689	3312.5715
439.91235	1.2832247	0.35141143	3312.9385
440.91333	1.2865117	0.3525497	3315.1162
441.91431	1.2908487	0.35392261	3323.4216
442.91528	1.2916217	0.35525319	3306.1116
443.91626	1.2949929	0.35641235	3318.4309
444.91724	1.2945966	0.35761574	3316.1572
445.91821	1.3031926	0.35897326	3320.7234
446.91919	1.306022	0.36022231	3321.6338
447.92017	1.3069961	0.36134699	3320.6875
448.92114	1.3130363	0.36230856	3326.4324
449.92212	1.3143206	0.36341271	3326.1431
450.9231	1.3159795	0.36422491	3313.1731
451.92407	1.3217745	0.36549842	3330.6365
452.92505	1.3214422	0.36688694	3331.9375
453.92603	1.3275129	0.36827752	3334.6699
454.927	1.3282343	0.36949494	3332.7417
455.92798	1.3337624	0.37086108	3336.283
456.92896	1.3346463	0.37197474	3330.6648
457.92993	1.3401455	0.37310997	3340.6362
458.93091	1.3398509	0.37447321	3335.4021
459.93188	1.3436751	0.37577671	3335.5295
460.93286	1.344162	0.37698203	3331.7319
461.93384	1.3499937	0.37801927	3344.7725
462.93481	1.353084	0.37924236	3337.6963
463.93579	1.3566827	0.38045171	3340.6035
464.93677	1.3586926	0.38150123	3337.4766
465.93774	1.3635107	0.38257962	3350.677
466.93872	1.3629736	0.38401657	3343.8506
467.9397	1.3677758	0.38526922	3351.468
468.94067	1.3694869	0.38676152	3350.4216
469.94165	1.3717037	0.38808203	3345.0657
470.94263	1.3764046	0.38934538	3347.0891
471.9436	1.3803461	0.39056012	3344.8564
472.94458	1.3851286	0.39161357	3353.1436
473.94556	1.3835014	0.39286479	3351.8315
474.94653	1.3876114	0.39407852	3359.6609
475.94751	1.3901051	0.39524335	3343.1169
476.94849	1.3939575	0.39659697	3363.6843
477.94946	1.3964953	0.3979907	3361.3594
478.95044	1.3992583	0.39934483	3351.8149
479.95142	1.403488	0.40052173	3357.6421
480.95239	1.4087549	0.40177357	3363.8848
481.95337	1.4109572	0.4028191	3357.5164
482.95435	1.4121163	0.40394768	3361.6067
483.95532	1.4187524	0.40509444	3368.376
484.9563	1.4164987	0.40634817	3361.0908
485.95728	1.4206259	0.40769064	3363.6509
486.95825	1.4258854	0.40903944	3370.3401
487.95923	1.4256096	0.41033038	3364.9863
488.96021	1.4303032	0.41155052	3366.7461
489.96118	1.432438	0.41247872	3360.9785
490.96216	1.4371603	0.41358778	3368.9539
491.96313	1.4390312	0.41481346	3373.9692
492.96411	1.4433571	0.41618836	3375.5503
493.96509	1.4459965	0.41754392	3381.3811
494.96606	1.4486269	0.41894415	3375.27
495.96704	1.4505537	0.42020565	3369.0928
496.96802	1.4541596	0.42139024	3375.4692
497.96899	1.4608912	0.42262635	3373.8091
498.96997	1.459749	0.42371929	3374.6187
499.97095	1.4640259	0.42505431	3377.5471
500.97192	1.4638989	0.4263269	3380.2024
501.9729	1.4686637	0.42754203	3375.2288
502.97388	1.4714373	0.42861512	3379.447
503.97485	1.476707	0.42997718	3383.9998
504.97583	1.4785538	0.43123648	3387.8232
505.97681	1.481174	0.43252835	3383.196
506.97778	1.4844229	0.43382508	3387.5068
507.97876	1.487234	0.43512365	3389.2322
508.97974	1.4901271	0.43601492	3378.2744
509.98071	1.4959491	0.43731016	3390.844
510.98169	1.4989645	0.43863198	3389.8582
511.98267	1.4987328	0.44001931	3399.1729
512.98364	1.5017076	0.44165742	3395.1809
513.98462	1.5048901	0.44322482	3390.3713
514.9856	1.5056992	0.4442986	3385.6248
515.98657	1.5109277	0.44545016	3388.9683
516.98755	1.5135639	0.44653067	3390.2468
517.98853	1.5134758	0.44757992	3384.9299
518.9895	1.5216508	0.44873658	3397.7393
519.99048	1.5235646	0.44998395	3398.656
520.99146	1.5255545	0.45126873	3403.6243
521.99243	1.5303218	0.45255718	3402.6763
522.99341	1.533024	0.45380202	3400.6665
523.99438	1.5365355	0.45513347	3405.7644
524.99536	1.5410593	0.45613977	3399.675
525.99634	1.5415392	0.45725328	3401.4041
526.99731	1.5431933	0.45847365	3405.3804
527.99829	1.5497593	0.45979103	3399.7449
528.99927	1.54809	0.46076477	3397.74
530.00024	1.5556134	0.46203822	3408.8901
531.00122	1.5567076	0.46324897	3407.272
532.0022	1.5605688	0.46473375	3417.5229
533.00317	1.5634134	0.46615496	3407.1208
534.00415	1.5637534	0.46736115	3405.687
535.00513	1.5680298	0.46880463	3412.6584
536.0061	1.5731547	0.47006911	3407.7356
537.00708	1.5743164	0.47122651	3415.6555
538.00806	1.5759937	0.4726252	3412.0918
539.00903	1.5817143	0.47371128	3411.1172
540.01001	1.5837665	0.47514814	3418.7559
541.01099	1.585927	0.47670263	3424.2849
542.01196	1.5880514	0.47827783	3416.7246
543.01294	1.594403	0.47959498	3418.334
544.01392	1.5954041	0.48081547	3416.2876
545.01489	1.6000288	0.48214808	3417.429
546.01587	1.6003934	0.48351055	3417.8333
547.01685	1.6058006	0.48467579	3421.04
548.01782	1.6054971	0.4858503	3422.0859
549.0188	1.6115047	0.48709852	3424.2151
550.01978	1.6149389	0.48852479	3423.873
551.02075	1.6189307	0.48976573	3427.4473
552.02173	1.6195399	0.49099058	3421.5547
553.02271	1.6231471	0.49230427	3427.0969
554.02368	1.624215	0.49354368	3424.7012
555.02466	1.6291839	0.49474645	3430.1812
556.02563	1.6313872	0.49594665	3424.6509
557.02661	1.6354134	0.49743259	3436.3008
558.02759	1.639019	0.49882945	3427.5374
559.02856	1.6403313	0.50003982	3433.1572
560.02954	1.6454133	0.50135064	3432.6443
561.03052	1.6469549	0.50253713	3426.6067
562.03149	1.6477009	0.50349784	3426.5049
563.03247	1.6566429	0.50473011	3436.4297
564.03345	1.6558559	0.50588393	3438.3723
565.03442	1.6557676	0.50742137	3440.0669
566.0354	1.6617103	0.50879675	3437.063
567.03638	1.6651454	0.51000178	3435.7979
568.03735	1.6681968	0.51127344	3437.4446
569.03833	1.6730248	0.5123834	3438.2227
570.03931	1.6745424	0.51346469	3441.6221
571.04028	1.6790478	0.51496112	3450.6895
572.04126	1.6792738	0.51634079	3447.0769
573.04224	1.6824783	0.51756275	3451.1279
574.04321	1.6873536	0.51873428	3441.042
575.04419	1.6890018	0.5202533	3449.2969
576.04517	1.6924119	0.52174824	3448.9661
577.04614	1.6974943	0.52305979	3446.6335
578.04712	1.6987559	0.52439857	3449.3333
579.0481	1.7023414	0.52581227	3453.9783
580.04907	1.7016094	0.52711487	3447.6555
581.05005	1.7079048	0.52864754	3460.7407
582.05103	1.709689	0.53001416	3446.6279
583.052	1.710946	0.53122401	3442.6956
584.05298	1.714058	0.53239298	3448.5708
585.05396	1.7168934	0.5337587	3454.0125
586.05493	1.7232155	0.53531587	3458.481
587.05591	1.7246804	0.53653812	3452.7476
588.05688	1.7293806	0.53780115	3458.1709
589.05786	1.7310835	0.53919959	3459.5583
590.05884	1.7317185	0.54042	3451.1731
591.05981	1.7396392	0.54188621	3461.0696
592.06079	1.7397078	0.5432235	3460.1592
593.06177	1.7441525	0.54450113	3462.7534
594.06274	1.7448217	0.54555058	3454.624
595.06372	1.7489305	0.54644978	3447.7241
596.0647	1.7521164	0.54746461	3451.5327
597.06567	1.7565401	0.54863667	3464.0598
598.06665	1.7590327	0.54988414	3465.8059
599.06763	1.7617577	0.55111378	3468.8569
600.0686	1.7630539	0.55241466	3464.4646
601.06958	1.7663507	0.55372894	3466.9675
602.07056	1.7718204	0.55536073	3475.1912
603.07153	1.773585	0.55655777	3463.531
604.07251	1.7763613	0.55809057	3471.9548
605.07349	1.7787602	0.55968183	3473.7673
606.07446	1.7849851	0.56146562	3472.6621
607.07544	1.7845542	0.56259203	3468.0862
608.07642	1.7899815	0.56367397	3467.0398
609.07739	1.7927654	0.56497872	3474.9338
610.07837	1.7966181	0.56626171	3477.7214
611.07935	1.7971182	0.56769383	3477.7629
612.08032	1.8001223	0.56886399	3472.937
613.0813	1.8036646	0.56992602	3470.5476
614.08228	1.8055489	0.57088763	3472.3206
615.08325	1.8075966	0.57245994	3479.6606
616.08423	1.8136333	0.57418346	3487.6887
617.08521	1.8151828	0.57540339	3472.3899
618.08618	1.8208448	0.57679993	3478.4263
619.08716	1.8207282	0.57807082	3483.1025
620.08813	1.8266025	0.57932198	3488.3311
621.08911	1.8287139	0.58076513	3478.5637
622.09009	1.8307964	0.58226019	3486.3179
623.09106	1.8317461	0.583507	3480.4719
624.09204	1.8372965	0.58496004	3483.1982
625.09302	1.8421909	0.58656895	3484.9783
626.09399	1.8415488	0.58785397	3481.0408
627.09497	1.8439705	0.58928984	3482.0369
628.09595	1.850384	0.59065455	3486.8318
629.09692	1.8508795	0.59193552	3479.1177
630.0979	1.8565701	0.59330863	3486.6433
631.09888	1.8541898	0.59448278	3489.3738
632.09985	1.862281	0.59565169	3486.199
633.10083	1.8617806	0.59701794	3488.6338
634.10181	1.8661815	0.59814948	3482.3884
635.10278	1.8720639	0.59961933	3493.6819
636.10376	1.8703188	0.60086435	3496.9026
637.10474	1.8735925	0.60214311	3493.5234
638.10571	1.8802135	0.603751	3498.7683
639.10669	1.8812649	0.6051839	3490.4463
640.10767	1.8843752	0.60671455	3496.2114
641.10864	1.8871895	0.6082381	3495.1289
642.10962	1.888764	0.60960549	3492.3611
643.1106	1.8915869	0.61077482	3493.7563
644.11157	1.8926145	0.61223853	3502.3862
645.11255	1.8983976	0.61371309	3499.415
646.11353	1.9017882	0.61502755	3498.905
647.1145	1.9046617	0.61637443	3494.6279
648.11548	1.9101132	0.61789906	3507.9756
649.11646	1.9071858	0.61925906	3498.0256
650.11743	1.9162458	0.62059408	3501.0903
651.11841	1.9163225	0.62178367	3493.3635
652.11938	1.9189078	0.62298822	3502.584
653.12036	1.9215629	0.62432277	3499.9021
654.12134	1.9273764	0.62574381	3503.8403
655.12231	1.9287932	0.62721109	3507.3242
656.12329	1.9333068	0.62871981	3507.7537
657.12427	1.935967	0.6302377	3503.6321
658.12524	1.9367144	0.63161445	3500.6445
659.12622	1.9383273	0.63273346	3501.7068
660.1272	1.9441439	0.63424283	3507.5386
661.12817	1.9491233	0.63567793	3510.8599
662.12915	1.9465349	0.63701737	3508.6392
663.13013	1.9562167	0.63841569	3508.8198
664.1311	1.9571606	0.6396367	3507.3367
665.13208	1.9580463	0.64101768	3509.9697
666.13306	1.9596781	0.64232016	3503.0469
667.13403	1.964452	0.64373171	3509.9929
668.13501	1.9678658	0.64505988	3513.9324
669.13599	1.970113	0.64645106	3505.4338
670.13696	1.9722718	0.64788783	3514.8992
671.13794	1.9762548	0.64939684	3515.8372
672.13892	1.9793013	0.65092671	3508.4827
673.13989	1.9819856	0.65227121	3511.8301
674.14087	1.986424	0.65378195	3511.229
675.14185	1.9913892	0.65515965	3514.0408
676.14282	1.9902182	0.65641665	3510.6816
677.1438	1.9951376	0.65788043	3515.2458
678.14478	1.9991335	0.65932685	3520.1628
679.14575	2.0015957	0.66094017	3525.9258
680.14673	2.0039268	0.66240913	3516.1169
681.14771	2.0086739	0.6637857	3517.8062
682.14868	2.0115011	0.66515756	3520.03
683.14966	2.0123012	0.66665804	3517.8564
684.15063	2.0158293	0.66812813	3523.7705
685.15161	2.0208726	0.66962051	3524.9448
686.15259	2.0236893	0.67116004	3529.1963
687.15356	2.0249996	0.6727013	3524.5396
688.15454	2.0290625	0.67410755	3517.769
689.15552	2.0301106	0.67546058	3518.2466
690.15649	2.0335927	0.67683095	3524.947
691.15747	2.0352094	0.67821485	3524.9749
692.15845	2.0407281	0.67979378	3525.6736
693.15942	2.044009	0.68133676	3529.1748
694.1604	2.0476017	0.68288404	3532.05
695.16138	2.0525603	0.68426079	3526.9722
696.16235	2.0526536	0.68559092	3525.2361
697.16333	2.0555561	0.68707651	3524.6201
698.16431	2.059778	0.68855453	3527.575
699.16528	2.0593913	0.68994206	3527.7749
700.16626	2.0626404	0.69150227	3523.9534
701.16724	2.0648351	0.69286662	3520.7358
702.16821	2.071331	0.69427669	3530.1116
703.16919	2.0727396	0.69566804	3528.9087
704.17017	2.0767348	0.69716674	3530.0474
705.17114	2.0797896	0.69873428	3537.1257
706.17212	2.0832269	0.6998992	3531.7153
707.1731	2.0839903	0.70154071	3536.9143
708.17407	2.0897295	0.70305336	3540.1157
709.17505	2.0916886	0.70429862	3530.49
710.17603	2.0942349	0.70585746	3536.8909
711.177	2.0987871	0.7072252	3535.8638
712.17798	2.1002088	0.70863271	3530.9148
713.17896	2.1009164	0.71001625	3526.2031
714.17993	2.1070242	0.71128118	3533.1912
715.18091	2.1073663	0.71268755	3532.842
716.18188	2.1123998	0.71417445	3535.7776
717.18286	2.114696	0.715855	3544.8372
718.18384	2.1159117	0.71767741	3539.8855
719.18481	2.1159823	0.71947849	3534.782
720.18579	2.1281011	0.72103959	3545.8999
721.18677	2.1259778	0.72275513	3542.9475
722.18774	2.1279881	0.72442287	3539.0215
723.18872	2.1353221	0.72589874	3545.9753
724.1897	2.137948	0.72726285	3542.6306
725.19067	2.140907	0.72867715	3545.2188
726.19165	2.1407669	0.73029107	3542.2612
727.19263	2.1425633	0.73188508	3542.8313
728.1936	2.1467428	0.7334978	3544.9023
729.19458	2.1497529	0.73466569	3533.2451
730.19556	2.1541297	0.73627967	3544.3423
731.19653	2.1583419	0.7377333	3550.0444
732.19751	2.1609724	0.73894465	3542.0037
733.19849	2.1635423	0.74033451	3546.4551
734.19946	2.1647594	0.74181944	3546.4832
735.20044	2.1685667	0.7431702	3540.9636
736.20142	2.1746175	0.74454159	3547.72
737.20239	2.1760931	0.74622798	3546.1885
738.20337	2.1778626	0.74757874	3546.7061
739.20435	2.1826699	0.74906743	3553.2219
740.20532	2.1858797	0.75045323	3552.7117
741.2063	2.1860046	0.75197393	3545.0161
742.20728	2.1911111	0.75356418	3547.0081
743.20825	2.1912279	0.7549299	3548.5876
744.20923	2.1946158	0.75667524	3551.2395
745.21021	2.1986625	0.75812733	3545.4995
746.21118	2.2037139	0.75976753	3552.104
747.21216	2.204618	0.76115435	3540.9041
748.21313	2.2092934	0.76268983	3548.6792
749.21411	2.2102358	0.7639966	3549.6873
750.21509	2.2125177	0.76574713	3554.0613
751.21606	2.2177193	0.76730889	3557.3618
752.21704	2.2173793	0.76895636	3553.5066
753.21802	2.2235081	0.77066737	3553.9456
754.21899	2.226979	0.77238625	3551.8538
755.21997	2.2278025	0.77388382	3551.937
756.22095	2.2337217	0.77553761	3561.0952
757.22192	2.2360418	0.77699268	3557.4282
758.2229	2.2381055	0.7785446	3555.9297
759.22388	2.2413962	0.77990323	3549.0059
760.22485	2.2446294	0.78129166	3554.0361
761.22583	2.2486155	0.78287512	3555.676
762.22681	2.2507553	0.7843399	3555.5732
763.22778	2.2521615	0.78623658	3559.0938
764.22876	2.256501	0.7878626	3552.6543
765.22974	2.2620978	0.78950715	3562.1216
766.23071	2.2613883	0.79081047	3551.6575
767.23169	2.2671695	0.79216623	3555.262
768.23267	2.2690387	0.79342872	3558.1416
769.23364	2.2702899	0.79490322	3556.0701
770.23462	2.272635	0.79671454	3562.3054
771.2356	2.2781923	0.79849017	3566.614
772.23657	2.2807784	0.8001948	3561.3269
773.23755	2.2819295	0.80184597	3555.0317
774.23853	2.2880728	0.80337155	3555.9253
775.2395	2.2912955	0.80487978	3563.9343
776.24048	2.2921894	0.80666089	3568.9907
777.24146	2.2953296	0.80833644	3565.6306
778.24243	2.296489	0.80989695	3560.478
779.24341	2.2997172	0.81146538	3564.2805
780.24438	2.3060482	0.81308693	3563.5217
781.24536	2.3066056	0.81467402	3558.2979
782.24634	2.3097489	0.8160851	3561.3682
783.24731	2.3142183	0.81765598	3558.677
784.24829	2.3166077	0.81922543	3560.0935
785.24927	2.3205764	0.82092011	3568.6013
786.25024	2.3233778	0.82259142	3572.0078
787.25122	2.3249769	0.82426274	3564.0303
788.2522	2.3289499	0.82598025	3561.8042
789.25317	2.3331926	0.82756275	3561.2112
790.25415	2.3359849	0.82903755	3567.6355
791.25513	2.3369615	0.83094025	3567.6511
792.2561	2.3413939	0.83266616	3566.7068
793.25708	2.3431454	0.83437335	3568.0532
794.25806	2.3481331	0.83603483	3567.6199
795.25903	2.3498654	0.83780056	3571.3887
796.26001	2.3543816	0.83980542	3574.3433
797.26099	2.3564918	0.84183747	3577.5879
798.26196	2.3614886	0.84348935	3568.8486
799.26294	2.3608432	0.84508413	3568.9014
800.26392	2.3656464	0.84674829	3567.6116
801.26489	2.367646	0.84838367	3569.0342
802.26587	2.3683908	0.85002691	3569.4326
803.26685	2.3706732	0.85139418	3562.5217
804.26782	2.3783183	0.8529312	3573.7502
805.2688	2.3805356	0.85462916	3567.7043
806.26978	2.3809338	0.85622787	3571.2737
807.27075	2.3874085	0.85777372	3567.9927
808.27173	2.3917007	0.85949224	3575.6213
809.27271	2.3918502	0.86128169	3572.0552
810.27368	2.3944197	0.86277103	3565.8672
811.27466	2.3964722	0.86452198	3570.9209
812.27563	2.40222	0.86610663	3566.9146
813.27661	2.4025989	0.8676303	3571.6084
814.27759	2.4060862	0.86911607	3569.7427
815.27856	2.4085367	0.87096834	3575.4578
816.27954	2.4145534	0.87255538	3570.168
817.28052	2.4138784	0.874102	3569.3025
818.28149	2.4177494	0.87585771	3578.5645
819.28247	2.4223819	0.87736124	3573.9211
820.28345	2.4233534	0.87924087	3577.5229
821.28442	2.427798	0.88104683	3576.6943
822.2854	2.4292591	0.88279021	3573.7642
823.28638	2.435004	0.88458622	3570.9326
824.28735	2.4355791	0.88593125	3567.896
825.28833	2.4416714	0.88761622	3575.6755
826.28931	2.4437797	0.88986468	3584.0212
827.29028	2.4458749	0.89197284	3583.2104
828.29126	2.4493821	0.89404964	3579.3723
829.29224	2.4501133	0.89577007	3571.7646
830.29321	2.4543495	0.89747155	3577.6746
831.29419	2.4576318	0.89948964	3576.168
832.29517	2.4591081	0.9011451	3569.7798
833.29614	2.4626806	0.90281284	3571.7305
834.29712	2.466604	0.90457058	3574.9915
835.2981	2.4699872	0.90640348	3576.6978
836.29907	2.4726031	0.90805769	3575.0803
837.30005	2.4770129	0.90977734	3579.2419
838.30103	2.4819212	0.9114446	3581.6611
839.302	2.4791441	0.91303879	3570.9404
840.30298	2.4853954	0.91474539	3575.05
841.30396	2.4889307	0.91660738	3575.7822
842.30493	2.4896431	0.91832435	3573.3792
843.30591	2.4948277	0.92000079	3574.7051
844.30688	2.4953804	0.92202812	3579.7615
845.30786	2.5004501	0.92386866	3579.0811
846.30884	2.5033884	0.92582113	3575.3582
847.30981	2.5034366	0.92758298	3573.2708
848.31079	2.5082772	0.92971665	3584.7529
849.31177	2.5115998	0.93162405	3579.9233
850.31274	2.5148339	0.93366486	3580.9412
851.31372	2.519223	0.93569237	3580.762
852.3147	2.5203216	0.93717498	3571.7844
853.31567	2.5251093	0.93906498	3582.3127
854.31665	2.5292549	0.94116527	3586.658
855.31763	2.5322323	0.94288725	3579.3525
856.3186	2.5337214	0.94465625	3580.7502
857.31958	2.5356038	0.94633114	3583.1978
858.32056	2.5374718	0.94807357	3575.6892
859.32153	2.538445	0.94976234	3576.1423
860.32251	2.5456295	0.95153326	3579.7463
861.32349	2.5465446	0.95338851	3582.0901
862.32446	2.5486813	0.95538521	3579.8521
863.32544	2.5518382	0.95724642	3580.2212
864.32642	2.5584433	0.95914787	3584.4763
865.32739	2.5591443	0.96113598	3582.7329
866.32837	2.5642848	0.96280628	3580.1169
867.32935	2.5622182	0.96440101	3572.1667
868.33032	2.5651362	0.96609634	3578.4668
869.3313	2.5730331	0.96796316	3582.7485
870.33228	2.5729563	0.97004181	3580.7109
871.33325	2.5771968	0.97227424	3582.8831
872.33423	2.580977	0.97430617	3579.4155
873.33521	2.5824714	0.97598344	3575.6699
874.33618	2.5851119	0.97783589	3585.0452
875.33716	2.5882359	0.97970158	3585.1511
876.33813	2.5927582	0.98204631	3583.2661
877.33911	2.5965972	0.98383516	3581.2837
878.34009	2.5983717	0.98574263	3576.1072
879.34106	2.6031716	0.98735493	3582.8503
880.34204	2.6034272	0.98913848	3581.0076
881.34302	2.6085386	0.99096674	3584.4858
882.34399	2.6115158	0.99269998	3582.2158
883.34497	2.6156425	0.99453151	3583.9819
884.34595	2.6164284	0.99665612	3587.8845
885.34692	2.6227994	0.99854392	3584.5662
886.3479	2.6220257	1.000932	3580.5232
887.34888	2.627979	1.0026503	3581.2463
888.34985	2.6267877	1.0045745	3575.616
889.35083	2.6340964	1.0061672	3585.7869
890.35181	2.6351464	1.0082349	3584.5369
891.35278	2.6376359	1.0105973	3584.4146
892.35376	2.6432414	1.0129195	3580.1721
893.35474	2.6429338	1.0148425	3580.2578
894.35571	2.6466169	1.0170871	3582.4058
895.35669	2.6454027	1.0189134	3576.5132
896.35767	2.6521175	1.0206988	3581.6807
897.35864	2.6555595	1.0225499	3576.9006
898.35962	2.6592605	1.0245614	3585.0098
899.3606	2.6634219	1.0267831	3589.333
900.36157	2.6664484	1.0289022	3583.6074
901.36255	2.6670175	1.0311184	3582.5146
902.36353	2.6702321	1.0331167	3584.8325
903.3645	2.6765745	1.0353647	3588.4429
904.36548	2.6770389	1.0373906	3582.3997
905.36646	2.6786096	1.0395145	3579.8115
906.36743	2.6823518	1.0418173	3586.7239
907.36841	2.6866448	1.0443124	3582.3442
908.36938	2.6905708	1.0462443	3575.5662
909.37036	2.6930449	1.0479854	3584.5691
910.37134	2.6946232	1.0499852	3579.5203
911.37231	2.6977272	1.0520867	3584.5918
912.37329	2.6996596	1.0541338	3579.3589
913.37427	2.7024748	1.0561626	3578.3643
914.37524	2.705617	1.0583212	3579.427
915.37622	2.7103057	1.0605395	3583.2734
916.3772	2.7146242	1.0629747	3582.9331
917.37817	2.7189	1.0649344	3578.2676
918.37915	2.7185583	1.0671866	3579.938
919.38013	2.721766	1.0694188	3583.3032
920.3811	2.7251861	1.0716916	3576.8279
921.38208	2.7270744	1.0738573	3581.7922
922.38306	2.73084	1.0761366	3577.5715
923.38403	2.7325013	1.0783979	3575.0996
924.38501	2.7373993	1.0801641	3583.3953
925.38599	2.7406285	1.0826669	3584.6401
926.38696	2.7425096	1.0852145	3577.9111
927.38794	2.7446434	1.0875971	3582.5186
928.38892	2.7512538	1.0896709	3578.1482
929.38989	2.753432	1.0917307	3583.6863
930.39087	2.7563715	1.0941244	3582.4512
931.39185	2.7576261	1.096212	3576.7495
932.39282	2.7630587	1.0984186	3578.7393
933.3938	2.7640178	1.100637	3582.7319
934.39478	2.7675624	1.1026599	3579.8716
935.39575	2.7703917	1.1053429	3584.7761
936.39673	2.7756243	1.107885	3581.7117
937.39771	2.7750192	1.1102087	3581.6838
938.39868	2.7805202	1.112716	3579.7224
939.39966	2.7819502	1.1150914	3573.3418
940.40063	2.7842269	1.1169831	3578.2161
941.40161	2.7891245	1.1193511	3579.8569
942.40259	2.7896781	1.1217233	3573.0154
943.40356	2.794435	1.1240671	3578.6335
944.40454	2.7962573	1.1263137	3576.5171
945.40552	2.8009651	1.1283767	3578.4087
946.40649	2.8052535	1.130911	3576.9827
947.40747	2.8043427	1.1331211	3568.6587
948.40845	2.8108544	1.1352524	3574.2563
949.40942	2.8128684	1.1378151	3579.7288
950.4104	2.8176591	1.1401677	3579.5571
951.41138	2.8146877	1.1427362	3574.8882
952.41235	2.822787	1.1450907	3577.6565
953.41333	2.8220415	1.1473778	3575.3232
954.41431	2.827848	1.1496342	3572.3237
955.41528	2.830153	1.15207	3573.2544
956.41626	2.8349771	1.154696	3577.5371
957.41724	2.83517	1.1572033	3566.7876
958.41821	2.8390627	1.1595135	3577.2192
959.41919	2.8430519	1.1618741	3575.5496
960.42017	2.8481047	1.1640909	3571.6748
961.42114	2.8467159	1.1665817	3577.9597
962.42212	2.852103	1.168957	3567.9263
963.4231	2.8561282	1.1714305	3572.1382
964.42407	2.8579974	1.1736425	3571.7166
965.42505	2.8600819	1.1757118	3569.0313
966.42603	2.8622026	1.1781564	3570.9976
967.427	2.8670406	1.1805918	3571.3174
968.42798	2.8687296	1.1835082	3570.3418
969.42896	2.8730841	1.1864291	3574.6519
970.42993	2.8760517	1.1891743	3570.7825
971.43091	2.8768115	1.1917127	3568.3184
972.43188	2.8820312	1.1943265	3563.4797
973.43286	2.8850584	1.1968077	3570.5815
974.43384	2.8873565	1.1997792	3575.8984
975.43481	2.8931882	1.202687	3571.626
976.43579	2.8930628	1.2051167	3561.9446
977.43677	2.8943653	1.2074522	3560.9092
978.43774	2.8974521	1.2100968	3564.6418
979.43872	2.9035623	1.2126782	3570.7268
980.4397	2.9039578	1.216058	3571.0864
981.44067	2.907469	1.2195697	3569.2205
982.44165	2.9122093	1.2224191	3557.4229
983.44263	2.912667	1.2249174	3555.0522
984.4436	2.9194062	1.2276371	3563.5681
985.44458	2.9214597	1.2302227	3561.8574
986.44556	2.9229269	1.2329453	3560.4075
987.44653	2.9268086	1.2355092	3559.2949
988.44751	2.9300148	1.2379168	3554.946
989.44849	2.9329998	1.2402046	3557.7954
990.44946	2.9321306	1.2428108	3558.7375
991.45044	2.9394047	1.2455033	3557.5913
992.45142	2.9433663	1.2485985	3566.7773
993.45239	2.9422758	1.2510719	3556.9556
994.45337	2.9467518	1.2539451	3561.9302
995.45435	2.9513903	1.2566072	3550.96
996.45532	2.9530325	1.2592399	3550.2832
997.4563	2.9559579	1.2620714	3558.3926
998.45728	2.960444	1.2651643	3553.6482
999.45825	2.9600787	1.2679886	3552.2358
1000.4592	2.9654441	1.2706145	3552.1208
1001.4602	2.9678288	1.2734902	3555.3987
1002.4612	2.9732265	1.2765896	3554.7981
1003.4622	2.9742229	1.2799934	3550.0564
1004.4631	2.9778597	1.2826751	3548.1755
1005.4641	2.9819896	1.2852263	3553.9583
1006.4651	2.9818678	1.288184	3547.7266
1007.4661	2.9862411	1.2907035	3547.8113
1008.467	2.9904468	1.2939647	3556.2205
1009.468	2.9929357	1.2969174	3537.9626
1010.469	2.9970686	1.2995781	3548.04
1011.47	2.9972985	1.3020076	3541.344
1012.4709	3.0031662	1.3051816	3551.4644
1013.4719	3.0022736	1.3084667	3540.3784
1014.4729	3.0089538	1.311669	3544.3665
1015.4739	3.0084176	1.3143706	3531.6953
1016.4749	3.013057	1.317058	3537.9507
1017.4758	3.0177681	1.3197533	3546.5244
1018.4768	3.0174894	1.3229086	3537.8088
1019.4778	3.023766	1.3261396	3539.2329
1020.4788	3.0248449	1.3289324	3527.3469
1021.4797	3.0295999	1.3316263	3536.7085
1022.4807	3.0289533	1.3347828	3533.52
1023.4817	3.0339544	1.3380038	3530.9368
1024.4827	3.0387995	1.3409837	3528.3083
1025.4836	3.0417879	1.3433927	3525.9028
1026.4846	3.0417571	1.3461515	3527.0706
1027.4856	3.0483046	1.3489465	3540.2993
1028.4866	3.0498343	1.3516271	3527.7554
1029.4875	3.0532608	1.3546886	3522.2625
1030.4885	3.0555563	1.3580074	3526.4436
1031.4895	3.0575635	1.3611752	3521.1611
1032.4905	3.0584559	1.3642253	3522.6958
1033.4915	3.0622761	1.3673445	3519.0889
1034.4924	3.0665665	1.3700753	3506.8677
1035.4934	3.0719399	1.3720229	3513.043
1036.4944	3.0697405	1.3743788	3506.7769
1037.4954	3.0728343	1.3764135	3509.6882
1038.4963	3.0817754	1.3789618	3514.6267
1039.4973	3.0842202	1.3819765	3517.0825
1040.4983	3.0854175	1.384497	3507.7856
1041.4993	3.0897942	1.3872868	3507.1128
1042.5002	3.0911963	1.389809	3507.6018
1043.5012	3.0941525	1.3931022	3509.303
1044.5022	3.0973895	1.3963475	3503.3984
1045.5032	3.0994601	1.3992891	3498.5803
1046.5042	3.1044564	1.4022816	3504.5701
1047.5051	3.1042488	1.4056886	3502.2588
1048.5061	3.1100271	1.4093171	3499.7065
1049.5071	3.1113346	1.4122303	3496.9907
1050.5081	3.1151161	1.415086	3495.9043
1051.509	3.1191866	1.4181068	3488.252
1052.51	3.1223314	1.4204365	3494.3562
1053.511	3.1228187	1.4232242	3495.1868
1054.512	3.1288261	1.4263506	3489.561
1055.5129	3.1297591	1.4293149	3489.9924
1056.5139	3.1342399	1.4324794	3485.9922
1057.5149	3.1381671	1.4359969	3484.9834
1058.5159	3.1395099	1.4387473	3480.1104
1059.5168	3.1431022	1.4416072	3475.0405
1060.5178	3.1430547	1.4447328	3472.2261
1061.5188	3.1475818	1.4477874	3472.0796
1062.5198	3.1517503	1.4506968	3467.8042
1063.5208	3.1538391	1.4537643	3470.9871
1064.5217	3.1568215	1.4571604	3466.9912
1065.5227	3.1593788	1.4599987	3461.6592
1066.5237	3.1626372	1.4625477	3461.5098
1067.5247	3.1691942	1.4659623	3468.3237
1068.5256	3.1682496	1.4692898	3459.5591
1069.5266	3.1722474	1.4728858	3459.0325
1070.5276	3.1752846	1.4761212	3452.2585
1071.5286	3.1786447	1.4796053	3455.2292
1072.5295	3.1809449	1.4829206	3449.9075
1073.5305	3.1844792	1.48616	3442.3369
1074.5315	3.1881316	1.4893796	3447.4243
1075.5325	3.1891286	1.4930402	3441.7673
1076.5334	3.1965239	1.4963586	3440.0837
1077.5344	3.1978853	1.4995955	3435.8564
1078.5354	3.1985393	1.5030082	3434.0071
1079.5364	3.2012367	1.5065106	3428.3599
1080.5374	3.2032695	1.5091656	3422.5623
1081.5383	3.210892	1.5122221	3428.2632
1082.5393	3.2118094	1.5159426	3426.2273
1083.5403	3.2165854	1.5189736	3422.4341
1084.5413	3.2161279	1.5216565	3412.0044
1085.5422	3.2202139	1.525141	3419.3425
1086.5432	3.2225723	1.5282217	3406.9509
1087.5442	3.2240546	1.5315038	3411.0869
1088.5452	3.2292352	1.5348065	3405.0908
1089.5461	3.2327077	1.538136	3406.8945
1090.5471	3.2345302	1.5420787	3394.8684
1091.5481	3.2377391	1.5458692	3393.6572
1092.5491	3.2425561	1.5493459	3386.0703
1093.55	3.2437053	1.552452	3381.7434
1094.551	3.247308	1.5554212	3379.0291
1095.552	3.2473893	1.5585704	3370.3096
1096.553	3.2539315	1.5610584	3362.8362
1097.554	3.2591963	1.5637895	3368.7275
1098.5549	3.260721	1.5669675	3366.4221
1099.5559	3.2606413	1.5708265	3355.9263
1100.5569	3.2661562	1.5741709	3352.5068
1101.5579	3.268564	1.5773364	3350.8621
1102.5588	3.2708666	1.5806284	3346.1272
1103.5598	3.2760749	1.5836127	3337.0686
1104.5608	3.2796302	1.5866917	3342.052
1105.5618	3.2816591	1.5900029	3334.2495
1106.5627	3.2837615	1.5925362	3326.8774
1107.5637	3.2860737	1.5949229	3324.9204
1108.5647	3.2884586	1.597191	3315.5562
1109.5657	3.2901874	1.5996259	3309.9553
1110.5667	3.294806	1.6032035	3299.9604
1111.5676	3.2980347	1.6069634	3296.5466
1112.5686	3.3017564	1.6107908	3294.3057
1113.5696	3.3047659	1.6166714	3265.2385
1114.5706	3.3105633	1.627816	3170.0393
1115.5715	3.3121986	1.644488	3005.0571
1115.6716	3.3145149	1.6484925	2947.5747