File: datasets/am_bench_2022/raw_data/0-X.20-4/specimen.dat
MTS793|MPT|ENU|1|2|.|/|:|1|0|0|A

Operator Information						Time:	33.304199	Sec	10/13/2021 11:35:19 AM
Operator	Nick Derimow
Project	AM Bench 2022 mini-tensile challenge
Specimen ID	0-X.20-4
Material	PBF-L Inconel 625
Specimen Width	2.55	mm
Specimen Thickness	1.54	mm
Notes
Operator Information End

Data Acquisition						Time:	1034.2981	Sec	10/13/2021 11:52:00 AM
Time	Axial Displacement	Axial Extensometer	Axial Force
Sec	mm	mm	N
33.417969	-0.0027132456	-0.00010674247	69.98391
34.418945	0.0013103521	4.3862638e-05	77.778351
35.419922	0.0030500812	9.2917631e-05	93.261566
36.420898	0.0044324808	0.00016932045	110.30416
37.421875	0.010609021	0.00025022676	125.92393
38.422852	0.012727543	0.00021527646	135.12773
39.423828	0.0152225	0.00028159455	147.10808
40.424805	0.017261164	0.00031021782	162.88797
41.425781	0.018628197	0.00037638532	173.09094
42.426758	0.021632053	0.00057979801	198.93683
43.427734	0.026201019	0.00060889253	219.11732
44.428711	0.02908445	0.00052935485	235.7682
45.429688	0.031732049	0.00070257171	249.93324
46.430664	0.033401042	0.00085309485	274.74414
47.431641	0.03807148	0.00076065317	298.69806
48.432617	0.03789179	0.0010250784	314.44614
49.433594	0.047236353	0.0010016972	341.70801
50.43457	0.046324998	0.0010083151	357.58676
51.435547	0.05222581	0.001047858	382.60681
52.436523	0.055147503	0.0011134017	401.93686
53.4375	0.054456405	0.0012811818	420.43869
54.438477	0.059448112	0.0012359296	442.76682
55.439453	0.062560968	0.0014614838	461.36044
56.44043	0.06662821	0.0015924193	494.31113
57.441406	0.065150999	0.0015697953	509.6882
58.442383	0.069799103	0.0016904627	530.07825
59.443359	0.071997583	0.0018285695	561.68317
60.444336	0.074957177	0.0018824067	573.96826
61.445313	0.08102943	0.0019462784	610.76892
62.446289	0.083859183	0.00221433	632.27087
63.447266	0.085478023	0.002215801	662.11255
64.448242	0.089076065	0.0023636485	693.08911
65.449219	0.093638681	0.0023629109	719.19733
66.450195	0.09394069	0.0025450168	746.56274
67.451172	0.097359091	0.002679202	772.58435
68.452148	0.10225552	0.0027749834	799.98541
69.453125	0.102948	0.0029350177	818.39636
70.454102	0.10850275	0.003000766	849.94879
71.455078	0.10655198	0.0030515995	875.50818
72.456055	0.10955609	0.0030608934	901.0708
73.457031	0.11447691	0.0033581872	934.65765
74.458008	0.12213563	0.0034271975	964.52203
75.458984	0.12261385	0.003399574	990.39465
76.459961	0.12395608	0.0036891433	1019.6328
77.460938	0.12406857	0.0036557133	1034.6479
78.461914	0.13030842	0.0038229884	1063.5481
79.462891	0.13380873	0.0039508231	1095.4922
80.463867	0.13475737	0.0040773	1126.8026
81.464844	0.13920371	0.0042610443	1156.9407
82.46582	0.14526142	0.0043263463	1198.7393
83.466797	0.14790405	0.0045590266	1216.7278
84.467773	0.14881787	0.0046433709	1248.5437
85.46875	0.15417592	0.0048025935	1286.859
86.469727	0.15649323	0.0048232344	1306.0151
87.470703	0.15682039	0.0049441559	1332.1505
88.47168	0.16166519	0.0052054338	1371.9066
89.472656	0.16323896	0.0052206982	1390.5219
90.473633	0.16529524	0.0054853898	1416.7036
91.474609	0.1715896	0.0055901157	1447.5842
92.475586	0.17282468	0.0055912547	1469.7891
93.476563	0.17769346	0.0056857495	1508.1462
94.477539	0.17673764	0.0060060117	1533.0742
95.478516	0.1842179	0.006074768	1561.2911
96.479492	0.18189675	0.0060900976	1577.557
97.480469	0.1912999	0.0063279606	1610.4581
98.481445	0.19239914	0.0064040152	1636.2069
99.482422	0.19045617	0.0064362856	1656.8568
100.4834	0.19428614	0.0066015157	1685.1306
101.48438	0.20163527	0.0068159075	1724.3676
102.48535	0.20150845	0.0068737967	1738.9423
103.48633	0.2063158	0.0070324335	1762.5862
104.4873	0.20881009	0.007167812	1794.2167
105.48828	0.21257307	0.0073017143	1818.7006
106.48926	0.21724208	0.0075250682	1846.5509
107.49023	0.21805651	0.0076126619	1878.3251
108.49121	0.22044796	0.0077581941	1894.1344
109.49219	0.22181499	0.0079007763	1919.741
110.49316	0.22640736	0.007997144	1946.2754
111.49414	0.23187564	0.0081686033	1966.1392
112.49512	0.23137878	0.0084085763	1997
113.49609	0.23439083	0.0083191711	2013.5408
114.49707	0.23919158	0.0084781563	2044.0347
115.49805	0.24457607	0.0088225864	2067.0767
116.49902	0.24589679	0.0089882882	2091.4321
117.5	0.24788582	0.0091148317	2108.4204
118.50098	0.25030926	0.0092554716	2129.8015
119.50195	0.25335801	0.0094664777	2149.8936
120.50293	0.2541599	0.0095641231	2163.7971
121.50391	0.26239216	0.0097902641	2191.2236
122.50488	0.26466292	0.0099782851	2206.6934
123.50586	0.26465309	0.010144074	2228.2634
124.50684	0.26963821	0.010320589	2247.5242
125.50781	0.27554581	0.010612223	2260.4658
126.50879	0.27615288	0.010750953	2280.5776
127.50977	0.27859062	0.01099752	2296.0586
128.51074	0.28199342	0.011153355	2303.9805
129.51172	0.28645757	0.011450333	2327.8215
130.5127	0.28874594	0.011644124	2334.4492
131.51367	0.29056928	0.011881402	2356.312
132.51465	0.29049939	0.012280197	2365.427
133.51563	0.29835051	0.012509258	2376.0857
134.5166	0.29768831	0.012811084	2397.521
135.51758	0.3012464	0.013103608	2404.6897
136.51855	0.30391327	0.013515823	2414.5305
137.51953	0.30722588	0.013831524	2427.0977
138.52051	0.30948845	0.014226241	2441.5039
139.52148	0.3155669	0.014822369	2460.4832
140.52246	0.31653315	0.015216263	2461.0867
141.52344	0.31764469	0.0155486	2469.2344
142.52441	0.32553208	0.015935143	2483.3604
143.52539	0.32696077	0.01651095	2495.4888
144.52637	0.33125928	0.017131869	2511.5271
145.52734	0.33382615	0.017683532	2514.7861
146.52832	0.33509848	0.018462867	2523.0605
147.5293	0.33895841	0.019011727	2529.1167
148.53027	0.34327215	0.019709639	2545.5684
149.53125	0.34458771	0.02042241	2549.9534
150.53223	0.34658599	0.021203814	2553.7644
151.5332	0.34950092	0.021934589	2556.5901
152.53418	0.35174757	0.022875298	2565.531
153.53516	0.35590905	0.023788262	2570.0977
154.53613	0.36015639	0.024576468	2576.8047
155.53711	0.3631832	0.02560571	2586.0747
156.53809	0.36704662	0.026315821	2589.1563
157.53906	0.36680096	0.027548058	2591.6775
158.54004	0.37326905	0.028453264	2598.4321
159.54102	0.37382719	0.029347332	2599.575
160.54199	0.37611473	0.030304154	2608.3262
161.54297	0.38199198	0.031240925	2613.0522
162.54395	0.38730413	0.032319847	2619.4004
163.54492	0.38727218	0.033449776	2616.5444
164.5459	0.39273819	0.034829866	2628.5552
165.54688	0.39393416	0.036055449	2628.4946
166.54785	0.39750248	0.037287474	2632.4749
167.54883	0.40261114	0.038537763	2638.3599
168.5498	0.40247938	0.039794408	2638.8708
169.55078	0.40451518	0.040893987	2637.6213
170.55176	0.40748486	0.041801862	2635.0352
171.55273	0.40816656	0.043135617	2640.2822
172.55371	0.41606125	0.044694338	2662.3667
173.55469	0.4146781	0.046021841	2647.7253
174.55566	0.42398104	0.047618646	2661.5535
175.55664	0.4227933	0.048979972	2659.7646
176.55762	0.4260709	0.050271388	2658.7231
177.55859	0.4313097	0.051675182	2666.8884
178.55957	0.43191618	0.053324893	2667.9902
179.56055	0.4373439	0.054984339	2671.6123
180.56152	0.44024181	0.056509208	2676.3062
181.5625	0.44126812	0.058196303	2673.2307
182.56348	0.44463462	0.059513811	2671.0261
183.56445	0.44976526	0.061133716	2679.5652
184.56543	0.44904855	0.062771849	2681.5242
185.56641	0.45453465	0.064611584	2684.5576
186.56738	0.45646939	0.066172533	2679.1545
187.56836	0.45962265	0.067321777	2678.9236
188.56934	0.46281275	0.068907253	2689.1311
189.57031	0.46553877	0.070619754	2688.3696
190.57129	0.46790302	0.072367005	2689.1443
191.57227	0.47253063	0.073839366	2697.3733
192.57324	0.47508687	0.075644262	2694.2046
193.57422	0.47662655	0.0769464	2690.9063
194.5752	0.47927779	0.078317702	2692.2319
195.57617	0.48311925	0.079980679	2701.7639
196.57715	0.48791164	0.081361085	2700.8008
197.57813	0.48809564	0.082784511	2700.9868
198.5791	0.49593154	0.084787786	2709.8879
199.58008	0.49920917	0.08619877	2711.4919
200.58105	0.49608481	0.087963484	2706.0164
201.58203	0.5028156	0.089581542	2708.0054
202.58301	0.50438547	0.091202341	2713.0977
203.58398	0.50884426	0.092572324	2707.1462
204.58496	0.51017886	0.094163992	2712.2224
205.58594	0.51361203	0.09575896	2716.9963
206.58691	0.514799	0.097615533	2715.3914
207.58789	0.52066225	0.099185877	2711.6841
208.58887	0.5208782	0.10058235	2713.7034
209.58984	0.52706808	0.1023588	2727.5
210.59082	0.52474445	0.10406383	2717.6575
211.5918	0.53474897	0.1059186	2726.5537
212.59277	0.53477168	0.10768062	2721.041
213.59375	0.53650093	0.10967272	2725.1604
214.59473	0.54157978	0.11152694	2728.2793
215.5957	0.54367572	0.11318836	2731.1067
216.59668	0.54766595	0.11518212	2728.5825
217.59766	0.5501641	0.1167613	2723.7886
218.59863	0.55357784	0.1183116	2724.9707
219.59961	0.55605102	0.12029301	2734.99
220.60059	0.56061488	0.12212226	2738.5686
221.60156	0.56149143	0.1239131	2732.6836
222.60254	0.56320179	0.12575598	2732.1555
223.60352	0.57018012	0.12755865	2738.5088
224.60449	0.57066226	0.12910765	2735.5522
225.60547	0.57567507	0.13093844	2736.6201
226.60645	0.57617289	0.13291247	2739.4951
227.60742	0.57861274	0.13466398	2742.3164
228.6084	0.57918686	0.13607571	2744.7891
229.60938	0.58522838	0.13812388	2751.283
230.61035	0.58400214	0.14014013	2742.1106
231.61133	0.59106874	0.14198165	2746.3701
232.6123	0.59487623	0.14375223	2751.3555
233.61328	0.59812349	0.14558412	2753.053
234.61426	0.6002875	0.14703001	2741.4751
235.61523	0.60436189	0.14856341	2747.71
236.61621	0.60916024	0.15008673	2752.0759
237.61719	0.60929012	0.15186033	2751.9092
238.61816	0.61281461	0.15324229	2747.2324
239.61914	0.61625385	0.15463379	2757.1462
240.62012	0.61777776	0.15691827	2765.615
241.62109	0.62351221	0.15878335	2760.4041
242.62207	0.62403595	0.1607344	2756.696
243.62305	0.62816912	0.16213064	2760.9089
244.62402	0.62933046	0.1638224	2748.8533
245.625	0.63390785	0.16513242	2763.686
246.62598	0.63771552	0.16697741	2766.3503
247.62695	0.64290476	0.16871841	2765.3799
248.62793	0.64445406	0.17018226	2760.2983
249.62891	0.64458442	0.17205575	2769.948
250.62988	0.64848	0.17411359	2769.5078
251.63086	0.65400743	0.17645805	2775.1357
252.63184	0.65386587	0.17838217	2775.1458
253.63281	0.65810931	0.18012093	2765.3342
254.63379	0.66099846	0.18198939	2769.3604
255.63477	0.66361058	0.1835902	2775.0071
256.63574	0.66714305	0.18524876	2767.2429
257.63672	0.67039973	0.18684426	2775.7461
258.6377	0.67488682	0.18858764	2775.1694
259.63867	0.6740464	0.19035582	2775.7205
260.63965	0.68003589	0.19246133	2782.249
261.64063	0.68258268	0.19460586	2781.0146
262.6416	0.68307441	0.1960886	2769.7048
263.64258	0.68814784	0.19786994	2782.9053
264.64355	0.69532835	0.19955602	2786.4492
265.64453	0.69235623	0.20135581	2781.2878
266.64551	0.69834328	0.20297961	2780.2397
267.64648	0.70113778	0.20436902	2780.4421
268.64746	0.70335287	0.20599145	2781.8967
269.64844	0.70789599	0.20772833	2792.3003
270.64941	0.71042168	0.20960937	2796.2417
271.65039	0.71271932	0.21164359	2792.1301
272.65137	0.7175383	0.2139146	2790.4136
273.65234	0.71988958	0.21568586	2790.7131
274.65332	0.72113466	0.21728255	2791.9258
275.6543	0.72328478	0.21890743	2793.8994
276.65527	0.72828412	0.2206333	2794.8975
277.65625	0.73181367	0.22236635	2795.9426
278.65723	0.73277241	0.22414188	2793.614
279.6582	0.73749828	0.22616453	2803.7944
280.65918	0.74153179	0.22779353	2794.907
281.66016	0.74281073	0.2293444	2800.1006
282.66113	0.74525625	0.23135161	2799.384
283.66211	0.74858463	0.23292014	2799.7705
284.66309	0.75410765	0.23483305	2812.5422
285.66406	0.75541461	0.23683906	2807.2749
286.66504	0.75879955	0.23901375	2803.8713
287.66602	0.76354009	0.24091449	2811.1804
288.66699	0.76491201	0.24254295	2804.957
289.66797	0.76827937	0.24429266	2805.343
290.66895	0.77167457	0.24609201	2808.2144
291.66992	0.76955521	0.24774671	2805.1487
292.6709	0.77489334	0.2496575	2804.2515
293.67188	0.77795559	0.25141174	2811.6133
294.67285	0.78219068	0.253461	2815.7036
295.67383	0.78726518	0.25504905	2810.98
296.6748	0.78948635	0.25706944	2817.6167
297.67578	0.79307067	0.25896212	2820.4783
298.67676	0.79147232	0.26097691	2814.1501
299.67773	0.79512447	0.26300704	2817.2468
300.67871	0.80053395	0.26497445	2812.6882
301.67969	0.80030859	0.26626381	2810.0271
302.68066	0.80446368	0.26781967	2813.658
303.68164	0.80979413	0.26958022	2819.1006
304.68262	0.81282091	0.27142644	2822.8621
305.68359	0.81721151	0.27318308	2827.822
306.68457	0.81954515	0.27498159	2826.4211
307.68555	0.82179052	0.27674839	2815.208
308.68652	0.82327336	0.27845043	2826.6687
309.6875	0.82425702	0.28007889	2825.3853
310.68848	0.82857579	0.28198773	2820.1946
311.68945	0.83386976	0.28372547	2829.6292
312.69043	0.83434159	0.28573158	2831.821
313.69141	0.83915937	0.28760824	2832.6782
314.69238	0.84308666	0.28955141	2831.9651
315.69336	0.84154016	0.29134569	2828.115
316.69434	0.8489393	0.29318854	2833.0249
317.69531	0.85108721	0.29489154	2827.1968
318.69629	0.85537297	0.29637453	2836.0769
319.69727	0.85358375	0.2982668	2835.3518
320.69824	0.8582623	0.3000887	2836.2874
321.69922	0.86078984	0.30193892	2838.0564
322.7002	0.86248493	0.30390185	2836.0876
323.70117	0.87091976	0.30603337	2847.3977
324.70215	0.87174237	0.30792707	2835.7024
325.70313	0.87271291	0.30955419	2836.2612
326.7041	0.87916243	0.31119749	2838.8625
327.70508	0.87980413	0.31280884	2840.0349
328.70605	0.88335073	0.31450841	2837.5947
329.70703	0.88475651	0.31614009	2839.4868
330.70801	0.8889842	0.31806442	2844.1301
331.70898	0.89439118	0.32002261	2844.9128
332.70996	0.896254	0.32185721	2845.9192
333.71094	0.89665747	0.32416111	2846.5002
334.71191	0.90130001	0.32626945	2850.8057
335.71289	0.90371263	0.32860178	2853.3884
336.71387	0.90783846	0.33036995	2850.4561
337.71484	0.91266948	0.33213547	2853.312
338.71582	0.91318315	0.33368886	2846.9438
339.7168	0.91627204	0.33498514	2850.9041
340.71777	0.91602027	0.33683574	2851.8623
341.71875	0.92277354	0.33859658	2854.5994
342.71973	0.92507923	0.34062141	2857.8323
343.7207	0.92966133	0.34257391	2857.4021
344.72168	0.9317674	0.34423658	2855.7527
345.72266	0.93294197	0.34610811	2860.4954
346.72363	0.93707502	0.34796673	2855.7817
347.72461	0.94043291	0.34958223	2864.0754
348.72559	0.94299161	0.35140127	2865.1086
349.72656	0.94549429	0.35350809	2864.2271
350.72754	0.94849104	0.35528922	2859.1121
351.72852	0.95224762	0.3570812	2861.0444
352.72949	0.95591414	0.35912412	2865.6104
353.73047	0.95900732	0.36104318	2872.6458
354.73145	0.95893621	0.36306417	2868.8022
355.73242	0.96705693	0.36491421	2870.3623
356.7334	0.96720082	0.36668938	2866.6765
357.73438	0.96893066	0.36855394	2866.5186
358.73535	0.97290164	0.37031177	2864.9336
359.73633	0.97621036	0.37219632	2868.667
360.7373	0.98011899	0.37452811	2870.657
361.73828	0.98352796	0.37639269	2865.2197
362.73926	0.98198575	0.37801343	2866.7224
363.74023	0.98793656	0.3796044	2865.1267
364.74121	0.99334109	0.38118339	2867.3911
365.74219	0.99534798	0.38321894	2877.7656
366.74316	1.0015479	0.38545239	2882.9094
367.74414	1.0014049	0.38746756	2877.7307
368.74512	1.0042803	0.38944453	2874.9717
369.74609	1.00722	0.39113683	2875.7969
370.74707	1.0087035	0.39304894	2878.2358
371.74805	1.0115441	0.39484358	2888.8398
372.74902	1.0166042	0.39670897	2885.957
373.75	1.0184891	0.39864749	2881.0491
374.75098	1.0236419	0.4003408	2884.2107
375.75195	1.0245848	0.40213695	2880.5042
376.75293	1.028787	0.40382773	2882.1328
377.75391	1.0298711	0.40565971	2881.3892
378.75488	1.0344329	0.40727553	2886.7261
379.75586	1.0368679	0.40902925	2883.9409
380.75684	1.0396873	0.41091183	2888.9968
381.75781	1.0432708	0.4124288	2886.2615
382.75879	1.0456918	0.41434258	2883.2197
383.75977	1.0465869	0.41579616	2883.5767
384.76074	1.0510271	0.4175739	2889.6147
385.76172	1.0538912	0.41950852	2893.281
386.7627	1.0563054	0.4215447	2891.7905
387.76367	1.0594589	0.42369118	2890.5093
388.76465	1.0655721	0.42533562	2893.1123
389.76563	1.0664513	0.42701298	2895.3301
390.7666	1.0711972	0.42881808	2895.6721
391.76758	1.074589	0.43085653	2903.1448
392.76855	1.0752745	0.43256426	2901.3718
393.76953	1.0775846	0.43448946	2893.1848
394.77051	1.0805432	0.43643495	2900.698
395.77148	1.0857092	0.43826959	2905.3643
396.77246	1.0875497	0.4404861	2905.8923
397.77344	1.0911494	0.44281924	2901.8535
398.77441	1.0925392	0.44454539	2899.6091
399.77539	1.0962657	0.44669822	2901.7202
400.77637	1.0999371	0.44799182	2890.1018
401.77734	1.1025627	0.44978696	2900.073
402.77832	1.1054384	0.45156252	2907.8481
403.7793	1.1084945	0.45355552	2903.4763
404.78027	1.1108931	0.4552128	2905.4585
405.78125	1.1159766	0.45708498	2912.9619
406.78223	1.1192901	0.45897669	2910.2649
407.7832	1.1216469	0.46064797	2905.0049
408.78418	1.1261519	0.46268758	2908.1328
409.78516	1.1279638	0.46461624	2919.3108
410.78613	1.1282126	0.46645501	2908.1655
411.78711	1.136218	0.4682155	2914.4666
412.78809	1.1371344	0.47008646	2914.8813
413.78906	1.1396362	0.47178972	2910.1863
414.79004	1.1423926	0.47347447	2910.1475
415.79102	1.1462375	0.47548023	2919.1091
416.79199	1.1488582	0.47754273	2921.8101
417.79297	1.1535087	0.47923949	2914.4644
418.79395	1.1541305	0.4810707	2916.3398
419.79492	1.1545517	0.48307401	2912.8276
420.7959	1.1598302	0.48472768	2918.6628
421.79688	1.1657065	0.48689988	2932.0818
422.79785	1.1683666	0.48867327	2922.1853
423.79883	1.1699307	0.49011511	2917.4026
424.7998	1.1696464	0.49221748	2927.3716
425.80078	1.1762919	0.49434841	2923.0693
426.80176	1.1798425	0.49636135	2925.0925
427.80273	1.1800826	0.49814957	2926.3357
428.80371	1.1850169	0.49985307	2924.3289
429.80469	1.1896328	0.50195122	2930.4302
430.80566	1.1903052	0.50380009	2931.9246
431.80664	1.1936699	0.50564831	2922.7976
432.80762	1.1943157	0.50758636	2928.9958
433.80859	1.1959394	0.50929016	2925.6277
434.80957	1.1995965	0.51100779	2925.4524
435.81055	1.2025663	0.51288658	2931.0396
436.81152	1.2064482	0.51486993	2928.2537
437.8125	1.2115828	0.51659381	2932.0073
438.81348	1.2150804	0.51843089	2939.8186
439.81445	1.2196001	0.52042055	2938.0032
440.81543	1.2190843	0.52243245	2935.6563
441.81641	1.2247939	0.52450269	2947.043
442.81738	1.2260768	0.52638251	2937.533
443.81836	1.2284207	0.52836734	2935.8687
444.81934	1.2301672	0.5303179	2938.0425
445.82031	1.2343608	0.53221828	2938.8127
446.82129	1.2360134	0.53420806	2936.186
447.82227	1.2392987	0.53601378	2935.0359
448.82324	1.245356	0.5373832	2932.1494
449.82422	1.2480086	0.53905666	2948.77
450.8252	1.2480668	0.5409255	2940.967
451.82617	1.2533342	0.54275423	2946.2344
452.82715	1.2542689	0.5448705	2938.519
453.82813	1.2585313	0.54684961	2948.4929
454.8291	1.2624949	0.54866201	2941.6272
455.83008	1.2680769	0.55025637	2946.5989
456.83105	1.2665007	0.55187863	2947.8608
457.83203	1.2731748	0.55375564	2948.7056
458.83301	1.274799	0.555848	2952.6316
459.83398	1.2768756	0.55775881	2943.2432
460.83496	1.2813221	0.55950791	2945.4927
461.83594	1.2832848	0.5613811	2944.9575
462.83691	1.2872819	0.56314105	2953.9788
463.83789	1.2883352	0.5648967	2949.1853
464.83887	1.2927428	0.56686831	2960.4426
465.83984	1.294814	0.56861877	2955.1248
466.84082	1.2982879	0.57058454	2955.0837
467.8418	1.3025471	0.57261473	2957.5576
468.84277	1.3050714	0.57466596	2954.8586
469.84375	1.3077019	0.57655698	2954.3035
470.84473	1.3100768	0.57847351	2951.9353
471.8457	1.3140237	0.58009648	2956.9346
472.84668	1.3173776	0.58184272	2958.2021
473.84766	1.3202889	0.58392274	2960.8821
474.84863	1.3232862	0.58573377	2957.5879
475.84961	1.3253456	0.58782095	2962.8794
476.85059	1.3299856	0.58955669	2959.1426
477.85156	1.3306427	0.59127474	2957.2949
478.85254	1.3367304	0.59303933	2964.8706
479.85352	1.3347642	0.59493673	2966.1577
480.85449	1.3373532	0.59684074	2965.0005
481.85547	1.3427362	0.59883368	2963.5564
482.85645	1.3457067	0.60094756	2963.1399
483.85742	1.3482643	0.60258561	2966.8386
484.8584	1.3555444	0.60437369	2975.6221
485.85938	1.3564932	0.60644311	2969.8594
486.86035	1.3580847	0.60840034	2973.3108
487.86133	1.361131	0.61028761	2969.9373
488.8623	1.3638839	0.61195034	2963.0935
489.86328	1.3702272	0.61394334	2977.2075
490.86426	1.3698764	0.61577857	2975.8601
491.86523	1.3719685	0.61775601	2975.8931
492.86621	1.3773603	0.61968082	2973.7808
493.86719	1.380078	0.62136161	2971.7896
494.86816	1.3838619	0.62375772	2984.8479
495.86914	1.3852615	0.62538558	2971.8962
496.87012	1.3890091	0.62724936	2974.0847
497.87109	1.3926504	0.62887603	2980.8306
498.87207	1.3924795	0.63079739	2983.041
499.87305	1.3972932	0.63290435	2980.1003
500.87402	1.3998983	0.63467866	2974.5425
501.875	1.4044129	0.63662457	2983.4429
502.87598	1.4041079	0.63872248	2978.1213
503.87695	1.4130454	0.64095998	2984.2661
504.87793	1.4104675	0.64242572	2975.7144
505.87891	1.4155893	0.64393508	2976.9954
506.87988	1.4168955	0.64582437	2984.2441
507.88086	1.4194527	0.64798582	2983.6824
508.88184	1.4255381	0.65049291	2987.0505
509.88281	1.4243422	0.65253597	2975.6692
510.88379	1.4289708	0.65441197	2984.3088
511.88477	1.4327646	0.65617377	2979.6155
512.88574	1.4353074	0.65761095	2981.2241
513.88672	1.4372202	0.65920919	2988.3469
514.8877	1.4401321	0.66093814	2981.5322
515.88867	1.4437375	0.66271979	2989.5801
516.88965	1.4479927	0.66424012	2980.9229
517.89063	1.4533515	0.66586864	2988.2488
518.8916	1.453287	0.66768306	2987.626
519.89258	1.4581103	0.66967541	2989.9546
520.89355	1.4577878	0.67196339	2994.7664
521.89453	1.4613022	0.67373908	2988.9641
522.89551	1.467886	0.67581964	2992.5996
523.89648	1.4674482	0.67779124	2990.7756
524.89746	1.4722188	0.67966837	2991.5034
525.89844	1.4755362	0.68146288	2994.0227
526.89941	1.4796475	0.6830793	2993.4187
527.90039	1.4815865	0.68494284	2993.3818
528.90137	1.4827836	0.68674707	2994.5498
529.90234	1.4855983	0.68871742	2991.5906
530.90332	1.4900384	0.69023734	2994.166
531.9043	1.4933362	0.69213635	2997.2024
532.90527	1.4980562	0.69399798	3000.5667
533.90625	1.4995494	0.69590944	3003.0386
534.90723	1.5028751	0.6979537	3004.8733
535.9082	1.5023125	0.69979364	2999.3428
536.90918	1.5087516	0.70198119	3000.252
537.91016	1.5116007	0.7038756	3002.3572
538.91113	1.5161544	0.70579904	3002.9287
539.91211	1.5185339	0.70725781	3000.2996
540.91309	1.5224342	0.70894456	3007.3918
541.91406	1.5237556	0.71123087	3010.7896
542.91504	1.5289065	0.71304715	3008.0464
543.91602	1.5280943	0.71476287	3001.1016
544.91699	1.5328439	0.71682006	3013.2092
545.91797	1.5352982	0.71908051	3010.4519
546.91895	1.5408053	0.72113568	3010.7146
547.91992	1.5426588	0.7230342	3002.8379
548.9209	1.5458657	0.72469491	3004.9116
549.92188	1.5463476	0.72660393	3007.968
550.92285	1.5528626	0.72829205	3016.6104
551.92383	1.5519128	0.73040551	3009.8711
552.9248	1.5578927	0.73273575	3007.1367
553.92578	1.5596008	0.73461628	3006.0522
554.92676	1.5616704	0.73616225	3009.7197
555.92773	1.5652326	0.73791057	3002.1213
556.92871	1.5674288	0.73935986	3008.75
557.92969	1.5704458	0.74096185	3013.7178
558.93066	1.5734516	0.74269933	3008.6497
559.93164	1.5778006	0.74502122	3013.3167
560.93262	1.5819453	0.74705607	3015.0793
561.93359	1.5822719	0.74912167	3015.989
562.93457	1.5890138	0.75083447	3019.4089
563.93555	1.5927525	0.75244564	3015.3696
564.93652	1.5952415	0.75415367	3020.9619
565.9375	1.5938815	0.75589883	3010.2983
566.93848	1.5992752	0.75792342	3017.7366
567.93945	1.5981946	0.75972795	3021.9814
568.94043	1.6027426	0.76170284	3022.8594
569.94141	1.6075451	0.76382762	3022.3618
570.94238	1.6102165	0.76582402	3015.4126
571.94336	1.6137978	0.7677598	3027.5886
572.94434	1.6160567	0.76963007	3024.6414
573.94531	1.6207858	0.77162194	3022.8577
574.94629	1.6243856	0.77351677	3022.4697
575.94727	1.6263467	0.77516836	3021.5793
576.94824	1.6267512	0.77721739	3025.3948
577.94922	1.630168	0.77902973	3023.2603
578.9502	1.6342626	0.78098494	3024.7041
579.95117	1.6386294	0.78257877	3018.7217
580.95215	1.6394453	0.78443825	3024.1604
581.95313	1.6440777	0.78621048	3026.5474
582.9541	1.6484528	0.78804028	3032.7004
583.95508	1.6486876	0.78990591	3025.4165
584.95605	1.6541715	0.79148555	3027.8728
585.95703	1.6550738	0.79350561	3030.1992
586.95801	1.6607877	0.79568845	3036.2725
587.95898	1.6615235	0.7980867	3033.6267
588.95996	1.661706	0.79984736	3027.6418
589.96094	1.6696402	0.80153441	3028.9473
590.96191	1.6683466	0.80310661	3029.4094
591.96289	1.673859	0.80478048	3027.8628
592.96387	1.6761388	0.80636269	3029.8362
593.96484	1.6804709	0.80797648	3035.9167
594.96582	1.6831141	0.80981994	3032.0962
595.9668	1.6865166	0.81141752	3036.9116
596.96777	1.6872028	0.81320065	3030.3098
597.96875	1.6928042	0.81525016	3041.0046
598.96973	1.6940844	0.81724256	3041.7139
599.9707	1.6987183	0.81950253	3045.0313
600.97168	1.7001889	0.82188052	3036.3147
601.97266	1.70121	0.82373428	3038.6873
602.97363	1.7072667	0.82560563	3037.2144
603.97461	1.7098944	0.82743555	3042.2849
604.97559	1.7153924	0.82924592	3045.4856
605.97656	1.7168499	0.83075881	3041.0244
606.97754	1.717504	0.83231735	3038.3762
607.97852	1.7248597	0.83409649	3049.053
608.97949	1.7238365	0.83661616	3042.6299
609.98047	1.7289995	0.83881009	3045.6763
610.98145	1.7302835	0.84083027	3041.6235
611.98242	1.731809	0.84277493	3037.4607
612.9834	1.736051	0.84483314	3044.6443
613.98438	1.7393471	0.8469733	3043.1855
614.98535	1.7427448	0.84913081	3043.3806
615.98633	1.7470171	0.85095626	3043.3311
616.9873	1.745943	0.85262811	3039.4846
617.98828	1.7531561	0.8546226	3055.9802
618.98926	1.7536494	0.85661483	3040.7456
619.99023	1.7572714	0.85839331	3047.9368
620.99121	1.7616917	0.86011946	3042.1538
621.99219	1.7642963	0.86184168	3047.7336
622.99316	1.766937	0.86362296	3050.8552
623.99414	1.7663283	0.86555767	3046.1311
624.99512	1.7728562	0.86731213	3045.5605
625.99609	1.7733756	0.86913908	3048.4526
626.99707	1.7777714	0.87082148	3048.7271
627.99805	1.782267	0.87256521	3050.4517
628.99902	1.7844431	0.87428564	3044.4546
630	1.789811	0.87625974	3053.1023
631.00098	1.7927188	0.87844211	3055.6694
632.00195	1.7936529	0.88025886	3047.5818
633.00293	1.7975435	0.88236314	3047.7329
634.00391	1.7976763	0.88405722	3047.3992
635.00488	1.8056418	0.8860265	3056.3049
636.00586	1.8064779	0.88768536	3052.8936
637.00684	1.8096445	0.88971221	3056.8396
638.00781	1.8089204	0.89158094	3049.7461
639.00879	1.8137158	0.89358407	3059.6848
640.00977	1.8197029	0.89545345	3055.9543
641.01074	1.8215872	0.89723188	3058.6379
642.01172	1.823477	0.89932501	3059.623
643.0127	1.8311268	0.90126866	3060.2275
644.01367	1.8321879	0.90333557	3065.5703
645.01465	1.8324448	0.90554082	3064.322
646.01563	1.8377975	0.90769845	3057.0513
647.0166	1.839366	0.90974259	3057.5308
648.01758	1.8416548	0.91174698	3061.4668
649.01855	1.8436955	0.91362303	3056.6738
650.01953	1.8501863	0.91568995	3069.2
651.02051	1.8517884	0.91768676	3063.6724
652.02148	1.8549632	0.91956645	3060.0427
653.02246	1.8561476	0.92145586	3059.9456
654.02344	1.8592623	0.92329204	3060.0303
655.02441	1.8635846	0.92489123	3066.1008
656.02539	1.8666877	0.92699957	3069.0383
657.02637	1.8704084	0.92940313	3068.4312
658.02734	1.8676736	0.93113631	3060.3086
659.02832	1.8758496	0.93300992	3065.7683
660.0293	1.877912	0.93483484	3063.4578
661.03027	1.8801219	0.93655276	3059.6631
662.03125	1.8865768	0.93838137	3070.0608
663.03223	1.8879735	0.94033027	3064.387
664.0332	1.8919859	0.94247758	3071.3125
665.03418	1.8902167	0.94426805	3060.1538
666.03516	1.8971175	0.94582832	3061.0854
667.03613	1.8986599	0.9475041	3064.2878
668.03711	1.901204	0.94947439	3068.2705
669.03809	1.9037414	0.95143044	3069.1106
670.03906	1.9081086	0.95353305	3071.6072
671.04004	1.9098758	0.95544434	3067.7996
672.04102	1.9119468	0.95725304	3069.772
673.04199	1.9174279	0.95927024	3076.6436
674.04297	1.9185895	0.96092629	3067.8345
675.04395	1.9222758	0.96295172	3067.1763
676.04492	1.9251418	0.96488178	3077.4536
677.0459	1.9308826	0.96692872	3071.6082
678.04688	1.9328408	0.96932781	3069.7903
679.04785	1.9338608	0.97129291	3072.4121
680.04883	1.9384454	0.973414	3072.1499
681.0498	1.9422631	0.97562665	3077.5049
682.05078	1.9435232	0.97776508	3067.7908
683.05176	1.9468304	0.97972286	3070.2539
684.05273	1.9490296	0.98182344	3070.9485
685.05371	1.9509399	0.9836328	3070.1716
686.05469	1.9527677	0.98562068	3072.8501
687.05566	1.9597394	0.98762518	3076.6382
688.05664	1.9617993	0.98932642	3069.7466
689.05762	1.9658661	0.99159586	3079.6045
690.05859	1.9656782	0.99343139	3071.3181
691.05957	1.9718506	0.99512559	3070.4849
692.06055	1.9742045	0.99684799	3070.5305
693.06152	1.9771603	0.99882513	3081.7258
694.0625	1.9790537	1.0004239	3071.7622
695.06348	1.9815755	1.0023805	3076.2986
696.06445	1.9851694	1.0046312	3081.7439
697.06543	1.9875649	1.0066599	3081.3655
698.06641	1.9915112	1.0086066	3081.687
699.06738	1.9916569	1.0105841	3074.3623
700.06836	1.9996303	1.0122384	3078.0356
701.06934	1.9988294	1.0142077	3086.2231
702.07031	2.0053256	1.0160505	3081.7449
703.07129	2.0066824	1.0182173	3085.8972
704.07227	2.0072246	1.0199884	3082.6233
705.07324	2.0133767	1.0218414	3081.3074
706.07422	2.0163639	1.0236342	3076.6418
707.0752	2.0198467	1.0258778	3083.6399
708.07617	2.0224471	1.0275103	3083.4612
709.07715	2.0265439	1.0295076	3086.7717
710.07813	2.0275662	1.0314844	3082.5186
711.0791	2.0322735	1.0335799	3087.8745
712.08008	2.0332882	1.0356153	3086.9431
713.08105	2.0375135	1.0375583	3081.8701
714.08203	2.041111	1.0391686	3092.3713
715.08301	2.0430841	1.0415127	3088.375
716.08398	2.0450485	1.0440547	3082.7351
717.08496	2.047195	1.0465002	3081.1182
718.08594	2.0551579	1.0486177	3088.6877
719.08691	2.054713	1.0508248	3089.5503
720.08789	2.056638	1.0530353	3085.0837
721.08887	2.061043	1.0550834	3087.7925
722.08984	2.0662887	1.0569832	3078.8855
723.09082	2.0667613	1.0587327	3085.9329
724.0918	2.0692952	1.0605037	3081.0354
725.09277	2.0720873	1.0623181	3086.1125
726.09375	2.074744	1.0644507	3085.7971
727.09473	2.0775452	1.066313	3081.2134
728.0957	2.0813992	1.0679786	3088.1169
729.09668	2.0864053	1.0698441	3092.2405
730.09766	2.0865178	1.0717455	3088.7974
731.09863	2.0880492	1.0735642	3083.8701
732.09961	2.0932784	1.0755314	3088.9211
733.10059	2.0962498	1.077866	3094.8123
734.10156	2.10151	1.0799434	3098.0149
735.10254	2.1026249	1.0815166	3094.0098
736.10352	2.1042018	1.0833006	3092.7126
737.10449	2.110069	1.0853287	3097.3892
738.10547	2.1124706	1.0876236	3092.3303
739.10645	2.1155558	1.0895724	3089.5298
740.10742	2.1197028	1.0913277	3090.311
741.1084	2.1212933	1.0930626	3089.2932
742.10938	2.1278389	1.0949284	3096.0596
743.11035	2.1231973	1.0967711	3095.7483
744.11133	2.1311963	1.0990659	3099.1914
745.1123	2.1296794	1.1013554	3092.218
746.11328	2.1344175	1.1034045	3095.6733
747.11426	2.1398733	1.1058316	3097.4294
748.11523	2.1431015	1.1079042	3093.4685
749.11621	2.1436081	1.1097407	3094.3223
750.11719	2.1512961	1.1119422	3097.0149
751.11816	2.1528573	1.113898	3094.4692
752.11914	2.1513245	1.1158221	3091.9802
753.12012	2.157161	1.1176872	3092.6045
754.12109	2.1594815	1.1199175	3100.2576
755.12207	2.1625512	1.1218582	3089.9797
756.12305	2.1644428	1.1235681	3089.384
757.12402	2.1687586	1.1254615	3102.2041
758.125	2.174489	1.1275213	3102.5911
759.12598	2.1749084	1.1296316	3103.2256
760.12695	2.1779976	1.1316805	3095.2134
761.12793	2.1796834	1.1336656	3098.5793
762.12891	2.1829929	1.1361244	3104.7361
763.12988	2.1883559	1.1383632	3102.4978
764.13086	2.1930482	1.1405598	3100.178
765.13184	2.1948776	1.1427824	3103.2231
766.13281	2.196564	1.1451899	3098.1658
767.13379	2.1989951	1.1472312	3098.9529
768.13477	2.2030091	1.149055	3096.4883
769.13574	2.2035966	1.1514994	3102.0486
770.13672	2.2063375	1.1535541	3090.5957
771.1377	2.2100301	1.1554483	3093.5916
772.13867	2.2102749	1.156963	3091.8728
773.13965	2.2151849	1.1589313	3097.0535
774.14063	2.2207167	1.1607306	3104.801
775.1416	2.2218335	1.162918	3099.8628
776.14258	2.226558	1.1649786	3108.4104
777.14355	2.2304885	1.1670016	3103.9502
778.14453	2.234113	1.1692539	3105.1968
779.14551	2.2361114	1.1712601	3096.394
780.14648	2.2337127	1.1732942	3098.075
781.14746	2.2432473	1.1754701	3107.3809
782.14844	2.2470298	1.1778405	3109.584
783.14941	2.2486646	1.1800934	3103.9419
784.15039	2.2485003	1.1821469	3098.8921
785.15137	2.2533987	1.1843686	3110.958
786.15234	2.2592936	1.1865759	3107.6443
787.15332	2.2583096	1.1882106	3098.0039
788.1543	2.2599852	1.1902933	3108.96
789.15527	2.2636001	1.1921903	3102.3379
790.15625	2.2688723	1.1941369	3101.0752
791.15723	2.2729084	1.1960346	3111.9607
792.1582	2.2735648	1.1980562	3108.4324
793.15918	2.2770164	1.2003504	3111.4397
794.16016	2.2814026	1.2029586	3107.6382
795.16113	2.2824786	1.2051157	3101.6313
796.16211	2.28423	1.2073075	3106.7881
797.16309	2.2893946	1.2095269	3102.5022
798.16406	2.2924175	1.2116933	3102.6038
799.16504	2.2950528	1.2139269	3111.8145
800.16602	2.2988224	1.2161214	3105.0603
801.16699	2.3011668	1.2182655	3110.8872
802.16797	2.3029692	1.2203972	3107.5813
803.16895	2.3079488	1.2224371	3102.2083
804.16992	2.3084145	1.2245718	3104.8962
805.1709	2.3101687	1.2264966	3102.748
806.17188	2.3149924	1.2282875	3103.0994
807.17285	2.3212872	1.2301731	3104.8435
808.17383	2.3213458	1.2319634	3101.52
809.1748	2.3237982	1.2337495	3106.4229
810.17578	2.3279238	1.235934	3113.9141
811.17676	2.3321884	1.2381431	3117.9097
812.17773	2.3345141	1.2404752	3116.1929
813.17871	2.3384776	1.2429469	3112.4084
814.17969	2.3384495	1.2450552	3099.3438
815.18066	2.3456128	1.2469467	3108.2668
816.18164	2.3458061	1.2487358	3103.6768
817.18262	2.3497348	1.2504216	3102.5698
818.18359	2.3513575	1.2525597	3113.4399
819.18457	2.3561163	1.2551209	3115.4424
820.18555	2.3586588	1.2574776	3117.4031
821.18652	2.3608065	1.2597723	3109.3931
822.1875	2.3634512	1.2619572	3104.9155
823.18848	2.3705382	1.2642834	3112.1313
824.18945	2.3715711	1.2665088	3116.3584
825.19043	2.3748422	1.268991	3113.647
826.19141	2.3745503	1.2709146	3109.7141
827.19238	2.3799822	1.2730206	3108.1956
828.19336	2.3807292	1.2750014	3108.627
829.19434	2.3846114	1.2770188	3111.1677
830.19531	2.3862112	1.2792921	3116.1199
831.19629	2.3867779	1.2817341	3116.1377
832.19727	2.394944	1.2840047	3112.2896
833.19824	2.3963561	1.2858286	3109.4482
834.19922	2.3980923	1.2878339	3113.6912
835.2002	2.4067607	1.2900206	3109.1201
836.20117	2.4055276	1.2919563	3105.7949
837.20215	2.4092798	1.2939221	3111.5647
838.20313	2.410538	1.2962153	3115.7834
839.2041	2.4134736	1.2985276	3111.6143
840.20508	2.4189386	1.3007838	3115.2493
841.20605	2.4236627	1.3029876	3113.6326
842.20703	2.4237258	1.3047017	3102.9973
843.20801	2.4253097	1.3068466	3111.7871
844.20898	2.4282033	1.3089052	3108.7495
845.20996	2.4314699	1.310835	3113.4871
846.21094	2.4359918	1.3133012	3117.3364
847.21191	2.4412439	1.3159498	3116.0417
848.21289	2.443526	1.3188446	3123.9412
849.21387	2.4449584	1.3210378	3106.8398
850.21484	2.4486332	1.3234054	3114.3818
851.21582	2.4505806	1.3253958	3110.8811
852.2168	2.4537175	1.3275453	3111.6626
853.21777	2.4574091	1.3296121	3118.0947
854.21875	2.4589097	1.3316218	3110.2849
855.21973	2.4615588	1.3340389	3117.5032
856.2207	2.4642448	1.3362103	3112.1404
857.22168	2.4703789	1.3383718	3106.8525
858.22266	2.4712722	1.3406168	3116.5669
859.22363	2.4738355	1.3430008	3117.8508
860.22461	2.479697	1.3455844	3124.2688
861.22559	2.4806814	1.3479582	3122.8169
862.22656	2.4868963	1.3501514	3114.6763
863.22754	2.4864459	1.3521373	3108.5745
864.22852	2.488471	1.3542222	3110.1055
865.22949	2.4952154	1.3563503	3116.446
866.23047	2.4946437	1.3587455	3115.9094
867.23145	2.4991913	1.3612186	3120.4917
868.23242	2.5007746	1.3635011	3113.2478
869.2334	2.5041542	1.3655965	3108.7036
870.23438	2.5080795	1.3675839	3112.0813
871.23535	2.5126569	1.3700283	3115.1292
872.23633	2.5158706	1.3719763	3117.6079
873.2373	2.5139074	1.3743906	3118.7214
874.23828	2.5221858	1.376768	3117.3247
875.23926	2.5219624	1.3789138	3108.5295
876.24023	2.5257015	1.3811759	3114.7104
877.24121	2.5289001	1.3834258	3114.5249
878.24219	2.5297315	1.3859082	3113.6548
879.24316	2.5354548	1.3879005	3113.2944
880.24414	2.5368783	1.3898479	3109.165
881.24512	2.5405943	1.3923273	3118.5173
882.24609	2.5449471	1.3945422	3112.0964
883.24707	2.548357	1.3966289	3108.0645
884.24805	2.5500495	1.3988422	3121.2559
885.24902	2.5547483	1.4014437	3115.7761
886.25	2.5548661	1.4035881	3113.7542
887.25098	2.5566847	1.4058548	3112.3767
888.25195	2.5626495	1.408254	3117
889.25293	2.5652242	1.4103252	3116.6763
890.25391	2.5673304	1.412636	3117.1379
891.25488	2.5731344	1.4146212	3117.3914
892.25586	2.5719013	1.416937	3114.7539
893.25684	2.5776317	1.4193571	3113.1226
894.25781	2.5807278	1.4218366	3121.3633
895.25879	2.5807295	1.4245346	3116.5178
896.25977	2.5863831	1.4273801	3120.8611
897.26074	2.5900772	1.4302454	3115.5476
898.26172	2.5924199	1.4328349	3113.8115
899.2627	2.5951202	1.4350439	3112.5808
900.26367	2.598732	1.4370871	3113.8433
901.26465	2.6014416	1.4390328	3109.917
902.26563	2.6072352	1.4413257	3119.6165
903.2666	2.6098831	1.4437459	3121.106
904.26758	2.6103451	1.4457688	3112.9153
905.26855	2.6138189	1.4481078	3116.4268
906.26953	2.6141248	1.4504815	3116.5156
907.27051	2.6204271	1.452916	3117.5469
908.27148	2.6248019	1.4554813	3117.7346
909.27246	2.6230533	1.4579523	3115.7708
910.27344	2.6290298	1.4600658	3115.9426
911.27441	2.6305852	1.4624038	3118.7642
912.27539	2.6350827	1.4653045	3116.6694
913.27637	2.6387346	1.4677494	3108.3606
914.27734	2.6412334	1.469891	3106.9021
915.27832	2.6463356	1.4724716	3123.1277
916.2793	2.6463675	1.4745623	3113.0957
917.28027	2.6505001	1.4766276	3115.7205
918.28125	2.6520982	1.4789846	3115.2148
919.28223	2.6547098	1.4813672	3116.7307
920.2832	2.6587629	1.4836117	3114.6389
921.28418	2.6594484	1.4857835	3111.8054
922.28516	2.6665168	1.4882882	3116.6826
923.28613	2.6675982	1.4910204	3114.9646
924.28711	2.6706822	1.4935048	3114.3325
925.28809	2.6743166	1.4959428	3116.0029
926.28906	2.6747413	1.4982605	3115.7222
927.29004	2.680079	1.5008703	3115.7556
928.29102	2.6830752	1.5028987	3112.522
929.29199	2.6859877	1.5053924	3114.9355
930.29297	2.685919	1.5077169	3107.281
931.29395	2.6949835	1.5102526	3121.6643
932.29492	2.6921742	1.5130564	3118.0745
933.2959	2.6983521	1.5154332	3108.658
934.29688	2.7011847	1.5183381	3117.0527
935.29785	2.7037354	1.5208969	3118.8508
936.29883	2.7073212	1.523473	3117.7952
937.2998	2.7110221	1.5259515	3118.0288
938.30078	2.7129674	1.5280231	3113.4185
939.30176	2.7155728	1.5306401	3115.3516
940.30273	2.7171538	1.5329018	3108.345
941.30371	2.7242832	1.5358262	3124.0986
942.30469	2.7255504	1.5384688	3111.9353
943.30566	2.7302341	1.540886	3116.6611
944.30664	2.7301888	1.5430312	3111.5085
945.30762	2.7319398	1.5453846	3112.7505
946.30859	2.7361946	1.5478917	3107.3855
947.30957	2.7369525	1.5503665	3107.6086
948.31055	2.7436986	1.5531175	3120.7119
949.31152	2.7444596	1.555477	3112.0042
950.3125	2.7493188	1.5580301	3116.1438
951.31348	2.753407	1.5607744	3112.75
952.31445	2.7538207	1.5629591	3109.2234
953.31543	2.7566252	1.5654451	3108.0134
954.31641	2.7617309	1.5679377	3115.5059
955.31738	2.7641852	1.5708203	3116.2383
956.31836	2.7653837	1.5732875	3108.9521
957.31934	2.7713764	1.5758157	3118.9194
958.32031	2.771085	1.5790391	3116.1299
959.32129	2.7752244	1.5815018	3108.4119
960.32227	2.7782922	1.5842081	3107.7961
961.32324	2.7836037	1.5869689	3108.4917
962.32422	2.7869942	1.5897715	3114.2678
963.3252	2.7860384	1.5919664	3104.4575
964.32617	2.7906542	1.5943187	3104.5229
965.32715	2.7937174	1.5964882	3106.7473
966.32813	2.7975562	1.5988594	3111.625
967.3291	2.7998455	1.6018412	3114.1885
968.33008	2.8030841	1.6047671	3116.3745
969.33105	2.809181	1.6079789	3119.5876
970.33203	2.8077283	1.6107837	3111.3103
971.33301	2.8138888	1.6136415	3110.7581
972.33398	2.8125844	1.6164578	3109.6575
973.33496	2.8187025	1.6190913	3108.8462
974.33594	2.8220351	1.6216851	3107.8718
975.33691	2.8236039	1.6244289	3112.1589
976.33789	2.8298278	1.6277831	3115.041
977.33887	2.8296056	1.6307281	3106.2781
978.33984	2.8294656	1.6335015	3103.0364
979.34082	2.8334992	1.63592	3098.5647
980.3418	2.8391759	1.6379004	3103.0625
981.34277	2.8413281	1.6401522	3106.481
982.34375	2.8458345	1.6425433	3106.0435
983.34473	2.8496444	1.6452523	3110.8318
984.3457	2.8490608	1.6478201	3106.6362
985.34668	2.8527057	1.6508018	3104.502
986.34766	2.8541026	1.6534543	3105.5159
987.34863	2.8600571	1.6559006	3103.9543
988.34961	2.8621616	1.6581331	3099.9219
989.35059	2.8668284	1.6609192	3103.9863
990.35156	2.8681412	1.6636463	3099.365
991.35254	2.8724635	1.6662259	3109.7803
992.35352	2.8734379	1.6688236	3103.8179
993.35449	2.8766346	1.6717275	3099.6616
994.35547	2.8827982	1.6742625	3104.7776
995.35645	2.8832786	1.6765064	3100.0952
996.35742	2.8873658	1.6794908	3103.2385
997.3584	2.8889506	1.6824137	3105.1313
998.35938	2.8912983	1.6851747	3101.6184
999.36035	2.8955731	1.6883301	3100.1733
1000.3613	2.8954842	1.6912252	3105.3342
1001.3623	2.8996916	1.6940514	3091.7134
1002.3633	2.904506	1.6962984	3094.1365
1003.3643	2.9090066	1.6984992	3099.5442
1004.3652	2.9092901	1.7014338	3097.542
1005.3662	2.912751	1.7039558	3099.0286
1006.3672	2.9149494	1.7070627	3104.0671
1007.3682	2.9187908	1.7102835	3098.552
1008.3691	2.9224942	1.7128431	3098.0103
1009.3701	2.9244916	1.715772	3103.9229
1010.3711	2.9260974	1.7189565	3097.9456
1011.3721	2.9295151	1.7218738	3092.6575
1012.373	2.9378259	1.7245122	3096.886
1013.374	2.9382081	1.7269341	3092.666
1014.375	2.9406538	1.7299826	3098.9238
1015.376	2.9436264	1.7324548	3091.9631
1016.377	2.947088	1.7350045	3098.9597
1017.3779	2.9507947	1.7377719	3095.4749
1018.3789	2.9520471	1.7406859	3089.7827
1019.3799	2.9570551	1.7432349	3095.3782
1020.3809	2.9617445	1.745863	3095.459
1021.3818	2.9623787	1.7483618	3097.0896
1022.3828	2.9654129	1.7511404	3097.406
1023.3838	2.9679799	1.7541521	3097.5745
1024.3848	2.9716284	1.7571908	3101.554
1025.3857	2.9741018	1.7599171	3092.3564
1026.3867	2.9779139	1.7625531	3096.4583
1027.3877	2.9798622	1.7651776	3090.647
1028.3887	2.9831688	1.7681078	3089.8411
1029.3896	2.9846842	1.770462	3088.6414
1030.3906	2.9899218	1.7733057	3094.0483
1031.3916	2.990303	1.7755761	3087.2185
1032.3926	2.9960389	1.7785239	3094.895
1033.3936	2.9957235	1.7808228	3084.5242
1034.3945	2.9989445	1.7829064	3078.4456
1035.3955	2.9993274	1.7850691	3083.3826
1036.3965	3.006	1.7871279	3081.042
1037.3975	3.0092051	1.7897193	3092.0542
1038.3984	3.01388	1.7928461	3095.0725
1039.3994	3.0167451	1.7959183	3090.8179
1040.4004	3.0182323	1.7990468	3090.9153
1041.4014	3.0228975	1.8022276	3087.7878
1042.4023	3.0241017	1.8052194	3081.4873
1043.4033	3.0299385	1.807695	3083.4478
1044.4043	3.0331039	1.810578	3083.5964
1045.4053	3.0298774	1.813496	3080.9551
1046.4063	3.036361	1.8160861	3079.855
1047.4072	3.0388312	1.8192958	3086.2268
1048.4082	3.0458806	1.8225874	3080.1116
1049.4092	3.0455501	1.8255267	3083.812
1050.4102	3.048898	1.8279567	3080.8569
1051.4111	3.0521502	1.8308702	3082.6052
1052.4121	3.0546374	1.8341554	3079.6089
1053.4131	3.0593092	1.8374814	3083.7021
1054.4141	3.0621631	1.8403913	3078.7476
1055.415	3.0638623	1.8435055	3078.0862
1056.416	3.0662372	1.8460839	3070.1233
1057.417	3.070152	1.8487824	3076.0349
1058.418	3.0736406	1.8517857	3075.9485
1059.4189	3.0781431	1.8544743	3073.5342
1060.4199	3.0820072	1.856833	3073.9807
1061.4209	3.0839729	1.8597374	3077.6172
1062.4219	3.0863974	1.8629603	3079.1079
1063.4229	3.0873017	1.8661462	3073.6316
1064.4238	3.091171	1.8692493	3080.9102
1065.4248	3.0930536	1.872618	3075.2532
1066.4258	3.0926759	1.8759664	3067.1538
1067.4268	3.1000292	1.8791257	3066.6929
1068.4277	3.1023343	1.8815975	3063.1948
1069.4287	3.1052389	1.8844545	3067.4104
1070.4297	3.1107142	1.8874118	3070.583
1071.4307	3.1128595	1.8900875	3066.7085
1072.4316	3.1158621	1.8932525	3070.0203
1073.4326	3.1162505	1.896248	3068.0159
1074.4336	3.1200154	1.8996084	3069.2437
1075.4346	3.1250358	1.9028745	3069.5664
1076.4355	3.1255224	1.9061991	3062.4382
1077.4365	3.1299877	1.9098768	3066.6343
1078.4375	3.1348515	1.9131056	3063.7444
1079.4385	3.1366436	1.9160408	3054.2808
1080.4395	3.1381695	1.9187936	3057.8308
1081.4404	3.1415513	1.9217144	3055.1602
1082.4414	3.1450262	1.9246454	3059.7273
1083.4424	3.1466208	1.9280012	3059.6262
1084.4434	3.1524212	1.9309591	3054.592
1085.4443	3.1517365	1.9333221	3050.6082
1086.4453	3.1575656	1.9358793	3053.458
1087.4463	3.1591856	1.9389747	3056.6909
1088.4473	3.1641092	1.9425912	3061.0095
1089.4482	3.1673832	1.9455966	3053.8477
1090.4492	3.1674926	1.9488497	3052.6257
1091.4502	3.1704369	1.9523035	3050.1665
1092.4512	3.1772707	1.955148	3047.1619
1093.4521	3.1797426	1.9576463	3048.8357
1094.4531	3.1829119	1.9604752	3048.0259
1095.4541	3.1845737	1.9629349	3045.8362
1096.4551	3.1867542	1.9660238	3045.7407
1097.4561	3.1890302	1.9692358	3049.7817
1098.457	3.1933224	1.9722989	3044.488
1099.458	3.1976194	1.9752363	3040.6914
1100.459	3.1989629	1.9778949	3045.802
1101.46	3.2016828	1.9811752	3047.146
1102.4609	3.206567	1.9847202	3041.3052
1103.4619	3.2064557	1.9875516	3033.4646
1104.4629	3.2101467	1.9911921	3034.3213
1105.4639	3.2159064	1.994354	3039.7222
1106.4648	3.21415	1.9971505	3035.8633
1107.4658	3.2219636	2.0001323	3036.9099
1108.4668	3.2241428	2.003149	3029.2141
1109.4678	3.2240546	2.006248	3029.2964
1110.4688	3.2308726	2.0094583	3030.55
1111.4697	3.2350435	2.0123024	3031.5725
1112.4707	3.2351468	2.0153601	3026.2368
1113.4717	3.2416735	2.0181231	3024.4084
1114.4727	3.2381253	2.0212688	3029.6292
1115.4736	3.2430718	2.0244689	3023.696
1116.4746	3.2458916	2.0272648	3024.696
1117.4756	3.248487	2.0305202	3022.9612
1118.4766	3.2511261	2.0331275	3023.4934
1119.4775	3.2559845	2.0364411	3023.6409
1120.4785	3.2606211	2.0392175	3018.5813
1121.4795	3.2639656	2.0411651	3015.7771
1122.4805	3.2668397	2.0429912	3019.699
1123.4814	3.2703934	2.0442653	3019.5378
1124.4824	3.2700646	2.0445173	3014.2961
1125.4834	3.2764528	2.0447369	3015.6287
1126.4844	3.2772832	2.0450993	3009.5269
1127.4854	3.2806339	2.0450461	3005.7729
1128.4863	3.2852542	2.0449753	3017.8777
1129.4873	3.2865434	2.0451405	3006.094
1130.4883	3.2889705	2.0453115	3010.4348
1131.4893	3.294373	2.0447867	3010.1018
1132.4902	3.2941029	2.0452096	3001.7791
1133.4912	3.2974117	2.0453053	2997.948
1134.4922	3.3032994	2.0450873	3007.7097
1135.4932	3.3063207	2.045408	2998.4053
1136.4941	3.305872	2.045644	2991.1787
1137.4951	3.3114688	2.0453796	3003.2754
1138.4961	3.311167	2.0454779	2998.5955
1139.4971	3.3149393	2.045624	2994.0847
1140.498	3.3181238	2.0455735	2990.217
1141.499	3.3221223	2.0453579	2992.7986
1142.5	3.3252263	2.0455897	2991.9963
1143.501	3.3281157	2.0459118	2981.0435
1144.502	3.330718	2.0455525	2980.7856
1145.5029	3.3325536	2.045671	2983.7654
1146.5039	3.3364441	2.0459688	2982.623
1147.5049	3.3387539	2.0460236	2984.5356
1148.5059	3.3419921	2.0458744	2983.7854
1149.5068	3.3472798	2.0460699	2978.2415
1150.5078	3.3507652	2.0459499	2979.2173
1151.5088	3.3530092	2.0458832	2979.5205
1152.5098	3.3586709	2.0458584	2977.0044
1153.5107	3.35501	2.0459857	2974.8147
1154.5117	3.3597014	2.0459785	2964.4639
1155.5127	3.3649867	2.0461011	2967.614
1156.5137	3.3698826	2.0459001	2964.2776
1157.5146	3.3692098	2.0462389	2962.7605
1158.5156	3.3707526	2.046334	2964.8147
1159.5166	3.3784096	2.046217	2964.1067
1160.5176	3.379174	2.0462055	2954.2876
1161.5186	3.3832448	2.0461769	2960.6289
1162.5195	3.3863325	2.0462208	2960.2009
1163.5205	3.3890598	2.0463598	2952.3184
1164.5215	3.3914509	2.0467691	2943.2839
1165.5225	3.3954074	2.0463374	2954.1484
1166.5234	3.3977585	2.0466835	2935.0991
1167.5244	3.4024739	2.046499	2942.0195
1168.5254	3.4029431	2.0468233	2943.0112
1169.5264	3.4042706	2.046654	2943.707
1170.5273	3.4076462	2.0464914	2940.2126
1171.5283	3.4125216	2.0465405	2945.4063
1172.5293	3.4158106	2.0466831	2939.9526
1173.5303	3.4180405	2.0465872	2932.3752
1174.5313	3.4211888	2.0466356	2932.8992
1175.5322	3.4199531	2.0466483	2925.1504
1176.5332	3.4290595	2.0465572	2926.3362
1177.5342	3.4326169	2.046818	2924.4783
1178.5352	3.4317353	2.0466812	2918.7109
1179.5361	3.438596	2.0465498	2925.5339
1180.5371	3.43613	2.0466995	2917.3894
1181.5381	3.443223	2.0465875	2916.5576
1182.5391	3.4450865	2.0468931	2912.4326
1183.54	3.4472606	2.046813	2910.8848
1184.541	3.4537811	2.0469611	2906.9363
1185.542	3.4549026	2.0470626	2902.8125
1186.543	3.456578	2.0466878	2898.1272
1187.5439	3.4604604	2.0468464	2908.0322
1188.5449	3.4621882	2.0468593	2899.9597
1189.5459	3.4655237	2.0469565	2897.0642
1190.5469	3.4681051	2.047029	2892.3643
1191.5479	3.4718688	2.0468228	2887.5864
1192.5488	3.4719422	2.0470009	2887.8032
1193.5498	3.4785683	2.0468361	2884.6428
1194.5508	3.479274	2.0469253	2882.8254
1195.5518	3.4835055	2.0467577	2881.5498
1196.5527	3.4867733	2.0470998	2879.5193
1197.5537	3.4923079	2.0466359	2880.1892
1198.5547	3.4951169	2.0466459	2869.7744
1199.5557	3.4951029	2.0468876	2871.041
1200.5566	3.5015826	2.046736	2865.6057
1201.5576	3.5050955	2.0469382	2863.2712
1202.5586	3.5096252	2.0469835	2863.365
1203.5596	3.5090477	2.0473135	2861.7798
1204.5605	3.5120859	2.0471401	2849.5022
1205.5615	3.5135767	2.0473876	2847.7368
1206.5625	3.5146596	2.0474145	2843.8445
1207.5635	3.5204906	2.0473342	2839.3442
1208.5645	3.5237217	2.0471296	2845.0486
1209.5654	3.5259824	2.0471992	2837.0698
1210.5664	3.5306251	2.0472112	2830.0833
1211.5674	3.5336583	2.0469863	2831.407
1212.5684	3.5360215	2.0468812	2829.6025
1213.5693	3.5386951	2.0473521	2827.7529
1214.5703	3.541539	2.0470545	2822.0642
1215.5713	3.544682	2.0471146	2820.5625
1216.5723	3.5467877	2.0474548	2808.9238
1217.5732	3.548238	2.0472078	2806.0391
1218.5742	3.5543292	2.0470481	2804.7864
1219.5752	3.5569267	2.0470638	2790.9954
1220.5762	3.558553	2.0471087	2774.8989
1221.5771	3.5620668	2.0468264	2766.822
1222.5781	3.5685084	2.0467217	2769.7046
1223.5791	3.5729682	2.0467038	2761.3657
1224.5801	3.5715592	2.0468442	2742.1228
1225.5811	3.5754364	2.0466506	2737.8586
1226.582	3.5798249	2.0466216	2734.165
1227.583	3.5808661	2.0468752	2719.9434
1228.584	3.5854731	2.0466247	2711.9436
1229.585	3.5896194	2.0464399	2700.6941
1230.5859	3.591835	2.0465741	2678.0071
1231.1865	3.5947325	2.0464888	2624.4741