File: datasets/am_bench_2022/raw_data/0-X.11-4/specimen.dat
MTS793|MPT|ENU|1|2|.|/|:|1|0|0|A

Operator Information						Time:	15.200684	Sec	10/13/2021 8:59:42 AM
Operator	Jake Benzing
Project	AM Bench 2022 mini-tensile challenge
Specimen ID	O-X.11-4
Material	PBF-L Inconel 625
Specimen Width	2.56	mm
Specimen Thickness	1.54	mm
Notes
Operator Information End

Data Acquisition						Time:	1016.1936	Sec	10/13/2021 9:16:23 AM
Time	Axial Displacement	Axial Extensometer	Axial Force
Sec	mm	mm	N
15.313477	0.0016098655	-0.00012610243	92.906975
16.314453	0.0025634279	-3.5991427e-06	105.47159
17.31543	0.0071246596	-5.3386622e-05	118.90946
18.316406	0.009744959	3.4017816e-05	134.78072
19.317383	0.011767028	0.0002509625	142.03828
20.318359	0.015448253	0.00013900702	152.42047
21.319336	0.01699272	0.00014810827	166.84372
22.320313	0.022343345	0.00028618737	184.85039
23.321289	0.025085811	0.00043193245	206.69814
24.322266	0.028088233	0.00041088607	224.6299
25.323242	0.030379938	0.00060876773	243.22758
26.324219	0.033979207	0.00078533252	269.00586
27.325195	0.039519817	0.00071841205	289.30432
28.326172	0.041325469	0.0009599959	315.49121
29.327148	0.042024761	0.00091013772	334.03452
30.328125	0.045839779	0.0010368219	355.07416
31.329102	0.047641795	0.0011292952	381.56583
32.330078	0.048808396	0.0011726748	397.95844
33.331055	0.053678859	0.001361697	420.7876
34.332031	0.056558754	0.0013900446	443.10287
35.333008	0.061601836	0.0014855679	469.66037
36.333984	0.06318114	0.0016785157	493.70889
37.334961	0.065644749	0.0018988084	516.03021
38.335938	0.067745492	0.0017872135	539.50348
39.336914	0.073831879	0.0019473542	566.35754
40.337891	0.075816199	0.0020899368	586.03766
41.338867	0.078083523	0.0020908997	608.80237
42.339844	0.080547132	0.0022843548	634.61377
43.34082	0.084861211	0.0023678846	661.96838
44.341797	0.086445838	0.0025873445	689.01337
45.342773	0.089415886	0.002586402	712.34558
46.34375	0.093604267	0.0027365398	732.76971
47.344727	0.095147461	0.0029204192	761.74945
48.345703	0.094967157	0.0029303033	785.32123
49.34668	0.10086079	0.0031545626	819.26813
50.347656	0.10363537	0.0032792857	842.23566
51.348633	0.10747892	0.0034131277	869.71771
52.349609	0.11428919	0.0034800728	904.55701
53.350586	0.11336473	0.0035802347	933.55957
54.351563	0.11755879	0.0038193394	955.39691
55.352539	0.11925795	0.0037905287	983.00983
56.353516	0.12377841	0.0039997031	1009.4604
57.354492	0.12388556	0.0041271239	1036.8621
58.355469	0.12806325	0.0044264407	1066.498
59.356445	0.1325462	0.0043373839	1091.6271
60.357422	0.13555518	0.0045428299	1113.7819
61.358398	0.13953862	0.0046483153	1152.673
62.359375	0.1394915	0.0047443956	1175.7466
63.360352	0.14440781	0.0049193418	1202.9667
64.361328	0.14739348	0.0051248902	1243.1259
65.362305	0.14930342	0.0053246282	1273.5355
66.363281	0.15411277	0.0053974376	1300.3472
67.364258	0.15497455	0.0054780599	1325.4008
68.365234	0.15857217	0.0056597521	1351.5947
69.366211	0.16192126	0.005684637	1379.1298
70.367188	0.16557319	0.0059441817	1411.6472
71.368164	0.16954352	0.0060733072	1436.9315
72.369141	0.16884485	0.0062681851	1474.7207
73.370117	0.17187005	0.0064263013	1500.6837
74.371094	0.17868489	0.0065908679	1529.6802
75.37207	0.17873216	0.0067707193	1558.9802
76.373047	0.18166108	0.0067494186	1581.5613
77.374023	0.18472518	0.0069944579	1616.0715
78.375	0.18963473	0.0071489108	1641.8477
79.375977	0.19422176	0.0073040361	1666.7325
80.376953	0.19234517	0.0075028026	1686.8817
81.37793	0.20040798	0.0076491092	1717.5532
82.378906	0.20008139	0.0077593927	1735.8872
83.379883	0.20235522	0.0078792861	1761.2971
84.380859	0.20804991	0.0080327597	1790.9851
85.381836	0.21292564	0.0082512777	1827.9735
86.382813	0.21634543	0.0084369266	1845.6183
87.383789	0.21449634	0.0085027739	1861.4561
88.384766	0.21915054	0.0087083383	1888.2263
89.385742	0.21819682	0.0089166444	1914.307
90.386719	0.22402506	0.0090279197	1939.2516
91.387695	0.22700888	0.009286616	1966.5101
92.388672	0.231004	0.0094345622	1984.7615
93.389648	0.23501673	0.0096277939	2008.2135
94.390625	0.23722644	0.009680544	2026.5138
95.391602	0.24260661	0.0098899975	2057.7971
96.392578	0.24047498	0.010148345	2072.6628
97.393555	0.2444953	0.010350799	2109.1333
98.394531	0.24719673	0.010559118	2119.9221
99.395508	0.2523331	0.010798432	2143.0669
100.39648	0.25535461	0.011084059	2162.8101
101.39746	0.25629419	0.011254231	2185.74
102.39844	0.26080707	0.011528471	2199.6282
103.39941	0.26458666	0.011853132	2225.1528
104.40039	0.26764506	0.012025093	2235.0347
105.40137	0.27037129	0.012344485	2256.2026
106.40234	0.27641484	0.012613783	2279.4558
107.40332	0.27557689	0.013048904	2295.5583
108.4043	0.27720287	0.013266962	2304.1838
109.40527	0.2812345	0.013589835	2314.3496
110.40625	0.28378597	0.013882727	2332.624
111.40723	0.29032639	0.014347709	2355.3135
112.4082	0.28942758	0.014658649	2361.0771
113.40918	0.29422301	0.01518095	2383.9375
114.41016	0.2972537	0.015680518	2388.1433
115.41113	0.30077633	0.016154541	2405.9541
116.41211	0.30336735	0.016567022	2408.9358
117.41309	0.30466083	0.017111862	2421.2246
118.41406	0.3106688	0.0174702	2437.5378
119.41504	0.31461635	0.018046843	2448.3345
120.41602	0.31588382	0.01867274	2455.7583
121.41699	0.32153139	0.019415081	2473.2292
122.41797	0.32169795	0.019856546	2480.5549
123.41895	0.32493007	0.020570878	2479.8767
124.41992	0.32555294	0.021297077	2491.1096
125.4209	0.32967979	0.021871464	2494.9836
126.42188	0.33393657	0.022720823	2506.6177
127.42285	0.33473685	0.023517089	2515.4858
128.42383	0.3379747	0.02449536	2524.0461
129.4248	0.34436658	0.02534659	2534.781
130.42578	0.34706643	0.026512738	2539.9482
131.42676	0.34914443	0.027395684	2539.0923
132.42773	0.34917885	0.028167529	2549.2039
133.42871	0.35658291	0.029102637	2551.3103
134.42969	0.35625303	0.030159518	2556.793
135.43066	0.35958204	0.031263229	2563.125
136.43164	0.36451289	0.032247066	2564.366
137.43262	0.36754134	0.033300661	2578.4148
138.43359	0.37366691	0.034543779	2585.2581
139.43457	0.37410477	0.03552882	2581.374
140.43555	0.37551442	0.036604136	2583.0774
141.43652	0.38323399	0.037895169	2593.2017
142.4375	0.38421988	0.039413631	2601.8242
143.43848	0.38668081	0.040580828	2601.3657
144.43945	0.38958454	0.041919962	2606.2756
145.44043	0.39194053	0.043316871	2604.5371
146.44141	0.394375	0.044269048	2600.0581
147.44238	0.39790624	0.045264702	2602.0017
148.44336	0.40038297	0.046601016	2614.1011
149.44434	0.40312624	0.047974631	2612.9182
150.44531	0.4095341	0.049300756	2617.8081
151.44629	0.41006273	0.050672505	2621.5051
152.44727	0.41186181	0.051875032	2615.4629
153.44824	0.41600287	0.052884504	2620.6194
154.44922	0.41615817	0.054176256	2623.0933
155.4502	0.4218815	0.055320308	2635.7593
156.45117	0.42538938	0.056894857	2631.8601
157.45215	0.42640647	0.058398996	2630.8247
158.45313	0.43298218	0.059742935	2634.2759
159.4541	0.43186572	0.061088823	2637.6709
160.45508	0.43841928	0.062420029	2641.5254
161.45605	0.44025776	0.063634753	2642.9338
162.45703	0.44257733	0.065038115	2636.8159
163.45801	0.44501364	0.066710159	2646.0554
164.45898	0.4516395	0.068392262	2649.2666
165.45996	0.45231318	0.069952615	2650.5339
166.46094	0.45564491	0.07157471	2647.5693
167.46191	0.45793596	0.072976887	2659.5081
168.46289	0.46111172	0.074562922	2655.2539
169.46387	0.46327925	0.076006532	2654.5969
170.46484	0.4657928	0.077820718	2655.9561
171.46582	0.47023547	0.079354011	2660.4387
172.4668	0.47323564	0.081142843	2665.3936
173.46777	0.47380379	0.082944341	2662.9426
174.46875	0.47786176	0.084336646	2661.8066
175.46973	0.48269799	0.08561299	2660.9194
176.4707	0.48773596	0.087146148	2663.7595
177.47168	0.4904221	0.088798918	2673.2087
178.47266	0.49112254	0.090230495	2665.8362
179.47363	0.49497285	0.09213718	2676.9639
180.47461	0.49614629	0.093965046	2673.5444
181.47559	0.50174236	0.095738947	2675.9458
182.47656	0.50536233	0.097495578	2680.563
183.47754	0.50696582	0.099162221	2679.2358
184.47852	0.50745815	0.10060357	2670.1875
185.47949	0.51122254	0.1021152	2685.9814
186.48047	0.5128631	0.10374722	2676.6509
187.48145	0.51899439	0.10525849	2674.0469
188.48242	0.52052408	0.10676615	2684.6855
189.4834	0.52425313	0.10855301	2683.855
190.48438	0.52761984	0.11042588	2690.0747
191.48535	0.52962339	0.1121461	2689.5754
192.48633	0.53252465	0.11371464	2686.3899
193.4873	0.53830147	0.11530517	2689.2737
194.48828	0.54001254	0.11712188	2698.2668
195.48926	0.53925031	0.11911711	2684.3167
196.49023	0.54677588	0.12072276	2690.0356
197.49121	0.5480628	0.12185548	2691.1021
198.49219	0.55208451	0.12326554	2689.5024
199.49316	0.55516684	0.12466227	2689.8313
200.49414	0.55566949	0.12654555	2704.5452
201.49512	0.55838829	0.12860501	2694.0862
202.49609	0.56252283	0.13021314	2695.9138
203.49707	0.56747723	0.13222067	2704.4502
204.49805	0.5672797	0.13367316	2693.7803
205.49902	0.57287806	0.13515493	2701.9897
206.5	0.57346672	0.13693364	2708.1655
207.50098	0.57821035	0.13859977	2704.1296
208.50195	0.58078003	0.14001799	2701.446
209.50293	0.58407915	0.1418449	2707.6467
210.50391	0.58791423	0.1434164	2707.8416
211.50488	0.5890891	0.14517477	2714.9663
212.50586	0.59175873	0.14741424	2715.8528
213.50684	0.593494	0.14918715	2706.7783
214.50781	0.59880853	0.15080214	2714.0981
215.50879	0.60045218	0.15266395	2712.1191
216.50977	0.60671401	0.15451439	2719.1843
217.51074	0.60723424	0.1562613	2711.7639
218.51172	0.61427623	0.15781987	2716.2791
219.5127	0.61314768	0.15915215	2711.3391
220.51367	0.61853564	0.16071472	2713.509
221.51465	0.62001926	0.16249524	2723.7161
222.51563	0.62205929	0.16463871	2722.2083
223.5166	0.62582535	0.16638245	2714.363
224.51758	0.63054049	0.16834611	2730.2969
225.51855	0.63306761	0.16975431	2718.5332
226.51953	0.63363308	0.17113185	2717.8811
227.52051	0.63673466	0.17284802	2729.2302
228.52148	0.63922894	0.17479192	2730.219
229.52246	0.6439423	0.17649975	2723.2498
230.52344	0.64691949	0.17805949	2731.3223
231.52441	0.65205932	0.1798629	2731.7058
232.52539	0.65181017	0.18169749	2727.7983
233.52637	0.65698099	0.18368818	2738.9158
234.52734	0.66102463	0.18558319	2733.0747
235.52832	0.66061735	0.18733233	2731.3945
236.5293	0.66677481	0.18897326	2738.7637
237.53027	0.66606957	0.19065717	2736.6084
238.53125	0.67322618	0.1925181	2740.4663
239.53223	0.67575634	0.1939964	2732.4426
240.5332	0.67599398	0.195751	2742.6697
241.53418	0.68021613	0.19753644	2738.3691
242.53516	0.6826064	0.19950798	2736.5061
243.53613	0.68696642	0.20135349	2740.5227
244.53711	0.68824637	0.20320769	2748.2375
245.53809	0.69101113	0.20494181	2745.6018
246.53906	0.69289237	0.20667949	2744.0352
247.54004	0.70034152	0.20853324	2749.5586
248.54102	0.70301408	0.21046418	2749.9131
249.54199	0.70587635	0.2126787	2754.5303
250.54297	0.70567173	0.21422929	2742.7952
251.54395	0.71211487	0.21573824	2745.6377
252.54492	0.71155983	0.21750845	2746.5764
253.5459	0.71810865	0.21930583	2754.1509
254.54688	0.71960741	0.2210345	2752.0735
255.54785	0.72136348	0.22285281	2752.238
256.54883	0.72275084	0.22482848	2752.0039
257.5498	0.72667134	0.22654209	2760.7336
258.55078	0.72975081	0.22847	2752.8435
259.55176	0.73583621	0.23033561	2763.8701
260.55273	0.73527217	0.23204578	2753.9121
261.55371	0.73914832	0.233344	2756.6047
262.55469	0.74436492	0.23504581	2762.6438
263.55566	0.74571824	0.23681436	2752.4329
264.55664	0.75290161	0.23872183	2764.2471
265.55762	0.75334686	0.24052195	2764.8701
266.55859	0.75548178	0.24222702	2761.8142
267.55957	0.75959426	0.24387754	2764.4189
268.56055	0.76115966	0.24545857	2765.9087
269.56152	0.76250803	0.24687192	2768.4382
270.5625	0.76839733	0.24867545	2776.0049
271.56348	0.77102029	0.25051153	2767.1106
272.56445	0.7763499	0.25248805	2777.5977
273.56543	0.77814537	0.25433883	2777.1814
274.56641	0.77943265	0.25641942	2764.7332
275.56738	0.78083593	0.25805783	2771.6785
276.56836	0.78652257	0.25993457	2771.0771
277.56934	0.78845346	0.2616559	2771.7834
278.57031	0.7912277	0.26352245	2776.9194
279.57129	0.79508573	0.26546112	2781.8945
280.57227	0.79950291	0.26729843	2779.1697
281.57324	0.80211604	0.26912102	2779.3296
282.57422	0.80285531	0.27083713	2780.2124
283.5752	0.80722642	0.27244264	2782.4766
284.57617	0.80939108	0.27419424	2783.7271
285.57715	0.81481916	0.27615678	2785.9844
286.57813	0.81392169	0.27796251	2782.5386
287.5791	0.81734359	0.27983311	2786.1799
288.58008	0.82010221	0.28148597	2783.5603
289.58105	0.82550716	0.28320223	2782.147
290.58203	0.82699215	0.28475499	2784.3162
291.58301	0.83090949	0.28627881	2785.2883
292.58398	0.83329296	0.28819862	2792.1189
293.58496	0.83910829	0.29023203	2794.0359
294.58594	0.84440571	0.29212928	2797.8962
295.58691	0.84157634	0.29398572	2790.0479
296.58789	0.84548157	0.29572231	2788.0667
297.58887	0.84538937	0.29706201	2785.6965
298.58984	0.85243261	0.29846042	2788.7957
299.59082	0.85577619	0.30007666	2798.231
300.5918	0.85778576	0.30186948	2805.8528
301.59277	0.85825086	0.30389863	2800.386
302.59375	0.8623572	0.30574444	2791.8025
303.59473	0.86401045	0.30752039	2793.4106
304.5957	0.86993504	0.30908039	2799.8025
305.59668	0.87049663	0.31085923	2795.79
306.59766	0.8752265	0.3126713	2800.8008
307.59863	0.87702537	0.31463856	2806.532
308.59961	0.87949842	0.3170056	2802.4026
309.60059	0.88205683	0.31886765	2798.9526
310.60156	0.88762283	0.32037863	2801.2666
311.60254	0.89039892	0.32242244	2804.0684
312.60352	0.89360559	0.32416204	2802.4426
313.60449	0.89973629	0.32564858	2804.7151
314.60547	0.89633429	0.3274996	2809.3865
315.60645	0.90454543	0.32946554	2810.1306
316.60742	0.90455341	0.33142158	2812.9666
317.6084	0.90713501	0.33313599	2810.2859
318.60938	0.91217363	0.33503017	2819.7693
319.61035	0.91829836	0.33712727	2817.4995
320.61133	0.91719407	0.33899605	2809.7598
321.6123	0.92064703	0.34042892	2816.7493
322.61328	0.92780274	0.34216556	2821.0447
323.61426	0.92487466	0.34382823	2812.4746
324.61523	0.92782587	0.34560725	2814.0732
325.61621	0.93247521	0.3475211	2817.3076
326.61719	0.93416244	0.34963962	2821.3733
327.61816	0.93530267	0.3517077	2817.3921
328.61914	0.94119549	0.35341716	2819.2021
329.62012	0.94569337	0.35518545	2818.5913
330.62109	0.94768304	0.357122	2824.8096
331.62207	0.95138687	0.35872838	2821.2749
332.62305	0.95415086	0.36035913	2826.0317
333.62402	0.9564001	0.36201936	2818.5537
334.625	0.95988238	0.36375856	2826.8167
335.62598	0.96176809	0.36528862	2825.7285
336.62695	0.96669471	0.36709911	2825.4353
337.62793	0.96751755	0.36882263	2829.5017
338.62891	0.97102112	0.37043902	2828.2041
339.62988	0.97429442	0.37249255	2828.25
340.63086	0.97929311	0.3743625	2828.6699
341.63184	0.98217916	0.37611499	2831.4473
342.63281	0.98455358	0.37782615	2830.9299
343.63379	0.98646563	0.37980318	2834.7754
344.63477	0.98631215	0.38184068	2829.7869
345.63574	0.99203205	0.38366053	2839.6738
346.63672	0.99800265	0.38588843	2834.6394
347.6377	0.9957149	0.38777348	2831.5691
348.63867	1.0045573	0.38967127	2838.9316
349.63965	1.0059333	0.3910867	2837.157
350.64063	1.009055	0.39320022	2842.1379
351.6416	1.0109642	0.39528456	2843.1924
352.64258	1.0147214	0.39712	2842.0044
353.64355	1.0145333	0.39872506	2836.5171
354.64453	1.0216198	0.40056378	2847.325
355.64551	1.0241129	0.4023999	2851.1414
356.64648	1.0270512	0.40442118	2848.7515
357.64746	1.0283457	0.40623802	2842.8665
358.64844	1.029986	0.40822354	2849.9744
359.64941	1.0360007	0.41000953	2847.0359
360.65039	1.0413663	0.41184914	2850.7656
361.65137	1.0425395	0.4137623	2850.5305
362.65234	1.0414741	0.41538355	2842.5085
363.65332	1.0450255	0.41699088	2847.197
364.6543	1.0476456	0.41904062	2847.1733
365.65527	1.0495464	0.4211387	2857.168
366.65625	1.0544678	0.42281401	2852.2673
367.65723	1.0575347	0.42437631	2851.5371
368.6582	1.0604427	0.42626205	2852.3262
369.65918	1.0653049	0.42787221	2854.3594
370.66016	1.0665046	0.42956322	2855.9497
371.66113	1.0718427	0.43131965	2854.0117
372.66211	1.0739193	0.43340287	2862.283
373.66309	1.0760859	0.43508336	2853.2969
374.66406	1.0782191	0.43677199	2851.5042
375.66504	1.0816696	0.43820536	2858.4033
376.66602	1.085233	0.44024983	2862.8242
377.66699	1.0896233	0.44243813	2865.821
378.66797	1.0913807	0.44436797	2866.5005
379.66895	1.0926758	0.44625464	2861.698
380.66992	1.1001602	0.44805053	2866.5305
381.6709	1.0990682	0.45007789	2866.2849
382.67188	1.1047411	0.45209527	2863.7063
383.67285	1.1057683	0.45377657	2862.7021
384.67383	1.1102513	0.45556074	2868.5002
385.6748	1.1105101	0.45755875	2869.7642
386.67578	1.1146462	0.45942283	2874.884
387.67676	1.1144438	0.46119633	2866.8835
388.67773	1.1240547	0.463231	2867.5435
389.67871	1.1262302	0.46509457	2876.7314
390.67969	1.12669	0.46695307	2872.2268
391.68066	1.1294842	0.46914014	2878.2859
392.68164	1.1313244	0.4710511	2869.6543
393.68262	1.1364088	0.47249976	2868.7046
394.68359	1.1402979	0.47391912	2871.6865
395.68457	1.1432408	0.47565907	2875.2153
396.68555	1.1474108	0.47768721	2875.7341
397.68652	1.1473107	0.47954521	2872.0859
398.6875	1.1486186	0.48116902	2876.1426
399.68848	1.1560432	0.48304275	2883.3782
400.68945	1.1587313	0.48523459	2887.1614
401.69043	1.1619159	0.48725405	2880.3022
402.69141	1.1637102	0.48917484	2885.0686
403.69238	1.16784	0.49096534	2882.3474
404.69336	1.1702876	0.49300393	2889.0632
405.69434	1.1736052	0.49480239	2888.4343
406.69531	1.1709248	0.49644834	2880.0122
407.69629	1.1814266	0.49825448	2885.8271
408.69727	1.1816233	0.49970075	2878.2549
409.69824	1.1837189	0.50136858	2887.8123
410.69922	1.189998	0.50328404	2888.7749
411.7002	1.1909174	0.50537586	2894.6379
412.70117	1.1935675	0.50710607	2892.3862
413.70215	1.196288	0.50913733	2890.1292
414.70313	1.198306	0.51131624	2891.9646
415.7041	1.2034539	0.51291895	2891.6829
416.70508	1.2048002	0.51467669	2890.5664
417.70605	1.2105167	0.51624256	2887.6714
418.70703	1.2122682	0.51787293	2895.9312
419.70801	1.2160915	0.51949537	2895.2046
420.70898	1.2171952	0.52127421	2895.4294
421.70996	1.2186093	0.52331972	2898.8196
422.71094	1.2254053	0.52530086	2905.7268
423.71191	1.2266998	0.52738017	2898.3245
424.71289	1.2308701	0.5294525	2898.0227
425.71387	1.2349757	0.53137505	2899.5974
426.71484	1.2328997	0.53355473	2898.0637
427.71582	1.2379482	0.53530318	2900.3425
428.7168	1.2435049	0.53715336	2908.8809
429.71777	1.2477632	0.53889042	2906.0637
430.71875	1.2472996	0.54070807	2902.2261
431.71973	1.2489073	0.54273558	2902.5374
432.7207	1.2525578	0.54503793	2903.5493
433.72168	1.2579185	0.54695356	2909.8894
434.72266	1.2588724	0.54903519	2907.8359
435.72363	1.2615174	0.55090332	2905.5103
436.72461	1.2680914	0.55246824	2908.5701
437.72559	1.2691084	0.55453789	2912.9719
438.72656	1.2720976	0.55632704	2909.1516
439.72754	1.2750273	0.55802721	2904.165
440.72852	1.2790191	0.55912131	2902.4873
441.72949	1.2793664	0.56052828	2907.7324
442.73047	1.280817	0.56202209	2908.9609
443.73145	1.2854489	0.5638023	2918.2239
444.73242	1.2873034	0.56529301	2909.9067
445.7334	1.295997	0.56748503	2915.4695
446.73438	1.2949483	0.56927639	2914.7925
447.73535	1.3009	0.57132643	2922.8804
448.73633	1.3015171	0.57347095	2919.0854
449.7373	1.3069391	0.5756039	2922.6719
450.73828	1.3090826	0.5774312	2914.1025
451.73926	1.3071513	0.5793668	2916.6509
452.74023	1.3134402	0.58129489	2918.314
453.74121	1.3142598	0.58311385	2923.1135
454.74219	1.3209624	0.58494723	2924.886
455.74316	1.3228589	0.58694351	2919.1558
456.74414	1.3255901	0.58907926	2927.8296
457.74512	1.3308252	0.5910275	2931.0781
458.74609	1.3324494	0.59295571	2925.3079
459.74707	1.3359017	0.59500766	2931.7998
460.74805	1.3382068	0.59682059	2927.3188
461.74902	1.3397365	0.59860253	2925.8813
462.75	1.3444173	0.60058928	2924.6643
463.75098	1.3478465	0.60244489	2930.168
464.75195	1.3522369	0.60436064	2934.2957
465.75293	1.354087	0.60657096	2926.8672
466.75391	1.3570821	0.60825849	2930.0984
467.75488	1.3623557	0.61019176	2934.0808
468.75586	1.3625438	0.6115188	2923.1895
469.75684	1.3631505	0.61348873	2929.2556
470.75781	1.3643165	0.61553001	2931.9045
471.75879	1.3707813	0.61727417	2931.1121
472.75977	1.3727798	0.61906511	2933.0029
473.76074	1.3778529	0.62072754	2936.499
474.76172	1.3808898	0.62237287	2937.4192
475.7627	1.3851109	0.62417072	2938.1284
476.76367	1.3892523	0.62597299	2935.2124
477.76465	1.3900722	0.62773645	2937.283
478.76563	1.3921455	0.62930167	2935.9385
479.7666	1.3955584	0.63133174	2938.5989
480.76758	1.3993076	0.63350499	2940.4731
481.76855	1.4011415	0.63555455	2941.9548
482.76953	1.403919	0.63744187	2933.7114
483.77051	1.4056983	0.63907158	2937.7815
484.77148	1.4100006	0.64090723	2944.2485
485.77246	1.4120083	0.6427514	2943.4873
486.77344	1.4171658	0.64469045	2943.5024
487.77441	1.4216725	0.64640486	2945.0547
488.77539	1.4192371	0.64835548	2943.4431
489.77637	1.4220502	0.65038705	2942.7708
490.77734	1.4287828	0.65249813	2945.8586
491.77832	1.4289521	0.65435916	2946.8086
492.7793	1.4306701	0.65626889	2944.3967
493.78027	1.4376409	0.65833205	2952.7222
494.78125	1.4405806	0.66041791	2952.9839
495.78223	1.4406726	0.66256469	2949.3013
496.7832	1.4442934	0.6643433	2947.967
497.78418	1.4466798	0.66613942	2943.8181
498.78516	1.4540166	0.66819477	2951.6296
499.78613	1.4555907	0.67030966	2957.5786
500.78711	1.4589344	0.6720323	2951.9382
501.78809	1.4610946	0.67390978	2954.3425
502.78906	1.46275	0.67575949	2948.2646
503.79004	1.4661441	0.67739934	2951.1016
504.79102	1.4703063	0.67890733	2952.0574
505.79199	1.4709657	0.68040913	2956.5898
506.79297	1.4748977	0.68208915	2953.4785
507.79395	1.4807283	0.68419909	2962.5774
508.79492	1.4851762	0.68602848	2962.0535
509.7959	1.4839205	0.6879307	2953.519
510.79688	1.4863807	0.68960482	2956.6455
511.79785	1.4910489	0.69137746	2958.5447
512.79883	1.4930692	0.69337046	2963.7007
513.7998	1.4960265	0.69521052	2960.5095
514.80078	1.5005102	0.69723856	2958.5085
515.80176	1.5040729	0.69894785	2961.2246
516.80273	1.5046755	0.70090216	2964.061
517.80371	1.5081754	0.70271534	2962.8955
518.80469	1.5125163	0.70460153	2967.3708
519.80566	1.518337	0.70652455	2969.2068
520.80664	1.5169578	0.70828909	2963.6782
521.80762	1.5234004	0.71028489	2970.1672
522.80859	1.5249583	0.71228874	2968.6147
523.80957	1.5284598	0.71417534	2972.4551
524.81055	1.5317202	0.71623522	2972.0056
525.81152	1.5350031	0.71807557	2962.4697
526.8125	1.5367012	0.71962678	2963.8376
527.81348	1.5382403	0.72126633	2966.5066
528.81445	1.542979	0.7232126	2971.532
529.81543	1.544428	0.72513598	2971.4502
530.81641	1.5471054	0.72713578	2961.7869
531.81738	1.5526913	0.72876501	2972.3865
532.81836	1.5538676	0.73064905	2968.9312
533.81934	1.5580127	0.7322098	2973.656
534.82031	1.5617353	0.73389053	2973.4165
535.82129	1.5641301	0.73576897	2978.762
536.82227	1.5641298	0.73774648	2976.5027
537.82324	1.5697833	0.7399835	2973.488
538.82422	1.5731652	0.74179804	2979.6389
539.8252	1.5778418	0.74426001	2987.4941
540.82617	1.5775204	0.74624342	2974.2925
541.82715	1.5814331	0.7478407	2969.6357
542.82813	1.5858949	0.74996924	2987.3406
543.8291	1.5878266	0.75190383	2974.6741
544.83008	1.5885332	0.75388968	2976.2065
545.83105	1.5946517	0.75557381	2977.3806
546.83203	1.5958136	0.75738657	2979.5095
547.83301	1.6003331	0.75923628	2985.7998
548.83398	1.6024088	0.76101393	2984.2427
549.83496	1.606202	0.76291507	2991.5781
550.83594	1.6085067	0.76495564	2985.2102
551.83691	1.6121219	0.76679128	2979.9768
552.83789	1.6146494	0.7685014	2980.0659
553.83887	1.6170614	0.7702511	2984.8794
554.83984	1.6185639	0.77213866	2984.7205
555.84082	1.623476	0.77403414	2987.4973
556.8418	1.6244652	0.77604187	2984.739
557.84277	1.6303382	0.77812374	2986.9395
558.84375	1.6319857	0.77978557	2986.6768
559.84473	1.6335717	0.78141516	2985.7166
560.8457	1.6367449	0.78365982	2992.2219
561.84668	1.6415038	0.78561777	2984.4731
562.84766	1.6445808	0.78753954	2990.4421
563.84863	1.6478533	0.78957015	2993.1829
564.84961	1.6491606	0.79170585	2993.6094
565.85059	1.6543477	0.79351336	2988.5508
566.85156	1.6579266	0.79524457	2994.7397
567.85254	1.6578144	0.79716206	2989.6919
568.85352	1.6619685	0.7990613	2990.0532
569.85449	1.6640493	0.80071509	2990.7202
570.85547	1.6682024	0.80246675	2991.8645
571.85645	1.6717085	0.80439448	3002.9446
572.85742	1.6716332	0.8065846	2993.1184
573.8584	1.6776769	0.80850303	3003.2988
574.85938	1.6781294	0.81056499	2991.3933
575.86035	1.6843793	0.81242305	2996.8711
576.86133	1.6849971	0.81420875	2994.7144
577.8623	1.6890789	0.8161602	2996.5588
578.86328	1.6933191	0.81814373	3003.189
579.86426	1.6952171	0.81992489	3001.2776
580.86523	1.7013775	0.82189459	3008.6753
581.86621	1.7031335	0.8237868	3003.9512
582.86719	1.7034633	0.82566065	3001.1055
583.86816	1.7056229	0.82762581	2996.8811
584.86914	1.7112716	0.82948792	3002.1328
585.87012	1.7100006	0.8311103	2996.8606
586.87109	1.7189146	0.83280182	3002.3455
587.87207	1.7200499	0.83439279	3003.8462
588.87305	1.721882	0.83633459	3006.0449
589.87402	1.7230554	0.83844912	3005.1284
590.875	1.7282032	0.84043437	3007.5056
591.87598	1.7312003	0.842682	3010.4583
592.87695	1.7332965	0.84459716	3004.094
593.87793	1.739091	0.8465355	3009.2375
594.87891	1.7386101	0.84815079	3003.5789
595.87988	1.7458218	0.85004717	3008.6506
596.88086	1.7464755	0.85182112	3007.5046
597.88184	1.7498536	0.85370547	3011.958
598.88281	1.7518446	0.85550362	3005.2725
599.88379	1.7564336	0.8574397	3018.949
600.88477	1.7578596	0.85952073	3012.0391
601.88574	1.761487	0.86158788	3011.8311
602.88672	1.7658943	0.86385363	3014.9956
603.8877	1.7678165	0.86589062	3015.1826
604.88867	1.7695364	0.86760175	3005.3313
605.88965	1.7705263	0.8696115	3010.29
606.89063	1.7781307	0.87169933	3018.429
607.8916	1.7806333	0.87379509	3019.4744
608.89258	1.780637	0.87549126	3011.3264
609.89355	1.7851804	0.87739104	3016.0735
610.89453	1.7871543	0.87930995	3016.0737
611.89551	1.7909108	0.88113678	3014.1284
612.89648	1.7953237	0.88296163	3011.2302
613.89746	1.7948807	0.88435572	3007.6509
614.89844	1.80204	0.8862744	3021.1912
615.89941	1.8020941	0.88798088	3019.7813
616.90039	1.8070474	0.89029914	3031.2791
617.90137	1.8131549	0.89252615	3029.7024
618.90234	1.810061	0.89452624	3013.595
619.90332	1.8136836	0.89659888	3022.8105
620.9043	1.8214194	0.89850211	3026.0034
621.90527	1.8245882	0.90033793	3024.0308
622.90625	1.8251951	0.90219045	3023.6531
623.90723	1.8262345	0.9044897	3024.2017
624.9082	1.8287423	0.90637898	3015.8772
625.90918	1.8323723	0.90781087	3015.5002
626.91016	1.8386505	0.90968829	3024.561
627.91113	1.8413464	0.91185373	3029.2217
628.91211	1.8413095	0.91418046	3027.5564
629.91309	1.8473271	0.91596431	3023.1794
630.91406	1.8507143	0.91777438	3028.2686
631.91504	1.8506978	0.91980433	3023.0288
632.91602	1.8553969	0.92159313	3026.4229
633.91699	1.8603355	0.92374349	3028.3792
634.91797	1.8611015	0.92558026	3024.009
635.91895	1.8610753	0.9274742	3024.9956
636.91992	1.864626	0.92926729	3029.2625
637.9209	1.8687707	0.93132752	3029.2722
638.92188	1.8729219	0.93340641	3029.7407
639.92285	1.8746575	0.93534714	3029.228
640.92383	1.877098	0.93757212	3030.0955
641.9248	1.8838438	0.93993652	3032.6445
642.92578	1.8846434	0.94197047	3033.9883
643.92676	1.8882952	0.94387943	3027.3394
644.92773	1.8908576	0.94584537	3034.1414
645.92871	1.8920326	0.94758236	3025.7014
646.92969	1.8982249	0.9491958	3033.501
647.93066	1.8986318	0.95125055	3029.5593
648.93164	1.899845	0.9531287	3030.1997
649.93262	1.9052604	0.95505404	3033.1475
650.93359	1.9102998	0.95686001	3035.948
651.93457	1.9091361	0.95870221	3033.8687
652.93555	1.9131781	0.96082264	3035.2698
653.93652	1.915815	0.96289045	3038.8853
654.9375	1.9219785	0.96502453	3034.0051
655.93848	1.9226774	0.96698546	3035.1567
656.93945	1.9233029	0.96870989	3031.374
657.94043	1.9277428	0.9703815	3034.7136
658.94141	1.9330084	0.9723959	3043.0913
659.94238	1.9365319	0.97439408	3038.5098
660.94336	1.9396813	0.97634047	3040.4377
661.94434	1.9421747	0.97824591	3035.2053
662.94531	1.9425528	0.98028451	3035.436
663.94629	1.9483199	0.98218805	3036.5786
664.94727	1.9503925	0.98405927	3042.5745
665.94824	1.9567493	0.98611271	3046.8401
666.94922	1.9532988	0.98810619	3040.0518
667.9502	1.9579715	0.99013108	3035.0911
668.95117	1.9633566	0.99199998	3041.3035
669.95215	1.9656321	0.99380529	3039.5327
670.95313	1.9696822	0.99573249	3038.5078
671.9541	1.9691881	0.9979291	3045.8591
672.95508	1.9753442	1.0001554	3045.8333
673.95605	1.9765913	1.0022858	3039.4932
674.95703	1.9783826	1.0045475	3040.9434
675.95801	1.9818	1.0068662	3045.6172
676.95898	1.9872781	1.0090381	3046.3418
677.95996	1.9867593	1.0111592	3043.7417
678.96094	1.9932774	1.0126989	3041.8286
679.96191	1.9937954	1.0146465	3042.3289
680.96289	1.9981786	1.0165095	3043.0303
681.96387	2.0019057	1.0184915	3050.9861
682.96484	2.0048585	1.0206329	3043.9968
683.96582	2.0078096	1.0224288	3044.3062
684.9668	2.0099661	1.0245311	3052.0532
685.96777	2.0138776	1.0264425	3050.5959
686.96875	2.0150874	1.0283805	3044.1311
687.96973	2.0201848	1.0303364	3051.3225
688.9707	2.024117	1.032166	3054.0388
689.97168	2.0249331	1.0341525	3049.9817
690.97266	2.0286274	1.0362622	3053.7405
691.97363	2.032933	1.0383881	3050.449
692.97461	2.0308177	1.0402943	3051.1853
693.97559	2.036556	1.0427712	3051.4111
694.97656	2.041795	1.0446409	3050.719
695.97754	2.0446842	1.0463268	3048.8167
696.97852	2.0459297	1.0481822	3049.7793
697.97949	2.0509179	1.0503312	3052.8723
698.98047	2.0514538	1.0523866	3052.5051
699.98145	2.0514221	1.0543717	3049.49
700.98242	2.0591002	1.0566821	3051.9568
701.9834	2.0598614	1.0586171	3052.0583
702.98438	2.0658295	1.060352	3049.5225
703.98535	2.0657804	1.0619358	3044.8218
704.98633	2.0699439	1.0637686	3054.8462
705.9873	2.0719428	1.065647	3049.6096
706.98828	2.0793836	1.0675309	3056.5999
707.98926	2.0786452	1.0695447	3056.2014
708.99023	2.0856304	1.0719388	3065.7805
709.99121	2.0860844	1.0739858	3057.6433
710.99219	2.0868657	1.0758915	3054.0496
711.99316	2.0914731	1.0778142	3061.0913
712.99414	2.0952704	1.0798422	3058.4978
713.99512	2.099936	1.081784	3063.762
714.99609	2.1021564	1.0842946	3062.9326
715.99707	2.1039512	1.0866828	3060.6187
716.99805	2.1075263	1.0887295	3059.2468
717.99902	2.1102738	1.0907757	3057.3735
719	2.1151462	1.0926175	3061.2183
720.00098	2.1144454	1.0945275	3060.4836
721.00195	2.1182258	1.0968226	3060.7578
722.00293	2.1234424	1.0990018	3063.4495
723.00391	2.1248367	1.1008704	3058.3267
724.00488	2.1270144	1.1027019	3058.7351
725.00586	2.1266737	1.1044813	3057.1389
726.00684	2.1351342	1.1066355	3061.6008
727.00781	2.1356127	1.1088257	3060.4028
728.00879	2.1383784	1.11069	3052.8445
729.00977	2.1422164	1.1127529	3064.1533
730.01074	2.1463146	1.1147861	3061.5908
731.01172	2.1478059	1.1162992	3058.6272
732.0127	2.1519184	1.1182988	3062.6492
733.01367	2.15468	1.1205484	3066.4539
734.01465	2.1591117	1.122515	3063.0342
735.01563	2.1599178	1.1245021	3064.2805
736.0166	2.1639106	1.1267092	3068.5625
737.01758	2.1672571	1.1288048	3071.4407
738.01855	2.1680036	1.1309848	3066.2734
739.01953	2.1753168	1.1331104	3070.2673
740.02051	2.1769493	1.1351516	3067.6768
741.02148	2.1774035	1.1369796	3065.9106
742.02246	2.1806736	1.1388812	3069.6868
743.02344	2.1860299	1.1408989	3068.5764
744.02441	2.1884964	1.1432157	3070.8987
745.02539	2.1915591	1.1451001	3065.8464
746.02637	2.1941512	1.1470802	3064.9307
747.02734	2.1963634	1.149037	3067.1799
748.02832	2.2011442	1.1512693	3075.375
749.0293	2.2005093	1.1531312	3063.7336
750.03027	2.2046783	1.1557324	3075.1624
751.03125	2.2108247	1.1578797	3069.6802
752.03223	2.2105794	1.1598585	3065.4653
753.0332	2.2155738	1.1621451	3070.2268
754.03418	2.2198589	1.1642189	3067.8054
755.03516	2.2207043	1.1661339	3073.9788
756.03613	2.2237358	1.1682581	3064.9211
757.03711	2.2266562	1.170169	3066.7078
758.03809	2.2291095	1.1721989	3072.531
759.03906	2.2360804	1.1739061	3072.3918
760.04004	2.2361777	1.1758544	3075.1768
761.04102	2.2401133	1.1777844	3073.5813
762.04199	2.2407649	1.180025	3079.0405
763.04297	2.2462931	1.1823014	3071.8708
764.04395	2.2484639	1.1842256	3068.5957
765.04492	2.2521746	1.186227	3074.1863
766.0459	2.254564	1.1883807	3074.9194
767.04688	2.2562041	1.1906265	3071.1687
768.04785	2.2602282	1.1926284	3069.3115
769.04883	2.2625005	1.1944522	3074.5076
770.0498	2.2649648	1.1966941	3070.7856
771.05078	2.2694025	1.1989702	3074.5388
772.05176	2.2708459	1.2012793	3076.1147
773.05273	2.2759583	1.2033125	3073.0405
774.05371	2.2796252	1.2056583	3074.0964
775.05469	2.2779696	1.2078475	3070.6006
776.05566	2.2847266	1.2096946	3070.4192
777.05664	2.2851784	1.2115391	3075.0037
778.05762	2.2888305	1.2138225	3076.783
779.05859	2.2919579	1.2163852	3075.3347
780.05957	2.2966425	1.2186366	3079.5645
781.06055	2.301966	1.2209305	3079.8877
782.06152	2.3029225	1.2229416	3078.509
783.0625	2.305187	1.225009	3076.26
784.06348	2.3087108	1.2270949	3076.7361
785.06445	2.3088753	1.2289737	3073.1997
786.06543	2.3124635	1.2310374	3077.9292
787.06641	2.3162656	1.2331264	3077.0806
788.06738	2.318049	1.2355695	3079.7288
789.06836	2.322752	1.2379936	3082.512
790.06934	2.3224568	1.2403101	3078.2471
791.07031	2.3320417	1.2429087	3086.1372
792.07129	2.3335233	1.2448444	3072.7017
793.07227	2.3335111	1.2470824	3077.554
794.07324	2.3344233	1.249382	3075.9231
795.07422	2.3407609	1.251561	3076.0088
796.0752	2.3434508	1.2537367	3083.5217
797.07617	2.3464918	1.2556373	3078.2131
798.07715	2.352499	1.2575539	3083.322
799.07813	2.3550303	1.2593802	3073.4109
800.0791	2.3561325	1.2613257	3075.5759
801.08008	2.3597517	1.263364	3083.1362
802.08105	2.3605275	1.2653316	3077.2388
803.08203	2.365258	1.2676985	3080.4082
804.08301	2.3723631	1.2696251	3077.8757
805.08398	2.3690786	1.2716976	3078.9331
806.08496	2.3716521	1.2740703	3084.6963
807.08594	2.3758497	1.2762198	3078.1467
808.08691	2.3835542	1.2786072	3084.9688
809.08789	2.383127	1.2807628	3077.8589
810.08887	2.38503	1.2826189	3071.2432
811.08984	2.3903694	1.2847118	3078.4492
812.09082	2.3928688	1.2867982	3086.2153
813.0918	2.3932273	1.2891016	3087.7881
814.09277	2.3994451	1.2912253	3082.686
815.09375	2.4007807	1.2936159	3084.4514
816.09473	2.4040205	1.2960695	3087.614
817.0957	2.4064214	1.2984601	3082.1863
818.09668	2.4086943	1.3008265	3083.2598
819.09766	2.411659	1.3028293	3075.187
820.09863	2.4162347	1.3046324	3080.7517
821.09961	2.4191797	1.3068556	3084.3064
822.10059	2.4211094	1.3089458	3086.1885
823.10156	2.4225338	1.310932	3079.6025
824.10254	2.4290257	1.3131725	3085.4729
825.10352	2.4306638	1.3155986	3087.6606
826.10449	2.4328501	1.3182088	3079.906
827.10547	2.4375277	1.320624	3083.1145
828.10645	2.4401906	1.3226601	3078.9702
829.10742	2.4436486	1.3249152	3082.1377
830.1084	2.4460158	1.326775	3075.6919
831.10938	2.450778	1.3290577	3091.0969
832.11035	2.4506743	1.3310076	3083.0415
833.11133	2.4548173	1.3332689	3075.2822
834.1123	2.4549863	1.3348712	3078.4272
835.11328	2.4608991	1.3369099	3086.376
836.11426	2.463197	1.3390082	3082.7715
837.11523	2.4701943	1.3414664	3088.8176
838.11621	2.4691966	1.3437753	3089.3967
839.11719	2.4727511	1.3459774	3083.2112
840.11816	2.4739175	1.3489776	3090.5264
841.11914	2.476352	1.351371	3083.9751
842.12012	2.4848475	1.3540837	3092.1387
843.12109	2.4861588	1.3563737	3082.9795
844.12207	2.4859593	1.3584989	3083.7078
845.12305	2.4910357	1.3604349	3083.0442
846.12402	2.4967461	1.3622957	3086.7539
847.125	2.4957707	1.364377	3082.3748
848.12598	2.4994605	1.3664339	3081.8701
849.12695	2.5032263	1.3686073	3087.7644
850.12793	2.5072882	1.3710889	3091.3806
851.12891	2.5104303	1.3736637	3089.6047
852.12988	2.511188	1.375809	3087.5798
853.13086	2.5154681	1.3780905	3091.9946
854.13184	2.5174789	1.3805069	3087.8442
855.13281	2.5224681	1.3830365	3093.6057
856.13379	2.5226495	1.3855722	3088.364
857.13477	2.5287175	1.3879364	3090.8972
858.13574	2.5315285	1.3905784	3093.616
859.13672	2.5344813	1.3929402	3091.1213
860.1377	2.5348403	1.3947828	3084.8533
861.13867	2.5386219	1.3971546	3089.113
862.13965	2.5404119	1.3994397	3087.1169
863.14063	2.5462832	1.401618	3084.2339
864.1416	2.5456367	1.4037777	3088.5215
865.14258	2.5497615	1.4060197	3088.6724
866.14355	2.5574484	1.408262	3093.5996
867.14453	2.5539079	1.4109585	3090.563
868.14551	2.5578249	1.4135268	3085.5688
869.14648	2.5649912	1.4159652	3088.5999
870.14746	2.5677159	1.4183415	3094.4753
871.14844	2.5691891	1.4206792	3091.1436
872.14941	2.5742655	1.4229743	3083.3147
873.15039	2.576478	1.4251127	3086.8967
874.15137	2.577116	1.4273738	3084.1985
875.15234	2.5822837	1.4295975	3089.3652
876.15332	2.5853567	1.4318554	3089.8159
877.1543	2.5877883	1.4339283	3088.3735
878.15527	2.5919917	1.4362483	3093.8594
879.15625	2.593961	1.438536	3088.4338
880.15723	2.5928876	1.4408597	3089.1523
881.1582	2.6021438	1.4431301	3088.8882
882.15918	2.6033521	1.4454912	3092.0779
883.16016	2.6029577	1.4481009	3091.3904
884.16113	2.6075282	1.4508635	3085.7947
885.16211	2.609072	1.4532139	3085.2944
886.16309	2.6143277	1.4553398	3088.8237
887.16406	2.6181564	1.45814	3094.3274
888.16504	2.6223128	1.4604162	3090.6003
889.16602	2.6224475	1.4627662	3087.5281
890.16699	2.6276076	1.465144	3087.7629
891.16797	2.6306098	1.4676384	3095.4849
892.16895	2.6343005	1.4699816	3089.6499
893.16992	2.6331189	1.4725881	3088.9912
894.1709	2.6393197	1.4747813	3088.1016
895.17188	2.6415703	1.4767735	3079.9727
896.17285	2.6418939	1.4792843	3086.9075
897.17383	2.6458712	1.4820043	3087.1772
898.1748	2.6498075	1.4843417	3086.48
899.17578	2.6539695	1.4865812	3087.6143
900.17676	2.6559007	1.4893248	3090.3584
901.17773	2.6581862	1.4920661	3086.3452
902.17871	2.6624799	1.4943725	3080.0994
903.17969	2.6651037	1.4967651	3086.4656
904.18066	2.6700826	1.4990767	3085.7952
905.18164	2.6731951	1.5015593	3093.3816
906.18262	2.6708081	1.5037549	3084.2073
907.18359	2.6791143	1.5060536	3091.2913
908.18457	2.6830637	1.5086324	3093.1316
909.18555	2.6829753	1.5112216	3089.21
910.18652	2.6858616	1.5136123	3088.5535
911.1875	2.6882753	1.5157824	3084.0625
912.18848	2.6934667	1.5186713	3097.8652
913.18945	2.6958058	1.5214437	3094.2754
914.19043	2.6972921	1.5241162	3084.0029
915.19141	2.7010183	1.5263616	3082.3721
916.19238	2.7051108	1.5284183	3089.0122
917.19336	2.7062361	1.5310597	3090.6885
918.19434	2.713815	1.5335127	3087.4312
919.19531	2.7129974	1.5358022	3083.0127
920.19629	2.7181642	1.538197	3088.8442
921.19727	2.7192388	1.5406659	3083.0845
922.19824	2.7244601	1.5430808	3085.7844
923.19922	2.7239006	1.5457147	3089.6978
924.2002	2.7282708	1.548504	3086.1287
925.20117	2.7326322	1.5511378	3085.7925
926.20215	2.7330456	1.5533615	3081.0935
927.20313	2.7348561	1.5560627	3088.6074
928.2041	2.7420545	1.5587039	3089.8318
929.20508	2.7431846	1.5613803	3089.5242
930.20605	2.7464075	1.5641212	3088.3948
931.20703	2.7509091	1.5669895	3087.2476
932.20801	2.7531292	1.5697229	3091.6133
933.20898	2.7567718	1.5725307	3082.9753
934.20996	2.7616966	1.5750141	3084.3235
935.21094	2.7602556	1.5773512	3086.3933
936.21191	2.7654142	1.579812	3085.7573
937.21289	2.7700276	1.5825933	3085.8906
938.21387	2.7708564	1.585555	3085.3838
939.21484	2.7734346	1.5881021	3079.2517
940.21582	2.7753732	1.5902621	3076.0681
941.2168	2.7787383	1.5926708	3079.4832
942.21777	2.7792821	1.5953312	3083.7339
943.21875	2.7836132	1.5978764	3082.4727
944.21973	2.7871215	1.6005689	3081.6328
945.2207	2.7925923	1.603287	3082.2153
946.22168	2.7951393	1.6061994	3086.4089
947.22266	2.7982814	1.6088237	3081.5596
948.22363	2.8003113	1.6115347	3083.7454
949.22461	2.8048346	1.6141386	3085.0505
950.22559	2.8050323	1.6164004	3077.0042
951.22656	2.8069029	1.6185359	3081.5452
952.22754	2.813853	1.6211669	3084.6504
953.22852	2.8139696	1.6239498	3083.5569
954.22949	2.8173504	1.626985	3082.6272
955.23047	2.8207448	1.6296523	3082.1082
956.23145	2.8247473	1.6325645	3083.3599
957.23242	2.8292136	1.6356697	3086.6548
958.2334	2.8293569	1.6382627	3077.4072
959.23438	2.832263	1.6409143	3071.9871
960.23535	2.8373289	1.6435195	3077.355
961.23633	2.8389237	1.6466002	3081.7441
962.2373	2.8435793	1.6489199	3079.4246
963.23828	2.8429508	1.6513647	3080.5083
964.23926	2.8464468	1.6539841	3074.2607
965.24023	2.8482935	1.6566567	3084.2761
966.24121	2.8545032	1.6596366	3085.8801
967.24219	2.8548229	1.6620421	3074.9929
968.24316	2.8598108	1.6645156	3077.7585
969.24414	2.8644745	1.6668041	3078.8477
970.24512	2.8638051	1.6695966	3075.9358
971.24609	2.8704569	1.6726061	3075.0193
972.24707	2.8709173	1.6753618	3080.1628
973.24805	2.8749821	1.6784549	3075.4268
974.24902	2.8778176	1.6811599	3077.4827
975.25	2.8821471	1.6837525	3081.0911
976.25098	2.8817139	1.6865555	3076.3933
977.25195	2.8858256	1.68945	3072.3101
978.25293	2.8913407	1.6921635	3078.3494
979.25391	2.8951581	1.6946669	3072.0266
980.25488	2.8970735	1.6973149	3081.8767
981.25586	2.8993869	1.6998831	3075.7644
982.25684	2.9030614	1.7026184	3076.0657
983.25781	2.906029	1.7051959	3074.7354
984.25879	2.909102	1.7082423	3080.0498
985.25977	2.9097021	1.7111411	3075.0168
986.26074	2.912375	1.7137368	3072.8213
987.26172	2.917273	1.7161433	3067.4473
988.2627	2.9189465	1.7187886	3070.448
989.26367	2.9254422	1.7214601	3069.4363
990.26465	2.9262357	1.7238153	3070.5278
991.26563	2.9288108	1.7267004	3070.4468
992.2666	2.9310701	1.7301991	3070.4795
993.26758	2.9348967	1.7331982	3068.4768
994.26855	2.9388764	1.7363647	3068.2859
995.26953	2.9424834	1.7393023	3075.946
996.27051	2.9455645	1.7425773	3071.2156
997.27148	2.9489784	1.7455992	3070.7883
998.27246	2.9513078	1.7488058	3063.0684
999.27344	2.9538786	1.7517755	3069.2029
1000.2744	2.9583144	1.7544094	3066.3208
1001.2754	2.960516	1.7570887	3062.4119
1002.2764	2.963999	1.7598079	3067.2097
1003.2773	2.9625897	1.7623672	3059.906
1004.2783	2.9685829	1.764833	3072.0667
1005.2793	2.9710946	1.7677412	3070.2173
1006.2803	2.9748065	1.7707103	3063.1309
1007.2813	2.9783862	1.7736338	3063.74
1008.2822	2.9823124	1.7772151	3066.1025
1009.2832	2.9836171	1.7803278	3058.8533
1010.2842	2.9846931	1.7832677	3057.9866
1011.2852	2.988447	1.7861313	3057.6094
1012.2861	2.9932432	1.788717	3058.519
1013.2871	2.9912138	1.7913028	3058.8213
1014.2881	2.9994876	1.7935746	3058.0127
1015.2891	2.9990473	1.7963732	3056.7361
1016.29	3.0065026	1.7989372	3056.4727
1017.291	3.0095084	1.8017609	3061.104
1018.292	3.0112698	1.8044575	3061.9636
1019.293	3.0141964	1.8075207	3057.3093
1020.2939	3.01194	1.8110545	3059.4082
1021.2949	3.0234122	1.8142527	3057.1829
1022.2959	3.0202343	1.8172964	3051.8533
1023.2969	3.0245516	1.8203027	3046.3245
1024.2979	3.0290015	1.8230343	3055.668
1025.2988	3.0284157	1.8250039	3042.0327
1026.2998	3.0360718	1.8269233	3047.7739
1027.3008	3.0380003	1.8292415	3055.418
1028.3018	3.0392368	1.8320632	3050.3557
1029.3027	3.0445819	1.8351203	3054.6155
1030.3037	3.0490942	1.8381788	3051.7178
1031.3047	3.0511131	1.8410369	3049.5029
1032.3057	3.0542767	1.8438838	3054.3794
1033.3066	3.0549748	1.8469787	3044.7883
1034.3076	3.0591464	1.8502436	3047.4397
1035.3086	3.0595384	1.8535349	3050.4565
1036.3096	3.0637879	1.8571501	3046.6487
1037.3105	3.0668261	1.8598474	3041.7532
1038.3115	3.0705717	1.8626349	3036.0085
1039.3125	3.0729938	1.8655419	3047.6204
1040.3135	3.0760586	1.8688548	3040.8484
1041.3145	3.0746078	1.8716499	3034.0615
1042.3154	3.0804331	1.8749214	3033.4104
1043.3164	3.0876298	1.8776759	3038.6936
1044.3174	3.0886142	1.8803087	3036.8079
1045.3184	3.0938272	1.8837662	3042.2747
1046.3193	3.0935919	1.8867174	3033.5759
1047.3203	3.0993259	1.8902779	3038.9087
1048.3213	3.101366	1.8928604	3030.8213
1049.3223	3.1038871	1.8955176	3036.4575
1050.3232	3.1070628	1.8986462	3029.8599
1051.3242	3.1080539	1.9017677	3031.4243
1052.3252	3.1116116	1.9049994	3028.2563
1053.3262	3.111773	1.9074565	3020.9451
1054.3271	3.1153111	1.9101273	3027.2058
1055.3281	3.1223898	1.9133372	3028.7148
1056.3291	3.1254432	1.9168664	3029.25
1057.3301	3.1287291	1.9199749	3024.7876
1058.3311	3.1296358	1.9224155	3021.9456
1059.332	3.134207	1.9254528	3029.9497
1060.333	3.1369545	1.9284307	3025.5686
1061.334	3.1408665	1.931704	3023.6013
1062.335	3.1440411	1.9344867	3020.2705
1063.3359	3.146436	1.9372993	3021.5313
1064.3369	3.1483543	1.9405106	3013.9543
1065.3379	3.1517916	1.9438125	3015.8269
1066.3389	3.1558015	1.9466976	3012.8579
1067.3398	3.1555541	1.9499303	3013.782
1068.3408	3.1610892	1.9540536	3017.3525
1069.3418	3.1638088	1.957391	3008.1301
1070.3428	3.1665468	1.9602426	3010.4495
1071.3438	3.1677005	1.9629965	3006.4109
1072.3447	3.1737778	1.9658478	3009.2661
1073.3457	3.1782188	1.969159	3009.9734
1074.3467	3.1771638	1.9720995	3002.4937
1075.3477	3.1809509	1.9751124	3008.394
1076.3486	3.1841826	1.9786432	3008.1057
1077.3496	3.1880622	1.9820035	3004.0225
1078.3506	3.1923354	1.9846398	2996.4983
1079.3516	3.1952593	1.9876972	3004.3906
1080.3525	3.1961672	1.9906163	2997.6897
1081.3535	3.2001143	1.9936421	3003.1563
1082.3545	3.2048814	1.9969505	2996.2974
1083.3555	3.2040763	2.0000076	2988.5591
1084.3564	3.2123635	2.0024538	2990.7932
1085.3574	3.2117059	2.0049202	2985.8396
1086.3584	3.2177205	2.0077538	2993.5513
1087.3594	3.220294	2.0109446	2997.2419
1088.3604	3.2180741	2.0140245	2984.1841
1089.3613	3.2223911	2.0172095	2985.5298
1090.3623	3.2292442	2.0202534	2991.4785
1091.3633	3.230653	2.0235641	2985.7866
1092.3643	3.2317748	2.0271502	2985.3987
1093.3652	3.234673	2.0302432	2978.5396
1094.3662	3.2402568	2.0332577	2977.6509
1095.3672	3.2413828	2.0360651	2975.2893
1096.3682	3.2468624	2.0392723	2980.9072
1097.3691	3.2488101	2.0425131	2974.0881
1098.3701	3.2512074	2.045331	2973.4487
1099.3711	3.2538285	2.0477319	2975.3806
1100.3721	3.2561638	2.0490539	2968.9031
1101.373	3.256326	2.0502131	2966.6992
1102.374	3.2645357	2.0505228	2964.8306
1103.375	3.2652252	2.0509746	2959.7725
1104.376	3.2680655	2.0514166	2962.9492
1105.377	3.2732899	2.0516849	2956.6592
1106.3779	3.2766862	2.0517445	2960.4722
1107.3789	3.2774913	2.05195	2961.4661
1108.3799	3.2805343	2.0521288	2951.0413
1109.3809	3.2854548	2.0522017	2953.8789
1110.3818	3.2872133	2.0522504	2955.5408
1111.3828	3.2883654	2.0525324	2946.5095
1112.3838	3.2887855	2.052402	2945.875
1113.3848	3.2960391	2.0526066	2950.5156
1114.3857	3.3010242	2.0524266	2942.8884
1115.3867	3.3012681	2.0522504	2947.24
1116.3877	3.3052058	2.0523169	2941.6196
1117.3887	3.3081172	2.0522807	2939.49
1118.3896	3.3107216	2.0522861	2935.7437
1119.3906	3.3126643	2.0524867	2933.3901
1120.3916	3.3190925	2.0524178	2938.5464
1121.3926	3.3214381	2.0523825	2931.3228
1122.3936	3.3245866	2.0525072	2939.9775
1123.3945	3.3278522	2.0524881	2930.1067
1124.3955	3.3296707	2.0524836	2931.217
1125.3965	3.3339179	2.0526352	2923.1047
1126.3975	3.3359535	2.0525382	2921.9241
1127.3984	3.3377111	2.0525131	2913.926
1128.3994	3.3403146	2.0526028	2919.3196
1129.4004	3.343837	2.0526979	2914.8645
1130.4014	3.3460855	2.0524909	2913.8423
1131.4023	3.3476555	2.0527043	2910.7307
1132.4033	3.3525896	2.0526521	2909.3694
1133.4043	3.3576601	2.0525436	2908.4624
1134.4053	3.3588212	2.052701	2897.1963
1135.4063	3.364933	2.0526471	2906.3486
1136.4072	3.3651171	2.0525181	2895.2271
1137.4082	3.3681531	2.0525341	2895.8025
1138.4092	3.3728228	2.0525987	2893.6733
1139.4102	3.3749082	2.052485	2892.6704
1140.4111	3.3759952	2.0523055	2890.9626
1141.4121	3.3799789	2.052634	2884.677
1142.4131	3.3851786	2.0526719	2890.4458
1143.4141	3.3874063	2.0525079	2881.3191
1144.415	3.389462	2.0525565	2877.4717
1145.416	3.3933983	2.0525334	2879.6384
1146.417	3.3945122	2.0524523	2874.2986
1147.418	3.3993981	2.0524747	2878.8027
1148.4189	3.403038	2.0525889	2873.0356
1149.4199	3.4034595	2.0527084	2867.9163
1150.4209	3.4057164	2.052613	2861.6326
1151.4219	3.4113719	2.0526116	2862.0588
1152.4229	3.4137142	2.0529008	2849.7727
1153.4238	3.4126334	2.0528469	2852.9734
1154.4248	3.4177766	2.0526643	2855.1401
1155.4258	3.4244721	2.0528259	2844.9436
1156.4268	3.42311	2.0529296	2840.4834
1157.4277	3.4263163	2.0528293	2844.1702
1158.4287	3.4306967	2.0527031	2841.4387
1159.4297	3.4299507	2.0526643	2841.6897
1160.4307	3.438607	2.0528874	2834.1223
1161.4316	3.4413445	2.0527377	2832.5164
1162.4326	3.4418776	2.0525391	2825.5117
1163.4336	3.4446836	2.0529122	2828.8452
1164.4346	3.4508779	2.0527024	2833.3066
1165.4355	3.4524035	2.0528674	2822.1238
1166.4365	3.4572256	2.0531058	2819.3472
1167.4375	3.458307	2.0530598	2804.6519
1168.4385	3.4616339	2.0525417	2803.1658
1169.4395	3.4642932	2.0527158	2804.1248
1170.4404	3.4690201	2.0527356	2809.5242
1171.4414	3.4712656	2.0527236	2808.8623
1172.4424	3.4717751	2.0529888	2794.3794
1173.4434	3.477838	2.0529797	2796.4221
1174.4443	3.4812729	2.0525959	2792.238
1175.4453	3.4804502	2.0526557	2790.0161
1176.4463	3.4855149	2.0527556	2780.9631
1177.4473	3.488831	2.0527122	2780.7361
1178.4482	3.491173	2.0525262	2778.5056
1179.4492	3.4950395	2.0526354	2778.6636
1180.4502	3.4955144	2.0525317	2771.2004
1181.4512	3.4989722	2.0526757	2764.5068
1182.4521	3.5012178	2.0527036	2760.0557
1183.4531	3.5053599	2.0526934	2756.4436
1184.4541	3.5084877	2.0525839	2750.969
1185.4551	3.5128143	2.0527813	2754.3369
1186.4561	3.5141885	2.0525656	2748.6021
1187.457	3.5178254	2.0526154	2749.4429
1188.458	3.5223689	2.0527716	2744.7603
1189.459	3.5239415	2.052439	2739.7634
1190.46	3.5269237	2.052474	2731.2231
1191.4609	3.5296686	2.0525882	2725.4844
1192.4619	3.5313675	2.0522842	2719.5188
1193.4629	3.5359597	2.0522099	2720.2869
1194.4639	3.5410457	2.0526145	2711.886
1195.4648	3.5438843	2.052367	2705.959
1196.4658	3.5451434	2.0523303	2695.106
1197.4668	3.5486004	2.052608	2692.4065
1198.4678	3.5534427	2.0521646	2688.8896
1199.4688	3.554553	2.0523748	2679.3589
1200.4697	3.5605443	2.0521977	2678.8137
1201.4707	3.5628974	2.0522089	2665.2227
1202.4717	3.5627656	2.0521202	2659.3701
1203.4727	3.5682569	2.052248	2640.8425
1204.4736	3.5731063	2.0520995	2636.1111
1205.4746	3.5739033	2.0523934	2617.4648
1206.4756	3.5758481	2.0523374	2587.0493
1207.4766	3.5805953	2.0523067	2559.5959
1208.4775	3.5829968	2.0524225	2494.3218
1208.8779	3.5827696	2.0524387	2450.6523