File: datasets/am_bench_2022/raw_data/TH1-C/specimen.dat
MTS793|MPT|ENU|1|2|.|/|:|1|0|0|A

Operator Information						Time:	14.347168	Sec	11/3/2021 10:53:59 AM
Operator	Nick Derimow
Project	AM Bench 2022 mini-tensile challenge
Specimen ID	TH1-C
Material	PBF-L Inconel 625
Specimen Width	2.57	mm
Specimen Thickness	1.52	mm
Notes
Operator Information End

Data Acquisition						Time:	1015.3406	Sec	11/3/2021 11:10:40 AM
Time	Axial Displacement	Axial Extensometer	Axial Force
Sec	mm	mm	N
14.460205	-0.00426332	1.5399281e-05	23.980709
15.461182	0.0042711059	9.8137323e-05	38.576862
16.462158	0.0089708436	0.00024721393	48.518539
17.463135	0.01034054	0.00015610918	56.037254
18.464111	0.014945362	0.00031684307	67.584442
19.465088	0.018325038	0.00039197248	79.610588
20.466064	0.017003492	0.00031418359	86.529892
21.467041	0.019271225	0.00043428247	98.278328
22.468018	0.027301772	0.00045934779	110.85516
23.468994	0.025677448	0.00058341131	120.80133
24.469971	0.030818315	0.00063420378	135.14658
25.470947	0.029001547	0.00066419982	141.66158
26.471924	0.035128966	0.00073472637	158.03522
27.4729	0.040411208	0.00078964431	174.42682
28.473877	0.040658459	0.00088553637	188.28328
29.474854	0.045339193	0.00099503319	208.11763
30.47583	0.045884408	0.0011196018	221.21716
31.476807	0.050650328	0.0013073372	244.67343
32.477783	0.054269828	0.0013539612	264.31329
33.47876	0.057444204	0.0014944088	284.38281
34.479736	0.058808163	0.0015606326	298.56558
35.480713	0.061780669	0.0017056032	321.30511
36.481689	0.06378819	0.001878316	340.93576
37.482666	0.069237575	0.0019552107	355.85468
38.483643	0.074521661	0.0021214746	384.09592
39.484619	0.072358884	0.0023474253	405.64496
40.485596	0.079172634	0.0024450342	431.0152
41.486572	0.082958765	0.0024921296	445.34952
42.487549	0.083455421	0.0026334007	460.96387
43.488525	0.086919919	0.0026769596	478.86444
44.489502	0.088635422	0.0028335485	499.70746
45.490479	0.092142902	0.0030929088	533.12555
46.491455	0.096306026	0.0032586716	554.99243
47.492432	0.096778505	0.0033098892	576.26794
48.493408	0.099282481	0.0034970059	599.3266
49.494385	0.10492568	0.0036864625	625.24963
50.495361	0.10648204	0.0038716451	648.14001
51.496338	0.10948712	0.0039784661	676.6084
52.497314	0.10945414	0.0040641176	695.86548
53.498291	0.11552214	0.0042838766	737.35028
54.499268	0.11791644	0.0044881259	758.41614
55.500244	0.11943509	0.0046081585	782.6745
56.501221	0.12821335	0.0047840592	816.88129
57.502197	0.127175	0.0049086516	835.70093
58.503174	0.13051447	0.005103386	863.01483
59.50415	0.13229267	0.0052738134	884.98755
60.505127	0.13735977	0.0055071935	916.99347
61.506104	0.13799678	0.0055973199	947.10547
62.50708	0.14438093	0.0057364427	974.31836
63.508057	0.14561084	0.0059964461	1001.7767
64.509033	0.14659043	0.0061093974	1024.4584
65.51001	0.15028763	0.0061586606	1048.5377
66.510986	0.15272726	0.0063231378	1067.855
67.511963	0.15895154	0.0064636539	1096.0077
68.512939	0.16343266	0.0067771538	1123.7715
69.513916	0.16292228	0.0068221642	1149.0764
70.514893	0.16681071	0.0070155915	1172.6864
71.515869	0.16904089	0.0071766623	1206.4794
72.516846	0.17028028	0.0072760088	1230.7506
73.517822	0.17536372	0.0074711367	1257.0648
74.518799	0.17933819	0.0076747718	1285.5538
75.519775	0.18382813	0.0077960161	1319.8918
76.520752	0.18297988	0.0079421224	1330.8717
77.521729	0.1875784	0.0080632027	1360.639
78.522705	0.18902631	0.0084279003	1387.9857
79.523682	0.19564198	0.008511167	1417.577
80.524658	0.19462024	0.0086387806	1436.5223
81.525635	0.19956231	0.008839678	1471.0775
82.526611	0.20174353	0.0090707475	1507.04
83.527588	0.20581226	0.0091736466	1535.0634
84.528564	0.20849915	0.0093316277	1563.1333
85.529541	0.21085928	0.0095510595	1589.7361
86.530518	0.21529241	0.0098335845	1623.9501
87.531494	0.21782322	0.0099904835	1652.5858
88.532471	0.21906282	0.010211271	1673.3091
89.533447	0.22409755	0.010335516	1697.0219
90.534424	0.22779332	0.010516306	1724.3704
91.5354	0.22967212	0.010639575	1754.538
92.536377	0.23199598	0.010776564	1779.8252
93.537354	0.23457639	0.010970196	1807.1611
94.53833	0.24158643	0.011162652	1837.6294
95.539307	0.23990448	0.011289203	1856.524
96.540283	0.24241844	0.011436728	1881.7704
97.54126	0.24749646	0.011636702	1906.9093
98.542236	0.25148439	0.011793693	1933.8458
99.543213	0.25367114	0.011903422	1950.5702
100.54419	0.25535187	0.012095522	1979.4097
101.54517	0.26067898	0.012285269	2008.8666
102.54614	0.26238671	0.012509836	2038.0009
103.54712	0.26686168	0.012618385	2055.4731
104.5481	0.26951107	0.012791435	2081.4351
105.54907	0.27075988	0.012946948	2099.6428
106.55005	0.2716409	0.013089998	2119.2751
107.55103	0.27702171	0.013138483	2139.1736
108.552	0.27996963	0.013316499	2162.1267
109.55298	0.28243133	0.01350863	2182.9009
110.55396	0.28681415	0.013639833	2204.3779
111.55493	0.28874424	0.013741401	2220.7771
112.55591	0.29259649	0.013976313	2240.7686
113.55688	0.2950941	0.014133959	2265.6284
114.55786	0.29782054	0.014216549	2290.9797
115.55884	0.30042654	0.014405232	2301.7141
116.55981	0.30360845	0.014531069	2322.1487
117.56079	0.30781934	0.014676283	2341.8596
118.56177	0.31047323	0.014806206	2356.7231
119.56274	0.3159534	0.014994565	2372.1526
120.56372	0.31776813	0.015135503	2397.3538
121.5647	0.3191874	0.015148903	2404.7551
122.56567	0.32327917	0.015330013	2418.988
123.56665	0.32597819	0.015489575	2436.3374
124.56763	0.32845041	0.015692886	2449.6951
125.5686	0.33284214	0.015771236	2470.3828
126.56958	0.33928859	0.01588404	2474.9275
127.57056	0.33727676	0.016100943	2489.7078
128.57153	0.34137848	0.016281074	2510.322
129.57251	0.34413093	0.01646108	2528.1162
130.57349	0.34614414	0.016554125	2538.1611
131.57446	0.35168576	0.016808141	2553.197
132.57544	0.3554951	0.016917281	2564.6128
133.57642	0.35789782	0.017086593	2574.9089
134.57739	0.36046135	0.017284675	2586.1799
135.57837	0.36391577	0.017424244	2594.647
136.57935	0.36597103	0.01767318	2611.9421
137.58032	0.36667544	0.017770059	2615.5706
138.5813	0.37158087	0.017978283	2631.5793
139.58228	0.37632361	0.018262789	2642.6826
140.58325	0.37577373	0.018492244	2653.21
141.58423	0.37997067	0.018684827	2661.53
142.58521	0.38156697	0.018926136	2669.1624
143.58618	0.38589665	0.019154897	2683.7173
144.58716	0.39054984	0.019594261	2697.5129
145.58813	0.39195088	0.01963805	2698.5298
146.58911	0.39498144	0.019808426	2702.1721
147.59009	0.39850101	0.020013632	2714.7532
148.59106	0.40024456	0.020400325	2725.0967
149.59204	0.40477547	0.020686064	2734.4885
150.59302	0.40771013	0.021036586	2740.4658
151.59399	0.41023844	0.021241287	2756.7988
152.59497	0.41504553	0.021663936	2762.5757
153.59595	0.41654491	0.021943482	2764.5391
154.59692	0.41847536	0.022240382	2768.4722
155.5979	0.42413786	0.022642696	2781.302
156.59888	0.42834607	0.02309834	2792.2192
157.59985	0.42768162	0.023530496	2799.6057
158.60083	0.43124524	0.023950569	2804.6133
159.60181	0.43614438	0.024322886	2812.4514
160.60278	0.43574691	0.024709404	2816.4753
161.60376	0.44070762	0.025192425	2820.9858
162.60474	0.44176424	0.025731156	2834.6658
163.60571	0.44630682	0.026501499	2845.6768
164.60669	0.45014936	0.026933432	2848.0813
165.60767	0.45367277	0.02762185	2858.179
166.60864	0.45502934	0.028141895	2855.8899
167.60962	0.45921132	0.028659493	2865.3425
168.6106	0.46243405	0.029365793	2879.6846
169.61157	0.46621239	0.030047137	2876.8794
170.61255	0.47111675	0.030860398	2887.3987
171.61353	0.47085902	0.031504333	2886.7468
172.6145	0.47659063	0.032086533	2894.2656
173.61548	0.4791888	0.032815583	2898.4922
174.61646	0.47810882	0.033470001	2908.1599
175.61743	0.48299256	0.034196403	2911.084
176.61841	0.48577452	0.034982577	2916.2832
177.61938	0.48893782	0.035878621	2924.0859
178.62036	0.49491397	0.036687426	2930.616
179.62134	0.49460602	0.037298352	2925.2014
180.62231	0.49656007	0.038140934	2935.0867
181.62329	0.50099629	0.039167598	2942.6001
182.62427	0.50567579	0.040116124	2944.7712
183.62524	0.51114237	0.041148148	2955.7058
184.62622	0.51301771	0.042025499	2956.4146
185.6272	0.51199859	0.042812198	2958.9207
186.62817	0.51426017	0.043703556	2956.3276
187.62915	0.52107745	0.044471007	2957.6372
188.63013	0.52502006	0.045304623	2966.8657
189.6311	0.52673155	0.04635337	2974.3911
190.63208	0.53039825	0.047302276	2977.5906
191.63306	0.53080022	0.048303131	2981.3352
192.63403	0.53554851	0.049245067	2978.6843
193.63501	0.53643245	0.050028361	2983.1567
194.63599	0.53988928	0.051039334	2990.6033
195.63696	0.54383057	0.052076217	2998.8223
196.63794	0.54842514	0.053036124	2994.99
197.63892	0.54945409	0.054123398	2995.9141
198.63989	0.55454868	0.055043429	3002.1506
199.64087	0.55704343	0.055928808	3013.1738
200.64185	0.56000978	0.056974769	3009.6821
201.64282	0.56248522	0.057904929	3009.4885
202.6438	0.56491703	0.058915034	3010.7815
203.64478	0.56970674	0.059935771	3022.5168
204.64575	0.5687694	0.0608542	3017.8838
205.64673	0.57579887	0.061679751	3020.1326
206.64771	0.57424057	0.062718309	3025.0842
207.64868	0.58038205	0.063789971	3027.7104
208.64966	0.5851379	0.064852186	3030.2087
209.65063	0.58339232	0.065692551	3028.4539
210.65161	0.58981305	0.066694342	3035.6074
211.65259	0.59339821	0.067634441	3035.2271
212.65356	0.59811556	0.068579726	3048.594
213.65454	0.60071766	0.069696531	3051.8916
214.65552	0.601134	0.070563316	3051.3501
215.65649	0.60425669	0.071466416	3044.8499
216.65747	0.6051932	0.072339185	3051.9661
217.65845	0.60667497	0.073260985	3050.5635
218.65942	0.61346316	0.074290872	3060.0735
219.6604	0.61598289	0.075427741	3061.9666
220.66138	0.61818808	0.0766249	3068.6499
221.66235	0.62330663	0.077755354	3067.3137
222.66333	0.62285364	0.078524664	3061.3325
223.66431	0.62694609	0.079520553	3071.2405
224.66528	0.63152486	0.080693051	3077.4417
225.66626	0.63507992	0.081848383	3083.1023
226.66724	0.63780808	0.083025038	3079.708
227.66821	0.63692188	0.084011324	3082.5583
228.66919	0.64181852	0.085223027	3084.3005
229.67017	0.64403212	0.086150423	3088.7742
230.67114	0.6514309	0.08705271	3085.2832
231.67212	0.65131021	0.088135578	3090.677
232.6731	0.65428108	0.089123912	3092.7039
233.67407	0.65730339	0.090139546	3097.4016
234.67505	0.66067213	0.091333158	3103.4346
235.67603	0.66225392	0.092495285	3102.4365
236.677	0.66842204	0.093557462	3103.6462
237.67798	0.67193693	0.094701841	3106.5349
238.67896	0.67512786	0.095683515	3108.594
239.67993	0.67379689	0.096640125	3114.9639
240.68091	0.67798138	0.097833142	3119.2002
241.68188	0.68403828	0.098854229	3112.4009
242.68286	0.68882674	0.099841386	3118.4167
243.68384	0.6864832	0.10093661	3118.7942
244.68481	0.69215065	0.10202845	3125.9414
245.68579	0.69700772	0.10312194	3125.3833
246.68677	0.69494247	0.10432829	3121.7937
247.68774	0.6994254	0.10528602	3127.729
248.68872	0.70525861	0.10644549	3135.9607
249.6897	0.70726079	0.10740526	3133.9539
250.69067	0.70717347	0.10848736	3129.0237
251.69165	0.71312058	0.10938107	3138.1355
252.69263	0.71519262	0.11042205	3138.0388
253.6936	0.71646291	0.11158622	3143.7085
254.69458	0.71931946	0.11251546	3143.8025
255.69556	0.72415692	0.11350473	3141.1963
256.69653	0.72915167	0.11460649	3146.7266
257.69751	0.72755784	0.11560387	3143.6284
258.69849	0.73233706	0.11645003	3149.7744
259.69946	0.73790634	0.11736532	3149.7834
260.70044	0.74032569	0.11857814	3157.8306
261.70142	0.74003041	0.11962233	3153.7605
262.70239	0.74462938	0.12078674	3155.626
263.70337	0.74659485	0.12168946	3153.5278
264.70435	0.74907297	0.1225462	3158.3618
265.70532	0.75322855	0.12379909	3162.7151
266.7063	0.75615168	0.12483002	3159.9341
267.70728	0.75714868	0.12603839	3171.2034
268.70825	0.76294702	0.1270227	3167.6992
269.70923	0.76594818	0.12805761	3171.7769
270.71021	0.76816142	0.12898673	3163.7175
271.71118	0.77128214	0.13012099	3175.7656
272.71216	0.77692449	0.13142724	3187.4421
273.71313	0.77808666	0.13264577	3176.887
274.71411	0.78308266	0.13361757	3177.5471
275.71509	0.78333139	0.13472	3180.02
276.71606	0.78810656	0.13572413	3186.1519
277.71704	0.78842497	0.13663687	3180.7507
278.71802	0.79403436	0.13754676	3183.2871
279.71899	0.7924813	0.13858983	3186.8425
280.71997	0.79838645	0.13954838	3188.887
281.72095	0.80294883	0.140274	3189.6628
282.72192	0.80532807	0.14149059	3198.5601
283.7229	0.80667168	0.14263326	3201.9258
284.72388	0.81146222	0.14386076	3199.21
285.72485	0.81531107	0.14504053	3204.521
286.72583	0.81478101	0.14609942	3201.5229
287.72681	0.82443166	0.14710693	3203.9885
288.72778	0.82493818	0.14796084	3200.9868
289.72876	0.82558376	0.14891355	3206.8247
290.72974	0.82797438	0.14981708	3208.9119
291.73071	0.83137202	0.15090625	3210.2053
292.73169	0.83576649	0.15187888	3210.9885
293.73267	0.83937603	0.15312064	3217.6304
294.73364	0.84015846	0.15422095	3213.2805
295.73462	0.84506947	0.15514196	3214.5454
296.7356	0.84425175	0.15621515	3217.7771
297.73657	0.84847611	0.15727687	3216.3081
298.73755	0.85487771	0.15835637	3225.4106
299.73853	0.8581596	0.15933996	3221.0054
300.7395	0.85844684	0.16040722	3219.6482
301.74048	0.86341316	0.16134033	3224.699
302.74146	0.86760229	0.16243976	3230.1326
303.74243	0.86815429	0.1634957	3229.8264
304.74341	0.86915147	0.16450103	3229.4736
305.74438	0.87491703	0.16565104	3231.9382
306.74536	0.87939447	0.16687852	3239.5596
307.74634	0.87959957	0.16775848	3231.9634
308.74731	0.88308471	0.16873538	3234.0056
309.74829	0.8880803	0.16971517	3240.8687
310.74927	0.88737565	0.17060365	3237.8611
311.75024	0.8939448	0.1716626	3246.4475
312.75122	0.89703226	0.17264882	3245.4546
313.7522	0.89883715	0.17370984	3246.1404
314.75317	0.90095443	0.17475937	3251.0378
315.75415	0.90305132	0.17586976	3249.4084
316.75513	0.90840793	0.17699808	3248.7664
317.7561	0.91107965	0.17790407	3243.7874
318.75708	0.91461992	0.17888016	3254.5488
319.75806	0.91504997	0.17985833	3258.1216
320.75903	0.91781992	0.18106849	3257.1121
321.76001	0.92235714	0.18219373	3255.6772
322.76099	0.92512292	0.18321893	3257.4243
323.76196	0.92873901	0.18421875	3260.4961
324.76294	0.93548763	0.18523684	3260.3599
325.76392	0.93274254	0.18625492	3260.1045
326.76489	0.93840605	0.18734615	3262.9998
327.76587	0.93598247	0.18838437	3257.5854
328.76685	0.9423309	0.18922603	3265.2766
329.76782	0.94513178	0.19049327	3272.7102
330.7688	0.94783545	0.19163173	3270.9055
331.76978	0.95157939	0.19255595	3272.2935
332.77075	0.95500714	0.19359677	3272.2329
333.77173	0.95934856	0.19445133	3272.4485
334.77271	0.96187216	0.19550133	3281.1047
335.77368	0.96663421	0.19652188	3282.3716
336.77466	0.9683755	0.19750564	3277.8142
337.77563	0.97004539	0.19839911	3276.7856
338.77661	0.97415626	0.19935541	3283.9873
339.77759	0.97334558	0.20037448	3283.7163
340.77856	0.97874373	0.20149992	3283.2427
341.77954	0.98295152	0.20247154	3287.291
342.78052	0.98256302	0.20351812	3288.8188
343.78149	0.98963046	0.20475508	3291.5898
344.78247	0.99021238	0.20605093	3296.6665
345.78345	0.99603426	0.20727828	3290.8171
346.78442	0.9987759	0.208261	3295.0298
347.7854	1.0005115	0.20927201	3291.0247
348.78638	1.0047532	0.21037209	3300.4109
349.78735	1.006617	0.21113488	3295.8152
350.78833	1.0104642	0.21230251	3309.1301
351.78931	1.0121926	0.2133677	3301.8757
352.79028	1.0165584	0.21446238	3302.6851
353.79126	1.0185134	0.21534473	3303.7668
354.79224	1.0215437	0.21640612	3305.6833
355.79321	1.0234306	0.21753819	3310.3989
356.79419	1.02839	0.21854867	3312.2434
357.79517	1.0306158	0.21965747	3310.7964
358.79614	1.034332	0.22069702	3311.9277
359.79712	1.0340948	0.22159712	3310.467
360.7981	1.0393561	0.22262305	3314.9429
361.79907	1.0455475	0.22369294	3317.2927
362.80005	1.0448211	0.22468753	3310.3042
363.80103	1.0498863	0.22552748	3311.5183
364.802	1.0499218	0.22650953	3317.6414
365.80298	1.0535126	0.22765277	3327.5208
366.80396	1.0609758	0.2287555	3324.7446
367.80493	1.0634146	0.22979006	3324.6362
368.80591	1.0622282	0.23072575	3325.3169
369.80688	1.0661068	0.23179959	3325.6487
370.80786	1.0688421	0.23278701	3327.9868
371.80884	1.0711825	0.23380587	3329.0239
372.80981	1.0768526	0.23503517	3337.3259
373.81079	1.078761	0.23606496	3326.1775
374.81177	1.0784221	0.23718205	3328.9729
375.81274	1.0816753	0.23820803	3326.425
376.81372	1.0871341	0.23904422	3332.8137
377.8147	1.0937631	0.24011984	3340.1387
378.81567	1.0933656	0.24095713	3332.4641
379.81665	1.0961685	0.2420346	3339.8745
380.81763	1.1015724	0.24299797	3338.9124
381.8186	1.103705	0.24399215	3340.3379
382.81958	1.1039094	0.24495605	3344.9021
383.82056	1.1095763	0.24616791	3349.8091
384.82153	1.1137772	0.247467	3358.3306
385.82251	1.1176312	0.24860761	3350.1262
386.82349	1.117137	0.24970573	3349.5649
387.82446	1.1204689	0.25073498	3349.8459
388.82544	1.1242251	0.25174463	3352.2546
389.82642	1.1266326	0.25261188	3349.155
390.82739	1.1301086	0.25359851	3359.936
391.82837	1.1325507	0.25474194	3359.3748
392.82935	1.1342554	0.25575855	3357.896
393.83032	1.1429	0.25679937	3355.8232
394.8313	1.1376959	0.25768366	3351.8406
395.83228	1.1421391	0.25866157	3358.1218
396.83325	1.1489813	0.25966513	3362.2078
397.83423	1.1485739	0.2609317	3368.5198
398.83521	1.1543161	0.26187637	3362.2361
399.83618	1.1543101	0.26262477	3354.1433
400.83716	1.1589289	0.26357844	3364.6709
401.83813	1.1645985	0.26465291	3370.5496
402.83911	1.1641788	0.26554495	3365.4688
403.84009	1.1701781	0.2665635	3375.8052
404.84106	1.1683145	0.26761362	3370.1082
405.84204	1.172837	0.26877108	3377.2471
406.84302	1.1790998	0.26986107	3379.1926
407.84399	1.1777782	0.27100134	3375.2798
408.84497	1.1848694	0.27209607	3380.6948
409.84595	1.1866949	0.27307865	3370.8193
410.84692	1.1915622	0.2742413	3382.7148
411.8479	1.1929269	0.27511853	3376.1841
412.84888	1.1955818	0.2760427	3381.1587
413.84985	1.1972848	0.27700588	3380.54
414.85083	1.2025026	0.27836686	3395.0466
415.85181	1.2031877	0.27951258	3390.0088
416.85278	1.2071276	0.28077418	3387.572
417.85376	1.2126317	0.28191623	3391.0349
418.85474	1.2137783	0.28294864	3391.3257
419.85571	1.2178103	0.28407201	3390.8506
420.85669	1.222851	0.28521004	3388.5981
421.85767	1.2229775	0.28607082	3391.4451
422.85864	1.2245064	0.28703776	3394.4255
423.85962	1.2310202	0.28800011	3397.9546
424.8606	1.2296896	0.28897664	3398.3264
425.86157	1.2319244	0.28973955	3387.9888
426.86255	1.2373269	0.29086998	3406.5613
427.86353	1.2406281	0.2921935	3406.2222
428.8645	1.2437934	0.29322991	3400.0522
429.86548	1.2465497	0.29415569	3406.1602
430.86646	1.24742	0.29528439	3404.9727
431.86743	1.253727	0.29632768	3402.8906
432.86841	1.2569764	0.29723251	3400.6653
433.86938	1.2600384	0.29813391	3400.8645
434.87036	1.2646197	0.29909226	3408.6409
435.87134	1.2620686	0.300134	3409.5259
436.87231	1.2709466	0.30111316	3415.0496
437.87329	1.2713597	0.30204594	3409.5698
438.87427	1.2736889	0.30300504	3413.7822
439.87524	1.2762764	0.30414268	3415.7832
440.87622	1.2799292	0.30504104	3412.2708
441.8772	1.2840621	0.30606556	3421.7576
442.87817	1.2840205	0.30702507	3415.2578
443.87915	1.2854534	0.30796301	3414.9517
444.88013	1.2905506	0.30905485	3421.0225
445.8811	1.2978418	0.31018159	3424.7405
446.88208	1.2940267	0.31115112	3417.7598
447.88306	1.2992682	0.31223032	3424.3464
448.88403	1.3054541	0.31331062	3426.0496
449.88501	1.3045843	0.31419137	3422.8496
450.88599	1.3088017	0.31544322	3424.7952
451.88696	1.3114892	0.3167403	3428.8757
452.88794	1.3148454	0.31756359	3422.1538
453.88892	1.3204973	0.31861272	3435.7358
454.88989	1.3218094	0.31968278	3433.1484
455.89087	1.3225104	0.32082534	3433.8867
456.89185	1.3286916	0.32201904	3440.6035
457.89282	1.328967	0.3230401	3432.9343
458.8938	1.3321071	0.32410654	3437.7043
459.89478	1.33711	0.32529655	3435.6726
460.89575	1.3390228	0.32633474	3437.5469
461.89673	1.341801	0.32735196	3438.4915
462.89771	1.3485376	0.32827523	3437.6489
463.89868	1.3484237	0.32951149	3450.1692
464.89966	1.3533864	0.33057928	3447.2197
465.90063	1.3555251	0.33154726	3441.2063
466.90161	1.3589158	0.3326081	3443.157
467.90259	1.3606163	0.3337661	3449.5693
468.90356	1.3618737	0.33488393	3451.3499
469.90454	1.3669251	0.33605933	3454.5317
470.90552	1.372721	0.33691049	3449.2537
471.90649	1.3736882	0.33797264	3449.4702
472.90747	1.3723598	0.33888665	3445.1382
473.90845	1.3804758	0.33986309	3449.6936
474.90942	1.3828309	0.34077349	3448.7781
475.9104	1.3845907	0.34177998	3452.2793
476.91138	1.3876381	0.34295052	3458.4883
477.91235	1.3894475	0.34413618	3461.9978
478.91333	1.3944951	0.34535494	3463.6912
479.91431	1.3964989	0.34642771	3461.5508
480.91528	1.3985637	0.34755477	3461.9084
481.91626	1.4016869	0.3486056	3456.2395
482.91724	1.4053751	0.34978604	3463.4854
483.91821	1.4089879	0.35074767	3461.4028
484.91919	1.4117069	0.35165018	3463.8921
485.92017	1.4142189	0.35265142	3464.2864
486.92114	1.4202313	0.35380715	3468.6228
487.92212	1.4213377	0.35485959	3469.0078
488.9231	1.4247733	0.35607171	3473.6328
489.92407	1.4289008	0.35714844	3470.5181
490.92505	1.4293529	0.35811701	3461.4709
491.92603	1.4338268	0.35905728	3470.8088
492.927	1.4371545	0.36024636	3478.2476
493.92798	1.4394411	0.36133644	3475.2695
494.92896	1.4405454	0.3623876	3469.6433
495.92993	1.4442667	0.36342701	3472.5393
496.93091	1.4479579	0.36446175	3470.5955
497.93188	1.4524372	0.36543581	3475.8154
498.93286	1.4507202	0.36653411	3481.894
499.93384	1.4588757	0.36763924	3486.9612
500.93481	1.4602591	0.36875093	3485.488
501.93579	1.4669244	0.36983722	3480.7576
502.93677	1.4668255	0.37078565	3484.6406
503.93774	1.4682593	0.37202296	3486.7854
504.93872	1.4727316	0.37314504	3486.593
505.9397	1.474146	0.37412092	3482.811
506.94067	1.4779567	0.37510908	3481.9399
507.94165	1.480093	0.37600482	3484.4128
508.94263	1.4857795	0.37710258	3494.5281
509.9436	1.4886918	0.37814522	3494.9478
510.94458	1.4909667	0.37924141	3494.5325
511.94556	1.4936945	0.38022301	3491.9211
512.94653	1.4967142	0.38125274	3492.2917
513.94751	1.4969282	0.38247132	3497.4258
514.94849	1.5008368	0.38369969	3498.9055
515.94946	1.5051198	0.38470179	3495.0798
516.95044	1.506531	0.38550201	3492.4736
517.95142	1.5084914	0.38646463	3496.9099
518.95239	1.5148569	0.38756192	3497.2493
519.95337	1.5198648	0.38872012	3503.3662
520.95435	1.51855	0.38966057	3496.4153
521.95532	1.5247782	0.3908284	3505.9966
522.9563	1.5226153	0.39199379	3504.2915
523.95728	1.5278987	0.39311638	3500.2183
524.95825	1.5327882	0.39425781	3508.9722
525.95923	1.5322151	0.39534724	3503.2837
526.96021	1.5380495	0.39650562	3510.2915
527.96118	1.5417838	0.39751396	3501.3054
528.96216	1.5456971	0.3985481	3511.9749
529.96313	1.5431254	0.39971218	3512.4824
530.96411	1.5494086	0.40085047	3512.2136
531.96509	1.5530723	0.40199128	3513.5991
532.96606	1.5564005	0.40309116	3511.0254
533.96704	1.5566833	0.40421137	3507.5884
534.96802	1.5617555	0.40539381	3513.1929
535.96899	1.5637672	0.40633616	3511.5671
536.96997	1.5675303	0.4073621	3510.3591
537.97095	1.5700973	0.40848315	3515.2317
538.97192	1.5737581	0.40958437	3522.8521
539.9729	1.5754267	0.41080418	3519.7737
540.97388	1.5782404	0.41173393	3511.2661
541.97485	1.5830293	0.41278249	3517.4744
542.97583	1.5875753	0.41394064	3524.1965
543.97681	1.5892663	0.41509342	3523.3013
544.97778	1.593089	0.41623232	3524.4507
545.97876	1.5942472	0.41721201	3517.9521
546.97974	1.5994298	0.41807789	3518.8242
547.98071	1.599345	0.41913503	3524.4485
548.98169	1.6047537	0.42010432	3529.8005
549.98267	1.6052969	0.42132318	3531.1128
550.98364	1.6060506	0.42249551	3530.1785
551.98462	1.6125146	0.42349869	3524.0793
552.9856	1.6165806	0.42463163	3529.6433
553.98657	1.6194972	0.42569739	3534.0723
554.98755	1.6233071	0.42694375	3539.4133
555.98853	1.6250702	0.42820781	3533.5889
556.9895	1.6281074	0.42943546	3538.8994
557.99048	1.6296511	0.430729	3538.6111
558.99146	1.6342646	0.43202212	3536.8953
559.99243	1.6383306	0.43296286	3532.5828
560.99341	1.6402893	0.43409505	3534.1587
561.99438	1.6443219	0.43499011	3540.0078
562.99536	1.6453193	0.43604091	3539.8379
563.99634	1.6483698	0.43693668	3532.1938
564.99731	1.6521982	0.43812579	3548.5425
565.99829	1.6540174	0.43926454	3542.73
566.99927	1.6583683	0.44069397	3542.4436
568.00024	1.6624794	0.44162157	3538.6184
569.00122	1.6639773	0.4426268	3541.926
570.0022	1.6685497	0.44378552	3545.1851
571.00317	1.6724181	0.44495201	3550.623
572.00415	1.6729141	0.44601309	3547.3186
573.00513	1.6765962	0.44711679	3550.1689
574.0061	1.6798021	0.44818792	3551.5522
575.00708	1.6815422	0.44918689	3546.0417
576.00806	1.6835259	0.45009285	3543.3462
577.00903	1.6874784	0.45102131	3545.8489
578.01001	1.6923659	0.45203748	3550.8835
579.01099	1.6925662	0.45304179	3554.3022
580.01196	1.6969255	0.45417234	3556.3806
581.01294	1.7029554	0.4551017	3557.5549
582.01392	1.7016088	0.45624274	3549.0464
583.01489	1.7068603	0.45724005	3555.5662
584.01587	1.7091979	0.45827168	3552.5898
585.01685	1.7100414	0.45954722	3560.4485
586.01782	1.7139982	0.46084774	3560.6997
587.0188	1.7189076	0.46198887	3560.6309
588.01978	1.71916	0.46306467	3553.4822
589.02075	1.7268378	0.46432805	3567.7578
590.02173	1.7274891	0.46550599	3564.689
591.02271	1.731481	0.46667978	3562.0945
592.02368	1.7314531	0.46783406	3564.9338
593.02466	1.7369896	0.46895322	3566.4443
594.02563	1.7401613	0.47013319	3563.4377
595.02661	1.7428131	0.4714098	3568.5083
596.02759	1.7452126	0.47240764	3563.5769
597.02856	1.7461023	0.47365886	3570.6108
598.02954	1.7506456	0.47473624	3562.7268
599.03052	1.755765	0.47596702	3574.0654
600.03149	1.759589	0.47712556	3573.7651
601.03247	1.7602659	0.47813711	3568.3203
602.03345	1.7621868	0.47937486	3565.5845
603.03442	1.7643404	0.48053345	3571.4583
604.0354	1.771065	0.48170772	3570.2612
605.03638	1.7723835	0.48292199	3578.8972
606.03735	1.7748975	0.48397842	3572.0671
607.03833	1.7775933	0.48518211	3572.8872
608.03931	1.7819393	0.48628032	3577.0813
609.04028	1.7850357	0.48737472	3576.636
610.04126	1.7875817	0.48836941	3569.583
611.04224	1.7931303	0.48927167	3580.2161
612.04321	1.790013	0.49056986	3580.4443
613.04419	1.7945801	0.49191251	3581.7695
614.04517	1.7985201	0.49315453	3579.3809
615.04614	1.8016243	0.4940685	3572.8245
616.04712	1.8048822	0.49516737	3581.4707
617.0481	1.8086166	0.49624681	3582.2754
618.04907	1.8111453	0.49729398	3585.3452
619.05005	1.8166702	0.49852476	3589.0168
620.05103	1.8160462	0.49970213	3583.8257
621.052	1.8199581	0.50104535	3588.3657
622.05298	1.8226826	0.50199062	3584.9973
623.05396	1.8259174	0.50313032	3586.8958
624.05493	1.8301395	0.50422078	3590.5474
625.05591	1.8314077	0.50520581	3583.7649
626.05688	1.8358496	0.50639886	3588.4229
627.05786	1.8379875	0.50764698	3588.0229
628.05884	1.8411244	0.50889909	3590.5073
629.05981	1.843082	0.5103119	3593.4871
630.06079	1.8476329	0.51161557	3594.9175
631.06177	1.8499447	0.5129168	3591.5781
632.06274	1.8556741	0.5142259	3595.1138
633.06372	1.8551208	0.51519167	3584.8535
634.0647	1.8592532	0.51628292	3592.676
635.06567	1.864912	0.51746321	3598.4397
636.06665	1.8676502	0.51854885	3601.8276
637.06763	1.867715	0.51962906	3596.2415
638.0686	1.8705653	0.52077758	3595.647
639.06958	1.8754791	0.52184463	3599.4773
640.07056	1.8764799	0.5230397	3602.0857
641.07153	1.8814254	0.52446377	3604.3174
642.07251	1.8859445	0.52568352	3604.1807
643.07349	1.8863707	0.52690941	3604.3621
644.07446	1.8884518	0.52802545	3601.4551
645.07544	1.8912121	0.52940422	3604.3135
646.07642	1.8955067	0.53052872	3602.8242
647.07739	1.8984523	0.5318231	3607.9014
648.07837	1.9028852	0.53305089	3601.3525
649.07935	1.9036186	0.53428197	3605.8699
650.08032	1.9053355	0.53542382	3598.3118
651.0813	1.9108052	0.53646868	3602.1304
652.08228	1.9146223	0.53764904	3611.1338
653.08325	1.9175053	0.53863597	3602.2771
654.08423	1.9208109	0.53959674	3605.5474
655.08521	1.9254146	0.54078925	3610.2446
656.08618	1.9252845	0.54190451	3604.4429
657.08716	1.9297093	0.54305333	3612.8342
658.08813	1.9325974	0.54417151	3611.5146
659.08911	1.9357953	0.54543668	3614.7681
660.09009	1.9392321	0.54681414	3618.2974
661.09106	1.9402803	0.54831654	3611.7737
662.09204	1.9433751	0.54969525	3613.6096
663.09302	1.9448404	0.5506283	3606.7654
664.09399	1.947623	0.55182105	3606.4858
665.09497	1.9526415	0.55301106	3616.9294
666.09595	1.9536935	0.55428928	3618.8884
667.09692	1.9565519	0.55547053	3615.22
668.0979	1.9625895	0.55684263	3617.179
669.09888	1.9670421	0.55796516	3612.1565
670.09985	1.9657371	0.55893803	3608.3218
671.10083	1.9682475	0.56002927	3613.3691
672.10181	1.9750017	0.5613507	3619.7961
673.10278	1.9767922	0.56246662	3619.0713
674.10376	1.9818907	0.5636397	3618.0923
675.10474	1.9803404	0.56481397	3622.936
676.10571	1.9830443	0.5660249	3617.7668
677.10669	1.9891646	0.56720209	3623.6108
678.10767	1.9923151	0.56847858	3625.6282
679.10864	1.9944254	0.56986338	3622.5474
680.10962	1.9967006	0.57104903	3623.6975
681.1106	2.0000353	0.57209867	3619.3147
682.11157	2.002712	0.57332408	3624.4939
683.11255	2.0059381	0.57453644	3626.9014
684.11353	2.0079961	0.57569742	3621.0315
685.1145	2.0142057	0.57697022	3624.3044
686.11548	2.0164068	0.57825512	3628.0469
687.11646	2.0200362	0.57948858	3627.3962
688.11743	2.0195725	0.58056623	3620.5747
689.11841	2.0259817	0.58182764	3629.8555
690.11938	2.0244226	0.58298743	3626.3025
691.12036	2.0305936	0.58440042	3634.9446
692.12134	2.0329914	0.58570528	3626.9714
693.12231	2.0372441	0.58706295	3630.9993
694.12329	2.0377386	0.58811408	3624.605
695.12427	2.0420606	0.58937007	3630.6531
696.12524	2.0457079	0.59055376	3629.1543
697.12622	2.0471973	0.59170282	3632.1323
698.1272	2.0541923	0.59298593	3634.1047
699.12817	2.0548756	0.59424323	3640.1228
700.12915	2.0588179	0.59583318	3645.3066
701.13013	2.0603051	0.59730482	3633.4282
702.1311	2.0640914	0.59865284	3636.1021
703.13208	2.0668871	0.59997636	3635.3308
704.13306	2.0713525	0.60122073	3637.543
705.13403	2.0716338	0.60231686	3629.1096
706.13501	2.0732999	0.60360885	3633.4231
707.13599	2.0813582	0.60508317	3639.46
708.13696	2.0837634	0.60642052	3641.6433
709.13794	2.0813258	0.60766542	3635.1553
710.13892	2.0886488	0.60884058	3634.7158
711.13989	2.0935516	0.61021107	3638.4607
712.14087	2.0938938	0.61153066	3643.4912
713.14185	2.0955412	0.61269909	3633.0769
714.14282	2.0989883	0.61369359	3631.6282
715.1438	2.1023955	0.61490065	3641.7104
716.14478	2.1062615	0.61601031	3639.0823
717.14575	2.1053848	0.61723334	3638.2949
718.14673	2.1108716	0.61842221	3639.0774
719.14771	2.115639	0.61942863	3639.9868
720.14868	2.1146562	0.62071794	3646.6304
721.14966	2.1187394	0.62208277	3644.1494
722.15063	2.1250086	0.62329185	3644.6082
723.15161	2.1248302	0.6245665	3646.3313
724.15259	2.1294951	0.62591487	3645.3142
725.15356	2.1343429	0.62725455	3641.8396
726.15454	2.1393859	0.62865579	3648.4429
727.15552	2.1394165	0.62986833	3641.002
728.15649	2.1391628	0.63081777	3640.8125
729.15747	2.1434629	0.63186103	3639.4678
730.15845	2.1472244	0.63303697	3641.2529
731.15942	2.1501296	0.63450497	3649.6526
732.1604	2.1538022	0.63584465	3645.8481
733.16138	2.1578977	0.63722253	3648.478
734.16235	2.161196	0.63847208	3649.376
735.16333	2.1641009	0.63979441	3649.0791
736.16431	2.163517	0.64111394	3648.0298
737.16528	2.1678774	0.6423614	3645.1323
738.16626	2.1707292	0.64377373	3654.0808
739.16724	2.1743431	0.64522862	3653.252
740.16821	2.1769202	0.64652109	3651.9885
741.16919	2.1831815	0.64804888	3653.9485
742.17017	2.1829455	0.64936179	3650.8477
743.17114	2.1879203	0.65064269	3646.73
744.17212	2.1881306	0.65161783	3644.8752
745.1731	2.189573	0.65282547	3649.7732
746.17407	2.1948755	0.65406585	3649.4084
747.17505	2.195395	0.655366	3651.8684
748.17603	2.2012594	0.65665448	3648.5747
749.177	2.2047553	0.65807158	3656.7336
750.17798	2.204953	0.65928179	3646.1453
751.17896	2.2100871	0.66076422	3656.0212
752.17993	2.2146039	0.66220337	3659.7839
753.18091	2.2160318	0.66381121	3660.1804
754.18188	2.2189906	0.66528147	3652.6917
755.18286	2.2255099	0.66654897	3656.928
756.18384	2.2249589	0.667705	3650.5938
757.18481	2.2288125	0.66899765	3652.7761
758.18579	2.2323008	0.67036432	3657.2566
759.18677	2.2343566	0.67169893	3660.3311
760.18774	2.2384205	0.67299992	3654.6633
761.18872	2.2417374	0.67439377	3657.7068
762.1897	2.2451017	0.67558229	3657.8423
763.19067	2.2443469	0.67688781	3659.8586
764.19165	2.2476389	0.67811	3655.6821
765.19263	2.2549624	0.67956465	3657.7048
766.1936	2.2537868	0.68083721	3657.7261
767.19458	2.2612321	0.68244106	3668.2249
768.19556	2.2594192	0.68369985	3651.6958
769.19653	2.2644742	0.68491417	3653.8081
770.19751	2.268358	0.68619877	3659.6851
771.19849	2.2707233	0.6875447	3659.5513
772.19946	2.2738526	0.68913168	3664.1807
773.20044	2.2777011	0.69067067	3664.1709
774.20142	2.2794363	0.69215864	3660.3743
775.20239	2.2858894	0.69372243	3664.0498
776.20337	2.2868407	0.695081	3663.4539
777.20435	2.2872539	0.69661409	3662.9329
778.20532	2.2926073	0.69825953	3663.7288
779.2063	2.2950795	0.69967383	3661.2922
780.20728	2.2974422	0.70072109	3655.1384
781.20825	2.2988789	0.70174605	3657.2988
782.20923	2.3022435	0.70292526	3663.1411
783.21021	2.3100591	0.70429891	3666.78
784.21118	2.3090656	0.70564568	3657.0579
785.21216	2.3121316	0.70713431	3665.7542
786.21313	2.3166728	0.70875919	3669.8582
787.21411	2.3170531	0.71014506	3660.9937
788.21509	2.3200593	0.71175027	3665.29
789.21606	2.3219028	0.7131477	3661.2603
790.21704	2.3282146	0.71457553	3666.3323
791.21802	2.3325388	0.71571189	3658.8662
792.21899	2.3331466	0.71689677	3661.3821
793.21997	2.3374701	0.71789241	3659.2659
794.22095	2.3392651	0.71912074	3666.5591
795.22192	2.3443825	0.72076017	3669.458
796.2229	2.3440866	0.72208273	3666.6865
797.22388	2.3487272	0.72344565	3663.5723
798.22485	2.3526678	0.7250312	3666.1445
799.22583	2.3544168	0.72654057	3665.8301
800.22681	2.3583171	0.72806931	3663.0317
801.22778	2.3587887	0.7293064	3660.8987
802.22876	2.3635359	0.73072976	3665.0264
803.22974	2.3666825	0.73216903	3668.4143
804.23071	2.3699546	0.73378962	3667.3167
805.23169	2.3727922	0.73530453	3671.3086
806.23267	2.3740015	0.73687911	3671.4304
807.23364	2.3797259	0.73835391	3670.5581
808.23462	2.3831322	0.73985058	3670.5989
809.2356	2.3859379	0.74125475	3666.4658
810.23657	2.3876722	0.74289495	3665.2729
811.23755	2.3917494	0.74431878	3665.2952
812.23853	2.3935692	0.74566758	3665.259
813.2395	2.3951936	0.74710429	3670.4063
814.24048	2.3998981	0.7486558	3665.7527
815.24146	2.402323	0.75011539	3666.2703
816.24243	2.4046323	0.75198871	3675.9504
817.24341	2.4069695	0.75339615	3665.8193
818.24438	2.4139707	0.75495839	3670.3987
819.24536	2.4161191	0.75638205	3665.6152
820.24634	2.4207754	0.75750864	3665.4951
821.24731	2.4212003	0.75880182	3668.8364
822.24829	2.4249163	0.76052314	3681.6604
823.24927	2.4250708	0.76210952	3669.0288
824.25024	2.4294407	0.76380789	3671.228
825.25122	2.4324596	0.76531404	3671.9534
826.2522	2.4380126	0.76678324	3672.365
827.25317	2.4414845	0.76805514	3673.3149
828.25415	2.4383891	0.76946396	3667.209
829.25513	2.4461877	0.77104509	3670.5022
830.2561	2.4457059	0.77258092	3671.9705
831.25708	2.4537399	0.77424443	3676.2834
832.25806	2.4529479	0.77587533	3679.8401
833.25903	2.4570928	0.77747649	3674.3716
834.26001	2.4598701	0.77878147	3664.8887
835.26099	2.4632733	0.78064477	3677.5117
836.26196	2.4667134	0.78193039	3663.3191
837.26294	2.4703002	0.78338003	3673.7212
838.26392	2.4703183	0.78471726	3667.8906
839.26489	2.4742486	0.78633159	3672.2231
840.26587	2.4786904	0.78796887	3672.5784
841.26685	2.4824548	0.78959304	3670.0874
842.26782	2.484303	0.79109418	3676.1743
843.2688	2.4840367	0.79301214	3675.2791
844.26978	2.4893651	0.79457796	3673.6306
845.27075	2.4968019	0.79624975	3674.4753
846.27173	2.495949	0.79793668	3668.6892
847.27271	2.4993896	0.79944587	3664.7917
848.27368	2.503746	0.80118531	3674.1748
849.27466	2.5071647	0.80264199	3674.5273
850.27563	2.5075195	0.80413508	3670.842
851.27661	2.5110404	0.80549806	3663.894
852.27759	2.5147495	0.80687922	3671.8691
853.27856	2.5171454	0.80844617	3676.1812
854.27954	2.5202549	0.81057435	3677.7466
855.28052	2.5222824	0.81214726	3669.5664
856.28149	2.5234563	0.81384188	3671.7646
857.28247	2.5288084	0.81563461	3669.4714
858.28345	2.5341935	0.8174305	3677.8323
859.28442	2.5353425	0.81889695	3669.9377
860.2854	2.5380597	0.82023251	3670.8149
861.28638	2.54164	0.82175452	3671.9546
862.28735	2.5457809	0.82335651	3675.218
863.28833	2.545243	0.82477552	3672.0928
864.28931	2.5474744	0.82638592	3670.95
865.29028	2.5506129	0.8279708	3669.3904
866.29126	2.5561159	0.82965547	3673.2556
867.29224	2.5565283	0.83158201	3674.0249
868.29321	2.5593157	0.83349675	3669.4497
869.29419	2.5612371	0.83520496	3665.5457
870.29517	2.5690038	0.83669448	3668.5779
871.29614	2.5708859	0.83798307	3666.0471
872.29712	2.5771155	0.83932549	3669.1096
873.2981	2.5754325	0.84088242	3667.9517
874.29907	2.5790687	0.84241855	3671.7581
875.30005	2.5814574	0.84443223	3672.8594
876.30103	2.5868607	0.84609503	3670.2483
877.302	2.5911081	0.84770626	3667.9741
878.30298	2.5908329	0.8495875	3674.321
879.30396	2.5949044	0.85138869	3671.8762
880.30493	2.5991354	0.85329056	3671.4377
881.30591	2.6005929	0.85525084	3671.1831
882.30688	2.6045992	0.85710508	3675.4067
883.30786	2.606813	0.85880733	3663.9839
884.30884	2.6091974	0.86063302	3674.623
885.30981	2.6139903	0.86234218	3667.3572
886.31079	2.6143382	0.86372095	3661.6965
887.31177	2.6157069	0.86546177	3669.137
888.31274	2.6228178	0.86721236	3663.7195
889.31372	2.6247072	0.86895245	3669.8665
890.3147	2.6284685	0.87083447	3669.3645
891.31567	2.6319954	0.87269545	3669.2656
892.31665	2.6341467	0.8743102	3670.2336
893.31763	2.6371348	0.87599134	3670.4355
894.3186	2.642833	0.87789428	3666.8284
895.31958	2.6448901	0.87942064	3665.6335
896.32056	2.6456103	0.88121337	3665.8689
897.32153	2.648186	0.8829518	3662.2998
898.32251	2.6519418	0.88482773	3667.3748
899.32349	2.6542404	0.88659292	3668.1189
900.32446	2.6571231	0.8884297	3664.4612
901.32544	2.6607337	0.8902002	3662.4287
902.32642	2.6623178	0.89194798	3662.2798
903.32739	2.6668336	0.89402056	3667.8884
904.32837	2.6728261	0.89590037	3669.2937
905.32935	2.6725533	0.89784485	3663.9512
906.33032	2.6761107	0.89969599	3664.5168
907.3313	2.6791379	0.90124524	3664.6587
908.33228	2.6792896	0.90320927	3666.8657
909.33325	2.6851747	0.90521628	3662.0144
910.33423	2.6881769	0.90704393	3660.2178
911.33521	2.6906681	0.90881139	3658.3865
912.33618	2.6950881	0.91068846	3667.2075
913.33716	2.6968694	0.91247439	3662.9746
914.33813	2.6992743	0.91436464	3661.7927
915.33911	2.7034929	0.91646385	3672.2422
916.34009	2.7065942	0.91889596	3670.0154
917.34106	2.7100134	0.92136908	3662.3386
918.34204	2.711585	0.92301822	3658.1116
919.34302	2.716023	0.92468715	3661.8787
920.34399	2.717803	0.92648417	3655.4949
921.34497	2.7201192	0.92830074	3662.8657
922.34595	2.7228613	0.93010944	3664.1619
923.34692	2.726927	0.93238693	3663.8125
924.3479	2.730442	0.93454564	3664.3425
925.34888	2.7325692	0.93668097	3667.9177
926.34985	2.7370031	0.93882853	3658.7336
927.35083	2.7378428	0.94085068	3657.3623
928.35181	2.7425046	0.94279945	3661.1257
929.35278	2.7443142	0.94480854	3657.98
930.35376	2.7502842	0.94687587	3656.9697
931.35474	2.7509747	0.9487375	3660.4751
932.35571	2.7537899	0.95079172	3660.0176
933.35669	2.7566278	0.9528833	3655.7522
934.35767	2.763828	0.95500672	3656.9438
935.35864	2.7601504	0.95687938	3656.77
936.35962	2.7669301	0.95905185	3658.345
937.3606	2.7724152	0.96156228	3664.0933
938.36157	2.7708735	0.96369606	3657.3376
939.36255	2.7743883	0.9661203	3657.5625
940.36353	2.7796819	0.9682759	3651.7222
941.3645	2.783196	0.97031677	3648.6292
942.36548	2.7850294	0.97270107	3657.7075
943.36646	2.788496	0.97497869	3653.7937
944.36743	2.7900755	0.97692108	3650.3623
945.36841	2.7934532	0.97876662	3648.3582
946.36938	2.797205	0.98056608	3652.4089
947.37036	2.7989686	0.98288888	3653.2058
948.37134	2.8022549	0.98528987	3657.2563
949.37231	2.8030016	0.98713195	3644.0015
950.37329	2.8073227	0.98937535	3652.3794
951.37427	2.8131361	0.99183428	3655.3706
952.37524	2.8128653	0.99406916	3650.1833
953.37622	2.8191123	0.99641865	3655.4058
954.3772	2.8224726	0.99900436	3652.2222
955.37817	2.8226051	1.0012159	3642.2139
956.37915	2.8247352	1.0036894	3650.2778
957.38013	2.8293381	1.0058635	3644.1262
958.3811	2.8327553	1.0082521	3649.7583
959.38208	2.8354137	1.0103345	3641.5535
960.38306	2.8372908	1.0126867	3651.1128
961.38403	2.8400023	1.0152862	3646.5049
962.38501	2.8447852	1.0180271	3651.1799
963.38599	2.8502831	1.0206602	3642.4734
964.38696	2.8502231	1.0230323	3643.6477
965.38794	2.8545358	1.0253474	3641.3533
966.38892	2.8572931	1.0277728	3642.0168
967.38989	2.8572056	1.030081	3638.592
968.39087	2.8617983	1.0323354	3638.542
969.39185	2.8655195	1.0345792	3638.2205
970.39282	2.8652904	1.0369707	3634.8496
971.3938	2.8737872	1.0391731	3638.4468
972.39478	2.8769448	1.0415721	3644.897
973.39575	2.8781345	1.0442269	3632.6169
974.39673	2.8798084	1.0464826	3634.4343
975.39771	2.881578	1.0489796	3634.7048
976.39868	2.8846397	1.0516039	3634.0864
977.39966	2.8893683	1.0539637	3633.7622
978.40063	2.8919969	1.0565512	3634.6848
979.40161	2.8937249	1.0592169	3625.738
980.40259	2.8985417	1.0614122	3625.7507
981.40356	2.9020364	1.0636716	3630.3611
982.40454	2.9052794	1.0661412	3636.2112
983.40552	2.9060643	1.0688291	3632.2122
984.40649	2.911623	1.071745	3630.7969
985.40747	2.9147406	1.0744128	3627.9578
986.40845	2.916889	1.0770167	3624.0273
987.40942	2.9174337	1.0798382	3623.3687
988.4104	2.9238849	1.0829636	3633.8157
989.41138	2.9251359	1.0859419	3618.1345
990.41235	2.9298935	1.0881674	3621.8083
991.41333	2.931155	1.0907992	3617.5161
992.41431	2.9333227	1.0940884	3624.2847
993.41528	2.9393225	1.0971867	3620.8289
994.41626	2.9373546	1.1002302	3621.1155
995.41724	2.9448354	1.1029168	3618.3176
996.41821	2.9449503	1.1056639	3621.5481
997.41919	2.94888	1.1088096	3613.8604
998.42017	2.9524326	1.1114112	3613.4341
999.42114	2.9547026	1.1139768	3611.6047
1000.4221	2.9577577	1.1163127	3611.6238
1001.4231	2.9624839	1.1188012	3609.1821
1002.4241	2.9681001	1.1218491	3613.7402
1003.425	2.9683244	1.1247311	3613.2334
1004.426	2.9728796	1.127656	3612.6553
1005.427	2.9738088	1.1303271	3602.2593
1006.428	2.9742732	1.1328819	3601.802
1007.429	2.9821031	1.135271	3603.6558
1008.4299	2.9836769	1.1377443	3602.7603
1009.4309	2.9859209	1.1404012	3601.1375
1010.4319	2.9878249	1.1431608	3599.073
1011.4329	2.9934199	1.14613	3601.9209
1012.4338	2.9940066	1.1487795	3597.5481
1013.4348	2.9963369	1.1513988	3590.9063
1014.4358	3.0012908	1.1542653	3603.2019
1015.4368	3.0051498	1.1574519	3597.2168
1016.4377	3.0063667	1.160282	3590.3401
1017.4387	3.0097001	1.1629521	3584.2832
1018.4397	3.0110369	1.1652528	3581.0034
1019.4407	3.0139413	1.1671507	3580.9944
1020.4417	3.0176899	1.1692234	3585.0945
1021.4426	3.0200634	1.1717224	3586.0747
1022.4436	3.0254269	1.1743591	3588.0586
1023.4446	3.0252755	1.1775306	3588.0308
1024.4456	3.0298865	1.1806279	3585.8921
1025.4465	3.0334618	1.1839614	3584.6892
1026.4475	3.0363059	1.1871173	3579.9304
1027.4485	3.0412548	1.1899451	3581.4119
1028.4495	3.0418315	1.1930939	3573.873
1029.4504	3.0459821	1.196391	3575.6096
1030.4514	3.0464454	1.1993215	3570.0681
1031.4524	3.0525172	1.2023352	3569.4536
1032.4534	3.0538538	1.2049947	3566.4558
1033.4543	3.0540905	1.2078944	3565.9978
1034.4553	3.0602243	1.2112874	3566.0542
1035.4563	3.0655274	1.2146484	3565.762
1036.4573	3.0675719	1.2181906	3564.3948
1037.4583	3.0696752	1.2211643	3555.1042
1038.4592	3.0722902	1.2241321	3557.7554
1039.4602	3.0761085	1.2267292	3554.0313
1040.4612	3.0767415	1.2300022	3548.6836
1041.4622	3.0804157	1.2331355	3545.7769
1042.4631	3.0856698	1.2362016	3552.6831
1043.4641	3.0866044	1.2393904	3548.7827
1044.4651	3.0914629	1.2424302	3540.6091
1045.4661	3.0918198	1.245289	3536.26
1046.467	3.0966117	1.2483668	3542.1614
1047.468	3.100224	1.251201	3538.3181
1048.469	3.1012373	1.2544805	3535.9175
1049.47	3.1047289	1.2574444	3527.6941
1050.4709	3.1099074	1.260363	3534.2573
1051.4719	3.1151488	1.263736	3536.363
1052.4729	3.1171236	1.2670778	3532.2561
1053.4739	3.1179352	1.2699627	3523.0793
1054.4749	3.122036	1.2728779	3522.8262
1055.4758	3.1252902	1.2761154	3524.9429
1056.4768	3.1248903	1.2792801	3520.0107
1057.4778	3.1315594	1.2825946	3517.0288
1058.4788	3.1339109	1.2863555	3516.6709
1059.4797	3.1367781	1.2904428	3508.6377
1060.4807	3.1400898	1.2934779	3502.9717
1061.4817	3.1410773	1.2965424	3501.9514
1062.4827	3.1435902	1.2993153	3496.5271
1063.4836	3.1466048	1.3019571	3498.9163
1064.4846	3.151701	1.3048435	3499.0613
1065.4856	3.1555033	1.3081105	3499.2515
1066.4866	3.1596429	1.3120278	3494.7808
1067.4875	3.1629705	1.3155442	3490.8662
1068.4885	3.1631474	1.3189027	3485.8647
1069.4895	3.166935	1.3218629	3482.6262
1070.4905	3.1685519	1.3251989	3480.8599
1071.4915	3.1719019	1.3287101	3474.4612
1072.4924	3.1771395	1.3324077	3478.2319
1073.4934	3.1767697	1.3354621	3466.5801
1074.4944	3.1809125	1.3384802	3461.5271
1075.4954	3.1846712	1.3411776	3465.0486
1076.4963	3.1843479	1.3441249	3456.5217
1077.4973	3.1886303	1.3477428	3464.7397
1078.4983	3.1933923	1.3512021	3454.3997
1079.4993	3.1962125	1.3540317	3452.1079
1080.5002	3.2001023	1.3566958	3448.1589
1081.5012	3.2001793	1.3597178	3451.6179
1082.5022	3.2044284	1.3632146	3443.5627
1083.5032	3.2059777	1.3665372	3438.334
1084.5042	3.2126355	1.3695127	3438.2932
1085.5051	3.2137654	1.372376	3434.1196
1086.5061	3.2167027	1.375481	3425.5232
1087.5071	3.2185555	1.3788165	3426.114
1088.5081	3.2252054	1.3825921	3427.4138
1089.509	3.2291026	1.3858472	3417.4084
1090.51	3.23052	1.3886168	3410.0149
1091.511	3.2315042	1.3913443	3409.8267
1092.512	3.2350218	1.3948762	3411.022
1093.5129	3.2395229	1.399258	3410.304
1094.5139	3.2393517	1.4029232	3399.8887
1095.5149	3.243865	1.4060837	3396.8579
1096.5159	3.2496655	1.4095297	3399.1064
1097.5168	3.2506535	1.4127111	3384.4294
1098.5178	3.2530615	1.4155601	3384.408
1099.5188	3.255651	1.4192516	3386.0002
1100.5198	3.2625232	1.4228837	3382.0808
1101.5208	3.2623894	1.4259405	3372.0144
1102.5217	3.2646735	1.4288905	3370.2195
1103.5227	3.2688322	1.4317504	3363.4712
1104.5237	3.2703247	1.4349439	3363.4019
1105.5247	3.2754095	1.4380794	3357.7856
1106.5256	3.2729688	1.4413828	3356.9602
1107.5266	3.2815316	1.4452004	3355.0515
1108.5276	3.2848194	1.4488289	3346.0286
1109.5286	3.2847626	1.4530897	3345.1106
1110.5295	3.2888656	1.4569403	3334.5774
1111.5305	3.2945163	1.4604236	3334.5898
1112.5315	3.2956533	1.463693	3322.219
1113.5325	3.2947719	1.4667321	3318.7129
1114.5334	3.3012846	1.4696306	3318.9177
1115.5344	3.3070371	1.4725862	3314.5361
1116.5354	3.308641	1.4757642	3316.5139
1117.5364	3.3104763	1.4794707	3306.5928
1118.5374	3.3150859	1.4832529	3302.4448
1119.5383	3.318032	1.4868872	3290.5488
1120.5393	3.3219199	1.4905512	3291.9641
1121.5403	3.323328	1.4937454	3284.043
1122.5413	3.3232281	1.4971	3280.5073
1123.5422	3.3264413	1.5004038	3270.6099
1124.5432	3.3324647	1.5036165	3271.7131
1125.5442	3.333564	1.5069308	3263.8003
1126.5452	3.3372164	1.5105134	3265.0862
1127.5461	3.3387234	1.514528	3254.3118
1128.5471	3.3430398	1.5177078	3244.7476
1129.5481	3.3483243	1.5206656	3246.3862
1130.5491	3.3495715	1.5242288	3238.6497
1131.55	3.3506496	1.5275683	3231.6917
1132.551	3.3551981	1.5315502	3232.1226
1133.552	3.35443	1.5352523	3222.4939
1134.553	3.3603678	1.5388119	3211.5354
1135.554	3.3659575	1.5417868	3211.178
1136.5549	3.3676908	1.5449332	3202.0786
1137.5559	3.3702011	1.5478114	3201.1565
1138.5569	3.3721442	1.5517777	3197.9253
1139.5579	3.3782451	1.5558487	3187.8906
1140.5588	3.3796344	1.559426	3185.6062
1141.5598	3.3829272	1.5632683	3176.4766
1142.5608	3.3871341	1.5668676	3174.053
1143.5618	3.3887823	1.5700306	3162.7322
1144.5627	3.3908091	1.5729136	3155.2854
1145.5637	3.3950806	1.5764642	3159.229
1146.5647	3.3985093	1.5800294	3146.2224
1147.5657	3.4024737	1.5841517	3144.7126
1148.5667	3.4043417	1.5876602	3132.4954
1149.5676	3.4077826	1.5909694	3123.7915
1150.5686	3.4097705	1.593877	3113.2471
1151.5696	3.4099655	1.5971702	3111.5791
1152.5706	3.4140677	1.6006564	3106.5457
1153.5715	3.4214611	1.6038921	3101.7559
1154.5725	3.423707	1.6067348	3092.9919
1155.5735	3.4242783	1.609798	3090.8022
1156.5745	3.4264534	1.6140156	3083.353
1157.5754	3.4305797	1.6182935	3070.9399
1158.5764	3.4333465	1.6217166	3066.6824
1159.5774	3.4377229	1.6255784	3061.6926
1160.5784	3.4393787	1.6297446	3052.0811
1161.5793	3.4428806	1.6336031	3043.0051
1162.5803	3.4452384	1.6372216	3036.5146
1163.5813	3.4502511	1.6407938	3025.9529
1164.5823	3.4519615	1.6445116	3020.9258
1165.5833	3.4547505	1.6483433	3007.4788
1166.5842	3.4599559	1.651646	3003.4282
1167.5852	3.4594929	1.6558239	2995.1694
1168.5862	3.4638531	1.6599663	2979.3574
1169.5872	3.4662347	1.664189	2968.5542
1170.5881	3.4702592	1.667895	2961.8826
1171.5891	3.4742286	1.6713134	2949.1716
1172.5901	3.4796627	1.674876	2938.6997
1173.5911	3.478502	1.6790388	2930.9233
1174.592	3.4811382	1.6832944	2916.8853
1175.593	3.4828792	1.687129	2904.5454
1176.594	3.4878974	1.6914288	2897.3455
1177.595	3.4915671	1.6957028	2874.4988
1178.5959	3.4942441	1.6992334	2865.5437
1179.5969	3.5002913	1.7033955	2859.9897
1180.5979	3.5022838	1.7085556	2843.7339
1181.5989	3.5054398	1.7139672	2814.2905
1182.5999	3.5063546	1.7183175	2791.6338
1183.6008	3.5087819	1.7228881	2768.3247
1184.6018	3.5148995	1.7285224	2752.2737
1185.6028	3.5183797	1.7331024	2725.478
1186.6038	3.5191326	1.7372689	2713.7432
1187.6047	3.5237784	1.7429563	2685.0664
1188.6057	3.526334	1.747771	2652.2109
1189.4065	3.5284283	1.7552432	2601.0151