File: datasets/am_bench_2022/raw_data/60-X.05-2/specimen.dat
MTS793|MPT|ENU|1|2|.|/|:|1|0|0|A

Operator Information						Time:	21.750488	Sec	11/1/2021 8:04:29 AM
Operator	Nick Derimow
Project	AM Bench 2022 mini-tensile challenge
Specimen ID	60-X.05-2
Material	PBF-L Inconel 625
Specimen Width	2.55	mm
Specimen Thickness	1.52	mm
Notes
Operator Information End

Data Acquisition						Time:	1022.7441	Sec	11/1/2021 8:21:10 AM
Time	Axial Displacement	Axial Extensometer	Axial Force
Sec	mm	mm	N
21.864014	0.00024150946	0.00015186393	62.161049
22.86499	0.0030464667	0.00029874823	74.988228
23.865967	0.0050496859	0.0003390011	89.873726
24.866943	0.0085411817	0.00041612104	100.771
25.86792	0.011575566	0.00041925587	109.80546
26.868896	0.016634068	0.00033312893	127.10473
27.869873	0.016589196	0.00055133575	138.48836
28.87085	0.021973269	0.00051441032	153.06584
29.871826	0.02466733	0.00071332359	167.82417
30.872803	0.029524423	0.000639109	179.63983
31.873779	0.03048024	0.00078701467	197.28516
32.874756	0.032901794	0.0007759874	219.61285
33.875732	0.036322195	0.00087245315	232.87881
34.876709	0.037593953	0.00093914004	246.44138
35.877686	0.041480478	0.0011390992	271.85104
36.878662	0.044659156	0.0011280761	286.1525
37.879639	0.049266692	0.0011358169	307.04398
38.880615	0.048434835	0.0012633431	323.23044
39.881592	0.054378826	0.0013724056	346.78018
40.882568	0.055148806	0.0014754852	363.16913
41.883545	0.058381986	0.0016103433	392.53503
42.884521	0.064782269	0.0018055728	413.58173
43.885498	0.0648757	0.0017232363	433.1618
44.886475	0.068810783	0.0019509419	458.60468
45.887451	0.071097367	0.0019455409	475.39514
46.888428	0.071944386	0.002016932	494.28076
47.889404	0.078778215	0.0021300351	520.73706
48.890381	0.079580978	0.0021798224	542.47705
49.891357	0.084754221	0.0023132043	564.66711
50.892334	0.084745407	0.0024941263	581.388
51.893311	0.087989807	0.0025562972	609.9281
52.894287	0.092326269	0.0026416334	631.19189
53.895264	0.092772111	0.0028262136	666.06824
54.89624	0.098515563	0.0029004731	692.79407
55.897217	0.1014512	0.0031533136	732.04535
56.898193	0.10312694	0.0032731125	757.50665
57.89917	0.10642385	0.0033566128	782.34412
58.900146	0.11167781	0.0034713876	805.85144
59.901123	0.11082854	0.0036560567	837.04755
60.9021	0.11650704	0.0037636491	859.42804
61.903076	0.11828504	0.0038214396	885.02222
62.904053	0.12074286	0.0040025939	916.3324
63.905029	0.12642632	0.0041015963	943.26367
64.906006	0.13032652	0.0042638308	970.52148
65.906982	0.13092747	0.0044113258	998.47675
66.907959	0.13613391	0.0045288051	1025.7111
67.908936	0.13815598	0.0045916126	1050.7151
68.909912	0.14173046	0.0046656253	1076.4977
69.910889	0.14291801	0.0048651788	1107.7152
70.911865	0.14816003	0.0050316099	1134.5492
71.912842	0.15190175	0.0050851721	1158.5424
72.913818	0.1547585	0.0053000138	1184.3337
73.914795	0.15702577	0.0054847375	1220.6741
74.915771	0.15939759	0.0055417819	1238.5159
75.916748	0.15689977	0.0055839117	1264.3961
76.917725	0.1625379	0.0058143944	1293.6244
77.918701	0.16613989	0.005971082	1320.2051
78.919678	0.16862598	0.0060985181	1344.9226
79.920654	0.17354679	0.0063123442	1381.9169
80.921631	0.17642033	0.006310205	1401.1306
81.922607	0.17988771	0.0064525623	1428.2142
82.923584	0.18172286	0.0066371989	1468.1178
83.924561	0.18798956	0.0068097366	1494.5205
84.925537	0.18753347	0.0069134953	1509.322
85.926514	0.19230846	0.0069410079	1534.8225
86.92749	0.19255555	0.0070666382	1558.2938
87.928467	0.1971911	0.0071451636	1582.7239
88.929443	0.20266882	0.0072995098	1612.2037
89.93042	0.2041467	0.0074888435	1636.156
90.931396	0.2064005	0.0074866922	1661.2059
91.932373	0.20935313	0.0077350619	1694.027
92.93335	0.21263276	0.0078356871	1722.8645
93.934326	0.21704832	0.0079268254	1746.826
94.935303	0.21859053	0.0080705639	1773.9772
95.936279	0.22059539	0.0082208524	1796.7653
96.937256	0.22504266	0.0082550198	1809.4069
97.938232	0.22931212	0.0083185276	1830.9976
98.939209	0.22916439	0.0084100803	1852.0687
99.940186	0.23357734	0.0085953651	1870.7205
100.94116	0.23689303	0.0087718181	1901.53
101.94214	0.23980469	0.0087071434	1918.9618
102.94312	0.23893206	0.0088600572	1921.7979
103.94409	0.24926153	0.0089452127	1950.2369
104.94507	0.2506837	0.0090114241	1964.9005
105.94604	0.25089753	0.0090887938	1975.8258
106.94702	0.25490639	0.0090397596	1989.6697
107.948	0.25781932	0.0093051931	2007.4222
108.94897	0.2579228	0.0093360739	2023.4828
109.94995	0.26235452	0.0094053596	2031.6539
110.95093	0.26830649	0.0094480906	2049.3479
111.9519	0.27053389	0.0094216364	2046.9668
112.95288	0.27340645	0.0095956884	2071.1079
113.95386	0.27878577	0.0097452495	2088.7712
114.95483	0.2789427	0.0097350497	2099.7659
115.95581	0.28521642	0.0097783664	2104.7305
116.95679	0.28711823	0.0097966678	2120.4023
117.95776	0.28966251	0.009929481	2129.9846
118.95874	0.28933507	0.010037945	2144.4578
119.95972	0.29273951	0.010021771	2147.4089
120.96069	0.29464841	0.010040129	2160.7295
121.96167	0.29879111	0.010251902	2172.4805
122.96265	0.30265427	0.010247443	2188.9165
123.96362	0.30527151	0.010402748	2197.4666
124.9646	0.31069326	0.010350425	2203.3958
125.96558	0.31017655	0.010420934	2209.1814
126.96655	0.31694362	0.010519462	2230.3401
127.96753	0.31854439	0.010573335	2241.5862
128.96851	0.32123297	0.010677459	2248.3362
129.96948	0.32479146	0.010702509	2255.9126
130.97046	0.32574359	0.010796131	2261.6355
131.97144	0.32838765	0.010857302	2273.4216
132.97241	0.33312491	0.010868608	2287.0479
133.97339	0.33355907	0.010946978	2288.3982
134.97437	0.33851716	0.010996688	2298.7656
135.97534	0.34186688	0.01113209	2316.0708
136.97632	0.34235042	0.011216373	2317.031
137.97729	0.34806007	0.011345028	2334.0576
138.97827	0.35255513	0.011384148	2339.7478
139.97925	0.35423973	0.011439187	2352.7163
140.98022	0.3558071	0.011484417	2357.1016
141.9812	0.36164925	0.011555424	2364.7205
142.98218	0.36323735	0.011714695	2375.0027
143.98315	0.36572534	0.011733139	2384.9988
144.98413	0.37148109	0.011868133	2397.5696
145.98511	0.36996245	0.011891831	2394.8408
146.98608	0.37646496	0.012058737	2408.8923
147.98706	0.37774226	0.012061593	2410.5349
148.98804	0.3805126	0.012187345	2425.3625
149.98901	0.38672581	0.012372368	2443.8574
150.98999	0.38777506	0.012478696	2447.564
151.99097	0.39163557	0.012570622	2451.3889
152.99194	0.39245123	0.012660482	2457.6348
153.99292	0.39881873	0.012751019	2473.4685
154.9939	0.39562002	0.012887073	2468.3689
155.99487	0.40487462	0.012952428	2482.1301
156.99585	0.40700817	0.013217283	2491.1917
157.99683	0.40972763	0.01317043	2500.5938
158.9978	0.41174129	0.01334533	2506.7339
159.99878	0.41674608	0.013580531	2514.7678
160.99976	0.41505003	0.013549645	2517.1887
162.00073	0.42048678	0.013785969	2531.5305
163.00171	0.42311937	0.01392594	2541.0425
164.00269	0.4277398	0.014123453	2555.394
165.00366	0.43069693	0.014306422	2550.7122
166.00464	0.42921743	0.014378662	2552.8335
167.00562	0.43771482	0.014458347	2555.1011
168.00659	0.43835327	0.014696981	2569.7354
169.00757	0.44110119	0.014904008	2578.8323
170.00854	0.44694197	0.015170589	2587.665
171.00952	0.44876018	0.015352604	2597.9202
172.0105	0.45098874	0.015634375	2601.3743
173.01147	0.45385367	0.015850069	2609.5513
174.01245	0.45593101	0.01605184	2611.791
175.01343	0.45854643	0.016175538	2609.6936
176.0144	0.46613058	0.016477214	2624.7871
177.01538	0.46622196	0.016883969	2638.3618
178.01636	0.46868187	0.017130533	2645.9768
179.01733	0.46828213	0.017410096	2640.6057
180.01831	0.47400758	0.01775766	2644.188
181.01929	0.47950959	0.017909007	2651.3906
182.02026	0.47911933	0.018361103	2657.2271
183.02124	0.48265094	0.018653674	2668.0542
184.02222	0.48536327	0.01900333	2665.9976
185.02319	0.49121204	0.019429728	2681.3618
186.02417	0.49024108	0.019764168	2678.4414
187.02515	0.493608	0.020178091	2683.9043
188.02612	0.4983446	0.020621011	2700.9878
189.0271	0.50342691	0.021040289	2694.1614
190.02808	0.50525451	0.021573199	2704.1465
191.02905	0.50958747	0.022096219	2713.6953
192.03003	0.50911069	0.022529578	2715.1917
193.03101	0.51112926	0.023143966	2712.8245
194.03198	0.51590216	0.02361929	2723.9854
195.03296	0.52082336	0.024112305	2726.0715
196.03394	0.52359217	0.024640238	2738.8586
197.03491	0.52350962	0.025288006	2737.865
198.03589	0.52801394	0.025992142	2740.1311
199.03687	0.53246415	0.026686542	2752.2922
200.03784	0.53569686	0.027337203	2751.7791
201.03882	0.53731626	0.027989445	2754.2275
202.03979	0.53677678	0.028689103	2760.6824
203.04077	0.54504508	0.029336827	2763.8977
204.04175	0.54827309	0.030078113	2771.4438
205.04272	0.55116159	0.030809451	2772.4294
206.0437	0.55402005	0.031438388	2776.2842
207.04468	0.55397332	0.032243412	2779.2544
208.04565	0.55791187	0.033016868	2788.2542
209.04663	0.56252086	0.033674557	2788.8279
210.04761	0.56355345	0.034384467	2783.9509
211.04858	0.56669056	0.035219304	2796.0667
212.04956	0.56842518	0.03589201	2800.5801
213.05054	0.5733062	0.036787525	2800.5271
214.05151	0.57937682	0.037555985	2806.6836
215.05249	0.58037466	0.038383309	2808.3145
216.05347	0.58243322	0.039121069	2809.8667
217.05444	0.5846349	0.040085603	2814.6873
218.05542	0.5892629	0.040693816	2817.5598
219.0564	0.59464556	0.04157171	2826.886
220.05737	0.59616566	0.042510711	2824.5725
221.05835	0.59712571	0.043311454	2824.2231
222.05933	0.60105896	0.044169877	2829.2346
223.0603	0.60188055	0.045139045	2833.4854
224.06128	0.60425562	0.046312582	2836.7568
225.06226	0.60893393	0.047180679	2832.7683
226.06323	0.61265671	0.047944542	2839.2305
227.06421	0.61839461	0.048837122	2844.6365
228.06519	0.61882055	0.049635112	2841.4263
229.06616	0.6222232	0.050624918	2852.1545
230.06714	0.62372905	0.051661957	2854.3718
231.06812	0.62921661	0.05275771	2868.3008
232.06909	0.63077128	0.053700093	2862.4348
233.07007	0.63575506	0.054841112	2871.0596
234.07104	0.63886237	0.055943925	2871.3323
235.07202	0.64108884	0.056902047	2871.49
236.073	0.64260894	0.057944972	2870.4106
237.07397	0.64796948	0.058888134	2876.0806
238.07495	0.65042216	0.059770241	2874.9102
239.07593	0.65218997	0.060745999	2873.4556
240.0769	0.65714782	0.061890919	2882.1223
241.07788	0.65992469	0.063073859	2880.2053
242.07886	0.65808499	0.064255945	2885.7439
243.07983	0.66669673	0.0654222	2892.5403
244.08081	0.66855729	0.066410236	2895.0854
245.08179	0.66943747	0.06740766	2886.9912
246.08276	0.67354244	0.068452559	2897.3762
247.08374	0.67547637	0.069828793	2900.2122
248.08472	0.67878699	0.071063668	2900.5254
249.08569	0.68367827	0.072057627	2902.5015
250.08667	0.68565708	0.072821341	2903.1304
251.08765	0.68547183	0.073918633	2900.3486
252.08862	0.69143289	0.074908614	2899.4023
253.0896	0.6942054	0.075921632	2903.7935
254.09058	0.69680321	0.076880008	2909.9204
255.09155	0.69980711	0.07795345	2907.8047
256.09253	0.70078379	0.078933433	2914.4629
257.09351	0.70519197	0.080067381	2914.866
258.09448	0.70961714	0.081466824	2921.1165
259.09546	0.71079469	0.082566351	2918.8521
260.09644	0.71237963	0.083817899	2918.3379
261.09741	0.72111732	0.084937245	2928.8481
262.09839	0.72100484	0.086180091	2926.7969
263.09937	0.72314823	0.087469473	2935.4463
264.10034	0.72796005	0.088503033	2920.832
265.10132	0.72980177	0.089627072	2935.7334
266.10229	0.73282081	0.09083347	2929.5088
267.10327	0.73376083	0.092003927	2939.3132
268.10425	0.73918521	0.093017124	2939.6123
269.10522	0.74325192	0.094159059	2942.9587
270.1062	0.74384671	0.095368482	2947.1521
271.10718	0.74976552	0.096735619	2945.6667
272.10815	0.74897152	0.097800449	2946.7881
273.10913	0.75246817	0.098954327	2948.3884
274.11011	0.75689894	0.10012972	2948.7322
275.11108	0.76095861	0.1012776	2946.1055
276.11206	0.76117426	0.10253046	2953.4768
277.11304	0.76819032	0.10379049	2961.2778
278.11401	0.76830649	0.10506585	2956.6399
279.11499	0.77100879	0.10619965	2958.1416
280.11597	0.77659708	0.10727399	2957.5444
281.11694	0.77937007	0.10855274	2969.9573
282.11792	0.78177053	0.10978144	2969.9075
283.1189	0.78294927	0.11092249	2968.4321
284.11987	0.78749496	0.11232707	2972.281
285.12085	0.78830135	0.11356634	2961.1438
286.12183	0.79117411	0.11467524	2976.4937
287.1228	0.79506105	0.11570752	2976.4421
288.12378	0.79978496	0.11678518	2979.6577
289.12476	0.80279988	0.11776634	2977.1611
290.12573	0.80459166	0.11906442	2974.397
291.12671	0.80835688	0.12034025	2981.0439
292.12769	0.80845255	0.12168518	2983.0129
293.12866	0.81237227	0.12257037	2978.5269
294.12964	0.81641942	0.12377971	2984.8374
295.13062	0.8186177	0.12494215	2989.7075
296.13159	0.82201457	0.12613349	2982.3296
297.13257	0.82478511	0.12726173	2983.0039
298.13354	0.82755375	0.12863693	2997.5222
299.13452	0.83431399	0.12998675	2997.7126
300.1355	0.83378828	0.13114384	2994.8657
301.13647	0.83800554	0.13237971	2991.7693
302.13745	0.83958763	0.13378161	2997.4668
303.13843	0.84596193	0.13487323	2995.8972
304.1394	0.84655672	0.13611116	2997.8235
305.14038	0.85121655	0.13736103	3003.8101
306.14136	0.85439295	0.13877966	3003.1438
307.14233	0.85361964	0.14009467	3002.9976
308.14331	0.85862362	0.14155243	3009.7925
309.14429	0.86072558	0.14274614	3009.1145
310.14526	0.86717016	0.14387046	3010.9341
311.14624	0.86681676	0.14494026	3007.7161
312.14722	0.87133801	0.14618836	3016.8987
313.14819	0.8718726	0.14757802	3015.0298
314.14917	0.87569457	0.14855187	3020.4319
315.15015	0.87877995	0.14987849	3017.6863
316.15112	0.88331109	0.15085387	3011.9785
317.1521	0.88327831	0.15202594	3025.0046
318.15308	0.89009231	0.15337226	3029.6855
319.15405	0.89325804	0.15461239	3024.7285
320.15503	0.8939774	0.15583891	3022.3201
321.15601	0.89633173	0.157005	3030.7246
322.15698	0.90076572	0.15805249	3024.9067
323.15796	0.90227085	0.15908638	3026.2434
324.15894	0.90763956	0.16026978	3029.072
325.15991	0.90996116	0.16120471	3026.1931
326.16089	0.91299576	0.1623795	3040.9788
327.16187	0.91644365	0.16355662	3040.3745
328.16284	0.9193188	0.16466732	3033.8713
329.16382	0.92277569	0.16606295	3042.1558
330.16479	0.92528027	0.16747861	3040.4509
331.16577	0.92688102	0.16863844	3033.4468
332.16675	0.93196541	0.16961059	3044.1433
333.16772	0.93491763	0.17069346	3047.6316
334.1687	0.93610245	0.17186008	3049.1924
335.16968	0.9392606	0.17321421	3046.6624
336.17065	0.9398638	0.17454368	3046.0242
337.17163	0.94530058	0.17581207	3054.0686
338.17261	0.94792354	0.17698716	3042.5349
339.17358	0.94981384	0.17800654	3052.9321
340.17456	0.95363271	0.17910731	3057.9692
341.17554	0.95766437	0.18052763	3060.541
342.17651	0.95839256	0.18189034	3051.4775
343.17749	0.96778357	0.18309711	3063.9871
344.17847	0.9691301	0.18422127	3060.8254
345.17944	0.97011769	0.18521672	3057.8994
346.18042	0.97616333	0.18626162	3067.6233
347.1814	0.97527719	0.18770547	3064.4297
348.18237	0.97814602	0.18883316	3068.866
349.18335	0.98416364	0.19019958	3078.7244
350.18433	0.98782396	0.1916838	3080.7451
351.1853	0.9887476	0.19288264	3066.843
352.18628	0.99337208	0.1940769	3077.4707
353.18726	0.99239749	0.19536778	3068.436
354.18823	0.99810714	0.19635116	3071.6921
355.18921	1.0022473	0.19732723	3082.1255
356.19019	1.0063256	0.19854793	3086.8564
357.19116	1.0095012	0.19984677	3083.8342
358.19214	1.0081601	0.20103043	3079.05
359.19312	1.0107695	0.20216362	3078.8816
360.19409	1.0119244	0.20332231	3077.0686
361.19507	1.0172017	0.20441955	3083.0808
362.19604	1.0190252	0.20599584	3089.218
363.19702	1.0259081	0.20722786	3089.2683
364.198	1.0258994	0.20834433	3086.9624
365.19897	1.0287548	0.20958558	3087.3718
366.19995	1.0361432	0.21083842	3089.8635
367.20093	1.0333651	0.21186429	3092.6421
368.2019	1.0369333	0.21306907	3088.2007
369.20288	1.0444914	0.21398479	3091.6045
370.20386	1.0452677	0.21501236	3095.5942
371.20483	1.0495297	0.21628478	3100.9292
372.20581	1.0488789	0.21768828	3110.8115
373.20679	1.0562984	0.21923485	3109.1355
374.20776	1.056047	0.22037798	3097.5679
375.20874	1.061385	0.22146472	3102.6816
376.20972	1.0627992	0.22274223	3104.5938
377.21069	1.0647641	0.22397664	3111.8662
378.21167	1.0706221	0.22545387	3115.28
379.21265	1.0726444	0.22665107	3110.2703
380.21362	1.0714685	0.22770448	3113.1624
381.2146	1.0796049	0.22887209	3108.981
382.21558	1.0796468	0.23009478	3118.4846
383.21655	1.0858206	0.23105195	3113.5967
384.21753	1.086639	0.23215725	3108.9836
385.21851	1.0922694	0.23329082	3124.3057
386.21948	1.0896833	0.23452075	3113.6108
387.22046	1.0944426	0.23593263	3115.7312
388.22144	1.0994608	0.23720498	3124.6538
389.22241	1.1043378	0.23825237	3118.5427
390.22339	1.1074713	0.23949985	3130.4521
391.22437	1.1076113	0.24070811	3126.8401
392.22534	1.1140928	0.24186577	3131.4055
393.22632	1.1134473	0.24314794	3125.5293
394.22729	1.1167781	0.24438767	3124.0957
395.22827	1.1209731	0.24561188	3127.7117
396.22925	1.120913	0.24685581	3132.7896
397.23022	1.1274437	0.24804631	3136.4905
398.2312	1.1300546	0.24937905	3136.5762
399.23218	1.131411	0.25072485	3134.0674
400.23315	1.1387849	0.25172597	3131.741
401.23413	1.1347055	0.25294012	3136.8103
402.23511	1.1410561	0.25394145	3133.9438
403.23608	1.1456144	0.25500798	3142.6606
404.23706	1.1477646	0.25613126	3144.3779
405.23804	1.1516238	0.25755367	3144.9165
406.23901	1.1555792	0.25874248	3149.5354
407.23999	1.1562022	0.2599045	3147.0757
408.24097	1.1559629	0.26117966	3147.9387
409.24194	1.1604041	0.26246142	3142.4087
410.24292	1.1648948	0.26359007	3142.5376
411.2439	1.165596	0.26463255	3153.5945
412.24487	1.1696367	0.26583946	3149.5608
413.24585	1.1724961	0.26701227	3145.981
414.24683	1.1758096	0.2684308	3152.074
415.2478	1.1772571	0.26959071	3154.2925
416.24878	1.1830195	0.27076375	3156.377
417.24976	1.1883703	0.27181461	3155.917
418.25073	1.1874105	0.27281672	3153.8555
419.25171	1.1907241	0.27375555	3155.9722
420.25269	1.199228	0.27503303	3170.675
421.25366	1.1981483	0.27639022	3171.5669
422.25464	1.1997979	0.2777558	3167.3696
423.25562	1.2059141	0.27922225	3167.3264
424.25659	1.2075961	0.28053355	3164.0208
425.25757	1.208585	0.28170061	3168.365
426.25854	1.2165717	0.28277391	3171.8518
427.25952	1.2157924	0.28386834	3166.9333
428.2605	1.2209483	0.28504547	3173.8135
429.26147	1.2260494	0.28592619	3171.2334
430.26245	1.2248353	0.28710732	3177.6963
431.26343	1.2280046	0.28826463	3177.6111
432.2644	1.2322667	0.28967497	3183.9646
433.26538	1.2351863	0.29106373	3186.6189
434.26636	1.2389309	0.29224971	3176.4153
435.26733	1.2396528	0.29335892	3179.894
436.26831	1.2421234	0.2943829	3181.6931
437.26929	1.2458488	0.2954095	3179.1428
438.27026	1.2486137	0.29641339	3179.0281
439.27124	1.2542959	0.29760528	3184.2515
440.27222	1.2579032	0.2988289	3192.2896
441.27319	1.2561007	0.30006537	3183.9751
442.27417	1.2611706	0.30113989	3185.4041
443.27515	1.2623621	0.30253878	3187.9551
444.27612	1.2668664	0.30359229	3188.7356
445.2771	1.2708838	0.30477944	3199.3828
446.27808	1.2727814	0.30602527	3193.5068
447.27905	1.2766296	0.30743295	3196.7346
448.28003	1.2784591	0.30853745	3193.644
449.28101	1.2842962	0.30993593	3204.4534
450.28198	1.2837414	0.31108451	3198.6187
451.28296	1.2895178	0.31207803	3200.2644
452.28394	1.2929937	0.31334972	3205.4868
453.28491	1.2948523	0.31425861	3195.4534
454.28589	1.2985779	0.31535813	3203.6501
455.28687	1.2997336	0.31642696	3204.3516
456.28784	1.3016111	0.31765455	3202.4346
457.28882	1.3085674	0.31882751	3216.3486
458.28979	1.312084	0.31990835	3208.5334
459.29077	1.31013	0.32113802	3209.7271
460.29175	1.3160969	0.32246336	3213.8682
461.29272	1.3187133	0.32335415	3208.7131
462.2937	1.3192153	0.32450786	3215.1406
463.29468	1.3264033	0.32561865	3215.1841
464.29565	1.3260616	0.32682994	3208.3855
465.29663	1.3326765	0.32812673	3227.9639
466.29761	1.3345027	0.32923859	3219.3706
467.29858	1.336606	0.33027309	3216.387
468.29956	1.3386939	0.33137664	3219.2417
469.30054	1.3414254	0.3325372	3218.4192
470.30151	1.3474979	0.33369967	3223.2795
471.30249	1.3474334	0.33492056	3226.4402
472.30347	1.3507532	0.3359586	3213.7202
473.30444	1.3566103	0.33714241	3220.8103
474.30542	1.3585525	0.3384423	3229.4553
475.3064	1.3615093	0.3396807	3230.5793
476.30737	1.3625146	0.34085691	3226.1479
477.30835	1.3641126	0.3420763	3226.2798
478.30933	1.368454	0.34294713	3222.5527
479.3103	1.3736295	0.34409338	3228.5149
480.31128	1.3749436	0.34535319	3229.7312
481.31226	1.3784941	0.34639755	3228.1741
482.31323	1.380955	0.3475264	3232.6433
483.31421	1.3819102	0.34872091	3232.6724
484.31519	1.38797	0.35003978	3240.821
485.31616	1.3920264	0.35122606	3235.4268
486.31714	1.394914	0.35252279	3240.0491
487.31812	1.3966655	0.35376373	3249.97
488.31909	1.3988756	0.35479525	3236.7869
489.32007	1.4005504	0.35593021	3247.5859
490.32104	1.4085557	0.35714614	3245.2891
491.32202	1.4081929	0.35830995	3244.9155
492.323	1.4130447	0.35971597	3249.2202
493.32397	1.412582	0.36095762	3244.9358
494.32495	1.4177692	0.36219659	3249.9722
495.32593	1.4207759	0.36323559	3242.4861
496.3269	1.4240946	0.3643783	3251.572
497.32788	1.4280905	0.36551577	3251.9368
498.32886	1.4304103	0.36661991	3252.7644
499.32983	1.4324042	0.36781722	3255.4202
500.33081	1.4349273	0.36904603	3252.5125
501.33179	1.4385941	0.37016317	3256.3596
502.33276	1.4409779	0.37121338	3255.5344
503.33374	1.4412775	0.37234044	3255.1145
504.33472	1.4453009	0.37362427	3255.2195
505.33569	1.4514608	0.37454128	3255.3076
506.33667	1.4537169	0.37566766	3262.4792
507.33765	1.4580618	0.37707192	3266.5164
508.33862	1.4600195	0.37816581	3264.772
509.3396	1.4626483	0.37904769	3262.3481
510.34058	1.4659538	0.38028249	3271.0969
511.34155	1.4675022	0.38150185	3265.9536
512.34253	1.4733573	0.38283324	3272.3853
513.34351	1.4729902	0.38408959	3265.4602
514.34448	1.4780335	0.38516891	3263.1089
515.34546	1.4811687	0.38616517	3268.0105
516.34644	1.4824485	0.38725853	3265.9526
517.34741	1.4866095	0.38829648	3270.8218
518.34839	1.4881191	0.38951573	3272.5088
519.34937	1.4935178	0.39058739	3273.4805
520.35034	1.4941306	0.3918089	3277.1538
521.35132	1.4973727	0.39304367	3279.2258
522.35229	1.500425	0.39416426	3276.6931
523.35327	1.5068784	0.39535165	3278.7935
524.35425	1.506217	0.39663699	3273.9834
525.35522	1.5096821	0.39784101	3283.1099
526.3562	1.5116158	0.39897895	3280.5242
527.35718	1.5140234	0.40007058	3274.4482
528.35815	1.5188553	0.40134183	3280.7515
529.35913	1.5218263	0.40249342	3290.8035
530.36011	1.5273237	0.4036555	3284.5234
531.36108	1.5295367	0.40496206	3292.5178
532.36206	1.5309281	0.40617013	3289.1907
533.36304	1.5335679	0.40714982	3284.8442
534.36401	1.5364653	0.40826699	3289.0334
535.36499	1.54118	0.40967482	3304.5017
536.36597	1.5432594	0.41086155	3286.5918
537.36694	1.5459741	0.41207013	3288.3779
538.36792	1.5462757	0.41329369	3291.1724
539.3689	1.551867	0.41427952	3292.5959
540.36987	1.5543187	0.41533759	3294.4265
541.37085	1.5581044	0.41647524	3294.7034
542.37183	1.5633864	0.41761345	3299.5684
543.3728	1.5660102	0.4187378	3294.2087
544.37378	1.5673923	0.41979158	3289.8923
545.37476	1.5736624	0.42092994	3302.978
546.37573	1.5739759	0.42220047	3305.1504
547.37671	1.5783515	0.42337501	3304.3145
548.37769	1.5800012	0.42458859	3304.8374
549.37866	1.5837981	0.42590088	3303.8828
550.37964	1.5866739	0.42691785	3307.0139
551.38062	1.5875057	0.42804447	3304.5269
552.38159	1.5928324	0.42930448	3310.9878
553.38257	1.5932516	0.4303804	3302.3704
554.38354	1.5982672	0.43158641	3315.855
555.38452	1.600695	0.4329125	3313.3931
556.3855	1.6028932	0.43449789	3314.1438
557.38647	1.6088372	0.43591976	3315.6338
558.38745	1.6058811	0.43697068	3311.1057
559.38843	1.6149012	0.43809688	3316.6479
560.3894	1.6155965	0.43910149	3314.6045
561.39038	1.6217227	0.4401992	3317.6985
562.39136	1.6205827	0.44129914	3316.6887
563.39233	1.624928	0.44254035	3317.6453
564.39331	1.6301316	0.44380513	3328.1084
565.39429	1.6292245	0.44515002	3320.72
566.39526	1.6332655	0.44622543	3310.8269
567.39624	1.6389136	0.44722831	3326.0754
568.39722	1.6403862	0.44826958	3318.3682
569.39819	1.6439583	0.44938043	3324.9006
570.39917	1.64566	0.45056769	3330.1365
571.40015	1.6468941	0.45180786	3319.8884
572.40112	1.65317	0.45299578	3330.8503
573.4021	1.6517602	0.45409727	3315.4116
574.40308	1.6571689	0.45510417	3324.7952
575.40405	1.660476	0.45617661	3322.425
576.40503	1.6653275	0.45742625	3338.1592
577.40601	1.6677983	0.45856631	3332.4924
578.40698	1.6672701	0.45962867	3331.8164
579.40796	1.6730793	0.46081841	3338.1052
580.40894	1.6793886	0.46218625	3335.8779
581.40991	1.6797099	0.46361658	3338.6526
582.41089	1.681769	0.4647046	3333.2861
583.41187	1.6844115	0.46601877	3338.6619
584.41284	1.6881709	0.46701166	3338.9746
585.41382	1.6905822	0.46819451	3342.8801
586.41479	1.6941009	0.46930316	3336.927
587.41577	1.6994761	0.47042361	3345.9888
588.41675	1.7005553	0.4715341	3338.4656
589.41772	1.7035378	0.4727686	3336.7273
590.4187	1.7033596	0.4738988	3341.4795
591.41968	1.71052	0.47522649	3350.0391
592.42065	1.7138516	0.47650874	3346.6353
593.42163	1.7130084	0.47795498	3349.1143
594.42261	1.7197726	0.47919723	3345.3965
595.42358	1.719061	0.48039347	3346.0439
596.42456	1.7240068	0.4815695	3351.9082
597.42554	1.7253234	0.48302853	3353.7615
598.42651	1.729857	0.48431152	3349.374
599.42749	1.73444	0.48537946	3346.9592
600.42847	1.734223	0.48666313	3351.9468
601.42944	1.7401465	0.48782218	3352.2786
602.43042	1.7408583	0.48895007	3351.5735
603.4314	1.7447422	0.48995882	3355.4592
604.43237	1.7471309	0.49120238	3354.8359
605.43335	1.7510648	0.49234429	3357.4878
606.43433	1.7532735	0.49365166	3357.0876
607.4353	1.7579036	0.49463239	3357.283
608.43628	1.7583756	0.49580038	3358.2498
609.43726	1.7617141	0.4967379	3351.3796
610.43823	1.7678021	0.49776894	3358.2305
611.43921	1.7688671	0.49873587	3359.157
612.44019	1.7724952	0.49990851	3365.5811
613.44116	1.7727654	0.50114983	3357.4668
614.44214	1.7767583	0.50242406	3364.9377
615.44312	1.7805307	0.5038861	3363.5288
616.44409	1.7835858	0.50522989	3366.5537
617.44507	1.7877624	0.50625974	3372.3875
618.44604	1.7906883	0.50753689	3370.2737
619.44702	1.791886	0.50862968	3365.8279
620.448	1.797129	0.50989592	3380.0598
621.44897	1.7987893	0.51137072	3379.2839
622.44995	1.8025148	0.5125739	3366.282
623.45093	1.8032109	0.51371902	3364.0286
624.4519	1.810342	0.51478279	3372.8242
625.45288	1.8102978	0.51574332	3368.821
626.45386	1.8134019	0.51699346	3371.7571
627.45483	1.8158594	0.51828814	3373.0129
628.45581	1.8214203	0.51979887	3381.5007
629.45679	1.8218009	0.52104539	3369.4058
630.45776	1.8261591	0.52247655	3372.5212
631.45874	1.8284913	0.52337611	3369.3167
632.45972	1.8318659	0.52450514	3373.7971
633.46069	1.8346567	0.52571571	3376.5071
634.46167	1.8375026	0.52691633	3377.1489
635.46265	1.8394873	0.52817476	3379.9084
636.46362	1.8422961	0.52944916	3379.9775
637.4646	1.8489262	0.53072816	3381.0591
638.46558	1.8494849	0.53180552	3378.4819
639.46655	1.8515928	0.53314805	3382.3445
640.46753	1.8547804	0.5344432	3386.4434
641.46851	1.8597575	0.53554612	3384.4763
642.46948	1.8616856	0.53664374	3381.082
643.47046	1.8670875	0.53770679	3386.4314
644.47144	1.8671468	0.53874326	3380.9058
645.47241	1.8725164	0.53993535	3389.0635
646.47339	1.8749334	0.54102558	3390.6616
647.47437	1.8754935	0.5420112	3388.7554
648.47534	1.8798287	0.54320455	3390.522
649.47632	1.8846991	0.54457921	3395.6091
650.47729	1.8881267	0.54594874	3395.9846
651.47827	1.8884267	0.54719776	3392.6394
652.47925	1.8921874	0.54844069	3395.874
653.48022	1.8972573	0.54961443	3392.8367
654.4812	1.8980548	0.55074543	3396.5439
655.48218	1.9029059	0.55199713	3399.9353
656.48315	1.9038005	0.55345362	3404.3901
657.48413	1.910096	0.55477107	3396.9048
658.48511	1.9086413	0.55603385	3397.0703
659.48608	1.911606	0.55715179	3395.4065
660.48706	1.9154165	0.55826968	3396.7173
661.48804	1.918852	0.55912757	3390.7441
662.48901	1.9214723	0.56029677	3396.8184
663.48999	1.9258341	0.56151837	3408.8657
664.49097	1.9273534	0.5627988	3407.7634
665.49194	1.9305019	0.5643369	3407.4653
666.49292	1.9372609	0.56564248	3407.1538
667.4939	1.9379448	0.56714851	3406.5627
668.49487	1.9406025	0.56848192	3410.8955
669.49585	1.9428488	0.56991225	3404.8574
670.49683	1.9456103	0.571347	3408.9094
671.4978	1.9489911	0.57270277	3405.4319
672.49878	1.9534091	0.57375544	3408.4143
673.49976	1.9529568	0.574875	3404.3621
674.50073	1.9591266	0.57585526	3402.9158
675.50171	1.9600821	0.57702428	3414.4641
676.50269	1.9654686	0.57848322	3416.2014
677.50366	1.9686512	0.57997108	3421.3726
678.50464	1.9669191	0.58117634	3408.8567
679.50562	1.9724338	0.58232105	3409.8596
680.50659	1.9778548	0.58335	3408.7485
681.50757	1.9794439	0.58460861	3416.9026
682.50854	1.9819925	0.58590531	3421.4309
683.50952	1.9879904	0.58705747	3416.8452
684.5105	1.9865735	0.58817059	3408.6003
685.51147	1.9902692	0.58922982	3415.948
686.51245	1.995858	0.59058458	3421.4429
687.51343	1.9989198	0.59180349	3420.3909
688.5144	1.9987438	0.5932312	3422.5408
689.51538	2.0049751	0.59440821	3423.8311
690.51636	2.0045109	0.5954743	3414.9905
691.51733	2.0118558	0.59660637	3419.2795
692.51831	2.011385	0.59779978	3422.2659
693.51929	2.0149386	0.59930372	3424.428
694.52026	2.0184798	0.60049832	3424.0005
695.52124	2.0186872	0.6017096	3423.1682
696.52222	2.022383	0.60300839	3427.8474
697.52319	2.0298512	0.60438955	3435.7544
698.52417	2.0307286	0.6058569	3428.7065
699.52515	2.0350046	0.60730594	3438.5828
700.52612	2.0367279	0.60878748	3435.4856
701.5271	2.0416553	0.61004114	3433.8755
702.52808	2.0425057	0.61122125	3426.3672
703.52905	2.0457833	0.61258245	3433.3342
704.53003	2.0492465	0.61363488	3433.8674
705.53101	2.0536022	0.61473984	3426.2659
706.53198	2.0521817	0.61598563	3428.4729
707.53296	2.0569601	0.61722535	3434.9688
708.53394	2.0606439	0.61847836	3435.4988
709.53491	2.0649292	0.62013251	3442.1545
710.53589	2.0650868	0.62142873	3426.6731
711.53687	2.0709894	0.62258089	3435.3645
712.53784	2.072896	0.62384164	3435.5569
713.53882	2.0759029	0.62502116	3437.0374
714.53979	2.0766833	0.62633073	3434.1699
715.54077	2.08074	0.62761909	3431.5935
716.54175	2.0826151	0.62883335	3432.8989
717.54272	2.0867827	0.63004637	3435.1853
718.5437	2.0903082	0.6310904	3436.1765
719.54468	2.0928118	0.63251626	3441.0674
720.54565	2.0969925	0.63380188	3443.1372
721.54663	2.0989182	0.63510549	3442.0825
722.54761	2.1015828	0.63651848	3441.8303
723.54858	2.103713	0.6377278	3440.8982
724.54956	2.1100576	0.63916236	3446.2805
725.55054	2.1113906	0.64051837	3444.4829
726.55151	2.115489	0.64158982	3447.7065
727.55249	2.1174114	0.64297396	3454.1218
728.55347	2.1222208	0.64429826	3456.9534
729.55444	2.1211505	0.64551729	3437.9033
730.55542	2.128861	0.64666176	3446.7109
731.5564	2.1264982	0.64780903	3442.344
732.55737	2.133847	0.64895004	3451.3396
733.55835	2.1344473	0.65009439	3453.7307
734.55933	2.1390805	0.65140671	3452.7759
735.5603	2.1407516	0.65300041	3457.7927
736.56128	2.1437309	0.65437549	3448.627
737.56226	2.1475668	0.65555322	3450.2224
738.56323	2.1462717	0.65677333	3449.5256
739.56421	2.152318	0.65806735	3450.7632
740.56519	2.1550109	0.65905428	3456.3367
741.56616	2.1605418	0.66021842	3452.7212
742.56714	2.1616209	0.66126281	3455.2981
743.56812	2.1663353	0.66233814	3449.7529
744.56909	2.1702337	0.66335183	3461.2954
745.57007	2.1723104	0.6646173	3460.3206
746.57104	2.1756229	0.66585386	3462.9937
747.57202	2.174185	0.6669606	3449.3953
748.573	2.177181	0.66812891	3450.4695
749.57397	2.183636	0.66923058	3456.8455
750.57495	2.1883774	0.67032069	3464.2129
751.57593	2.1887836	0.67142171	3460.4456
752.5769	2.1930485	0.67254013	3461.4976
753.57788	2.1961973	0.67383188	3463.9297
754.57886	2.198781	0.67496485	3460.5891
755.57983	2.2020752	0.67609173	3461.1692
756.58081	2.2066283	0.67729169	3463.7546
757.58179	2.2072155	0.67850804	3458.5911
758.58276	2.2090783	0.67971689	3460.5967
759.58374	2.2161629	0.68093431	3469.8977
760.58472	2.2140615	0.68217695	3463.5818
761.58569	2.2190912	0.68331552	3466.5056
762.58667	2.2216449	0.68486935	3473.9934
763.58765	2.2238615	0.68649536	3462.3611
764.58862	2.2283394	0.68771523	3471.3899
765.5896	2.229372	0.68901908	3466.6301
766.59058	2.2373893	0.69014108	3473.3623
767.59155	2.2358367	0.69143248	3466.9436
768.59253	2.2403903	0.69288141	3468.7791
769.59351	2.2437022	0.69429505	3472.5972
770.59448	2.2460482	0.6956681	3471.4187
771.59546	2.2480655	0.69712037	3472.8025
772.59644	2.255332	0.69877034	3470.3088
773.59741	2.2535961	0.699929	3468.8352
774.59839	2.257169	0.70105278	3471.1821
775.59937	2.2627673	0.70240945	3475.5989
776.60034	2.2640696	0.70379412	3472.6343
777.60132	2.2686861	0.70505863	3472.0833
778.60229	2.2690408	0.70642102	3470.3601
779.60327	2.2736008	0.7074582	3468.2227
780.60425	2.2767036	0.70869207	3474.2058
781.60522	2.277827	0.70969588	3470.1323
782.6062	2.2841234	0.71082824	3474.6238
783.60718	2.2827597	0.71225703	3477.9727
784.60815	2.2888303	0.71366495	3475.3618
785.60913	2.2918012	0.71536762	3479.2266
786.61011	2.2956121	0.71711212	3480.5642
787.61108	2.297034	0.7189731	3480.9624
788.61206	2.3025503	0.72044557	3484.5791
789.61304	2.305464	0.72209102	3481.4873
790.61401	2.3068318	0.72349548	3481.4277
791.61499	2.3104265	0.72502905	3484.8284
792.61597	2.3115261	0.72687161	3475.3833
793.61694	2.3141966	0.72830164	3484.387
794.61792	2.318687	0.72973078	3479.4148
795.6189	2.3232617	0.73117334	3481.96
796.61987	2.3231497	0.73283708	3483.0796
797.62085	2.3267257	0.73424935	3481.2607
798.62183	2.329591	0.73563868	3481.9143
799.6228	2.3381565	0.73698491	3489.3506
800.62378	2.3383782	0.73835194	3486.0264
801.62476	2.3397326	0.7396639	3484.4409
802.62573	2.3462436	0.74117386	3488.0662
803.62671	2.3458743	0.74259967	3490.8425
804.62769	2.3497622	0.74395025	3491.2668
805.62866	2.3501823	0.74535733	3483.075
806.62964	2.3550782	0.74662226	3493.0315
807.63062	2.3587611	0.74802542	3495.2754
808.63159	2.3597677	0.74932146	3495.4553
809.63257	2.3613484	0.75080895	3493.1885
810.63354	2.3656812	0.75204366	3492.5095
811.63452	2.3710833	0.75324202	3492.8579
812.6355	2.3702648	0.75469804	3491.4636
813.63647	2.3757842	0.75615078	3488.041
814.63745	2.3790166	0.75756669	3497.031
815.63843	2.380275	0.75874901	3487.7
816.6394	2.3848276	0.75998592	3495.3562
817.64038	2.3856907	0.76130629	3494.603
818.64136	2.3887508	0.76276386	3494.0911
819.64233	2.3955505	0.76426119	3497.7952
820.64331	2.3951457	0.76588827	3493.2505
821.64429	2.3987567	0.76727217	3491.2058
822.64526	2.4053497	0.76883662	3498.9241
823.64624	2.406512	0.77063596	3501.1233
824.64722	2.4057074	0.77224243	3492.3694
825.64819	2.412492	0.77358752	3490.8977
826.64917	2.4146895	0.77525371	3495.5398
827.65015	2.4185343	0.77698582	3496.7725
828.65112	2.4203339	0.77855438	3496.9072
829.6521	2.4238663	0.77986276	3498.3403
830.65308	2.4283812	0.78168255	3497.9673
831.65405	2.4285281	0.78341448	3489.1521
832.65503	2.4347892	0.78494126	3501.158
833.65601	2.4367328	0.78682894	3498.7217
834.65698	2.4389522	0.78842783	3503.8374
835.65796	2.4427042	0.79015112	3501.939
836.65894	2.4444969	0.79206282	3497.8013
837.65991	2.4441235	0.79393977	3496.0686
838.66089	2.4500644	0.79540884	3499.3169
839.66187	2.4529781	0.79708862	3497.8401
840.66284	2.4555342	0.7988745	3505.4531
841.66382	2.459671	0.80065602	3501.1658
842.66479	2.464642	0.80231673	3505.9314
843.66577	2.4679203	0.80411196	3501.0554
844.66675	2.4696183	0.80579472	3507.9866
845.66772	2.4705677	0.807284	3508.429
846.6687	2.4732046	0.80914098	3499.8286
847.66968	2.4787889	0.81104422	3508.3765
848.67065	2.4783587	0.81324905	3505.5242
849.67163	2.4816735	0.81486225	3499.6272
850.67261	2.4885478	0.81634802	3497.7876
851.67358	2.4882305	0.81768805	3508.0176
852.67456	2.4923561	0.81953257	3505.2122
853.67554	2.4955056	0.8212868	3508.0833
854.67651	2.4993999	0.82283282	3503.3103
855.67749	2.5044065	0.82451159	3508.9939
856.67847	2.5066161	0.82608277	3509.9521
857.67944	2.5082712	0.82780796	3511.2573
858.68042	2.5121129	0.8296361	3506.7546
859.6814	2.5169282	0.83137465	3511.2881
860.68237	2.5157053	0.83317703	3506.2656
861.68335	2.5196958	0.83496082	3509.4846
862.68433	2.5223708	0.83652067	3506.1531
863.6853	2.5255809	0.8380326	3507.9192
864.68628	2.531141	0.83985448	3515.3003
865.68726	2.5316393	0.84190965	3516.8445
866.68823	2.5347946	0.8439309	3514.3364
867.68921	2.5368307	0.84576613	3508.2168
868.69019	2.5404198	0.8471722	3511.144
869.69116	2.543632	0.84886074	3511.9321
870.69214	2.5469279	0.85049087	3506.2317
871.69312	2.5490184	0.85205859	3505.8228
872.69409	2.5506799	0.85368794	3510.0122
873.69507	2.5581648	0.85534704	3518.8489
874.69604	2.5601647	0.85718256	3511.1799
875.69702	2.5636322	0.85878634	3513.0664
876.698	2.5613282	0.86039835	3506.8362
877.69897	2.5654144	0.86208767	3513.1895
878.69995	2.570533	0.86380571	3522.0515
879.70093	2.5708501	0.86567807	3507.5256
880.7019	2.5782762	0.86727232	3514.3914
881.70288	2.5778389	0.86874104	3505.6035
882.70386	2.5815115	0.87027365	3510.9651
883.70483	2.585258	0.87209713	3518.2561
884.70581	2.5921988	0.87373328	3518.9604
885.70679	2.5891454	0.87538487	3516.7144
886.70776	2.5935302	0.87696022	3517.6096
887.70874	2.5980749	0.87876546	3520.1201
888.70972	2.6004145	0.8808037	3515.3206
889.71069	2.6033566	0.88224983	3517.5947
890.71167	2.6058242	0.88358271	3508.9585
891.71265	2.6106286	0.88533932	3528.0374
892.71362	2.6142612	0.88712806	3516.9734
893.7146	2.6158369	0.88857764	3516.5068
894.71558	2.6171074	0.88994557	3516.6519
895.71655	2.6212604	0.89123172	3514.916
896.71753	2.6273637	0.89236969	3520.6951
897.71851	2.6286516	0.89371103	3518.9631
898.71948	2.6319413	0.89496583	3520.7073
899.72046	2.6346552	0.8963694	3521.0537
900.72144	2.6378944	0.8980341	3518.8296
901.72241	2.6404505	0.89942467	3521.5525
902.72339	2.6429956	0.90112877	3526.7415
903.72437	2.6419077	0.90285498	3515.5525
904.72534	2.6508479	0.90440392	3515.199
905.72632	2.6517949	0.90609932	3523.0232
906.72729	2.6567466	0.90781778	3522.4653
907.72827	2.6566784	0.90980601	3523.5149
908.72925	2.6600862	0.91204655	3521.8347
909.73022	2.6638615	0.91401273	3520.2046
910.7312	2.6642203	0.91582477	3516.3442
911.73218	2.6697066	0.91739202	3514.4314
912.73315	2.6740601	0.91912484	3516.6443
913.73413	2.6757519	0.92111957	3520.1309
914.73511	2.6772995	0.92329478	3523.5554
915.73608	2.6824179	0.92529178	3522.6802
916.73706	2.6840932	0.92743474	3521.9434
917.73804	2.6863868	0.92987585	3517.7593
918.73901	2.6916628	0.93177837	3518.9768
919.73999	2.6965809	0.93333584	3516.2329
920.74097	2.695482	0.93481231	3512.0759
921.74194	2.7012465	0.93642139	3520.9124
922.74292	2.7019427	0.93819553	3525.8767
923.7439	2.7093003	0.94024712	3530.2065
924.74487	2.7112494	0.94226873	3532.6418
925.74585	2.7117565	0.94439685	3519.0054
926.74683	2.7116868	0.94616681	3516.5989
927.7478	2.7167571	0.94824219	3516.9851
928.74878	2.719872	0.95021874	3526.4487
929.74976	2.7219055	0.95213127	3517.7766
930.75073	2.7277615	0.95384735	3522.2617
931.75171	2.7315302	0.95591325	3520.6475
932.75269	2.733537	0.95781755	3524.186
933.75366	2.7352178	0.95953518	3529.4272
934.75464	2.7402976	0.96149111	3518.6772
935.75562	2.7413566	0.96340519	3518.2366
936.75659	2.7454157	0.96507972	3528.2102
937.75757	2.7486119	0.96718794	3527.6089
938.75854	2.7521253	0.96910906	3525.8096
939.75952	2.7517557	0.97099525	3523.2659
940.7605	2.7575328	0.97276908	3523.0347
941.76147	2.7606125	0.97461897	3530.5203
942.76245	2.7630484	0.97614503	3523.0945
943.76343	2.7669978	0.9782787	3524.8901
944.7644	2.7693503	0.98036152	3530.1538
945.76538	2.7766414	0.98258227	3528.5886
946.76636	2.7737286	0.98476624	3519.7124
947.76733	2.7775264	0.98680425	3523.7771
948.76831	2.7804923	0.98862988	3528.7151
949.76929	2.7834651	0.99059325	3525.644
950.77026	2.7867072	0.99304551	3526.2434
951.77124	2.7905953	0.99527341	3526.7334
952.77222	2.79375	0.99721223	3524.6504
953.77319	2.7975287	0.99910325	3520.8142
954.77417	2.7992389	1.0006871	3522.5229
955.77515	2.8025041	1.0022792	3531.3037
956.77612	2.8020518	1.0039589	3526.4001
957.7771	2.8082445	1.0057874	3522.5984
958.77808	2.8093596	1.0075924	3519.4539
959.77905	2.8143067	1.0094671	3521.7456
960.78003	2.8174179	1.011583	3527.8638
961.78101	2.8206675	1.013588	3520.6111
962.78198	2.8232722	1.0159655	3530.1179
963.78296	2.8243537	1.0180997	3526.9519
964.78394	2.8287113	1.0203279	3525.3291
965.78491	2.8299489	1.022676	3525.012
966.78589	2.8352642	1.024976	3522.3545
967.78687	2.8352704	1.0268135	3514.96
968.78784	2.8403466	1.0286647	3516.5605
969.78882	2.8446128	1.0305291	3526.2781
970.78979	2.8466964	1.0326055	3522.3264
971.79077	2.8495007	1.0344239	3524.8167
972.79175	2.8561296	1.0363579	3524.9148
973.79272	2.8568425	1.0385151	3527.3982
974.7937	2.8586912	1.0409875	3517.3237
975.79468	2.8627551	1.0435562	3522.4429
976.79565	2.866154	1.0460062	3523.6934
977.79663	2.8680913	1.0485895	3526.2949
978.79761	2.8703132	1.0514239	3522.761
979.79858	2.8767185	1.0537392	3525.6992
980.79956	2.8779576	1.0563365	3521.7178
981.80054	2.8785925	1.0589367	3519.6294
982.80151	2.8811293	1.0617859	3523.0037
983.80249	2.8878713	1.0643409	3520.3374
984.80347	2.8895593	1.0667081	3519.8718
985.80444	2.8926404	1.0691414	3522.0552
986.80542	2.8928831	1.0718623	3524.6689
987.8064	2.898633	1.0746659	3522.7485
988.80737	2.8988609	1.0776236	3527.8086
989.80835	2.9067633	1.0800456	3525.0334
990.80933	2.9066417	1.082425	3522.3379
991.8103	2.9120326	1.0844746	3518.4436
992.81128	2.9127834	1.0860845	3517.2856
993.81226	2.918571	1.0879205	3525.616
994.81323	2.9190323	1.0900061	3525.1436
995.81421	2.9210348	1.0921757	3522.5991
996.81519	2.9240818	1.0941242	3519.4443
997.81616	2.9281111	1.0960757	3521.9487
998.81714	2.928544	1.0981458	3517.1787
999.81812	2.9345763	1.1001598	3523.1301
1000.8191	2.9352114	1.1025432	3518.3892
1001.8201	2.9401157	1.104773	3519.3938
1002.821	2.9412818	1.1070046	3519.8665
1003.822	2.9463434	1.1091808	3518.9871
1004.823	2.9488022	1.1114691	3515.8132
1005.824	2.955828	1.1136739	3525.9941
1006.825	2.9556723	1.1161463	3523.1438
1007.8259	2.9559722	1.1193527	3527.532
1008.8269	2.9622214	1.1220232	3519.1252
1009.8279	2.9638915	1.1247253	3514.8479
1010.8289	2.9699311	1.1271162	3519.1208
1011.8298	2.9700034	1.1297864	3516.5864
1012.8308	2.9724936	1.1328354	3515.3591
1013.8318	2.9756744	1.1360837	3518.7397
1014.8328	2.9797339	1.1393578	3512.5684
1015.8337	2.9841464	1.1424245	3519.1702
1016.8347	2.9836974	1.1452652	3519.658
1017.8357	2.9896486	1.148051	3520.9531
1018.8367	2.9917374	1.150399	3512.3394
1019.8376	2.9962239	1.1527711	3513.853
1020.8386	2.9958687	1.1556308	3522.7617
1021.8396	2.9984822	1.1586462	3519.0481
1022.8406	3.0032303	1.1613482	3508.4763
1023.8416	3.005955	1.1637639	3509.3262
1024.8425	3.0100377	1.1662526	3508.3086
1025.8435	3.0111349	1.1687795	3510.8542
1026.8445	3.0161872	1.1714746	3511.238
1027.8455	3.0186419	1.1743394	3513.2944
1028.8464	3.0191793	1.1773643	3508.7561
1029.8474	3.0234551	1.1803954	3511.5452
1030.8484	3.0260179	1.1830609	3501.5156
1031.8494	3.0319915	1.1862431	3514.999
1032.8503	3.0353453	1.1892965	3505.0947
1033.8513	3.0356307	1.1921003	3510.3157
1034.8523	3.0376225	1.1950405	3506.0112
1035.8533	3.0433729	1.1974339	3504.3789
1036.8542	3.0429533	1.2001351	3506.4736
1037.8552	3.0501468	1.2025898	3509.8826
1038.8562	3.0547385	1.2057966	3511.2305
1039.8572	3.0532835	1.2091104	3499.636
1040.8582	3.0562954	1.2120587	3506.05
1041.8591	3.0598688	1.2147387	3500.6101
1042.8601	3.0638041	1.2172928	3504.72
1043.8611	3.068197	1.2196921	3502.5823
1044.8621	3.0686522	1.222677	3504.4766
1045.863	3.0739098	1.2254124	3502.8262
1046.864	3.0750651	1.2283213	3502.9827
1047.865	3.0791156	1.2312948	3503.7722
1048.866	3.0816784	1.2345769	3511.6431
1049.8669	3.0819077	1.2377132	3493.8608
1050.8679	3.0885475	1.2402967	3493.4827
1051.8689	3.0895157	1.242408	3485.0361
1052.8699	3.0938735	1.2445207	3496.616
1053.8708	3.0966754	1.2464359	3497.9524
1054.8718	3.099684	1.2486088	3496.5991
1055.8728	3.0997458	1.2515936	3496.4934
1056.8738	3.1058159	1.2543925	3488.0447
1057.8748	3.1066337	1.2566901	3495.5127
1058.8757	3.1103556	1.2595875	3493.9536
1059.8767	3.1152856	1.2627825	3493.9775
1060.8777	3.1174159	1.2662586	3489.8203
1061.8787	3.1227901	1.269441	3492.2693
1062.8796	3.1224442	1.2724377	3485.8777
1063.8806	3.1274104	1.2748456	3479.123
1064.8816	3.1256347	1.2774036	3487.6011
1065.8826	3.1321995	1.2804155	3485.1118
1066.8835	3.1341317	1.2831359	3483.4392
1067.8845	3.1379762	1.2862468	3483.2778
1068.8855	3.1402934	1.2891525	3481.8772
1069.8865	3.1427848	1.2923726	3482.6284
1070.8875	3.1449618	1.2951676	3479.5737
1071.8884	3.1523423	1.2977659	3476.283
1072.8894	3.1541207	1.3006766	3477.4958
1073.8904	3.1551912	1.3037038	3471.6892
1074.8914	3.1602583	1.3067001	3489.8284
1075.8923	3.164278	1.3097457	3474.2791
1076.8933	3.1658862	1.3124152	3475.0972
1077.8943	3.1679704	1.3153546	3470.9736
1078.8953	3.1721056	1.3179412	3473.5566
1079.8962	3.1754165	1.3206233	3471.4385
1080.8972	3.1763611	1.3233844	3476.2461
1081.8982	3.1826684	1.3262593	3471.0947
1082.8992	3.1843946	1.3291037	3461.749
1083.9001	3.1855383	1.3321773	3465.043
1084.9011	3.1893075	1.3352646	3463.3394
1085.9021	3.1926041	1.3381362	3464.8406
1086.9031	3.1969371	1.34094	3462.3142
1087.9041	3.1985188	1.3439169	3463.6365
1088.905	3.200439	1.3469645	3459.1375
1089.906	3.205158	1.349876	3459.3647
1090.907	3.2070179	1.3531919	3457.8691
1091.908	3.212481	1.3563706	3455.1501
1092.9089	3.2115934	1.3594271	3455.2964
1093.9099	3.2166905	1.3624096	3456.9106
1094.9109	3.2175281	1.3656223	3456.843
1095.9119	3.2249906	1.3686727	3449.8875
1096.9128	3.227669	1.3716871	3452.2065
1097.9138	3.2286565	1.3751674	3449.6277
1098.9148	3.2307243	1.3784183	3439.3782
1099.9158	3.2322626	1.3812072	3440.689
1100.9167	3.2391028	1.3838807	3441.5403
1101.9177	3.2416797	1.3865777	3441.981
1102.9187	3.242857	1.3897662	3443.1997
1103.9197	3.2506475	1.3927909	3438.4709
1104.9207	3.2491341	1.3954768	3428.7288
1105.9216	3.251677	1.3976754	3426.9912
1106.9226	3.2560494	1.4009416	3439.7122
1107.9236	3.2569373	1.4039499	3426.3862
1108.9246	3.2631252	1.4071562	3428.7437
1109.9255	3.265492	1.410395	3426.9314
1110.9265	3.2662735	1.4134483	3426.6018
1111.9275	3.2711856	1.4166881	3420.6116
1112.9285	3.2720807	1.4200091	3419.3169
1113.9294	3.2785265	1.4225613	3417.3357
1114.9304	3.2828839	1.4255005	3422.3801
1115.9314	3.2825561	1.4290891	3414.2336
1116.9324	3.288166	1.4320514	3417.0017
1117.9333	3.2877297	1.435406	3408.7021
1118.9343	3.2938254	1.4383864	3409.7046
1119.9353	3.2953954	1.441346	3404.8955
1120.9363	3.2974927	1.444164	3405.448
1121.9373	3.3029852	1.4473178	3404.3423
1122.9382	3.3035662	1.4503052	3397.4775
1123.9392	3.30439	1.4528623	3392.1191
1124.9402	3.3103745	1.455464	3403.8455
1125.9412	3.3116643	1.4590869	3395.2876
1126.9421	3.3124819	1.4623021	3393.949
1127.9431	3.3196347	1.4658809	3391.1169
1128.9441	3.3233924	1.4691201	3385.3442
1129.9451	3.3246765	1.4727386	3390.0884
1130.946	3.3291149	1.4767735	3386.4783
1131.947	3.3333104	1.4803933	3381.7595
1132.948	3.3348622	1.4836609	3377.0974
1133.949	3.3381836	1.4865422	3375.2773
1134.95	3.3391511	1.4898437	3371.8865
1135.9509	3.3437502	1.4930416	3369.6919
1136.9519	3.3457797	1.4964242	3373.7163
1137.9529	3.3489101	1.4997169	3357.1523
1138.9539	3.3539603	1.5024706	3361.3669
1139.9548	3.3547096	1.5052863	3358.8677
1140.9558	3.3565245	1.508086	3358.7375
1141.9568	3.3576376	1.5115747	3356.6829
1142.9578	3.3617184	1.5149711	3352.9163
1143.9587	3.3661127	1.5181345	3351.3594
1144.9597	3.3726013	1.5211852	3346.76
1145.9607	3.3746152	1.5238123	3345.4102
1146.9617	3.3742354	1.526619	3342.8218
1147.9626	3.379529	1.5297763	3337.2339
1148.9636	3.3799014	1.5326722	3335.209
1149.9646	3.3853965	1.5359432	3334.1572
1150.9656	3.3880556	1.5392005	3328.6006
1151.9666	3.3887527	1.5428175	3329.4568
1152.9675	3.3935301	1.5465609	3320.4146
1153.9685	3.3991563	1.5496315	3320.5645
1154.9695	3.3989997	1.5529416	3313.8552
1155.9705	3.4014742	1.5561596	3315.5938
1156.9714	3.4050698	1.5591505	3307.4761
1157.9724	3.4078603	1.5626236	3309.8157
1158.9734	3.4109077	1.5659426	3303.5708
1159.9744	3.4127154	1.5694615	3299.9785
1160.9753	3.4171686	1.5735081	3300.6689
1161.9763	3.4192412	1.5774041	3292.7302
1162.9773	3.4228032	1.5810605	3288.6665
1163.9783	3.4251649	1.5840604	3286.9028
1164.9792	3.4319775	1.5872118	3283.0742
1165.9802	3.4301491	1.5902535	3272.7456
1166.9812	3.4368594	1.5935252	3279.5374
1167.9822	3.4419851	1.5975379	3275.6118
1168.9832	3.4430921	1.6009949	3266.551
1169.9841	3.4453144	1.6047072	3255.0073
1170.9851	3.4459608	1.6076684	3252.6384
1171.9861	3.4521194	1.6113174	3250.3884
1172.9871	3.454093	1.615026	3256.3242
1173.988	3.455416	1.6187205	3235.4631
1174.989	3.459866	1.6223147	3239.519
1175.99	3.4642093	1.626314	3234.1318
1176.991	3.467942	1.6295714	3227.2188
1177.9919	3.4693046	1.6332475	3224.4932
1178.9929	3.4730999	1.6372211	3211.488
1179.9939	3.4753573	1.6400837	3203.5974
1180.9949	3.4795797	1.6427091	3198.5313
1181.9958	3.4814	1.6455709	3189.0603
1182.9968	3.4823084	1.6488941	3177.5613
1183.9978	3.4853692	1.6539789	3160.2791
1184.9988	3.4926231	1.6596819	3117.5544
1185.9998	3.49578	1.6698987	3045.6838
1186.2	3.4964323	1.6780964	2967.0198