File: datasets/al_6061_comp/csv/T_020_A_1.csv
Time,Strain(%),Stress(MPa),Temp(C),SR(%/s),Si(%),Fe(%),Cu(%),Mn(%),Mg(%),Cr(%),Zn(%),Ti(%)
0.0,0.0001053895395712,20.3206153297892,20.0,8.333333333333333e-05,0.56,0.23,0.18,0.07,0.86,0.06,0.02,0.01
0.7920876341616001,0.000171396842418,26.1785984029967,20.0,8.333333333333333e-05,0.56,0.23,0.18,0.07,0.86,0.06,0.02,0.01
1.6355163263904,0.0002416825667704,32.2167871641982,20.0,8.333333333333333e-05,0.56,0.23,0.18,0.07,0.86,0.06,0.02,0.01
2.5477873237032003,0.0003177051498798,38.4074800194281,20.0,8.333333333333333e-05,0.56,0.23,0.18,0.07,0.86,0.06,0.02,0.01
3.5628736549884006,0.0004022956774869,44.7015935993965,20.0,8.333333333333333e-05,0.56,0.23,0.18,0.07,0.86,0.06,0.02,0.01
4.6236716732652,0.0004906955123433,51.1080901543093,20.0,8.333333333333333e-05,0.56,0.23,0.18,0.07,0.86,0.06,0.02,0.01
5.770579275511199,0.0005862711458638,57.6609020726713,20.0,8.333333333333333e-05,0.56,0.23,0.18,0.07,0.86,0.06,0.02,0.01
6.9397788525204,0.0006837044439479,64.2870922813771,20.0,8.333333333333333e-05,0.56,0.23,0.18,0.07,0.86,0.06,0.02,0.01
8.0816803869804,0.0007788629051529,71.0139967033423,20.0,8.333333333333333e-05,0.56,0.23,0.18,0.07,0.86,0.06,0.02,0.01
9.213715292916,0.0008731991473142,77.73565003267,20.0,8.333333333333333e-05,0.56,0.23,0.18,0.07,0.86,0.06,0.02,0.01
10.480568292238798,0.0009787702305911,84.4437455056709,20.0,8.333333333333333e-05,0.56,0.23,0.18,0.07,0.86,0.06,0.02,0.01
11.7193283125872,0.0010820002322868,91.0933893209124,20.0,8.333333333333333e-05,0.56,0.23,0.18,0.07,0.86,0.06,0.02,0.01
12.907268153322,0.0011809952190147,97.7559440054167,20.0,8.333333333333333e-05,0.56,0.23,0.18,0.07,0.86,0.06,0.02,0.01
14.131560190189202,0.0012830195554203,104.302857174281,20.0,8.333333333333333e-05,0.56,0.23,0.18,0.07,0.86,0.06,0.02,0.01
15.369829476069604,0.001386208662577,110.904289094843,20.0,8.333333333333333e-05,0.56,0.23,0.18,0.07,0.86,0.06,0.02,0.01
16.581780149196,0.0014872045520042,117.438193694686,20.0,8.333333333333333e-05,0.56,0.23,0.18,0.07,0.86,0.06,0.02,0.01
17.827396206632404,0.0015910058901239,123.948222993824,20.0,8.333333333333333e-05,0.56,0.23,0.18,0.07,0.86,0.06,0.02,0.01
19.021237520368803,0.0016904926662686,130.455263987453,20.0,8.333333333333333e-05,0.56,0.23,0.18,0.07,0.86,0.06,0.02,0.01
20.202980560836004,0.0017889712529742,136.837755118448,20.0,8.333333333333333e-05,0.56,0.23,0.18,0.07,0.86,0.06,0.02,0.01
21.4712798989356,0.0018946628644825,143.137784939564,20.0,8.333333333333333e-05,0.56,0.23,0.18,0.07,0.86,0.06,0.02,0.01
22.625851159027203,0.0019908771361568,149.27407450921,20.0,8.333333333333333e-05,0.56,0.23,0.18,0.07,0.86,0.06,0.02,0.01
23.828300429196,0.0020910812420042,155.377212411562,20.0,8.333333333333333e-05,0.56,0.23,0.18,0.07,0.86,0.06,0.02,0.01
25.022938800145205,0.0021906344395833,161.398391479763,20.0,8.333333333333333e-05,0.56,0.23,0.18,0.07,0.86,0.06,0.02,0.01
26.2541814971328,0.0022932379976656,167.370173457097,20.0,8.333333333333333e-05,0.56,0.23,0.18,0.07,0.86,0.06,0.02,0.01
27.5458768285308,0.0024008792752821,173.254223154617,20.0,8.333333333333333e-05,0.56,0.23,0.18,0.07,0.86,0.06,0.02,0.01
28.7564546064288,0.0025017607567736,179.005689474721,20.0,8.333333333333333e-05,0.56,0.23,0.18,0.07,0.86,0.06,0.02,0.01
30.0133451770332,0.0026065016376573,184.745757016066,20.0,8.333333333333333e-05,0.56,0.23,0.18,0.07,0.86,0.06,0.02,0.01
31.202902326781203,0.0027056314001363,190.392481500369,20.0,8.333333333333333e-05,0.56,0.23,0.18,0.07,0.86,0.06,0.02,0.01
32.4281666445996,0.0028077367599545,196.012135842829,20.0,8.333333333333333e-05,0.56,0.23,0.18,0.07,0.86,0.06,0.02,0.01
33.6956900381376,0.002913363709416,201.540058626422,20.0,8.333333333333333e-05,0.56,0.23,0.18,0.07,0.86,0.06,0.02,0.01
34.9520276888124,0.0030180585136389,206.957297758593,20.0,8.333333333333333e-05,0.56,0.23,0.18,0.07,0.86,0.06,0.02,0.01
36.2696994039852,0.0031278644899033,212.23020727269,20.0,8.333333333333333e-05,0.56,0.23,0.18,0.07,0.86,0.06,0.02,0.01
37.6080342956376,0.003239392397541,217.393985588057,20.0,8.333333333333333e-05,0.56,0.23,0.18,0.07,0.86,0.06,0.02,0.01
39.0567787223844,0.0033601210997699,222.375665992428,20.0,8.333333333333333e-05,0.56,0.23,0.18,0.07,0.86,0.06,0.02,0.01
40.6227521196588,0.0034906188828761,227.247203390896,20.0,8.333333333333333e-05,0.56,0.23,0.18,0.07,0.86,0.06,0.02,0.01
42.3686818634052,0.0036361130281883,231.966383790584,20.0,8.333333333333333e-05,0.56,0.23,0.18,0.07,0.86,0.06,0.02,0.01
44.490436740594,0.0038129259346207,236.475107110724,20.0,8.333333333333333e-05,0.56,0.23,0.18,0.07,0.86,0.06,0.02,0.01
47.08664677331161,0.0040292767706805,240.72701363776,20.0,8.333333333333333e-05,0.56,0.23,0.18,0.07,0.86,0.06,0.02,0.01
50.296236190098,0.0042967425554127,244.468177731051,20.0,8.333333333333333e-05,0.56,0.23,0.18,0.07,0.86,0.06,0.02,0.01
54.0278370423888,0.0046077092931036,247.490584501575,20.0,8.333333333333333e-05,0.56,0.23,0.18,0.07,0.86,0.06,0.02,0.01
58.0400359634088,0.0049420592031886,249.695010995204,20.0,8.333333333333333e-05,0.56,0.23,0.18,0.07,0.86,0.06,0.02,0.01
62.2622876403012,0.0052939135095963,251.142040420514,20.0,8.333333333333333e-05,0.56,0.23,0.18,0.07,0.86,0.06,0.02,0.01
66.5675984098944,0.0056526894070624,252.060041828653,20.0,8.333333333333333e-05,0.56,0.23,0.18,0.07,0.86,0.06,0.02,0.01
70.9468131935424,0.0060176239723664,252.686637984363,20.0,8.333333333333333e-05,0.56,0.23,0.18,0.07,0.86,0.06,0.02,0.01
75.4412425529856,0.00639215975232,253.154021380283,20.0,8.333333333333333e-05,0.56,0.23,0.18,0.07,0.86,0.06,0.02,0.01
79.8662034893328,0.0067609064970156,253.544474174261,20.0,8.333333333333333e-05,0.56,0.23,0.18,0.07,0.86,0.06,0.02,0.01
84.3444464094576,0.007134093407026,253.869082530057,20.0,8.333333333333333e-05,0.56,0.23,0.18,0.07,0.86,0.06,0.02,0.01
88.90715416377961,0.0075143190532195,254.138325060819,20.0,8.333333333333333e-05,0.56,0.23,0.18,0.07,0.86,0.06,0.02,0.01
93.5127273955224,0.0078981168225314,254.385019381995,20.0,8.333333333333333e-05,0.56,0.23,0.18,0.07,0.86,0.06,0.02,0.01
98.1208255531056,0.00828212500233,254.603805876196,20.0,8.333333333333333e-05,0.56,0.23,0.18,0.07,0.86,0.06,0.02,0.01
102.6556758834504,0.0086600291965254,254.833253824579,20.0,8.333333333333333e-05,0.56,0.23,0.18,0.07,0.86,0.06,0.02,0.01
107.0887193808816,0.009029449487978,255.040187824702,20.0,8.333333333333333e-05,0.56,0.23,0.18,0.07,0.86,0.06,0.02,0.01
111.607446492162,0.0094060100805847,255.254446224687,20.0,8.333333333333333e-05,0.56,0.23,0.18,0.07,0.86,0.06,0.02,0.01
116.095976839746,0.0097800542762167,255.438973072396,20.0,8.333333333333333e-05,0.56,0.23,0.18,0.07,0.86,0.06,0.02,0.01
120.6195333608796,0.0101570173196445,255.65788281013,20.0,8.333333333333333e-05,0.56,0.23,0.18,0.07,0.86,0.06,0.02,0.01
125.1698131891236,0.0105362073053315,255.862738007872,20.0,8.333333333333333e-05,0.56,0.23,0.18,0.07,0.86,0.06,0.02,0.01
129.67609372664162,0.010911730683458,256.068549601226,20.0,8.333333333333333e-05,0.56,0.23,0.18,0.07,0.86,0.06,0.02,0.01
134.265362562282,0.0112941697530947,256.262512187711,20.0,8.333333333333333e-05,0.56,0.23,0.18,0.07,0.86,0.06,0.02,0.01
138.7426933503288,0.0116672806520986,256.432719718654,20.0,8.333333333333333e-05,0.56,0.23,0.18,0.07,0.86,0.06,0.02,0.01
143.17502945106602,0.0120366419938267,256.630737661954,20.0,8.333333333333333e-05,0.56,0.23,0.18,0.07,0.86,0.06,0.02,0.01
147.59214887409362,0.012404735279079,256.826758740541,20.0,8.333333333333333e-05,0.56,0.23,0.18,0.07,0.86,0.06,0.02,0.01
151.94696183149202,0.0127676363588622,257.025396623305,20.0,8.333333333333333e-05,0.56,0.23,0.18,0.07,0.86,0.06,0.02,0.01
156.38334901799402,0.0131373352910707,257.222409737787,20.0,8.333333333333333e-05,0.56,0.23,0.18,0.07,0.86,0.06,0.02,0.01
160.77820947482283,0.0135035736624731,257.41071597433,20.0,8.333333333333333e-05,0.56,0.23,0.18,0.07,0.86,0.06,0.02,0.01
165.1684875440544,0.0138694301682424,257.588548040973,20.0,8.333333333333333e-05,0.56,0.23,0.18,0.07,0.86,0.06,0.02,0.01
169.4646398404248,0.0142274428596066,257.786067729971,20.0,8.333333333333333e-05,0.56,0.23,0.18,0.07,0.86,0.06,0.02,0.01
173.8060484400708,0.0145892269095771,257.989277202691,20.0,8.333333333333333e-05,0.56,0.23,0.18,0.07,0.86,0.06,0.02,0.01
178.1045647638084,0.0149474366032219,258.196533114792,20.0,8.333333333333333e-05,0.56,0.23,0.18,0.07,0.86,0.06,0.02,0.01
182.3808748029984,0.0153037957731544,258.41342108313,20.0,8.333333333333333e-05,0.56,0.23,0.18,0.07,0.86,0.06,0.02,0.01
186.6752781716184,0.0156616627205394,258.581805349499,20.0,8.333333333333333e-05,0.56,0.23,0.18,0.07,0.86,0.06,0.02,0.01
190.90366084386363,0.0160140279432265,258.752776281599,20.0,8.333333333333333e-05,0.56,0.23,0.18,0.07,0.86,0.06,0.02,0.01
195.0649526702244,0.0163608022620899,258.959082836953,20.0,8.333333333333333e-05,0.56,0.23,0.18,0.07,0.86,0.06,0.02,0.01
199.22462131783684,0.0167074413160576,259.136726494583,20.0,8.333333333333333e-05,0.56,0.23,0.18,0.07,0.86,0.06,0.02,0.01
203.3708558190372,0.0170529608578243,259.310909911467,20.0,8.333333333333333e-05,0.56,0.23,0.18,0.07,0.86,0.06,0.02,0.01
207.6005424409488,0.0174054347429836,259.495027662,20.0,8.333333333333333e-05,0.56,0.23,0.18,0.07,0.86,0.06,0.02,0.01
211.8699885105012,0.0177612219154463,259.710626764444,20.0,8.333333333333333e-05,0.56,0.23,0.18,0.07,0.86,0.06,0.02,0.01
216.128225495334,0.0181160749975157,259.916102447407,20.0,8.333333333333333e-05,0.56,0.23,0.18,0.07,0.86,0.06,0.02,0.01
220.3523059475796,0.0184680817018695,260.096431690738,20.0,8.333333333333333e-05,0.56,0.23,0.18,0.07,0.86,0.06,0.02,0.01
224.5606549082832,0.0188187774485948,260.263763776694,20.0,8.333333333333333e-05,0.56,0.23,0.18,0.07,0.86,0.06,0.02,0.01
228.77834167506845,0.0191702513458269,260.428201715826,20.0,8.333333333333333e-05,0.56,0.23,0.18,0.07,0.86,0.06,0.02,0.01
233.030404102632,0.0195245898814572,260.630854188141,20.0,8.333333333333333e-05,0.56,0.23,0.18,0.07,0.86,0.06,0.02,0.01
237.25649499569283,0.0198767641225456,260.811474620434,20.0,8.333333333333333e-05,0.56,0.23,0.18,0.07,0.86,0.06,0.02,0.01
241.4907509015424,0.0202296187813664,261.010385152317,20.0,8.333333333333333e-05,0.56,0.23,0.18,0.07,0.86,0.06,0.02,0.01
245.6335735174068,0.0205748539993551,261.190890919789,20.0,8.333333333333333e-05,0.56,0.23,0.18,0.07,0.86,0.06,0.02,0.01
249.84859262066283,0.0209261055912931,261.370827695693,20.0,8.333333333333333e-05,0.56,0.23,0.18,0.07,0.86,0.06,0.02,0.01
254.0343275812704,0.0212749168380104,261.560305747623,20.0,8.333333333333333e-05,0.56,0.23,0.18,0.07,0.86,0.06,0.02,0.01
258.1552528996152,0.0216183272812058,261.738881865241,20.0,8.333333333333333e-05,0.56,0.23,0.18,0.07,0.86,0.06,0.02,0.01
262.3237701579624,0.0219657037194014,261.899072490684,20.0,8.333333333333333e-05,0.56,0.23,0.18,0.07,0.86,0.06,0.02,0.01
266.3870934119964,0.0223043139905709,262.094456480775,20.0,8.333333333333333e-05,0.56,0.23,0.18,0.07,0.86,0.06,0.02,0.01
270.5128600862652,0.0226481278800933,262.291544385687,20.0,8.333333333333333e-05,0.56,0.23,0.18,0.07,0.86,0.06,0.02,0.01
274.547007919314,0.0229843068661807,262.444581039581,20.0,8.333333333333333e-05,0.56,0.23,0.18,0.07,0.86,0.06,0.02,0.01
278.6426020854504,0.0233256063800254,262.630936441886,20.0,8.333333333333333e-05,0.56,0.23,0.18,0.07,0.86,0.06,0.02,0.01
282.6904891150284,0.0236629302991569,262.800461448933,20.0,8.333333333333333e-05,0.56,0.23,0.18,0.07,0.86,0.06,0.02,0.01
286.78111602646203,0.0240038158751097,262.971373870042,20.0,8.333333333333333e-05,0.56,0.23,0.18,0.07,0.86,0.06,0.02,0.01
290.9240425952004,0.0243490597558379,263.159384322672,20.0,8.333333333333333e-05,0.56,0.23,0.18,0.07,0.86,0.06,0.02,0.01
295.0043643752652,0.0246890865708433,263.35448284001,20.0,8.333333333333333e-05,0.56,0.23,0.18,0.07,0.86,0.06,0.02,0.01
299.062253225364,0.0250272439750182,263.538863158676,20.0,8.333333333333333e-05,0.56,0.23,0.18,0.07,0.86,0.06,0.02,0.01
303.1815337674828,0.0253705173535281,263.697905955278,20.0,8.333333333333333e-05,0.56,0.23,0.18,0.07,0.86,0.06,0.02,0.01
307.2640419394332,0.0257107263678573,263.870323413208,20.0,8.333333333333333e-05,0.56,0.23,0.18,0.07,0.86,0.06,0.02,0.01
311.4049943022468,0.0260558057314251,264.041760275167,20.0,8.333333333333333e-05,0.56,0.23,0.18,0.07,0.86,0.06,0.02,0.01
315.3792114697428,0.0263869904953831,264.215393050577,20.0,8.333333333333333e-05,0.56,0.23,0.18,0.07,0.86,0.06,0.02,0.01
319.360687374156,0.0267187801540842,264.370724003471,20.0,8.333333333333333e-05,0.56,0.23,0.18,0.07,0.86,0.06,0.02,0.01
323.3278969540416,0.027049380952408,264.560386092373,20.0,8.333333333333333e-05,0.56,0.23,0.18,0.07,0.86,0.06,0.02,0.01
327.3965577243108,0.0273884360165971,264.748313324246,20.0,8.333333333333333e-05,0.56,0.23,0.18,0.07,0.86,0.06,0.02,0.01
331.42333062786963,0.027724000425227,264.930577488948,20.0,8.333333333333333e-05,0.56,0.23,0.18,0.07,0.86,0.06,0.02,0.01
335.5218806422896,0.028065546259762,265.118230378913,20.0,8.333333333333333e-05,0.56,0.23,0.18,0.07,0.86,0.06,0.02,0.01
339.6028578537516,0.0284056276940505,265.24544077683,20.0,8.333333333333333e-05,0.56,0.23,0.18,0.07,0.86,0.06,0.02,0.01
343.640891017986,0.0287421304577367,265.400091692061,20.0,8.333333333333333e-05,0.56,0.23,0.18,0.07,0.86,0.06,0.02,0.01
347.7066658640616,0.029080945028243,265.572445411373,20.0,8.333333333333333e-05,0.56,0.23,0.18,0.07,0.86,0.06,0.02,0.01
351.6952529338788,0.0294133272840611,265.753415848324,20.0,8.333333333333333e-05,0.56,0.23,0.18,0.07,0.86,0.06,0.02,0.01
355.6439447555448,0.0297423849358666,265.892076311165,20.0,8.333333333333333e-05,0.56,0.23,0.18,0.07,0.86,0.06,0.02,0.01
359.6687965222164,0.0300777892497559,266.059178183003,20.0,8.333333333333333e-05,0.56,0.23,0.18,0.07,0.86,0.06,0.02,0.01
363.6568112710128,0.0304101238121556,266.223108987912,20.0,8.333333333333333e-05,0.56,0.23,0.18,0.07,0.86,0.06,0.02,0.01
367.6435141743588,0.0307423490541011,266.37487286201,20.0,8.333333333333333e-05,0.56,0.23,0.18,0.07,0.86,0.06,0.02,0.01
371.7822758580876,0.0310872458610785,266.528031180721,20.0,8.333333333333333e-05,0.56,0.23,0.18,0.07,0.86,0.06,0.02,0.01
375.8158305562032,0.0314233754192548,266.686465806086,20.0,8.333333333333333e-05,0.56,0.23,0.18,0.07,0.86,0.06,0.02,0.01
379.91354541933,0.0317648516578487,266.859031553115,20.0,8.333333333333333e-05,0.56,0.23,0.18,0.07,0.86,0.06,0.02,0.01
383.9950566376152,0.0321049775927058,267.019265591174,20.0,8.333333333333333e-05,0.56,0.23,0.18,0.07,0.86,0.06,0.02,0.01
387.9735294615168,0.0324365169946976,267.184617807775,20.0,8.333333333333333e-05,0.56,0.23,0.18,0.07,0.86,0.06,0.02,0.01
392.0533041530028,0.0327764982189881,267.328515423906,20.0,8.333333333333333e-05,0.56,0.23,0.18,0.07,0.86,0.06,0.02,0.01
396.1040966184924,0.0331140642577789,267.481489446393,20.0,8.333333333333333e-05,0.56,0.23,0.18,0.07,0.86,0.06,0.02,0.01
400.1037479106996,0.0334473685321295,267.628617444361,20.0,8.333333333333333e-05,0.56,0.23,0.18,0.07,0.86,0.06,0.02,0.01
404.1221004397356,0.0337822312428825,267.753454034876,20.0,8.333333333333333e-05,0.56,0.23,0.18,0.07,0.86,0.06,0.02,0.01
408.15022139059073,0.0341179079887871,267.905752666053,20.0,8.333333333333333e-05,0.56,0.23,0.18,0.07,0.86,0.06,0.02,0.01
412.1817857429208,0.0344538716848146,268.063974246176,20.0,8.333333333333333e-05,0.56,0.23,0.18,0.07,0.86,0.06,0.02,0.01
416.2437529004088,0.0347923689479386,268.23522497024,20.0,8.333333333333333e-05,0.56,0.23,0.18,0.07,0.86,0.06,0.02,0.01
420.3811013854116,0.0351371479883555,268.375466481871,20.0,8.333333333333333e-05,0.56,0.23,0.18,0.07,0.86,0.06,0.02,0.01
424.3927790845404,0.0354714544632829,268.5050460706,20.0,8.333333333333333e-05,0.56,0.23,0.18,0.07,0.86,0.06,0.02,0.01
428.3823373582032,0.0358039176527548,268.626983140469,20.0,8.333333333333333e-05,0.56,0.23,0.18,0.07,0.86,0.06,0.02,0.01
432.2890273765788,0.0361294751542861,268.776131576425,20.0,8.333333333333333e-05,0.56,0.23,0.18,0.07,0.86,0.06,0.02,0.01
436.199109099954,0.0364553152979007,268.903518273461,20.0,8.333333333333333e-05,0.56,0.23,0.18,0.07,0.86,0.06,0.02,0.01
440.1679950094392,0.0367860557903578,269.060261266801,20.0,8.333333333333333e-05,0.56,0.23,0.18,0.07,0.86,0.06,0.02,0.01
444.1399339483248,0.0371170507019316,269.18003751332,20.0,8.333333333333333e-05,0.56,0.23,0.18,0.07,0.86,0.06,0.02,0.01
448.1615943283584,0.0374521890669344,269.328715353012,20.0,8.333333333333333e-05,0.56,0.23,0.18,0.07,0.86,0.06,0.02,0.01
452.178230332884,0.0377869087339782,269.501213618814,20.0,8.333333333333333e-05,0.56,0.23,0.18,0.07,0.86,0.06,0.02,0.01
456.2108837026884,0.0381229631814619,269.603591204504,20.0,8.333333333333333e-05,0.56,0.23,0.18,0.07,0.86,0.06,0.02,0.01
460.2435791304216,0.038459021133773,269.762752717891,20.0,8.333333333333333e-05,0.56,0.23,0.18,0.07,0.86,0.06,0.02,0.01
464.2927167411048,0.0387964492679966,269.871507058427,20.0,8.333333333333333e-05,0.56,0.23,0.18,0.07,0.86,0.06,0.02,0.01
468.33299276769,0.0391331389368787,270.015086027649,20.0,8.333333333333333e-05,0.56,0.23,0.18,0.07,0.86,0.06,0.02,0.01
472.4269776001872,0.0394743043395868,270.173988365094,20.0,8.333333333333333e-05,0.56,0.23,0.18,0.07,0.86,0.06,0.02,0.01
476.5092220311504,0.0398144913755004,270.329281185654,20.0,8.333333333333333e-05,0.56,0.23,0.18,0.07,0.86,0.06,0.02,0.01
480.613896125646,0.0401565475500417,270.464048167392,20.0,8.333333333333333e-05,0.56,0.23,0.18,0.07,0.86,0.06,0.02,0.01
484.6573326898824,0.0404935005970614,270.558617467482,20.0,8.333333333333333e-05,0.56,0.23,0.18,0.07,0.86,0.06,0.02,0.01
488.8195761555072,0.0408403542191968,270.6980790331,20.0,8.333333333333333e-05,0.56,0.23,0.18,0.07,0.86,0.06,0.02,0.01
492.8550606215928,0.0411766445913706,270.806630072131,20.0,8.333333333333333e-05,0.56,0.23,0.18,0.07,0.86,0.06,0.02,0.01
496.925187459282,0.0415158218278447,270.931652720259,20.0,8.333333333333333e-05,0.56,0.23,0.18,0.07,0.86,0.06,0.02,0.01
500.99435648974566,0.04185491924705,271.057599752941,20.0,8.333333333333333e-05,0.56,0.23,0.18,0.07,0.86,0.06,0.02,0.01
505.011567108186,0.0421896867985867,271.187605178598,20.0,8.333333333333333e-05,0.56,0.23,0.18,0.07,0.86,0.06,0.02,0.01
509.040368765484,0.0425254202700282,271.310841946446,20.0,8.333333333333333e-05,0.56,0.23,0.18,0.07,0.86,0.06,0.02,0.01
513.1008544563264,0.0428637940775984,271.417242869388,20.0,8.333333333333333e-05,0.56,0.23,0.18,0.07,0.86,0.06,0.02,0.01
517.088554404732,0.0431961024066322,271.511422421122,20.0,8.333333333333333e-05,0.56,0.23,0.18,0.07,0.86,0.06,0.02,0.01
521.1201246517237,0.0435320665938815,271.640667708084,20.0,8.333333333333333e-05,0.56,0.23,0.18,0.07,0.86,0.06,0.02,0.01
525.1374594580801,0.0438668444944112,271.729087146435,20.0,8.333333333333333e-05,0.56,0.23,0.18,0.07,0.86,0.06,0.02,0.01
529.1005575854197,0.0441971026716895,271.864714930771,20.0,8.333333333333333e-05,0.56,0.23,0.18,0.07,0.86,0.06,0.02,0.01
533.1075036461568,0.0445310148434176,271.947891190444,20.0,8.333333333333333e-05,0.56,0.23,0.18,0.07,0.86,0.06,0.02,0.01
537.112656009888,0.0448647775403952,272.044252860665,20.0,8.333333333333333e-05,0.56,0.23,0.18,0.07,0.86,0.06,0.02,0.01
541.1608953952957,0.0452021308225125,272.182719147185,20.0,8.333333333333333e-05,0.56,0.23,0.18,0.07,0.86,0.06,0.02,0.01
545.2410704955756,0.0455421454142025,272.307706023477,20.0,8.333333333333333e-05,0.56,0.23,0.18,0.07,0.86,0.06,0.02,0.01
549.3341314299672,0.0458832338254018,272.44512900431,20.0,8.333333333333333e-05,0.56,0.23,0.18,0.07,0.86,0.06,0.02,0.01
553.4474605880916,0.0462260112552455,272.533308534382,20.0,8.333333333333333e-05,0.56,0.23,0.18,0.07,0.86,0.06,0.02,0.01
557.5545200608465,0.0465682662113084,272.639422684297,20.0,8.333333333333333e-05,0.56,0.23,0.18,0.07,0.86,0.06,0.02,0.01
561.6283824169873,0.0469077547409868,272.742437828038,20.0,8.333333333333333e-05,0.56,0.23,0.18,0.07,0.86,0.06,0.02,0.01
565.7190822821821,0.0472486463964197,272.871805270183,20.0,8.333333333333333e-05,0.56,0.23,0.18,0.07,0.86,0.06,0.02,0.01
569.8142958981732,0.0475899141977523,272.963859762619,20.0,8.333333333333333e-05,0.56,0.23,0.18,0.07,0.86,0.06,0.02,0.01
573.9435195272521,0.0479340161668422,273.06251262037,20.0,8.333333333333333e-05,0.56,0.23,0.18,0.07,0.86,0.06,0.02,0.01
578.0688393041257,0.048277792814915,273.140547572921,20.0,8.333333333333333e-05,0.56,0.23,0.18,0.07,0.86,0.06,0.02,0.01
582.1922975124085,0.0486214143322719,273.260045716805,20.0,8.333333333333333e-05,0.56,0.23,0.18,0.07,0.86,0.06,0.02,0.01
586.26865113237,0.0489611104672687,273.352207639635,20.0,8.333333333333333e-05,0.56,0.23,0.18,0.07,0.86,0.06,0.02,0.01
590.3510513993892,0.0493013104895203,273.447617228187,20.0,8.333333333333333e-05,0.56,0.23,0.18,0.07,0.86,0.06,0.02,0.01
594.4703530069645,0.0496445856234849,273.51190349722,20.0,8.333333333333333e-05,0.56,0.23,0.18,0.07,0.86,0.06,0.02,0.01
598.5590080101865,0.0499853068737534,273.552670357528,20.0,8.333333333333333e-05,0.56,0.23,0.18,0.07,0.86,0.06,0.02,0.01
602.6596680879109,0.0503270285468971,273.677697876703,20.0,8.333333333333333e-05,0.56,0.23,0.18,0.07,0.86,0.06,0.02,0.01
606.7344301883905,0.0506665920552704,273.738632796364,20.0,8.333333333333333e-05,0.56,0.23,0.18,0.07,0.86,0.06,0.02,0.01
610.8237260241157,0.0510073667082475,273.877155888978,20.0,8.333333333333333e-05,0.56,0.23,0.18,0.07,0.86,0.06,0.02,0.01
614.9862706611349,0.0513542454279991,273.961445434619,20.0,8.333333333333333e-05,0.56,0.23,0.18,0.07,0.86,0.06,0.02,0.01
619.1188124813592,0.0516986239130178,274.040256611816,20.0,8.333333333333333e-05,0.56,0.23,0.18,0.07,0.86,0.06,0.02,0.01
623.2588595856324,0.0520436278383739,274.15133154655,20.0,8.333333333333333e-05,0.56,0.23,0.18,0.07,0.86,0.06,0.02,0.01
627.4739774194237,0.0523948876578565,274.219497964353,20.0,8.333333333333333e-05,0.56,0.23,0.18,0.07,0.86,0.06,0.02,0.01
631.5823719512041,0.0527372538688382,274.294186302116,20.0,8.333333333333333e-05,0.56,0.23,0.18,0.07,0.86,0.06,0.02,0.01
635.6909290555585,0.0530796336275344,274.380515572281,20.0,8.333333333333333e-05,0.56,0.23,0.18,0.07,0.86,0.06,0.02,0.01
639.7480371517033,0.0534177259688798,274.453131128538,20.0,8.333333333333333e-05,0.56,0.23,0.18,0.07,0.86,0.06,0.02,0.01
643.7903555187866,0.0537545858328034,274.519398236435,20.0,8.333333333333333e-05,0.56,0.23,0.18,0.07,0.86,0.06,0.02,0.01
647.880621368178,0.0540954413202527,274.60026224823,20.0,8.333333333333333e-05,0.56,0.23,0.18,0.07,0.86,0.06,0.02,0.01
651.9994709875057,0.05443867878853,274.657335817416,20.0,8.333333333333333e-05,0.56,0.23,0.18,0.07,0.86,0.06,0.02,0.01
656.2002497814001,0.0547887436880212,274.743891308798,20.0,8.333333333333333e-05,0.56,0.23,0.18,0.07,0.86,0.06,0.02,0.01
660.4722255459612,0.0551447416684013,274.848513877143,20.0,8.333333333333333e-05,0.56,0.23,0.18,0.07,0.86,0.06,0.02,0.01
664.6976961300061,0.0554968642170717,274.91176489146,20.0,8.333333333333333e-05,0.56,0.23,0.18,0.07,0.86,0.06,0.02,0.01
668.9746258843633,0.0558532750299348,274.998867956068,20.0,8.333333333333333e-05,0.56,0.23,0.18,0.07,0.86,0.06,0.02,0.01
673.1471747044657,0.05620098743161,275.055443580075,20.0,8.333333333333333e-05,0.56,0.23,0.18,0.07,0.86,0.06,0.02,0.01
677.312755138788,0.0565481191344702,275.137310871367,20.0,8.333333333333333e-05,0.56,0.23,0.18,0.07,0.86,0.06,0.02,0.01
681.4328036211457,0.056891456508,275.157779471739,20.0,8.333333333333333e-05,0.56,0.23,0.18,0.07,0.86,0.06,0.02,0.01
685.5653409440185,0.0572358346182394,275.23298354125,20.0,8.333333333333333e-05,0.56,0.23,0.18,0.07,0.86,0.06,0.02,0.01
689.7834275010013,0.0575873418313213,275.271400193469,20.0,8.333333333333333e-05,0.56,0.23,0.18,0.07,0.86,0.06,0.02,0.01
693.9882138865273,0.0579377406967818,275.367587032372,20.0,8.333333333333333e-05,0.56,0.23,0.18,0.07,0.86,0.06,0.02,0.01
698.2433247999289,0.0582923332728986,275.44032056208,20.0,8.333333333333333e-05,0.56,0.23,0.18,0.07,0.86,0.06,0.02,0.01
702.4375179123973,0.0586418493656043,275.499603000282,20.0,8.333333333333333e-05,0.56,0.23,0.18,0.07,0.86,0.06,0.02,0.01
706.6572205413685,0.0589934912513519,275.578629748226,20.0,8.333333333333333e-05,0.56,0.23,0.18,0.07,0.86,0.06,0.02,0.01
710.8760806632337,0.059345062928174,275.634851786292,20.0,8.333333333333333e-05,0.56,0.23,0.18,0.07,0.86,0.06,0.02,0.01
715.1235792566629,0.0596990211442931,275.690360655902,20.0,8.333333333333333e-05,0.56,0.23,0.18,0.07,0.86,0.06,0.02,0.01
719.3903406791412,0.0600545845961663,275.729601827452,20.0,8.333333333333333e-05,0.56,0.23,0.18,0.07,0.86,0.06,0.02,0.01
723.6598422787237,0.0604103763961315,275.766737004595,20.0,8.333333333333333e-05,0.56,0.23,0.18,0.07,0.86,0.06,0.02,0.01
727.9061767983745,0.0607642376061024,275.832892951189,20.0,8.333333333333333e-05,0.56,0.23,0.18,0.07,0.86,0.06,0.02,0.01
732.1100170741933,0.0611145576290873,275.902692307861,20.0,8.333333333333333e-05,0.56,0.23,0.18,0.07,0.86,0.06,0.02,0.01
736.2530324981605,0.0614598089144179,275.975407339203,20.0,8.333333333333333e-05,0.56,0.23,0.18,0.07,0.86,0.06,0.02,0.01
740.4887008192009,0.0618127812745046,275.998251315907,20.0,8.333333333333333e-05,0.56,0.23,0.18,0.07,0.86,0.06,0.02,0.01
744.774112305894,0.0621698988983957,276.058954791969,20.0,8.333333333333333e-05,0.56,0.23,0.18,0.07,0.86,0.06,0.02,0.01
749.0293635791664,0.0625245031711684,276.092055462534,20.0,8.333333333333333e-05,0.56,0.23,0.18,0.07,0.86,0.06,0.02,0.01
753.3106542585265,0.0628812773944484,276.162416358674,20.0,8.333333333333333e-05,0.56,0.23,0.18,0.07,0.86,0.06,0.02,0.01
757.4661075020017,0.063227565164738,276.209990296058,20.0,8.333333333333333e-05,0.56,0.23,0.18,0.07,0.86,0.06,0.02,0.01
761.6767247782813,0.0635784499377613,276.245693792125,20.0,8.333333333333333e-05,0.56,0.23,0.18,0.07,0.86,0.06,0.02,0.01
765.8614508053824,0.0639271771066864,276.263418965157,20.0,8.333333333333333e-05,0.56,0.23,0.18,0.07,0.86,0.06,0.02,0.01
770.1186574928772,0.0642819443306443,276.329214974592,20.0,8.333333333333333e-05,0.56,0.23,0.18,0.07,0.86,0.06,0.02,0.01
774.4134088764025,0.0646398402792714,276.364225385266,20.0,8.333333333333333e-05,0.56,0.23,0.18,0.07,0.86,0.06,0.02,0.01
778.6886432164044,0.0649961098076049,276.443300633861,20.0,8.333333333333333e-05,0.56,0.23,0.18,0.07,0.86,0.06,0.02,0.01
782.9653113655718,0.0653524988200355,276.499560502903,20.0,8.333333333333333e-05,0.56,0.23,0.18,0.07,0.86,0.06,0.02,0.01
787.2733677646872,0.0657115035199618,276.521302094814,20.0,8.333333333333333e-05,0.56,0.23,0.18,0.07,0.86,0.06,0.02,0.01
791.650585509251,0.0660762716653421,276.581706989927,20.0,8.333333333333333e-05,0.56,0.23,0.18,0.07,0.86,0.06,0.02,0.01
796.0020201131916,0.0664388912156705,276.596065335226,20.0,8.333333333333333e-05,0.56,0.23,0.18,0.07,0.86,0.06,0.02,0.01
800.3741485627237,0.0668032352531315,276.633145504532,20.0,8.333333333333333e-05,0.56,0.23,0.18,0.07,0.86,0.06,0.02,0.01
804.8004285668509,0.0671720919201421,276.654211095047,20.0,8.333333333333333e-05,0.56,0.23,0.18,0.07,0.86,0.06,0.02,0.01
809.1722068085234,0.0675364067736148,276.686711775533,20.0,8.333333333333333e-05,0.56,0.23,0.18,0.07,0.86,0.06,0.02,0.01
813.5390072266272,0.0679003068084568,276.727635942334,20.0,8.333333333333333e-05,0.56,0.23,0.18,0.07,0.86,0.06,0.02,0.01
817.8626798922948,0.0682606128639291,276.725162572331,20.0,8.333333333333333e-05,0.56,0.23,0.18,0.07,0.86,0.06,0.02,0.01
822.1534377750073,0.0686181760208218,276.750765659567,20.0,8.333333333333333e-05,0.56,0.23,0.18,0.07,0.86,0.06,0.02,0.01
826.4671251721153,0.0689776499705808,276.771950575565,20.0,8.333333333333333e-05,0.56,0.23,0.18,0.07,0.86,0.06,0.02,0.01
830.7963200131608,0.0693384162073346,276.814917816531,20.0,8.333333333333333e-05,0.56,0.23,0.18,0.07,0.86,0.06,0.02,0.01
835.19725196646,0.0697051605367762,276.828982275049,20.0,8.333333333333333e-05,0.56,0.23,0.18,0.07,0.86,0.06,0.02,0.01
839.5511171352301,0.0700679826341737,276.856261039485,20.0,8.333333333333333e-05,0.56,0.23,0.18,0.07,0.86,0.06,0.02,0.01
843.9960812391744,0.0704383963095024,276.893068490081,20.0,8.333333333333333e-05,0.56,0.23,0.18,0.07,0.86,0.06,0.02,0.01
848.316177905831,0.0707984043650571,276.918087497237,20.0,8.333333333333333e-05,0.56,0.23,0.18,0.07,0.86,0.06,0.02,0.01
852.6392739396986,0.0711586623678794,276.962317342854,20.0,8.333333333333333e-05,0.56,0.23,0.18,0.07,0.86,0.06,0.02,0.01
857.0570523979177,0.071526810572731,276.953552959205,20.0,8.333333333333333e-05,0.56,0.23,0.18,0.07,0.86,0.06,0.02,0.01
861.4949221834081,0.0718966330548552,276.945294859469,20.0,8.333333333333333e-05,0.56,0.23,0.18,0.07,0.86,0.06,0.02,0.01
865.9893155731561,0.0722711658373342,276.980435923797,20.0,8.333333333333333e-05,0.56,0.23,0.18,0.07,0.86,0.06,0.02,0.01
870.4185111649849,0.0726402654699866,277.006319812241,20.0,8.333333333333333e-05,0.56,0.23,0.18,0.07,0.86,0.06,0.02,0.01
874.8291170632225,0.0730078159615064,277.038777321118,20.0,8.333333333333333e-05,0.56,0.23,0.18,0.07,0.86,0.06,0.02,0.01
879.1885073602788,0.0733710984862611,277.021720070694,20.0,8.333333333333333e-05,0.56,0.23,0.18,0.07,0.86,0.06,0.02,0.01
883.5850113457693,0.0737374738183853,277.01804492417,20.0,8.333333333333333e-05,0.56,0.23,0.18,0.07,0.86,0.06,0.02,0.01
888.034448434344,0.0741082602424332,277.015284078801,20.0,8.333333333333333e-05,0.56,0.23,0.18,0.07,0.86,0.06,0.02,0.01
892.5512401910267,0.0744846595554901,277.055896346563,20.0,8.333333333333333e-05,0.56,0.23,0.18,0.07,0.86,0.06,0.02,0.01
897.1078891767756,0.0748643803043025,277.070169547806,20.0,8.333333333333333e-05,0.56,0.23,0.18,0.07,0.86,0.06,0.02,0.01
899.3658211351153,0.0750525413008308,277.080919182671,20.0,8.333333333333333e-05,0.56,0.23,0.18,0.07,0.86,0.06,0.02,0.01