File: datasets/al_6061_comp/csv/T_020_D_1.csv
Time,Strain(%),Stress(MPa),Temp(C),SR(%/s),Si(%),Fe(%),Cu(%),Mn(%),Mg(%),Cr(%),Zn(%),Ti(%)
0.0,9.69551156537664e-05,4.0718168447158,20.0,8.333333333333333e-05,0.67,0.28,0.23,0.05,0.9,0.05,0.03,0.02
0.4278590105884032,0.0001326100332028,6.81095533061962,20.0,8.333333333333333e-05,0.67,0.28,0.23,0.05,0.9,0.05,0.03,0.02
0.9603294076564032,0.0001769825662918,10.5850679489926,20.0,8.333333333333333e-05,0.67,0.28,0.23,0.05,0.9,0.05,0.03,0.02
1.6012936956628032,0.000230396256959,14.8915452181599,20.0,8.333333333333333e-05,0.67,0.28,0.23,0.05,0.9,0.05,0.03,0.02
2.2843505166748037,0.00028731765871,19.5394766691745,20.0,8.333333333333333e-05,0.67,0.28,0.23,0.05,0.9,0.05,0.03,0.02
3.201499501290403,0.0003637467407613,24.3414170410342,20.0,8.333333333333333e-05,0.67,0.28,0.23,0.05,0.9,0.05,0.03,0.02
3.994191085469203,0.0004298043727762,29.4357955001479,20.0,8.333333333333333e-05,0.67,0.28,0.23,0.05,0.9,0.05,0.03,0.02
5.023677614683604,0.0005155949168774,34.8762937157234,20.0,8.333333333333333e-05,0.67,0.28,0.23,0.05,0.9,0.05,0.03,0.02
6.090372311128004,0.0006044861415811,40.5231975417432,20.0,8.333333333333333e-05,0.67,0.28,0.23,0.05,0.9,0.05,0.03,0.02
6.984363231918404,0.0006789853849803,46.2759959221109,20.0,8.333333333333333e-05,0.67,0.28,0.23,0.05,0.9,0.05,0.03,0.02
8.077469066543202,0.0007700775378657,51.9812573938816,20.0,8.333333333333333e-05,0.67,0.28,0.23,0.05,0.9,0.05,0.03,0.02
9.208335567038803,0.000864316412907,57.6446031274631,20.0,8.333333333333333e-05,0.67,0.28,0.23,0.05,0.9,0.05,0.03,0.02
10.315337774396802,0.0009565665968535,63.4062707161491,20.0,8.333333333333333e-05,0.67,0.28,0.23,0.05,0.9,0.05,0.03,0.02
11.662908881286402,0.0010688641890943,69.1055074703282,20.0,8.333333333333333e-05,0.67,0.28,0.23,0.05,0.9,0.05,0.03,0.02
12.924697724822805,0.001174013259389,74.9573401346784,20.0,8.333333333333333e-05,0.67,0.28,0.23,0.05,0.9,0.05,0.03,0.02
14.116716189443204,0.0012733481314407,80.7862825851129,20.0,8.333333333333333e-05,0.67,0.28,0.23,0.05,0.9,0.05,0.03,0.02
15.309082870426002,0.0013727120215226,86.6391629856978,20.0,8.333333333333333e-05,0.67,0.28,0.23,0.05,0.9,0.05,0.03,0.02
16.319447981942805,0.001456909114149,92.6615061426464,20.0,8.333333333333333e-05,0.67,0.28,0.23,0.05,0.9,0.05,0.03,0.02
17.514051894376006,0.0015564594401851,98.5357929974782,20.0,8.333333333333333e-05,0.67,0.28,0.23,0.05,0.9,0.05,0.03,0.02
18.710302832022403,0.0016561470183223,104.440226006895,20.0,8.333333333333333e-05,0.67,0.28,0.23,0.05,0.9,0.05,0.03,0.02
20.002182320436404,0.0017638036423568,110.246959021844,20.0,8.333333333333333e-05,0.67,0.28,0.23,0.05,0.9,0.05,0.03,0.02
21.262947291082007,0.0018688673899106,116.119652031253,20.0,8.333333333333333e-05,0.67,0.28,0.23,0.05,0.9,0.05,0.03,0.02
22.599559069996005,0.0019802517048201,122.049653663834,20.0,8.333333333333333e-05,0.67,0.28,0.23,0.05,0.9,0.05,0.03,0.02
23.802684124080407,0.0020805121259938,127.817953013955,20.0,8.333333333333333e-05,0.67,0.28,0.23,0.05,0.9,0.05,0.03,0.02
25.09460814276401,0.0021881724608841,133.711361011399,20.0,8.333333333333333e-05,0.67,0.28,0.23,0.05,0.9,0.05,0.03,0.02
26.284231455234405,0.0022873077369233,139.563701607476,20.0,8.333333333333333e-05,0.67,0.28,0.23,0.05,0.9,0.05,0.03,0.02
27.57020461556321,0.0023944721669507,145.318636146941,20.0,8.333333333333333e-05,0.67,0.28,0.23,0.05,0.9,0.05,0.03,0.02
28.94927635108601,0.0025093948115776,151.023288065701,20.0,8.333333333333333e-05,0.67,0.28,0.23,0.05,0.9,0.05,0.03,0.02
30.162667927291608,0.0026105107762614,156.610011716928,20.0,8.333333333333333e-05,0.67,0.28,0.23,0.05,0.9,0.05,0.03,0.02
31.44039440991041,0.0027169879831463,162.295102388275,20.0,8.333333333333333e-05,0.67,0.28,0.23,0.05,0.9,0.05,0.03,0.02
32.599758930763606,0.0028136016932174,167.849094696005,20.0,8.333333333333333e-05,0.67,0.28,0.23,0.05,0.9,0.05,0.03,0.02
33.767232585152804,0.0029108911644165,173.246369547752,20.0,8.333333333333333e-05,0.67,0.28,0.23,0.05,0.9,0.05,0.03,0.02
34.969007734567604,0.0030110390935344,178.486834834835,20.0,8.333333333333333e-05,0.67,0.28,0.23,0.05,0.9,0.05,0.03,0.02
36.122957493028,0.0031072015734061,183.541507417681,20.0,8.333333333333333e-05,0.67,0.28,0.23,0.05,0.9,0.05,0.03,0.02
37.33698668988641,0.0032083706731443,188.492526339197,20.0,8.333333333333333e-05,0.67,0.28,0.23,0.05,0.9,0.05,0.03,0.02
38.4975811823812,0.0033050868808522,193.34092499525,20.0,8.333333333333333e-05,0.67,0.28,0.23,0.05,0.9,0.05,0.03,0.02
39.8393453363356,0.0034169005603484,198.248020384042,20.0,8.333333333333333e-05,0.67,0.28,0.23,0.05,0.9,0.05,0.03,0.02
41.13828327643721,0.0035251453886902,203.161268267398,20.0,8.333333333333333e-05,0.67,0.28,0.23,0.05,0.9,0.05,0.03,0.02
42.50217047943521,0.0036388026556067,208.044038881346,20.0,8.333333333333333e-05,0.67,0.28,0.23,0.05,0.9,0.05,0.03,0.02
43.90216077280961,0.0037554685133879,212.725969329506,20.0,8.333333333333333e-05,0.67,0.28,0.23,0.05,0.9,0.05,0.03,0.02
45.22648811938241,0.0038658291256023,217.200940991075,20.0,8.333333333333333e-05,0.67,0.28,0.23,0.05,0.9,0.05,0.03,0.02
46.6180240320148,0.003981790451655,221.32620670825,20.0,8.333333333333333e-05,0.67,0.28,0.23,0.05,0.9,0.05,0.03,0.02
48.036305919466,0.0040999806089426,225.16841290749,20.0,8.333333333333333e-05,0.67,0.28,0.23,0.05,0.9,0.05,0.03,0.02
49.52539432484921,0.0042240713093912,228.658583305038,20.0,8.333333333333333e-05,0.67,0.28,0.23,0.05,0.9,0.05,0.03,0.02
51.16975217933561,0.0043611011305984,231.984474092215,20.0,8.333333333333333e-05,0.67,0.28,0.23,0.05,0.9,0.05,0.03,0.02
53.053312935324406,0.0045180645269308,235.086473230094,20.0,8.333333333333333e-05,0.67,0.28,0.23,0.05,0.9,0.05,0.03,0.02
55.1818224385108,0.004695440318863,237.864177858516,20.0,8.333333333333333e-05,0.67,0.28,0.23,0.05,0.9,0.05,0.03,0.02
57.51312911963681,0.0048897158756235,240.509948967569,20.0,8.333333333333333e-05,0.67,0.28,0.23,0.05,0.9,0.05,0.03,0.02
60.21851760184121,0.0051151649158072,242.870116771038,20.0,8.333333333333333e-05,0.67,0.28,0.23,0.05,0.9,0.05,0.03,0.02
63.30221086234601,0.0053721393541826,244.959652216748,20.0,8.333333333333333e-05,0.67,0.28,0.23,0.05,0.9,0.05,0.03,0.02
66.74448563359,0.0056589955851196,246.65591402658,20.0,8.333333333333333e-05,0.67,0.28,0.23,0.05,0.9,0.05,0.03,0.02
70.50826967119,0.0059726442549196,247.914778998425,20.0,8.333333333333333e-05,0.67,0.28,0.23,0.05,0.9,0.05,0.03,0.02
74.369197511644,0.0062943882416241,248.870648671972,20.0,8.333333333333333e-05,0.67,0.28,0.23,0.05,0.9,0.05,0.03,0.02
78.42679968067961,0.0066325217557104,249.645253084639,20.0,8.333333333333333e-05,0.67,0.28,0.23,0.05,0.9,0.05,0.03,0.02
82.6628727778456,0.0069855278471409,250.314451388935,20.0,8.333333333333333e-05,0.67,0.28,0.23,0.05,0.9,0.05,0.03,0.02
86.97748745534679,0.007345079070266,250.934654545422,20.0,8.333333333333333e-05,0.67,0.28,0.23,0.05,0.9,0.05,0.03,0.02
91.3884332142316,0.0077126578835064,251.463987947201,20.0,8.333333333333333e-05,0.67,0.28,0.23,0.05,0.9,0.05,0.03,0.02
95.7742413807088,0.0080781418973795,251.860778419526,20.0,8.333333333333333e-05,0.67,0.28,0.23,0.05,0.9,0.05,0.03,0.02
100.26142399411,0.0084520737818296,252.182390390725,20.0,8.333333333333333e-05,0.67,0.28,0.23,0.05,0.9,0.05,0.03,0.02
104.6451207351052,0.0088173818435792,252.433996112555,20.0,8.333333333333333e-05,0.67,0.28,0.23,0.05,0.9,0.05,0.03,0.02
109.054022266024,0.0091847903044891,252.688319818604,20.0,8.333333333333333e-05,0.67,0.28,0.23,0.05,0.9,0.05,0.03,0.02
113.4496510260496,0.0095510927011579,253.06751983577,20.0,8.333333333333333e-05,0.67,0.28,0.23,0.05,0.9,0.05,0.03,0.02
117.9919312175956,0.0099296160504534,253.417974242593,20.0,8.333333333333333e-05,0.67,0.28,0.23,0.05,0.9,0.05,0.03,0.02
122.3969044588228,0.010296697153889,253.742625657303,20.0,8.333333333333333e-05,0.67,0.28,0.23,0.05,0.9,0.05,0.03,0.02
126.8317642105756,0.0106662687998684,253.974420501317,20.0,8.333333333333333e-05,0.67,0.28,0.23,0.05,0.9,0.05,0.03,0.02
131.1668845904332,0.0110275288315232,254.071307731969,20.0,8.333333333333333e-05,0.67,0.28,0.23,0.05,0.9,0.05,0.03,0.02
135.5704591507744,0.0113944933782183,254.25988249948,20.0,8.333333333333333e-05,0.67,0.28,0.23,0.05,0.9,0.05,0.03,0.02
140.02649681257603,0.0117658298500351,254.510405960201,20.0,8.333333333333333e-05,0.67,0.28,0.23,0.05,0.9,0.05,0.03,0.02
144.36373415367282,0.0121272662951265,254.802779952519,20.0,8.333333333333333e-05,0.67,0.28,0.23,0.05,0.9,0.05,0.03,0.02
148.5819574107808,0.0124787848998855,255.110225846949,20.0,8.333333333333333e-05,0.67,0.28,0.23,0.05,0.9,0.05,0.03,0.02
152.96987107330722,0.0128444443717627,255.353973920217,20.0,8.333333333333333e-05,0.67,0.28,0.23,0.05,0.9,0.05,0.03,0.02
157.0456237883776,0.0131840904313519,255.633518158024,20.0,8.333333333333333e-05,0.67,0.28,0.23,0.05,0.9,0.05,0.03,0.02
161.2525600628632,0.0135346684542257,255.928467270821,20.0,8.333333333333333e-05,0.67,0.28,0.23,0.05,0.9,0.05,0.03,0.02
165.47618583662083,0.0138866372687055,256.108855355333,20.0,8.333333333333333e-05,0.67,0.28,0.23,0.05,0.9,0.05,0.03,0.02
169.8173204118916,0.0142483984833114,256.446613581112,20.0,8.333333333333333e-05,0.67,0.28,0.23,0.05,0.9,0.05,0.03,0.02
174.1965900523312,0.0146133376200147,256.626081182295,20.0,8.333333333333333e-05,0.67,0.28,0.23,0.05,0.9,0.05,0.03,0.02
178.5340629421708,0.014974793694168,256.835626745878,20.0,8.333333333333333e-05,0.67,0.28,0.23,0.05,0.9,0.05,0.03,0.02
182.68617696159643,0.0153208031957868,257.131469249348,20.0,8.333333333333333e-05,0.67,0.28,0.23,0.05,0.9,0.05,0.03,0.02
186.96612271220923,0.0156774653416712,257.309250721739,20.0,8.333333333333333e-05,0.67,0.28,0.23,0.05,0.9,0.05,0.03,0.02
191.2307115215188,0.016032847742447,257.563070402739,20.0,8.333333333333333e-05,0.67,0.28,0.23,0.05,0.9,0.05,0.03,0.02
195.5818701622396,0.0163954442958404,257.836778618701,20.0,8.333333333333333e-05,0.67,0.28,0.23,0.05,0.9,0.05,0.03,0.02
199.8050461959364,0.0167473756319818,258.051952451413,20.0,8.333333333333333e-05,0.67,0.28,0.23,0.05,0.9,0.05,0.03,0.02
203.96816938247923,0.0170943025641937,258.364492178177,20.0,8.333333333333333e-05,0.67,0.28,0.23,0.05,0.9,0.05,0.03,0.02
208.2077359313188,0.017447599776597,258.649857938651,20.0,8.333333333333333e-05,0.67,0.28,0.23,0.05,0.9,0.05,0.03,0.02
212.50879151330204,0.0178060210750956,258.837615225747,20.0,8.333333333333333e-05,0.67,0.28,0.23,0.05,0.9,0.05,0.03,0.02
216.7835562171448,0.0181622514670825,259.113780726602,20.0,8.333333333333333e-05,0.67,0.28,0.23,0.05,0.9,0.05,0.03,0.02
221.0611170724924,0.0185187148716948,259.280856454763,20.0,8.333333333333333e-05,0.67,0.28,0.23,0.05,0.9,0.05,0.03,0.02
225.1899964025164,0.0188627881491968,259.511640088397,20.0,8.333333333333333e-05,0.67,0.28,0.23,0.05,0.9,0.05,0.03,0.02
229.3456087527616,0.0192090891783839,259.630377641849,20.0,8.333333333333333e-05,0.67,0.28,0.23,0.05,0.9,0.05,0.03,0.02
233.421847562374,0.0195487757458516,259.778741094652,20.0,8.333333333333333e-05,0.67,0.28,0.23,0.05,0.9,0.05,0.03,0.02
237.5581578039748,0.019893468265985,260.029611884501,20.0,8.333333333333333e-05,0.67,0.28,0.23,0.05,0.9,0.05,0.03,0.02
241.62202070454043,0.0202321235076988,260.255721129673,20.0,8.333333333333333e-05,0.67,0.28,0.23,0.05,0.9,0.05,0.03,0.02
245.7508952593204,0.0205761963872638,260.478661915657,20.0,8.333333333333333e-05,0.67,0.28,0.23,0.05,0.9,0.05,0.03,0.02
249.90804911665964,0.0209226258753754,260.644712394806,20.0,8.333333333333333e-05,0.67,0.28,0.23,0.05,0.9,0.05,0.03,0.02
254.021348752,0.0212654008449871,260.801578812758,20.0,8.333333333333333e-05,0.67,0.28,0.23,0.05,0.9,0.05,0.03,0.02
258.1420354510024,0.0216087914032373,261.010947305344,20.0,8.333333333333333e-05,0.67,0.28,0.23,0.05,0.9,0.05,0.03,0.02
262.3678977192052,0.0219609465922542,261.2514398132,20.0,8.333333333333333e-05,0.67,0.28,0.23,0.05,0.9,0.05,0.03,0.02
266.4783202043668,0.022303481799351,261.557764554425,20.0,8.333333333333333e-05,0.67,0.28,0.23,0.05,0.9,0.05,0.03,0.02
270.7599122258644,0.0226602811344758,261.840393464282,20.0,8.333333333333333e-05,0.67,0.28,0.23,0.05,0.9,0.05,0.03,0.02
274.8411579826516,0.0230003849475414,262.079115738593,20.0,8.333333333333333e-05,0.67,0.28,0.23,0.05,0.9,0.05,0.03,0.02
278.97255696311083,0.023344668195913,262.247348510582,20.0,8.333333333333333e-05,0.67,0.28,0.23,0.05,0.9,0.05,0.03,0.02
283.028766677194,0.0236826856720866,262.384802563686,20.0,8.333333333333333e-05,0.67,0.28,0.23,0.05,0.9,0.05,0.03,0.02
287.10542744228326,0.0240224074025107,262.482090975282,20.0,8.333333333333333e-05,0.67,0.28,0.23,0.05,0.9,0.05,0.03,0.02
291.23562831334243,0.0243665908084323,262.683301767341,20.0,8.333333333333333e-05,0.67,0.28,0.23,0.05,0.9,0.05,0.03,0.02
295.33851601118084,0.0247084981165855,262.910745587882,20.0,8.333333333333333e-05,0.67,0.28,0.23,0.05,0.9,0.05,0.03,0.02
299.5297174108564,0.0250577648998918,263.214461970098,20.0,8.333333333333333e-05,0.67,0.28,0.23,0.05,0.9,0.05,0.03,0.02
303.72221196750644,0.0254071394462793,263.463447994023,20.0,8.333333333333333e-05,0.67,0.28,0.23,0.05,0.9,0.05,0.03,0.02
307.86519295831965,0.0257523878621804,263.628729206885,20.0,8.333333333333333e-05,0.67,0.28,0.23,0.05,0.9,0.05,0.03,0.02
311.9745679961188,0.026094835781997,263.730312884441,20.0,8.333333333333333e-05,0.67,0.28,0.23,0.05,0.9,0.05,0.03,0.02
315.95283749643767,0.0264263582403569,263.877013537358,20.0,8.333333333333333e-05,0.67,0.28,0.23,0.05,0.9,0.05,0.03,0.02
319.95503283540404,0.0267598745186041,264.063880911678,20.0,8.333333333333333e-05,0.67,0.28,0.23,0.05,0.9,0.05,0.03,0.02
323.945172605146,0.0270923861660826,264.297314321466,20.0,8.333333333333333e-05,0.67,0.28,0.23,0.05,0.9,0.05,0.03,0.02
328.0197475559308,0.027431934078648,264.472653897467,20.0,8.333333333333333e-05,0.67,0.28,0.23,0.05,0.9,0.05,0.03,0.02
332.0522069701012,0.0277679723631622,264.610617819757,20.0,8.333333333333333e-05,0.67,0.28,0.23,0.05,0.9,0.05,0.03,0.02
336.1271625286888,0.0281075519930445,264.794521517894,20.0,8.333333333333333e-05,0.67,0.28,0.23,0.05,0.9,0.05,0.03,0.02
340.20071536224884,0.0284470147291745,265.051202666203,20.0,8.333333333333333e-05,0.67,0.28,0.23,0.05,0.9,0.05,0.03,0.02
344.26804866502124,0.0287859591710722,265.253203385478,20.0,8.333333333333333e-05,0.67,0.28,0.23,0.05,0.9,0.05,0.03,0.02
348.401562258676,0.0291304186372101,265.432749739582,20.0,8.333333333333333e-05,0.67,0.28,0.23,0.05,0.9,0.05,0.03,0.02
352.5725587205524,0.0294780016756998,265.632390491549,20.0,8.333333333333333e-05,0.67,0.28,0.23,0.05,0.9,0.05,0.03,0.02
356.6704646789056,0.0298194938388959,265.77401301825,20.0,8.333333333333333e-05,0.67,0.28,0.23,0.05,0.9,0.05,0.03,0.02
360.7610002522996,0.0301603718033454,266.008092046361,20.0,8.333333333333333e-05,0.67,0.28,0.23,0.05,0.9,0.05,0.03,0.02
364.8378779324884,0.0305001116100278,266.142328171564,20.0,8.333333333333333e-05,0.67,0.28,0.23,0.05,0.9,0.05,0.03,0.02
368.96240598028,0.0308438222806771,266.392588931978,20.0,8.333333333333333e-05,0.67,0.28,0.23,0.05,0.9,0.05,0.03,0.02
373.0732263915076,0.0311863906482794,266.61435310898,20.0,8.333333333333333e-05,0.67,0.28,0.23,0.05,0.9,0.05,0.03,0.02
377.1765925028764,0.0315283378242268,266.769058371446,20.0,8.333333333333333e-05,0.67,0.28,0.23,0.05,0.9,0.05,0.03,0.02
381.22117305156286,0.031865386203284,267.014149976858,20.0,8.333333333333333e-05,0.67,0.28,0.23,0.05,0.9,0.05,0.03,0.02
385.2733094195056,0.0322030642339459,267.093786315765,20.0,8.333333333333333e-05,0.67,0.28,0.23,0.05,0.9,0.05,0.03,0.02
389.37586133790046,0.0325449435604788,267.256832622673,20.0,8.333333333333333e-05,0.67,0.28,0.23,0.05,0.9,0.05,0.03,0.02
393.5004882072388,0.032888662466257,267.399041087626,20.0,8.333333333333333e-05,0.67,0.28,0.23,0.05,0.9,0.05,0.03,0.02
397.6322083270505,0.0332329724762413,267.595261066145,20.0,8.333333333333333e-05,0.67,0.28,0.23,0.05,0.9,0.05,0.03,0.02
401.746072039168,0.0335757944522511,267.865256317694,20.0,8.333333333333333e-05,0.67,0.28,0.23,0.05,0.9,0.05,0.03,0.02
405.7190913786124,0.0339068793972048,268.107581581831,20.0,8.333333333333333e-05,0.67,0.28,0.23,0.05,0.9,0.05,0.03,0.02
409.7635302944452,0.0342439159735242,268.23867036932,20.0,8.333333333333333e-05,0.67,0.28,0.23,0.05,0.9,0.05,0.03,0.02
413.7651827332816,0.0345773870100939,268.327347588067,20.0,8.333333333333333e-05,0.67,0.28,0.23,0.05,0.9,0.05,0.03,0.02
417.8995028926396,0.0349219136900404,268.475937405892,20.0,8.333333333333333e-05,0.67,0.28,0.23,0.05,0.9,0.05,0.03,0.02
421.87108508942566,0.0352528788731059,268.637017065436,20.0,8.333333333333333e-05,0.67,0.28,0.23,0.05,0.9,0.05,0.03,0.02
425.971698813232,0.0355945966834231,268.755272938134,20.0,8.333333333333333e-05,0.67,0.28,0.23,0.05,0.9,0.05,0.03,0.02
430.0250114141873,0.0359323727335027,268.912405566052,20.0,8.333333333333333e-05,0.67,0.28,0.23,0.05,0.9,0.05,0.03,0.02
434.0135405668468,0.036264750162891,269.02243143291,20.0,8.333333333333333e-05,0.67,0.28,0.23,0.05,0.9,0.05,0.03,0.02
438.2781431154028,0.036620133708604,269.22272884036,20.0,8.333333333333333e-05,0.67,0.28,0.23,0.05,0.9,0.05,0.03,0.02
442.4622567602548,0.036968809845675,269.475983688701,20.0,8.333333333333333e-05,0.67,0.28,0.23,0.05,0.9,0.05,0.03,0.02
446.7499622189644,0.0373261186339008,269.715643121189,20.0,8.333333333333333e-05,0.67,0.28,0.23,0.05,0.9,0.05,0.03,0.02
451.0360447930312,0.0376832921817397,269.880203091325,20.0,8.333333333333333e-05,0.67,0.28,0.23,0.05,0.9,0.05,0.03,0.02
455.22000841159,0.0380319558166196,269.982828549813,20.0,8.333333333333333e-05,0.67,0.28,0.23,0.05,0.9,0.05,0.03,0.02
459.3941396428192,0.0383798000858887,270.057708126512,20.0,8.333333333333333e-05,0.67,0.28,0.23,0.05,0.9,0.05,0.03,0.02
463.47036641862286,0.038719485650539,270.186559816496,20.0,8.333333333333333e-05,0.67,0.28,0.23,0.05,0.9,0.05,0.03,0.02
467.5737707719168,0.0390614360133135,270.355597618348,20.0,8.333333333333333e-05,0.67,0.28,0.23,0.05,0.9,0.05,0.03,0.02
471.6315762789365,0.0393995864722318,270.505717790128,20.0,8.333333333333333e-05,0.67,0.28,0.23,0.05,0.9,0.05,0.03,0.02
475.7409450686405,0.0397420338713738,270.624951650557,20.0,8.333333333333333e-05,0.67,0.28,0.23,0.05,0.9,0.05,0.03,0.02
479.8657813678912,0.0400857702296447,270.759600787905,20.0,8.333333333333333e-05,0.67,0.28,0.23,0.05,0.9,0.05,0.03,0.02
483.9567042423472,0.0404266804691827,270.964094698577,20.0,8.333333333333333e-05,0.67,0.28,0.23,0.05,0.9,0.05,0.03,0.02
487.9655945055184,0.0407607546577803,271.17566566851,20.0,8.333333333333333e-05,0.67,0.28,0.23,0.05,0.9,0.05,0.03,0.02
491.9309777946016,0.0410912032652039,271.404477906419,20.0,8.333333333333333e-05,0.67,0.28,0.23,0.05,0.9,0.05,0.03,0.02
495.78313648654,0.0414122164895321,271.624199811655,20.0,8.333333333333333e-05,0.67,0.28,0.23,0.05,0.9,0.05,0.03,0.02
499.7626515342436,0.0417438427435074,271.789314069594,20.0,8.333333333333333e-05,0.67,0.28,0.23,0.05,0.9,0.05,0.03,0.02
503.79009001144,0.0420794626166071,271.966108105175,20.0,8.333333333333333e-05,0.67,0.28,0.23,0.05,0.9,0.05,0.03,0.02
508.0911115699792,0.0424378810798187,272.09101860767,20.0,8.333333333333333e-05,0.67,0.28,0.23,0.05,0.9,0.05,0.03,0.02
512.2839324025408,0.0427872828158655,272.179590600191,20.0,8.333333333333333e-05,0.67,0.28,0.23,0.05,0.9,0.05,0.03,0.02
516.451778310508,0.0431346033081961,272.264071617452,20.0,8.333333333333333e-05,0.67,0.28,0.23,0.05,0.9,0.05,0.03,0.02
520.5397303867096,0.0434752659812129,272.396757696498,20.0,8.333333333333333e-05,0.67,0.28,0.23,0.05,0.9,0.05,0.03,0.02
524.7640407011739,0.0438272918407516,272.529948769323,20.0,8.333333333333333e-05,0.67,0.28,0.23,0.05,0.9,0.05,0.03,0.02
528.878689215808,0.0441701792169711,272.692263765074,20.0,8.333333333333333e-05,0.67,0.28,0.23,0.05,0.9,0.05,0.03,0.02
533.0599473623104,0.0445186173958463,272.864417270073,20.0,8.333333333333333e-05,0.67,0.28,0.23,0.05,0.9,0.05,0.03,0.02
537.1516192021,0.0448595900491621,273.010739737455,20.0,8.333333333333333e-05,0.67,0.28,0.23,0.05,0.9,0.05,0.03,0.02
541.241299913998,0.0452003967751536,273.173487262863,20.0,8.333333333333333e-05,0.67,0.28,0.23,0.05,0.9,0.05,0.03,0.02
545.4496868447008,0.0455510956860455,273.287989548043,20.0,8.333333333333333e-05,0.67,0.28,0.23,0.05,0.9,0.05,0.03,0.02
549.6898022958616,0.0459044386403089,273.386732085722,20.0,8.333333333333333e-05,0.67,0.28,0.23,0.05,0.9,0.05,0.03,0.02
553.9152930634359,0.0462565628709401,273.528088418338,20.0,8.333333333333333e-05,0.67,0.28,0.23,0.05,0.9,0.05,0.03,0.02
558.0756617950324,0.0466032602652398,273.68516087388,20.0,8.333333333333333e-05,0.67,0.28,0.23,0.05,0.9,0.05,0.03,0.02
562.2791634740896,0.0469535520718279,273.844403965749,20.0,8.333333333333333e-05,0.67,0.28,0.23,0.05,0.9,0.05,0.03,0.02
566.4069889896411,0.0472975375314572,273.949013873985,20.0,8.333333333333333e-05,0.67,0.28,0.23,0.05,0.9,0.05,0.03,0.02
570.4782942820648,0.0476368129724925,274.038499282876,20.0,8.333333333333333e-05,0.67,0.28,0.23,0.05,0.9,0.05,0.03,0.02
574.7020184606272,0.0479887899873727,274.084857390939,20.0,8.333333333333333e-05,0.67,0.28,0.23,0.05,0.9,0.05,0.03,0.02
578.80681272571,0.0483308561761296,274.158458467398,20.0,8.333333333333333e-05,0.67,0.28,0.23,0.05,0.9,0.05,0.03,0.02
582.9924839850063,0.0486796621144043,274.284270856797,20.0,8.333333333333333e-05,0.67,0.28,0.23,0.05,0.9,0.05,0.03,0.02
587.1214336551063,0.0490237412535793,274.474398052587,20.0,8.333333333333333e-05,0.67,0.28,0.23,0.05,0.9,0.05,0.03,0.02
591.3565313180104,0.0493766660588213,274.701639472244,20.0,8.333333333333333e-05,0.67,0.28,0.23,0.05,0.9,0.05,0.03,0.02
595.67248388539,0.0497363287727696,274.91587282769,20.0,8.333333333333333e-05,0.67,0.28,0.23,0.05,0.9,0.05,0.03,0.02
599.9780389260976,0.0500951250261619,275.046584557181,20.0,8.333333333333333e-05,0.67,0.28,0.23,0.05,0.9,0.05,0.03,0.02
604.2126414072784,0.0504480085662603,275.127878217095,20.0,8.333333333333333e-05,0.67,0.28,0.23,0.05,0.9,0.05,0.03,0.02
608.4517191040155,0.0508012650409884,275.197841143622,20.0,8.333333333333333e-05,0.67,0.28,0.23,0.05,0.9,0.05,0.03,0.02
612.6736322356948,0.051153091135295,275.227924473735,20.0,8.333333333333333e-05,0.67,0.28,0.23,0.05,0.9,0.05,0.03,0.02
616.9963673658052,0.0515133190628042,275.260379872331,20.0,8.333333333333333e-05,0.67,0.28,0.23,0.05,0.9,0.05,0.03,0.02
621.2262230743396,0.0518658070385154,275.325212710642,20.0,8.333333333333333e-05,0.67,0.28,0.23,0.05,0.9,0.05,0.03,0.02
625.4845295399632,0.0522206659106507,275.44837516508,20.0,8.333333333333333e-05,0.67,0.28,0.23,0.05,0.9,0.05,0.03,0.02
629.6910715498312,0.0525712110781397,275.634500191082,20.0,8.333333333333333e-05,0.67,0.28,0.23,0.05,0.9,0.05,0.03,0.02
633.9710967441904,0.0529278798443363,275.851559424949,20.0,8.333333333333333e-05,0.67,0.28,0.23,0.05,0.9,0.05,0.03,0.02
638.179987668334,0.0532786207546816,276.057793506798,20.0,8.333333333333333e-05,0.67,0.28,0.23,0.05,0.9,0.05,0.03,0.02
642.3781846708372,0.0536284705048902,276.210840987713,20.0,8.333333333333333e-05,0.67,0.28,0.23,0.05,0.9,0.05,0.03,0.02
646.63334853838,0.0539830674938521,276.36958902719,20.0,8.333333333333333e-05,0.67,0.28,0.23,0.05,0.9,0.05,0.03,0.02
650.8716745961643,0.0543362613320008,276.419727529572,20.0,8.333333333333333e-05,0.67,0.28,0.23,0.05,0.9,0.05,0.03,0.02
655.1472405327772,0.0546925584933852,276.516604040679,20.0,8.333333333333333e-05,0.67,0.28,0.23,0.05,0.9,0.05,0.03,0.02
659.4361606757368,0.0550499685052985,276.5445367284,20.0,8.333333333333333e-05,0.67,0.28,0.23,0.05,0.9,0.05,0.03,0.02
663.7827766751019,0.0554121865052456,276.583256120705,20.0,8.333333333333333e-05,0.67,0.28,0.23,0.05,0.9,0.05,0.03,0.02
668.1898828596879,0.0557794453539611,276.659467588916,20.0,8.333333333333333e-05,0.67,0.28,0.23,0.05,0.9,0.05,0.03,0.02
672.4889466501904,0.0561377006698363,276.709788625293,20.0,8.333333333333333e-05,0.67,0.28,0.23,0.05,0.9,0.05,0.03,0.02
676.8388003418704,0.0565001884774763,276.828505057271,20.0,8.333333333333333e-05,0.67,0.28,0.23,0.05,0.9,0.05,0.03,0.02
681.2815676271999,0.0568704190845871,276.94860569214,20.0,8.333333333333333e-05,0.67,0.28,0.23,0.05,0.9,0.05,0.03,0.02
685.765637184052,0.0572440915476581,277.077979066631,20.0,8.333333333333333e-05,0.67,0.28,0.23,0.05,0.9,0.05,0.03,0.02
690.1271842342684,0.0576075538018428,277.189683836512,20.0,8.333333333333333e-05,0.67,0.28,0.23,0.05,0.9,0.05,0.03,0.02
694.4468997564268,0.057967530095356,277.328995864618,20.0,8.333333333333333e-05,0.67,0.28,0.23,0.05,0.9,0.05,0.03,0.02
698.7754667255116,0.0583282440094464,277.513335522666,20.0,8.333333333333333e-05,0.67,0.28,0.23,0.05,0.9,0.05,0.03,0.02
703.1889409102108,0.058696033524838,277.631361917705,20.0,8.333333333333333e-05,0.67,0.28,0.23,0.05,0.9,0.05,0.03,0.02
707.6113211215779,0.0590645652091186,277.744240279215,20.0,8.333333333333333e-05,0.67,0.28,0.23,0.05,0.9,0.05,0.03,0.02
711.9722084406784,0.0594279724857103,277.821435881029,20.0,8.333333333333333e-05,0.67,0.28,0.23,0.05,0.9,0.05,0.03,0.02
716.3472784967296,0.0597925616570479,277.90951977695,20.0,8.333333333333333e-05,0.67,0.28,0.23,0.05,0.9,0.05,0.03,0.02
720.7026458274244,0.0601555089346058,278.024779370169,20.0,8.333333333333333e-05,0.67,0.28,0.23,0.05,0.9,0.05,0.03,0.02
725.0228133373492,0.0605155228937662,278.091716860056,20.0,8.333333333333333e-05,0.67,0.28,0.23,0.05,0.9,0.05,0.03,0.02
729.0560205500548,0.060851623494825,278.146301670752,20.0,8.333333333333333e-05,0.67,0.28,0.23,0.05,0.9,0.05,0.03,0.02
733.3970888414032,0.0612133791857707,278.202576088136,20.0,8.333333333333333e-05,0.67,0.28,0.23,0.05,0.9,0.05,0.03,0.02
737.8294753240875,0.0615827447259944,278.309156280441,20.0,8.333333333333333e-05,0.67,0.28,0.23,0.05,0.9,0.05,0.03,0.02
742.2975090928204,0.0619550808733888,278.424355542474,20.0,8.333333333333333e-05,0.67,0.28,0.23,0.05,0.9,0.05,0.03,0.02
747.0723736161327,0.0623529862503315,278.544459480551,20.0,8.333333333333333e-05,0.67,0.28,0.23,0.05,0.9,0.05,0.03,0.02
751.5320715121048,0.0627246277416625,278.616977041317,20.0,8.333333333333333e-05,0.67,0.28,0.23,0.05,0.9,0.05,0.03,0.02
756.0761629184633,0.0631033020255257,278.700404494088,20.0,8.333333333333333e-05,0.67,0.28,0.23,0.05,0.9,0.05,0.03,0.02
760.5806173719603,0.0634786732299838,278.815293143419,20.0,8.333333333333333e-05,0.67,0.28,0.23,0.05,0.9,0.05,0.03,0.02
765.0764853726148,0.063853328896705,278.898563392082,20.0,8.333333333333333e-05,0.67,0.28,0.23,0.05,0.9,0.05,0.03,0.02
769.5157844837847,0.0642232704893025,278.997130160991,20.0,8.333333333333333e-05,0.67,0.28,0.23,0.05,0.9,0.05,0.03,0.02
774.1638958218724,0.0646106131008098,279.0461772708,20.0,8.333333333333333e-05,0.67,0.28,0.23,0.05,0.9,0.05,0.03,0.02
778.6803558793431,0.0649869847722657,279.136044168434,20.0,8.333333333333333e-05,0.67,0.28,0.23,0.05,0.9,0.05,0.03,0.02
783.4383890535207,0.0653834875367805,279.26795105569,20.0,8.333333333333333e-05,0.67,0.28,0.23,0.05,0.9,0.05,0.03,0.02
788.0283082777972,0.0657659808054702,279.367389315638,20.0,8.333333333333333e-05,0.67,0.28,0.23,0.05,0.9,0.05,0.03,0.02
792.5735364915471,0.0661447498232827,279.4764296355,20.0,8.333333333333333e-05,0.67,0.28,0.23,0.05,0.9,0.05,0.03,0.02
797.3280465365008,0.0665409589936955,279.556050554143,20.0,8.333333333333333e-05,0.67,0.28,0.23,0.05,0.9,0.05,0.03,0.02
801.9054768597339,0.0669224115206316,279.620482243272,20.0,8.333333333333333e-05,0.67,0.28,0.23,0.05,0.9,0.05,0.03,0.02
806.5224108112959,0.0673071560165951,279.715212860348,20.0,8.333333333333333e-05,0.67,0.28,0.23,0.05,0.9,0.05,0.03,0.02
810.9894865963552,0.0676794123320167,279.801264886432,20.0,8.333333333333333e-05,0.67,0.28,0.23,0.05,0.9,0.05,0.03,0.02
815.6009821981048,0.0680637036321625,279.909187515104,20.0,8.333333333333333e-05,0.67,0.28,0.23,0.05,0.9,0.05,0.03,0.02
820.1792194742883,0.0684452234051778,279.949894358631,20.0,8.333333333333333e-05,0.67,0.28,0.23,0.05,0.9,0.05,0.03,0.02
824.7074784902344,0.0688225783231733,280.049004664036,20.0,8.333333333333333e-05,0.67,0.28,0.23,0.05,0.9,0.05,0.03,0.02
829.2772888085789,0.069203395849702,280.11760420741,20.0,8.333333333333333e-05,0.67,0.28,0.23,0.05,0.9,0.05,0.03,0.02
833.9790668905359,0.0695952106898651,280.149870767332,20.0,8.333333333333333e-05,0.67,0.28,0.23,0.05,0.9,0.05,0.03,0.02
838.5222430489923,0.0699738087030698,280.182857474203,20.0,8.333333333333333e-05,0.67,0.28,0.23,0.05,0.9,0.05,0.03,0.02
843.2001790768095,0.0703636367053879,280.28997461247,20.0,8.333333333333333e-05,0.67,0.28,0.23,0.05,0.9,0.05,0.03,0.02
847.927475221936,0.0707575780508151,280.343822934865,20.0,8.333333333333333e-05,0.67,0.28,0.23,0.05,0.9,0.05,0.03,0.02
852.7066867336636,0.0711558456767924,280.428142190227,20.0,8.333333333333333e-05,0.67,0.28,0.23,0.05,0.9,0.05,0.03,0.02
857.5525656244828,0.071559668917694,280.479981638193,20.0,8.333333333333333e-05,0.67,0.28,0.23,0.05,0.9,0.05,0.03,0.02
862.321662836686,0.0719570936853776,280.551404503179,20.0,8.333333333333333e-05,0.67,0.28,0.23,0.05,0.9,0.05,0.03,0.02
867.1823805909916,0.0723621534982364,280.595325796709,20.0,8.333333333333333e-05,0.67,0.28,0.23,0.05,0.9,0.05,0.03,0.02
872.0045659230784,0.0727640022759103,280.691879895675,20.0,8.333333333333333e-05,0.67,0.28,0.23,0.05,0.9,0.05,0.03,0.02
876.8955339671512,0.0731715829462497,280.774573353431,20.0,8.333333333333333e-05,0.67,0.28,0.23,0.05,0.9,0.05,0.03,0.02
881.7672092254228,0.073577555884439,280.849707308895,20.0,8.333333333333333e-05,0.67,0.28,0.23,0.05,0.9,0.05,0.03,0.02
886.5700791761536,0.0739777950469999,280.976970187673,20.0,8.333333333333333e-05,0.67,0.28,0.23,0.05,0.9,0.05,0.03,0.02
891.530110038946,0.0743911309522326,281.02194852359,20.0,8.333333333333333e-05,0.67,0.28,0.23,0.05,0.9,0.05,0.03,0.02
896.3746378976189,0.074794841607122,281.061520032351,20.0,8.333333333333333e-05,0.67,0.28,0.23,0.05,0.9,0.05,0.03,0.02
901.2801233850112,0.0752036320644047,281.095447375295,20.0,8.333333333333333e-05,0.67,0.28,0.23,0.05,0.9,0.05,0.03,0.02
906.0344026733452,0.0755998220050992,281.149672136337,20.0,8.333333333333333e-05,0.67,0.28,0.23,0.05,0.9,0.05,0.03,0.02
910.9992759587932,0.0760135614455532,281.286864108485,20.0,8.333333333333333e-05,0.67,0.28,0.23,0.05,0.9,0.05,0.03,0.02
915.950035744768,0.0764261247610511,281.311129346185,20.0,8.333333333333333e-05,0.67,0.28,0.23,0.05,0.9,0.05,0.03,0.02
920.9438985389957,0.0768422799939034,281.412300360973,20.0,8.333333333333333e-05,0.67,0.28,0.23,0.05,0.9,0.05,0.03,0.02
925.8245749602723,0.0772490030290098,281.421704768364,20.0,8.333333333333333e-05,0.67,0.28,0.23,0.05,0.9,0.05,0.03,0.02
930.7949539789564,0.0776632012805668,281.494910158639,20.0,8.333333333333333e-05,0.67,0.28,0.23,0.05,0.9,0.05,0.03,0.02
935.8598241321292,0.0780852737933312,281.541297884407,20.0,8.333333333333333e-05,0.67,0.28,0.23,0.05,0.9,0.05,0.03,0.02
941.0089751394676,0.0785143697106094,281.618784073226,20.0,8.333333333333333e-05,0.67,0.28,0.23,0.05,0.9,0.05,0.03,0.02
946.1560276365832,0.0789432907520357,281.684782800975,20.0,8.333333333333333e-05,0.67,0.28,0.23,0.05,0.9,0.05,0.03,0.02
951.2116764117112,0.0793645948166297,281.626693397933,20.0,8.333333333333333e-05,0.67,0.28,0.23,0.05,0.9,0.05,0.03,0.02
956.44987430326,0.0798011113075921,281.706593262949,20.0,8.333333333333333e-05,0.67,0.28,0.23,0.05,0.9,0.05,0.03,0.02
961.66729319056,0.0802358962148671,281.754687619629,20.0,8.333333333333333e-05,0.67,0.28,0.23,0.05,0.9,0.05,0.03,0.02
966.9629266200556,0.0806771990006584,281.838477170678,20.0,8.333333333333333e-05,0.67,0.28,0.23,0.05,0.9,0.05,0.03,0.02
972.188740884622,0.0811126835227056,281.883021404739,20.0,8.333333333333333e-05,0.67,0.28,0.23,0.05,0.9,0.05,0.03,0.02
977.3890962281404,0.0815460464679988,281.890493324382,20.0,8.333333333333333e-05,0.67,0.28,0.23,0.05,0.9,0.05,0.03,0.02
982.6212968263144,0.0819820631845133,281.933239438202,20.0,8.333333333333333e-05,0.67,0.28,0.23,0.05,0.9,0.05,0.03,0.02
987.8667544363756,0.0824191846520184,282.001085135554,20.0,8.333333333333333e-05,0.67,0.28,0.23,0.05,0.9,0.05,0.03,0.02
993.1149619021948,0.08285653527417,282.017618580087,20.0,8.333333333333333e-05,0.67,0.28,0.23,0.05,0.9,0.05,0.03,0.02
998.4693779712976,0.0833027366132619,282.088723447795,20.0,8.333333333333333e-05,0.67,0.28,0.23,0.05,0.9,0.05,0.03,0.02
1003.8588315744652,0.0837518577468592,282.108054868171,20.0,8.333333333333333e-05,0.67,0.28,0.23,0.05,0.9,0.05,0.03,0.02
1009.2559423627408,0.0842016169792155,282.205825706919,20.0,8.333333333333333e-05,0.67,0.28,0.23,0.05,0.9,0.05,0.03,0.02
1014.535347349396,0.0846415673947701,282.2655730662,20.0,8.333333333333333e-05,0.67,0.28,0.23,0.05,0.9,0.05,0.03,0.02
1019.9505410792488,0.0850928335389245,282.229866834672,20.0,8.333333333333333e-05,0.67,0.28,0.23,0.05,0.9,0.05,0.03,0.02
1025.2604718748012,0.0855353277718872,282.285530920885,20.0,8.333333333333333e-05,0.67,0.28,0.23,0.05,0.9,0.05,0.03,0.02
1030.7466335947204,0.0859925079152138,282.284083893523,20.0,8.333333333333333e-05,0.67,0.28,0.23,0.05,0.9,0.05,0.03,0.02
1036.2078309652914,0.0864476076960947,282.362311795427,20.0,8.333333333333333e-05,0.67,0.28,0.23,0.05,0.9,0.05,0.03,0.02
1041.8106630627688,0.0869145103708845,282.385757837584,20.0,8.333333333333333e-05,0.67,0.28,0.23,0.05,0.9,0.05,0.03,0.02
1047.46079587165,0.0873853547716246,282.379716556311,20.0,8.333333333333333e-05,0.67,0.28,0.23,0.05,0.9,0.05,0.03,0.02
1053.1433184378593,0.0878588983188087,282.369485838775,20.0,8.333333333333333e-05,0.67,0.28,0.23,0.05,0.9,0.05,0.03,0.02
1058.7738389099163,0.0883281083581468,282.357606328226,20.0,8.333333333333333e-05,0.67,0.28,0.23,0.05,0.9,0.05,0.03,0.02
1064.5368166207577,0.0888083565007169,282.394579895787,20.0,8.333333333333333e-05,0.67,0.28,0.23,0.05,0.9,0.05,0.03,0.02
1070.3801323654648,0.0892952994794425,282.453728564529,20.0,8.333333333333333e-05,0.67,0.28,0.23,0.05,0.9,0.05,0.03,0.02
1076.2394732358675,0.0897835778853094,282.510381945608,20.0,8.333333333333333e-05,0.67,0.28,0.23,0.05,0.9,0.05,0.03,0.02
1082.2279887266848,0.0902826208428775,282.552103143912,20.0,8.333333333333333e-05,0.67,0.28,0.23,0.05,0.9,0.05,0.03,0.02
1088.163820305466,0.0907772734744426,282.587277320768,20.0,8.333333333333333e-05,0.67,0.28,0.23,0.05,0.9,0.05,0.03,0.02
1094.124619038646,0.0912740067022076,282.576265219891,20.0,8.333333333333333e-05,0.67,0.28,0.23,0.05,0.9,0.05,0.03,0.02
1100.123987644636,0.0917739540860401,282.581503345236,20.0,8.333333333333333e-05,0.67,0.28,0.23,0.05,0.9,0.05,0.03,0.02
1106.2578580857796,0.0922851099561354,282.583676188997,20.0,8.333333333333333e-05,0.67,0.28,0.23,0.05,0.9,0.05,0.03,0.02
1112.363239027462,0.0927938917012756,282.593173991413,20.0,8.333333333333333e-05,0.67,0.28,0.23,0.05,0.9,0.05,0.03,0.02
1118.6092127680347,0.09331438951299,282.622139614456,20.0,8.333333333333333e-05,0.67,0.28,0.23,0.05,0.9,0.05,0.03,0.02