File: datasets/al_6061_comp/csv/T_020_G_1.csv
Time,Strain(%),Stress(MPa),Temp(C),SR(%/s),Si(%),Fe(%),Cu(%),Mn(%),Mg(%),Cr(%),Zn(%),Ti(%)
0.0,9.68144450692949e-05,14.8374596720181,20.0,8.333333333333333e-05,0.61,0.15,0.17,0.02,0.88,0.05,0.01,0.01
0.4358774022228613,0.0001331375619212,19.1087232092717,20.0,8.333333333333333e-05,0.61,0.15,0.17,0.02,0.88,0.05,0.01,0.01
1.0691311874112612,0.0001859087106869,23.4583589967875,20.0,8.333333333333333e-05,0.61,0.15,0.17,0.02,0.88,0.05,0.01,0.01
1.854155015988061,0.0002513273630683,27.8857373516246,20.0,8.333333333333333e-05,0.61,0.15,0.17,0.02,0.88,0.05,0.01,0.01
2.602743866823661,0.0003137097673046,32.3434303107433,20.0,8.333333333333333e-05,0.61,0.15,0.17,0.02,0.88,0.05,0.01,0.01
3.4582621981056616,0.0003850029615781,36.8411899930128,20.0,8.333333333333333e-05,0.61,0.15,0.17,0.02,0.88,0.05,0.01,0.01
4.367722321358462,0.0004607913051825,41.4766493641687,20.0,8.333333333333333e-05,0.61,0.15,0.17,0.02,0.88,0.05,0.01,0.01
5.225007487107661,0.0005322317356616,45.9680198248956,20.0,8.333333333333333e-05,0.61,0.15,0.17,0.02,0.88,0.05,0.01,0.01
6.2263754630676615,0.0006156790669916,50.5007355257731,20.0,8.333333333333333e-05,0.61,0.15,0.17,0.02,0.88,0.05,0.01,0.01
7.194882644570463,0.0006963879987835,55.1080376881418,20.0,8.333333333333333e-05,0.61,0.15,0.17,0.02,0.88,0.05,0.01,0.01
8.135820360955261,0.0007747994751489,59.6884951224318,20.0,8.333333333333333e-05,0.61,0.15,0.17,0.02,0.88,0.05,0.01,0.01
9.201684071338862,0.0008636214510142,64.381644243964,20.0,8.333333333333333e-05,0.61,0.15,0.17,0.02,0.88,0.05,0.01,0.01
10.224914892433262,0.0009488906861054,69.1438856247543,20.0,8.333333333333333e-05,0.61,0.15,0.17,0.02,0.88,0.05,0.01,0.01
11.26861889305806,0.0010358660194908,73.726718696629,20.0,8.333333333333333e-05,0.61,0.15,0.17,0.02,0.88,0.05,0.01,0.01
12.301036451026862,0.0011219008159882,78.5656891759014,20.0,8.333333333333333e-05,0.61,0.15,0.17,0.02,0.88,0.05,0.01,0.01
13.36952442966006,0.0012109414808743,83.2352277374893,20.0,8.333333333333333e-05,0.61,0.15,0.17,0.02,0.88,0.05,0.01,0.01
14.43715204990446,0.001299910449228,87.9621507700463,20.0,8.333333333333333e-05,0.61,0.15,0.17,0.02,0.88,0.05,0.01,0.01
15.505299525984062,0.0013889227389013,92.6600868556074,20.0,8.333333333333333e-05,0.61,0.15,0.17,0.02,0.88,0.05,0.01,0.01
16.542156133070463,0.0014753274561585,97.1930043566598,20.0,8.333333333333333e-05,0.61,0.15,0.17,0.02,0.88,0.05,0.01,0.01
17.612298715012862,0.0015645060046537,101.717628777423,20.0,8.333333333333333e-05,0.61,0.15,0.17,0.02,0.88,0.05,0.01,0.01
18.651727330123265,0.0016511250559129,106.125631652254,20.0,8.333333333333333e-05,0.61,0.15,0.17,0.02,0.88,0.05,0.01,0.01
19.712313856554065,0.0017395072664488,110.52747980109,20.0,8.333333333333333e-05,0.61,0.15,0.17,0.02,0.88,0.05,0.01,0.01
20.776915247660465,0.001828224049041,114.799444458998,20.0,8.333333333333333e-05,0.61,0.15,0.17,0.02,0.88,0.05,0.01,0.01
21.852186912344465,0.001917830021098,118.914529965841,20.0,8.333333333333333e-05,0.61,0.15,0.17,0.02,0.88,0.05,0.01,0.01
22.89520272373086,0.0020047480053802,123.291492070694,20.0,8.333333333333333e-05,0.61,0.15,0.17,0.02,0.88,0.05,0.01,0.01
23.951699554126865,0.0020927894079132,127.477050095447,20.0,8.333333333333333e-05,0.61,0.15,0.17,0.02,0.88,0.05,0.01,0.01
25.005343024533666,0.0021805930304471,131.61398589783,20.0,8.333333333333333e-05,0.61,0.15,0.17,0.02,0.88,0.05,0.01,0.01
26.038183446240065,0.0022666630655893,136.006598864537,20.0,8.333333333333333e-05,0.61,0.15,0.17,0.02,0.88,0.05,0.01,0.01
27.085581989520065,0.0023539462775293,140.380333763192,20.0,8.333333333333333e-05,0.61,0.15,0.17,0.02,0.88,0.05,0.01,0.01
28.08109842425886,0.0024369059804242,144.930987130065,20.0,8.333333333333333e-05,0.61,0.15,0.17,0.02,0.88,0.05,0.01,0.01
29.072433289657265,0.0025195172192074,149.197139502792,20.0,8.333333333333333e-05,0.61,0.15,0.17,0.02,0.88,0.05,0.01,0.01
30.070232841756063,0.0026026671818823,153.343287125017,20.0,8.333333333333333e-05,0.61,0.15,0.17,0.02,0.88,0.05,0.01,0.01
31.049641578910855,0.0026842845766452,157.747456400216,20.0,8.333333333333333e-05,0.61,0.15,0.17,0.02,0.88,0.05,0.01,0.01
32.00712299526966,0.0027640746946751,161.884096458845,20.0,8.333333333333333e-05,0.61,0.15,0.17,0.02,0.88,0.05,0.01,0.01
32.95322743434367,0.0028429167312646,165.764210783502,20.0,8.333333333333333e-05,0.61,0.15,0.17,0.02,0.88,0.05,0.01,0.01
33.87712192484287,0.0029199079388062,169.676052045332,20.0,8.333333333333333e-05,0.61,0.15,0.17,0.02,0.88,0.05,0.01,0.01
34.84018477760526,0.0030001631765364,173.507613077898,20.0,8.333333333333333e-05,0.61,0.15,0.17,0.02,0.88,0.05,0.01,0.01
35.76133098516367,0.0030769253604996,177.555993596253,20.0,8.333333333333333e-05,0.61,0.15,0.17,0.02,0.88,0.05,0.01,0.01
36.69159253227127,0.0031544471560919,181.361630702894,20.0,8.333333333333333e-05,0.61,0.15,0.17,0.02,0.88,0.05,0.01,0.01
37.60614948589087,0.0032306602355602,185.132885702446,20.0,8.333333333333333e-05,0.61,0.15,0.17,0.02,0.88,0.05,0.01,0.01
38.53713633758046,0.003308242473201,189.237395558318,20.0,8.333333333333333e-05,0.61,0.15,0.17,0.02,0.88,0.05,0.01,0.01
39.49466235079207,0.0033880363076353,193.387891285278,20.0,8.333333333333333e-05,0.61,0.15,0.17,0.02,0.88,0.05,0.01,0.01
40.43452670213166,0.0034663583369136,197.344621579808,20.0,8.333333333333333e-05,0.61,0.15,0.17,0.02,0.88,0.05,0.01,0.01
41.368646543654464,0.0035442016570405,201.340924922803,20.0,8.333333333333333e-05,0.61,0.15,0.17,0.02,0.88,0.05,0.01,0.01
42.35097213830527,0.0036260621232614,205.318314725626,20.0,8.333333333333333e-05,0.61,0.15,0.17,0.02,0.88,0.05,0.01,0.01
43.30341180057607,0.0037054320951173,209.320917354202,20.0,8.333333333333333e-05,0.61,0.15,0.17,0.02,0.88,0.05,0.01,0.01
44.27333491047367,0.0037862590209421,213.153568273934,20.0,8.333333333333333e-05,0.61,0.15,0.17,0.02,0.88,0.05,0.01,0.01
45.21907214407926,0.0038650704570759,216.803186234405,20.0,8.333333333333333e-05,0.61,0.15,0.17,0.02,0.88,0.05,0.01,0.01
46.19414447331726,0.0039463264845124,220.410439333674,20.0,8.333333333333333e-05,0.61,0.15,0.17,0.02,0.88,0.05,0.01,0.01
47.18037916137726,0.0040285127085174,224.192829419324,20.0,8.333333333333333e-05,0.61,0.15,0.17,0.02,0.88,0.05,0.01,0.01
48.16616895759967,0.0041106618582026,227.601528876447,20.0,8.333333333333333e-05,0.61,0.15,0.17,0.02,0.88,0.05,0.01,0.01
49.12377852060967,0.0041904626551201,231.400262846119,20.0,8.333333333333333e-05,0.61,0.15,0.17,0.02,0.88,0.05,0.01,0.01
50.07805079017686,0.0042699853442507,235.137875237733,20.0,8.333333333333333e-05,0.61,0.15,0.17,0.02,0.88,0.05,0.01,0.01
51.02005472589487,0.0043484856722272,238.84011139364,20.0,8.333333333333333e-05,0.61,0.15,0.17,0.02,0.88,0.05,0.01,0.01
51.99572208522606,0.0044297912855048,242.298732302475,20.0,8.333333333333333e-05,0.61,0.15,0.17,0.02,0.88,0.05,0.01,0.01
52.94123203641126,0.0045085837814369,245.741032033204,20.0,8.333333333333333e-05,0.61,0.15,0.17,0.02,0.88,0.05,0.01,0.01
53.877552089977264,0.0045866104525674,248.817521362675,20.0,8.333333333333333e-05,0.61,0.15,0.17,0.02,0.88,0.05,0.01,0.01
54.82393057315207,0.0046654753261653,252.148330956721,20.0,8.333333333333333e-05,0.61,0.15,0.17,0.02,0.88,0.05,0.01,0.01
55.81918699647486,0.0047484133614422,254.9613521171,20.0,8.333333333333333e-05,0.61,0.15,0.17,0.02,0.88,0.05,0.01,0.01
56.82084736593607,0.0048318850588973,257.71730797603,20.0,8.333333333333333e-05,0.61,0.15,0.17,0.02,0.88,0.05,0.01,0.01
57.83165084081647,0.004916118681804,260.639305097977,20.0,8.333333333333333e-05,0.61,0.15,0.17,0.02,0.88,0.05,0.01,0.01
58.87724854704607,0.0050032518239898,263.714538595541,20.0,8.333333333333333e-05,0.61,0.15,0.17,0.02,0.88,0.05,0.01,0.01
59.976137175003664,0.0050948258763196,266.650363804785,20.0,8.333333333333333e-05,0.61,0.15,0.17,0.02,0.88,0.05,0.01,0.01
61.24286848942687,0.0052003868191882,269.649994933261,20.0,8.333333333333333e-05,0.61,0.15,0.17,0.02,0.88,0.05,0.01,0.01
62.66463512052366,0.0053188673717796,272.365690967974,20.0,8.333333333333333e-05,0.61,0.15,0.17,0.02,0.88,0.05,0.01,0.01
64.29672830161206,0.0054548751368703,274.872795086284,20.0,8.333333333333333e-05,0.61,0.15,0.17,0.02,0.88,0.05,0.01,0.01
66.27980829727805,0.0056201318031758,277.069705709249,20.0,8.333333333333333e-05,0.61,0.15,0.17,0.02,0.88,0.05,0.01,0.01
68.65710691401846,0.0058182400212375,278.78582820378,20.0,8.333333333333333e-05,0.61,0.15,0.17,0.02,0.88,0.05,0.01,0.01
71.36058110879526,0.0060435295374689,280.156752189107,20.0,8.333333333333333e-05,0.61,0.15,0.17,0.02,0.88,0.05,0.01,0.01
74.45396576620325,0.0063013115922529,281.256216806023,20.0,8.333333333333333e-05,0.61,0.15,0.17,0.02,0.88,0.05,0.01,0.01
77.81288544048246,0.0065812215651095,282.020204485666,20.0,8.333333333333333e-05,0.61,0.15,0.17,0.02,0.88,0.05,0.01,0.01
81.43003735599605,0.0068826508914023,282.6011206756,20.0,8.333333333333333e-05,0.61,0.15,0.17,0.02,0.88,0.05,0.01,0.01
85.23774111150725,0.0071999595376949,283.076454712473,20.0,8.333333333333333e-05,0.61,0.15,0.17,0.02,0.88,0.05,0.01,0.01
89.19818915309526,0.0075299968744939,283.46832536367,20.0,8.333333333333333e-05,0.61,0.15,0.17,0.02,0.88,0.05,0.01,0.01
93.21612917578204,0.0078648252097178,283.802716535422,20.0,8.333333333333333e-05,0.61,0.15,0.17,0.02,0.88,0.05,0.01,0.01
97.37104400337246,0.008211068112017,284.090263227093,20.0,8.333333333333333e-05,0.61,0.15,0.17,0.02,0.88,0.05,0.01,0.01
101.53917890773084,0.0085584126873802,284.323079525129,20.0,8.333333333333333e-05,0.61,0.15,0.17,0.02,0.88,0.05,0.01,0.01
105.76093462221723,0.0089102256635874,284.5274229532,20.0,8.333333333333333e-05,0.61,0.15,0.17,0.02,0.88,0.05,0.01,0.01
110.02058090661606,0.0092651961872873,284.738910045629,20.0,8.333333333333333e-05,0.61,0.15,0.17,0.02,0.88,0.05,0.01,0.01
114.32712144638889,0.0096240745656017,284.934770386728,20.0,8.333333333333333e-05,0.61,0.15,0.17,0.02,0.88,0.05,0.01,0.01
118.63616270666644,0.0099831613372915,285.103030261502,20.0,8.333333333333333e-05,0.61,0.15,0.17,0.02,0.88,0.05,0.01,0.01
122.98144248487206,0.0103452679854753,285.276289155767,20.0,8.333333333333333e-05,0.61,0.15,0.17,0.02,0.88,0.05,0.01,0.01
127.29797704773364,0.0107049791990471,285.426336576409,20.0,8.333333333333333e-05,0.61,0.15,0.17,0.02,0.88,0.05,0.01,0.01
131.63182319513888,0.0110661330446642,285.570225083178,20.0,8.333333333333333e-05,0.61,0.15,0.17,0.02,0.88,0.05,0.01,0.01
135.93378127863008,0.0114246295516218,285.700164951236,20.0,8.333333333333333e-05,0.61,0.15,0.17,0.02,0.88,0.05,0.01,0.01
140.21084890590848,0.011781051853895,285.820375756147,20.0,8.333333333333333e-05,0.61,0.15,0.17,0.02,0.88,0.05,0.01,0.01
144.46162304674806,0.0121352830322983,285.927076929453,20.0,8.333333333333333e-05,0.61,0.15,0.17,0.02,0.88,0.05,0.01,0.01
148.66959963732486,0.0124859477481797,286.037751798277,20.0,8.333333333333333e-05,0.61,0.15,0.17,0.02,0.88,0.05,0.01,0.01
152.8313161419697,0.0128327574569001,286.144018677534,20.0,8.333333333333333e-05,0.61,0.15,0.17,0.02,0.88,0.05,0.01,0.01
157.00313296586887,0.0131804088588917,286.249105382839,20.0,8.333333333333333e-05,0.61,0.15,0.17,0.02,0.88,0.05,0.01,0.01
161.18179817469968,0.0135286309596276,286.34695138463,20.0,8.333333333333333e-05,0.61,0.15,0.17,0.02,0.88,0.05,0.01,0.01
165.38176750678326,0.0138786284039679,286.451451309354,20.0,8.333333333333333e-05,0.61,0.15,0.17,0.02,0.88,0.05,0.01,0.01
169.6139720215993,0.0142313121135359,286.552172188994,20.0,8.333333333333333e-05,0.61,0.15,0.17,0.02,0.88,0.05,0.01,0.01
173.84600605932488,0.0145839816166797,286.652395044042,20.0,8.333333333333333e-05,0.61,0.15,0.17,0.02,0.88,0.05,0.01,0.01
178.08944993805608,0.0149376019399073,286.747023770422,20.0,8.333333333333333e-05,0.61,0.15,0.17,0.02,0.88,0.05,0.01,0.01
182.34437311174207,0.0152921788710478,286.835676390292,20.0,8.333333333333333e-05,0.61,0.15,0.17,0.02,0.88,0.05,0.01,0.01
186.6126820930681,0.0156478712861583,286.931266065183,20.0,8.333333333333333e-05,0.61,0.15,0.17,0.02,0.88,0.05,0.01,0.01
190.8408988021405,0.016000222678581,287.032822037761,20.0,8.333333333333333e-05,0.61,0.15,0.17,0.02,0.88,0.05,0.01,0.01
195.03678274619287,0.0163498796739187,287.124513899269,20.0,8.333333333333333e-05,0.61,0.15,0.17,0.02,0.88,0.05,0.01,0.01
199.18389199859408,0.0166954721116188,287.200737914257,20.0,8.333333333333333e-05,0.61,0.15,0.17,0.02,0.88,0.05,0.01,0.01
203.28151539776528,0.0170369407282164,287.278907532069,20.0,8.333333333333333e-05,0.61,0.15,0.17,0.02,0.88,0.05,0.01,0.01
207.38441164879688,0.0173788487491357,287.369421540223,20.0,8.333333333333333e-05,0.61,0.15,0.17,0.02,0.88,0.05,0.01,0.01
211.46484939984367,0.0177188852283896,287.474615662593,20.0,8.333333333333333e-05,0.61,0.15,0.17,0.02,0.88,0.05,0.01,0.01
215.46410655684727,0.0180521566581399,287.595077570039,20.0,8.333333333333333e-05,0.61,0.15,0.17,0.02,0.88,0.05,0.01,0.01
219.46688547551767,0.0183857215680291,287.725392907022,20.0,8.333333333333333e-05,0.61,0.15,0.17,0.02,0.88,0.05,0.01,0.01
223.4329581861793,0.0187162276272509,287.868576579621,20.0,8.333333333333333e-05,0.61,0.15,0.17,0.02,0.88,0.05,0.01,0.01
227.37014373636967,0.0190443264231001,288.025846237288,20.0,8.333333333333333e-05,0.61,0.15,0.17,0.02,0.88,0.05,0.01,0.01
231.33715483677247,0.019374910681467,288.19522683861,20.0,8.333333333333333e-05,0.61,0.15,0.17,0.02,0.88,0.05,0.01,0.01
235.23767363711409,0.0196999539148288,288.370492726362,20.0,8.333333333333333e-05,0.61,0.15,0.17,0.02,0.88,0.05,0.01,0.01
239.0855784948073,0.0200206126529699,288.53517100114,20.0,8.333333333333333e-05,0.61,0.15,0.17,0.02,0.88,0.05,0.01,0.01
242.92519643410088,0.0203405808145777,288.684765121982,20.0,8.333333333333333e-05,0.61,0.15,0.17,0.02,0.88,0.05,0.01,0.01
246.72825992819045,0.0206575027724185,288.82846993104,20.0,8.333333333333333e-05,0.61,0.15,0.17,0.02,0.88,0.05,0.01,0.01
250.5078089455993,0.0209724651905359,288.961385901338,20.0,8.333333333333333e-05,0.61,0.15,0.17,0.02,0.88,0.05,0.01,0.01
254.27722416192128,0.0212865831252294,289.09066926292,20.0,8.333333333333333e-05,0.61,0.15,0.17,0.02,0.88,0.05,0.01,0.01
258.0032857002313,0.0215970882534219,289.215383792432,20.0,8.333333333333333e-05,0.61,0.15,0.17,0.02,0.88,0.05,0.01,0.01
261.7075785093769,0.0219057793208507,289.320506853856,20.0,8.333333333333333e-05,0.61,0.15,0.17,0.02,0.88,0.05,0.01,0.01
265.43906424388086,0.0222167364653927,289.426631511965,20.0,8.333333333333333e-05,0.61,0.15,0.17,0.02,0.88,0.05,0.01,0.01
269.1463322905117,0.0225256754692786,289.529489474014,20.0,8.333333333333333e-05,0.61,0.15,0.17,0.02,0.88,0.05,0.01,0.01
272.8266997879789,0.0228323727607342,289.633143139291,20.0,8.333333333333333e-05,0.61,0.15,0.17,0.02,0.88,0.05,0.01,0.01
276.5068914030229,0.0231390553953212,289.748088119788,20.0,8.333333333333333e-05,0.61,0.15,0.17,0.02,0.88,0.05,0.01,0.01
280.21322789742965,0.0234479167698551,289.853457656303,20.0,8.333333333333333e-05,0.61,0.15,0.17,0.02,0.88,0.05,0.01,0.01
283.91119351163525,0.0237560805710389,289.953866453917,20.0,8.333333333333333e-05,0.61,0.15,0.17,0.02,0.88,0.05,0.01,0.01
287.62218027027006,0.0240653294675918,290.053875664907,20.0,8.333333333333333e-05,0.61,0.15,0.17,0.02,0.88,0.05,0.01,0.01
291.30214157929566,0.0243719929100106,290.147607748037,20.0,8.333333333333333e-05,0.61,0.15,0.17,0.02,0.88,0.05,0.01,0.01
295.0047120645781,0.0246805404504508,290.241471436086,20.0,8.333333333333333e-05,0.61,0.15,0.17,0.02,0.88,0.05,0.01,0.01
298.7063795662945,0.0249890127422605,290.322053807564,20.0,8.333333333333333e-05,0.61,0.15,0.17,0.02,0.88,0.05,0.01,0.01
302.42100031340647,0.0252985644711865,290.390107599477,20.0,8.333333333333333e-05,0.61,0.15,0.17,0.02,0.88,0.05,0.01,0.01
306.1074988868365,0.025605772685639,290.46841012489,20.0,8.333333333333333e-05,0.61,0.15,0.17,0.02,0.88,0.05,0.01,0.01
309.8137575346441,0.0259146275729563,290.540033723327,20.0,8.333333333333333e-05,0.61,0.15,0.17,0.02,0.88,0.05,0.01,0.01
313.4766361269805,0.026219867455651,290.611568956347,20.0,8.333333333333333e-05,0.61,0.15,0.17,0.02,0.88,0.05,0.01,0.01
317.1719246347753,0.0265278081646339,290.685781962259,20.0,8.333333333333333e-05,0.61,0.15,0.17,0.02,0.88,0.05,0.01,0.01
320.84181483050764,0.0268336323476116,290.753922437611,20.0,8.333333333333333e-05,0.61,0.15,0.17,0.02,0.88,0.05,0.01,0.01
324.5327961496021,0.0271412141242028,290.820263602204,20.0,8.333333333333333e-05,0.61,0.15,0.17,0.02,0.88,0.05,0.01,0.01
328.20626112507847,0.0274473362054925,290.883833161846,20.0,8.333333333333333e-05,0.61,0.15,0.17,0.02,0.88,0.05,0.01,0.01
331.8651168417877,0.0277522408485516,290.940330437428,20.0,8.333333333333333e-05,0.61,0.15,0.17,0.02,0.88,0.05,0.01,0.01
335.5146818877973,0.0280563712690524,291.000800097002,20.0,8.333333333333333e-05,0.61,0.15,0.17,0.02,0.88,0.05,0.01,0.01
339.1494527837833,0.0283592688437179,291.066529632541,20.0,8.333333333333333e-05,0.61,0.15,0.17,0.02,0.88,0.05,0.01,0.01
342.7412991824593,0.0286585893769409,291.131177981449,20.0,8.333333333333333e-05,0.61,0.15,0.17,0.02,0.88,0.05,0.01,0.01
346.33091944259047,0.0289577243986185,291.212201020056,20.0,8.333333333333333e-05,0.61,0.15,0.17,0.02,0.88,0.05,0.01,0.01
349.88998365059047,0.0292543130826185,291.30054602698,20.0,8.333333333333333e-05,0.61,0.15,0.17,0.02,0.88,0.05,0.01,0.01
353.4528584650621,0.0295512193171578,291.388255602439,20.0,8.333333333333333e-05,0.61,0.15,0.17,0.02,0.88,0.05,0.01,0.01
357.00482123796604,0.0298472162148998,291.486045494186,20.0,8.333333333333333e-05,0.61,0.15,0.17,0.02,0.88,0.05,0.01,0.01
360.50485618584605,0.0301388857938898,291.600001132509,20.0,8.333333333333333e-05,0.61,0.15,0.17,0.02,0.88,0.05,0.01,0.01
364.07186025659286,0.0304361361331187,291.717327049068,20.0,8.333333333333333e-05,0.61,0.15,0.17,0.02,0.88,0.05,0.01,0.01
367.65470816501767,0.0307347067921541,291.846206734517,20.0,8.333333333333333e-05,0.61,0.15,0.17,0.02,0.88,0.05,0.01,0.01
371.2245344260213,0.0310321923139044,291.964637682351,20.0,8.333333333333333e-05,0.61,0.15,0.17,0.02,0.88,0.05,0.01,0.01
374.8007981846293,0.0313302142937884,292.090258800246,20.0,8.333333333333333e-05,0.61,0.15,0.17,0.02,0.88,0.05,0.01,0.01
378.3811845054121,0.0316285798205203,292.232131609599,20.0,8.333333333333333e-05,0.61,0.15,0.17,0.02,0.88,0.05,0.01,0.01
381.9549565045261,0.0319263941537798,292.385533038106,20.0,8.333333333333333e-05,0.61,0.15,0.17,0.02,0.88,0.05,0.01,0.01
385.5359552830417,0.0322248107186561,292.544028569086,20.0,8.333333333333333e-05,0.61,0.15,0.17,0.02,0.88,0.05,0.01,0.01
389.08485706896727,0.0325205525341499,292.694735680323,20.0,8.333333333333333e-05,0.61,0.15,0.17,0.02,0.88,0.05,0.01,0.01
392.58638800252805,0.0328123467786133,292.841725026688,20.0,8.333333333333333e-05,0.61,0.15,0.17,0.02,0.88,0.05,0.01,0.01
396.0845482908181,0.0331038601359708,292.984717582861,20.0,8.333333333333333e-05,0.61,0.15,0.17,0.02,0.88,0.05,0.01,0.01
399.6390820171873,0.0334000712798349,293.116232960938,20.0,8.333333333333333e-05,0.61,0.15,0.17,0.02,0.88,0.05,0.01,0.01
403.16645081827926,0.0336940186799259,293.232557560554,20.0,8.333333333333333e-05,0.61,0.15,0.17,0.02,0.88,0.05,0.01,0.01
406.6956845415373,0.0339881214901974,293.332203624933,20.0,8.333333333333333e-05,0.61,0.15,0.17,0.02,0.88,0.05,0.01,0.01
410.2113195264061,0.0342810910722698,293.411262998886,20.0,8.333333333333333e-05,0.61,0.15,0.17,0.02,0.88,0.05,0.01,0.01
413.71822623246845,0.034573333297775,293.495773216751,20.0,8.333333333333333e-05,0.61,0.15,0.17,0.02,0.88,0.05,0.01,0.01
417.24345887418485,0.0348671026845847,293.574436368659,20.0,8.333333333333333e-05,0.61,0.15,0.17,0.02,0.88,0.05,0.01,0.01
420.7511583783121,0.0351594109765953,293.652552858061,20.0,8.333333333333333e-05,0.61,0.15,0.17,0.02,0.88,0.05,0.01,0.01
424.1558675238349,0.0354431367387222,293.730988344613,20.0,8.333333333333333e-05,0.61,0.15,0.17,0.02,0.88,0.05,0.01,0.01
427.5910649658709,0.0357294031922252,293.810088492305,20.0,8.333333333333333e-05,0.61,0.15,0.17,0.02,0.88,0.05,0.01,0.01
431.0134174173949,0.0360145992298522,293.879780141159,20.0,8.333333333333333e-05,0.61,0.15,0.17,0.02,0.88,0.05,0.01,0.01
434.4500558337469,0.0363009857645482,293.953363741122,20.0,8.333333333333333e-05,0.61,0.15,0.17,0.02,0.88,0.05,0.01,0.01
437.8698547943125,0.036585969011262,294.018305845308,20.0,8.333333333333333e-05,0.61,0.15,0.17,0.02,0.88,0.05,0.01,0.01
441.28829103773046,0.0368708386982135,294.080541260951,20.0,8.333333333333333e-05,0.61,0.15,0.17,0.02,0.88,0.05,0.01,0.01
444.7247352241873,0.0371572090470849,294.145349540747,20.0,8.333333333333333e-05,0.61,0.15,0.17,0.02,0.88,0.05,0.01,0.01
448.19658692412486,0.0374465300220797,294.205049030304,20.0,8.333333333333333e-05,0.61,0.15,0.17,0.02,0.88,0.05,0.01,0.01
451.5844196571169,0.0377288494164957,294.26179645066,20.0,8.333333333333333e-05,0.61,0.15,0.17,0.02,0.88,0.05,0.01,0.01
455.0013421512973,0.0380135929576774,294.319430843003,20.0,8.333333333333333e-05,0.61,0.15,0.17,0.02,0.88,0.05,0.01,0.01
458.40724179557645,0.038297417928034,294.36936408533,20.0,8.333333333333333e-05,0.61,0.15,0.17,0.02,0.88,0.05,0.01,0.01
461.8460837903329,0.0385839880942637,294.416357628495,20.0,8.333333333333333e-05,0.61,0.15,0.17,0.02,0.88,0.05,0.01,0.01
465.28590514464247,0.0388706398737895,294.468504755023,20.0,8.333333333333333e-05,0.61,0.15,0.17,0.02,0.88,0.05,0.01,0.01
468.7373261489316,0.0391582582908136,294.520671404776,20.0,8.333333333333333e-05,0.61,0.15,0.17,0.02,0.88,0.05,0.01,0.01
472.1600476913509,0.0394434850860152,294.579743754892,20.0,8.333333333333333e-05,0.61,0.15,0.17,0.02,0.88,0.05,0.01,0.01
475.6542722157625,0.0397346704630495,294.637670933369,20.0,8.333333333333333e-05,0.61,0.15,0.17,0.02,0.88,0.05,0.01,0.01
479.1481559339725,0.040025827439567,294.696479212702,20.0,8.333333333333333e-05,0.61,0.15,0.17,0.02,0.88,0.05,0.01,0.01
482.6384658421825,0.0403166865985845,294.758107237514,20.0,8.333333333333333e-05,0.61,0.15,0.17,0.02,0.88,0.05,0.01,0.01
486.09048514586055,0.040604354873891,294.821450849226,20.0,8.333333333333333e-05,0.61,0.15,0.17,0.02,0.88,0.05,0.01,0.01
489.5482176747985,0.0408924992513025,294.878969969464,20.0,8.333333333333333e-05,0.61,0.15,0.17,0.02,0.88,0.05,0.01,0.01
492.96945761373007,0.0411776025795468,294.930690915881,20.0,8.333333333333333e-05,0.61,0.15,0.17,0.02,0.88,0.05,0.01,0.01
496.368638406018,0.0414608676455708,294.977971781897,20.0,8.333333333333333e-05,0.61,0.15,0.17,0.02,0.88,0.05,0.01,0.01
499.7088762429985,0.0417392207986525,295.024010389222,20.0,8.333333333333333e-05,0.61,0.15,0.17,0.02,0.88,0.05,0.01,0.01
503.01510196725366,0.0420147396090071,295.072946992215,20.0,8.333333333333333e-05,0.61,0.15,0.17,0.02,0.88,0.05,0.01,0.01
506.3274712880125,0.042290770385737,295.120131752741,20.0,8.333333333333333e-05,0.61,0.15,0.17,0.02,0.88,0.05,0.01,0.01
509.6707988603461,0.0425693810167648,295.168625656444,20.0,8.333333333333333e-05,0.61,0.15,0.17,0.02,0.88,0.05,0.01,0.01
512.9976677250156,0.0428466200888206,295.219960221509,20.0,8.333333333333333e-05,0.61,0.15,0.17,0.02,0.88,0.05,0.01,0.01
516.3771063085644,0.043128239970783,295.273716802097,20.0,8.333333333333333e-05,0.61,0.15,0.17,0.02,0.88,0.05,0.01,0.01
519.7626041470633,0.0434103647906579,295.337170418149,20.0,8.333333333333333e-05,0.61,0.15,0.17,0.02,0.88,0.05,0.01,0.01
523.2305282956404,0.043699358469706,295.404914247006,20.0,8.333333333333333e-05,0.61,0.15,0.17,0.02,0.88,0.05,0.01,0.01
526.683936509664,0.0439871424875413,295.4710723443,20.0,8.333333333333333e-05,0.61,0.15,0.17,0.02,0.88,0.05,0.01,0.01
530.1360490265856,0.0442748185306181,295.54725174258,20.0,8.333333333333333e-05,0.61,0.15,0.17,0.02,0.88,0.05,0.01,0.01
533.5562636790048,0.0445598364183197,295.653612455479,20.0,8.333333333333333e-05,0.61,0.15,0.17,0.02,0.88,0.05,0.01,0.01
536.999806040328,0.0448467982817633,295.754478912986,20.0,8.333333333333333e-05,0.61,0.15,0.17,0.02,0.88,0.05,0.01,0.01
540.3864754549668,0.0451290207329832,295.871933324315,20.0,8.333333333333333e-05,0.61,0.15,0.17,0.02,0.88,0.05,0.01,0.01
543.7915755830101,0.0454127790769868,296.011078264957,20.0,8.333333333333333e-05,0.61,0.15,0.17,0.02,0.88,0.05,0.01,0.01
547.1422972378381,0.0456920058815558,296.157421939049,20.0,8.333333333333333e-05,0.61,0.15,0.17,0.02,0.88,0.05,0.01,0.01
550.522599999672,0.0459736977783753,296.326591757708,20.0,8.333333333333333e-05,0.61,0.15,0.17,0.02,0.88,0.05,0.01,0.01
553.887945967866,0.0462541432757248,296.511420826191,20.0,8.333333333333333e-05,0.61,0.15,0.17,0.02,0.88,0.05,0.01,0.01
557.286874323756,0.0465373873053823,296.683971583542,20.0,8.333333333333333e-05,0.61,0.15,0.17,0.02,0.88,0.05,0.01,0.01
560.6837253364885,0.04682045822311,296.860372977444,20.0,8.333333333333333e-05,0.61,0.15,0.17,0.02,0.88,0.05,0.01,0.01
564.0849700900045,0.047103895285903,297.020527405953,20.0,8.333333333333333e-05,0.61,0.15,0.17,0.02,0.88,0.05,0.01,0.01
567.4775089509131,0.0473866068576454,297.15445301573,20.0,8.333333333333333e-05,0.61,0.15,0.17,0.02,0.88,0.05,0.01,0.01
570.9078712314877,0.0476724703810266,297.282445907348,20.0,8.333333333333333e-05,0.61,0.15,0.17,0.02,0.88,0.05,0.01,0.01
574.357491340578,0.0479599387234508,297.391642920618,20.0,8.333333333333333e-05,0.61,0.15,0.17,0.02,0.88,0.05,0.01,0.01
577.7999658294252,0.0482468115975214,297.478190879759,20.0,8.333333333333333e-05,0.61,0.15,0.17,0.02,0.88,0.05,0.01,0.01
581.2202439186228,0.0485318347716212,297.545494791486,20.0,8.333333333333333e-05,0.61,0.15,0.17,0.02,0.88,0.05,0.01,0.01
584.6470067900773,0.0488173983442424,297.608431761823,20.0,8.333333333333333e-05,0.61,0.15,0.17,0.02,0.88,0.05,0.01,0.01
588.0853626603792,0.0491039280001009,297.664643045338,20.0,8.333333333333333e-05,0.61,0.15,0.17,0.02,0.88,0.05,0.01,0.01
591.5348199454477,0.0493913827738566,297.713145599066,20.0,8.333333333333333e-05,0.61,0.15,0.17,0.02,0.88,0.05,0.01,0.01
594.9574611920244,0.049676602877738,297.757919857038,20.0,8.333333333333333e-05,0.61,0.15,0.17,0.02,0.88,0.05,0.01,0.01
598.3601026845024,0.0499601563354445,297.798464061134,20.0,8.333333333333333e-05,0.61,0.15,0.17,0.02,0.88,0.05,0.01,0.01
601.8172871120232,0.0502482550377379,297.837667673353,20.0,8.333333333333333e-05,0.61,0.15,0.17,0.02,0.88,0.05,0.01,0.01
605.2735864758732,0.0505362799847254,297.877017386883,20.0,8.333333333333333e-05,0.61,0.15,0.17,0.02,0.88,0.05,0.01,0.01
608.7179579326776,0.0508233109394591,297.923651119896,20.0,8.333333333333333e-05,0.61,0.15,0.17,0.02,0.88,0.05,0.01,0.01
612.1542819899221,0.0511096712775628,297.978187785111,20.0,8.333333333333333e-05,0.61,0.15,0.17,0.02,0.88,0.05,0.01,0.01
615.6009834456072,0.0513968963988699,298.040897379374,20.0,8.333333333333333e-05,0.61,0.15,0.17,0.02,0.88,0.05,0.01,0.01
619.0501154321173,0.0516843240644124,298.106309059306,20.0,8.333333333333333e-05,0.61,0.15,0.17,0.02,0.88,0.05,0.01,0.01
622.5126235385748,0.0519728664066172,298.171105930539,20.0,8.333333333333333e-05,0.61,0.15,0.17,0.02,0.88,0.05,0.01,0.01
625.9456581205417,0.0522589526217811,298.244780582987,20.0,8.333333333333333e-05,0.61,0.15,0.17,0.02,0.88,0.05,0.01,0.01
629.40709975377,0.0525474060912168,298.316847007231,20.0,8.333333333333333e-05,0.61,0.15,0.17,0.02,0.88,0.05,0.01,0.01
632.8269314414052,0.0528323920651864,298.388358787636,20.0,8.333333333333333e-05,0.61,0.15,0.17,0.02,0.88,0.05,0.01,0.01
636.2670979015213,0.0531190726035294,298.45557648488,20.0,8.333333333333333e-05,0.61,0.15,0.17,0.02,0.88,0.05,0.01,0.01
639.719282601252,0.0534067546618403,298.521514386594,20.0,8.333333333333333e-05,0.61,0.15,0.17,0.02,0.88,0.05,0.01,0.01
643.190084103306,0.0536959881203448,298.592525135907,20.0,8.333333333333333e-05,0.61,0.15,0.17,0.02,0.88,0.05,0.01,0.01
646.6590393343153,0.0539850677229289,298.668725199616,20.0,8.333333333333333e-05,0.61,0.15,0.17,0.02,0.88,0.05,0.01,0.01
650.1383703821821,0.0542750119769178,298.740249002928,20.0,8.333333333333333e-05,0.61,0.15,0.17,0.02,0.88,0.05,0.01,0.01
653.6447468072365,0.054567210012339,298.815885114935,20.0,8.333333333333333e-05,0.61,0.15,0.17,0.02,0.88,0.05,0.01,0.01
657.1885235063809,0.0548625247372677,298.893488369067,20.0,8.333333333333333e-05,0.61,0.15,0.17,0.02,0.88,0.05,0.01,0.01
660.730769395458,0.0551577118946908,298.978248430301,20.0,8.333333333333333e-05,0.61,0.15,0.17,0.02,0.88,0.05,0.01,0.01
664.2709685776008,0.0554527284932027,299.065669733879,20.0,8.333333333333333e-05,0.61,0.15,0.17,0.02,0.88,0.05,0.01,0.01
667.7928563773272,0.0557462191431799,299.152651472839,20.0,8.333333333333333e-05,0.61,0.15,0.17,0.02,0.88,0.05,0.01,0.01
671.299530666798,0.0560384420006358,299.241811667551,20.0,8.333333333333333e-05,0.61,0.15,0.17,0.02,0.88,0.05,0.01,0.01
674.8109504294484,0.05633106031419,299.330841275668,20.0,8.333333333333333e-05,0.61,0.15,0.17,0.02,0.88,0.05,0.01,0.01
678.2945572861609,0.0566213608855827,299.42233121921,20.0,8.333333333333333e-05,0.61,0.15,0.17,0.02,0.88,0.05,0.01,0.01
681.7787744052588,0.0569117123121742,299.512062561359,20.0,8.333333333333333e-05,0.61,0.15,0.17,0.02,0.88,0.05,0.01,0.01
685.2888480929197,0.0572042184528126,299.602401065095,20.0,8.333333333333333e-05,0.61,0.15,0.17,0.02,0.88,0.05,0.01,0.01
688.8014002253605,0.057496931130516,299.689156807994,20.0,8.333333333333333e-05,0.61,0.15,0.17,0.02,0.88,0.05,0.01,0.01
692.3221183768477,0.0577903243098066,299.769924097403,20.0,8.333333333333333e-05,0.61,0.15,0.17,0.02,0.88,0.05,0.01,0.01
695.8574739760093,0.0580849372764034,299.842990638235,20.0,8.333333333333333e-05,0.61,0.15,0.17,0.02,0.88,0.05,0.01,0.01
699.4239775816225,0.0583821459102045,299.915033404808,20.0,8.333333333333333e-05,0.61,0.15,0.17,0.02,0.88,0.05,0.01,0.01
702.9942064499256,0.0586796649825631,299.984583932185,20.0,8.333333333333333e-05,0.61,0.15,0.17,0.02,0.88,0.05,0.01,0.01
706.5780670351609,0.0589783200313327,300.04959922757,20.0,8.333333333333333e-05,0.61,0.15,0.17,0.02,0.88,0.05,0.01,0.01
710.1441487143336,0.0592754935045971,300.114544977851,20.0,8.333333333333333e-05,0.61,0.15,0.17,0.02,0.88,0.05,0.01,0.01
713.7222413449405,0.059573667890481,300.183202035366,20.0,8.333333333333333e-05,0.61,0.15,0.17,0.02,0.88,0.05,0.01,0.01
717.3005448845904,0.0598718598521185,300.25371967006,20.0,8.333333333333333e-05,0.61,0.15,0.17,0.02,0.88,0.05,0.01,0.01
720.8821150878624,0.0601703240357245,300.325537875506,20.0,8.333333333333333e-05,0.61,0.15,0.17,0.02,0.88,0.05,0.01,0.01
724.4326298106721,0.0604662002626253,300.396172817084,20.0,8.333333333333333e-05,0.61,0.15,0.17,0.02,0.88,0.05,0.01,0.01
727.9804409431837,0.0607618511903346,300.463575799972,20.0,8.333333333333333e-05,0.61,0.15,0.17,0.02,0.88,0.05,0.01,0.01
731.5019835981876,0.0610553130782516,300.528819234508,20.0,8.333333333333333e-05,0.61,0.15,0.17,0.02,0.88,0.05,0.01,0.01
735.0525875019408,0.0613511967368977,300.58370003655,20.0,8.333333333333333e-05,0.61,0.15,0.17,0.02,0.88,0.05,0.01,0.01
738.5757598464623,0.0616447944322745,300.637710147612,20.0,8.333333333333333e-05,0.61,0.15,0.17,0.02,0.88,0.05,0.01,0.01
742.1022908968368,0.0619386720198057,300.686516597404,20.0,8.333333333333333e-05,0.61,0.15,0.17,0.02,0.88,0.05,0.01,0.01
745.6155280863649,0.0622314417855997,300.739586434236,20.0,8.333333333333333e-05,0.61,0.15,0.17,0.02,0.88,0.05,0.01,0.01
749.1717701430265,0.0625277952903215,300.793307392616,20.0,8.333333333333333e-05,0.61,0.15,0.17,0.02,0.88,0.05,0.01,0.01
752.6947970672137,0.0628213808673371,300.85439389461,20.0,8.333333333333333e-05,0.61,0.15,0.17,0.02,0.88,0.05,0.01,0.01
756.2622646503985,0.0631186698326025,300.920953919957,20.0,8.333333333333333e-05,0.61,0.15,0.17,0.02,0.88,0.05,0.01,0.01
759.8246506072093,0.0634155353290034,300.988124783276,20.0,8.333333333333333e-05,0.61,0.15,0.17,0.02,0.88,0.05,0.01,0.01
763.4310179967756,0.0637160659448006,301.05141995227,20.0,8.333333333333333e-05,0.61,0.15,0.17,0.02,0.88,0.05,0.01,0.01
767.066205389622,0.0640189982275378,301.113909005803,20.0,8.333333333333333e-05,0.61,0.15,0.17,0.02,0.88,0.05,0.01,0.01
770.7248987166121,0.0643238893381203,301.166615229322,20.0,8.333333333333333e-05,0.61,0.15,0.17,0.02,0.88,0.05,0.01,0.01
774.3406064694385,0.0646251983175225,301.216180075279,20.0,8.333333333333333e-05,0.61,0.15,0.17,0.02,0.88,0.05,0.01,0.01
778.0142024725368,0.0649313313177807,301.264716680741,20.0,8.333333333333333e-05,0.61,0.15,0.17,0.02,0.88,0.05,0.01,0.01
781.7046873722101,0.0652388717260868,301.307172021205,20.0,8.333333333333333e-05,0.61,0.15,0.17,0.02,0.88,0.05,0.01,0.01
785.4157839324432,0.0655481297727729,301.34961074759,20.0,8.333333333333333e-05,0.61,0.15,0.17,0.02,0.88,0.05,0.01,0.01
789.103523577318,0.0658554414098458,301.390759529304,20.0,8.333333333333333e-05,0.61,0.15,0.17,0.02,0.88,0.05,0.01,0.01
792.8005447716516,0.0661635265093736,301.432980379826,20.0,8.333333333333333e-05,0.61,0.15,0.17,0.02,0.88,0.05,0.01,0.01
796.4967486579312,0.0664715434998969,301.481099247779,20.0,8.333333333333333e-05,0.61,0.15,0.17,0.02,0.88,0.05,0.01,0.01
800.2286343556909,0.0667825339747102,301.531304072757,20.0,8.333333333333333e-05,0.61,0.15,0.17,0.02,0.88,0.05,0.01,0.01
803.9629619250888,0.0670937279388267,301.580620905389,20.0,8.333333333333333e-05,0.61,0.15,0.17,0.02,0.88,0.05,0.01,0.01
807.6801925652005,0.067403497158836,301.630670724717,20.0,8.333333333333333e-05,0.61,0.15,0.17,0.02,0.88,0.05,0.01,0.01
811.3925300928707,0.0677128586194752,301.68289750526,20.0,8.333333333333333e-05,0.61,0.15,0.17,0.02,0.88,0.05,0.01,0.01
815.1148675073556,0.0680230534040156,301.732322449204,20.0,8.333333333333333e-05,0.61,0.15,0.17,0.02,0.88,0.05,0.01,0.01
818.8322722102428,0.0683328371292562,301.782300737958,20.0,8.333333333333333e-05,0.61,0.15,0.17,0.02,0.88,0.05,0.01,0.01
822.569403649092,0.0686442647491603,301.831051979406,20.0,8.333333333333333e-05,0.61,0.15,0.17,0.02,0.88,0.05,0.01,0.01
826.312287768942,0.0689561717591478,301.877904844643,20.0,8.333333333333333e-05,0.61,0.15,0.17,0.02,0.88,0.05,0.01,0.01
830.0306218113997,0.0692660329293526,301.918851781441,20.0,8.333333333333333e-05,0.61,0.15,0.17,0.02,0.88,0.05,0.01,0.01
833.7600990326089,0.0695768226977867,301.961886023787,20.0,8.333333333333333e-05,0.61,0.15,0.17,0.02,0.88,0.05,0.01,0.01
837.4671239987435,0.0698857414449646,302.004191744052,20.0,8.333333333333333e-05,0.61,0.15,0.17,0.02,0.88,0.05,0.01,0.01
841.1969953519285,0.07019656405773,302.045361591684,20.0,8.333333333333333e-05,0.61,0.15,0.17,0.02,0.88,0.05,0.01,0.01
844.8896690209056,0.0705042868634781,302.087888397034,20.0,8.333333333333333e-05,0.61,0.15,0.17,0.02,0.88,0.05,0.01,0.01
848.585854520796,0.0708123023218023,302.133310845695,20.0,8.333333333333333e-05,0.61,0.15,0.17,0.02,0.88,0.05,0.01,0.01
852.2834811770401,0.0711204378764893,302.177354888112,20.0,8.333333333333333e-05,0.61,0.15,0.17,0.02,0.88,0.05,0.01,0.01
856.0109942363077,0.0714310639647616,302.227121828106,20.0,8.333333333333333e-05,0.61,0.15,0.17,0.02,0.88,0.05,0.01,0.01
859.728389025708,0.0717408468638783,302.27272331854,20.0,8.333333333333333e-05,0.61,0.15,0.17,0.02,0.88,0.05,0.01,0.01
863.4937703076037,0.0720546286373696,302.316282605917,20.0,8.333333333333333e-05,0.61,0.15,0.17,0.02,0.88,0.05,0.01,0.01
867.2578012759249,0.0723682978847297,302.36482104024,20.0,8.333333333333333e-05,0.61,0.15,0.17,0.02,0.88,0.05,0.01,0.01
871.0689069720817,0.0726858900260761,302.419577734882,20.0,8.333333333333333e-05,0.61,0.15,0.17,0.02,0.88,0.05,0.01,0.01
874.911872013804,0.0730061371128863,302.467706084901,20.0,8.333333333333333e-05,0.61,0.15,0.17,0.02,0.88,0.05,0.01,0.01
878.7556862619037,0.0733264549668946,302.513272564073,20.0,8.333333333333333e-05,0.61,0.15,0.17,0.02,0.88,0.05,0.01,0.01
882.6245967276769,0.0736488641723757,302.551890413549,20.0,8.333333333333333e-05,0.61,0.15,0.17,0.02,0.88,0.05,0.01,0.01
886.5167186300304,0.0739732076642385,302.591923368513,20.0,8.333333333333333e-05,0.61,0.15,0.17,0.02,0.88,0.05,0.01,0.01
890.4027313180188,0.0742970420549042,302.635309702492,20.0,8.333333333333333e-05,0.61,0.15,0.17,0.02,0.88,0.05,0.01,0.01
894.3130142800752,0.0746228989684089,302.674672630152,20.0,8.333333333333333e-05,0.61,0.15,0.17,0.02,0.88,0.05,0.01,0.01
898.2411756610979,0.0749502457501608,302.706294955544,20.0,8.333333333333333e-05,0.61,0.15,0.17,0.02,0.88,0.05,0.01,0.01
902.2049464928004,0.075280559986136,302.736403218856,20.0,8.333333333333333e-05,0.61,0.15,0.17,0.02,0.88,0.05,0.01,0.01
906.1928935086,0.0756128889041193,302.769938784218,20.0,8.333333333333333e-05,0.61,0.15,0.17,0.02,0.88,0.05,0.01,0.01
910.1854495211448,0.0759456019051647,302.806170902842,20.0,8.333333333333333e-05,0.61,0.15,0.17,0.02,0.88,0.05,0.01,0.01
914.1802379279808,0.0762785009390677,302.844460471947,20.0,8.333333333333333e-05,0.61,0.15,0.17,0.02,0.88,0.05,0.01,0.01
918.174387428064,0.0766113467307413,302.883227934599,20.0,8.333333333333333e-05,0.61,0.15,0.17,0.02,0.88,0.05,0.01,0.01
922.1671239498636,0.0769440747742246,302.928293814339,20.0,8.333333333333333e-05,0.61,0.15,0.17,0.02,0.88,0.05,0.01,0.01
926.1765473077968,0.0772781933873857,302.970899938902,20.0,8.333333333333333e-05,0.61,0.15,0.17,0.02,0.88,0.05,0.01,0.01
930.1437778569878,0.0776087959331516,303.015874693942,20.0,8.333333333333333e-05,0.61,0.15,0.17,0.02,0.88,0.05,0.01,0.01
934.0903463179776,0.0779376766382341,303.057624583439,20.0,8.333333333333333e-05,0.61,0.15,0.17,0.02,0.88,0.05,0.01,0.01
938.0250602782116,0.0782655694682536,303.097240575271,20.0,8.333333333333333e-05,0.61,0.15,0.17,0.02,0.88,0.05,0.01,0.01
941.9796169082196,0.0785951158540876,303.135011472186,20.0,8.333333333333333e-05,0.61,0.15,0.17,0.02,0.88,0.05,0.01,0.01
945.9538331885605,0.078926300544116,303.167997107877,20.0,8.333333333333333e-05,0.61,0.15,0.17,0.02,0.88,0.05,0.01,0.01
949.9486721296608,0.0792592037892077,303.193165279396,20.0,8.333333333333333e-05,0.61,0.15,0.17,0.02,0.88,0.05,0.01,0.01
953.9389513608456,0.0795917270584731,303.216735371152,20.0,8.333333333333333e-05,0.61,0.15,0.17,0.02,0.88,0.05,0.01,0.01
957.963146178462,0.0799270766266078,303.23977480767,20.0,8.333333333333333e-05,0.61,0.15,0.17,0.02,0.88,0.05,0.01,0.01
962.0442003676644,0.080267164475708,303.264362194931,20.0,8.333333333333333e-05,0.61,0.15,0.17,0.02,0.88,0.05,0.01,0.01
966.1304586636828,0.0806076860003762,303.289301868598,20.0,8.333333333333333e-05,0.61,0.15,0.17,0.02,0.88,0.05,0.01,0.01
970.236217691178,0.0809498325860008,303.312086677614,20.0,8.333333333333333e-05,0.61,0.15,0.17,0.02,0.88,0.05,0.01,0.01
974.3395578948252,0.0812917776029714,303.335821597811,20.0,8.333333333333333e-05,0.61,0.15,0.17,0.02,0.88,0.05,0.01,0.01
978.4326619706484,0.08163286960929,303.35754121178,20.0,8.333333333333333e-05,0.61,0.15,0.17,0.02,0.88,0.05,0.01,0.01
982.5416998919136,0.0819752894360621,303.381653906492,20.0,8.333333333333333e-05,0.61,0.15,0.17,0.02,0.88,0.05,0.01,0.01
986.6483896453068,0.0823175135821782,303.408334129687,20.0,8.333333333333333e-05,0.61,0.15,0.17,0.02,0.88,0.05,0.01,0.01
990.7588296289812,0.0826600502474844,303.433517874741,20.0,8.333333333333333e-05,0.61,0.15,0.17,0.02,0.88,0.05,0.01,0.01
994.887573758766,0.0830041122582998,303.459041954362,20.0,8.333333333333333e-05,0.61,0.15,0.17,0.02,0.88,0.05,0.01,0.01
999.0623848010736,0.0833520131784921,303.490632274446,20.0,8.333333333333333e-05,0.61,0.15,0.17,0.02,0.88,0.05,0.01,0.01
1003.2592832504916,0.0837017547159436,303.520629449986,20.0,8.333333333333333e-05,0.61,0.15,0.17,0.02,0.88,0.05,0.01,0.01
1007.5175181319152,0.0840566076227289,303.552672653355,20.0,8.333333333333333e-05,0.61,0.15,0.17,0.02,0.88,0.05,0.01,0.01
1011.7761078195804,0.084411490096701,303.587477604192,20.0,8.333333333333333e-05,0.61,0.15,0.17,0.02,0.88,0.05,0.01,0.01
1016.0618491980612,0.0847686352115744,303.620872354818,20.0,8.333333333333333e-05,0.61,0.15,0.17,0.02,0.88,0.05,0.01,0.01
1020.3562669328712,0.0851265033561419,303.65655366128,20.0,8.333333333333333e-05,0.61,0.15,0.17,0.02,0.88,0.05,0.01,0.01
1024.6619738109,0.0854853122626443,303.69261300484,20.0,8.333333333333333e-05,0.61,0.15,0.17,0.02,0.88,0.05,0.01,0.01
1028.9064751629348,0.0858390207086472,303.722454352349,20.0,8.333333333333333e-05,0.61,0.15,0.17,0.02,0.88,0.05,0.01,0.01
1033.1448371505624,0.0861922175409495,303.757867556631,20.0,8.333333333333333e-05,0.61,0.15,0.17,0.02,0.88,0.05,0.01,0.01
1037.35923577629,0.0865434174264268,303.794079185166,20.0,8.333333333333333e-05,0.61,0.15,0.17,0.02,0.88,0.05,0.01,0.01
1041.597310372459,0.0868965903094409,303.832835522005,20.0,8.333333333333333e-05,0.61,0.15,0.17,0.02,0.88,0.05,0.01,0.01
1045.8407682531576,0.0872502117994991,303.871817472213,20.0,8.333333333333333e-05,0.61,0.15,0.17,0.02,0.88,0.05,0.01,0.01
1050.114501220044,0.0876063562134063,303.914345000108,20.0,8.333333333333333e-05,0.61,0.15,0.17,0.02,0.88,0.05,0.01,0.01
1054.3895151700715,0.0879626073759086,303.959528111663,20.0,8.333333333333333e-05,0.61,0.15,0.17,0.02,0.88,0.05,0.01,0.01
1058.7555426055633,0.0883264429955329,304.009364737074,20.0,8.333333333333333e-05,0.61,0.15,0.17,0.02,0.88,0.05,0.01,0.01
1063.1777281059071,0.0886949584538949,304.059489156778,20.0,8.333333333333333e-05,0.61,0.15,0.17,0.02,0.88,0.05,0.01,0.01
1067.6674369906716,0.0890691008609586,304.112348845287,20.0,8.333333333333333e-05,0.61,0.15,0.17,0.02,0.88,0.05,0.01,0.01
1072.172251781563,0.0894445020935329,304.161666665197,20.0,8.333333333333333e-05,0.61,0.15,0.17,0.02,0.88,0.05,0.01,0.01
1076.71648337565,0.0898231880597068,304.21181155018,20.0,8.333333333333333e-05,0.61,0.15,0.17,0.02,0.88,0.05,0.01,0.01
1081.2568660221589,0.0902015532802492,304.255784902061,20.0,8.333333333333333e-05,0.61,0.15,0.17,0.02,0.88,0.05,0.01,0.01
1085.8692152716478,0.0905859157177066,304.296619059697,20.0,8.333333333333333e-05,0.61,0.15,0.17,0.02,0.88,0.05,0.01,0.01
1090.4937182764895,0.0909712909681101,304.336678625208,20.0,8.333333333333333e-05,0.61,0.15,0.17,0.02,0.88,0.05,0.01,0.01
1095.13424303655,0.0913580013647818,304.38494607443,20.0,8.333333333333333e-05,0.61,0.15,0.17,0.02,0.88,0.05,0.01,0.01
1099.7523765271442,0.0917428458223313,304.467620526287,20.0,8.333333333333333e-05,0.61,0.15,0.17,0.02,0.88,0.05,0.01,0.01
1104.40632047025,0.0921306744842568,304.521240397452,20.0,8.333333333333333e-05,0.61,0.15,0.17,0.02,0.88,0.05,0.01,0.01
1109.0791022371584,0.0925200729648325,304.566442471555,20.0,8.333333333333333e-05,0.61,0.15,0.17,0.02,0.88,0.05,0.01,0.01
1113.7561586264196,0.0929098276639376,304.609663760364,20.0,8.333333333333333e-05,0.61,0.15,0.17,0.02,0.88,0.05,0.01,0.01
1118.4144011767717,0.0932980145431336,304.658203499654,20.0,8.333333333333333e-05,0.61,0.15,0.17,0.02,0.88,0.05,0.01,0.01
1123.0723049274648,0.0936861731890247,304.707011941395,20.0,8.333333333333333e-05,0.61,0.15,0.17,0.02,0.88,0.05,0.01,0.01
1127.713370122679,0.0940729286219592,304.743333329536,20.0,8.333333333333333e-05,0.61,0.15,0.17,0.02,0.88,0.05,0.01,0.01