File: datasets/al_6061_comp/csv/T_020_A_2.csv
Time,Strain(%),Stress(MPa),Temp(C),SR(%/s),Si(%),Fe(%),Cu(%),Mn(%),Mg(%),Cr(%),Zn(%),Ti(%)
0.0,0.000101568440273,24.5426970366831,20.0,8.333333333333333e-05,0.56,0.23,0.18,0.07,0.86,0.06,0.02,0.01
1.0578040143324,0.0001897187748007,30.7051544939357,20.0,8.333333333333333e-05,0.56,0.23,0.18,0.07,0.86,0.06,0.02,0.01
2.179147425018,0.0002831640590245,37.0730063026533,20.0,8.333333333333333e-05,0.56,0.23,0.18,0.07,0.86,0.06,0.02,0.01
3.2315484212388004,0.0003708641420429,43.5322459770351,20.0,8.333333333333333e-05,0.56,0.23,0.18,0.07,0.86,0.06,0.02,0.01
4.5572270456628,0.0004813373607449,50.0714465034105,20.0,8.333333333333333e-05,0.56,0.23,0.18,0.07,0.86,0.06,0.02,0.01
5.7657665248728005,0.0005820489840124,56.694078064152,20.0,8.333333333333333e-05,0.56,0.23,0.18,0.07,0.86,0.06,0.02,0.01
7.0516684281408,0.0006892074759514,63.3252300874686,20.0,8.333333333333333e-05,0.56,0.23,0.18,0.07,0.86,0.06,0.02,0.01
8.4895031124108,0.0008090270329739,69.9526818148845,20.0,8.333333333333333e-05,0.56,0.23,0.18,0.07,0.86,0.06,0.02,0.01
9.7599340324872,0.0009148962763136,76.6549735048416,20.0,8.333333333333333e-05,0.56,0.23,0.18,0.07,0.86,0.06,0.02,0.01
11.2982655521592,0.0010430905696196,83.3748887794096,20.0,8.333333333333333e-05,0.56,0.23,0.18,0.07,0.86,0.06,0.02,0.01
12.711569979659998,0.001160865938578,90.2011502996086,20.0,8.333333333333333e-05,0.56,0.23,0.18,0.07,0.86,0.06,0.02,0.01
14.189642216832,0.001284038625009,96.9930838458363,20.0,8.333333333333333e-05,0.56,0.23,0.18,0.07,0.86,0.06,0.02,0.01
15.682661300227204,0.0014084568819586,103.719418848853,20.0,8.333333333333333e-05,0.56,0.23,0.18,0.07,0.86,0.06,0.02,0.01
17.1144325713156,0.0015277711545493,110.390173042397,20.0,8.333333333333333e-05,0.56,0.23,0.18,0.07,0.86,0.06,0.02,0.01
18.5528032721772,0.0016476353796211,116.947652649312,20.0,8.333333333333333e-05,0.56,0.23,0.18,0.07,0.86,0.06,0.02,0.01
19.9135429169172,0.0017610303500161,123.506880654231,20.0,8.333333333333333e-05,0.56,0.23,0.18,0.07,0.86,0.06,0.02,0.01
21.3431770727604,0.0018801665296697,129.939871408534,20.0,8.333333333333333e-05,0.56,0.23,0.18,0.07,0.86,0.06,0.02,0.01
22.766517401214003,0.0019987782237075,136.371846696917,20.0,8.333333333333333e-05,0.56,0.23,0.18,0.07,0.86,0.06,0.02,0.01
24.1204854134088,0.0021116088913904,142.683921232984,20.0,8.333333333333333e-05,0.56,0.23,0.18,0.07,0.86,0.06,0.02,0.01
25.5409967474496,0.0022299848358938,148.91474067775,20.0,8.333333333333333e-05,0.56,0.23,0.18,0.07,0.86,0.06,0.02,0.01
26.8340632887396,0.0023377403810013,154.976005234871,20.0,8.333333333333333e-05,0.56,0.23,0.18,0.07,0.86,0.06,0.02,0.01
28.1522235037536,0.0024475870655858,160.948206979988,20.0,8.333333333333333e-05,0.56,0.23,0.18,0.07,0.86,0.06,0.02,0.01
29.4754883165928,0.0025578591333224,166.843459458492,20.0,8.333333333333333e-05,0.56,0.23,0.18,0.07,0.86,0.06,0.02,0.01
30.788845863861603,0.0026673055955948,172.751575973983,20.0,8.333333333333333e-05,0.56,0.23,0.18,0.07,0.86,0.06,0.02,0.01
32.117921156937605,0.0027780618700178,178.57375210727,20.0,8.333333333333333e-05,0.56,0.23,0.18,0.07,0.86,0.06,0.02,0.01
33.3225328696344,0.0028784461794092,184.332980279823,20.0,8.333333333333333e-05,0.56,0.23,0.18,0.07,0.86,0.06,0.02,0.01
34.6719635813316,0.0029908987387173,190.042702394731,20.0,8.333333333333333e-05,0.56,0.23,0.18,0.07,0.86,0.06,0.02,0.01
36.0367131875976,0.0031046278725728,195.708097216822,20.0,8.333333333333333e-05,0.56,0.23,0.18,0.07,0.86,0.06,0.02,0.01
37.529259854064,0.003229006761445,201.286574021208,20.0,8.333333333333333e-05,0.56,0.23,0.18,0.07,0.86,0.06,0.02,0.01
38.8424947883892,0.0033384430059721,206.74967831307,20.0,8.333333333333333e-05,0.56,0.23,0.18,0.07,0.86,0.06,0.02,0.01
40.1652389738016,0.0034486716880898,212.076660252993,20.0,8.333333333333333e-05,0.56,0.23,0.18,0.07,0.86,0.06,0.02,0.01
41.4252195947448,0.0035536700731684,217.324191180056,20.0,8.333333333333333e-05,0.56,0.23,0.18,0.07,0.86,0.06,0.02,0.01
42.8861210629596,0.0036754118621863,222.418051201976,20.0,8.333333333333333e-05,0.56,0.23,0.18,0.07,0.86,0.06,0.02,0.01
44.3606111949252,0.0037982860398501,227.379395721559,20.0,8.333333333333333e-05,0.56,0.23,0.18,0.07,0.86,0.06,0.02,0.01
45.93701176381081,0.0039296527539239,232.149404861122,20.0,8.333333333333333e-05,0.56,0.23,0.18,0.07,0.86,0.06,0.02,0.01
47.7513570464568,0.0040808481941444,236.736838783488,20.0,8.333333333333333e-05,0.56,0.23,0.18,0.07,0.86,0.06,0.02,0.01
49.8541898315136,0.0042560842595658,240.992340574665,20.0,8.333333333333333e-05,0.56,0.23,0.18,0.07,0.86,0.06,0.02,0.01
52.60505172200641,0.0044853227504402,244.739488432025,20.0,8.333333333333333e-05,0.56,0.23,0.18,0.07,0.86,0.06,0.02,0.01
55.978431129282,0.0047664377010465,247.750096242013,20.0,8.333333333333333e-05,0.56,0.23,0.18,0.07,0.86,0.06,0.02,0.01
59.924068319676,0.005095240800246,249.934862912635,20.0,8.333333333333333e-05,0.56,0.23,0.18,0.07,0.86,0.06,0.02,0.01
64.20944391419759,0.0054523554331228,251.381278695098,20.0,8.333333333333333e-05,0.56,0.23,0.18,0.07,0.86,0.06,0.02,0.01
68.68682051381761,0.0058254701497578,252.315694879226,20.0,8.333333333333333e-05,0.56,0.23,0.18,0.07,0.86,0.06,0.02,0.01
73.3051212402168,0.0062103285436244,252.958267297516,20.0,8.333333333333333e-05,0.56,0.23,0.18,0.07,0.86,0.06,0.02,0.01
77.985728531544,0.006600379151235,253.442938905039,20.0,8.333333333333333e-05,0.56,0.23,0.18,0.07,0.86,0.06,0.02,0.01
82.7283142691436,0.0069955946293683,253.81732890275,20.0,8.333333333333333e-05,0.56,0.23,0.18,0.07,0.86,0.06,0.02,0.01
87.3895815450276,0.0073840335690253,254.131716063648,20.0,8.333333333333333e-05,0.56,0.23,0.18,0.07,0.86,0.06,0.02,0.01
91.9944019327236,0.0077677686013333,254.394847800542,20.0,8.333333333333333e-05,0.56,0.23,0.18,0.07,0.86,0.06,0.02,0.01
96.6014958727704,0.0081516930963372,254.641519270479,20.0,8.333333333333333e-05,0.56,0.23,0.18,0.07,0.86,0.06,0.02,0.01
101.1675357703572,0.0085321964211361,254.876236731582,20.0,8.333333333333333e-05,0.56,0.23,0.18,0.07,0.86,0.06,0.02,0.01
105.8282694300168,0.0089205908927744,255.114790542523,20.0,8.333333333333333e-05,0.56,0.23,0.18,0.07,0.86,0.06,0.02,0.01
110.4244995756792,0.0093036100715796,255.326453736522,20.0,8.333333333333333e-05,0.56,0.23,0.18,0.07,0.86,0.06,0.02,0.01
114.9415490236284,0.0096800308589087,255.515835023706,20.0,8.333333333333333e-05,0.56,0.23,0.18,0.07,0.86,0.06,0.02,0.01
119.3992808459952,0.0100515085107726,255.731314942207,20.0,8.333333333333333e-05,0.56,0.23,0.18,0.07,0.86,0.06,0.02,0.01
123.8696793973188,0.0104240417233829,255.924536565625,20.0,8.333333333333333e-05,0.56,0.23,0.18,0.07,0.86,0.06,0.02,0.01
128.31793427290322,0.0107947296296816,256.140611958157,20.0,8.333333333333333e-05,0.56,0.23,0.18,0.07,0.86,0.06,0.02,0.01
132.7877164338192,0.0111672114764246,256.326226939878,20.0,8.333333333333333e-05,0.56,0.23,0.18,0.07,0.86,0.06,0.02,0.01
137.17254845119805,0.0115326141445395,256.529131778652,20.0,8.333333333333333e-05,0.56,0.23,0.18,0.07,0.86,0.06,0.02,0.01
141.6442128577728,0.0119052528450874,256.702707100503,20.0,8.333333333333333e-05,0.56,0.23,0.18,0.07,0.86,0.06,0.02,0.01
146.0915862393912,0.0122758672935556,256.891541960858,20.0,8.333333333333333e-05,0.56,0.23,0.18,0.07,0.86,0.06,0.02,0.01
150.57026380381322,0.0126490904239241,257.111726408255,20.0,8.333333333333333e-05,0.56,0.23,0.18,0.07,0.86,0.06,0.02,0.01
155.04129867835323,0.0130216766634691,257.301052450762,20.0,8.333333333333333e-05,0.56,0.23,0.18,0.07,0.86,0.06,0.02,0.01
159.49707900208202,0.0133929916904465,257.4872615024,20.0,8.333333333333333e-05,0.56,0.23,0.18,0.07,0.86,0.06,0.02,0.01
164.0123102964612,0.0137692609649781,257.677397541943,20.0,8.333333333333333e-05,0.56,0.23,0.18,0.07,0.86,0.06,0.02,0.01
168.46124255945043,0.0141400053202272,257.870628397017,20.0,8.333333333333333e-05,0.56,0.23,0.18,0.07,0.86,0.06,0.02,0.01
172.9146139988856,0.0145111196068468,258.072452938475,20.0,8.333333333333333e-05,0.56,0.23,0.18,0.07,0.86,0.06,0.02,0.01
177.31315668996723,0.0148776648311036,258.277163792401,20.0,8.333333333333333e-05,0.56,0.23,0.18,0.07,0.86,0.06,0.02,0.01
181.6889599052352,0.0152423150990426,258.490917923997,20.0,8.333333333333333e-05,0.56,0.23,0.18,0.07,0.86,0.06,0.02,0.01
186.0364949535516,0.0156046096864023,258.691556310752,20.0,8.333333333333333e-05,0.56,0.23,0.18,0.07,0.86,0.06,0.02,0.01
190.3499400108024,0.0159640634411732,258.861451946533,20.0,8.333333333333333e-05,0.56,0.23,0.18,0.07,0.86,0.06,0.02,0.01
194.657248157628,0.016323005786742,259.047808268892,20.0,8.333333333333333e-05,0.56,0.23,0.18,0.07,0.86,0.06,0.02,0.01
198.8981341178748,0.0166764129500959,259.23642321573,20.0,8.333333333333333e-05,0.56,0.23,0.18,0.07,0.86,0.06,0.02,0.01
203.1430566234252,0.0170301564922251,259.443697419448,20.0,8.333333333333333e-05,0.56,0.23,0.18,0.07,0.86,0.06,0.02,0.01
207.3515382951912,0.0173808632982056,259.634412535537,20.0,8.333333333333333e-05,0.56,0.23,0.18,0.07,0.86,0.06,0.02,0.01
211.43135892365044,0.0177208483505772,259.786226377058,20.0,8.333333333333333e-05,0.56,0.23,0.18,0.07,0.86,0.06,0.02,0.01
215.48441850738243,0.0180586033158882,259.969020474861,20.0,8.333333333333333e-05,0.56,0.23,0.18,0.07,0.86,0.06,0.02,0.01
219.5412282171552,0.0183966707917026,260.137368226769,20.0,8.333333333333333e-05,0.56,0.23,0.18,0.07,0.86,0.06,0.02,0.01
223.61698182771244,0.0187363169259157,260.363025157336,20.0,8.333333333333333e-05,0.56,0.23,0.18,0.07,0.86,0.06,0.02,0.01
227.77962799950245,0.0190832041068982,260.56236938548,20.0,8.333333333333333e-05,0.56,0.23,0.18,0.07,0.86,0.06,0.02,0.01
231.95877041861883,0.0194314659751579,260.744635648878,20.0,8.333333333333333e-05,0.56,0.23,0.18,0.07,0.86,0.06,0.02,0.01
236.1664161185352,0.0197821031168176,260.946147831154,20.0,8.333333333333333e-05,0.56,0.23,0.18,0.07,0.86,0.06,0.02,0.01
240.3006983277948,0.0201266266342559,261.110235835952,20.0,8.333333333333333e-05,0.56,0.23,0.18,0.07,0.86,0.06,0.02,0.01
244.49484775837084,0.0204761390868039,261.301347509729,20.0,8.333333333333333e-05,0.56,0.23,0.18,0.07,0.86,0.06,0.02,0.01
248.7094085377752,0.0208273524850876,261.493088662952,20.0,8.333333333333333e-05,0.56,0.23,0.18,0.07,0.86,0.06,0.02,0.01
252.83544444906244,0.0211711888110282,261.672044038446,20.0,8.333333333333333e-05,0.56,0.23,0.18,0.07,0.86,0.06,0.02,0.01
257.0143386267876,0.0215194299925053,261.856616149789,20.0,8.333333333333333e-05,0.56,0.23,0.18,0.07,0.86,0.06,0.02,0.01
261.1466656916316,0.0218637905812423,262.034650893639,20.0,8.333333333333333e-05,0.56,0.23,0.18,0.07,0.86,0.06,0.02,0.01
265.2838785214692,0.0222085583170621,262.218617524612,20.0,8.333333333333333e-05,0.56,0.23,0.18,0.07,0.86,0.06,0.02,0.01
269.50534904383323,0.0225603475272591,262.413789657951,20.0,8.333333333333333e-05,0.56,0.23,0.18,0.07,0.86,0.06,0.02,0.01
273.62275226809805,0.0229034644626145,262.593480951292,20.0,8.333333333333333e-05,0.56,0.23,0.18,0.07,0.86,0.06,0.02,0.01
277.8541216155648,0.0232560785749034,262.773245290911,20.0,8.333333333333333e-05,0.56,0.23,0.18,0.07,0.86,0.06,0.02,0.01
281.9549879837724,0.0235978174389207,262.961674345784,20.0,8.333333333333333e-05,0.56,0.23,0.18,0.07,0.86,0.06,0.02,0.01
286.0427552742012,0.0239384647131231,263.111033680663,20.0,8.333333333333333e-05,0.56,0.23,0.18,0.07,0.86,0.06,0.02,0.01
290.05400655846006,0.024272735653478,263.288999784252,20.0,8.333333333333333e-05,0.56,0.23,0.18,0.07,0.86,0.06,0.02,0.01
294.00000024167406,0.0246015684604125,263.454907425735,20.0,8.333333333333333e-05,0.56,0.23,0.18,0.07,0.86,0.06,0.02,0.01
298.0280899260396,0.0249372426007763,263.654939734967,20.0,8.333333333333333e-05,0.56,0.23,0.18,0.07,0.86,0.06,0.02,0.01
302.0450830915452,0.0252719920312351,263.814976931479,20.0,8.333333333333333e-05,0.56,0.23,0.18,0.07,0.86,0.06,0.02,0.01
306.09043099983126,0.0256091043569256,263.997220180296,20.0,8.333333333333333e-05,0.56,0.23,0.18,0.07,0.86,0.06,0.02,0.01
310.0941349461264,0.0259427463524502,264.182597463039,20.0,8.333333333333333e-05,0.56,0.23,0.18,0.07,0.86,0.06,0.02,0.01
314.136664423986,0.0262796238089385,264.355961296064,20.0,8.333333333333333e-05,0.56,0.23,0.18,0.07,0.86,0.06,0.02,0.01
318.137529396528,0.026613029223317,264.590020033387,20.0,8.333333333333333e-05,0.56,0.23,0.18,0.07,0.86,0.06,0.02,0.01
322.10441419979645,0.0269436029569227,264.753076771934,20.0,8.333333333333333e-05,0.56,0.23,0.18,0.07,0.86,0.06,0.02,0.01
326.086834943364,0.02727547135222,264.912159121575,20.0,8.333333333333333e-05,0.56,0.23,0.18,0.07,0.86,0.06,0.02,0.01
330.0682072518324,0.0276072523779257,265.063614816841,20.0,8.333333333333333e-05,0.56,0.23,0.18,0.07,0.86,0.06,0.02,0.01
334.11594979135083,0.0279445642562189,265.246668030417,20.0,8.333333333333333e-05,0.56,0.23,0.18,0.07,0.86,0.06,0.02,0.01
338.0978367691344,0.0282763881710342,265.431117483407,20.0,8.333333333333333e-05,0.56,0.23,0.18,0.07,0.86,0.06,0.02,0.01
342.1049191449876,0.0286103117023553,265.602028601247,20.0,8.333333333333333e-05,0.56,0.23,0.18,0.07,0.86,0.06,0.02,0.01
346.11990932881565,0.0289448942176743,265.771715572573,20.0,8.333333333333333e-05,0.56,0.23,0.18,0.07,0.86,0.06,0.02,0.01
350.1553735411332,0.0292811829020341,265.93271399096,20.0,8.333333333333333e-05,0.56,0.23,0.18,0.07,0.86,0.06,0.02,0.01
354.19476617180044,0.0296177989545897,266.103065835123,20.0,8.333333333333333e-05,0.56,0.23,0.18,0.07,0.86,0.06,0.02,0.01
358.1771117978904,0.0299496610900972,266.268208524236,20.0,8.333333333333333e-05,0.56,0.23,0.18,0.07,0.86,0.06,0.02,0.01
362.2165645386097,0.0302862821518238,266.43232115754,20.0,8.333333333333333e-05,0.56,0.23,0.18,0.07,0.86,0.06,0.02,0.01
366.2488896684876,0.0306223092459803,266.573971414857,20.0,8.333333333333333e-05,0.56,0.23,0.18,0.07,0.86,0.06,0.02,0.01
370.2098744512116,0.0309523913112073,266.739641954514,20.0,8.333333333333333e-05,0.56,0.23,0.18,0.07,0.86,0.06,0.02,0.01
374.1801963834504,0.0312832514722272,266.872439167583,20.0,8.333333333333333e-05,0.56,0.23,0.18,0.07,0.86,0.06,0.02,0.01
378.0878417846004,0.0316088885889897,267.040139025153,20.0,8.333333333333333e-05,0.56,0.23,0.18,0.07,0.86,0.06,0.02,0.01
382.0513819461516,0.0319391836024523,267.193558803455,20.0,8.333333333333333e-05,0.56,0.23,0.18,0.07,0.86,0.06,0.02,0.01
386.1050594816485,0.0322769900637437,267.389903663635,20.0,8.333333333333333e-05,0.56,0.23,0.18,0.07,0.86,0.06,0.02,0.01
390.0937785963636,0.0326093833233033,267.569741420735,20.0,8.333333333333333e-05,0.56,0.23,0.18,0.07,0.86,0.06,0.02,0.01
394.09876966292165,0.0329431325788498,267.70102575598,20.0,8.333333333333333e-05,0.56,0.23,0.18,0.07,0.86,0.06,0.02,0.01
398.0626314091225,0.0332734543910332,267.860354422964,20.0,8.333333333333333e-05,0.56,0.23,0.18,0.07,0.86,0.06,0.02,0.01
402.0633139273356,0.0336068446008843,268.009079065417,20.0,8.333333333333333e-05,0.56,0.23,0.18,0.07,0.86,0.06,0.02,0.01
406.0993723149828,0.0339431827998549,268.152872083485,20.0,8.333333333333333e-05,0.56,0.23,0.18,0.07,0.86,0.06,0.02,0.01
410.134795446846,0.0342794680608435,268.311087044891,20.0,8.333333333333333e-05,0.56,0.23,0.18,0.07,0.86,0.06,0.02,0.01
414.1425373017768,0.0346134465487544,268.441388757606,20.0,8.333333333333333e-05,0.56,0.23,0.18,0.07,0.86,0.06,0.02,0.01
418.1641879826725,0.0349485841054957,268.607455677417,20.0,8.333333333333333e-05,0.56,0.23,0.18,0.07,0.86,0.06,0.02,0.01
422.2384849414741,0.0352881088520625,268.759703519702,20.0,8.333333333333333e-05,0.56,0.23,0.18,0.07,0.86,0.06,0.02,0.01
426.4582804677421,0.0356397584792515,268.914405465147,20.0,8.333333333333333e-05,0.56,0.23,0.18,0.07,0.86,0.06,0.02,0.01
430.6330241944488,0.0359876537898104,269.121451572744,20.0,8.333333333333333e-05,0.56,0.23,0.18,0.07,0.86,0.06,0.02,0.01
434.836611718128,0.036337952750117,269.21777764761,20.0,8.333333333333333e-05,0.56,0.23,0.18,0.07,0.86,0.06,0.02,0.01
438.8840076136788,0.0366752357414129,269.331837183149,20.0,8.333333333333333e-05,0.56,0.23,0.18,0.07,0.86,0.06,0.02,0.01
442.90199935883766,0.0370100683868428,269.485504263288,20.0,8.333333333333333e-05,0.56,0.23,0.18,0.07,0.86,0.06,0.02,0.01
446.9600342588844,0.0373482379618467,269.570362137098,20.0,8.333333333333333e-05,0.56,0.23,0.18,0.07,0.86,0.06,0.02,0.01
450.9344552484493,0.0376794397109771,269.746613493035,20.0,8.333333333333333e-05,0.56,0.23,0.18,0.07,0.86,0.06,0.02,0.01
454.9370699211445,0.0380129909337017,269.896560506683,20.0,8.333333333333333e-05,0.56,0.23,0.18,0.07,0.86,0.06,0.02,0.01
458.7997267020636,0.0383348789987783,270.022209110173,20.0,8.333333333333333e-05,0.56,0.23,0.18,0.07,0.86,0.06,0.02,0.01
462.7260068248656,0.0386620690090118,270.14255608067,20.0,8.333333333333333e-05,0.56,0.23,0.18,0.07,0.86,0.06,0.02,0.01
466.702430001654,0.0389934376070775,270.291918401311,20.0,8.333333333333333e-05,0.56,0.23,0.18,0.07,0.86,0.06,0.02,0.01
470.7062256531,0.039327087244698,270.459382754841,20.0,8.333333333333333e-05,0.56,0.23,0.18,0.07,0.86,0.06,0.02,0.01
474.8692555880952,0.0396740064059476,270.625173338292,20.0,8.333333333333333e-05,0.56,0.23,0.18,0.07,0.86,0.06,0.02,0.01
478.9237683080856,0.0400118824659468,270.787226634665,20.0,8.333333333333333e-05,0.56,0.23,0.18,0.07,0.86,0.06,0.02,0.01
482.8755009107688,0.0403411935161704,270.907332904282,20.0,8.333333333333333e-05,0.56,0.23,0.18,0.07,0.86,0.06,0.02,0.01
486.917825946372,0.040678053935804,271.007301851571,20.0,8.333333333333333e-05,0.56,0.23,0.18,0.07,0.86,0.06,0.02,0.01
490.914468284892,0.041011107464014,271.138657845118,20.0,8.333333333333333e-05,0.56,0.23,0.18,0.07,0.86,0.06,0.02,0.01
494.983671745488,0.041350207752397,271.265875942946,20.0,8.333333333333333e-05,0.56,0.23,0.18,0.07,0.86,0.06,0.02,0.01
498.9866076248041,0.04168378574234,271.416740360388,20.0,8.333333333333333e-05,0.56,0.23,0.18,0.07,0.86,0.06,0.02,0.01
502.9820838616284,0.0420167420954087,271.534244045678,20.0,8.333333333333333e-05,0.56,0.23,0.18,0.07,0.86,0.06,0.02,0.01
507.03175026139087,0.0423542142953889,271.642767654628,20.0,8.333333333333333e-05,0.56,0.23,0.18,0.07,0.86,0.06,0.02,0.01
511.125287322588,0.042695342383822,271.764033658983,20.0,8.333333333333333e-05,0.56,0.23,0.18,0.07,0.86,0.06,0.02,0.01
515.235336361662,0.0430378464704115,271.892040514586,20.0,8.333333333333333e-05,0.56,0.23,0.18,0.07,0.86,0.06,0.02,0.01
519.3637410665988,0.0433818801958229,272.023324462489,20.0,8.333333333333333e-05,0.56,0.23,0.18,0.07,0.86,0.06,0.02,0.01
523.49492260611,0.0437261453241155,272.141089878112,20.0,8.333333333333333e-05,0.56,0.23,0.18,0.07,0.86,0.06,0.02,0.01
527.547609715218,0.0440638692498745,272.2601912853,20.0,8.333333333333333e-05,0.56,0.23,0.18,0.07,0.86,0.06,0.02,0.01
531.5607564940487,0.0443982981481104,272.331009409521,20.0,8.333333333333333e-05,0.56,0.23,0.18,0.07,0.86,0.06,0.02,0.01
535.5246373716132,0.0447286215545741,272.464618588617,20.0,8.333333333333333e-05,0.56,0.23,0.18,0.07,0.86,0.06,0.02,0.01
539.43832814295,0.0450547624521855,272.566397940936,20.0,8.333333333333333e-05,0.56,0.23,0.18,0.07,0.86,0.06,0.02,0.01
543.3844289174172,0.0453836041833911,272.657824201893,20.0,8.333333333333333e-05,0.56,0.23,0.18,0.07,0.86,0.06,0.02,0.01
547.3327909536815,0.0457126343530798,272.775642844785,20.0,8.333333333333333e-05,0.56,0.23,0.18,0.07,0.86,0.06,0.02,0.01
551.336408462226,0.0460462691454585,272.894755258947,20.0,8.333333333333333e-05,0.56,0.23,0.18,0.07,0.86,0.06,0.02,0.01
555.3038072664815,0.0463768857124798,273.037858565862,20.0,8.333333333333333e-05,0.56,0.23,0.18,0.07,0.86,0.06,0.02,0.01
559.3993621868316,0.0467181819558423,273.149916801238,20.0,8.333333333333333e-05,0.56,0.23,0.18,0.07,0.86,0.06,0.02,0.01
563.4846756710604,0.0470586247461947,273.277783584229,20.0,8.333333333333333e-05,0.56,0.23,0.18,0.07,0.86,0.06,0.02,0.01
567.5381488131108,0.0473964141746989,273.358066398263,20.0,8.333333333333333e-05,0.56,0.23,0.18,0.07,0.86,0.06,0.02,0.01
571.5902382266939,0.0477340882924975,273.481049571159,20.0,8.333333333333333e-05,0.56,0.23,0.18,0.07,0.86,0.06,0.02,0.01
575.6194549282632,0.0480698563509616,273.54385745928,20.0,8.333333333333333e-05,0.56,0.23,0.18,0.07,0.86,0.06,0.02,0.01
579.609334163262,0.0484023462872115,273.64384963096,20.0,8.333333333333333e-05,0.56,0.23,0.18,0.07,0.86,0.06,0.02,0.01
583.7210316138431,0.0487449877414266,273.761620243423,20.0,8.333333333333333e-05,0.56,0.23,0.18,0.07,0.86,0.06,0.02,0.01
587.8780324974936,0.0490914044817308,273.870360360507,20.0,8.333333333333333e-05,0.56,0.23,0.18,0.07,0.86,0.06,0.02,0.01
592.0574047197252,0.0494396855002501,273.970360311309,20.0,8.333333333333333e-05,0.56,0.23,0.18,0.07,0.86,0.06,0.02,0.01
596.1830197787484,0.0497834867551687,274.035724932127,20.0,8.333333333333333e-05,0.56,0.23,0.18,0.07,0.86,0.06,0.02,0.01
600.3585903482327,0.0501314509692924,274.127145996243,20.0,8.333333333333333e-05,0.56,0.23,0.18,0.07,0.86,0.06,0.02,0.01
604.5001265811084,0.0504765789886987,274.23489906864,20.0,8.333333333333333e-05,0.56,0.23,0.18,0.07,0.86,0.06,0.02,0.01
608.565910458762,0.0508153943118365,274.322999416044,20.0,8.333333333333333e-05,0.56,0.23,0.18,0.07,0.86,0.06,0.02,0.01
612.6662445032772,0.0511570888155461,274.390960246182,20.0,8.333333333333333e-05,0.56,0.23,0.18,0.07,0.86,0.06,0.02,0.01
616.7370147440652,0.0514963196689451,274.472244113779,20.0,8.333333333333333e-05,0.56,0.23,0.18,0.07,0.86,0.06,0.02,0.01
620.8580500282992,0.0518397392759646,274.561556035216,20.0,8.333333333333333e-05,0.56,0.23,0.18,0.07,0.86,0.06,0.02,0.01
625.0285717770347,0.0521872827550259,274.653068350692,20.0,8.333333333333333e-05,0.56,0.23,0.18,0.07,0.86,0.06,0.02,0.01
629.1181768268327,0.0525280831758424,274.764212942722,20.0,8.333333333333333e-05,0.56,0.23,0.18,0.07,0.86,0.06,0.02,0.01
633.2671263340968,0.0528738289681144,274.835864643434,20.0,8.333333333333333e-05,0.56,0.23,0.18,0.07,0.86,0.06,0.02,0.01
637.4160532678139,0.0532195728792575,274.942428349416,20.0,8.333333333333333e-05,0.56,0.23,0.18,0.07,0.86,0.06,0.02,0.01
641.5634566042463,0.0535651898239602,275.012093759474,20.0,8.333333333333333e-05,0.56,0.23,0.18,0.07,0.86,0.06,0.02,0.01
645.7508911598484,0.0539141427035937,275.103580058468,20.0,8.333333333333333e-05,0.56,0.23,0.18,0.07,0.86,0.06,0.02,0.01
649.8667391623308,0.0542571300371339,275.157474299431,20.0,8.333333333333333e-05,0.56,0.23,0.18,0.07,0.86,0.06,0.02,0.01
653.9968779343139,0.0546013082681325,275.211661677722,20.0,8.333333333333333e-05,0.56,0.23,0.18,0.07,0.86,0.06,0.02,0.01
658.1075220062784,0.0549438619407962,275.289939366589,20.0,8.333333333333333e-05,0.56,0.23,0.18,0.07,0.86,0.06,0.02,0.01
662.1825975011208,0.0552834515653664,275.360977581859,20.0,8.333333333333333e-05,0.56,0.23,0.18,0.07,0.86,0.06,0.02,0.01
666.3130328696881,0.055627654512747,275.456667979804,20.0,8.333333333333333e-05,0.56,0.23,0.18,0.07,0.86,0.06,0.02,0.01
670.4755544692164,0.0559745313127077,275.526717149118,20.0,8.333333333333333e-05,0.56,0.23,0.18,0.07,0.86,0.06,0.02,0.01
674.6694686648028,0.0563240241623399,275.625268843682,20.0,8.333333333333333e-05,0.56,0.23,0.18,0.07,0.86,0.06,0.02,0.01
678.899387144034,0.0566765173689425,275.690481029216,20.0,8.333333333333333e-05,0.56,0.23,0.18,0.07,0.86,0.06,0.02,0.01
683.185906039032,0.057033727276859,275.775306511537,20.0,8.333333333333333e-05,0.56,0.23,0.18,0.07,0.86,0.06,0.02,0.01
687.4221862362251,0.0573867506266251,275.838425548396,20.0,8.333333333333333e-05,0.56,0.23,0.18,0.07,0.86,0.06,0.02,0.01
691.6455593781,0.057738698388448,275.890695841168,20.0,8.333333333333333e-05,0.56,0.23,0.18,0.07,0.86,0.06,0.02,0.01
695.8821964249644,0.0580917514756867,275.927041319116,20.0,8.333333333333333e-05,0.56,0.23,0.18,0.07,0.86,0.06,0.02,0.01
700.126999390674,0.0584454850561625,275.984989999699,20.0,8.333333333333333e-05,0.56,0.23,0.18,0.07,0.86,0.06,0.02,0.01
704.2878152131055,0.0587922197080318,276.049563683943,20.0,8.333333333333333e-05,0.56,0.23,0.18,0.07,0.86,0.06,0.02,0.01
708.4745444985875,0.0591411138151553,276.11754930398,20.0,8.333333333333333e-05,0.56,0.23,0.18,0.07,0.86,0.06,0.02,0.01
712.6483205332548,0.0594889284847109,276.216500574271,20.0,8.333333333333333e-05,0.56,0.23,0.18,0.07,0.86,0.06,0.02,0.01
716.90250779397,0.0598434440897705,276.275460702099,20.0,8.333333333333333e-05,0.56,0.23,0.18,0.07,0.86,0.06,0.02,0.01
721.2215607151811,0.0602033651665381,276.352648716742,20.0,8.333333333333333e-05,0.56,0.23,0.18,0.07,0.86,0.06,0.02,0.01
725.4847181908764,0.0605586282895127,276.40266701827,20.0,8.333333333333333e-05,0.56,0.23,0.18,0.07,0.86,0.06,0.02,0.01
729.7639374198216,0.0609152298919248,276.45523606483,20.0,8.333333333333333e-05,0.56,0.23,0.18,0.07,0.86,0.06,0.02,0.01
734.0534269107263,0.0612726873495002,276.502267199672,20.0,8.333333333333333e-05,0.56,0.23,0.18,0.07,0.86,0.06,0.02,0.01
738.2964227532516,0.0616262703363773,276.550592315595,20.0,8.333333333333333e-05,0.56,0.23,0.18,0.07,0.86,0.06,0.02,0.01
742.56371401908,0.061981877941863,276.579399775968,20.0,8.333333333333333e-05,0.56,0.23,0.18,0.07,0.86,0.06,0.02,0.01
746.7590364655296,0.0623314881457338,276.636324194736,20.0,8.333333333333333e-05,0.56,0.23,0.18,0.07,0.86,0.06,0.02,0.01
751.0215538877051,0.0626866979309151,276.702723099848,20.0,8.333333333333333e-05,0.56,0.23,0.18,0.07,0.86,0.06,0.02,0.01
755.2675983353976,0.0630405349682228,276.768044532013,20.0,8.333333333333333e-05,0.56,0.23,0.18,0.07,0.86,0.06,0.02,0.01
759.5360493540528,0.0633962392197774,276.829456568063,20.0,8.333333333333333e-05,0.56,0.23,0.18,0.07,0.86,0.06,0.02,0.01
763.8113275117656,0.0637525123995868,276.874139828335,20.0,8.333333333333333e-05,0.56,0.23,0.18,0.07,0.86,0.06,0.02,0.01
767.9518348502831,0.0640975546777966,276.911039980273,20.0,8.333333333333333e-05,0.56,0.23,0.18,0.07,0.86,0.06,0.02,0.01
772.1853604515431,0.0644503484779016,276.945715706817,20.0,8.333333333333333e-05,0.56,0.23,0.18,0.07,0.86,0.06,0.02,0.01
776.4229365269724,0.0648034798175207,276.999752409003,20.0,8.333333333333333e-05,0.56,0.23,0.18,0.07,0.86,0.06,0.02,0.01
780.6988135698288,0.0651598029044254,277.037521127342,20.0,8.333333333333333e-05,0.56,0.23,0.18,0.07,0.86,0.06,0.02,0.01
785.0750964009659,0.0655244931403535,277.091344129624,20.0,8.333333333333333e-05,0.56,0.23,0.18,0.07,0.86,0.06,0.02,0.01
789.4428348661609,0.0658884713457864,277.138861685538,20.0,8.333333333333333e-05,0.56,0.23,0.18,0.07,0.86,0.06,0.02,0.01
793.8328518108216,0.0662543060911748,277.178117491168,20.0,8.333333333333333e-05,0.56,0.23,0.18,0.07,0.86,0.06,0.02,0.01
798.2317887472896,0.0666208841692138,277.230613911071,20.0,8.333333333333333e-05,0.56,0.23,0.18,0.07,0.86,0.06,0.02,0.01
802.6282951725143,0.0669872597046492,277.25755914326,20.0,8.333333333333333e-05,0.56,0.23,0.18,0.07,0.86,0.06,0.02,0.01
806.9222308317733,0.0673450876762541,277.299782296567,20.0,8.333333333333333e-05,0.56,0.23,0.18,0.07,0.86,0.06,0.02,0.01
811.2634046117016,0.0677068521579148,277.329543409504,20.0,8.333333333333333e-05,0.56,0.23,0.18,0.07,0.86,0.06,0.02,0.01
815.5955247955692,0.0680678621732371,277.362168998494,20.0,8.333333333333333e-05,0.56,0.23,0.18,0.07,0.86,0.06,0.02,0.01
820.055630302482,0.0684395376321465,277.388980759026,20.0,8.333333333333333e-05,0.56,0.23,0.18,0.07,0.86,0.06,0.02,0.01
824.4835759278576,0.0688085331009278,277.411108778024,20.0,8.333333333333333e-05,0.56,0.23,0.18,0.07,0.86,0.06,0.02,0.01
828.9931033961448,0.0691843270566184,277.448627773637,20.0,8.333333333333333e-05,0.56,0.23,0.18,0.07,0.86,0.06,0.02,0.01
833.4434307253343,0.0695551876673842,277.464995998411,20.0,8.333333333333333e-05,0.56,0.23,0.18,0.07,0.86,0.06,0.02,0.01
837.8179804511053,0.0699197334778651,277.50205081285,20.0,8.333333333333333e-05,0.56,0.23,0.18,0.07,0.86,0.06,0.02,0.01
842.2702446504696,0.0702907554944788,277.506537058294,20.0,8.333333333333333e-05,0.56,0.23,0.18,0.07,0.86,0.06,0.02,0.01
846.7334228473021,0.0706626870108815,277.522404062298,20.0,8.333333333333333e-05,0.56,0.23,0.18,0.07,0.86,0.06,0.02,0.01
851.1895722759372,0.0710340327966011,277.567236191078,20.0,8.333333333333333e-05,0.56,0.23,0.18,0.07,0.86,0.06,0.02,0.01
855.8018806299156,0.0714183918260993,277.601392475632,20.0,8.333333333333333e-05,0.56,0.23,0.18,0.07,0.86,0.06,0.02,0.01
860.3121749098212,0.0717942496827581,277.637816003028,20.0,8.333333333333333e-05,0.56,0.23,0.18,0.07,0.86,0.06,0.02,0.01
864.8379416838948,0.0721713969139309,277.635058546389,20.0,8.333333333333333e-05,0.56,0.23,0.18,0.07,0.86,0.06,0.02,0.01
869.3079848588076,0.0725439005118403,277.61878777045,20.0,8.333333333333333e-05,0.56,0.23,0.18,0.07,0.86,0.06,0.02,0.01
873.6854757424092,0.0729086914188071,277.643059179631,20.0,8.333333333333333e-05,0.56,0.23,0.18,0.07,0.86,0.06,0.02,0.01
878.1873009348732,0.0732838435181791,277.668633979079,20.0,8.333333333333333e-05,0.56,0.23,0.18,0.07,0.86,0.06,0.02,0.01
882.6882927414769,0.0736589261687294,277.717353086547,20.0,8.333333333333333e-05,0.56,0.23,0.18,0.07,0.86,0.06,0.02,0.01
887.3661188325109,0.0740487450096489,277.743436514683,20.0,8.333333333333333e-05,0.56,0.23,0.18,0.07,0.86,0.06,0.02,0.01
892.0448190554496,0.0744386366948938,277.741695524598,20.0,8.333333333333333e-05,0.56,0.23,0.18,0.07,0.86,0.06,0.02,0.01
896.6833225267355,0.0748251786508343,277.75988396707,20.0,8.333333333333333e-05,0.56,0.23,0.18,0.07,0.86,0.06,0.02,0.01
901.3372853209656,0.0752130088836868,277.78795889884,20.0,8.333333333333333e-05,0.56,0.23,0.18,0.07,0.86,0.06,0.02,0.01
905.9750457762648,0.0755994889216284,277.795132943889,20.0,8.333333333333333e-05,0.56,0.23,0.18,0.07,0.86,0.06,0.02,0.01
910.7697191192052,0.0759990450335401,277.81863959437,20.0,8.333333333333333e-05,0.56,0.23,0.18,0.07,0.86,0.06,0.02,0.01
915.6731035488984,0.0764076604026812,277.81360751925,20.0,8.333333333333333e-05,0.56,0.23,0.18,0.07,0.86,0.06,0.02,0.01
920.6022552104567,0.0768184230411444,277.816248095388,20.0,8.333333333333333e-05,0.56,0.23,0.18,0.07,0.86,0.06,0.02,0.01
925.5461183963891,0.0772304116399721,277.825949709496,20.0,8.333333333333333e-05,0.56,0.23,0.18,0.07,0.86,0.06,0.02,0.01
930.5090299330308,0.0776439876013589,277.820951236309,20.0,8.333333333333333e-05,0.56,0.23,0.18,0.07,0.86,0.06,0.02,0.01
935.4889942912656,0.0780589846312118,277.826926957654,20.0,8.333333333333333e-05,0.56,0.23,0.18,0.07,0.86,0.06,0.02,0.01
937.9898085934956,0.0782673858230643,277.834142238505,20.0,8.333333333333333e-05,0.56,0.23,0.18,0.07,0.86,0.06,0.02,0.01