File: datasets/al_6061_comp/csv/T_020_D_2.csv
Time,Strain(%),Stress(MPa),Temp(C),SR(%/s),Si(%),Fe(%),Cu(%),Mn(%),Mg(%),Cr(%),Zn(%),Ti(%)
0.0,9.59362942424773e-05,29.460329663772804,20.0,8.333333333333333e-05,0.67,0.28,0.23,0.05,0.9,0.05,0.03,0.02
0.5849713846399363,0.00014468390962913867,33.71078520190116,20.0,8.333333333333333e-05,0.67,0.28,0.23,0.05,0.9,0.05,0.03,0.02
1.1699427692798725,0.0001934315250158,37.96124074002951,20.0,8.333333333333333e-05,0.67,0.28,0.23,0.05,0.9,0.05,0.03,0.02
1.8544239902720725,0.00025047162676515,42.46943962701171,20.0,8.333333333333333e-05,0.67,0.28,0.23,0.05,0.9,0.05,0.03,0.02
2.5389052112642725,0.0003075117285145,46.977638513993924,20.0,8.333333333333333e-05,0.67,0.28,0.23,0.05,0.9,0.05,0.03,0.02
3.2969401484666725,0.0003706813066147,51.62542933057847,20.0,8.333333333333333e-05,0.67,0.28,0.23,0.05,0.9,0.05,0.03,0.02
4.0549750856690725,0.0004338508847149,56.273220147163,20.0,8.333333333333333e-05,0.67,0.28,0.23,0.05,0.9,0.05,0.03,0.02
4.903608237706472,0.00050457031405135,60.99328888374085,20.0,8.333333333333333e-05,0.67,0.28,0.23,0.05,0.9,0.05,0.03,0.02
5.752241389743872,0.0005752897433878,65.71335762031872,20.0,8.333333333333333e-05,0.67,0.28,0.23,0.05,0.9,0.05,0.03,0.02
6.649119932792672,0.0006500296219752,70.45497739516625,20.0,8.333333333333333e-05,0.67,0.28,0.23,0.05,0.9,0.05,0.03,0.02
7.545998475841473,0.0007247695005626,75.19659717001377,20.0,8.333333333333333e-05,0.67,0.28,0.23,0.05,0.9,0.05,0.03,0.02
8.447167978908272,0.0007998669591515,79.95782453916166,20.0,8.333333333333333e-05,0.67,0.28,0.23,0.05,0.9,0.05,0.03,0.02
9.348337481975072,0.0008749644177404,84.71905190830961,20.0,8.333333333333333e-05,0.67,0.28,0.23,0.05,0.9,0.05,0.03,0.02
10.284022973518471,0.00095293820870235,89.47999493853376,20.0,8.333333333333333e-05,0.67,0.28,0.23,0.05,0.9,0.05,0.03,0.02
11.21970846506187,0.0010309119996643,94.24093796875795,20.0,8.333333333333333e-05,0.67,0.28,0.23,0.05,0.9,0.05,0.03,0.02
12.144911900237071,0.0011080122859289,98.9809474967085,20.0,8.333333333333333e-05,0.67,0.28,0.23,0.05,0.9,0.05,0.03,0.02
13.070115335412272,0.0011851125721935,103.72095702465889,20.0,8.333333333333333e-05,0.67,0.28,0.23,0.05,0.9,0.05,0.03,0.02
14.004059761244072,0.00126294127434615,108.39156218452389,20.0,8.333333333333333e-05,0.67,0.28,0.23,0.05,0.9,0.05,0.03,0.02
14.93800418707587,0.0013407699764988,113.0621673443889,20.0,8.333333333333333e-05,0.67,0.28,0.23,0.05,0.9,0.05,0.03,0.02
15.877700932971273,0.00141907803865675,117.6572404639129,20.0,8.333333333333333e-05,0.67,0.28,0.23,0.05,0.9,0.05,0.03,0.02
16.817397678866673,0.0014973861008147,122.25231358343692,20.0,8.333333333333333e-05,0.67,0.28,0.23,0.05,0.9,0.05,0.03,0.02
17.748059698246472,0.00157494126909635,126.77456575999742,20.0,8.333333333333333e-05,0.67,0.28,0.23,0.05,0.9,0.05,0.03,0.02
18.678721717626274,0.001652496437378,131.29681793655791,20.0,8.333333333333333e-05,0.67,0.28,0.23,0.05,0.9,0.05,0.03,0.02
19.603275785935473,0.0017295426097371,135.7596420206214,20.0,8.333333333333333e-05,0.67,0.28,0.23,0.05,0.9,0.05,0.03,0.02
20.527829854244672,0.0018065887820962,140.22246610468494,20.0,8.333333333333333e-05,0.67,0.28,0.23,0.05,0.9,0.05,0.03,0.02
21.463059538773877,0.0018845245891403,144.59822190758445,20.0,8.333333333333333e-05,0.67,0.28,0.23,0.05,0.9,0.05,0.03,0.02
22.398289223303077,0.0019624603961844,148.97397771048415,20.0,8.333333333333333e-05,0.67,0.28,0.23,0.05,0.9,0.05,0.03,0.02
23.31422061662368,0.00203878801229445,153.25854193031313,20.0,8.333333333333333e-05,0.67,0.28,0.23,0.05,0.9,0.05,0.03,0.02
24.23015200994428,0.0021151156284045,157.54310615014202,20.0,8.333333333333333e-05,0.67,0.28,0.23,0.05,0.9,0.05,0.03,0.02
25.170877551694478,0.00219350942355035,161.74643091020852,20.0,8.333333333333333e-05,0.67,0.28,0.23,0.05,0.9,0.05,0.03,0.02
26.111603093444675,0.0022719032186962,165.94975567027524,20.0,8.333333333333333e-05,0.67,0.28,0.23,0.05,0.9,0.05,0.03,0.02
27.04375003255828,0.0023495821302890003,170.06396148300425,20.0,8.333333333333333e-05,0.67,0.28,0.23,0.05,0.9,0.05,0.03,0.02
27.97589697167188,0.0024272610418818,174.17816729573306,20.0,8.333333333333333e-05,0.67,0.28,0.23,0.05,0.9,0.05,0.03,0.02
28.893120576905076,0.0025036963423179003,178.22287994476457,20.0,8.333333333333333e-05,0.67,0.28,0.23,0.05,0.9,0.05,0.03,0.02
29.810344182138277,0.002580131642754,182.26759259379583,20.0,8.333333333333333e-05,0.67,0.28,0.23,0.05,0.9,0.05,0.03,0.02
30.70953811604788,0.0026550644705798003,186.23226932423182,20.0,8.333333333333333e-05,0.67,0.28,0.23,0.05,0.9,0.05,0.03,0.02
31.60873204995748,0.0027299972984056,190.1969460546682,20.0,8.333333333333333e-05,0.67,0.28,0.23,0.05,0.9,0.05,0.03,0.02
32.52370106469267,0.0028062447163002,194.0103274704627,20.0,8.333333333333333e-05,0.67,0.28,0.23,0.05,0.9,0.05,0.03,0.02
33.43867007942787,0.0028824921341948,197.82370888625667,20.0,8.333333333333333e-05,0.67,0.28,0.23,0.05,0.9,0.05,0.03,0.02
34.35075308032647,0.00295849905093635,201.50413862030064,20.0,8.333333333333333e-05,0.67,0.28,0.23,0.05,0.9,0.05,0.03,0.02
35.26283608122507,0.0030345059676779,205.18456835434512,20.0,8.333333333333333e-05,0.67,0.28,0.23,0.05,0.9,0.05,0.03,0.02
36.200189867097265,0.00311261878316725,208.68468849908214,20.0,8.333333333333333e-05,0.67,0.28,0.23,0.05,0.9,0.05,0.03,0.02
37.13754365296947,0.0031907315986566,212.1848086438195,20.0,8.333333333333333e-05,0.67,0.28,0.23,0.05,0.9,0.05,0.03,0.02
38.08347917023527,0.0032695595584287503,215.49039640874804,20.0,8.333333333333333e-05,0.67,0.28,0.23,0.05,0.9,0.05,0.03,0.02
39.029414687501074,0.0033483875182009,218.79598417367572,20.0,8.333333333333333e-05,0.67,0.28,0.23,0.05,0.9,0.05,0.03,0.02
40.025816818966476,0.00343142102915635,221.93603207742973,20.0,8.333333333333333e-05,0.67,0.28,0.23,0.05,0.9,0.05,0.03,0.02
41.02221895043187,0.0035144545401118,225.07607998118414,20.0,8.333333333333333e-05,0.67,0.28,0.23,0.05,0.9,0.05,0.03,0.02
42.050707679266466,0.00360016193418135,227.9925402886331,20.0,8.333333333333333e-05,0.67,0.28,0.23,0.05,0.9,0.05,0.03,0.02
43.07919640810107,0.0036858693282509,230.90900059608197,20.0,8.333333333333333e-05,0.67,0.28,0.23,0.05,0.9,0.05,0.03,0.02
44.209776374544276,0.0037800843254545,233.58206522685794,20.0,8.333333333333333e-05,0.67,0.28,0.23,0.05,0.9,0.05,0.03,0.02
45.34035634098748,0.0038742993226581,236.2551298576344,20.0,8.333333333333333e-05,0.67,0.28,0.23,0.05,0.9,0.05,0.03,0.02
46.61657229783148,0.0039806506523951,238.7044878151969,20.0,8.333333333333333e-05,0.67,0.28,0.23,0.05,0.9,0.05,0.03,0.02
47.89278825467547,0.0040870019821321,241.15384577275933,20.0,8.333333333333333e-05,0.67,0.28,0.23,0.05,0.9,0.05,0.03,0.02
49.363895083751075,0.0042095942178884006,243.34302059786484,20.0,8.333333333333333e-05,0.67,0.28,0.23,0.05,0.9,0.05,0.03,0.02
50.83500191282667,0.0043321864536447,245.53219542297037,20.0,8.333333333333333e-05,0.67,0.28,0.23,0.05,0.9,0.05,0.03,0.02
52.60196050057107,0.0044794330026233994,247.48103306935536,20.0,8.333333333333333e-05,0.67,0.28,0.23,0.05,0.9,0.05,0.03,0.02
54.36891908831547,0.0046266795516021,249.42987071573984,20.0,8.333333333333333e-05,0.67,0.28,0.23,0.05,0.9,0.05,0.03,0.02
56.418331483124675,0.0047974639178361995,251.11494008705984,20.0,8.333333333333333e-05,0.67,0.28,0.23,0.05,0.9,0.05,0.03,0.02
58.46774387793387,0.0049682482840703,252.80000945837958,20.0,8.333333333333333e-05,0.67,0.28,0.23,0.05,0.9,0.05,0.03,0.02
60.80607088872807,0.0051631088683031495,254.13372693783955,20.0,8.333333333333333e-05,0.67,0.28,0.23,0.05,0.9,0.05,0.03,0.02
63.14439789952228,0.005357969452536,255.46744441730027,20.0,8.333333333333333e-05,0.67,0.28,0.23,0.05,0.9,0.05,0.03,0.02
65.76033551948308,0.0055759642541994,256.52884230689926,20.0,8.333333333333333e-05,0.67,0.28,0.23,0.05,0.9,0.05,0.03,0.02
68.37627313944387,0.0057939590558628,257.5902401964982,20.0,8.333333333333333e-05,0.67,0.28,0.23,0.05,0.9,0.05,0.03,0.02
72.47000834664327,0.00613510365646275,258.5433020774937,20.0,8.333333333333333e-05,0.67,0.28,0.23,0.05,0.9,0.05,0.03,0.02
76.56374355384267,0.0064762482570627,259.4963639584891,20.0,8.333333333333333e-05,0.67,0.28,0.23,0.05,0.9,0.05,0.03,0.02
80.89918088022208,0.00683753470092765,260.2109091922466,20.0,8.333333333333333e-05,0.67,0.28,0.23,0.05,0.9,0.05,0.03,0.02
85.23461820660147,0.0071988211447926,260.925454426004,20.0,8.333333333333333e-05,0.67,0.28,0.23,0.05,0.9,0.05,0.03,0.02
89.76143948443828,0.0075760562512790005,261.470846201525,20.0,8.333333333333333e-05,0.67,0.28,0.23,0.05,0.9,0.05,0.03,0.02
94.28826076227509,0.0079532913577654,262.0162379770461,20.0,8.333333333333333e-05,0.67,0.28,0.23,0.05,0.9,0.05,0.03,0.02
98.93017794133468,0.0083401177893537,262.4191678061156,20.0,8.333333333333333e-05,0.67,0.28,0.23,0.05,0.9,0.05,0.03,0.02
103.57209512039428,0.008726944220942,262.82209763518506,20.0,8.333333333333333e-05,0.67,0.28,0.23,0.05,0.9,0.05,0.03,0.02
108.30594139232127,0.009121431410269248,263.142698115066,20.0,8.333333333333333e-05,0.67,0.28,0.23,0.05,0.9,0.05,0.03,0.02
113.03978766424828,0.0095159185995965,263.4632985949472,20.0,8.333333333333333e-05,0.67,0.28,0.23,0.05,0.9,0.05,0.03,0.02
117.81998441907388,0.0099142683291653,263.78289397935873,20.0,8.333333333333333e-05,0.67,0.28,0.23,0.05,0.9,0.05,0.03,0.02
122.60018117389949,0.0103126180587341,264.10248936376985,20.0,8.333333333333333e-05,0.67,0.28,0.23,0.05,0.9,0.05,0.03,0.02
127.4636631461259,0.010717908223086301,264.3960220023333,20.0,8.333333333333333e-05,0.67,0.28,0.23,0.05,0.9,0.05,0.03,0.02
132.3271451183523,0.0111231983874385,264.6895546408973,20.0,8.333333333333333e-05,0.67,0.28,0.23,0.05,0.9,0.05,0.03,0.02
135.9702821530995,0.0114267931403341,264.8121290591083,20.0,8.333333333333333e-05,0.67,0.28,0.23,0.05,0.9,0.05,0.03,0.02
139.6134191878467,0.0117303878932297,264.93470347731943,20.0,8.333333333333333e-05,0.67,0.28,0.23,0.05,0.9,0.05,0.03,0.02
143.1944136313083,0.0120288040968515,265.06646541016744,20.0,8.333333333333333e-05,0.67,0.28,0.23,0.05,0.9,0.05,0.03,0.02
146.77540807476987,0.0123272203004733,265.1982273430152,20.0,8.333333333333333e-05,0.67,0.28,0.23,0.05,0.9,0.05,0.03,0.02
150.27774691792166,0.01261908187073595,265.36414259262176,20.0,8.333333333333333e-05,0.67,0.28,0.23,0.05,0.9,0.05,0.03,0.02
153.78008576107348,0.0129109434409986,265.53005784222825,20.0,8.333333333333333e-05,0.67,0.28,0.23,0.05,0.9,0.05,0.03,0.02
157.18420493395348,0.0131946200387386,265.68662375534126,20.0,8.333333333333333e-05,0.67,0.28,0.23,0.05,0.9,0.05,0.03,0.02
160.58832410683348,0.0134782966364786,265.84318966845376,20.0,8.333333333333333e-05,0.67,0.28,0.23,0.05,0.9,0.05,0.03,0.02
163.9168534611921,0.01375567408267515,266.0060586465083,20.0,8.333333333333333e-05,0.67,0.28,0.23,0.05,0.9,0.05,0.03,0.02
167.24538281555067,0.0140330515288717,266.1689276245632,20.0,8.333333333333333e-05,0.67,0.28,0.23,0.05,0.9,0.05,0.03,0.02
170.51903997929128,0.01430585629251675,266.3173956752127,20.0,8.333333333333333e-05,0.67,0.28,0.23,0.05,0.9,0.05,0.03,0.02
173.7926971430319,0.0145786610561618,266.46586372586154,20.0,8.333333333333333e-05,0.67,0.28,0.23,0.05,0.9,0.05,0.03,0.02
176.9702178550179,0.0148434544488273,266.599617177895,20.0,8.333333333333333e-05,0.67,0.28,0.23,0.05,0.9,0.05,0.03,0.02
180.1477385670039,0.0151082478414928,266.7333706299295,20.0,8.333333333333333e-05,0.67,0.28,0.23,0.05,0.9,0.05,0.03,0.02
183.3049516354929,0.015371348930533551,266.89476953762994,20.0,8.333333333333333e-05,0.67,0.28,0.23,0.05,0.9,0.05,0.03,0.02
186.4621647039819,0.0156344500195743,267.05616844532926,20.0,8.333333333333333e-05,0.67,0.28,0.23,0.05,0.9,0.05,0.03,0.02
189.61392522154165,0.015897096729370952,267.2624885454463,20.0,8.333333333333333e-05,0.67,0.28,0.23,0.05,0.9,0.05,0.03,0.02
192.76568573910143,0.0161597434391676,267.4688086455638,20.0,8.333333333333333e-05,0.67,0.28,0.23,0.05,0.9,0.05,0.03,0.02
195.93051564805643,0.01642347926491385,267.6468331239243,20.0,8.333333333333333e-05,0.67,0.28,0.23,0.05,0.9,0.05,0.03,0.02
199.09534555701143,0.0166872150906601,267.82485760228525,20.0,8.333333333333333e-05,0.67,0.28,0.23,0.05,0.9,0.05,0.03,0.02
202.24216311777985,0.016949449887390798,267.9881457576307,20.0,8.333333333333333e-05,0.67,0.28,0.23,0.05,0.9,0.05,0.03,0.02
205.38898067854828,0.0172116846841215,268.1514339129763,20.0,8.333333333333333e-05,0.67,0.28,0.23,0.05,0.9,0.05,0.03,0.02
208.5482862774939,0.0174749601507003,268.2992860014033,20.0,8.333333333333333e-05,0.67,0.28,0.23,0.05,0.9,0.05,0.03,0.02
211.7075918764395,0.0177382356172791,268.4471380898305,20.0,8.333333333333333e-05,0.67,0.28,0.23,0.05,0.9,0.05,0.03,0.02
214.8691705934835,0.0180017005103661,268.6336480692105,20.0,8.333333333333333e-05,0.67,0.28,0.23,0.05,0.9,0.05,0.03,0.02
218.03074931052748,0.0182651654034531,268.82015804858986,20.0,8.333333333333333e-05,0.67,0.28,0.23,0.05,0.9,0.05,0.03,0.02
221.22756222284247,0.01853156647947935,268.99757165774287,20.0,8.333333333333333e-05,0.67,0.28,0.23,0.05,0.9,0.05,0.03,0.02
224.42437513515745,0.0187979675555056,269.1749852668962,20.0,8.333333333333333e-05,0.67,0.28,0.23,0.05,0.9,0.05,0.03,0.02
227.60404243193366,0.01906293983023695,269.32284127789376,20.0,8.333333333333333e-05,0.67,0.28,0.23,0.05,0.9,0.05,0.03,0.02
230.78370972870988,0.0193279121049683,269.4706972888908,20.0,8.333333333333333e-05,0.67,0.28,0.23,0.05,0.9,0.05,0.03,0.02
233.96745857096005,0.01959322450848915,269.58319400617324,20.0,8.333333333333333e-05,0.67,0.28,0.23,0.05,0.9,0.05,0.03,0.02
237.15120741321024,0.01985853691201,269.6956907234558,20.0,8.333333333333333e-05,0.67,0.28,0.23,0.05,0.9,0.05,0.03,0.02
240.32662596196226,0.020123155124406,269.8258325397123,20.0,8.333333333333333e-05,0.67,0.28,0.23,0.05,0.9,0.05,0.03,0.02
243.50204451071428,0.020387773336802,269.9559743559691,20.0,8.333333333333333e-05,0.67,0.28,0.23,0.05,0.9,0.05,0.03,0.02
246.68312591253928,0.020652863453620753,270.13009398639457,20.0,8.333333333333333e-05,0.67,0.28,0.23,0.05,0.9,0.05,0.03,0.02
249.86420731436428,0.0209179535704395,270.30421361681886,20.0,8.333333333333333e-05,0.67,0.28,0.23,0.05,0.9,0.05,0.03,0.02
253.09285284146847,0.02118700736436485,270.45293619960034,20.0,8.333333333333333e-05,0.67,0.28,0.23,0.05,0.9,0.05,0.03,0.02
256.3214983685727,0.0214560611582902,270.60165878238263,20.0,8.333333333333333e-05,0.67,0.28,0.23,0.05,0.9,0.05,0.03,0.02
259.5272130916155,0.0217232040518771,270.7158061348046,20.0,8.333333333333333e-05,0.67,0.28,0.23,0.05,0.9,0.05,0.03,0.02
262.7329278146583,0.021990346945464,270.8299534872267,20.0,8.333333333333333e-05,0.67,0.28,0.23,0.05,0.9,0.05,0.03,0.02
265.8977228812047,0.022254079867676198,270.96474780446175,20.0,8.333333333333333e-05,0.67,0.28,0.23,0.05,0.9,0.05,0.03,0.02
269.0625179477511,0.0225178127898884,271.09954212169635,20.0,8.333333333333333e-05,0.67,0.28,0.23,0.05,0.9,0.05,0.03,0.02
272.2458757463373,0.02278309260643725,271.2333234192363,20.0,8.333333333333333e-05,0.67,0.28,0.23,0.05,0.9,0.05,0.03,0.02
275.4292335449235,0.0230483724229861,271.3671047167772,20.0,8.333333333333333e-05,0.67,0.28,0.23,0.05,0.9,0.05,0.03,0.02
278.58745528137626,0.0233115575676905,271.52114769727865,20.0,8.333333333333333e-05,0.67,0.28,0.23,0.05,0.9,0.05,0.03,0.02
281.74567701782905,0.0235747427123949,271.67519067777874,20.0,8.333333333333333e-05,0.67,0.28,0.23,0.05,0.9,0.05,0.03,0.02
284.89255336944206,0.02383698240836265,271.80697347300827,20.0,8.333333333333333e-05,0.67,0.28,0.23,0.05,0.9,0.05,0.03,0.02
288.03942972105506,0.0240992221043304,271.9387562682383,20.0,8.333333333333333e-05,0.67,0.28,0.23,0.05,0.9,0.05,0.03,0.02
291.18837565985245,0.02436163426589685,272.0438955715408,20.0,8.333333333333333e-05,0.67,0.28,0.23,0.05,0.9,0.05,0.03,0.02
294.3373215986499,0.0246240464274633,272.14903487484384,20.0,8.333333333333333e-05,0.67,0.28,0.23,0.05,0.9,0.05,0.03,0.02
297.4194149853771,0.0248808875430239,272.28468909707334,20.0,8.333333333333333e-05,0.67,0.28,0.23,0.05,0.9,0.05,0.03,0.02
300.5015083721043,0.0251377286585845,272.4203433193025,20.0,8.333333333333333e-05,0.67,0.28,0.23,0.05,0.9,0.05,0.03,0.02
303.6089745162363,0.0253966841705955,272.5921869413595,20.0,8.333333333333333e-05,0.67,0.28,0.23,0.05,0.9,0.05,0.03,0.02
306.7164406603683,0.0256556396826065,272.76403056341593,20.0,8.333333333333333e-05,0.67,0.28,0.23,0.05,0.9,0.05,0.03,0.02
309.79313798110763,0.025912031126001447,272.92586300216846,20.0,8.333333333333333e-05,0.67,0.28,0.23,0.05,0.9,0.05,0.03,0.02
312.86983530184705,0.0261684225693964,273.08769544092166,20.0,8.333333333333333e-05,0.67,0.28,0.23,0.05,0.9,0.05,0.03,0.02
315.93388347590303,0.026423759917234398,273.23408138156515,20.0,8.333333333333333e-05,0.67,0.28,0.23,0.05,0.9,0.05,0.03,0.02
318.99793164995907,0.0266790972650724,273.38046732220806,20.0,8.333333333333333e-05,0.67,0.28,0.23,0.05,0.9,0.05,0.03,0.02
322.0599281124471,0.0269342636369464,273.5405415872806,20.0,8.333333333333333e-05,0.67,0.28,0.23,0.05,0.9,0.05,0.03,0.02
325.12192457493506,0.0271894300088204,273.70061585235544,20.0,8.333333333333333e-05,0.67,0.28,0.23,0.05,0.9,0.05,0.03,0.02
328.1712383419299,0.0274435394894033,273.8352992541594,20.0,8.333333333333333e-05,0.67,0.28,0.23,0.05,0.9,0.05,0.03,0.02
331.22055210892466,0.0276976489699862,273.96998265596244,20.0,8.333333333333333e-05,0.67,0.28,0.23,0.05,0.9,0.05,0.03,0.02
334.2487132251117,0.02794999572966845,274.11684062579144,20.0,8.333333333333333e-05,0.67,0.28,0.23,0.05,0.9,0.05,0.03,0.02
337.2768743412987,0.0282023424893507,274.263698595619,20.0,8.333333333333333e-05,0.67,0.28,0.23,0.05,0.9,0.05,0.03,0.02
340.3218251827563,0.0284560883928055,274.3922533840665,20.0,8.333333333333333e-05,0.67,0.28,0.23,0.05,0.9,0.05,0.03,0.02
343.3667760242139,0.0287098342962603,274.5208081725164,20.0,8.333333333333333e-05,0.67,0.28,0.23,0.05,0.9,0.05,0.03,0.02
346.4027167568271,0.028962829357311398,274.6345497603089,20.0,8.333333333333333e-05,0.67,0.28,0.23,0.05,0.9,0.05,0.03,0.02
349.4386574894403,0.0292158244183625,274.74829134810153,20.0,8.333333333333333e-05,0.67,0.28,0.23,0.05,0.9,0.05,0.03,0.02
352.5187275175929,0.029472496920708552,274.87874360893903,20.0,8.333333333333333e-05,0.67,0.28,0.23,0.05,0.9,0.05,0.03,0.02
355.5987975457455,0.0297291694230546,275.0091958697771,20.0,8.333333333333333e-05,0.67,0.28,0.23,0.05,0.9,0.05,0.03,0.02
358.6908516844965,0.02998684060128385,275.1559065375871,20.0,8.333333333333333e-05,0.67,0.28,0.23,0.05,0.9,0.05,0.03,0.02
361.7829058232475,0.0302445117795131,275.30261720539585,20.0,8.333333333333333e-05,0.67,0.28,0.23,0.05,0.9,0.05,0.03,0.02
364.88316150865114,0.0305028664199634,275.39126616391735,20.0,8.333333333333333e-05,0.67,0.28,0.23,0.05,0.9,0.05,0.03,0.02
367.9834171940547,0.0307612210604137,275.4799151224388,20.0,8.333333333333333e-05,0.67,0.28,0.23,0.05,0.9,0.05,0.03,0.02
371.10772209284494,0.03102157980197955,275.6130788918913,20.0,8.333333333333333e-05,0.67,0.28,0.23,0.05,0.9,0.05,0.03,0.02
374.2320269916351,0.0312819385435454,275.7462426613433,20.0,8.333333333333333e-05,0.67,0.28,0.23,0.05,0.9,0.05,0.03,0.02
377.3577347339775,0.0315424141887406,275.86626872931777,20.0,8.333333333333333e-05,0.67,0.28,0.23,0.05,0.9,0.05,0.03,0.02
380.4834424763199,0.0318028898339358,275.9862947972917,20.0,8.333333333333333e-05,0.67,0.28,0.23,0.05,0.9,0.05,0.03,0.02
383.59182409324353,0.0320619216353461,276.1217185764022,20.0,8.333333333333333e-05,0.67,0.28,0.23,0.05,0.9,0.05,0.03,0.02
386.7002057101671,0.0323209534367564,276.2571423555137,20.0,8.333333333333333e-05,0.67,0.28,0.23,0.05,0.9,0.05,0.03,0.02
389.7835851006855,0.0325779017192996,276.3730547856572,20.0,8.333333333333333e-05,0.67,0.28,0.23,0.05,0.9,0.05,0.03,0.02
392.86696449120393,0.0328348500018428,276.4889672158005,20.0,8.333333333333333e-05,0.67,0.28,0.23,0.05,0.9,0.05,0.03,0.02
395.95758313152453,0.03309240155520285,276.5997204295005,20.0,8.333333333333333e-05,0.67,0.28,0.23,0.05,0.9,0.05,0.03,0.02
399.04820177184513,0.0333499531085629,276.7104736432006,20.0,8.333333333333333e-05,0.67,0.28,0.23,0.05,0.9,0.05,0.03,0.02
402.1118330406213,0.03360525571429425,276.8250413354496,20.0,8.333333333333333e-05,0.67,0.28,0.23,0.05,0.9,0.05,0.03,0.02
405.1754643093975,0.0338605583200256,276.9396090276982,20.0,8.333333333333333e-05,0.67,0.28,0.23,0.05,0.9,0.05,0.03,0.02
408.24813707243004,0.034116614383611646,277.0755955928922,20.0,8.333333333333333e-05,0.67,0.28,0.23,0.05,0.9,0.05,0.03,0.02
411.3208098354626,0.0343726704471977,277.21158215808657,20.0,8.333333333333333e-05,0.67,0.28,0.23,0.05,0.9,0.05,0.03,0.02
414.3672917037242,0.0346265439362195,277.3386256891876,20.0,8.333333333333333e-05,0.67,0.28,0.23,0.05,0.9,0.05,0.03,0.02
417.4137735719858,0.0348804174252413,277.46566922028876,20.0,8.333333333333333e-05,0.67,0.28,0.23,0.05,0.9,0.05,0.03,0.02
420.4855673649482,0.0351364002413215,277.6012035905857,20.0,8.333333333333333e-05,0.67,0.28,0.23,0.05,0.9,0.05,0.03,0.02
423.5573611579107,0.0353923830574017,277.7367379608847,20.0,8.333333333333333e-05,0.67,0.28,0.23,0.05,0.9,0.05,0.03,0.02
426.6261214131807,0.0356481130786742,277.8679004759012,20.0,8.333333333333333e-05,0.67,0.28,0.23,0.05,0.9,0.05,0.03,0.02
429.6948816684507,0.0359038430999467,277.9990629909164,20.0,8.333333333333333e-05,0.67,0.28,0.23,0.05,0.9,0.05,0.03,0.02
432.7968144790701,0.03616233750083165,278.1238083938294,20.0,8.333333333333333e-05,0.67,0.28,0.23,0.05,0.9,0.05,0.03,0.02
435.8987472896895,0.0364208319017166,278.24855379673943,20.0,8.333333333333333e-05,0.67,0.28,0.23,0.05,0.9,0.05,0.03,0.02
438.99063277867043,0.036678489025798344,278.3600233699094,20.0,8.333333333333333e-05,0.67,0.28,0.23,0.05,0.9,0.05,0.03,0.02
442.0825182676514,0.0369361461498801,278.4714929430799,20.0,8.333333333333333e-05,0.67,0.28,0.23,0.05,0.9,0.05,0.03,0.02
445.212671756807,0.037196992273976395,278.59820555473044,20.0,8.333333333333333e-05,0.67,0.28,0.23,0.05,0.9,0.05,0.03,0.02
448.3428252459627,0.0374578383980727,278.72491816638427,20.0,8.333333333333333e-05,0.67,0.28,0.23,0.05,0.9,0.05,0.03,0.02
451.45561309154965,0.03771723738520495,278.8682622246423,20.0,8.333333333333333e-05,0.67,0.28,0.23,0.05,0.9,0.05,0.03,0.02
454.56840093713663,0.0379766363723372,279.0116062828964,20.0,8.333333333333333e-05,0.67,0.28,0.23,0.05,0.9,0.05,0.03,0.02
457.69460934645383,0.0382371537397803,279.1454784955024,20.0,8.333333333333333e-05,0.67,0.28,0.23,0.05,0.9,0.05,0.03,0.02
460.8208177557711,0.0384976711072234,279.2793507081101,20.0,8.333333333333333e-05,0.67,0.28,0.23,0.05,0.9,0.05,0.03,0.02
463.9364266557099,0.0387573051822183,279.3860156146121,20.0,8.333333333333333e-05,0.67,0.28,0.23,0.05,0.9,0.05,0.03,0.02
467.05203555564873,0.0390169392572132,279.49268052111415,20.0,8.333333333333333e-05,0.67,0.28,0.23,0.05,0.9,0.05,0.03,0.02
470.1953218988109,0.03927887978581005,279.61145112131067,20.0,8.333333333333333e-05,0.67,0.28,0.23,0.05,0.9,0.05,0.03,0.02
473.3386082419731,0.0395408203144069,279.73022172150723,20.0,8.333333333333333e-05,0.67,0.28,0.23,0.05,0.9,0.05,0.03,0.02
476.4226835591121,0.03979782659083515,279.83747592307776,20.0,8.333333333333333e-05,0.67,0.28,0.23,0.05,0.9,0.05,0.03,0.02
479.5067588762511,0.0400548328672634,279.94473012464823,20.0,8.333333333333333e-05,0.67,0.28,0.23,0.05,0.9,0.05,0.03,0.02
482.60639066846375,0.040313135516614446,280.0504909656007,20.0,8.333333333333333e-05,0.67,0.28,0.23,0.05,0.9,0.05,0.03,0.02
485.7060224606763,0.0405714381659655,280.15625180655115,20.0,8.333333333333333e-05,0.67,0.28,0.23,0.05,0.9,0.05,0.03,0.02
488.7532208218521,0.04082537136273015,280.26716345730966,20.0,8.333333333333333e-05,0.67,0.28,0.23,0.05,0.9,0.05,0.03,0.02
491.8004191830279,0.0410793045594948,280.37807510806965,20.0,8.333333333333333e-05,0.67,0.28,0.23,0.05,0.9,0.05,0.03,0.02
494.8503066839571,0.0413334618512389,280.48011785815766,20.0,8.333333333333333e-05,0.67,0.28,0.23,0.05,0.9,0.05,0.03,0.02
497.9001941848863,0.041587619142983,280.58216060824714,20.0,8.333333333333333e-05,0.67,0.28,0.23,0.05,0.9,0.05,0.03,0.02
500.9590720440807,0.0418425256312492,280.68070599906315,20.0,8.333333333333333e-05,0.67,0.28,0.23,0.05,0.9,0.05,0.03,0.02
504.0179499032751,0.0420974321195154,280.7792513898759,20.0,8.333333333333333e-05,0.67,0.28,0.23,0.05,0.9,0.05,0.03,0.02
507.0694221937413,0.04235172147705425,280.9035030312964,20.0,8.333333333333333e-05,0.67,0.28,0.23,0.05,0.9,0.05,0.03,0.02
510.1208944842075,0.0426060108345931,281.0277546727203,20.0,8.333333333333333e-05,0.67,0.28,0.23,0.05,0.9,0.05,0.03,0.02
513.1663973310963,0.0428598027385005,281.11017602042676,20.0,8.333333333333333e-05,0.67,0.28,0.23,0.05,0.9,0.05,0.03,0.02
516.2119001779852,0.0431135946424079,281.1925973681319,20.0,8.333333333333333e-05,0.67,0.28,0.23,0.05,0.9,0.05,0.03,0.02
519.2956680955905,0.04337057530220835,281.3180668253969,20.0,8.333333333333333e-05,0.67,0.28,0.23,0.05,0.9,0.05,0.03,0.02
522.3794360131958,0.0436275559620088,281.4435362826636,20.0,8.333333333333333e-05,0.67,0.28,0.23,0.05,0.9,0.05,0.03,0.02
525.4573334734029,0.04388404741702605,281.5710006360046,20.0,8.333333333333333e-05,0.67,0.28,0.23,0.05,0.9,0.05,0.03,0.02
528.5352309336099,0.0441405388720433,281.6984649893443,20.0,8.333333333333333e-05,0.67,0.28,0.23,0.05,0.9,0.05,0.03,0.02
531.6431331949467,0.044399530727154704,281.8002871739153,20.0,8.333333333333333e-05,0.67,0.28,0.23,0.05,0.9,0.05,0.03,0.02
534.7510354562835,0.0446585225822661,281.9021093584853,20.0,8.333333333333333e-05,0.67,0.28,0.23,0.05,0.9,0.05,0.03,0.02
537.8841484110098,0.0449196153284933,281.9922270508403,20.0,8.333333333333333e-05,0.67,0.28,0.23,0.05,0.9,0.05,0.03,0.02
541.0172613657363,0.0451807080747205,282.0823447431952,20.0,8.333333333333333e-05,0.67,0.28,0.23,0.05,0.9,0.05,0.03,0.02
544.1668161836553,0.045443170976213754,282.1803604446182,20.0,8.333333333333333e-05,0.67,0.28,0.23,0.05,0.9,0.05,0.03,0.02
547.3163710015743,0.045705633877707,282.27837614604084,20.0,8.333333333333333e-05,0.67,0.28,0.23,0.05,0.9,0.05,0.03,0.02
550.4787776134672,0.0459691677620314,282.3779409860879,20.0,8.333333333333333e-05,0.67,0.28,0.23,0.05,0.9,0.05,0.03,0.02
553.6411842253599,0.0462327016463558,282.4775058261365,20.0,8.333333333333333e-05,0.67,0.28,0.23,0.05,0.9,0.05,0.03,0.02
556.7991458283927,0.046495865113275206,282.608617047214,20.0,8.333333333333333e-05,0.67,0.28,0.23,0.05,0.9,0.05,0.03,0.02
559.9571074314255,0.0467590285801946,282.7397282682911,20.0,8.333333333333333e-05,0.67,0.28,0.23,0.05,0.9,0.05,0.03,0.02
563.1144252521589,0.047022138398589056,282.8282930576196,20.0,8.333333333333333e-05,0.67,0.28,0.23,0.05,0.9,0.05,0.03,0.02
566.2717430728923,0.0472852482169835,282.91685784694835,20.0,8.333333333333333e-05,0.67,0.28,0.23,0.05,0.9,0.05,0.03,0.02
569.399918747758,0.0475459295232223,283.0061173583414,20.0,8.333333333333333e-05,0.67,0.28,0.23,0.05,0.9,0.05,0.03,0.02
572.5280944226236,0.0478066108294611,283.0953768697342,20.0,8.333333333333333e-05,0.67,0.28,0.23,0.05,0.9,0.05,0.03,0.02
575.7033219987219,0.0480712131274693,283.18859346410017,20.0,8.333333333333333e-05,0.67,0.28,0.23,0.05,0.9,0.05,0.03,0.02
578.8785495748202,0.0483358154254775,283.28181005846614,20.0,8.333333333333333e-05,0.67,0.28,0.23,0.05,0.9,0.05,0.03,0.02
582.0453995708276,0.04859971959181145,283.3973008834376,20.0,8.333333333333333e-05,0.67,0.28,0.23,0.05,0.9,0.05,0.03,0.02
585.2122495668351,0.0488636237581454,283.5127917084087,20.0,8.333333333333333e-05,0.67,0.28,0.23,0.05,0.9,0.05,0.03,0.02
588.3661463560582,0.04912644849058065,283.6188841726602,20.0,8.333333333333333e-05,0.67,0.28,0.23,0.05,0.9,0.05,0.03,0.02
591.5200431452811,0.0493892732230159,283.7249766369129,20.0,8.333333333333333e-05,0.67,0.28,0.23,0.05,0.9,0.05,0.03,0.02
594.6881239608776,0.049653279957648955,283.8101368563279,20.0,8.333333333333333e-05,0.67,0.28,0.23,0.05,0.9,0.05,0.03,0.02
597.8562047764743,0.049917286692282,283.895297075743,20.0,8.333333333333333e-05,0.67,0.28,0.23,0.05,0.9,0.05,0.03,0.02
601.0204733104557,0.05018097573678045,283.996752167803,20.0,8.333333333333333e-05,0.67,0.28,0.23,0.05,0.9,0.05,0.03,0.02
604.1847418444371,0.0504446647812789,284.0982072598614,20.0,8.333333333333333e-05,0.67,0.28,0.23,0.05,0.9,0.05,0.03,0.02
607.3228509905985,0.050706173876792354,284.19694042793185,20.0,8.333333333333333e-05,0.67,0.28,0.23,0.05,0.9,0.05,0.03,0.02
610.4609601367599,0.0509676829723058,284.29567359600173,20.0,8.333333333333333e-05,0.67,0.28,0.23,0.05,0.9,0.05,0.03,0.02
613.6482036615537,0.05123328659937195,284.3858709023058,20.0,8.333333333333333e-05,0.67,0.28,0.23,0.05,0.9,0.05,0.03,0.02
616.8354471863476,0.0514988902264381,284.47606820861165,20.0,8.333333333333333e-05,0.67,0.28,0.23,0.05,0.9,0.05,0.03,0.02
619.9920215582523,0.0517619380907635,284.58825682220265,20.0,8.333333333333333e-05,0.67,0.28,0.23,0.05,0.9,0.05,0.03,0.02
623.1485959301571,0.0520249859550889,284.70044543579354,20.0,8.333333333333333e-05,0.67,0.28,0.23,0.05,0.9,0.05,0.03,0.02
626.3203370949807,0.0522892977188242,284.78187400933103,20.0,8.333333333333333e-05,0.67,0.28,0.23,0.05,0.9,0.05,0.03,0.02
629.4920782598043,0.0525536094825595,284.86330258286927,20.0,8.333333333333333e-05,0.67,0.28,0.23,0.05,0.9,0.05,0.03,0.02
632.7007236037143,0.052820996594552,284.93712454056276,20.0,8.333333333333333e-05,0.67,0.28,0.23,0.05,0.9,0.05,0.03,0.02
635.9093689476243,0.0530883837065445,285.01094649825495,20.0,8.333333333333333e-05,0.67,0.28,0.23,0.05,0.9,0.05,0.03,0.02
639.1128523118775,0.0533553406535656,285.1194441705474,20.0,8.333333333333333e-05,0.67,0.28,0.23,0.05,0.9,0.05,0.03,0.02
642.3163356761306,0.0536222976005867,285.2279418428391,20.0,8.333333333333333e-05,0.67,0.28,0.23,0.05,0.9,0.05,0.03,0.02
645.5324728628084,0.05389030903280985,285.2863995894146,20.0,8.333333333333333e-05,0.67,0.28,0.23,0.05,0.9,0.05,0.03,0.02
648.7486100494863,0.054158320465033,285.3448573359911,20.0,8.333333333333333e-05,0.67,0.28,0.23,0.05,0.9,0.05,0.03,0.02
651.9943547610537,0.054428799190996954,285.42421806629164,20.0,8.333333333333333e-05,0.67,0.28,0.23,0.05,0.9,0.05,0.03,0.02
655.2400994726211,0.0546992779169609,285.5035787965936,20.0,8.333333333333333e-05,0.67,0.28,0.23,0.05,0.9,0.05,0.03,0.02
658.473616222637,0.054968737646128904,285.59275320560107,20.0,8.333333333333333e-05,0.67,0.28,0.23,0.05,0.9,0.05,0.03,0.02
661.7071329726531,0.0552381973752969,285.68192761460836,20.0,8.333333333333333e-05,0.67,0.28,0.23,0.05,0.9,0.05,0.03,0.02
664.9661012199879,0.0555097780625748,285.76676146190783,20.0,8.333333333333333e-05,0.67,0.28,0.23,0.05,0.9,0.05,0.03,0.02
668.2250694673227,0.0557813587498527,285.85159530920384,20.0,8.333333333333333e-05,0.67,0.28,0.23,0.05,0.9,0.05,0.03,0.02
671.4786891140835,0.0560524937204161,285.92978755631333,20.0,8.333333333333333e-05,0.67,0.28,0.23,0.05,0.9,0.05,0.03,0.02
674.7323087608444,0.0563236286909795,286.00797980342844,20.0,8.333333333333333e-05,0.67,0.28,0.23,0.05,0.9,0.05,0.03,0.02
677.9843924126499,0.0565946356619633,286.106061389804,20.0,8.333333333333333e-05,0.67,0.28,0.23,0.05,0.9,0.05,0.03,0.02
681.2364760644555,0.0568656426329471,286.20414297617805,20.0,8.333333333333333e-05,0.67,0.28,0.23,0.05,0.9,0.05,0.03,0.02
684.5147014601055,0.057138828082584595,286.3043178945916,20.0,8.333333333333333e-05,0.67,0.28,0.23,0.05,0.9,0.05,0.03,0.02
687.7929268557555,0.0574120135322221,286.40449281300164,20.0,8.333333333333333e-05,0.67,0.28,0.23,0.05,0.9,0.05,0.03,0.02
691.0932206674142,0.057687038016527,286.5151980147526,20.0,8.333333333333333e-05,0.67,0.28,0.23,0.05,0.9,0.05,0.03,0.02
694.393514479073,0.0579620625008319,286.6259032165039,20.0,8.333333333333333e-05,0.67,0.28,0.23,0.05,0.9,0.05,0.03,0.02
697.7151551857166,0.0582388658930522,286.7363468318224,20.0,8.333333333333333e-05,0.67,0.28,0.23,0.05,0.9,0.05,0.03,0.02
701.0367958923603,0.0585156692852725,286.84679044714204,20.0,8.333333333333333e-05,0.67,0.28,0.23,0.05,0.9,0.05,0.03,0.02
704.5113249929163,0.0588052133769855,286.93914352237056,20.0,8.333333333333333e-05,0.67,0.28,0.23,0.05,0.9,0.05,0.03,0.02
707.9858540934723,0.0590947574686985,287.03149659759765,20.0,8.333333333333333e-05,0.67,0.28,0.23,0.05,0.9,0.05,0.03,0.02
711.4620729422493,0.059384442372763246,287.08267363384863,20.0,8.333333333333333e-05,0.67,0.28,0.23,0.05,0.9,0.05,0.03,0.02
714.9382917910262,0.059674127276828,287.1338506700999,20.0,8.333333333333333e-05,0.67,0.28,0.23,0.05,0.9,0.05,0.03,0.02
718.3948855378359,0.0599621767557288,287.21364750168584,20.0,8.333333333333333e-05,0.67,0.28,0.23,0.05,0.9,0.05,0.03,0.02
721.8514792846455,0.0602502262346296,287.2934443332727,20.0,8.333333333333333e-05,0.67,0.28,0.23,0.05,0.9,0.05,0.03,0.02
725.2462870115967,0.060533126878542204,287.3549094420302,20.0,8.333333333333333e-05,0.67,0.28,0.23,0.05,0.9,0.05,0.03,0.02
728.641094738548,0.0608160275224548,287.4163745507869,20.0,8.333333333333333e-05,0.67,0.28,0.23,0.05,0.9,0.05,0.03,0.02
732.084468259849,0.06110297531589655,287.4680738978854,20.0,8.333333333333333e-05,0.67,0.28,0.23,0.05,0.9,0.05,0.03,0.02
735.52784178115,0.0613899231093383,287.51977324498216,20.0,8.333333333333333e-05,0.67,0.28,0.23,0.05,0.9,0.05,0.03,0.02
738.9675798065091,0.061676567944784905,287.59248978904316,20.0,8.333333333333333e-05,0.67,0.28,0.23,0.05,0.9,0.05,0.03,0.02
742.4073178318683,0.0619632127802315,287.6652063331075,20.0,8.333333333333333e-05,0.67,0.28,0.23,0.05,0.9,0.05,0.03,0.02
745.852580883157,0.06225031803450555,287.712885068986,20.0,8.333333333333333e-05,0.67,0.28,0.23,0.05,0.9,0.05,0.03,0.02
749.2978439344456,0.0625374232887796,287.7605638048646,20.0,8.333333333333333e-05,0.67,0.28,0.23,0.05,0.9,0.05,0.03,0.02
752.6252663726151,0.0628147084919604,287.8401179590236,20.0,8.333333333333333e-05,0.67,0.28,0.23,0.05,0.9,0.05,0.03,0.02
755.9526888107846,0.0630919936951412,287.91967211318433,20.0,8.333333333333333e-05,0.67,0.28,0.23,0.05,0.9,0.05,0.03,0.02
759.271937584811,0.0633685977596434,288.01341815969135,20.0,8.333333333333333e-05,0.67,0.28,0.23,0.05,0.9,0.05,0.03,0.02
762.5911863588375,0.0636452018241456,288.10716420619684,20.0,8.333333333333333e-05,0.67,0.28,0.23,0.05,0.9,0.05,0.03,0.02
765.9679040596461,0.06392659496587966,288.1754734336723,20.0,8.333333333333333e-05,0.67,0.28,0.23,0.05,0.9,0.05,0.03,0.02
769.3446217604547,0.0642079881076137,288.24378266114456,20.0,8.333333333333333e-05,0.67,0.28,0.23,0.05,0.9,0.05,0.03,0.02
772.7940843449055,0.0644954433229846,288.3252801722801,20.0,8.333333333333333e-05,0.67,0.28,0.23,0.05,0.9,0.05,0.03,0.02
776.2435469293564,0.0647828985383555,288.40677768341925,20.0,8.333333333333333e-05,0.67,0.28,0.23,0.05,0.9,0.05,0.03,0.02
779.6434259818245,0.06506622179272785,288.5017483707272,20.0,8.333333333333333e-05,0.67,0.28,0.23,0.05,0.9,0.05,0.03,0.02
783.0433050342926,0.0653495450471002,288.5967190580345,20.0,8.333333333333333e-05,0.67,0.28,0.23,0.05,0.9,0.05,0.03,0.02
786.4542319226595,0.06563378895446409,288.64283719600553,20.0,8.333333333333333e-05,0.67,0.28,0.23,0.05,0.9,0.05,0.03,0.02
789.8651588110263,0.065918032861828,288.6889553339775,20.0,8.333333333333333e-05,0.67,0.28,0.23,0.05,0.9,0.05,0.03,0.02
793.3065305735745,0.06620481384204036,288.749334467971,20.0,8.333333333333333e-05,0.67,0.28,0.23,0.05,0.9,0.05,0.03,0.02
796.7479023361227,0.0664915948222527,288.8097136019616,20.0,8.333333333333333e-05,0.67,0.28,0.23,0.05,0.9,0.05,0.03,0.02
800.183887729396,0.0667779269383588,288.88446990650016,20.0,8.333333333333333e-05,0.67,0.28,0.23,0.05,0.9,0.05,0.03,0.02
803.6198731226692,0.0670642590544649,288.9592262110398,20.0,8.333333333333333e-05,0.67,0.28,0.23,0.05,0.9,0.05,0.03,0.02
807.0889606058122,0.06735334967806014,289.02417337629873,20.0,8.333333333333333e-05,0.67,0.28,0.23,0.05,0.9,0.05,0.03,0.02
810.558048088955,0.0676424403016554,289.0891205415614,20.0,8.333333333333333e-05,0.67,0.28,0.23,0.05,0.9,0.05,0.03,0.02
814.000450040462,0.06792930713094765,289.1726163256634,20.0,8.333333333333333e-05,0.67,0.28,0.23,0.05,0.9,0.05,0.03,0.02
817.4428519919692,0.0682161739602399,289.25611210976047,20.0,8.333333333333333e-05,0.67,0.28,0.23,0.05,0.9,0.05,0.03,0.02
820.9208177364585,0.06850600443894736,289.3158875949234,20.0,8.333333333333333e-05,0.67,0.28,0.23,0.05,0.9,0.05,0.03,0.02
824.3987834809479,0.0687958349176548,289.3756630800855,20.0,8.333333333333333e-05,0.67,0.28,0.23,0.05,0.9,0.05,0.03,0.02
827.9171256466216,0.0690890300981276,289.419900930638,20.0,8.333333333333333e-05,0.67,0.28,0.23,0.05,0.9,0.05,0.03,0.02
831.4354678122951,0.0693822252786004,289.4641387811901,20.0,8.333333333333333e-05,0.67,0.28,0.23,0.05,0.9,0.05,0.03,0.02
834.9695964659606,0.0696767359997392,289.5257358971046,20.0,8.333333333333333e-05,0.67,0.28,0.23,0.05,0.9,0.05,0.03,0.02
838.5037251196262,0.069971246720878,289.5873330130231,20.0,8.333333333333333e-05,0.67,0.28,0.23,0.05,0.9,0.05,0.03,0.02
842.0257257245132,0.07026474677128525,289.6487858874721,20.0,8.333333333333333e-05,0.67,0.28,0.23,0.05,0.9,0.05,0.03,0.02
845.5477263294002,0.0705582468216925,289.71023876191884,20.0,8.333333333333333e-05,0.67,0.28,0.23,0.05,0.9,0.05,0.03,0.02
849.0998337038733,0.07085425576956525,289.7537964735133,20.0,8.333333333333333e-05,0.67,0.28,0.23,0.05,0.9,0.05,0.03,0.02
852.6519410783463,0.071150264717438,289.7973541851098,20.0,8.333333333333333e-05,0.67,0.28,0.23,0.05,0.9,0.05,0.03,0.02
856.2111035011972,0.07144686158600891,289.86931757187483,20.0,8.333333333333333e-05,0.67,0.28,0.23,0.05,0.9,0.05,0.03,0.02
859.7702659240479,0.0717434584545798,289.9412809586415,20.0,8.333333333333333e-05,0.67,0.28,0.23,0.05,0.9,0.05,0.03,0.02
863.3503581373029,0.07204179947235105,290.008656709197,20.0,8.333333333333333e-05,0.67,0.28,0.23,0.05,0.9,0.05,0.03,0.02
866.9304503505579,0.0723401404901223,290.07603245974866,20.0,8.333333333333333e-05,0.67,0.28,0.23,0.05,0.9,0.05,0.03,0.02
870.5237257763763,0.0726395801089405,290.14683599930464,20.0,8.333333333333333e-05,0.67,0.28,0.23,0.05,0.9,0.05,0.03,0.02
874.1170012021946,0.0729390197277587,290.21763953885807,20.0,8.333333333333333e-05,0.67,0.28,0.23,0.05,0.9,0.05,0.03,0.02
877.7259829360119,0.07323976820557679,290.26364488710504,20.0,8.333333333333333e-05,0.67,0.28,0.23,0.05,0.9,0.05,0.03,0.02
881.3349646698291,0.0735405166833949,290.30965023535515,20.0,8.333333333333333e-05,0.67,0.28,0.23,0.05,0.9,0.05,0.03,0.02
884.9762080154667,0.0738439536288647,290.3740398736226,20.0,8.333333333333333e-05,0.67,0.28,0.23,0.05,0.9,0.05,0.03,0.02
888.6174513611044,0.0741473905743345,290.4384295118938,20.0,8.333333333333333e-05,0.67,0.28,0.23,0.05,0.9,0.05,0.03,0.02
892.2983904573832,0.07445413549902441,290.5148093810898,20.0,8.333333333333333e-05,0.67,0.28,0.23,0.05,0.9,0.05,0.03,0.02
895.979329553662,0.0747608804237143,290.59118925028474,20.0,8.333333333333333e-05,0.67,0.28,0.23,0.05,0.9,0.05,0.03,0.02
899.6606290702791,0.07506765538343241,290.6609584332603,20.0,8.333333333333333e-05,0.67,0.28,0.23,0.05,0.9,0.05,0.03,0.02
903.3419285868964,0.0753744303431505,290.73072761623797,20.0,8.333333333333333e-05,0.67,0.28,0.23,0.05,0.9,0.05,0.03,0.02
907.0522641396027,0.07568362497254269,290.76583913160243,20.0,8.333333333333333e-05,0.67,0.28,0.23,0.05,0.9,0.05,0.03,0.02
910.762599692309,0.0759928196019349,290.8009506469616,20.0,8.333333333333333e-05,0.67,0.28,0.23,0.05,0.9,0.05,0.03,0.02
914.5287985416177,0.07630666950604395,290.82554488832113,20.0,8.333333333333333e-05,0.67,0.28,0.23,0.05,0.9,0.05,0.03,0.02
918.2949973909264,0.076620519410153,290.8501391296789,20.0,8.333333333333333e-05,0.67,0.28,0.23,0.05,0.9,0.05,0.03,0.02
922.0586521119947,0.07693415730357536,290.88501642170536,20.0,8.333333333333333e-05,0.67,0.28,0.23,0.05,0.9,0.05,0.03,0.02
925.8223068330628,0.0772477951969977,290.91989371373165,20.0,8.333333333333333e-05,0.67,0.28,0.23,0.05,0.9,0.05,0.03,0.02
929.5973140914856,0.0775623791351996,290.9818732881957,20.0,8.333333333333333e-05,0.67,0.28,0.23,0.05,0.9,0.05,0.03,0.02
933.3723213499084,0.0778769630734015,291.04385286266375,20.0,8.333333333333333e-05,0.67,0.28,0.23,0.05,0.9,0.05,0.03,0.02
937.1687718304114,0.07819333394677674,291.0984434132382,20.0,8.333333333333333e-05,0.67,0.28,0.23,0.05,0.9,0.05,0.03,0.02
940.9652223109144,0.078509704820152,291.153033963814,20.0,8.333333333333333e-05,0.67,0.28,0.23,0.05,0.9,0.05,0.03,0.02
944.7775037439358,0.07882739493957044,291.18558481555,20.0,8.333333333333333e-05,0.67,0.28,0.23,0.05,0.9,0.05,0.03,0.02
948.5897851769572,0.0791450850589889,291.21813566728696,20.0,8.333333333333333e-05,0.67,0.28,0.23,0.05,0.9,0.05,0.03,0.02
952.4635824393855,0.0794679014975246,291.254983228605,20.0,8.333333333333333e-05,0.67,0.28,0.23,0.05,0.9,0.05,0.03,0.02
956.3373797018138,0.0797907179360603,291.2918307899223,20.0,8.333333333333333e-05,0.67,0.28,0.23,0.05,0.9,0.05,0.03,0.02
960.2632709363152,0.0801178755389354,291.3502734630708,20.0,8.333333333333333e-05,0.67,0.28,0.23,0.05,0.9,0.05,0.03,0.02
964.1891621708164,0.0804450331418105,291.4087161362121,20.0,8.333333333333333e-05,0.67,0.28,0.23,0.05,0.9,0.05,0.03,0.02
968.1407698795036,0.0807743337842011,291.4509092835316,20.0,8.333333333333333e-05,0.67,0.28,0.23,0.05,0.9,0.05,0.03,0.02
972.0923775881909,0.0811036344265917,291.49310243085625,20.0,8.333333333333333e-05,0.67,0.28,0.23,0.05,0.9,0.05,0.03,0.02
976.0786883841567,0.0814358269929222,291.53165105923574,20.0,8.333333333333333e-05,0.67,0.28,0.23,0.05,0.9,0.05,0.03,0.02
980.0649991801226,0.0817680195592527,291.5701996876139,20.0,8.333333333333333e-05,0.67,0.28,0.23,0.05,0.9,0.05,0.03,0.02
984.0985742820933,0.08210415081775024,291.5955578337964,20.0,8.333333333333333e-05,0.67,0.28,0.23,0.05,0.9,0.05,0.03,0.02
988.132149384064,0.0824402820762478,291.62091597997795,20.0,8.333333333333333e-05,0.67,0.28,0.23,0.05,0.9,0.05,0.03,0.02
992.1767077082284,0.08277732860326151,291.6367897219549,20.0,8.333333333333333e-05,0.67,0.28,0.23,0.05,0.9,0.05,0.03,0.02
996.2212660323928,0.0831143751302752,291.65266346393565,20.0,8.333333333333333e-05,0.67,0.28,0.23,0.05,0.9,0.05,0.03,0.02
1000.3404000870868,0.0834576363014997,291.6788714002582,20.0,8.333333333333333e-05,0.67,0.28,0.23,0.05,0.9,0.05,0.03,0.02
1004.4595341417808,0.0838008974727242,291.7050793365751,20.0,8.333333333333333e-05,0.67,0.28,0.23,0.05,0.9,0.05,0.03,0.02
1008.5843148270405,0.08414462919649585,291.71215830339617,20.0,8.333333333333333e-05,0.67,0.28,0.23,0.05,0.9,0.05,0.03,0.02
1012.7090955123005,0.0844883609202675,291.7192372702211,20.0,8.333333333333333e-05,0.67,0.28,0.23,0.05,0.9,0.05,0.03,0.02
1016.8007570161942,0.08482933271225865,291.7280017008131,20.0,8.333333333333333e-05,0.67,0.28,0.23,0.05,0.9,0.05,0.03,0.02
1020.892418520088,0.0851703045042498,291.7367661314034,20.0,8.333333333333333e-05,0.67,0.28,0.23,0.05,0.9,0.05,0.03,0.02
1025.0230232916315,0.0855145215685451,291.75467234230587,20.0,8.333333333333333e-05,0.67,0.28,0.23,0.05,0.9,0.05,0.03,0.02
1029.1536280631751,0.0858587386328404,291.772578553208,20.0,8.333333333333333e-05,0.67,0.28,0.23,0.05,0.9,0.05,0.03,0.02
1033.3061421130053,0.08620478147032624,291.7970109094425,20.0,8.333333333333333e-05,0.67,0.28,0.23,0.05,0.9,0.05,0.03,0.02
1037.4586561628355,0.0865508243078121,291.821443265679,20.0,8.333333333333333e-05,0.67,0.28,0.23,0.05,0.9,0.05,0.03,0.02