File: datasets/al_6061_comp/csv/T_020_A_3.csv
Time,Strain(%),Stress(MPa),Temp(C),SR(%/s),Si(%),Fe(%),Cu(%),Mn(%),Mg(%),Cr(%),Zn(%),Ti(%)
0.0,0.0001158289051822,42.5915873102486,20.0,8.333333333333333e-05,0.56,0.23,0.18,0.07,0.86,0.06,0.02,0.01
1.0595408862071998,0.0002041239790328,48.9394886754054,20.0,8.333333333333333e-05,0.56,0.23,0.18,0.07,0.86,0.06,0.02,0.01
2.1400579061316,0.0002941670640265,55.3361995960319,20.0,8.333333333333333e-05,0.56,0.23,0.18,0.07,0.86,0.06,0.02,0.01
3.461486289534,0.0004042860959767,61.8767486433341,20.0,8.333333333333333e-05,0.56,0.23,0.18,0.07,0.86,0.06,0.02,0.01
4.644459468735601,0.0005028671942435,68.5002100695586,20.0,8.333333333333333e-05,0.56,0.23,0.18,0.07,0.86,0.06,0.02,0.01
5.874281941128,0.0006053524002762,75.2323223460231,20.0,8.333333333333333e-05,0.56,0.23,0.18,0.07,0.86,0.06,0.02,0.01
7.264980082695601,0.0007212439120735,82.0074645910808,20.0,8.333333333333333e-05,0.56,0.23,0.18,0.07,0.86,0.06,0.02,0.01
8.377445299245599,0.000813949346786,88.7861735372194,20.0,8.333333333333333e-05,0.56,0.23,0.18,0.07,0.86,0.06,0.02,0.01
9.4501698526812,0.0009033430595723,95.5581595703871,20.0,8.333333333333333e-05,0.56,0.23,0.18,0.07,0.86,0.06,0.02,0.01
10.714415993274,0.0010086969046217,102.249879519597,20.0,8.333333333333333e-05,0.56,0.23,0.18,0.07,0.86,0.06,0.02,0.01
11.9898244960236,0.0011149809465175,108.964718625063,20.0,8.333333333333333e-05,0.56,0.23,0.18,0.07,0.86,0.06,0.02,0.01
13.4966002067904,0.0012405455890814,115.590404178709,20.0,8.333333333333333e-05,0.56,0.23,0.18,0.07,0.86,0.06,0.02,0.01
14.869406063368798,0.0013549460771296,122.167097092043,20.0,8.333333333333333e-05,0.56,0.23,0.18,0.07,0.86,0.06,0.02,0.01
16.253894119210802,0.0014703200817831,128.704896858146,20.0,8.333333333333333e-05,0.56,0.23,0.18,0.07,0.86,0.06,0.02,0.01
17.578279172629202,0.0015806855029013,135.170923710138,20.0,8.333333333333333e-05,0.56,0.23,0.18,0.07,0.86,0.06,0.02,0.01
18.8494551172704,0.0016866168316214,141.624283449291,20.0,8.333333333333333e-05,0.56,0.23,0.18,0.07,0.86,0.06,0.02,0.01
20.123632482956403,0.0017927982787619,147.972113434166,20.0,8.333333333333333e-05,0.56,0.23,0.18,0.07,0.86,0.06,0.02,0.01
21.3319072886004,0.0018934878458989,154.217221531817,20.0,8.333333333333333e-05,0.56,0.23,0.18,0.07,0.86,0.06,0.02,0.01
22.5767986365936,0.001997228791565,160.368876018169,20.0,8.333333333333333e-05,0.56,0.23,0.18,0.07,0.86,0.06,0.02,0.01
23.9941707085716,0.0021153431308965,166.472860380865,20.0,8.333333333333333e-05,0.56,0.23,0.18,0.07,0.86,0.06,0.02,0.01
25.234677795787203,0.0022187187214978,172.53965052145,20.0,8.333333333333333e-05,0.56,0.23,0.18,0.07,0.86,0.06,0.02,0.01
26.519103889026,0.0023257542292677,178.554463475125,20.0,8.333333333333333e-05,0.56,0.23,0.18,0.07,0.86,0.06,0.02,0.01
27.87812769108361,0.0024390062127725,184.480357285103,20.0,8.333333333333333e-05,0.56,0.23,0.18,0.07,0.86,0.06,0.02,0.01
29.057553649690803,0.0025372917093231,190.30546296165,20.0,8.333333333333333e-05,0.56,0.23,0.18,0.07,0.86,0.06,0.02,0.01
30.347615632699203,0.0026447968745738,196.017963258863,20.0,8.333333333333333e-05,0.56,0.23,0.18,0.07,0.86,0.06,0.02,0.01
31.8111652082004,0.0027667593391989,201.653112822058,20.0,8.333333333333333e-05,0.56,0.23,0.18,0.07,0.86,0.06,0.02,0.01
33.1540066946448,0.0028786627964026,207.253520277212,20.0,8.333333333333333e-05,0.56,0.23,0.18,0.07,0.86,0.06,0.02,0.01
34.7060611763412,0.0030080006698773,212.827022703757,20.0,8.333333333333333e-05,0.56,0.23,0.18,0.07,0.86,0.06,0.02,0.01
36.18409340832,0.0031311700225422,218.336345829498,20.0,8.333333333333333e-05,0.56,0.23,0.18,0.07,0.86,0.06,0.02,0.01
37.5960139240836,0.0032488300655225,223.651506241568,20.0,8.333333333333333e-05,0.56,0.23,0.18,0.07,0.86,0.06,0.02,0.01
39.216843635235605,0.0033838992081185,228.800310951366,20.0,8.333333333333333e-05,0.56,0.23,0.18,0.07,0.86,0.06,0.02,0.01
41.080575392023206,0.0035392101878508,233.705076537441,20.0,8.333333333333333e-05,0.56,0.23,0.18,0.07,0.86,0.06,0.02,0.01
43.277069323276805,0.0037222513487886,238.37505262594,20.0,8.333333333333333e-05,0.56,0.23,0.18,0.07,0.86,0.06,0.02,0.01
46.0421293618128,0.0039526730186666,242.750588997389,20.0,8.333333333333333e-05,0.56,0.23,0.18,0.07,0.86,0.06,0.02,0.01
49.3125147678192,0.0042252051358338,246.604182765988,20.0,8.333333333333333e-05,0.56,0.23,0.18,0.07,0.86,0.06,0.02,0.01
53.1479335496376,0.004544823367652,249.79252759059,20.0,8.333333333333333e-05,0.56,0.23,0.18,0.07,0.86,0.06,0.02,0.01
57.3159387454884,0.0048921571339729,252.127423380718,20.0,8.333333333333333e-05,0.56,0.23,0.18,0.07,0.86,0.06,0.02,0.01
61.685591686308,0.0052562948790412,253.71378850794,20.0,8.333333333333333e-05,0.56,0.23,0.18,0.07,0.86,0.06,0.02,0.01
66.2233039503504,0.0056344375677114,254.713923439874,20.0,8.333333333333333e-05,0.56,0.23,0.18,0.07,0.86,0.06,0.02,0.01
70.8080243673264,0.0060164976024594,255.373977765927,20.0,8.333333333333333e-05,0.56,0.23,0.18,0.07,0.86,0.06,0.02,0.01
75.4977656648664,0.0064073093772544,255.856449887214,20.0,8.333333333333333e-05,0.56,0.23,0.18,0.07,0.86,0.06,0.02,0.01
80.2435238538912,0.0068027892263398,256.240170906248,20.0,8.333333333333333e-05,0.56,0.23,0.18,0.07,0.86,0.06,0.02,0.01
84.9454751826804,0.0071946185037389,256.57000624993,20.0,8.333333333333333e-05,0.56,0.23,0.18,0.07,0.86,0.06,0.02,0.01
89.6426911155924,0.0075860531648149,256.857061690545,20.0,8.333333333333333e-05,0.56,0.23,0.18,0.07,0.86,0.06,0.02,0.01
94.2713610213516,0.0079717756569615,257.100457308004,20.0,8.333333333333333e-05,0.56,0.23,0.18,0.07,0.86,0.06,0.02,0.01
98.917503277218,0.0083589541782837,257.350513435277,20.0,8.333333333333333e-05,0.56,0.23,0.18,0.07,0.86,0.06,0.02,0.01
103.5212362662084,0.0087425985940329,257.565222671198,20.0,8.333333333333333e-05,0.56,0.23,0.18,0.07,0.86,0.06,0.02,0.01
108.0593633182512,0.0091207758483698,257.781276890854,20.0,8.333333333333333e-05,0.56,0.23,0.18,0.07,0.86,0.06,0.02,0.01
112.581174733464,0.0094975934663042,258.000374016514,20.0,8.333333333333333e-05,0.56,0.23,0.18,0.07,0.86,0.06,0.02,0.01
117.0918275008356,0.0098734811969185,258.197429467474,20.0,8.333333333333333e-05,0.56,0.23,0.18,0.07,0.86,0.06,0.02,0.01
121.5269210634792,0.0102430723271388,258.40902962546,20.0,8.333333333333333e-05,0.56,0.23,0.18,0.07,0.86,0.06,0.02,0.01
126.0321286968852,0.0106185062965893,258.615484887458,20.0,8.333333333333333e-05,0.56,0.23,0.18,0.07,0.86,0.06,0.02,0.01
130.4972570238024,0.0109906003238324,258.845765182784,20.0,8.333333333333333e-05,0.56,0.23,0.18,0.07,0.86,0.06,0.02,0.01
134.9805704676948,0.0113642097774901,259.05410907032,20.0,8.333333333333333e-05,0.56,0.23,0.18,0.07,0.86,0.06,0.02,0.01
139.371851649468,0.0117301498759712,259.236570674599,20.0,8.333333333333333e-05,0.56,0.23,0.18,0.07,0.86,0.06,0.02,0.01
143.7782410609656,0.012097348993596,259.444073332652,20.0,8.333333333333333e-05,0.56,0.23,0.18,0.07,0.86,0.06,0.02,0.01
148.1772294451944,0.0124639313589484,259.622425192521,20.0,8.333333333333333e-05,0.56,0.23,0.18,0.07,0.86,0.06,0.02,0.01
152.7411218137152,0.0128442557229918,259.827274179809,20.0,8.333333333333333e-05,0.56,0.23,0.18,0.07,0.86,0.06,0.02,0.01
157.25597772364682,0.0132204937154861,260.034089788493,20.0,8.333333333333333e-05,0.56,0.23,0.18,0.07,0.86,0.06,0.02,0.01
161.73954804945,0.0135941245759697,260.225178523983,20.0,8.333333333333333e-05,0.56,0.23,0.18,0.07,0.86,0.06,0.02,0.01
166.2113408156016,0.013966773973149,260.409258809199,20.0,8.333333333333333e-05,0.56,0.23,0.18,0.07,0.86,0.06,0.02,0.01
170.6529248440272,0.0143369059755178,260.577160841625,20.0,8.333333333333333e-05,0.56,0.23,0.18,0.07,0.86,0.06,0.02,0.01
175.039997385954,0.0147024953540117,260.779763654964,20.0,8.333333333333333e-05,0.56,0.23,0.18,0.07,0.86,0.06,0.02,0.01
179.4364266334584,0.0150688644579704,260.97677336302,20.0,8.333333333333333e-05,0.56,0.23,0.18,0.07,0.86,0.06,0.02,0.01
183.810665845734,0.0154333843923267,261.163008174625,20.0,8.333333333333333e-05,0.56,0.23,0.18,0.07,0.86,0.06,0.02,0.01
188.1953573423784,0.0157987753503804,261.353717104903,20.0,8.333333333333333e-05,0.56,0.23,0.18,0.07,0.86,0.06,0.02,0.01
192.5195989158624,0.0161591288148374,261.545528798265,20.0,8.333333333333333e-05,0.56,0.23,0.18,0.07,0.86,0.06,0.02,0.01
196.8779283673116,0.0165223229357915,261.746648266905,20.0,8.333333333333333e-05,0.56,0.23,0.18,0.07,0.86,0.06,0.02,0.01
201.0452091152952,0.0168695963314568,261.913307994508,20.0,8.333333333333333e-05,0.56,0.23,0.18,0.07,0.86,0.06,0.02,0.01
205.1271694988616,0.017209759696754,262.079292706943,20.0,8.333333333333333e-05,0.56,0.23,0.18,0.07,0.86,0.06,0.02,0.01
209.1461981798712,0.0175446787535048,262.269589142329,20.0,8.333333333333333e-05,0.56,0.23,0.18,0.07,0.86,0.06,0.02,0.01
213.2404138077696,0.017885863389163,262.457175359145,20.0,8.333333333333333e-05,0.56,0.23,0.18,0.07,0.86,0.06,0.02,0.01
217.3927478882232,0.0182318912292008,262.664745596354,20.0,8.333333333333333e-05,0.56,0.23,0.18,0.07,0.86,0.06,0.02,0.01
221.6295058547052,0.0185849543930743,262.858717639107,20.0,8.333333333333333e-05,0.56,0.23,0.18,0.07,0.86,0.06,0.02,0.01
225.8843395803192,0.0189395238702088,263.026512965048,20.0,8.333333333333333e-05,0.56,0.23,0.18,0.07,0.86,0.06,0.02,0.01
230.052030984072,0.0192868314871882,263.236472363221,20.0,8.333333333333333e-05,0.56,0.23,0.18,0.07,0.86,0.06,0.02,0.01
234.312791589348,0.0196418948709612,263.394995612111,20.0,8.333333333333333e-05,0.56,0.23,0.18,0.07,0.86,0.06,0.02,0.01
238.552487499744,0.0199952028634942,263.565634923886,20.0,8.333333333333333e-05,0.56,0.23,0.18,0.07,0.86,0.06,0.02,0.01
242.7355892079372,0.0203437946725103,263.764637149516,20.0,8.333333333333333e-05,0.56,0.23,0.18,0.07,0.86,0.06,0.02,0.01
246.9224517832452,0.0206926998871193,263.947114362671,20.0,8.333333333333333e-05,0.56,0.23,0.18,0.07,0.86,0.06,0.02,0.01
251.17446432447,0.0210470342655547,264.140599084975,20.0,8.333333333333333e-05,0.56,0.23,0.18,0.07,0.86,0.06,0.02,0.01
255.4777586923404,0.0214056421295439,264.322400927114,20.0,8.333333333333333e-05,0.56,0.23,0.18,0.07,0.86,0.06,0.02,0.01
259.7236568432376,0.021759466975452,264.500897148872,20.0,8.333333333333333e-05,0.56,0.23,0.18,0.07,0.86,0.06,0.02,0.01
263.91730529425803,0.0221089376797037,264.681932732659,20.0,8.333333333333333e-05,0.56,0.23,0.18,0.07,0.86,0.06,0.02,0.01
268.0743804054516,0.0224553606056365,264.854224239974,20.0,8.333333333333333e-05,0.56,0.23,0.18,0.07,0.86,0.06,0.02,0.01
272.1368548568244,0.0227939001432509,265.057868416092,20.0,8.333333333333333e-05,0.56,0.23,0.18,0.07,0.86,0.06,0.02,0.01
276.1591151749272,0.0231290885030928,265.232375833927,20.0,8.333333333333333e-05,0.56,0.23,0.18,0.07,0.86,0.06,0.02,0.01
280.09517598985803,0.0234570935710037,265.436831558401,20.0,8.333333333333333e-05,0.56,0.23,0.18,0.07,0.86,0.06,0.02,0.01
284.11586949024365,0.0237921513627025,265.607604637439,20.0,8.333333333333333e-05,0.56,0.23,0.18,0.07,0.86,0.06,0.02,0.01
288.0905028746761,0.0241233708114052,265.77800248879,20.0,8.333333333333333e-05,0.56,0.23,0.18,0.07,0.86,0.06,0.02,0.01
292.2168181476408,0.0244672304174856,265.979938325937,20.0,8.333333333333333e-05,0.56,0.23,0.18,0.07,0.86,0.06,0.02,0.01
296.1837425078712,0.0247978074475048,266.116727111934,20.0,8.333333333333333e-05,0.56,0.23,0.18,0.07,0.86,0.06,0.02,0.01
300.250856932842,0.0251367336495857,266.319186339784,20.0,8.333333333333333e-05,0.56,0.23,0.18,0.07,0.86,0.06,0.02,0.01
304.34729034101645,0.0254781031002669,266.482720927675,20.0,8.333333333333333e-05,0.56,0.23,0.18,0.07,0.86,0.06,0.02,0.01
308.48885138133966,0.0258232331869605,266.683378955869,20.0,8.333333333333333e-05,0.56,0.23,0.18,0.07,0.86,0.06,0.02,0.01
312.6143620468116,0.0261670257424165,266.852447076512,20.0,8.333333333333333e-05,0.56,0.23,0.18,0.07,0.86,0.06,0.02,0.01
316.7798413568124,0.0265141490182499,267.023083379737,20.0,8.333333333333333e-05,0.56,0.23,0.18,0.07,0.86,0.06,0.02,0.01
320.80467549013684,0.0268495518626936,267.162525238024,20.0,8.333333333333333e-05,0.56,0.23,0.18,0.07,0.86,0.06,0.02,0.01
324.85497699345245,0.0271870769879699,267.344186082673,20.0,8.333333333333333e-05,0.56,0.23,0.18,0.07,0.86,0.06,0.02,0.01
328.8448575541464,0.0275195670346944,267.493922731012,20.0,8.333333333333333e-05,0.56,0.23,0.18,0.07,0.86,0.06,0.02,0.01
332.86788116871,0.0278548190025747,267.687894773765,20.0,8.333333333333333e-05,0.56,0.23,0.18,0.07,0.86,0.06,0.02,0.01
336.98399723615404,0.0281978286748617,267.857703062482,20.0,8.333333333333333e-05,0.56,0.23,0.18,0.07,0.86,0.06,0.02,0.01
340.98785126563087,0.0285314831773181,268.035302703901,20.0,8.333333333333333e-05,0.56,0.23,0.18,0.07,0.86,0.06,0.02,0.01
345.105730841238,0.0288746398086187,268.204719751679,20.0,8.333333333333333e-05,0.56,0.23,0.18,0.07,0.86,0.06,0.02,0.01
349.12531358249527,0.0292096050370568,268.358484929745,20.0,8.333333333333333e-05,0.56,0.23,0.18,0.07,0.86,0.06,0.02,0.01
353.07171826387804,0.0295384720938387,268.521588372968,20.0,8.333333333333333e-05,0.56,0.23,0.18,0.07,0.86,0.06,0.02,0.01
356.97478928891763,0.029863728012592,268.682782535175,20.0,8.333333333333333e-05,0.56,0.23,0.18,0.07,0.86,0.06,0.02,0.01
360.8750671465992,0.0301887511673988,268.849288648788,20.0,8.333333333333333e-05,0.56,0.23,0.18,0.07,0.86,0.06,0.02,0.01
364.8501010694844,0.0305200039943059,268.993202797971,20.0,8.333333333333333e-05,0.56,0.23,0.18,0.07,0.86,0.06,0.02,0.01
368.88647469979327,0.0308563684634983,269.135889296882,20.0,8.333333333333333e-05,0.56,0.23,0.18,0.07,0.86,0.06,0.02,0.01
373.002722150988,0.0311993890844312,269.310393285617,20.0,8.333333333333333e-05,0.56,0.23,0.18,0.07,0.86,0.06,0.02,0.01
377.021281277064,0.0315342690116042,269.455618726006,20.0,8.333333333333333e-05,0.56,0.23,0.18,0.07,0.86,0.06,0.02,0.01
381.05669492107086,0.0318705534819381,269.642999617351,20.0,8.333333333333333e-05,0.56,0.23,0.18,0.07,0.86,0.06,0.02,0.01
385.1305152139476,0.0322100385063445,269.779586879004,20.0,8.333333333333333e-05,0.56,0.23,0.18,0.07,0.86,0.06,0.02,0.01
389.1763203830952,0.0325471889371068,269.918436344032,20.0,8.333333333333333e-05,0.56,0.23,0.18,0.07,0.86,0.06,0.02,0.01
393.2384685533784,0.0328857012846304,270.100647446061,20.0,8.333333333333333e-05,0.56,0.23,0.18,0.07,0.86,0.06,0.02,0.01
397.3056650406132,0.0332246343252333,270.247057042143,20.0,8.333333333333333e-05,0.56,0.23,0.18,0.07,0.86,0.06,0.02,0.01
401.32742650375445,0.0335597811138284,270.427857797257,20.0,8.333333333333333e-05,0.56,0.23,0.18,0.07,0.86,0.06,0.02,0.01
405.3557483608872,0.0338954746019228,270.5711194307,20.0,8.333333333333333e-05,0.56,0.23,0.18,0.07,0.86,0.06,0.02,0.01
409.4109250271892,0.0342334059907813,270.706867031844,20.0,8.333333333333333e-05,0.56,0.23,0.18,0.07,0.86,0.06,0.02,0.01
413.49285469976286,0.0345735667968291,270.851620615086,20.0,8.333333333333333e-05,0.56,0.23,0.18,0.07,0.86,0.06,0.02,0.01
417.56915457639127,0.0349132584532148,271.008351512048,20.0,8.333333333333333e-05,0.56,0.23,0.18,0.07,0.86,0.06,0.02,0.01
421.6820258074392,0.0352559977224688,271.164579253235,20.0,8.333333333333333e-05,0.56,0.23,0.18,0.07,0.86,0.06,0.02,0.01
425.7484355684773,0.0355948652025553,271.33702858004,20.0,8.333333333333333e-05,0.56,0.23,0.18,0.07,0.86,0.06,0.02,0.01
429.6758862968053,0.0359221527632493,271.471066645263,20.0,8.333333333333333e-05,0.56,0.23,0.18,0.07,0.86,0.06,0.02,0.01
433.7693486119812,0.0362632746228473,271.61191162024,20.0,8.333333333333333e-05,0.56,0.23,0.18,0.07,0.86,0.06,0.02,0.01
437.77163661103685,0.0365967986227686,271.735982940619,20.0,8.333333333333333e-05,0.56,0.23,0.18,0.07,0.86,0.06,0.02,0.01
441.9231974068789,0.0369427620224221,271.879961466309,20.0,8.333333333333333e-05,0.56,0.23,0.18,0.07,0.86,0.06,0.02,0.01
445.98401407659,0.0372811634115647,272.028431159121,20.0,8.333333333333333e-05,0.56,0.23,0.18,0.07,0.86,0.06,0.02,0.01
449.90667369168847,0.0376080517128229,272.168260036672,20.0,8.333333333333333e-05,0.56,0.23,0.18,0.07,0.86,0.06,0.02,0.01
453.8718012234637,0.0379384790071375,272.332500711909,20.0,8.333333333333333e-05,0.56,0.23,0.18,0.07,0.86,0.06,0.02,0.01
457.876851210096,0.0382722331726902,272.425587943246,20.0,8.333333333333333e-05,0.56,0.23,0.18,0.07,0.86,0.06,0.02,0.01
461.9530848272808,0.0386119193074556,272.587854168385,20.0,8.333333333333333e-05,0.56,0.23,0.18,0.07,0.86,0.06,0.02,0.01
465.9908743450909,0.0389484017672731,272.707818364704,20.0,8.333333333333333e-05,0.56,0.23,0.18,0.07,0.86,0.06,0.02,0.01
469.9288934405064,0.0392765700252244,272.860388760101,20.0,8.333333333333333e-05,0.56,0.23,0.18,0.07,0.86,0.06,0.02,0.01
473.9649633534432,0.0396129091846358,273.007350813364,20.0,8.333333333333333e-05,0.56,0.23,0.18,0.07,0.86,0.06,0.02,0.01
477.9705274303416,0.039946706191044,273.112986449203,20.0,8.333333333333333e-05,0.56,0.23,0.18,0.07,0.86,0.06,0.02,0.01
482.09295178039326,0.0402902415535483,273.254465516593,20.0,8.333333333333333e-05,0.56,0.23,0.18,0.07,0.86,0.06,0.02,0.01
486.2313183096324,0.0406351054309849,273.372736012318,20.0,8.333333333333333e-05,0.56,0.23,0.18,0.07,0.86,0.06,0.02,0.01
490.3627017717852,0.0409793873861643,273.523929559228,20.0,8.333333333333333e-05,0.56,0.23,0.18,0.07,0.86,0.06,0.02,0.01
494.4208666585908,0.0413175677933981,273.635490583408,20.0,8.333333333333333e-05,0.56,0.23,0.18,0.07,0.86,0.06,0.02,0.01
498.56734187183287,0.0416631073945016,273.754557196538,20.0,8.333333333333333e-05,0.56,0.23,0.18,0.07,0.86,0.06,0.02,0.01
502.7029129712652,0.0420077383194543,273.879994948702,20.0,8.333333333333333e-05,0.56,0.23,0.18,0.07,0.86,0.06,0.02,0.01
506.7795293800321,0.0423474563535182,274.010588644382,20.0,8.333333333333333e-05,0.56,0.23,0.18,0.07,0.86,0.06,0.02,0.01
510.8762798972592,0.0426888522299538,274.141389881507,20.0,8.333333333333333e-05,0.56,0.23,0.18,0.07,0.86,0.06,0.02,0.01
514.9440104489544,0.0430278297759284,274.239253429071,20.0,8.333333333333333e-05,0.56,0.23,0.18,0.07,0.86,0.06,0.02,0.01
519.0479704582092,0.0433698264433663,274.364875479204,20.0,8.333333333333333e-05,0.56,0.23,0.18,0.07,0.86,0.06,0.02,0.01
523.120850049624,0.0437092330759842,274.464840013903,20.0,8.333333333333333e-05,0.56,0.23,0.18,0.07,0.86,0.06,0.02,0.01
527.2230720938412,0.0440510849130023,274.587628333153,20.0,8.333333333333333e-05,0.56,0.23,0.18,0.07,0.86,0.06,0.02,0.01
531.2274104863824,0.0443847797790474,274.69664318563,20.0,8.333333333333333e-05,0.56,0.23,0.18,0.07,0.86,0.06,0.02,0.01
535.2432692928179,0.0447194346795837,274.829237599609,20.0,8.333333333333333e-05,0.56,0.23,0.18,0.07,0.86,0.06,0.02,0.01
539.1934870920912,0.0450486194961898,274.928674538104,20.0,8.333333333333333e-05,0.56,0.23,0.18,0.07,0.86,0.06,0.02,0.01
543.1713655791827,0.0453801093701141,275.028601967349,20.0,8.333333333333333e-05,0.56,0.23,0.18,0.07,0.86,0.06,0.02,0.01
547.1794079121528,0.0457141128978616,275.119143010808,20.0,8.333333333333333e-05,0.56,0.23,0.18,0.07,0.86,0.06,0.02,0.01
551.3158639535316,0.0460588175679765,275.221895177634,20.0,8.333333333333333e-05,0.56,0.23,0.18,0.07,0.86,0.06,0.02,0.01
555.45493034484,0.0464037397672522,275.359149221378,20.0,8.333333333333333e-05,0.56,0.23,0.18,0.07,0.86,0.06,0.02,0.01
559.5670400940036,0.0467464155796825,275.483112654496,20.0,8.333333333333333e-05,0.56,0.23,0.18,0.07,0.86,0.06,0.02,0.01
563.6348065686036,0.0470853961192325,275.608453178726,20.0,8.333333333333333e-05,0.56,0.23,0.18,0.07,0.86,0.06,0.02,0.01
567.740826228288,0.0474275644242062,275.697219695107,20.0,8.333333333333333e-05,0.56,0.23,0.18,0.07,0.86,0.06,0.02,0.01
571.8118784219196,0.0477668187736755,275.790768366891,20.0,8.333333333333333e-05,0.56,0.23,0.18,0.07,0.86,0.06,0.02,0.01
575.981978925396,0.0481143271489652,275.88733466315,20.0,8.333333333333333e-05,0.56,0.23,0.18,0.07,0.86,0.06,0.02,0.01
580.1563306251071,0.0484621897906078,275.973229146245,20.0,8.333333333333333e-05,0.56,0.23,0.18,0.07,0.86,0.06,0.02,0.01
584.3063874152004,0.0488080278564489,276.072554590455,20.0,8.333333333333333e-05,0.56,0.23,0.18,0.07,0.86,0.06,0.02,0.01
588.4302081391476,0.0491516795834445,276.187910092089,20.0,8.333333333333333e-05,0.56,0.23,0.18,0.07,0.86,0.06,0.02,0.01
592.6229783400456,0.049501077100186,276.289694265944,20.0,8.333333333333333e-05,0.56,0.23,0.18,0.07,0.86,0.06,0.02,0.01
596.8084338100512,0.0498498650560198,276.396063049906,20.0,8.333333333333333e-05,0.56,0.23,0.18,0.07,0.86,0.06,0.02,0.01
600.98804749257,0.0501981661962297,276.470504855458,20.0,8.333333333333333e-05,0.56,0.23,0.18,0.07,0.86,0.06,0.02,0.01
605.2370187387228,0.0505522471334091,276.569832920018,20.0,8.333333333333333e-05,0.56,0.23,0.18,0.07,0.86,0.06,0.02,0.01
609.2647051098936,0.05088788766434,276.624779804875,20.0,8.333333333333333e-05,0.56,0.23,0.18,0.07,0.86,0.06,0.02,0.01
613.3858474541399,0.0512313161930272,276.718721917398,20.0,8.333333333333333e-05,0.56,0.23,0.18,0.07,0.86,0.06,0.02,0.01
617.525504570328,0.0515762876193762,276.807633232394,20.0,8.333333333333333e-05,0.56,0.23,0.18,0.07,0.86,0.06,0.02,0.01
621.7680492479448,0.0519298330091776,276.87685573695,20.0,8.333333333333333e-05,0.56,0.23,0.18,0.07,0.86,0.06,0.02,0.01
625.9144933190424,0.0522753700151024,277.000551861991,20.0,8.333333333333333e-05,0.56,0.23,0.18,0.07,0.86,0.06,0.02,0.01
630.0694460982228,0.0526216160800341,277.087768861743,20.0,8.333333333333333e-05,0.56,0.23,0.18,0.07,0.86,0.06,0.02,0.01
634.180440565386,0.0529641989522977,277.192080589875,20.0,8.333333333333333e-05,0.56,0.23,0.18,0.07,0.86,0.06,0.02,0.01
638.2564833160295,0.053303869181518,277.287966064142,20.0,8.333333333333333e-05,0.56,0.23,0.18,0.07,0.86,0.06,0.02,0.01
642.413852996604,0.0536503166548992,277.358795846258,20.0,8.333333333333333e-05,0.56,0.23,0.18,0.07,0.86,0.06,0.02,0.01
646.5904333892232,0.0539983650209508,277.444994936983,20.0,8.333333333333333e-05,0.56,0.23,0.18,0.07,0.86,0.06,0.02,0.01
650.7520925964312,0.0543451699548848,277.555935099902,20.0,8.333333333333333e-05,0.56,0.23,0.18,0.07,0.86,0.06,0.02,0.01
654.8724181193256,0.054688530415126,277.618760763345,20.0,8.333333333333333e-05,0.56,0.23,0.18,0.07,0.86,0.06,0.02,0.01
659.0313240871092,0.0550351059124413,277.691595905987,20.0,8.333333333333333e-05,0.56,0.23,0.18,0.07,0.86,0.06,0.02,0.01
663.2301284125836,0.0553850062728975,277.715697467142,20.0,8.333333333333333e-05,0.56,0.23,0.18,0.07,0.86,0.06,0.02,0.01
667.2201904547148,0.0557175114430751,277.82187795791,20.0,8.333333333333333e-05,0.56,0.23,0.18,0.07,0.86,0.06,0.02,0.01
671.509021934232,0.0560749140663682,277.917657162416,20.0,8.333333333333333e-05,0.56,0.23,0.18,0.07,0.86,0.06,0.02,0.01
675.7410656799851,0.0564275843785143,278.034848769358,20.0,8.333333333333333e-05,0.56,0.23,0.18,0.07,0.86,0.06,0.02,0.01
680.2758970417416,0.056805486991994,278.106499740132,20.0,8.333333333333333e-05,0.56,0.23,0.18,0.07,0.86,0.06,0.02,0.01
684.5530894847255,0.057161919695576,278.157302185201,20.0,8.333333333333333e-05,0.56,0.23,0.18,0.07,0.86,0.06,0.02,0.01
688.8600351061068,0.0575208318306911,278.226700948749,20.0,8.333333333333333e-05,0.56,0.23,0.18,0.07,0.86,0.06,0.02,0.01
693.1563208414489,0.0578788556419696,278.262349245081,20.0,8.333333333333333e-05,0.56,0.23,0.18,0.07,0.86,0.06,0.02,0.01
697.4268260678195,0.0582347310775005,278.324844631166,20.0,8.333333333333333e-05,0.56,0.23,0.18,0.07,0.86,0.06,0.02,0.01
701.6436017826384,0.0585861290537354,278.376161861836,20.0,8.333333333333333e-05,0.56,0.23,0.18,0.07,0.86,0.06,0.02,0.01
705.8485594528404,0.0589365421929189,278.434389489921,20.0,8.333333333333333e-05,0.56,0.23,0.18,0.07,0.86,0.06,0.02,0.01
710.1372937477872,0.0592939367174978,278.516421495855,20.0,8.333333333333333e-05,0.56,0.23,0.18,0.07,0.86,0.06,0.02,0.01
714.4714827957168,0.0596551191381586,278.587856675932,20.0,8.333333333333333e-05,0.56,0.23,0.18,0.07,0.86,0.06,0.02,0.01
718.8442398605112,0.0600195155602248,278.673997019051,20.0,8.333333333333333e-05,0.56,0.23,0.18,0.07,0.86,0.06,0.02,0.01
723.244758149892,0.0603862254176732,278.73031795412,20.0,8.333333333333333e-05,0.56,0.23,0.18,0.07,0.86,0.06,0.02,0.01
727.5691573219644,0.0607465920153459,278.779503109303,20.0,8.333333333333333e-05,0.56,0.23,0.18,0.07,0.86,0.06,0.02,0.01
731.8578234490392,0.0611039808592688,278.822820038599,20.0,8.333333333333333e-05,0.56,0.23,0.18,0.07,0.86,0.06,0.02,0.01
736.1774445080364,0.0614639492808519,278.873808787337,20.0,8.333333333333333e-05,0.56,0.23,0.18,0.07,0.86,0.06,0.02,0.01
740.5453758259008,0.0618279435573406,278.899931139968,20.0,8.333333333333333e-05,0.56,0.23,0.18,0.07,0.86,0.06,0.02,0.01
744.940815088902,0.0621942301625907,278.962951340155,20.0,8.333333333333333e-05,0.56,0.23,0.18,0.07,0.86,0.06,0.02,0.01
749.3553575721684,0.0625621087028629,279.018751504873,20.0,8.333333333333333e-05,0.56,0.23,0.18,0.07,0.86,0.06,0.02,0.01
753.575097671094,0.0629137537111067,279.095934407073,20.0,8.333333333333333e-05,0.56,0.23,0.18,0.07,0.86,0.06,0.02,0.01
757.9073471237051,0.0632747744988243,279.133909720012,20.0,8.333333333333333e-05,0.56,0.23,0.18,0.07,0.86,0.06,0.02,0.01
762.2373445501751,0.0636356076176968,279.173136136976,20.0,8.333333333333333e-05,0.56,0.23,0.18,0.07,0.86,0.06,0.02,0.01
766.7078446665707,0.0640081492940631,279.215620441889,20.0,8.333333333333333e-05,0.56,0.23,0.18,0.07,0.86,0.06,0.02,0.01
771.0161344333704,0.0643671734412964,279.261878989329,20.0,8.333333333333333e-05,0.56,0.23,0.18,0.07,0.86,0.06,0.02,0.01
775.3284338678101,0.0647265317274997,279.290784331863,20.0,8.333333333333333e-05,0.56,0.23,0.18,0.07,0.86,0.06,0.02,0.01
779.709681481632,0.0650916356953182,279.304090761641,20.0,8.333333333333333e-05,0.56,0.23,0.18,0.07,0.86,0.06,0.02,0.01
784.1685096949019,0.0654632047130907,279.36342150866,20.0,8.333333333333333e-05,0.56,0.23,0.18,0.07,0.86,0.06,0.02,0.01
788.6672381576244,0.0658380987516509,279.435722002799,20.0,8.333333333333333e-05,0.56,0.23,0.18,0.07,0.86,0.06,0.02,0.01
793.138225371504,0.0662106810194742,279.482813773097,20.0,8.333333333333333e-05,0.56,0.23,0.18,0.07,0.86,0.06,0.02,0.01
797.6790004034448,0.0665890789388026,279.559595794058,20.0,8.333333333333333e-05,0.56,0.23,0.18,0.07,0.86,0.06,0.02,0.01
802.1662178885796,0.0669630137292305,279.581080191426,20.0,8.333333333333333e-05,0.56,0.23,0.18,0.07,0.86,0.06,0.02,0.01
806.7453616885668,0.0673446090458961,279.634409171747,20.0,8.333333333333333e-05,0.56,0.23,0.18,0.07,0.86,0.06,0.02,0.01
811.3370037169033,0.0677272458815908,279.64566173217,20.0,8.333333333333333e-05,0.56,0.23,0.18,0.07,0.86,0.06,0.02,0.01
815.9835816875352,0.0681144607124768,279.683114851356,20.0,8.333333333333333e-05,0.56,0.23,0.18,0.07,0.86,0.06,0.02,0.01
820.6934773761996,0.0685069520198655,279.717675669979,20.0,8.333333333333333e-05,0.56,0.23,0.18,0.07,0.86,0.06,0.02,0.01
825.3323426753497,0.068893524128128,279.752696521823,20.0,8.333333333333333e-05,0.56,0.23,0.18,0.07,0.86,0.06,0.02,0.01
829.9721884556473,0.0692801779431528,279.7835318332,20.0,8.333333333333333e-05,0.56,0.23,0.18,0.07,0.86,0.06,0.02,0.01
834.5816974668575,0.069664303694087,279.791580465478,20.0,8.333333333333333e-05,0.56,0.23,0.18,0.07,0.86,0.06,0.02,0.01
839.2128157486524,0.0700502302175699,279.81776096724,20.0,8.333333333333333e-05,0.56,0.23,0.18,0.07,0.86,0.06,0.02,0.01
843.8413071943621,0.0704359378380457,279.829083516895,20.0,8.333333333333333e-05,0.56,0.23,0.18,0.07,0.86,0.06,0.02,0.01
848.5378048944228,0.0708273126463841,279.884207275394,20.0,8.333333333333333e-05,0.56,0.23,0.18,0.07,0.86,0.06,0.02,0.01
853.1759601813168,0.0712138255869586,279.903214875641,20.0,8.333333333333333e-05,0.56,0.23,0.18,0.07,0.86,0.06,0.02,0.01
857.8370272125132,0.0716022478395583,279.936863246248,20.0,8.333333333333333e-05,0.56,0.23,0.18,0.07,0.86,0.06,0.02,0.01
862.4981699352193,0.0719906763997838,279.950403501849,20.0,8.333333333333333e-05,0.56,0.23,0.18,0.07,0.86,0.06,0.02,0.01
867.2884130325552,0.0723898633245618,279.975731548676,20.0,8.333333333333333e-05,0.56,0.23,0.18,0.07,0.86,0.06,0.02,0.01
872.1623253193441,0.0727960226817942,279.977950467747,20.0,8.333333333333333e-05,0.56,0.23,0.18,0.07,0.86,0.06,0.02,0.01
877.0661119729535,0.073204671569595,280.025258028742,20.0,8.333333333333333e-05,0.56,0.23,0.18,0.07,0.86,0.06,0.02,0.01
881.9839798029707,0.0736144938887631,280.029339483074,20.0,8.333333333333333e-05,0.56,0.23,0.18,0.07,0.86,0.06,0.02,0.01
886.866229269126,0.0740213480109427,280.062250095683,20.0,8.333333333333333e-05,0.56,0.23,0.18,0.07,0.86,0.06,0.02,0.01
891.7810941271752,0.0744309200824468,280.098208822645,20.0,8.333333333333333e-05,0.56,0.23,0.18,0.07,0.86,0.06,0.02,0.01
896.7248219809932,0.0748428974035983,280.11414344756,20.0,8.333333333333333e-05,0.56,0.23,0.18,0.07,0.86,0.06,0.02,0.01
901.733934671412,0.0752603234611332,280.131971485814,20.0,8.333333333333333e-05,0.56,0.23,0.18,0.07,0.86,0.06,0.02,0.01
906.7276014386664,0.0756764623584044,280.130818224374,20.0,8.333333333333333e-05,0.56,0.23,0.18,0.07,0.86,0.06,0.02,0.01
911.7762703902216,0.076097184771034,280.135619207478,20.0,8.333333333333333e-05,0.56,0.23,0.18,0.07,0.86,0.06,0.02,0.01
916.9163157599615,0.076525521885179,280.165326506592,20.0,8.333333333333333e-05,0.56,0.23,0.18,0.07,0.86,0.06,0.02,0.01
921.9837883172412,0.0769478112649523,280.185897679544,20.0,8.333333333333333e-05,0.56,0.23,0.18,0.07,0.86,0.06,0.02,0.01
927.3037298874744,0.0773911397291384,280.197545104106,20.0,8.333333333333333e-05,0.56,0.23,0.18,0.07,0.86,0.06,0.02,0.01
929.9735876802577,0.077613627878537,280.209188306993,20.0,8.333333333333333e-05,0.56,0.23,0.18,0.07,0.86,0.06,0.02,0.01