File: datasets/al_6061_comp/csv/T_020_I_1.csv
Time,Strain(%),Stress(MPa),Temp(C),SR(%/s),Si(%),Fe(%),Cu(%),Mn(%),Mg(%),Cr(%),Zn(%),Ti(%)
0.0,0.0002303539511328,5.324095827714508,20.0,8.333333333333333e-05,0.68,0.23,0.2,0.04,0.87,0.05,0.02,0.02
0.6764997249966,0.00028672892821585,7.021456259762062,20.0,8.333333333333333e-05,0.68,0.23,0.2,0.04,0.87,0.05,0.02,0.02
1.3529994499932,0.0003431039052989,8.718816691809621,20.0,8.333333333333333e-05,0.68,0.23,0.2,0.04,0.87,0.05,0.02,0.02
1.9316156583204,0.0003913219226595,10.676091140338709,20.0,8.333333333333333e-05,0.68,0.23,0.2,0.04,0.87,0.05,0.02,0.02
2.5102318666476,0.0004395399400201,12.633365588867804,20.0,8.333333333333333e-05,0.68,0.23,0.2,0.04,0.87,0.05,0.02,0.02
3.0537695773206,0.00048483474924285,14.737759505090356,20.0,8.333333333333333e-05,0.68,0.23,0.2,0.04,0.87,0.05,0.02,0.02
3.5973072879936,0.0005301295584656,16.842153421312908,20.0,8.333333333333333e-05,0.68,0.23,0.2,0.04,0.87,0.05,0.02,0.02
4.6278238563462,0.00061600593916165,20.584038231679806,20.0,8.333333333333333e-05,0.68,0.23,0.2,0.04,0.87,0.05,0.02,0.02
5.658340424698801,0.0007018823198577,24.325923042046707,20.0,8.333333333333333e-05,0.68,0.23,0.2,0.04,0.87,0.05,0.02,0.02
6.700190600410801,0.0007887031678337,28.78135367782441,20.0,8.333333333333333e-05,0.68,0.23,0.2,0.04,0.87,0.05,0.02,0.02
7.742040776122801,0.0008755240158097,33.23678431360207,20.0,8.333333333333333e-05,0.68,0.23,0.2,0.04,0.87,0.05,0.02,0.02
8.796322654571402,0.00096338083901375,38.032212395680574,20.0,8.333333333333333e-05,0.68,0.23,0.2,0.04,0.87,0.05,0.02,0.02
9.85060453302,0.0010512376622178,42.82764047775913,20.0,8.333333333333333e-05,0.68,0.23,0.2,0.04,0.87,0.05,0.02,0.02
10.7985545727588,0.0011302334988626999,47.85235013545878,20.0,8.333333333333333e-05,0.68,0.23,0.2,0.04,0.87,0.05,0.02,0.02
11.7465046124976,0.0012092293355076,52.87705979315844,20.0,8.333333333333333e-05,0.68,0.23,0.2,0.04,0.87,0.05,0.02,0.02
12.605788039233602,0.0012808362877356001,58.01597788378355,20.0,8.333333333333333e-05,0.68,0.23,0.2,0.04,0.87,0.05,0.02,0.02
13.465071465969602,0.0013524432399636,63.154895974408575,20.0,8.333333333333333e-05,0.68,0.23,0.2,0.04,0.87,0.05,0.02,0.02
14.324011393830002,0.0014240215672853,68.31808040185928,20.0,8.333333333333333e-05,0.68,0.23,0.2,0.04,0.87,0.05,0.02,0.02
15.182951321690402,0.001495599894607,73.48126482930994,20.0,8.333333333333333e-05,0.68,0.23,0.2,0.04,0.87,0.05,0.02,0.02
16.045905051329402,0.00156751270541025,78.6886712005828,20.0,8.333333333333333e-05,0.68,0.23,0.2,0.04,0.87,0.05,0.02,0.02
16.9088587809684,0.0016394255162135,83.89607757185573,20.0,8.333333333333333e-05,0.68,0.23,0.2,0.04,0.87,0.05,0.02,0.02
17.809117358776803,0.0017144470643642,89.12464774092012,20.0,8.333333333333333e-05,0.68,0.23,0.2,0.04,0.87,0.05,0.02,0.02
18.7093759365852,0.0017894686125149,94.3532179099845,20.0,8.333333333333333e-05,0.68,0.23,0.2,0.04,0.87,0.05,0.02,0.02
19.6110739710294,0.00186461011538525,99.61676222005624,20.0,8.333333333333333e-05,0.68,0.23,0.2,0.04,0.87,0.05,0.02,0.02
20.5127720054736,0.0019397516182556,104.88030653012808,20.0,8.333333333333333e-05,0.68,0.23,0.2,0.04,0.87,0.05,0.02,0.02
21.3830032316028,0.0020122708870997,110.1080128174641,20.0,8.333333333333333e-05,0.68,0.23,0.2,0.04,0.87,0.05,0.02,0.02
22.253234457732,0.0020847901559438,115.33571910480008,20.0,8.333333333333333e-05,0.68,0.23,0.2,0.04,0.87,0.05,0.02,0.02
23.1652802511186,0.00216079397205935,120.49419060856108,20.0,8.333333333333333e-05,0.68,0.23,0.2,0.04,0.87,0.05,0.02,0.02
24.0773260445052,0.0022367977881749,125.65266211232218,20.0,8.333333333333333e-05,0.68,0.23,0.2,0.04,0.87,0.05,0.02,0.02
24.955655701539598,0.0023099919262611,130.8131502176317,20.0,8.333333333333333e-05,0.68,0.23,0.2,0.04,0.87,0.05,0.02,0.02
25.833985358574,0.0023831860643473,135.97363832294113,20.0,8.333333333333333e-05,0.68,0.23,0.2,0.04,0.87,0.05,0.02,0.02
26.732288234427003,0.0024580446373350497,141.1002995076181,20.0,8.333333333333333e-05,0.68,0.23,0.2,0.04,0.87,0.05,0.02,0.02
27.63059111028,0.0025329032103228,146.22696069229482,20.0,8.333333333333333e-05,0.68,0.23,0.2,0.04,0.87,0.05,0.02,0.02
28.512655407489,0.0026064085684235497,151.25920193506383,20.0,8.333333333333333e-05,0.68,0.23,0.2,0.04,0.87,0.05,0.02,0.02
29.394719704698,0.0026799139265243,156.2914431778328,20.0,8.333333333333333e-05,0.68,0.23,0.2,0.04,0.87,0.05,0.02,0.02
30.2325087015228,0.0027497296762597,161.2451274510803,20.0,8.333333333333333e-05,0.68,0.23,0.2,0.04,0.87,0.05,0.02,0.02
31.0702976983476,0.0028195454259951,166.19881172432767,20.0,8.333333333333333e-05,0.68,0.23,0.2,0.04,0.87,0.05,0.02,0.02
31.903141219161,0.00288894905272955,171.04869933615169,20.0,8.333333333333333e-05,0.68,0.23,0.2,0.04,0.87,0.05,0.02,0.02
32.7359847399744,0.002958352679464,175.8985869479757,20.0,8.333333333333333e-05,0.68,0.23,0.2,0.04,0.87,0.05,0.02,0.02
33.580969286312396,0.0030287680583255,180.70299824233473,20.0,8.333333333333333e-05,0.68,0.23,0.2,0.04,0.87,0.05,0.02,0.02
34.4259538326504,0.003099183437187,185.50740953669396,20.0,8.333333333333333e-05,0.68,0.23,0.2,0.04,0.87,0.05,0.02,0.02
35.2457556067008,0.0031675002516912,190.17394482129896,20.0,8.333333333333333e-05,0.68,0.23,0.2,0.04,0.87,0.05,0.02,0.02
36.0655573807512,0.0032358170661954,194.8404801059032,20.0,8.333333333333333e-05,0.68,0.23,0.2,0.04,0.87,0.05,0.02,0.02
36.886596295302596,0.00330423697574135,199.2823900958457,20.0,8.333333333333333e-05,0.68,0.23,0.2,0.04,0.87,0.05,0.02,0.02
37.707635209854,0.0033726568852873,203.7243000857888,20.0,8.333333333333333e-05,0.68,0.23,0.2,0.04,0.87,0.05,0.02,0.02
38.5247157966096,0.0034407469341836,207.95930544132278,20.0,8.333333333333333e-05,0.68,0.23,0.2,0.04,0.87,0.05,0.02,0.02
39.3417963833652,0.0035088369830799,212.19431079685694,20.0,8.333333333333333e-05,0.68,0.23,0.2,0.04,0.87,0.05,0.02,0.02
40.1566683102492,0.0035767429769869,216.23509843530246,20.0,8.333333333333333e-05,0.68,0.23,0.2,0.04,0.87,0.05,0.02,0.02
40.9715402371332,0.0036446489708939,220.2758860737485,20.0,8.333333333333333e-05,0.68,0.23,0.2,0.04,0.87,0.05,0.02,0.02
41.826977268102,0.0037159353901413,224.06061751335199,20.0,8.333333333333333e-05,0.68,0.23,0.2,0.04,0.87,0.05,0.02,0.02
42.6824142990708,0.0037872218093887,227.8453489529547,20.0,8.333333333333333e-05,0.68,0.23,0.2,0.04,0.87,0.05,0.02,0.02
43.5117972789228,0.0038563370577097003,231.43731252160973,20.0,8.333333333333333e-05,0.68,0.23,0.2,0.04,0.87,0.05,0.02,0.02
44.341180258774806,0.0039254523060307,235.02927609026506,20.0,8.333333333333333e-05,0.68,0.23,0.2,0.04,0.87,0.05,0.02,0.02
45.216174968925,0.00399836853187655,238.39176275141256,20.0,8.333333333333333e-05,0.68,0.23,0.2,0.04,0.87,0.05,0.02,0.02
46.0911696790752,0.0040712847577224,241.75424941256028,20.0,8.333333333333333e-05,0.68,0.23,0.2,0.04,0.87,0.05,0.02,0.02
47.201108328009596,0.0041637796451336005,244.88183770450928,20.0,8.333333333333333e-05,0.68,0.23,0.2,0.04,0.87,0.05,0.02,0.02
48.311046976944,0.0042562745325448,248.0094259964576,20.0,8.333333333333333e-05,0.68,0.23,0.2,0.04,0.87,0.05,0.02,0.02
49.790960343399604,0.0043796006464161,250.83457217622612,20.0,8.333333333333333e-05,0.68,0.23,0.2,0.04,0.87,0.05,0.02,0.02
51.2708737098552,0.0045029267602874,253.65971835599458,20.0,8.333333333333333e-05,0.68,0.23,0.2,0.04,0.87,0.05,0.02,0.02
53.232184873071006,0.00466636935722205,256.02263448046256,20.0,8.333333333333333e-05,0.68,0.23,0.2,0.04,0.87,0.05,0.02,0.02
55.1934960362868,0.0048298119541567,258.385550604931,20.0,8.333333333333333e-05,0.68,0.23,0.2,0.04,0.87,0.05,0.02,0.02
57.6812114591076,0.0050371215727251,260.3984388794295,20.0,8.333333333333333e-05,0.68,0.23,0.2,0.04,0.87,0.05,0.02,0.02
60.1689268819284,0.0052444311912935,262.41132715392837,20.0,8.333333333333333e-05,0.68,0.23,0.2,0.04,0.87,0.05,0.02,0.02
63.1801735888752,0.0054953684168724,264.02742642948033,20.0,8.333333333333333e-05,0.68,0.23,0.2,0.04,0.87,0.05,0.02,0.02
66.191420295822,0.0057463056424513,265.64352570503195,20.0,8.333333333333333e-05,0.68,0.23,0.2,0.04,0.87,0.05,0.02,0.02
69.7958524888422,0.00604667499186965,266.7933407242999,20.0,8.333333333333333e-05,0.68,0.23,0.2,0.04,0.87,0.05,0.02,0.02
73.4002846818624,0.006347044341288,267.94315574356784,20.0,8.333333333333333e-05,0.68,0.23,0.2,0.04,0.87,0.05,0.02,0.02
77.5301799104736,0.0066912022770056,268.70041897768687,20.0,8.333333333333333e-05,0.68,0.23,0.2,0.04,0.87,0.05,0.02,0.02
81.66007513908481,0.0070353602127232,269.45768221180583,20.0,8.333333333333333e-05,0.68,0.23,0.2,0.04,0.87,0.05,0.02,0.02
86.128564627089,0.00740773433672355,269.78603661219734,20.0,8.333333333333333e-05,0.68,0.23,0.2,0.04,0.87,0.05,0.02,0.02
90.5970541150932,0.0077801084607239,270.11439101258884,20.0,8.333333333333333e-05,0.68,0.23,0.2,0.04,0.87,0.05,0.02,0.02
95.23925523040981,0.00816695855366695,270.32163576898535,20.0,8.333333333333333e-05,0.68,0.23,0.2,0.04,0.87,0.05,0.02,0.02
99.8814563457264,0.00855380864661,270.5288805253821,20.0,8.333333333333333e-05,0.68,0.23,0.2,0.04,0.87,0.05,0.02,0.02
104.6007321997572,0.0089470816344459,270.7435433626571,20.0,8.333333333333333e-05,0.68,0.23,0.2,0.04,0.87,0.05,0.02,0.02
109.320008053788,0.0093403546222818,270.95820619993214,20.0,8.333333333333333e-05,0.68,0.23,0.2,0.04,0.87,0.05,0.02,0.02
114.0700291370448,0.0097361897125532,271.00293121026664,20.0,8.333333333333333e-05,0.68,0.23,0.2,0.04,0.87,0.05,0.02,0.02
118.8200502203016,0.0101320248028246,271.0476562206013,20.0,8.333333333333333e-05,0.68,0.23,0.2,0.04,0.87,0.05,0.02,0.02
123.569727721311,0.01052783126124205,271.0949854295438,20.0,8.333333333333333e-05,0.68,0.23,0.2,0.04,0.87,0.05,0.02,0.02
128.3194052223204,0.0109236377196595,271.142314638486,20.0,8.333333333333333e-05,0.68,0.23,0.2,0.04,0.87,0.05,0.02,0.02
133.0365150098604,0.0113167302019545,271.2318610400705,20.0,8.333333333333333e-05,0.68,0.23,0.2,0.04,0.87,0.05,0.02,0.02
137.7536247974004,0.0117098226842495,271.32140744165537,20.0,8.333333333333333e-05,0.68,0.23,0.2,0.04,0.87,0.05,0.02,0.02
142.4338773762948,0.0120998437324907,271.3228595375683,20.0,8.333333333333333e-05,0.68,0.23,0.2,0.04,0.87,0.05,0.02,0.02
147.1141299551892,0.0124898647807319,271.3243116334811,20.0,8.333333333333333e-05,0.68,0.23,0.2,0.04,0.87,0.05,0.02,0.02
151.757275585923,0.01287679358329305,271.5218541015946,20.0,8.333333333333333e-05,0.68,0.23,0.2,0.04,0.87,0.05,0.02,0.02
156.40042121665678,0.0132637223858542,271.71939656970824,20.0,8.333333333333333e-05,0.68,0.23,0.2,0.04,0.87,0.05,0.02,0.02
161.03101523089438,0.013649605220373999,271.89389142979275,20.0,8.333333333333333e-05,0.68,0.23,0.2,0.04,0.87,0.05,0.02,0.02
165.66160924513198,0.0140354880548938,272.0683862898765,20.0,8.333333333333333e-05,0.68,0.23,0.2,0.04,0.87,0.05,0.02,0.02
170.2402817516622,0.014417044097104651,272.1584129790175,20.0,8.333333333333333e-05,0.68,0.23,0.2,0.04,0.87,0.05,0.02,0.02
174.8189542581924,0.0147986001393155,272.24843966815854,20.0,8.333333333333333e-05,0.68,0.23,0.2,0.04,0.87,0.05,0.02,0.02
179.3543583465258,0.015176550480009949,272.39204767082305,20.0,8.333333333333333e-05,0.68,0.23,0.2,0.04,0.87,0.05,0.02,0.02
183.8897624348592,0.0155545008207044,272.5356556734884,20.0,8.333333333333333e-05,0.68,0.23,0.2,0.04,0.87,0.05,0.02,0.02
188.4395935575852,0.0159336534142649,272.6838923895754,20.0,8.333333333333333e-05,0.68,0.23,0.2,0.04,0.87,0.05,0.02,0.02
192.9894246803112,0.0163128060078254,272.8321291056611,20.0,8.333333333333333e-05,0.68,0.23,0.2,0.04,0.87,0.05,0.02,0.02
197.4951585990528,0.0166882838343872,272.90177755069163,20.0,8.333333333333333e-05,0.68,0.23,0.2,0.04,0.87,0.05,0.02,0.02
202.0008925177944,0.017063761660949,272.9714259957233,20.0,8.333333333333333e-05,0.68,0.23,0.2,0.04,0.87,0.05,0.02,0.02
206.49942303079803,0.0174386392036993,273.0929755641533,20.0,8.333333333333333e-05,0.68,0.23,0.2,0.04,0.87,0.05,0.02,0.02
210.99795354380163,0.0178135167464496,273.21452513258293,20.0,8.333333333333333e-05,0.68,0.23,0.2,0.04,0.87,0.05,0.02,0.02
215.48202241594743,0.01818718915246175,273.2250720857799,20.0,8.333333333333333e-05,0.68,0.23,0.2,0.04,0.87,0.05,0.02,0.02
219.9660912880932,0.0185608615584739,273.2356190389764,20.0,8.333333333333333e-05,0.68,0.23,0.2,0.04,0.87,0.05,0.02,0.02
224.4362156236212,0.018933371919767898,273.2722280465489,20.0,8.333333333333333e-05,0.68,0.23,0.2,0.04,0.87,0.05,0.02,0.02
228.9063399591492,0.0193058822810619,273.30883705412094,20.0,8.333333333333333e-05,0.68,0.23,0.2,0.04,0.87,0.05,0.02,0.02
233.3711598951336,0.0196779506090606,273.37625659867547,20.0,8.333333333333333e-05,0.68,0.23,0.2,0.04,0.87,0.05,0.02,0.02
237.835979831118,0.0200500189370593,273.4436761432306,20.0,8.333333333333333e-05,0.68,0.23,0.2,0.04,0.87,0.05,0.02,0.02
242.29965010079462,0.02042199145953235,273.5821054253766,20.0,8.333333333333333e-05,0.68,0.23,0.2,0.04,0.87,0.05,0.02,0.02
246.7633203704712,0.0207939639820054,273.7205347075228,20.0,8.333333333333333e-05,0.68,0.23,0.2,0.04,0.87,0.05,0.02,0.02
251.17873685472483,0.0211619153556932,273.8256882478883,20.0,8.333333333333333e-05,0.68,0.23,0.2,0.04,0.87,0.05,0.02,0.02
255.59415333897843,0.021529866729381,273.9308417882539,20.0,8.333333333333333e-05,0.68,0.23,0.2,0.04,0.87,0.05,0.02,0.02
260.01863558642464,0.02189857358333485,274.0748282762299,20.0,8.333333333333333e-05,0.68,0.23,0.2,0.04,0.87,0.05,0.02,0.02
264.4431178338708,0.0222672804372887,274.21881476420646,20.0,8.333333333333333e-05,0.68,0.23,0.2,0.04,0.87,0.05,0.02,0.02
268.81585752349383,0.022631675411423947,274.34079053189146,20.0,8.333333333333333e-05,0.68,0.23,0.2,0.04,0.87,0.05,0.02,0.02
273.18859721311685,0.0229960703855592,274.4627662995765,20.0,8.333333333333333e-05,0.68,0.23,0.2,0.04,0.87,0.05,0.02,0.02
277.54452641024466,0.02335906448531985,274.66930600980703,20.0,8.333333333333333e-05,0.68,0.23,0.2,0.04,0.87,0.05,0.02,0.02
281.9004556073724,0.0237220585850805,274.87584572003703,20.0,8.333333333333333e-05,0.68,0.23,0.2,0.04,0.87,0.05,0.02,0.02
286.2201997665384,0.024082037265011,275.00394908921953,20.0,8.333333333333333e-05,0.68,0.23,0.2,0.04,0.87,0.05,0.02,0.02
290.53994392570445,0.0244420159449415,275.13205245840106,20.0,8.333333333333333e-05,0.68,0.23,0.2,0.04,0.87,0.05,0.02,0.02
294.8434121034438,0.02480063829308645,275.3046663829581,20.0,8.333333333333333e-05,0.68,0.23,0.2,0.04,0.87,0.05,0.02,0.02
299.14688028118326,0.0251592606412314,275.47728030751506,20.0,8.333333333333333e-05,0.68,0.23,0.2,0.04,0.87,0.05,0.02,0.02
303.4163957953855,0.025515053600748253,275.65107205873807,20.0,8.333333333333333e-05,0.68,0.23,0.2,0.04,0.87,0.05,0.02,0.02
307.68591130958765,0.0258708465602651,275.82486380996096,20.0,8.333333333333333e-05,0.68,0.23,0.2,0.04,0.87,0.05,0.02,0.02
311.9407625020434,0.02622541749296975,276.006592503858,20.0,8.333333333333333e-05,0.68,0.23,0.2,0.04,0.87,0.05,0.02,0.02
316.19561369449923,0.0265799884256744,276.1883211977553,20.0,8.333333333333333e-05,0.68,0.23,0.2,0.04,0.87,0.05,0.02,0.02
320.42399336811127,0.0269323533984754,276.35866244499624,20.0,8.333333333333333e-05,0.68,0.23,0.2,0.04,0.87,0.05,0.02,0.02
324.65237304172325,0.0272847183712764,276.52900369223784,20.0,8.333333333333333e-05,0.68,0.23,0.2,0.04,0.87,0.05,0.02,0.02
328.86071550268923,0.0276354135763569,276.7255924829808,20.0,8.333333333333333e-05,0.68,0.23,0.2,0.04,0.87,0.05,0.02,0.02
333.0690579636552,0.0279861087814374,276.9221812737235,20.0,8.333333333333333e-05,0.68,0.23,0.2,0.04,0.87,0.05,0.02,0.02
337.27491854932566,0.028336597163576602,277.1480945636425,20.0,8.333333333333333e-05,0.68,0.23,0.2,0.04,0.87,0.05,0.02,0.02
341.48077913499606,0.0286870855457158,277.37400785356135,20.0,8.333333333333333e-05,0.68,0.23,0.2,0.04,0.87,0.05,0.02,0.02
345.67449106630085,0.0290365615399912,277.52046272570186,20.0,8.333333333333333e-05,0.68,0.23,0.2,0.04,0.87,0.05,0.02,0.02
349.86820299760564,0.0293860375342666,277.6669175978417,20.0,8.333333333333333e-05,0.68,0.23,0.2,0.04,0.87,0.05,0.02,0.02
354.0249708883632,0.0297324348584964,277.8863826076287,20.0,8.333333333333333e-05,0.68,0.23,0.2,0.04,0.87,0.05,0.02,0.02
358.1817387791208,0.0300788321827262,278.105847617418,20.0,8.333333333333333e-05,0.68,0.23,0.2,0.04,0.87,0.05,0.02,0.02
362.34180970957027,0.03042550476026365,278.149152755155,20.0,8.333333333333333e-05,0.68,0.23,0.2,0.04,0.87,0.05,0.02,0.02
366.5018806400197,0.0307721773378011,278.1924578928889,20.0,8.333333333333333e-05,0.68,0.23,0.2,0.04,0.87,0.05,0.02,0.02
370.6364044698853,0.0311167209902899,278.32533942137735,20.0,8.333333333333333e-05,0.68,0.23,0.2,0.04,0.87,0.05,0.02,0.02
374.7709282997509,0.0314612646427787,278.4582209498678,20.0,8.333333333333333e-05,0.68,0.23,0.2,0.04,0.87,0.05,0.02,0.02
378.88750035825484,0.031804312314320696,278.56449111212777,20.0,8.333333333333333e-05,0.68,0.23,0.2,0.04,0.87,0.05,0.02,0.02
383.0040724167588,0.0321473599858627,278.6707612743901,20.0,8.333333333333333e-05,0.68,0.23,0.2,0.04,0.87,0.05,0.02,0.02
387.1365541146696,0.0324917334606886,278.8388833154911,20.0,8.333333333333333e-05,0.68,0.23,0.2,0.04,0.87,0.05,0.02,0.02
391.26903581258046,0.0328361069355145,279.0070053565897,20.0,8.333333333333333e-05,0.68,0.23,0.2,0.04,0.87,0.05,0.02,0.02
395.33174306787606,0.0331746658734558,279.0837535239427,20.0,8.333333333333333e-05,0.68,0.23,0.2,0.04,0.87,0.05,0.02,0.02
399.39445032317167,0.0335132248113971,279.16050169129556,20.0,8.333333333333333e-05,0.68,0.23,0.2,0.04,0.87,0.05,0.02,0.02
403.45958249257325,0.0338519858255139,279.37315822285956,20.0,8.333333333333333e-05,0.68,0.23,0.2,0.04,0.87,0.05,0.02,0.02
407.5247146619748,0.0341907468396307,279.5858147544237,20.0,8.333333333333333e-05,0.68,0.23,0.2,0.04,0.87,0.05,0.02,0.02
411.60843189269883,0.034531056608857705,279.70526791684375,20.0,8.333333333333333e-05,0.68,0.23,0.2,0.04,0.87,0.05,0.02,0.02
415.6921491234229,0.0348713663780847,279.82472107926384,20.0,8.333333333333333e-05,0.68,0.23,0.2,0.04,0.87,0.05,0.02,0.02
419.77943395088704,0.03521197344704005,280.02273609352636,20.0,8.333333333333333e-05,0.68,0.23,0.2,0.04,0.87,0.05,0.02,0.02
423.8667187783512,0.0355525805159954,280.22075110778985,20.0,8.333333333333333e-05,0.68,0.23,0.2,0.04,0.87,0.05,0.02,0.02
427.9596790104018,0.03589366053533295,280.3563266383408,20.0,8.333333333333333e-05,0.68,0.23,0.2,0.04,0.87,0.05,0.02,0.02
432.0526392424524,0.0362347405546705,280.491902168892,20.0,8.333333333333333e-05,0.68,0.23,0.2,0.04,0.87,0.05,0.02,0.02
436.136763820188,0.0365750842694818,280.609311990269,20.0,8.333333333333333e-05,0.68,0.23,0.2,0.04,0.87,0.05,0.02,0.02
440.2208883979236,0.0369154279842931,280.72672181164364,20.0,8.333333333333333e-05,0.68,0.23,0.2,0.04,0.87,0.05,0.02,0.02
444.2723542219428,0.0372530501362947,280.7968280777441,20.0,8.333333333333333e-05,0.68,0.23,0.2,0.04,0.87,0.05,0.02,0.02
448.32382004596207,0.0375906722882963,280.8669343438464,20.0,8.333333333333333e-05,0.68,0.23,0.2,0.04,0.87,0.05,0.02,0.02
452.4408800275585,0.037933760620096,280.88183139009493,20.0,8.333333333333333e-05,0.68,0.23,0.2,0.04,0.87,0.05,0.02,0.02
456.5579400091549,0.0382768489518957,280.89672843634196,20.0,8.333333333333333e-05,0.68,0.23,0.2,0.04,0.87,0.05,0.02,0.02
460.66645984955403,0.038619225605262306,280.96444930210646,20.0,8.333333333333333e-05,0.68,0.23,0.2,0.04,0.87,0.05,0.02,0.02
464.7749796899532,0.0389616022586289,281.03217016787323,20.0,8.333333333333333e-05,0.68,0.23,0.2,0.04,0.87,0.05,0.02,0.02
468.8817028776744,0.039303829190939,281.09217884176076,20.0,8.333333333333333e-05,0.68,0.23,0.2,0.04,0.87,0.05,0.02,0.02
472.9884260653956,0.0396460561232491,281.15218751564714,20.0,8.333333333333333e-05,0.68,0.23,0.2,0.04,0.87,0.05,0.02,0.02
477.08153970045487,0.039987148926170696,281.24883673299263,20.0,8.333333333333333e-05,0.68,0.23,0.2,0.04,0.87,0.05,0.02,0.02
481.1746533355141,0.0403282417290923,281.3454859503375,20.0,8.333333333333333e-05,0.68,0.23,0.2,0.04,0.87,0.05,0.02,0.02
485.2605342722551,0.04066873180715405,281.418616029027,20.0,8.333333333333333e-05,0.68,0.23,0.2,0.04,0.87,0.05,0.02,0.02
489.34641520899606,0.0410092218852158,281.4917461077159,20.0,8.333333333333333e-05,0.68,0.23,0.2,0.04,0.87,0.05,0.02,0.02
493.44279775775584,0.041350587097612454,281.5985543563979,20.0,8.333333333333333e-05,0.68,0.23,0.2,0.04,0.87,0.05,0.02,0.02
497.5391803065156,0.0416919523100091,281.70536260508135,20.0,8.333333333333333e-05,0.68,0.23,0.2,0.04,0.87,0.05,0.02,0.02
501.6588906641166,0.04203526150647585,281.7984631642693,20.0,8.333333333333333e-05,0.68,0.23,0.2,0.04,0.87,0.05,0.02,0.02
505.7786010217176,0.0423785707029426,281.89156372345616,20.0,8.333333333333333e-05,0.68,0.23,0.2,0.04,0.87,0.05,0.02,0.02
509.901290792589,0.042722128183848546,282.0426438874886,20.0,8.333333333333333e-05,0.68,0.23,0.2,0.04,0.87,0.05,0.02,0.02
514.0239805634604,0.0430656856647545,282.19372405152006,20.0,8.333333333333333e-05,0.68,0.23,0.2,0.04,0.87,0.05,0.02,0.02
518.1372962572188,0.0434084619725677,282.24110408346803,20.0,8.333333333333333e-05,0.68,0.23,0.2,0.04,0.87,0.05,0.02,0.02
522.2506119509771,0.0437512382803809,282.2884841154197,20.0,8.333333333333333e-05,0.68,0.23,0.2,0.04,0.87,0.05,0.02,0.02
526.3713525802841,0.04409463333282315,282.35830223867066,20.0,8.333333333333333e-05,0.68,0.23,0.2,0.04,0.87,0.05,0.02,0.02
530.4920932095912,0.0444380283852654,282.4281203619207,20.0,8.333333333333333e-05,0.68,0.23,0.2,0.04,0.87,0.05,0.02,0.02
534.6135047485459,0.044781479346844955,282.5313243955412,20.0,8.333333333333333e-05,0.68,0.23,0.2,0.04,0.87,0.05,0.02,0.02
538.7349162875005,0.0451249303084245,282.63452842916,20.0,8.333333333333333e-05,0.68,0.23,0.2,0.04,0.87,0.05,0.02,0.02
542.8964798081682,0.04547172726848015,282.72953914749456,20.0,8.333333333333333e-05,0.68,0.23,0.2,0.04,0.87,0.05,0.02,0.02
547.058043328836,0.0458185242285358,282.8245498658303,20.0,8.333333333333333e-05,0.68,0.23,0.2,0.04,0.87,0.05,0.02,0.02
551.2286188925323,0.04616607219217715,282.9215948401848,20.0,8.333333333333333e-05,0.68,0.23,0.2,0.04,0.87,0.05,0.02,0.02
555.3991944562284,0.0465136201558185,283.01863981453744,20.0,8.333333333333333e-05,0.68,0.23,0.2,0.04,0.87,0.05,0.02,0.02
559.5563820180828,0.0468600524526397,283.15630965755895,20.0,8.333333333333333e-05,0.68,0.23,0.2,0.04,0.87,0.05,0.02,0.02
563.7135695799373,0.0472064847494609,283.29397950058166,20.0,8.333333333333333e-05,0.68,0.23,0.2,0.04,0.87,0.05,0.02,0.02
567.8643190761649,0.047552380540813205,283.39760594477667,20.0,8.333333333333333e-05,0.68,0.23,0.2,0.04,0.87,0.05,0.02,0.02
572.0150685723925,0.0478982763321655,283.50123238897027,20.0,8.333333333333333e-05,0.68,0.23,0.2,0.04,0.87,0.05,0.02,0.02
576.2076903534853,0.0482476614805899,283.6206081451248,20.0,8.333333333333333e-05,0.68,0.23,0.2,0.04,0.87,0.05,0.02,0.02
580.400312134578,0.0485970466290143,283.7399839012814,20.0,8.333333333333333e-05,0.68,0.23,0.2,0.04,0.87,0.05,0.02,0.02
584.590605867822,0.0489462377734513,283.89663444169287,20.0,8.333333333333333e-05,0.68,0.23,0.2,0.04,0.87,0.05,0.02,0.02
588.780899601066,0.0492954289178883,284.0532849821052,20.0,8.333333333333333e-05,0.68,0.23,0.2,0.04,0.87,0.05,0.02,0.02
592.9895916460279,0.04964615325496845,284.1438265178217,20.0,8.333333333333333e-05,0.68,0.23,0.2,0.04,0.87,0.05,0.02,0.02
597.1982836909897,0.0499968775920486,284.2343680535363,20.0,8.333333333333333e-05,0.68,0.23,0.2,0.04,0.87,0.05,0.02,0.02
601.3831988566549,0.0503456205225207,284.3560244549543,20.0,8.333333333333333e-05,0.68,0.23,0.2,0.04,0.87,0.05,0.02,0.02
605.5681140223201,0.0506943634529928,284.4776808563746,20.0,8.333333333333333e-05,0.68,0.23,0.2,0.04,0.87,0.05,0.02,0.02
609.752253017268,0.051043041702571804,284.6603379723741,20.0,8.333333333333333e-05,0.68,0.23,0.2,0.04,0.87,0.05,0.02,0.02
613.9363920122161,0.0513917199521508,284.8429950883719,20.0,8.333333333333333e-05,0.68,0.23,0.2,0.04,0.87,0.05,0.02,0.02
618.1632660383125,0.0517439594543255,284.9571738367874,20.0,8.333333333333333e-05,0.68,0.23,0.2,0.04,0.87,0.05,0.02,0.02
622.3901400644089,0.0520961989565002,285.0713525852032,20.0,8.333333333333333e-05,0.68,0.23,0.2,0.04,0.87,0.05,0.02,0.02
626.6295818631487,0.052449485773061855,285.2363225063272,20.0,8.333333333333333e-05,0.68,0.23,0.2,0.04,0.87,0.05,0.02,0.02
630.8690236618885,0.0528027725896235,285.4012924274508,20.0,8.333333333333333e-05,0.68,0.23,0.2,0.04,0.87,0.05,0.02,0.02
635.1126900026298,0.05315641145135195,285.54326812579234,20.0,8.333333333333333e-05,0.68,0.23,0.2,0.04,0.87,0.05,0.02,0.02
639.3563563433712,0.0535100503130804,285.6852438241315,20.0,8.333333333333333e-05,0.68,0.23,0.2,0.04,0.87,0.05,0.02,0.02
643.6134556620937,0.0538648085896406,285.723177549823,20.0,8.333333333333333e-05,0.68,0.23,0.2,0.04,0.87,0.05,0.02,0.02
647.8705549808161,0.0542195668662008,285.7611112755185,20.0,8.333333333333333e-05,0.68,0.23,0.2,0.04,0.87,0.05,0.02,0.02
652.1356302347004,0.054574989804024504,285.831487319131,20.0,8.333333333333333e-05,0.68,0.23,0.2,0.04,0.87,0.05,0.02,0.02
656.4007054885848,0.0549304127418482,285.90186336274377,20.0,8.333333333333333e-05,0.68,0.23,0.2,0.04,0.87,0.05,0.02,0.02
660.668520013947,0.055286063952295045,285.98581064865726,20.0,8.333333333333333e-05,0.68,0.23,0.2,0.04,0.87,0.05,0.02,0.02
664.9363345393092,0.0556417151627419,286.069757934568,20.0,8.333333333333333e-05,0.68,0.23,0.2,0.04,0.87,0.05,0.02,0.02
669.2036730511302,0.055997326705393646,286.0376725728775,20.0,8.333333333333333e-05,0.68,0.23,0.2,0.04,0.87,0.05,0.02,0.02
673.4710115629513,0.0563529382480454,286.00558721119086,20.0,8.333333333333333e-05,0.68,0.23,0.2,0.04,0.87,0.05,0.02,0.02
677.73849137235,0.0567085615654953,286.0719234586194,20.0,8.333333333333333e-05,0.68,0.23,0.2,0.04,0.87,0.05,0.02,0.02
682.0059711817488,0.0570641848829452,286.1382597060434,20.0,8.333333333333333e-05,0.68,0.23,0.2,0.04,0.87,0.05,0.02,0.02
686.274323298735,0.05741988089269405,286.1685678717564,20.0,8.333333333333333e-05,0.68,0.23,0.2,0.04,0.87,0.05,0.02,0.02
690.5426754157212,0.0577755769024429,286.1988760374735,20.0,8.333333333333333e-05,0.68,0.23,0.2,0.04,0.87,0.05,0.02,0.02
694.8114106920996,0.0581313048421411,286.26719564761197,20.0,8.333333333333333e-05,0.68,0.23,0.2,0.04,0.87,0.05,0.02,0.02
699.0801459684781,0.0584870327818393,286.3355152577469,20.0,8.333333333333333e-05,0.68,0.23,0.2,0.04,0.87,0.05,0.02,0.02
703.3793890856371,0.058845303041602556,286.4702038151454,20.0,8.333333333333333e-05,0.68,0.23,0.2,0.04,0.87,0.05,0.02,0.02
707.678632202796,0.0592035733013658,286.60489237254984,20.0,8.333333333333333e-05,0.68,0.23,0.2,0.04,0.87,0.05,0.02,0.02
712.0054177353468,0.059564138762411706,286.7064484393629,20.0,8.333333333333333e-05,0.68,0.23,0.2,0.04,0.87,0.05,0.02,0.02
716.3322032678976,0.0599247042234576,286.80800450617147,20.0,8.333333333333333e-05,0.68,0.23,0.2,0.04,0.87,0.05,0.02,0.02
720.6880335564055,0.06028769008083325,286.8679592558035,20.0,8.333333333333333e-05,0.68,0.23,0.2,0.04,0.87,0.05,0.02,0.02
725.0438638449133,0.0606506759382089,286.92791400543695,20.0,8.333333333333333e-05,0.68,0.23,0.2,0.04,0.87,0.05,0.02,0.02
729.4651739092669,0.061019118443571704,287.03062094069446,20.0,8.333333333333333e-05,0.68,0.23,0.2,0.04,0.87,0.05,0.02,0.02
733.8864839736204,0.0613875609489345,287.1333278759541,20.0,8.333333333333333e-05,0.68,0.23,0.2,0.04,0.87,0.05,0.02,0.02
738.3276638601973,0.0617576592728159,287.2163554966956,20.0,8.333333333333333e-05,0.68,0.23,0.2,0.04,0.87,0.05,0.02,0.02
742.7688437467741,0.0621277575966973,287.2993831174326,20.0,8.333333333333333e-05,0.68,0.23,0.2,0.04,0.87,0.05,0.02,0.02
747.2332628374332,0.062499792520918904,287.3527601234116,20.0,8.333333333333333e-05,0.68,0.23,0.2,0.04,0.87,0.05,0.02,0.02
751.6976819280924,0.0628718274451405,287.4061371293913,20.0,8.333333333333333e-05,0.68,0.23,0.2,0.04,0.87,0.05,0.02,0.02
756.1848009110358,0.06324575402705246,287.4599845020513,20.0,8.333333333333333e-05,0.68,0.23,0.2,0.04,0.87,0.05,0.02,0.02
760.6719198939793,0.0636196806089644,287.5138318747117,20.0,8.333333333333333e-05,0.68,0.23,0.2,0.04,0.87,0.05,0.02,0.02
765.1786237145191,0.06399523926067605,287.55863963452265,20.0,8.333333333333333e-05,0.68,0.23,0.2,0.04,0.87,0.05,0.02,0.02
769.6853275350588,0.0643707979123877,287.60344739433435,20.0,8.333333333333333e-05,0.68,0.23,0.2,0.04,0.87,0.05,0.02,0.02
774.175141514256,0.0647449490773208,287.6750804441369,20.0,8.333333333333333e-05,0.68,0.23,0.2,0.04,0.87,0.05,0.02,0.02
778.6649554934532,0.0651191002422539,287.74671349394043,20.0,8.333333333333333e-05,0.68,0.23,0.2,0.04,0.87,0.05,0.02,0.02
783.1477321354116,0.0654926649624171,287.87599872063345,20.0,8.333333333333333e-05,0.68,0.23,0.2,0.04,0.87,0.05,0.02,0.02
787.63050877737,0.0658662296825803,288.00528394732544,20.0,8.333333333333333e-05,0.68,0.23,0.2,0.04,0.87,0.05,0.02,0.02
792.1054466736906,0.06623914117394035,288.1060834419129,20.0,8.333333333333333e-05,0.68,0.23,0.2,0.04,0.87,0.05,0.02,0.02
796.5803845700112,0.0666120526653004,288.2068829364969,20.0,8.333333333333333e-05,0.68,0.23,0.2,0.04,0.87,0.05,0.02,0.02
801.0941590226209,0.06698820053635121,288.24914576516693,20.0,8.333333333333333e-05,0.68,0.23,0.2,0.04,0.87,0.05,0.02,0.02
805.6079334752305,0.067364348407402,288.29140859383716,20.0,8.333333333333333e-05,0.68,0.23,0.2,0.04,0.87,0.05,0.02,0.02
810.1721962369213,0.0677447036375429,288.3692302936752,20.0,8.333333333333333e-05,0.68,0.23,0.2,0.04,0.87,0.05,0.02,0.02
814.7364589986121,0.0681250588676838,288.4470519935138,20.0,8.333333333333333e-05,0.68,0.23,0.2,0.04,0.87,0.05,0.02,0.02
819.3301496931103,0.06850786642555864,288.52115149017584,20.0,8.333333333333333e-05,0.68,0.23,0.2,0.04,0.87,0.05,0.02,0.02
823.9238403876085,0.0688906739834335,288.5952509868365,20.0,8.333333333333333e-05,0.68,0.23,0.2,0.04,0.87,0.05,0.02,0.02
828.5527521723548,0.06927641663216236,288.66795199156104,20.0,8.333333333333333e-05,0.68,0.23,0.2,0.04,0.87,0.05,0.02,0.02
833.1816639571009,0.0696621592808912,288.74065299628734,20.0,8.333333333333333e-05,0.68,0.23,0.2,0.04,0.87,0.05,0.02,0.02
837.8675209688215,0.07005264736520125,288.80679895819634,20.0,8.333333333333333e-05,0.68,0.23,0.2,0.04,0.87,0.05,0.02,0.02
842.553377980542,0.0704431354495113,288.8729449201069,20.0,8.333333333333333e-05,0.68,0.23,0.2,0.04,0.87,0.05,0.02,0.02
847.3072276910257,0.0708392895920516,288.8627162473484,20.0,8.333333333333333e-05,0.68,0.23,0.2,0.04,0.87,0.05,0.02,0.02
852.0610774015092,0.0712354437345919,288.8524875745866,20.0,8.333333333333333e-05,0.68,0.23,0.2,0.04,0.87,0.05,0.02,0.02
856.8745631568672,0.0716365675475384,288.88514248827954,20.0,8.333333333333333e-05,0.68,0.23,0.2,0.04,0.87,0.05,0.02,0.02
861.6880489122253,0.0720376913604849,288.9177974019759,20.0,8.333333333333333e-05,0.68,0.23,0.2,0.04,0.87,0.05,0.02,0.02
866.4949177000062,0.07243826375946666,288.9660876469224,20.0,8.333333333333333e-05,0.68,0.23,0.2,0.04,0.87,0.05,0.02,0.02
871.3017864877872,0.0728388361584484,289.0143778918674,20.0,8.333333333333333e-05,0.68,0.23,0.2,0.04,0.87,0.05,0.02,0.02
876.1328301697374,0.07324142313194425,289.1017550588409,20.0,8.333333333333333e-05,0.68,0.23,0.2,0.04,0.87,0.05,0.02,0.02
880.9638738516876,0.0736440101054401,289.18913222581307,20.0,8.333333333333333e-05,0.68,0.23,0.2,0.04,0.87,0.05,0.02,0.02
885.8431829358576,0.07405061919578759,289.237668383488,20.0,8.333333333333333e-05,0.68,0.23,0.2,0.04,0.87,0.05,0.02,0.02
890.7224920200276,0.0744572282861351,289.286204541165,20.0,8.333333333333333e-05,0.68,0.23,0.2,0.04,0.87,0.05,0.02,0.02
895.6452616901131,0.07486745909197555,289.3250239276415,20.0,8.333333333333333e-05,0.68,0.23,0.2,0.04,0.87,0.05,0.02,0.02
900.5680313601985,0.075277689897816,289.3638433141209,20.0,8.333333333333333e-05,0.68,0.23,0.2,0.04,0.87,0.05,0.02,0.02
905.5489628707392,0.0756927675236944,289.4280873426179,20.0,8.333333333333333e-05,0.68,0.23,0.2,0.04,0.87,0.05,0.02,0.02
910.52989438128,0.0761078451495728,289.49233137111304,20.0,8.333333333333333e-05,0.68,0.23,0.2,0.04,0.87,0.05,0.02,0.02
915.541489872522,0.0765254781071763,289.54648927499204,20.0,8.333333333333333e-05,0.68,0.23,0.2,0.04,0.87,0.05,0.02,0.02
920.553085363764,0.0769431110647798,289.60064717887195,20.0,8.333333333333333e-05,0.68,0.23,0.2,0.04,0.87,0.05,0.02,0.02
925.6046074853496,0.0773640712415786,289.6580384054859,20.0,8.333333333333333e-05,0.68,0.23,0.2,0.04,0.87,0.05,0.02,0.02
930.6561296069352,0.0777850314183774,289.7154296320967,20.0,8.333333333333333e-05,0.68,0.23,0.2,0.04,0.87,0.05,0.02,0.02
935.8169238289122,0.07821509760354214,289.7756349502382,20.0,8.333333333333333e-05,0.68,0.23,0.2,0.04,0.87,0.05,0.02,0.02
940.9777180508892,0.0786451637887069,289.83584026838287,20.0,8.333333333333333e-05,0.68,0.23,0.2,0.04,0.87,0.05,0.02,0.02
946.2212545882487,0.0790821251668202,289.83849800847287,20.0,8.333333333333333e-05,0.68,0.23,0.2,0.04,0.87,0.05,0.02,0.02
951.4647911256084,0.0795190865449335,289.84115574856025,20.0,8.333333333333333e-05,0.68,0.23,0.2,0.04,0.87,0.05,0.02,0.02
956.7903025560925,0.0799628791641405,289.8447568623713,20.0,8.333333333333333e-05,0.68,0.23,0.2,0.04,0.87,0.05,0.02,0.02
962.1158139865764,0.0804066717833475,289.8483579761834,20.0,8.333333333333333e-05,0.68,0.23,0.2,0.04,0.87,0.05,0.02,0.02
967.4931139297416,0.08085478011194461,289.8594154404549,20.0,8.333333333333333e-05,0.68,0.23,0.2,0.04,0.87,0.05,0.02,0.02
972.8704138729069,0.0813028884405417,289.87047290472793,20.0,8.333333333333333e-05,0.68,0.23,0.2,0.04,0.87,0.05,0.02,0.02
978.2978930100576,0.0817551783686376,289.8758865390829,20.0,8.333333333333333e-05,0.68,0.23,0.2,0.04,0.87,0.05,0.02,0.02
983.7253721472084,0.0822074682967335,289.881300173436,20.0,8.333333333333333e-05,0.68,0.23,0.2,0.04,0.87,0.05,0.02,0.02