File: datasets/al_6061_comp/csv/T_020_D_3.csv
Time,Strain(%),Stress(MPa),Temp(C),SR(%/s),Si(%),Fe(%),Cu(%),Mn(%),Mg(%),Cr(%),Zn(%),Ti(%)
0.0,9.08812221706725e-05,0.630253284700771,20.0,8.333333333333333e-05,0.67,0.28,0.23,0.05,0.9,0.05,0.03,0.02
1.0185382323891303,0.0001757594082031,0.63984922529198,20.0,8.333333333333333e-05,0.67,0.28,0.23,0.05,0.9,0.05,0.03,0.02
2.01455826493953,0.0002587610775823,1.1877034029416,20.0,8.333333333333333e-05,0.67,0.28,0.23,0.05,0.9,0.05,0.03,0.02
2.81217038198913,0.0003252287540031,3.09791398807863,20.0,8.333333333333333e-05,0.67,0.28,0.23,0.05,0.9,0.05,0.03,0.02
3.7098806962959294,0.000400037946862,6.65647256907576,20.0,8.333333333333333e-05,0.67,0.28,0.23,0.05,0.9,0.05,0.03,0.02
4.91793059266953,0.0005007087715598,11.6115331757236,20.0,8.333333333333333e-05,0.67,0.28,0.23,0.05,0.9,0.05,0.03,0.02
6.0280685322399306,0.000593220266524,17.0343104190664,20.0,8.333333333333333e-05,0.67,0.28,0.23,0.05,0.9,0.05,0.03,0.02
7.401379607018731,0.0007076628560889,22.6138616734892,20.0,8.333333333333333e-05,0.67,0.28,0.23,0.05,0.9,0.05,0.03,0.02
8.63254872112953,0.0008102602822648,28.2614287328066,20.0,8.333333333333333e-05,0.67,0.28,0.23,0.05,0.9,0.05,0.03,0.02
9.763651102124731,0.0009045188140144,34.324055549528,20.0,8.333333333333333e-05,0.67,0.28,0.23,0.05,0.9,0.05,0.03,0.02
11.270267124552332,0.0010300701492167,40.5581957246098,20.0,8.333333333333333e-05,0.67,0.28,0.23,0.05,0.9,0.05,0.03,0.02
12.50641237591593,0.001133082253497,46.917531288873,20.0,8.333333333333333e-05,0.67,0.28,0.23,0.05,0.9,0.05,0.03,0.02
13.85515016202273,0.0012454770690059,53.3302892539676,20.0,8.333333333333333e-05,0.67,0.28,0.23,0.05,0.9,0.05,0.03,0.02
15.228964859264732,0.0013599616271094,59.801787845166,20.0,8.333333333333333e-05,0.67,0.28,0.23,0.05,0.9,0.05,0.03,0.02
16.34728189952073,0.0014531547137974,66.3962774880503,20.0,8.333333333333333e-05,0.67,0.28,0.23,0.05,0.9,0.05,0.03,0.02
17.47553768001993,0.001547176028839,73.0438260502468,20.0,8.333333333333333e-05,0.67,0.28,0.23,0.05,0.9,0.05,0.03,0.02
18.70058135202993,0.0016492630015065,79.7328818666109,20.0,8.333333333333333e-05,0.67,0.28,0.23,0.05,0.9,0.05,0.03,0.02
19.92548640151233,0.0017513384222967,86.3976329634354,20.0,8.333333333333333e-05,0.67,0.28,0.23,0.05,0.9,0.05,0.03,0.02
21.29608543584273,0.0018655550084909,93.0559839343734,20.0,8.333333333333333e-05,0.67,0.28,0.23,0.05,0.9,0.05,0.03,0.02
22.558097832752733,0.0019707227082334,99.5822444585668,20.0,8.333333333333333e-05,0.67,0.28,0.23,0.05,0.9,0.05,0.03,0.02
23.786446901804734,0.0020730851306544,106.113385267625,20.0,8.333333333333333e-05,0.67,0.28,0.23,0.05,0.9,0.05,0.03,0.02
25.04933941513833,0.0021783261734322,112.521308784531,20.0,8.333333333333333e-05,0.67,0.28,0.23,0.05,0.9,0.05,0.03,0.02
26.32045587876273,0.0022842525454009,118.896443936209,20.0,8.333333333333333e-05,0.67,0.28,0.23,0.05,0.9,0.05,0.03,0.02
27.54179540900193,0.0023860308395875,125.253365187648,20.0,8.333333333333333e-05,0.67,0.28,0.23,0.05,0.9,0.05,0.03,0.02
28.84639078084233,0.0024947471205742,131.518683811617,20.0,8.333333333333333e-05,0.67,0.28,0.23,0.05,0.9,0.05,0.03,0.02
30.043245125688333,0.0025944849826447,137.77644701028,20.0,8.333333333333333e-05,0.67,0.28,0.23,0.05,0.9,0.05,0.03,0.02
31.30636318116153,0.0026997448206008,143.910190861978,20.0,8.333333333333333e-05,0.67,0.28,0.23,0.05,0.9,0.05,0.03,0.02
32.56491556894233,0.0028046241862492,149.969061001552,20.0,8.333333333333333e-05,0.67,0.28,0.23,0.05,0.9,0.05,0.03,0.02
33.76359727309593,0.002904514328262,155.873721832103,20.0,8.333333333333333e-05,0.67,0.28,0.23,0.05,0.9,0.05,0.03,0.02
34.95514570035633,0.0030038100305337,161.719839718095,20.0,8.333333333333333e-05,0.67,0.28,0.23,0.05,0.9,0.05,0.03,0.02
36.20644987517073,0.0031080853784349,167.499673751528,20.0,8.333333333333333e-05,0.67,0.28,0.23,0.05,0.9,0.05,0.03,0.02
37.36277713685553,0.0032044459835753,173.236897697518,20.0,8.333333333333333e-05,0.67,0.28,0.23,0.05,0.9,0.05,0.03,0.02
38.56522836789513,0.0033046502528286,178.973453111551,20.0,8.333333333333333e-05,0.67,0.28,0.23,0.05,0.9,0.05,0.03,0.02
39.79453196125833,0.0034070922189422,184.522891125366,20.0,8.333333333333333e-05,0.67,0.28,0.23,0.05,0.9,0.05,0.03,0.02
40.893733717053934,0.0034986923652585,190.060954112163,20.0,8.333333333333333e-05,0.67,0.28,0.23,0.05,0.9,0.05,0.03,0.02
42.077783916164734,0.0035973632151844,195.474827316139,20.0,8.333333333333333e-05,0.67,0.28,0.23,0.05,0.9,0.05,0.03,0.02
43.19965079759553,0.0036908521219703,200.846590079339,20.0,8.333333333333333e-05,0.67,0.28,0.23,0.05,0.9,0.05,0.03,0.02
44.44912412969673,0.0037949748996454,206.185990835929,20.0,8.333333333333333e-05,0.67,0.28,0.23,0.05,0.9,0.05,0.03,0.02
45.70727286967233,0.0038998206279767,211.352309597724,20.0,8.333333333333333e-05,0.67,0.28,0.23,0.05,0.9,0.05,0.03,0.02
46.948647795595534,0.0040032685384703,216.201769052837,20.0,8.333333333333333e-05,0.67,0.28,0.23,0.05,0.9,0.05,0.03,0.02
48.25430217983433,0.0041120730704902,220.694857495924,20.0,8.333333333333333e-05,0.67,0.28,0.23,0.05,0.9,0.05,0.03,0.02
49.60075532745993,0.004224277499459,224.784146798889,20.0,8.333333333333333e-05,0.67,0.28,0.23,0.05,0.9,0.05,0.03,0.02
51.16058705216673,0.0043542634765179,228.733797776953,20.0,8.333333333333333e-05,0.67,0.28,0.23,0.05,0.9,0.05,0.03,0.02
52.85158031912553,0.0044951795820978,232.469012521759,20.0,8.333333333333333e-05,0.67,0.28,0.23,0.05,0.9,0.05,0.03,0.02
54.842013342957934,0.0046610490007505,236.150085212514,20.0,8.333333333333333e-05,0.67,0.28,0.23,0.05,0.9,0.05,0.03,0.02
57.03995914195113,0.0048442111506666,239.687593430513,20.0,8.333333333333333e-05,0.67,0.28,0.23,0.05,0.9,0.05,0.03,0.02
59.68752916239513,0.0050648419857036,242.926578816019,20.0,8.333333333333333e-05,0.67,0.28,0.23,0.05,0.9,0.05,0.03,0.02
63.02434127070394,0.005342909661396,245.853390899918,20.0,8.333333333333333e-05,0.67,0.28,0.23,0.05,0.9,0.05,0.03,0.02
67.05261366550474,0.0056785990276294,248.555221403772,20.0,8.333333333333333e-05,0.67,0.28,0.23,0.05,0.9,0.05,0.03,0.02
71.84326052307753,0.0060778195990938,250.902020237898,20.0,8.333333333333333e-05,0.67,0.28,0.23,0.05,0.9,0.05,0.03,0.02
76.95392261437473,0.0065037081067019,252.870839334453,20.0,8.333333333333333e-05,0.67,0.28,0.23,0.05,0.9,0.05,0.03,0.02
82.51064218153593,0.006966768070632,254.407588266955,20.0,8.333333333333333e-05,0.67,0.28,0.23,0.05,0.9,0.05,0.03,0.02
88.22487274444234,0.0074429539508742,255.531847760964,20.0,8.333333333333333e-05,0.67,0.28,0.23,0.05,0.9,0.05,0.03,0.02
94.08494336024792,0.007931293168858,256.286653360677,20.0,8.333333333333333e-05,0.67,0.28,0.23,0.05,0.9,0.05,0.03,0.02
100.21292052957033,0.0084419579329682,256.95641214845,20.0,8.333333333333333e-05,0.67,0.28,0.23,0.05,0.9,0.05,0.03,0.02
106.20235083230192,0.0089410771248625,257.546177155034,20.0,8.333333333333333e-05,0.67,0.28,0.23,0.05,0.9,0.05,0.03,0.02
112.43429823010592,0.0094604060746795,258.127631309282,20.0,8.333333333333333e-05,0.67,0.28,0.23,0.05,0.9,0.05,0.03,0.02
118.44445719049833,0.0099612526547122,258.619452120169,20.0,8.333333333333333e-05,0.67,0.28,0.23,0.05,0.9,0.05,0.03,0.02
124.47066283887996,0.010463436458744,258.973492012067,20.0,8.333333333333333e-05,0.67,0.28,0.23,0.05,0.9,0.05,0.03,0.02
130.34391689032833,0.0109528742963647,259.310833572775,20.0,8.333333333333333e-05,0.67,0.28,0.23,0.05,0.9,0.05,0.03,0.02
136.06182712368272,0.0114293668158109,259.618824598078,20.0,8.333333333333333e-05,0.67,0.28,0.23,0.05,0.9,0.05,0.03,0.02
141.82517220123032,0.0119096455722732,260.041615675276,20.0,8.333333333333333e-05,0.67,0.28,0.23,0.05,0.9,0.05,0.03,0.02
147.47232133758874,0.0123802413336364,260.382197795638,20.0,8.333333333333333e-05,0.67,0.28,0.23,0.05,0.9,0.05,0.03,0.02
152.92361796170673,0.0128345160523129,260.648989164572,20.0,8.333333333333333e-05,0.67,0.28,0.23,0.05,0.9,0.05,0.03,0.02
158.16509113351833,0.0132713054832972,260.811195335997,20.0,8.333333333333333e-05,0.67,0.28,0.23,0.05,0.9,0.05,0.03,0.02
163.27187697654873,0.0136968709702164,261.016864517787,20.0,8.333333333333333e-05,0.67,0.28,0.23,0.05,0.9,0.05,0.03,0.02
168.38948555266833,0.0141233383515597,261.226876823532,20.0,8.333333333333333e-05,0.67,0.28,0.23,0.05,0.9,0.05,0.03,0.02
173.45528102894312,0.0145454879745826,261.469101411185,20.0,8.333333333333333e-05,0.67,0.28,0.23,0.05,0.9,0.05,0.03,0.02
178.50920464320873,0.0149666482757714,261.756698501526,20.0,8.333333333333333e-05,0.67,0.28,0.23,0.05,0.9,0.05,0.03,0.02
183.53741460716552,0.0153856657727678,262.018551534244,20.0,8.333333333333333e-05,0.67,0.28,0.23,0.05,0.9,0.05,0.03,0.02
188.32665792007117,0.0157847693821766,262.335682933892,20.0,8.333333333333333e-05,0.67,0.28,0.23,0.05,0.9,0.05,0.03,0.02
193.06400435948436,0.0161795482521277,262.653027283427,20.0,8.333333333333333e-05,0.67,0.28,0.23,0.05,0.9,0.05,0.03,0.02
197.7581138133268,0.0165707240399479,262.900461224357,20.0,8.333333333333333e-05,0.67,0.28,0.23,0.05,0.9,0.05,0.03,0.02
202.52459389223196,0.01696793071319,263.137410227345,20.0,8.333333333333333e-05,0.67,0.28,0.23,0.05,0.9,0.05,0.03,0.02
207.31829901548312,0.0173674061401276,263.344460996489,20.0,8.333333333333333e-05,0.67,0.28,0.23,0.05,0.9,0.05,0.03,0.02
211.95224214632432,0.0177535680676977,263.595457793619,20.0,8.333333333333333e-05,0.67,0.28,0.23,0.05,0.9,0.05,0.03,0.02
216.54606654272797,0.018136386767398,263.81374987706,20.0,8.333333333333333e-05,0.67,0.28,0.23,0.05,0.9,0.05,0.03,0.02
221.0173160793244,0.0185089908954477,264.045644409485,20.0,8.333333333333333e-05,0.67,0.28,0.23,0.05,0.9,0.05,0.03,0.02
225.4411075561744,0.0188776401851852,264.28337869584,20.0,8.333333333333333e-05,0.67,0.28,0.23,0.05,0.9,0.05,0.03,0.02
229.94822901159276,0.0192532336398034,264.60507871627,20.0,8.333333333333333e-05,0.67,0.28,0.23,0.05,0.9,0.05,0.03,0.02
234.36810006212195,0.0196215562273475,264.885428596166,20.0,8.333333333333333e-05,0.67,0.28,0.23,0.05,0.9,0.05,0.03,0.02
238.91983372534116,0.0200008673659491,265.150683495032,20.0,8.333333333333333e-05,0.67,0.28,0.23,0.05,0.9,0.05,0.03,0.02
243.49022067548196,0.0203817329451275,265.462365282539,20.0,8.333333333333333e-05,0.67,0.28,0.23,0.05,0.9,0.05,0.03,0.02
248.1146362031535,0.0207671009057668,265.742050886627,20.0,8.333333333333333e-05,0.67,0.28,0.23,0.05,0.9,0.05,0.03,0.02
252.63658714363356,0.0211439301508068,266.006820726819,20.0,8.333333333333333e-05,0.67,0.28,0.23,0.05,0.9,0.05,0.03,0.02
257.1257120220328,0.0215180238906734,266.155063356881,20.0,8.333333333333333e-05,0.67,0.28,0.23,0.05,0.9,0.05,0.03,0.02
261.6525879566728,0.0218952635518934,266.304350025228,20.0,8.333333333333333e-05,0.67,0.28,0.23,0.05,0.9,0.05,0.03,0.02
266.1552218993992,0.0222704830471206,266.492801799599,20.0,8.333333333333333e-05,0.67,0.28,0.23,0.05,0.9,0.05,0.03,0.02
270.8010406315012,0.0226576346081291,266.654651593635,20.0,8.333333333333333e-05,0.67,0.28,0.23,0.05,0.9,0.05,0.03,0.02
275.3736752729116,0.0230386874949133,266.910090703579,20.0,8.333333333333333e-05,0.67,0.28,0.23,0.05,0.9,0.05,0.03,0.02
279.89838345963034,0.0234157465104732,267.121770043511,20.0,8.333333333333333e-05,0.67,0.28,0.23,0.05,0.9,0.05,0.03,0.02
284.44367535240394,0.023794520834871,267.316137644555,20.0,8.333333333333333e-05,0.67,0.28,0.23,0.05,0.9,0.05,0.03,0.02
288.8464807079536,0.0241614212811668,267.524428757004,20.0,8.333333333333333e-05,0.67,0.28,0.23,0.05,0.9,0.05,0.03,0.02
293.2959737068168,0.0245322123644054,267.652662087795,20.0,8.333333333333333e-05,0.67,0.28,0.23,0.05,0.9,0.05,0.03,0.02
297.7601400284656,0.0249042262245428,267.872228595384,20.0,8.333333333333333e-05,0.67,0.28,0.23,0.05,0.9,0.05,0.03,0.02
302.15742400207114,0.0252706665556766,268.189317481,20.0,8.333333333333333e-05,0.67,0.28,0.23,0.05,0.9,0.05,0.03,0.02
306.5918931221884,0.0256402056490197,268.45280001784,20.0,8.333333333333333e-05,0.67,0.28,0.23,0.05,0.9,0.05,0.03,0.02
310.9975381209508,0.0260073427322499,268.730444616159,20.0,8.333333333333333e-05,0.67,0.28,0.23,0.05,0.9,0.05,0.03,0.02
315.2969904043816,0.0263656304225358,268.940644445648,20.0,8.333333333333333e-05,0.67,0.28,0.23,0.05,0.9,0.05,0.03,0.02
319.6725550472908,0.0267302608094449,269.154784567965,20.0,8.333333333333333e-05,0.67,0.28,0.23,0.05,0.9,0.05,0.03,0.02
324.0267307468312,0.0270931087844066,269.370749597563,20.0,8.333333333333333e-05,0.67,0.28,0.23,0.05,0.9,0.05,0.03,0.02
328.5292638370708,0.0274683198752599,269.567255193961,20.0,8.333333333333333e-05,0.67,0.28,0.23,0.05,0.9,0.05,0.03,0.02
333.1023859622608,0.0278494133856924,269.751307660036,20.0,8.333333333333333e-05,0.67,0.28,0.23,0.05,0.9,0.05,0.03,0.02
337.615280539864,0.028225487933826,269.867746044794,20.0,8.333333333333333e-05,0.67,0.28,0.23,0.05,0.9,0.05,0.03,0.02
342.0781736308276,0.0285973956914063,270.04963635514,20.0,8.333333333333333e-05,0.67,0.28,0.23,0.05,0.9,0.05,0.03,0.02
346.4965860010372,0.0289655967222571,270.119737894933,20.0,8.333333333333333e-05,0.67,0.28,0.23,0.05,0.9,0.05,0.03,0.02
350.7757189818628,0.0293221911373259,270.284037316762,20.0,8.333333333333333e-05,0.67,0.28,0.23,0.05,0.9,0.05,0.03,0.02
355.14992212647394,0.0296867080660435,270.414574806791,20.0,8.333333333333333e-05,0.67,0.28,0.23,0.05,0.9,0.05,0.03,0.02
359.6431012022284,0.0300611396556897,270.545121726803,20.0,8.333333333333333e-05,0.67,0.28,0.23,0.05,0.9,0.05,0.03,0.02
364.22296273915833,0.0304427947837672,270.695537034302,20.0,8.333333333333333e-05,0.67,0.28,0.23,0.05,0.9,0.05,0.03,0.02
368.8774096185748,0.0308306653570519,270.946506680678,20.0,8.333333333333333e-05,0.67,0.28,0.23,0.05,0.9,0.05,0.03,0.02
373.42048260356194,0.0312092547724675,271.264814565562,20.0,8.333333333333333e-05,0.67,0.28,0.23,0.05,0.9,0.05,0.03,0.02
377.88718932842073,0.0315814803328724,271.545479716983,20.0,8.333333333333333e-05,0.67,0.28,0.23,0.05,0.9,0.05,0.03,0.02
382.320170906632,0.03195089546439,271.818494035725,20.0,8.333333333333333e-05,0.67,0.28,0.23,0.05,0.9,0.05,0.03,0.02
386.7200253571828,0.0323175500019359,272.022574012328,20.0,8.333333333333333e-05,0.67,0.28,0.23,0.05,0.9,0.05,0.03,0.02
391.0810684481944,0.0326809702595202,272.234548687916,20.0,8.333333333333333e-05,0.67,0.28,0.23,0.05,0.9,0.05,0.03,0.02
395.50643217305554,0.0330497505699253,272.410081592094,20.0,8.333333333333333e-05,0.67,0.28,0.23,0.05,0.9,0.05,0.03,0.02
399.78232288912,0.033406074796264,272.58508187631,20.0,8.333333333333333e-05,0.67,0.28,0.23,0.05,0.9,0.05,0.03,0.02
404.2259892523275,0.0337763803265313,272.733017557281,20.0,8.333333333333333e-05,0.67,0.28,0.23,0.05,0.9,0.05,0.03,0.02
408.6282126205035,0.0341432322738793,272.913893669856,20.0,8.333333333333333e-05,0.67,0.28,0.23,0.05,0.9,0.05,0.03,0.02
413.082144169276,0.034514393236277,273.008838514088,20.0,8.333333333333333e-05,0.67,0.28,0.23,0.05,0.9,0.05,0.03,0.02
417.6973851152404,0.0348989966484407,273.052662933275,20.0,8.333333333333333e-05,0.67,0.28,0.23,0.05,0.9,0.05,0.03,0.02
422.1881452125052,0.0352732266565461,273.184227516102,20.0,8.333333333333333e-05,0.67,0.28,0.23,0.05,0.9,0.05,0.03,0.02
426.7412687763088,0.0356526536201964,273.310770886458,20.0,8.333333333333333e-05,0.67,0.28,0.23,0.05,0.9,0.05,0.03,0.02
431.352736166074,0.0360369425693435,273.582292815553,20.0,8.333333333333333e-05,0.67,0.28,0.23,0.05,0.9,0.05,0.03,0.02
435.9222820459,0.036417738059329,273.861052240314,20.0,8.333333333333333e-05,0.67,0.28,0.23,0.05,0.9,0.05,0.03,0.02
440.5024950033784,0.0367994224724522,274.177264359078,20.0,8.333333333333333e-05,0.67,0.28,0.23,0.05,0.9,0.05,0.03,0.02
445.0268199090796,0.0371764495479273,274.415739342069,20.0,8.333333333333333e-05,0.67,0.28,0.23,0.05,0.9,0.05,0.03,0.02
449.5752542418928,0.0375554857423284,274.563678630483,20.0,8.333333333333333e-05,0.67,0.28,0.23,0.05,0.9,0.05,0.03,0.02
454.215318425488,0.037942157757628,274.648181224848,20.0,8.333333333333333e-05,0.67,0.28,0.23,0.05,0.9,0.05,0.03,0.02
458.8601910406828,0.0383292304755609,274.621492317797,20.0,8.333333333333333e-05,0.67,0.28,0.23,0.05,0.9,0.05,0.03,0.02
463.4700352865992,0.0387133841627206,274.65098708763,20.0,8.333333333333333e-05,0.67,0.28,0.23,0.05,0.9,0.05,0.03,0.02
468.006500951674,0.0390914229681435,274.763803900308,20.0,8.333333333333333e-05,0.67,0.28,0.23,0.05,0.9,0.05,0.03,0.02
472.470894052678,0.0394634557265605,274.921347942232,20.0,8.333333333333333e-05,0.67,0.28,0.23,0.05,0.9,0.05,0.03,0.02
477.0012385847692,0.0398409844375681,275.090659621213,20.0,8.333333333333333e-05,0.67,0.28,0.23,0.05,0.9,0.05,0.03,0.02
481.5418685960668,0.0402193702718429,275.273513957393,20.0,8.333333333333333e-05,0.67,0.28,0.23,0.05,0.9,0.05,0.03,0.02
486.1125006261412,0.0406002562743491,275.41956323051,20.0,8.333333333333333e-05,0.67,0.28,0.23,0.05,0.9,0.05,0.03,0.02
490.7174715314656,0.0409840038497928,275.573424801021,20.0,8.333333333333333e-05,0.67,0.28,0.23,0.05,0.9,0.05,0.03,0.02
495.2711439555328,0.0413634765517984,275.793150906315,20.0,8.333333333333333e-05,0.67,0.28,0.23,0.05,0.9,0.05,0.03,0.02
499.8715994319616,0.0417468478415008,276.073142810788,20.0,8.333333333333333e-05,0.67,0.28,0.23,0.05,0.9,0.05,0.03,0.02
504.4586339212828,0.0421291007156109,276.336853217773,20.0,8.333333333333333e-05,0.67,0.28,0.23,0.05,0.9,0.05,0.03,0.02
509.0585655666304,0.0425124283527232,276.557186765826,20.0,8.333333333333333e-05,0.67,0.28,0.23,0.05,0.9,0.05,0.03,0.02
513.6602445453148,0.0428959016009469,276.660269700687,20.0,8.333333333333333e-05,0.67,0.28,0.23,0.05,0.9,0.05,0.03,0.02
518.2612024379728,0.0432793147586684,276.766162105772,20.0,8.333333333333333e-05,0.67,0.28,0.23,0.05,0.9,0.05,0.03,0.02
522.9949976289232,0.0436737976912476,276.83991662455,20.0,8.333333333333333e-05,0.67,0.28,0.23,0.05,0.9,0.05,0.03,0.02
527.6731431861639,0.044063643154351,276.931039193133,20.0,8.333333333333333e-05,0.67,0.28,0.23,0.05,0.9,0.05,0.03,0.02
532.3994452563028,0.0444575016601959,277.059515915567,20.0,8.333333333333333e-05,0.67,0.28,0.23,0.05,0.9,0.05,0.03,0.02
537.1126128031551,0.0448502656224336,277.264459004535,20.0,8.333333333333333e-05,0.67,0.28,0.23,0.05,0.9,0.05,0.03,0.02
541.7769441051412,0.0452389598975991,277.401813090244,20.0,8.333333333333333e-05,0.67,0.28,0.23,0.05,0.9,0.05,0.03,0.02
546.6487386975111,0.0456449427802966,277.619178677915,20.0,8.333333333333333e-05,0.67,0.28,0.23,0.05,0.9,0.05,0.03,0.02
551.5648257305392,0.0460546166997156,277.800231634305,20.0,8.333333333333333e-05,0.67,0.28,0.23,0.05,0.9,0.05,0.03,0.02
556.448210683756,0.046461565445817,277.930234795584,20.0,8.333333333333333e-05,0.67,0.28,0.23,0.05,0.9,0.05,0.03,0.02
561.1592342852584,0.0468541507459422,278.137146361732,20.0,8.333333333333333e-05,0.67,0.28,0.23,0.05,0.9,0.05,0.03,0.02
565.8680730953224,0.0472465539801142,278.19301416585,20.0,8.333333333333333e-05,0.67,0.28,0.23,0.05,0.9,0.05,0.03,0.02
570.4549138107376,0.0476287907063988,278.400228773027,20.0,8.333333333333333e-05,0.67,0.28,0.23,0.05,0.9,0.05,0.03,0.02
575.1859169168799,0.048023040965244,278.544182754686,20.0,8.333333333333333e-05,0.67,0.28,0.23,0.05,0.9,0.05,0.03,0.02
579.9081932707276,0.0484165639947313,278.709827673617,20.0,8.333333333333333e-05,0.67,0.28,0.23,0.05,0.9,0.05,0.03,0.02
584.662750035406,0.0488127770584545,278.882083611447,20.0,8.333333333333333e-05,0.67,0.28,0.23,0.05,0.9,0.05,0.03,0.02
589.4339079077536,0.0492103735478168,278.924988591528,20.0,8.333333333333333e-05,0.67,0.28,0.23,0.05,0.9,0.05,0.03,0.02
594.195812675608,0.049607198945138,279.030754340558,20.0,8.333333333333333e-05,0.67,0.28,0.23,0.05,0.9,0.05,0.03,0.02
598.8652426442763,0.0499963181091937,279.209488090874,20.0,8.333333333333333e-05,0.67,0.28,0.23,0.05,0.9,0.05,0.03,0.02
603.56435108788,0.050387910479494,279.374457611049,20.0,8.333333333333333e-05,0.67,0.28,0.23,0.05,0.9,0.05,0.03,0.02
608.3190196203243,0.0507841328571977,279.539378778832,20.0,8.333333333333333e-05,0.67,0.28,0.23,0.05,0.9,0.05,0.03,0.02
613.1346157637644,0.0511854325358177,279.639560127096,20.0,8.333333333333333e-05,0.67,0.28,0.23,0.05,0.9,0.05,0.03,0.02
618.1281807561976,0.0516015629518538,279.71021938073,20.0,8.333333333333333e-05,0.67,0.28,0.23,0.05,0.9,0.05,0.03,0.02
623.0134041993268,0.0520086649054479,279.911159252306,20.0,8.333333333333333e-05,0.67,0.28,0.23,0.05,0.9,0.05,0.03,0.02
627.9996839403424,0.0524241882171992,280.061063916765,20.0,8.333333333333333e-05,0.67,0.28,0.23,0.05,0.9,0.05,0.03,0.02
632.979928003246,0.0528392085557745,280.190298613589,20.0,8.333333333333333e-05,0.67,0.28,0.23,0.05,0.9,0.05,0.03,0.02
637.9859486096643,0.0532563769396427,280.324296812225,20.0,8.333333333333333e-05,0.67,0.28,0.23,0.05,0.9,0.05,0.03,0.02
643.0970198987644,0.0536822995470677,280.370479375717,20.0,8.333333333333333e-05,0.67,0.28,0.23,0.05,0.9,0.05,0.03,0.02
648.2110793815036,0.0541084711706293,280.512550541143,20.0,8.333333333333333e-05,0.67,0.28,0.23,0.05,0.9,0.05,0.03,0.02
653.37145851757,0.0545385027653015,280.630889447085,20.0,8.333333333333333e-05,0.67,0.28,0.23,0.05,0.9,0.05,0.03,0.02
658.5008375326479,0.054965951016558,280.827289589066,20.0,8.333333333333333e-05,0.67,0.28,0.23,0.05,0.9,0.05,0.03,0.02
663.6292225221808,0.0553933164323524,281.068817560503,20.0,8.333333333333333e-05,0.67,0.28,0.23,0.05,0.9,0.05,0.03,0.02
668.7557009666835,0.0558205229693943,281.243447812842,20.0,8.333333333333333e-05,0.67,0.28,0.23,0.05,0.9,0.05,0.03,0.02
673.8415017927424,0.0562443397048992,281.259715829886,20.0,8.333333333333333e-05,0.67,0.28,0.23,0.05,0.9,0.05,0.03,0.02
678.9518557205296,0.0566702025322148,281.303273630561,20.0,8.333333333333333e-05,0.67,0.28,0.23,0.05,0.9,0.05,0.03,0.02
684.1192723255288,0.0571008205826314,281.35383085149,20.0,8.333333333333333e-05,0.67,0.28,0.23,0.05,0.9,0.05,0.03,0.02
689.3646797245372,0.0575379378658821,281.521614825857,20.0,8.333333333333333e-05,0.67,0.28,0.23,0.05,0.9,0.05,0.03,0.02
694.544183716942,0.0579695631985825,281.778126991851,20.0,8.333333333333333e-05,0.67,0.28,0.23,0.05,0.9,0.05,0.03,0.02
699.8610336612976,0.0584126340272788,282.005944259372,20.0,8.333333333333333e-05,0.67,0.28,0.23,0.05,0.9,0.05,0.03,0.02
705.0976465880224,0.0588490184378392,282.146873779865,20.0,8.333333333333333e-05,0.67,0.28,0.23,0.05,0.9,0.05,0.03,0.02
710.3648408165452,0.0592879512902161,282.177454959616,20.0,8.333333333333333e-05,0.67,0.28,0.23,0.05,0.9,0.05,0.03,0.02
715.5711151314808,0.0597218074831274,282.09981258251,20.0,8.333333333333333e-05,0.67,0.28,0.23,0.05,0.9,0.05,0.03,0.02
720.7965091708624,0.0601572569864092,282.113143223327,20.0,8.333333333333333e-05,0.67,0.28,0.23,0.05,0.9,0.05,0.03,0.02
726.0662366776924,0.0605964009453117,282.220469476222,20.0,8.333333333333333e-05,0.67,0.28,0.23,0.05,0.9,0.05,0.03,0.02
731.3522113434688,0.0610368988341264,282.374629831611,20.0,8.333333333333333e-05,0.67,0.28,0.23,0.05,0.9,0.05,0.03,0.02
736.5675800402475,0.0614715128921913,282.577465066359,20.0,8.333333333333333e-05,0.67,0.28,0.23,0.05,0.9,0.05,0.03,0.02
741.8972845453948,0.0619156549342869,282.780511510563,20.0,8.333333333333333e-05,0.67,0.28,0.23,0.05,0.9,0.05,0.03,0.02
747.2490425742004,0.0623616347700207,282.882851090671,20.0,8.333333333333333e-05,0.67,0.28,0.23,0.05,0.9,0.05,0.03,0.02
752.6816477884312,0.0628143518712066,283.053259068394,20.0,8.333333333333333e-05,0.67,0.28,0.23,0.05,0.9,0.05,0.03,0.02
758.2247872782928,0.0632762801620284,283.069653883892,20.0,8.333333333333333e-05,0.67,0.28,0.23,0.05,0.9,0.05,0.03,0.02
763.7516817202719,0.06373685469886,283.216678606412,20.0,8.333333333333333e-05,0.67,0.28,0.23,0.05,0.9,0.05,0.03,0.02
769.318369677766,0.0642007453619845,283.324890866277,20.0,8.333333333333333e-05,0.67,0.28,0.23,0.05,0.9,0.05,0.03,0.02
775.0019999152204,0.0646743812151057,283.417087440238,20.0,8.333333333333333e-05,0.67,0.28,0.23,0.05,0.9,0.05,0.03,0.02
780.5402120260263,0.0651358988910062,283.510476986082,20.0,8.333333333333333e-05,0.67,0.28,0.23,0.05,0.9,0.05,0.03,0.02
786.2269364744535,0.0656097925950418,283.619854734811,20.0,8.333333333333333e-05,0.67,0.28,0.23,0.05,0.9,0.05,0.03,0.02
791.7654438536164,0.0660713348766387,283.718970067868,20.0,8.333333333333333e-05,0.67,0.28,0.23,0.05,0.9,0.05,0.03,0.02
797.3402237728192,0.0665358998699056,283.820695892193,20.0,8.333333333333333e-05,0.67,0.28,0.23,0.05,0.9,0.05,0.03,0.02
803.026791420208,0.067009780507188,283.911688054878,20.0,8.333333333333333e-05,0.67,0.28,0.23,0.05,0.9,0.05,0.03,0.02
808.764587188666,0.0674879301545595,283.931526475273,20.0,8.333333333333333e-05,0.67,0.28,0.23,0.05,0.9,0.05,0.03,0.02
814.6461005988411,0.0679780562720741,284.106430877454,20.0,8.333333333333333e-05,0.67,0.28,0.23,0.05,0.9,0.05,0.03,0.02
820.438186450384,0.068460730093036,284.17269933509,20.0,8.333333333333333e-05,0.67,0.28,0.23,0.05,0.9,0.05,0.03,0.02
826.2137657367543,0.0689420283669002,284.28941217031,20.0,8.333333333333333e-05,0.67,0.28,0.23,0.05,0.9,0.05,0.03,0.02
832.0957746849748,0.0694321957792519,284.33495760875,20.0,8.333333333333333e-05,0.67,0.28,0.23,0.05,0.9,0.05,0.03,0.02
837.9496374507219,0.0699200176763975,284.434528508054,20.0,8.333333333333333e-05,0.67,0.28,0.23,0.05,0.9,0.05,0.03,0.02
843.9067087151357,0.0704164402817653,284.551715579619,20.0,8.333333333333333e-05,0.67,0.28,0.23,0.05,0.9,0.05,0.03,0.02
849.745145090698,0.0709029766463955,284.621176102119,20.0,8.333333333333333e-05,0.67,0.28,0.23,0.05,0.9,0.05,0.03,0.02
855.6769652485419,0.0713972949928825,284.635739570734,20.0,8.333333333333333e-05,0.67,0.28,0.23,0.05,0.9,0.05,0.03,0.02
861.6685985862389,0.0718965977710239,284.64147681316,20.0,8.333333333333333e-05,0.67,0.28,0.23,0.05,0.9,0.05,0.03,0.02
867.7051628999751,0.0723996447971686,284.73450776652,20.0,8.333333333333333e-05,0.67,0.28,0.23,0.05,0.9,0.05,0.03,0.02
873.7789404745492,0.0729057929283831,284.88226707834,20.0,8.333333333333333e-05,0.67,0.28,0.23,0.05,0.9,0.05,0.03,0.02
879.7057535300297,0.0733996940163398,285.078058796591,20.0,8.333333333333333e-05,0.67,0.28,0.23,0.05,0.9,0.05,0.03,0.02
885.7887604217392,0.0739066112573156,285.243529213381,20.0,8.333333333333333e-05,0.67,0.28,0.23,0.05,0.9,0.05,0.03,0.02
891.8439837986765,0.0744112132053937,285.375847372049,20.0,8.333333333333333e-05,0.67,0.28,0.23,0.05,0.9,0.05,0.03,0.02
897.8594863361247,0.0749125050835144,285.401457258112,20.0,8.333333333333333e-05,0.67,0.28,0.23,0.05,0.9,0.05,0.03,0.02
903.809291120002,0.0754083221488375,285.385894005675,20.0,8.333333333333333e-05,0.67,0.28,0.23,0.05,0.9,0.05,0.03,0.02
909.6321055138312,0.0758935566816566,285.350060452307,20.0,8.333333333333333e-05,0.67,0.28,0.23,0.05,0.9,0.05,0.03,0.02
915.6628452819772,0.0763961183290021,285.333504646757,20.0,8.333333333333333e-05,0.67,0.28,0.23,0.05,0.9,0.05,0.03,0.02
921.7364931226132,0.0769022556490551,285.376520887973,20.0,8.333333333333333e-05,0.67,0.28,0.23,0.05,0.9,0.05,0.03,0.02
927.9132985393696,0.0774169894337848,285.426258175097,20.0,8.333333333333333e-05,0.67,0.28,0.23,0.05,0.9,0.05,0.03,0.02
934.2424794686068,0.0779444211778879,285.55984147033,20.0,8.333333333333333e-05,0.67,0.28,0.23,0.05,0.9,0.05,0.03,0.02
940.409082509602,0.0784583047646375,285.603928900586,20.0,8.333333333333333e-05,0.67,0.28,0.23,0.05,0.9,0.05,0.03,0.02
946.4705038741708,0.0789634232116849,285.661528530465,20.0,8.333333333333333e-05,0.67,0.28,0.23,0.05,0.9,0.05,0.03,0.02
949.5000100934872,0.0792158820632946,285.69504833639,20.0,8.333333333333333e-05,0.67,0.28,0.23,0.05,0.9,0.05,0.03,0.02