File: datasets/al_6061_comp/csv/T_100_D_3.csv
Time,Strain(%),Stress(MPa),Temp(C),SR(%/s),Si(%),Fe(%),Cu(%),Mn(%),Mg(%),Cr(%),Zn(%),Ti(%)
0.0,8.76222436180531e-05,3.62086269641244,100.0,8.333333333333333e-05,0.67,0.28,0.23,0.05,0.9,0.05,0.03,0.02
0.4547683322213629,0.0001255196046365,6.69490467831517,100.0,8.333333333333333e-05,0.67,0.28,0.23,0.05,0.9,0.05,0.03,0.02
1.0226233700273626,0.000172840857787,10.2339301050654,100.0,8.333333333333333e-05,0.67,0.28,0.23,0.05,0.9,0.05,0.03,0.02
1.739479331971763,0.0002325788546157,14.2635247926042,100.0,8.333333333333333e-05,0.67,0.28,0.23,0.05,0.9,0.05,0.03,0.02
2.240889557899763,0.0002743630401097,18.7047277485564,100.0,8.333333333333333e-05,0.67,0.28,0.23,0.05,0.9,0.05,0.03,0.02
2.808088564434563,0.0003216296239876,23.2744018079902,100.0,8.333333333333333e-05,0.67,0.28,0.23,0.05,0.9,0.05,0.03,0.02
3.269915897880564,0.0003601152351081,28.1657826312096,100.0,8.333333333333333e-05,0.67,0.28,0.23,0.05,0.9,0.05,0.03,0.02
3.882721625380164,0.0004111823790664,33.1833472065012,100.0,8.333333333333333e-05,0.67,0.28,0.23,0.05,0.9,0.05,0.03,0.02
4.782760945382964,0.0004861856557333,38.2756558086233,100.0,8.333333333333333e-05,0.67,0.28,0.23,0.05,0.9,0.05,0.03,0.02
5.445639002140164,0.0005414254937964,43.5074827386462,100.0,8.333333333333333e-05,0.67,0.28,0.23,0.05,0.9,0.05,0.03,0.02
6.529871197925363,0.0006317781767785,48.7577813612479,100.0,8.333333333333333e-05,0.67,0.28,0.23,0.05,0.9,0.05,0.03,0.02
7.387723014899363,0.000703265828193,54.155546944505,100.0,8.333333333333333e-05,0.67,0.28,0.23,0.05,0.9,0.05,0.03,0.02
8.308273374997764,0.0007799783582012,59.6583169360725,100.0,8.333333333333333e-05,0.67,0.28,0.23,0.05,0.9,0.05,0.03,0.02
9.355255131671363,0.000867226837924,65.1724377581397,100.0,8.333333333333333e-05,0.67,0.28,0.23,0.05,0.9,0.05,0.03,0.02
10.334463353666964,0.0009488275230903,70.7079145859132,100.0,8.333333333333333e-05,0.67,0.28,0.23,0.05,0.9,0.05,0.03,0.02
11.374214946676164,0.0010354734891744,76.1736823788285,100.0,8.333333333333333e-05,0.67,0.28,0.23,0.05,0.9,0.05,0.03,0.02
12.295405249573763,0.0011122393477492,81.6873504097509,100.0,8.333333333333333e-05,0.67,0.28,0.23,0.05,0.9,0.05,0.03,0.02
13.299395110595364,0.001195905169501,87.2031575086774,100.0,8.333333333333333e-05,0.67,0.28,0.23,0.05,0.9,0.05,0.03,0.02
14.213428512870564,0.0012720746196906,92.6920191685606,100.0,8.333333333333333e-05,0.67,0.28,0.23,0.05,0.9,0.05,0.03,0.02
15.297673296774564,0.0013624283516826,98.1289144076335,100.0,8.333333333333333e-05,0.67,0.28,0.23,0.05,0.9,0.05,0.03,0.02
16.363858022246962,0.0014512770788053,103.574598135535,100.0,8.333333333333333e-05,0.67,0.28,0.23,0.05,0.9,0.05,0.03,0.02
17.407630950020966,0.0015382581561198,109.027271557817,100.0,8.333333333333333e-05,0.67,0.28,0.23,0.05,0.9,0.05,0.03,0.02
18.479206755604164,0.0016275561399184,114.385822444552,100.0,8.333333333333333e-05,0.67,0.28,0.23,0.05,0.9,0.05,0.03,0.02
19.535072465252963,0.0017155449490558,119.810763295057,100.0,8.333333333333333e-05,0.67,0.28,0.23,0.05,0.9,0.05,0.03,0.02
20.582251667784565,0.0018028098826001,125.159332370633,100.0,8.333333333333333e-05,0.67,0.28,0.23,0.05,0.9,0.05,0.03,0.02
21.649724851387766,0.0018917659812337,130.49464830445,100.0,8.333333333333333e-05,0.67,0.28,0.23,0.05,0.9,0.05,0.03,0.02
22.72876984480856,0.0019816863973521,135.758225805647,100.0,8.333333333333333e-05,0.67,0.28,0.23,0.05,0.9,0.05,0.03,0.02
23.726952906317365,0.0020648683191445,140.918363878491,100.0,8.333333333333333e-05,0.67,0.28,0.23,0.05,0.9,0.05,0.03,0.02
24.79042612315976,0.0021534910872147,146.028209864354,100.0,8.333333333333333e-05,0.67,0.28,0.23,0.05,0.9,0.05,0.03,0.02
25.729903985634564,0.0022317809090876,151.067595306076,100.0,8.333333333333333e-05,0.67,0.28,0.23,0.05,0.9,0.05,0.03,0.02
26.815831371113365,0.0023222748578775,155.960731754827,100.0,8.333333333333333e-05,0.67,0.28,0.23,0.05,0.9,0.05,0.03,0.02
27.798460589642964,0.0024041606260883,160.803026515718,100.0,8.333333333333333e-05,0.67,0.28,0.23,0.05,0.9,0.05,0.03,0.02
28.830273480586165,0.0024901450336669,165.549834878578,100.0,8.333333333333333e-05,0.67,0.28,0.23,0.05,0.9,0.05,0.03,0.02
29.911749111768565,0.0025802680029321,170.25409738843,100.0,8.333333333333333e-05,0.67,0.28,0.23,0.05,0.9,0.05,0.03,0.02
30.98963375443016,0.0026700917231539,174.922913599721,100.0,8.333333333333333e-05,0.67,0.28,0.23,0.05,0.9,0.05,0.03,0.02
32.11104145620416,0.0027635423649684,179.421371840908,100.0,8.333333333333333e-05,0.67,0.28,0.23,0.05,0.9,0.05,0.03,0.02
33.11178234958856,0.0028469374394171,183.885732855641,100.0,8.333333333333333e-05,0.67,0.28,0.23,0.05,0.9,0.05,0.03,0.02
34.13935522276016,0.0029325685121814,188.187823198732,100.0,8.333333333333333e-05,0.67,0.28,0.23,0.05,0.9,0.05,0.03,0.02
35.09229541992896,0.0030119801952788,192.474851276081,100.0,8.333333333333333e-05,0.67,0.28,0.23,0.05,0.9,0.05,0.03,0.02
36.09418253158856,0.0030954707879171,196.708044188397,100.0,8.333333333333333e-05,0.67,0.28,0.23,0.05,0.9,0.05,0.03,0.02
37.16137396744376,0.0031844034075717,200.90674877559,100.0,8.333333333333333e-05,0.67,0.28,0.23,0.05,0.9,0.05,0.03,0.02
38.23504660135376,0.0032738761270642,205.163432680421,100.0,8.333333333333333e-05,0.67,0.28,0.23,0.05,0.9,0.05,0.03,0.02
39.418432337752165,0.0033724916050974,209.379525782663,100.0,8.333333333333333e-05,0.67,0.28,0.23,0.05,0.9,0.05,0.03,0.02
40.50756914811896,0.0034632530059613,213.554826933202,100.0,8.333333333333333e-05,0.67,0.28,0.23,0.05,0.9,0.05,0.03,0.02
41.64054887380976,0.0035576679831022,217.626930901182,100.0,8.333333333333333e-05,0.67,0.28,0.23,0.05,0.9,0.05,0.03,0.02
42.69282379445696,0.0036453575598228,221.602551710525,100.0,8.333333333333333e-05,0.67,0.28,0.23,0.05,0.9,0.05,0.03,0.02
43.75999065975416,0.0037342881319309,225.342621641508,100.0,8.333333333333333e-05,0.67,0.28,0.23,0.05,0.9,0.05,0.03,0.02
44.94033605288696,0.0038326502480253,228.812344998107,100.0,8.333333333333333e-05,0.67,0.28,0.23,0.05,0.9,0.05,0.03,0.02
46.18407936727376,0.0039362955242242,232.018754343067,100.0,8.333333333333333e-05,0.67,0.28,0.23,0.05,0.9,0.05,0.03,0.02
47.49965608657016,0.0040459269174989,235.049959758027,100.0,8.333333333333333e-05,0.67,0.28,0.23,0.05,0.9,0.05,0.03,0.02
48.87038410776296,0.0041601542525983,238.014982749037,100.0,8.333333333333333e-05,0.67,0.28,0.23,0.05,0.9,0.05,0.03,0.02
50.26727684383376,0.0042765619806042,240.809583293395,100.0,8.333333333333333e-05,0.67,0.28,0.23,0.05,0.9,0.05,0.03,0.02
51.89377674352016,0.0044121036389114,243.351420948105,100.0,8.333333333333333e-05,0.67,0.28,0.23,0.05,0.9,0.05,0.03,0.02
53.74401168492417,0.0045662898840284,245.657884702773,100.0,8.333333333333333e-05,0.67,0.28,0.23,0.05,0.9,0.05,0.03,0.02
55.863421000020566,0.0047429073269531,247.683436144693,100.0,8.333333333333333e-05,0.67,0.28,0.23,0.05,0.9,0.05,0.03,0.02
58.36009943243696,0.0049509638629878,249.377517086667,100.0,8.333333333333333e-05,0.67,0.28,0.23,0.05,0.9,0.05,0.03,0.02
61.14514588940336,0.005183051067735,250.771200510827,100.0,8.333333333333333e-05,0.67,0.28,0.23,0.05,0.9,0.05,0.03,0.02
64.23024313955337,0.0054401425052475,251.7681667436,100.0,8.333333333333333e-05,0.67,0.28,0.23,0.05,0.9,0.05,0.03,0.02
67.66845037530176,0.0057266597748932,252.550844125514,100.0,8.333333333333333e-05,0.67,0.28,0.23,0.05,0.9,0.05,0.03,0.02
71.35297037151896,0.0060337031079113,253.139145089947,100.0,8.333333333333333e-05,0.67,0.28,0.23,0.05,0.9,0.05,0.03,0.02
75.20073465436256,0.0063543501314816,253.565953087595,100.0,8.333333333333333e-05,0.67,0.28,0.23,0.05,0.9,0.05,0.03,0.02
79.30405222925097,0.0066962932627223,253.897887815523,100.0,8.333333333333333e-05,0.67,0.28,0.23,0.05,0.9,0.05,0.03,0.02
83.48366418577017,0.0070445942590989,254.189360061213,100.0,8.333333333333333e-05,0.67,0.28,0.23,0.05,0.9,0.05,0.03,0.02
87.72449251248416,0.0073979966196584,254.401929700921,100.0,8.333333333333333e-05,0.67,0.28,0.23,0.05,0.9,0.05,0.03,0.02
92.02146314901776,0.0077560775060362,254.606459244823,100.0,8.333333333333333e-05,0.67,0.28,0.23,0.05,0.9,0.05,0.03,0.02
96.33134808564895,0.0081152345840888,254.776090493365,100.0,8.333333333333333e-05,0.67,0.28,0.23,0.05,0.9,0.05,0.03,0.02
100.67300236486857,0.0084770391073571,255.033132911057,100.0,8.333333333333333e-05,0.67,0.28,0.23,0.05,0.9,0.05,0.03,0.02
105.09252356589175,0.0088453325407757,255.247697748749,100.0,8.333333333333333e-05,0.67,0.28,0.23,0.05,0.9,0.05,0.03,0.02
109.55198777545736,0.0092169545582395,255.454558414082,100.0,8.333333333333333e-05,0.67,0.28,0.23,0.05,0.9,0.05,0.03,0.02
114.01846918603376,0.0095891613424542,255.626899828962,100.0,8.333333333333333e-05,0.67,0.28,0.23,0.05,0.9,0.05,0.03,0.02
118.41594241058937,0.0099556174445005,255.768516112368,100.0,8.333333333333333e-05,0.67,0.28,0.23,0.05,0.9,0.05,0.03,0.02
122.85633131310776,0.0103256498530437,255.956365370859,100.0,8.333333333333333e-05,0.67,0.28,0.23,0.05,0.9,0.05,0.03,0.02
127.26975914539256,0.0106934355057341,256.187578666971,100.0,8.333333333333333e-05,0.67,0.28,0.23,0.05,0.9,0.05,0.03,0.02
131.78826618242337,0.01106997775882,256.436840508543,100.0,8.333333333333333e-05,0.67,0.28,0.23,0.05,0.9,0.05,0.03,0.02
136.2583752798918,0.0114424868502757,256.603727106235,100.0,8.333333333333333e-05,0.67,0.28,0.23,0.05,0.9,0.05,0.03,0.02
140.65789904039818,0.0118091138303179,256.676068163626,100.0,8.333333333333333e-05,0.67,0.28,0.23,0.05,0.9,0.05,0.03,0.02
145.06173020474697,0.0121760997606803,256.802255680521,100.0,8.333333333333333e-05,0.67,0.28,0.23,0.05,0.9,0.05,0.03,0.02
149.35891187827977,0.0125341982334747,256.940952834096,100.0,8.333333333333333e-05,0.67,0.28,0.23,0.05,0.9,0.05,0.03,0.02
153.76508781511376,0.0129013795615442,257.219068373759,100.0,8.333333333333333e-05,0.67,0.28,0.23,0.05,0.9,0.05,0.03,0.02
158.09444199495658,0.0132621590765311,257.412524481848,100.0,8.333333333333333e-05,0.67,0.28,0.23,0.05,0.9,0.05,0.03,0.02
162.54335579488858,0.0136329018931921,257.551756319376,100.0,8.333333333333333e-05,0.67,0.28,0.23,0.05,0.9,0.05,0.03,0.02
166.9573449793818,0.0140007343252332,257.710709185419,100.0,8.333333333333333e-05,0.67,0.28,0.23,0.05,0.9,0.05,0.03,0.02
171.3127607892918,0.0143636856427257,257.83228518965,100.0,8.333333333333333e-05,0.67,0.28,0.23,0.05,0.9,0.05,0.03,0.02
175.71279660966658,0.0147303552944236,258.055422624138,100.0,8.333333333333333e-05,0.67,0.28,0.23,0.05,0.9,0.05,0.03,0.02
180.14309223462058,0.0150995465965031,258.261161198224,100.0,8.333333333333333e-05,0.67,0.28,0.23,0.05,0.9,0.05,0.03,0.02
184.53034798861617,0.0154651512426694,258.428614006306,100.0,8.333333333333333e-05,0.67,0.28,0.23,0.05,0.9,0.05,0.03,0.02
188.8980524769186,0.0158291266166946,258.583535522068,100.0,8.333333333333333e-05,0.67,0.28,0.23,0.05,0.9,0.05,0.03,0.02
193.1275412513706,0.0161815840145656,258.72511118335,100.0,8.333333333333333e-05,0.67,0.28,0.23,0.05,0.9,0.05,0.03,0.02
197.56355889078057,0.0165512521511831,258.887949489056,100.0,8.333333333333333e-05,0.67,0.28,0.23,0.05,0.9,0.05,0.03,0.02
201.94307449170776,0.0169162117845937,259.057700626645,100.0,8.333333333333333e-05,0.67,0.28,0.23,0.05,0.9,0.05,0.03,0.02
206.30912589675415,0.0172800494016809,259.197532890162,100.0,8.333333333333333e-05,0.67,0.28,0.23,0.05,0.9,0.05,0.03,0.02
210.63688180601216,0.0176406957274524,259.369184124409,100.0,8.333333333333333e-05,0.67,0.28,0.23,0.05,0.9,0.05,0.03,0.02
214.9486604122722,0.0180000106113074,259.522512091849,100.0,8.333333333333333e-05,0.67,0.28,0.23,0.05,0.9,0.05,0.03,0.02
219.20830154945455,0.0183549807060726,259.719450582085,100.0,8.333333333333333e-05,0.67,0.28,0.23,0.05,0.9,0.05,0.03,0.02
223.46625235937935,0.018709809940233,259.832750667062,100.0,8.333333333333333e-05,0.67,0.28,0.23,0.05,0.9,0.05,0.03,0.02
227.70243308830135,0.0190628250009765,260.011427709517,100.0,8.333333333333333e-05,0.67,0.28,0.23,0.05,0.9,0.05,0.03,0.02
231.91909001316776,0.0194142130780487,260.162989089148,100.0,8.333333333333333e-05,0.67,0.28,0.23,0.05,0.9,0.05,0.03,0.02
236.13268349759576,0.0197653458684177,260.284874489061,100.0,8.333333333333333e-05,0.67,0.28,0.23,0.05,0.9,0.05,0.03,0.02
240.3579289595238,0.0201174496569117,260.429780816452,100.0,8.333333333333333e-05,0.67,0.28,0.23,0.05,0.9,0.05,0.03,0.02
244.58812943194133,0.0204699663629465,260.590281436015,100.0,8.333333333333333e-05,0.67,0.28,0.23,0.05,0.9,0.05,0.03,0.02
248.91106040755977,0.0208302106109147,260.758823068863,100.0,8.333333333333333e-05,0.67,0.28,0.23,0.05,0.9,0.05,0.03,0.02
253.1240330202102,0.0211812916619689,261.004637202624,100.0,8.333333333333333e-05,0.67,0.28,0.23,0.05,0.9,0.05,0.03,0.02
257.338889381625,0.0215325296920868,261.09351530815,100.0,8.333333333333333e-05,0.67,0.28,0.23,0.05,0.9,0.05,0.03,0.02
261.5772275876837,0.0218857245425917,261.265289705891,100.0,8.333333333333333e-05,0.67,0.28,0.23,0.05,0.9,0.05,0.03,0.02
265.8431650886886,0.0222412193343421,261.41879417709,100.0,8.333333333333333e-05,0.67,0.28,0.23,0.05,0.9,0.05,0.03,0.02
270.1201600374714,0.022597635580074,261.593529133533,100.0,8.333333333333333e-05,0.67,0.28,0.23,0.05,0.9,0.05,0.03,0.02
274.3467023387682,0.0229498474385154,261.771135985515,100.0,8.333333333333333e-05,0.67,0.28,0.23,0.05,0.9,0.05,0.03,0.02
278.623541447883,0.0233062506976083,261.91586644189,100.0,8.333333333333333e-05,0.67,0.28,0.23,0.05,0.9,0.05,0.03,0.02
282.8089677358518,0.0236550362216057,262.036266381866,100.0,8.333333333333333e-05,0.67,0.28,0.23,0.05,0.9,0.05,0.03,0.02
287.0566262774982,0.0240090077667429,262.175282817738,100.0,8.333333333333333e-05,0.67,0.28,0.23,0.05,0.9,0.05,0.03,0.02
291.2616541503138,0.0243594267561442,262.350385366433,100.0,8.333333333333333e-05,0.67,0.28,0.23,0.05,0.9,0.05,0.03,0.02
295.48056127670577,0.0247110023500102,262.566978494586,100.0,8.333333333333333e-05,0.67,0.28,0.23,0.05,0.9,0.05,0.03,0.02
299.734303844451,0.0250654808973223,262.742752083428,100.0,8.333333333333333e-05,0.67,0.28,0.23,0.05,0.9,0.05,0.03,0.02
304.0086084176946,0.0254216729450926,262.829397158561,100.0,8.333333333333333e-05,0.67,0.28,0.23,0.05,0.9,0.05,0.03,0.02
308.2012379737422,0.0257710587414299,262.888984783258,100.0,8.333333333333333e-05,0.67,0.28,0.23,0.05,0.9,0.05,0.03,0.02
312.43114103782136,0.0261235506634365,262.901414710093,100.0,8.333333333333333e-05,0.67,0.28,0.23,0.05,0.9,0.05,0.03,0.02
316.5892183041054,0.0264700571022935,263.026973090271,100.0,8.333333333333333e-05,0.67,0.28,0.23,0.05,0.9,0.05,0.03,0.02
320.7799846197774,0.0268192876285995,263.107840459281,100.0,8.333333333333333e-05,0.67,0.28,0.23,0.05,0.9,0.05,0.03,0.02
324.9333414052518,0.0271654006940557,263.227049750268,100.0,8.333333333333333e-05,0.67,0.28,0.23,0.05,0.9,0.05,0.03,0.02
329.0528889353754,0.027508696321566,263.391119975649,100.0,8.333333333333333e-05,0.67,0.28,0.23,0.05,0.9,0.05,0.03,0.02
333.10894062341816,0.0278467006289029,263.469788656413,100.0,8.333333333333333e-05,0.67,0.28,0.23,0.05,0.9,0.05,0.03,0.02
337.2069741812958,0.0281882034253927,263.644299099695,100.0,8.333333333333333e-05,0.67,0.28,0.23,0.05,0.9,0.05,0.03,0.02
341.3239154312298,0.0285312818628872,263.792939609451,100.0,8.333333333333333e-05,0.67,0.28,0.23,0.05,0.9,0.05,0.03,0.02
345.54027628679216,0.0288826452675174,263.961686614973,100.0,8.333333333333333e-05,0.67,0.28,0.23,0.05,0.9,0.05,0.03,0.02
349.7152313464602,0.0292305581891564,264.163927114877,100.0,8.333333333333333e-05,0.67,0.28,0.23,0.05,0.9,0.05,0.03,0.02
353.8989378902009,0.0295792004011348,264.254454007218,100.0,8.333333333333333e-05,0.67,0.28,0.23,0.05,0.9,0.05,0.03,0.02
358.0840747234746,0.0299279618039076,264.332147772839,100.0,8.333333333333333e-05,0.67,0.28,0.23,0.05,0.9,0.05,0.03,0.02
362.2240925449506,0.0302729632890306,264.442724071677,100.0,8.333333333333333e-05,0.67,0.28,0.23,0.05,0.9,0.05,0.03,0.02
366.4614563058426,0.0306260769357716,264.61219121823,100.0,8.333333333333333e-05,0.67,0.28,0.23,0.05,0.9,0.05,0.03,0.02
370.70940590986015,0.0309800727361064,264.750712484971,100.0,8.333333333333333e-05,0.67,0.28,0.23,0.05,0.9,0.05,0.03,0.02
375.00843277983176,0.0313383249752707,264.85045066525,100.0,8.333333333333333e-05,0.67,0.28,0.23,0.05,0.9,0.05,0.03,0.02
379.313222142993,0.0316970574222008,265.005072671944,100.0,8.333333333333333e-05,0.67,0.28,0.23,0.05,0.9,0.05,0.03,0.02
383.63154781303984,0.0320569178947047,265.11808848115,100.0,8.333333333333333e-05,0.67,0.28,0.23,0.05,0.9,0.05,0.03,0.02
387.9530924374974,0.0324170466134095,265.252171606906,100.0,8.333333333333333e-05,0.67,0.28,0.23,0.05,0.9,0.05,0.03,0.02
392.2124170200798,0.0327719903286247,265.264396335072,100.0,8.333333333333333e-05,0.67,0.28,0.23,0.05,0.9,0.05,0.03,0.02
396.5077927437918,0.0331299383056007,265.272851099236,100.0,8.333333333333333e-05,0.67,0.28,0.23,0.05,0.9,0.05,0.03,0.02
400.6492109942058,0.0334750564931352,265.305727684665,100.0,8.333333333333333e-05,0.67,0.28,0.23,0.05,0.9,0.05,0.03,0.02
404.8796004261845,0.0338275889458001,265.431077860642,100.0,8.333333333333333e-05,0.67,0.28,0.23,0.05,0.9,0.05,0.03,0.02
409.0811440403538,0.0341777175803142,265.638013347876,100.0,8.333333333333333e-05,0.67,0.28,0.23,0.05,0.9,0.05,0.03,0.02
413.2722252477966,0.0345269743476011,265.76925153296,100.0,8.333333333333333e-05,0.67,0.28,0.23,0.05,0.9,0.05,0.03,0.02
417.4805464746294,0.0348776677831705,265.907778146383,100.0,8.333333333333333e-05,0.67,0.28,0.23,0.05,0.9,0.05,0.03,0.02
421.65206901187264,0.0352252946612741,266.010804962793,100.0,8.333333333333333e-05,0.67,0.28,0.23,0.05,0.9,0.05,0.03,0.02
425.81083970285096,0.0355718588855223,266.142084418562,100.0,8.333333333333333e-05,0.67,0.28,0.23,0.05,0.9,0.05,0.03,0.02
430.0761910686006,0.0359273048326681,266.219291493814,100.0,8.333333333333333e-05,0.67,0.28,0.23,0.05,0.9,0.05,0.03,0.02
434.3105572067766,0.0362801686775161,266.33591251647,100.0,8.333333333333333e-05,0.67,0.28,0.23,0.05,0.9,0.05,0.03,0.02
438.54722070629697,0.0366332239691428,266.447740792947,100.0,8.333333333333333e-05,0.67,0.28,0.23,0.05,0.9,0.05,0.03,0.02
442.77193631822337,0.03698528360347,266.521795113702,100.0,8.333333333333333e-05,0.67,0.28,0.23,0.05,0.9,0.05,0.03,0.02
446.9639120593542,0.0373346149152309,266.617321074012,100.0,8.333333333333333e-05,0.67,0.28,0.23,0.05,0.9,0.05,0.03,0.02
451.0952126105778,0.0376788899611662,266.621843654597,100.0,8.333333333333333e-05,0.67,0.28,0.23,0.05,0.9,0.05,0.03,0.02
455.331108922833,0.0380318813205208,266.732813124337,100.0,8.333333333333333e-05,0.67,0.28,0.23,0.05,0.9,0.05,0.03,0.02
459.5704308534042,0.0383851581480684,266.862696400257,100.0,8.333333333333333e-05,0.67,0.28,0.23,0.05,0.9,0.05,0.03,0.02
463.88789973396655,0.0387449472214486,267.017735131725,100.0,8.333333333333333e-05,0.67,0.28,0.23,0.05,0.9,0.05,0.03,0.02
468.2139161218578,0.0391054485871062,267.136289865529,100.0,8.333333333333333e-05,0.67,0.28,0.23,0.05,0.9,0.05,0.03,0.02
472.50319501694577,0.0394628884950302,267.23911036015,100.0,8.333333333333333e-05,0.67,0.28,0.23,0.05,0.9,0.05,0.03,0.02
476.8122398105094,0.0398219755611605,267.280948458078,100.0,8.333333333333333e-05,0.67,0.28,0.23,0.05,0.9,0.05,0.03,0.02
481.0641676300686,0.0401763028794571,267.389008336594,100.0,8.333333333333333e-05,0.67,0.28,0.23,0.05,0.9,0.05,0.03,0.02
485.3455134514373,0.0405330816979045,267.483407618267,100.0,8.333333333333333e-05,0.67,0.28,0.23,0.05,0.9,0.05,0.03,0.02
489.62186498174935,0.0408894443254305,267.535701942502,100.0,8.333333333333333e-05,0.67,0.28,0.23,0.05,0.9,0.05,0.03,0.02
493.95250220994654,0.0412503307611136,267.61997260074,100.0,8.333333333333333e-05,0.67,0.28,0.23,0.05,0.9,0.05,0.03,0.02
498.2516511493098,0.0416085931727272,267.70935622075,100.0,8.333333333333333e-05,0.67,0.28,0.23,0.05,0.9,0.05,0.03,0.02
502.580817404919,0.0419693570273613,267.830082023555,100.0,8.333333333333333e-05,0.67,0.28,0.23,0.05,0.9,0.05,0.03,0.02
506.87237098008177,0.0423269864919582,267.899868427106,100.0,8.333333333333333e-05,0.67,0.28,0.23,0.05,0.9,0.05,0.03,0.02
511.1838841269534,0.0426862792541975,267.979552993145,100.0,8.333333333333333e-05,0.67,0.28,0.23,0.05,0.9,0.05,0.03,0.02
515.4911191236185,0.0430452155039196,268.022896782979,100.0,8.333333333333333e-05,0.67,0.28,0.23,0.05,0.9,0.05,0.03,0.02
519.8436434256665,0.0434079258624236,268.097154119439,100.0,8.333333333333333e-05,0.67,0.28,0.23,0.05,0.9,0.05,0.03,0.02
524.2150735591481,0.0437722117068804,268.164963516379,100.0,8.333333333333333e-05,0.67,0.28,0.23,0.05,0.9,0.05,0.03,0.02
528.4885840804769,0.0441283375836578,268.223774828254,100.0,8.333333333333333e-05,0.67,0.28,0.23,0.05,0.9,0.05,0.03,0.02
532.8291422119734,0.0444900507612825,268.286254580459,100.0,8.333333333333333e-05,0.67,0.28,0.23,0.05,0.9,0.05,0.03,0.02
537.1596080670317,0.0448509229158707,268.409627148717,100.0,8.333333333333333e-05,0.67,0.28,0.23,0.05,0.9,0.05,0.03,0.02
541.445101637307,0.0452080473800603,268.534014020391,100.0,8.333333333333333e-05,0.67,0.28,0.23,0.05,0.9,0.05,0.03,0.02
545.7904167169902,0.0455701569700339,268.682837946627,100.0,8.333333333333333e-05,0.67,0.28,0.23,0.05,0.9,0.05,0.03,0.02
550.0424109717256,0.0459244898245952,268.781028863761,100.0,8.333333333333333e-05,0.67,0.28,0.23,0.05,0.9,0.05,0.03,0.02
554.3869110994085,0.0462865315019021,268.843546596387,100.0,8.333333333333333e-05,0.67,0.28,0.23,0.05,0.9,0.05,0.03,0.02
558.6315164705501,0.0466402486161639,268.862139886419,100.0,8.333333333333333e-05,0.67,0.28,0.23,0.05,0.9,0.05,0.03,0.02
562.9252518028073,0.046998059893852,268.821291130183,100.0,8.333333333333333e-05,0.67,0.28,0.23,0.05,0.9,0.05,0.03,0.02
567.2429465058425,0.0473578677857716,268.835814630775,100.0,8.333333333333333e-05,0.67,0.28,0.23,0.05,0.9,0.05,0.03,0.02
571.580153786229,0.0477193017258038,268.944820128416,100.0,8.333333333333333e-05,0.67,0.28,0.23,0.05,0.9,0.05,0.03,0.02
575.9159041410342,0.0480806142553709,269.094813206186,100.0,8.333333333333333e-05,0.67,0.28,0.23,0.05,0.9,0.05,0.03,0.02
580.2589711555781,0.0484425365065829,269.258060675383,100.0,8.333333333333333e-05,0.67,0.28,0.23,0.05,0.9,0.05,0.03,0.02
584.5907363388833,0.048803516938525,269.375913934086,100.0,8.333333333333333e-05,0.67,0.28,0.23,0.05,0.9,0.05,0.03,0.02
589.0167968613498,0.0491723553153972,269.428109724362,100.0,8.333333333333333e-05,0.67,0.28,0.23,0.05,0.9,0.05,0.03,0.02
593.4564336134717,0.0495423250447407,269.449490660157,100.0,8.333333333333333e-05,0.67,0.28,0.23,0.05,0.9,0.05,0.03,0.02
597.8478695557253,0.0499082780399285,269.477877156372,100.0,8.333333333333333e-05,0.67,0.28,0.23,0.05,0.9,0.05,0.03,0.02
602.3063374741157,0.0502798170331277,269.504250563786,100.0,8.333333333333333e-05,0.67,0.28,0.23,0.05,0.9,0.05,0.03,0.02
606.7671925830978,0.0506515549588762,269.639333091853,100.0,8.333333333333333e-05,0.67,0.28,0.23,0.05,0.9,0.05,0.03,0.02
611.2600210034849,0.0510259573272418,269.691935103363,100.0,8.333333333333333e-05,0.67,0.28,0.23,0.05,0.9,0.05,0.03,0.02
615.7322872248521,0.0513986461790224,269.74131295529,100.0,8.333333333333333e-05,0.67,0.28,0.23,0.05,0.9,0.05,0.03,0.02
620.2115880640529,0.0517719212489558,269.746146323592,100.0,8.333333333333333e-05,0.67,0.28,0.23,0.05,0.9,0.05,0.03,0.02
624.6432373091466,0.0521412253527136,269.760956298739,100.0,8.333333333333333e-05,0.67,0.28,0.23,0.05,0.9,0.05,0.03,0.02
629.1295896327233,0.052515088046345,269.804213181273,100.0,8.333333333333333e-05,0.67,0.28,0.23,0.05,0.9,0.05,0.03,0.02
633.5689188008537,0.0528850321436892,269.891689301528,100.0,8.333333333333333e-05,0.67,0.28,0.23,0.05,0.9,0.05,0.03,0.02
638.0666037900198,0.0532598392261197,270.000101127716,100.0,8.333333333333333e-05,0.67,0.28,0.23,0.05,0.9,0.05,0.03,0.02
642.493123294389,0.0536287158514838,270.063366936991,100.0,8.333333333333333e-05,0.67,0.28,0.23,0.05,0.9,0.05,0.03,0.02
646.9686330574625,0.0540016749984066,270.077343525865,100.0,8.333333333333333e-05,0.67,0.28,0.23,0.05,0.9,0.05,0.03,0.02
651.4036997591874,0.054371263890217,270.059362272661,100.0,8.333333333333333e-05,0.67,0.28,0.23,0.05,0.9,0.05,0.03,0.02
655.869287965959,0.0547433962407813,270.125907258554,100.0,8.333333333333333e-05,0.67,0.28,0.23,0.05,0.9,0.05,0.03,0.02
660.2221818374729,0.0551061373967408,270.21900372166,100.0,8.333333333333333e-05,0.67,0.28,0.23,0.05,0.9,0.05,0.03,0.02
664.6709379352566,0.0554768670715561,270.319633990976,100.0,8.333333333333333e-05,0.67,0.28,0.23,0.05,0.9,0.05,0.03,0.02
669.097146467655,0.0558457177825893,270.402574511952,100.0,8.333333333333333e-05,0.67,0.28,0.23,0.05,0.9,0.05,0.03,0.02
673.6643634068106,0.0562263191941856,270.436821398028,100.0,8.333333333333333e-05,0.67,0.28,0.23,0.05,0.9,0.05,0.03,0.02
678.2323312513265,0.0566069831812286,270.484102718123,100.0,8.333333333333333e-05,0.67,0.28,0.23,0.05,0.9,0.05,0.03,0.02
682.8366225780761,0.0569906741251244,270.539255318096,100.0,8.333333333333333e-05,0.67,0.28,0.23,0.05,0.9,0.05,0.03,0.02
687.2897005603817,0.0573617639569832,270.560609741944,100.0,8.333333333333333e-05,0.67,0.28,0.23,0.05,0.9,0.05,0.03,0.02
691.8166228727154,0.057739007483011,270.587825488949,100.0,8.333333333333333e-05,0.67,0.28,0.23,0.05,0.9,0.05,0.03,0.02
696.334043376561,0.0581154591916648,270.656407576255,100.0,8.333333333333333e-05,0.67,0.28,0.23,0.05,0.9,0.05,0.03,0.02
700.9408844480981,0.0584993626142929,270.71700558136,100.0,8.333333333333333e-05,0.67,0.28,0.23,0.05,0.9,0.05,0.03,0.02
705.6208177927482,0.0588893570596804,270.767631835926,100.0,8.333333333333333e-05,0.67,0.28,0.23,0.05,0.9,0.05,0.03,0.02
710.2263325329258,0.0592731499546952,270.787388298068,100.0,8.333333333333333e-05,0.67,0.28,0.23,0.05,0.9,0.05,0.03,0.02
714.8495569951889,0.0596584186598838,270.816605206663,100.0,8.333333333333333e-05,0.67,0.28,0.23,0.05,0.9,0.05,0.03,0.02
719.5120544054178,0.0600469601107362,270.867992224383,100.0,8.333333333333333e-05,0.67,0.28,0.23,0.05,0.9,0.05,0.03,0.02
723.9951717856926,0.0604205532257591,270.874408336913,100.0,8.333333333333333e-05,0.67,0.28,0.23,0.05,0.9,0.05,0.03,0.02
728.5235058006846,0.0607979143936751,270.885692492082,100.0,8.333333333333333e-05,0.67,0.28,0.23,0.05,0.9,0.05,0.03,0.02
733.0820948363921,0.0611777968133174,270.904213459549,100.0,8.333333333333333e-05,0.67,0.28,0.23,0.05,0.9,0.05,0.03,0.02
737.636433156825,0.0615573250066868,270.938053839657,100.0,8.333333333333333e-05,0.67,0.28,0.23,0.05,0.9,0.05,0.03,0.02
742.291444522881,0.0619452426205248,270.989903234583,100.0,8.333333333333333e-05,0.67,0.28,0.23,0.05,0.9,0.05,0.03,0.02
746.8493550216833,0.062325068495425,271.018054998833,100.0,8.333333333333333e-05,0.67,0.28,0.23,0.05,0.9,0.05,0.03,0.02
751.3737797341997,0.0627021038881347,271.075765242359,100.0,8.333333333333333e-05,0.67,0.28,0.23,0.05,0.9,0.05,0.03,0.02
755.9351311101977,0.0630822165028012,271.119095538941,100.0,8.333333333333333e-05,0.67,0.28,0.23,0.05,0.9,0.05,0.03,0.02
760.5125519371051,0.0634636682383768,271.184893254932,100.0,8.333333333333333e-05,0.67,0.28,0.23,0.05,0.9,0.05,0.03,0.02
765.2084111673665,0.0638549898408986,271.196666441621,100.0,8.333333333333333e-05,0.67,0.28,0.23,0.05,0.9,0.05,0.03,0.02
769.8441725075634,0.064241303285915,271.247000874952,100.0,8.333333333333333e-05,0.67,0.28,0.23,0.05,0.9,0.05,0.03,0.02
774.5330497053258,0.0646320430523952,271.275049248937,100.0,8.333333333333333e-05,0.67,0.28,0.23,0.05,0.9,0.05,0.03,0.02
779.2353241974497,0.0650238992600722,271.339795630207,100.0,8.333333333333333e-05,0.67,0.28,0.23,0.05,0.9,0.05,0.03,0.02
783.9857838255942,0.0654197708957509,271.415986994187,100.0,8.333333333333333e-05,0.67,0.28,0.23,0.05,0.9,0.05,0.03,0.02
788.7334222931478,0.0658154074347137,271.455379143584,100.0,8.333333333333333e-05,0.67,0.28,0.23,0.05,0.9,0.05,0.03,0.02
793.4332496154917,0.0662070597115757,271.49037377412,100.0,8.333333333333333e-05,0.67,0.28,0.23,0.05,0.9,0.05,0.03,0.02
798.2379779284157,0.0666074537376527,271.483730332721,100.0,8.333333333333333e-05,0.67,0.28,0.23,0.05,0.9,0.05,0.03,0.02
802.9482814547368,0.0669999790315128,271.407266620181,100.0,8.333333333333333e-05,0.67,0.28,0.23,0.05,0.9,0.05,0.03,0.02
807.6690121659773,0.0673933732574495,271.330223520371,100.0,8.333333333333333e-05,0.67,0.28,0.23,0.05,0.9,0.05,0.03,0.02
812.3699123070413,0.0677851149358715,271.30411336583,100.0,8.333333333333333e-05,0.67,0.28,0.23,0.05,0.9,0.05,0.03,0.02
817.0742941570205,0.0681771467567031,271.327566852484,100.0,8.333333333333333e-05,0.67,0.28,0.23,0.05,0.9,0.05,0.03,0.02
821.7969327225522,0.0685706999704974,271.407337218521,100.0,8.333333333333333e-05,0.67,0.28,0.23,0.05,0.9,0.05,0.03,0.02
826.5385834254258,0.0689658375290702,271.417073303798,100.0,8.333333333333333e-05,0.67,0.28,0.23,0.05,0.9,0.05,0.03,0.02
831.2689472379378,0.0693600345134462,271.45605375873,100.0,8.333333333333333e-05,0.67,0.28,0.23,0.05,0.9,0.05,0.03,0.02
835.978440948213,0.0697524923226358,271.443525614308,100.0,8.333333333333333e-05,0.67,0.28,0.23,0.05,0.9,0.05,0.03,0.02
840.675137695101,0.0701438837182098,271.438806930738,100.0,8.333333333333333e-05,0.67,0.28,0.23,0.05,0.9,0.05,0.03,0.02
845.350612614693,0.0705335066281758,271.452400535878,100.0,8.333333333333333e-05,0.67,0.28,0.23,0.05,0.9,0.05,0.03,0.02
850.1431234517393,0.070932882531263,271.444161521379,100.0,8.333333333333333e-05,0.67,0.28,0.23,0.05,0.9,0.05,0.03,0.02
854.8848589077413,0.0713280271525965,271.496271353471,100.0,8.333333333333333e-05,0.67,0.28,0.23,0.05,0.9,0.05,0.03,0.02
859.7103798642377,0.0717301538989712,271.549325365197,100.0,8.333333333333333e-05,0.67,0.28,0.23,0.05,0.9,0.05,0.03,0.02
864.5940173423586,0.0721371236888146,271.611353117186,100.0,8.333333333333333e-05,0.67,0.28,0.23,0.05,0.9,0.05,0.03,0.02
869.4518749835106,0.0725419451589106,271.657851543928,100.0,8.333333333333333e-05,0.67,0.28,0.23,0.05,0.9,0.05,0.03,0.02