File: datasets/al_6061_comp/csv/T_100_A_3.csv
Time,Strain(%),Stress(MPa),Temp(C),SR(%/s),Si(%),Fe(%),Cu(%),Mn(%),Mg(%),Cr(%),Zn(%),Ti(%)
0.0,8.57809057752141e-05,5.43611008844988,100.0,8.333333333333333e-05,0.56,0.23,0.18,0.07,0.86,0.06,0.02,0.01
0.0839098203500243,9.27733908043828e-05,7.54211315903313,100.0,8.333333333333333e-05,0.56,0.23,0.18,0.07,0.86,0.06,0.02,0.01
0.1473950208503962,9.80638241794138e-05,9.86922633812785,100.0,8.333333333333333e-05,0.56,0.23,0.18,0.07,0.86,0.06,0.02,0.01
0.3371633339122306,0.0001138778502679,12.2485083229864,100.0,8.333333333333333e-05,0.56,0.23,0.18,0.07,0.86,0.06,0.02,0.01
0.6271264650730306,0.0001380414445313,14.7673744910801,100.0,8.333333333333333e-05,0.56,0.23,0.18,0.07,0.86,0.06,0.02,0.01
0.7344994026754308,0.0001469891893315,17.3486292774302,100.0,8.333333333333333e-05,0.56,0.23,0.18,0.07,0.86,0.06,0.02,0.01
0.7922744702038307,0.0001518037782922,19.9816491068734,100.0,8.333333333333333e-05,0.56,0.23,0.18,0.07,0.86,0.06,0.02,0.01
0.9162061309786308,0.0001621314166901,22.5800967616731,100.0,8.333333333333333e-05,0.56,0.23,0.18,0.07,0.86,0.06,0.02,0.01
1.1707321837198308,0.0001833419210852,25.3179409665392,100.0,8.333333333333333e-05,0.56,0.23,0.18,0.07,0.86,0.06,0.02,0.01
1.5193571296498305,0.0002123939999127,28.1100335148517,100.0,8.333333333333333e-05,0.56,0.23,0.18,0.07,0.86,0.06,0.02,0.01
1.861693622165831,0.0002409220409557,30.9680555931326,100.0,8.333333333333333e-05,0.56,0.23,0.18,0.07,0.86,0.06,0.02,0.01
2.051958737005031,0.0002567774671923,33.8651854639563,100.0,8.333333333333333e-05,0.56,0.23,0.18,0.07,0.86,0.06,0.02,0.01
2.509423858456631,0.0002948995606466,36.8408148008536,100.0,8.333333333333333e-05,0.56,0.23,0.18,0.07,0.86,0.06,0.02,0.01
2.8975915255054305,0.000327246866234,39.8498920480483,100.0,8.333333333333333e-05,0.56,0.23,0.18,0.07,0.86,0.06,0.02,0.01
3.3078119749630304,0.0003614319036888,42.863381816737,100.0,8.333333333333333e-05,0.56,0.23,0.18,0.07,0.86,0.06,0.02,0.01
3.8272771169158313,0.0004047206655182,45.8879484364465,100.0,8.333333333333333e-05,0.56,0.23,0.18,0.07,0.86,0.06,0.02,0.01
4.3258473860602304,0.0004462681879469,48.9404803139532,100.0,8.333333333333333e-05,0.56,0.23,0.18,0.07,0.86,0.06,0.02,0.01
4.838684703376631,0.0004890046310566,52.0041505422202,100.0,8.333333333333333e-05,0.56,0.23,0.18,0.07,0.86,0.06,0.02,0.01
5.522890499229431,0.000546021780711,55.0641228220095,100.0,8.333333333333333e-05,0.56,0.23,0.18,0.07,0.86,0.06,0.02,0.01
6.083731816897031,0.0005927585571833,58.1179818144609,100.0,8.333333333333333e-05,0.56,0.23,0.18,0.07,0.86,0.06,0.02,0.01
6.689646634960631,0.0006432514586886,61.1999430538849,100.0,8.333333333333333e-05,0.56,0.23,0.18,0.07,0.86,0.06,0.02,0.01
7.294175610607031,0.0006936288733258,64.3099485460434,100.0,8.333333333333333e-05,0.56,0.23,0.18,0.07,0.86,0.06,0.02,0.01
7.8837873376378305,0.0007427631839117,67.4566799314588,100.0,8.333333333333333e-05,0.56,0.23,0.18,0.07,0.86,0.06,0.02,0.01
8.46156127136743,0.0007909110117225,70.5869880271185,100.0,8.333333333333333e-05,0.56,0.23,0.18,0.07,0.86,0.06,0.02,0.01
8.952944000629032,0.0008318595724943,73.6898272407343,100.0,8.333333333333333e-05,0.56,0.23,0.18,0.07,0.86,0.06,0.02,0.01
9.377282143282631,0.0008672210843821,76.786453171376,100.0,8.333333333333333e-05,0.56,0.23,0.18,0.07,0.86,0.06,0.02,0.01
9.82859823623623,0.0009048307587949,79.9012621211185,100.0,8.333333333333333e-05,0.56,0.23,0.18,0.07,0.86,0.06,0.02,0.01
10.451331956547431,0.0009567252354875,82.9934292318019,100.0,8.333333333333333e-05,0.56,0.23,0.18,0.07,0.86,0.06,0.02,0.01
11.08673963553223,0.0010096758754029,86.0830832372935,100.0,8.333333333333333e-05,0.56,0.23,0.18,0.07,0.86,0.06,0.02,0.01
11.651462941251433,0.0010567361508795,89.1364168568723,100.0,8.333333333333333e-05,0.56,0.23,0.18,0.07,0.86,0.06,0.02,0.01
12.298642243574232,0.0011106677594064,92.2090226887308,100.0,8.333333333333333e-05,0.56,0.23,0.18,0.07,0.86,0.06,0.02,0.01
12.790691123374632,0.0011516718327231,95.3088841647658,100.0,8.333333333333333e-05,0.56,0.23,0.18,0.07,0.86,0.06,0.02,0.01
13.432352100247032,0.0012051435807958,98.4052351639482,100.0,8.333333333333333e-05,0.56,0.23,0.18,0.07,0.86,0.06,0.02,0.01
14.22218211902983,0.0012709627490277,101.47332418161,100.0,8.333333333333333e-05,0.56,0.23,0.18,0.07,0.86,0.06,0.02,0.01
14.806853328616633,0.0013196853498266,104.558597861295,100.0,8.333333333333333e-05,0.56,0.23,0.18,0.07,0.86,0.06,0.02,0.01
15.38428742864143,0.001367804858162,107.646446000521,100.0,8.333333333333333e-05,0.56,0.23,0.18,0.07,0.86,0.06,0.02,0.01
15.981608745915432,0.0014175816346015,110.723475274237,100.0,8.333333333333333e-05,0.56,0.23,0.18,0.07,0.86,0.06,0.02,0.01
16.573838597487434,0.0014669341222325,113.780391645382,100.0,8.333333333333333e-05,0.56,0.23,0.18,0.07,0.86,0.06,0.02,0.01
17.461625101762635,0.0015409163309221,116.792685198099,100.0,8.333333333333333e-05,0.56,0.23,0.18,0.07,0.86,0.06,0.02,0.01
18.042320646566235,0.0015893076263224,119.819653538523,100.0,8.333333333333333e-05,0.56,0.23,0.18,0.07,0.86,0.06,0.02,0.01
18.553221594501437,0.001631882705317,122.846437298957,100.0,8.333333333333333e-05,0.56,0.23,0.18,0.07,0.86,0.06,0.02,0.01
19.183714974093437,0.001684423820283,125.830816706347,100.0,8.333333333333333e-05,0.56,0.23,0.18,0.07,0.86,0.06,0.02,0.01
19.753954143487032,0.0017319437510658,128.816247974135,100.0,8.333333333333333e-05,0.56,0.23,0.18,0.07,0.86,0.06,0.02,0.01
20.325765370759036,0.0017795946866718,131.781968664282,100.0,8.333333333333333e-05,0.56,0.23,0.18,0.07,0.86,0.06,0.02,0.01
20.876392244895435,0.0018254802595165,134.719372076453,100.0,8.333333333333333e-05,0.56,0.23,0.18,0.07,0.86,0.06,0.02,0.01
21.303829271396232,0.0018611000117249,137.672564153408,100.0,8.333333333333333e-05,0.56,0.23,0.18,0.07,0.86,0.06,0.02,0.01
21.889559518871835,0.0019099108656812,140.607922178264,100.0,8.333333333333333e-05,0.56,0.23,0.18,0.07,0.86,0.06,0.02,0.01
22.480922139467832,0.0019591910840642,143.515838234279,100.0,8.333333333333333e-05,0.56,0.23,0.18,0.07,0.86,0.06,0.02,0.01
22.99039918261183,0.0020016475043262,146.407084242324,100.0,8.333333333333333e-05,0.56,0.23,0.18,0.07,0.86,0.06,0.02,0.01
23.654437970939835,0.0020569840700202,149.277186471946,100.0,8.333333333333333e-05,0.56,0.23,0.18,0.07,0.86,0.06,0.02,0.01
24.30396378011743,0.002111111220785,152.107179676466,100.0,8.333333333333333e-05,0.56,0.23,0.18,0.07,0.86,0.06,0.02,0.01
24.845485261563432,0.0021562380109055,154.923301127701,100.0,8.333333333333333e-05,0.56,0.23,0.18,0.07,0.86,0.06,0.02,0.01
25.439609962234638,0.0022057484026281,157.721897915595,100.0,8.333333333333333e-05,0.56,0.23,0.18,0.07,0.86,0.06,0.02,0.01
26.048382213004636,0.0022564794235256,160.511187856003,100.0,8.333333333333333e-05,0.56,0.23,0.18,0.07,0.86,0.06,0.02,0.01
26.660133158233037,0.0023074586689613,163.292549644815,100.0,8.333333333333333e-05,0.56,0.23,0.18,0.07,0.86,0.06,0.02,0.01
27.27839237839784,0.0023589802706417,166.061810152352,100.0,8.333333333333333e-05,0.56,0.23,0.18,0.07,0.86,0.06,0.02,0.01
27.811586755952234,0.0024034131354379,168.825512857196,100.0,8.333333333333333e-05,0.56,0.23,0.18,0.07,0.86,0.06,0.02,0.01
28.42835063057263,0.0024548101249896,171.561594134149,100.0,8.333333333333333e-05,0.56,0.23,0.18,0.07,0.86,0.06,0.02,0.01
29.026762117336634,0.0025046777488866,174.299448597049,100.0,8.333333333333333e-05,0.56,0.23,0.18,0.07,0.86,0.06,0.02,0.01
29.668655722480636,0.0025581688826486,176.979439785403,100.0,8.333333333333333e-05,0.56,0.23,0.18,0.07,0.86,0.06,0.02,0.01
30.269938754723835,0.0026082758020022,179.617083161058,100.0,8.333333333333333e-05,0.56,0.23,0.18,0.07,0.86,0.06,0.02,0.01
30.685147108113437,0.002642876498118,182.218888908407,100.0,8.333333333333333e-05,0.56,0.23,0.18,0.07,0.86,0.06,0.02,0.01
31.371544103577435,0.00270007624774,184.814327728436,100.0,8.333333333333333e-05,0.56,0.23,0.18,0.07,0.86,0.06,0.02,0.01
32.01904493984743,0.0027540346507625,187.35248471866,100.0,8.333333333333333e-05,0.56,0.23,0.18,0.07,0.86,0.06,0.02,0.01
32.50907640460424,0.0027948706061589,189.886496590906,100.0,8.333333333333333e-05,0.56,0.23,0.18,0.07,0.86,0.06,0.02,0.01
33.091861084388235,0.0028434359961409,192.389881431368,100.0,8.333333333333333e-05,0.56,0.23,0.18,0.07,0.86,0.06,0.02,0.01
33.633320381578635,0.0028885576042401,194.876580990276,100.0,8.333333333333333e-05,0.56,0.23,0.18,0.07,0.86,0.06,0.02,0.01
34.23289032707023,0.0029385217663644,197.379186817884,100.0,8.333333333333333e-05,0.56,0.23,0.18,0.07,0.86,0.06,0.02,0.01
35.09279304087343,0.003010180325848,199.853993390144,100.0,8.333333333333333e-05,0.56,0.23,0.18,0.07,0.86,0.06,0.02,0.01
35.67828878413304,0.0030589716377863,202.276350264213,100.0,8.333333333333333e-05,0.56,0.23,0.18,0.07,0.86,0.06,0.02,0.01
36.32059207810903,0.0031124969122843,204.673168462796,100.0,8.333333333333333e-05,0.56,0.23,0.18,0.07,0.86,0.06,0.02,0.01
37.01134980046543,0.003170060055814,207.047005612567,100.0,8.333333333333333e-05,0.56,0.23,0.18,0.07,0.86,0.06,0.02,0.01
37.74334751317903,0.0032310598652068,209.353289846025,100.0,8.333333333333333e-05,0.56,0.23,0.18,0.07,0.86,0.06,0.02,0.01
38.38536574639063,0.0032845613846411,211.633421117396,100.0,8.333333333333333e-05,0.56,0.23,0.18,0.07,0.86,0.06,0.02,0.01
39.31431989755544,0.0033619742305715,213.848238114663,100.0,8.333333333333333e-05,0.56,0.23,0.18,0.07,0.86,0.06,0.02,0.01
39.94784480965183,0.0034147679732462,216.052396287901,100.0,8.333333333333333e-05,0.56,0.23,0.18,0.07,0.86,0.06,0.02,0.01
40.61153517769663,0.0034700755039166,218.241498187656,100.0,8.333333333333333e-05,0.56,0.23,0.18,0.07,0.86,0.06,0.02,0.01
41.29648207359223,0.0035271544119079,220.351356695805,100.0,8.333333333333333e-05,0.56,0.23,0.18,0.07,0.86,0.06,0.02,0.01
42.05783409795704,0.0035906004139383,222.427340785614,100.0,8.333333333333333e-05,0.56,0.23,0.18,0.07,0.86,0.06,0.02,0.01
42.89342736436424,0.0036602331861389,224.470618790587,100.0,8.333333333333333e-05,0.56,0.23,0.18,0.07,0.86,0.06,0.02,0.01
43.78506435174104,0.0037345362684203,226.463495392474,100.0,8.333333333333333e-05,0.56,0.23,0.18,0.07,0.86,0.06,0.02,0.01
44.50988527968224,0.0037949380124154,228.364984690062,100.0,8.333333333333333e-05,0.56,0.23,0.18,0.07,0.86,0.06,0.02,0.01
45.48685662415663,0.0038763522911216,230.200051619738,100.0,8.333333333333333e-05,0.56,0.23,0.18,0.07,0.86,0.06,0.02,0.01
46.59368492600744,0.0039685879829425,231.922051205763,100.0,8.333333333333333e-05,0.56,0.23,0.18,0.07,0.86,0.06,0.02,0.01
47.77592645192624,0.0040671081101024,233.520226405454,100.0,8.333333333333333e-05,0.56,0.23,0.18,0.07,0.86,0.06,0.02,0.01
49.17749618492744,0.0041839055878525,234.932417265858,100.0,8.333333333333333e-05,0.56,0.23,0.18,0.07,0.86,0.06,0.02,0.01
50.67355499026303,0.0043085771549638,236.188206809392,100.0,8.333333333333333e-05,0.56,0.23,0.18,0.07,0.86,0.06,0.02,0.01
52.34565518957623,0.0044479188382399,237.252712971867,100.0,8.333333333333333e-05,0.56,0.23,0.18,0.07,0.86,0.06,0.02,0.01
54.07178246733703,0.0045917627780533,238.150673801348,100.0,8.333333333333333e-05,0.56,0.23,0.18,0.07,0.86,0.06,0.02,0.01
55.92286805841943,0.0047460199106435,238.831986233911,100.0,8.333333333333333e-05,0.56,0.23,0.18,0.07,0.86,0.06,0.02,0.01
57.97914543748544,0.004917376358899,239.336265164363,100.0,8.333333333333333e-05,0.56,0.23,0.18,0.07,0.86,0.06,0.02,0.01
60.11628043866343,0.0050954709423305,239.729123690601,100.0,8.333333333333333e-05,0.56,0.23,0.18,0.07,0.86,0.06,0.02,0.01
62.20321733260423,0.0052693823501589,240.020603264564,100.0,8.333333333333333e-05,0.56,0.23,0.18,0.07,0.86,0.06,0.02,0.01
64.33549941272624,0.0054470725235024,240.233036530405,100.0,8.333333333333333e-05,0.56,0.23,0.18,0.07,0.86,0.06,0.02,0.01
66.45323677397742,0.00562355063694,240.397657585499,100.0,8.333333333333333e-05,0.56,0.23,0.18,0.07,0.86,0.06,0.02,0.01
68.59633674958184,0.0058021423015737,240.526691760635,100.0,8.333333333333333e-05,0.56,0.23,0.18,0.07,0.86,0.06,0.02,0.01
70.98907485899143,0.0060015371440245,240.637791581101,100.0,8.333333333333333e-05,0.56,0.23,0.18,0.07,0.86,0.06,0.02,0.01
73.19185698189943,0.0061851023209335,240.750195448052,100.0,8.333333333333333e-05,0.56,0.23,0.18,0.07,0.86,0.06,0.02,0.01
75.47824344614143,0.006375634526287,240.846338312187,100.0,8.333333333333333e-05,0.56,0.23,0.18,0.07,0.86,0.06,0.02,0.01
77.82541505328584,0.0065712321602157,240.927194008231,100.0,8.333333333333333e-05,0.56,0.23,0.18,0.07,0.86,0.06,0.02,0.01
80.12204239739263,0.0067626177722246,240.990067290312,100.0,8.333333333333333e-05,0.56,0.23,0.18,0.07,0.86,0.06,0.02,0.01
82.51037124583303,0.0069616451762613,241.079109252697,100.0,8.333333333333333e-05,0.56,0.23,0.18,0.07,0.86,0.06,0.02,0.01
84.94020456075704,0.0071641312858383,241.153782762955,100.0,8.333333333333333e-05,0.56,0.23,0.18,0.07,0.86,0.06,0.02,0.01
87.14312234212423,0.0073477077676189,241.211249802772,100.0,8.333333333333333e-05,0.56,0.23,0.18,0.07,0.86,0.06,0.02,0.01
89.46429692047784,0.0075411389824817,241.242693180191,100.0,8.333333333333333e-05,0.56,0.23,0.18,0.07,0.86,0.06,0.02,0.01
91.80571106306384,0.0077362568276972,241.307463180793,100.0,8.333333333333333e-05,0.56,0.23,0.18,0.07,0.86,0.06,0.02,0.01
94.11190676962782,0.0079284398032442,241.403087569978,100.0,8.333333333333333e-05,0.56,0.23,0.18,0.07,0.86,0.06,0.02,0.01
96.43228727699862,0.0081218048455251,241.498996987112,100.0,8.333333333333333e-05,0.56,0.23,0.18,0.07,0.86,0.06,0.02,0.01
98.70596081272664,0.0083112776401691,241.555988183397,100.0,8.333333333333333e-05,0.56,0.23,0.18,0.07,0.86,0.06,0.02,0.01
100.97302402019024,0.0085001995741244,241.612861614225,100.0,8.333333333333333e-05,0.56,0.23,0.18,0.07,0.86,0.06,0.02,0.01
103.29103623699343,0.008693367258858,241.680568336427,100.0,8.333333333333333e-05,0.56,0.23,0.18,0.07,0.86,0.06,0.02,0.01
105.56884625158784,0.0088831847600742,241.797525881878,100.0,8.333333333333333e-05,0.56,0.23,0.18,0.07,0.86,0.06,0.02,0.01
107.70448076966863,0.0090611543032476,241.840436707166,100.0,8.333333333333333e-05,0.56,0.23,0.18,0.07,0.86,0.06,0.02,0.01
109.93389257054744,0.0092469386199875,241.897002186973,100.0,8.333333333333333e-05,0.56,0.23,0.18,0.07,0.86,0.06,0.02,0.01
112.13509619268945,0.009430372255166,241.951773496289,100.0,8.333333333333333e-05,0.56,0.23,0.18,0.07,0.86,0.06,0.02,0.01
114.40593322401584,0.0096196086744432,242.035591082463,100.0,8.333333333333333e-05,0.56,0.23,0.18,0.07,0.86,0.06,0.02,0.01
116.63539878504582,0.0098053974711957,242.127026122967,100.0,8.333333333333333e-05,0.56,0.23,0.18,0.07,0.86,0.06,0.02,0.01
118.88377345462784,0.0099927620269942,242.207338514771,100.0,8.333333333333333e-05,0.56,0.23,0.18,0.07,0.86,0.06,0.02,0.01
121.10864261375744,0.010178167790255,242.253230922383,100.0,8.333333333333333e-05,0.56,0.23,0.18,0.07,0.86,0.06,0.02,0.01
123.42635569597785,0.0103713105471067,242.367415810157,100.0,8.333333333333333e-05,0.56,0.23,0.18,0.07,0.86,0.06,0.02,0.01
125.71687808985104,0.0105621874132628,242.476226683662,100.0,8.333333333333333e-05,0.56,0.23,0.18,0.07,0.86,0.06,0.02,0.01
128.01366282163784,0.0107535861409117,242.604258026955,100.0,8.333333333333333e-05,0.56,0.23,0.18,0.07,0.86,0.06,0.02,0.01
130.29866090765384,0.0109440026480797,242.704535751035,100.0,8.333333333333333e-05,0.56,0.23,0.18,0.07,0.86,0.06,0.02,0.01
132.54879938536305,0.0111315141878888,242.785874543928,100.0,8.333333333333333e-05,0.56,0.23,0.18,0.07,0.86,0.06,0.02,0.01
134.72102286847664,0.0113125328114816,242.87360926126,100.0,8.333333333333333e-05,0.56,0.23,0.18,0.07,0.86,0.06,0.02,0.01
136.99621085089186,0.0115021318100162,242.954179283179,100.0,8.333333333333333e-05,0.56,0.23,0.18,0.07,0.86,0.06,0.02,0.01
139.24787886500624,0.0116897708111924,243.01756753471,100.0,8.333333333333333e-05,0.56,0.23,0.18,0.07,0.86,0.06,0.02,0.01
141.54088360766505,0.0118808545397473,243.056647283242,100.0,8.333333333333333e-05,0.56,0.23,0.18,0.07,0.86,0.06,0.02,0.01
143.80358795863904,0.0120694132356618,243.124423857001,100.0,8.333333333333333e-05,0.56,0.23,0.18,0.07,0.86,0.06,0.02,0.01
146.01032673286304,0.0122533081335138,243.193703483098,100.0,8.333333333333333e-05,0.56,0.23,0.18,0.07,0.86,0.06,0.02,0.01
148.23520966358984,0.0124387150444077,243.29956656925,100.0,8.333333333333333e-05,0.56,0.23,0.18,0.07,0.86,0.06,0.02,0.01
150.54383667849345,0.012631100628983,243.379863420538,100.0,8.333333333333333e-05,0.56,0.23,0.18,0.07,0.86,0.06,0.02,0.01
152.79602190283543,0.0128187827310115,243.466477055937,100.0,8.333333333333333e-05,0.56,0.23,0.18,0.07,0.86,0.06,0.02,0.01
154.96931038548345,0.0129998901045655,243.529020433191,100.0,8.333333333333333e-05,0.56,0.23,0.18,0.07,0.86,0.06,0.02,0.01
157.09466222299184,0.0131770027576912,243.597010907146,100.0,8.333333333333333e-05,0.56,0.23,0.18,0.07,0.86,0.06,0.02,0.01
159.22688462352224,0.0133546879577354,243.632845659971,100.0,8.333333333333333e-05,0.56,0.23,0.18,0.07,0.86,0.06,0.02,0.01
161.31954868068465,0.0135290766291656,243.684582513664,100.0,8.333333333333333e-05,0.56,0.23,0.18,0.07,0.86,0.06,0.02,0.01
163.48368663221262,0.0137094214584596,243.716853916338,100.0,8.333333333333333e-05,0.56,0.23,0.18,0.07,0.86,0.06,0.02,0.01
165.53579424044383,0.0138804304258122,243.788519254156,100.0,8.333333333333333e-05,0.56,0.23,0.18,0.07,0.86,0.06,0.02,0.01
167.65962572886946,0.014057416383181,243.879362284953,100.0,8.333333333333333e-05,0.56,0.23,0.18,0.07,0.86,0.06,0.02,0.01
169.86621411788386,0.0142412987489322,243.978993688288,100.0,8.333333333333333e-05,0.56,0.23,0.18,0.07,0.86,0.06,0.02,0.01
172.04437994379583,0.0144228125677582,244.019854942275,100.0,8.333333333333333e-05,0.56,0.23,0.18,0.07,0.86,0.06,0.02,0.01
174.27243118723905,0.0146084835047118,244.133697276338,100.0,8.333333333333333e-05,0.56,0.23,0.18,0.07,0.86,0.06,0.02,0.01
176.46773007183705,0.0147914250784283,244.24192156801,100.0,8.333333333333333e-05,0.56,0.23,0.18,0.07,0.86,0.06,0.02,0.01
178.66425769602105,0.0149744690471103,244.334401102513,100.0,8.333333333333333e-05,0.56,0.23,0.18,0.07,0.86,0.06,0.02,0.01
180.91530919624665,0.0151620566721291,244.417239393781,100.0,8.333333333333333e-05,0.56,0.23,0.18,0.07,0.86,0.06,0.02,0.01
183.11837859007545,0.0153456457882815,244.488776061932,100.0,8.333333333333333e-05,0.56,0.23,0.18,0.07,0.86,0.06,0.02,0.01
185.25494056864184,0.0155236926198287,244.549138015804,100.0,8.333333333333333e-05,0.56,0.23,0.18,0.07,0.86,0.06,0.02,0.01
187.35642686733945,0.0156988164780535,244.689549432729,100.0,8.333333333333333e-05,0.56,0.23,0.18,0.07,0.86,0.06,0.02,0.01
189.44120154106423,0.0158725477008639,244.747658819313,100.0,8.333333333333333e-05,0.56,0.23,0.18,0.07,0.86,0.06,0.02,0.01
191.58945661321903,0.0160515689568768,244.798086974059,100.0,8.333333333333333e-05,0.56,0.23,0.18,0.07,0.86,0.06,0.02,0.01
193.66953794991943,0.0162249090682685,244.862023343835,100.0,8.333333333333333e-05,0.56,0.23,0.18,0.07,0.86,0.06,0.02,0.01
195.56378256766183,0.0163827627864137,244.907667087016,100.0,8.333333333333333e-05,0.56,0.23,0.18,0.07,0.86,0.06,0.02,0.01
197.64823966319383,0.0165564675443747,244.963653205999,100.0,8.333333333333333e-05,0.56,0.23,0.18,0.07,0.86,0.06,0.02,0.01
199.72720478844943,0.016729714638146,245.044315194826,100.0,8.333333333333333e-05,0.56,0.23,0.18,0.07,0.86,0.06,0.02,0.01
201.8086399147186,0.0169031675653351,245.111973211561,100.0,8.333333333333333e-05,0.56,0.23,0.18,0.07,0.86,0.06,0.02,0.01
203.85460600007025,0.0170736647391144,245.185325697077,100.0,8.333333333333333e-05,0.56,0.23,0.18,0.07,0.86,0.06,0.02,0.01
205.95483030949663,0.0172486834315666,245.256303682015,100.0,8.333333333333333e-05,0.56,0.23,0.18,0.07,0.86,0.06,0.02,0.01
208.15536001030185,0.0174320609066337,245.330907340718,100.0,8.333333333333333e-05,0.56,0.23,0.18,0.07,0.86,0.06,0.02,0.01
210.37142439090945,0.017616732938351,245.432484006496,100.0,8.333333333333333e-05,0.56,0.23,0.18,0.07,0.86,0.06,0.02,0.01
212.42859135681465,0.0177881635188431,245.510837194624,100.0,8.333333333333333e-05,0.56,0.23,0.18,0.07,0.86,0.06,0.02,0.01
214.53137202285103,0.0179633952410128,245.613886623272,100.0,8.333333333333333e-05,0.56,0.23,0.18,0.07,0.86,0.06,0.02,0.01
216.61833981300467,0.0181373092235256,245.722759981934,100.0,8.333333333333333e-05,0.56,0.23,0.18,0.07,0.86,0.06,0.02,0.01
218.75487449939143,0.0183153537807245,245.82257515754,100.0,8.333333333333333e-05,0.56,0.23,0.18,0.07,0.86,0.06,0.02,0.01
220.82095435462185,0.0184875271019937,245.920877830491,100.0,8.333333333333333e-05,0.56,0.23,0.18,0.07,0.86,0.06,0.02,0.01
222.81352901673583,0.0186535749905032,246.008275260442,100.0,8.333333333333333e-05,0.56,0.23,0.18,0.07,0.86,0.06,0.02,0.01
224.9435283819946,0.0188310749376081,246.096039281826,100.0,8.333333333333333e-05,0.56,0.23,0.18,0.07,0.86,0.06,0.02,0.01
227.07219863200905,0.0190084641251093,246.184303846795,100.0,8.333333333333333e-05,0.56,0.23,0.18,0.07,0.86,0.06,0.02,0.01
229.12756978917105,0.0191797450548728,246.252199946839,100.0,8.333333333333333e-05,0.56,0.23,0.18,0.07,0.86,0.06,0.02,0.01
231.21657146971305,0.0193538285282513,246.325033456619,100.0,8.333333333333333e-05,0.56,0.23,0.18,0.07,0.86,0.06,0.02,0.01
233.25153639758383,0.0195234089389072,246.380623809352,100.0,8.333333333333333e-05,0.56,0.23,0.18,0.07,0.86,0.06,0.02,0.01
235.33868935962823,0.0196973383524109,246.448113739723,100.0,8.333333333333333e-05,0.56,0.23,0.18,0.07,0.86,0.06,0.02,0.01
237.39805875743747,0.019868952468895,246.524428260759,100.0,8.333333333333333e-05,0.56,0.23,0.18,0.07,0.86,0.06,0.02,0.01
239.49017245257585,0.0200432952768232,246.577863957924,100.0,8.333333333333333e-05,0.56,0.23,0.18,0.07,0.86,0.06,0.02,0.01
241.58397830766225,0.0202177790980804,246.641628719681,100.0,8.333333333333333e-05,0.56,0.23,0.18,0.07,0.86,0.06,0.02,0.01
243.69047290768424,0.0203933203147489,246.706359142042,100.0,8.333333333333333e-05,0.56,0.23,0.18,0.07,0.86,0.06,0.02,0.01
245.75023598093264,0.0205649672375196,246.768904457822,100.0,8.333333333333333e-05,0.56,0.23,0.18,0.07,0.86,0.06,0.02,0.01
247.95928566534704,0.0207490547112208,246.837112676718,100.0,8.333333333333333e-05,0.56,0.23,0.18,0.07,0.86,0.06,0.02,0.01
250.11770299566825,0.0209289228220809,246.914833953811,100.0,8.333333333333333e-05,0.56,0.23,0.18,0.07,0.86,0.06,0.02,0.01
252.22271332996303,0.0211043403499388,246.981527263049,100.0,8.333333333333333e-05,0.56,0.23,0.18,0.07,0.86,0.06,0.02,0.01
254.28135512967705,0.0212758938332483,247.060151715591,100.0,8.333333333333333e-05,0.56,0.23,0.18,0.07,0.86,0.06,0.02,0.01
256.30013717150024,0.0214441256700669,247.144390365781,100.0,8.333333333333333e-05,0.56,0.23,0.18,0.07,0.86,0.06,0.02,0.01
258.34929576092264,0.0216148888858521,247.212107491406,100.0,8.333333333333333e-05,0.56,0.23,0.18,0.07,0.86,0.06,0.02,0.01
260.46514017385783,0.0217912092535967,247.277845381918,100.0,8.333333333333333e-05,0.56,0.23,0.18,0.07,0.86,0.06,0.02,0.01
262.3440594490558,0.0219477858598632,247.359939925353,100.0,8.333333333333333e-05,0.56,0.23,0.18,0.07,0.86,0.06,0.02,0.01
264.33988098598064,0.0221141043212736,247.41740265195,100.0,8.333333333333333e-05,0.56,0.23,0.18,0.07,0.86,0.06,0.02,0.01
266.43553624257584,0.0222887422593232,247.483145679556,100.0,8.333333333333333e-05,0.56,0.23,0.18,0.07,0.86,0.06,0.02,0.01
268.53235411130623,0.0224634770817174,247.556184430783,100.0,8.333333333333333e-05,0.56,0.23,0.18,0.07,0.86,0.06,0.02,0.01
270.60905125739265,0.0226365351772246,247.606992148933,100.0,8.333333333333333e-05,0.56,0.23,0.18,0.07,0.86,0.06,0.02,0.01
272.89789112921625,0.0228272718332099,247.669904847711,100.0,8.333333333333333e-05,0.56,0.23,0.18,0.07,0.86,0.06,0.02,0.01
274.88572190366386,0.0229929243977472,247.700005553514,100.0,8.333333333333333e-05,0.56,0.23,0.18,0.07,0.86,0.06,0.02,0.01
277.01516423780384,0.0231703779255922,247.731951219191,100.0,8.333333333333333e-05,0.56,0.23,0.18,0.07,0.86,0.06,0.02,0.01
279.06506636330386,0.0233412031027172,247.78187130241,100.0,8.333333333333333e-05,0.56,0.23,0.18,0.07,0.86,0.06,0.02,0.01
280.9995222509651,0.0235024077600223,247.821385894648,100.0,8.333333333333333e-05,0.56,0.23,0.18,0.07,0.86,0.06,0.02,0.01
282.99367894434585,0.0236685874844707,247.86396634663,100.0,8.333333333333333e-05,0.56,0.23,0.18,0.07,0.86,0.06,0.02,0.01
284.9968298839955,0.0238355167294415,247.916574002387,100.0,8.333333333333333e-05,0.56,0.23,0.18,0.07,0.86,0.06,0.02,0.01
286.71479436922664,0.0239786804365441,247.973714691341,100.0,8.333333333333333e-05,0.56,0.23,0.18,0.07,0.86,0.06,0.02,0.01
288.7379536483655,0.024147277043139,248.032268371945,100.0,8.333333333333333e-05,0.56,0.23,0.18,0.07,0.86,0.06,0.02,0.01
290.84669045506666,0.0243230051103641,248.099841303539,100.0,8.333333333333333e-05,0.56,0.23,0.18,0.07,0.86,0.06,0.02,0.01
293.038201281391,0.0245056310125578,248.189041401188,100.0,8.333333333333333e-05,0.56,0.23,0.18,0.07,0.86,0.06,0.02,0.01
295.14443461540424,0.0246811504570589,248.262109973407,100.0,8.333333333333333e-05,0.56,0.23,0.18,0.07,0.86,0.06,0.02,0.01
297.18554977038104,0.0248512433866403,248.336686395818,100.0,8.333333333333333e-05,0.56,0.23,0.18,0.07,0.86,0.06,0.02,0.01
299.19706463600744,0.0250188696254425,248.437294347813,100.0,8.333333333333333e-05,0.56,0.23,0.18,0.07,0.86,0.06,0.02,0.01
301.31180174901226,0.0251950977181929,248.519161534449,100.0,8.333333333333333e-05,0.56,0.23,0.18,0.07,0.86,0.06,0.02,0.01
303.36567422672266,0.0253662537580021,248.585993125213,100.0,8.333333333333333e-05,0.56,0.23,0.18,0.07,0.86,0.06,0.02,0.01
305.2917479646142,0.0255267599028264,248.633537270114,100.0,8.333333333333333e-05,0.56,0.23,0.18,0.07,0.86,0.06,0.02,0.01
307.18191924623505,0.0256842741762948,248.67290925145,100.0,8.333333333333333e-05,0.56,0.23,0.18,0.07,0.86,0.06,0.02,0.01
309.2055210681094,0.025852907661451,248.752679922146,100.0,8.333333333333333e-05,0.56,0.23,0.18,0.07,0.86,0.06,0.02,0.01
311.263442041579,0.0260244010759068,248.815405488542,100.0,8.333333333333333e-05,0.56,0.23,0.18,0.07,0.86,0.06,0.02,0.01
313.32805537086944,0.026196452186681,248.8624776185,100.0,8.333333333333333e-05,0.56,0.23,0.18,0.07,0.86,0.06,0.02,0.01
315.381450033247,0.0263675684085458,248.915090718283,100.0,8.333333333333333e-05,0.56,0.23,0.18,0.07,0.86,0.06,0.02,0.01
317.43298141915307,0.0265385293573713,249.011748535714,100.0,8.333333333333333e-05,0.56,0.23,0.18,0.07,0.86,0.06,0.02,0.01
319.5059513440462,0.0267112768511124,249.109691030522,100.0,8.333333333333333e-05,0.56,0.23,0.18,0.07,0.86,0.06,0.02,0.01
321.54152030808706,0.0268809075981158,249.168857236899,100.0,8.333333333333333e-05,0.56,0.23,0.18,0.07,0.86,0.06,0.02,0.01
323.68235755220627,0.0270593107017924,249.21731657611,100.0,8.333333333333333e-05,0.56,0.23,0.18,0.07,0.86,0.06,0.02,0.01
325.67800587852224,0.0272256147289854,249.27447165862,100.0,8.333333333333333e-05,0.56,0.23,0.18,0.07,0.86,0.06,0.02,0.01
327.74737513182345,0.0273980621667605,249.310566610106,100.0,8.333333333333333e-05,0.56,0.23,0.18,0.07,0.86,0.06,0.02,0.01
329.78060838349063,0.0275674982710661,249.351578956045,100.0,8.333333333333333e-05,0.56,0.23,0.18,0.07,0.86,0.06,0.02,0.01
331.8547972641023,0.0277403473444504,249.382835346471,100.0,8.333333333333333e-05,0.56,0.23,0.18,0.07,0.86,0.06,0.02,0.01
333.90951988229625,0.0279115742292999,249.413180225786,100.0,8.333333333333333e-05,0.56,0.23,0.18,0.07,0.86,0.06,0.02,0.01
335.9841659632967,0.0280844614027166,249.462087235283,100.0,8.333333333333333e-05,0.56,0.23,0.18,0.07,0.86,0.06,0.02,0.01
337.9358380934938,0.0282471007468997,249.52243332555,100.0,8.333333333333333e-05,0.56,0.23,0.18,0.07,0.86,0.06,0.02,0.01
340.04937477293146,0.0284232288035195,249.579766267827,100.0,8.333333333333333e-05,0.56,0.23,0.18,0.07,0.86,0.06,0.02,0.01
342.08600948003385,0.0285929483624447,249.630743186993,100.0,8.333333333333333e-05,0.56,0.23,0.18,0.07,0.86,0.06,0.02,0.01
344.16726157461466,0.0287663860369931,249.691713030331,100.0,8.333333333333333e-05,0.56,0.23,0.18,0.07,0.86,0.06,0.02,0.01
346.24207216923463,0.0289392869198781,249.74282596941,100.0,8.333333333333333e-05,0.56,0.23,0.18,0.07,0.86,0.06,0.02,0.01
348.33551956059824,0.0291137408691584,249.786015425511,100.0,8.333333333333333e-05,0.56,0.23,0.18,0.07,0.86,0.06,0.02,0.01
350.34216754163504,0.0292809615342448,249.850870010467,100.0,8.333333333333333e-05,0.56,0.23,0.18,0.07,0.86,0.06,0.02,0.01
352.4210143154242,0.0294541987653939,249.895688280785,100.0,8.333333333333333e-05,0.56,0.23,0.18,0.07,0.86,0.06,0.02,0.01
354.42757955100825,0.0296214125350259,249.938299975347,100.0,8.333333333333333e-05,0.56,0.23,0.18,0.07,0.86,0.06,0.02,0.01
356.44144650870345,0.0297892347815005,249.977378108441,100.0,8.333333333333333e-05,0.56,0.23,0.18,0.07,0.86,0.06,0.02,0.01
358.53139029038624,0.0299633967633074,249.983322840937,100.0,8.333333333333333e-05,0.56,0.23,0.18,0.07,0.86,0.06,0.02,0.01
360.5298337435187,0.0301299337177351,249.986382610479,100.0,8.333333333333333e-05,0.56,0.23,0.18,0.07,0.86,0.06,0.02,0.01
362.5679443379015,0.030299776267267,250.013224379341,100.0,8.333333333333333e-05,0.56,0.23,0.18,0.07,0.86,0.06,0.02,0.01
364.6602731769286,0.0304741370038526,250.042078871353,100.0,8.333333333333333e-05,0.56,0.23,0.18,0.07,0.86,0.06,0.02,0.01
366.6341608425215,0.030638627642652,250.086470633629,100.0,8.333333333333333e-05,0.56,0.23,0.18,0.07,0.86,0.06,0.02,0.01
368.6890133501543,0.0308098653516214,250.11322797968,100.0,8.333333333333333e-05,0.56,0.23,0.18,0.07,0.86,0.06,0.02,0.01
370.7442252819478,0.0309811330126042,250.154782353662,100.0,8.333333333333333e-05,0.56,0.23,0.18,0.07,0.86,0.06,0.02,0.01
372.67087855494464,0.0311416874520206,250.213863491054,100.0,8.333333333333333e-05,0.56,0.23,0.18,0.07,0.86,0.06,0.02,0.01
374.6929851228575,0.03131019633268,250.293959753356,100.0,8.333333333333333e-05,0.56,0.23,0.18,0.07,0.86,0.06,0.02,0.01
376.7404946414927,0.0314808221258996,250.358038556335,100.0,8.333333333333333e-05,0.56,0.23,0.18,0.07,0.86,0.06,0.02,0.01
378.751118510011,0.0316483741149428,250.401722304274,100.0,8.333333333333333e-05,0.56,0.23,0.18,0.07,0.86,0.06,0.02,0.01
380.8271585025214,0.031821377447652,250.420788645085,100.0,8.333333333333333e-05,0.56,0.23,0.18,0.07,0.86,0.06,0.02,0.01
382.8729001934986,0.0319918559219001,250.464479743269,100.0,8.333333333333333e-05,0.56,0.23,0.18,0.07,0.86,0.06,0.02,0.01
384.9429836637502,0.0321643628777544,250.514964454513,100.0,8.333333333333333e-05,0.56,0.23,0.18,0.07,0.86,0.06,0.02,0.01
387.0955887810706,0.0323437466375311,250.568764659196,100.0,8.333333333333333e-05,0.56,0.23,0.18,0.07,0.86,0.06,0.02,0.01
389.1254702009687,0.0325129034225226,250.601553745256,100.0,8.333333333333333e-05,0.56,0.23,0.18,0.07,0.86,0.06,0.02,0.01
391.0893442450786,0.0326765595928651,250.640595999463,100.0,8.333333333333333e-05,0.56,0.23,0.18,0.07,0.86,0.06,0.02,0.01
393.06688530208186,0.0328413546809487,250.673993605009,100.0,8.333333333333333e-05,0.56,0.23,0.18,0.07,0.86,0.06,0.02,0.01
395.1070134323374,0.03301136535847,250.717642572559,100.0,8.333333333333333e-05,0.56,0.23,0.18,0.07,0.86,0.06,0.02,0.01
397.124235140737,0.0331794671675033,250.747249794243,100.0,8.333333333333333e-05,0.56,0.23,0.18,0.07,0.86,0.06,0.02,0.01
399.1704301875311,0.0333499834214028,250.80770547585,100.0,8.333333333333333e-05,0.56,0.23,0.18,0.07,0.86,0.06,0.02,0.01
401.1366099210994,0.0335138317325335,250.871552269568,100.0,8.333333333333333e-05,0.56,0.23,0.18,0.07,0.86,0.06,0.02,0.01
403.2097762833394,0.0336865955960535,250.927115062922,100.0,8.333333333333333e-05,0.56,0.23,0.18,0.07,0.86,0.06,0.02,0.01
405.1540132777162,0.0338486153455849,250.9802677999,100.0,8.333333333333333e-05,0.56,0.23,0.18,0.07,0.86,0.06,0.02,0.01
407.1837628067638,0.0340177611396722,251.039615371545,100.0,8.333333333333333e-05,0.56,0.23,0.18,0.07,0.86,0.06,0.02,0.01
409.2388019004778,0.0341890143974817,251.096383201165,100.0,8.333333333333333e-05,0.56,0.23,0.18,0.07,0.86,0.06,0.02,0.01
411.2860844476919,0.0343596212764162,251.158868584181,100.0,8.333333333333333e-05,0.56,0.23,0.18,0.07,0.86,0.06,0.02,0.01
413.2522431987082,0.0345234678390009,251.195329804012,100.0,8.333333333333333e-05,0.56,0.23,0.18,0.07,0.86,0.06,0.02,0.01
415.3299635187251,0.0346966111990023,251.214973098644,100.0,8.333333333333333e-05,0.56,0.23,0.18,0.07,0.86,0.06,0.02,0.01
417.3598756350214,0.034865770542027,251.24952029861,100.0,8.333333333333333e-05,0.56,0.23,0.18,0.07,0.86,0.06,0.02,0.01
419.50996468697264,0.0350449446296896,251.285110377136,100.0,8.333333333333333e-05,0.56,0.23,0.18,0.07,0.86,0.06,0.02,0.01
421.60796286081467,0.0352197778108431,251.327116750779,100.0,8.333333333333333e-05,0.56,0.23,0.18,0.07,0.86,0.06,0.02,0.01
423.7595122787699,0.0353990735956727,251.364141968615,100.0,8.333333333333333e-05,0.56,0.23,0.18,0.07,0.86,0.06,0.02,0.01
425.8370509805255,0.035572201820819,251.397149429636,100.0,8.333333333333333e-05,0.56,0.23,0.18,0.07,0.86,0.06,0.02,0.01
427.9554729231334,0.035748736982703,251.432036630919,100.0,8.333333333333333e-05,0.56,0.23,0.18,0.07,0.86,0.06,0.02,0.01
430.0680832876967,0.0359247878464166,251.457449382983,100.0,8.333333333333333e-05,0.56,0.23,0.18,0.07,0.86,0.06,0.02,0.01
432.18524884853264,0.0361012183098196,251.496012578936,100.0,8.333333333333333e-05,0.56,0.23,0.18,0.07,0.86,0.06,0.02,0.01
434.2838813798122,0.0362761043540929,251.526389670092,100.0,8.333333333333333e-05,0.56,0.23,0.18,0.07,0.86,0.06,0.02,0.01
436.3594480840547,0.0364490682461131,251.555521516722,100.0,8.333333333333333e-05,0.56,0.23,0.18,0.07,0.86,0.06,0.02,0.01
438.3509855076635,0.0366150296980805,251.58297534288,100.0,8.333333333333333e-05,0.56,0.23,0.18,0.07,0.86,0.06,0.02,0.01
440.4600213957142,0.0367907826887514,251.594989648951,100.0,8.333333333333333e-05,0.56,0.23,0.18,0.07,0.86,0.06,0.02,0.01
442.5755516146955,0.0369670768736665,251.594147844007,100.0,8.333333333333333e-05,0.56,0.23,0.18,0.07,0.86,0.06,0.02,0.01
444.59267508193903,0.0371351704959368,251.611465666616,100.0,8.333333333333333e-05,0.56,0.23,0.18,0.07,0.86,0.06,0.02,0.01
446.6630639169394,0.0373077028988535,251.642858238498,100.0,8.333333333333333e-05,0.56,0.23,0.18,0.07,0.86,0.06,0.02,0.01
448.7204839436842,0.0374791545677489,251.67226742359,100.0,8.333333333333333e-05,0.56,0.23,0.18,0.07,0.86,0.06,0.02,0.01
450.7706635615438,0.0376500028692372,251.66751682315,100.0,8.333333333333333e-05,0.56,0.23,0.18,0.07,0.86,0.06,0.02,0.01
452.6925629713714,0.0378101611533895,251.675338565818,100.0,8.333333333333333e-05,0.56,0.23,0.18,0.07,0.86,0.06,0.02,0.01
454.6643912687254,0.037974480178169,251.722891353314,100.0,8.333333333333333e-05,0.56,0.23,0.18,0.07,0.86,0.06,0.02,0.01
456.6644438957158,0.0381411512304182,251.760189887171,100.0,8.333333333333333e-05,0.56,0.23,0.18,0.07,0.86,0.06,0.02,0.01
458.6835777613546,0.0383094123858881,251.814993392174,100.0,8.333333333333333e-05,0.56,0.23,0.18,0.07,0.86,0.06,0.02,0.01
460.7503507608802,0.0384816434691819,251.844036470464,100.0,8.333333333333333e-05,0.56,0.23,0.18,0.07,0.86,0.06,0.02,0.01
462.79199694216464,0.0386517806509556,251.884039732814,100.0,8.333333333333333e-05,0.56,0.23,0.18,0.07,0.86,0.06,0.02,0.01
464.8413046633247,0.0388225562943856,251.927045562033,100.0,8.333333333333333e-05,0.56,0.23,0.18,0.07,0.86,0.06,0.02,0.01
466.9544339747866,0.0389986504036741,251.952854710368,100.0,8.333333333333333e-05,0.56,0.23,0.18,0.07,0.86,0.06,0.02,0.01
469.0996493624542,0.0391774183526464,251.968520634144,100.0,8.333333333333333e-05,0.56,0.23,0.18,0.07,0.86,0.06,0.02,0.01
471.2044162840498,0.0393528155961127,251.989656416149,100.0,8.333333333333333e-05,0.56,0.23,0.18,0.07,0.86,0.06,0.02,0.01
473.2712366867999,0.0395250506296752,252.016305447056,100.0,8.333333333333333e-05,0.56,0.23,0.18,0.07,0.86,0.06,0.02,0.01
475.3263380014127,0.0396963090725596,252.04842462697,100.0,8.333333333333333e-05,0.56,0.23,0.18,0.07,0.86,0.06,0.02,0.01
477.42741539387146,0.0398713988552645,252.080870190056,100.0,8.333333333333333e-05,0.56,0.23,0.18,0.07,0.86,0.06,0.02,0.01
479.5571765783903,0.0400488789539744,252.116645494748,100.0,8.333333333333333e-05,0.56,0.23,0.18,0.07,0.86,0.06,0.02,0.01
481.60273266268064,0.0402193419609986,252.166225576649,100.0,8.333333333333333e-05,0.56,0.23,0.18,0.07,0.86,0.06,0.02,0.01
483.69571317273466,0.0403937570035031,252.204829303952,100.0,8.333333333333333e-05,0.56,0.23,0.18,0.07,0.86,0.06,0.02,0.01
485.6370592791023,0.0405555358457004,252.252917237723,100.0,8.333333333333333e-05,0.56,0.23,0.18,0.07,0.86,0.06,0.02,0.01
487.7015646282754,0.0407275779581315,252.269144251715,100.0,8.333333333333333e-05,0.56,0.23,0.18,0.07,0.86,0.06,0.02,0.01
489.684765309349,0.0408928446815543,252.275861906862,100.0,8.333333333333333e-05,0.56,0.23,0.18,0.07,0.86,0.06,0.02,0.01
491.720187456547,0.0410624631938208,252.269173895009,100.0,8.333333333333333e-05,0.56,0.23,0.18,0.07,0.86,0.06,0.02,0.01
493.71750160480906,0.0412289060395093,252.283820170229,100.0,8.333333333333333e-05,0.56,0.23,0.18,0.07,0.86,0.06,0.02,0.01
495.8617794643151,0.0414075958611348,252.297202445682,100.0,8.333333333333333e-05,0.56,0.23,0.18,0.07,0.86,0.06,0.02,0.01
497.909229021931,0.0415782166576028,252.295105445111,100.0,8.333333333333333e-05,0.56,0.23,0.18,0.07,0.86,0.06,0.02,0.01
500.04412622137545,0.0417561247575565,252.300061448542,100.0,8.333333333333333e-05,0.56,0.23,0.18,0.07,0.86,0.06,0.02,0.01
502.1603143128034,0.0419324737651755,252.329676359712,100.0,8.333333333333333e-05,0.56,0.23,0.18,0.07,0.86,0.06,0.02,0.01
504.2788876717607,0.0421090215450886,252.372701590346,100.0,8.333333333333333e-05,0.56,0.23,0.18,0.07,0.86,0.06,0.02,0.01
506.1507828287627,0.0422650128081721,252.429952177574,100.0,8.333333333333333e-05,0.56,0.23,0.18,0.07,0.86,0.06,0.02,0.01
508.3225681374287,0.0424459949172276,252.488004523028,100.0,8.333333333333333e-05,0.56,0.23,0.18,0.07,0.86,0.06,0.02,0.01
510.4825544579255,0.042625993777269,252.541129700627,100.0,8.333333333333333e-05,0.56,0.23,0.18,0.07,0.86,0.06,0.02,0.01
512.4946493222698,0.0427936683492977,252.599098737923,100.0,8.333333333333333e-05,0.56,0.23,0.18,0.07,0.86,0.06,0.02,0.01
514.6258871675986,0.0429712715030751,252.653262480861,100.0,8.333333333333333e-05,0.56,0.23,0.18,0.07,0.86,0.06,0.02,0.01
516.6591297592149,0.0431407083857098,252.699197519892,100.0,8.333333333333333e-05,0.56,0.23,0.18,0.07,0.86,0.06,0.02,0.01
518.7552148984978,0.0433153821473167,252.72667441451,100.0,8.333333333333333e-05,0.56,0.23,0.18,0.07,0.86,0.06,0.02,0.01
521.0530890375478,0.0435068716589042,252.748362951068,100.0,8.333333333333333e-05,0.56,0.23,0.18,0.07,0.86,0.06,0.02,0.01
523.0319548981473,0.0436717771472875,252.740844975434,100.0,8.333333333333333e-05,0.56,0.23,0.18,0.07,0.86,0.06,0.02,0.01
525.0464534834122,0.0438396520293929,252.738396778557,100.0,8.333333333333333e-05,0.56,0.23,0.18,0.07,0.86,0.06,0.02,0.01
527.1818120313826,0.0440175985750571,252.738155642069,100.0,8.333333333333333e-05,0.56,0.23,0.18,0.07,0.86,0.06,0.02,0.01
529.1980931476414,0.044185622001412,252.745912331033,100.0,8.333333333333333e-05,0.56,0.23,0.18,0.07,0.86,0.06,0.02,0.01
531.3364799249362,0.0443638208995199,252.749193690259,100.0,8.333333333333333e-05,0.56,0.23,0.18,0.07,0.86,0.06,0.02,0.01
533.4186632531543,0.0445373361768714,252.731475319702,100.0,8.333333333333333e-05,0.56,0.23,0.18,0.07,0.86,0.06,0.02,0.01
535.2105459251518,0.0446866597328712,252.728130683754,100.0,8.333333333333333e-05,0.56,0.23,0.18,0.07,0.86,0.06,0.02,0.01
537.3490974758649,0.0448648723620973,252.752022290568,100.0,8.333333333333333e-05,0.56,0.23,0.18,0.07,0.86,0.06,0.02,0.01
539.4692323743262,0.0450415502703024,252.779599164668,100.0,8.333333333333333e-05,0.56,0.23,0.18,0.07,0.86,0.06,0.02,0.01
541.5356730731602,0.0452137536618719,252.809049365741,100.0,8.333333333333333e-05,0.56,0.23,0.18,0.07,0.86,0.06,0.02,0.01
543.6173478822082,0.0453872265626259,252.836916727972,100.0,8.333333333333333e-05,0.56,0.23,0.18,0.07,0.86,0.06,0.02,0.01
545.6842451661526,0.0455594680029546,252.866799365746,100.0,8.333333333333333e-05,0.56,0.23,0.18,0.07,0.86,0.06,0.02,0.01
547.7962828308298,0.0457354711416777,252.902875723536,100.0,8.333333333333333e-05,0.56,0.23,0.18,0.07,0.86,0.06,0.02,0.01
550.1333982892318,0.0459302307632112,252.925929677082,100.0,8.333333333333333e-05,0.56,0.23,0.18,0.07,0.86,0.06,0.02,0.01
552.2104933146994,0.0461033220153335,252.949945931122,100.0,8.333333333333333e-05,0.56,0.23,0.18,0.07,0.86,0.06,0.02,0.01
554.3021505462118,0.0462776267846262,252.963824582329,100.0,8.333333333333333e-05,0.56,0.23,0.18,0.07,0.86,0.06,0.02,0.01
556.4120971273522,0.0464534556663879,252.982902441216,100.0,8.333333333333333e-05,0.56,0.23,0.18,0.07,0.86,0.06,0.02,0.01
558.5128382298262,0.0466285174249274,252.998756628182,100.0,8.333333333333333e-05,0.56,0.23,0.18,0.07,0.86,0.06,0.02,0.01
560.437125957817,0.0467888747355933,252.994609264745,100.0,8.333333333333333e-05,0.56,0.23,0.18,0.07,0.86,0.06,0.02,0.01
562.5336236225505,0.0469635828743211,253.008413735021,100.0,8.333333333333333e-05,0.56,0.23,0.18,0.07,0.86,0.06,0.02,0.01
564.7503269409526,0.0471483081508546,253.042699120888,100.0,8.333333333333333e-05,0.56,0.23,0.18,0.07,0.86,0.06,0.02,0.01
566.7945928591425,0.0473186636440371,253.062340331604,100.0,8.333333333333333e-05,0.56,0.23,0.18,0.07,0.86,0.06,0.02,0.01
568.9157466638073,0.0474954264610925,253.092055852277,100.0,8.333333333333333e-05,0.56,0.23,0.18,0.07,0.86,0.06,0.02,0.01
571.0407688858078,0.0476725116462592,253.122574261984,100.0,8.333333333333333e-05,0.56,0.23,0.18,0.07,0.86,0.06,0.02,0.01
573.2291890648089,0.0478548799945093,253.133954718495,100.0,8.333333333333333e-05,0.56,0.23,0.18,0.07,0.86,0.06,0.02,0.01
575.5740102385546,0.0480502817589881,253.15584705876,100.0,8.333333333333333e-05,0.56,0.23,0.18,0.07,0.86,0.06,0.02,0.01
577.7176823582241,0.0482289211022939,253.182425737325,100.0,8.333333333333333e-05,0.56,0.23,0.18,0.07,0.86,0.06,0.02,0.01
579.7446981359698,0.0483978390837727,253.185850175929,100.0,8.333333333333333e-05,0.56,0.23,0.18,0.07,0.86,0.06,0.02,0.01
581.8568357987039,0.0485738505556672,253.160992116945,100.0,8.333333333333333e-05,0.56,0.23,0.18,0.07,0.86,0.06,0.02,0.01
583.949331086137,0.0487482251629533,253.138973045539,100.0,8.333333333333333e-05,0.56,0.23,0.18,0.07,0.86,0.06,0.02,0.01
586.0589974199686,0.0489240306907726,253.12244929167,100.0,8.333333333333333e-05,0.56,0.23,0.18,0.07,0.86,0.06,0.02,0.01
588.2284908945597,0.0491048218136552,253.126053657802,100.0,8.333333333333333e-05,0.56,0.23,0.18,0.07,0.86,0.06,0.02,0.01
590.3683034321409,0.0492831395251203,253.139536542758,100.0,8.333333333333333e-05,0.56,0.23,0.18,0.07,0.86,0.06,0.02,0.01
592.4359738128634,0.0494554453901805,253.157509199472,100.0,8.333333333333333e-05,0.56,0.23,0.18,0.07,0.86,0.06,0.02,0.01
594.5882652690118,0.0496348030115262,253.166194070871,100.0,8.333333333333333e-05,0.56,0.23,0.18,0.07,0.86,0.06,0.02,0.01
596.7210489419147,0.0498125349842681,253.210521732551,100.0,8.333333333333333e-05,0.56,0.23,0.18,0.07,0.86,0.06,0.02,0.01
598.7800694776702,0.0499841200289144,253.24475922067,100.0,8.333333333333333e-05,0.56,0.23,0.18,0.07,0.86,0.06,0.02,0.01
600.8998892718322,0.0501607716784279,253.282931448224,100.0,8.333333333333333e-05,0.56,0.23,0.18,0.07,0.86,0.06,0.02,0.01
602.521442702899,0.0502959011310168,253.294026069067,100.0,8.333333333333333e-05,0.56,0.23,0.18,0.07,0.86,0.06,0.02,0.01
604.4382492250559,0.0504556350078632,253.290731737871,100.0,8.333333333333333e-05,0.56,0.23,0.18,0.07,0.86,0.06,0.02,0.01
606.6054118269501,0.0506362318913544,253.25938242743,100.0,8.333333333333333e-05,0.56,0.23,0.18,0.07,0.86,0.06,0.02,0.01
608.6618210860751,0.0508075993296148,253.250201034887,100.0,8.333333333333333e-05,0.56,0.23,0.18,0.07,0.86,0.06,0.02,0.01
610.7886285879166,0.0509848332881016,253.241227129251,100.0,8.333333333333333e-05,0.56,0.23,0.18,0.07,0.86,0.06,0.02,0.01
612.861164843317,0.0511575446427183,253.241884208816,100.0,8.333333333333333e-05,0.56,0.23,0.18,0.07,0.86,0.06,0.02,0.01
614.932796335165,0.0513301806003723,253.237878971648,100.0,8.333333333333333e-05,0.56,0.23,0.18,0.07,0.86,0.06,0.02,0.01
617.401402132171,0.0515358977501228,253.233356212638,100.0,8.333333333333333e-05,0.56,0.23,0.18,0.07,0.86,0.06,0.02,0.01
619.6282413124953,0.0517214676818165,253.241291876022,100.0,8.333333333333333e-05,0.56,0.23,0.18,0.07,0.86,0.06,0.02,0.01
621.6731418016847,0.0518918760559156,253.271270648535,100.0,8.333333333333333e-05,0.56,0.23,0.18,0.07,0.86,0.06,0.02,0.01
623.8057929698566,0.0520695969865966,253.291626933054,100.0,8.333333333333333e-05,0.56,0.23,0.18,0.07,0.86,0.06,0.02,0.01
625.9121615061022,0.0522451276979504,253.32837736482,100.0,8.333333333333333e-05,0.56,0.23,0.18,0.07,0.86,0.06,0.02,0.01
628.0263037138894,0.052421306215266,253.362093017876,100.0,8.333333333333333e-05,0.56,0.23,0.18,0.07,0.86,0.06,0.02,0.01
630.1805515639786,0.0526008268694401,253.381098618204,100.0,8.333333333333333e-05,0.56,0.23,0.18,0.07,0.86,0.06,0.02,0.01
632.3854387071539,0.0527845674647047,253.415847214874,100.0,8.333333333333333e-05,0.56,0.23,0.18,0.07,0.86,0.06,0.02,0.01
634.389726290383,0.0529515914299738,253.447350185815,100.0,8.333333333333333e-05,0.56,0.23,0.18,0.07,0.86,0.06,0.02,0.01
636.4945560495346,0.0531269939099031,253.466461209652,100.0,8.333333333333333e-05,0.56,0.23,0.18,0.07,0.86,0.06,0.02,0.01
638.6517895140357,0.0533067633652782,253.477286973084,100.0,8.333333333333333e-05,0.56,0.23,0.18,0.07,0.86,0.06,0.02,0.01
640.8344965824874,0.0534886556209825,253.48567814163,100.0,8.333333333333333e-05,0.56,0.23,0.18,0.07,0.86,0.06,0.02,0.01
643.0655752087306,0.0536745788398361,253.495277076533,100.0,8.333333333333333e-05,0.56,0.23,0.18,0.07,0.86,0.06,0.02,0.01
645.2150970110938,0.0538537056566997,253.496730454142,100.0,8.333333333333333e-05,0.56,0.23,0.18,0.07,0.86,0.06,0.02,0.01
647.3211432043654,0.054029209506139,253.505200310692,100.0,8.333333333333333e-05,0.56,0.23,0.18,0.07,0.86,0.06,0.02,0.01
649.6360302037414,0.054222116756087,253.51888333231,100.0,8.333333333333333e-05,0.56,0.23,0.18,0.07,0.86,0.06,0.02,0.01
651.8300407685614,0.054404950969822,253.516925582527,100.0,8.333333333333333e-05,0.56,0.23,0.18,0.07,0.86,0.06,0.02,0.01
653.979876081865,0.0545841039125973,253.520997472683,100.0,8.333333333333333e-05,0.56,0.23,0.18,0.07,0.86,0.06,0.02,0.01
655.980345402979,0.0547508096893568,253.516405976769,100.0,8.333333333333333e-05,0.56,0.23,0.18,0.07,0.86,0.06,0.02,0.01
658.1254486155502,0.0549295682904044,253.493615097365,100.0,8.333333333333333e-05,0.56,0.23,0.18,0.07,0.86,0.06,0.02,0.01
660.2003448961354,0.0551024763137865,253.486058367364,100.0,8.333333333333333e-05,0.56,0.23,0.18,0.07,0.86,0.06,0.02,0.01
662.3307140627038,0.0552800070776672,253.467239737875,100.0,8.333333333333333e-05,0.56,0.23,0.18,0.07,0.86,0.06,0.02,0.01
664.4112423985401,0.0554533844389869,253.448609694663,100.0,8.333333333333333e-05,0.56,0.23,0.18,0.07,0.86,0.06,0.02,0.01
666.5848115139166,0.0556345151986016,253.461879164054,100.0,8.333333333333333e-05,0.56,0.23,0.18,0.07,0.86,0.06,0.02,0.01
668.6994397053274,0.0558107342145525,253.463802957321,100.0,8.333333333333333e-05,0.56,0.23,0.18,0.07,0.86,0.06,0.02,0.01
671.094999929221,0.0560103642332103,253.472607839639,100.0,8.333333333333333e-05,0.56,0.23,0.18,0.07,0.86,0.06,0.02,0.01
673.2419347788261,0.0561892754706774,253.486749904229,100.0,8.333333333333333e-05,0.56,0.23,0.18,0.07,0.86,0.06,0.02,0.01
675.4762507403817,0.0563754684674737,253.508048296261,100.0,8.333333333333333e-05,0.56,0.23,0.18,0.07,0.86,0.06,0.02,0.01
677.702470066729,0.0565609867446693,253.507616328036,100.0,8.333333333333333e-05,0.56,0.23,0.18,0.07,0.86,0.06,0.02,0.01
680.0105890682878,0.0567533299947992,253.515113626059,100.0,8.333333333333333e-05,0.56,0.23,0.18,0.07,0.86,0.06,0.02,0.01
682.1117008000234,0.0569284226391105,253.50875808758,100.0,8.333333333333333e-05,0.56,0.23,0.18,0.07,0.86,0.06,0.02,0.01
684.3398059686274,0.0571140980698275,253.522025650754,100.0,8.333333333333333e-05,0.56,0.23,0.18,0.07,0.86,0.06,0.02,0.01
686.4234031655194,0.0572877311695685,253.520802666967,100.0,8.333333333333333e-05,0.56,0.23,0.18,0.07,0.86,0.06,0.02,0.01
688.607483194447,0.0574697378386458,253.532674200594,100.0,8.333333333333333e-05,0.56,0.23,0.18,0.07,0.86,0.06,0.02,0.01
690.7503205047814,0.057648307614507,253.519899653063,100.0,8.333333333333333e-05,0.56,0.23,0.18,0.07,0.86,0.06,0.02,0.01
692.8860292707586,0.0578262833450051,253.523113083105,100.0,8.333333333333333e-05,0.56,0.23,0.18,0.07,0.86,0.06,0.02,0.01
695.0154972792634,0.0580037390123805,253.514278880581,100.0,8.333333333333333e-05,0.56,0.23,0.18,0.07,0.86,0.06,0.02,0.01
697.2146730880594,0.0581870036631135,253.521478162529,100.0,8.333333333333333e-05,0.56,0.23,0.18,0.07,0.86,0.06,0.02,0.01
699.3622954494766,0.0583659721932316,253.524816885973,100.0,8.333333333333333e-05,0.56,0.23,0.18,0.07,0.86,0.06,0.02,0.01
701.4509540694478,0.0585400270782292,253.508176804385,100.0,8.333333333333333e-05,0.56,0.23,0.18,0.07,0.86,0.06,0.02,0.01
703.6621374751559,0.0587242923620382,253.482958551104,100.0,8.333333333333333e-05,0.56,0.23,0.18,0.07,0.86,0.06,0.02,0.01
705.8132586882622,0.0589035524631304,253.490756579137,100.0,8.333333333333333e-05,0.56,0.23,0.18,0.07,0.86,0.06,0.02,0.01
707.981471055355,0.0590842368270548,253.510314158608,100.0,8.333333333333333e-05,0.56,0.23,0.18,0.07,0.86,0.06,0.02,0.01
710.2227549891059,0.0592710104882007,253.51893942033,100.0,8.333333333333333e-05,0.56,0.23,0.18,0.07,0.86,0.06,0.02,0.01
712.4513028049846,0.0594567228061906,253.527611626693,100.0,8.333333333333333e-05,0.56,0.23,0.18,0.07,0.86,0.06,0.02,0.01
714.5252761344934,0.059629553916983,253.534588026607,100.0,8.333333333333333e-05,0.56,0.23,0.18,0.07,0.86,0.06,0.02,0.01
716.935236248917,0.0598303839265183,253.550012183874,100.0,8.333333333333333e-05,0.56,0.23,0.18,0.07,0.86,0.06,0.02,0.01
719.1885250916434,0.0600181579967455,253.566560298554,100.0,8.333333333333333e-05,0.56,0.23,0.18,0.07,0.86,0.06,0.02,0.01
721.1804768163202,0.0601841539738019,253.567507704706,100.0,8.333333333333333e-05,0.56,0.23,0.18,0.07,0.86,0.06,0.02,0.01