File: datasets/al_6061_comp/csv/T_100_G_1.csv
Time,Strain(%),Stress(MPa),Temp(C),SR(%/s),Si(%),Fe(%),Cu(%),Mn(%),Mg(%),Cr(%),Zn(%),Ti(%)
0.0,0.000127480716755,42.5000472940636,100.0,8.333333333333333e-05,0.61,0.15,0.17,0.02,0.88,0.05,0.01,0.01
1.3620315998819998,0.0002409833500785,48.335056444439,100.0,8.333333333333333e-05,0.61,0.15,0.17,0.02,0.88,0.05,0.01,0.01
2.6770518090936006,0.0003505683675128,54.1923989637904,100.0,8.333333333333333e-05,0.61,0.15,0.17,0.02,0.88,0.05,0.01,0.01
4.150450933116001,0.000473351627848,60.0252495360403,100.0,8.333333333333333e-05,0.61,0.15,0.17,0.02,0.88,0.05,0.01,0.01
5.496715680064801,0.0005855403567604,65.8198276480437,100.0,8.333333333333333e-05,0.61,0.15,0.17,0.02,0.88,0.05,0.01,0.01
7.056846720294,0.0007155512767795,71.6243591817221,100.0,8.333333333333333e-05,0.61,0.15,0.17,0.02,0.88,0.05,0.01,0.01
8.6425308048996,0.0008476916171633,77.4492258173954,100.0,8.333333333333333e-05,0.61,0.15,0.17,0.02,0.88,0.05,0.01,0.01
10.1651675336484,0.0009745780112257,83.286289221428,100.0,8.333333333333333e-05,0.61,0.15,0.17,0.02,0.88,0.05,0.01,0.01
11.706369822798,0.0011030115353215,89.0775560921556,100.0,8.333333333333333e-05,0.61,0.15,0.17,0.02,0.88,0.05,0.01,0.01
13.078129193451598,0.0012173248162093,94.7123755457332,100.0,8.333333333333333e-05,0.61,0.15,0.17,0.02,0.88,0.05,0.01,0.01
14.4092309130864,0.0013282499595122,100.166799037006,100.0,8.333333333333333e-05,0.61,0.15,0.17,0.02,0.88,0.05,0.01,0.01
15.768302962547995,0.001441505963634,105.508285448229,100.0,8.333333333333333e-05,0.61,0.15,0.17,0.02,0.88,0.05,0.01,0.01
17.136467060646,0.0015555196384755,110.815520756556,100.0,8.333333333333333e-05,0.61,0.15,0.17,0.02,0.88,0.05,0.01,0.01
18.554589483144,0.001673696507017,116.073575554935,100.0,8.333333333333333e-05,0.61,0.15,0.17,0.02,0.88,0.05,0.01,0.01
19.8856093535088,0.0017846148295474,121.265923995961,100.0,8.333333333333333e-05,0.61,0.15,0.17,0.02,0.88,0.05,0.01,0.01
21.3294926886504,0.0019049384408092,126.342069788171,100.0,8.333333333333333e-05,0.61,0.15,0.17,0.02,0.88,0.05,0.01,0.01
22.609539485642404,0.0020116090072252,131.302489070648,100.0,8.333333333333333e-05,0.61,0.15,0.17,0.02,0.88,0.05,0.01,0.01
24.002698213087204,0.0021277055678456,136.199513425407,100.0,8.333333333333333e-05,0.61,0.15,0.17,0.02,0.88,0.05,0.01,0.01
25.278680491034404,0.0022340374243412,141.030030403301,100.0,8.333333333333333e-05,0.61,0.15,0.17,0.02,0.88,0.05,0.01,0.01
26.479693480298405,0.0023341218401132,145.769383361774,100.0,8.333333333333333e-05,0.61,0.15,0.17,0.02,0.88,0.05,0.01,0.01
27.716946439192803,0.0024372262533544,150.457403335511,100.0,8.333333333333333e-05,0.61,0.15,0.17,0.02,0.88,0.05,0.01,0.01
28.948805454644404,0.0025398811713087,155.098654610682,100.0,8.333333333333333e-05,0.61,0.15,0.17,0.02,0.88,0.05,0.01,0.01
30.2170581603192,0.0026455688967816,159.808963511014,100.0,8.333333333333333e-05,0.61,0.15,0.17,0.02,0.88,0.05,0.01,0.01
31.547301824193603,0.0027564225354378,164.618048111144,100.0,8.333333333333333e-05,0.61,0.15,0.17,0.02,0.88,0.05,0.01,0.01
32.791716762948006,0.002860123780334,169.254569568834,100.0,8.333333333333333e-05,0.61,0.15,0.17,0.02,0.88,0.05,0.01,0.01
33.981858761095204,0.0029593022801796,173.84247677055,100.0,8.333333333333333e-05,0.61,0.15,0.17,0.02,0.88,0.05,0.01,0.01
35.211653659824,0.003061785188407,178.231225833918,100.0,8.333333333333333e-05,0.61,0.15,0.17,0.02,0.88,0.05,0.01,0.01
36.340858111338,0.0031558855593665,182.671217640964,100.0,8.333333333333333e-05,0.61,0.15,0.17,0.02,0.88,0.05,0.01,0.01
37.5945664720224,0.0032603612560902,187.099827482923,100.0,8.333333333333333e-05,0.61,0.15,0.17,0.02,0.88,0.05,0.01,0.01
38.6929223672832,0.0033518909140286,191.560121888149,100.0,8.333333333333333e-05,0.61,0.15,0.17,0.02,0.88,0.05,0.01,0.01
39.8663287903788,0.0034496747826199,195.913622402617,100.0,8.333333333333333e-05,0.61,0.15,0.17,0.02,0.88,0.05,0.01,0.01
41.0023746184308,0.0035443452682909,200.262897878629,100.0,8.333333333333333e-05,0.61,0.15,0.17,0.02,0.88,0.05,0.01,0.01
42.0934216248444,0.0036352658521587,204.567943643952,100.0,8.333333333333333e-05,0.61,0.15,0.17,0.02,0.88,0.05,0.01,0.01
43.249044366645606,0.0037315677473088,208.76678523958,100.0,8.333333333333333e-05,0.61,0.15,0.17,0.02,0.88,0.05,0.01,0.01
44.418338670222006,0.0038290089392735,213.003008807658,100.0,8.333333333333333e-05,0.61,0.15,0.17,0.02,0.88,0.05,0.01,0.01
45.57908590819321,0.0039257378757711,217.035846565193,100.0,8.333333333333333e-05,0.61,0.15,0.17,0.02,0.88,0.05,0.01,0.01
46.77164032891561,0.0040251174108313,220.833117465384,100.0,8.333333333333333e-05,0.61,0.15,0.17,0.02,0.88,0.05,0.01,0.01
47.8464877302984,0.0041146880276132,224.384650211645,100.0,8.333333333333333e-05,0.61,0.15,0.17,0.02,0.88,0.05,0.01,0.01
48.9025532863128,0.0042026934906144,227.856849538212,100.0,8.333333333333333e-05,0.61,0.15,0.17,0.02,0.88,0.05,0.01,0.01
50.090541144279605,0.0043016924787783,231.203178562901,100.0,8.333333333333333e-05,0.61,0.15,0.17,0.02,0.88,0.05,0.01,0.01
51.1824581744208,0.0043926855646234,234.425940404086,100.0,8.333333333333333e-05,0.61,0.15,0.17,0.02,0.88,0.05,0.01,0.01
52.370722833433206,0.0044917076195411,237.528791512158,100.0,8.333333333333333e-05,0.61,0.15,0.17,0.02,0.88,0.05,0.01,0.01
53.53472395006921,0.0045887077125941,240.674713895622,100.0,8.333333333333333e-05,0.61,0.15,0.17,0.02,0.88,0.05,0.01,0.01
54.8107068416232,0.0046950396202236,243.698378158695,100.0,8.333333333333333e-05,0.61,0.15,0.17,0.02,0.88,0.05,0.01,0.01
56.1111851685972,0.0048034128141381,246.669097225782,100.0,8.333333333333333e-05,0.61,0.15,0.17,0.02,0.88,0.05,0.01,0.01
57.5343145217136,0.0049220069268978,249.581086553506,100.0,8.333333333333333e-05,0.61,0.15,0.17,0.02,0.88,0.05,0.01,0.01
59.0530710591036,0.0050485699716803,252.239160124137,100.0,8.333333333333333e-05,0.61,0.15,0.17,0.02,0.88,0.05,0.01,0.01
60.69839415851881,0.0051856802299649,254.864358949393,100.0,8.333333333333333e-05,0.61,0.15,0.17,0.02,0.88,0.05,0.01,0.01
62.6455285539012,0.0053479414295801,257.180063476431,100.0,8.333333333333333e-05,0.61,0.15,0.17,0.02,0.88,0.05,0.01,0.01
65.2290580456236,0.0055632355538903,259.200986357124,100.0,8.333333333333333e-05,0.61,0.15,0.17,0.02,0.88,0.05,0.01,0.01
68.7776008297176,0.0058589474525648,260.719659863345,100.0,8.333333333333333e-05,0.61,0.15,0.17,0.02,0.88,0.05,0.01,0.01
73.2369615095436,0.0062305608425503,261.651527586271,100.0,8.333333333333333e-05,0.61,0.15,0.17,0.02,0.88,0.05,0.01,0.01
78.614537758302,0.0066786921966135,262.242772403291,100.0,8.333333333333333e-05,0.61,0.15,0.17,0.02,0.88,0.05,0.01,0.01
84.58682468244001,0.007176382773625,262.500310656037,100.0,8.333333333333333e-05,0.61,0.15,0.17,0.02,0.88,0.05,0.01,0.01
90.9088262851848,0.0077032162405204,262.738526613645,100.0,8.333333333333333e-05,0.61,0.15,0.17,0.02,0.88,0.05,0.01,0.01
97.3160411741172,0.0082371508145981,262.888339041924,100.0,8.333333333333333e-05,0.61,0.15,0.17,0.02,0.88,0.05,0.01,0.01
103.75320210387122,0.0087735808920776,262.979856881366,100.0,8.333333333333333e-05,0.61,0.15,0.17,0.02,0.88,0.05,0.01,0.01
110.122847253516,0.009304384654548,263.051385916119,100.0,8.333333333333333e-05,0.61,0.15,0.17,0.02,0.88,0.05,0.01,0.01
116.5337428037268,0.0098386259503989,263.093715281313,100.0,8.333333333333333e-05,0.61,0.15,0.17,0.02,0.88,0.05,0.01,0.01
122.8977303660192,0.0103689582472566,263.185834401886,100.0,8.333333333333333e-05,0.61,0.15,0.17,0.02,0.88,0.05,0.01,0.01
129.2584638764172,0.0108990193731231,263.314755488714,100.0,8.333333333333333e-05,0.61,0.15,0.17,0.02,0.88,0.05,0.01,0.01
135.59260498219442,0.0114268644652712,263.433590378706,100.0,8.333333333333333e-05,0.61,0.15,0.17,0.02,0.88,0.05,0.01,0.01
141.77716266876482,0.0119422442724854,263.545821695448,100.0,8.333333333333333e-05,0.61,0.15,0.17,0.02,0.88,0.05,0.01,0.01
147.81357346995,0.0124452785059175,263.542238295843,100.0,8.333333333333333e-05,0.61,0.15,0.17,0.02,0.88,0.05,0.01,0.01
153.707265622368,0.012936419518619,263.541921395485,100.0,8.333333333333333e-05,0.61,0.15,0.17,0.02,0.88,0.05,0.01,0.01
159.5109051249024,0.0134200561438302,263.583519022708,100.0,8.333333333333333e-05,0.61,0.15,0.17,0.02,0.88,0.05,0.01,0.01
165.24764241966122,0.0138981175850601,263.707924776223,100.0,8.333333333333333e-05,0.61,0.15,0.17,0.02,0.88,0.05,0.01,0.01
170.972003376666,0.0143751476648105,263.78478584007,100.0,8.333333333333333e-05,0.61,0.15,0.17,0.02,0.88,0.05,0.01,0.01
176.57869865997242,0.0148423722717527,263.949236118871,100.0,8.333333333333333e-05,0.61,0.15,0.17,0.02,0.88,0.05,0.01,0.01
182.0996148930984,0.0153024486245132,263.987803431764,100.0,8.333333333333333e-05,0.61,0.15,0.17,0.02,0.88,0.05,0.01,0.01
187.5602697022248,0.0157575031919404,264.109231261862,100.0,8.333333333333333e-05,0.61,0.15,0.17,0.02,0.88,0.05,0.01,0.01
192.913831521516,0.016203633343548,264.149704077334,100.0,8.333333333333333e-05,0.61,0.15,0.17,0.02,0.88,0.05,0.01,0.01
198.1628388958548,0.0166410506247429,264.27393057886,100.0,8.333333333333333e-05,0.61,0.15,0.17,0.02,0.88,0.05,0.01,0.01
203.44369247740445,0.0170811217565387,264.428089576109,100.0,8.333333333333333e-05,0.61,0.15,0.17,0.02,0.88,0.05,0.01,0.01
208.5480315264408,0.0175064833439584,264.566409106829,100.0,8.333333333333333e-05,0.61,0.15,0.17,0.02,0.88,0.05,0.01,0.01
213.505443580332,0.017919601015116,264.643853772634,100.0,8.333333333333333e-05,0.61,0.15,0.17,0.02,0.88,0.05,0.01,0.01
218.441261079204,0.018330919140022,264.633623650612,100.0,8.333333333333333e-05,0.61,0.15,0.17,0.02,0.88,0.05,0.01,0.01
223.23475782703923,0.0187303772023416,264.684427174872,100.0,8.333333333333333e-05,0.61,0.15,0.17,0.02,0.88,0.05,0.01,0.01
227.9421863435808,0.0191226629120534,264.754500114461,100.0,8.333333333333333e-05,0.61,0.15,0.17,0.02,0.88,0.05,0.01,0.01
232.6377955268748,0.0195139636773279,264.919197381243,100.0,8.333333333333333e-05,0.61,0.15,0.17,0.02,0.88,0.05,0.01,0.01
237.2408109191436,0.0198975482933503,265.050535767724,100.0,8.333333333333333e-05,0.61,0.15,0.17,0.02,0.88,0.05,0.01,0.01
241.7600933455176,0.0202741551622148,265.267708825584,100.0,8.333333333333333e-05,0.61,0.15,0.17,0.02,0.88,0.05,0.01,0.01
246.3455544165948,0.0206562769181379,265.428516406215,100.0,8.333333333333333e-05,0.61,0.15,0.17,0.02,0.88,0.05,0.01,0.01
250.81638405025203,0.021028846054276,265.50366281108,100.0,8.333333333333333e-05,0.61,0.15,0.17,0.02,0.88,0.05,0.01,0.01
255.35108944777923,0.0214067381707366,265.566249685467,100.0,8.333333333333333e-05,0.61,0.15,0.17,0.02,0.88,0.05,0.01,0.01
259.8828054482052,0.0217843811707721,265.601284743766,100.0,8.333333333333333e-05,0.61,0.15,0.17,0.02,0.88,0.05,0.01,0.01
264.30626244871195,0.022153002587481,265.745740288021,100.0,8.333333333333333e-05,0.61,0.15,0.17,0.02,0.88,0.05,0.01,0.01
268.6930752281064,0.0225185703190972,265.88470426481,100.0,8.333333333333333e-05,0.61,0.15,0.17,0.02,0.88,0.05,0.01,0.01
273.0683651234448,0.0228831778103754,266.068714443048,100.0,8.333333333333333e-05,0.61,0.15,0.17,0.02,0.88,0.05,0.01,0.01
277.4661579617436,0.0232496605469003,266.28923659233,100.0,8.333333333333333e-05,0.61,0.15,0.17,0.02,0.88,0.05,0.01,0.01
281.78876029269,0.0236098774078125,266.529588622997,100.0,8.333333333333333e-05,0.61,0.15,0.17,0.02,0.88,0.05,0.01,0.01
286.060596710712,0.023965863775981,266.64184481044,100.0,8.333333333333333e-05,0.61,0.15,0.17,0.02,0.88,0.05,0.01,0.01
290.30590475363283,0.0243196394462244,266.694110690909,100.0,8.333333333333333e-05,0.61,0.15,0.17,0.02,0.88,0.05,0.01,0.01
294.4873311740652,0.0246680916479271,266.683526449218,100.0,8.333333333333333e-05,0.61,0.15,0.17,0.02,0.88,0.05,0.01,0.01
298.8248349829428,0.0250295502986669,266.787526384047,100.0,8.333333333333333e-05,0.61,0.15,0.17,0.02,0.88,0.05,0.01,0.01
303.051167358342,0.0253817446632835,266.875704216101,100.0,8.333333333333333e-05,0.61,0.15,0.17,0.02,0.88,0.05,0.01,0.01
307.2630460014984,0.0257327345502132,267.010483039028,100.0,8.333333333333333e-05,0.61,0.15,0.17,0.02,0.88,0.05,0.01,0.01
311.475302574096,0.026083755931263,267.108112005533,100.0,8.333333333333333e-05,0.61,0.15,0.17,0.02,0.88,0.05,0.01,0.01
315.5769086130996,0.0264255564345133,267.165415677515,100.0,8.333333333333333e-05,0.61,0.15,0.17,0.02,0.88,0.05,0.01,0.01
319.731682494756,0.026771787591318,267.321663655931,100.0,8.333333333333333e-05,0.61,0.15,0.17,0.02,0.88,0.05,0.01,0.01
323.8441534873572,0.0271144935073681,267.321921115787,100.0,8.333333333333333e-05,0.61,0.15,0.17,0.02,0.88,0.05,0.01,0.01
327.9930166472496,0.0274602321040258,267.493897502091,100.0,8.333333333333333e-05,0.61,0.15,0.17,0.02,0.88,0.05,0.01,0.01
332.1555542919216,0.0278071102410818,267.622684063188,100.0,8.333333333333333e-05,0.61,0.15,0.17,0.02,0.88,0.05,0.01,0.01
336.2488670800356,0.0281482196400913,267.829831279424,100.0,8.333333333333333e-05,0.61,0.15,0.17,0.02,0.88,0.05,0.01,0.01
340.3829406407232,0.0284927257701486,267.967724885591,100.0,8.333333333333333e-05,0.61,0.15,0.17,0.02,0.88,0.05,0.01,0.01
344.4273163450584,0.0288297570788432,267.951844919405,100.0,8.333333333333333e-05,0.61,0.15,0.17,0.02,0.88,0.05,0.01,0.01
348.5741375541972,0.0291753255129381,267.953445255172,100.0,8.333333333333333e-05,0.61,0.15,0.17,0.02,0.88,0.05,0.01,0.01
352.763964134976,0.029524477728003,268.066499039843,100.0,8.333333333333333e-05,0.61,0.15,0.17,0.02,0.88,0.05,0.01,0.01
356.8314357023916,0.0298634336919543,268.247377544212,100.0,8.333333333333333e-05,0.61,0.15,0.17,0.02,0.88,0.05,0.01,0.01
360.906172355952,0.030202995079751,268.506831314055,100.0,8.333333333333333e-05,0.61,0.15,0.17,0.02,0.88,0.05,0.01,0.01
364.9215925795896,0.0305376134317208,268.600712185501,100.0,8.333333333333333e-05,0.61,0.15,0.17,0.02,0.88,0.05,0.01,0.01
369.0719110442604,0.0308834733037767,268.677289042056,100.0,8.333333333333333e-05,0.61,0.15,0.17,0.02,0.88,0.05,0.01,0.01
373.2279545199108,0.0312298102600809,268.700079009975,100.0,8.333333333333333e-05,0.61,0.15,0.17,0.02,0.88,0.05,0.01,0.01
377.4073109778816,0.0315780899649118,268.792187012067,100.0,8.333333333333333e-05,0.61,0.15,0.17,0.02,0.88,0.05,0.01,0.01
381.5966375172648,0.0319272005098604,268.906987202531,100.0,8.333333333333333e-05,0.61,0.15,0.17,0.02,0.88,0.05,0.01,0.01
385.7230264894836,0.0322710662575453,268.990730858296,100.0,8.333333333333333e-05,0.61,0.15,0.17,0.02,0.88,0.05,0.01,0.01
389.7738069795132,0.0326086312983811,269.105297686832,100.0,8.333333333333333e-05,0.61,0.15,0.17,0.02,0.88,0.05,0.01,0.01
393.8048896002288,0.0329445548501074,269.220296543256,100.0,8.333333333333333e-05,0.61,0.15,0.17,0.02,0.88,0.05,0.01,0.01
397.8410183336569,0.0332808989112264,269.234168417194,100.0,8.333333333333333e-05,0.61,0.15,0.17,0.02,0.88,0.05,0.01,0.01
401.891082587652,0.033618404265726,269.432827864081,100.0,8.333333333333333e-05,0.61,0.15,0.17,0.02,0.88,0.05,0.01,0.01
405.9576708658404,0.0339572866222417,269.496398148376,100.0,8.333333333333333e-05,0.61,0.15,0.17,0.02,0.88,0.05,0.01,0.01
410.0573398852824,0.0342989257071952,269.720133144322,100.0,8.333333333333333e-05,0.61,0.15,0.17,0.02,0.88,0.05,0.01,0.01
414.2047217200908,0.0346445408600959,269.878803579474,100.0,8.333333333333333e-05,0.61,0.15,0.17,0.02,0.88,0.05,0.01,0.01
418.2665688463572,0.0349830281206181,269.957501621362,100.0,8.333333333333333e-05,0.61,0.15,0.17,0.02,0.88,0.05,0.01,0.01
422.3759892034872,0.0353254798170456,270.039844711284,100.0,8.333333333333333e-05,0.61,0.15,0.17,0.02,0.88,0.05,0.01,0.01
426.4881110815068,0.0356681566402139,270.114927291338,100.0,8.333333333333333e-05,0.61,0.15,0.17,0.02,0.88,0.05,0.01,0.01
430.568174123874,0.0360081618937445,270.177598476928,100.0,8.333333333333333e-05,0.61,0.15,0.17,0.02,0.88,0.05,0.01,0.01
434.703758670774,0.0363527939393195,270.366662391053,100.0,8.333333333333333e-05,0.61,0.15,0.17,0.02,0.88,0.05,0.01,0.01
438.8597222990976,0.0366991242416798,270.437861230584,100.0,8.333333333333333e-05,0.61,0.15,0.17,0.02,0.88,0.05,0.01,0.01
443.0197476437736,0.0370457930204028,270.554476824506,100.0,8.333333333333333e-05,0.61,0.15,0.17,0.02,0.88,0.05,0.01,0.01
447.25340498765394,0.0373985977990595,270.663045619064,100.0,8.333333333333333e-05,0.61,0.15,0.17,0.02,0.88,0.05,0.01,0.01
451.4116657233061,0.0377451195270305,270.655354185271,100.0,8.333333333333333e-05,0.61,0.15,0.17,0.02,0.88,0.05,0.01,0.01
455.5924558505748,0.0380935187043029,270.77459481307,100.0,8.333333333333333e-05,0.61,0.15,0.17,0.02,0.88,0.05,0.01,0.01
459.8180020878048,0.0384456475574054,270.839090785799,100.0,8.333333333333333e-05,0.61,0.15,0.17,0.02,0.88,0.05,0.01,0.01
464.0807682690095,0.0388008780725058,271.008455748508,100.0,8.333333333333333e-05,0.61,0.15,0.17,0.02,0.88,0.05,0.01,0.01
468.3854570110632,0.0391596021343436,271.121405808005,100.0,8.333333333333333e-05,0.61,0.15,0.17,0.02,0.88,0.05,0.01,0.01
472.6470498862728,0.0395147348739444,271.186207278735,100.0,8.333333333333333e-05,0.61,0.15,0.17,0.02,0.88,0.05,0.01,0.01
476.8218627822384,0.0398626359486082,271.236978724996,100.0,8.333333333333333e-05,0.61,0.15,0.17,0.02,0.88,0.05,0.01,0.01
481.0355976188064,0.0402137805183222,271.281295080981,100.0,8.333333333333333e-05,0.61,0.15,0.17,0.02,0.88,0.05,0.01,0.01
485.2086963933036,0.0405615387495303,271.402927522666,100.0,8.333333333333333e-05,0.61,0.15,0.17,0.02,0.88,0.05,0.01,0.01
489.476824703652,0.040917216108726,271.537299188405,100.0,8.333333333333333e-05,0.61,0.15,0.17,0.02,0.88,0.05,0.01,0.01
493.6872530665356,0.0412680851389663,271.689919025187,100.0,8.333333333333333e-05,0.61,0.15,0.17,0.02,0.88,0.05,0.01,0.01
497.9169108832692,0.0416205566236941,271.767933982315,100.0,8.333333333333333e-05,0.61,0.15,0.17,0.02,0.88,0.05,0.01,0.01
502.1939053164672,0.0419769728264606,271.826086380765,100.0,8.333333333333333e-05,0.61,0.15,0.17,0.02,0.88,0.05,0.01,0.01
506.4844889782944,0.0423345214649462,271.919036091277,100.0,8.333333333333333e-05,0.61,0.15,0.17,0.02,0.88,0.05,0.01,0.01
510.788907684666,0.0426932230238105,271.942821975424,100.0,8.333333333333333e-05,0.61,0.15,0.17,0.02,0.88,0.05,0.01,0.01
515.0909334525048,0.0430517251711304,271.958547434155,100.0,8.333333333333333e-05,0.61,0.15,0.17,0.02,0.88,0.05,0.01,0.01
519.325611009708,0.043404614967564,272.05025922406,100.0,8.333333333333333e-05,0.61,0.15,0.17,0.02,0.88,0.05,0.01,0.01
523.561236856392,0.043757583788121,272.176375709605,100.0,8.333333333333333e-05,0.61,0.15,0.17,0.02,0.88,0.05,0.01,0.01
527.8640419769976,0.0441161508815048,272.274439511218,100.0,8.333333333333333e-05,0.61,0.15,0.17,0.02,0.88,0.05,0.01,0.01
532.084320768234,0.0444678407807745,272.313449497354,100.0,8.333333333333333e-05,0.61,0.15,0.17,0.02,0.88,0.05,0.01,0.01
536.4897271333907,0.0448349579778709,272.447580767345,100.0,8.333333333333333e-05,0.61,0.15,0.17,0.02,0.88,0.05,0.01,0.01
540.8372435438868,0.0451972510120789,272.507620216427,100.0,8.333333333333333e-05,0.61,0.15,0.17,0.02,0.88,0.05,0.01,0.01
545.273975678694,0.0455669786899795,272.625848967852,100.0,8.333333333333333e-05,0.61,0.15,0.17,0.02,0.88,0.05,0.01,0.01
549.7350926978148,0.0459387384415729,272.694060831473,100.0,8.333333333333333e-05,0.61,0.15,0.17,0.02,0.88,0.05,0.01,0.01
554.0795026050288,0.0463007726005074,272.780778483702,100.0,8.333333333333333e-05,0.61,0.15,0.17,0.02,0.88,0.05,0.01,0.01
558.482935266216,0.046667725322273,272.880248828328,100.0,8.333333333333333e-05,0.61,0.15,0.17,0.02,0.88,0.05,0.01,0.01
562.7833088026944,0.0470260897836462,272.878038789773,100.0,8.333333333333333e-05,0.61,0.15,0.17,0.02,0.88,0.05,0.01,0.01
567.085301765226,0.0473845891971905,272.962903961172,100.0,8.333333333333333e-05,0.61,0.15,0.17,0.02,0.88,0.05,0.01,0.01
571.4943836259084,0.0477520126855807,273.030148375029,100.0,8.333333333333333e-05,0.61,0.15,0.17,0.02,0.88,0.05,0.01,0.01
575.8729656223404,0.0481168945186167,273.174765665579,100.0,8.333333333333333e-05,0.61,0.15,0.17,0.02,0.88,0.05,0.01,0.01
580.3128533904083,0.0484868851659557,273.282385131133,100.0,8.333333333333333e-05,0.61,0.15,0.17,0.02,0.88,0.05,0.01,0.01
584.7870810641497,0.0488597374721008,273.391093892382,100.0,8.333333333333333e-05,0.61,0.15,0.17,0.02,0.88,0.05,0.01,0.01
589.2848696448324,0.0492345531871577,273.459539906476,100.0,8.333333333333333e-05,0.61,0.15,0.17,0.02,0.88,0.05,0.01,0.01
593.6979777013704,0.0496023121918692,273.480507105929,100.0,8.333333333333333e-05,0.61,0.15,0.17,0.02,0.88,0.05,0.01,0.01
598.2153319668864,0.0499787583806622,273.49255107009,100.0,8.333333333333333e-05,0.61,0.15,0.17,0.02,0.88,0.05,0.01,0.01
602.7881005746708,0.0503598224313109,273.531906281111,100.0,8.333333333333333e-05,0.61,0.15,0.17,0.02,0.88,0.05,0.01,0.01
607.2131375604204,0.0507285755134567,273.58329872212,100.0,8.333333333333333e-05,0.61,0.15,0.17,0.02,0.88,0.05,0.01,0.01
611.7435803264268,0.0511061124106239,273.675621791903,100.0,8.333333333333333e-05,0.61,0.15,0.17,0.02,0.88,0.05,0.01,0.01
616.2649797414829,0.0514828956952119,273.765809451005,100.0,8.333333333333333e-05,0.61,0.15,0.17,0.02,0.88,0.05,0.01,0.01
620.7707895486805,0.0518583798458117,273.860579406639,100.0,8.333333333333333e-05,0.61,0.15,0.17,0.02,0.88,0.05,0.01,0.01
625.3356410452536,0.0522387841371928,274.004388943506,100.0,8.333333333333333e-05,0.61,0.15,0.17,0.02,0.88,0.05,0.01,0.01
629.8583871824004,0.0526156796486217,274.003707120416,100.0,8.333333333333333e-05,0.61,0.15,0.17,0.02,0.88,0.05,0.01,0.01
634.289810505324,0.052984964925532,274.049910810909,100.0,8.333333333333333e-05,0.61,0.15,0.17,0.02,0.88,0.05,0.01,0.01
638.8581701311883,0.0533656615610207,274.070623357726,100.0,8.333333333333333e-05,0.61,0.15,0.17,0.02,0.88,0.05,0.01,0.01
643.2553514067828,0.0537320933339869,274.115286184496,100.0,8.333333333333333e-05,0.61,0.15,0.17,0.02,0.88,0.05,0.01,0.01
647.7913837217616,0.0541100960269018,274.17529464377,100.0,8.333333333333333e-05,0.61,0.15,0.17,0.02,0.88,0.05,0.01,0.01
652.317578791542,0.0544872789493835,274.276401612991,100.0,8.333333333333333e-05,0.61,0.15,0.17,0.02,0.88,0.05,0.01,0.01
656.8439646951564,0.0548644777746847,274.343911640257,100.0,8.333333333333333e-05,0.61,0.15,0.17,0.02,0.88,0.05,0.01,0.01
661.4448087550668,0.0552478814463439,274.438680176511,100.0,8.333333333333333e-05,0.61,0.15,0.17,0.02,0.88,0.05,0.01,0.01
666.0156931216512,0.0556287884768926,274.487248775744,100.0,8.333333333333333e-05,0.61,0.15,0.17,0.02,0.88,0.05,0.01,0.01
670.566190097892,0.056007996558246,274.573533280351,100.0,8.333333333333333e-05,0.61,0.15,0.17,0.02,0.88,0.05,0.01,0.01
675.2784736441524,0.0564006868537677,274.655623121246,100.0,8.333333333333333e-05,0.61,0.15,0.17,0.02,0.88,0.05,0.01,0.01
680.03322018861,0.0567969157324725,274.726391809625,100.0,8.333333333333333e-05,0.61,0.15,0.17,0.02,0.88,0.05,0.01,0.01
684.7982326363368,0.0571940001031164,274.807089837522,100.0,8.333333333333333e-05,0.61,0.15,0.17,0.02,0.88,0.05,0.01,0.01
689.5923318049596,0.0575935083671683,274.860484598633,100.0,8.333333333333333e-05,0.61,0.15,0.17,0.02,0.88,0.05,0.01,0.01
694.3482271878648,0.0579898329824104,274.907143310979,100.0,8.333333333333333e-05,0.61,0.15,0.17,0.02,0.88,0.05,0.01,0.01
699.1710624818484,0.0583917359235757,274.917341701961,100.0,8.333333333333333e-05,0.61,0.15,0.17,0.02,0.88,0.05,0.01,0.01
703.991722241298,0.0587934575701965,274.944039618727,100.0,8.333333333333333e-05,0.61,0.15,0.17,0.02,0.88,0.05,0.01,0.01
708.652356250866,0.0591818437376605,274.987964935378,100.0,8.333333333333333e-05,0.61,0.15,0.17,0.02,0.88,0.05,0.01,0.01
713.4462499578384,0.0595813348799082,275.04545035115,100.0,8.333333333333333e-05,0.61,0.15,0.17,0.02,0.88,0.05,0.01,0.01
718.1656861837656,0.0599746212320688,275.062347350793,100.0,8.333333333333333e-05,0.61,0.15,0.17,0.02,0.88,0.05,0.01,0.01
722.9245482280679,0.060371193069094,275.052773234906,100.0,8.333333333333333e-05,0.61,0.15,0.17,0.02,0.88,0.05,0.01,0.01
727.8601886076565,0.0607824964340597,275.10518974319,100.0,8.333333333333333e-05,0.61,0.15,0.17,0.02,0.88,0.05,0.01,0.01
732.7143257919145,0.0611870078660812,275.059117140374,100.0,8.333333333333333e-05,0.61,0.15,0.17,0.02,0.88,0.05,0.01,0.01
737.5415492931924,0.0615892764911877,275.082684487233,100.0,8.333333333333333e-05,0.61,0.15,0.17,0.02,0.88,0.05,0.01,0.01
742.4217169944432,0.0619959571329586,275.157100100381,100.0,8.333333333333333e-05,0.61,0.15,0.17,0.02,0.88,0.05,0.01,0.01
747.2977382484672,0.0624022922374606,275.163660634858,100.0,8.333333333333333e-05,0.61,0.15,0.17,0.02,0.88,0.05,0.01,0.01
752.2124659481328,0.0628118528790994,275.256446880047,100.0,8.333333333333333e-05,0.61,0.15,0.17,0.02,0.88,0.05,0.01,0.01
757.1388236672448,0.0632223826890254,275.199653601529,100.0,8.333333333333333e-05,0.61,0.15,0.17,0.02,0.88,0.05,0.01,0.01
762.1033128845569,0.0636360901238014,275.138842246007,100.0,8.333333333333333e-05,0.61,0.15,0.17,0.02,0.88,0.05,0.01,0.01
767.1845319172884,0.0640595250431957,275.130643998743,100.0,8.333333333333333e-05,0.61,0.15,0.17,0.02,0.88,0.05,0.01,0.01
772.1307387320579,0.0644717089444265,275.150308695776,100.0,8.333333333333333e-05,0.61,0.15,0.17,0.02,0.88,0.05,0.01,0.01
777.2151882257388,0.0648954130688999,275.177682032648,100.0,8.333333333333333e-05,0.61,0.15,0.17,0.02,0.88,0.05,0.01,0.01
782.28668515473,0.0653180378129825,275.264761642681,100.0,8.333333333333333e-05,0.61,0.15,0.17,0.02,0.88,0.05,0.01,0.01
787.5526372548612,0.0657568671546601,275.343401663448,100.0,8.333333333333333e-05,0.61,0.15,0.17,0.02,0.88,0.05,0.01,0.01
792.7754370599977,0.0661921004717548,275.422362968882,100.0,8.333333333333333e-05,0.61,0.15,0.17,0.02,0.88,0.05,0.01,0.01
798.1605933167449,0.0666408634931504,275.460161024846,100.0,8.333333333333333e-05,0.61,0.15,0.17,0.02,0.88,0.05,0.01,0.01
800.8314825635221,0.0668634375970485,275.464486634296,100.0,8.333333333333333e-05,0.61,0.15,0.17,0.02,0.88,0.05,0.01,0.01