File: datasets/al_6061_comp/csv/T_100_D_2.csv
Time,Strain(%),Stress(MPa),Temp(C),SR(%/s),Si(%),Fe(%),Cu(%),Mn(%),Mg(%),Cr(%),Zn(%),Ti(%)
0.0,0.0001207201184842,57.0694127931744,100.0,8.333333333333333e-05,0.67,0.28,0.23,0.05,0.9,0.05,0.03,0.02
0.3641325347184001,0.0001510644963774,59.2624167046206,100.0,8.333333333333333e-05,0.67,0.28,0.23,0.05,0.9,0.05,0.03,0.02
0.8728657307076,0.0001934589293765,61.442129929212,100.0,8.333333333333333e-05,0.67,0.28,0.23,0.05,0.9,0.05,0.03,0.02
1.3780266193176005,0.000235555670094,63.6574117369541,100.0,8.333333333333333e-05,0.67,0.28,0.23,0.05,0.9,0.05,0.03,0.02
1.9032184594716004,0.0002793216567735,65.8605633557733,100.0,8.333333333333333e-05,0.67,0.28,0.23,0.05,0.9,0.05,0.03,0.02
2.430594248178,0.0003232696391657,68.0725359219461,100.0,8.333333333333333e-05,0.67,0.28,0.23,0.05,0.9,0.05,0.03,0.02
3.036795118638,0.0003737863783707,70.2761256311973,100.0,8.333333333333333e-05,0.67,0.28,0.23,0.05,0.9,0.05,0.03,0.02
3.5787923997911992,0.0004189528184668,72.4795062258331,100.0,8.333333333333333e-05,0.67,0.28,0.23,0.05,0.9,0.05,0.03,0.02
4.1427292022964,0.0004659475520089,74.7207773210431,100.0,8.333333333333333e-05,0.67,0.28,0.23,0.05,0.9,0.05,0.03,0.02
4.5313822056504,0.0004983353022884,76.9870228281163,100.0,8.333333333333333e-05,0.67,0.28,0.23,0.05,0.9,0.05,0.03,0.02
5.0726995393608005,0.0005434450800976,79.2349385438059,100.0,8.333333333333333e-05,0.67,0.28,0.23,0.05,0.9,0.05,0.03,0.02
5.6283231616728,0.0005897470486236,81.5188120745233,100.0,8.333333333333333e-05,0.67,0.28,0.23,0.05,0.9,0.05,0.03,0.02
6.162758372274,0.0006342833161737,83.8170631764712,100.0,8.333333333333333e-05,0.67,0.28,0.23,0.05,0.9,0.05,0.03,0.02
6.582604336277999,0.0006692704798407,86.1371858939828,100.0,8.333333333333333e-05,0.67,0.28,0.23,0.05,0.9,0.05,0.03,0.02
7.0787664611616,0.000710617323581,88.4336642645545,100.0,8.333333333333333e-05,0.67,0.28,0.23,0.05,0.9,0.05,0.03,0.02
7.572831789361199,0.0007517894342643,90.7062109839938,100.0,8.333333333333333e-05,0.67,0.28,0.23,0.05,0.9,0.05,0.03,0.02
8.3266933466064,0.0008146112307014,92.9960114626015,100.0,8.333333333333333e-05,0.67,0.28,0.23,0.05,0.9,0.05,0.03,0.02
8.8627802996124,0.0008592851434519,95.2862149011486,100.0,8.333333333333333e-05,0.67,0.28,0.23,0.05,0.9,0.05,0.03,0.02
9.3762204307452,0.0009020718210463,97.5353018239297,100.0,8.333333333333333e-05,0.67,0.28,0.23,0.05,0.9,0.05,0.03,0.02
9.8995824759192,0.0009456853248108,99.7880158310556,100.0,8.333333333333333e-05,0.67,0.28,0.23,0.05,0.9,0.05,0.03,0.02
10.466022110779202,0.0009928886277158,102.010549455921,100.0,8.333333333333333e-05,0.67,0.28,0.23,0.05,0.9,0.05,0.03,0.02
11.013883177458,0.0010385437166057,104.224625053191,100.0,8.333333333333333e-05,0.67,0.28,0.23,0.05,0.9,0.05,0.03,0.02
11.6058245371464,0.0010878721632464,106.429388654768,100.0,8.333333333333333e-05,0.67,0.28,0.23,0.05,0.9,0.05,0.03,0.02
12.1240243530252,0.0011310554812363,108.640946280725,100.0,8.333333333333333e-05,0.67,0.28,0.23,0.05,0.9,0.05,0.03,0.02
12.680671099974,0.0011774427101487,110.840493027967,100.0,8.333333333333333e-05,0.67,0.28,0.23,0.05,0.9,0.05,0.03,0.02
13.2031792345956,0.0012209850547005,113.052165054442,100.0,8.333333333333333e-05,0.67,0.28,0.23,0.05,0.9,0.05,0.03,0.02
13.7853689291664,0.0012695008625814,115.22074377185,100.0,8.333333333333333e-05,0.67,0.28,0.23,0.05,0.9,0.05,0.03,0.02
14.305281870972,0.0013128269410652,117.373120007304,100.0,8.333333333333333e-05,0.67,0.28,0.23,0.05,0.9,0.05,0.03,0.02
14.8105693427472,0.0013549342303798,119.508445480955,100.0,8.333333333333333e-05,0.67,0.28,0.23,0.05,0.9,0.05,0.03,0.02
15.264735043344,0.0013927813720962,121.616533080806,100.0,8.333333333333333e-05,0.67,0.28,0.23,0.05,0.9,0.05,0.03,0.02
15.7289696095944,0.0014314675859504,123.743021686364,100.0,8.333333333333333e-05,0.67,0.28,0.23,0.05,0.9,0.05,0.03,0.02
16.238376760572002,0.0014739181818652,125.825890120798,100.0,8.333333333333333e-05,0.67,0.28,0.23,0.05,0.9,0.05,0.03,0.02
16.7643981934368,0.0015177533012706,127.921132385482,100.0,8.333333333333333e-05,0.67,0.28,0.23,0.05,0.9,0.05,0.03,0.02
17.185270654794,0.0015528260063837,130.013376641564,100.0,8.333333333333333e-05,0.67,0.28,0.23,0.05,0.9,0.05,0.03,0.02
17.707546164852,0.0015963489655552,132.113762496584,100.0,8.333333333333333e-05,0.67,0.28,0.23,0.05,0.9,0.05,0.03,0.02
18.1125328503312,0.0016300978560118,134.208358795559,100.0,8.333333333333333e-05,0.67,0.28,0.23,0.05,0.9,0.05,0.03,0.02
18.6458003509752,0.0016745368143988,136.321133734232,100.0,8.333333333333333e-05,0.67,0.28,0.23,0.05,0.9,0.05,0.03,0.02
19.1273668538052,0.0017146673563013,138.36056214658,100.0,8.333333333333333e-05,0.67,0.28,0.23,0.05,0.9,0.05,0.03,0.02
19.649569311408,0.0017581842277682,140.418872698262,100.0,8.333333333333333e-05,0.67,0.28,0.23,0.05,0.9,0.05,0.03,0.02
20.1050366556528,0.0017961398397886,142.439334521449,100.0,8.333333333333333e-05,0.67,0.28,0.23,0.05,0.9,0.05,0.03,0.02
20.6455632258936,0.001841183720642,144.445290327044,100.0,8.333333333333333e-05,0.67,0.28,0.23,0.05,0.9,0.05,0.03,0.02
21.092185289526,0.0018784022259447,146.4381278569,100.0,8.333333333333333e-05,0.67,0.28,0.23,0.05,0.9,0.05,0.03,0.02
21.660650962878,0.0019257743653907,148.431007937394,100.0,8.333333333333333e-05,0.67,0.28,0.23,0.05,0.9,0.05,0.03,0.02
22.101168311468403,0.0019624841444399,150.407627239335,100.0,8.333333333333333e-05,0.67,0.28,0.23,0.05,0.9,0.05,0.03,0.02
22.6520150866716,0.0020083880423735,152.378921562562,100.0,8.333333333333333e-05,0.67,0.28,0.23,0.05,0.9,0.05,0.03,0.02
23.072134200675603,0.0020433979685405,154.346824704847,100.0,8.333333333333333e-05,0.67,0.28,0.23,0.05,0.9,0.05,0.03,0.02
23.544452276794804,0.0020827578082171,156.318271101319,100.0,8.333333333333333e-05,0.67,0.28,0.23,0.05,0.9,0.05,0.03,0.02
23.9871255205224,0.0021196472451944,158.253543179782,100.0,8.333333333333333e-05,0.67,0.28,0.23,0.05,0.9,0.05,0.03,0.02
24.4642326057756,0.0021594061689655,160.190897792581,100.0,8.333333333333333e-05,0.67,0.28,0.23,0.05,0.9,0.05,0.03,0.02
24.928746760753203,0.0021981156818803,162.093835517677,100.0,8.333333333333333e-05,0.67,0.28,0.23,0.05,0.9,0.05,0.03,0.02
25.4522875832904,0.0022417440837584,163.988809917977,100.0,8.333333333333333e-05,0.67,0.28,0.23,0.05,0.9,0.05,0.03,0.02
25.870999241948404,0.0022766367219799,165.861599245291,100.0,8.333333333333333e-05,0.67,0.28,0.23,0.05,0.9,0.05,0.03,0.02
26.3854097573904,0.0023195042649334,167.731683238665,100.0,8.333333333333333e-05,0.67,0.28,0.23,0.05,0.9,0.05,0.03,0.02
26.9159370299448,0.0023637148709796,169.586178095755,100.0,8.333333333333333e-05,0.67,0.28,0.23,0.05,0.9,0.05,0.03,0.02
27.3704225937876,0.0024015886679665,171.442820266477,100.0,8.333333333333333e-05,0.67,0.28,0.23,0.05,0.9,0.05,0.03,0.02
27.8156532486012,0.0024386912225343,173.264267212853,100.0,8.333333333333333e-05,0.67,0.28,0.23,0.05,0.9,0.05,0.03,0.02
28.3210067972484,0.0024808040182549,175.06403653199,100.0,8.333333333333333e-05,0.67,0.28,0.23,0.05,0.9,0.05,0.03,0.02
28.7647120349916,0.0025177794547335,176.870831854337,100.0,8.333333333333333e-05,0.67,0.28,0.23,0.05,0.9,0.05,0.03,0.02
29.237244841074,0.0025571571885737,178.686367281004,100.0,8.333333333333333e-05,0.67,0.28,0.23,0.05,0.9,0.05,0.03,0.02
29.674602799890003,0.0025936036851417,180.47400515599,100.0,8.333333333333333e-05,0.67,0.28,0.23,0.05,0.9,0.05,0.03,0.02
30.1223478537756,0.0026309157729655,182.275747661634,100.0,8.333333333333333e-05,0.67,0.28,0.23,0.05,0.9,0.05,0.03,0.02
30.6208262923584,0.0026724556428474,184.108420222496,100.0,8.333333333333333e-05,0.67,0.28,0.23,0.05,0.9,0.05,0.03,0.02
31.187491935825605,0.002719677779803,185.923507771131,100.0,8.333333333333333e-05,0.67,0.28,0.23,0.05,0.9,0.05,0.03,0.02
31.6532856488136,0.002758493922552,187.747334645527,100.0,8.333333333333333e-05,0.67,0.28,0.23,0.05,0.9,0.05,0.03,0.02
32.1597318245496,0.00280069777053,189.568081730839,100.0,8.333333333333333e-05,0.67,0.28,0.23,0.05,0.9,0.05,0.03,0.02
32.6498245978896,0.002841538834975,191.39202443576,100.0,8.333333333333333e-05,0.67,0.28,0.23,0.05,0.9,0.05,0.03,0.02
33.134884942962,0.0028819605303977,193.205425609522,100.0,8.333333333333333e-05,0.67,0.28,0.23,0.05,0.9,0.05,0.03,0.02
33.6571459784928,0.0029254822833586,195.001335229925,100.0,8.333333333333333e-05,0.67,0.28,0.23,0.05,0.9,0.05,0.03,0.02
34.163192812056,0.0029676528528222,196.759050362153,100.0,8.333333333333333e-05,0.67,0.28,0.23,0.05,0.9,0.05,0.03,0.02
34.5530655893844,0.0030001422509329,198.532253942318,100.0,8.333333333333333e-05,0.67,0.28,0.23,0.05,0.9,0.05,0.03,0.02
34.996123719223206,0.0030370637617528,200.323117848384,100.0,8.333333333333333e-05,0.67,0.28,0.23,0.05,0.9,0.05,0.03,0.02
35.465679069576,0.0030761933742822,202.074357768234,100.0,8.333333333333333e-05,0.67,0.28,0.23,0.05,0.9,0.05,0.03,0.02
35.9734218729132,0.0031185052745603,203.801281524096,100.0,8.333333333333333e-05,0.67,0.28,0.23,0.05,0.9,0.05,0.03,0.02
36.4869437899668,0.0031612987676481,205.551753355684,100.0,8.333333333333333e-05,0.67,0.28,0.23,0.05,0.9,0.05,0.03,0.02
36.9467720501724,0.0031996177893319,207.262118510309,100.0,8.333333333333333e-05,0.67,0.28,0.23,0.05,0.9,0.05,0.03,0.02
37.384770628363206,0.0032361176708478,209.017958332029,100.0,8.333333333333333e-05,0.67,0.28,0.23,0.05,0.9,0.05,0.03,0.02
37.9145584856436,0.0032802666589545,210.749917410847,100.0,8.333333333333333e-05,0.67,0.28,0.23,0.05,0.9,0.05,0.03,0.02
38.4654378651792,0.0033261732739158,212.47254510944,100.0,8.333333333333333e-05,0.67,0.28,0.23,0.05,0.9,0.05,0.03,0.02
38.9396728414944,0.0033656928552754,214.196034974834,100.0,8.333333333333333e-05,0.67,0.28,0.23,0.05,0.9,0.05,0.03,0.02
39.450259042904406,0.0034082417053929,215.935952214536,100.0,8.333333333333333e-05,0.67,0.28,0.23,0.05,0.9,0.05,0.03,0.02
39.9556684440096,0.003450359155485,217.655325838032,100.0,8.333333333333333e-05,0.67,0.28,0.23,0.05,0.9,0.05,0.03,0.02
40.481556222516,0.0034941831370272,219.360240713597,100.0,8.333333333333333e-05,0.67,0.28,0.23,0.05,0.9,0.05,0.03,0.02
41.0767547976804,0.0035437830182909,221.014834407634,100.0,8.333333333333333e-05,0.67,0.28,0.23,0.05,0.9,0.05,0.03,0.02
41.5452372412152,0.0035828232219188,222.653462015678,100.0,8.333333333333333e-05,0.67,0.28,0.23,0.05,0.9,0.05,0.03,0.02
42.1032514111116,0.0036293244027435,224.243420274468,100.0,8.333333333333333e-05,0.67,0.28,0.23,0.05,0.9,0.05,0.03,0.02
42.7383715127868,0.0036822510778831,225.806090561564,100.0,8.333333333333333e-05,0.67,0.28,0.23,0.05,0.9,0.05,0.03,0.02
43.2837131862684,0.0037276962173399,227.322014095461,100.0,8.333333333333333e-05,0.67,0.28,0.23,0.05,0.9,0.05,0.03,0.02
43.8828351751476,0.0037776230497465,228.786448211975,100.0,8.333333333333333e-05,0.67,0.28,0.23,0.05,0.9,0.05,0.03,0.02
44.543535079596005,0.0038326813751172,230.247775130948,100.0,8.333333333333333e-05,0.67,0.28,0.23,0.05,0.9,0.05,0.03,0.02
45.14143084242,0.0038825060220192,231.640352565452,100.0,8.333333333333333e-05,0.67,0.28,0.23,0.05,0.9,0.05,0.03,0.02
45.8470080529896,0.0039413041229,232.988828726981,100.0,8.333333333333333e-05,0.67,0.28,0.23,0.05,0.9,0.05,0.03,0.02
46.5536617633476,0.0040001919320965,234.319835404919,100.0,8.333333333333333e-05,0.67,0.28,0.23,0.05,0.9,0.05,0.03,0.02
47.299733743570805,0.0040623645971151,235.565594645316,100.0,8.333333333333333e-05,0.67,0.28,0.23,0.05,0.9,0.05,0.03,0.02
48.1380344739384,0.0041322229913124,236.756019117327,100.0,8.333333333333333e-05,0.67,0.28,0.23,0.05,0.9,0.05,0.03,0.02
48.967093033447206,0.0042013112046048,237.937982892398,100.0,8.333333333333333e-05,0.67,0.28,0.23,0.05,0.9,0.05,0.03,0.02
49.8520784627676,0.0042750599903815,239.042923721574,100.0,8.333333333333333e-05,0.67,0.28,0.23,0.05,0.9,0.05,0.03,0.02
50.8325220552096,0.004356763623085,240.11018901193,100.0,8.333333333333333e-05,0.67,0.28,0.23,0.05,0.9,0.05,0.03,0.02
52.0185846405876,0.0044556021718665,241.133667265292,100.0,8.333333333333333e-05,0.67,0.28,0.23,0.05,0.9,0.05,0.03,0.02
53.2693496693928,0.0045598325909336,242.067081183704,100.0,8.333333333333333e-05,0.67,0.28,0.23,0.05,0.9,0.05,0.03,0.02
54.6452169804168,0.0046744882001856,243.010688204249,100.0,8.333333333333333e-05,0.67,0.28,0.23,0.05,0.9,0.05,0.03,0.02
56.166080856348,0.0048012268565132,243.879548181894,100.0,8.333333333333333e-05,0.67,0.28,0.23,0.05,0.9,0.05,0.03,0.02
58.0008457567068,0.0049541239315431,244.605053171032,100.0,8.333333333333333e-05,0.67,0.28,0.23,0.05,0.9,0.05,0.03,0.02
59.8253283605544,0.0051061641485304,245.262730267216,100.0,8.333333333333333e-05,0.67,0.28,0.23,0.05,0.9,0.05,0.03,0.02
61.9012887153492,0.0052791608447633,245.826502253468,100.0,8.333333333333333e-05,0.67,0.28,0.23,0.05,0.9,0.05,0.03,0.02
64.04721211472162,0.005457987794711,246.312966214088,100.0,8.333333333333333e-05,0.67,0.28,0.23,0.05,0.9,0.05,0.03,0.02
66.30977131562881,0.0056465343947866,246.748266973583,100.0,8.333333333333333e-05,0.67,0.28,0.23,0.05,0.9,0.05,0.03,0.02
68.64228762081962,0.0058409107535525,247.080048355859,100.0,8.333333333333333e-05,0.67,0.28,0.23,0.05,0.9,0.05,0.03,0.02
71.05415947780801,0.0060419000749682,247.359740067585,100.0,8.333333333333333e-05,0.67,0.28,0.23,0.05,0.9,0.05,0.03,0.02
73.4509401602328,0.0062416317985036,247.624299339434,100.0,8.333333333333333e-05,0.67,0.28,0.23,0.05,0.9,0.05,0.03,0.02
76.0918923551292,0.0064617111480783,247.857608822504,100.0,8.333333333333333e-05,0.67,0.28,0.23,0.05,0.9,0.05,0.03,0.02
78.6936791393076,0.0066785267134265,248.066898423041,100.0,8.333333333333333e-05,0.67,0.28,0.23,0.05,0.9,0.05,0.03,0.02
81.3274241707344,0.0068980054660454,248.234224435525,100.0,8.333333333333333e-05,0.67,0.28,0.23,0.05,0.9,0.05,0.03,0.02
84.03482442807721,0.0071236221541573,248.367545513397,100.0,8.333333333333333e-05,0.67,0.28,0.23,0.05,0.9,0.05,0.03,0.02
86.79163847349962,0.0073533566579425,248.543187093052,100.0,8.333333333333333e-05,0.67,0.28,0.23,0.05,0.9,0.05,0.03,0.02
89.5439933832048,0.0075827195670846,248.704748940051,100.0,8.333333333333333e-05,0.67,0.28,0.23,0.05,0.9,0.05,0.03,0.02
92.297209377576,0.0078121542332822,248.839279040741,100.0,8.333333333333333e-05,0.67,0.28,0.23,0.05,0.9,0.05,0.03,0.02
95.04549503222404,0.0080411780378362,248.964748493212,100.0,8.333333333333333e-05,0.67,0.28,0.23,0.05,0.9,0.05,0.03,0.02
97.8835314711624,0.0082776810744144,249.107721797098,100.0,8.333333333333333e-05,0.67,0.28,0.23,0.05,0.9,0.05,0.03,0.02
100.699773588126,0.0085123679174947,249.25723715822,100.0,8.333333333333333e-05,0.67,0.28,0.23,0.05,0.9,0.05,0.03,0.02
103.486368525798,0.0087445841623007,249.433181772139,100.0,8.333333333333333e-05,0.67,0.28,0.23,0.05,0.9,0.05,0.03,0.02
106.3194272045148,0.0089806723855271,249.534935822237,100.0,8.333333333333333e-05,0.67,0.28,0.23,0.05,0.9,0.05,0.03,0.02
109.2103885504344,0.0092215858310204,249.634119721674,100.0,8.333333333333333e-05,0.67,0.28,0.23,0.05,0.9,0.05,0.03,0.02
112.0640072520888,0.0094593873894916,249.760153359372,100.0,8.333333333333333e-05,0.67,0.28,0.23,0.05,0.9,0.05,0.03,0.02
114.9612058079556,0.0097008206024805,249.893402412583,100.0,8.333333333333333e-05,0.67,0.28,0.23,0.05,0.9,0.05,0.03,0.02
117.8088043112376,0.009938120477754,250.000653677733,100.0,8.333333333333333e-05,0.67,0.28,0.23,0.05,0.9,0.05,0.03,0.02
120.732755067678,0.0101817830407907,250.121141861493,100.0,8.333333333333333e-05,0.67,0.28,0.23,0.05,0.9,0.05,0.03,0.02
123.55273502868,0.0104167813708742,250.21345941,100.0,8.333333333333333e-05,0.67,0.28,0.23,0.05,0.9,0.05,0.03,0.02
126.40364018890682,0.0106543568008931,250.334786451455,100.0,8.333333333333333e-05,0.67,0.28,0.23,0.05,0.9,0.05,0.03,0.02
129.1474435125792,0.0108830070778658,250.452759206137,100.0,8.333333333333333e-05,0.67,0.28,0.23,0.05,0.9,0.05,0.03,0.02
131.9356533972852,0.0111153579015913,250.569842512672,100.0,8.333333333333333e-05,0.67,0.28,0.23,0.05,0.9,0.05,0.03,0.02
134.603112370692,0.0113376461493752,250.689046042159,100.0,8.333333333333333e-05,0.67,0.28,0.23,0.05,0.9,0.05,0.03,0.02
137.209713985218,0.0115548629505857,250.809737366286,100.0,8.333333333333333e-05,0.67,0.28,0.23,0.05,0.9,0.05,0.03,0.02
139.866686338878,0.0117762773133907,250.944314275855,100.0,8.333333333333333e-05,0.67,0.28,0.23,0.05,0.9,0.05,0.03,0.02
142.6486005162852,0.0120081034948413,251.105426211035,100.0,8.333333333333333e-05,0.67,0.28,0.23,0.05,0.9,0.05,0.03,0.02
145.2202497642972,0.0122224075988423,251.227924777361,100.0,8.333333333333333e-05,0.67,0.28,0.23,0.05,0.9,0.05,0.03,0.02
147.80300550092878,0.0124376372435616,251.352630399811,100.0,8.333333333333333e-05,0.67,0.28,0.23,0.05,0.9,0.05,0.03,0.02
150.3977227442496,0.012653863680505,251.468011569623,100.0,8.333333333333333e-05,0.67,0.28,0.23,0.05,0.9,0.05,0.03,0.02
153.0245755150236,0.0128727680780695,251.560503404143,100.0,8.333333333333333e-05,0.67,0.28,0.23,0.05,0.9,0.05,0.03,0.02
155.7627197141676,0.0131009467613315,251.645193901825,100.0,8.333333333333333e-05,0.67,0.28,0.23,0.05,0.9,0.05,0.03,0.02
158.3665911858696,0.01331793605064,251.737632476547,100.0,8.333333333333333e-05,0.67,0.28,0.23,0.05,0.9,0.05,0.03,0.02
160.9048495949292,0.0135294575847283,251.81851764752,100.0,8.333333333333333e-05,0.67,0.28,0.23,0.05,0.9,0.05,0.03,0.02
163.5777573555036,0.0137521998981095,251.917731497648,100.0,8.333333333333333e-05,0.67,0.28,0.23,0.05,0.9,0.05,0.03,0.02
166.3009562403156,0.0139791331385105,252.028251805296,100.0,8.333333333333333e-05,0.67,0.28,0.23,0.05,0.9,0.05,0.03,0.02
168.977646152592,0.0142021906312002,252.141313727031,100.0,8.333333333333333e-05,0.67,0.28,0.23,0.05,0.9,0.05,0.03,0.02
171.55921045398122,0.0144173209896493,252.25067669865,100.0,8.333333333333333e-05,0.67,0.28,0.23,0.05,0.9,0.05,0.03,0.02
174.038737433646,0.0146239482379547,252.397824255029,100.0,8.333333333333333e-05,0.67,0.28,0.23,0.05,0.9,0.05,0.03,0.02
176.5864538256672,0.0148362579372898,252.507769048621,100.0,8.333333333333333e-05,0.67,0.28,0.23,0.05,0.9,0.05,0.03,0.02
179.1765677569572,0.0150521007648973,252.628862077459,100.0,8.333333333333333e-05,0.67,0.28,0.23,0.05,0.9,0.05,0.03,0.02
181.6595136721248,0.0152590129244946,252.745270897601,100.0,8.333333333333333e-05,0.67,0.28,0.23,0.05,0.9,0.05,0.03,0.02
184.1042530031352,0.0154627412020788,252.860610454224,100.0,8.333333333333333e-05,0.67,0.28,0.23,0.05,0.9,0.05,0.03,0.02
186.5368019329596,0.0156654536128975,252.955804651449,100.0,8.333333333333333e-05,0.67,0.28,0.23,0.05,0.9,0.05,0.03,0.02
189.027502442748,0.0158730119887132,253.055861283846,100.0,8.333333333333333e-05,0.67,0.28,0.23,0.05,0.9,0.05,0.03,0.02
191.5146230223264,0.0160802720370114,253.131166982616,100.0,8.333333333333333e-05,0.67,0.28,0.23,0.05,0.9,0.05,0.03,0.02
193.912744860048,0.0162801155234882,253.202135010928,100.0,8.333333333333333e-05,0.67,0.28,0.23,0.05,0.9,0.05,0.03,0.02
196.2714453275484,0.0164766738957799,253.185606964163,100.0,8.333333333333333e-05,0.67,0.28,0.23,0.05,0.9,0.05,0.03,0.02
198.7513160450916,0.0166833297889085,253.305465118843,100.0,8.333333333333333e-05,0.67,0.28,0.23,0.05,0.9,0.05,0.03,0.02
201.2060514312528,0.0168878910710886,253.344604825418,100.0,8.333333333333333e-05,0.67,0.28,0.23,0.05,0.9,0.05,0.03,0.02
203.6318762478564,0.0170900431391389,253.388962657445,100.0,8.333333333333333e-05,0.67,0.28,0.23,0.05,0.9,0.05,0.03,0.02
206.024974874118,0.0172894680246607,253.391965385068,100.0,8.333333333333333e-05,0.67,0.28,0.23,0.05,0.9,0.05,0.03,0.02
208.3581418333068,0.0174838986045931,253.499713513916,100.0,8.333333333333333e-05,0.67,0.28,0.23,0.05,0.9,0.05,0.03,0.02
210.7929187996272,0.0176867966851198,253.577147618454,100.0,8.333333333333333e-05,0.67,0.28,0.23,0.05,0.9,0.05,0.03,0.02
213.1809393568452,0.0178857983982213,253.717606097041,100.0,8.333333333333333e-05,0.67,0.28,0.23,0.05,0.9,0.05,0.03,0.02
215.4431314570512,0.0180743144065718,253.723980446294,100.0,8.333333333333333e-05,0.67,0.28,0.23,0.05,0.9,0.05,0.03,0.02
217.7972681423808,0.0182704924636826,253.839461224003,100.0,8.333333333333333e-05,0.67,0.28,0.23,0.05,0.9,0.05,0.03,0.02
220.105985270616,0.0184628855577022,253.973623670025,100.0,8.333333333333333e-05,0.67,0.28,0.23,0.05,0.9,0.05,0.03,0.02
222.3691998534948,0.0186514867729421,254.133864906032,100.0,8.333333333333333e-05,0.67,0.28,0.23,0.05,0.9,0.05,0.03,0.02
224.6897298544944,0.0188448642730254,254.200244853861,100.0,8.333333333333333e-05,0.67,0.28,0.23,0.05,0.9,0.05,0.03,0.02
226.9291354829796,0.0190314814087325,254.287190614775,100.0,8.333333333333333e-05,0.67,0.28,0.23,0.05,0.9,0.05,0.03,0.02
229.1219866038828,0.0192142190021411,254.394126372826,100.0,8.333333333333333e-05,0.67,0.28,0.23,0.05,0.9,0.05,0.03,0.02
231.4770864225156,0.0194104773203605,254.483211280445,100.0,8.333333333333333e-05,0.67,0.28,0.23,0.05,0.9,0.05,0.03,0.02
233.712351566634,0.0195967494157037,254.543978500476,100.0,8.333333333333333e-05,0.67,0.28,0.23,0.05,0.9,0.05,0.03,0.02
235.9671286594488,0.0197846475067716,254.597307303427,100.0,8.333333333333333e-05,0.67,0.28,0.23,0.05,0.9,0.05,0.03,0.02
238.2181832352468,0.0199722353880881,254.680547822196,100.0,8.333333333333333e-05,0.67,0.28,0.23,0.05,0.9,0.05,0.03,0.02
240.4514244793488,0.0201583388250966,254.746212306002,100.0,8.333333333333333e-05,0.67,0.28,0.23,0.05,0.9,0.05,0.03,0.02
242.6662741699428,0.0203429096326461,254.814610358432,100.0,8.333333333333333e-05,0.67,0.28,0.23,0.05,0.9,0.05,0.03,0.02
244.8848920739484,0.0205277944579799,254.872822252203,100.0,8.333333333333333e-05,0.67,0.28,0.23,0.05,0.9,0.05,0.03,0.02
247.0108193246184,0.0207049550622024,254.965369412085,100.0,8.333333333333333e-05,0.67,0.28,0.23,0.05,0.9,0.05,0.03,0.02
249.13511761242,0.0208819799195192,255.03873689595,100.0,8.333333333333333e-05,0.67,0.28,0.23,0.05,0.9,0.05,0.03,0.02
251.3014522447116,0.0210625078055435,255.128757250257,100.0,8.333333333333333e-05,0.67,0.28,0.23,0.05,0.9,0.05,0.03,0.02
253.5381086545116,0.0212488958396935,255.200120198694,100.0,8.333333333333333e-05,0.67,0.28,0.23,0.05,0.9,0.05,0.03,0.02
255.7369147985376,0.021432129685029,255.284024796588,100.0,8.333333333333333e-05,0.67,0.28,0.23,0.05,0.9,0.05,0.03,0.02
257.9859587840256,0.021619550017153,255.365358783041,100.0,8.333333333333333e-05,0.67,0.28,0.23,0.05,0.9,0.05,0.03,0.02
260.2709182439496,0.02180996330548,255.478319063092,100.0,8.333333333333333e-05,0.67,0.28,0.23,0.05,0.9,0.05,0.03,0.02
262.5288332447556,0.0219981228888805,255.589679626663,100.0,8.333333333333333e-05,0.67,0.28,0.23,0.05,0.9,0.05,0.03,0.02
264.8111559698028,0.0221883164493011,255.685359040978,100.0,8.333333333333333e-05,0.67,0.28,0.23,0.05,0.9,0.05,0.03,0.02
267.0560126766804,0.0223753878415409,255.759589184201,100.0,8.333333333333333e-05,0.67,0.28,0.23,0.05,0.9,0.05,0.03,0.02
269.2833539446992,0.0225609996138758,255.844936356751,100.0,8.333333333333333e-05,0.67,0.28,0.23,0.05,0.9,0.05,0.03,0.02
271.5649809301512,0.0227511351959968,255.91437734469,100.0,8.333333333333333e-05,0.67,0.28,0.23,0.05,0.9,0.05,0.03,0.02
273.80501924142123,0.0229378050552693,255.999277115876,100.0,8.333333333333333e-05,0.67,0.28,0.23,0.05,0.9,0.05,0.03,0.02
275.9845836136512,0.0231194354196218,256.060814473846,100.0,8.333333333333333e-05,0.67,0.28,0.23,0.05,0.9,0.05,0.03,0.02
278.2082641539492,0.0233047421313133,256.099859164435,100.0,8.333333333333333e-05,0.67,0.28,0.23,0.05,0.9,0.05,0.03,0.02
280.4001840180588,0.0234874021199891,256.179782417709,100.0,8.333333333333333e-05,0.67,0.28,0.23,0.05,0.9,0.05,0.03,0.02
282.5847539869584,0.0236694496173974,256.270891245288,100.0,8.333333333333333e-05,0.67,0.28,0.23,0.05,0.9,0.05,0.03,0.02
284.7469097640564,0.0238496292654889,256.33686224304,100.0,8.333333333333333e-05,0.67,0.28,0.23,0.05,0.9,0.05,0.03,0.02
286.9236537409296,0.024031024596895,256.414079653927,100.0,8.333333333333333e-05,0.67,0.28,0.23,0.05,0.9,0.05,0.03,0.02
288.9951321613032,0.0242036477985928,256.512797720807,100.0,8.333333333333333e-05,0.67,0.28,0.23,0.05,0.9,0.05,0.03,0.02
291.1501370867304,0.0243832315423784,256.593587399124,100.0,8.333333333333333e-05,0.67,0.28,0.23,0.05,0.9,0.05,0.03,0.02
293.307014319372,0.0245629713117652,256.667670347012,100.0,8.333333333333333e-05,0.67,0.28,0.23,0.05,0.9,0.05,0.03,0.02
295.4479201525932,0.0247413801312003,256.744834974771,100.0,8.333333333333333e-05,0.67,0.28,0.23,0.05,0.9,0.05,0.03,0.02
297.5931974791248,0.0249201532417446,256.782461512037,100.0,8.333333333333333e-05,0.67,0.28,0.23,0.05,0.9,0.05,0.03,0.02
299.7466307329296,0.025099606012895,256.834013960928,100.0,8.333333333333333e-05,0.67,0.28,0.23,0.05,0.9,0.05,0.03,0.02
301.9076926957728,0.0252796945097986,256.888212191934,100.0,8.333333333333333e-05,0.67,0.28,0.23,0.05,0.9,0.05,0.03,0.02
304.1155060179756,0.0254636789533155,256.926014286329,100.0,8.333333333333333e-05,0.67,0.28,0.23,0.05,0.9,0.05,0.03,0.02
306.2737500939648,0.0256435326263146,256.98036001456,100.0,8.333333333333333e-05,0.67,0.28,0.23,0.05,0.9,0.05,0.03,0.02
308.4755173563684,0.0258270132315149,257.06595461001,100.0,8.333333333333333e-05,0.67,0.28,0.23,0.05,0.9,0.05,0.03,0.02
310.6680187933092,0.0260097216845933,257.121418603314,100.0,8.333333333333333e-05,0.67,0.28,0.23,0.05,0.9,0.05,0.03,0.02
312.8588223544524,0.0261922886480219,257.203985414249,100.0,8.333333333333333e-05,0.67,0.28,0.23,0.05,0.9,0.05,0.03,0.02
315.1010527029672,0.0263791411770648,257.297785895373,100.0,8.333333333333333e-05,0.67,0.28,0.23,0.05,0.9,0.05,0.03,0.02
317.1743090001936,0.026551912535167,257.387683014899,100.0,8.333333333333333e-05,0.67,0.28,0.23,0.05,0.9,0.05,0.03,0.02
319.3436416771176,0.026732690258244,257.4709745849,100.0,8.333333333333333e-05,0.67,0.28,0.23,0.05,0.9,0.05,0.03,0.02
321.5522160505572,0.0269167381226973,257.519877787882,100.0,8.333333333333333e-05,0.67,0.28,0.23,0.05,0.9,0.05,0.03,0.02
323.6283647095188,0.0270897505109441,257.569508435166,100.0,8.333333333333333e-05,0.67,0.28,0.23,0.05,0.9,0.05,0.03,0.02
325.8230387208408,0.0272726400118876,257.646072174198,100.0,8.333333333333333e-05,0.67,0.28,0.23,0.05,0.9,0.05,0.03,0.02
327.9732077344056,0.027451820763018,257.723267848987,100.0,8.333333333333333e-05,0.67,0.28,0.23,0.05,0.9,0.05,0.03,0.02
330.0959684403564,0.0276287174885139,257.798071138811,100.0,8.333333333333333e-05,0.67,0.28,0.23,0.05,0.9,0.05,0.03,0.02
332.3513277569328,0.0278166640982286,257.874851571493,100.0,8.333333333333333e-05,0.67,0.28,0.23,0.05,0.9,0.05,0.03,0.02
334.510094908824,0.0279965613608862,257.947977797375,100.0,8.333333333333333e-05,0.67,0.28,0.23,0.05,0.9,0.05,0.03,0.02
336.6669368335848,0.0281762981879496,258.046853149079,100.0,8.333333333333333e-05,0.67,0.28,0.23,0.05,0.9,0.05,0.03,0.02
338.88453643120084,0.0283610981544176,258.123014071173,100.0,8.333333333333333e-05,0.67,0.28,0.23,0.05,0.9,0.05,0.03,0.02
340.9937747510784,0.0285368680144074,258.161917699566,100.0,8.333333333333333e-05,0.67,0.28,0.23,0.05,0.9,0.05,0.03,0.02
343.2499583317956,0.0287248833128005,258.203182507004,100.0,8.333333333333333e-05,0.67,0.28,0.23,0.05,0.9,0.05,0.03,0.02
345.332825992404,0.0288984556178512,258.243150981784,100.0,8.333333333333333e-05,0.67,0.28,0.23,0.05,0.9,0.05,0.03,0.02
347.4928291141464,0.0290784558779964,258.268632346836,100.0,8.333333333333333e-05,0.67,0.28,0.23,0.05,0.9,0.05,0.03,0.02
349.647083429718,0.0292579770709607,258.312151003389,100.0,8.333333333333333e-05,0.67,0.28,0.23,0.05,0.9,0.05,0.03,0.02
351.8004263976024,0.0294374223182844,258.348561081802,100.0,8.333333333333333e-05,0.67,0.28,0.23,0.05,0.9,0.05,0.03,0.02
353.9474515042008,0.0296163410771676,258.400913778213,100.0,8.333333333333333e-05,0.67,0.28,0.23,0.05,0.9,0.05,0.03,0.02
356.1257894680332,0.0297978692408203,258.481108700943,100.0,8.333333333333333e-05,0.67,0.28,0.23,0.05,0.9,0.05,0.03,0.02
358.1844080831484,0.0299694207920799,258.548496914569,100.0,8.333333333333333e-05,0.67,0.28,0.23,0.05,0.9,0.05,0.03,0.02
360.4317315176808,0.0301566977449576,258.629272086264,100.0,8.333333333333333e-05,0.67,0.28,0.23,0.05,0.9,0.05,0.03,0.02
362.591794165626,0.0303367029656197,258.72022269157,100.0,8.333333333333333e-05,0.67,0.28,0.23,0.05,0.9,0.05,0.03,0.02
364.8035744495412,0.0305210179892793,258.793302108572,100.0,8.333333333333333e-05,0.67,0.28,0.23,0.05,0.9,0.05,0.03,0.02
366.9975563603604,0.0307038498151809,258.865427012133,100.0,8.333333333333333e-05,0.67,0.28,0.23,0.05,0.9,0.05,0.03,0.02
369.1813732727316,0.0308858345578785,258.947462750436,100.0,8.333333333333333e-05,0.67,0.28,0.23,0.05,0.9,0.05,0.03,0.02
371.4139681748076,0.0310718841330515,259.033424380884,100.0,8.333333333333333e-05,0.67,0.28,0.23,0.05,0.9,0.05,0.03,0.02
373.6613478401412,0.0312591657718293,259.125326194728,100.0,8.333333333333333e-05,0.67,0.28,0.23,0.05,0.9,0.05,0.03,0.02
375.9210464459604,0.0314474739889809,259.206156691785,100.0,8.333333333333333e-05,0.67,0.28,0.23,0.05,0.9,0.05,0.03,0.02
378.1797870838717,0.0316357023754735,259.287423547378,100.0,8.333333333333333e-05,0.67,0.28,0.23,0.05,0.9,0.05,0.03,0.02
380.4441288295752,0.0318243975209488,259.366991587041,100.0,8.333333333333333e-05,0.67,0.28,0.23,0.05,0.9,0.05,0.03,0.02
382.7009118375348,0.0320124627716121,259.444224283109,100.0,8.333333333333333e-05,0.67,0.28,0.23,0.05,0.9,0.05,0.03,0.02
384.98637163426565,0.032202917754673,259.502060800177,100.0,8.333333333333333e-05,0.67,0.28,0.23,0.05,0.9,0.05,0.03,0.02
387.1929326647213,0.0323867978405443,259.566246466607,100.0,8.333333333333333e-05,0.67,0.28,0.23,0.05,0.9,0.05,0.03,0.02
389.4508909473768,0.0325749610307656,259.64648568776,100.0,8.333333333333333e-05,0.67,0.28,0.23,0.05,0.9,0.05,0.03,0.02
391.7156820692808,0.0327636936242576,259.700339732093,100.0,8.333333333333333e-05,0.67,0.28,0.23,0.05,0.9,0.05,0.03,0.02
394.0376477524212,0.0329571907645193,259.766735123992,100.0,8.333333333333333e-05,0.67,0.28,0.23,0.05,0.9,0.05,0.03,0.02
396.3142463799048,0.0331469073168096,259.814660949319,100.0,8.333333333333333e-05,0.67,0.28,0.23,0.05,0.9,0.05,0.03,0.02
398.47756441695,0.0333271838198967,259.876802675697,100.0,8.333333333333333e-05,0.67,0.28,0.23,0.05,0.9,0.05,0.03,0.02
400.7394902157924,0.0335156776364669,259.932904436006,100.0,8.333333333333333e-05,0.67,0.28,0.23,0.05,0.9,0.05,0.03,0.02
403.0638313293216,0.033709372729261,259.974017646868,100.0,8.333333333333333e-05,0.67,0.28,0.23,0.05,0.9,0.05,0.03,0.02
405.28411211745,0.0338943961282717,259.987165380741,100.0,8.333333333333333e-05,0.67,0.28,0.23,0.05,0.9,0.05,0.03,0.02
407.4620456729508,0.0340758905912301,259.994566760654,100.0,8.333333333333333e-05,0.67,0.28,0.23,0.05,0.9,0.05,0.03,0.02
409.6160252170872,0.0342553888865748,260.004742051263,100.0,8.333333333333333e-05,0.67,0.28,0.23,0.05,0.9,0.05,0.03,0.02
411.88611702816,0.0344445632041642,260.055209029896,100.0,8.333333333333333e-05,0.67,0.28,0.23,0.05,0.9,0.05,0.03,0.02
414.2825494312896,0.034644265904425,260.109432317794,100.0,8.333333333333333e-05,0.67,0.28,0.23,0.05,0.9,0.05,0.03,0.02
416.6258019353772,0.0348395369464323,260.131361928065,100.0,8.333333333333333e-05,0.67,0.28,0.23,0.05,0.9,0.05,0.03,0.02
418.8940177253592,0.0350285549289308,260.152933019821,100.0,8.333333333333333e-05,0.67,0.28,0.23,0.05,0.9,0.05,0.03,0.02
421.2357875360952,0.0352237024131588,260.198935772422,100.0,8.333333333333333e-05,0.67,0.28,0.23,0.05,0.9,0.05,0.03,0.02
423.565233966948,0.0354178229490632,260.272768945844,100.0,8.333333333333333e-05,0.67,0.28,0.23,0.05,0.9,0.05,0.03,0.02
425.870684641962,0.0356099438386477,260.320042497545,100.0,8.333333333333333e-05,0.67,0.28,0.23,0.05,0.9,0.05,0.03,0.02
428.1812794072165,0.0358024934024189,260.359031544992,100.0,8.333333333333333e-05,0.67,0.28,0.23,0.05,0.9,0.05,0.03,0.02
430.479336040422,0.0359939981218527,260.406674816925,100.0,8.333333333333333e-05,0.67,0.28,0.23,0.05,0.9,0.05,0.03,0.02
432.4873241465376,0.036161330464029,260.486600580655,100.0,8.333333333333333e-05,0.67,0.28,0.23,0.05,0.9,0.05,0.03,0.02
434.7794378063976,0.036352339935684,260.556577678027,100.0,8.333333333333333e-05,0.67,0.28,0.23,0.05,0.9,0.05,0.03,0.02
437.141395380186,0.0365491697334997,260.621960879557,100.0,8.333333333333333e-05,0.67,0.28,0.23,0.05,0.9,0.05,0.03,0.02
439.4023228899468,0.0367375803593131,260.686618845351,100.0,8.333333333333333e-05,0.67,0.28,0.23,0.05,0.9,0.05,0.03,0.02
441.6918973896852,0.0369283782342913,260.773707400357,100.0,8.333333333333333e-05,0.67,0.28,0.23,0.05,0.9,0.05,0.03,0.02
443.8990562654604,0.0371123081406059,260.860434592723,100.0,8.333333333333333e-05,0.67,0.28,0.23,0.05,0.9,0.05,0.03,0.02
446.1774994131168,0.0373021784029106,260.937813070008,100.0,8.333333333333333e-05,0.67,0.28,0.23,0.05,0.9,0.05,0.03,0.02
448.6343548503,0.0375069163560092,260.997589994657,100.0,8.333333333333333e-05,0.67,0.28,0.23,0.05,0.9,0.05,0.03,0.02
450.9163436440512,0.0376970820888218,261.050911075573,100.0,8.333333333333333e-05,0.67,0.28,0.23,0.05,0.9,0.05,0.03,0.02
453.18313827560166,0.037885981641451,261.090507796332,100.0,8.333333333333333e-05,0.67,0.28,0.23,0.05,0.9,0.05,0.03,0.02
455.4341856003948,0.0380735689185171,261.121707630218,100.0,8.333333333333333e-05,0.67,0.28,0.23,0.05,0.9,0.05,0.03,0.02
457.7574220744392,0.0382671719580208,261.15116910055,100.0,8.333333333333333e-05,0.67,0.28,0.23,0.05,0.9,0.05,0.03,0.02
460.05414517917006,0.0384585655500817,261.169551357283,100.0,8.333333333333333e-05,0.67,0.28,0.23,0.05,0.9,0.05,0.03,0.02
462.3612022692624,0.0386508203075894,261.193026137231,100.0,8.333333333333333e-05,0.67,0.28,0.23,0.05,0.9,0.05,0.03,0.02
464.7053963318712,0.0388461698128068,261.220336178691,100.0,8.333333333333333e-05,0.67,0.28,0.23,0.05,0.9,0.05,0.03,0.02
467.0124315964909,0.0390384227515251,261.250228192199,100.0,8.333333333333333e-05,0.67,0.28,0.23,0.05,0.9,0.05,0.03,0.02
469.2385466229696,0.039223932337065,261.303046562277,100.0,8.333333333333333e-05,0.67,0.28,0.23,0.05,0.9,0.05,0.03,0.02
471.6362839120585,0.0394237437778224,261.390564071563,100.0,8.333333333333333e-05,0.67,0.28,0.23,0.05,0.9,0.05,0.03,0.02
473.9455553911812,0.0396161830677493,261.454458509226,100.0,8.333333333333333e-05,0.67,0.28,0.23,0.05,0.9,0.05,0.03,0.02
476.2829789799793,0.0398109683668158,261.530259673466,100.0,8.333333333333333e-05,0.67,0.28,0.23,0.05,0.9,0.05,0.03,0.02
478.5325914060756,0.0399984360689905,261.585155398081,100.0,8.333333333333333e-05,0.67,0.28,0.23,0.05,0.9,0.05,0.03,0.02
480.8875537414668,0.0401946829302731,261.665849265963,100.0,8.333333333333333e-05,0.67,0.28,0.23,0.05,0.9,0.05,0.03,0.02
483.2301880153728,0.0403899024530986,261.761293857324,100.0,8.333333333333333e-05,0.67,0.28,0.23,0.05,0.9,0.05,0.03,0.02
485.61407667509405,0.0405885598414087,261.821600917157,100.0,8.333333333333333e-05,0.67,0.28,0.23,0.05,0.9,0.05,0.03,0.02
487.950405138504,0.0407832538800262,261.871266393042,100.0,8.333333333333333e-05,0.67,0.28,0.23,0.05,0.9,0.05,0.03,0.02
490.3124325503988,0.0409800894976841,261.924852231714,100.0,8.333333333333333e-05,0.67,0.28,0.23,0.05,0.9,0.05,0.03,0.02
492.6905042191236,0.0411782621367445,261.960917503785,100.0,8.333333333333333e-05,0.67,0.28,0.23,0.05,0.9,0.05,0.03,0.02
495.1172360649504,0.0413804897905634,261.994819859265,100.0,8.333333333333333e-05,0.67,0.28,0.23,0.05,0.9,0.05,0.03,0.02
497.45414451443526,0.0415752321613538,262.018476170593,100.0,8.333333333333333e-05,0.67,0.28,0.23,0.05,0.9,0.05,0.03,0.02
499.7830825105429,0.0417693103276961,262.047835220682,100.0,8.333333333333333e-05,0.67,0.28,0.23,0.05,0.9,0.05,0.03,0.02
502.14261156686047,0.0419659377490559,262.084136570936,100.0,8.333333333333333e-05,0.67,0.28,0.23,0.05,0.9,0.05,0.03,0.02
504.4625531117424,0.0421592662111294,262.121671540119,100.0,8.333333333333333e-05,0.67,0.28,0.23,0.05,0.9,0.05,0.03,0.02
506.8833697273656,0.042361000929098,262.149563880221,100.0,8.333333333333333e-05,0.67,0.28,0.23,0.05,0.9,0.05,0.03,0.02
509.2983867156396,0.0425622523447875,262.187453284456,100.0,8.333333333333333e-05,0.67,0.28,0.23,0.05,0.9,0.05,0.03,0.02
511.62608414432646,0.0427562271305114,262.219058302736,100.0,8.333333333333333e-05,0.67,0.28,0.23,0.05,0.9,0.05,0.03,0.02
514.0306943613851,0.0429566113152663,262.277307392565,100.0,8.333333333333333e-05,0.67,0.28,0.23,0.05,0.9,0.05,0.03,0.02
516.4451798166432,0.0431578184365378,262.323294859986,100.0,8.333333333333333e-05,0.67,0.28,0.23,0.05,0.9,0.05,0.03,0.02
518.8379585731656,0.043357216666248,262.37662145437,100.0,8.333333333333333e-05,0.67,0.28,0.23,0.05,0.9,0.05,0.03,0.02
521.3506908653015,0.043566611023926,262.39128346978,100.0,8.333333333333333e-05,0.67,0.28,0.23,0.05,0.9,0.05,0.03,0.02
523.7225750818092,0.0437642680419683,262.445632677693,100.0,8.333333333333333e-05,0.67,0.28,0.23,0.05,0.9,0.05,0.03,0.02
526.1257326561564,0.0439645311731639,262.481869884211,100.0,8.333333333333333e-05,0.67,0.28,0.23,0.05,0.9,0.05,0.03,0.02
528.56664232014,0.0441679403118292,262.555167408981,100.0,8.333333333333333e-05,0.67,0.28,0.23,0.05,0.9,0.05,0.03,0.02
530.962240191828,0.0443675734678032,262.585751402628,100.0,8.333333333333333e-05,0.67,0.28,0.23,0.05,0.9,0.05,0.03,0.02
533.3711829277391,0.0445683186957958,262.617930822735,100.0,8.333333333333333e-05,0.67,0.28,0.23,0.05,0.9,0.05,0.03,0.02
535.7817030798468,0.0447691953751381,262.646202654781,100.0,8.333333333333333e-05,0.67,0.28,0.23,0.05,0.9,0.05,0.03,0.02
538.0937307650124,0.0449618643489019,262.691426133291,100.0,8.333333333333333e-05,0.67,0.28,0.23,0.05,0.9,0.05,0.03,0.02
540.5132946731665,0.0451634946745814,262.708788938399,100.0,8.333333333333333e-05,0.67,0.28,0.23,0.05,0.9,0.05,0.03,0.02
542.9276791365456,0.045364693379863,262.73803373097,100.0,8.333333333333333e-05,0.67,0.28,0.23,0.05,0.9,0.05,0.03,0.02
545.3557366360897,0.045567031504825,262.762131771302,100.0,8.333333333333333e-05,0.67,0.28,0.23,0.05,0.9,0.05,0.03,0.02
547.7663385329712,0.0457679149962318,262.789198187323,100.0,8.333333333333333e-05,0.67,0.28,0.23,0.05,0.9,0.05,0.03,0.02
550.214442410544,0.0459719236526962,262.820532155817,100.0,8.333333333333333e-05,0.67,0.28,0.23,0.05,0.9,0.05,0.03,0.02
552.6716679211308,0.0461766924452451,262.847146435565,100.0,8.333333333333333e-05,0.67,0.28,0.23,0.05,0.9,0.05,0.03,0.02
555.142662579402,0.0463826086667677,262.89436531335,100.0,8.333333333333333e-05,0.67,0.28,0.23,0.05,0.9,0.05,0.03,0.02
557.6094050322564,0.0465881705378389,262.933917592686,100.0,8.333333333333333e-05,0.67,0.28,0.23,0.05,0.9,0.05,0.03,0.02
560.0662475297604,0.0467929074126309,262.984958337589,100.0,8.333333333333333e-05,0.67,0.28,0.23,0.05,0.9,0.05,0.03,0.02
562.5924245928252,0.0470034221678863,263.036373219856,100.0,8.333333333333333e-05,0.67,0.28,0.23,0.05,0.9,0.05,0.03,0.02
565.1179133184456,0.047213879561688,263.101818022887,100.0,8.333333333333333e-05,0.67,0.28,0.23,0.05,0.9,0.05,0.03,0.02
567.5504905251744,0.0474165943289154,263.118129058223,100.0,8.333333333333333e-05,0.67,0.28,0.23,0.05,0.9,0.05,0.03,0.02
569.980181151192,0.0476190685477502,263.151053416377,100.0,8.333333333333333e-05,0.67,0.28,0.23,0.05,0.9,0.05,0.03,0.02
572.471329294614,0.0478266642263687,263.14975093469,100.0,8.333333333333333e-05,0.67,0.28,0.23,0.05,0.9,0.05,0.03,0.02
574.8665046159097,0.04802626216981,263.187400781061,100.0,8.333333333333333e-05,0.67,0.28,0.23,0.05,0.9,0.05,0.03,0.02
577.2867412671552,0.0482279485574138,263.201894659486,100.0,8.333333333333333e-05,0.67,0.28,0.23,0.05,0.9,0.05,0.03,0.02
579.7078997229253,0.0484297117620613,263.209532578361,100.0,8.333333333333333e-05,0.67,0.28,0.23,0.05,0.9,0.05,0.03,0.02
582.1453253629439,0.0486328305653962,263.223943881855,100.0,8.333333333333333e-05,0.67,0.28,0.23,0.05,0.9,0.05,0.03,0.02
584.6486802640728,0.0488414434738236,263.279021948186,100.0,8.333333333333333e-05,0.67,0.28,0.23,0.05,0.9,0.05,0.03,0.02
587.1986969726748,0.0490539448662071,263.33627238504,100.0,8.333333333333333e-05,0.67,0.28,0.23,0.05,0.9,0.05,0.03,0.02
589.7343032450473,0.0492652453889048,263.410496379235,100.0,8.333333333333333e-05,0.67,0.28,0.23,0.05,0.9,0.05,0.03,0.02
592.2678403219787,0.0494763734786491,263.441594110658,100.0,8.333333333333333e-05,0.67,0.28,0.23,0.05,0.9,0.05,0.03,0.02
594.9571271766852,0.0497004807165413,263.457427666827,100.0,8.333333333333333e-05,0.67,0.28,0.23,0.05,0.9,0.05,0.03,0.02
597.4658945686896,0.049909544665875,263.447490345186,100.0,8.333333333333333e-05,0.67,0.28,0.23,0.05,0.9,0.05,0.03,0.02
599.9427692101859,0.0501159508859997,263.448060504662,100.0,8.333333333333333e-05,0.67,0.28,0.23,0.05,0.9,0.05,0.03,0.02
602.4085063334844,0.0503214289796079,263.46687896104,100.0,8.333333333333333e-05,0.67,0.28,0.23,0.05,0.9,0.05,0.03,0.02
604.8475783342489,0.0505246849796716,263.477551750907,100.0,8.333333333333333e-05,0.67,0.28,0.23,0.05,0.9,0.05,0.03,0.02
607.2848385770641,0.0507277899999062,263.482418936878,100.0,8.333333333333333e-05,0.67,0.28,0.23,0.05,0.9,0.05,0.03,0.02
609.8588275291104,0.0509422890792434,263.516329491062,100.0,8.333333333333333e-05,0.67,0.28,0.23,0.05,0.9,0.05,0.03,0.02
612.1600330074805,0.0511340562024409,263.573859017515,100.0,8.333333333333333e-05,0.67,0.28,0.23,0.05,0.9,0.05,0.03,0.02
614.6619164098404,0.0513425464859709,263.643396133669,100.0,8.333333333333333e-05,0.67,0.28,0.23,0.05,0.9,0.05,0.03,0.02
617.18767638177,0.0515530264836317,263.705768408871,100.0,8.333333333333333e-05,0.67,0.28,0.23,0.05,0.9,0.05,0.03,0.02
619.7366354549556,0.0517654397397305,263.759501125098,100.0,8.333333333333333e-05,0.67,0.28,0.23,0.05,0.9,0.05,0.03,0.02
622.2480261451296,0.051974722297245,263.806734509505,100.0,8.333333333333333e-05,0.67,0.28,0.23,0.05,0.9,0.05,0.03,0.02
624.80445819357,0.0521877583012817,263.85185806234,100.0,8.333333333333333e-05,0.67,0.28,0.23,0.05,0.9,0.05,0.03,0.02
627.2755044324899,0.0523936788211917,263.895580177038,100.0,8.333333333333333e-05,0.67,0.28,0.23,0.05,0.9,0.05,0.03,0.02
629.9082879155712,0.0526130774447818,263.936164364944,100.0,8.333333333333333e-05,0.67,0.28,0.23,0.05,0.9,0.05,0.03,0.02
632.4811218593784,0.0528274802734324,263.957120696911,100.0,8.333333333333333e-05,0.67,0.28,0.23,0.05,0.9,0.05,0.03,0.02
635.0267543263525,0.0530396163123469,263.9670490254,100.0,8.333333333333333e-05,0.67,0.28,0.23,0.05,0.9,0.05,0.03,0.02
637.64463130242,0.0532577727270192,263.976932769464,100.0,8.333333333333333e-05,0.67,0.28,0.23,0.05,0.9,0.05,0.03,0.02
640.2660755570892,0.0534762264149083,263.99186537388,100.0,8.333333333333333e-05,0.67,0.28,0.23,0.05,0.9,0.05,0.03,0.02
642.841287610104,0.0536908274193262,263.999561764131,100.0,8.333333333333333e-05,0.67,0.28,0.23,0.05,0.9,0.05,0.03,0.02
645.444940593756,0.0539077985012972,264.017888234722,100.0,8.333333333333333e-05,0.67,0.28,0.23,0.05,0.9,0.05,0.03,0.02
647.9747922996733,0.0541186194767903,264.037029284675,100.0,8.333333333333333e-05,0.67,0.28,0.23,0.05,0.9,0.05,0.03,0.02
650.5712179847892,0.0543349882838833,264.057019424814,100.0,8.333333333333333e-05,0.67,0.28,0.23,0.05,0.9,0.05,0.03,0.02
653.201223932148,0.0545541554461632,264.074626490918,100.0,8.333333333333333e-05,0.67,0.28,0.23,0.05,0.9,0.05,0.03,0.02
655.8172199606172,0.0547721551152023,264.101009427394,100.0,8.333333333333333e-05,0.67,0.28,0.23,0.05,0.9,0.05,0.03,0.02
658.42528530519,0.0549894938939167,264.122568538874,100.0,8.333333333333333e-05,0.67,0.28,0.23,0.05,0.9,0.05,0.03,0.02
661.0416790766279,0.0552075267082032,264.152523425,100.0,8.333333333333333e-05,0.67,0.28,0.23,0.05,0.9,0.05,0.03,0.02
663.6766610573496,0.05542710853993,264.167031953047,100.0,8.333333333333333e-05,0.67,0.28,0.23,0.05,0.9,0.05,0.03,0.02
666.3042214825392,0.0556460719086958,264.177563537717,100.0,8.333333333333333e-05,0.67,0.28,0.23,0.05,0.9,0.05,0.03,0.02
668.9268473545704,0.0558646240646984,264.200079545982,100.0,8.333333333333333e-05,0.67,0.28,0.23,0.05,0.9,0.05,0.03,0.02
671.6113349226384,0.0560883313620374,264.223241361066,100.0,8.333333333333333e-05,0.67,0.28,0.23,0.05,0.9,0.05,0.03,0.02
674.2403582680428,0.0563074166408211,264.239318240784,100.0,8.333333333333333e-05,0.67,0.28,0.23,0.05,0.9,0.05,0.03,0.02
676.8498047286985,0.0565248705125424,264.266151263858,100.0,8.333333333333333e-05,0.67,0.28,0.23,0.05,0.9,0.05,0.03,0.02
679.5232083085788,0.0567476541441991,264.299764916917,100.0,8.333333333333333e-05,0.67,0.28,0.23,0.05,0.9,0.05,0.03,0.02
682.0719678024133,0.0569600507686853,264.306863723346,100.0,8.333333333333333e-05,0.67,0.28,0.23,0.05,0.9,0.05,0.03,0.02
684.7666301436133,0.0571846059637853,264.319383461925,100.0,8.333333333333333e-05,0.67,0.28,0.23,0.05,0.9,0.05,0.03,0.02
687.4525758640116,0.0574084347738185,264.337300823549,100.0,8.333333333333333e-05,0.67,0.28,0.23,0.05,0.9,0.05,0.03,0.02
690.1020980353344,0.0576292282880954,264.367569627877,100.0,8.333333333333333e-05,0.67,0.28,0.23,0.05,0.9,0.05,0.03,0.02
692.7254749641409,0.0578478430321626,264.381124579931,100.0,8.333333333333333e-05,0.67,0.28,0.23,0.05,0.9,0.05,0.03,0.02
695.4136757823336,0.058071859767012,264.387158873641,100.0,8.333333333333333e-05,0.67,0.28,0.23,0.05,0.9,0.05,0.03,0.02
698.0763312312156,0.0582937477210855,264.378050955763,100.0,8.333333333333333e-05,0.67,0.28,0.23,0.05,0.9,0.05,0.03,0.02
700.8414867983184,0.0585241773516774,264.382298329256,100.0,8.333333333333333e-05,0.67,0.28,0.23,0.05,0.9,0.05,0.03,0.02
703.4707564459908,0.0587432831556501,264.402301561898,100.0,8.333333333333333e-05,0.67,0.28,0.23,0.05,0.9,0.05,0.03,0.02
706.1099268430812,0.0589632140220743,264.418729222208,100.0,8.333333333333333e-05,0.67,0.28,0.23,0.05,0.9,0.05,0.03,0.02
708.7407881707212,0.0591824524660443,264.426116413279,100.0,8.333333333333333e-05,0.67,0.28,0.23,0.05,0.9,0.05,0.03,0.02
711.4344133188121,0.0594069212283852,264.404987670196,100.0,8.333333333333333e-05,0.67,0.28,0.23,0.05,0.9,0.05,0.03,0.02
714.0895174173468,0.0596281799032631,264.407460262637,100.0,8.333333333333333e-05,0.67,0.28,0.23,0.05,0.9,0.05,0.03,0.02
716.8270532111052,0.0598563078860763,264.429674793756,100.0,8.333333333333333e-05,0.67,0.28,0.23,0.05,0.9,0.05,0.03,0.02
719.5473514000812,0.0600829994018243,264.45126258481,100.0,8.333333333333333e-05,0.67,0.28,0.23,0.05,0.9,0.05,0.03,0.02
722.2787027207628,0.0603106120118811,264.481404213895,100.0,8.333333333333333e-05,0.67,0.28,0.23,0.05,0.9,0.05,0.03,0.02
725.0378567681844,0.0605405415158329,264.512297708612,100.0,8.333333333333333e-05,0.67,0.28,0.23,0.05,0.9,0.05,0.03,0.02
727.8302752484509,0.0607732430558551,264.540524463676,100.0,8.333333333333333e-05,0.67,0.28,0.23,0.05,0.9,0.05,0.03,0.02
730.490429489562,0.0609949225759477,264.597050459243,100.0,8.333333333333333e-05,0.67,0.28,0.23,0.05,0.9,0.05,0.03,0.02
733.2952964971272,0.0612286614932448,264.622315448425,100.0,8.333333333333333e-05,0.67,0.28,0.23,0.05,0.9,0.05,0.03,0.02
735.962189781924,0.0614509026003112,264.649460657803,100.0,8.333333333333333e-05,0.67,0.28,0.23,0.05,0.9,0.05,0.03,0.02
738.6210646974769,0.0616724755099406,264.661885539286,100.0,8.333333333333333e-05,0.67,0.28,0.23,0.05,0.9,0.05,0.03,0.02
741.4348302592368,0.0619069559734206,264.656192762902,100.0,8.333333333333333e-05,0.67,0.28,0.23,0.05,0.9,0.05,0.03,0.02
744.1775735477293,0.0621355179141283,264.651227891599,100.0,8.333333333333333e-05,0.67,0.28,0.23,0.05,0.9,0.05,0.03,0.02
746.910577177992,0.0623632682166502,264.654267799391,100.0,8.333333333333333e-05,0.67,0.28,0.23,0.05,0.9,0.05,0.03,0.02
749.7471028484651,0.0625996453558563,264.676835335557,100.0,8.333333333333333e-05,0.67,0.28,0.23,0.05,0.9,0.05,0.03,0.02
752.4986190386712,0.0628289383717068,264.686710722027,100.0,8.333333333333333e-05,0.67,0.28,0.23,0.05,0.9,0.05,0.03,0.02
755.3083482726588,0.0630630824745391,264.68075191677,100.0,8.333333333333333e-05,0.67,0.28,0.23,0.05,0.9,0.05,0.03,0.02
758.158071294774,0.0633005593930487,264.709634552254,100.0,8.333333333333333e-05,0.67,0.28,0.23,0.05,0.9,0.05,0.03,0.02
760.9387185719904,0.0635322799994834,264.734297556371,100.0,8.333333333333333e-05,0.67,0.28,0.23,0.05,0.9,0.05,0.03,0.02
763.742134294098,0.0637658979763257,264.757089651222,100.0,8.333333333333333e-05,0.67,0.28,0.23,0.05,0.9,0.05,0.03,0.02