File: datasets/al_6061_comp/csv/T_100_A_1.csv
Time,Strain(%),Stress(MPa),Temp(C),SR(%/s),Si(%),Fe(%),Cu(%),Mn(%),Mg(%),Cr(%),Zn(%),Ti(%)
0.0,9.70841865910464e-05,2.53345260324623,100.0,8.333333333333333e-05,0.56,0.23,0.18,0.07,0.86,0.06,0.02,0.01
0.4843804945098433,0.0001374492278002,4.02416681188541,100.0,8.333333333333333e-05,0.56,0.23,0.18,0.07,0.86,0.06,0.02,0.01
0.9793887102378432,0.0001786999124442,5.87788623789952,100.0,8.333333333333333e-05,0.56,0.23,0.18,0.07,0.86,0.06,0.02,0.01
1.4199269556654432,0.0002154114328965,8.00614286630474,100.0,8.333333333333333e-05,0.56,0.23,0.18,0.07,0.86,0.06,0.02,0.01
1.8893022838494435,0.0002545260435785,10.3333042443673,100.0,8.333333333333333e-05,0.56,0.23,0.18,0.07,0.86,0.06,0.02,0.01
2.589215720074243,0.0003128521632639,12.7949703063822,100.0,8.333333333333333e-05,0.56,0.23,0.18,0.07,0.86,0.06,0.02,0.01
3.2813795666082437,0.0003705324838084,15.3810340395013,100.0,8.333333333333333e-05,0.56,0.23,0.18,0.07,0.86,0.06,0.02,0.01
3.6510065838738432,0.0004013347352472,18.0474830849354,100.0,8.333333333333333e-05,0.56,0.23,0.18,0.07,0.86,0.06,0.02,0.01
4.054163342004643,0.0004349311317581,20.8077881076598,100.0,8.333333333333333e-05,0.56,0.23,0.18,0.07,0.86,0.06,0.02,0.01
4.685026687021844,0.0004875030771762,23.6172576120264,100.0,8.333333333333333e-05,0.56,0.23,0.18,0.07,0.86,0.06,0.02,0.01
5.379986363851844,0.0005454163835787,26.5194835649222,100.0,8.333333333333333e-05,0.56,0.23,0.18,0.07,0.86,0.06,0.02,0.01
6.011643128297443,0.0005980544472825,29.4604749333711,100.0,8.333333333333333e-05,0.56,0.23,0.18,0.07,0.86,0.06,0.02,0.01
6.496890135330643,0.0006384916978686,32.4486143399826,100.0,8.333333333333333e-05,0.56,0.23,0.18,0.07,0.86,0.06,0.02,0.01
6.942771116254243,0.0006756484462789,35.4502575906266,100.0,8.333333333333333e-05,0.56,0.23,0.18,0.07,0.86,0.06,0.02,0.01
7.717254311886642,0.0007401887125816,38.498398592524,100.0,8.333333333333333e-05,0.56,0.23,0.18,0.07,0.86,0.06,0.02,0.01
8.501178949567844,0.0008055157657217,41.5233127520149,100.0,8.333333333333333e-05,0.56,0.23,0.18,0.07,0.86,0.06,0.02,0.01
9.156838919812245,0.0008601540965754,44.5524150325165,100.0,8.333333333333333e-05,0.56,0.23,0.18,0.07,0.86,0.06,0.02,0.01
9.749111928123044,0.0009095101806013,47.55922531559,100.0,8.333333333333333e-05,0.56,0.23,0.18,0.07,0.86,0.06,0.02,0.01
10.330752092069444,0.0009579801942635,50.6037365221525,100.0,8.333333333333333e-05,0.56,0.23,0.18,0.07,0.86,0.06,0.02,0.01
10.911008880989446,0.0010063349266735,53.6178452932522,100.0,8.333333333333333e-05,0.56,0.23,0.18,0.07,0.86,0.06,0.02,0.01
11.538437220631844,0.0010586206216437,56.6643771108683,100.0,8.333333333333333e-05,0.56,0.23,0.18,0.07,0.86,0.06,0.02,0.01
12.111297809183444,0.001106359004023,59.7291537916654,100.0,8.333333333333333e-05,0.56,0.23,0.18,0.07,0.86,0.06,0.02,0.01
12.586792689191444,0.001145983577357,62.7920590217865,100.0,8.333333333333333e-05,0.56,0.23,0.18,0.07,0.86,0.06,0.02,0.01
13.137940629161443,0.0011919125723545,65.8464601719797,100.0,8.333333333333333e-05,0.56,0.23,0.18,0.07,0.86,0.06,0.02,0.01
13.654512334571445,0.001234960214472,68.9350973441037,100.0,8.333333333333333e-05,0.56,0.23,0.18,0.07,0.86,0.06,0.02,0.01
14.242890704499043,0.0012839917452993,72.0219032874857,100.0,8.333333333333333e-05,0.56,0.23,0.18,0.07,0.86,0.06,0.02,0.01
14.776000390734644,0.0013284175524856,75.1383210226398,100.0,8.333333333333333e-05,0.56,0.23,0.18,0.07,0.86,0.06,0.02,0.01
15.362031054627046,0.0013772534411433,78.2045079102944,100.0,8.333333333333333e-05,0.56,0.23,0.18,0.07,0.86,0.06,0.02,0.01
15.972184272327045,0.0014280995426183,81.2570840831065,100.0,8.333333333333333e-05,0.56,0.23,0.18,0.07,0.86,0.06,0.02,0.01
16.573475399097045,0.0014782071365158,84.3050264306479,100.0,8.333333333333333e-05,0.56,0.23,0.18,0.07,0.86,0.06,0.02,0.01
17.080207671215447,0.001520434825859,87.3957124014862,100.0,8.333333333333333e-05,0.56,0.23,0.18,0.07,0.86,0.06,0.02,0.01
17.675222403630645,0.0015700193868936,90.4587419642287,100.0,8.333333333333333e-05,0.56,0.23,0.18,0.07,0.86,0.06,0.02,0.01
18.323626892298645,0.0016240530942826,93.5269106786542,100.0,8.333333333333333e-05,0.56,0.23,0.18,0.07,0.86,0.06,0.02,0.01
18.956423565454244,0.0016767861503789,96.5898691180327,100.0,8.333333333333333e-05,0.56,0.23,0.18,0.07,0.86,0.06,0.02,0.01
19.574226410422245,0.0017282697207929,99.6642411046778,100.0,8.333333333333333e-05,0.56,0.23,0.18,0.07,0.86,0.06,0.02,0.01
20.135655455862643,0.0017750554745796,102.714668004707,100.0,8.333333333333333e-05,0.56,0.23,0.18,0.07,0.86,0.06,0.02,0.01
20.719923861726645,0.0018237445084016,105.764801074623,100.0,8.333333333333333e-05,0.56,0.23,0.18,0.07,0.86,0.06,0.02,0.01
21.390839787255043,0.0018796541688623,108.804452873862,100.0,8.333333333333333e-05,0.56,0.23,0.18,0.07,0.86,0.06,0.02,0.01
22.000049438244645,0.0019304216397781,111.840203823929,100.0,8.333333333333333e-05,0.56,0.23,0.18,0.07,0.86,0.06,0.02,0.01
22.520913464125847,0.0019738269752682,114.819900339643,100.0,8.333333333333333e-05,0.56,0.23,0.18,0.07,0.86,0.06,0.02,0.01
23.11411862289424,0.0020232607384989,117.80871872158,100.0,8.333333333333333e-05,0.56,0.23,0.18,0.07,0.86,0.06,0.02,0.01
23.733386390473846,0.0020748663857972,120.804585989403,100.0,8.333333333333333e-05,0.56,0.23,0.18,0.07,0.86,0.06,0.02,0.01
24.34775209192024,0.0021260635275844,123.769914309488,100.0,8.333333333333333e-05,0.56,0.23,0.18,0.07,0.86,0.06,0.02,0.01
24.964728877375848,0.0021774782597057,126.740565703723,100.0,8.333333333333333e-05,0.56,0.23,0.18,0.07,0.86,0.06,0.02,0.01
25.56765201790864,0.0022277218547501,129.68649690721,100.0,8.333333333333333e-05,0.56,0.23,0.18,0.07,0.86,0.06,0.02,0.01
26.103707487855047,0.0022723931439123,132.609977002406,100.0,8.333333333333333e-05,0.56,0.23,0.18,0.07,0.86,0.06,0.02,0.01
26.733627303358244,0.0023248864618709,135.533500517905,100.0,8.333333333333333e-05,0.56,0.23,0.18,0.07,0.86,0.06,0.02,0.01
27.350513098309847,0.0023762936114502,138.43262828344,100.0,8.333333333333333e-05,0.56,0.23,0.18,0.07,0.86,0.06,0.02,0.01
27.888270554373044,0.0024211067327888,141.33147118399,100.0,8.333333333333333e-05,0.56,0.23,0.18,0.07,0.86,0.06,0.02,0.01
28.489189001557843,0.0024711832700542,144.20815026424,100.0,8.333333333333333e-05,0.56,0.23,0.18,0.07,0.86,0.06,0.02,0.01
29.261992333147845,0.0025355835476867,147.057775974646,100.0,8.333333333333333e-05,0.56,0.23,0.18,0.07,0.86,0.06,0.02,0.01
29.804276081239845,0.0025807738600277,149.882679265137,100.0,8.333333333333333e-05,0.56,0.23,0.18,0.07,0.86,0.06,0.02,0.01
30.474622618795845,0.0026366360714907,152.698803060447,100.0,8.333333333333333e-05,0.56,0.23,0.18,0.07,0.86,0.06,0.02,0.01
30.984041850293448,0.0026790876741155,155.495729992701,100.0,8.333333333333333e-05,0.56,0.23,0.18,0.07,0.86,0.06,0.02,0.01
31.47538160932024,0.0027200326540344,158.271450047467,100.0,8.333333333333333e-05,0.56,0.23,0.18,0.07,0.86,0.06,0.02,0.01
31.99787975248144,0.0027635741659645,161.022747602258,100.0,8.333333333333333e-05,0.56,0.23,0.18,0.07,0.86,0.06,0.02,0.01
32.496377331010244,0.0028051156308419,163.756192158888,100.0,8.333333333333333e-05,0.56,0.23,0.18,0.07,0.86,0.06,0.02,0.01
32.86308804042544,0.0028356748566265,166.480294226333,100.0,8.333333333333333e-05,0.56,0.23,0.18,0.07,0.86,0.06,0.02,0.01
33.428029151217046,0.0028827532825258,169.196286162659,100.0,8.333333333333333e-05,0.56,0.23,0.18,0.07,0.86,0.06,0.02,0.01
33.90786164188624,0.0029227393234149,171.880246610574,100.0,8.333333333333333e-05,0.56,0.23,0.18,0.07,0.86,0.06,0.02,0.01
34.48994134822024,0.0029712459656094,174.554908151143,100.0,8.333333333333333e-05,0.56,0.23,0.18,0.07,0.86,0.06,0.02,0.01
35.03823102740224,0.0030169367722079,177.205241075224,100.0,8.333333333333333e-05,0.56,0.23,0.18,0.07,0.86,0.06,0.02,0.01
35.60147901708904,0.0030638741046818,179.803601138221,100.0,8.333333333333333e-05,0.56,0.23,0.18,0.07,0.86,0.06,0.02,0.01
36.18176089843864,0.0031122309281276,182.398811419938,100.0,8.333333333333333e-05,0.56,0.23,0.18,0.07,0.86,0.06,0.02,0.01
36.99247529667784,0.0031797904613142,184.962353082935,100.0,8.333333333333333e-05,0.56,0.23,0.18,0.07,0.86,0.06,0.02,0.01
37.59612431764624,0.0032300945463949,187.501132911751,100.0,8.333333333333333e-05,0.56,0.23,0.18,0.07,0.86,0.06,0.02,0.01
38.15974941922985,0.0032770633048602,190.029515402891,100.0,8.333333333333333e-05,0.56,0.23,0.18,0.07,0.86,0.06,0.02,0.01
38.73541497158704,0.0033250354342233,192.551901142868,100.0,8.333333333333333e-05,0.56,0.23,0.18,0.07,0.86,0.06,0.02,0.01
39.22717819597024,0.0033660157029219,195.020787510515,100.0,8.333333333333333e-05,0.56,0.23,0.18,0.07,0.86,0.06,0.02,0.01
39.88415117043784,0.0034207634507942,197.476422043123,100.0,8.333333333333333e-05,0.56,0.23,0.18,0.07,0.86,0.06,0.02,0.01
40.45533805231264,0.0034683623576171,199.936012717948,100.0,8.333333333333333e-05,0.56,0.23,0.18,0.07,0.86,0.06,0.02,0.01
40.73725386946864,0.0034918553423801,202.358203180741,100.0,8.333333333333333e-05,0.56,0.23,0.18,0.07,0.86,0.06,0.02,0.01
41.27300395075744,0.0035365011824875,204.713986890995,100.0,8.333333333333333e-05,0.56,0.23,0.18,0.07,0.86,0.06,0.02,0.01
41.92884111963544,0.003591154279894,207.039869938453,100.0,8.333333333333333e-05,0.56,0.23,0.18,0.07,0.86,0.06,0.02,0.01
42.494129028202245,0.0036382616056079,209.309725156188,100.0,8.333333333333333e-05,0.56,0.23,0.18,0.07,0.86,0.06,0.02,0.01
43.20990900855184,0.0036979099373037,211.578684781675,100.0,8.333333333333333e-05,0.56,0.23,0.18,0.07,0.86,0.06,0.02,0.01
43.72656128500384,0.0037409642936747,213.822464410247,100.0,8.333333333333333e-05,0.56,0.23,0.18,0.07,0.86,0.06,0.02,0.01
43.99715659690384,0.0037635139029997,216.00497146272,100.0,8.333333333333333e-05,0.56,0.23,0.18,0.07,0.86,0.06,0.02,0.01
44.59067429007544,0.003812973710764,218.150542761503,100.0,8.333333333333333e-05,0.56,0.23,0.18,0.07,0.86,0.06,0.02,0.01
45.09134711746504,0.0038546964463798,220.232988319146,100.0,8.333333333333333e-05,0.56,0.23,0.18,0.07,0.86,0.06,0.02,0.01
45.70499237938984,0.0039058335515402,222.290201655973,100.0,8.333333333333333e-05,0.56,0.23,0.18,0.07,0.86,0.06,0.02,0.01
46.43085849306424,0.0039663223943464,224.324308299287,100.0,8.333333333333333e-05,0.56,0.23,0.18,0.07,0.86,0.06,0.02,0.01
47.18200201674425,0.0040289176879864,226.286927691328,100.0,8.333333333333333e-05,0.56,0.23,0.18,0.07,0.86,0.06,0.02,0.01
48.02087955278704,0.0040988241493233,228.182988957439,100.0,8.333333333333333e-05,0.56,0.23,0.18,0.07,0.86,0.06,0.02,0.01
49.26795704241064,0.0042027472734586,230.003235156773,100.0,8.333333333333333e-05,0.56,0.23,0.18,0.07,0.86,0.06,0.02,0.01
50.36303233994704,0.0042940035482533,231.722837935503,100.0,8.333333333333333e-05,0.56,0.23,0.18,0.07,0.86,0.06,0.02,0.01
51.708839091016245,0.0044061541108424,233.363198690204,100.0,8.333333333333333e-05,0.56,0.23,0.18,0.07,0.86,0.06,0.02,0.01
53.04617329047544,0.004517598627464,234.796868988757,100.0,8.333333333333333e-05,0.56,0.23,0.18,0.07,0.86,0.06,0.02,0.01
54.51200228314624,0.0046397510435199,236.033132828931,100.0,8.333333333333333e-05,0.56,0.23,0.18,0.07,0.86,0.06,0.02,0.01
56.20809514388345,0.004781092115248,237.076984547292,100.0,8.333333333333333e-05,0.56,0.23,0.18,0.07,0.86,0.06,0.02,0.01
57.97639997094304,0.0049284508508363,237.944270584394,100.0,8.333333333333333e-05,0.56,0.23,0.18,0.07,0.86,0.06,0.02,0.01
59.84722531710064,0.0050843529630161,238.606686829773,100.0,8.333333333333333e-05,0.56,0.23,0.18,0.07,0.86,0.06,0.02,0.01
61.78452939543424,0.0052457949695439,239.087315278414,100.0,8.333333333333333e-05,0.56,0.23,0.18,0.07,0.86,0.06,0.02,0.01
63.84103301025065,0.0054171702707786,239.462231195854,100.0,8.333333333333333e-05,0.56,0.23,0.18,0.07,0.86,0.06,0.02,0.01
65.96529119658065,0.0055941917863061,239.745431734418,100.0,8.333333333333333e-05,0.56,0.23,0.18,0.07,0.86,0.06,0.02,0.01
68.13962342956384,0.0057753861390547,239.939554144562,100.0,8.333333333333333e-05,0.56,0.23,0.18,0.07,0.86,0.06,0.02,0.01
70.26629498870345,0.005952608768983,240.102821662868,100.0,8.333333333333333e-05,0.56,0.23,0.18,0.07,0.86,0.06,0.02,0.01
72.19912121155265,0.0061136776208871,240.224649846974,100.0,8.333333333333333e-05,0.56,0.23,0.18,0.07,0.86,0.06,0.02,0.01
74.41922748773945,0.006298686477236,240.316946327802,100.0,8.333333333333333e-05,0.56,0.23,0.18,0.07,0.86,0.06,0.02,0.01
76.70937642209825,0.0064895322217659,240.429731296529,100.0,8.333333333333333e-05,0.56,0.23,0.18,0.07,0.86,0.06,0.02,0.01
78.94266846984306,0.0066756398924113,240.496696697811,100.0,8.333333333333333e-05,0.56,0.23,0.18,0.07,0.86,0.06,0.02,0.01
81.15638458634585,0.0068601162354532,240.579626814749,100.0,8.333333333333333e-05,0.56,0.23,0.18,0.07,0.86,0.06,0.02,0.01
83.38297586149265,0.0070456655083821,240.663258667133,100.0,8.333333333333333e-05,0.56,0.23,0.18,0.07,0.86,0.06,0.02,0.01
85.64367901373225,0.0072340574377354,240.751691936181,100.0,8.333333333333333e-05,0.56,0.23,0.18,0.07,0.86,0.06,0.02,0.01
88.20146338121945,0.007447206135026,240.826667640651,100.0,8.333333333333333e-05,0.56,0.23,0.18,0.07,0.86,0.06,0.02,0.01
90.45930735978304,0.0076353597999063,240.893537381574,100.0,8.333333333333333e-05,0.56,0.23,0.18,0.07,0.86,0.06,0.02,0.01
92.71279122714904,0.0078231501221868,240.957338253534,100.0,8.333333333333333e-05,0.56,0.23,0.18,0.07,0.86,0.06,0.02,0.01
94.93980024037624,0.0080087342066224,241.024984407014,100.0,8.333333333333333e-05,0.56,0.23,0.18,0.07,0.86,0.06,0.02,0.01
97.13989585410066,0.0081920755077661,241.076483828471,100.0,8.333333333333333e-05,0.56,0.23,0.18,0.07,0.86,0.06,0.02,0.01
99.39648808294623,0.0083801248601699,241.142785632453,100.0,8.333333333333333e-05,0.56,0.23,0.18,0.07,0.86,0.06,0.02,0.01
101.64536034255784,0.0085675308818042,241.20470705781,100.0,8.333333333333333e-05,0.56,0.23,0.18,0.07,0.86,0.06,0.02,0.01
103.87685121327785,0.0087534884543642,241.273546316623,100.0,8.333333333333333e-05,0.56,0.23,0.18,0.07,0.86,0.06,0.02,0.01
106.14037364104026,0.0089421153233444,241.370333729859,100.0,8.333333333333333e-05,0.56,0.23,0.18,0.07,0.86,0.06,0.02,0.01
108.37126638481143,0.009128023051992,241.417717623628,100.0,8.333333333333333e-05,0.56,0.23,0.18,0.07,0.86,0.06,0.02,0.01
110.61717932051104,0.0093151824633003,241.464673727244,100.0,8.333333333333333e-05,0.56,0.23,0.18,0.07,0.86,0.06,0.02,0.01
112.90225708939144,0.009505605610707,241.535207072541,100.0,8.333333333333333e-05,0.56,0.23,0.18,0.07,0.86,0.06,0.02,0.01
115.14327814455426,0.0096923573653039,241.609870532036,100.0,8.333333333333333e-05,0.56,0.23,0.18,0.07,0.86,0.06,0.02,0.01
117.37219850843944,0.009878100728961,241.66833776553,100.0,8.333333333333333e-05,0.56,0.23,0.18,0.07,0.86,0.06,0.02,0.01
119.65930632580624,0.0100686930470749,241.736863325564,100.0,8.333333333333333e-05,0.56,0.23,0.18,0.07,0.86,0.06,0.02,0.01
121.88484123364026,0.0102541542893944,241.767592124062,100.0,8.333333333333333e-05,0.56,0.23,0.18,0.07,0.86,0.06,0.02,0.01
124.12066209530585,0.0104404726945332,241.851794320242,100.0,8.333333333333333e-05,0.56,0.23,0.18,0.07,0.86,0.06,0.02,0.01
126.36543114655986,0.0106275367821377,241.939559517502,100.0,8.333333333333333e-05,0.56,0.23,0.18,0.07,0.86,0.06,0.02,0.01
128.53252425533583,0.0108081278745357,242.015587986677,100.0,8.333333333333333e-05,0.56,0.23,0.18,0.07,0.86,0.06,0.02,0.01
130.79858579836983,0.0109969663364552,242.105801859751,100.0,8.333333333333333e-05,0.56,0.23,0.18,0.07,0.86,0.06,0.02,0.01
132.93272024790062,0.0111748108739161,242.201971163625,100.0,8.333333333333333e-05,0.56,0.23,0.18,0.07,0.86,0.06,0.02,0.01
135.09394328158265,0.0113549127933896,242.279995076876,100.0,8.333333333333333e-05,0.56,0.23,0.18,0.07,0.86,0.06,0.02,0.01
137.33391799021263,0.0115415773524421,242.403786818272,100.0,8.333333333333333e-05,0.56,0.23,0.18,0.07,0.86,0.06,0.02,0.01
139.56872128780384,0.0117278109605747,242.489504008333,100.0,8.333333333333333e-05,0.56,0.23,0.18,0.07,0.86,0.06,0.02,0.01
141.78988040609224,0.0119129075537654,242.577169846108,100.0,8.333333333333333e-05,0.56,0.23,0.18,0.07,0.86,0.06,0.02,0.01
144.16643505514864,0.0121109537745201,242.657964662942,100.0,8.333333333333333e-05,0.56,0.23,0.18,0.07,0.86,0.06,0.02,0.01
146.32134356164025,0.0122905294833944,242.722585674677,100.0,8.333333333333333e-05,0.56,0.23,0.18,0.07,0.86,0.06,0.02,0.01
148.62577644872223,0.0124825655573179,242.786534592431,100.0,8.333333333333333e-05,0.56,0.23,0.18,0.07,0.86,0.06,0.02,0.01
150.85480527299944,0.012668317959341,242.842410548008,100.0,8.333333333333333e-05,0.56,0.23,0.18,0.07,0.86,0.06,0.02,0.01
153.03621327231423,0.0128501019592839,242.885981370111,100.0,8.333333333333333e-05,0.56,0.23,0.18,0.07,0.86,0.06,0.02,0.01
155.21367831803704,0.0130315573797608,242.955719581076,100.0,8.333333333333333e-05,0.56,0.23,0.18,0.07,0.86,0.06,0.02,0.01
157.39718365676703,0.0132135161579883,243.01326335773,100.0,8.333333333333333e-05,0.56,0.23,0.18,0.07,0.86,0.06,0.02,0.01
159.41559989034903,0.0133817175107868,243.070149287689,100.0,8.333333333333333e-05,0.56,0.23,0.18,0.07,0.86,0.06,0.02,0.01
161.60312387022665,0.0135640111757766,243.149148106319,100.0,8.333333333333333e-05,0.56,0.23,0.18,0.07,0.86,0.06,0.02,0.01
163.80800994011102,0.0137477516816003,243.24258466091,100.0,8.333333333333333e-05,0.56,0.23,0.18,0.07,0.86,0.06,0.02,0.01
166.02152833962543,0.0139322115482265,243.328740512354,100.0,8.333333333333333e-05,0.56,0.23,0.18,0.07,0.86,0.06,0.02,0.01
168.27841280117704,0.0141202852533558,243.425236647712,100.0,8.333333333333333e-05,0.56,0.23,0.18,0.07,0.86,0.06,0.02,0.01
170.43388485025383,0.0142999079241122,243.517494182723,100.0,8.333333333333333e-05,0.56,0.23,0.18,0.07,0.86,0.06,0.02,0.01
172.58935095862145,0.0144795300998095,243.60618682671,100.0,8.333333333333333e-05,0.56,0.23,0.18,0.07,0.86,0.06,0.02,0.01
174.77579079476226,0.0146617334194879,243.693836818011,100.0,8.333333333333333e-05,0.56,0.23,0.18,0.07,0.86,0.06,0.02,0.01
176.93398828868945,0.0148415832106485,243.792880504067,100.0,8.333333333333333e-05,0.56,0.23,0.18,0.07,0.86,0.06,0.02,0.01
179.06072314515785,0.0150188111153542,243.853653682047,100.0,8.333333333333333e-05,0.56,0.23,0.18,0.07,0.86,0.06,0.02,0.01
181.15408438940585,0.0151932578857082,243.940016199927,100.0,8.333333333333333e-05,0.56,0.23,0.18,0.07,0.86,0.06,0.02,0.01
183.25894957040464,0.0153686633174581,244.020853936311,100.0,8.333333333333333e-05,0.56,0.23,0.18,0.07,0.86,0.06,0.02,0.01
185.41868688254945,0.0155486414268035,244.105476863615,100.0,8.333333333333333e-05,0.56,0.23,0.18,0.07,0.86,0.06,0.02,0.01
187.57514764096743,0.015728346490005,244.216442944788,100.0,8.333333333333333e-05,0.56,0.23,0.18,0.07,0.86,0.06,0.02,0.01
189.75600966034025,0.0159100849916194,244.308621828957,100.0,8.333333333333333e-05,0.56,0.23,0.18,0.07,0.86,0.06,0.02,0.01
191.88185118679985,0.0160872384521577,244.359315535614,100.0,8.333333333333333e-05,0.56,0.23,0.18,0.07,0.86,0.06,0.02,0.01
193.94414441885465,0.0162590962214956,244.410581362939,100.0,8.333333333333333e-05,0.56,0.23,0.18,0.07,0.86,0.06,0.02,0.01
196.09283320023425,0.0164381536199439,244.460669640643,100.0,8.333333333333333e-05,0.56,0.23,0.18,0.07,0.86,0.06,0.02,0.01
198.18406064565664,0.0166124225737291,244.496906243427,100.0,8.333333333333333e-05,0.56,0.23,0.18,0.07,0.86,0.06,0.02,0.01
200.28787622083985,0.0167877405383277,244.549286040642,100.0,8.333333333333333e-05,0.56,0.23,0.18,0.07,0.86,0.06,0.02,0.01
202.37388821329623,0.0169615748710324,244.592870948498,100.0,8.333333333333333e-05,0.56,0.23,0.18,0.07,0.86,0.06,0.02,0.01
204.49048730064663,0.0171379581283116,244.698490710797,100.0,8.333333333333333e-05,0.56,0.23,0.18,0.07,0.86,0.06,0.02,0.01
206.56998110242503,0.0173112492784598,244.77116433144,100.0,8.333333333333333e-05,0.56,0.23,0.18,0.07,0.86,0.06,0.02,0.01
208.70633207717944,0.017489278526356,244.840689769989,100.0,8.333333333333333e-05,0.56,0.23,0.18,0.07,0.86,0.06,0.02,0.01
210.72993055757465,0.0176579117330556,244.915269441864,100.0,8.333333333333333e-05,0.56,0.23,0.18,0.07,0.86,0.06,0.02,0.01
212.83528678640585,0.0178333580854582,245.006288545138,100.0,8.333333333333333e-05,0.56,0.23,0.18,0.07,0.86,0.06,0.02,0.01
214.89323581691224,0.0180048538380004,245.065452070388,100.0,8.333333333333333e-05,0.56,0.23,0.18,0.07,0.86,0.06,0.02,0.01
216.9325350708654,0.0181747954424965,245.163014103155,100.0,8.333333333333333e-05,0.56,0.23,0.18,0.07,0.86,0.06,0.02,0.01
219.03187906947423,0.0183497407757139,245.223947490429,100.0,8.333333333333333e-05,0.56,0.23,0.18,0.07,0.86,0.06,0.02,0.01
221.15600343448503,0.0185267511394648,245.306658599742,100.0,8.333333333333333e-05,0.56,0.23,0.18,0.07,0.86,0.06,0.02,0.01
223.25283062771345,0.0187014867389005,245.419225513895,100.0,8.333333333333333e-05,0.56,0.23,0.18,0.07,0.86,0.06,0.02,0.01
225.41850942364383,0.0188819599718947,245.525648099538,100.0,8.333333333333333e-05,0.56,0.23,0.18,0.07,0.86,0.06,0.02,0.01
227.52954153000184,0.0190578793140912,245.614092094435,100.0,8.333333333333333e-05,0.56,0.23,0.18,0.07,0.86,0.06,0.02,0.01
229.64599011487024,0.0192342500294969,245.702002429879,100.0,8.333333333333333e-05,0.56,0.23,0.18,0.07,0.86,0.06,0.02,0.01
231.77581216750505,0.0194117352005498,245.759929429491,100.0,8.333333333333333e-05,0.56,0.23,0.18,0.07,0.86,0.06,0.02,0.01
233.86406471177824,0.0195857562459059,245.811742872796,100.0,8.333333333333333e-05,0.56,0.23,0.18,0.07,0.86,0.06,0.02,0.01
236.01645056750343,0.019765121733883,245.877538575003,100.0,8.333333333333333e-05,0.56,0.23,0.18,0.07,0.86,0.06,0.02,0.01
238.24316981279344,0.0199506816709905,245.944438135079,100.0,8.333333333333333e-05,0.56,0.23,0.18,0.07,0.86,0.06,0.02,0.01
240.27317810438947,0.0201198490286235,246.000570590292,100.0,8.333333333333333e-05,0.56,0.23,0.18,0.07,0.86,0.06,0.02,0.01
242.4256948545618,0.0202992254244712,246.050408135119,100.0,8.333333333333333e-05,0.56,0.23,0.18,0.07,0.86,0.06,0.02,0.01
244.53942901817345,0.0204753699381055,246.124701827427,100.0,8.333333333333333e-05,0.56,0.23,0.18,0.07,0.86,0.06,0.02,0.01
246.59581743153544,0.020646735639219,246.193601806823,100.0,8.333333333333333e-05,0.56,0.23,0.18,0.07,0.86,0.06,0.02,0.01
248.69542212669185,0.0208217026971487,246.250579068034,100.0,8.333333333333333e-05,0.56,0.23,0.18,0.07,0.86,0.06,0.02,0.01
250.66473796338784,0.0209858123502067,246.320697287433,100.0,8.333333333333333e-05,0.56,0.23,0.18,0.07,0.86,0.06,0.02,0.01
252.59948780295665,0.0211470415035041,246.385574152669,100.0,8.333333333333333e-05,0.56,0.23,0.18,0.07,0.86,0.06,0.02,0.01
254.71938532323185,0.0213236996301937,246.459189354253,100.0,8.333333333333333e-05,0.56,0.23,0.18,0.07,0.86,0.06,0.02,0.01
256.66600088806507,0.0214859175939298,246.552256610106,100.0,8.333333333333333e-05,0.56,0.23,0.18,0.07,0.86,0.06,0.02,0.01
258.7634505291582,0.0216607050640209,246.632815732867,100.0,8.333333333333333e-05,0.56,0.23,0.18,0.07,0.86,0.06,0.02,0.01
260.89179363639425,0.0218380669896239,246.702624905663,100.0,8.333333333333333e-05,0.56,0.23,0.18,0.07,0.86,0.06,0.02,0.01
262.94481193385224,0.0220091518477454,246.765519459525,100.0,8.333333333333333e-05,0.56,0.23,0.18,0.07,0.86,0.06,0.02,0.01
265.1714524777506,0.0221947052264036,246.836490658537,100.0,8.333333333333333e-05,0.56,0.23,0.18,0.07,0.86,0.06,0.02,0.01
267.21885905605865,0.0223653224412626,246.903990203874,100.0,8.333333333333333e-05,0.56,0.23,0.18,0.07,0.86,0.06,0.02,0.01
269.28382367025665,0.0225374028257791,246.948821410168,100.0,8.333333333333333e-05,0.56,0.23,0.18,0.07,0.86,0.06,0.02,0.01
271.33371117501065,0.0227082267845086,246.998230066412,100.0,8.333333333333333e-05,0.56,0.23,0.18,0.07,0.86,0.06,0.02,0.01
273.3509314670683,0.0228763284755134,247.049238602585,100.0,8.333333333333333e-05,0.56,0.23,0.18,0.07,0.86,0.06,0.02,0.01
275.37869447982064,0.0230453087265761,247.053870828671,100.0,8.333333333333333e-05,0.56,0.23,0.18,0.07,0.86,0.06,0.02,0.01
277.4304458061786,0.0232162880037726,247.093554095839,100.0,8.333333333333333e-05,0.56,0.23,0.18,0.07,0.86,0.06,0.02,0.01
279.3745839121506,0.0233782995126036,247.152500051117,100.0,8.333333333333333e-05,0.56,0.23,0.18,0.07,0.86,0.06,0.02,0.01
281.3999163192942,0.0235470772131989,247.220787380996,100.0,8.333333333333333e-05,0.56,0.23,0.18,0.07,0.86,0.06,0.02,0.01
283.41148146304624,0.0237147076418449,247.294092405239,100.0,8.333333333333333e-05,0.56,0.23,0.18,0.07,0.86,0.06,0.02,0.01
285.4620074959194,0.023885584811251,247.36464560305,100.0,8.333333333333333e-05,0.56,0.23,0.18,0.07,0.86,0.06,0.02,0.01
287.48574221635386,0.0240542293712872,247.413663815771,100.0,8.333333333333333e-05,0.56,0.23,0.18,0.07,0.86,0.06,0.02,0.01
289.48588452298145,0.0242209078968395,247.500083371261,100.0,8.333333333333333e-05,0.56,0.23,0.18,0.07,0.86,0.06,0.02,0.01
291.4583053749054,0.0243852763011665,247.567946917026,100.0,8.333333333333333e-05,0.56,0.23,0.18,0.07,0.86,0.06,0.02,0.01
293.4895515175974,0.0245545468130575,247.616685869989,100.0,8.333333333333333e-05,0.56,0.23,0.18,0.07,0.86,0.06,0.02,0.01
295.5532412517906,0.0247265209575736,247.651697803721,100.0,8.333333333333333e-05,0.56,0.23,0.18,0.07,0.86,0.06,0.02,0.01
297.61543370965023,0.0248983703290619,247.729832755356,100.0,8.333333333333333e-05,0.56,0.23,0.18,0.07,0.86,0.06,0.02,0.01
299.60850979397947,0.025064460002756,247.79677861104,100.0,8.333333333333333e-05,0.56,0.23,0.18,0.07,0.86,0.06,0.02,0.01
301.5984167361091,0.0252302855812668,247.87901901065,100.0,8.333333333333333e-05,0.56,0.23,0.18,0.07,0.86,0.06,0.02,0.01
303.63696077553186,0.0254001642512187,247.951443174535,100.0,8.333333333333333e-05,0.56,0.23,0.18,0.07,0.86,0.06,0.02,0.01
305.6903880446034,0.025571283190308,248.008777070229,100.0,8.333333333333333e-05,0.56,0.23,0.18,0.07,0.86,0.06,0.02,0.01
307.68620146098783,0.0257376009750067,248.068357789011,100.0,8.333333333333333e-05,0.56,0.23,0.18,0.07,0.86,0.06,0.02,0.01
309.6237053886679,0.0258990596356467,248.137549983181,100.0,8.333333333333333e-05,0.56,0.23,0.18,0.07,0.86,0.06,0.02,0.01
311.62594676516227,0.0260659130836879,248.183457667353,100.0,8.333333333333333e-05,0.56,0.23,0.18,0.07,0.86,0.06,0.02,0.01
313.64924735528103,0.0262345214661978,248.234467964246,100.0,8.333333333333333e-05,0.56,0.23,0.18,0.07,0.86,0.06,0.02,0.01
315.7009157207179,0.0264054938299842,248.289461961034,100.0,8.333333333333333e-05,0.56,0.23,0.18,0.07,0.86,0.06,0.02,0.01
317.75347647726545,0.0265765405596965,248.362724534175,100.0,8.333333333333333e-05,0.56,0.23,0.18,0.07,0.86,0.06,0.02,0.01
319.7257690873279,0.0267408982772017,248.455835856468,100.0,8.333333333333333e-05,0.56,0.23,0.18,0.07,0.86,0.06,0.02,0.01
321.81030357051304,0.0269146094841338,248.525976206008,100.0,8.333333333333333e-05,0.56,0.23,0.18,0.07,0.86,0.06,0.02,0.01
323.93158503531544,0.027091382939534,248.586447380261,100.0,8.333333333333333e-05,0.56,0.23,0.18,0.07,0.86,0.06,0.02,0.01
325.95851951799546,0.027260294146424,248.648783269227,100.0,8.333333333333333e-05,0.56,0.23,0.18,0.07,0.86,0.06,0.02,0.01
328.0608208467546,0.0274354859238206,248.706193425061,100.0,8.333333333333333e-05,0.56,0.23,0.18,0.07,0.86,0.06,0.02,0.01
330.15547846333504,0.0276100407252023,248.740184965477,100.0,8.333333333333333e-05,0.56,0.23,0.18,0.07,0.86,0.06,0.02,0.01
332.15348567939463,0.0277765413265406,248.794138845662,100.0,8.333333333333333e-05,0.56,0.23,0.18,0.07,0.86,0.06,0.02,0.01
334.2799913261995,0.027953750130441,248.841282877784,100.0,8.333333333333333e-05,0.56,0.23,0.18,0.07,0.86,0.06,0.02,0.01
336.29527005485227,0.0281216900244954,248.872663901598,100.0,8.333333333333333e-05,0.56,0.23,0.18,0.07,0.86,0.06,0.02,0.01
338.35519894898346,0.028293350765673,248.882656693845,100.0,8.333333333333333e-05,0.56,0.23,0.18,0.07,0.86,0.06,0.02,0.01
340.10839275842585,0.0284394502497932,248.933838103569,100.0,8.333333333333333e-05,0.56,0.23,0.18,0.07,0.86,0.06,0.02,0.01
342.1755176711682,0.0286117106591884,248.975849413056,100.0,8.333333333333333e-05,0.56,0.23,0.18,0.07,0.86,0.06,0.02,0.01
344.2014536922234,0.028780538660943,249.033199639825,100.0,8.333333333333333e-05,0.56,0.23,0.18,0.07,0.86,0.06,0.02,0.01
346.26022091682063,0.0289521025963261,249.078845687583,100.0,8.333333333333333e-05,0.56,0.23,0.18,0.07,0.86,0.06,0.02,0.01
348.3450676684806,0.0291258398256311,249.128882209835,100.0,8.333333333333333e-05,0.56,0.23,0.18,0.07,0.86,0.06,0.02,0.01
350.32152362026864,0.0292905444882801,249.164588496917,100.0,8.333333333333333e-05,0.56,0.23,0.18,0.07,0.86,0.06,0.02,0.01
352.3457356316779,0.0294592288225642,249.253276504881,100.0,8.333333333333333e-05,0.56,0.23,0.18,0.07,0.86,0.06,0.02,0.01
354.70030147391344,0.0296554426427505,249.303666124023,100.0,8.333333333333333e-05,0.56,0.23,0.18,0.07,0.86,0.06,0.02,0.01
356.6056674127866,0.0298142231376566,249.348245321323,100.0,8.333333333333333e-05,0.56,0.23,0.18,0.07,0.86,0.06,0.02,0.01
358.6060454623375,0.0299809213084525,249.379152113995,100.0,8.333333333333333e-05,0.56,0.23,0.18,0.07,0.86,0.06,0.02,0.01
360.66139707037024,0.0301522006091219,249.386765431538,100.0,8.333333333333333e-05,0.56,0.23,0.18,0.07,0.86,0.06,0.02,0.01
362.6479822150303,0.0303177493711769,249.411170001253,100.0,8.333333333333333e-05,0.56,0.23,0.18,0.07,0.86,0.06,0.02,0.01
364.8173208397386,0.0304985275899026,249.469133378294,100.0,8.333333333333333e-05,0.56,0.23,0.18,0.07,0.86,0.06,0.02,0.01
366.844490204295,0.0306674583702823,249.503576551262,100.0,8.333333333333333e-05,0.56,0.23,0.18,0.07,0.86,0.06,0.02,0.01
368.8638085173546,0.0308357348963706,249.532046363171,100.0,8.333333333333333e-05,0.56,0.23,0.18,0.07,0.86,0.06,0.02,0.01
370.9794580566318,0.0310120390246437,249.545080628238,100.0,8.333333333333333e-05,0.56,0.23,0.18,0.07,0.86,0.06,0.02,0.01
373.0228540265982,0.0311823220221409,249.596159334725,100.0,8.333333333333333e-05,0.56,0.23,0.18,0.07,0.86,0.06,0.02,0.01
375.08396196186783,0.0313540810167467,249.670946157638,100.0,8.333333333333333e-05,0.56,0.23,0.18,0.07,0.86,0.06,0.02,0.01
377.1146555449122,0.0315233054820004,249.719554542772,100.0,8.333333333333333e-05,0.56,0.23,0.18,0.07,0.86,0.06,0.02,0.01
379.0537671800803,0.0316848981182644,249.740337975368,100.0,8.333333333333333e-05,0.56,0.23,0.18,0.07,0.86,0.06,0.02,0.01
381.0790735412526,0.0318536736483621,249.768687137628,100.0,8.333333333333333e-05,0.56,0.23,0.18,0.07,0.86,0.06,0.02,0.01
383.06345189510586,0.0320190385111832,249.79960995446,100.0,8.333333333333333e-05,0.56,0.23,0.18,0.07,0.86,0.06,0.02,0.01
385.107067432419,0.0321893398059593,249.859304263861,100.0,8.333333333333333e-05,0.56,0.23,0.18,0.07,0.86,0.06,0.02,0.01
387.12190786115343,0.0323572431750205,249.89810843139,100.0,8.333333333333333e-05,0.56,0.23,0.18,0.07,0.86,0.06,0.02,0.01
389.11180323062223,0.0325230677891429,249.95440607114,100.0,8.333333333333333e-05,0.56,0.23,0.18,0.07,0.86,0.06,0.02,0.01
391.0851368416278,0.0326875122567267,250.017773095426,100.0,8.333333333333333e-05,0.56,0.23,0.18,0.07,0.86,0.06,0.02,0.01
393.1135745445727,0.0328565487319721,250.112223323525,100.0,8.333333333333333e-05,0.56,0.23,0.18,0.07,0.86,0.06,0.02,0.01
395.1844519814322,0.0330291218517104,250.183512065822,100.0,8.333333333333333e-05,0.56,0.23,0.18,0.07,0.86,0.06,0.02,0.01
397.2471344324706,0.0332010120559636,250.209905989787,100.0,8.333333333333333e-05,0.56,0.23,0.18,0.07,0.86,0.06,0.02,0.01
399.2563202619679,0.0333684442084217,250.268841849198,100.0,8.333333333333333e-05,0.56,0.23,0.18,0.07,0.86,0.06,0.02,0.01
401.294389429137,0.0335382833056858,250.331321293316,100.0,8.333333333333333e-05,0.56,0.23,0.18,0.07,0.86,0.06,0.02,0.01
403.313104027173,0.0337065095221888,250.370579984855,100.0,8.333333333333333e-05,0.56,0.23,0.18,0.07,0.86,0.06,0.02,0.01
405.36659290917066,0.0338776335956886,250.393184243411,100.0,8.333333333333333e-05,0.56,0.23,0.18,0.07,0.86,0.06,0.02,0.01
407.46593690777945,0.034052578928906,250.421981355252,100.0,8.333333333333333e-05,0.56,0.23,0.18,0.07,0.86,0.06,0.02,0.01
409.4363802162535,0.0342167825379455,250.464327831371,100.0,8.333333333333333e-05,0.56,0.23,0.18,0.07,0.86,0.06,0.02,0.01
411.45702363483423,0.0343851694894939,250.540128489326,100.0,8.333333333333333e-05,0.56,0.23,0.18,0.07,0.86,0.06,0.02,0.01
413.51138971474745,0.03455636666282,250.575060625325,100.0,8.333333333333333e-05,0.56,0.23,0.18,0.07,0.86,0.06,0.02,0.01
415.5463650170094,0.0347259479380085,250.6051309633,100.0,8.333333333333333e-05,0.56,0.23,0.18,0.07,0.86,0.06,0.02,0.01
417.6682225820071,0.0349027694017583,250.629252590285,100.0,8.333333333333333e-05,0.56,0.23,0.18,0.07,0.86,0.06,0.02,0.01
419.74885729787707,0.0350761556280808,250.680754580131,100.0,8.333333333333333e-05,0.56,0.23,0.18,0.07,0.86,0.06,0.02,0.01
421.79652909496986,0.0352467949445052,250.714424086619,100.0,8.333333333333333e-05,0.56,0.23,0.18,0.07,0.86,0.06,0.02,0.01
423.952974779169,0.0354264987515218,250.758039282076,100.0,8.333333333333333e-05,0.56,0.23,0.18,0.07,0.86,0.06,0.02,0.01
426.052848212535,0.0356014882043023,250.794914008269,100.0,8.333333333333333e-05,0.56,0.23,0.18,0.07,0.86,0.06,0.02,0.01
428.1368460457218,0.0357751546904012,250.832282026601,100.0,8.333333333333333e-05,0.56,0.23,0.18,0.07,0.86,0.06,0.02,0.01
430.2405417442602,0.0359504626652794,250.878570526876,100.0,8.333333333333333e-05,0.56,0.23,0.18,0.07,0.86,0.06,0.02,0.01
432.2633704817526,0.0361190317267371,250.904180850027,100.0,8.333333333333333e-05,0.56,0.23,0.18,0.07,0.86,0.06,0.02,0.01
434.2879526122615,0.0362877469042795,250.92763038303,100.0,8.333333333333333e-05,0.56,0.23,0.18,0.07,0.86,0.06,0.02,0.01
436.4203854887647,0.0364654496439881,250.952954096631,100.0,8.333333333333333e-05,0.56,0.23,0.18,0.07,0.86,0.06,0.02,0.01
438.38586370549626,0.0366292394953824,250.954762904471,100.0,8.333333333333333e-05,0.56,0.23,0.18,0.07,0.86,0.06,0.02,0.01
440.4395481459031,0.0368003798654163,250.964518419614,100.0,8.333333333333333e-05,0.56,0.23,0.18,0.07,0.86,0.06,0.02,0.01
442.46871707487423,0.0369694772761639,250.966550564186,100.0,8.333333333333333e-05,0.56,0.23,0.18,0.07,0.86,0.06,0.02,0.01
444.5234196284238,0.0371407024889597,250.956210603341,100.0,8.333333333333333e-05,0.56,0.23,0.18,0.07,0.86,0.06,0.02,0.01
446.5593070453758,0.0373103597737057,251.008179942986,100.0,8.333333333333333e-05,0.56,0.23,0.18,0.07,0.86,0.06,0.02,0.01
448.649762213421,0.0374845643710428,251.056690600127,100.0,8.333333333333333e-05,0.56,0.23,0.18,0.07,0.86,0.06,0.02,0.01
450.5576336221027,0.0376435536550996,251.078647915525,100.0,8.333333333333333e-05,0.56,0.23,0.18,0.07,0.86,0.06,0.02,0.01
452.632319139147,0.0378164441148533,251.088867404409,100.0,8.333333333333333e-05,0.56,0.23,0.18,0.07,0.86,0.06,0.02,0.01
454.6753181232546,0.0379866940301956,251.119031302803,100.0,8.333333333333333e-05,0.56,0.23,0.18,0.07,0.86,0.06,0.02,0.01
456.7276480229334,0.0381577215218355,251.190855626807,100.0,8.333333333333333e-05,0.56,0.23,0.18,0.07,0.86,0.06,0.02,0.01
458.77355078006826,0.0383282134182634,251.236336813095,100.0,8.333333333333333e-05,0.56,0.23,0.18,0.07,0.86,0.06,0.02,0.01
460.8125470180351,0.0384981297714273,251.276071334961,100.0,8.333333333333333e-05,0.56,0.23,0.18,0.07,0.86,0.06,0.02,0.01
462.8396213670786,0.0386670526338476,251.306171314402,100.0,8.333333333333333e-05,0.56,0.23,0.18,0.07,0.86,0.06,0.02,0.01
464.8606858553454,0.0388354746745365,251.341815281716,100.0,8.333333333333333e-05,0.56,0.23,0.18,0.07,0.86,0.06,0.02,0.01
466.9227562779823,0.0390073138764229,251.395764348192,100.0,8.333333333333333e-05,0.56,0.23,0.18,0.07,0.86,0.06,0.02,0.01
468.9130793026314,0.039173174128477,251.435966526771,100.0,8.333333333333333e-05,0.56,0.23,0.18,0.07,0.86,0.06,0.02,0.01
470.97093669245226,0.0393446622442954,251.432685063078,100.0,8.333333333333333e-05,0.56,0.23,0.18,0.07,0.86,0.06,0.02,0.01
472.9707757920523,0.0395113155025954,251.463513204908,100.0,8.333333333333333e-05,0.56,0.23,0.18,0.07,0.86,0.06,0.02,0.01
475.0865060927563,0.0396876263609874,251.478235466631,100.0,8.333333333333333e-05,0.56,0.23,0.18,0.07,0.86,0.06,0.02,0.01
477.1435602301854,0.0398590475391065,251.505148479694,100.0,8.333333333333333e-05,0.56,0.23,0.18,0.07,0.86,0.06,0.02,0.01
479.2259863273111,0.0400325830472003,251.543844984897,100.0,8.333333333333333e-05,0.56,0.23,0.18,0.07,0.86,0.06,0.02,0.01
481.330522154199,0.0402079610327743,251.565134373888,100.0,8.333333333333333e-05,0.56,0.23,0.18,0.07,0.86,0.06,0.02,0.01
483.4063895413639,0.0403809499817047,251.607421728609,100.0,8.333333333333333e-05,0.56,0.23,0.18,0.07,0.86,0.06,0.02,0.01
485.5083720109686,0.0405561151875051,251.647274477116,100.0,8.333333333333333e-05,0.56,0.23,0.18,0.07,0.86,0.06,0.02,0.01
487.6004212249662,0.0407304526220049,251.675408799326,100.0,8.333333333333333e-05,0.56,0.23,0.18,0.07,0.86,0.06,0.02,0.01
489.6063601730334,0.0408976142010105,251.659858563434,100.0,8.333333333333333e-05,0.56,0.23,0.18,0.07,0.86,0.06,0.02,0.01
491.6739166734691,0.0410699105760468,251.628846499138,100.0,8.333333333333333e-05,0.56,0.23,0.18,0.07,0.86,0.06,0.02,0.01
493.69734535249984,0.0412385296326327,251.627589474851,100.0,8.333333333333333e-05,0.56,0.23,0.18,0.07,0.86,0.06,0.02,0.01
495.61418359947305,0.0413982661532138,251.668496441868,100.0,8.333333333333333e-05,0.56,0.23,0.18,0.07,0.86,0.06,0.02,0.01
497.6402578485403,0.0415671056739694,251.645980623107,100.0,8.333333333333333e-05,0.56,0.23,0.18,0.07,0.86,0.06,0.02,0.01
499.6410422052774,0.0417338377036975,251.567523815232,100.0,8.333333333333333e-05,0.56,0.23,0.18,0.07,0.86,0.06,0.02,0.01
501.68879613365226,0.0419044838643954,251.518130698547,100.0,8.333333333333333e-05,0.56,0.23,0.18,0.07,0.86,0.06,0.02,0.01
503.7372159332574,0.0420751855143625,251.634373202887,100.0,8.333333333333333e-05,0.56,0.23,0.18,0.07,0.86,0.06,0.02,0.01
505.74451038138426,0.0422424600517064,251.726561536788,100.0,8.333333333333333e-05,0.56,0.23,0.18,0.07,0.86,0.06,0.02,0.01
507.85833326716624,0.0424186119588549,251.795544173066,100.0,8.333333333333333e-05,0.56,0.23,0.18,0.07,0.86,0.06,0.02,0.01
509.9872158587778,0.0425960188414892,251.831866970324,100.0,8.333333333333333e-05,0.56,0.23,0.18,0.07,0.86,0.06,0.02,0.01
512.1027314321407,0.0427723118059361,251.90328002909,100.0,8.333333333333333e-05,0.56,0.23,0.18,0.07,0.86,0.06,0.02,0.01
514.1461296067374,0.0429425949871525,252.049118640263,100.0,8.333333333333333e-05,0.56,0.23,0.18,0.07,0.86,0.06,0.02,0.01
516.2517905045502,0.0431180667286369,252.168840341909,100.0,8.333333333333333e-05,0.56,0.23,0.18,0.07,0.86,0.06,0.02,0.01
518.3059422669907,0.0432892460421736,252.141908590917,100.0,8.333333333333333e-05,0.56,0.23,0.18,0.07,0.86,0.06,0.02,0.01
520.4079017790895,0.0434644093348485,252.136024784237,100.0,8.333333333333333e-05,0.56,0.23,0.18,0.07,0.86,0.06,0.02,0.01
522.4665143316006,0.0436359603808911,252.125324166715,100.0,8.333333333333333e-05,0.56,0.23,0.18,0.07,0.86,0.06,0.02,0.01
524.5608840064123,0.0438104911871254,252.105487257997,100.0,8.333333333333333e-05,0.56,0.23,0.18,0.07,0.86,0.06,0.02,0.01
526.6295588509063,0.0439828807574999,252.086573676892,100.0,8.333333333333333e-05,0.56,0.23,0.18,0.07,0.86,0.06,0.02,0.01
528.6885964520634,0.044154467224263,252.080632671067,100.0,8.333333333333333e-05,0.56,0.23,0.18,0.07,0.86,0.06,0.02,0.01
530.6605629442987,0.0443187977652826,252.084905387367,100.0,8.333333333333333e-05,0.56,0.23,0.18,0.07,0.86,0.06,0.02,0.01
532.7626004877799,0.0444939675605727,252.094904737889,100.0,8.333333333333333e-05,0.56,0.23,0.18,0.07,0.86,0.06,0.02,0.01
534.8270974910166,0.0446660089775091,252.09118779503,100.0,8.333333333333333e-05,0.56,0.23,0.18,0.07,0.86,0.06,0.02,0.01
536.8374043664322,0.0448335345504604,252.105998189634,100.0,8.333333333333333e-05,0.56,0.23,0.18,0.07,0.86,0.06,0.02,0.01
538.8657249259987,0.0450025612637576,252.154030771127,100.0,8.333333333333333e-05,0.56,0.23,0.18,0.07,0.86,0.06,0.02,0.01
540.9090837457206,0.0451728411654011,252.193048971037,100.0,8.333333333333333e-05,0.56,0.23,0.18,0.07,0.86,0.06,0.02,0.01
543.0420224815674,0.045350586060055,252.219321776904,100.0,8.333333333333333e-05,0.56,0.23,0.18,0.07,0.86,0.06,0.02,0.01
545.1886193906671,0.0455294691358133,252.244601424065,100.0,8.333333333333333e-05,0.56,0.23,0.18,0.07,0.86,0.06,0.02,0.01
547.3144185426247,0.0457066190651431,252.267778433272,100.0,8.333333333333333e-05,0.56,0.23,0.18,0.07,0.86,0.06,0.02,0.01
549.2538975431959,0.0458682423151907,252.309885871567,100.0,8.333333333333333e-05,0.56,0.23,0.18,0.07,0.86,0.06,0.02,0.01
551.3922613362055,0.0460464392979415,252.330688688227,100.0,8.333333333333333e-05,0.56,0.23,0.18,0.07,0.86,0.06,0.02,0.01
553.4803051482535,0.0462204429489455,252.318712793092,100.0,8.333333333333333e-05,0.56,0.23,0.18,0.07,0.86,0.06,0.02,0.01
555.5235519849379,0.0463907135186692,252.334379365679,100.0,8.333333333333333e-05,0.56,0.23,0.18,0.07,0.86,0.06,0.02,0.01
557.5458928616094,0.0465592419250585,252.337095929267,100.0,8.333333333333333e-05,0.56,0.23,0.18,0.07,0.86,0.06,0.02,0.01
559.6668012830071,0.0467359842935083,252.346220202344,100.0,8.333333333333333e-05,0.56,0.23,0.18,0.07,0.86,0.06,0.02,0.01
561.6968661597091,0.0469051563665668,252.355270945202,100.0,8.333333333333333e-05,0.56,0.23,0.18,0.07,0.86,0.06,0.02,0.01
563.981262141921,0.0470955226984178,252.352648895082,100.0,8.333333333333333e-05,0.56,0.23,0.18,0.07,0.86,0.06,0.02,0.01
566.0486316165499,0.0472678034879702,252.358262762509,100.0,8.333333333333333e-05,0.56,0.23,0.18,0.07,0.86,0.06,0.02,0.01
568.0684473718962,0.0474361214675824,252.391856170389,100.0,8.333333333333333e-05,0.56,0.23,0.18,0.07,0.86,0.06,0.02,0.01
570.2016828626874,0.047613891091815,252.422699997158,100.0,8.333333333333333e-05,0.56,0.23,0.18,0.07,0.86,0.06,0.02,0.01
572.2894727396827,0.0477878735815646,252.473532622944,100.0,8.333333333333333e-05,0.56,0.23,0.18,0.07,0.86,0.06,0.02,0.01
574.2880870455931,0.0479544247737238,252.478414467323,100.0,8.333333333333333e-05,0.56,0.23,0.18,0.07,0.86,0.06,0.02,0.01
576.4043142887874,0.04813077704399,252.504222976381,100.0,8.333333333333333e-05,0.56,0.23,0.18,0.07,0.86,0.06,0.02,0.01
578.5513082297958,0.0483096932057407,252.561691300563,100.0,8.333333333333333e-05,0.56,0.23,0.18,0.07,0.86,0.06,0.02,0.01
580.7168187439459,0.0484901524152532,252.62242168822,100.0,8.333333333333333e-05,0.56,0.23,0.18,0.07,0.86,0.06,0.02,0.01
582.8783860155751,0.0486702830212223,252.618065184301,100.0,8.333333333333333e-05,0.56,0.23,0.18,0.07,0.86,0.06,0.02,0.01
584.9959826110087,0.0488467494041751,252.598530456997,100.0,8.333333333333333e-05,0.56,0.23,0.18,0.07,0.86,0.06,0.02,0.01
587.1050891561047,0.0490225082829331,252.605735853053,100.0,8.333333333333333e-05,0.56,0.23,0.18,0.07,0.86,0.06,0.02,0.01
589.2321264973579,0.0491997613947042,252.634035182114,100.0,8.333333333333333e-05,0.56,0.23,0.18,0.07,0.86,0.06,0.02,0.01
591.2356956665875,0.04936672549214,252.63562192934,100.0,8.333333333333333e-05,0.56,0.23,0.18,0.07,0.86,0.06,0.02,0.01
593.1873964285411,0.0495293672223028,252.619163582325,100.0,8.333333333333333e-05,0.56,0.23,0.18,0.07,0.86,0.06,0.02,0.01
595.238654337621,0.0497003053813928,252.606951217754,100.0,8.333333333333333e-05,0.56,0.23,0.18,0.07,0.86,0.06,0.02,0.01
597.3306382026126,0.0498746373701421,252.647764931266,100.0,8.333333333333333e-05,0.56,0.23,0.18,0.07,0.86,0.06,0.02,0.01
599.4177559466766,0.0500485638488141,252.698678776284,100.0,8.333333333333333e-05,0.56,0.23,0.18,0.07,0.86,0.06,0.02,0.01
601.4981806129591,0.0502219325710043,252.707350302224,100.0,8.333333333333333e-05,0.56,0.23,0.18,0.07,0.86,0.06,0.02,0.01
603.5548757816107,0.0503933238350586,252.703045392224,100.0,8.333333333333333e-05,0.56,0.23,0.18,0.07,0.86,0.06,0.02,0.01
605.7419482972626,0.0505755798780296,252.673564491348,100.0,8.333333333333333e-05,0.56,0.23,0.18,0.07,0.86,0.06,0.02,0.01
607.7252565327342,0.0507408555643189,252.661690491779,100.0,8.333333333333333e-05,0.56,0.23,0.18,0.07,0.86,0.06,0.02,0.01
609.7604389225842,0.0509104540968064,252.639301557874,100.0,8.333333333333333e-05,0.56,0.23,0.18,0.07,0.86,0.06,0.02,0.01
611.869798663281,0.0510862340751978,252.63784730073,100.0,8.333333333333333e-05,0.56,0.23,0.18,0.07,0.86,0.06,0.02,0.01
613.9309487766162,0.0512579965846424,252.626934879995,100.0,8.333333333333333e-05,0.56,0.23,0.18,0.07,0.86,0.06,0.02,0.01
615.9739407102991,0.0514282459124493,252.625529809915,100.0,8.333333333333333e-05,0.56,0.23,0.18,0.07,0.86,0.06,0.02,0.01
618.1123316532066,0.0516064451576916,252.628940096871,100.0,8.333333333333333e-05,0.56,0.23,0.18,0.07,0.86,0.06,0.02,0.01
620.2233236447563,0.0517823611569874,252.664655833684,100.0,8.333333333333333e-05,0.56,0.23,0.18,0.07,0.86,0.06,0.02,0.01
622.4453945685823,0.0519675337339729,252.689344460714,100.0,8.333333333333333e-05,0.56,0.23,0.18,0.07,0.86,0.06,0.02,0.01
624.5947082683854,0.0521466432089565,252.738196697381,100.0,8.333333333333333e-05,0.56,0.23,0.18,0.07,0.86,0.06,0.02,0.01
626.7033335467735,0.0523223619821555,252.777920331864,100.0,8.333333333333333e-05,0.56,0.23,0.18,0.07,0.86,0.06,0.02,0.01
628.7719849025586,0.0524947495951376,252.812052697509,100.0,8.333333333333333e-05,0.56,0.23,0.18,0.07,0.86,0.06,0.02,0.01
630.9296265026659,0.0526745530618132,252.823874957779,100.0,8.333333333333333e-05,0.56,0.23,0.18,0.07,0.86,0.06,0.02,0.01
632.9885526877182,0.0528461302439009,252.8641338509,100.0,8.333333333333333e-05,0.56,0.23,0.18,0.07,0.86,0.06,0.02,0.01
634.9972192155594,0.053013519121221,252.909359829825,100.0,8.333333333333333e-05,0.56,0.23,0.18,0.07,0.86,0.06,0.02,0.01
637.0949930818302,0.0531883336100769,252.9217372174,100.0,8.333333333333333e-05,0.56,0.23,0.18,0.07,0.86,0.06,0.02,0.01
639.1504651097862,0.0533596229457399,252.916676248111,100.0,8.333333333333333e-05,0.56,0.23,0.18,0.07,0.86,0.06,0.02,0.01
641.2375828538503,0.0535335494244119,252.910805881048,100.0,8.333333333333333e-05,0.56,0.23,0.18,0.07,0.86,0.06,0.02,0.01
643.4185884756655,0.0537152998928965,252.906371840871,100.0,8.333333333333333e-05,0.56,0.23,0.18,0.07,0.86,0.06,0.02,0.01
645.4971771841266,0.0538885156186016,252.912196057706,100.0,8.333333333333333e-05,0.56,0.23,0.18,0.07,0.86,0.06,0.02,0.01
647.616289652757,0.0540651083243208,252.90644747103,100.0,8.333333333333333e-05,0.56,0.23,0.18,0.07,0.86,0.06,0.02,0.01
649.7718739533678,0.0542447403493717,252.90640951057,100.0,8.333333333333333e-05,0.56,0.23,0.18,0.07,0.86,0.06,0.02,0.01
651.9222125796487,0.0544239352348951,252.899488640277,100.0,8.333333333333333e-05,0.56,0.23,0.18,0.07,0.86,0.06,0.02,0.01
654.092729601105,0.0546048116533498,252.911104702559,100.0,8.333333333333333e-05,0.56,0.23,0.18,0.07,0.86,0.06,0.02,0.01
656.2208157562279,0.0547821521662767,252.924565788575,100.0,8.333333333333333e-05,0.56,0.23,0.18,0.07,0.86,0.06,0.02,0.01
658.3369376018778,0.0549584956534142,252.899941888168,100.0,8.333333333333333e-05,0.56,0.23,0.18,0.07,0.86,0.06,0.02,0.01
660.5017798695618,0.0551388991757212,252.882636021386,100.0,8.333333333333333e-05,0.56,0.23,0.18,0.07,0.86,0.06,0.02,0.01
662.6373928625839,0.0553168669251397,252.888644483756,100.0,8.333333333333333e-05,0.56,0.23,0.18,0.07,0.86,0.06,0.02,0.01
664.7845709745907,0.0554957984344736,252.880246612349,100.0,8.333333333333333e-05,0.56,0.23,0.18,0.07,0.86,0.06,0.02,0.01
666.9108514425294,0.0556729884734685,252.916573415648,100.0,8.333333333333333e-05,0.56,0.23,0.18,0.07,0.86,0.06,0.02,0.01
669.0506828888479,0.0558513077606617,252.90743087309,100.0,8.333333333333333e-05,0.56,0.23,0.18,0.07,0.86,0.06,0.02,0.01
671.1687805963746,0.0560278159029556,252.89620315439,100.0,8.333333333333333e-05,0.56,0.23,0.18,0.07,0.86,0.06,0.02,0.01
673.3617725748499,0.0562105652344952,252.924925766809,100.0,8.333333333333333e-05,0.56,0.23,0.18,0.07,0.86,0.06,0.02,0.01
675.4958465614279,0.0563884047333767,252.955680200733,100.0,8.333333333333333e-05,0.56,0.23,0.18,0.07,0.86,0.06,0.02,0.01
677.5955815008523,0.0565633826449954,252.929215621853,100.0,8.333333333333333e-05,0.56,0.23,0.18,0.07,0.86,0.06,0.02,0.01
679.7069597378071,0.0567393308314083,252.905860602319,100.0,8.333333333333333e-05,0.56,0.23,0.18,0.07,0.86,0.06,0.02,0.01
681.7980301877478,0.0569135867022367,252.894454097929,100.0,8.333333333333333e-05,0.56,0.23,0.18,0.07,0.86,0.06,0.02,0.01
683.8878324496842,0.0570877368907314,252.908314107996,100.0,8.333333333333333e-05,0.56,0.23,0.18,0.07,0.86,0.06,0.02,0.01
685.989109863135,0.0572628433418523,252.912648820996,100.0,8.333333333333333e-05,0.56,0.23,0.18,0.07,0.86,0.06,0.02,0.01
688.0645766439055,0.0574357989069165,252.911108547065,100.0,8.333333333333333e-05,0.56,0.23,0.18,0.07,0.86,0.06,0.02,0.01
690.1545123921834,0.057609960219273,252.893723383305,100.0,8.333333333333333e-05,0.56,0.23,0.18,0.07,0.86,0.06,0.02,0.01
692.3484085332211,0.0577927848976928,252.905953855823,100.0,8.333333333333333e-05,0.56,0.23,0.18,0.07,0.86,0.06,0.02,0.01
694.496866507005,0.0579718230621748,252.930412248624,100.0,8.333333333333333e-05,0.56,0.23,0.18,0.07,0.86,0.06,0.02,0.01
696.6511943392243,0.0581513503815264,252.934715397906,100.0,8.333333333333333e-05,0.56,0.23,0.18,0.07,0.86,0.06,0.02,0.01
698.762855892033,0.0583273221775938,252.940957292874,100.0,8.333333333333333e-05,0.56,0.23,0.18,0.07,0.86,0.06,0.02,0.01
700.9450379948935,0.0585091706861655,252.910846442204,100.0,8.333333333333333e-05,0.56,0.23,0.18,0.07,0.86,0.06,0.02,0.01
703.0707432294738,0.0586863127890472,252.907538680796,100.0,8.333333333333333e-05,0.56,0.23,0.18,0.07,0.86,0.06,0.02,0.01
705.2635032011046,0.0588690427866831,252.922503517936,100.0,8.333333333333333e-05,0.56,0.23,0.18,0.07,0.86,0.06,0.02,0.01
707.4442332771654,0.0590507702930215,252.944124229051,100.0,8.333333333333333e-05,0.56,0.23,0.18,0.07,0.86,0.06,0.02,0.01
709.526174365713,0.0592242653837338,252.961810605023,100.0,8.333333333333333e-05,0.56,0.23,0.18,0.07,0.86,0.06,0.02,0.01
711.6983602276183,0.0594052808722259,252.974673127276,100.0,8.333333333333333e-05,0.56,0.23,0.18,0.07,0.86,0.06,0.02,0.01
713.9149641268218,0.0595899978638262,252.97292953066,100.0,8.333333333333333e-05,0.56,0.23,0.18,0.07,0.86,0.06,0.02,0.01
716.0472736533078,0.0597676903243667,252.998046400138,100.0,8.333333333333333e-05,0.56,0.23,0.18,0.07,0.86,0.06,0.02,0.01