File: datasets/al_6061_comp/csv/T_100_I_1.csv
Time,Strain(%),Stress(MPa),Temp(C),SR(%/s),Si(%),Fe(%),Cu(%),Mn(%),Mg(%),Cr(%),Zn(%),Ti(%)
0.0,0.0001133255298859,43.0952502605584,100.0,8.333333333333333e-05,0.68,0.23,0.2,0.04,0.87,0.05,0.02,0.02
1.2088343163312,0.0002140617229135,48.4975578711888,100.0,8.333333333333333e-05,0.68,0.23,0.2,0.04,0.87,0.05,0.02,0.02
2.569185393036,0.0003274243126389,54.0730620068567,100.0,8.333333333333333e-05,0.68,0.23,0.2,0.04,0.87,0.05,0.02,0.02
3.8026821481464,0.0004302157088981,59.9503809353551,100.0,8.333333333333333e-05,0.68,0.23,0.2,0.04,0.87,0.05,0.02,0.02
5.1506095189452,0.000542542989798,65.7302293827934,100.0,8.333333333333333e-05,0.68,0.23,0.2,0.04,0.87,0.05,0.02,0.02
6.444032341338,0.0006503282249974,71.5018912696109,100.0,8.333333333333333e-05,0.68,0.23,0.2,0.04,0.87,0.05,0.02,0.02
7.6956753377076,0.0007546318080282,77.1506554174012,100.0,8.333333333333333e-05,0.68,0.23,0.2,0.04,0.87,0.05,0.02,0.02
8.892274117782,0.0008543483730344,82.8505526861792,100.0,8.333333333333333e-05,0.68,0.23,0.2,0.04,0.87,0.05,0.02,0.02
10.15039922586,0.0009591921320409,88.5113635067363,100.0,8.333333333333333e-05,0.68,0.23,0.2,0.04,0.87,0.05,0.02,0.02
11.41905430809,0.0010649133888934,93.945786250827,100.0,8.333333333333333e-05,0.68,0.23,0.2,0.04,0.87,0.05,0.02,0.02
12.7399745477952,0.0011749900755355,99.2642195369072,100.0,8.333333333333333e-05,0.68,0.23,0.2,0.04,0.87,0.05,0.02,0.02
14.0685799678896,0.0012857071938767,104.579901871682,100.0,8.333333333333333e-05,0.68,0.23,0.2,0.04,0.87,0.05,0.02,0.02
15.3880992971772,0.001395667137984,109.866966556093,100.0,8.333333333333333e-05,0.68,0.23,0.2,0.04,0.87,0.05,0.02,0.02
16.658456291320803,0.0015015302208293,115.2973993886,100.0,8.333333333333333e-05,0.68,0.23,0.2,0.04,0.87,0.05,0.02,0.02
17.957980091490004,0.0016098238708434,120.614650370762,100.0,8.333333333333333e-05,0.68,0.23,0.2,0.04,0.87,0.05,0.02,0.02
19.1910102945156,0.0017125763877622,125.854165441099,100.0,8.333333333333333e-05,0.68,0.23,0.2,0.04,0.87,0.05,0.02,0.02
20.402096210821203,0.001813500214121,130.930248721116,100.0,8.333333333333333e-05,0.68,0.23,0.2,0.04,0.87,0.05,0.02,0.02
21.653485174200004,0.0019177826277359,135.891646773166,100.0,8.333333333333333e-05,0.68,0.23,0.2,0.04,0.87,0.05,0.02,0.02
22.7314684391628,0.0020076145664828,140.765695472257,100.0,8.333333333333333e-05,0.68,0.23,0.2,0.04,0.87,0.05,0.02,0.02
23.895117825427203,0.0021045853486715,145.645171702645,100.0,8.333333333333333e-05,0.68,0.23,0.2,0.04,0.87,0.05,0.02,0.02
25.0322878854204,0.0021993495203376,150.490849028603,100.0,8.333333333333333e-05,0.68,0.23,0.2,0.04,0.87,0.05,0.02,0.02
26.218724399904,0.0022982192298779,155.263966374444,100.0,8.333333333333333e-05,0.68,0.23,0.2,0.04,0.87,0.05,0.02,0.02
27.326144462964,0.0023905042351329,160.028096270519,100.0,8.333333333333333e-05,0.68,0.23,0.2,0.04,0.87,0.05,0.02,0.02
28.3984862289852,0.002479866048968,164.783378814562,100.0,8.333333333333333e-05,0.68,0.23,0.2,0.04,0.87,0.05,0.02,0.02
29.579203404228004,0.0025782591469049,169.392380620088,100.0,8.333333333333333e-05,0.68,0.23,0.2,0.04,0.87,0.05,0.02,0.02
30.80805414493441,0.0026806633752971,174.036890185388,100.0,8.333333333333333e-05,0.68,0.23,0.2,0.04,0.87,0.05,0.02,0.02
32.0506520880204,0.0027842132038876,178.54042719979,100.0,8.333333333333333e-05,0.68,0.23,0.2,0.04,0.87,0.05,0.02,0.02
33.2759255002812,0.002886319321576,183.075397471507,100.0,8.333333333333333e-05,0.68,0.23,0.2,0.04,0.87,0.05,0.02,0.02
34.3709075620284,0.0029775678267216,187.591288517068,100.0,8.333333333333333e-05,0.68,0.23,0.2,0.04,0.87,0.05,0.02,0.02
35.546952362994,0.0030755715601354,192.087123431544,100.0,8.333333333333333e-05,0.68,0.23,0.2,0.04,0.87,0.05,0.02,0.02
36.613979385054,0.0031644904786404,196.617389603456,100.0,8.333333333333333e-05,0.68,0.23,0.2,0.04,0.87,0.05,0.02,0.02
37.7448315020268,0.0032587281550548,201.03009263105,100.0,8.333333333333333e-05,0.68,0.23,0.2,0.04,0.87,0.05,0.02,0.02
38.8604486293428,0.0033516962489978,205.311680149183,100.0,8.333333333333333e-05,0.68,0.23,0.2,0.04,0.87,0.05,0.02,0.02
39.9018641249208,0.0034384808736293,209.468116775071,100.0,8.333333333333333e-05,0.68,0.23,0.2,0.04,0.87,0.05,0.02,0.02
41.0223717669564,0.0035318565104656,213.64916788108,100.0,8.333333333333333e-05,0.68,0.23,0.2,0.04,0.87,0.05,0.02,0.02
42.1080079642836,0.0036223261935762,217.677681421218,100.0,8.333333333333333e-05,0.68,0.23,0.2,0.04,0.87,0.05,0.02,0.02
43.2463013650908,0.0037171839769768,221.460348464234,100.0,8.333333333333333e-05,0.68,0.23,0.2,0.04,0.87,0.05,0.02,0.02
44.4092230963584,0.0038140941212491,225.005997607929,100.0,8.333333333333333e-05,0.68,0.23,0.2,0.04,0.87,0.05,0.02,0.02
45.6719861806596,0.0039193243782742,228.376753811077,100.0,8.333333333333333e-05,0.68,0.23,0.2,0.04,0.87,0.05,0.02,0.02
46.9304275670196,0.0040241944938042,231.850081252598,100.0,8.333333333333333e-05,0.68,0.23,0.2,0.04,0.87,0.05,0.02,0.02
48.1976194350084,0.0041297938161366,235.13752782095,100.0,8.333333333333333e-05,0.68,0.23,0.2,0.04,0.87,0.05,0.02,0.02
49.5553110676968,0.0042429347855273,238.306501215975,100.0,8.333333333333333e-05,0.68,0.23,0.2,0.04,0.87,0.05,0.02,0.02
51.0036830599728,0.0043636324515503,241.267992547804,100.0,8.333333333333333e-05,0.68,0.23,0.2,0.04,0.87,0.05,0.02,0.02
52.6832442414084,0.0045035958833366,244.058621744657,100.0,8.333333333333333e-05,0.68,0.23,0.2,0.04,0.87,0.05,0.02,0.02
54.62455630016281,0.0046653718882328,246.698710110801,100.0,8.333333333333333e-05,0.68,0.23,0.2,0.04,0.87,0.05,0.02,0.02
57.1565400135036,0.0048763705310112,249.133559142701,100.0,8.333333333333333e-05,0.68,0.23,0.2,0.04,0.87,0.05,0.02,0.02
60.2107411070304,0.0051308872888051,250.799857246534,100.0,8.333333333333333e-05,0.68,0.23,0.2,0.04,0.87,0.05,0.02,0.02
63.92500518161879,0.0054404092950208,252.112285392865,100.0,8.333333333333333e-05,0.68,0.23,0.2,0.04,0.87,0.05,0.02,0.02
68.034590978148,0.0057828747780649,252.749761894418,100.0,8.333333333333333e-05,0.68,0.23,0.2,0.04,0.87,0.05,0.02,0.02
72.42240066266162,0.0061485255851077,253.127384708161,100.0,8.333333333333333e-05,0.68,0.23,0.2,0.04,0.87,0.05,0.02,0.02
77.09801695226041,0.0065381602759076,253.481259972276,100.0,8.333333333333333e-05,0.68,0.23,0.2,0.04,0.87,0.05,0.02,0.02
81.95632801880761,0.0069430195314532,253.639080106003,100.0,8.333333333333333e-05,0.68,0.23,0.2,0.04,0.87,0.05,0.02,0.02
86.9975999049528,0.0073631255219653,253.844811112898,100.0,8.333333333333333e-05,0.68,0.23,0.2,0.04,0.87,0.05,0.02,0.02
92.0610612760812,0.007785080636226,254.080213975271,100.0,8.333333333333333e-05,0.68,0.23,0.2,0.04,0.87,0.05,0.02,0.02
97.19326881609962,0.0082127645978942,253.953082409424,100.0,8.333333333333333e-05,0.68,0.23,0.2,0.04,0.87,0.05,0.02,0.02
102.260171718648,0.0086350065064399,253.932967716636,100.0,8.333333333333333e-05,0.68,0.23,0.2,0.04,0.87,0.05,0.02,0.02
107.3150301394944,0.0090562447081771,253.898211133908,100.0,8.333333333333333e-05,0.68,0.23,0.2,0.04,0.87,0.05,0.02,0.02
112.3687852557696,0.0094773909678667,253.845874655763,100.0,8.333333333333333e-05,0.68,0.23,0.2,0.04,0.87,0.05,0.02,0.02
117.48237260388962,0.0099035232468767,253.932757483433,100.0,8.333333333333333e-05,0.68,0.23,0.2,0.04,0.87,0.05,0.02,0.02
122.55876899569802,0.0103265562795274,254.127978625269,100.0,8.333333333333333e-05,0.68,0.23,0.2,0.04,0.87,0.05,0.02,0.02
127.59872612849522,0.0107465527072605,254.136993096244,100.0,8.333333333333333e-05,0.68,0.23,0.2,0.04,0.87,0.05,0.02,0.02
132.6549776494548,0.0111679070006738,254.284193107039,100.0,8.333333333333333e-05,0.68,0.23,0.2,0.04,0.87,0.05,0.02,0.02
137.6737804371384,0.0115861405663141,254.296969116281,100.0,8.333333333333333e-05,0.68,0.23,0.2,0.04,0.87,0.05,0.02,0.02
142.7688142720572,0.012010726719224,254.390309603772,100.0,8.333333333333333e-05,0.68,0.23,0.2,0.04,0.87,0.05,0.02,0.02
147.857158649058,0.0124347554173074,254.472252966818,100.0,8.333333333333333e-05,0.68,0.23,0.2,0.04,0.87,0.05,0.02,0.02
152.9814759526392,0.0128617818592725,254.634566998641,100.0,8.333333333333333e-05,0.68,0.23,0.2,0.04,0.87,0.05,0.02,0.02
158.0799403576068,0.0132866538930198,254.794587691856,100.0,8.333333333333333e-05,0.68,0.23,0.2,0.04,0.87,0.05,0.02,0.02
163.0659362345076,0.0137021535494282,254.940480339028,100.0,8.333333333333333e-05,0.68,0.23,0.2,0.04,0.87,0.05,0.02,0.02
168.0322925655492,0.014116016577015,255.061813304339,100.0,8.333333333333333e-05,0.68,0.23,0.2,0.04,0.87,0.05,0.02,0.02
172.89331568533922,0.0145211018369975,255.196573086943,100.0,8.333333333333333e-05,0.68,0.23,0.2,0.04,0.87,0.05,0.02,0.02
177.8988727863936,0.0149382315954187,255.174806179425,100.0,8.333333333333333e-05,0.68,0.23,0.2,0.04,0.87,0.05,0.02,0.02
182.8389964258416,0.0153499085653727,255.165127011874,100.0,8.333333333333333e-05,0.68,0.23,0.2,0.04,0.87,0.05,0.02,0.02
187.8651372890952,0.0157687536373105,255.220395102365,100.0,8.333333333333333e-05,0.68,0.23,0.2,0.04,0.87,0.05,0.02,0.02
192.738990383514,0.0161749080618454,255.241391417247,100.0,8.333333333333333e-05,0.68,0.23,0.2,0.04,0.87,0.05,0.02,0.02
197.589803027358,0.0165791424488324,255.368593575219,100.0,8.333333333333333e-05,0.68,0.23,0.2,0.04,0.87,0.05,0.02,0.02
202.4058186628428,0.0169804770851228,255.335464406286,100.0,8.333333333333333e-05,0.68,0.23,0.2,0.04,0.87,0.05,0.02,0.02
207.1725502242672,0.0173777047152415,255.405054698717,100.0,8.333333333333333e-05,0.68,0.23,0.2,0.04,0.87,0.05,0.02,0.02
211.8439030548288,0.0177669841177883,255.535580182102,100.0,8.333333333333333e-05,0.68,0.23,0.2,0.04,0.87,0.05,0.02,0.02
216.4034698807188,0.0181469480199458,255.709940713478,100.0,8.333333333333333e-05,0.68,0.23,0.2,0.04,0.87,0.05,0.02,0.02
221.0049727128912,0.0185304065892935,255.912833942171,100.0,8.333333333333333e-05,0.68,0.23,0.2,0.04,0.87,0.05,0.02,0.02
225.7328295871152,0.0189243946621455,255.964764362072,100.0,8.333333333333333e-05,0.68,0.23,0.2,0.04,0.87,0.05,0.02,0.02
230.452170595974,0.0193176730795504,256.046743029054,100.0,8.333333333333333e-05,0.68,0.23,0.2,0.04,0.87,0.05,0.02,0.02
235.0400429650848,0.0196999957769763,256.187834262272,100.0,8.333333333333333e-05,0.68,0.23,0.2,0.04,0.87,0.05,0.02,0.02
239.627296196514,0.0200822668795954,256.406986134236,100.0,8.333333333333333e-05,0.68,0.23,0.2,0.04,0.87,0.05,0.02,0.02
244.3055987164128,0.0204721254229203,256.514129043291,100.0,8.333333333333333e-05,0.68,0.23,0.2,0.04,0.87,0.05,0.02,0.02
248.92199819868,0.0208568253797759,256.562283390789,100.0,8.333333333333333e-05,0.68,0.23,0.2,0.04,0.87,0.05,0.02,0.02
253.5732430528608,0.0212444291176243,256.50488969475,100.0,8.333333333333333e-05,0.68,0.23,0.2,0.04,0.87,0.05,0.02,0.02
257.97321596557447,0.0216110935270171,256.580044592857,100.0,8.333333333333333e-05,0.68,0.23,0.2,0.04,0.87,0.05,0.02,0.02
262.52556024002286,0.0219904555498878,256.753104468674,100.0,8.333333333333333e-05,0.68,0.23,0.2,0.04,0.87,0.05,0.02,0.02
267.01659700931884,0.0223647086139958,256.946239985646,100.0,8.333333333333333e-05,0.68,0.23,0.2,0.04,0.87,0.05,0.02,0.02
271.502224774296,0.0227385109277439,257.060068423947,100.0,8.333333333333333e-05,0.68,0.23,0.2,0.04,0.87,0.05,0.02,0.02
276.101972852178,0.0231218232675674,257.19501951231,100.0,8.333333333333333e-05,0.68,0.23,0.2,0.04,0.87,0.05,0.02,0.02
280.54700184179643,0.0234922423500356,257.320325965474,100.0,8.333333333333333e-05,0.68,0.23,0.2,0.04,0.87,0.05,0.02,0.02
285.05020244087285,0.0238675090666253,257.543949076138,100.0,8.333333333333333e-05,0.68,0.23,0.2,0.04,0.87,0.05,0.02,0.02
289.56968148395526,0.0242441323202155,257.662641536977,100.0,8.333333333333333e-05,0.68,0.23,0.2,0.04,0.87,0.05,0.02,0.02
293.9918325979812,0.024612644913051,257.783390239477,100.0,8.333333333333333e-05,0.68,0.23,0.2,0.04,0.87,0.05,0.02,0.02
298.37541507704407,0.0249779434529729,257.905583899617,100.0,8.333333333333333e-05,0.68,0.23,0.2,0.04,0.87,0.05,0.02,0.02
302.8519864453608,0.0253509910669993,257.933626514693,100.0,8.333333333333333e-05,0.68,0.23,0.2,0.04,0.87,0.05,0.02,0.02
307.30106414709843,0.0257217475421441,258.064671132844,100.0,8.333333333333333e-05,0.68,0.23,0.2,0.04,0.87,0.05,0.02,0.02
311.73587881936686,0.0260913154314998,258.202309918316,100.0,8.333333333333333e-05,0.68,0.23,0.2,0.04,0.87,0.05,0.02,0.02
316.08638997166565,0.0264538580275247,258.141924788501,100.0,8.333333333333333e-05,0.68,0.23,0.2,0.04,0.87,0.05,0.02,0.02
320.4854424491328,0.0268204457339803,258.240981726382,100.0,8.333333333333333e-05,0.68,0.23,0.2,0.04,0.87,0.05,0.02,0.02
324.8759129598528,0.0271863182765403,258.251362122681,100.0,8.333333333333333e-05,0.68,0.23,0.2,0.04,0.87,0.05,0.02,0.02
329.3919555165612,0.027562655156266,258.390166142729,100.0,8.333333333333333e-05,0.68,0.23,0.2,0.04,0.87,0.05,0.02,0.02
333.78618614049964,0.0279288410415942,258.500870844101,100.0,8.333333333333333e-05,0.68,0.23,0.2,0.04,0.87,0.05,0.02,0.02
338.1992915203224,0.0282965998232461,258.582451562351,100.0,8.333333333333333e-05,0.68,0.23,0.2,0.04,0.87,0.05,0.02,0.02
342.523906479528,0.0286569844031799,258.712750876947,100.0,8.333333333333333e-05,0.68,0.23,0.2,0.04,0.87,0.05,0.02,0.02
346.95300609433684,0.0290260760377473,258.854578973528,100.0,8.333333333333333e-05,0.68,0.23,0.2,0.04,0.87,0.05,0.02,0.02
351.45525487046166,0.0294012634357577,258.953703369955,100.0,8.333333333333333e-05,0.68,0.23,0.2,0.04,0.87,0.05,0.02,0.02
355.91125602638766,0.0297725968654182,259.052479183322,100.0,8.333333333333333e-05,0.68,0.23,0.2,0.04,0.87,0.05,0.02,0.02
360.3596982144492,0.03014330038109,259.269618856938,100.0,8.333333333333333e-05,0.68,0.23,0.2,0.04,0.87,0.05,0.02,0.02
364.87659678067325,0.030519708594942,259.34563353657,100.0,8.333333333333333e-05,0.68,0.23,0.2,0.04,0.87,0.05,0.02,0.02
369.3704122098361,0.0308941932140389,259.495365966994,100.0,8.333333333333333e-05,0.68,0.23,0.2,0.04,0.87,0.05,0.02,0.02
373.8373962423637,0.0312664418834162,259.601858256957,100.0,8.333333333333333e-05,0.68,0.23,0.2,0.04,0.87,0.05,0.02,0.02
378.2365689308653,0.031633039607458,259.700207384,100.0,8.333333333333333e-05,0.68,0.23,0.2,0.04,0.87,0.05,0.02,0.02
382.6609269470424,0.0320017361088061,259.867109006343,100.0,8.333333333333333e-05,0.68,0.23,0.2,0.04,0.87,0.05,0.02,0.02
387.036447473196,0.0323663628193189,259.973064966224,100.0,8.333333333333333e-05,0.68,0.23,0.2,0.04,0.87,0.05,0.02,0.02
391.3177182024192,0.0327231353800875,259.889062527125,100.0,8.333333333333333e-05,0.68,0.23,0.2,0.04,0.87,0.05,0.02,0.02
395.6971823466972,0.033088090725444,259.938219367819,100.0,8.333333333333333e-05,0.68,0.23,0.2,0.04,0.87,0.05,0.02,0.02
400.0295247217884,0.0334491192567016,260.0327044933,100.0,8.333333333333333e-05,0.68,0.23,0.2,0.04,0.87,0.05,0.02,0.02
404.446994407368,0.0338172417304999,260.157156644764,100.0,8.333333333333333e-05,0.68,0.23,0.2,0.04,0.87,0.05,0.02,0.02
408.88112392930566,0.0341867525239947,260.339664858342,100.0,8.333333333333333e-05,0.68,0.23,0.2,0.04,0.87,0.05,0.02,0.02
413.2842723316932,0.034553681557527,260.458118679064,100.0,8.333333333333333e-05,0.68,0.23,0.2,0.04,0.87,0.05,0.02,0.02
417.68492893587,0.0349204029412084,260.585886676294,100.0,8.333333333333333e-05,0.68,0.23,0.2,0.04,0.87,0.05,0.02,0.02
422.05083899325246,0.0352842287793236,260.615976462974,100.0,8.333333333333333e-05,0.68,0.23,0.2,0.04,0.87,0.05,0.02,0.02
426.4753094604193,0.0356529346515875,260.723077360031,100.0,8.333333333333333e-05,0.68,0.23,0.2,0.04,0.87,0.05,0.02,0.02
430.9497317688253,0.036025803177288,260.870507885683,100.0,8.333333333333333e-05,0.68,0.23,0.2,0.04,0.87,0.05,0.02,0.02
435.393372168654,0.0363961065439404,260.938719277571,100.0,8.333333333333333e-05,0.68,0.23,0.2,0.04,0.87,0.05,0.02,0.02
439.79148214999685,0.0367626157090523,261.086777196042,100.0,8.333333333333333e-05,0.68,0.23,0.2,0.04,0.87,0.05,0.02,0.02
444.2491927437816,0.0371340915918677,261.184583127475,100.0,8.333333333333333e-05,0.68,0.23,0.2,0.04,0.87,0.05,0.02,0.02
448.647385971456,0.0375006076941739,261.262640317709,100.0,8.333333333333333e-05,0.68,0.23,0.2,0.04,0.87,0.05,0.02,0.02
453.0808976738112,0.0378700670027035,261.420833725205,100.0,8.333333333333333e-05,0.68,0.23,0.2,0.04,0.87,0.05,0.02,0.02
457.4671445274769,0.0382355875738423,261.467059709392,100.0,8.333333333333333e-05,0.68,0.23,0.2,0.04,0.87,0.05,0.02,0.02
461.9403040412544,0.0386083508666571,261.441251855475,100.0,8.333333333333333e-05,0.68,0.23,0.2,0.04,0.87,0.05,0.02,0.02
466.5153743611932,0.038989606726652,261.502456455453,100.0,8.333333333333333e-05,0.68,0.23,0.2,0.04,0.87,0.05,0.02,0.02
471.0079309779024,0.0393639864447111,261.523950820369,100.0,8.333333333333333e-05,0.68,0.23,0.2,0.04,0.87,0.05,0.02,0.02
475.5043066771932,0.039738684419652,261.608598099549,100.0,8.333333333333333e-05,0.68,0.23,0.2,0.04,0.87,0.05,0.02,0.02
479.936454077874,0.0401080300363754,261.639947017935,100.0,8.333333333333333e-05,0.68,0.23,0.2,0.04,0.87,0.05,0.02,0.02
484.40740776684487,0.0404806095104563,261.602899616059,100.0,8.333333333333333e-05,0.68,0.23,0.2,0.04,0.87,0.05,0.02,0.02
488.883623439696,0.0408536274831939,261.643241290823,100.0,8.333333333333333e-05,0.68,0.23,0.2,0.04,0.87,0.05,0.02,0.02
493.38527966554807,0.0412287655020149,261.730501281679,100.0,8.333333333333333e-05,0.68,0.23,0.2,0.04,0.87,0.05,0.02,0.02
497.9198558394792,0.0416066468498425,261.887295790416,100.0,8.333333333333333e-05,0.68,0.23,0.2,0.04,0.87,0.05,0.02,0.02
502.3671101709649,0.0419772513774663,262.081505652439,100.0,8.333333333333333e-05,0.68,0.23,0.2,0.04,0.87,0.05,0.02,0.02
506.8879881050413,0.042353991205306,262.230455648765,100.0,8.333333333333333e-05,0.68,0.23,0.2,0.04,0.87,0.05,0.02,0.02
511.32779987846646,0.0427239755197581,262.331784494096,100.0,8.333333333333333e-05,0.68,0.23,0.2,0.04,0.87,0.05,0.02,0.02
515.8619399754707,0.0431018205278418,262.402629981577,100.0,8.333333333333333e-05,0.68,0.23,0.2,0.04,0.87,0.05,0.02,0.02
520.3053801991008,0.0434721072131443,262.41863108878,100.0,8.333333333333333e-05,0.68,0.23,0.2,0.04,0.87,0.05,0.02,0.02
524.865187857186,0.0438520911846514,262.464297028467,100.0,8.333333333333333e-05,0.68,0.23,0.2,0.04,0.87,0.05,0.02,0.02
529.3962700219823,0.0442296813650511,262.485080181274,100.0,8.333333333333333e-05,0.68,0.23,0.2,0.04,0.87,0.05,0.02,0.02
533.8751026752648,0.0446029174194913,262.460818016163,100.0,8.333333333333333e-05,0.68,0.23,0.2,0.04,0.87,0.05,0.02,0.02
538.3300325756076,0.0449741615778532,262.439837794332,100.0,8.333333333333333e-05,0.68,0.23,0.2,0.04,0.87,0.05,0.02,0.02
542.8729586421421,0.0453527387500644,262.499353789126,100.0,8.333333333333333e-05,0.68,0.23,0.2,0.04,0.87,0.05,0.02,0.02
547.3988011330164,0.0457298922909706,262.55357299686,100.0,8.333333333333333e-05,0.68,0.23,0.2,0.04,0.87,0.05,0.02,0.02
552.0599132469516,0.0461183183004652,262.655473775393,100.0,8.333333333333333e-05,0.68,0.23,0.2,0.04,0.87,0.05,0.02,0.02
556.7194756193832,0.0465066151648345,262.67656770361,100.0,8.333333333333333e-05,0.68,0.23,0.2,0.04,0.87,0.05,0.02,0.02
561.303781650312,0.0468886406674119,262.683544498197,100.0,8.333333333333333e-05,0.68,0.23,0.2,0.04,0.87,0.05,0.02,0.02
565.905886418382,0.0472721493980844,262.793758030811,100.0,8.333333333333333e-05,0.68,0.23,0.2,0.04,0.87,0.05,0.02,0.02
570.4414849922496,0.0476501159459067,262.82708524506,100.0,8.333333333333333e-05,0.68,0.23,0.2,0.04,0.87,0.05,0.02,0.02
575.0635757689777,0.0480352901773007,262.87005866917,100.0,8.333333333333333e-05,0.68,0.23,0.2,0.04,0.87,0.05,0.02,0.02
579.6509014031795,0.0484175673134842,262.933751188814,100.0,8.333333333333333e-05,0.68,0.23,0.2,0.04,0.87,0.05,0.02,0.02
584.2421728189188,0.0488001732647958,263.004305096021,100.0,8.333333333333333e-05,0.68,0.23,0.2,0.04,0.87,0.05,0.02,0.02
588.9121928766275,0.0491893416029382,263.132153353804,100.0,8.333333333333333e-05,0.68,0.23,0.2,0.04,0.87,0.05,0.02,0.02
593.5903749307164,0.0495791901074456,263.197423905823,100.0,8.333333333333333e-05,0.68,0.23,0.2,0.04,0.87,0.05,0.02,0.02
598.1920791097608,0.0499626654556993,263.27565819836,100.0,8.333333333333333e-05,0.68,0.23,0.2,0.04,0.87,0.05,0.02,0.02
602.8669050563279,0.0503522342845799,263.356871122666,100.0,8.333333333333333e-05,0.68,0.23,0.2,0.04,0.87,0.05,0.02,0.02
607.5945464961155,0.0507462044045622,263.3712682628,100.0,8.333333333333333e-05,0.68,0.23,0.2,0.04,0.87,0.05,0.02,0.02
612.3205862833332,0.051140041053497,263.444351629272,100.0,8.333333333333333e-05,0.68,0.23,0.2,0.04,0.87,0.05,0.02,0.02
617.0542358496311,0.0515345118506885,263.440831534021,100.0,8.333333333333333e-05,0.68,0.23,0.2,0.04,0.87,0.05,0.02,0.02
621.6989236355064,0.0519215691661781,263.472055975329,100.0,8.333333333333333e-05,0.68,0.23,0.2,0.04,0.87,0.05,0.02,0.02
626.3277806210064,0.0523073072483031,263.590034846319,100.0,8.333333333333333e-05,0.68,0.23,0.2,0.04,0.87,0.05,0.02,0.02
631.0125838979112,0.0526977075213785,263.653457956938,100.0,8.333333333333333e-05,0.68,0.23,0.2,0.04,0.87,0.05,0.02,0.02
635.6784542005931,0.053086530046602,263.7141116927,100.0,8.333333333333333e-05,0.68,0.23,0.2,0.04,0.87,0.05,0.02,0.02
640.3297120561056,0.0534741348678947,263.631067262579,100.0,8.333333333333333e-05,0.68,0.23,0.2,0.04,0.87,0.05,0.02,0.02
644.8177242537863,0.0538481358843681,263.591925354741,100.0,8.333333333333333e-05,0.68,0.23,0.2,0.04,0.87,0.05,0.02,0.02
649.4362919012748,0.0542330165216588,263.624736741016,100.0,8.333333333333333e-05,0.68,0.23,0.2,0.04,0.87,0.05,0.02,0.02
654.0039311791464,0.0546136531281481,263.699943193575,100.0,8.333333333333333e-05,0.68,0.23,0.2,0.04,0.87,0.05,0.02,0.02
658.7153760223116,0.0550062735317452,263.7909511806,100.0,8.333333333333333e-05,0.68,0.23,0.2,0.04,0.87,0.05,0.02,0.02
663.3499209239376,0.0553924856068807,263.800695775382,100.0,8.333333333333333e-05,0.68,0.23,0.2,0.04,0.87,0.05,0.02,0.02
668.042687532756,0.0557835494909489,263.893876497606,100.0,8.333333333333333e-05,0.68,0.23,0.2,0.04,0.87,0.05,0.02,0.02
672.769983954594,0.0561774908594354,263.978921111399,100.0,8.333333333333333e-05,0.68,0.23,0.2,0.04,0.87,0.05,0.02,0.02
677.4971171354567,0.0565714186245073,264.01832085449,100.0,8.333333333333333e-05,0.68,0.23,0.2,0.04,0.87,0.05,0.02,0.02
682.2562782213528,0.0569680153816653,264.118110876544,100.0,8.333333333333333e-05,0.68,0.23,0.2,0.04,0.87,0.05,0.02,0.02
687.0976717856016,0.0573714648453527,264.087352629844,100.0,8.333333333333333e-05,0.68,0.23,0.2,0.04,0.87,0.05,0.02,0.02
691.9816252680899,0.0577784609688934,264.178389637901,100.0,8.333333333333333e-05,0.68,0.23,0.2,0.04,0.87,0.05,0.02,0.02
696.9533689826819,0.0581927729451094,264.273911159063,100.0,8.333333333333333e-05,0.68,0.23,0.2,0.04,0.87,0.05,0.02,0.02
701.9469363038244,0.0586089035552046,264.371683833623,100.0,8.333333333333333e-05,0.68,0.23,0.2,0.04,0.87,0.05,0.02,0.02
706.7421200112767,0.0590085021974923,264.525324954534,100.0,8.333333333333333e-05,0.68,0.23,0.2,0.04,0.87,0.05,0.02,0.02
711.6036912571572,0.059413633134649,264.5021477477,100.0,8.333333333333333e-05,0.68,0.23,0.2,0.04,0.87,0.05,0.02,0.02
716.5200196498871,0.0598233271673765,264.447113604832,100.0,8.333333333333333e-05,0.68,0.23,0.2,0.04,0.87,0.05,0.02,0.02
721.4129322919068,0.0602310698875448,264.381519617115,100.0,8.333333333333333e-05,0.68,0.23,0.2,0.04,0.87,0.05,0.02,0.02
726.3238480670028,0.0606403128688028,264.349072623513,100.0,8.333333333333333e-05,0.68,0.23,0.2,0.04,0.87,0.05,0.02,0.02
731.1391556254764,0.0610415884986756,264.409388106002,100.0,8.333333333333333e-05,0.68,0.23,0.2,0.04,0.87,0.05,0.02,0.02
735.9844009106099,0.0614453589391034,264.464091160312,100.0,8.333333333333333e-05,0.68,0.23,0.2,0.04,0.87,0.05,0.02,0.02
740.8592321656631,0.0618515948770245,264.505092681691,100.0,8.333333333333333e-05,0.68,0.23,0.2,0.04,0.87,0.05,0.02,0.02
745.809944404506,0.0622641542302614,264.489122815794,100.0,8.333333333333333e-05,0.68,0.23,0.2,0.04,0.87,0.05,0.02,0.02
750.7711301386643,0.0626775863747746,264.418962306543,100.0,8.333333333333333e-05,0.68,0.23,0.2,0.04,0.87,0.05,0.02,0.02
755.5936578039457,0.0630794636802147,264.419636057429,100.0,8.333333333333333e-05,0.68,0.23,0.2,0.04,0.87,0.05,0.02,0.02
760.5531391374144,0.0634927537913371,264.383900727416,100.0,8.333333333333333e-05,0.68,0.23,0.2,0.04,0.87,0.05,0.02,0.02
765.4012216022987,0.0638967606634108,264.449925306621,100.0,8.333333333333333e-05,0.68,0.23,0.2,0.04,0.87,0.05,0.02,0.02
770.34287148399,0.0643085648202184,264.478448178042,100.0,8.333333333333333e-05,0.68,0.23,0.2,0.04,0.87,0.05,0.02,0.02
775.2520760166191,0.0647176651979375,264.546761230147,100.0,8.333333333333333e-05,0.68,0.23,0.2,0.04,0.87,0.05,0.02,0.02
780.0894963766943,0.0651207835612771,264.659485955939,100.0,8.333333333333333e-05,0.68,0.23,0.2,0.04,0.87,0.05,0.02,0.02
785.0683713145283,0.0655356898060966,264.73256214195,100.0,8.333333333333333e-05,0.68,0.23,0.2,0.04,0.87,0.05,0.02,0.02
790.0573151732063,0.0659514351276531,264.772783559732,100.0,8.333333333333333e-05,0.68,0.23,0.2,0.04,0.87,0.05,0.02,0.02
795.2445813073751,0.0663837073055005,264.837501704365,100.0,8.333333333333333e-05,0.68,0.23,0.2,0.04,0.87,0.05,0.02,0.02
800.3689759020635,0.0668107401883912,264.839817513408,100.0,8.333333333333333e-05,0.68,0.23,0.2,0.04,0.87,0.05,0.02,0.02
805.5517929876577,0.0672426416121907,264.893915834294,100.0,8.333333333333333e-05,0.68,0.23,0.2,0.04,0.87,0.05,0.02,0.02
810.6893577265224,0.0676707720070961,264.896062650547,100.0,8.333333333333333e-05,0.68,0.23,0.2,0.04,0.87,0.05,0.02,0.02
815.7991033881359,0.0680965841455639,264.85963872058,100.0,8.333333333333333e-05,0.68,0.23,0.2,0.04,0.87,0.05,0.02,0.02
820.9472890445796,0.0685255996169342,264.867378124263,100.0,8.333333333333333e-05,0.68,0.23,0.2,0.04,0.87,0.05,0.02,0.02
826.2397461121548,0.0689666377058988,264.846140681297,100.0,8.333333333333333e-05,0.68,0.23,0.2,0.04,0.87,0.05,0.02,0.02
831.433182683382,0.0693994240868344,264.867629566386,100.0,8.333333333333333e-05,0.68,0.23,0.2,0.04,0.87,0.05,0.02,0.02
836.618685259104,0.0698315493014779,264.907767873476,100.0,8.333333333333333e-05,0.68,0.23,0.2,0.04,0.87,0.05,0.02,0.02
841.7748975606768,0.0702612336599423,264.902861996405,100.0,8.333333333333333e-05,0.68,0.23,0.2,0.04,0.87,0.05,0.02,0.02
846.7013596156823,0.0706717721645261,264.888704913585,100.0,8.333333333333333e-05,0.68,0.23,0.2,0.04,0.87,0.05,0.02,0.02
851.8442085971208,0.0711003429129793,264.867606781019,100.0,8.333333333333333e-05,0.68,0.23,0.2,0.04,0.87,0.05,0.02,0.02
856.921909106052,0.0715234846220569,264.909913319773,100.0,8.333333333333333e-05,0.68,0.23,0.2,0.04,0.87,0.05,0.02,0.02
862.1088347916324,0.0719557284291886,264.894749791353,100.0,8.333333333333333e-05,0.68,0.23,0.2,0.04,0.87,0.05,0.02,0.02
867.282815184516,0.0723868934619289,264.915359416341,100.0,8.333333333333333e-05,0.68,0.23,0.2,0.04,0.87,0.05,0.02,0.02
872.3816332030297,0.0728117949634717,264.878124157217,100.0,8.333333333333333e-05,0.68,0.23,0.2,0.04,0.87,0.05,0.02,0.02
877.5577151059032,0.0732431351220445,264.880457476508,100.0,8.333333333333333e-05,0.68,0.23,0.2,0.04,0.87,0.05,0.02,0.02
882.797651365758,0.0736797964770324,264.911025173287,100.0,8.333333333333333e-05,0.68,0.23,0.2,0.04,0.87,0.05,0.02,0.02
888.2267191779407,0.0741322187947143,264.947327570794,100.0,8.333333333333333e-05,0.68,0.23,0.2,0.04,0.87,0.05,0.02,0.02
893.5806185379024,0.0745783770747111,264.996627154653,100.0,8.333333333333333e-05,0.68,0.23,0.2,0.04,0.87,0.05,0.02,0.02
898.8315463250821,0.0750159543903094,264.97615466703,100.0,8.333333333333333e-05,0.68,0.23,0.2,0.04,0.87,0.05,0.02,0.02
904.1306373238248,0.0754575453068713,264.958775462362,100.0,8.333333333333333e-05,0.68,0.23,0.2,0.04,0.87,0.05,0.02,0.02
909.3217087348728,0.0758901345911253,264.878066682032,100.0,8.333333333333333e-05,0.68,0.23,0.2,0.04,0.87,0.05,0.02,0.02
914.6796861086424,0.0763366327056061,264.849481816144,100.0,8.333333333333333e-05,0.68,0.23,0.2,0.04,0.87,0.05,0.02,0.02
920.1059675983956,0.0767888228297522,264.849418089548,100.0,8.333333333333333e-05,0.68,0.23,0.2,0.04,0.87,0.05,0.02,0.02
925.4622625908492,0.07723518074579,264.902373173895,100.0,8.333333333333333e-05,0.68,0.23,0.2,0.04,0.87,0.05,0.02,0.02
931.0731962619648,0.0777027585517163,264.957306270664,100.0,8.333333333333333e-05,0.68,0.23,0.2,0.04,0.87,0.05,0.02,0.02
936.5888521717224,0.0781623965441961,265.002305939113,100.0,8.333333333333333e-05,0.68,0.23,0.2,0.04,0.87,0.05,0.02,0.02
939.37567036002,0.0783946313932209,265.015192851842,100.0,8.333333333333333e-05,0.68,0.23,0.2,0.04,0.87,0.05,0.02,0.02