File: datasets/al_6061_comp/csv/T_150_G_1.csv
Time,Strain(%),Stress(MPa),Temp(C),SR(%/s),Si(%),Fe(%),Cu(%),Mn(%),Mg(%),Cr(%),Zn(%),Ti(%)
0.0,8.50181419632563e-05,42.2478071937533,150.0,8.333333333333333e-05,0.61,0.15,0.17,0.02,0.88,0.05,0.01,0.01
0.1962137099153242,0.0001013692844562,42.9696497934672,150.0,8.333333333333333e-05,0.61,0.15,0.17,0.02,0.88,0.05,0.01,0.01
0.3955472201921244,0.0001179804103126,43.671790891409,150.0,8.333333333333333e-05,0.61,0.15,0.17,0.02,0.88,0.05,0.01,0.01
0.5557816777925244,0.0001313332817793,44.3917334894935,150.0,8.333333333333333e-05,0.61,0.15,0.17,0.02,0.88,0.05,0.01,0.01
0.7573366975157245,0.0001481295334229,45.1344424165764,150.0,8.333333333333333e-05,0.61,0.15,0.17,0.02,0.88,0.05,0.01,0.01
0.9049050262589244,0.0001604268941515,45.8840367399483,150.0,8.333333333333333e-05,0.61,0.15,0.17,0.02,0.88,0.05,0.01,0.01
1.1292168676217242,0.0001791195475984,46.6316564770088,150.0,8.333333333333333e-05,0.61,0.15,0.17,0.02,0.88,0.05,0.01,0.01
1.3649476718777245,0.0001987637812864,47.3774988473255,150.0,8.333333333333333e-05,0.61,0.15,0.17,0.02,0.88,0.05,0.01,0.01
1.5190505524325242,0.0002116056879993,48.1409136125138,150.0,8.333333333333333e-05,0.61,0.15,0.17,0.02,0.88,0.05,0.01,0.01
1.6438901947265243,0.0002220089915238,48.8945593517425,150.0,8.333333333333333e-05,0.61,0.15,0.17,0.02,0.88,0.05,0.01,0.01
1.8932921420261244,0.0002427924871321,49.6470851808364,150.0,8.333333333333333e-05,0.61,0.15,0.17,0.02,0.88,0.05,0.01,0.01
2.0713318373189247,0.0002576291284065,50.38756920142,150.0,8.333333333333333e-05,0.61,0.15,0.17,0.02,0.88,0.05,0.01,0.01
2.3700382687709243,0.0002825213310275,51.1425275265589,150.0,8.333333333333333e-05,0.61,0.15,0.17,0.02,0.88,0.05,0.01,0.01
2.570326631964525,0.0002992120279603,51.8969003041578,150.0,8.333333333333333e-05,0.61,0.15,0.17,0.02,0.88,0.05,0.01,0.01
2.791966245175724,0.0003176819957279,52.6436948759411,150.0,8.333333333333333e-05,0.61,0.15,0.17,0.02,0.88,0.05,0.01,0.01
3.0498763543277247,0.0003391745048239,53.3581104973667,150.0,8.333333333333333e-05,0.61,0.15,0.17,0.02,0.88,0.05,0.01,0.01
3.241083692701724,0.0003551084496884,54.0945044877782,150.0,8.333333333333333e-05,0.61,0.15,0.17,0.02,0.88,0.05,0.01,0.01
3.337787705567324,0.0003631671174272,54.817246694963,150.0,8.333333333333333e-05,0.61,0.15,0.17,0.02,0.88,0.05,0.01,0.01
3.596831224379325,0.0003847540773282,55.5156959698904,150.0,8.333333333333333e-05,0.61,0.15,0.17,0.02,0.88,0.05,0.01,0.01
3.808925582664525,0.0004024286071853,56.2073353673004,150.0,8.333333333333333e-05,0.61,0.15,0.17,0.02,0.88,0.05,0.01,0.01
3.896382332593725,0.0004097166696794,56.9027399058444,150.0,8.333333333333333e-05,0.61,0.15,0.17,0.02,0.88,0.05,0.01,0.01
4.040484017138925,0.0004217251433915,57.619443381911,150.0,8.333333333333333e-05,0.61,0.15,0.17,0.02,0.88,0.05,0.01,0.01
4.201679866922925,0.0004351581308735,58.3459700453036,150.0,8.333333333333333e-05,0.61,0.15,0.17,0.02,0.88,0.05,0.01,0.01
4.325293694518124,0.0004454592831731,59.053337105564,150.0,8.333333333333333e-05,0.61,0.15,0.17,0.02,0.88,0.05,0.01,0.01
4.426962984576525,0.0004539317240113,59.7745517595681,150.0,8.333333333333333e-05,0.61,0.15,0.17,0.02,0.88,0.05,0.01,0.01
4.589688457937324,0.0004674921801247,60.5090028752196,150.0,8.333333333333333e-05,0.61,0.15,0.17,0.02,0.88,0.05,0.01,0.01
4.679085531493724,0.0004749419362544,61.2409387566499,150.0,8.333333333333333e-05,0.61,0.15,0.17,0.02,0.88,0.05,0.01,0.01
4.828394914943325,0.0004873843848752,61.9734190540126,150.0,8.333333333333333e-05,0.61,0.15,0.17,0.02,0.88,0.05,0.01,0.01
4.968936847604924,0.000499096212597,62.6715553614188,150.0,8.333333333333333e-05,0.61,0.15,0.17,0.02,0.88,0.05,0.01,0.01
5.0456127184001245,0.0005054858684966,63.3680512332878,150.0,8.333333333333333e-05,0.61,0.15,0.17,0.02,0.88,0.05,0.01,0.01
5.212420786988925,0.000519386540879,64.0640355090176,150.0,8.333333333333333e-05,0.61,0.15,0.17,0.02,0.88,0.05,0.01,0.01
5.490779516258924,0.0005425831016515,64.7512373632503,150.0,8.333333333333333e-05,0.61,0.15,0.17,0.02,0.88,0.05,0.01,0.01
5.608596915817725,0.0005524012182814,65.4494611426089,150.0,8.333333333333333e-05,0.61,0.15,0.17,0.02,0.88,0.05,0.01,0.01
5.819491063206525,0.0005699757305638,66.1347287505364,150.0,8.333333333333333e-05,0.61,0.15,0.17,0.02,0.88,0.05,0.01,0.01
6.022362871013325,0.0005868817145477,66.7931533298608,150.0,8.333333333333333e-05,0.61,0.15,0.17,0.02,0.88,0.05,0.01,0.01
6.247024605415724,0.0006056035257479,67.4458516706272,150.0,8.333333333333333e-05,0.61,0.15,0.17,0.02,0.88,0.05,0.01,0.01
6.410381171406525,0.0006192165729138,68.0830208188408,150.0,8.333333333333333e-05,0.61,0.15,0.17,0.02,0.88,0.05,0.01,0.01
6.642252853981725,0.0006385392131284,68.714094873918,150.0,8.333333333333333e-05,0.61,0.15,0.17,0.02,0.88,0.05,0.01,0.01
6.864799289608125,0.0006570847494306,69.3331476862886,150.0,8.333333333333333e-05,0.61,0.15,0.17,0.02,0.88,0.05,0.01,0.01
7.047594349417726,0.0006723176710814,69.9603683366779,150.0,8.333333333333333e-05,0.61,0.15,0.17,0.02,0.88,0.05,0.01,0.01
7.191118324237725,0.0006842780023164,70.6082354709013,150.0,8.333333333333333e-05,0.61,0.15,0.17,0.02,0.88,0.05,0.01,0.01
7.420642742190526,0.0007034050371458,71.2752363070598,150.0,8.333333333333333e-05,0.61,0.15,0.17,0.02,0.88,0.05,0.01,0.01
7.582983302846924,0.0007169334172005,71.9649888750872,150.0,8.333333333333333e-05,0.61,0.15,0.17,0.02,0.88,0.05,0.01,0.01
7.834953077087325,0.0007379308983872,72.6569713683668,150.0,8.333333333333333e-05,0.61,0.15,0.17,0.02,0.88,0.05,0.01,0.01
7.948049335939724,0.0007473555866249,73.3615672380163,150.0,8.333333333333333e-05,0.61,0.15,0.17,0.02,0.88,0.05,0.01,0.01
8.034486712031324,0.0007545587012992,74.0720094796491,150.0,8.333333333333333e-05,0.61,0.15,0.17,0.02,0.88,0.05,0.01,0.01
8.190279102395323,0.0007675414004962,74.7698925062781,150.0,8.333333333333333e-05,0.61,0.15,0.17,0.02,0.88,0.05,0.01,0.01
8.336961832121325,0.0007797649613067,75.453014826973,150.0,8.333333333333333e-05,0.61,0.15,0.17,0.02,0.88,0.05,0.01,0.01
8.453547233484525,0.0007894804114203,76.1132704911108,150.0,8.333333333333333e-05,0.61,0.15,0.17,0.02,0.88,0.05,0.01,0.01
8.538404421500925,0.000796551843755,76.7649275910875,150.0,8.333333333333333e-05,0.61,0.15,0.17,0.02,0.88,0.05,0.01,0.01
8.645341923764924,0.000805463302277,77.4238493119098,150.0,8.333333333333333e-05,0.61,0.15,0.17,0.02,0.88,0.05,0.01,0.01
8.787038951488125,0.0008172713879206,78.0941363862002,150.0,8.333333333333333e-05,0.61,0.15,0.17,0.02,0.88,0.05,0.01,0.01
8.955185780905726,0.0008312836237054,78.7754579404146,150.0,8.333333333333333e-05,0.61,0.15,0.17,0.02,0.88,0.05,0.01,0.01
9.084216097428524,0.0008420361500823,79.4511862609346,150.0,8.333333333333333e-05,0.61,0.15,0.17,0.02,0.88,0.05,0.01,0.01
9.296555184842926,0.0008597310740335,80.1419807030328,150.0,8.333333333333333e-05,0.61,0.15,0.17,0.02,0.88,0.05,0.01,0.01
9.484653095651325,0.0008754058999342,80.834492366002,150.0,8.333333333333333e-05,0.61,0.15,0.17,0.02,0.88,0.05,0.01,0.01
9.746465347348124,0.0008972235875756,81.5213014909586,150.0,8.333333333333333e-05,0.61,0.15,0.17,0.02,0.88,0.05,0.01,0.01
10.002161079052126,0.0009185315652176,82.2312010581821,150.0,8.333333333333333e-05,0.61,0.15,0.17,0.02,0.88,0.05,0.01,0.01
10.266310466760526,0.0009405440141933,82.9386874444344,150.0,8.333333333333333e-05,0.61,0.15,0.17,0.02,0.88,0.05,0.01,0.01
10.469388534008925,0.000957467186464,83.6298672222517,150.0,8.333333333333333e-05,0.61,0.15,0.17,0.02,0.88,0.05,0.01,0.01
10.664845242822524,0.0009737552455318,84.3198378922911,150.0,8.333333333333333e-05,0.61,0.15,0.17,0.02,0.88,0.05,0.01,0.01
10.739886887359724,0.0009800087159099,85.0093285510863,150.0,8.333333333333333e-05,0.61,0.15,0.17,0.02,0.88,0.05,0.01,0.01
10.875186887009324,0.0009912837158807,85.706021167562,150.0,8.333333333333333e-05,0.61,0.15,0.17,0.02,0.88,0.05,0.01,0.01
11.094399921412126,0.0010095514687476,86.3989911993936,150.0,8.333333333333333e-05,0.61,0.15,0.17,0.02,0.88,0.05,0.01,0.01
11.231088721625325,0.0010209422020987,87.0965750956937,150.0,8.333333333333333e-05,0.61,0.15,0.17,0.02,0.88,0.05,0.01,0.01
11.323408123692523,0.0010286354856043,87.8021561449232,150.0,8.333333333333333e-05,0.61,0.15,0.17,0.02,0.88,0.05,0.01,0.01
11.402055789786528,0.0010351894577788,88.4995960489325,150.0,8.333333333333333e-05,0.61,0.15,0.17,0.02,0.88,0.05,0.01,0.01
11.611463718581328,0.0010526401185117,89.1921648813533,150.0,8.333333333333333e-05,0.61,0.15,0.17,0.02,0.88,0.05,0.01,0.01
11.758454313559724,0.0010648893347599,89.8922395038958,150.0,8.333333333333333e-05,0.61,0.15,0.17,0.02,0.88,0.05,0.01,0.01
12.013443592218524,0.0010861384413148,90.5850989806788,150.0,8.333333333333333e-05,0.61,0.15,0.17,0.02,0.88,0.05,0.01,0.01
12.082894976436524,0.0010919260566663,91.2826304254715,150.0,8.333333333333333e-05,0.61,0.15,0.17,0.02,0.88,0.05,0.01,0.01
12.148732759577324,0.0010974125385947,91.9542828379881,150.0,8.333333333333333e-05,0.61,0.15,0.17,0.02,0.88,0.05,0.01,0.01
12.402802285729724,0.0011185849991074,92.6010314869593,150.0,8.333333333333333e-05,0.61,0.15,0.17,0.02,0.88,0.05,0.01,0.01
12.713207787110925,0.0011444521242225,93.2519893496061,150.0,8.333333333333333e-05,0.61,0.15,0.17,0.02,0.88,0.05,0.01,0.01
12.884983096453729,0.0011587667333344,93.8950015609092,150.0,8.333333333333333e-05,0.61,0.15,0.17,0.02,0.88,0.05,0.01,0.01
13.074225505075724,0.0011745369340529,94.5162598063852,150.0,8.333333333333333e-05,0.61,0.15,0.17,0.02,0.88,0.05,0.01,0.01
13.229811422906923,0.0011875024272055,95.1392071708833,150.0,8.333333333333333e-05,0.61,0.15,0.17,0.02,0.88,0.05,0.01,0.01
13.358964928104529,0.0011982652193053,95.7610971300917,150.0,8.333333333333333e-05,0.61,0.15,0.17,0.02,0.88,0.05,0.01,0.01
13.696746175388924,0.001226413656579,96.3882700310858,150.0,8.333333333333333e-05,0.61,0.15,0.17,0.02,0.88,0.05,0.01,0.01
13.869986820470924,0.0012408503770025,97.0235584769116,150.0,8.333333333333333e-05,0.61,0.15,0.17,0.02,0.88,0.05,0.01,0.01
13.998621947632127,0.0012515699709326,97.6883834225282,150.0,8.333333333333333e-05,0.61,0.15,0.17,0.02,0.88,0.05,0.01,0.01
14.158850227786123,0.0012649223276121,98.3604379843772,150.0,8.333333333333333e-05,0.61,0.15,0.17,0.02,0.88,0.05,0.01,0.01
14.382152908474126,0.0012835308843361,99.0353739435811,150.0,8.333333333333333e-05,0.61,0.15,0.17,0.02,0.88,0.05,0.01,0.01
14.506014308514525,0.0012938526676728,99.7264835221882,150.0,8.333333333333333e-05,0.61,0.15,0.17,0.02,0.88,0.05,0.01,0.01
14.805594495882527,0.0013188176832868,100.416173743691,150.0,8.333333333333333e-05,0.61,0.15,0.17,0.02,0.88,0.05,0.01,0.01
14.886764827351724,0.0013255818775759,101.095066601547,150.0,8.333333333333333e-05,0.61,0.15,0.17,0.02,0.88,0.05,0.01,0.01
15.110481556477726,0.0013442249383364,101.791863804397,150.0,8.333333333333333e-05,0.61,0.15,0.17,0.02,0.88,0.05,0.01,0.01
15.265013414302125,0.0013571025931551,102.4810948971,150.0,8.333333333333333e-05,0.61,0.15,0.17,0.02,0.88,0.05,0.01,0.01
15.452216147574523,0.0013727028209278,103.16166618736,150.0,8.333333333333333e-05,0.61,0.15,0.17,0.02,0.88,0.05,0.01,0.01
15.682720813632525,0.0013919115430993,103.828788091033,150.0,8.333333333333333e-05,0.61,0.15,0.17,0.02,0.88,0.05,0.01,0.01
15.824618505466123,0.0014037363507521,104.481375100981,150.0,8.333333333333333e-05,0.61,0.15,0.17,0.02,0.88,0.05,0.01,0.01
16.017718332290922,0.0014198280029875,105.141570777567,150.0,8.333333333333333e-05,0.61,0.15,0.17,0.02,0.88,0.05,0.01,0.01
16.219270121518125,0.0014366239854231,105.811561998758,150.0,8.333333333333333e-05,0.61,0.15,0.17,0.02,0.88,0.05,0.01,0.01
16.311844030260524,0.0014443384778183,106.454686031672,150.0,8.333333333333333e-05,0.61,0.15,0.17,0.02,0.88,0.05,0.01,0.01
16.548945256325325,0.0014640969133237,107.077989680118,150.0,8.333333333333333e-05,0.61,0.15,0.17,0.02,0.88,0.05,0.01,0.01
16.828753388000926,0.00148741425763,107.736162229396,150.0,8.333333333333333e-05,0.61,0.15,0.17,0.02,0.88,0.05,0.01,0.01
17.001994075889325,0.0015018509816207,108.405327208732,150.0,8.333333333333333e-05,0.61,0.15,0.17,0.02,0.88,0.05,0.01,0.01
17.217908567519324,0.0015198438559232,109.071165594097,150.0,8.333333333333333e-05,0.61,0.15,0.17,0.02,0.88,0.05,0.01,0.01
17.148856320352124,0.0015140895019926,109.724648744303,150.0,8.333333333333333e-05,0.61,0.15,0.17,0.02,0.88,0.05,0.01,0.01
17.487842375185725,0.0015423383398954,110.375139625464,150.0,8.333333333333333e-05,0.61,0.15,0.17,0.02,0.88,0.05,0.01,0.01
17.752883134414123,0.0015644250698311,111.023716208675,150.0,8.333333333333333e-05,0.61,0.15,0.17,0.02,0.88,0.05,0.01,0.01
17.931320841178124,0.0015792948787281,111.685023626069,150.0,8.333333333333333e-05,0.61,0.15,0.17,0.02,0.88,0.05,0.01,0.01
17.995026863839726,0.0015846037139499,112.340577003864,150.0,8.333333333333333e-05,0.61,0.15,0.17,0.02,0.88,0.05,0.01,0.01
18.19054555097812,0.0016008969378781,112.968248154598,150.0,8.333333333333333e-05,0.61,0.15,0.17,0.02,0.88,0.05,0.01,0.01
18.437100952085324,0.0016214432213037,113.590234356702,150.0,8.333333333333333e-05,0.61,0.15,0.17,0.02,0.88,0.05,0.01,0.01
18.703303797506923,0.0016436267917555,114.237767656792,150.0,8.333333333333333e-05,0.61,0.15,0.17,0.02,0.88,0.05,0.01,0.01
18.725648601923325,0.0016454888587902,114.882627133241,150.0,8.333333333333333e-05,0.61,0.15,0.17,0.02,0.88,0.05,0.01,0.01
18.78535908701332,0.0016504647325477,115.541098971167,150.0,8.333333333333333e-05,0.61,0.15,0.17,0.02,0.88,0.05,0.01,0.01
18.866026413388123,0.0016571870097456,116.186282845861,150.0,8.333333333333333e-05,0.61,0.15,0.17,0.02,0.88,0.05,0.01,0.01
18.990753340829325,0.0016675809203657,116.797639218834,150.0,8.333333333333333e-05,0.61,0.15,0.17,0.02,0.88,0.05,0.01,0.01
19.10657205259732,0.0016772324796797,117.443489051936,150.0,8.333333333333333e-05,0.61,0.15,0.17,0.02,0.88,0.05,0.01,0.01
19.348857481862925,0.0016974229321185,118.091381311587,150.0,8.333333333333333e-05,0.61,0.15,0.17,0.02,0.88,0.05,0.01,0.01
19.668457479149325,0.0017240562652257,118.717185438805,150.0,8.333333333333333e-05,0.61,0.15,0.17,0.02,0.88,0.05,0.01,0.01
19.832273649532127,0.0017377076127576,119.330993290424,150.0,8.333333333333333e-05,0.61,0.15,0.17,0.02,0.88,0.05,0.01,0.01
20.027298235128526,0.0017539596615573,119.949100503283,150.0,8.333333333333333e-05,0.61,0.15,0.17,0.02,0.88,0.05,0.01,0.01
20.174337754849724,0.0017662129548674,120.587989247172,150.0,8.333333333333333e-05,0.61,0.15,0.17,0.02,0.88,0.05,0.01,0.01
20.374570017397723,0.0017828989767464,121.240341499816,150.0,8.333333333333333e-05,0.61,0.15,0.17,0.02,0.88,0.05,0.01,0.01
20.414375483756924,0.001786216098943,121.864655595758,150.0,8.333333333333333e-05,0.61,0.15,0.17,0.02,0.88,0.05,0.01,0.01
20.410124043774523,0.0017858618122778,122.485145972065,150.0,8.333333333333333e-05,0.61,0.15,0.17,0.02,0.88,0.05,0.01,0.01
20.519694860422124,0.0017949927136651,123.129727343117,150.0,8.333333333333333e-05,0.61,0.15,0.17,0.02,0.88,0.05,0.01,0.01
20.567394962464125,0.0017989677221686,123.792698754105,150.0,8.333333333333333e-05,0.61,0.15,0.17,0.02,0.88,0.05,0.01,0.01
20.666059602624525,0.0018071897755153,124.420750696766,150.0,8.333333333333333e-05,0.61,0.15,0.17,0.02,0.88,0.05,0.01,0.01
20.870927341097325,0.0018242620870547,125.026762699687,150.0,8.333333333333333e-05,0.61,0.15,0.17,0.02,0.88,0.05,0.01,0.01
21.027443066022524,0.0018373050641318,125.612957943674,150.0,8.333333333333333e-05,0.61,0.15,0.17,0.02,0.88,0.05,0.01,0.01
21.325299925843726,0.0018621264691169,126.209139223223,150.0,8.333333333333333e-05,0.61,0.15,0.17,0.02,0.88,0.05,0.01,0.01
21.519596750448525,0.0018783178711673,126.837446963953,150.0,8.333333333333333e-05,0.61,0.15,0.17,0.02,0.88,0.05,0.01,0.01
21.635217439178927,0.0018879529285615,127.443171773893,150.0,8.333333333333333e-05,0.61,0.15,0.17,0.02,0.88,0.05,0.01,0.01
21.842303065562927,0.0019052100640935,128.03583677595,150.0,8.333333333333333e-05,0.61,0.15,0.17,0.02,0.88,0.05,0.01,0.01
22.026457875041324,0.0019205562982167,128.655090734231,150.0,8.333333333333333e-05,0.61,0.15,0.17,0.02,0.88,0.05,0.01,0.01
22.162503941220525,0.0019318934703983,129.277061547604,150.0,8.333333333333333e-05,0.61,0.15,0.17,0.02,0.88,0.05,0.01,0.01
22.276665531910123,0.0019414069362891,129.91082104703,150.0,8.333333333333333e-05,0.61,0.15,0.17,0.02,0.88,0.05,0.01,0.01
22.321623868321726,0.0019451534643234,130.533894181156,150.0,8.333333333333333e-05,0.61,0.15,0.17,0.02,0.88,0.05,0.01,0.01
22.377795522745725,0.0019498344355254,131.140472574862,150.0,8.333333333333333e-05,0.61,0.15,0.17,0.02,0.88,0.05,0.01,0.01
22.54444766370292,0.0019637221139385,131.762652228511,150.0,8.333333333333333e-05,0.61,0.15,0.17,0.02,0.88,0.05,0.01,0.01
22.68281903627812,0.0019752530616531,132.383621840292,150.0,8.333333333333333e-05,0.61,0.15,0.17,0.02,0.88,0.05,0.01,0.01
22.876158280571325,0.0019913646653442,133.016847610405,150.0,8.333333333333333e-05,0.61,0.15,0.17,0.02,0.88,0.05,0.01,0.01
23.09136444419452,0.0020092985123128,133.637710150184,150.0,8.333333333333333e-05,0.61,0.15,0.17,0.02,0.88,0.05,0.01,0.01
23.34678271389533,0.0020305833681212,134.236632618652,150.0,8.333333333333333e-05,0.61,0.15,0.17,0.02,0.88,0.05,0.01,0.01
23.655877383691724,0.0020563412572709,134.842889115574,150.0,8.333333333333333e-05,0.61,0.15,0.17,0.02,0.88,0.05,0.01,0.01
24.009433142441324,0.0020858042371667,135.441419963007,150.0,8.333333333333333e-05,0.61,0.15,0.17,0.02,0.88,0.05,0.01,0.01
24.189447561444524,0.0021008054387503,136.034129722205,150.0,8.333333333333333e-05,0.61,0.15,0.17,0.02,0.88,0.05,0.01,0.01
24.401460988796924,0.002118473224363,136.64907412342,150.0,8.333333333333333e-05,0.61,0.15,0.17,0.02,0.88,0.05,0.01,0.01
24.456522756457723,0.0021230617050014,137.234722291694,150.0,8.333333333333333e-05,0.61,0.15,0.17,0.02,0.88,0.05,0.01,0.01
24.62379343657492,0.0021370009283445,137.825937159185,150.0,8.333333333333333e-05,0.61,0.15,0.17,0.02,0.88,0.05,0.01,0.01
24.764523618396524,0.0021487284434963,138.444833091994,150.0,8.333333333333333e-05,0.61,0.15,0.17,0.02,0.88,0.05,0.01,0.01
24.834123812794125,0.0021545284596961,139.075537817532,150.0,8.333333333333333e-05,0.61,0.15,0.17,0.02,0.88,0.05,0.01,0.01
24.88366203547252,0.0021586566449193,139.703696230579,150.0,8.333333333333333e-05,0.61,0.15,0.17,0.02,0.88,0.05,0.01,0.01
24.99447645345293,0.002167891179751,140.299478353048,150.0,8.333333333333333e-05,0.61,0.15,0.17,0.02,0.88,0.05,0.01,0.01
25.078338177192524,0.0021748796567293,140.862098583901,150.0,8.333333333333333e-05,0.61,0.15,0.17,0.02,0.88,0.05,0.01,0.01
25.294422829783723,0.0021928867111119,141.423136783565,150.0,8.333333333333333e-05,0.61,0.15,0.17,0.02,0.88,0.05,0.01,0.01
25.389954153385723,0.0022008476547454,141.982401226188,150.0,8.333333333333333e-05,0.61,0.15,0.17,0.02,0.88,0.05,0.01,0.01
25.522987950235727,0.0022119338044829,142.525471166964,150.0,8.333333333333333e-05,0.61,0.15,0.17,0.02,0.88,0.05,0.01,0.01
25.632842750287725,0.0022210883711539,143.041611082145,150.0,8.333333333333333e-05,0.61,0.15,0.17,0.02,0.88,0.05,0.01,0.01
25.814795111383724,0.0022362510679119,143.57543959928,150.0,8.333333333333333e-05,0.61,0.15,0.17,0.02,0.88,0.05,0.01,0.01
26.040444346646925,0.0022550551708505,144.12477500164,150.0,8.333333333333333e-05,0.61,0.15,0.17,0.02,0.88,0.05,0.01,0.01
26.300010134862525,0.0022766856532018,144.677629198786,150.0,8.333333333333333e-05,0.61,0.15,0.17,0.02,0.88,0.05,0.01,0.01
26.489999369178523,0.0022925180893948,145.220390415024,150.0,8.333333333333333e-05,0.61,0.15,0.17,0.02,0.88,0.05,0.01,0.01
26.722535289090526,0.0023118960827208,145.75851954413,150.0,8.333333333333333e-05,0.61,0.15,0.17,0.02,0.88,0.05,0.01,0.01
26.90305934266613,0.0023269397538521,146.301794715479,150.0,8.333333333333333e-05,0.61,0.15,0.17,0.02,0.88,0.05,0.01,0.01
27.122828127726525,0.0023452538192738,146.891361136426,150.0,8.333333333333333e-05,0.61,0.15,0.17,0.02,0.88,0.05,0.01,0.01
27.27737472217732,0.0023581327021447,147.45997046499,150.0,8.333333333333333e-05,0.61,0.15,0.17,0.02,0.88,0.05,0.01,0.01
27.380630292374924,0.0023667373329945,148.022568404347,150.0,8.333333333333333e-05,0.61,0.15,0.17,0.02,0.88,0.05,0.01,0.01
27.527430440940524,0.0023789706787083,148.590351158584,150.0,8.333333333333333e-05,0.61,0.15,0.17,0.02,0.88,0.05,0.01,0.01
27.679857836239723,0.0023916729616499,149.164134013791,150.0,8.333333333333333e-05,0.61,0.15,0.17,0.02,0.88,0.05,0.01,0.01
27.74399149486013,0.0023970174332016,149.784210319248,150.0,8.333333333333333e-05,0.61,0.15,0.17,0.02,0.88,0.05,0.01,0.01
27.82714971565853,0.0024039472849348,150.416466773473,150.0,8.333333333333333e-05,0.61,0.15,0.17,0.02,0.88,0.05,0.01,0.01
28.020006460481326,0.0024200186803367,150.994208237192,150.0,8.333333333333333e-05,0.61,0.15,0.17,0.02,0.88,0.05,0.01,0.01
28.097059919324924,0.002426439801907,151.547988560455,150.0,8.333333333333333e-05,0.61,0.15,0.17,0.02,0.88,0.05,0.01,0.01
28.24974997234852,0.0024391639729923,152.104662851702,150.0,8.333333333333333e-05,0.61,0.15,0.17,0.02,0.88,0.05,0.01,0.01
28.363611134827725,0.0024486524031989,152.666683397014,150.0,8.333333333333333e-05,0.61,0.15,0.17,0.02,0.88,0.05,0.01,0.01
28.483226321708923,0.002458620335439,153.255497195034,150.0,8.333333333333333e-05,0.61,0.15,0.17,0.02,0.88,0.05,0.01,0.01
28.613944912453725,0.0024695135513344,153.826415118195,150.0,8.333333333333333e-05,0.61,0.15,0.17,0.02,0.88,0.05,0.01,0.01
28.82473147461413,0.0024870790981811,154.375136396206,150.0,8.333333333333333e-05,0.61,0.15,0.17,0.02,0.88,0.05,0.01,0.01
28.858147545845323,0.0024898637707837,154.935059720321,150.0,8.333333333333333e-05,0.61,0.15,0.17,0.02,0.88,0.05,0.01,0.01
29.057782531187325,0.0025065000195622,155.524837023876,150.0,8.333333333333333e-05,0.61,0.15,0.17,0.02,0.88,0.05,0.01,0.01
29.197290046958923,0.0025181256458765,156.109516034582,150.0,8.333333333333333e-05,0.61,0.15,0.17,0.02,0.88,0.05,0.01,0.01
29.41023732848092,0.00253587125267,156.678036023014,150.0,8.333333333333333e-05,0.61,0.15,0.17,0.02,0.88,0.05,0.01,0.01
29.494530009720528,0.0025428956427733,157.216056496915,150.0,8.333333333333333e-05,0.61,0.15,0.17,0.02,0.88,0.05,0.01,0.01
29.68274697249413,0.0025585803896711,157.723058324099,150.0,8.333333333333333e-05,0.61,0.15,0.17,0.02,0.88,0.05,0.01,0.01
29.74927216248532,0.0025641241555037,158.242496240608,150.0,8.333333333333333e-05,0.61,0.15,0.17,0.02,0.88,0.05,0.01,0.01
29.92768861154452,0.0025789921929253,158.770557371745,150.0,8.333333333333333e-05,0.61,0.15,0.17,0.02,0.88,0.05,0.01,0.01
30.098905510650525,0.0025932602678508,159.314814904574,150.0,8.333333333333333e-05,0.61,0.15,0.17,0.02,0.88,0.05,0.01,0.01
30.301572543548925,0.002610149187259,159.871966246476,150.0,8.333333333333333e-05,0.61,0.15,0.17,0.02,0.88,0.05,0.01,0.01
30.365765095829325,0.0026154985666157,160.446727204347,150.0,8.333333333333333e-05,0.61,0.15,0.17,0.02,0.88,0.05,0.01,0.01
30.571582113452923,0.002632649984751,161.029925303026,150.0,8.333333333333333e-05,0.61,0.15,0.17,0.02,0.88,0.05,0.01,0.01
30.794544674980123,0.0026512301982116,161.649208629718,150.0,8.333333333333333e-05,0.61,0.15,0.17,0.02,0.88,0.05,0.01,0.01
30.971348433592127,0.0026659638447626,162.26626439013,150.0,8.333333333333333e-05,0.61,0.15,0.17,0.02,0.88,0.05,0.01,0.01
31.123913391248927,0.002678677591234,162.887348324982,150.0,8.333333333333333e-05,0.61,0.15,0.17,0.02,0.88,0.05,0.01,0.01
31.221553984740524,0.0026868143073583,163.470558661819,150.0,8.333333333333333e-05,0.61,0.15,0.17,0.02,0.88,0.05,0.01,0.01
31.348560392210928,0.0026973981746475,164.06085793149,150.0,8.333333333333333e-05,0.61,0.15,0.17,0.02,0.88,0.05,0.01,0.01
31.534858428935323,0.0027129230110412,164.648895865167,150.0,8.333333333333333e-05,0.61,0.15,0.17,0.02,0.88,0.05,0.01,0.01
31.66109799457853,0.0027234429748448,165.234041382398,150.0,8.333333333333333e-05,0.61,0.15,0.17,0.02,0.88,0.05,0.01,0.01
31.755302596098524,0.0027312933583048,165.779253143192,150.0,8.333333333333333e-05,0.61,0.15,0.17,0.02,0.88,0.05,0.01,0.01
31.90013981014613,0.0027433631261421,166.328042894723,150.0,8.333333333333333e-05,0.61,0.15,0.17,0.02,0.88,0.05,0.01,0.01
32.091960253304926,0.002759348163072,166.877634253473,150.0,8.333333333333333e-05,0.61,0.15,0.17,0.02,0.88,0.05,0.01,0.01
32.255279428651725,0.0027729580943509,167.435696506914,150.0,8.333333333333333e-05,0.61,0.15,0.17,0.02,0.88,0.05,0.01,0.01
32.30852353955573,0.0027773951035929,167.973331629263,150.0,8.333333333333333e-05,0.61,0.15,0.17,0.02,0.88,0.05,0.01,0.01
32.43865050448972,0.0027882390173374,168.496195074083,150.0,8.333333333333333e-05,0.61,0.15,0.17,0.02,0.88,0.05,0.01,0.01
32.573402329301324,0.0027994683360717,169.011572012191,150.0,8.333333333333333e-05,0.61,0.15,0.17,0.02,0.88,0.05,0.01,0.01
32.718680193493725,0.0028115748247544,169.528543536285,150.0,8.333333333333333e-05,0.61,0.15,0.17,0.02,0.88,0.05,0.01,0.01
32.82360351030892,0.002820318434489,170.033137992852,150.0,8.333333333333333e-05,0.61,0.15,0.17,0.02,0.88,0.05,0.01,0.01
32.911563383513325,0.0028276484239227,170.535628309625,150.0,8.333333333333333e-05,0.61,0.15,0.17,0.02,0.88,0.05,0.01,0.01
33.08994530320492,0.002842513583897,171.043532245741,150.0,8.333333333333333e-05,0.61,0.15,0.17,0.02,0.88,0.05,0.01,0.01
33.27480743570212,0.0028579187616051,171.551566194467,150.0,8.333333333333333e-05,0.61,0.15,0.17,0.02,0.88,0.05,0.01,0.01
33.440469593875726,0.0028717239414529,172.071727365492,150.0,8.333333333333333e-05,0.61,0.15,0.17,0.02,0.88,0.05,0.01,0.01
33.58825963562212,0.0028840397782651,172.603808501743,150.0,8.333333333333333e-05,0.61,0.15,0.17,0.02,0.88,0.05,0.01,0.01
33.653061269652525,0.0028894399144343,173.157545176106,150.0,8.333333333333333e-05,0.61,0.15,0.17,0.02,0.88,0.05,0.01,0.01
33.828095167516125,0.0029040260725896,173.721765027528,150.0,8.333333333333333e-05,0.61,0.15,0.17,0.02,0.88,0.05,0.01,0.01
33.986536797679726,0.0029172295417699,174.271704516733,150.0,8.333333333333333e-05,0.61,0.15,0.17,0.02,0.88,0.05,0.01,0.01
34.08326453327452,0.0029252901864028,174.810475412909,150.0,8.333333333333333e-05,0.61,0.15,0.17,0.02,0.88,0.05,0.01,0.01
34.201529325036525,0.0029351455857163,175.35962364904,150.0,8.333333333333333e-05,0.61,0.15,0.17,0.02,0.88,0.05,0.01,0.01
34.32812836584293,0.0029456955057835,175.911705274904,150.0,8.333333333333333e-05,0.61,0.15,0.17,0.02,0.88,0.05,0.01,0.01
34.51614982367813,0.0029613639606031,176.480648595922,150.0,8.333333333333333e-05,0.61,0.15,0.17,0.02,0.88,0.05,0.01,0.01
34.73890456028933,0.0029799268553207,177.032281114659,150.0,8.333333333333333e-05,0.61,0.15,0.17,0.02,0.88,0.05,0.01,0.01
34.86209914905893,0.0029901930710515,177.579523697127,150.0,8.333333333333333e-05,0.61,0.15,0.17,0.02,0.88,0.05,0.01,0.01
35.02052459739413,0.0030033951917461,178.132187260829,150.0,8.333333333333333e-05,0.61,0.15,0.17,0.02,0.88,0.05,0.01,0.01
35.203407879287326,0.0030186354652372,178.689328707714,150.0,8.333333333333333e-05,0.61,0.15,0.17,0.02,0.88,0.05,0.01,0.01
35.383553013610126,0.0030336475597641,179.247660263944,150.0,8.333333333333333e-05,0.61,0.15,0.17,0.02,0.88,0.05,0.01,0.01
35.52893413128772,0.0030457626529039,179.800851746606,150.0,8.333333333333333e-05,0.61,0.15,0.17,0.02,0.88,0.05,0.01,0.01
35.70670411776652,0.0030605768184438,180.339610705432,150.0,8.333333333333333e-05,0.61,0.15,0.17,0.02,0.88,0.05,0.01,0.01
35.87569361416492,0.003074659276477,180.896371376222,150.0,8.333333333333333e-05,0.61,0.15,0.17,0.02,0.88,0.05,0.01,0.01
36.06101613931132,0.0030901028202392,181.467125200418,150.0,8.333333333333333e-05,0.61,0.15,0.17,0.02,0.88,0.05,0.01,0.01
36.248017946237326,0.0031056863041497,182.041962326173,150.0,8.333333333333333e-05,0.61,0.15,0.17,0.02,0.88,0.05,0.01,0.01
36.42889314314692,0.0031207592372255,182.621055623398,150.0,8.333333333333333e-05,0.61,0.15,0.17,0.02,0.88,0.05,0.01,0.01
36.618073054278526,0.0031365242298198,183.18916152515,150.0,8.333333333333333e-05,0.61,0.15,0.17,0.02,0.88,0.05,0.01,0.01
36.76055874009173,0.0031483980369709,183.754086265936,150.0,8.333333333333333e-05,0.61,0.15,0.17,0.02,0.88,0.05,0.01,0.01
36.86948343540772,0.0031574750949139,184.311907175949,150.0,8.333333333333333e-05,0.61,0.15,0.17,0.02,0.88,0.05,0.01,0.01
37.000377021962926,0.0031683828937935,184.857488582923,150.0,8.333333333333333e-05,0.61,0.15,0.17,0.02,0.88,0.05,0.01,0.01
37.19966279235532,0.0031849900413262,185.390208193182,150.0,8.333333333333333e-05,0.61,0.15,0.17,0.02,0.88,0.05,0.01,0.01
37.27550340466372,0.0031913100923519,185.920905768543,150.0,8.333333333333333e-05,0.61,0.15,0.17,0.02,0.88,0.05,0.01,0.01
37.47007435691573,0.0032075243383729,186.46182193612,150.0,8.333333333333333e-05,0.61,0.15,0.17,0.02,0.88,0.05,0.01,0.01
37.572373554550126,0.0032160492715091,187.020854613691,150.0,8.333333333333333e-05,0.61,0.15,0.17,0.02,0.88,0.05,0.01,0.01
37.676445282809325,0.0032247219155307,187.58118572334,150.0,8.333333333333333e-05,0.61,0.15,0.17,0.02,0.88,0.05,0.01,0.01
37.80078445397092,0.0032350835131275,188.125618010089,150.0,8.333333333333333e-05,0.61,0.15,0.17,0.02,0.88,0.05,0.01,0.01
37.96517785826693,0.0032487829634855,188.658686684892,150.0,8.333333333333333e-05,0.61,0.15,0.17,0.02,0.88,0.05,0.01,0.01
38.01250483518893,0.003252726878229,189.187259712977,150.0,8.333333333333333e-05,0.61,0.15,0.17,0.02,0.88,0.05,0.01,0.01
38.21556285836933,0.0032696483801607,189.749321722369,150.0,8.333333333333333e-05,0.61,0.15,0.17,0.02,0.88,0.05,0.01,0.01
38.300853517735725,0.0032767559351079,190.291046589914,150.0,8.333333333333333e-05,0.61,0.15,0.17,0.02,0.88,0.05,0.01,0.01
38.49981422566853,0.0032933359941023,190.814327082004,150.0,8.333333333333333e-05,0.61,0.15,0.17,0.02,0.88,0.05,0.01,0.01
38.66917806552292,0.0033074496474235,191.350054983319,150.0,8.333333333333333e-05,0.61,0.15,0.17,0.02,0.88,0.05,0.01,0.01
38.92282177094213,0.0033285866228751,191.909139938246,150.0,8.333333333333333e-05,0.61,0.15,0.17,0.02,0.88,0.05,0.01,0.01
39.07018843448332,0.0033408671781702,192.47152257786,150.0,8.333333333333333e-05,0.61,0.15,0.17,0.02,0.88,0.05,0.01,0.01
39.29658040555972,0.0033597331757599,193.037472838233,150.0,8.333333333333333e-05,0.61,0.15,0.17,0.02,0.88,0.05,0.01,0.01
39.43831815384052,0.0033715446547833,193.593516365669,150.0,8.333333333333333e-05,0.61,0.15,0.17,0.02,0.88,0.05,0.01,0.01
39.56551986107572,0.0033821447970529,194.175389798601,150.0,8.333333333333333e-05,0.61,0.15,0.17,0.02,0.88,0.05,0.01,0.01
39.729340586369325,0.0033957965241607,194.744468325134,150.0,8.333333333333333e-05,0.61,0.15,0.17,0.02,0.88,0.05,0.01,0.01
39.90383448873532,0.0034103376826912,195.292044884224,150.0,8.333333333333333e-05,0.61,0.15,0.17,0.02,0.88,0.05,0.01,0.01
39.99465023738093,0.003417905661745,195.856753549497,150.0,8.333333333333333e-05,0.61,0.15,0.17,0.02,0.88,0.05,0.01,0.01
40.09130556977813,0.0034259602727781,196.437009313347,150.0,8.333333333333333e-05,0.61,0.15,0.17,0.02,0.88,0.05,0.01,0.01
40.18133703836212,0.0034334628951601,197.001921641824,150.0,8.333333333333333e-05,0.61,0.15,0.17,0.02,0.88,0.05,0.01,0.01
40.29261514350173,0.0034427360705884,197.537357948855,150.0,8.333333333333333e-05,0.61,0.15,0.17,0.02,0.88,0.05,0.01,0.01
40.37370374281252,0.0034494934538643,198.057281702795,150.0,8.333333333333333e-05,0.61,0.15,0.17,0.02,0.88,0.05,0.01,0.01
40.48315571662613,0.0034586144516821,198.592565990697,150.0,8.333333333333333e-05,0.61,0.15,0.17,0.02,0.88,0.05,0.01,0.01
40.608555292279725,0.0034690644163199,199.146663825273,150.0,8.333333333333333e-05,0.61,0.15,0.17,0.02,0.88,0.05,0.01,0.01
40.69985426174573,0.0034766726637754,199.681503755658,150.0,8.333333333333333e-05,0.61,0.15,0.17,0.02,0.88,0.05,0.01,0.01
40.84926372836813,0.0034891234526606,200.204379422803,150.0,8.333333333333333e-05,0.61,0.15,0.17,0.02,0.88,0.05,0.01,0.01
40.98248163770213,0.0035002249451051,200.718526845649,150.0,8.333333333333333e-05,0.61,0.15,0.17,0.02,0.88,0.05,0.01,0.01
41.187492380824125,0.0035173091736986,201.252737722082,150.0,8.333333333333333e-05,0.61,0.15,0.17,0.02,0.88,0.05,0.01,0.01
41.43473782924372,0.0035379129610669,201.817871303144,150.0,8.333333333333333e-05,0.61,0.15,0.17,0.02,0.88,0.05,0.01,0.01
41.660610839941725,0.0035567357119584,202.3724677041,150.0,8.333333333333333e-05,0.61,0.15,0.17,0.02,0.88,0.05,0.01,0.01
41.820223501913325,0.0035700367671227,202.980329616115,150.0,8.333333333333333e-05,0.61,0.15,0.17,0.02,0.88,0.05,0.01,0.01
42.04560826583453,0.0035888188307828,203.553473997314,150.0,8.333333333333333e-05,0.61,0.15,0.17,0.02,0.88,0.05,0.01,0.01
42.17368808219933,0.0035994921488132,204.130801073543,150.0,8.333333333333333e-05,0.61,0.15,0.17,0.02,0.88,0.05,0.01,0.01
42.31745475998813,0.0036114727052956,204.722773756865,150.0,8.333333333333333e-05,0.61,0.15,0.17,0.02,0.88,0.05,0.01,0.01
42.44588268689933,0.0036221750325382,205.297575862176,150.0,8.333333333333333e-05,0.61,0.15,0.17,0.02,0.88,0.05,0.01,0.01
42.50198100867652,0.0036268498926863,205.835157757248,150.0,8.333333333333333e-05,0.61,0.15,0.17,0.02,0.88,0.05,0.01,0.01
42.54388875914093,0.003630342205225,206.369202809024,150.0,8.333333333333333e-05,0.61,0.15,0.17,0.02,0.88,0.05,0.01,0.01
42.72071197638893,0.003645077473329,206.830692702336,150.0,8.333333333333333e-05,0.61,0.15,0.17,0.02,0.88,0.05,0.01,0.01
42.80443614044092,0.003652054487,207.324189556685,150.0,8.333333333333333e-05,0.61,0.15,0.17,0.02,0.88,0.05,0.01,0.01
42.98132187652013,0.0036667949650066,207.818441234613,150.0,8.333333333333333e-05,0.61,0.15,0.17,0.02,0.88,0.05,0.01,0.01
43.15707748611893,0.0036814412658065,208.319572815116,150.0,8.333333333333333e-05,0.61,0.15,0.17,0.02,0.88,0.05,0.01,0.01
43.31799982184573,0.0036948514604504,208.820576583661,150.0,8.333333333333333e-05,0.61,0.15,0.17,0.02,0.88,0.05,0.01,0.01
43.48687658169892,0.0037089245237715,209.323810894906,150.0,8.333333333333333e-05,0.61,0.15,0.17,0.02,0.88,0.05,0.01,0.01
43.67817519502493,0.003724866074882,209.833264042416,150.0,8.333333333333333e-05,0.61,0.15,0.17,0.02,0.88,0.05,0.01,0.01
43.82816978723693,0.003737365624233,210.34663700997,150.0,8.333333333333333e-05,0.61,0.15,0.17,0.02,0.88,0.05,0.01,0.01
44.05008861984172,0.0037558588602834,210.863491551211,150.0,8.333333333333333e-05,0.61,0.15,0.17,0.02,0.88,0.05,0.01,0.01
44.148967879594124,0.0037640987985961,211.390893959177,150.0,8.333333333333333e-05,0.61,0.15,0.17,0.02,0.88,0.05,0.01,0.01
44.32060845216533,0.0037784021796437,211.924810264905,150.0,8.333333333333333e-05,0.61,0.15,0.17,0.02,0.88,0.05,0.01,0.01
44.43857335947053,0.0037882325885858,212.464881635489,150.0,8.333333333333333e-05,0.61,0.15,0.17,0.02,0.88,0.05,0.01,0.01
44.59016592639293,0.003800865302496,212.9956214507,150.0,8.333333333333333e-05,0.61,0.15,0.17,0.02,0.88,0.05,0.01,0.01
44.652671188582126,0.0038060740743451,213.526428472868,150.0,8.333333333333333e-05,0.61,0.15,0.17,0.02,0.88,0.05,0.01,0.01
44.76760993792132,0.0038156523034567,214.082499801346,150.0,8.333333333333333e-05,0.61,0.15,0.17,0.02,0.88,0.05,0.01,0.01
45.06242145795533,0.0038402199301262,214.622689722153,150.0,8.333333333333333e-05,0.61,0.15,0.17,0.02,0.88,0.05,0.01,0.01
45.26231055561773,0.0038568773549314,215.173803124539,150.0,8.333333333333333e-05,0.61,0.15,0.17,0.02,0.88,0.05,0.01,0.01
45.42250190616532,0.0038702266341437,215.71817038915,150.0,8.333333333333333e-05,0.61,0.15,0.17,0.02,0.88,0.05,0.01,0.01
45.64990511093572,0.0038891769012079,216.263714733347,150.0,8.333333333333333e-05,0.61,0.15,0.17,0.02,0.88,0.05,0.01,0.01
45.75935322163973,0.0038982975770999,216.805692565029,150.0,8.333333333333333e-05,0.61,0.15,0.17,0.02,0.88,0.05,0.01,0.01
45.96873775836653,0.0039157462884938,217.31969034355,150.0,8.333333333333333e-05,0.61,0.15,0.17,0.02,0.88,0.05,0.01,0.01
46.13528273992373,0.0039296250369569,217.787867162853,150.0,8.333333333333333e-05,0.61,0.15,0.17,0.02,0.88,0.05,0.01,0.01
46.06737768870653,0.0039239662826888,218.262774715367,150.0,8.333333333333333e-05,0.61,0.15,0.17,0.02,0.88,0.05,0.01,0.01
46.24459057922453,0.0039387340235653,218.710010622619,150.0,8.333333333333333e-05,0.61,0.15,0.17,0.02,0.88,0.05,0.01,0.01
46.42894843534973,0.0039540971782424,219.161655812879,150.0,8.333333333333333e-05,0.61,0.15,0.17,0.02,0.88,0.05,0.01,0.01
46.50015467800972,0.0039600310317974,219.611472894747,150.0,8.333333333333333e-05,0.61,0.15,0.17,0.02,0.88,0.05,0.01,0.01
46.71371399187292,0.003977827641286,220.076117097904,150.0,8.333333333333333e-05,0.61,0.15,0.17,0.02,0.88,0.05,0.01,0.01
46.793601869588926,0.003984484964429,220.589787010967,150.0,8.333333333333333e-05,0.61,0.15,0.17,0.02,0.88,0.05,0.01,0.01
46.93659361822733,0.0039964009434822,221.139031030864,150.0,8.333333333333333e-05,0.61,0.15,0.17,0.02,0.88,0.05,0.01,0.01
47.16946740060652,0.0040158070920138,221.703380277448,150.0,8.333333333333333e-05,0.61,0.15,0.17,0.02,0.88,0.05,0.01,0.01
47.29130445907133,0.0040259601802192,222.271621226395,150.0,8.333333333333333e-05,0.61,0.15,0.17,0.02,0.88,0.05,0.01,0.01
47.38377455950253,0.0040336660219218,222.866296310168,150.0,8.333333333333333e-05,0.61,0.15,0.17,0.02,0.88,0.05,0.01,0.01
47.56070930944372,0.0040484105844169,223.454190251554,150.0,8.333333333333333e-05,0.61,0.15,0.17,0.02,0.88,0.05,0.01,0.01
47.73367908865372,0.0040628247326844,224.037611011869,150.0,8.333333333333333e-05,0.61,0.15,0.17,0.02,0.88,0.05,0.01,0.01
48.00460144484213,0.0040854015957001,224.59035905527,150.0,8.333333333333333e-05,0.61,0.15,0.17,0.02,0.88,0.05,0.01,0.01
48.19513335116212,0.0041012792545601,225.108874297044,150.0,8.333333333333333e-05,0.61,0.15,0.17,0.02,0.88,0.05,0.01,0.01
48.29494634352292,0.0041095970039235,225.604043298482,150.0,8.333333333333333e-05,0.61,0.15,0.17,0.02,0.88,0.05,0.01,0.01
48.47356672928453,0.0041244820360703,226.083127878159,150.0,8.333333333333333e-05,0.61,0.15,0.17,0.02,0.88,0.05,0.01,0.01
48.65573432089372,0.0041396626687044,226.519832858956,150.0,8.333333333333333e-05,0.61,0.15,0.17,0.02,0.88,0.05,0.01,0.01
48.91408194184133,0.0041611916371167,226.939124984224,150.0,8.333333333333333e-05,0.61,0.15,0.17,0.02,0.88,0.05,0.01,0.01
49.06126939543133,0.0041734572582492,227.348593130564,150.0,8.333333333333333e-05,0.61,0.15,0.17,0.02,0.88,0.05,0.01,0.01
49.22870708473733,0.0041874103990247,227.754791994873,150.0,8.333333333333333e-05,0.61,0.15,0.17,0.02,0.88,0.05,0.01,0.01
49.34549901489173,0.0041971430598709,228.157893845444,150.0,8.333333333333333e-05,0.61,0.15,0.17,0.02,0.88,0.05,0.01,0.01
49.62658558626893,0.004220566940819,228.632897815006,150.0,8.333333333333333e-05,0.61,0.15,0.17,0.02,0.88,0.05,0.01,0.01
49.85675331770213,0.0042397475851051,229.116814076188,150.0,8.333333333333333e-05,0.61,0.15,0.17,0.02,0.88,0.05,0.01,0.01
50.05111076850773,0.0042559440393389,229.564395121641,150.0,8.333333333333333e-05,0.61,0.15,0.17,0.02,0.88,0.05,0.01,0.01
50.156534204615326,0.0042647293256812,230.020056390672,150.0,8.333333333333333e-05,0.61,0.15,0.17,0.02,0.88,0.05,0.01,0.01
50.34746073301853,0.0042806398697148,230.488302142623,150.0,8.333333333333333e-05,0.61,0.15,0.17,0.02,0.88,0.05,0.01,0.01
50.59992607479653,0.0043016786481963,230.964953307998,150.0,8.333333333333333e-05,0.61,0.15,0.17,0.02,0.88,0.05,0.01,0.01
50.93655199229933,0.0043297308079882,231.465104743506,150.0,8.333333333333333e-05,0.61,0.15,0.17,0.02,0.88,0.05,0.01,0.01
51.12202967452133,0.0043451872815067,231.898347956481,150.0,8.333333333333333e-05,0.61,0.15,0.17,0.02,0.88,0.05,0.01,0.01
51.24429576973013,0.0043553761227741,232.307716709352,150.0,8.333333333333333e-05,0.61,0.15,0.17,0.02,0.88,0.05,0.01,0.01
51.46821095094173,0.0043740357212084,232.741218237689,150.0,8.333333333333333e-05,0.61,0.15,0.17,0.02,0.88,0.05,0.01,0.01
51.64232644208573,0.0043885453454704,233.141362839662,150.0,8.333333333333333e-05,0.61,0.15,0.17,0.02,0.88,0.05,0.01,0.01
51.882267162964126,0.0044085404055436,233.514746074629,150.0,8.333333333333333e-05,0.61,0.15,0.17,0.02,0.88,0.05,0.01,0.01
52.04527477357252,0.0044221243730943,233.88922157701,150.0,8.333333333333333e-05,0.61,0.15,0.17,0.02,0.88,0.05,0.01,0.01
52.14160415612572,0.0044301518216404,234.28687654515,150.0,8.333333333333333e-05,0.61,0.15,0.17,0.02,0.88,0.05,0.01,0.01
52.30726660955932,0.0044439570260932,234.622340015909,150.0,8.333333333333333e-05,0.61,0.15,0.17,0.02,0.88,0.05,0.01,0.01
52.60123594582733,0.0044684544707822,234.955620360888,150.0,8.333333333333333e-05,0.61,0.15,0.17,0.02,0.88,0.05,0.01,0.01
52.79096965944172,0.0044842656135834,235.32021158015,150.0,8.333333333333333e-05,0.61,0.15,0.17,0.02,0.88,0.05,0.01,0.01
53.090296817521725,0.0045092095434234,235.682749068794,150.0,8.333333333333333e-05,0.61,0.15,0.17,0.02,0.88,0.05,0.01,0.01
53.42410091287972,0.0045370265513699,236.041063031609,150.0,8.333333333333333e-05,0.61,0.15,0.17,0.02,0.88,0.05,0.01,0.01
53.75401798164173,0.0045645196404334,236.412950599099,150.0,8.333333333333333e-05,0.61,0.15,0.17,0.02,0.88,0.05,0.01,0.01
54.06523279217573,0.0045904542079779,236.762484182749,150.0,8.333333333333333e-05,0.61,0.15,0.17,0.02,0.88,0.05,0.01,0.01
54.33724608084892,0.004613121982034,237.105271786945,150.0,8.333333333333333e-05,0.61,0.15,0.17,0.02,0.88,0.05,0.01,0.01
54.69085152115613,0.0046425891020596,237.469670029622,150.0,8.333333333333333e-05,0.61,0.15,0.17,0.02,0.88,0.05,0.01,0.01
55.05896691204772,0.0046732653846339,237.81387369786,150.0,8.333333333333333e-05,0.61,0.15,0.17,0.02,0.88,0.05,0.01,0.01
55.47661687292933,0.0047080695480407,238.114010690527,150.0,8.333333333333333e-05,0.61,0.15,0.17,0.02,0.88,0.05,0.01,0.01
55.74316357954492,0.004730281773592,238.418210102309,150.0,8.333333333333333e-05,0.61,0.15,0.17,0.02,0.88,0.05,0.01,0.01
56.054037493764525,0.0047561879331103,238.711093144917,150.0,8.333333333333333e-05,0.61,0.15,0.17,0.02,0.88,0.05,0.01,0.01
56.49255868981732,0.0047927313661147,238.920812541503,150.0,8.333333333333333e-05,0.61,0.15,0.17,0.02,0.88,0.05,0.01,0.01
56.953837310966925,0.0048311712512105,239.15121736871,150.0,8.333333333333333e-05,0.61,0.15,0.17,0.02,0.88,0.05,0.01,0.01
57.336188389748926,0.004863033841109,239.384008193297,150.0,8.333333333333333e-05,0.61,0.15,0.17,0.02,0.88,0.05,0.01,0.01
57.81798795233573,0.0049031838046579,239.604799290903,150.0,8.333333333333333e-05,0.61,0.15,0.17,0.02,0.88,0.05,0.01,0.01
58.225980587635725,0.0049371831909329,239.864322589045,150.0,8.333333333333333e-05,0.61,0.15,0.17,0.02,0.88,0.05,0.01,0.01
58.77431555015693,0.004982877771143,240.071262625693,150.0,8.333333333333333e-05,0.61,0.15,0.17,0.02,0.88,0.05,0.01,0.01
59.31805889695613,0.0050281897167096,240.244296174635,150.0,8.333333333333333e-05,0.61,0.15,0.17,0.02,0.88,0.05,0.01,0.01
59.82215842410413,0.0050701980106386,240.401758291175,150.0,8.333333333333333e-05,0.61,0.15,0.17,0.02,0.88,0.05,0.01,0.01
60.351897357606525,0.0051143429217638,240.52867456867,150.0,8.333333333333333e-05,0.61,0.15,0.17,0.02,0.88,0.05,0.01,0.01
60.83738415580612,0.0051548001549471,240.627825760275,150.0,8.333333333333333e-05,0.61,0.15,0.17,0.02,0.88,0.05,0.01,0.01
61.31321889071333,0.0051944530495227,240.65305879833,150.0,8.333333333333333e-05,0.61,0.15,0.17,0.02,0.88,0.05,0.01,0.01
61.81371221578493,0.005236160826612,240.672145558304,150.0,8.333333333333333e-05,0.61,0.15,0.17,0.02,0.88,0.05,0.01,0.01
62.40038542395892,0.0052850502606265,240.735982367487,150.0,8.333333333333333e-05,0.61,0.15,0.17,0.02,0.88,0.05,0.01,0.01
62.95784999559893,0.0053315056415965,240.772107159737,150.0,8.333333333333333e-05,0.61,0.15,0.17,0.02,0.88,0.05,0.01,0.01
63.49857431726812,0.0053765660017356,240.815508351861,150.0,8.333333333333333e-05,0.61,0.15,0.17,0.02,0.88,0.05,0.01,0.01
64.07626383963893,0.0054247067952665,240.917760958509,150.0,8.333333333333333e-05,0.61,0.15,0.17,0.02,0.88,0.05,0.01,0.01
64.74597291103014,0.0054805158845491,240.996239606763,150.0,8.333333333333333e-05,0.61,0.15,0.17,0.02,0.88,0.05,0.01,0.01
65.36315000898293,0.0055319473093785,241.077204120827,150.0,8.333333333333333e-05,0.61,0.15,0.17,0.02,0.88,0.05,0.01,0.01
66.09915785727173,0.0055932812967359,241.097741632815,150.0,8.333333333333333e-05,0.61,0.15,0.17,0.02,0.88,0.05,0.01,0.01
66.66333143806014,0.0056402957618016,241.10099190058,150.0,8.333333333333333e-05,0.61,0.15,0.17,0.02,0.88,0.05,0.01,0.01