File: datasets/al_6061_comp/csv/T_150_D_1.csv
Time,Strain(%),Stress(MPa),Temp(C),SR(%/s),Si(%),Fe(%),Cu(%),Mn(%),Mg(%),Cr(%),Zn(%),Ti(%)
0.0,8.97841239138227e-05,43.0173851026609,150.0,8.333333333333333e-05,0.67,0.28,0.23,0.05,0.9,0.05,0.03,0.02
0.5454789015585275,0.0001352406990437,45.6715623155562,150.0,8.333333333333333e-05,0.67,0.28,0.23,0.05,0.9,0.05,0.03,0.02
1.0571718067413276,0.0001778817744756,48.3527648246466,150.0,8.333333333333333e-05,0.67,0.28,0.23,0.05,0.9,0.05,0.03,0.02
1.6605893005677272,0.0002281665656278,50.9306079155076,150.0,8.333333333333333e-05,0.67,0.28,0.23,0.05,0.9,0.05,0.03,0.02
2.329999257557727,0.0002839507287103,53.5430512599717,150.0,8.333333333333333e-05,0.67,0.28,0.23,0.05,0.9,0.05,0.03,0.02
2.950827300996928,0.0003356863989969,56.082994637152,150.0,8.333333333333333e-05,0.67,0.28,0.23,0.05,0.9,0.05,0.03,0.02
3.441797798018128,0.000376600607082,58.677798207542,150.0,8.333333333333333e-05,0.67,0.28,0.23,0.05,0.9,0.05,0.03,0.02
4.058301513839728,0.0004279759167338,61.3047097952926,150.0,8.333333333333333e-05,0.67,0.28,0.23,0.05,0.9,0.05,0.03,0.02
4.737483699022528,0.0004845744321657,63.8185587825239,150.0,8.333333333333333e-05,0.67,0.28,0.23,0.05,0.9,0.05,0.03,0.02
5.493893830767329,0.0005476086098111,66.2607263249046,150.0,8.333333333333333e-05,0.67,0.28,0.23,0.05,0.9,0.05,0.03,0.02
6.043885392938128,0.000593441239992,68.7658737751422,150.0,8.333333333333333e-05,0.67,0.28,0.23,0.05,0.9,0.05,0.03,0.02
6.5795287207293285,0.0006380781839746,71.1291106096397,150.0,8.333333333333333e-05,0.67,0.28,0.23,0.05,0.9,0.05,0.03,0.02
7.200659449547728,0.0006898390780428,73.5023682549026,150.0,8.333333333333333e-05,0.67,0.28,0.23,0.05,0.9,0.05,0.03,0.02
7.886097955173327,0.0007469589535116,75.7778588760539,150.0,8.333333333333333e-05,0.67,0.28,0.23,0.05,0.9,0.05,0.03,0.02
8.416758995054126,0.000791180706835,77.9958383169015,150.0,8.333333333333333e-05,0.67,0.28,0.23,0.05,0.9,0.05,0.03,0.02
8.926641089236528,0.0008336708813502,80.2643790482572,150.0,8.333333333333333e-05,0.67,0.28,0.23,0.05,0.9,0.05,0.03,0.02
9.444301866914127,0.00087680927949,82.5242086712962,150.0,8.333333333333333e-05,0.67,0.28,0.23,0.05,0.9,0.05,0.03,0.02
10.033282700004929,0.0009258910155809,84.7053689437882,150.0,8.333333333333333e-05,0.67,0.28,0.23,0.05,0.9,0.05,0.03,0.02
10.614905102982927,0.0009743595491624,86.9249809132322,150.0,8.333333333333333e-05,0.67,0.28,0.23,0.05,0.9,0.05,0.03,0.02
11.143486450736129,0.0010184079948085,89.1497552803521,150.0,8.333333333333333e-05,0.67,0.28,0.23,0.05,0.9,0.05,0.03,0.02
11.676419105030126,0.001062819049333,91.3027121123525,150.0,8.333333333333333e-05,0.67,0.28,0.23,0.05,0.9,0.05,0.03,0.02
12.225863527998929,0.0011086060845804,93.4020387453884,150.0,8.333333333333333e-05,0.67,0.28,0.23,0.05,0.9,0.05,0.03,0.02
12.798135753126928,0.0011562954366744,95.4528202617627,150.0,8.333333333333333e-05,0.67,0.28,0.23,0.05,0.9,0.05,0.03,0.02
13.335108798500128,0.0012010431904555,97.5218549726009,150.0,8.333333333333333e-05,0.67,0.28,0.23,0.05,0.9,0.05,0.03,0.02
13.968954951413728,0.0012538637031983,99.5575587235532,150.0,8.333333333333333e-05,0.67,0.28,0.23,0.05,0.9,0.05,0.03,0.02
14.527673340509727,0.0013004235689563,101.649775464064,150.0,8.333333333333333e-05,0.67,0.28,0.23,0.05,0.9,0.05,0.03,0.02
15.06313528575453,0.0013450453977267,103.651807522368,150.0,8.333333333333333e-05,0.67,0.28,0.23,0.05,0.9,0.05,0.03,0.02
15.566394216550528,0.0013869836419597,105.719085863733,150.0,8.333333333333333e-05,0.67,0.28,0.23,0.05,0.9,0.05,0.03,0.02
16.12711343427813,0.001433710243437,107.817616127828,150.0,8.333333333333333e-05,0.67,0.28,0.23,0.05,0.9,0.05,0.03,0.02
16.680534386018127,0.001479828656082,109.91064167683,150.0,8.333333333333333e-05,0.67,0.28,0.23,0.05,0.9,0.05,0.03,0.02
17.273606058240926,0.0015292512954339,111.970529118597,150.0,8.333333333333333e-05,0.67,0.28,0.23,0.05,0.9,0.05,0.03,0.02
17.728566274136128,0.0015671646467585,114.003451449408,150.0,8.333333333333333e-05,0.67,0.28,0.23,0.05,0.9,0.05,0.03,0.02
18.257076028086928,0.0016112071262544,116.003493274687,150.0,8.333333333333333e-05,0.67,0.28,0.23,0.05,0.9,0.05,0.03,0.02
18.826866775680926,0.0016586896885539,118.107710711184,150.0,8.333333333333333e-05,0.67,0.28,0.23,0.05,0.9,0.05,0.03,0.02
19.401376500230125,0.001706565498933,120.150649288951,150.0,8.333333333333333e-05,0.67,0.28,0.23,0.05,0.9,0.05,0.03,0.02
19.958526476244927,0.0017529946636009,122.226789946521,150.0,8.333333333333333e-05,0.67,0.28,0.23,0.05,0.9,0.05,0.03,0.02
20.57909426857533,0.0018047086462951,124.284933902069,150.0,8.333333333333333e-05,0.67,0.28,0.23,0.05,0.9,0.05,0.03,0.02
21.066078052871728,0.0018452906283198,126.318565540814,150.0,8.333333333333333e-05,0.67,0.28,0.23,0.05,0.9,0.05,0.03,0.02
21.603870066356127,0.0018901066294435,128.354156765334,150.0,8.333333333333333e-05,0.67,0.28,0.23,0.05,0.9,0.05,0.03,0.02
22.09352027702373,0.0019309108136658,130.364106874946,150.0,8.333333333333333e-05,0.67,0.28,0.23,0.05,0.9,0.05,0.03,0.02
22.668042488979328,0.0019787876646621,132.336550820228,150.0,8.333333333333333e-05,0.67,0.28,0.23,0.05,0.9,0.05,0.03,0.02
23.311452651669324,0.0020324051782196,134.299844992682,150.0,8.333333333333333e-05,0.67,0.28,0.23,0.05,0.9,0.05,0.03,0.02
23.844019109597728,0.0020767857163803,136.264487358883,150.0,8.333333333333333e-05,0.67,0.28,0.23,0.05,0.9,0.05,0.03,0.02
24.34854585460413,0.0021188296117975,138.250461240861,150.0,8.333333333333333e-05,0.67,0.28,0.23,0.05,0.9,0.05,0.03,0.02
24.901820605512924,0.0021649358410399,140.195164750481,150.0,8.333333333333333e-05,0.67,0.28,0.23,0.05,0.9,0.05,0.03,0.02
25.467793785734127,0.002212100272725,142.143172283989,150.0,8.333333333333333e-05,0.67,0.28,0.23,0.05,0.9,0.05,0.03,0.02
26.07514978485573,0.0022627132726518,144.108232555705,150.0,8.333333333333333e-05,0.67,0.28,0.23,0.05,0.9,0.05,0.03,0.02
26.553655755222927,0.0023025887701824,146.059327363833,150.0,8.333333333333333e-05,0.67,0.28,0.23,0.05,0.9,0.05,0.03,0.02
26.97996224951373,0.0023381143113733,148.01365420492,150.0,8.333333333333333e-05,0.67,0.28,0.23,0.05,0.9,0.05,0.03,0.02
27.475171639724127,0.0023793817605575,149.93857540614,150.0,8.333333333333333e-05,0.67,0.28,0.23,0.05,0.9,0.05,0.03,0.02
28.03981469757213,0.0024264353487115,151.878296027931,150.0,8.333333333333333e-05,0.67,0.28,0.23,0.05,0.9,0.05,0.03,0.02
28.54620129101253,0.0024686342314982,153.831667923538,150.0,8.333333333333333e-05,0.67,0.28,0.23,0.05,0.9,0.05,0.03,0.02
29.068626410921727,0.0025121696581573,155.768176463191,150.0,8.333333333333333e-05,0.67,0.28,0.23,0.05,0.9,0.05,0.03,0.02
29.575629402047724,0.0025544199074178,157.679847023358,150.0,8.333333333333333e-05,0.67,0.28,0.23,0.05,0.9,0.05,0.03,0.02
30.11314312904973,0.0025992127180013,159.564515058838,150.0,8.333333333333333e-05,0.67,0.28,0.23,0.05,0.9,0.05,0.03,0.02
30.697437874226125,0.002647903946766,161.47400975936,150.0,8.333333333333333e-05,0.67,0.28,0.23,0.05,0.9,0.05,0.03,0.02
31.33211692511853,0.0027007938676737,163.329504132783,150.0,8.333333333333333e-05,0.67,0.28,0.23,0.05,0.9,0.05,0.03,0.02
31.819456477462527,0.0027414054970357,165.158457908784,150.0,8.333333333333333e-05,0.67,0.28,0.23,0.05,0.9,0.05,0.03,0.02
32.392810137414926,0.0027891849686984,166.975869303045,150.0,8.333333333333333e-05,0.67,0.28,0.23,0.05,0.9,0.05,0.03,0.02
32.93927572721373,0.0028347237678483,168.848605955398,150.0,8.333333333333333e-05,0.67,0.28,0.23,0.05,0.9,0.05,0.03,0.02
33.43387373167053,0.0028759402682197,170.671442229777,150.0,8.333333333333333e-05,0.67,0.28,0.23,0.05,0.9,0.05,0.03,0.02
33.943808178280534,0.0029184348054372,172.492589720267,150.0,8.333333333333333e-05,0.67,0.28,0.23,0.05,0.9,0.05,0.03,0.02
34.45498579270653,0.0029610329399727,174.407847038668,150.0,8.333333333333333e-05,0.67,0.28,0.23,0.05,0.9,0.05,0.03,0.02
34.951060069220134,0.0030023724630155,176.312353495223,150.0,8.333333333333333e-05,0.67,0.28,0.23,0.05,0.9,0.05,0.03,0.02
35.422429532465735,0.0030416532516193,178.168646915656,150.0,8.333333333333333e-05,0.67,0.28,0.23,0.05,0.9,0.05,0.03,0.02
35.94279237060093,0.0030850168214639,180.006484400719,150.0,8.333333333333333e-05,0.67,0.28,0.23,0.05,0.9,0.05,0.03,0.02
36.42253276768413,0.0031249951878875,181.834008880272,150.0,8.333333333333333e-05,0.67,0.28,0.23,0.05,0.9,0.05,0.03,0.02
37.00425348671853,0.0031734719144737,183.706653131326,150.0,8.333333333333333e-05,0.67,0.28,0.23,0.05,0.9,0.05,0.03,0.02
37.56513666128733,0.0032202121790211,185.52385989894,150.0,8.333333333333333e-05,0.67,0.28,0.23,0.05,0.9,0.05,0.03,0.02
38.07994758158613,0.003263113089046,187.259836083837,150.0,8.333333333333333e-05,0.67,0.28,0.23,0.05,0.9,0.05,0.03,0.02
38.60805562148853,0.0033071220923712,189.008298756905,150.0,8.333333333333333e-05,0.67,0.28,0.23,0.05,0.9,0.05,0.03,0.02
39.18103215731613,0.0033548701370235,190.806708666229,150.0,8.333333333333333e-05,0.67,0.28,0.23,0.05,0.9,0.05,0.03,0.02
39.738023727635735,0.0034012861012168,192.678017131394,150.0,8.333333333333333e-05,0.67,0.28,0.23,0.05,0.9,0.05,0.03,0.02
40.39105733228733,0.0034557055682711,194.496150415757,150.0,8.333333333333333e-05,0.67,0.28,0.23,0.05,0.9,0.05,0.03,0.02
40.97483770737453,0.0035043539328617,196.275939506241,150.0,8.333333333333333e-05,0.67,0.28,0.23,0.05,0.9,0.05,0.03,0.02
41.57800276432413,0.0035546176876075,198.072959244277,150.0,8.333333333333333e-05,0.67,0.28,0.23,0.05,0.9,0.05,0.03,0.02
42.15807303359853,0.0036029568767137,199.815173332968,150.0,8.333333333333333e-05,0.67,0.28,0.23,0.05,0.9,0.05,0.03,0.02
42.81221599540893,0.0036574687901979,201.543158239598,150.0,8.333333333333333e-05,0.67,0.28,0.23,0.05,0.9,0.05,0.03,0.02
43.483086356072135,0.0037133746535865,203.23938419692,150.0,8.333333333333333e-05,0.67,0.28,0.23,0.05,0.9,0.05,0.03,0.02
44.13025402748613,0.003767305292871,204.886266608587,150.0,8.333333333333333e-05,0.67,0.28,0.23,0.05,0.9,0.05,0.03,0.02
44.74035670460853,0.0038181471826312,206.550436731274,150.0,8.333333333333333e-05,0.67,0.28,0.23,0.05,0.9,0.05,0.03,0.02
45.372656009171735,0.0038708387913448,208.205271755599,150.0,8.333333333333333e-05,0.67,0.28,0.23,0.05,0.9,0.05,0.03,0.02
46.05417956648254,0.0039276324211207,209.852820261626,150.0,8.333333333333333e-05,0.67,0.28,0.23,0.05,0.9,0.05,0.03,0.02
46.79804251584693,0.0039896210002344,211.46416899384,150.0,8.333333333333333e-05,0.67,0.28,0.23,0.05,0.9,0.05,0.03,0.02
47.46588443634813,0.0040452744936095,213.107909270091,150.0,8.333333333333333e-05,0.67,0.28,0.23,0.05,0.9,0.05,0.03,0.02
48.20725163017054,0.0041070550930947,214.677460161306,150.0,8.333333333333333e-05,0.67,0.28,0.23,0.05,0.9,0.05,0.03,0.02
48.95072586851013,0.004169011279623,216.18126324164,150.0,8.333333333333333e-05,0.67,0.28,0.23,0.05,0.9,0.05,0.03,0.02
49.72570681978173,0.0042335930255623,217.623690513983,150.0,8.333333333333333e-05,0.67,0.28,0.23,0.05,0.9,0.05,0.03,0.02
50.60649927051214,0.0043069923964565,219.017834027,150.0,8.333333333333333e-05,0.67,0.28,0.23,0.05,0.9,0.05,0.03,0.02
51.54511234557333,0.0043852101527116,220.382884964816,150.0,8.333333333333333e-05,0.67,0.28,0.23,0.05,0.9,0.05,0.03,0.02
52.54085133953853,0.0044681884022087,221.732124504805,150.0,8.333333333333333e-05,0.67,0.28,0.23,0.05,0.9,0.05,0.03,0.02
53.651647249484135,0.0045607547280375,222.933759014774,150.0,8.333333333333333e-05,0.67,0.28,0.23,0.05,0.9,0.05,0.03,0.02
54.78139753220253,0.0046549005849307,224.090084212523,150.0,8.333333333333333e-05,0.67,0.28,0.23,0.05,0.9,0.05,0.03,0.02
56.09417052283054,0.0047642983341497,225.14788246431,150.0,8.333333333333333e-05,0.67,0.28,0.23,0.05,0.9,0.05,0.03,0.02
57.52519128333573,0.0048835500641918,226.069349928152,150.0,8.333333333333333e-05,0.67,0.28,0.23,0.05,0.9,0.05,0.03,0.02
59.01848474859813,0.005007991186297,226.926329002423,150.0,8.333333333333333e-05,0.67,0.28,0.23,0.05,0.9,0.05,0.03,0.02
60.56795445010413,0.0051371136614225,227.628618318488,150.0,8.333333333333333e-05,0.67,0.28,0.23,0.05,0.9,0.05,0.03,0.02
62.19190577596053,0.0052724429385772,228.220854977435,150.0,8.333333333333333e-05,0.67,0.28,0.23,0.05,0.9,0.05,0.03,0.02
63.87809427186093,0.0054129586465689,228.721960787691,150.0,8.333333333333333e-05,0.67,0.28,0.23,0.05,0.9,0.05,0.03,0.02
65.67820164007293,0.0055629675939199,229.103657005905,150.0,8.333333333333333e-05,0.67,0.28,0.23,0.05,0.9,0.05,0.03,0.02
67.42172200335813,0.005708260957527,229.420960230848,150.0,8.333333333333333e-05,0.67,0.28,0.23,0.05,0.9,0.05,0.03,0.02
69.27423193986694,0.0058626367855694,229.716127853797,150.0,8.333333333333333e-05,0.67,0.28,0.23,0.05,0.9,0.05,0.03,0.02
71.17154996512292,0.0060207466210074,229.926204798457,150.0,8.333333333333333e-05,0.67,0.28,0.23,0.05,0.9,0.05,0.03,0.02
73.06111359410372,0.0061782102567558,230.12250111382,150.0,8.333333333333333e-05,0.67,0.28,0.23,0.05,0.9,0.05,0.03,0.02
75.06538909989693,0.0063452332155719,230.245852823235,150.0,8.333333333333333e-05,0.67,0.28,0.23,0.05,0.9,0.05,0.03,0.02
77.05994501779412,0.00651144620873,230.373001432134,150.0,8.333333333333333e-05,0.67,0.28,0.23,0.05,0.9,0.05,0.03,0.02
79.12369030041452,0.0066834249822817,230.511159946619,150.0,8.333333333333333e-05,0.67,0.28,0.23,0.05,0.9,0.05,0.03,0.02
81.13396997425413,0.006850948288435,230.642758032246,150.0,8.333333333333333e-05,0.67,0.28,0.23,0.05,0.9,0.05,0.03,0.02
83.23622708373213,0.0070261363808915,230.782947949122,150.0,8.333333333333333e-05,0.67,0.28,0.23,0.05,0.9,0.05,0.03,0.02
85.35781985565453,0.0072029357785517,230.898447005988,150.0,8.333333333333333e-05,0.67,0.28,0.23,0.05,0.9,0.05,0.03,0.02
87.69429126677493,0.0073976417294784,231.002883055442,150.0,8.333333333333333e-05,0.67,0.28,0.23,0.05,0.9,0.05,0.03,0.02
89.85259999063892,0.0075775007898004,231.072261012442,150.0,8.333333333333333e-05,0.67,0.28,0.23,0.05,0.9,0.05,0.03,0.02
92.11853979764732,0.0077663291070511,231.142766658288,150.0,8.333333333333333e-05,0.67,0.28,0.23,0.05,0.9,0.05,0.03,0.02
94.27556724148772,0.0079460813940378,231.218604751259,150.0,8.333333333333333e-05,0.67,0.28,0.23,0.05,0.9,0.05,0.03,0.02
96.62096860274131,0.0081415315074756,231.3151004216,150.0,8.333333333333333e-05,0.67,0.28,0.23,0.05,0.9,0.05,0.03,0.02
98.78012543150491,0.0083214612432059,231.385085523752,150.0,8.333333333333333e-05,0.67,0.28,0.23,0.05,0.9,0.05,0.03,0.02
101.00694699459332,0.0085070297067966,231.456373244939,150.0,8.333333333333333e-05,0.67,0.28,0.23,0.05,0.9,0.05,0.03,0.02
103.08660212746652,0.0086803343012027,231.508409882002,150.0,8.333333333333333e-05,0.67,0.28,0.23,0.05,0.9,0.05,0.03,0.02
105.26741911302334,0.0088620690499991,231.619694434952,150.0,8.333333333333333e-05,0.67,0.28,0.23,0.05,0.9,0.05,0.03,0.02
107.43721752393692,0.0090428855842419,231.72075244123,150.0,8.333333333333333e-05,0.67,0.28,0.23,0.05,0.9,0.05,0.03,0.02
109.64379131556214,0.009226766733544,231.811343096491,150.0,8.333333333333333e-05,0.67,0.28,0.23,0.05,0.9,0.05,0.03,0.02
111.79923653384252,0.0094063871684007,231.872441193495,150.0,8.333333333333333e-05,0.67,0.28,0.23,0.05,0.9,0.05,0.03,0.02
114.07916937545252,0.0095963815718682,231.910680071129,150.0,8.333333333333333e-05,0.67,0.28,0.23,0.05,0.9,0.05,0.03,0.02
116.27491449864452,0.0097793603321342,231.991906866518,150.0,8.333333333333333e-05,0.67,0.28,0.23,0.05,0.9,0.05,0.03,0.02
118.49301325794454,0.0099642018954092,232.036957341006,150.0,8.333333333333333e-05,0.67,0.28,0.23,0.05,0.9,0.05,0.03,0.02
120.70644170898692,0.0101486542663294,232.094867410952,150.0,8.333333333333333e-05,0.67,0.28,0.23,0.05,0.9,0.05,0.03,0.02
122.93939529522692,0.0103347337318494,232.127433251316,150.0,8.333333333333333e-05,0.67,0.28,0.23,0.05,0.9,0.05,0.03,0.02
125.18927167802492,0.0105222234304159,232.171643477735,150.0,8.333333333333333e-05,0.67,0.28,0.23,0.05,0.9,0.05,0.03,0.02
127.47263768101531,0.0107125039306651,232.224647198744,150.0,8.333333333333333e-05,0.67,0.28,0.23,0.05,0.9,0.05,0.03,0.02
129.62781413212295,0.0108921019682574,232.30190690258,150.0,8.333333333333333e-05,0.67,0.28,0.23,0.05,0.9,0.05,0.03,0.02
131.88391746997053,0.0110801105797447,232.320394451839,150.0,8.333333333333333e-05,0.67,0.28,0.23,0.05,0.9,0.05,0.03,0.02
134.10199255490133,0.0112649501701556,232.380168077399,150.0,8.333333333333333e-05,0.67,0.28,0.23,0.05,0.9,0.05,0.03,0.02
136.34659182813454,0.0114520001095917,232.449472950059,150.0,8.333333333333333e-05,0.67,0.28,0.23,0.05,0.9,0.05,0.03,0.02
138.59063847979175,0.0116390039972298,232.52330792675,150.0,8.333333333333333e-05,0.67,0.28,0.23,0.05,0.9,0.05,0.03,0.02
140.81616849144453,0.0118244648315342,232.594897097074,150.0,8.333333333333333e-05,0.67,0.28,0.23,0.05,0.9,0.05,0.03,0.02
143.0694568532001,0.0120122388616805,232.66526066265,150.0,8.333333333333333e-05,0.67,0.28,0.23,0.05,0.9,0.05,0.03,0.02
145.38287669460573,0.0122050238484643,232.737699018503,150.0,8.333333333333333e-05,0.67,0.28,0.23,0.05,0.9,0.05,0.03,0.02
147.63754970639732,0.0123929132661136,232.818534942611,150.0,8.333333333333333e-05,0.67,0.28,0.23,0.05,0.9,0.05,0.03,0.02
149.96068544372253,0.0125865079108907,232.895849808327,150.0,8.333333333333333e-05,0.67,0.28,0.23,0.05,0.9,0.05,0.03,0.02
152.25432288643174,0.0127776443644498,232.938274111435,150.0,8.333333333333333e-05,0.67,0.28,0.23,0.05,0.9,0.05,0.03,0.02
154.48568565720572,0.0129635912620143,233.003722501539,150.0,8.333333333333333e-05,0.67,0.28,0.23,0.05,0.9,0.05,0.03,0.02
156.77801989047933,0.0131546191147871,233.037716719251,150.0,8.333333333333333e-05,0.67,0.28,0.23,0.05,0.9,0.05,0.03,0.02
159.04665188220213,0.013343671780764,233.068827956209,150.0,8.333333333333333e-05,0.67,0.28,0.23,0.05,0.9,0.05,0.03,0.02
161.28602335354532,0.0135302860700426,233.104020887053,150.0,8.333333333333333e-05,0.67,0.28,0.23,0.05,0.9,0.05,0.03,0.02
163.50439503095973,0.0137151503764938,233.132262058208,150.0,8.333333333333333e-05,0.67,0.28,0.23,0.05,0.9,0.05,0.03,0.02
165.7160436692865,0.0138994544296877,233.190553412266,150.0,8.333333333333333e-05,0.67,0.28,0.23,0.05,0.9,0.05,0.03,0.02
167.97893826132213,0.014088028979024,233.266064432211,150.0,8.333333333333333e-05,0.67,0.28,0.23,0.05,0.9,0.05,0.03,0.02
170.19881940765333,0.0142730190745516,233.295430629988,150.0,8.333333333333333e-05,0.67,0.28,0.23,0.05,0.9,0.05,0.03,0.02
172.44649827597573,0.0144603256469118,233.366646677178,150.0,8.333333333333333e-05,0.67,0.28,0.23,0.05,0.9,0.05,0.03,0.02
174.65451355728092,0.0146443269203539,233.427761127834,150.0,8.333333333333333e-05,0.67,0.28,0.23,0.05,0.9,0.05,0.03,0.02
176.9323208369289,0.0148341441936579,233.489507095652,150.0,8.333333333333333e-05,0.67,0.28,0.23,0.05,0.9,0.05,0.03,0.02
179.13459833089294,0.0150176673181549,233.572944819127,150.0,8.333333333333333e-05,0.67,0.28,0.23,0.05,0.9,0.05,0.03,0.02
181.36971007987773,0.0152039266305703,233.625349096412,150.0,8.333333333333333e-05,0.67,0.28,0.23,0.05,0.9,0.05,0.03,0.02
183.63711025018773,0.0153928766447628,233.692071835287,150.0,8.333333333333333e-05,0.67,0.28,0.23,0.05,0.9,0.05,0.03,0.02
185.85581625277771,0.0155777688116453,233.776826154465,150.0,8.333333333333333e-05,0.67,0.28,0.23,0.05,0.9,0.05,0.03,0.02
188.08445913026972,0.0157634890514363,233.836472944148,150.0,8.333333333333333e-05,0.67,0.28,0.23,0.05,0.9,0.05,0.03,0.02
190.3038271466301,0.015948436386133,233.875418467491,150.0,8.333333333333333e-05,0.67,0.28,0.23,0.05,0.9,0.05,0.03,0.02
192.53076885289053,0.0161340148616547,233.906515711936,150.0,8.333333333333333e-05,0.67,0.28,0.23,0.05,0.9,0.05,0.03,0.02
194.7889984109841,0.0163222006581625,233.942486170159,150.0,8.333333333333333e-05,0.67,0.28,0.23,0.05,0.9,0.05,0.03,0.02
196.9761083403081,0.0165044598189395,233.99982980477,150.0,8.333333333333333e-05,0.67,0.28,0.23,0.05,0.9,0.05,0.03,0.02
199.1311965737625,0.0166840505050607,234.015718232731,150.0,8.333333333333333e-05,0.67,0.28,0.23,0.05,0.9,0.05,0.03,0.02
201.4536477690141,0.016877588104665,234.067209351919,150.0,8.333333333333333e-05,0.67,0.28,0.23,0.05,0.9,0.05,0.03,0.02
203.68864258558892,0.0170638376727129,234.132689815463,150.0,8.333333333333333e-05,0.67,0.28,0.23,0.05,0.9,0.05,0.03,0.02
205.9765036643049,0.0172544927626059,234.210687097497,150.0,8.333333333333333e-05,0.67,0.28,0.23,0.05,0.9,0.05,0.03,0.02
208.24316991694653,0.0174433816169927,234.277726529899,150.0,8.333333333333333e-05,0.67,0.28,0.23,0.05,0.9,0.05,0.03,0.02
210.5627331884373,0.0176366785562836,234.350266256206,150.0,8.333333333333333e-05,0.67,0.28,0.23,0.05,0.9,0.05,0.03,0.02
212.90016597905972,0.0178314646221688,234.40988082983,150.0,8.333333333333333e-05,0.67,0.28,0.23,0.05,0.9,0.05,0.03,0.02
215.2236416495685,0.0180250875947112,234.471058777656,150.0,8.333333333333333e-05,0.67,0.28,0.23,0.05,0.9,0.05,0.03,0.02
217.5054028242093,0.0182152343592646,234.506951429263,150.0,8.333333333333333e-05,0.67,0.28,0.23,0.05,0.9,0.05,0.03,0.02
219.8297636965101,0.018408931098623,234.570433007559,150.0,8.333333333333333e-05,0.67,0.28,0.23,0.05,0.9,0.05,0.03,0.02
222.1376968358601,0.0186012588602355,234.607702630268,150.0,8.333333333333333e-05,0.67,0.28,0.23,0.05,0.9,0.05,0.03,0.02
224.3846916609525,0.0187885084289932,234.65135868659,150.0,8.333333333333333e-05,0.67,0.28,0.23,0.05,0.9,0.05,0.03,0.02
226.6134585330345,0.0189742390016667,234.66571801646,150.0,8.333333333333333e-05,0.67,0.28,0.23,0.05,0.9,0.05,0.03,0.02
228.85383499037252,0.0191609370397782,234.686411597218,150.0,8.333333333333333e-05,0.67,0.28,0.23,0.05,0.9,0.05,0.03,0.02
231.1270778498757,0.0193503739447368,234.729117715574,150.0,8.333333333333333e-05,0.67,0.28,0.23,0.05,0.9,0.05,0.03,0.02
233.40211259873732,0.0195399601738086,234.761778191603,150.0,8.333333333333333e-05,0.67,0.28,0.23,0.05,0.9,0.05,0.03,0.02
235.6448316853557,0.0197268534310268,234.7714631345,150.0,8.333333333333333e-05,0.67,0.28,0.23,0.05,0.9,0.05,0.03,0.02
237.9127348878789,0.0199158453645704,234.818444892806,150.0,8.333333333333333e-05,0.67,0.28,0.23,0.05,0.9,0.05,0.03,0.02
240.1827973733421,0.020105017238359,234.849144974884,150.0,8.333333333333333e-05,0.67,0.28,0.23,0.05,0.9,0.05,0.03,0.02
242.5084890186525,0.0202988248754682,234.884361485411,150.0,8.333333333333333e-05,0.67,0.28,0.23,0.05,0.9,0.05,0.03,0.02
244.8174327690369,0.0204912368546669,234.892783885227,150.0,8.333333333333333e-05,0.67,0.28,0.23,0.05,0.9,0.05,0.03,0.02
247.0302565940073,0.0206756388400811,234.922256635282,150.0,8.333333333333333e-05,0.67,0.28,0.23,0.05,0.9,0.05,0.03,0.02
249.1830543652977,0.0208550386543553,234.958834238657,150.0,8.333333333333333e-05,0.67,0.28,0.23,0.05,0.9,0.05,0.03,0.02
251.3930744951913,0.0210392069985131,234.966875195894,150.0,8.333333333333333e-05,0.67,0.28,0.23,0.05,0.9,0.05,0.03,0.02
253.60115520922776,0.0212232137246828,234.956765739465,150.0,8.333333333333333e-05,0.67,0.28,0.23,0.05,0.9,0.05,0.03,0.02
255.83383643926047,0.0214092704938522,234.968977036251,150.0,8.333333333333333e-05,0.67,0.28,0.23,0.05,0.9,0.05,0.03,0.02
258.00981286222896,0.0215906018624329,234.998077154417,150.0,8.333333333333333e-05,0.67,0.28,0.23,0.05,0.9,0.05,0.03,0.02
260.1469330063581,0.021768695207777,235.051157572782,150.0,8.333333333333333e-05,0.67,0.28,0.23,0.05,0.9,0.05,0.03,0.02
262.40025324754896,0.0219564718945429,235.085728589479,150.0,8.333333333333333e-05,0.67,0.28,0.23,0.05,0.9,0.05,0.03,0.02
264.65021865784297,0.0221439690120674,235.12626686655,150.0,8.333333333333333e-05,0.67,0.28,0.23,0.05,0.9,0.05,0.03,0.02
266.88155523361297,0.0223299137267149,235.172114961857,150.0,8.333333333333333e-05,0.67,0.28,0.23,0.05,0.9,0.05,0.03,0.02
269.07005179439136,0.0225122884401131,235.244442043156,150.0,8.333333333333333e-05,0.67,0.28,0.23,0.05,0.9,0.05,0.03,0.02
271.27469919866616,0.022696009057136,235.295387612777,150.0,8.333333333333333e-05,0.67,0.28,0.23,0.05,0.9,0.05,0.03,0.02
273.5100432679713,0.0228822877295781,235.343967465101,150.0,8.333333333333333e-05,0.67,0.28,0.23,0.05,0.9,0.05,0.03,0.02
275.80156465104693,0.0230732478448344,235.408184593235,150.0,8.333333333333333e-05,0.67,0.28,0.23,0.05,0.9,0.05,0.03,0.02
278.0725152866794,0.0232624937311371,235.453147040075,150.0,8.333333333333333e-05,0.67,0.28,0.23,0.05,0.9,0.05,0.03,0.02
280.2703707642657,0.0234456483542693,235.492568150417,150.0,8.333333333333333e-05,0.67,0.28,0.23,0.05,0.9,0.05,0.03,0.02
282.4409343057562,0.0236265286493935,235.539082340083,150.0,8.333333333333333e-05,0.67,0.28,0.23,0.05,0.9,0.05,0.03,0.02
284.66467313241697,0.0238118402182819,235.577065517603,150.0,8.333333333333333e-05,0.67,0.28,0.23,0.05,0.9,0.05,0.03,0.02
286.9757466324058,0.0240044296766143,235.615575371435,150.0,8.333333333333333e-05,0.67,0.28,0.23,0.05,0.9,0.05,0.03,0.02
289.19127534261696,0.0241890570691319,235.647995534361,150.0,8.333333333333333e-05,0.67,0.28,0.23,0.05,0.9,0.05,0.03,0.02
291.3610715154406,0.0243698734168672,235.659535713428,150.0,8.333333333333333e-05,0.67,0.28,0.23,0.05,0.9,0.05,0.03,0.02
293.53092759853416,0.024550694757125,235.679912901742,150.0,8.333333333333333e-05,0.67,0.28,0.23,0.05,0.9,0.05,0.03,0.02
295.84194744629974,0.0247432797444388,235.713304522265,150.0,8.333333333333333e-05,0.67,0.28,0.23,0.05,0.9,0.05,0.03,0.02
298.1703768374854,0.0249373155270376,235.746283720182,150.0,8.333333333333333e-05,0.67,0.28,0.23,0.05,0.9,0.05,0.03,0.02
300.42350142771096,0.0251250759095564,235.772541408945,150.0,8.333333333333333e-05,0.67,0.28,0.23,0.05,0.9,0.05,0.03,0.02
302.57886231436413,0.0253046893167775,235.825200752483,150.0,8.333333333333333e-05,0.67,0.28,0.23,0.05,0.9,0.05,0.03,0.02
304.8027031944958,0.0254900093901218,235.87359247443,150.0,8.333333333333333e-05,0.67,0.28,0.23,0.05,0.9,0.05,0.03,0.02
307.0732135054185,0.0256792185826987,235.924197136977,150.0,8.333333333333333e-05,0.67,0.28,0.23,0.05,0.9,0.05,0.03,0.02
309.3077209418637,0.0258654275357358,235.967648408187,150.0,8.333333333333333e-05,0.67,0.28,0.23,0.05,0.9,0.05,0.03,0.02
311.535767372479,0.0260510980716204,235.988679108691,150.0,8.333333333333333e-05,0.67,0.28,0.23,0.05,0.9,0.05,0.03,0.02
313.85405160774934,0.0262442884245596,236.015067563278,150.0,8.333333333333333e-05,0.67,0.28,0.23,0.05,0.9,0.05,0.03,0.02
316.19775301201776,0.0264395968749153,236.048708925608,150.0,8.333333333333333e-05,0.67,0.28,0.23,0.05,0.9,0.05,0.03,0.02
318.4643965879761,0.0266284838395785,236.063780558411,150.0,8.333333333333333e-05,0.67,0.28,0.23,0.05,0.9,0.05,0.03,0.02
320.806722325483,0.0268236776510374,236.091655055982,150.0,8.333333333333333e-05,0.67,0.28,0.23,0.05,0.9,0.05,0.03,0.02
323.1164441667706,0.0270161544711447,236.118786936149,150.0,8.333333333333333e-05,0.67,0.28,0.23,0.05,0.9,0.05,0.03,0.02
325.44848644477537,0.0272104913276451,236.154427801742,150.0,8.333333333333333e-05,0.67,0.28,0.23,0.05,0.9,0.05,0.03,0.02
327.72974990189016,0.027400596615738,236.186544154394,150.0,8.333333333333333e-05,0.67,0.28,0.23,0.05,0.9,0.05,0.03,0.02
329.99303677953696,0.0275892038555419,236.200346002237,150.0,8.333333333333333e-05,0.67,0.28,0.23,0.05,0.9,0.05,0.03,0.02
332.1701460865113,0.0277706296311231,236.201392746846,150.0,8.333333333333333e-05,0.67,0.28,0.23,0.05,0.9,0.05,0.03,0.02
334.47398364883657,0.0279626160946502,236.200678399707,150.0,8.333333333333333e-05,0.67,0.28,0.23,0.05,0.9,0.05,0.03,0.02
336.7122184962297,0.0281491356652663,236.201804044346,150.0,8.333333333333333e-05,0.67,0.28,0.23,0.05,0.9,0.05,0.03,0.02
338.98901839516657,0.0283388689901777,236.205745068306,150.0,8.333333333333333e-05,0.67,0.28,0.23,0.05,0.9,0.05,0.03,0.02
341.2125932081253,0.0285241668912576,236.180867646729,150.0,8.333333333333333e-05,0.67,0.28,0.23,0.05,0.9,0.05,0.03,0.02
343.50069076952855,0.0287148416880412,236.1741414153,150.0,8.333333333333333e-05,0.67,0.28,0.23,0.05,0.9,0.05,0.03,0.02
345.72542891132133,0.0289002365331906,236.196039699191,150.0,8.333333333333333e-05,0.67,0.28,0.23,0.05,0.9,0.05,0.03,0.02
348.11395847545657,0.0290992806635352,236.226878739766,150.0,8.333333333333333e-05,0.67,0.28,0.23,0.05,0.9,0.05,0.03,0.02
350.35341873465575,0.0292859023518018,236.27401216551,150.0,8.333333333333333e-05,0.67,0.28,0.23,0.05,0.9,0.05,0.03,0.02
352.62449699399855,0.0294751588734137,236.301438886797,150.0,8.333333333333333e-05,0.67,0.28,0.23,0.05,0.9,0.05,0.03,0.02
354.8932177306726,0.0296642189348032,236.328046277476,150.0,8.333333333333333e-05,0.67,0.28,0.23,0.05,0.9,0.05,0.03,0.02
357.28676768262216,0.029863681430799,236.428942379438,150.0,8.333333333333333e-05,0.67,0.28,0.23,0.05,0.9,0.05,0.03,0.02
359.6121196195522,0.0300574607588765,236.515915312283,150.0,8.333333333333333e-05,0.67,0.28,0.23,0.05,0.9,0.05,0.03,0.02
361.9846957076614,0.0302551754328856,236.581513183,150.0,8.333333333333333e-05,0.67,0.28,0.23,0.05,0.9,0.05,0.03,0.02
364.25000900374295,0.0304439515408924,236.631970900383,150.0,8.333333333333333e-05,0.67,0.28,0.23,0.05,0.9,0.05,0.03,0.02
366.6822283588365,0.0306466364871502,236.669642724665,150.0,8.333333333333333e-05,0.67,0.28,0.23,0.05,0.9,0.05,0.03,0.02
369.10830668476297,0.0308488096809774,236.69368102328,150.0,8.333333333333333e-05,0.67,0.28,0.23,0.05,0.9,0.05,0.03,0.02
371.5219727139549,0.0310499485167434,236.703713164337,150.0,8.333333333333333e-05,0.67,0.28,0.23,0.05,0.9,0.05,0.03,0.02
373.8332731860573,0.0312425568894186,236.641971617709,150.0,8.333333333333333e-05,0.67,0.28,0.23,0.05,0.9,0.05,0.03,0.02
376.141935770359,0.0314349454381104,236.563745955033,150.0,8.333333333333333e-05,0.67,0.28,0.23,0.05,0.9,0.05,0.03,0.02
378.3828619320921,0.0316216892849215,236.479958529643,150.0,8.333333333333333e-05,0.67,0.28,0.23,0.05,0.9,0.05,0.03,0.02
380.5636672744858,0.0318034230634543,236.420191496252,150.0,8.333333333333333e-05,0.67,0.28,0.23,0.05,0.9,0.05,0.03,0.02
382.71977302677817,0.031983098542812,236.38020756359,150.0,8.333333333333333e-05,0.67,0.28,0.23,0.05,0.9,0.05,0.03,0.02
384.8657435447241,0.0321619294193075,236.353996400331,150.0,8.333333333333333e-05,0.67,0.28,0.23,0.05,0.9,0.05,0.03,0.02
387.0576842205682,0.0323445911422945,236.331883427227,150.0,8.333333333333333e-05,0.67,0.28,0.23,0.05,0.9,0.05,0.03,0.02
389.2785996548361,0.0325296674284835,236.348711730588,150.0,8.333333333333333e-05,0.67,0.28,0.23,0.05,0.9,0.05,0.03,0.02
391.494767454253,0.0327143480784349,236.389932122891,150.0,8.333333333333333e-05,0.67,0.28,0.23,0.05,0.9,0.05,0.03,0.02
393.71311711924056,0.0328992105505172,236.418773054699,150.0,8.333333333333333e-05,0.67,0.28,0.23,0.05,0.9,0.05,0.03,0.02
396.017483822587,0.0330912411091294,236.464852810886,150.0,8.333333333333333e-05,0.67,0.28,0.23,0.05,0.9,0.05,0.03,0.02
398.3404343688526,0.0332848203213182,236.497094256293,150.0,8.333333333333333e-05,0.67,0.28,0.23,0.05,0.9,0.05,0.03,0.02
400.6775901449793,0.0334795833026621,236.538905598563,150.0,8.333333333333333e-05,0.67,0.28,0.23,0.05,0.9,0.05,0.03,0.02
402.98030226460656,0.0336714759792977,236.57324840893,150.0,8.333333333333333e-05,0.67,0.28,0.23,0.05,0.9,0.05,0.03,0.02
405.27419155129775,0.0338626334198553,236.601485491672,150.0,8.333333333333333e-05,0.67,0.28,0.23,0.05,0.9,0.05,0.03,0.02
407.63909751789697,0.0340597089170719,236.629977513892,150.0,8.333333333333333e-05,0.67,0.28,0.23,0.05,0.9,0.05,0.03,0.02
409.94908089931056,0.0342522075321897,236.66882103292,150.0,8.333333333333333e-05,0.67,0.28,0.23,0.05,0.9,0.05,0.03,0.02
412.31466564306817,0.0344493395941695,236.686037862272,150.0,8.333333333333333e-05,0.67,0.28,0.23,0.05,0.9,0.05,0.03,0.02
414.5935423974345,0.0346392459903667,236.692967151538,150.0,8.333333333333333e-05,0.67,0.28,0.23,0.05,0.9,0.05,0.03,0.02
416.9058263873842,0.0348319363228625,236.687486174593,150.0,8.333333333333333e-05,0.67,0.28,0.23,0.05,0.9,0.05,0.03,0.02
419.2082953561618,0.0350238087369273,236.693334142052,150.0,8.333333333333333e-05,0.67,0.28,0.23,0.05,0.9,0.05,0.03,0.02
421.4002667511334,0.0352064730198416,236.676358418131,150.0,8.333333333333333e-05,0.67,0.28,0.23,0.05,0.9,0.05,0.03,0.02
423.7028135143594,0.0353983519167771,236.641459694545,150.0,8.333333333333333e-05,0.67,0.28,0.23,0.05,0.9,0.05,0.03,0.02
426.040918804813,0.0355931940243149,236.626285597876,150.0,8.333333333333333e-05,0.67,0.28,0.23,0.05,0.9,0.05,0.03,0.02
428.3253542370862,0.035783563643671,236.61294331616,150.0,8.333333333333333e-05,0.67,0.28,0.23,0.05,0.9,0.05,0.03,0.02
430.65019903717774,0.0359773007103453,236.62109366221,150.0,8.333333333333333e-05,0.67,0.28,0.23,0.05,0.9,0.05,0.03,0.02
432.99002254479456,0.0361722860026467,236.605563112991,150.0,8.333333333333333e-05,0.67,0.28,0.23,0.05,0.9,0.05,0.03,0.02
435.297747294865,0.0363645963984859,236.605811745538,150.0,8.333333333333333e-05,0.67,0.28,0.23,0.05,0.9,0.05,0.03,0.02
437.65618141060656,0.0365611325747977,236.617309471668,150.0,8.333333333333333e-05,0.67,0.28,0.23,0.05,0.9,0.05,0.03,0.02
439.933068212953,0.0367508731416599,236.642594609422,150.0,8.333333333333333e-05,0.67,0.28,0.23,0.05,0.9,0.05,0.03,0.02
442.3530974906998,0.0369525422481388,236.668737886013,150.0,8.333333333333333e-05,0.67,0.28,0.23,0.05,0.9,0.05,0.03,0.02
444.732634448995,0.0371508369946634,236.684189693669,150.0,8.333333333333333e-05,0.67,0.28,0.23,0.05,0.9,0.05,0.03,0.02
447.1185457487542,0.03734966293631,236.682054385374,150.0,8.333333333333333e-05,0.67,0.28,0.23,0.05,0.9,0.05,0.03,0.02
449.4386010925726,0.0375430008816282,236.709124178713,150.0,8.333333333333333e-05,0.67,0.28,0.23,0.05,0.9,0.05,0.03,0.02
451.76460907058737,0.0377368348797961,236.710090771416,150.0,8.333333333333333e-05,0.67,0.28,0.23,0.05,0.9,0.05,0.03,0.02
454.22042461396654,0.0379414861750777,236.711571315642,150.0,8.333333333333333e-05,0.67,0.28,0.23,0.05,0.9,0.05,0.03,0.02
456.6429641438866,0.0381433644692377,236.712298530189,150.0,8.333333333333333e-05,0.67,0.28,0.23,0.05,0.9,0.05,0.03,0.02