File: datasets/al_6061_comp/csv/T_150_I_1.csv
Time,Strain(%),Stress(MPa),Temp(C),SR(%/s),Si(%),Fe(%),Cu(%),Mn(%),Mg(%),Cr(%),Zn(%),Ti(%)
0.0,9.25278994534876e-05,46.0376817645766,150.0,8.333333333333333e-05,0.68,0.23,0.2,0.04,0.87,0.05,0.02,0.02
0.1561724705413487,0.0001055422719986,46.7305603307497,150.0,8.333333333333333e-05,0.68,0.23,0.2,0.04,0.87,0.05,0.02,0.02
0.3190700831233488,0.0001191170730471,47.4476771205292,150.0,8.333333333333333e-05,0.68,0.23,0.2,0.04,0.87,0.05,0.02,0.02
0.4886590327393487,0.0001332494855151,48.1346368374562,150.0,8.333333333333333e-05,0.68,0.23,0.2,0.04,0.87,0.05,0.02,0.02
0.6213742186669489,0.0001443090843424,48.8287385438016,150.0,8.333333333333333e-05,0.68,0.23,0.2,0.04,0.87,0.05,0.02,0.02
0.7824488718457487,0.0001577319721073,49.5499085208601,150.0,8.333333333333333e-05,0.68,0.23,0.2,0.04,0.87,0.05,0.02,0.02
0.9141353169421488,0.000168705842532,50.2976164741647,150.0,8.333333333333333e-05,0.68,0.23,0.2,0.04,0.87,0.05,0.02,0.02
1.1007661671241489,0.0001842584133805,51.02214048666,150.0,8.333333333333333e-05,0.68,0.23,0.2,0.04,0.87,0.05,0.02,0.02
1.2558503953633489,0.0001971820990671,51.701980559487,150.0,8.333333333333333e-05,0.68,0.23,0.2,0.04,0.87,0.05,0.02,0.02
1.404755031566549,0.0002095908187507,52.3522396555721,150.0,8.333333333333333e-05,0.68,0.23,0.2,0.04,0.87,0.05,0.02,0.02
1.4781634882789487,0.0002157081901434,53.0313932670705,150.0,8.333333333333333e-05,0.68,0.23,0.2,0.04,0.87,0.05,0.02,0.02
1.6730507162869488,0.0002319487924774,53.7373336264351,150.0,8.333333333333333e-05,0.68,0.23,0.2,0.04,0.87,0.05,0.02,0.02
1.8346200311941487,0.000245412902053,54.4638421786178,150.0,8.333333333333333e-05,0.68,0.23,0.2,0.04,0.87,0.05,0.02,0.02
1.8986384603881483,0.0002507477711525,55.1653498714884,150.0,8.333333333333333e-05,0.68,0.23,0.2,0.04,0.87,0.05,0.02,0.02
1.9794821975389487,0.0002574847492484,55.8605865572748,150.0,8.333333333333333e-05,0.68,0.23,0.2,0.04,0.87,0.05,0.02,0.02
2.090205633493349,0.0002667117022446,56.5727366305776,150.0,8.333333333333333e-05,0.68,0.23,0.2,0.04,0.87,0.05,0.02,0.02
2.273242268919749,0.0002819647551968,57.3096753922027,150.0,8.333333333333333e-05,0.68,0.23,0.2,0.04,0.87,0.05,0.02,0.02
2.447754122418149,0.000296507409655,58.0406049687808,150.0,8.333333333333333e-05,0.68,0.23,0.2,0.04,0.87,0.05,0.02,0.02
2.6590776493873487,0.0003141177035691,58.7683011089204,150.0,8.333333333333333e-05,0.68,0.23,0.2,0.04,0.87,0.05,0.02,0.02
2.8531905275353484,0.0003302937767481,59.4573937397016,150.0,8.333333333333333e-05,0.68,0.23,0.2,0.04,0.87,0.05,0.02,0.02
3.114213517606949,0.0003520456925874,60.1606356358413,150.0,8.333333333333333e-05,0.68,0.23,0.2,0.04,0.87,0.05,0.02,0.02
3.388283631375749,0.0003748848687348,60.8889167288495,150.0,8.333333333333333e-05,0.68,0.23,0.2,0.04,0.87,0.05,0.02,0.02
3.605666162110949,0.0003930000796294,61.607913279428,150.0,8.333333333333333e-05,0.68,0.23,0.2,0.04,0.87,0.05,0.02,0.02
3.803968109224949,0.0004095252418889,62.3198144089829,150.0,8.333333333333333e-05,0.68,0.23,0.2,0.04,0.87,0.05,0.02,0.02
3.998894785480948,0.0004257691315769,63.0300893532894,150.0,8.333333333333333e-05,0.68,0.23,0.2,0.04,0.87,0.05,0.02,0.02
4.19904361614735,0.0004424482007991,63.7133124729121,150.0,8.333333333333333e-05,0.68,0.23,0.2,0.04,0.87,0.05,0.02,0.02
4.361102939409749,0.0004559531444043,64.4063498191601,150.0,8.333333333333333e-05,0.68,0.23,0.2,0.04,0.87,0.05,0.02,0.02
4.460668017205348,0.0004642502342206,65.0799376468334,150.0,8.333333333333333e-05,0.68,0.23,0.2,0.04,0.87,0.05,0.02,0.02
4.583559196002149,0.000474491165787,65.7547195876721,150.0,8.333333333333333e-05,0.68,0.23,0.2,0.04,0.87,0.05,0.02,0.02
4.7254830880873495,0.0004863181567941,66.4436276817998,150.0,8.333333333333333e-05,0.68,0.23,0.2,0.04,0.87,0.05,0.02,0.02
4.86489632313735,0.0004979359263816,67.1163397232085,150.0,8.333333333333333e-05,0.68,0.23,0.2,0.04,0.87,0.05,0.02,0.02
5.080636111684948,0.0005159142420939,67.7787416690857,150.0,8.333333333333333e-05,0.68,0.23,0.2,0.04,0.87,0.05,0.02,0.02
5.208725067513749,0.0005265883217463,68.4518365853215,150.0,8.333333333333333e-05,0.68,0.23,0.2,0.04,0.87,0.05,0.02,0.02
5.368376623870949,0.0005398926181094,69.1179294833391,150.0,8.333333333333333e-05,0.68,0.23,0.2,0.04,0.87,0.05,0.02,0.02
5.526086447275349,0.0005530351033931,69.7895427077936,150.0,8.333333333333333e-05,0.68,0.23,0.2,0.04,0.87,0.05,0.02,0.02
5.712320174689348,0.0005685545806776,70.4499242488082,150.0,8.333333333333333e-05,0.68,0.23,0.2,0.04,0.87,0.05,0.02,0.02
5.898849558278549,0.0005840986959767,71.1250249703392,150.0,8.333333333333333e-05,0.68,0.23,0.2,0.04,0.87,0.05,0.02,0.02
6.092384186782949,0.0006002265816854,71.8244388536631,150.0,8.333333333333333e-05,0.68,0.23,0.2,0.04,0.87,0.05,0.02,0.02
6.230620642256548,0.0006117462863082,72.519410306152,150.0,8.333333333333333e-05,0.68,0.23,0.2,0.04,0.87,0.05,0.02,0.02
6.399563190354149,0.000625824831983,73.1893149274361,150.0,8.333333333333333e-05,0.68,0.23,0.2,0.04,0.87,0.05,0.02,0.02
6.498235458730949,0.0006340475210144,73.8803990769048,150.0,8.333333333333333e-05,0.68,0.23,0.2,0.04,0.87,0.05,0.02,0.02
6.708342398737349,0.0006515564326816,74.5689073650887,150.0,8.333333333333333e-05,0.68,0.23,0.2,0.04,0.87,0.05,0.02,0.02
6.790583289561749,0.0006584098402503,75.2451916373972,150.0,8.333333333333333e-05,0.68,0.23,0.2,0.04,0.87,0.05,0.02,0.02
6.9632181890809495,0.0006727960818769,75.9298579547651,150.0,8.333333333333333e-05,0.68,0.23,0.2,0.04,0.87,0.05,0.02,0.02
7.065313737202949,0.0006813040442204,76.6169975452468,150.0,8.333333333333333e-05,0.68,0.23,0.2,0.04,0.87,0.05,0.02,0.02
7.262149783040549,0.0006977070480402,77.2959687951612,150.0,8.333333333333333e-05,0.68,0.23,0.2,0.04,0.87,0.05,0.02,0.02
7.388810888848949,0.0007082621401909,77.9699576649689,150.0,8.333333333333333e-05,0.68,0.23,0.2,0.04,0.87,0.05,0.02,0.02
7.62637380715935,0.0007280590500501,78.6439884400728,150.0,8.333333333333333e-05,0.68,0.23,0.2,0.04,0.87,0.05,0.02,0.02
7.79581701611175,0.0007421793174628,79.3164530868837,150.0,8.333333333333333e-05,0.68,0.23,0.2,0.04,0.87,0.05,0.02,0.02
8.05669384785255,0.0007639190534412,79.9958750456279,150.0,8.333333333333333e-05,0.68,0.23,0.2,0.04,0.87,0.05,0.02,0.02
8.24048999375175,0.0007792353989328,80.648657222354,150.0,8.333333333333333e-05,0.68,0.23,0.2,0.04,0.87,0.05,0.02,0.02
8.46219329530815,0.0007977106740625,81.272637691849,150.0,8.333333333333333e-05,0.68,0.23,0.2,0.04,0.87,0.05,0.02,0.02
8.57444694015495,0.0008070651444664,81.9185954080104,150.0,8.333333333333333e-05,0.68,0.23,0.2,0.04,0.87,0.05,0.02,0.02
8.76147831565935,0.0008226510924251,82.6024368263516,150.0,8.333333333333333e-05,0.68,0.23,0.2,0.04,0.87,0.05,0.02,0.02
8.86391325372135,0.0008311873372636,83.2533168813122,150.0,8.333333333333333e-05,0.68,0.23,0.2,0.04,0.87,0.05,0.02,0.02
8.94414106275975,0.0008378729880168,83.8905973845269,150.0,8.333333333333333e-05,0.68,0.23,0.2,0.04,0.87,0.05,0.02,0.02
9.07484892662775,0.0008487653100058,84.5344544686212,150.0,8.333333333333333e-05,0.68,0.23,0.2,0.04,0.87,0.05,0.02,0.02
9.24584763515415,0.000863015202383,85.2066812035116,150.0,8.333333333333333e-05,0.68,0.23,0.2,0.04,0.87,0.05,0.02,0.02
9.408185832744149,0.0008765433855155,85.8635341245527,150.0,8.333333333333333e-05,0.68,0.23,0.2,0.04,0.87,0.05,0.02,0.02
9.67439452305975,0.0008987274430418,86.5159072004337,150.0,8.333333333333333e-05,0.68,0.23,0.2,0.04,0.87,0.05,0.02,0.02
9.92056807841295,0.0009192419059879,87.1439264454162,150.0,8.333333333333333e-05,0.68,0.23,0.2,0.04,0.87,0.05,0.02,0.02
10.15467745866255,0.0009387510210087,87.7742611066686,150.0,8.333333333333333e-05,0.68,0.23,0.2,0.04,0.87,0.05,0.02,0.02
10.39292624247615,0.0009586050863265,88.4287014374707,150.0,8.333333333333333e-05,0.68,0.23,0.2,0.04,0.87,0.05,0.02,0.02
10.644652350345748,0.0009795822619823,89.0993086531531,150.0,8.333333333333333e-05,0.68,0.23,0.2,0.04,0.87,0.05,0.02,0.02
10.798798582476149,0.0009924277813265,89.730802344795,150.0,8.333333333333333e-05,0.68,0.23,0.2,0.04,0.87,0.05,0.02,0.02
10.98175350475575,0.0010076740248498,90.368069484633,150.0,8.333333333333333e-05,0.68,0.23,0.2,0.04,0.87,0.05,0.02,0.02
11.042897337472947,0.0010127693442429,90.9918303503466,150.0,8.333333333333333e-05,0.68,0.23,0.2,0.04,0.87,0.05,0.02,0.02
11.116624821452548,0.0010189133012412,91.6499028281721,150.0,8.333333333333333e-05,0.68,0.23,0.2,0.04,0.87,0.05,0.02,0.02
11.243115743283749,0.0010294542113938,92.3278986454715,150.0,8.333333333333333e-05,0.68,0.23,0.2,0.04,0.87,0.05,0.02,0.02
11.43446393961255,0.0010453998944212,92.9717169382182,150.0,8.333333333333333e-05,0.68,0.23,0.2,0.04,0.87,0.05,0.02,0.02
11.54497593522375,0.0010546092273888,93.5804317840124,150.0,8.333333333333333e-05,0.68,0.23,0.2,0.04,0.87,0.05,0.02,0.02
11.74168422651735,0.0010710015849966,94.2031183531599,150.0,8.333333333333333e-05,0.68,0.23,0.2,0.04,0.87,0.05,0.02,0.02
11.98578914759415,0.001091343661753,94.8778782616398,150.0,8.333333333333333e-05,0.68,0.23,0.2,0.04,0.87,0.05,0.02,0.02
12.196743892608149,0.0011089232238375,95.5516245407803,150.0,8.333333333333333e-05,0.68,0.23,0.2,0.04,0.87,0.05,0.02,0.02
12.362144085694949,0.0011227065732614,96.1874487958327,150.0,8.333333333333333e-05,0.68,0.23,0.2,0.04,0.87,0.05,0.02,0.02
12.62666832915015,0.001144750260216,96.8068542804362,150.0,8.333333333333333e-05,0.68,0.23,0.2,0.04,0.87,0.05,0.02,0.02
12.766290580658548,0.0011563854478417,97.4331323275015,150.0,8.333333333333333e-05,0.68,0.23,0.2,0.04,0.87,0.05,0.02,0.02
12.96389293321095,0.0011728523105544,98.0864092777751,150.0,8.333333333333333e-05,0.68,0.23,0.2,0.04,0.87,0.05,0.02,0.02
13.116941554744953,0.0011856063623489,98.7226960245877,150.0,8.333333333333333e-05,0.68,0.23,0.2,0.04,0.87,0.05,0.02,0.02
13.19577882729975,0.0011921761350618,99.3182964530266,150.0,8.333333333333333e-05,0.68,0.23,0.2,0.04,0.87,0.05,0.02,0.02
13.345235361738151,0.001204630846265,99.9231289718589,150.0,8.333333333333333e-05,0.68,0.23,0.2,0.04,0.87,0.05,0.02,0.02
13.51481543627415,0.001218762519143,100.529959378107,150.0,8.333333333333333e-05,0.68,0.23,0.2,0.04,0.87,0.05,0.02,0.02
13.61045034136815,0.0012267320945675,101.138911212591,150.0,8.333333333333333e-05,0.68,0.23,0.2,0.04,0.87,0.05,0.02,0.02
13.79104284010935,0.0012417814694626,101.736277828775,150.0,8.333333333333333e-05,0.68,0.23,0.2,0.04,0.87,0.05,0.02,0.02
13.97092336566735,0.0012567715132591,102.302200920198,150.0,8.333333333333333e-05,0.68,0.23,0.2,0.04,0.87,0.05,0.02,0.02
14.08946466274215,0.001266649954682,102.876431087198,150.0,8.333333333333333e-05,0.68,0.23,0.2,0.04,0.87,0.05,0.02,0.02
14.28363113983695,0.0012828304944399,103.423493024175,150.0,8.333333333333333e-05,0.68,0.23,0.2,0.04,0.87,0.05,0.02,0.02
14.478316585418549,0.0012990542815717,103.973825029516,150.0,8.333333333333333e-05,0.68,0.23,0.2,0.04,0.87,0.05,0.02,0.02
14.608494117306147,0.001309902409229,104.567939103075,150.0,8.333333333333333e-05,0.68,0.23,0.2,0.04,0.87,0.05,0.02,0.02
14.72058614879175,0.0013192434118528,105.161522553559,150.0,8.333333333333333e-05,0.68,0.23,0.2,0.04,0.87,0.05,0.02,0.02
14.878994634763348,0.0013324441190171,105.770498126032,150.0,8.333333333333333e-05,0.68,0.23,0.2,0.04,0.87,0.05,0.02,0.02
14.98262487807975,0.0013410799726268,106.385963855579,150.0,8.333333333333333e-05,0.68,0.23,0.2,0.04,0.87,0.05,0.02,0.02
15.19314821971815,0.00135862358443,107.01136580342,150.0,8.333333333333333e-05,0.68,0.23,0.2,0.04,0.87,0.05,0.02,0.02
15.39553648870455,0.0013754892735122,107.642705080774,150.0,8.333333333333333e-05,0.68,0.23,0.2,0.04,0.87,0.05,0.02,0.02
15.583263070980152,0.0013911331553685,108.244475179965,150.0,8.333333333333333e-05,0.68,0.23,0.2,0.04,0.87,0.05,0.02,0.02
15.802629631696949,0.0014094137020949,108.80336771125,150.0,8.333333333333333e-05,0.68,0.23,0.2,0.04,0.87,0.05,0.02,0.02
15.992338570777347,0.0014252227803516,109.361630286071,150.0,8.333333333333333e-05,0.68,0.23,0.2,0.04,0.87,0.05,0.02,0.02
16.167609533506948,0.0014398286939124,109.920675995453,150.0,8.333333333333333e-05,0.68,0.23,0.2,0.04,0.87,0.05,0.02,0.02
16.39445868901215,0.0014587327902045,110.497096504402,150.0,8.333333333333333e-05,0.68,0.23,0.2,0.04,0.87,0.05,0.02,0.02
16.615861096814548,0.0014771829908547,111.058009737861,150.0,8.333333333333333e-05,0.68,0.23,0.2,0.04,0.87,0.05,0.02,0.02
16.78346050883895,0.0014911496085234,111.649949790317,150.0,8.333333333333333e-05,0.68,0.23,0.2,0.04,0.87,0.05,0.02,0.02
16.95898452171735,0.0015057766095966,112.245511896847,150.0,8.333333333333333e-05,0.68,0.23,0.2,0.04,0.87,0.05,0.02,0.02
17.175805938304947,0.0015238450609789,112.835849345564,150.0,8.333333333333333e-05,0.68,0.23,0.2,0.04,0.87,0.05,0.02,0.02
17.358702136098152,0.001539086410795,113.43674350201,150.0,8.333333333333333e-05,0.68,0.23,0.2,0.04,0.87,0.05,0.02,0.02
17.56374123870375,0.0015561730026788,114.022674197291,150.0,8.333333333333333e-05,0.68,0.23,0.2,0.04,0.87,0.05,0.02,0.02
17.71927905750495,0.0015691344875789,114.615251028732,150.0,8.333333333333333e-05,0.68,0.23,0.2,0.04,0.87,0.05,0.02,0.02
17.80785126540375,0.0015765155049038,115.188989364005,150.0,8.333333333333333e-05,0.68,0.23,0.2,0.04,0.87,0.05,0.02,0.02
17.873188679907752,0.0015819602894458,115.724916932343,150.0,8.333333333333333e-05,0.68,0.23,0.2,0.04,0.87,0.05,0.02,0.02
18.06814532775255,0.0015982066767662,116.267110077915,150.0,8.333333333333333e-05,0.68,0.23,0.2,0.04,0.87,0.05,0.02,0.02
17.993358910650148,0.001591974475341,116.828606089174,150.0,8.333333333333333e-05,0.68,0.23,0.2,0.04,0.87,0.05,0.02,0.02
18.15501157240335,0.0016054455304871,117.38588701913,150.0,8.333333333333333e-05,0.68,0.23,0.2,0.04,0.87,0.05,0.02,0.02
18.22862030687175,0.0016115795916928,117.993357318313,150.0,8.333333333333333e-05,0.68,0.23,0.2,0.04,0.87,0.05,0.02,0.02
18.29654681997375,0.0016172401344513,118.564142347324,150.0,8.333333333333333e-05,0.68,0.23,0.2,0.04,0.87,0.05,0.02,0.02
18.46075530800895,0.0016309241751209,119.132414075683,150.0,8.333333333333333e-05,0.68,0.23,0.2,0.04,0.87,0.05,0.02,0.02
18.85142903440575,0.0016634803189873,119.71389022859,150.0,8.333333333333333e-05,0.68,0.23,0.2,0.04,0.87,0.05,0.02,0.02
18.932554132866148,0.001670240743859,120.305539588482,150.0,8.333333333333333e-05,0.68,0.23,0.2,0.04,0.87,0.05,0.02,0.02
19.30352173201455,0.0017011547104547,120.882438424948,150.0,8.333333333333333e-05,0.68,0.23,0.2,0.04,0.87,0.05,0.02,0.02
19.543381949516547,0.0017211430619132,121.445823053764,150.0,8.333333333333333e-05,0.68,0.23,0.2,0.04,0.87,0.05,0.02,0.02
19.74118593710055,0.0017376267275452,121.970248291163,150.0,8.333333333333333e-05,0.68,0.23,0.2,0.04,0.87,0.05,0.02,0.02
19.99406296088895,0.0017586998128609,122.519354370991,150.0,8.333333333333333e-05,0.68,0.23,0.2,0.04,0.87,0.05,0.02,0.02
20.14083070974135,0.0017709304585986,123.077686313316,150.0,8.333333333333333e-05,0.68,0.23,0.2,0.04,0.87,0.05,0.02,0.02
20.09489950638375,0.0017671028583188,123.644779451308,150.0,8.333333333333333e-05,0.68,0.23,0.2,0.04,0.87,0.05,0.02,0.02
20.22458569201815,0.001777910040455,124.204017145784,150.0,8.333333333333333e-05,0.68,0.23,0.2,0.04,0.87,0.05,0.02,0.02
20.31583216276575,0.0017855139130173,124.751607061326,150.0,8.333333333333333e-05,0.68,0.23,0.2,0.04,0.87,0.05,0.02,0.02
20.41635722059215,0.0017938910011695,125.296011360664,150.0,8.333333333333333e-05,0.68,0.23,0.2,0.04,0.87,0.05,0.02,0.02
20.57362854272775,0.0018069969446808,125.844560262792,150.0,8.333333333333333e-05,0.68,0.23,0.2,0.04,0.87,0.05,0.02,0.02
20.66716804706775,0.0018147919033758,126.368221925606,150.0,8.333333333333333e-05,0.68,0.23,0.2,0.04,0.87,0.05,0.02,0.02
20.858775132730948,0.0018307591605144,126.889327130634,150.0,8.333333333333333e-05,0.68,0.23,0.2,0.04,0.87,0.05,0.02,0.02
20.95472604783735,0.0018387550701066,127.397949909009,150.0,8.333333333333333e-05,0.68,0.23,0.2,0.04,0.87,0.05,0.02,0.02
21.129856722333752,0.0018533492929813,127.904707948647,150.0,8.333333333333333e-05,0.68,0.23,0.2,0.04,0.87,0.05,0.02,0.02
21.36232105762695,0.0018727213209224,128.438244677442,150.0,8.333333333333333e-05,0.68,0.23,0.2,0.04,0.87,0.05,0.02,0.02
21.55044292495935,0.0018883981432001,128.979698612338,150.0,8.333333333333333e-05,0.68,0.23,0.2,0.04,0.87,0.05,0.02,0.02
21.79248911647695,0.0019085686591599,129.522081740062,150.0,8.333333333333333e-05,0.68,0.23,0.2,0.04,0.87,0.05,0.02,0.02
21.985274534046148,0.001924634110624,130.128925478391,150.0,8.333333333333333e-05,0.68,0.23,0.2,0.04,0.87,0.05,0.02,0.02
22.202089171834952,0.0019427019971064,130.737186970846,150.0,8.333333333333333e-05,0.68,0.23,0.2,0.04,0.87,0.05,0.02,0.02
22.42907744319855,0.0019616176863867,131.336132890924,150.0,8.333333333333333e-05,0.68,0.23,0.2,0.04,0.87,0.05,0.02,0.02
22.689225940258957,0.0019832967278084,131.95435094405,150.0,8.333333333333333e-05,0.68,0.23,0.2,0.04,0.87,0.05,0.02,0.02
22.80126378984975,0.0019926332152743,132.540371505692,150.0,8.333333333333333e-05,0.68,0.23,0.2,0.04,0.87,0.05,0.02,0.02
22.92513715007775,0.0020029559952933,133.113992512395,150.0,8.333333333333333e-05,0.68,0.23,0.2,0.04,0.87,0.05,0.02,0.02
22.99146681499815,0.00200848346737,133.69000500021,150.0,8.333333333333333e-05,0.68,0.23,0.2,0.04,0.87,0.05,0.02,0.02
23.116466807977357,0.0020189001334516,134.224770142546,150.0,8.333333333333333e-05,0.68,0.23,0.2,0.04,0.87,0.05,0.02,0.02
23.17041670619535,0.0020233959583031,134.758887787029,150.0,8.333333333333333e-05,0.68,0.23,0.2,0.04,0.87,0.05,0.02,0.02
23.347276756746147,0.002038134295849,135.286060544077,150.0,8.333333333333333e-05,0.68,0.23,0.2,0.04,0.87,0.05,0.02,0.02
23.434615107782548,0.0020454124917687,135.794521741389,150.0,8.333333333333333e-05,0.68,0.23,0.2,0.04,0.87,0.05,0.02,0.02
23.56230342571215,0.0020560531849295,136.337261517922,150.0,8.333333333333333e-05,0.68,0.23,0.2,0.04,0.87,0.05,0.02,0.02
23.747920614530557,0.0020715212839977,136.910855218896,150.0,8.333333333333333e-05,0.68,0.23,0.2,0.04,0.87,0.05,0.02,0.02
23.96256141585495,0.0020894080174414,137.482306069547,150.0,8.333333333333333e-05,0.68,0.23,0.2,0.04,0.87,0.05,0.02,0.02
24.22036562289015,0.002110891701361,138.029027177825,150.0,8.333333333333333e-05,0.68,0.23,0.2,0.04,0.87,0.05,0.02,0.02
24.46317722493015,0.002131126001531,138.569193268142,150.0,8.333333333333333e-05,0.68,0.23,0.2,0.04,0.87,0.05,0.02,0.02
24.675925379665347,0.0021488550144256,139.140081511244,150.0,8.333333333333333e-05,0.68,0.23,0.2,0.04,0.87,0.05,0.02,0.02
24.85398631155255,0.0021636934254162,139.706452823467,150.0,8.333333333333333e-05,0.68,0.23,0.2,0.04,0.87,0.05,0.02,0.02
25.120077399022957,0.0021858676827054,140.250359078829,150.0,8.333333333333333e-05,0.68,0.23,0.2,0.04,0.87,0.05,0.02,0.02
25.28984641771455,0.0022000151009297,140.764329116958,150.0,8.333333333333333e-05,0.68,0.23,0.2,0.04,0.87,0.05,0.02,0.02
25.40485857773415,0.002209599447598,141.276467011098,150.0,8.333333333333333e-05,0.68,0.23,0.2,0.04,0.87,0.05,0.02,0.02
25.50744013228695,0.0022181479104774,141.808985776062,150.0,8.333333333333333e-05,0.68,0.23,0.2,0.04,0.87,0.05,0.02,0.02
25.63284969927855,0.0022285987077267,142.352365586361,150.0,8.333333333333333e-05,0.68,0.23,0.2,0.04,0.87,0.05,0.02,0.02
25.777339741227756,0.0022406395445558,142.894022366049,150.0,8.333333333333333e-05,0.68,0.23,0.2,0.04,0.87,0.05,0.02,0.02
25.918608345698548,0.0022524119282617,143.43620823531,150.0,8.333333333333333e-05,0.68,0.23,0.2,0.04,0.87,0.05,0.02,0.02
26.026063191434552,0.0022613664987397,144.000899501931,150.0,8.333333333333333e-05,0.68,0.23,0.2,0.04,0.87,0.05,0.02,0.02
26.14077434536215,0.002270925761567,144.574762614213,150.0,8.333333333333333e-05,0.68,0.23,0.2,0.04,0.87,0.05,0.02,0.02
26.324211518559757,0.0022862121926668,145.1467467168,150.0,8.333333333333333e-05,0.68,0.23,0.2,0.04,0.87,0.05,0.02,0.02
26.50134025524735,0.0023009729207241,145.708246608758,150.0,8.333333333333333e-05,0.68,0.23,0.2,0.04,0.87,0.05,0.02,0.02
26.698263768374552,0.0023173832134847,146.255736126847,150.0,8.333333333333333e-05,0.68,0.23,0.2,0.04,0.87,0.05,0.02,0.02
26.880136650800548,0.0023325392870202,146.788855836917,150.0,8.333333333333333e-05,0.68,0.23,0.2,0.04,0.87,0.05,0.02,0.02
27.06373637595375,0.0023478392641163,147.327339393603,150.0,8.333333333333333e-05,0.68,0.23,0.2,0.04,0.87,0.05,0.02,0.02
27.30713141863095,0.0023681221843394,147.847942830435,150.0,8.333333333333333e-05,0.68,0.23,0.2,0.04,0.87,0.05,0.02,0.02
27.472489999256556,0.0023819020660582,148.367898769414,150.0,8.333333333333333e-05,0.68,0.23,0.2,0.04,0.87,0.05,0.02,0.02
27.64282419735855,0.0023960965825667,148.872673364724,150.0,8.333333333333333e-05,0.68,0.23,0.2,0.04,0.87,0.05,0.02,0.02
27.78048503825175,0.0024075683193078,149.381722315892,150.0,8.333333333333333e-05,0.68,0.23,0.2,0.04,0.87,0.05,0.02,0.02
27.93679563648855,0.0024205942024942,149.912009459531,150.0,8.333333333333333e-05,0.68,0.23,0.2,0.04,0.87,0.05,0.02,0.02
28.027298051492547,0.0024281360704112,150.438999526387,150.0,8.333333333333333e-05,0.68,0.23,0.2,0.04,0.87,0.05,0.02,0.02
28.17291242709615,0.0024402706017115,151.03109461905,150.0,8.333333333333333e-05,0.68,0.23,0.2,0.04,0.87,0.05,0.02,0.02
28.26547664800935,0.0024479842867876,151.639237844056,150.0,8.333333333333333e-05,0.68,0.23,0.2,0.04,0.87,0.05,0.02,0.02
28.49403226687575,0.0024670305883598,152.19575177252,150.0,8.333333333333333e-05,0.68,0.23,0.2,0.04,0.87,0.05,0.02,0.02
28.59542026534815,0.0024754795882325,152.787666678668,150.0,8.333333333333333e-05,0.68,0.23,0.2,0.04,0.87,0.05,0.02,0.02
28.81985752541055,0.0024941826932377,153.362386032886,150.0,8.333333333333333e-05,0.68,0.23,0.2,0.04,0.87,0.05,0.02,0.02
29.08786265957655,0.0025165164544182,153.907771351168,150.0,8.333333333333333e-05,0.68,0.23,0.2,0.04,0.87,0.05,0.02,0.02
29.284716206409747,0.0025329209166543,154.438606972228,150.0,8.333333333333333e-05,0.68,0.23,0.2,0.04,0.87,0.05,0.02,0.02
29.43361668275175,0.0025453292896828,154.913327536648,150.0,8.333333333333333e-05,0.68,0.23,0.2,0.04,0.87,0.05,0.02,0.02
29.590847489702558,0.0025584318569287,155.433537238954,150.0,8.333333333333333e-05,0.68,0.23,0.2,0.04,0.87,0.05,0.02,0.02
29.72430921468135,0.0025695536673436,156.0374107712,150.0,8.333333333333333e-05,0.68,0.23,0.2,0.04,0.87,0.05,0.02,0.02
29.92638300236415,0.0025863931496505,156.573220385049,150.0,8.333333333333333e-05,0.68,0.23,0.2,0.04,0.87,0.05,0.02,0.02
30.051253685811748,0.0025967990399378,157.10357303114,150.0,8.333333333333333e-05,0.68,0.23,0.2,0.04,0.87,0.05,0.02,0.02
30.12423753538815,0.0026028810274025,157.633764878567,150.0,8.333333333333333e-05,0.68,0.23,0.2,0.04,0.87,0.05,0.02,0.02
30.22415232378015,0.0026112072597685,158.165979603238,150.0,8.333333333333333e-05,0.68,0.23,0.2,0.04,0.87,0.05,0.02,0.02
30.44131239572415,0.0026293039324305,158.668258893075,150.0,8.333333333333333e-05,0.68,0.23,0.2,0.04,0.87,0.05,0.02,0.02
30.55101207827775,0.0026384455726433,159.104170302355,150.0,8.333333333333333e-05,0.68,0.23,0.2,0.04,0.87,0.05,0.02,0.02
30.66483835060695,0.0026479310953374,159.508308843795,150.0,8.333333333333333e-05,0.68,0.23,0.2,0.04,0.87,0.05,0.02,0.02
30.854773938529352,0.0026637590609976,159.959647598671,150.0,8.333333333333333e-05,0.68,0.23,0.2,0.04,0.87,0.05,0.02,0.02
31.00188700627455,0.0026760184833097,160.422017648928,150.0,8.333333333333333e-05,0.68,0.23,0.2,0.04,0.87,0.05,0.02,0.02
31.137077916494547,0.0026872843924947,160.925414063858,150.0,8.333333333333333e-05,0.68,0.23,0.2,0.04,0.87,0.05,0.02,0.02
31.27319124255375,0.0026986271696663,161.443424270146,150.0,8.333333333333333e-05,0.68,0.23,0.2,0.04,0.87,0.05,0.02,0.02
31.383391397838157,0.00270781051594,161.960600892776,150.0,8.333333333333333e-05,0.68,0.23,0.2,0.04,0.87,0.05,0.02,0.02
31.54654570639815,0.00272140670832,162.486087376324,150.0,8.333333333333333e-05,0.68,0.23,0.2,0.04,0.87,0.05,0.02,0.02
31.709482085440943,0.0027349847399069,163.011697259859,150.0,8.333333333333333e-05,0.68,0.23,0.2,0.04,0.87,0.05,0.02,0.02
31.80836709234255,0.0027432251571487,163.523544320603,150.0,8.333333333333333e-05,0.68,0.23,0.2,0.04,0.87,0.05,0.02,0.02
31.905732045723752,0.0027513389032638,164.040551929378,150.0,8.333333333333333e-05,0.68,0.23,0.2,0.04,0.87,0.05,0.02,0.02
32.03068837780095,0.0027617519309369,164.519384048051,150.0,8.333333333333333e-05,0.68,0.23,0.2,0.04,0.87,0.05,0.02,0.02
32.24109973920135,0.0027792862110536,164.996328002958,150.0,8.333333333333333e-05,0.68,0.23,0.2,0.04,0.87,0.05,0.02,0.02
32.395421314173745,0.0027921463423013,165.50247098301,150.0,8.333333333333333e-05,0.68,0.23,0.2,0.04,0.87,0.05,0.02,0.02
32.56961008598415,0.0028066620732855,165.980895565635,150.0,8.333333333333333e-05,0.68,0.23,0.2,0.04,0.87,0.05,0.02,0.02
32.67300357465615,0.0028152781973415,166.439352102502,150.0,8.333333333333333e-05,0.68,0.23,0.2,0.04,0.87,0.05,0.02,0.02
32.783076881113345,0.0028244509728796,166.885787609117,150.0,8.333333333333333e-05,0.68,0.23,0.2,0.04,0.87,0.05,0.02,0.02
32.978054883738146,0.002840699139765,167.324005593557,150.0,8.333333333333333e-05,0.68,0.23,0.2,0.04,0.87,0.05,0.02,0.02
33.06066293951055,0.0028475831444127,167.785052419148,150.0,8.333333333333333e-05,0.68,0.23,0.2,0.04,0.87,0.05,0.02,0.02
33.22378120598895,0.0028611763332859,168.233265912086,150.0,8.333333333333333e-05,0.68,0.23,0.2,0.04,0.87,0.05,0.02,0.02
33.35176560860175,0.0028718417001703,168.650345334759,150.0,8.333333333333333e-05,0.68,0.23,0.2,0.04,0.87,0.05,0.02,0.02
33.45291535068495,0.0028802708453439,169.107540550377,150.0,8.333333333333333e-05,0.68,0.23,0.2,0.04,0.87,0.05,0.02,0.02
33.66224160597495,0.0028977146999514,169.58819503305,150.0,8.333333333333333e-05,0.68,0.23,0.2,0.04,0.87,0.05,0.02,0.02
33.88500923228535,0.0029162786688106,170.07323872777,150.0,8.333333333333333e-05,0.68,0.23,0.2,0.04,0.87,0.05,0.02,0.02
33.96702869222775,0.0029231136238058,170.560416431704,150.0,8.333333333333333e-05,0.68,0.23,0.2,0.04,0.87,0.05,0.02,0.02
34.29251135917455,0.0029502371793847,171.033364768258,150.0,8.333333333333333e-05,0.68,0.23,0.2,0.04,0.87,0.05,0.02,0.02
34.31604101829255,0.0029521979843112,171.510150741137,150.0,8.333333333333333e-05,0.68,0.23,0.2,0.04,0.87,0.05,0.02,0.02
34.45202233373415,0.002963529760598,172.021406182972,150.0,8.333333333333333e-05,0.68,0.23,0.2,0.04,0.87,0.05,0.02,0.02
34.630346434321346,0.0029783901023136,172.510786168264,150.0,8.333333333333333e-05,0.68,0.23,0.2,0.04,0.87,0.05,0.02,0.02
34.75394173426695,0.0029886897106424,172.995599086544,150.0,8.333333333333333e-05,0.68,0.23,0.2,0.04,0.87,0.05,0.02,0.02
34.84352200003215,0.0029961547327895,173.467327709834,150.0,8.333333333333333e-05,0.68,0.23,0.2,0.04,0.87,0.05,0.02,0.02
35.103139295139755,0.0030177895073818,173.926262574218,150.0,8.333333333333333e-05,0.68,0.23,0.2,0.04,0.87,0.05,0.02,0.02
35.13650247047535,0.0030205697719931,174.384271046764,150.0,8.333333333333333e-05,0.68,0.23,0.2,0.04,0.87,0.05,0.02,0.02
35.36989285176015,0.0030400189704335,174.84537063735,150.0,8.333333333333333e-05,0.68,0.23,0.2,0.04,0.87,0.05,0.02,0.02
35.49895951200495,0.0030507745254539,175.282857469825,150.0,8.333333333333333e-05,0.68,0.23,0.2,0.04,0.87,0.05,0.02,0.02
35.55307425512295,0.0030552840873804,175.708832973771,150.0,8.333333333333333e-05,0.68,0.23,0.2,0.04,0.87,0.05,0.02,0.02
35.75348996703135,0.0030719853967061,176.13007098853,150.0,8.333333333333333e-05,0.68,0.23,0.2,0.04,0.87,0.05,0.02,0.02
35.901331520522554,0.0030843055261637,176.612823630889,150.0,8.333333333333333e-05,0.68,0.23,0.2,0.04,0.87,0.05,0.02,0.02
35.97422360439375,0.0030903798664863,177.129990160571,150.0,8.333333333333333e-05,0.68,0.23,0.2,0.04,0.87,0.05,0.02,0.02
36.08427830672655,0.0030995510916807,177.652242284449,150.0,8.333333333333333e-05,0.68,0.23,0.2,0.04,0.87,0.05,0.02,0.02
36.29447438352495,0.0031170674314139,178.162589486105,150.0,8.333333333333333e-05,0.68,0.23,0.2,0.04,0.87,0.05,0.02,0.02
36.55333096812616,0.003138638813464,178.660452398997,150.0,8.333333333333333e-05,0.68,0.23,0.2,0.04,0.87,0.05,0.02,0.02
36.85392635327535,0.0031636884288931,179.160245834743,150.0,8.333333333333333e-05,0.68,0.23,0.2,0.04,0.87,0.05,0.02,0.02
37.06857886788495,0.0031815761384439,179.659190805601,150.0,8.333333333333333e-05,0.68,0.23,0.2,0.04,0.87,0.05,0.02,0.02
37.30162594267815,0.00320099672801,180.115264389507,150.0,8.333333333333333e-05,0.68,0.23,0.2,0.04,0.87,0.05,0.02,0.02
37.56374381529376,0.0032228398840613,180.590784237207,150.0,8.333333333333333e-05,0.68,0.23,0.2,0.04,0.87,0.05,0.02,0.02
37.85123022323536,0.0032467970847231,181.076622724236,150.0,8.333333333333333e-05,0.68,0.23,0.2,0.04,0.87,0.05,0.02,0.02
38.03186839895175,0.0032618502660328,181.572779521988,150.0,8.333333333333333e-05,0.68,0.23,0.2,0.04,0.87,0.05,0.02,0.02
38.15452434521415,0.003272071594888,182.084073285731,150.0,8.333333333333333e-05,0.68,0.23,0.2,0.04,0.87,0.05,0.02,0.02
38.35504759053615,0.0032887818653315,182.617465990497,150.0,8.333333333333333e-05,0.68,0.23,0.2,0.04,0.87,0.05,0.02,0.02
38.48038149943815,0.00329922635774,183.137137762121,150.0,8.333333333333333e-05,0.68,0.23,0.2,0.04,0.87,0.05,0.02,0.02
38.68068123870975,0.0033159180026793,183.639161598649,150.0,8.333333333333333e-05,0.68,0.23,0.2,0.04,0.87,0.05,0.02,0.02
38.76436336279456,0.0033228915130197,184.093312734061,150.0,8.333333333333333e-05,0.68,0.23,0.2,0.04,0.87,0.05,0.02,0.02
38.89709488617855,0.0033339524733017,184.528277252645,150.0,8.333333333333333e-05,0.68,0.23,0.2,0.04,0.87,0.05,0.02,0.02
39.02829249529455,0.0033448856073947,184.955413946402,150.0,8.333333333333333e-05,0.68,0.23,0.2,0.04,0.87,0.05,0.02,0.02
39.18748809236055,0.0033581519071502,185.446933511589,150.0,8.333333333333333e-05,0.68,0.23,0.2,0.04,0.87,0.05,0.02,0.02
39.29515295940975,0.0033671239794043,185.939106317438,150.0,8.333333333333333e-05,0.68,0.23,0.2,0.04,0.87,0.05,0.02,0.02
39.43152976024575,0.0033784887128073,186.411083415037,150.0,8.333333333333333e-05,0.68,0.23,0.2,0.04,0.87,0.05,0.02,0.02
39.53865008083215,0.0033874154061895,186.884226522025,150.0,8.333333333333333e-05,0.68,0.23,0.2,0.04,0.87,0.05,0.02,0.02
39.69646921333935,0.0034005670005651,187.363009599921,150.0,8.333333333333333e-05,0.68,0.23,0.2,0.04,0.87,0.05,0.02,0.02
39.80571052907895,0.0034096704435434,187.852914778438,150.0,8.333333333333333e-05,0.68,0.23,0.2,0.04,0.87,0.05,0.02,0.02
39.92667495680535,0.0034197508125206,188.363710200894,150.0,8.333333333333333e-05,0.68,0.23,0.2,0.04,0.87,0.05,0.02,0.02
40.06520313589815,0.003431294827445,188.81607234945,150.0,8.333333333333333e-05,0.68,0.23,0.2,0.04,0.87,0.05,0.02,0.02
40.24235151736935,0.0034460571925676,189.231125953059,150.0,8.333333333333333e-05,0.68,0.23,0.2,0.04,0.87,0.05,0.02,0.02
40.40593998581175,0.0034596895649378,189.661610939443,150.0,8.333333333333333e-05,0.68,0.23,0.2,0.04,0.87,0.05,0.02,0.02
40.62083217685695,0.0034775972475249,190.133527667126,150.0,8.333333333333333e-05,0.68,0.23,0.2,0.04,0.87,0.05,0.02,0.02
40.85369897799495,0.0034970028142864,190.630404131224,150.0,8.333333333333333e-05,0.68,0.23,0.2,0.04,0.87,0.05,0.02,0.02
41.14970829595935,0.0035216702574501,191.130170574201,150.0,8.333333333333333e-05,0.68,0.23,0.2,0.04,0.87,0.05,0.02,0.02
41.35570735530255,0.0035388368457287,191.608476889377,150.0,8.333333333333333e-05,0.68,0.23,0.2,0.04,0.87,0.05,0.02,0.02
41.52392055165135,0.0035528546120911,192.122469585785,150.0,8.333333333333333e-05,0.68,0.23,0.2,0.04,0.87,0.05,0.02,0.02
41.70001947397096,0.0035675295222844,192.650929405012,150.0,8.333333333333333e-05,0.68,0.23,0.2,0.04,0.87,0.05,0.02,0.02
41.76431765039175,0.0035728877036528,193.192277966397,150.0,8.333333333333333e-05,0.68,0.23,0.2,0.04,0.87,0.05,0.02,0.02
41.84861680995855,0.0035799126336167,193.693146934899,150.0,8.333333333333333e-05,0.68,0.23,0.2,0.04,0.87,0.05,0.02,0.02
41.96794963506135,0.0035898570357086,194.161486596456,150.0,8.333333333333333e-05,0.68,0.23,0.2,0.04,0.87,0.05,0.02,0.02
42.01011085891335,0.0035933704710296,194.613054109183,150.0,8.333333333333333e-05,0.68,0.23,0.2,0.04,0.87,0.05,0.02,0.02
42.11952404826015,0.0036024882368085,195.073007844981,150.0,8.333333333333333e-05,0.68,0.23,0.2,0.04,0.87,0.05,0.02,0.02
42.30326455629735,0.0036177999458116,195.509569537455,150.0,8.333333333333333e-05,0.68,0.23,0.2,0.04,0.87,0.05,0.02,0.02
42.46761604025295,0.0036314959028079,195.958254222432,150.0,8.333333333333333e-05,0.68,0.23,0.2,0.04,0.87,0.05,0.02,0.02
42.68989724831895,0.0036500193368134,196.404935887455,150.0,8.333333333333333e-05,0.68,0.23,0.2,0.04,0.87,0.05,0.02,0.02
42.88291024672575,0.0036661037533473,196.854918822918,150.0,8.333333333333333e-05,0.68,0.23,0.2,0.04,0.87,0.05,0.02,0.02
43.03507612167255,0.0036787842429262,197.334665394019,150.0,8.333333333333333e-05,0.68,0.23,0.2,0.04,0.87,0.05,0.02,0.02
43.18914296672055,0.0036916231466802,197.832577973607,150.0,8.333333333333333e-05,0.68,0.23,0.2,0.04,0.87,0.05,0.02,0.02
43.41694063595055,0.0037106062857827,198.321786159703,150.0,8.333333333333333e-05,0.68,0.23,0.2,0.04,0.87,0.05,0.02,0.02
43.56751142520735,0.0037231538515541,198.805365531903,150.0,8.333333333333333e-05,0.68,0.23,0.2,0.04,0.87,0.05,0.02,0.02
43.62674832599535,0.0037280902599531,199.310774574649,150.0,8.333333333333333e-05,0.68,0.23,0.2,0.04,0.87,0.05,0.02,0.02
43.81192716219495,0.0037435218296364,199.829617112754,150.0,8.333333333333333e-05,0.68,0.23,0.2,0.04,0.87,0.05,0.02,0.02
43.98389458285455,0.0037578524480247,200.343430702358,150.0,8.333333333333333e-05,0.68,0.23,0.2,0.04,0.87,0.05,0.02,0.02
44.14364965400775,0.0037711653706208,200.817503612445,150.0,8.333333333333333e-05,0.68,0.23,0.2,0.04,0.87,0.05,0.02,0.02
44.20213726440135,0.0037760393381536,201.270537920075,150.0,8.333333333333333e-05,0.68,0.23,0.2,0.04,0.87,0.05,0.02,0.02
44.28821208646335,0.0037832122399921,201.747887736694,150.0,8.333333333333333e-05,0.68,0.23,0.2,0.04,0.87,0.05,0.02,0.02
44.41401089399775,0.0037936954739533,202.225933466024,150.0,8.333333333333333e-05,0.68,0.23,0.2,0.04,0.87,0.05,0.02,0.02
44.63856663697215,0.0038124084525345,202.65652568803,150.0,8.333333333333333e-05,0.68,0.23,0.2,0.04,0.87,0.05,0.02,0.02
44.75182062832575,0.0038218462851473,203.065251012939,150.0,8.333333333333333e-05,0.68,0.23,0.2,0.04,0.87,0.05,0.02,0.02
44.82566042856976,0.0038279996018343,203.475154145817,150.0,8.333333333333333e-05,0.68,0.23,0.2,0.04,0.87,0.05,0.02,0.02
44.91899869986735,0.0038357777911091,203.895741720902,150.0,8.333333333333333e-05,0.68,0.23,0.2,0.04,0.87,0.05,0.02,0.02
45.14336083844535,0.0038544746359906,204.347314679127,150.0,8.333333333333333e-05,0.68,0.23,0.2,0.04,0.87,0.05,0.02,0.02
45.31959396181335,0.0038691607296046,204.784026294918,150.0,8.333333333333333e-05,0.68,0.23,0.2,0.04,0.87,0.05,0.02,0.02
45.48430042974495,0.0038828862685989,205.217640893379,150.0,8.333333333333333e-05,0.68,0.23,0.2,0.04,0.87,0.05,0.02,0.02
45.58938341502735,0.0038916431840391,205.671623171415,150.0,8.333333333333333e-05,0.68,0.23,0.2,0.04,0.87,0.05,0.02,0.02
45.59881214623695,0.0038924289116399,206.107221370685,150.0,8.333333333333333e-05,0.68,0.23,0.2,0.04,0.87,0.05,0.02,0.02
45.74728517947575,0.0039048016644098,206.538198971195,150.0,8.333333333333333e-05,0.68,0.23,0.2,0.04,0.87,0.05,0.02,0.02
45.93947555178495,0.0039208175287689,206.971414718239,150.0,8.333333333333333e-05,0.68,0.23,0.2,0.04,0.87,0.05,0.02,0.02
46.03606874112855,0.0039288669612142,207.38207166136,150.0,8.333333333333333e-05,0.68,0.23,0.2,0.04,0.87,0.05,0.02,0.02
46.16031852841096,0.0039392211101544,207.787991271775,150.0,8.333333333333333e-05,0.68,0.23,0.2,0.04,0.87,0.05,0.02,0.02
46.34189813590455,0.0039543527441122,208.221810577138,150.0,8.333333333333333e-05,0.68,0.23,0.2,0.04,0.87,0.05,0.02,0.02
46.54247052376096,0.0039710671097669,208.658382832,150.0,8.333333333333333e-05,0.68,0.23,0.2,0.04,0.87,0.05,0.02,0.02
46.85180362970056,0.0039968448685952,209.121515392779,150.0,8.333333333333333e-05,0.68,0.23,0.2,0.04,0.87,0.05,0.02,0.02
47.02845709460535,0.0040115659906706,209.598654133768,150.0,8.333333333333333e-05,0.68,0.23,0.2,0.04,0.87,0.05,0.02,0.02
47.20491429084735,0.0040262707570241,210.06703105317,150.0,8.333333333333333e-05,0.68,0.23,0.2,0.04,0.87,0.05,0.02,0.02
47.43519039205575,0.0040454604321248,210.543259081598,150.0,8.333333333333333e-05,0.68,0.23,0.2,0.04,0.87,0.05,0.02,0.02
47.56215329739495,0.0040560406742364,211.040123747118,150.0,8.333333333333333e-05,0.68,0.23,0.2,0.04,0.87,0.05,0.02,0.02
47.71434958464855,0.0040687236981742,211.497859537926,150.0,8.333333333333333e-05,0.68,0.23,0.2,0.04,0.87,0.05,0.02,0.02
47.91991334093776,0.0040858540111983,211.942631617096,150.0,8.333333333333333e-05,0.68,0.23,0.2,0.04,0.87,0.05,0.02,0.02
48.04644297598575,0.0040963981474523,212.390464410277,150.0,8.333333333333333e-05,0.68,0.23,0.2,0.04,0.87,0.05,0.02,0.02
48.24328507320615,0.004112801655554,212.838826261734,150.0,8.333333333333333e-05,0.68,0.23,0.2,0.04,0.87,0.05,0.02,0.02
48.42666061389615,0.0041280829506115,213.307204730287,150.0,8.333333333333333e-05,0.68,0.23,0.2,0.04,0.87,0.05,0.02,0.02
48.61907388670335,0.0041441173900121,213.80060842206,150.0,8.333333333333333e-05,0.68,0.23,0.2,0.04,0.87,0.05,0.02,0.02
48.82208446162696,0.0041610349379224,214.277338985434,150.0,8.333333333333333e-05,0.68,0.23,0.2,0.04,0.87,0.05,0.02,0.02
48.99575008839735,0.0041755070734866,214.745344359149,150.0,8.333333333333333e-05,0.68,0.23,0.2,0.04,0.87,0.05,0.02,0.02
49.08674308150575,0.0041830898229123,215.234323145827,150.0,8.333333333333333e-05,0.68,0.23,0.2,0.04,0.87,0.05,0.02,0.02
49.16631129068655,0.0041897205070107,215.709512883695,150.0,8.333333333333333e-05,0.68,0.23,0.2,0.04,0.87,0.05,0.02,0.02
49.37060845174455,0.0042067452704322,216.164726673574,150.0,8.333333333333333e-05,0.68,0.23,0.2,0.04,0.87,0.05,0.02,0.02
49.54009460078295,0.0042208691161854,216.618556540264,150.0,8.333333333333333e-05,0.68,0.23,0.2,0.04,0.87,0.05,0.02,0.02
49.65295370276896,0.0042302740413509,217.05831178247,150.0,8.333333333333333e-05,0.68,0.23,0.2,0.04,0.87,0.05,0.02,0.02
49.817282689788144,0.0042439681236025,217.488782654374,150.0,8.333333333333333e-05,0.68,0.23,0.2,0.04,0.87,0.05,0.02,0.02
49.96792003594695,0.0042565212357824,217.909212075304,150.0,8.333333333333333e-05,0.68,0.23,0.2,0.04,0.87,0.05,0.02,0.02
50.14601665719615,0.0042713626208865,218.299629073329,150.0,8.333333333333333e-05,0.68,0.23,0.2,0.04,0.87,0.05,0.02,0.02
50.48016076414935,0.0042992079631326,218.705130272349,150.0,8.333333333333333e-05,0.68,0.23,0.2,0.04,0.87,0.05,0.02,0.02
50.57962945866975,0.0043074970210093,219.145717236102,150.0,8.333333333333333e-05,0.68,0.23,0.2,0.04,0.87,0.05,0.02,0.02
50.710246189350144,0.004318381748566,219.578585175447,150.0,8.333333333333333e-05,0.68,0.23,0.2,0.04,0.87,0.05,0.02,0.02
50.81745736992615,0.004327316013614,219.991502453941,150.0,8.333333333333333e-05,0.68,0.23,0.2,0.04,0.87,0.05,0.02,0.02
51.04444250509575,0.0043462314415448,220.412279823402,150.0,8.333333333333333e-05,0.68,0.23,0.2,0.04,0.87,0.05,0.02,0.02
51.20542540502055,0.0043596466832052,220.867155272611,150.0,8.333333333333333e-05,0.68,0.23,0.2,0.04,0.87,0.05,0.02,0.02
51.40125422348896,0.0043759657514109,221.328622700314,150.0,8.333333333333333e-05,0.68,0.23,0.2,0.04,0.87,0.05,0.02,0.02
51.60570450956176,0.0043930032752503,221.773895921759,150.0,8.333333333333333e-05,0.68,0.23,0.2,0.04,0.87,0.05,0.02,0.02
51.78443750207416,0.004407897691293,222.239667812038,150.0,8.333333333333333e-05,0.68,0.23,0.2,0.04,0.87,0.05,0.02,0.02
51.91121879711535,0.0044184627992131,222.701601440073,150.0,8.333333333333333e-05,0.68,0.23,0.2,0.04,0.87,0.05,0.02,0.02
52.09519042342455,0.0044337937680722,223.138817296441,150.0,8.333333333333333e-05,0.68,0.23,0.2,0.04,0.87,0.05,0.02,0.02
52.11560963713935,0.0044354953692151,223.559415120955,150.0,8.333333333333333e-05,0.68,0.23,0.2,0.04,0.87,0.05,0.02,0.02
52.27520349354615,0.004448794857249,223.950593847102,150.0,8.333333333333333e-05,0.68,0.23,0.2,0.04,0.87,0.05,0.02,0.02
52.39466744684055,0.0044587501866902,224.334655245051,150.0,8.333333333333333e-05,0.68,0.23,0.2,0.04,0.87,0.05,0.02,0.02
52.49478371525655,0.0044670932090582,224.721874812644,150.0,8.333333333333333e-05,0.68,0.23,0.2,0.04,0.87,0.05,0.02,0.02
52.65734510329455,0.0044806399913947,225.077642937598,150.0,8.333333333333333e-05,0.68,0.23,0.2,0.04,0.87,0.05,0.02,0.02
52.917267014282544,0.0045023001506437,225.436613469041,150.0,8.333333333333333e-05,0.68,0.23,0.2,0.04,0.87,0.05,0.02,0.02
53.19008095819575,0.0045250346459698,225.835776312062,150.0,8.333333333333333e-05,0.68,0.23,0.2,0.04,0.87,0.05,0.02,0.02
53.50159607570175,0.0045509942390953,226.254085540948,150.0,8.333333333333333e-05,0.68,0.23,0.2,0.04,0.87,0.05,0.02,0.02
53.67683651746096,0.0045655976092419,226.681770571295,150.0,8.333333333333333e-05,0.68,0.23,0.2,0.04,0.87,0.05,0.02,0.02
53.91480265232536,0.0045854281204806,227.113408391467,150.0,8.333333333333333e-05,0.68,0.23,0.2,0.04,0.87,0.05,0.02,0.02
54.03665286076695,0.0045955823045174,227.522118975978,150.0,8.333333333333333e-05,0.68,0.23,0.2,0.04,0.87,0.05,0.02,0.02
54.16255390498215,0.004606074058202,227.911042014203,150.0,8.333333333333333e-05,0.68,0.23,0.2,0.04,0.87,0.05,0.02,0.02
54.36441591602655,0.0046228958924557,228.314529646529,150.0,8.333333333333333e-05,0.68,0.23,0.2,0.04,0.87,0.05,0.02,0.02
54.53815113307935,0.0046373738272101,228.689143246651,150.0,8.333333333333333e-05,0.68,0.23,0.2,0.04,0.87,0.05,0.02,0.02
54.697056159223344,0.0046506159127221,229.074193894383,150.0,8.333333333333333e-05,0.68,0.23,0.2,0.04,0.87,0.05,0.02,0.02
54.89434556142015,0.0046670566962385,229.531968320059,150.0,8.333333333333333e-05,0.68,0.23,0.2,0.04,0.87,0.05,0.02,0.02
54.98805209741895,0.0046748655742384,229.965402106087,150.0,8.333333333333333e-05,0.68,0.23,0.2,0.04,0.87,0.05,0.02,0.02
55.21646079371895,0.0046938996322634,230.420076572613,150.0,8.333333333333333e-05,0.68,0.23,0.2,0.04,0.87,0.05,0.02,0.02
55.51573105095135,0.0047188388203661,230.857261852823,150.0,8.333333333333333e-05,0.68,0.23,0.2,0.04,0.87,0.05,0.02,0.02
55.70557815060255,0.0047346594120037,231.241789310272,150.0,8.333333333333333e-05,0.68,0.23,0.2,0.04,0.87,0.05,0.02,0.02
55.91616849801735,0.0047522086076216,231.634771920153,150.0,8.333333333333333e-05,0.68,0.23,0.2,0.04,0.87,0.05,0.02,0.02
56.17710989388015,0.0047739537239435,231.986697917811,150.0,8.333333333333333e-05,0.68,0.23,0.2,0.04,0.87,0.05,0.02,0.02
56.41298395499536,0.0047936098957031,232.230978880028,150.0,8.333333333333333e-05,0.68,0.23,0.2,0.04,0.87,0.05,0.02,0.02
56.71247569238055,0.0048185675404852,232.509379641392,150.0,8.333333333333333e-05,0.68,0.23,0.2,0.04,0.87,0.05,0.02,0.02
56.99134976648175,0.0048418070466603,232.80829581493,150.0,8.333333333333333e-05,0.68,0.23,0.2,0.04,0.87,0.05,0.02,0.02
57.17650539612495,0.0048572366824639,233.131026355182,150.0,8.333333333333333e-05,0.68,0.23,0.2,0.04,0.87,0.05,0.02,0.02
57.23868153013336,0.0048624180269646,233.482481630241,150.0,8.333333333333333e-05,0.68,0.23,0.2,0.04,0.87,0.05,0.02,0.02
57.42098601259815,0.00487761006717,233.845163753513,150.0,8.333333333333333e-05,0.68,0.23,0.2,0.04,0.87,0.05,0.02,0.02
57.66680932442535,0.0048980953431556,234.177950954578,150.0,8.333333333333333e-05,0.68,0.23,0.2,0.04,0.87,0.05,0.02,0.02
57.89346189142455,0.0049169830570722,234.4960804404,150.0,8.333333333333333e-05,0.68,0.23,0.2,0.04,0.87,0.05,0.02,0.02
58.13440243585815,0.004937061435775,234.821949277359,150.0,8.333333333333333e-05,0.68,0.23,0.2,0.04,0.87,0.05,0.02,0.02
58.34998709977095,0.0049550268244344,235.113940905838,150.0,8.333333333333333e-05,0.68,0.23,0.2,0.04,0.87,0.05,0.02,0.02
58.61552830830255,0.0049771552584787,235.364144770129,150.0,8.333333333333333e-05,0.68,0.23,0.2,0.04,0.87,0.05,0.02,0.02
59.10043597181176,0.0050175642304378,235.631518883563,150.0,8.333333333333333e-05,0.68,0.23,0.2,0.04,0.87,0.05,0.02,0.02
59.44213389535816,0.0050460390574,235.862934857259,150.0,8.333333333333333e-05,0.68,0.23,0.2,0.04,0.87,0.05,0.02,0.02
59.70010380006855,0.0050675365494592,236.096885397216,150.0,8.333333333333333e-05,0.68,0.23,0.2,0.04,0.87,0.05,0.02,0.02
59.96413558766295,0.0050895391984254,236.358705196796,150.0,8.333333333333333e-05,0.68,0.23,0.2,0.04,0.87,0.05,0.02,0.02
60.25936381569736,0.0051141415507616,236.59027279944,150.0,8.333333333333333e-05,0.68,0.23,0.2,0.04,0.87,0.05,0.02,0.02
60.60708804435856,0.0051431185698167,236.811116699088,150.0,8.333333333333333e-05,0.68,0.23,0.2,0.04,0.87,0.05,0.02,0.02
60.92173444081935,0.0051693391028551,237.084237408781,150.0,8.333333333333333e-05,0.68,0.23,0.2,0.04,0.87,0.05,0.02,0.02
61.14019410319815,0.00518754407472,237.374617279451,150.0,8.333333333333333e-05,0.68,0.23,0.2,0.04,0.87,0.05,0.02,0.02
61.41835155590535,0.0052107238624456,237.660216206489,150.0,8.333333333333333e-05,0.68,0.23,0.2,0.04,0.87,0.05,0.02,0.02
61.76649590217375,0.0052397358913013,237.92077189948,150.0,8.333333333333333e-05,0.68,0.23,0.2,0.04,0.87,0.05,0.02,0.02
62.19498952082895,0.0052754436928559,238.173844336209,150.0,8.333333333333333e-05,0.68,0.23,0.2,0.04,0.87,0.05,0.02,0.02
62.58194098653615,0.0053076896483315,238.407753127349,150.0,8.333333333333333e-05,0.68,0.23,0.2,0.04,0.87,0.05,0.02,0.02
62.88873080866095,0.0053332554668419,238.632776243125,150.0,8.333333333333333e-05,0.68,0.23,0.2,0.04,0.87,0.05,0.02,0.02
63.39152842839856,0.0053751552684867,238.844059194387,150.0,8.333333333333333e-05,0.68,0.23,0.2,0.04,0.87,0.05,0.02,0.02
63.89872222316775,0.0054174214180508,239.009831757804,150.0,8.333333333333333e-05,0.68,0.23,0.2,0.04,0.87,0.05,0.02,0.02
64.40223301175895,0.0054593806504334,239.148871903149,150.0,8.333333333333333e-05,0.68,0.23,0.2,0.04,0.87,0.05,0.02,0.02
64.87553414831174,0.0054988224118128,239.347459505665,150.0,8.333333333333333e-05,0.68,0.23,0.2,0.04,0.87,0.05,0.02,0.02
65.27886510205336,0.0055324333246246,239.587235163455,150.0,8.333333333333333e-05,0.68,0.23,0.2,0.04,0.87,0.05,0.02,0.02
65.73995341209854,0.0055708573504617,239.754703905544,150.0,8.333333333333333e-05,0.68,0.23,0.2,0.04,0.87,0.05,0.02,0.02
66.24266958528976,0.0056127503648943,239.910531566037,150.0,8.333333333333333e-05,0.68,0.23,0.2,0.04,0.87,0.05,0.02,0.02
66.68760131072415,0.0056498280086805,240.050979356912,150.0,8.333333333333333e-05,0.68,0.23,0.2,0.04,0.87,0.05,0.02,0.02
67.13366456042776,0.0056869999461558,240.130686829287,150.0,8.333333333333333e-05,0.68,0.23,0.2,0.04,0.87,0.05,0.02,0.02
67.60492466926216,0.005726271621892,240.219106613034,150.0,8.333333333333333e-05,0.68,0.23,0.2,0.04,0.87,0.05,0.02,0.02
68.07892549019896,0.0057657716903034,240.320648559887,150.0,8.333333333333333e-05,0.68,0.23,0.2,0.04,0.87,0.05,0.02,0.02
68.58110545540335,0.0058076200207371,240.340317838723,150.0,8.333333333333333e-05,0.68,0.23,0.2,0.04,0.87,0.05,0.02,0.02
69.16536854188095,0.0058563086112769,240.393779592215,150.0,8.333333333333333e-05,0.68,0.23,0.2,0.04,0.87,0.05,0.02,0.02
69.80569716957734,0.0059096693302516,240.509147376283,150.0,8.333333333333333e-05,0.68,0.23,0.2,0.04,0.87,0.05,0.02,0.02
70.51613427237135,0.0059688724221511,240.636644365104,150.0,8.333333333333333e-05,0.68,0.23,0.2,0.04,0.87,0.05,0.02,0.02
71.09312213723415,0.006016954744223,240.749924708354,150.0,8.333333333333333e-05,0.68,0.23,0.2,0.04,0.87,0.05,0.02,0.02
71.71453311805215,0.0060687389926245,240.881696193865,150.0,8.333333333333333e-05,0.68,0.23,0.2,0.04,0.87,0.05,0.02,0.02
72.31471882382056,0.0061187544681052,240.957986475548,150.0,8.333333333333333e-05,0.68,0.23,0.2,0.04,0.87,0.05,0.02,0.02
72.92720517631454,0.0061697949974797,241.065589449213,150.0,8.333333333333333e-05,0.68,0.23,0.2,0.04,0.87,0.05,0.02,0.02
73.54859749068974,0.0062215776903443,241.244970264654,150.0,8.333333333333333e-05,0.68,0.23,0.2,0.04,0.87,0.05,0.02,0.02
74.13386847680056,0.0062703502725202,241.327060064071,150.0,8.333333333333333e-05,0.68,0.23,0.2,0.04,0.87,0.05,0.02,0.02
74.39346610015936,0.0062919834078001,241.298279919759,150.0,8.333333333333333e-05,0.68,0.23,0.2,0.04,0.87,0.05,0.02,0.02
75.03864370224495,0.0063457482079739,241.350524448016,150.0,8.333333333333333e-05,0.68,0.23,0.2,0.04,0.87,0.05,0.02,0.02
75.59294072707574,0.0063919396267098,241.366238464645,150.0,8.333333333333333e-05,0.68,0.23,0.2,0.04,0.87,0.05,0.02,0.02
76.25105545948935,0.0064467825210776,241.376261435352,150.0,8.333333333333333e-05,0.68,0.23,0.2,0.04,0.87,0.05,0.02,0.02
76.97282455946535,0.0065069299460756,241.377854399935,150.0,8.333333333333333e-05,0.68,0.23,0.2,0.04,0.87,0.05,0.02,0.02
77.66172696518295,0.0065643384798854,241.291001824192,150.0,8.333333333333333e-05,0.68,0.23,0.2,0.04,0.87,0.05,0.02,0.02
78.36234299932934,0.0066227231493976,241.297172731135,150.0,8.333333333333333e-05,0.68,0.23,0.2,0.04,0.87,0.05,0.02,0.02
79.23531538143375,0.0066954708479063,241.391950587338,150.0,8.333333333333333e-05,0.68,0.23,0.2,0.04,0.87,0.05,0.02,0.02
79.93897010624656,0.0067541087416407,241.395047604668,150.0,8.333333333333333e-05,0.68,0.23,0.2,0.04,0.87,0.05,0.02,0.02
80.66826595587615,0.0068148833957765,241.419898697143,150.0,8.333333333333333e-05,0.68,0.23,0.2,0.04,0.87,0.05,0.02,0.02
81.40977724456096,0.0068766760031669,241.460254420598,150.0,8.333333333333333e-05,0.68,0.23,0.2,0.04,0.87,0.05,0.02,0.02
82.05440635126214,0.006930395095392,241.465042343231,150.0,8.333333333333333e-05,0.68,0.23,0.2,0.04,0.87,0.05,0.02,0.02
82.67797960665375,0.0069823595333413,241.484548491853,150.0,8.333333333333333e-05,0.68,0.23,0.2,0.04,0.87,0.05,0.02,0.02