File: datasets/al_6061_comp/csv/T_150_D_2.csv
Time,Strain(%),Stress(MPa),Temp(C),SR(%/s),Si(%),Fe(%),Cu(%),Mn(%),Mg(%),Cr(%),Zn(%),Ti(%)
0.0,0.0001162329103307,39.0200345751017,150.0,8.333333333333333e-05,0.67,0.28,0.23,0.05,0.9,0.05,0.03,0.02
0.6234776401716,0.000168189380345,41.7559839327216,150.0,8.333333333333333e-05,0.67,0.28,0.23,0.05,0.9,0.05,0.03,0.02
1.2107115650928,0.0002171255407551,44.4737867993441,150.0,8.333333333333333e-05,0.67,0.28,0.23,0.05,0.9,0.05,0.03,0.02
1.8027733160568005,0.0002664640200021,47.1925329761954,150.0,8.333333333333333e-05,0.67,0.28,0.23,0.05,0.9,0.05,0.03,0.02
2.3771517755304,0.0003143288916249,49.9532970855636,150.0,8.333333333333333e-05,0.67,0.28,0.23,0.05,0.9,0.05,0.03,0.02
3.0804930986952,0.0003729406685553,52.7483094127717,150.0,8.333333333333333e-05,0.67,0.28,0.23,0.05,0.9,0.05,0.03,0.02
3.7417570600452,0.0004280459986678,55.4923692421868,150.0,8.333333333333333e-05,0.67,0.28,0.23,0.05,0.9,0.05,0.03,0.02
4.4574973112256,0.0004876910195995,58.2973037023577,150.0,8.333333333333333e-05,0.67,0.28,0.23,0.05,0.9,0.05,0.03,0.02
5.064320259936,0.0005382595986587,61.0415292046158,150.0,8.333333333333333e-05,0.67,0.28,0.23,0.05,0.9,0.05,0.03,0.02
5.7176416256124,0.0005927030457984,63.8075035145225,150.0,8.333333333333333e-05,0.67,0.28,0.23,0.05,0.9,0.05,0.03,0.02
6.3836000122716,0.00064819957802,66.5559340605353,150.0,8.333333333333333e-05,0.67,0.28,0.23,0.05,0.9,0.05,0.03,0.02
7.1330253119904015,0.0007106516863299,69.2752782825003,150.0,8.333333333333333e-05,0.67,0.28,0.23,0.05,0.9,0.05,0.03,0.02
7.754576650557601,0.0007624476312105,71.9851015199624,150.0,8.333333333333333e-05,0.67,0.28,0.23,0.05,0.9,0.05,0.03,0.02
8.4564136645584,0.0008209340490439,74.6507896955384,150.0,8.333333333333333e-05,0.67,0.28,0.23,0.05,0.9,0.05,0.03,0.02
9.0699736095552,0.0008720640444603,77.2871342590712,150.0,8.333333333333333e-05,0.67,0.28,0.23,0.05,0.9,0.05,0.03,0.02
9.693339974532002,0.0009240112415417,79.8759821078345,150.0,8.333333333333333e-05,0.67,0.28,0.23,0.05,0.9,0.05,0.03,0.02
10.376780519802,0.0009809646203142,82.4674721489824,150.0,8.333333333333333e-05,0.67,0.28,0.23,0.05,0.9,0.05,0.03,0.02
11.0346638011032,0.0010357882270893,85.0162695290988,150.0,8.333333333333333e-05,0.67,0.28,0.23,0.05,0.9,0.05,0.03,0.02
11.6980547728872,0.0010910708080713,87.5191168802969,150.0,8.333333333333333e-05,0.67,0.28,0.23,0.05,0.9,0.05,0.03,0.02
12.297688854366,0.0011410403148612,90.0173123740618,150.0,8.333333333333333e-05,0.67,0.28,0.23,0.05,0.9,0.05,0.03,0.02
12.851110889598,0.0011871588177972,92.4890406742001,150.0,8.333333333333333e-05,0.67,0.28,0.23,0.05,0.9,0.05,0.03,0.02
13.4383096988316,0.0012360920519,94.9407282862849,150.0,8.333333333333333e-05,0.67,0.28,0.23,0.05,0.9,0.05,0.03,0.02
14.1302669649084,0.0012937551574064,97.3196871178729,150.0,8.333333333333333e-05,0.67,0.28,0.23,0.05,0.9,0.05,0.03,0.02
14.7595500969504,0.0013461954184099,99.6699938799702,150.0,8.333333333333333e-05,0.67,0.28,0.23,0.05,0.9,0.05,0.03,0.02
15.3743520973716,0.001397428918445,101.949789843532,150.0,8.333333333333333e-05,0.67,0.28,0.23,0.05,0.9,0.05,0.03,0.02
15.9180293524332,0.0014427353563668,104.201543376968,150.0,8.333333333333333e-05,0.67,0.28,0.23,0.05,0.9,0.05,0.03,0.02
16.572701417353198,0.0014972913617768,106.423782753718,150.0,8.333333333333333e-05,0.67,0.28,0.23,0.05,0.9,0.05,0.03,0.02
17.249236585798798,0.0015536692924806,108.593879695468,150.0,8.333333333333333e-05,0.67,0.28,0.23,0.05,0.9,0.05,0.03,0.02
17.8613275405584,0.0016046768720439,110.784986386445,150.0,8.333333333333333e-05,0.67,0.28,0.23,0.05,0.9,0.05,0.03,0.02
18.3833231391804,0.0016481765052624,113.001055311849,150.0,8.333333333333333e-05,0.67,0.28,0.23,0.05,0.9,0.05,0.03,0.02
18.9041287682988,0.0016915769743556,115.180344265046,150.0,8.333333333333333e-05,0.67,0.28,0.23,0.05,0.9,0.05,0.03,0.02
19.5429631705092,0.0017448131745398,117.355065763167,150.0,8.333333333333333e-05,0.67,0.28,0.23,0.05,0.9,0.05,0.03,0.02
20.2276028269236,0.001801866479241,119.589157091021,150.0,8.333333333333333e-05,0.67,0.28,0.23,0.05,0.9,0.05,0.03,0.02
20.8622528795832,0.0018547539836293,121.853925069348,150.0,8.333333333333333e-05,0.67,0.28,0.23,0.05,0.9,0.05,0.03,0.02
21.4082718041412,0.0019002555606758,124.149567037693,150.0,8.333333333333333e-05,0.67,0.28,0.23,0.05,0.9,0.05,0.03,0.02
22.0718210327388,0.0019555513297256,126.363128203927,150.0,8.333333333333333e-05,0.67,0.28,0.23,0.05,0.9,0.05,0.03,0.02
22.6974303334896,0.0020076854381215,128.610222034434,150.0,8.333333333333333e-05,0.67,0.28,0.23,0.05,0.9,0.05,0.03,0.02
23.378099327724,0.0020644078543077,130.806230325876,150.0,8.333333333333333e-05,0.67,0.28,0.23,0.05,0.9,0.05,0.03,0.02
23.909610911214,0.0021087004862652,133.067893290796,150.0,8.333333333333333e-05,0.67,0.28,0.23,0.05,0.9,0.05,0.03,0.02
24.4519879392912,0.0021538985719383,135.246158580695,150.0,8.333333333333333e-05,0.67,0.28,0.23,0.05,0.9,0.05,0.03,0.02
25.0667387619312,0.0022051278071583,137.347075721878,150.0,8.333333333333333e-05,0.67,0.28,0.23,0.05,0.9,0.05,0.03,0.02
25.7258724030516,0.002260055610585,139.475920299719,150.0,8.333333333333333e-05,0.67,0.28,0.23,0.05,0.9,0.05,0.03,0.02
26.3424525361548,0.0023114372883436,141.599969017305,150.0,8.333333333333333e-05,0.67,0.28,0.23,0.05,0.9,0.05,0.03,0.02
27.0033617194944,0.0023665130536219,143.705496273451,150.0,8.333333333333333e-05,0.67,0.28,0.23,0.05,0.9,0.05,0.03,0.02
27.6216844231452,0.0024180399455928,145.847942980812,150.0,8.333333333333333e-05,0.67,0.28,0.23,0.05,0.9,0.05,0.03,0.02
28.2465382007484,0.0024701110937264,147.883368922722,150.0,8.333333333333333e-05,0.67,0.28,0.23,0.05,0.9,0.05,0.03,0.02
28.8155975857704,0.0025175327091449,150.044183803808,150.0,8.333333333333333e-05,0.67,0.28,0.23,0.05,0.9,0.05,0.03,0.02
29.3620607331528,0.0025630713047601,152.133046466192,150.0,8.333333333333333e-05,0.67,0.28,0.23,0.05,0.9,0.05,0.03,0.02
29.9975093925492,0.0026160253597098,154.16480296184,150.0,8.333333333333333e-05,0.67,0.28,0.23,0.05,0.9,0.05,0.03,0.02
30.57321317031,0.0026640006745232,156.204736109842,150.0,8.333333333333333e-05,0.67,0.28,0.23,0.05,0.9,0.05,0.03,0.02
31.1618281811904,0.0027130519254299,158.251820570242,150.0,8.333333333333333e-05,0.67,0.28,0.23,0.05,0.9,0.05,0.03,0.02
31.7028793276176,0.0027581395209655,160.234535357745,150.0,8.333333333333333e-05,0.67,0.28,0.23,0.05,0.9,0.05,0.03,0.02
32.3758058855052,0.0028142167341228,162.237141357613,150.0,8.333333333333333e-05,0.67,0.28,0.23,0.05,0.9,0.05,0.03,0.02
33.067447581774005,0.0028718535421452,164.157394351441,150.0,8.333333333333333e-05,0.67,0.28,0.23,0.05,0.9,0.05,0.03,0.02
33.6569653708572,0.0029209800245688,166.130552549174,150.0,8.333333333333333e-05,0.67,0.28,0.23,0.05,0.9,0.05,0.03,0.02
34.1828876912364,0.0029648068846004,168.118866300548,150.0,8.333333333333333e-05,0.67,0.28,0.23,0.05,0.9,0.05,0.03,0.02
34.7782802821404,0.0030144229338424,170.132880253362,150.0,8.333333333333333e-05,0.67,0.28,0.23,0.05,0.9,0.05,0.03,0.02
35.44962802918081,0.0030703685794291,172.067553965689,150.0,8.333333333333333e-05,0.67,0.28,0.23,0.05,0.9,0.05,0.03,0.02
36.082822841654405,0.0031231348138019,173.995298064165,150.0,8.333333333333333e-05,0.67,0.28,0.23,0.05,0.9,0.05,0.03,0.02
36.603651403626,0.0031665371939662,175.936250483036,150.0,8.333333333333333e-05,0.67,0.28,0.23,0.05,0.9,0.05,0.03,0.02
37.175943346414805,0.0032142281891986,177.831450876869,150.0,8.333333333333333e-05,0.67,0.28,0.23,0.05,0.9,0.05,0.03,0.02
37.861552910958,0.0032713623195772,179.679532341896,150.0,8.333333333333333e-05,0.67,0.28,0.23,0.05,0.9,0.05,0.03,0.02
38.48173761995881,0.0033230443786606,181.610250895859,150.0,8.333333333333333e-05,0.67,0.28,0.23,0.05,0.9,0.05,0.03,0.02
39.0826000994772,0.0033731162519538,183.433690795309,150.0,8.333333333333333e-05,0.67,0.28,0.23,0.05,0.9,0.05,0.03,0.02
39.5841695054088,0.0034149137024481,185.288720538878,150.0,8.333333333333333e-05,0.67,0.28,0.23,0.05,0.9,0.05,0.03,0.02
40.182804388812,0.0034647999427317,187.117177206253,150.0,8.333333333333333e-05,0.67,0.28,0.23,0.05,0.9,0.05,0.03,0.02
40.848253402806,0.0035202540272312,188.91431667633,150.0,8.333333333333333e-05,0.67,0.28,0.23,0.05,0.9,0.05,0.03,0.02
41.45299830010921,0.0035706494353398,190.703923489099,150.0,8.333333333333333e-05,0.67,0.28,0.23,0.05,0.9,0.05,0.03,0.02
42.01459324932121,0.0036174490144408,192.50004133634,150.0,8.333333333333333e-05,0.67,0.28,0.23,0.05,0.9,0.05,0.03,0.02
42.6146210104704,0.0036674513278699,194.218641771441,150.0,8.333333333333333e-05,0.67,0.28,0.23,0.05,0.9,0.05,0.03,0.02
43.313529437002806,0.0037256936967476,195.99658865796,150.0,8.333333333333333e-05,0.67,0.28,0.23,0.05,0.9,0.05,0.03,0.02
44.0396324679276,0.003786202282658,197.754060285518,150.0,8.333333333333333e-05,0.67,0.28,0.23,0.05,0.9,0.05,0.03,0.02
44.6568936740448,0.0038376407165011,199.555987311645,150.0,8.333333333333333e-05,0.67,0.28,0.23,0.05,0.9,0.05,0.03,0.02
45.2087361493164,0.0038836275894404,201.33895942847,150.0,8.333333333333333e-05,0.67,0.28,0.23,0.05,0.9,0.05,0.03,0.02
45.90172006774801,0.0039413762493097,203.104988468042,150.0,8.333333333333333e-05,0.67,0.28,0.23,0.05,0.9,0.05,0.03,0.02
46.574149452716405,0.0039974120313904,204.900018828238,150.0,8.333333333333333e-05,0.67,0.28,0.23,0.05,0.9,0.05,0.03,0.02
47.3188088920824,0.0040594669846709,206.592337498654,150.0,8.333333333333333e-05,0.67,0.28,0.23,0.05,0.9,0.05,0.03,0.02
47.953295534305205,0.0041123408715228,208.236815881662,150.0,8.333333333333333e-05,0.67,0.28,0.23,0.05,0.9,0.05,0.03,0.02
48.5645456186976,0.0041632783785555,209.866886105291,150.0,8.333333333333333e-05,0.67,0.28,0.23,0.05,0.9,0.05,0.03,0.02
49.368043780182006,0.0042302365586792,211.485364655326,150.0,8.333333333333333e-05,0.67,0.28,0.23,0.05,0.9,0.05,0.03,0.02
50.2397727633216,0.0043028806406075,213.092661632951,150.0,8.333333333333333e-05,0.67,0.28,0.23,0.05,0.9,0.05,0.03,0.02
51.0585347601432,0.0043711108070093,214.65195799665,150.0,8.333333333333333e-05,0.67,0.28,0.23,0.05,0.9,0.05,0.03,0.02
51.9939106058256,0.0044490587941495,216.162471996479,150.0,8.333333333333333e-05,0.67,0.28,0.23,0.05,0.9,0.05,0.03,0.02
52.87531594736281,0.0045225092392776,217.665556706581,150.0,8.333333333333333e-05,0.67,0.28,0.23,0.05,0.9,0.05,0.03,0.02
53.8333865593116,0.00460234845694,219.122645437831,150.0,8.333333333333333e-05,0.67,0.28,0.23,0.05,0.9,0.05,0.03,0.02
55.02247082682361,0.004701438812566,220.536326887715,150.0,8.333333333333333e-05,0.67,0.28,0.23,0.05,0.9,0.05,0.03,0.02
56.15355526703521,0.0047956958492503,221.786613409216,150.0,8.333333333333333e-05,0.67,0.28,0.23,0.05,0.9,0.05,0.03,0.02
57.41940368617201,0.0049011832175117,222.993217013018,150.0,8.333333333333333e-05,0.67,0.28,0.23,0.05,0.9,0.05,0.03,0.02
58.68415939497721,0.0050065795265788,224.1302449983,150.0,8.333333333333333e-05,0.67,0.28,0.23,0.05,0.9,0.05,0.03,0.02
59.954271022641606,0.0051124221622175,225.122329381696,150.0,8.333333333333333e-05,0.67,0.28,0.23,0.05,0.9,0.05,0.03,0.02
61.4308022352924,0.0052354664299384,226.027102689995,150.0,8.333333333333333e-05,0.67,0.28,0.23,0.05,0.9,0.05,0.03,0.02
62.9820913288032,0.0053647405210643,226.814273572013,150.0,8.333333333333333e-05,0.67,0.28,0.23,0.05,0.9,0.05,0.03,0.02
64.51408922478599,0.0054924070123962,227.487148936154,150.0,8.333333333333333e-05,0.67,0.28,0.23,0.05,0.9,0.05,0.03,0.02
66.25199865161879,0.0056372327979656,228.110196808734,150.0,8.333333333333333e-05,0.67,0.28,0.23,0.05,0.9,0.05,0.03,0.02
67.9801989176448,0.0057812494868011,228.63126311305,150.0,8.333333333333333e-05,0.67,0.28,0.23,0.05,0.9,0.05,0.03,0.02
69.86561483949,0.0059383674802882,229.086382957853,150.0,8.333333333333333e-05,0.67,0.28,0.23,0.05,0.9,0.05,0.03,0.02
71.8184215555956,0.006101101373297,229.486024734614,150.0,8.333333333333333e-05,0.67,0.28,0.23,0.05,0.9,0.05,0.03,0.02
73.7660964295368,0.0062634076127921,229.838222516444,150.0,8.333333333333333e-05,0.67,0.28,0.23,0.05,0.9,0.05,0.03,0.02
75.760256856138,0.0064295876483422,230.11787931935,150.0,8.333333333333333e-05,0.67,0.28,0.23,0.05,0.9,0.05,0.03,0.02
77.8275867137376,0.0066018651364755,230.334518943354,150.0,8.333333333333333e-05,0.67,0.28,0.23,0.05,0.9,0.05,0.03,0.02
79.795393129752,0.0067658490044767,230.52271481478,150.0,8.333333333333333e-05,0.67,0.28,0.23,0.05,0.9,0.05,0.03,0.02
81.802467401706,0.0069331051938062,230.637407242019,150.0,8.333333333333333e-05,0.67,0.28,0.23,0.05,0.9,0.05,0.03,0.02
83.762220559656,0.0070964179569687,230.698525209706,150.0,8.333333333333333e-05,0.67,0.28,0.23,0.05,0.9,0.05,0.03,0.02
85.75702727740199,0.0072626518501142,230.786025494137,150.0,8.333333333333333e-05,0.67,0.28,0.23,0.05,0.9,0.05,0.03,0.02
87.81483442686479,0.0074341357792361,230.806377597784,150.0,8.333333333333333e-05,0.67,0.28,0.23,0.05,0.9,0.05,0.03,0.02
89.89604923593359,0.0076075703466585,230.852426122482,150.0,8.333333333333333e-05,0.67,0.28,0.23,0.05,0.9,0.05,0.03,0.02
91.9141507024092,0.0077757454688648,230.932082950895,150.0,8.333333333333333e-05,0.67,0.28,0.23,0.05,0.9,0.05,0.03,0.02
93.912491441472,0.0079422738637867,231.019132356541,150.0,8.333333333333333e-05,0.67,0.28,0.23,0.05,0.9,0.05,0.03,0.02
95.977625388882,0.0081143683594042,231.113010665805,150.0,8.333333333333333e-05,0.67,0.28,0.23,0.05,0.9,0.05,0.03,0.02
98.0968282454736,0.0082909685974535,231.215883615337,150.0,8.333333333333333e-05,0.67,0.28,0.23,0.05,0.9,0.05,0.03,0.02
100.26611342199598,0.0084717423621637,231.310426640617,150.0,8.333333333333333e-05,0.67,0.28,0.23,0.05,0.9,0.05,0.03,0.02
102.394561596192,0.0086491130433467,231.430146955508,150.0,8.333333333333333e-05,0.67,0.28,0.23,0.05,0.9,0.05,0.03,0.02
104.470033664202,0.0088220690490142,231.546005324756,150.0,8.333333333333333e-05,0.67,0.28,0.23,0.05,0.9,0.05,0.03,0.02
106.6198120184892,0.0090012172452048,231.628351102183,150.0,8.333333333333333e-05,0.67,0.28,0.23,0.05,0.9,0.05,0.03,0.02
108.860134965432,0.0091879108241167,231.714543150075,150.0,8.333333333333333e-05,0.67,0.28,0.23,0.05,0.9,0.05,0.03,0.02
111.0634977615888,0.0093715243904631,231.820531774031,150.0,8.333333333333333e-05,0.67,0.28,0.23,0.05,0.9,0.05,0.03,0.02
113.2999296277116,0.00955789371264,231.906333192123,150.0,8.333333333333333e-05,0.67,0.28,0.23,0.05,0.9,0.05,0.03,0.02
115.5270346174632,0.0097434857951193,231.993657285051,150.0,8.333333333333333e-05,0.67,0.28,0.23,0.05,0.9,0.05,0.03,0.02
117.6781197307692,0.0099227428878948,232.063660878566,150.0,8.333333333333333e-05,0.67,0.28,0.23,0.05,0.9,0.05,0.03,0.02
119.9507490499092,0.0101121286644898,232.1344865251,150.0,8.333333333333333e-05,0.67,0.28,0.23,0.05,0.9,0.05,0.03,0.02
122.1675632208324,0.0102968631787334,232.191501883378,150.0,8.333333333333333e-05,0.67,0.28,0.23,0.05,0.9,0.05,0.03,0.02
124.3716415443852,0.0104805363723628,232.238491234952,150.0,8.333333333333333e-05,0.67,0.28,0.23,0.05,0.9,0.05,0.03,0.02
126.5645163962436,0.010663275943351,232.282545026352,150.0,8.333333333333333e-05,0.67,0.28,0.23,0.05,0.9,0.05,0.03,0.02
128.7884238544992,0.0108486015648723,232.36163267665,150.0,8.333333333333333e-05,0.67,0.28,0.23,0.05,0.9,0.05,0.03,0.02
130.99069394337602,0.0110321240722787,232.408121260939,150.0,8.333333333333333e-05,0.67,0.28,0.23,0.05,0.9,0.05,0.03,0.02
133.2053305582836,0.011216677123521,232.479093583459,150.0,8.333333333333333e-05,0.67,0.28,0.23,0.05,0.9,0.05,0.03,0.02
135.402922965216,0.0113998098240987,232.561683789227,150.0,8.333333333333333e-05,0.67,0.28,0.23,0.05,0.9,0.05,0.03,0.02
137.61964752471482,0.0115845368707236,232.636783981757,150.0,8.333333333333333e-05,0.67,0.28,0.23,0.05,0.9,0.05,0.03,0.02
139.8178354193676,0.011767719195278,232.720319395857,150.0,8.333333333333333e-05,0.67,0.28,0.23,0.05,0.9,0.05,0.03,0.02
142.034908107504,0.0119524752526227,232.789279554158,150.0,8.333333333333333e-05,0.67,0.28,0.23,0.05,0.9,0.05,0.03,0.02
144.26072750668922,0.0121379602025548,232.829784365629,150.0,8.333333333333333e-05,0.67,0.28,0.23,0.05,0.9,0.05,0.03,0.02
146.46289198255204,0.0123214739088767,232.885364725658,150.0,8.333333333333333e-05,0.67,0.28,0.23,0.05,0.9,0.05,0.03,0.02
148.68604035669722,0.0125067362733888,232.936965615773,150.0,8.333333333333333e-05,0.67,0.28,0.23,0.05,0.9,0.05,0.03,0.02
150.89682511750803,0.0126909683367897,233.010191224988,150.0,8.333333333333333e-05,0.67,0.28,0.23,0.05,0.9,0.05,0.03,0.02
153.11532768339725,0.0128758435506138,233.095403851223,150.0,8.333333333333333e-05,0.67,0.28,0.23,0.05,0.9,0.05,0.03,0.02
155.3250938499924,0.0130599907311634,233.161470176004,150.0,8.333333333333333e-05,0.67,0.28,0.23,0.05,0.9,0.05,0.03,0.02
157.58888969904723,0.0132486403852513,233.236280132617,150.0,8.333333333333333e-05,0.67,0.28,0.23,0.05,0.9,0.05,0.03,0.02
159.68660727255602,0.0134234501830437,233.3389383275,150.0,8.333333333333333e-05,0.67,0.28,0.23,0.05,0.9,0.05,0.03,0.02
161.8379906440848,0.0136027321306711,233.396985795638,150.0,8.333333333333333e-05,0.67,0.28,0.23,0.05,0.9,0.05,0.03,0.02
164.062996687488,0.0137881493009547,233.467205092853,150.0,8.333333333333333e-05,0.67,0.28,0.23,0.05,0.9,0.05,0.03,0.02
166.24277573038802,0.0139697975545297,233.5189650599,150.0,8.333333333333333e-05,0.67,0.28,0.23,0.05,0.9,0.05,0.03,0.02
168.40841071399322,0.0141502671364968,233.557250624007,150.0,8.333333333333333e-05,0.67,0.28,0.23,0.05,0.9,0.05,0.03,0.02
170.65243918931282,0.0143372695094401,233.615680417741,150.0,8.333333333333333e-05,0.67,0.28,0.23,0.05,0.9,0.05,0.03,0.02
172.7878419922116,0.014515219743015,233.650674289914,150.0,8.333333333333333e-05,0.67,0.28,0.23,0.05,0.9,0.05,0.03,0.02
175.060143924684,0.0147045782373877,233.667559142827,150.0,8.333333333333333e-05,0.67,0.28,0.23,0.05,0.9,0.05,0.03,0.02
177.24638164618082,0.0148867647141791,233.7218114944,150.0,8.333333333333333e-05,0.67,0.28,0.23,0.05,0.9,0.05,0.03,0.02
179.4080083571712,0.0150669002734283,233.762342974233,150.0,8.333333333333333e-05,0.67,0.28,0.23,0.05,0.9,0.05,0.03,0.02
181.58667923802363,0.015248456180166,233.805246198266,150.0,8.333333333333333e-05,0.67,0.28,0.23,0.05,0.9,0.05,0.03,0.02
183.7273607364852,0.0154268463050378,233.855306508098,150.0,8.333333333333333e-05,0.67,0.28,0.23,0.05,0.9,0.05,0.03,0.02
185.9401036956012,0.0156112415516308,233.901693591277,150.0,8.333333333333333e-05,0.67,0.28,0.23,0.05,0.9,0.05,0.03,0.02
188.1429994923012,0.0157948162013558,233.97441969861,150.0,8.333333333333333e-05,0.67,0.28,0.23,0.05,0.9,0.05,0.03,0.02
190.290170638578,0.0159737471302122,234.056191299581,150.0,8.333333333333333e-05,0.67,0.28,0.23,0.05,0.9,0.05,0.03,0.02
192.5008386401784,0.0161579694636789,234.149281595157,150.0,8.333333333333333e-05,0.67,0.28,0.23,0.05,0.9,0.05,0.03,0.02
194.7334228514184,0.0163440181479489,234.235790230977,150.0,8.333333333333333e-05,0.67,0.28,0.23,0.05,0.9,0.05,0.03,0.02
196.9148757429036,0.016525805888906,234.322611215626,150.0,8.333333333333333e-05,0.67,0.28,0.23,0.05,0.9,0.05,0.03,0.02
199.2181184218608,0.0167177427788191,234.42853944824,150.0,8.333333333333333e-05,0.67,0.28,0.23,0.05,0.9,0.05,0.03,0.02
201.4033737564912,0.0168998473900383,234.518570553803,150.0,8.333333333333333e-05,0.67,0.28,0.23,0.05,0.9,0.05,0.03,0.02
203.6526117510552,0.0170872838895853,234.573350182847,150.0,8.333333333333333e-05,0.67,0.28,0.23,0.05,0.9,0.05,0.03,0.02
205.93163528265123,0.0172772025172183,234.617487585728,150.0,8.333333333333333e-05,0.67,0.28,0.23,0.05,0.9,0.05,0.03,0.02
208.1678871104508,0.0174635568362016,234.656636613157,150.0,8.333333333333333e-05,0.67,0.28,0.23,0.05,0.9,0.05,0.03,0.02
210.36879308079844,0.0176469656670639,234.701677339543,150.0,8.333333333333333e-05,0.67,0.28,0.23,0.05,0.9,0.05,0.03,0.02
212.6178335476104,0.0178343857059649,234.729815007036,150.0,8.333333333333333e-05,0.67,0.28,0.23,0.05,0.9,0.05,0.03,0.02
214.8136806617628,0.0180173729654776,234.759637589802,150.0,8.333333333333333e-05,0.67,0.28,0.23,0.05,0.9,0.05,0.03,0.02
217.0389824692632,0.0182028147827693,234.797591491873,150.0,8.333333333333333e-05,0.67,0.28,0.23,0.05,0.9,0.05,0.03,0.02
219.21729234656283,0.0183843406058776,234.861002432446,150.0,8.333333333333333e-05,0.67,0.28,0.23,0.05,0.9,0.05,0.03,0.02
221.4233014656444,0.0185681746991344,234.930545403577,150.0,8.333333333333333e-05,0.67,0.28,0.23,0.05,0.9,0.05,0.03,0.02
223.6606295811864,0.0187546187087629,234.994003100778,150.0,8.333333333333333e-05,0.67,0.28,0.23,0.05,0.9,0.05,0.03,0.02
225.89980573245003,0.0189412167213682,235.046411143796,150.0,8.333333333333333e-05,0.67,0.28,0.23,0.05,0.9,0.05,0.03,0.02
228.18949424911443,0.0191320240977569,235.098383524496,150.0,8.333333333333333e-05,0.67,0.28,0.23,0.05,0.9,0.05,0.03,0.02
230.40798035700243,0.0193168979400809,235.147564822371,150.0,8.333333333333333e-05,0.67,0.28,0.23,0.05,0.9,0.05,0.03,0.02
232.62690139553283,0.0195018080266251,235.199931455087,150.0,8.333333333333333e-05,0.67,0.28,0.23,0.05,0.9,0.05,0.03,0.02
234.8441915242788,0.0196865822040206,235.244721805739,150.0,8.333333333333333e-05,0.67,0.28,0.23,0.05,0.9,0.05,0.03,0.02
236.996948416098,0.0198659786116722,235.295391138052,150.0,8.333333333333333e-05,0.67,0.28,0.23,0.05,0.9,0.05,0.03,0.02
239.3073851098092,0.0200585150028148,235.331680545285,150.0,8.333333333333333e-05,0.67,0.28,0.23,0.05,0.9,0.05,0.03,0.02
241.51055117154243,0.0202421121746259,235.378553811982,150.0,8.333333333333333e-05,0.67,0.28,0.23,0.05,0.9,0.05,0.03,0.02
243.7281464571444,0.0204269117817594,235.44984900199,150.0,8.333333333333333e-05,0.67,0.28,0.23,0.05,0.9,0.05,0.03,0.02
245.9955536005068,0.0206158623770396,235.500490574533,150.0,8.333333333333333e-05,0.67,0.28,0.23,0.05,0.9,0.05,0.03,0.02
248.270708508582,0.0208054586193792,235.543960287701,150.0,8.333333333333333e-05,0.67,0.28,0.23,0.05,0.9,0.05,0.03,0.02
250.5431431881924,0.0209948281760134,235.601665764953,150.0,8.333333333333333e-05,0.67,0.28,0.23,0.05,0.9,0.05,0.03,0.02
252.8631992834208,0.0211881661839491,235.631593613404,150.0,8.333333333333333e-05,0.67,0.28,0.23,0.05,0.9,0.05,0.03,0.02
255.0897163320024,0.0213737092713309,235.671933368916,150.0,8.333333333333333e-05,0.67,0.28,0.23,0.05,0.9,0.05,0.03,0.02
257.2989046974432,0.0215578083017843,235.701349615071,150.0,8.333333333333333e-05,0.67,0.28,0.23,0.05,0.9,0.05,0.03,0.02
259.5069312476988,0.0217418105143056,235.727463508276,150.0,8.333333333333333e-05,0.67,0.28,0.23,0.05,0.9,0.05,0.03,0.02
261.70657000833364,0.0219251137443585,235.746346257992,150.0,8.333333333333333e-05,0.67,0.28,0.23,0.05,0.9,0.05,0.03,0.02
263.8809021636876,0.022106308090638,235.747484756581,150.0,8.333333333333333e-05,0.67,0.28,0.23,0.05,0.9,0.05,0.03,0.02
266.1067758235848,0.0222917975622961,235.747310763716,150.0,8.333333333333333e-05,0.67,0.28,0.23,0.05,0.9,0.05,0.03,0.02
268.2888837564324,0.0224736398900334,235.773502779717,150.0,8.333333333333333e-05,0.67,0.28,0.23,0.05,0.9,0.05,0.03,0.02
270.4673635344684,0.0226551798715364,235.796199326503,150.0,8.333333333333333e-05,0.67,0.28,0.23,0.05,0.9,0.05,0.03,0.02
272.70725335301046,0.0228418373564149,235.837157215396,150.0,8.333333333333333e-05,0.67,0.28,0.23,0.05,0.9,0.05,0.03,0.02
274.8906845662344,0.0230237899575169,235.868800095704,150.0,8.333333333333333e-05,0.67,0.28,0.23,0.05,0.9,0.05,0.03,0.02
277.1079361543884,0.0232085609231964,235.931614256566,150.0,8.333333333333333e-05,0.67,0.28,0.23,0.05,0.9,0.05,0.03,0.02
279.294447223848,0.0233907701789847,235.982603925562,150.0,8.333333333333333e-05,0.67,0.28,0.23,0.05,0.9,0.05,0.03,0.02
281.5342683670692,0.0235774219409198,236.036387366364,150.0,8.333333333333333e-05,0.67,0.28,0.23,0.05,0.9,0.05,0.03,0.02
283.71939717988323,0.0237595160086543,236.062675394792,150.0,8.333333333333333e-05,0.67,0.28,0.23,0.05,0.9,0.05,0.03,0.02
285.8900299099836,0.023940402069496,236.088553654204,150.0,8.333333333333333e-05,0.67,0.28,0.23,0.05,0.9,0.05,0.03,0.02
288.1117970639688,0.0241255493323281,236.122493904672,150.0,8.333333333333333e-05,0.67,0.28,0.23,0.05,0.9,0.05,0.03,0.02
290.35589055492846,0.0243125571232414,236.148074715372,150.0,8.333333333333333e-05,0.67,0.28,0.23,0.05,0.9,0.05,0.03,0.02
292.5630930217752,0.0244964906621453,236.162385770913,150.0,8.333333333333333e-05,0.67,0.28,0.23,0.05,0.9,0.05,0.03,0.02
294.7890921391284,0.0246819905885914,236.200898822783,150.0,8.333333333333333e-05,0.67,0.28,0.23,0.05,0.9,0.05,0.03,0.02
296.9854445446416,0.0248650199557175,236.224215195427,150.0,8.333333333333333e-05,0.67,0.28,0.23,0.05,0.9,0.05,0.03,0.02
299.21278791963965,0.025050631903634,236.276560347932,150.0,8.333333333333333e-05,0.67,0.28,0.23,0.05,0.9,0.05,0.03,0.02
301.468659001944,0.0252386211604927,236.326581604274,150.0,8.333333333333333e-05,0.67,0.28,0.23,0.05,0.9,0.05,0.03,0.02
303.72039551973603,0.0254262658703087,236.350673763652,150.0,8.333333333333333e-05,0.67,0.28,0.23,0.05,0.9,0.05,0.03,0.02
305.87693489457723,0.0256059774848788,236.385488945153,150.0,8.333333333333333e-05,0.67,0.28,0.23,0.05,0.9,0.05,0.03,0.02
308.078175308676,0.0257894141860537,236.419177253952,150.0,8.333333333333333e-05,0.67,0.28,0.23,0.05,0.9,0.05,0.03,0.02
310.33268367283443,0.0259772898830669,236.479952898585,150.0,8.333333333333333e-05,0.67,0.28,0.23,0.05,0.9,0.05,0.03,0.02
312.5140239542544,0.0261590682398519,236.529408124501,150.0,8.333333333333333e-05,0.67,0.28,0.23,0.05,0.9,0.05,0.03,0.02
314.6425905615552,0.0263364487904603,236.565290720596,150.0,8.333333333333333e-05,0.67,0.28,0.23,0.05,0.9,0.05,0.03,0.02
316.8657368947392,0.0265217109848923,236.616652512878,150.0,8.333333333333333e-05,0.67,0.28,0.23,0.05,0.9,0.05,0.03,0.02
319.0935437791248,0.0267073615585911,236.660331349654,150.0,8.333333333333333e-05,0.67,0.28,0.23,0.05,0.9,0.05,0.03,0.02
321.346642413216,0.0268951197780987,236.703090855581,150.0,8.333333333333333e-05,0.67,0.28,0.23,0.05,0.9,0.05,0.03,0.02
323.6060120398344,0.0270834005803169,236.741801405171,150.0,8.333333333333333e-05,0.67,0.28,0.23,0.05,0.9,0.05,0.03,0.02
325.82718005127725,0.0272684979146038,236.75246590242,150.0,8.333333333333333e-05,0.67,0.28,0.23,0.05,0.9,0.05,0.03,0.02
328.08137221323125,0.0274563472614333,236.758316966135,150.0,8.333333333333333e-05,0.67,0.28,0.23,0.05,0.9,0.05,0.03,0.02
330.3911408839848,0.0276488279839961,236.764887648524,150.0,8.333333333333333e-05,0.67,0.28,0.23,0.05,0.9,0.05,0.03,0.02
332.5767750372324,0.0278309641634334,236.778893267498,150.0,8.333333333333333e-05,0.67,0.28,0.23,0.05,0.9,0.05,0.03,0.02
334.7920101461916,0.02801556708918,236.823937916633,150.0,8.333333333333333e-05,0.67,0.28,0.23,0.05,0.9,0.05,0.03,0.02
337.05313746981244,0.0282039943661484,236.839631108227,150.0,8.333333333333333e-05,0.67,0.28,0.23,0.05,0.9,0.05,0.03,0.02
339.28509948531723,0.0283899912007738,236.880985115604,150.0,8.333333333333333e-05,0.67,0.28,0.23,0.05,0.9,0.05,0.03,0.02
341.50985287122484,0.0285753873162661,236.893239923462,150.0,8.333333333333333e-05,0.67,0.28,0.23,0.05,0.9,0.05,0.03,0.02
343.76442309720005,0.0287632681684307,236.915344862871,150.0,8.333333333333333e-05,0.67,0.28,0.23,0.05,0.9,0.05,0.03,0.02
346.0664787142176,0.0289551061365155,236.942256339371,150.0,8.333333333333333e-05,0.67,0.28,0.23,0.05,0.9,0.05,0.03,0.02
348.3285297551988,0.0291436103899306,236.960524103395,150.0,8.333333333333333e-05,0.67,0.28,0.23,0.05,0.9,0.05,0.03,0.02
350.61252496052526,0.0293339433237078,236.959411498108,150.0,8.333333333333333e-05,0.67,0.28,0.23,0.05,0.9,0.05,0.03,0.02
352.8732094155312,0.0295223336949583,236.964930915604,150.0,8.333333333333333e-05,0.67,0.28,0.23,0.05,0.9,0.05,0.03,0.02
355.19013307941003,0.0297154106669482,236.971220773507,150.0,8.333333333333333e-05,0.67,0.28,0.23,0.05,0.9,0.05,0.03,0.02
357.4515916901568,0.0299038655511771,237.004564244265,150.0,8.333333333333333e-05,0.67,0.28,0.23,0.05,0.9,0.05,0.03,0.02
359.69996179528925,0.0300912297266048,237.018634019154,150.0,8.333333333333333e-05,0.67,0.28,0.23,0.05,0.9,0.05,0.03,0.02
362.036891817294,0.0302859738951052,237.048254374759,150.0,8.333333333333333e-05,0.67,0.28,0.23,0.05,0.9,0.05,0.03,0.02
364.30078849253766,0.0304746319513755,237.075789315148,150.0,8.333333333333333e-05,0.67,0.28,0.23,0.05,0.9,0.05,0.03,0.02
366.51335765799365,0.0306590127151635,237.09118614944,150.0,8.333333333333333e-05,0.67,0.28,0.23,0.05,0.9,0.05,0.03,0.02
368.8192776097045,0.0308511727111394,237.141141351763,150.0,8.333333333333333e-05,0.67,0.28,0.23,0.05,0.9,0.05,0.03,0.02
371.0765719531704,0.0310392805730949,237.149178398569,150.0,8.333333333333333e-05,0.67,0.28,0.23,0.05,0.9,0.05,0.03,0.02
373.3434507354396,0.031228187138284,237.175077220774,150.0,8.333333333333333e-05,0.67,0.28,0.23,0.05,0.9,0.05,0.03,0.02
375.59896539835086,0.0314161466935266,237.214132434413,150.0,8.333333333333333e-05,0.67,0.28,0.23,0.05,0.9,0.05,0.03,0.02
377.7547441872792,0.0315957949259373,237.235169642877,150.0,8.333333333333333e-05,0.67,0.28,0.23,0.05,0.9,0.05,0.03,0.02
380.0055454067724,0.0317833616942284,237.241180242232,150.0,8.333333333333333e-05,0.67,0.28,0.23,0.05,0.9,0.05,0.03,0.02
382.2471327782581,0.0319701606418522,237.239454074831,150.0,8.333333333333333e-05,0.67,0.28,0.23,0.05,0.9,0.05,0.03,0.02
384.4631141784888,0.0321548257585381,237.224440183019,150.0,8.333333333333333e-05,0.67,0.28,0.23,0.05,0.9,0.05,0.03,0.02
386.6227041226692,0.0323347915872198,237.201301551996,150.0,8.333333333333333e-05,0.67,0.28,0.23,0.05,0.9,0.05,0.03,0.02
388.83773007872526,0.0325193770835578,237.158410254382,150.0,8.333333333333333e-05,0.67,0.28,0.23,0.05,0.9,0.05,0.03,0.02
391.0136001440388,0.0327006995890006,237.131445899869,150.0,8.333333333333333e-05,0.67,0.28,0.23,0.05,0.9,0.05,0.03,0.02
393.2746749470989,0.0328891224892556,237.118665380477,150.0,8.333333333333333e-05,0.67,0.28,0.23,0.05,0.9,0.05,0.03,0.02
395.4752008348548,0.0330724996465686,237.11237631345,150.0,8.333333333333333e-05,0.67,0.28,0.23,0.05,0.9,0.05,0.03,0.02
397.674711845952,0.0332557922308267,237.124125814391,150.0,8.333333333333333e-05,0.67,0.28,0.23,0.05,0.9,0.05,0.03,0.02
399.8785241248848,0.0334394432540711,237.133171766736,150.0,8.333333333333333e-05,0.67,0.28,0.23,0.05,0.9,0.05,0.03,0.02
402.13106705318165,0.0336271551647625,237.166990111476,150.0,8.333333333333333e-05,0.67,0.28,0.23,0.05,0.9,0.05,0.03,0.02
404.35744864640407,0.0338126869641977,237.20393637341,150.0,8.333333333333333e-05,0.67,0.28,0.23,0.05,0.9,0.05,0.03,0.02
406.6586533406005,0.0340044540220474,237.243728478469,150.0,8.333333333333333e-05,0.67,0.28,0.23,0.05,0.9,0.05,0.03,0.02
408.87178492453086,0.0341888816540416,237.272636111844,150.0,8.333333333333333e-05,0.67,0.28,0.23,0.05,0.9,0.05,0.03,0.02
411.1377972149713,0.0343777160115783,237.296468325882,150.0,8.333333333333333e-05,0.67,0.28,0.23,0.05,0.9,0.05,0.03,0.02
413.47450103213527,0.0345724413296753,237.323422319911,150.0,8.333333333333333e-05,0.67,0.28,0.23,0.05,0.9,0.05,0.03,0.02
415.7905708495345,0.0347654471477919,237.347080541082,150.0,8.333333333333333e-05,0.67,0.28,0.23,0.05,0.9,0.05,0.03,0.02
418.0943645568384,0.0349574299567339,237.37914245948,150.0,8.333333333333333e-05,0.67,0.28,0.23,0.05,0.9,0.05,0.03,0.02
420.425129666976,0.0351516603825787,237.411435772571,150.0,8.333333333333333e-05,0.67,0.28,0.23,0.05,0.9,0.05,0.03,0.02
422.7269249806092,0.0353434766587148,237.44118774587,150.0,8.333333333333333e-05,0.67,0.28,0.23,0.05,0.9,0.05,0.03,0.02
425.0045200153429,0.0355332762449426,237.462423100572,150.0,8.333333333333333e-05,0.67,0.28,0.23,0.05,0.9,0.05,0.03,0.02
427.25926365999845,0.0357211715486639,237.469174023752,150.0,8.333333333333333e-05,0.67,0.28,0.23,0.05,0.9,0.05,0.03,0.02
429.5229238704192,0.0359098098995323,237.472875500519,150.0,8.333333333333333e-05,0.67,0.28,0.23,0.05,0.9,0.05,0.03,0.02
431.7639294987552,0.0360965603685603,237.474810791526,150.0,8.333333333333333e-05,0.67,0.28,0.23,0.05,0.9,0.05,0.03,0.02
434.0156793346344,0.0362842061882169,237.447856322971,150.0,8.333333333333333e-05,0.67,0.28,0.23,0.05,0.9,0.05,0.03,0.02
436.2977691799404,0.0364743803419924,237.445111664606,150.0,8.333333333333333e-05,0.67,0.28,0.23,0.05,0.9,0.05,0.03,0.02
438.522818895738,0.0366598011516422,237.414455418751,150.0,8.333333333333333e-05,0.67,0.28,0.23,0.05,0.9,0.05,0.03,0.02
440.8422560993485,0.0368530875852764,237.386757019974,150.0,8.333333333333333e-05,0.67,0.28,0.23,0.05,0.9,0.05,0.03,0.02
443.1672722946564,0.0370468389348854,237.368797682029,150.0,8.333333333333333e-05,0.67,0.28,0.23,0.05,0.9,0.05,0.03,0.02
445.4326321971312,0.0372356189267583,237.351314309477,150.0,8.333333333333333e-05,0.67,0.28,0.23,0.05,0.9,0.05,0.03,0.02
447.7331757645732,0.0374273308907118,237.354376805355,150.0,8.333333333333333e-05,0.67,0.28,0.23,0.05,0.9,0.05,0.03,0.02
450.0705856776409,0.0376221150501341,237.364068160508,150.0,8.333333333333333e-05,0.67,0.28,0.23,0.05,0.9,0.05,0.03,0.02
452.30198774759646,0.0378080652226304,237.358919316181,150.0,8.333333333333333e-05,0.67,0.28,0.23,0.05,0.9,0.05,0.03,0.02
454.5764806914252,0.0379976063012828,237.358637874812,150.0,8.333333333333333e-05,0.67,0.28,0.23,0.05,0.9,0.05,0.03,0.02
456.7384423168632,0.0381777697700693,237.367811363928,150.0,8.333333333333333e-05,0.67,0.28,0.23,0.05,0.9,0.05,0.03,0.02
459.1714899408853,0.0383805237387378,237.403339568191,150.0,8.333333333333333e-05,0.67,0.28,0.23,0.05,0.9,0.05,0.03,0.02
461.498746350354,0.0385744617728602,237.456856926449,150.0,8.333333333333333e-05,0.67,0.28,0.23,0.05,0.9,0.05,0.03,0.02
463.8753272203128,0.0387725101786901,237.483660321744,150.0,8.333333333333333e-05,0.67,0.28,0.23,0.05,0.9,0.05,0.03,0.02
466.153782885102,0.0389623814840892,237.503976661949,150.0,8.333333333333333e-05,0.67,0.28,0.23,0.05,0.9,0.05,0.03,0.02
468.488930488026,0.0391569771176662,237.512971618567,150.0,8.333333333333333e-05,0.67,0.28,0.23,0.05,0.9,0.05,0.03,0.02
470.8611362642581,0.0393546609323522,237.538604516404,150.0,8.333333333333333e-05,0.67,0.28,0.23,0.05,0.9,0.05,0.03,0.02
473.3125718862528,0.0395589472341851,237.543694076616,150.0,8.333333333333333e-05,0.67,0.28,0.23,0.05,0.9,0.05,0.03,0.02
475.5453616560804,0.0397450130483374,237.543726708187,150.0,8.333333333333333e-05,0.67,0.28,0.23,0.05,0.9,0.05,0.03,0.02