File: datasets/al_6061_comp/csv/T_200_D_1.csv
Time,Strain(%),Stress(MPa),Temp(C),SR(%/s),Si(%),Fe(%),Cu(%),Mn(%),Mg(%),Cr(%),Zn(%),Ti(%)
0.0,8.50507939660103e-05,24.307482339330907,200.0,8.333333333333333e-05,0.67,0.28,0.23,0.05,0.9,0.05,0.03,0.02
0.17754558635276907,9.984625949540773e-05,25.20185322656261,200.0,8.333333333333333e-05,0.67,0.28,0.23,0.05,0.9,0.05,0.03,0.02
0.35509117270553814,0.00011464172502480514,26.096224113794307,200.0,8.333333333333333e-05,0.67,0.28,0.23,0.05,0.9,0.05,0.03,0.02
0.5326367590583072,0.00012943719055420256,26.990595001026,200.0,8.333333333333333e-05,0.67,0.28,0.23,0.05,0.9,0.05,0.03,0.02
0.7101823454110763,0.0001442326560836,27.884965888257707,200.0,8.333333333333333e-05,0.67,0.28,0.23,0.05,0.9,0.05,0.03,0.02
0.9111781525096765,0.00016098230667515,28.80621021106316,200.0,8.333333333333333e-05,0.67,0.28,0.23,0.05,0.9,0.05,0.03,0.02
1.1121739596082767,0.0001777319572667,29.727454533868595,200.0,8.333333333333333e-05,0.67,0.28,0.23,0.05,0.9,0.05,0.03,0.02
1.313169766706877,0.00019448160785825,30.648698856674038,200.0,8.333333333333333e-05,0.67,0.28,0.23,0.05,0.9,0.05,0.03,0.02
1.514165573805477,0.0002112312584498,31.569943179479488,200.0,8.333333333333333e-05,0.67,0.28,0.23,0.05,0.9,0.05,0.03,0.02
1.721609072541777,0.000228518216677825,32.52337680367306,200.0,8.333333333333333e-05,0.67,0.28,0.23,0.05,0.9,0.05,0.03,0.02
1.9290525712780768,0.00024580517490585,33.47681042786661,200.0,8.333333333333333e-05,0.67,0.28,0.23,0.05,0.9,0.05,0.03,0.02
2.1364960700143767,0.000263092133133875,34.43024405206019,200.0,8.333333333333333e-05,0.67,0.28,0.23,0.05,0.9,0.05,0.03,0.02
2.3439395687506765,0.0002803790913619,35.383677676253804,200.0,8.333333333333333e-05,0.67,0.28,0.23,0.05,0.9,0.05,0.03,0.02
2.5636337895586765,0.00029868694309590003,36.380122345358956,200.0,8.333333333333333e-05,0.67,0.28,0.23,0.05,0.9,0.05,0.03,0.02
2.7833280103666764,0.0003169947948299,37.3765670144641,200.0,8.333333333333333e-05,0.67,0.28,0.23,0.05,0.9,0.05,0.03,0.02
3.0030222311746764,0.00033530264656389996,38.37301168356924,200.0,8.333333333333333e-05,0.67,0.28,0.23,0.05,0.9,0.05,0.03,0.02
3.222716451982676,0.0003536104982979,39.36945635267439,200.0,8.333333333333333e-05,0.67,0.28,0.23,0.05,0.9,0.05,0.03,0.02
3.447904009614776,0.00037237612810057496,40.39730444466049,200.0,8.333333333333333e-05,0.67,0.28,0.23,0.05,0.9,0.05,0.03,0.02
3.6730915672468756,0.00039114175790325,41.425152536646564,200.0,8.333333333333333e-05,0.67,0.28,0.23,0.05,0.9,0.05,0.03,0.02
3.8982791248789757,0.000409907387705925,42.453000628632665,200.0,8.333333333333333e-05,0.67,0.28,0.23,0.05,0.9,0.05,0.03,0.02
4.123466682511076,0.0004286730175086,43.48084872061884,200.0,8.333333333333333e-05,0.67,0.28,0.23,0.05,0.9,0.05,0.03,0.02
4.352580954779276,0.00044776587353095,44.52314875029893,200.0,8.333333333333333e-05,0.67,0.28,0.23,0.05,0.9,0.05,0.03,0.02
4.581695227047476,0.0004668587295533,45.56544877997904,200.0,8.333333333333333e-05,0.67,0.28,0.23,0.05,0.9,0.05,0.03,0.02
4.810809499315676,0.00048595158557565,46.60774880965914,200.0,8.333333333333333e-05,0.67,0.28,0.23,0.05,0.9,0.05,0.03,0.02
5.039923771583876,0.000505044441598,47.650048839339114,200.0,8.333333333333333e-05,0.67,0.28,0.23,0.05,0.9,0.05,0.03,0.02
5.268673161332876,0.00052410689074375,48.729253892127815,200.0,8.333333333333333e-05,0.67,0.28,0.23,0.05,0.9,0.05,0.03,0.02
5.497422551081876,0.0005431693398895,49.80845894491662,200.0,8.333333333333333e-05,0.67,0.28,0.23,0.05,0.9,0.05,0.03,0.02
5.726171940830877,0.00056223178903525,50.8876639977053,200.0,8.333333333333333e-05,0.67,0.28,0.23,0.05,0.9,0.05,0.03,0.02
5.954921330579877,0.000581294238181,51.96686905049396,200.0,8.333333333333333e-05,0.67,0.28,0.23,0.05,0.9,0.05,0.03,0.02
6.187102533911277,0.00060064267179195,53.050051698528186,200.0,8.333333333333333e-05,0.67,0.28,0.23,0.05,0.9,0.05,0.03,0.02
6.419283737242677,0.0006199911054029,54.13323434656229,200.0,8.333333333333333e-05,0.67,0.28,0.23,0.05,0.9,0.05,0.03,0.02
6.651464940574076,0.00063933953901385,55.21641699459656,200.0,8.333333333333333e-05,0.67,0.28,0.23,0.05,0.9,0.05,0.03,0.02
6.883646143905477,0.0006586879726248,56.29959964263092,200.0,8.333333333333333e-05,0.67,0.28,0.23,0.05,0.9,0.05,0.03,0.02
7.121128272940076,0.0006784781500443499,57.40465844582252,200.0,8.333333333333333e-05,0.67,0.28,0.23,0.05,0.9,0.05,0.03,0.02
7.358610401974676,0.0006982683274638999,58.50971724901409,200.0,8.333333333333333e-05,0.67,0.28,0.23,0.05,0.9,0.05,0.03,0.02
7.596092531009276,0.0007180585048834499,59.614776052205684,200.0,8.333333333333333e-05,0.67,0.28,0.23,0.05,0.9,0.05,0.03,0.02
7.833574660043876,0.000737848682303,60.71983485539724,200.0,8.333333333333333e-05,0.67,0.28,0.23,0.05,0.9,0.05,0.03,0.02
8.071098396172976,0.0007576423269804249,61.823584911339566,200.0,8.333333333333333e-05,0.67,0.28,0.23,0.05,0.9,0.05,0.03,0.02
8.308622132302077,0.00077743597165785,62.92733496728192,200.0,8.333333333333333e-05,0.67,0.28,0.23,0.05,0.9,0.05,0.03,0.02
8.546145868431177,0.000797229616335275,64.03108502322426,200.0,8.333333333333333e-05,0.67,0.28,0.23,0.05,0.9,0.05,0.03,0.02
8.783669604560277,0.0008170232610127,65.13483507916659,200.0,8.333333333333333e-05,0.67,0.28,0.23,0.05,0.9,0.05,0.03,0.02
9.021994820997177,0.000836883695715775,66.23162614712696,200.0,8.333333333333333e-05,0.67,0.28,0.23,0.05,0.9,0.05,0.03,0.02
9.260320037434077,0.00085674413041885,67.32841721508738,200.0,8.333333333333333e-05,0.67,0.28,0.23,0.05,0.9,0.05,0.03,0.02
9.498645253870976,0.000876604565121925,68.42520828304772,200.0,8.333333333333333e-05,0.67,0.28,0.23,0.05,0.9,0.05,0.03,0.02
9.736970470307876,0.000896464999825,69.52199935100828,200.0,8.333333333333333e-05,0.67,0.28,0.23,0.05,0.9,0.05,0.03,0.02
9.982276091427178,0.0009169071349182749,70.26940153665782,200.0,8.333333333333333e-05,0.67,0.28,0.23,0.05,0.9,0.05,0.03,0.02
10.227581712546478,0.00093734927001155,71.01680372230727,200.0,8.333333333333333e-05,0.67,0.28,0.23,0.05,0.9,0.05,0.03,0.02
10.472887333665778,0.0009577914051048251,71.76420590795688,200.0,8.333333333333333e-05,0.67,0.28,0.23,0.05,0.9,0.05,0.03,0.02
10.718192954785078,0.0009782335401981,72.51160809360624,200.0,8.333333333333333e-05,0.67,0.28,0.23,0.05,0.9,0.05,0.03,0.02
10.967161233756478,0.00099898089677905,73.32729582767345,200.0,8.333333333333333e-05,0.67,0.28,0.23,0.05,0.9,0.05,0.03,0.02
11.216129512727877,0.00101972825336,74.14298356174066,200.0,8.333333333333333e-05,0.67,0.28,0.23,0.05,0.9,0.05,0.03,0.02
11.465097791699275,0.00104047560994095,74.95867129580787,200.0,8.333333333333333e-05,0.67,0.28,0.23,0.05,0.9,0.05,0.03,0.02
11.714066070670675,0.0010612229665219,75.77435902987521,200.0,8.333333333333333e-05,0.67,0.28,0.23,0.05,0.9,0.05,0.03,0.02
11.946403696273077,0.0010805844353220999,76.64355057768067,200.0,8.333333333333333e-05,0.67,0.28,0.23,0.05,0.9,0.05,0.03,0.02
12.178741321875476,0.0010999459041223,77.51274212548633,200.0,8.333333333333333e-05,0.67,0.28,0.23,0.05,0.9,0.05,0.03,0.02
12.411078947477876,0.0011193073729225001,78.38193367329171,200.0,8.333333333333333e-05,0.67,0.28,0.23,0.05,0.9,0.05,0.03,0.02
12.643416573080277,0.0011386688417227,79.25112522109697,200.0,8.333333333333333e-05,0.67,0.28,0.23,0.05,0.9,0.05,0.03,0.02
12.885154820278677,0.0011588136956559,80.13977293297867,200.0,8.333333333333333e-05,0.67,0.28,0.23,0.05,0.9,0.05,0.03,0.02
13.126893067477077,0.0011789585495891,81.02842064486032,200.0,8.333333333333333e-05,0.67,0.28,0.23,0.05,0.9,0.05,0.03,0.02
13.368631314675477,0.0011991034035223002,81.91706835674206,200.0,8.333333333333333e-05,0.67,0.28,0.23,0.05,0.9,0.05,0.03,0.02
13.610369561873878,0.0012192482574555,82.80571606862381,200.0,8.333333333333333e-05,0.67,0.28,0.23,0.05,0.9,0.05,0.03,0.02
13.839371843543876,0.001238331780928,83.68877563836725,200.0,8.333333333333333e-05,0.67,0.28,0.23,0.05,0.9,0.05,0.03,0.02
14.068374125213877,0.0012574153044005,84.57183520811087,200.0,8.333333333333333e-05,0.67,0.28,0.23,0.05,0.9,0.05,0.03,0.02
14.297376406883878,0.001276498827873,85.4548947778543,200.0,8.333333333333333e-05,0.67,0.28,0.23,0.05,0.9,0.05,0.03,0.02
14.526378688553876,0.0012955823513455,86.33795434759764,200.0,8.333333333333333e-05,0.67,0.28,0.23,0.05,0.9,0.05,0.03,0.02
14.781414565669676,0.00131683534110515,87.21394388878613,200.0,8.333333333333333e-05,0.67,0.28,0.23,0.05,0.9,0.05,0.03,0.02
15.036450442785476,0.0013380883308647998,88.0899334299744,200.0,8.333333333333333e-05,0.67,0.28,0.23,0.05,0.9,0.05,0.03,0.02
15.291486319901278,0.0013593413206244498,88.96592297116288,200.0,8.333333333333333e-05,0.67,0.28,0.23,0.05,0.9,0.05,0.03,0.02
15.546522197017078,0.0013805943103841,89.84191251235127,200.0,8.333333333333333e-05,0.67,0.28,0.23,0.05,0.9,0.05,0.03,0.02
15.797333207377978,0.001401495227914175,90.6993797878061,200.0,8.333333333333333e-05,0.67,0.28,0.23,0.05,0.9,0.05,0.03,0.02
16.048144217738876,0.00142239614544425,91.55684706326176,200.0,8.333333333333333e-05,0.67,0.28,0.23,0.05,0.9,0.05,0.03,0.02
16.29895522809978,0.001443297062974325,92.41431433871648,200.0,8.333333333333333e-05,0.67,0.28,0.23,0.05,0.9,0.05,0.03,0.02
16.549766238460677,0.0014641979805044,93.2717816141708,200.0,8.333333333333333e-05,0.67,0.28,0.23,0.05,0.9,0.05,0.03,0.02
16.798862332256576,0.0014849559883207252,94.45524404383237,200.0,8.333333333333333e-05,0.67,0.28,0.23,0.05,0.9,0.05,0.03,0.02
17.047958426052475,0.0015057139961370501,95.6387064734939,200.0,8.333333333333333e-05,0.67,0.28,0.23,0.05,0.9,0.05,0.03,0.02
17.297054519848373,0.001526472003953375,96.82216890315553,200.0,8.333333333333333e-05,0.67,0.28,0.23,0.05,0.9,0.05,0.03,0.02
17.546150613644276,0.0015472300117697,98.00563133281719,200.0,8.333333333333333e-05,0.67,0.28,0.23,0.05,0.9,0.05,0.03,0.02
17.786192011685877,0.0015672334616065,99.09416525251069,200.0,8.333333333333333e-05,0.67,0.28,0.23,0.05,0.9,0.05,0.03,0.02
18.026233409727478,0.0015872369114432999,100.18269917220425,200.0,8.333333333333333e-05,0.67,0.28,0.23,0.05,0.9,0.05,0.03,0.02
18.26627480776908,0.0016072403612800998,101.27123309189768,200.0,8.333333333333333e-05,0.67,0.28,0.23,0.05,0.9,0.05,0.03,0.02
18.50631620581068,0.0016272438111169,102.3597670115903,200.0,8.333333333333333e-05,0.67,0.28,0.23,0.05,0.9,0.05,0.03,0.02
18.75058541870598,0.001647599578858175,103.35914668924502,200.0,8.333333333333333e-05,0.67,0.28,0.23,0.05,0.9,0.05,0.03,0.02
18.994854631601278,0.0016679553465994501,104.35852636690039,200.0,8.333333333333333e-05,0.67,0.28,0.23,0.05,0.9,0.05,0.03,0.02
19.23912384449658,0.001688311114340725,105.35790604455528,200.0,8.333333333333333e-05,0.67,0.28,0.23,0.05,0.9,0.05,0.03,0.02
19.48339305739188,0.001708666882082,106.35728572220977,200.0,8.333333333333333e-05,0.67,0.28,0.23,0.05,0.9,0.05,0.03,0.02
19.72762365767898,0.001729019432105925,107.30414038221078,200.0,8.333333333333333e-05,0.67,0.28,0.23,0.05,0.9,0.05,0.03,0.02
19.97185425796608,0.00174937198212985,108.2509950422121,200.0,8.333333333333333e-05,0.67,0.28,0.23,0.05,0.9,0.05,0.03,0.02
20.21608485825318,0.001769724532153775,109.19784970221306,200.0,8.333333333333333e-05,0.67,0.28,0.23,0.05,0.9,0.05,0.03,0.02
20.46031545854028,0.0017900770821777,110.1447043622141,200.0,8.333333333333333e-05,0.67,0.28,0.23,0.05,0.9,0.05,0.03,0.02
20.71534783707198,0.001811329780388675,111.07588769789287,200.0,8.333333333333333e-05,0.67,0.28,0.23,0.05,0.9,0.05,0.03,0.02
20.97038021560368,0.00183258247859965,112.00707103357198,200.0,8.333333333333333e-05,0.67,0.28,0.23,0.05,0.9,0.05,0.03,0.02
21.225412594135378,0.001853835176810625,112.93825436925076,200.0,8.333333333333333e-05,0.67,0.28,0.23,0.05,0.9,0.05,0.03,0.02
21.48044497266708,0.0018750878750216,113.8694377049288,200.0,8.333333333333333e-05,0.67,0.28,0.23,0.05,0.9,0.05,0.03,0.02
21.70163070908358,0.001893520019722975,114.7993408441633,200.0,8.333333333333333e-05,0.67,0.28,0.23,0.05,0.9,0.05,0.03,0.02
21.92281644550008,0.00191195216442435,115.72924398339802,200.0,8.333333333333333e-05,0.67,0.28,0.23,0.05,0.9,0.05,0.03,0.02
22.144002181916576,0.0019303843091257249,116.65914712263242,200.0,8.333333333333333e-05,0.67,0.28,0.23,0.05,0.9,0.05,0.03,0.02
22.365187918333078,0.0019488164538271,117.5890502618676,200.0,8.333333333333333e-05,0.67,0.28,0.23,0.05,0.9,0.05,0.03,0.02
22.597657693484578,0.001968188935089725,118.51447685464034,200.0,8.333333333333333e-05,0.67,0.28,0.23,0.05,0.9,0.05,0.03,0.02
22.83012746863608,0.00198756141635235,119.43990344741276,200.0,8.333333333333333e-05,0.67,0.28,0.23,0.05,0.9,0.05,0.03,0.02
23.06259724378758,0.002006933897614975,120.36533004018568,200.0,8.333333333333333e-05,0.67,0.28,0.23,0.05,0.9,0.05,0.03,0.02
23.29506701893908,0.0020263063788776,121.29075663295897,200.0,8.333333333333333e-05,0.67,0.28,0.23,0.05,0.9,0.05,0.03,0.02
23.514440439234477,0.00204458749723555,122.20359006722273,200.0,8.333333333333333e-05,0.67,0.28,0.23,0.05,0.9,0.05,0.03,0.02
23.733813859529878,0.0020628686155935,123.11642350148436,200.0,8.333333333333333e-05,0.67,0.28,0.23,0.05,0.9,0.05,0.03,0.02
23.95318727982528,0.00208114973395145,124.02925693574815,200.0,8.333333333333333e-05,0.67,0.28,0.23,0.05,0.9,0.05,0.03,0.02
24.172560700120677,0.0020994308523094,124.94209037001258,200.0,8.333333333333333e-05,0.67,0.28,0.23,0.05,0.9,0.05,0.03,0.02
24.408019989062876,0.00211905245972125,125.84802570912908,200.0,8.333333333333333e-05,0.67,0.28,0.23,0.05,0.9,0.05,0.03,0.02
24.643479278005074,0.0021386740671331,126.75396104824665,200.0,8.333333333333333e-05,0.67,0.28,0.23,0.05,0.9,0.05,0.03,0.02
24.878938566947276,0.00215829567454495,127.65989638736296,200.0,8.333333333333333e-05,0.67,0.28,0.23,0.05,0.9,0.05,0.03,0.02
25.114397855889475,0.0021779172819568,128.56583172647814,200.0,8.333333333333333e-05,0.67,0.28,0.23,0.05,0.9,0.05,0.03,0.02
25.333671827437676,0.0021961901129191504,129.47158285715892,200.0,8.333333333333333e-05,0.67,0.28,0.23,0.05,0.9,0.05,0.03,0.02
25.552945798985878,0.0022144629438815002,130.3773339878406,200.0,8.333333333333333e-05,0.67,0.28,0.23,0.05,0.9,0.05,0.03,0.02
25.77221977053408,0.00223273577484385,131.2830851185215,200.0,8.333333333333333e-05,0.67,0.28,0.23,0.05,0.9,0.05,0.03,0.02
25.99149374208228,0.0022510086058062,132.18883624920284,200.0,8.333333333333333e-05,0.67,0.28,0.23,0.05,0.9,0.05,0.03,0.02
26.230174143111476,0.0022708986392253,133.0922390267341,200.0,8.333333333333333e-05,0.67,0.28,0.23,0.05,0.9,0.05,0.03,0.02
26.468854544140676,0.0022907886726444,133.995641804265,200.0,8.333333333333333e-05,0.67,0.28,0.23,0.05,0.9,0.05,0.03,0.02
26.707534945169876,0.0023106787060635002,134.89904458179603,200.0,8.333333333333333e-05,0.67,0.28,0.23,0.05,0.9,0.05,0.03,0.02
26.946215346199075,0.0023305687394826,135.80244735932632,200.0,8.333333333333333e-05,0.67,0.28,0.23,0.05,0.9,0.05,0.03,0.02
27.187996986954175,0.002350717209545525,136.68977319106284,200.0,8.333333333333333e-05,0.67,0.28,0.23,0.05,0.9,0.05,0.03,0.02
27.429778627709275,0.00237086567960845,137.57709902279913,200.0,8.333333333333333e-05,0.67,0.28,0.23,0.05,0.9,0.05,0.03,0.02
27.671560268464376,0.002391014149671375,138.46442485453588,200.0,8.333333333333333e-05,0.67,0.28,0.23,0.05,0.9,0.05,0.03,0.02
27.91334190921948,0.0024111626197343,139.35175068627422,200.0,8.333333333333333e-05,0.67,0.28,0.23,0.05,0.9,0.05,0.03,0.02
28.16718718062048,0.00243231639235105,140.23058289459573,200.0,8.333333333333333e-05,0.67,0.28,0.23,0.05,0.9,0.05,0.03,0.02
28.42103245202148,0.0024534701649678,141.1094151029153,200.0,8.333333333333333e-05,0.67,0.28,0.23,0.05,0.9,0.05,0.03,0.02
28.674877723422476,0.00247462393758455,141.9882473112369,200.0,8.333333333333333e-05,0.67,0.28,0.23,0.05,0.9,0.05,0.03,0.02
28.928722994823477,0.0024957777102013,142.8670795195596,200.0,8.333333333333333e-05,0.67,0.28,0.23,0.05,0.9,0.05,0.03,0.02
29.16851634659448,0.00251576048951555,143.73773347582312,200.0,8.333333333333333e-05,0.67,0.28,0.23,0.05,0.9,0.05,0.03,0.02
29.40830969836548,0.0025357432688298,144.60838743208677,200.0,8.333333333333333e-05,0.67,0.28,0.23,0.05,0.9,0.05,0.03,0.02
29.648103050136477,0.00255572604814405,145.47904138834997,200.0,8.333333333333333e-05,0.67,0.28,0.23,0.05,0.9,0.05,0.03,0.02
29.88789640190748,0.0025757088274583,146.34969534461231,200.0,8.333333333333333e-05,0.67,0.28,0.23,0.05,0.9,0.05,0.03,0.02
30.15135066542358,0.002597663349417975,147.2152870438553,200.0,8.333333333333333e-05,0.67,0.28,0.23,0.05,0.9,0.05,0.03,0.02
30.414804928939677,0.00261961787137765,148.08087874309882,200.0,8.333333333333333e-05,0.67,0.28,0.23,0.05,0.9,0.05,0.03,0.02
30.678259192455776,0.002641572393337325,148.94647044234196,200.0,8.333333333333333e-05,0.67,0.28,0.23,0.05,0.9,0.05,0.03,0.02
30.941713455971875,0.002663526915297,149.81206214158516,200.0,8.333333333333333e-05,0.67,0.28,0.23,0.05,0.9,0.05,0.03,0.02
31.191524331834174,0.002684344488285525,150.66686193688918,200.0,8.333333333333333e-05,0.67,0.28,0.23,0.05,0.9,0.05,0.03,0.02
31.441335207696476,0.0027051620612740497,151.52166173219285,200.0,8.333333333333333e-05,0.67,0.28,0.23,0.05,0.9,0.05,0.03,0.02
31.691146083558777,0.0027259796342625747,152.37646152749676,200.0,8.333333333333333e-05,0.67,0.28,0.23,0.05,0.9,0.05,0.03,0.02
31.94095695942108,0.0027467972072511,153.23126132280117,200.0,8.333333333333333e-05,0.67,0.28,0.23,0.05,0.9,0.05,0.03,0.02
32.204332559901175,0.002768745173957775,154.07739607125916,200.0,8.333333333333333e-05,0.67,0.28,0.23,0.05,0.9,0.05,0.03,0.02
32.46770816038128,0.00279069314066445,154.92353081971677,200.0,8.333333333333333e-05,0.67,0.28,0.23,0.05,0.9,0.05,0.03,0.02
32.73108376086138,0.0028126411073711253,155.76966556817493,200.0,8.333333333333333e-05,0.67,0.28,0.23,0.05,0.9,0.05,0.03,0.02
32.994459361341484,0.0028345890740778,156.6158003166342,200.0,8.333333333333333e-05,0.67,0.28,0.23,0.05,0.9,0.05,0.03,0.02
33.265774751408884,0.00285719868991675,157.4439339800372,200.0,8.333333333333333e-05,0.67,0.28,0.23,0.05,0.9,0.05,0.03,0.02
33.537090141476284,0.0028798083057557,158.2720676434399,200.0,8.333333333333333e-05,0.67,0.28,0.23,0.05,0.9,0.05,0.03,0.02
33.808405531543684,0.00290241792159465,159.10020130684276,200.0,8.333333333333333e-05,0.67,0.28,0.23,0.05,0.9,0.05,0.03,0.02
34.07972092161108,0.0029250275374336,159.9283349702451,200.0,8.333333333333333e-05,0.67,0.28,0.23,0.05,0.9,0.05,0.03,0.02
34.321684919144275,0.0029451912038947,160.7498066578513,200.0,8.333333333333333e-05,0.67,0.28,0.23,0.05,0.9,0.05,0.03,0.02
34.56364891667748,0.0029653548703558,161.57127834545793,200.0,8.333333333333333e-05,0.67,0.28,0.23,0.05,0.9,0.05,0.03,0.02
34.805612914210684,0.0029855185368169,162.39275003306437,200.0,8.333333333333333e-05,0.67,0.28,0.23,0.05,0.9,0.05,0.03,0.02
35.04757691174388,0.003005682203278,163.21422172067048,200.0,8.333333333333333e-05,0.67,0.28,0.23,0.05,0.9,0.05,0.03,0.02
35.290362275310486,0.00302591431690855,164.0187372581837,200.0,8.333333333333333e-05,0.67,0.28,0.23,0.05,0.9,0.05,0.03,0.02
35.53314763887708,0.0030461464305391,164.82325279569733,200.0,8.333333333333333e-05,0.67,0.28,0.23,0.05,0.9,0.05,0.03,0.02
35.77593300244368,0.00306637854416965,165.62776833320993,200.0,8.333333333333333e-05,0.67,0.28,0.23,0.05,0.9,0.05,0.03,0.02
36.01871836601028,0.0030866106578002,166.43228387072116,200.0,8.333333333333333e-05,0.67,0.28,0.23,0.05,0.9,0.05,0.03,0.02
36.29321406831379,0.003109485299658825,167.2299591421069,200.0,8.333333333333333e-05,0.67,0.28,0.23,0.05,0.9,0.05,0.03,0.02
36.567709770617284,0.0031323599415174503,168.0276344134939,200.0,8.333333333333333e-05,0.67,0.28,0.23,0.05,0.9,0.05,0.03,0.02
36.84220547292078,0.003155234583376075,168.82530968488,200.0,8.333333333333333e-05,0.67,0.28,0.23,0.05,0.9,0.05,0.03,0.02
37.11670117522428,0.0031781092252347,169.6229849562668,200.0,8.333333333333333e-05,0.67,0.28,0.23,0.05,0.9,0.05,0.03,0.02
37.35980077382838,0.0031983675251183747,170.39975114701582,200.0,8.333333333333333e-05,0.67,0.28,0.23,0.05,0.9,0.05,0.03,0.02
37.60290037243248,0.00321862582500205,171.17651733776663,200.0,8.333333333333333e-05,0.67,0.28,0.23,0.05,0.9,0.05,0.03,0.02
37.845999971036576,0.003238884124885725,171.95328352851567,200.0,8.333333333333333e-05,0.67,0.28,0.23,0.05,0.9,0.05,0.03,0.02
38.08909956964068,0.0032591424247694,172.73004971925963,200.0,8.333333333333333e-05,0.67,0.28,0.23,0.05,0.9,0.05,0.03,0.02
38.33933414790438,0.003279995306291375,173.49530082310662,200.0,8.333333333333333e-05,0.67,0.28,0.23,0.05,0.9,0.05,0.03,0.02
38.58956872616808,0.00330084818781335,174.26055192695807,200.0,8.333333333333333e-05,0.67,0.28,0.23,0.05,0.9,0.05,0.03,0.02
38.83980330443178,0.0033217010693353246,175.02580303080526,200.0,8.333333333333333e-05,0.67,0.28,0.23,0.05,0.9,0.05,0.03,0.02
39.09003788269548,0.0033425539508573,175.7910541346501,200.0,8.333333333333333e-05,0.67,0.28,0.23,0.05,0.9,0.05,0.03,0.02
39.37397243381148,0.0033662151634503,176.5469386925941,200.0,8.333333333333333e-05,0.67,0.28,0.23,0.05,0.9,0.05,0.03,0.02
39.65790698492748,0.0033898763760433,177.30282325053864,200.0,8.333333333333333e-05,0.67,0.28,0.23,0.05,0.9,0.05,0.03,0.02
39.94184153604348,0.0034135375886362998,178.05870780848255,200.0,8.333333333333333e-05,0.67,0.28,0.23,0.05,0.9,0.05,0.03,0.02
40.22577608715948,0.0034371988012293,178.81459236642766,200.0,8.333333333333333e-05,0.67,0.28,0.23,0.05,0.9,0.05,0.03,0.02
40.47771290388738,0.0034581935359566255,179.56701658021467,200.0,8.333333333333333e-05,0.67,0.28,0.23,0.05,0.9,0.05,0.03,0.02
40.729649720615285,0.0034791882706839503,180.319440794,200.0,8.333333333333333e-05,0.67,0.28,0.23,0.05,0.9,0.05,0.03,0.02
40.98158653734318,0.003500183005411275,181.07186500778693,200.0,8.333333333333333e-05,0.67,0.28,0.23,0.05,0.9,0.05,0.03,0.02
41.23352335407108,0.0035211777401386,181.82428922157362,200.0,8.333333333333333e-05,0.67,0.28,0.23,0.05,0.9,0.05,0.03,0.02
41.54426615802138,0.003547072973801125,182.55420533963664,200.0,8.333333333333333e-05,0.67,0.28,0.23,0.05,0.9,0.05,0.03,0.02
41.85500896197168,0.0035729682074636497,183.284121457701,200.0,8.333333333333333e-05,0.67,0.28,0.23,0.05,0.9,0.05,0.03,0.02
42.16575176592198,0.0035988634411261745,184.01403757576395,200.0,8.333333333333333e-05,0.67,0.28,0.23,0.05,0.9,0.05,0.03,0.02
42.47649456987228,0.0036247586747887,184.7439536938274,200.0,8.333333333333333e-05,0.67,0.28,0.23,0.05,0.9,0.05,0.03,0.02
42.800033110411675,0.00365172021983365,185.4500380728444,200.0,8.333333333333333e-05,0.67,0.28,0.23,0.05,0.9,0.05,0.03,0.02
43.12357165095108,0.0036786817648786,186.15612245186045,200.0,8.333333333333333e-05,0.67,0.28,0.23,0.05,0.9,0.05,0.03,0.02
43.44711019149048,0.00370564330992355,186.86220683087726,200.0,8.333333333333333e-05,0.67,0.28,0.23,0.05,0.9,0.05,0.03,0.02
43.77064873202988,0.0037326048549685,187.56829120989295,200.0,8.333333333333333e-05,0.67,0.28,0.23,0.05,0.9,0.05,0.03,0.02
44.09200959477168,0.0037593849268636502,188.25286248202917,200.0,8.333333333333333e-05,0.67,0.28,0.23,0.05,0.9,0.05,0.03,0.02
44.41337045751349,0.0037861649987588003,188.93743375416722,200.0,8.333333333333333e-05,0.67,0.28,0.23,0.05,0.9,0.05,0.03,0.02
44.73473132025529,0.0038129450706539504,189.62200502630344,200.0,8.333333333333333e-05,0.67,0.28,0.23,0.05,0.9,0.05,0.03,0.02
45.05609218299709,0.0038397251425491,190.3065762984388,200.0,8.333333333333333e-05,0.67,0.28,0.23,0.05,0.9,0.05,0.03,0.02
45.45747186590029,0.0038731734494577,190.9757954523198,200.0,8.333333333333333e-05,0.67,0.28,0.23,0.05,0.9,0.05,0.03,0.02
45.858851548803486,0.0039066217563663,191.6450146062004,200.0,8.333333333333333e-05,0.67,0.28,0.23,0.05,0.9,0.05,0.03,0.02
46.26023123170668,0.0039400700632749,192.3142337600815,200.0,8.333333333333333e-05,0.67,0.28,0.23,0.05,0.9,0.05,0.03,0.02
46.66161091460988,0.0039735183701835,192.98345291396242,200.0,8.333333333333333e-05,0.67,0.28,0.23,0.05,0.9,0.05,0.03,0.02
47.095891038725284,0.00400970838052645,193.6236705615102,200.0,8.333333333333333e-05,0.67,0.28,0.23,0.05,0.9,0.05,0.03,0.02
47.53017116284068,0.0040458983908694,194.26388820905754,200.0,8.333333333333333e-05,0.67,0.28,0.23,0.05,0.9,0.05,0.03,0.02
47.96445128695608,0.00408208840121235,194.90410585660538,200.0,8.333333333333333e-05,0.67,0.28,0.23,0.05,0.9,0.05,0.03,0.02
48.39873141107148,0.0041182784115553,195.54432350415368,200.0,8.333333333333333e-05,0.67,0.28,0.23,0.05,0.9,0.05,0.03,0.02
48.88440791299368,0.00415875145338215,196.13903299453594,200.0,8.333333333333333e-05,0.67,0.28,0.23,0.05,0.9,0.05,0.03,0.02
49.37008441491588,0.004199224495209,196.73374248491945,200.0,8.333333333333333e-05,0.67,0.28,0.23,0.05,0.9,0.05,0.03,0.02
49.85576091683808,0.00423969753703585,197.3284519753018,200.0,8.333333333333333e-05,0.67,0.28,0.23,0.05,0.9,0.05,0.03,0.02
50.34143741876028,0.0042801705788627,197.92316146568294,200.0,8.333333333333333e-05,0.67,0.28,0.23,0.05,0.9,0.05,0.03,0.02
50.91473300582898,0.0043279452111184245,198.45861267652768,200.0,8.333333333333333e-05,0.67,0.28,0.23,0.05,0.9,0.05,0.03,0.02
51.48802859289768,0.00437571984337415,198.9940638873723,200.0,8.333333333333333e-05,0.67,0.28,0.23,0.05,0.9,0.05,0.03,0.02
52.06132417996638,0.004423494475629875,199.52951509821685,200.0,8.333333333333333e-05,0.67,0.28,0.23,0.05,0.9,0.05,0.03,0.02
52.63461976703508,0.0044712691078856,200.0649663090613,200.0,8.333333333333333e-05,0.67,0.28,0.23,0.05,0.9,0.05,0.03,0.02
53.26427041269528,0.004523739995023949,200.55116051787508,200.0,8.333333333333333e-05,0.67,0.28,0.23,0.05,0.9,0.05,0.03,0.02
53.893921058355474,0.0045762108821623,201.0373547266895,200.0,8.333333333333333e-05,0.67,0.28,0.23,0.05,0.9,0.05,0.03,0.02
54.52357170401567,0.00462868176930065,201.52354893550324,200.0,8.333333333333333e-05,0.67,0.28,0.23,0.05,0.9,0.05,0.03,0.02
55.15322234967587,0.004681152656439,202.00974314431642,200.0,8.333333333333333e-05,0.67,0.28,0.23,0.05,0.9,0.05,0.03,0.02
55.870709628583974,0.004740943263014675,202.43441866973242,200.0,8.333333333333333e-05,0.67,0.28,0.23,0.05,0.9,0.05,0.03,0.02
56.588196907492076,0.00480073386959035,202.85909419514869,200.0,8.333333333333333e-05,0.67,0.28,0.23,0.05,0.9,0.05,0.03,0.02
57.305684186400185,0.004860524476166025,203.28376972056483,200.0,8.333333333333333e-05,0.67,0.28,0.23,0.05,0.9,0.05,0.03,0.02
58.02317146530829,0.0049203150827417,203.70844524597962,200.0,8.333333333333333e-05,0.67,0.28,0.23,0.05,0.9,0.05,0.03,0.02
58.830943939095185,0.004987629455557275,204.07113505975988,200.0,8.333333333333333e-05,0.67,0.28,0.23,0.05,0.9,0.05,0.03,0.02
59.63871641288208,0.0050549438283728505,204.4338248735421,200.0,8.333333333333333e-05,0.67,0.28,0.23,0.05,0.9,0.05,0.03,0.02
60.44648888666898,0.005122258201188425,204.79651468732231,200.0,8.333333333333333e-05,0.67,0.28,0.23,0.05,0.9,0.05,0.03,0.02
61.25426136045588,0.005189572574004,205.15920450110252,200.0,8.333333333333333e-05,0.67,0.28,0.23,0.05,0.9,0.05,0.03,0.02
62.09837473749438,0.005259915355423875,205.45518947377352,200.0,8.333333333333333e-05,0.67,0.28,0.23,0.05,0.9,0.05,0.03,0.02
62.94248811453288,0.00533025813684375,205.75117444644394,200.0,8.333333333333333e-05,0.67,0.28,0.23,0.05,0.9,0.05,0.03,0.02
63.786601491571375,0.005400600918263625,206.04715941911493,200.0,8.333333333333333e-05,0.67,0.28,0.23,0.05,0.9,0.05,0.03,0.02
64.63071486860987,0.0054709436996835,206.34314439178596,200.0,8.333333333333333e-05,0.67,0.28,0.23,0.05,0.9,0.05,0.03,0.02
65.57144685100727,0.00554933803154995,206.5596238595467,200.0,8.333333333333333e-05,0.67,0.28,0.23,0.05,0.9,0.05,0.03,0.02
66.51217883340468,0.0056277323634164,206.7761033273072,200.0,8.333333333333333e-05,0.67,0.28,0.23,0.05,0.9,0.05,0.03,0.02
67.45291081580208,0.00570612669528285,206.9925827950679,200.0,8.333333333333333e-05,0.67,0.28,0.23,0.05,0.9,0.05,0.03,0.02
68.39364279819948,0.0057845210271493,207.20906226282867,200.0,8.333333333333333e-05,0.67,0.28,0.23,0.05,0.9,0.05,0.03,0.02
69.36502965102798,0.005865469931551675,207.37126089771192,200.0,8.333333333333333e-05,0.67,0.28,0.23,0.05,0.9,0.05,0.03,0.02
70.33641650385647,0.00594641883595405,207.53345953259551,200.0,8.333333333333333e-05,0.67,0.28,0.23,0.05,0.9,0.05,0.03,0.02
71.30780335668497,0.006027367740356425,207.69565816747905,200.0,8.333333333333333e-05,0.67,0.28,0.23,0.05,0.9,0.05,0.03,0.02
72.27919020951347,0.0061083166447588,207.85785680236242,200.0,8.333333333333333e-05,0.67,0.28,0.23,0.05,0.9,0.05,0.03,0.02
73.28362631059008,0.006192019653181851,207.97859231879517,200.0,8.333333333333333e-05,0.67,0.28,0.23,0.05,0.9,0.05,0.03,0.02
74.28806241166667,0.0062757226616049,208.0993278352274,200.0,8.333333333333333e-05,0.67,0.28,0.23,0.05,0.9,0.05,0.03,0.02
75.29249851274326,0.00635942567002795,208.22006335166012,200.0,8.333333333333333e-05,0.67,0.28,0.23,0.05,0.9,0.05,0.03,0.02
76.29693461381987,0.006443128678451,208.340798868094,200.0,8.333333333333333e-05,0.67,0.28,0.23,0.05,0.9,0.05,0.03,0.02
77.32534473297588,0.006528829521714,208.4178538742295,200.0,8.333333333333333e-05,0.67,0.28,0.23,0.05,0.9,0.05,0.03,0.02
78.35375485213189,0.006614530364977,208.4949088803648,200.0,8.333333333333333e-05,0.67,0.28,0.23,0.05,0.9,0.05,0.03,0.02
79.38216497128789,0.006700231208240001,208.5719638865001,200.0,8.333333333333333e-05,0.67,0.28,0.23,0.05,0.9,0.05,0.03,0.02
80.41057509044388,0.006785932051503,208.64901889263504,200.0,8.333333333333333e-05,0.67,0.28,0.23,0.05,0.9,0.05,0.03,0.02
81.46337040447588,0.006873664994339,208.7052111232543,200.0,8.333333333333333e-05,0.67,0.28,0.23,0.05,0.9,0.05,0.03,0.02
82.51616571850788,0.006961397937175,208.7614033538728,200.0,8.333333333333333e-05,0.67,0.28,0.23,0.05,0.9,0.05,0.03,0.02
83.56896103253987,0.0070491308800110005,208.81759558449198,200.0,8.333333333333333e-05,0.67,0.28,0.23,0.05,0.9,0.05,0.03,0.02
84.62175634657187,0.007136863822847,208.8737878151119,200.0,8.333333333333333e-05,0.67,0.28,0.23,0.05,0.9,0.05,0.03,0.02
85.70047461058307,0.0072267570115146,208.8968281054364,200.0,8.333333333333333e-05,0.67,0.28,0.23,0.05,0.9,0.05,0.03,0.02
86.77919287459427,0.0073166502001822,208.91986839576137,200.0,8.333333333333333e-05,0.67,0.28,0.23,0.05,0.9,0.05,0.03,0.02
87.85791113860547,0.007406543388849799,208.942908686086,200.0,8.333333333333333e-05,0.67,0.28,0.23,0.05,0.9,0.05,0.03,0.02
88.93662940261667,0.0074964365775174,208.96594897640972,200.0,8.333333333333333e-05,0.67,0.28,0.23,0.05,0.9,0.05,0.03,0.02
90.02799218482338,0.0075873834760346245,208.97693845492597,200.0,8.333333333333333e-05,0.67,0.28,0.23,0.05,0.9,0.05,0.03,0.02
91.11935496703008,0.00767833037455185,208.98792793344347,200.0,8.333333333333333e-05,0.67,0.28,0.23,0.05,0.9,0.05,0.03,0.02
92.21071774923678,0.007769277273069075,208.99891741195955,200.0,8.333333333333333e-05,0.67,0.28,0.23,0.05,0.9,0.05,0.03,0.02
93.30208053144348,0.0078602241715863,209.00990689047546,200.0,8.333333333333333e-05,0.67,0.28,0.23,0.05,0.9,0.05,0.03,0.02
94.40197489880538,0.007951882035533125,209.0233396490222,200.0,8.333333333333333e-05,0.67,0.28,0.23,0.05,0.9,0.05,0.03,0.02
95.50186926616726,0.00804353989947995,209.0367724075678,200.0,8.333333333333333e-05,0.67,0.28,0.23,0.05,0.9,0.05,0.03,0.02
96.60176363352916,0.008135197763426773,209.05020516611458,200.0,8.333333333333333e-05,0.67,0.28,0.23,0.05,0.9,0.05,0.03,0.02
97.70165800089106,0.0082268556273736,209.06363792466186,200.0,8.333333333333333e-05,0.67,0.28,0.23,0.05,0.9,0.05,0.03,0.02
98.81899257273676,0.008319966841694074,209.06676318230484,200.0,8.333333333333333e-05,0.67,0.28,0.23,0.05,0.9,0.05,0.03,0.02
99.93632714458246,0.00841307805601455,209.06988843994728,200.0,8.333333333333333e-05,0.67,0.28,0.23,0.05,0.9,0.05,0.03,0.02
101.05366171642817,0.008506189270335026,209.07301369759057,200.0,8.333333333333333e-05,0.67,0.28,0.23,0.05,0.9,0.05,0.03,0.02
102.17099628827388,0.0085993004846555,209.07613895523522,200.0,8.333333333333333e-05,0.67,0.28,0.23,0.05,0.9,0.05,0.03,0.02
103.30596620403318,0.008693881310968776,209.07949342974874,200.0,8.333333333333333e-05,0.67,0.28,0.23,0.05,0.9,0.05,0.03,0.02
104.44093611979248,0.00878846213728205,209.08284790426194,200.0,8.333333333333333e-05,0.67,0.28,0.23,0.05,0.9,0.05,0.03,0.02
105.57590603555178,0.008883042963595326,209.08620237877545,200.0,8.333333333333333e-05,0.67,0.28,0.23,0.05,0.9,0.05,0.03,0.02
106.71087595131108,0.0089776237899086,209.08955685328766,200.0,8.333333333333333e-05,0.67,0.28,0.23,0.05,0.9,0.05,0.03,0.02
107.86375814747629,0.0090736973062557,209.0942756309169,200.0,8.333333333333333e-05,0.67,0.28,0.23,0.05,0.9,0.05,0.03,0.02
109.01664034364148,0.009169770822602799,209.09899440854642,200.0,8.333333333333333e-05,0.67,0.28,0.23,0.05,0.9,0.05,0.03,0.02
110.16952253980668,0.0092658443389499,209.10371318617575,200.0,8.333333333333333e-05,0.67,0.28,0.23,0.05,0.9,0.05,0.03,0.02
111.32240473597189,0.009361917855297,209.10843196380569,200.0,8.333333333333333e-05,0.67,0.28,0.23,0.05,0.9,0.05,0.03,0.02
112.472411553836,0.009457751756785676,209.1108802210537,200.0,8.333333333333333e-05,0.67,0.28,0.23,0.05,0.9,0.05,0.03,0.02
113.62241837170009,0.009553585658274352,209.11332847830226,200.0,8.333333333333333e-05,0.67,0.28,0.23,0.05,0.9,0.05,0.03,0.02
114.77242518956419,0.009649419559763027,209.11577673554982,200.0,8.333333333333333e-05,0.67,0.28,0.23,0.05,0.9,0.05,0.03,0.02
115.92243200742828,0.0097452534612517,209.11822499279572,200.0,8.333333333333333e-05,0.67,0.28,0.23,0.05,0.9,0.05,0.03,0.02
117.07556193802577,0.009841347622134827,209.11935858468945,200.0,8.333333333333333e-05,0.67,0.28,0.23,0.05,0.9,0.05,0.03,0.02
118.22869186862327,0.00993744178301795,209.12049217658424,200.0,8.333333333333333e-05,0.67,0.28,0.23,0.05,0.9,0.05,0.03,0.02
119.38182179922077,0.010033535943901075,209.12162576847817,200.0,8.333333333333333e-05,0.67,0.28,0.23,0.05,0.9,0.05,0.03,0.02
120.53495172981826,0.0101296301047842,209.122759360372,200.0,8.333333333333333e-05,0.67,0.28,0.23,0.05,0.9,0.05,0.03,0.02
121.70996382497026,0.0102275477793802,209.12251708571824,200.0,8.333333333333333e-05,0.67,0.28,0.23,0.05,0.9,0.05,0.03,0.02
122.88497592012227,0.0103254654539762,209.12227481106365,200.0,8.333333333333333e-05,0.67,0.28,0.23,0.05,0.9,0.05,0.03,0.02
124.05998801527429,0.0104233831285722,209.12203253641002,200.0,8.333333333333333e-05,0.67,0.28,0.23,0.05,0.9,0.05,0.03,0.02
125.23500011042628,0.0105213008031682,209.12179026175707,200.0,8.333333333333333e-05,0.67,0.28,0.23,0.05,0.9,0.05,0.03,0.02
126.41004783823158,0.010619221447151975,209.12154018326908,200.0,8.333333333333333e-05,0.67,0.28,0.23,0.05,0.9,0.05,0.03,0.02
127.58509556603688,0.01071714209113575,209.12129010478253,200.0,8.333333333333333e-05,0.67,0.28,0.23,0.05,0.9,0.05,0.03,0.02
128.7601432938422,0.010815062735119525,209.12104002629442,200.0,8.333333333333333e-05,0.67,0.28,0.23,0.05,0.9,0.05,0.03,0.02
129.93519102164748,0.0109129833791033,209.12078994780535,200.0,8.333333333333333e-05,0.67,0.28,0.23,0.05,0.9,0.05,0.03,0.02
131.1322475285816,0.011012738088014475,209.12508718002934,200.0,8.333333333333333e-05,0.67,0.28,0.23,0.05,0.9,0.05,0.03,0.02
132.3293040355157,0.01111249279692565,209.12938441225202,200.0,8.333333333333333e-05,0.67,0.28,0.23,0.05,0.9,0.05,0.03,0.02
133.5263605424498,0.011212247505836825,209.13368164447604,200.0,8.333333333333333e-05,0.67,0.28,0.23,0.05,0.9,0.05,0.03,0.02
134.7234170493839,0.011312002214748,209.137978876701,200.0,8.333333333333333e-05,0.67,0.28,0.23,0.05,0.9,0.05,0.03,0.02