File: datasets/al_6061_comp/csv/T_200_A_1.csv
Time,Strain(%),Stress(MPa),Temp(C),SR(%/s),Si(%),Fe(%),Cu(%),Mn(%),Mg(%),Cr(%),Zn(%),Ti(%)
0.0,0.0001339743319084,30.577562695613725,200.0,8.333333333333333e-05,0.56,0.23,0.18,0.07,0.86,0.06,0.02,0.01
0.07803706861530002,0.00014047742095967499,31.25774974333295,200.0,8.333333333333333e-05,0.56,0.23,0.18,0.07,0.86,0.06,0.02,0.01
0.15607413723060004,0.00014698051001094998,31.937936791052188,200.0,8.333333333333333e-05,0.56,0.23,0.18,0.07,0.86,0.06,0.02,0.01
0.23411120584590006,0.000153483599062225,32.61812383877141,200.0,8.333333333333333e-05,0.56,0.23,0.18,0.07,0.86,0.06,0.02,0.01
0.3121482744612001,0.0001599866881135,33.298310886490626,200.0,8.333333333333333e-05,0.56,0.23,0.18,0.07,0.86,0.06,0.02,0.01
0.3901853430765001,0.000166489777164775,33.97849793420985,200.0,8.333333333333333e-05,0.56,0.23,0.18,0.07,0.86,0.06,0.02,0.01
0.4682224116918001,0.00017299286621605002,34.658684981929056,200.0,8.333333333333333e-05,0.56,0.23,0.18,0.07,0.86,0.06,0.02,0.01
0.5462594803071001,0.00017949595526732502,35.33887202964826,200.0,8.333333333333333e-05,0.56,0.23,0.18,0.07,0.86,0.06,0.02,0.01
0.6242965489224002,0.0001859990443186,36.01905907736749,200.0,8.333333333333333e-05,0.56,0.23,0.18,0.07,0.86,0.06,0.02,0.01
0.7194874295700002,0.00019393161770590002,36.71791463023122,200.0,8.333333333333333e-05,0.56,0.23,0.18,0.07,0.86,0.06,0.02,0.01
0.8146783102176002,0.00020186419109320002,37.4167701830949,200.0,8.333333333333333e-05,0.56,0.23,0.18,0.07,0.86,0.06,0.02,0.01
0.9098691908652001,0.0002097967644805,38.115625735958645,200.0,8.333333333333333e-05,0.56,0.23,0.18,0.07,0.86,0.06,0.02,0.01
1.0050600715128002,0.0002177293378678,38.814481288822456,200.0,8.333333333333333e-05,0.56,0.23,0.18,0.07,0.86,0.06,0.02,0.01
1.1002509521604003,0.00022566191125510002,39.51333684168618,200.0,8.333333333333333e-05,0.56,0.23,0.18,0.07,0.86,0.06,0.02,0.01
1.195441832808,0.0002335944846424,40.21219239454985,200.0,8.333333333333333e-05,0.56,0.23,0.18,0.07,0.86,0.06,0.02,0.01
1.2906327134556002,0.0002415270580297,40.91104794741357,200.0,8.333333333333333e-05,0.56,0.23,0.18,0.07,0.86,0.06,0.02,0.01
1.3858235941032002,0.000249459631417,41.60990350027727,200.0,8.333333333333333e-05,0.56,0.23,0.18,0.07,0.86,0.06,0.02,0.01
1.4999591570518502,0.0002589709283293875,42.310321705572804,200.0,8.333333333333333e-05,0.56,0.23,0.18,0.07,0.86,0.06,0.02,0.01
1.6140947200005002,0.000268482225241775,43.010739910868324,200.0,8.333333333333333e-05,0.56,0.23,0.18,0.07,0.86,0.06,0.02,0.01
1.7282302829491503,0.0002779935221541625,43.71115811616386,200.0,8.333333333333333e-05,0.56,0.23,0.18,0.07,0.86,0.06,0.02,0.01
1.8423658458978,0.00028750481906655,44.41157632145941,200.0,8.333333333333333e-05,0.56,0.23,0.18,0.07,0.86,0.06,0.02,0.01
1.9565014088464499,0.0002970161159789375,45.11199452675494,200.0,8.333333333333333e-05,0.56,0.23,0.18,0.07,0.86,0.06,0.02,0.01
2.0706369717951,0.000306527412891325,45.81241273205052,200.0,8.333333333333333e-05,0.56,0.23,0.18,0.07,0.86,0.06,0.02,0.01
2.18477253474375,0.0003160387098037125,46.51283093734605,200.0,8.333333333333333e-05,0.56,0.23,0.18,0.07,0.86,0.06,0.02,0.01
2.2989080976924,0.0003255500067161,47.2132491426416,200.0,8.333333333333333e-05,0.56,0.23,0.18,0.07,0.86,0.06,0.02,0.01
2.4202316860014,0.00033566030574185,47.915044211347414,200.0,8.333333333333333e-05,0.56,0.23,0.18,0.07,0.86,0.06,0.02,0.01
2.5415552743104,0.0003457706047676,48.61683928005323,200.0,8.333333333333333e-05,0.56,0.23,0.18,0.07,0.86,0.06,0.02,0.01
2.6628788626194,0.00035588090379335,49.31863434875903,200.0,8.333333333333333e-05,0.56,0.23,0.18,0.07,0.86,0.06,0.02,0.01
2.7842024509284005,0.00036599120281910003,50.02042941746486,200.0,8.333333333333333e-05,0.56,0.23,0.18,0.07,0.86,0.06,0.02,0.01
2.905526039237401,0.00037610150184485,50.722224486170674,200.0,8.333333333333333e-05,0.56,0.23,0.18,0.07,0.86,0.06,0.02,0.01
3.026849627546401,0.0003862118008706,51.42401955487644,200.0,8.333333333333333e-05,0.56,0.23,0.18,0.07,0.86,0.06,0.02,0.01
3.148173215855401,0.00039632209989635004,52.12581462358226,200.0,8.333333333333333e-05,0.56,0.23,0.18,0.07,0.86,0.06,0.02,0.01
3.269496804164401,0.0004064323989221,52.82760969228808,200.0,8.333333333333333e-05,0.56,0.23,0.18,0.07,0.86,0.06,0.02,0.01
3.389865326467951,0.00041646310911406257,53.535939450167966,200.0,8.333333333333333e-05,0.56,0.23,0.18,0.07,0.86,0.06,0.02,0.01
3.5102338487715006,0.00042649381930602505,54.244269208047925,200.0,8.333333333333333e-05,0.56,0.23,0.18,0.07,0.86,0.06,0.02,0.01
3.6306023710750503,0.00043652452949798754,54.95259896592779,200.0,8.333333333333333e-05,0.56,0.23,0.18,0.07,0.86,0.06,0.02,0.01
3.7509708933786006,0.00044655523968995,55.660928723807594,200.0,8.333333333333333e-05,0.56,0.23,0.18,0.07,0.86,0.06,0.02,0.01
3.871339415682151,0.0004565859498819125,56.36925848168747,200.0,8.333333333333333e-05,0.56,0.23,0.18,0.07,0.86,0.06,0.02,0.01
3.9917079379857006,0.000466616660073875,57.07758823956739,200.0,8.333333333333333e-05,0.56,0.23,0.18,0.07,0.86,0.06,0.02,0.01
4.11207646028925,0.0004766473702658375,57.78591799744724,200.0,8.333333333333333e-05,0.56,0.23,0.18,0.07,0.86,0.06,0.02,0.01
4.2324449825928,0.0004866780804578,58.49424775532705,200.0,8.333333333333333e-05,0.56,0.23,0.18,0.07,0.86,0.06,0.02,0.01
4.3833173086212,0.0004992507742934999,59.204129021398664,200.0,8.333333333333333e-05,0.56,0.23,0.18,0.07,0.86,0.06,0.02,0.01
4.5341896346496,0.0005118234681291999,59.914010287470305,200.0,8.333333333333333e-05,0.56,0.23,0.18,0.07,0.86,0.06,0.02,0.01
4.685061960678,0.0005243961619648999,60.623891553541924,200.0,8.333333333333333e-05,0.56,0.23,0.18,0.07,0.86,0.06,0.02,0.01
4.835934286706401,0.0005369688558006,61.33377281961339,200.0,8.333333333333333e-05,0.56,0.23,0.18,0.07,0.86,0.06,0.02,0.01
4.986806612734801,0.0005495415496363,62.04365408568499,200.0,8.333333333333333e-05,0.56,0.23,0.18,0.07,0.86,0.06,0.02,0.01
5.137678938763201,0.000562114243472,62.75353535175664,200.0,8.333333333333333e-05,0.56,0.23,0.18,0.07,0.86,0.06,0.02,0.01
5.2885512647916,0.0005746869373077,63.46341661782823,200.0,8.333333333333333e-05,0.56,0.23,0.18,0.07,0.86,0.06,0.02,0.01
5.439423590820001,0.0005872596311434,64.17329788390009,200.0,8.333333333333333e-05,0.56,0.23,0.18,0.07,0.86,0.06,0.02,0.01
5.575690797172051,0.0005986152316727376,64.87442039952978,200.0,8.333333333333333e-05,0.56,0.23,0.18,0.07,0.86,0.06,0.02,0.01
5.711958003524101,0.0006099708322020751,65.57554291515919,200.0,8.333333333333333e-05,0.56,0.23,0.18,0.07,0.86,0.06,0.02,0.01
5.848225209876151,0.0006213264327314125,66.27666543078891,200.0,8.333333333333333e-05,0.56,0.23,0.18,0.07,0.86,0.06,0.02,0.01
5.984492416228201,0.00063268203326075,66.9777879464188,200.0,8.333333333333333e-05,0.56,0.23,0.18,0.07,0.86,0.06,0.02,0.01
6.12075962258025,0.0006440376337900876,67.67891046204849,200.0,8.333333333333333e-05,0.56,0.23,0.18,0.07,0.86,0.06,0.02,0.01
6.2570268289323,0.000655393234319425,68.38003297767797,200.0,8.333333333333333e-05,0.56,0.23,0.18,0.07,0.86,0.06,0.02,0.01
6.393294035284351,0.0006667488348487625,69.0811554933077,200.0,8.333333333333333e-05,0.56,0.23,0.18,0.07,0.86,0.06,0.02,0.01
6.529561241636401,0.0006781044353781,69.78227800893781,200.0,8.333333333333333e-05,0.56,0.23,0.18,0.07,0.86,0.06,0.02,0.01
6.68537339021025,0.0006910887810925875,70.48246358879409,200.0,8.333333333333333e-05,0.56,0.23,0.18,0.07,0.86,0.06,0.02,0.01
6.8411855387841,0.000704073126807075,71.1826491686501,200.0,8.333333333333333e-05,0.56,0.23,0.18,0.07,0.86,0.06,0.02,0.01
6.9969976873579505,0.0007170574725215625,71.88283474850638,200.0,8.333333333333333e-05,0.56,0.23,0.18,0.07,0.86,0.06,0.02,0.01
7.1528098359318,0.0007300418182360499,72.58302032836266,200.0,8.333333333333333e-05,0.56,0.23,0.18,0.07,0.86,0.06,0.02,0.01
7.30862198450565,0.0007430261639505374,73.28320590821896,200.0,8.333333333333333e-05,0.56,0.23,0.18,0.07,0.86,0.06,0.02,0.01
7.4644341330795,0.0007560105096650249,73.98339148807551,200.0,8.333333333333333e-05,0.56,0.23,0.18,0.07,0.86,0.06,0.02,0.01
7.620246281653349,0.0007689948553795125,74.68357706793182,200.0,8.333333333333333e-05,0.56,0.23,0.18,0.07,0.86,0.06,0.02,0.01
7.7760584302272,0.000781979201094,75.3837626477881,200.0,8.333333333333333e-05,0.56,0.23,0.18,0.07,0.86,0.06,0.02,0.01
7.940609205290549,0.0007956917656826124,76.08432921405202,200.0,8.333333333333333e-05,0.56,0.23,0.18,0.07,0.86,0.06,0.02,0.01
8.1051599803539,0.000809404330271225,76.78489578031545,200.0,8.333333333333333e-05,0.56,0.23,0.18,0.07,0.86,0.06,0.02,0.01
8.26971075541725,0.0008231168948598375,77.48546234657934,200.0,8.333333333333333e-05,0.56,0.23,0.18,0.07,0.86,0.06,0.02,0.01
8.4342615304806,0.00083682945944845,78.18602891284357,200.0,8.333333333333333e-05,0.56,0.23,0.18,0.07,0.86,0.06,0.02,0.01
8.598812305543948,0.0008505420240370624,78.88659547910746,200.0,8.333333333333333e-05,0.56,0.23,0.18,0.07,0.86,0.06,0.02,0.01
8.763363080607299,0.000864254588625675,79.58716204537166,200.0,8.333333333333333e-05,0.56,0.23,0.18,0.07,0.86,0.06,0.02,0.01
8.92791385567065,0.0008779671532142875,80.28772861163543,200.0,8.333333333333333e-05,0.56,0.23,0.18,0.07,0.86,0.06,0.02,0.01
9.092464630734,0.0008916797178029,80.98829517789932,200.0,8.333333333333333e-05,0.56,0.23,0.18,0.07,0.86,0.06,0.02,0.01
9.252092435179051,0.0009049820348399874,81.69125162181561,200.0,8.333333333333333e-05,0.56,0.23,0.18,0.07,0.86,0.06,0.02,0.01
9.4117202396241,0.0009182843518770749,82.39420806573142,200.0,8.333333333333333e-05,0.56,0.23,0.18,0.07,0.86,0.06,0.02,0.01
9.57134804406915,0.0009315866689141624,83.09716450964788,200.0,8.333333333333333e-05,0.56,0.23,0.18,0.07,0.86,0.06,0.02,0.01
9.730975848514202,0.00094488898595125,83.80012095356471,200.0,8.333333333333333e-05,0.56,0.23,0.18,0.07,0.86,0.06,0.02,0.01
9.890603652959252,0.0009581913029883375,84.50307739748104,200.0,8.333333333333333e-05,0.56,0.23,0.18,0.07,0.86,0.06,0.02,0.01
10.050231457404301,0.000971493620025425,85.20603384139683,200.0,8.333333333333333e-05,0.56,0.23,0.18,0.07,0.86,0.06,0.02,0.01
10.209859261849353,0.0009847959370625126,85.90899028531311,200.0,8.333333333333333e-05,0.56,0.23,0.18,0.07,0.86,0.06,0.02,0.01
10.369487066294402,0.0009980982540996,86.61194672922963,200.0,8.333333333333333e-05,0.56,0.23,0.18,0.07,0.86,0.06,0.02,0.01
10.529983295824653,0.0010114729398937876,87.31505037417895,200.0,8.333333333333333e-05,0.56,0.23,0.18,0.07,0.86,0.06,0.02,0.01
10.690479525354903,0.0010248476256879751,88.0181540191283,200.0,8.333333333333333e-05,0.56,0.23,0.18,0.07,0.86,0.06,0.02,0.01
10.850975754885152,0.0010382223114821626,88.72125766407748,200.0,8.333333333333333e-05,0.56,0.23,0.18,0.07,0.86,0.06,0.02,0.01
11.011471984415401,0.0010515969972763502,89.4243613090266,200.0,8.333333333333333e-05,0.56,0.23,0.18,0.07,0.86,0.06,0.02,0.01
11.17196821394565,0.0010649716830705377,90.12746495397596,200.0,8.333333333333333e-05,0.56,0.23,0.18,0.07,0.86,0.06,0.02,0.01
11.3324644434759,0.0010783463688647252,90.83056859892555,200.0,8.333333333333333e-05,0.56,0.23,0.18,0.07,0.86,0.06,0.02,0.01
11.492960673006149,0.0010917210546589127,91.53367224387499,200.0,8.333333333333333e-05,0.56,0.23,0.18,0.07,0.86,0.06,0.02,0.01
11.6534569025364,0.0011050957404531,92.2367758888244,200.0,8.333333333333333e-05,0.56,0.23,0.18,0.07,0.86,0.06,0.02,0.01
11.79857893367415,0.0011171892430479127,92.92814403880047,200.0,8.333333333333333e-05,0.56,0.23,0.18,0.07,0.86,0.06,0.02,0.01
11.9437009648119,0.0011292827456427252,93.61951218877678,200.0,8.333333333333333e-05,0.56,0.23,0.18,0.07,0.86,0.06,0.02,0.01
12.08882299594965,0.0011413762482375377,94.31088033875277,200.0,8.333333333333333e-05,0.56,0.23,0.18,0.07,0.86,0.06,0.02,0.01
12.233945027087401,0.0011534697508323501,95.00224848872807,200.0,8.333333333333333e-05,0.56,0.23,0.18,0.07,0.86,0.06,0.02,0.01
12.37906705822515,0.0011655632534271626,95.69361663870413,200.0,8.333333333333333e-05,0.56,0.23,0.18,0.07,0.86,0.06,0.02,0.01
12.5241890893629,0.001177656756021975,96.38498478868013,200.0,8.333333333333333e-05,0.56,0.23,0.18,0.07,0.86,0.06,0.02,0.01
12.669311120500652,0.0011897502586167875,97.07635293865629,200.0,8.333333333333333e-05,0.56,0.23,0.18,0.07,0.86,0.06,0.02,0.01
12.8144331516384,0.0012018437612116,97.76772108863275,200.0,8.333333333333333e-05,0.56,0.23,0.18,0.07,0.86,0.06,0.02,0.01
12.95327145500925,0.0012134136198258376,98.44798638969954,200.0,8.333333333333333e-05,0.56,0.23,0.18,0.07,0.86,0.06,0.02,0.01
13.0921097583801,0.0012249834784400751,99.12825169076629,200.0,8.333333333333333e-05,0.56,0.23,0.18,0.07,0.86,0.06,0.02,0.01
13.23094806175095,0.0012365533370543125,99.80851699183285,200.0,8.333333333333333e-05,0.56,0.23,0.18,0.07,0.86,0.06,0.02,0.01
13.3697863651218,0.00124812319566855,100.48878229289997,200.0,8.333333333333333e-05,0.56,0.23,0.18,0.07,0.86,0.06,0.02,0.01
13.50862466849265,0.0012596930542827876,101.16904759396678,200.0,8.333333333333333e-05,0.56,0.23,0.18,0.07,0.86,0.06,0.02,0.01
13.6474629718635,0.001271262912897025,101.84931289503355,200.0,8.333333333333333e-05,0.56,0.23,0.18,0.07,0.86,0.06,0.02,0.01
13.78630127523435,0.0012828327715112625,102.52957819610029,200.0,8.333333333333333e-05,0.56,0.23,0.18,0.07,0.86,0.06,0.02,0.01
13.9251395786052,0.0012944026301255,103.20984349716679,200.0,8.333333333333333e-05,0.56,0.23,0.18,0.07,0.86,0.06,0.02,0.01
14.047969654221902,0.001304638469760225,103.88913770880778,200.0,8.333333333333333e-05,0.56,0.23,0.18,0.07,0.86,0.06,0.02,0.01
14.1707997298386,0.00131487430939495,104.56843192044853,200.0,8.333333333333333e-05,0.56,0.23,0.18,0.07,0.86,0.06,0.02,0.01
14.2936298054553,0.0013251101490296749,105.24772613209005,200.0,8.333333333333333e-05,0.56,0.23,0.18,0.07,0.86,0.06,0.02,0.01
14.416459881072,0.0013353459886643998,105.92702034373167,200.0,8.333333333333333e-05,0.56,0.23,0.18,0.07,0.86,0.06,0.02,0.01
14.539289956688702,0.0013455818282991248,106.60631455537268,200.0,8.333333333333333e-05,0.56,0.23,0.18,0.07,0.86,0.06,0.02,0.01
14.6621200323054,0.0013558176679338498,107.285608767013,200.0,8.333333333333333e-05,0.56,0.23,0.18,0.07,0.86,0.06,0.02,0.01
14.7849501079221,0.0013660535075685747,107.96490297865383,200.0,8.333333333333333e-05,0.56,0.23,0.18,0.07,0.86,0.06,0.02,0.01
14.9077801835388,0.0013762893472033,108.64419719029459,200.0,8.333333333333333e-05,0.56,0.23,0.18,0.07,0.86,0.06,0.02,0.01
15.0543920153289,0.001388506999852475,109.30921930554209,200.0,8.333333333333333e-05,0.56,0.23,0.18,0.07,0.86,0.06,0.02,0.01
15.201003847119,0.0014007246525016498,109.97424142079043,200.0,8.333333333333333e-05,0.56,0.23,0.18,0.07,0.86,0.06,0.02,0.01
15.3476156789091,0.001412942305150825,110.6392635360377,200.0,8.333333333333333e-05,0.56,0.23,0.18,0.07,0.86,0.06,0.02,0.01
15.4942275106992,0.0014251599578,111.30428565128481,200.0,8.333333333333333e-05,0.56,0.23,0.18,0.07,0.86,0.06,0.02,0.01
15.6408393424893,0.001437377610449175,111.96930776653228,200.0,8.333333333333333e-05,0.56,0.23,0.18,0.07,0.86,0.06,0.02,0.01
15.7874511742794,0.00144959526309835,112.63432988177944,200.0,8.333333333333333e-05,0.56,0.23,0.18,0.07,0.86,0.06,0.02,0.01
15.9340630060695,0.001461812915747525,113.29935199702705,200.0,8.333333333333333e-05,0.56,0.23,0.18,0.07,0.86,0.06,0.02,0.01
16.0806748378596,0.0014740305683967,113.96437411227458,200.0,8.333333333333333e-05,0.56,0.23,0.18,0.07,0.86,0.06,0.02,0.01
16.24212839065425,0.0014874850311295874,114.62047411951681,200.0,8.333333333333333e-05,0.56,0.23,0.18,0.07,0.86,0.06,0.02,0.01
16.4035819434489,0.001500939493862475,115.27657412675919,200.0,8.333333333333333e-05,0.56,0.23,0.18,0.07,0.86,0.06,0.02,0.01
16.56503549624355,0.0015143939565953625,115.93267413400125,200.0,8.333333333333333e-05,0.56,0.23,0.18,0.07,0.86,0.06,0.02,0.01
16.7264890490382,0.0015278484193282501,116.58877414124298,200.0,8.333333333333333e-05,0.56,0.23,0.18,0.07,0.86,0.06,0.02,0.01
16.88794260183285,0.0015413028820611377,117.24487414848521,200.0,8.333333333333333e-05,0.56,0.23,0.18,0.07,0.86,0.06,0.02,0.01
17.0493961546275,0.001554757344794025,117.9009741557274,200.0,8.333333333333333e-05,0.56,0.23,0.18,0.07,0.86,0.06,0.02,0.01
17.21084970742215,0.0015682118075269124,118.55707416296968,200.0,8.333333333333333e-05,0.56,0.23,0.18,0.07,0.86,0.06,0.02,0.01
17.3723032602168,0.0015816662702598,119.21317417021189,200.0,8.333333333333333e-05,0.56,0.23,0.18,0.07,0.86,0.06,0.02,0.01
17.516624629357352,0.0015936930510215125,119.85578610674415,200.0,8.333333333333333e-05,0.56,0.23,0.18,0.07,0.86,0.06,0.02,0.01
17.6609459984979,0.001605719831783225,120.49839804327758,200.0,8.333333333333333e-05,0.56,0.23,0.18,0.07,0.86,0.06,0.02,0.01
17.80526736763845,0.0016177466125449375,121.14100997981004,200.0,8.333333333333333e-05,0.56,0.23,0.18,0.07,0.86,0.06,0.02,0.01
17.949588736779,0.00162977339330665,121.7836219163415,200.0,8.333333333333333e-05,0.56,0.23,0.18,0.07,0.86,0.06,0.02,0.01
18.093910105919548,0.0016418001740683625,122.42623385287382,200.0,8.333333333333333e-05,0.56,0.23,0.18,0.07,0.86,0.06,0.02,0.01
18.238231475060097,0.001653826954830075,123.06884578940739,200.0,8.333333333333333e-05,0.56,0.23,0.18,0.07,0.86,0.06,0.02,0.01
18.382552844200646,0.0016658537355917875,123.71145772593974,200.0,8.333333333333333e-05,0.56,0.23,0.18,0.07,0.86,0.06,0.02,0.01
18.5268742133412,0.0016778805163535,124.35406966247163,200.0,8.333333333333333e-05,0.56,0.23,0.18,0.07,0.86,0.06,0.02,0.01
18.67305765713175,0.0016900624700027125,124.9810417293879,200.0,8.333333333333333e-05,0.56,0.23,0.18,0.07,0.86,0.06,0.02,0.01
18.819241100922298,0.001702244423651925,125.60801379630362,200.0,8.333333333333333e-05,0.56,0.23,0.18,0.07,0.86,0.06,0.02,0.01
18.96542454471285,0.0017144263773011376,126.2349858632198,200.0,8.333333333333333e-05,0.56,0.23,0.18,0.07,0.86,0.06,0.02,0.01
19.1116079885034,0.00172660833095035,126.86195793013624,200.0,8.333333333333333e-05,0.56,0.23,0.18,0.07,0.86,0.06,0.02,0.01
19.25779143229395,0.0017387902845995623,127.48892999705241,200.0,8.333333333333333e-05,0.56,0.23,0.18,0.07,0.86,0.06,0.02,0.01
19.4039748760845,0.0017509722382487748,128.1159020639682,200.0,8.333333333333333e-05,0.56,0.23,0.18,0.07,0.86,0.06,0.02,0.01
19.550158319875052,0.0017631541918979874,128.7428741308842,200.0,8.333333333333333e-05,0.56,0.23,0.18,0.07,0.86,0.06,0.02,0.01
19.6963417636656,0.0017753361455472,129.36984619779997,200.0,8.333333333333333e-05,0.56,0.23,0.18,0.07,0.86,0.06,0.02,0.01
19.8683845956546,0.00178967304821295,129.99080812811587,200.0,8.333333333333333e-05,0.56,0.23,0.18,0.07,0.86,0.06,0.02,0.01
20.0404274276436,0.0018040099508786999,130.6117700584325,200.0,8.333333333333333e-05,0.56,0.23,0.18,0.07,0.86,0.06,0.02,0.01
20.2124702596326,0.0018183468535444497,131.2327319887483,200.0,8.333333333333333e-05,0.56,0.23,0.18,0.07,0.86,0.06,0.02,0.01
20.3845130916216,0.0018326837562101998,131.8536939190639,200.0,8.333333333333333e-05,0.56,0.23,0.18,0.07,0.86,0.06,0.02,0.01
20.5565559236106,0.00184702065887595,132.47465584937984,200.0,8.333333333333333e-05,0.56,0.23,0.18,0.07,0.86,0.06,0.02,0.01
20.7285987555996,0.0018613575615417,133.09561777969645,200.0,8.333333333333333e-05,0.56,0.23,0.18,0.07,0.86,0.06,0.02,0.01
20.900641587588602,0.00187569446420745,133.71657971001247,200.0,8.333333333333333e-05,0.56,0.23,0.18,0.07,0.86,0.06,0.02,0.01
21.0726844195776,0.0018900313668732,134.3375416403283,200.0,8.333333333333333e-05,0.56,0.23,0.18,0.07,0.86,0.06,0.02,0.01
21.237172615527754,0.0019037387165357126,134.94666391710047,200.0,8.333333333333333e-05,0.56,0.23,0.18,0.07,0.86,0.06,0.02,0.01
21.401660811477903,0.001917446066198225,135.55578619387234,200.0,8.333333333333333e-05,0.56,0.23,0.18,0.07,0.86,0.06,0.02,0.01
21.566149007428052,0.0019311534158607375,136.1649084706442,200.0,8.333333333333333e-05,0.56,0.23,0.18,0.07,0.86,0.06,0.02,0.01
21.7306372033782,0.00194486076552325,136.77403074741585,200.0,8.333333333333333e-05,0.56,0.23,0.18,0.07,0.86,0.06,0.02,0.01
21.89512539932835,0.0019585681151857628,137.3831530241879,200.0,8.333333333333333e-05,0.56,0.23,0.18,0.07,0.86,0.06,0.02,0.01
22.0596135952785,0.0019722754648482752,137.9922753009606,200.0,8.333333333333333e-05,0.56,0.23,0.18,0.07,0.86,0.06,0.02,0.01
22.224101791228648,0.0019859828145107877,138.60139757773305,200.0,8.333333333333333e-05,0.56,0.23,0.18,0.07,0.86,0.06,0.02,0.01
22.3885899871788,0.0019996901641733,139.2105198545033,200.0,8.333333333333333e-05,0.56,0.23,0.18,0.07,0.86,0.06,0.02,0.01
22.587170305002303,0.002016238523991925,139.80869275631343,200.0,8.333333333333333e-05,0.56,0.23,0.18,0.07,0.86,0.06,0.02,0.01
22.7857506228258,0.00203278688381055,140.4068656581236,200.0,8.333333333333333e-05,0.56,0.23,0.18,0.07,0.86,0.06,0.02,0.01
22.9843309406493,0.002049335243629175,141.00503855993378,200.0,8.333333333333333e-05,0.56,0.23,0.18,0.07,0.86,0.06,0.02,0.01
23.1829112584728,0.0020658836034478,141.60321146174545,200.0,8.333333333333333e-05,0.56,0.23,0.18,0.07,0.86,0.06,0.02,0.01
23.3814915762963,0.002082431963266425,142.20138436355558,200.0,8.333333333333333e-05,0.56,0.23,0.18,0.07,0.86,0.06,0.02,0.01
23.580071894119797,0.0020989803230850503,142.79955726536508,200.0,8.333333333333333e-05,0.56,0.23,0.18,0.07,0.86,0.06,0.02,0.01
23.778652211943296,0.002115528682903675,143.39773016717496,200.0,8.333333333333333e-05,0.56,0.23,0.18,0.07,0.86,0.06,0.02,0.01
23.9772325297668,0.0021320770427223,143.99590306898733,200.0,8.333333333333333e-05,0.56,0.23,0.18,0.07,0.86,0.06,0.02,0.01
24.1480765240266,0.0021463140422439504,144.58381876309636,200.0,8.333333333333333e-05,0.56,0.23,0.18,0.07,0.86,0.06,0.02,0.01
24.318920518286397,0.0021605510417656002,145.17173445720277,200.0,8.333333333333333e-05,0.56,0.23,0.18,0.07,0.86,0.06,0.02,0.01
24.4897645125462,0.00217478804128725,145.75965015131172,200.0,8.333333333333333e-05,0.56,0.23,0.18,0.07,0.86,0.06,0.02,0.01
24.660608506806,0.0021890250408089004,146.34756584542018,200.0,8.333333333333333e-05,0.56,0.23,0.18,0.07,0.86,0.06,0.02,0.01
24.8314525010658,0.00220326204033055,146.9354815395292,200.0,8.333333333333333e-05,0.56,0.23,0.18,0.07,0.86,0.06,0.02,0.01
25.002296495325602,0.0022174990398522,147.52339723363895,200.0,8.333333333333333e-05,0.56,0.23,0.18,0.07,0.86,0.06,0.02,0.01
25.173140489585403,0.0022317360393738503,148.11131292774837,200.0,8.333333333333333e-05,0.56,0.23,0.18,0.07,0.86,0.06,0.02,0.01
25.343984483845205,0.0022459730388955,148.69922862185825,200.0,8.333333333333333e-05,0.56,0.23,0.18,0.07,0.86,0.06,0.02,0.01
25.504373139085505,0.0022593387601655248,149.26760570222797,200.0,8.333333333333333e-05,0.56,0.23,0.18,0.07,0.86,0.06,0.02,0.01
25.664761794325806,0.00227270448143555,149.83598278259805,200.0,8.333333333333333e-05,0.56,0.23,0.18,0.07,0.86,0.06,0.02,0.01
25.825150449566102,0.002286070202705575,150.40435986296782,200.0,8.333333333333333e-05,0.56,0.23,0.18,0.07,0.86,0.06,0.02,0.01
25.985539104806403,0.0022994359239756,150.97273694333748,200.0,8.333333333333333e-05,0.56,0.23,0.18,0.07,0.86,0.06,0.02,0.01
26.145927760046703,0.002312801645245625,151.54111402370717,200.0,8.333333333333333e-05,0.56,0.23,0.18,0.07,0.86,0.06,0.02,0.01
26.306316415287,0.00232616736651565,152.10949110407643,200.0,8.333333333333333e-05,0.56,0.23,0.18,0.07,0.86,0.06,0.02,0.01
26.4667050705273,0.002339533087785675,152.6778681844458,200.0,8.333333333333333e-05,0.56,0.23,0.18,0.07,0.86,0.06,0.02,0.01
26.6270937257676,0.0023528988090557,153.246245264815,200.0,8.333333333333333e-05,0.56,0.23,0.18,0.07,0.86,0.06,0.02,0.01
26.8043333204526,0.00236766877527945,153.79883601157812,200.0,8.333333333333333e-05,0.56,0.23,0.18,0.07,0.86,0.06,0.02,0.01
26.9815729151376,0.0023824387415032,154.35142675834197,200.0,8.333333333333333e-05,0.56,0.23,0.18,0.07,0.86,0.06,0.02,0.01
27.158812509822603,0.0023972087077269505,154.9040175051054,200.0,8.333333333333333e-05,0.56,0.23,0.18,0.07,0.86,0.06,0.02,0.01
27.3360521045076,0.0024119786739507003,155.4566082518689,200.0,8.333333333333333e-05,0.56,0.23,0.18,0.07,0.86,0.06,0.02,0.01
27.513291699192603,0.00242674864017445,156.00919899863197,200.0,8.333333333333333e-05,0.56,0.23,0.18,0.07,0.86,0.06,0.02,0.01
27.690531293877605,0.0024415186063982,156.56178974539557,200.0,8.333333333333333e-05,0.56,0.23,0.18,0.07,0.86,0.06,0.02,0.01
27.867770888562603,0.00245628857262195,157.11438049215838,200.0,8.333333333333333e-05,0.56,0.23,0.18,0.07,0.86,0.06,0.02,0.01
28.045010483247605,0.0024710585388457,157.66697123891905,200.0,8.333333333333333e-05,0.56,0.23,0.18,0.07,0.86,0.06,0.02,0.01
28.225040681918404,0.0024860610554016003,158.20278279171004,200.0,8.333333333333333e-05,0.56,0.23,0.18,0.07,0.86,0.06,0.02,0.01
28.405070880589204,0.0025010635719575,158.73859434450193,200.0,8.333333333333333e-05,0.56,0.23,0.18,0.07,0.86,0.06,0.02,0.01
28.585101079260003,0.0025160660885134,159.27440589729326,200.0,8.333333333333333e-05,0.56,0.23,0.18,0.07,0.86,0.06,0.02,0.01
28.765131277930802,0.0025310686050693003,159.81021745008368,200.0,8.333333333333333e-05,0.56,0.23,0.18,0.07,0.86,0.06,0.02,0.01
28.9451614766016,0.0025460711216252,160.3460290028748,200.0,8.333333333333333e-05,0.56,0.23,0.18,0.07,0.86,0.06,0.02,0.01
29.1251916752724,0.0025610736381811,160.8818405556659,200.0,8.333333333333333e-05,0.56,0.23,0.18,0.07,0.86,0.06,0.02,0.01
29.3052218739432,0.002576076154737,161.417652108457,200.0,8.333333333333333e-05,0.56,0.23,0.18,0.07,0.86,0.06,0.02,0.01
29.485252072614,0.0025910786712929,161.95346366124966,200.0,8.333333333333333e-05,0.56,0.23,0.18,0.07,0.86,0.06,0.02,0.01
29.6738454583599,0.002606794786771725,162.46492039563904,200.0,8.333333333333333e-05,0.56,0.23,0.18,0.07,0.86,0.06,0.02,0.01
29.8624388441058,0.00262251090225055,162.97637713002808,200.0,8.333333333333333e-05,0.56,0.23,0.18,0.07,0.86,0.06,0.02,0.01
30.0510322298517,0.002638227017729375,163.48783386441727,200.0,8.333333333333333e-05,0.56,0.23,0.18,0.07,0.86,0.06,0.02,0.01
30.2396256155976,0.0026539431332082,163.99929059880637,200.0,8.333333333333333e-05,0.56,0.23,0.18,0.07,0.86,0.06,0.02,0.01
30.4282190013435,0.0026696592486870245,164.5107473331957,200.0,8.333333333333333e-05,0.56,0.23,0.18,0.07,0.86,0.06,0.02,0.01
30.6168123870894,0.0026853753641658496,165.02220406758386,200.0,8.333333333333333e-05,0.56,0.23,0.18,0.07,0.86,0.06,0.02,0.01
30.8054057728353,0.0027010914796446748,165.5336608019732,200.0,8.333333333333333e-05,0.56,0.23,0.18,0.07,0.86,0.06,0.02,0.01
30.9939991585812,0.0027168075951235,166.04511753636297,200.0,8.333333333333333e-05,0.56,0.23,0.18,0.07,0.86,0.06,0.02,0.01
31.201182410185204,0.0027340728660905,166.5317168902181,200.0,8.333333333333333e-05,0.56,0.23,0.18,0.07,0.86,0.06,0.02,0.01
31.408365661789205,0.0027513381370574998,167.0183162440738,200.0,8.333333333333333e-05,0.56,0.23,0.18,0.07,0.86,0.06,0.02,0.01
31.615548913393205,0.0027686034080244997,167.50491559792886,200.0,8.333333333333333e-05,0.56,0.23,0.18,0.07,0.86,0.06,0.02,0.01
31.822732164997205,0.0027858686789914997,167.99151495178444,200.0,8.333333333333333e-05,0.56,0.23,0.18,0.07,0.86,0.06,0.02,0.01
32.029915416601206,0.0028031339499584996,168.47811430563945,200.0,8.333333333333333e-05,0.56,0.23,0.18,0.07,0.86,0.06,0.02,0.01
32.237098668205206,0.0028203992209254996,168.9647136594948,200.0,8.333333333333333e-05,0.56,0.23,0.18,0.07,0.86,0.06,0.02,0.01
32.44428191980921,0.0028376644918925,169.45131301335022,200.0,8.333333333333333e-05,0.56,0.23,0.18,0.07,0.86,0.06,0.02,0.01
32.65146517141321,0.0028549297628595,169.93791236720418,200.0,8.333333333333333e-05,0.56,0.23,0.18,0.07,0.86,0.06,0.02,0.01
32.87541324092041,0.0028735921019851,170.3930326098822,200.0,8.333333333333333e-05,0.56,0.23,0.18,0.07,0.86,0.06,0.02,0.01
33.09936131042761,0.0028922544411107,170.8481528525621,200.0,8.333333333333333e-05,0.56,0.23,0.18,0.07,0.86,0.06,0.02,0.01
33.32330937993481,0.0029109167802363,171.30327309523992,200.0,8.333333333333333e-05,0.56,0.23,0.18,0.07,0.86,0.06,0.02,0.01
33.54725744944201,0.0029295791193619,171.75839333791401,200.0,8.333333333333333e-05,0.56,0.23,0.18,0.07,0.86,0.06,0.02,0.01
33.7712055189492,0.0029482414584875,172.21351358059218,200.0,8.333333333333333e-05,0.56,0.23,0.18,0.07,0.86,0.06,0.02,0.01
33.995153588456404,0.0029669037976131,172.6686338232726,200.0,8.333333333333333e-05,0.56,0.23,0.18,0.07,0.86,0.06,0.02,0.01
34.219101657963606,0.0029855661367387,173.12375406595075,200.0,8.333333333333333e-05,0.56,0.23,0.18,0.07,0.86,0.06,0.02,0.01
34.44304972747081,0.0030042284758643,173.5788743086284,200.0,8.333333333333333e-05,0.56,0.23,0.18,0.07,0.86,0.06,0.02,0.01
34.7035732177287,0.0030259387667191254,173.98729975847164,200.0,8.333333333333333e-05,0.56,0.23,0.18,0.07,0.86,0.06,0.02,0.01
34.964096707986606,0.0030476490575739503,174.3957252083149,200.0,8.333333333333333e-05,0.56,0.23,0.18,0.07,0.86,0.06,0.02,0.01
35.22462019824451,0.0030693593484287752,174.80415065815805,200.0,8.333333333333333e-05,0.56,0.23,0.18,0.07,0.86,0.06,0.02,0.01
35.485143688502404,0.0030910696392836,175.2125761080027,200.0,8.333333333333333e-05,0.56,0.23,0.18,0.07,0.86,0.06,0.02,0.01
35.7456671787603,0.003112779930138425,175.62100155784591,200.0,8.333333333333333e-05,0.56,0.23,0.18,0.07,0.86,0.06,0.02,0.01
36.0061906690182,0.00313449022099325,176.02942700768634,200.0,8.333333333333333e-05,0.56,0.23,0.18,0.07,0.86,0.06,0.02,0.01
36.266714159276106,0.003156200511848075,176.43785245752954,200.0,8.333333333333333e-05,0.56,0.23,0.18,0.07,0.86,0.06,0.02,0.01
36.527237649534,0.0031779108027029,176.8462779073751,200.0,8.333333333333333e-05,0.56,0.23,0.18,0.07,0.86,0.06,0.02,0.01
36.8318870295684,0.0032032982510391004,177.2025697785131,200.0,8.333333333333333e-05,0.56,0.23,0.18,0.07,0.86,0.06,0.02,0.01
37.1365364096028,0.0032286856993753,177.5588616496513,200.0,8.333333333333333e-05,0.56,0.23,0.18,0.07,0.86,0.06,0.02,0.01
37.4411857896372,0.0032540731477115,177.91515352078946,200.0,8.333333333333333e-05,0.56,0.23,0.18,0.07,0.86,0.06,0.02,0.01
37.7458351696716,0.0032794605960477,178.27144539192756,200.0,8.333333333333333e-05,0.56,0.23,0.18,0.07,0.86,0.06,0.02,0.01
38.050484549706,0.0033048480443839,178.62773726306563,200.0,8.333333333333333e-05,0.56,0.23,0.18,0.07,0.86,0.06,0.02,0.01
38.355133929740404,0.0033302354927201,178.9840291342029,200.0,8.333333333333333e-05,0.56,0.23,0.18,0.07,0.86,0.06,0.02,0.01
38.6597833097748,0.0033556229410562997,179.3403210053412,200.0,8.333333333333333e-05,0.56,0.23,0.18,0.07,0.86,0.06,0.02,0.01
38.9644326898092,0.0033810103893925,179.6966128764813,200.0,8.333333333333333e-05,0.56,0.23,0.18,0.07,0.86,0.06,0.02,0.01
39.310022889367346,0.0034098095726890123,179.99221132926243,200.0,8.333333333333333e-05,0.56,0.23,0.18,0.07,0.86,0.06,0.02,0.01
39.6556130889255,0.003438608755985525,180.28780978204335,200.0,8.333333333333333e-05,0.56,0.23,0.18,0.07,0.86,0.06,0.02,0.01
40.00120328848365,0.0034674079392820376,180.58340823482433,200.0,8.333333333333333e-05,0.56,0.23,0.18,0.07,0.86,0.06,0.02,0.01
40.3467934880418,0.00349620712257855,180.8790066876051,200.0,8.333333333333333e-05,0.56,0.23,0.18,0.07,0.86,0.06,0.02,0.01
40.69238368759995,0.0035250063058750625,181.1746051403861,200.0,8.333333333333333e-05,0.56,0.23,0.18,0.07,0.86,0.06,0.02,0.01
41.0379738871581,0.003553805489171575,181.4702035931671,200.0,8.333333333333333e-05,0.56,0.23,0.18,0.07,0.86,0.06,0.02,0.01
41.38356408671625,0.0035826046724680874,181.76580204594808,200.0,8.333333333333333e-05,0.56,0.23,0.18,0.07,0.86,0.06,0.02,0.01
41.7291542862744,0.0036114038557646,182.06140049872891,200.0,8.333333333333333e-05,0.56,0.23,0.18,0.07,0.86,0.06,0.02,0.01
42.12343859966626,0.0036442608818805875,182.29396794925316,200.0,8.333333333333333e-05,0.56,0.23,0.18,0.07,0.86,0.06,0.02,0.01
42.51772291305811,0.0036771179079965748,182.52653539977663,200.0,8.333333333333333e-05,0.56,0.23,0.18,0.07,0.86,0.06,0.02,0.01
42.91200722644996,0.003709974934112562,182.75910285030102,200.0,8.333333333333333e-05,0.56,0.23,0.18,0.07,0.86,0.06,0.02,0.01
43.30629153984181,0.0037428319602285497,182.99167030082643,200.0,8.333333333333333e-05,0.56,0.23,0.18,0.07,0.86,0.06,0.02,0.01
43.70057585323366,0.0037756889863445374,183.2242377513507,200.0,8.333333333333333e-05,0.56,0.23,0.18,0.07,0.86,0.06,0.02,0.01
44.09486016662551,0.003808546012460525,183.45680520187403,200.0,8.333333333333333e-05,0.56,0.23,0.18,0.07,0.86,0.06,0.02,0.01
44.48914448001736,0.003841403038576513,183.68937265239788,200.0,8.333333333333333e-05,0.56,0.23,0.18,0.07,0.86,0.06,0.02,0.01
44.88342879340921,0.0038742600646925,183.92194010292212,200.0,8.333333333333333e-05,0.56,0.23,0.18,0.07,0.86,0.06,0.02,0.01
45.312966211764305,0.003910054849555425,184.09414564904563,200.0,8.333333333333333e-05,0.56,0.23,0.18,0.07,0.86,0.06,0.02,0.01
45.7425036301194,0.00394584963441835,184.26635119516945,200.0,8.333333333333333e-05,0.56,0.23,0.18,0.07,0.86,0.06,0.02,0.01
46.1720410484745,0.003981644419281275,184.43855674129287,200.0,8.333333333333333e-05,0.56,0.23,0.18,0.07,0.86,0.06,0.02,0.01
46.6015784668296,0.0040174392041442,184.6107622874142,200.0,8.333333333333333e-05,0.56,0.23,0.18,0.07,0.86,0.06,0.02,0.01
47.031115885184704,0.004053233989007124,184.78296783353773,200.0,8.333333333333333e-05,0.56,0.23,0.18,0.07,0.86,0.06,0.02,0.01
47.4606533035398,0.004089028773870049,184.9551733796632,200.0,8.333333333333333e-05,0.56,0.23,0.18,0.07,0.86,0.06,0.02,0.01
47.890190721894896,0.0041248235587329745,185.12737892578693,200.0,8.333333333333333e-05,0.56,0.23,0.18,0.07,0.86,0.06,0.02,0.01
48.31972814024999,0.0041606183435959,185.29958447191026,200.0,8.333333333333333e-05,0.56,0.23,0.18,0.07,0.86,0.06,0.02,0.01
48.795510090125546,0.004200266839418862,185.41445487232176,200.0,8.333333333333333e-05,0.56,0.23,0.18,0.07,0.86,0.06,0.02,0.01
49.27129204000109,0.004239915335241824,185.5293252727328,200.0,8.333333333333333e-05,0.56,0.23,0.18,0.07,0.86,0.06,0.02,0.01
49.74707398987664,0.0042795638310647865,185.6441956731443,200.0,8.333333333333333e-05,0.56,0.23,0.18,0.07,0.86,0.06,0.02,0.01
50.22285593975219,0.00431921232688775,185.75906607355626,200.0,8.333333333333333e-05,0.56,0.23,0.18,0.07,0.86,0.06,0.02,0.01
50.69863788962775,0.004358860822710713,185.87393647396783,200.0,8.333333333333333e-05,0.56,0.23,0.18,0.07,0.86,0.06,0.02,0.01
51.1744198395033,0.004398509318533675,185.98880687438,200.0,8.333333333333333e-05,0.56,0.23,0.18,0.07,0.86,0.06,0.02,0.01
51.650201789378855,0.0044381578143566375,186.10367727479147,200.0,8.333333333333333e-05,0.56,0.23,0.18,0.07,0.86,0.06,0.02,0.01
52.1259837392544,0.0044778063101796,186.2185476752026,200.0,8.333333333333333e-05,0.56,0.23,0.18,0.07,0.86,0.06,0.02,0.01
52.640695924172704,0.0045206989922561246,186.28349878934608,200.0,8.333333333333333e-05,0.56,0.23,0.18,0.07,0.86,0.06,0.02,0.01
53.155408109091,0.00456359167433265,186.3484499034881,200.0,8.333333333333333e-05,0.56,0.23,0.18,0.07,0.86,0.06,0.02,0.01
53.6701202940093,0.004606484356409176,186.41340101763177,200.0,8.333333333333333e-05,0.56,0.23,0.18,0.07,0.86,0.06,0.02,0.01
54.1848324789276,0.0046493770384857,186.47835213177643,200.0,8.333333333333333e-05,0.56,0.23,0.18,0.07,0.86,0.06,0.02,0.01
54.6995446638459,0.004692269720562225,186.5433032459199,200.0,8.333333333333333e-05,0.56,0.23,0.18,0.07,0.86,0.06,0.02,0.01
55.2142568487642,0.00473516240263875,186.60825436006326,200.0,8.333333333333333e-05,0.56,0.23,0.18,0.07,0.86,0.06,0.02,0.01
55.7289690336825,0.0047780550847152745,186.67320547420647,200.0,8.333333333333333e-05,0.56,0.23,0.18,0.07,0.86,0.06,0.02,0.01
56.2436812186008,0.0048209477667918,186.73815658834988,200.0,8.333333333333333e-05,0.56,0.23,0.18,0.07,0.86,0.06,0.02,0.01
56.78500134956025,0.004866057777705088,186.76952331065124,200.0,8.333333333333333e-05,0.56,0.23,0.18,0.07,0.86,0.06,0.02,0.01
57.326321480519695,0.004911167788618375,186.8008900329519,200.0,8.333333333333333e-05,0.56,0.23,0.18,0.07,0.86,0.06,0.02,0.01
57.867641611479144,0.0049562777995316625,186.83225675525355,200.0,8.333333333333333e-05,0.56,0.23,0.18,0.07,0.86,0.06,0.02,0.01
58.4089617424386,0.00500138781044495,186.86362347755534,200.0,8.333333333333333e-05,0.56,0.23,0.18,0.07,0.86,0.06,0.02,0.01
58.950281873398055,0.005046497821358238,186.89499019985666,200.0,8.333333333333333e-05,0.56,0.23,0.18,0.07,0.86,0.06,0.02,0.01
59.4916020043575,0.005091607832271526,186.9263569221577,200.0,8.333333333333333e-05,0.56,0.23,0.18,0.07,0.86,0.06,0.02,0.01
60.03292213531695,0.005136717843184813,186.9577236444586,200.0,8.333333333333333e-05,0.56,0.23,0.18,0.07,0.86,0.06,0.02,0.01
60.5742422662764,0.0051818278540981,186.9890903667594,200.0,8.333333333333333e-05,0.56,0.23,0.18,0.07,0.86,0.06,0.02,0.01
61.11347626748745,0.005226764020865688,186.99842935271366,200.0,8.333333333333333e-05,0.56,0.23,0.18,0.07,0.86,0.06,0.02,0.01
61.6527102686985,0.005271700187633276,187.00776833866823,200.0,8.333333333333333e-05,0.56,0.23,0.18,0.07,0.86,0.06,0.02,0.01
62.19194426990955,0.005316636354400863,187.01710732462288,200.0,8.333333333333333e-05,0.56,0.23,0.18,0.07,0.86,0.06,0.02,0.01
62.7311782711206,0.005361572521168451,187.0264463105779,200.0,8.333333333333333e-05,0.56,0.23,0.18,0.07,0.86,0.06,0.02,0.01
63.27041227233165,0.005406508687936038,187.0357852965322,200.0,8.333333333333333e-05,0.56,0.23,0.18,0.07,0.86,0.06,0.02,0.01
63.8096462735427,0.005451444854703625,187.0451242824855,200.0,8.333333333333333e-05,0.56,0.23,0.18,0.07,0.86,0.06,0.02,0.01
64.34888027475375,0.005496381021471213,187.05446326843975,200.0,8.333333333333333e-05,0.56,0.23,0.18,0.07,0.86,0.06,0.02,0.01
64.8881142759648,0.0055413171882388,187.063802254395,200.0,8.333333333333333e-05,0.56,0.23,0.18,0.07,0.86,0.06,0.02,0.01