File: datasets/al_6061_comp/csv/T_200_D_2.csv
Time,Strain(%),Stress(MPa),Temp(C),SR(%/s),Si(%),Fe(%),Cu(%),Mn(%),Mg(%),Cr(%),Zn(%),Ti(%)
0.0,9.0298004880001e-05,4.287924626148458,200.0,8.333333333333333e-05,0.67,0.28,0.23,0.05,0.9,0.05,0.03,0.02
0.2366287857557939,0.00011001707035965049,5.241153708316474,200.0,8.333333333333333e-05,0.67,0.28,0.23,0.05,0.9,0.05,0.03,0.02
0.4732575715115878,0.0001297361358393,6.194382790484491,200.0,8.333333333333333e-05,0.67,0.28,0.23,0.05,0.9,0.05,0.03,0.02
0.5873392147019879,0.0001392429394385,7.25506910213524,200.0,8.333333333333333e-05,0.67,0.28,0.23,0.05,0.9,0.05,0.03,0.02
0.701420857892388,0.0001487497430377,8.315755413785979,200.0,8.333333333333333e-05,0.67,0.28,0.23,0.05,0.9,0.05,0.03,0.02
0.8605232444321881,0.00016200827524935,9.37840613711764,200.0,8.333333333333333e-05,0.67,0.28,0.23,0.05,0.9,0.05,0.03,0.02
1.0196256309719882,0.000175266807461,10.4410568604493,200.0,8.333333333333333e-05,0.67,0.28,0.23,0.05,0.9,0.05,0.03,0.02
1.121476811555988,0.000183754405843,11.544458015323599,200.0,8.333333333333333e-05,0.67,0.28,0.23,0.05,0.9,0.05,0.03,0.02
1.223327992139988,0.000192242004225,12.6478591701979,200.0,8.333333333333333e-05,0.67,0.28,0.23,0.05,0.9,0.05,0.03,0.02
1.302519160055988,0.000198841268218,13.808979257035194,200.0,8.333333333333333e-05,0.67,0.28,0.23,0.05,0.9,0.05,0.03,0.02
1.381710327971988,0.000205440532211,14.970099343872503,200.0,8.333333333333333e-05,0.67,0.28,0.23,0.05,0.9,0.05,0.03,0.02
1.4723115687791881,0.0002129906356116,16.106567244107204,200.0,8.333333333333333e-05,0.67,0.28,0.23,0.05,0.9,0.05,0.03,0.02
1.5629128095863882,0.0002205407390122,17.243035144341874,200.0,8.333333333333333e-05,0.67,0.28,0.23,0.05,0.9,0.05,0.03,0.02
1.6610768760851882,0.00022872107788710002,18.35087193556488,200.0,8.333333333333333e-05,0.67,0.28,0.23,0.05,0.9,0.05,0.03,0.02
1.759240942583988,0.000236901416762,19.45870872678784,200.0,8.333333333333333e-05,0.67,0.28,0.23,0.05,0.9,0.05,0.03,0.02
1.8020290480115881,0.0002404670922143,20.617487884608444,200.0,8.333333333333333e-05,0.67,0.28,0.23,0.05,0.9,0.05,0.03,0.02
1.844817153439188,0.0002440327676666,21.77626704242912,200.0,8.333333333333333e-05,0.67,0.28,0.23,0.05,0.9,0.05,0.03,0.02
1.962627135875388,0.00025385026620295,22.955752707587816,200.0,8.333333333333333e-05,0.67,0.28,0.23,0.05,0.9,0.05,0.03,0.02
2.080437118311588,0.0002636677647393,24.1352383727465,200.0,8.333333333333333e-05,0.67,0.28,0.23,0.05,0.9,0.05,0.03,0.02
2.2143857387411883,0.0002748301497751,25.396347880766847,200.0,8.333333333333333e-05,0.67,0.28,0.23,0.05,0.9,0.05,0.03,0.02
2.348334359170788,0.0002859925348109,26.657457388787194,200.0,8.333333333333333e-05,0.67,0.28,0.23,0.05,0.9,0.05,0.03,0.02
2.5497013895297886,0.00030277312067415003,27.95484693961025,200.0,8.333333333333333e-05,0.67,0.28,0.23,0.05,0.9,0.05,0.03,0.02
2.7510684198887887,0.0003195537065374,29.25223649043329,200.0,8.333333333333333e-05,0.67,0.28,0.23,0.05,0.9,0.05,0.03,0.02
2.9916450240545887,0.00033960175688455,30.56379840796689,200.0,8.333333333333333e-05,0.67,0.28,0.23,0.05,0.9,0.05,0.03,0.02
3.2322216282203886,0.0003596498072317,31.875360325500477,200.0,8.333333333333333e-05,0.67,0.28,0.23,0.05,0.9,0.05,0.03,0.02
3.4284907208825883,0.00037600556495355,33.17953903992733,200.0,8.333333333333333e-05,0.67,0.28,0.23,0.05,0.9,0.05,0.03,0.02
3.624759813544788,0.0003923613226754,34.483717754354245,200.0,8.333333333333333e-05,0.67,0.28,0.23,0.05,0.9,0.05,0.03,0.02
3.831777137436588,0.00040961276633305003,35.78466024667555,200.0,8.333333333333333e-05,0.67,0.28,0.23,0.05,0.9,0.05,0.03,0.02
4.038794461328388,0.0004268642099907,37.08560273899681,200.0,8.333333333333333e-05,0.67,0.28,0.23,0.05,0.9,0.05,0.03,0.02
4.209162345413988,0.00044106153366450004,38.37334262710612,200.0,8.333333333333333e-05,0.67,0.28,0.23,0.05,0.9,0.05,0.03,0.02
4.379530229499588,0.0004552588573383,39.66108251521535,200.0,8.333333333333333e-05,0.67,0.28,0.23,0.05,0.9,0.05,0.03,0.02
4.595747490094789,0.0004732769623879,40.97300195740655,200.0,8.333333333333333e-05,0.67,0.28,0.23,0.05,0.9,0.05,0.03,0.02
4.811964750689989,0.0004912950674375,42.28492139959782,200.0,8.333333333333333e-05,0.67,0.28,0.23,0.05,0.9,0.05,0.03,0.02
5.085712510301988,0.0005141073807385,43.589656803643464,200.0,8.333333333333333e-05,0.67,0.28,0.23,0.05,0.9,0.05,0.03,0.02
5.359460269913988,0.0005369196940395,44.89439220768911,200.0,8.333333333333333e-05,0.67,0.28,0.23,0.05,0.9,0.05,0.03,0.02
5.628014569707588,0.0005592992190222999,46.188324074311204,200.0,8.333333333333333e-05,0.67,0.28,0.23,0.05,0.9,0.05,0.03,0.02
5.896568869501189,0.0005816787440051,47.4822559409333,200.0,8.333333333333333e-05,0.67,0.28,0.23,0.05,0.9,0.05,0.03,0.02
6.133679635058988,0.00060143797446825,48.782927412263454,200.0,8.333333333333333e-05,0.67,0.28,0.23,0.05,0.9,0.05,0.03,0.02
6.370790400616788,0.0006211972049314,50.083598883593716,200.0,8.333333333333333e-05,0.67,0.28,0.23,0.05,0.9,0.05,0.03,0.02
6.605315842935588,0.0006407409917913,51.37433147288097,200.0,8.333333333333333e-05,0.67,0.28,0.23,0.05,0.9,0.05,0.03,0.02
6.839841285254388,0.0006602847786512,52.665064062168085,200.0,8.333333333333333e-05,0.67,0.28,0.23,0.05,0.9,0.05,0.03,0.02
7.125654373105788,0.0006841025359721499,53.98597295901709,200.0,8.333333333333333e-05,0.67,0.28,0.23,0.05,0.9,0.05,0.03,0.02
7.411467460957188,0.0007079202932931,55.30688185586613,200.0,8.333333333333333e-05,0.67,0.28,0.23,0.05,0.9,0.05,0.03,0.02
7.589914156182588,0.00072279085122855,56.641910406998676,200.0,8.333333333333333e-05,0.67,0.28,0.23,0.05,0.9,0.05,0.03,0.02
7.768360851407988,0.000737661409164,57.97693895813116,200.0,8.333333333333333e-05,0.67,0.28,0.23,0.05,0.9,0.05,0.03,0.02
8.111367714440387,0.0007662453144167,59.31827380129931,200.0,8.333333333333333e-05,0.67,0.28,0.23,0.05,0.9,0.05,0.03,0.02
8.454374577472787,0.0007948292196694,60.659608644467625,200.0,8.333333333333333e-05,0.67,0.28,0.23,0.05,0.9,0.05,0.03,0.02
8.707583533926588,0.00081592996604055,61.994242964474026,200.0,8.333333333333333e-05,0.67,0.28,0.23,0.05,0.9,0.05,0.03,0.02
8.960792490380388,0.0008370307124117,63.32887728448031,200.0,8.333333333333333e-05,0.67,0.28,0.23,0.05,0.9,0.05,0.03,0.02
9.269109837145788,0.0008627238246421501,64.65367828233576,200.0,8.333333333333333e-05,0.67,0.28,0.23,0.05,0.9,0.05,0.03,0.02
9.577427183911189,0.0008884169368726,65.97847928019128,200.0,8.333333333333333e-05,0.67,0.28,0.23,0.05,0.9,0.05,0.03,0.02
9.887185601315988,0.000914230138323,67.31305387374519,200.0,8.333333333333333e-05,0.67,0.28,0.23,0.05,0.9,0.05,0.03,0.02
10.196944018720789,0.0009400433397734,68.64762846729897,200.0,8.333333333333333e-05,0.67,0.28,0.23,0.05,0.9,0.05,0.03,0.02
10.512297478579189,0.0009663227947616,69.94237859188067,200.0,8.333333333333333e-05,0.67,0.28,0.23,0.05,0.9,0.05,0.03,0.02
10.827650938437587,0.0009926022497498,71.23712871646251,200.0,8.333333333333333e-05,0.67,0.28,0.23,0.05,0.9,0.05,0.03,0.02
11.089323561288587,0.00101440830165405,72.5297341697029,200.0,8.333333333333333e-05,0.67,0.28,0.23,0.05,0.9,0.05,0.03,0.02
11.350996184139587,0.0010362143535583,73.82233962294328,200.0,8.333333333333333e-05,0.67,0.28,0.23,0.05,0.9,0.05,0.03,0.02
11.792058780550189,0.00107296956992585,75.09847567570533,200.0,8.333333333333333e-05,0.67,0.28,0.23,0.05,0.9,0.05,0.03,0.02
12.233121376960788,0.0011097247862934,76.37461172846714,200.0,8.333333333333333e-05,0.67,0.28,0.23,0.05,0.9,0.05,0.03,0.02
12.485092843259388,0.00113072240848495,77.64466436521484,200.0,8.333333333333333e-05,0.67,0.28,0.23,0.05,0.9,0.05,0.03,0.02
12.737064309557988,0.0011517200306765,78.91471700196276,200.0,8.333333333333333e-05,0.67,0.28,0.23,0.05,0.9,0.05,0.03,0.02
13.045292923673388,0.0011774057485194498,80.17249282231406,200.0,8.333333333333333e-05,0.67,0.28,0.23,0.05,0.9,0.05,0.03,0.02
13.353521537788788,0.0012030914663624,81.43026864266535,200.0,8.333333333333333e-05,0.67,0.28,0.23,0.05,0.9,0.05,0.03,0.02
13.636845259193388,0.00122670177647945,82.69840201803885,200.0,8.333333333333333e-05,0.67,0.28,0.23,0.05,0.9,0.05,0.03,0.02
13.920168980597987,0.0012503120865965,83.96653539341227,200.0,8.333333333333333e-05,0.67,0.28,0.23,0.05,0.9,0.05,0.03,0.02
14.206282744697386,0.00127415490027145,85.20751455299572,200.0,8.333333333333333e-05,0.67,0.28,0.23,0.05,0.9,0.05,0.03,0.02
14.492396508796787,0.0012979977139464,86.44849371257921,200.0,8.333333333333333e-05,0.67,0.28,0.23,0.05,0.9,0.05,0.03,0.02
14.810572207202387,0.0013245123554801999,87.71362413184055,200.0,8.333333333333333e-05,0.67,0.28,0.23,0.05,0.9,0.05,0.03,0.02
15.128747905607987,0.001351026997014,88.97875455110176,200.0,8.333333333333333e-05,0.67,0.28,0.23,0.05,0.9,0.05,0.03,0.02
15.464979674899787,0.00137904631112165,90.2380947136061,200.0,8.333333333333333e-05,0.67,0.28,0.23,0.05,0.9,0.05,0.03,0.02
15.801211444191589,0.0014070656252293,91.49743487611016,200.0,8.333333333333333e-05,0.67,0.28,0.23,0.05,0.9,0.05,0.03,0.02
16.101775317527387,0.00143211261467395,92.7638242771991,200.0,8.333333333333333e-05,0.67,0.28,0.23,0.05,0.9,0.05,0.03,0.02
16.402339190863188,0.0014571596041186,94.0302136782883,200.0,8.333333333333333e-05,0.67,0.28,0.23,0.05,0.9,0.05,0.03,0.02
16.77371236033379,0.00148810736824115,95.29380119464321,200.0,8.333333333333333e-05,0.67,0.28,0.23,0.05,0.9,0.05,0.03,0.02
17.145085529804387,0.0015190551323637,96.55738871099868,200.0,8.333333333333333e-05,0.67,0.28,0.23,0.05,0.9,0.05,0.03,0.02
17.45683003378199,0.0015450338410285,97.81489501960553,200.0,8.333333333333333e-05,0.67,0.28,0.23,0.05,0.9,0.05,0.03,0.02
17.76857453775959,0.0015710125496933,99.07240132821202,200.0,8.333333333333333e-05,0.67,0.28,0.23,0.05,0.9,0.05,0.03,0.02
18.06104243865539,0.00159538487476795,100.31790380343452,200.0,8.333333333333333e-05,0.67,0.28,0.23,0.05,0.9,0.05,0.03,0.02
18.35351033955119,0.0016197571998426,101.56340627865725,200.0,8.333333333333333e-05,0.67,0.28,0.23,0.05,0.9,0.05,0.03,0.02
18.677311492477187,0.0016467406292531,102.78521782238975,200.0,8.333333333333333e-05,0.67,0.28,0.23,0.05,0.9,0.05,0.03,0.02
19.001112645403182,0.0016737240586636,104.00702936612169,200.0,8.333333333333333e-05,0.67,0.28,0.23,0.05,0.9,0.05,0.03,0.02
19.226257466502584,0.00169248612708855,105.22498418082468,200.0,8.333333333333333e-05,0.67,0.28,0.23,0.05,0.9,0.05,0.03,0.02
19.451402287601987,0.0017112481955135,106.44293899552758,200.0,8.333333333333333e-05,0.67,0.28,0.23,0.05,0.9,0.05,0.03,0.02
19.78223448770939,0.0017388175455224498,107.6510643565176,200.0,8.333333333333333e-05,0.67,0.28,0.23,0.05,0.9,0.05,0.03,0.02
20.113066687816787,0.0017663868955314,108.85918971750829,200.0,8.333333333333333e-05,0.67,0.28,0.23,0.05,0.9,0.05,0.03,0.02
20.428045423603187,0.0017926351235135998,110.04235122450727,200.0,8.333333333333333e-05,0.67,0.28,0.23,0.05,0.9,0.05,0.03,0.02
20.743024159389588,0.0018188833514958,111.22551273150623,200.0,8.333333333333333e-05,0.67,0.28,0.23,0.05,0.9,0.05,0.03,0.02
21.036273829702786,0.0018433208240219,112.38429953882473,200.0,8.333333333333333e-05,0.67,0.28,0.23,0.05,0.9,0.05,0.03,0.02
21.329523500015988,0.001867758296548,113.54308634614276,200.0,8.333333333333333e-05,0.67,0.28,0.23,0.05,0.9,0.05,0.03,0.02
21.663080238265188,0.0018955546914020999,114.71145837134077,200.0,8.333333333333333e-05,0.67,0.28,0.23,0.05,0.9,0.05,0.03,0.02
21.996636976514388,0.0019233510862562,115.8798303965393,200.0,8.333333333333333e-05,0.67,0.28,0.23,0.05,0.9,0.05,0.03,0.02
22.33168806785879,0.0019512720105349,117.04227957368529,200.0,8.333333333333333e-05,0.67,0.28,0.23,0.05,0.9,0.05,0.03,0.02
22.66673915920319,0.0019791929348136,118.20472875083067,200.0,8.333333333333333e-05,0.67,0.28,0.23,0.05,0.9,0.05,0.03,0.02
22.99208917048679,0.0020063054357539,119.36306766138716,200.0,8.333333333333333e-05,0.67,0.28,0.23,0.05,0.9,0.05,0.03,0.02
23.31743918177039,0.0020334179366942,120.52140657194366,200.0,8.333333333333333e-05,0.67,0.28,0.23,0.05,0.9,0.05,0.03,0.02
23.717620188416987,0.00206676635391475,121.65667632093667,200.0,8.333333333333333e-05,0.67,0.28,0.23,0.05,0.9,0.05,0.03,0.02
24.117801195063585,0.0021001147711353,122.79194606992982,200.0,8.333333333333333e-05,0.67,0.28,0.23,0.05,0.9,0.05,0.03,0.02
24.431801187411587,0.0021262814371643003,123.90507701263084,200.0,8.333333333333333e-05,0.67,0.28,0.23,0.05,0.9,0.05,0.03,0.02
24.745801179759592,0.0021524481031933,125.0182079553317,200.0,8.333333333333333e-05,0.67,0.28,0.23,0.05,0.9,0.05,0.03,0.02
25.08194731012619,0.00218046028072385,126.10059282601019,200.0,8.333333333333333e-05,0.67,0.28,0.23,0.05,0.9,0.05,0.03,0.02
25.41809344049279,0.0022084724582544,127.18297769668922,200.0,8.333333333333333e-05,0.67,0.28,0.23,0.05,0.9,0.05,0.03,0.02
25.67522605635419,0.00222990017624285,128.26908496549672,200.0,8.333333333333333e-05,0.67,0.28,0.23,0.05,0.9,0.05,0.03,0.02
25.93235867221559,0.0022513278942313,129.35519223430418,200.0,8.333333333333333e-05,0.67,0.28,0.23,0.05,0.9,0.05,0.03,0.02
26.22753332179679,0.0022759257816964,130.4517786160412,200.0,8.333333333333333e-05,0.67,0.28,0.23,0.05,0.9,0.05,0.03,0.02
26.52270797137799,0.0023005236691615,131.548364997778,200.0,8.333333333333333e-05,0.67,0.28,0.23,0.05,0.9,0.05,0.03,0.02
26.855882174577587,0.0023282881860948,132.6064154259455,200.0,8.333333333333333e-05,0.67,0.28,0.23,0.05,0.9,0.05,0.03,0.02
27.189056377777188,0.0023560527030281,133.66446585411285,200.0,8.333333333333333e-05,0.67,0.28,0.23,0.05,0.9,0.05,0.03,0.02
27.51010501395539,0.00238280675604295,134.70986501383334,200.0,8.333333333333333e-05,0.67,0.28,0.23,0.05,0.9,0.05,0.03,0.02
27.83115365013359,0.0024095608090578,135.75526417355306,200.0,8.333333333333333e-05,0.67,0.28,0.23,0.05,0.9,0.05,0.03,0.02
28.12596375147539,0.00243412831750295,136.80032061512003,200.0,8.333333333333333e-05,0.67,0.28,0.23,0.05,0.9,0.05,0.03,0.02
28.42077385281719,0.0024586958259481,137.8453770566884,200.0,8.333333333333333e-05,0.67,0.28,0.23,0.05,0.9,0.05,0.03,0.02
28.694273379713387,0.00248148745318945,138.88652847333088,200.0,8.333333333333333e-05,0.67,0.28,0.23,0.05,0.9,0.05,0.03,0.02
28.967772906609586,0.0025042790804308,139.9276798899741,200.0,8.333333333333333e-05,0.67,0.28,0.23,0.05,0.9,0.05,0.03,0.02
29.250818417083188,0.0025278662063036,140.98590875876258,200.0,8.333333333333333e-05,0.67,0.28,0.23,0.05,0.9,0.05,0.03,0.02
29.53386392755679,0.0025514533321764,142.0441376275499,200.0,8.333333333333333e-05,0.67,0.28,0.23,0.05,0.9,0.05,0.03,0.02
29.845528082825993,0.0025774253451155,143.07476597246742,200.0,8.333333333333333e-05,0.67,0.28,0.23,0.05,0.9,0.05,0.03,0.02
30.157192238095192,0.0026033973580546,144.105394317385,200.0,8.333333333333333e-05,0.67,0.28,0.23,0.05,0.9,0.05,0.03,0.02
30.47447491440839,0.0026298375810807004,145.07111268611203,200.0,8.333333333333333e-05,0.67,0.28,0.23,0.05,0.9,0.05,0.03,0.02
30.79175759072159,0.0026562778041068,146.03683105483893,200.0,8.333333333333333e-05,0.67,0.28,0.23,0.05,0.9,0.05,0.03,0.02
31.094387240363986,0.0026814969415769998,147.0172516867944,200.0,8.333333333333333e-05,0.67,0.28,0.23,0.05,0.9,0.05,0.03,0.02
31.397016890006384,0.0027067160790472,147.99767231875006,200.0,8.333333333333333e-05,0.67,0.28,0.23,0.05,0.9,0.05,0.03,0.02
31.709906014892386,0.0027327901727876996,148.96766064031107,200.0,8.333333333333333e-05,0.67,0.28,0.23,0.05,0.9,0.05,0.03,0.02
32.02279513977839,0.0027588642665282,149.93764896187204,200.0,8.333333333333333e-05,0.67,0.28,0.23,0.05,0.9,0.05,0.03,0.02
32.33116831718399,0.002784562031312,150.90762412915655,200.0,8.333333333333333e-05,0.67,0.28,0.23,0.05,0.9,0.05,0.03,0.02
32.63954149458959,0.0028102597960958,151.8775992964414,200.0,8.333333333333333e-05,0.67,0.28,0.23,0.05,0.9,0.05,0.03,0.02
32.945212406598586,0.00283573237209655,152.8290962241094,200.0,8.333333333333333e-05,0.67,0.28,0.23,0.05,0.9,0.05,0.03,0.02
33.250883318607585,0.0028612049480973,153.7805931517767,200.0,8.333333333333333e-05,0.67,0.28,0.23,0.05,0.9,0.05,0.03,0.02
33.53885649459359,0.0028852027127628,154.7106442636367,200.0,8.333333333333333e-05,0.67,0.28,0.23,0.05,0.9,0.05,0.03,0.02
33.826829670579585,0.0029092004774283,155.64069537549653,200.0,8.333333333333333e-05,0.67,0.28,0.23,0.05,0.9,0.05,0.03,0.02
34.18472394449098,0.0029390250002542502,156.54773553505456,200.0,8.333333333333333e-05,0.67,0.28,0.23,0.05,0.9,0.05,0.03,0.02
34.54261821840239,0.0029688495230802,157.4547756946131,200.0,8.333333333333333e-05,0.67,0.28,0.23,0.05,0.9,0.05,0.03,0.02
34.844697442600186,0.00299402279176335,158.3940935812411,200.0,8.333333333333333e-05,0.67,0.28,0.23,0.05,0.9,0.05,0.03,0.02
35.14677666679798,0.0030191960604465,159.3334114678687,200.0,8.333333333333333e-05,0.67,0.28,0.23,0.05,0.9,0.05,0.03,0.02
35.45276378675878,0.0030446949871098996,160.2349399537817,200.0,8.333333333333333e-05,0.67,0.28,0.23,0.05,0.9,0.05,0.03,0.02
35.758750906719584,0.0030701939137733,161.13646843969568,200.0,8.333333333333333e-05,0.67,0.28,0.23,0.05,0.9,0.05,0.03,0.02
36.04677874844698,0.0030941962339172497,162.03257632308615,200.0,8.333333333333333e-05,0.67,0.28,0.23,0.05,0.9,0.05,0.03,0.02
36.33480659017439,0.0031181985540612,162.9286842064755,200.0,8.333333333333333e-05,0.67,0.28,0.23,0.05,0.9,0.05,0.03,0.02
36.68904914385299,0.00314771876686775,163.7711149602965,200.0,8.333333333333333e-05,0.67,0.28,0.23,0.05,0.9,0.05,0.03,0.02
37.04329169753159,0.0031772389796743,164.61354571411707,200.0,8.333333333333333e-05,0.67,0.28,0.23,0.05,0.9,0.05,0.03,0.02
37.40826564058679,0.0032076534749289,165.46424031649656,200.0,8.333333333333333e-05,0.67,0.28,0.23,0.05,0.9,0.05,0.03,0.02
37.77323958364199,0.0032380679701835,166.31493491887716,200.0,8.333333333333333e-05,0.67,0.28,0.23,0.05,0.9,0.05,0.03,0.02
38.11546693498319,0.0032665869161286,167.14968269347818,200.0,8.333333333333333e-05,0.67,0.28,0.23,0.05,0.9,0.05,0.03,0.02
38.45769428632439,0.0032951058620737,167.9844304680791,200.0,8.333333333333333e-05,0.67,0.28,0.23,0.05,0.9,0.05,0.03,0.02
38.817638089368586,0.00332510117899405,168.8201103455021,200.0,8.333333333333333e-05,0.67,0.28,0.23,0.05,0.9,0.05,0.03,0.02
39.17758189241279,0.0033550964959144,169.65579022292474,200.0,8.333333333333333e-05,0.67,0.28,0.23,0.05,0.9,0.05,0.03,0.02
39.55793722061759,0.0033867927732648,170.42298111240774,200.0,8.333333333333333e-05,0.67,0.28,0.23,0.05,0.9,0.05,0.03,0.02
39.93829254882239,0.0034184890506152,171.19017200189097,200.0,8.333333333333333e-05,0.67,0.28,0.23,0.05,0.9,0.05,0.03,0.02
40.30765724595659,0.00344926944204305,171.97469348390848,200.0,8.333333333333333e-05,0.67,0.28,0.23,0.05,0.9,0.05,0.03,0.02
40.67702194309079,0.0034800498334709,172.75921496592608,200.0,8.333333333333333e-05,0.67,0.28,0.23,0.05,0.9,0.05,0.03,0.02
41.06889827455979,0.00351270619442665,173.51510053317358,200.0,8.333333333333333e-05,0.67,0.28,0.23,0.05,0.9,0.05,0.03,0.02
41.46077460602879,0.0035453625553824,174.27098610042117,200.0,8.333333333333333e-05,0.67,0.28,0.23,0.05,0.9,0.05,0.03,0.02
41.84259728979299,0.0035771811123627498,175.01354087280666,200.0,8.333333333333333e-05,0.67,0.28,0.23,0.05,0.9,0.05,0.03,0.02
42.22441997355719,0.0036089996693431,175.75609564519152,200.0,8.333333333333333e-05,0.67,0.28,0.23,0.05,0.9,0.05,0.03,0.02
42.64264601026919,0.0036438518390691,176.443250268422,200.0,8.333333333333333e-05,0.67,0.28,0.23,0.05,0.9,0.05,0.03,0.02
43.06087204698119,0.0036787040087951,177.13040489165343,200.0,8.333333333333333e-05,0.67,0.28,0.23,0.05,0.9,0.05,0.03,0.02
43.55047342994279,0.0037195041240419002,177.77136650936444,200.0,8.333333333333333e-05,0.67,0.28,0.23,0.05,0.9,0.05,0.03,0.02
44.04007481290439,0.0037603042392887,178.41232812707398,200.0,8.333333333333333e-05,0.67,0.28,0.23,0.05,0.9,0.05,0.03,0.02
44.51216404352639,0.0037996450085072,179.01991817925048,200.0,8.333333333333333e-05,0.67,0.28,0.23,0.05,0.9,0.05,0.03,0.02
44.98425327414839,0.0038389857777257,179.62750823142747,200.0,8.333333333333333e-05,0.67,0.28,0.23,0.05,0.9,0.05,0.03,0.02
45.52335266790179,0.0038839107272051502,180.21141294427045,200.0,8.333333333333333e-05,0.67,0.28,0.23,0.05,0.9,0.05,0.03,0.02
46.06245206165519,0.0039288356766846,180.7953176571143,200.0,8.333333333333333e-05,0.67,0.28,0.23,0.05,0.9,0.05,0.03,0.02
46.72531502285159,0.0039840742567843,181.31976214858082,200.0,8.333333333333333e-05,0.67,0.28,0.23,0.05,0.9,0.05,0.03,0.02
47.38817798404799,0.004039312836884,181.84420664004645,200.0,8.333333333333333e-05,0.67,0.28,0.23,0.05,0.9,0.05,0.03,0.02
48.03882422736778,0.00409353335716065,182.31896804859196,200.0,8.333333333333333e-05,0.67,0.28,0.23,0.05,0.9,0.05,0.03,0.02
48.68947047068758,0.0041477538774373,182.79372945713834,200.0,8.333333333333333e-05,0.67,0.28,0.23,0.05,0.9,0.05,0.03,0.02
49.33087853567759,0.0042012045495197995,183.22568795394383,200.0,8.333333333333333e-05,0.67,0.28,0.23,0.05,0.9,0.05,0.03,0.02
49.9722866006676,0.0042546552216023,183.65764645074879,200.0,8.333333333333333e-05,0.67,0.28,0.23,0.05,0.9,0.05,0.03,0.02
50.65969188729299,0.004311938995487751,184.05673594528528,200.0,8.333333333333333e-05,0.67,0.28,0.23,0.05,0.9,0.05,0.03,0.02
51.34709717391839,0.0043692227693732,184.45582543982226,200.0,8.333333333333333e-05,0.67,0.28,0.23,0.05,0.9,0.05,0.03,0.02
52.105624676419794,0.00443243339458165,184.80944342819876,200.0,8.333333333333333e-05,0.67,0.28,0.23,0.05,0.9,0.05,0.03,0.02
52.86415217892119,0.0044956440197901,185.16306141657458,200.0,8.333333333333333e-05,0.67,0.28,0.23,0.05,0.9,0.05,0.03,0.02
53.66382654855239,0.0045622835505927,185.46656135713008,200.0,8.333333333333333e-05,0.67,0.28,0.23,0.05,0.9,0.05,0.03,0.02
54.46350091818359,0.0046289230813953,185.77006129768662,200.0,8.333333333333333e-05,0.67,0.28,0.23,0.05,0.9,0.05,0.03,0.02
55.24867379909279,0.0046943541548044,186.02817607688013,200.0,8.333333333333333e-05,0.67,0.28,0.23,0.05,0.9,0.05,0.03,0.02
56.03384668000199,0.0047597852282135,186.2862908560728,200.0,8.333333333333333e-05,0.67,0.28,0.23,0.05,0.9,0.05,0.03,0.02
56.762332789523995,0.004820492404007001,186.4876093534748,200.0,8.333333333333333e-05,0.67,0.28,0.23,0.05,0.9,0.05,0.03,0.02
57.49081889904599,0.0048811995798005,186.6889278508765,200.0,8.333333333333333e-05,0.67,0.28,0.23,0.05,0.9,0.05,0.03,0.02
58.322402103047395,0.0049504981801339505,186.8568809309385,200.0,8.333333333333333e-05,0.67,0.28,0.23,0.05,0.9,0.05,0.03,0.02
59.15398530704879,0.0050197967804674,187.02483401100085,200.0,8.333333333333333e-05,0.67,0.28,0.23,0.05,0.9,0.05,0.03,0.02
60.09283026181319,0.0050980338600311,187.16917430677887,200.0,8.333333333333333e-05,0.67,0.28,0.23,0.05,0.9,0.05,0.03,0.02
61.03167521657758,0.0051762709395948,187.31351460255723,200.0,8.333333333333333e-05,0.67,0.28,0.23,0.05,0.9,0.05,0.03,0.02
61.937186467500595,0.0052517302105050505,187.43619014643423,200.0,8.333333333333333e-05,0.67,0.28,0.23,0.05,0.9,0.05,0.03,0.02
62.8426977184236,0.0053271894814153,187.5588656903114,200.0,8.333333333333333e-05,0.67,0.28,0.23,0.05,0.9,0.05,0.03,0.02
63.753541715999404,0.005403093147879951,187.6717774088759,200.0,8.333333333333333e-05,0.67,0.28,0.23,0.05,0.9,0.05,0.03,0.02
64.6643857135752,0.0054789968143446,187.78468912743892,200.0,8.333333333333333e-05,0.67,0.28,0.23,0.05,0.9,0.05,0.03,0.02
65.5770462823044,0.0055550518617387,187.86530996465743,200.0,8.333333333333333e-05,0.67,0.28,0.23,0.05,0.9,0.05,0.03,0.02
66.48970685103359,0.0056311069091328,187.9459308018772,200.0,8.333333333333333e-05,0.67,0.28,0.23,0.05,0.9,0.05,0.03,0.02
67.429162011465,0.00570939483916875,188.0173182663402,200.0,8.333333333333333e-05,0.67,0.28,0.23,0.05,0.9,0.05,0.03,0.02
68.36861717189639,0.0057876827692047,188.08870573080304,200.0,8.333333333333333e-05,0.67,0.28,0.23,0.05,0.9,0.05,0.03,0.02
69.33470854239779,0.00586819038341315,188.16216546248253,200.0,8.333333333333333e-05,0.67,0.28,0.23,0.05,0.9,0.05,0.03,0.02
70.3007999128992,0.0059486979976216,188.2356251941615,200.0,8.333333333333333e-05,0.67,0.28,0.23,0.05,0.9,0.05,0.03,0.02
71.2782352279332,0.0060301509405411,188.30360468424402,200.0,8.333333333333333e-05,0.67,0.28,0.23,0.05,0.9,0.05,0.03,0.02
72.2556705429672,0.0061116038834606,188.37158417432732,200.0,8.333333333333333e-05,0.67,0.28,0.23,0.05,0.9,0.05,0.03,0.02
73.22241697771379,0.00619216608635615,188.43532404743482,200.0,8.333333333333333e-05,0.67,0.28,0.23,0.05,0.9,0.05,0.03,0.02
74.18916341246039,0.0062727282892517,188.49906392054262,200.0,8.333333333333333e-05,0.67,0.28,0.23,0.05,0.9,0.05,0.03,0.02
75.2332001183664,0.006359731348077199,188.5507297644066,200.0,8.333333333333333e-05,0.67,0.28,0.23,0.05,0.9,0.05,0.03,0.02
76.27723682427239,0.0064467344069027,188.6023956082695,200.0,8.333333333333333e-05,0.67,0.28,0.23,0.05,0.9,0.05,0.03,0.02
77.28831236446379,0.00653099070191865,188.6558575033725,200.0,8.333333333333333e-05,0.67,0.28,0.23,0.05,0.9,0.05,0.03,0.02
78.29938790465519,0.0066152469969346,188.70931939847563,200.0,8.333333333333333e-05,0.67,0.28,0.23,0.05,0.9,0.05,0.03,0.02
79.29400566257999,0.006698131810095,188.75690689234662,200.0,8.333333333333333e-05,0.67,0.28,0.23,0.05,0.9,0.05,0.03,0.02
80.28862342050479,0.0067810166232554,188.80449438621773,200.0,8.333333333333333e-05,0.67,0.28,0.23,0.05,0.9,0.05,0.03,0.02
81.37442722491178,0.00687150027362265,188.85044309235573,200.0,8.333333333333333e-05,0.67,0.28,0.23,0.05,0.9,0.05,0.03,0.02
82.46023102931879,0.0069619839239899,188.8963917984939,200.0,8.333333333333333e-05,0.67,0.28,0.23,0.05,0.9,0.05,0.03,0.02
83.54495176481039,0.0070523773186141996,188.9387762993874,200.0,8.333333333333333e-05,0.67,0.28,0.23,0.05,0.9,0.05,0.03,0.02
84.629672500302,0.0071427707132385,188.98116080028083,200.0,8.333333333333333e-05,0.67,0.28,0.23,0.05,0.9,0.05,0.03,0.02
85.68656471658599,0.0072308450645955005,189.01063908124183,200.0,8.333333333333333e-05,0.67,0.28,0.23,0.05,0.9,0.05,0.03,0.02
86.74345693286999,0.0073189194159525,189.04011736220298,200.0,8.333333333333333e-05,0.67,0.28,0.23,0.05,0.9,0.05,0.03,0.02
87.82624574310479,0.0074091518168054,189.05145765924496,200.0,8.333333333333333e-05,0.67,0.28,0.23,0.05,0.9,0.05,0.03,0.02
88.9090345533396,0.0074993842176583,189.06279795628672,200.0,8.333333333333333e-05,0.67,0.28,0.23,0.05,0.9,0.05,0.03,0.02
89.93126518324141,0.00758457010348345,189.07912767201123,200.0,8.333333333333333e-05,0.67,0.28,0.23,0.05,0.9,0.05,0.03,0.02
90.9534958131432,0.0076697559893086,189.09545738773625,200.0,8.333333333333333e-05,0.67,0.28,0.23,0.05,0.9,0.05,0.03,0.02
92.0175783369888,0.007758429532962401,189.10367128817273,200.0,8.333333333333333e-05,0.67,0.28,0.23,0.05,0.9,0.05,0.03,0.02
93.0816608608344,0.0078471030766162,189.11188518860882,200.0,8.333333333333333e-05,0.67,0.28,0.23,0.05,0.9,0.05,0.03,0.02
94.2277323497178,0.00794260903402315,189.13018341481035,200.0,8.333333333333333e-05,0.67,0.28,0.23,0.05,0.9,0.05,0.03,0.02
95.3738038386012,0.0080381149914301,189.1484816410118,200.0,8.333333333333333e-05,0.67,0.28,0.23,0.05,0.9,0.05,0.03,0.02
96.4693917741918,0.00812941398606265,189.1583343371243,200.0,8.333333333333333e-05,0.67,0.28,0.23,0.05,0.9,0.05,0.03,0.02
97.5649797097824,0.0082207129806952,189.16818703323707,200.0,8.333333333333333e-05,0.67,0.28,0.23,0.05,0.9,0.05,0.03,0.02
98.6504855498064,0.0083111718006972,189.18546412694806,200.0,8.333333333333333e-05,0.67,0.28,0.23,0.05,0.9,0.05,0.03,0.02
99.7359913898304,0.0084016306206992,189.20274122065857,200.0,8.333333333333333e-05,0.67,0.28,0.23,0.05,0.9,0.05,0.03,0.02
100.87161414221939,0.00849626585006495,189.22228250216307,200.0,8.333333333333333e-05,0.67,0.28,0.23,0.05,0.9,0.05,0.03,0.02
102.00723689460838,0.0085909010794307,189.2418237836675,200.0,8.333333333333333e-05,0.67,0.28,0.23,0.05,0.9,0.05,0.03,0.02
103.10266548739799,0.0086821867954965,189.27606844047702,200.0,8.333333333333333e-05,0.67,0.28,0.23,0.05,0.9,0.05,0.03,0.02
104.1980940801876,0.0087734725115623,189.31031309728712,200.0,8.333333333333333e-05,0.67,0.28,0.23,0.05,0.9,0.05,0.03,0.02
105.3538567898232,0.0088697860706986,189.32973297975312,200.0,8.333333333333333e-05,0.67,0.28,0.23,0.05,0.9,0.05,0.03,0.02
106.50961949945878,0.0089660996298349,189.34915286221934,200.0,8.333333333333333e-05,0.67,0.28,0.23,0.05,0.9,0.05,0.03,0.02
107.653344726765,0.00906141006544375,189.35951048873184,200.0,8.333333333333333e-05,0.67,0.28,0.23,0.05,0.9,0.05,0.03,0.02
108.7970699540712,0.0091567205010526,189.36986811524338,200.0,8.333333333333333e-05,0.67,0.28,0.23,0.05,0.9,0.05,0.03,0.02
109.91669171339879,0.009250022314329899,189.39014697355637,200.0,8.333333333333333e-05,0.67,0.28,0.23,0.05,0.9,0.05,0.03,0.02
111.03631347272638,0.0093433241276072,189.41042583186982,200.0,8.333333333333333e-05,0.67,0.28,0.23,0.05,0.9,0.05,0.03,0.02
112.14879466364337,0.00943603089351695,189.42323033651783,200.0,8.333333333333333e-05,0.67,0.28,0.23,0.05,0.9,0.05,0.03,0.02
113.26127585456038,0.0095287376594267,189.43603484116582,200.0,8.333333333333333e-05,0.67,0.28,0.23,0.05,0.9,0.05,0.03,0.02
114.26083097240519,0.009612033919247101,189.43503877011435,200.0,8.333333333333333e-05,0.67,0.28,0.23,0.05,0.9,0.05,0.03,0.02
115.26038609025,0.0096953301790675,189.43404269906384,200.0,8.333333333333333e-05,0.67,0.28,0.23,0.05,0.9,0.05,0.03,0.02
116.3881435523418,0.009789309967575151,189.44152791930432,200.0,8.333333333333333e-05,0.67,0.28,0.23,0.05,0.9,0.05,0.03,0.02
117.5159010144336,0.0098832897560828,189.449013139544,200.0,8.333333333333333e-05,0.67,0.28,0.23,0.05,0.9,0.05,0.03,0.02
118.67560325164439,0.009979931609183701,189.444981584142,200.0,8.333333333333333e-05,0.67,0.28,0.23,0.05,0.9,0.05,0.03,0.02
119.83530548885518,0.0100765734622846,189.44095002873968,200.0,8.333333333333333e-05,0.67,0.28,0.23,0.05,0.9,0.05,0.03,0.02
120.95689339169638,0.0101700391208547,189.44305057447318,200.0,8.333333333333333e-05,0.67,0.28,0.23,0.05,0.9,0.05,0.03,0.02
122.0784812945376,0.0102635047794248,189.4451511202067,200.0,8.333333333333333e-05,0.67,0.28,0.23,0.05,0.9,0.05,0.03,0.02
123.2305516518642,0.01035951064253535,189.4580619870307,200.0,8.333333333333333e-05,0.67,0.28,0.23,0.05,0.9,0.05,0.03,0.02
124.3826220091908,0.0104555165056459,189.47097285385553,200.0,8.333333333333333e-05,0.67,0.28,0.23,0.05,0.9,0.05,0.03,0.02
125.4827559253236,0.0105471943319903,189.46876445258656,200.0,8.333333333333333e-05,0.67,0.28,0.23,0.05,0.9,0.05,0.03,0.02
126.5828898414564,0.0106388721583347,189.46655605131727,200.0,8.333333333333333e-05,0.67,0.28,0.23,0.05,0.9,0.05,0.03,0.02
127.727706506571,0.010734273547094251,189.47317622695027,200.0,8.333333333333333e-05,0.67,0.28,0.23,0.05,0.9,0.05,0.03,0.02
128.8725231716856,0.0108296749358538,189.4797964025838,200.0,8.333333333333333e-05,0.67,0.28,0.23,0.05,0.9,0.05,0.03,0.02
130.163241974379,0.010937234836078249,189.4841077246648,200.0,8.333333333333333e-05,0.67,0.28,0.23,0.05,0.9,0.05,0.03,0.02
131.4539607770724,0.0110447947363027,189.48841904674524,200.0,8.333333333333333e-05,0.67,0.28,0.23,0.05,0.9,0.05,0.03,0.02
132.56072334036242,0.0111370249499102,189.49837006630872,200.0,8.333333333333333e-05,0.67,0.28,0.23,0.05,0.9,0.05,0.03,0.02
133.6674859036524,0.0112292551635177,189.5083210858728,200.0,8.333333333333333e-05,0.67,0.28,0.23,0.05,0.9,0.05,0.03,0.02
134.8243991650686,0.01132566460196905,189.51795727657378,200.0,8.333333333333333e-05,0.67,0.28,0.23,0.05,0.9,0.05,0.03,0.02
135.9813124264848,0.0114220740404204,189.52759346727385,200.0,8.333333333333333e-05,0.67,0.28,0.23,0.05,0.9,0.05,0.03,0.02
137.1372594677166,0.01151840296052305,189.52971142494835,200.0,8.333333333333333e-05,0.67,0.28,0.23,0.05,0.9,0.05,0.03,0.02
138.2932065089484,0.0116147318806257,189.531829382623,200.0,8.333333333333333e-05,0.67,0.28,0.23,0.05,0.9,0.05,0.03,0.02