File: datasets/al_6061_comp/csv/T_200_G_1.csv
Time,Strain(%),Stress(MPa),Temp(C),SR(%/s),Si(%),Fe(%),Cu(%),Mn(%),Mg(%),Cr(%),Zn(%),Ti(%)
0.0,8.91398008557037e-05,36.6551501203269,200.0,8.333333333333333e-05,0.61,0.15,0.17,0.02,0.88,0.05,0.01,0.01
0.1636134961976889,0.00010277425887217777,37.19616649378365,200.0,8.333333333333333e-05,0.61,0.15,0.17,0.02,0.88,0.05,0.01,0.01
0.3272269923953778,0.00011640871688865185,37.73718286724041,200.0,8.333333333333333e-05,0.61,0.15,0.17,0.02,0.88,0.05,0.01,0.01
0.49084048859306667,0.0001300431749051259,38.27819924069717,200.0,8.333333333333333e-05,0.61,0.15,0.17,0.02,0.88,0.05,0.01,0.01
0.6544539847907556,0.0001436776329216,38.81921561415392,200.0,8.333333333333333e-05,0.61,0.15,0.17,0.02,0.88,0.05,0.01,0.01
0.8159349168281556,0.00015713437725804998,39.37559540343387,200.0,8.333333333333333e-05,0.61,0.15,0.17,0.02,0.88,0.05,0.01,0.01
0.9774158488655555,0.00017059112159449998,39.93197519271381,200.0,8.333333333333333e-05,0.61,0.15,0.17,0.02,0.88,0.05,0.01,0.01
1.1388967809029555,0.00018404786593095,40.48835498199375,200.0,8.333333333333333e-05,0.61,0.15,0.17,0.02,0.88,0.05,0.01,0.01
1.3003777129403555,0.0001975046102674,41.04473477127371,200.0,8.333333333333333e-05,0.61,0.15,0.17,0.02,0.88,0.05,0.01,0.01
1.4169248795384557,0.00020721687415057498,41.6060827780484,200.0,8.333333333333333e-05,0.61,0.15,0.17,0.02,0.88,0.05,0.01,0.01
1.5334720461365556,0.00021692913803375,42.16743078482314,200.0,8.333333333333333e-05,0.61,0.15,0.17,0.02,0.88,0.05,0.01,0.01
1.6500192127346556,0.000226641401916925,42.72877879159782,200.0,8.333333333333333e-05,0.61,0.15,0.17,0.02,0.88,0.05,0.01,0.01
1.7665663793327555,0.0002363536658001,43.290126798372455,200.0,8.333333333333333e-05,0.61,0.15,0.17,0.02,0.88,0.05,0.01,0.01
1.9350278574614554,0.000250392122310825,43.85123646641833,200.0,8.333333333333333e-05,0.61,0.15,0.17,0.02,0.88,0.05,0.01,0.01
2.1034893355901554,0.00026443057882155,44.4123461344642,200.0,8.333333333333333e-05,0.61,0.15,0.17,0.02,0.88,0.05,0.01,0.01
2.2719508137188553,0.000278469035332275,44.97345580251008,200.0,8.333333333333333e-05,0.61,0.15,0.17,0.02,0.88,0.05,0.01,0.01
2.4404122918475557,0.000292507491843,45.53456547055599,200.0,8.333333333333333e-05,0.61,0.15,0.17,0.02,0.88,0.05,0.01,0.01
2.6264113867565557,0.00030800741641874997,46.094865730142544,200.0,8.333333333333333e-05,0.61,0.15,0.17,0.02,0.88,0.05,0.01,0.01
2.812410481665556,0.0003235073409945,46.65516598972911,200.0,8.333333333333333e-05,0.61,0.15,0.17,0.02,0.88,0.05,0.01,0.01
2.998409576574556,0.00033900726557025004,47.21546624931566,200.0,8.333333333333333e-05,0.61,0.15,0.17,0.02,0.88,0.05,0.01,0.01
3.184408671483556,0.000354507190146,47.775766508902244,200.0,8.333333333333333e-05,0.61,0.15,0.17,0.02,0.88,0.05,0.01,0.01
3.3610837390919563,0.00036923011244669997,48.34154582579501,200.0,8.333333333333333e-05,0.61,0.15,0.17,0.02,0.88,0.05,0.01,0.01
3.537758806700356,0.0003839530347474,48.907325142687725,200.0,8.333333333333333e-05,0.61,0.15,0.17,0.02,0.88,0.05,0.01,0.01
3.7144338743087557,0.0003986759570481,49.473104459580526,200.0,8.333333333333333e-05,0.61,0.15,0.17,0.02,0.88,0.05,0.01,0.01
3.891108941917156,0.0004133988793488,50.03888377647333,200.0,8.333333333333333e-05,0.61,0.15,0.17,0.02,0.88,0.05,0.01,0.01
4.064858137816756,0.0004278779790071,50.60574854584443,200.0,8.333333333333333e-05,0.61,0.15,0.17,0.02,0.88,0.05,0.01,0.01
4.238607333716356,0.0004423570786654,51.17261331521547,200.0,8.333333333333333e-05,0.61,0.15,0.17,0.02,0.88,0.05,0.01,0.01
4.4123565296159555,0.00045683617832369995,51.73947808458655,200.0,8.333333333333333e-05,0.61,0.15,0.17,0.02,0.88,0.05,0.01,0.01
4.586105725515556,0.000471315277982,52.30634285395769,200.0,8.333333333333333e-05,0.61,0.15,0.17,0.02,0.88,0.05,0.01,0.01
4.721220561465856,0.000482574847644525,52.882452016471035,200.0,8.333333333333333e-05,0.61,0.15,0.17,0.02,0.88,0.05,0.01,0.01
4.8563353974161565,0.00049383441730705,53.458561178984375,200.0,8.333333333333333e-05,0.61,0.15,0.17,0.02,0.88,0.05,0.01,0.01
4.991450233366456,0.0005050939869695749,54.034670341497694,200.0,8.333333333333333e-05,0.61,0.15,0.17,0.02,0.88,0.05,0.01,0.01
5.126565069316756,0.0005163535566321,54.61077950401112,200.0,8.333333333333333e-05,0.61,0.15,0.17,0.02,0.88,0.05,0.01,0.01
5.261477918115856,0.000527596294032025,55.17541197708047,200.0,8.333333333333333e-05,0.61,0.15,0.17,0.02,0.88,0.05,0.01,0.01
5.396390766914956,0.00053883903143195,55.740044450149725,200.0,8.333333333333333e-05,0.61,0.15,0.17,0.02,0.88,0.05,0.01,0.01
5.531303615714055,0.0005500817688318749,56.30467692321912,200.0,8.333333333333333e-05,0.61,0.15,0.17,0.02,0.88,0.05,0.01,0.01
5.666216464513155,0.0005613245062318,56.869309396288614,200.0,8.333333333333333e-05,0.61,0.15,0.17,0.02,0.88,0.05,0.01,0.01
5.830062801084556,0.00057497836761275,57.444504152723894,200.0,8.333333333333333e-05,0.61,0.15,0.17,0.02,0.88,0.05,0.01,0.01
5.993909137655956,0.0005886322289937,58.019698909159246,200.0,8.333333333333333e-05,0.61,0.15,0.17,0.02,0.88,0.05,0.01,0.01
6.157755474227356,0.0006022860903746501,58.59489366559447,200.0,8.333333333333333e-05,0.61,0.15,0.17,0.02,0.88,0.05,0.01,0.01
6.321601810798756,0.0006159399517556,59.17008842202962,200.0,8.333333333333333e-05,0.61,0.15,0.17,0.02,0.88,0.05,0.01,0.01
6.476574581009057,0.000628854349273125,59.74762884091072,200.0,8.333333333333333e-05,0.61,0.15,0.17,0.02,0.88,0.05,0.01,0.01
6.631547351219357,0.00064176874679065,60.32516925979165,200.0,8.333333333333333e-05,0.61,0.15,0.17,0.02,0.88,0.05,0.01,0.01
6.786520121429657,0.000654683144308175,60.902709678672736,200.0,8.333333333333333e-05,0.61,0.15,0.17,0.02,0.88,0.05,0.01,0.01
6.941492891639957,0.0006675975418257,61.48025009755378,200.0,8.333333333333333e-05,0.61,0.15,0.17,0.02,0.88,0.05,0.01,0.01
7.091820317412257,0.000680124827306725,62.055366154656525,200.0,8.333333333333333e-05,0.61,0.15,0.17,0.02,0.88,0.05,0.01,0.01
7.242147743184557,0.00069265211278775,62.63048221175934,200.0,8.333333333333333e-05,0.61,0.15,0.17,0.02,0.88,0.05,0.01,0.01
7.392475168956857,0.000705179398268775,63.20559826886211,200.0,8.333333333333333e-05,0.61,0.15,0.17,0.02,0.88,0.05,0.01,0.01
7.542802594729157,0.0007177066837498,63.7807143259649,200.0,8.333333333333333e-05,0.61,0.15,0.17,0.02,0.88,0.05,0.01,0.01
7.663340787420557,0.00072775153314075,64.36400069163025,200.0,8.333333333333333e-05,0.61,0.15,0.17,0.02,0.88,0.05,0.01,0.01
7.783878980111957,0.0007377963825317,64.94728705729577,200.0,8.333333333333333e-05,0.61,0.15,0.17,0.02,0.88,0.05,0.01,0.01
7.904417172803356,0.00074784123192265,65.5305734229611,200.0,8.333333333333333e-05,0.61,0.15,0.17,0.02,0.88,0.05,0.01,0.01
8.024955365494757,0.0007578860813136,66.1138597886264,200.0,8.333333333333333e-05,0.61,0.15,0.17,0.02,0.88,0.05,0.01,0.01
8.145863150851756,0.00076796173009335,66.70146983500715,200.0,8.333333333333333e-05,0.61,0.15,0.17,0.02,0.88,0.05,0.01,0.01
8.266770936208756,0.0007780373788731,67.28907988138772,200.0,8.333333333333333e-05,0.61,0.15,0.17,0.02,0.88,0.05,0.01,0.01
8.387678721565756,0.00078811302765285,67.87668992776855,200.0,8.333333333333333e-05,0.61,0.15,0.17,0.02,0.88,0.05,0.01,0.01
8.508586506922756,0.0007981886764326,68.46429997414945,200.0,8.333333333333333e-05,0.61,0.15,0.17,0.02,0.88,0.05,0.01,0.01
8.696196063218057,0.000813822806123875,69.06418816833448,200.0,8.333333333333333e-05,0.61,0.15,0.17,0.02,0.88,0.05,0.01,0.01
8.883805619513357,0.00082945693581515,69.66407636251954,200.0,8.333333333333333e-05,0.61,0.15,0.17,0.02,0.88,0.05,0.01,0.01
9.071415175808657,0.000845091065506425,70.26396455670458,200.0,8.333333333333333e-05,0.61,0.15,0.17,0.02,0.88,0.05,0.01,0.01
9.259024732103956,0.0008607251951977,70.86385275088985,200.0,8.333333333333333e-05,0.61,0.15,0.17,0.02,0.88,0.05,0.01,0.01
9.448056236812455,0.000876477820590075,71.45505471692775,200.0,8.333333333333333e-05,0.61,0.15,0.17,0.02,0.88,0.05,0.01,0.01
9.637087741520956,0.00089223044598245,72.0462566829654,200.0,8.333333333333333e-05,0.61,0.15,0.17,0.02,0.88,0.05,0.01,0.01
9.826119246229457,0.000907983071374825,72.63745864900329,200.0,8.333333333333333e-05,0.61,0.15,0.17,0.02,0.88,0.05,0.01,0.01
10.015150750937956,0.0009237356967672,73.22866061504104,200.0,8.333333333333333e-05,0.61,0.15,0.17,0.02,0.88,0.05,0.01,0.01
10.187854594904357,0.0009381276837644001,73.82490887613264,200.0,8.333333333333333e-05,0.61,0.15,0.17,0.02,0.88,0.05,0.01,0.01
10.360558438870758,0.0009525196707616001,74.42115713722413,200.0,8.333333333333333e-05,0.61,0.15,0.17,0.02,0.88,0.05,0.01,0.01
10.533262282837157,0.0009669116577588001,75.01740539831567,200.0,8.333333333333333e-05,0.61,0.15,0.17,0.02,0.88,0.05,0.01,0.01
10.705966126803558,0.000981303644756,75.61365365940728,200.0,8.333333333333333e-05,0.61,0.15,0.17,0.02,0.88,0.05,0.01,0.01
10.862266175703557,0.000994328648831,76.20511847535002,200.0,8.333333333333333e-05,0.61,0.15,0.17,0.02,0.88,0.05,0.01,0.01
11.018566224603557,0.001007353652906,76.79658329129289,200.0,8.333333333333333e-05,0.61,0.15,0.17,0.02,0.88,0.05,0.01,0.01
11.174866273503557,0.0010203786569810002,77.38804810723573,200.0,8.333333333333333e-05,0.61,0.15,0.17,0.02,0.88,0.05,0.01,0.01
11.331166322403558,0.001033403661056,77.9795129231787,200.0,8.333333333333333e-05,0.61,0.15,0.17,0.02,0.88,0.05,0.01,0.01
11.498662267495458,0.001047361656480325,78.56712010314399,200.0,8.333333333333333e-05,0.61,0.15,0.17,0.02,0.88,0.05,0.01,0.01
11.666158212587357,0.00106131965190465,79.15472728310917,200.0,8.333333333333333e-05,0.61,0.15,0.17,0.02,0.88,0.05,0.01,0.01
11.833654157679256,0.001075277647328975,79.74233446307446,200.0,8.333333333333333e-05,0.61,0.15,0.17,0.02,0.88,0.05,0.01,0.01
12.001150102771156,0.0010892356427533,80.32994164303989,200.0,8.333333333333333e-05,0.61,0.15,0.17,0.02,0.88,0.05,0.01,0.01
12.181512476994856,0.0011042658406052752,80.92866434019322,200.0,8.333333333333333e-05,0.61,0.15,0.17,0.02,0.88,0.05,0.01,0.01
12.361874851218555,0.00111929603845725,81.52738703734633,200.0,8.333333333333333e-05,0.61,0.15,0.17,0.02,0.88,0.05,0.01,0.01
12.542237225442257,0.001134326236309225,82.12610973449964,200.0,8.333333333333333e-05,0.61,0.15,0.17,0.02,0.88,0.05,0.01,0.01
12.722599599665957,0.0011493564341612,82.7248324316533,200.0,8.333333333333333e-05,0.61,0.15,0.17,0.02,0.88,0.05,0.01,0.01
12.918514298241256,0.001165682659042475,83.32706474362645,200.0,8.333333333333333e-05,0.61,0.15,0.17,0.02,0.88,0.05,0.01,0.01
13.114428996816557,0.0011820088839237502,83.92929705559939,200.0,8.333333333333333e-05,0.61,0.15,0.17,0.02,0.88,0.05,0.01,0.01
13.310343695391857,0.0011983351088050251,84.53152936757252,200.0,8.333333333333333e-05,0.61,0.15,0.17,0.02,0.88,0.05,0.01,0.01
13.506258393967157,0.0012146613336863,85.13376167954537,200.0,8.333333333333333e-05,0.61,0.15,0.17,0.02,0.88,0.05,0.01,0.01
13.655074625104156,0.0012270626862810501,85.70725891581903,200.0,8.333333333333333e-05,0.61,0.15,0.17,0.02,0.88,0.05,0.01,0.01
13.803890856241157,0.0012394640388758002,86.28075615209313,200.0,8.333333333333333e-05,0.61,0.15,0.17,0.02,0.88,0.05,0.01,0.01
13.952707087378158,0.00125186539147055,86.85425338836676,200.0,8.333333333333333e-05,0.61,0.15,0.17,0.02,0.88,0.05,0.01,0.01
14.101523318515158,0.0012642667440653,87.42775062464025,200.0,8.333333333333333e-05,0.61,0.15,0.17,0.02,0.88,0.05,0.01,0.01
14.263135827808757,0.0012777344531731002,88.01537510086136,200.0,8.333333333333333e-05,0.61,0.15,0.17,0.02,0.88,0.05,0.01,0.01
14.424748337102358,0.0012912021622809,88.60299957708231,200.0,8.333333333333333e-05,0.61,0.15,0.17,0.02,0.88,0.05,0.01,0.01
14.586360846395959,0.0013046698713887,89.19062405330338,200.0,8.333333333333333e-05,0.61,0.15,0.17,0.02,0.88,0.05,0.01,0.01
14.747973355689558,0.0013181375804965,89.77824852952446,200.0,8.333333333333333e-05,0.61,0.15,0.17,0.02,0.88,0.05,0.01,0.01
14.930958072395057,0.001333386306888625,90.3544551970891,200.0,8.333333333333333e-05,0.61,0.15,0.17,0.02,0.88,0.05,0.01,0.01
15.113942789100557,0.00134863503328075,90.93066186465417,200.0,8.333333333333333e-05,0.61,0.15,0.17,0.02,0.88,0.05,0.01,0.01
15.296927505806057,0.0013638837596728751,91.50686853221865,200.0,8.333333333333333e-05,0.61,0.15,0.17,0.02,0.88,0.05,0.01,0.01
15.479912222511556,0.001379132486065,92.08307519978229,200.0,8.333333333333333e-05,0.61,0.15,0.17,0.02,0.88,0.05,0.01,0.01
15.638920245190157,0.00139238315462155,92.65979895617866,200.0,8.333333333333333e-05,0.61,0.15,0.17,0.02,0.88,0.05,0.01,0.01
15.797928267868755,0.0014056338231781,93.23652271257525,200.0,8.333333333333333e-05,0.61,0.15,0.17,0.02,0.88,0.05,0.01,0.01
15.956936290547356,0.00141888449173465,93.8132464689717,200.0,8.333333333333333e-05,0.61,0.15,0.17,0.02,0.88,0.05,0.01,0.01
16.115944313225956,0.0014321351602912,94.38997022536795,200.0,8.333333333333333e-05,0.61,0.15,0.17,0.02,0.88,0.05,0.01,0.01
16.275476691068956,0.00144542952511145,94.98484280648502,200.0,8.333333333333333e-05,0.61,0.15,0.17,0.02,0.88,0.05,0.01,0.01
16.435009068911956,0.0014587238899317,95.57971538760285,200.0,8.333333333333333e-05,0.61,0.15,0.17,0.02,0.88,0.05,0.01,0.01
16.594541446754956,0.00147201825475195,96.17458796871998,200.0,8.333333333333333e-05,0.61,0.15,0.17,0.02,0.88,0.05,0.01,0.01
16.754073824597956,0.0014853126195722,96.76946054983677,200.0,8.333333333333333e-05,0.61,0.15,0.17,0.02,0.88,0.05,0.01,0.01
16.935555263846656,0.0015004360728429252,97.34586273196183,200.0,8.333333333333333e-05,0.61,0.15,0.17,0.02,0.88,0.05,0.01,0.01
17.117036703095355,0.0015155595261136501,97.92226491408707,200.0,8.333333333333333e-05,0.61,0.15,0.17,0.02,0.88,0.05,0.01,0.01
17.298518142344054,0.001530682979384375,98.49866709621223,200.0,8.333333333333333e-05,0.61,0.15,0.17,0.02,0.88,0.05,0.01,0.01
17.479999581592754,0.0015458064326551,99.07506927833734,200.0,8.333333333333333e-05,0.61,0.15,0.17,0.02,0.88,0.05,0.01,0.01
17.633404660880053,0.001558590189262375,99.63162868197956,200.0,8.333333333333333e-05,0.61,0.15,0.17,0.02,0.88,0.05,0.01,0.01
17.786809740167357,0.00157137394586965,100.18818808562129,200.0,8.333333333333333e-05,0.61,0.15,0.17,0.02,0.88,0.05,0.01,0.01
17.94021481945466,0.001584157702476925,100.74474748926343,200.0,8.333333333333333e-05,0.61,0.15,0.17,0.02,0.88,0.05,0.01,0.01
18.09361989874196,0.0015969414590842,101.30130689290564,200.0,8.333333333333333e-05,0.61,0.15,0.17,0.02,0.88,0.05,0.01,0.01
18.26043439218206,0.001610842666870875,101.86707310171589,200.0,8.333333333333333e-05,0.61,0.15,0.17,0.02,0.88,0.05,0.01,0.01
18.42724888562216,0.00162474387465755,102.43283931052679,200.0,8.333333333333333e-05,0.61,0.15,0.17,0.02,0.88,0.05,0.01,0.01
18.59406337906226,0.001638645082444225,102.99860551933705,200.0,8.333333333333333e-05,0.61,0.15,0.17,0.02,0.88,0.05,0.01,0.01
18.76087787250236,0.0016525462902309,103.56437172814759,200.0,8.333333333333333e-05,0.61,0.15,0.17,0.02,0.88,0.05,0.01,0.01
18.938710475113158,0.0016673656737818,104.13776416232858,200.0,8.333333333333333e-05,0.61,0.15,0.17,0.02,0.88,0.05,0.01,0.01
19.116543077723957,0.0016821850573326999,104.71115659650906,200.0,8.333333333333333e-05,0.61,0.15,0.17,0.02,0.88,0.05,0.01,0.01
19.294375680334756,0.0016970044408835998,105.28454903068999,200.0,8.333333333333333e-05,0.61,0.15,0.17,0.02,0.88,0.05,0.01,0.01
19.472208282945555,0.0017118238244345,105.85794146487095,200.0,8.333333333333333e-05,0.61,0.15,0.17,0.02,0.88,0.05,0.01,0.01
19.633534395925757,0.0017252676671828501,106.4212601967847,200.0,8.333333333333333e-05,0.61,0.15,0.17,0.02,0.88,0.05,0.01,0.01
19.794860508905955,0.0017387115099312001,106.98457892869902,200.0,8.333333333333333e-05,0.61,0.15,0.17,0.02,0.88,0.05,0.01,0.01
19.956186621886157,0.00175215535267955,107.54789766061299,200.0,8.333333333333333e-05,0.61,0.15,0.17,0.02,0.88,0.05,0.01,0.01
20.11751273486636,0.0017655991954279,108.11121639252642,200.0,8.333333333333333e-05,0.61,0.15,0.17,0.02,0.88,0.05,0.01,0.01
20.270061282503057,0.001778311574397625,108.67188577055741,200.0,8.333333333333333e-05,0.61,0.15,0.17,0.02,0.88,0.05,0.01,0.01
20.422609830139756,0.00179102395336735,109.23255514858758,200.0,8.333333333333333e-05,0.61,0.15,0.17,0.02,0.88,0.05,0.01,0.01
20.575158377776454,0.001803736332337075,109.79322452661847,200.0,8.333333333333333e-05,0.61,0.15,0.17,0.02,0.88,0.05,0.01,0.01
20.727706925413155,0.0018164487113068,110.35389390465065,200.0,8.333333333333333e-05,0.61,0.15,0.17,0.02,0.88,0.05,0.01,0.01
20.890380282453258,0.001830004824393475,110.9016348965514,200.0,8.333333333333333e-05,0.61,0.15,0.17,0.02,0.88,0.05,0.01,0.01
21.053053639493356,0.00184356093748015,111.4493758884521,200.0,8.333333333333333e-05,0.61,0.15,0.17,0.02,0.88,0.05,0.01,0.01
21.215726996533455,0.0018571170505668252,111.99711688035259,200.0,8.333333333333333e-05,0.61,0.15,0.17,0.02,0.88,0.05,0.01,0.01
21.378400353573557,0.0018706731636535,112.54485787225212,200.0,8.333333333333333e-05,0.61,0.15,0.17,0.02,0.88,0.05,0.01,0.01
21.532800891975555,0.0018835398751870002,113.08411168177088,200.0,8.333333333333333e-05,0.61,0.15,0.17,0.02,0.88,0.05,0.01,0.01
21.687201430377556,0.0018964065867205,113.62336549128986,200.0,8.333333333333333e-05,0.61,0.15,0.17,0.02,0.88,0.05,0.01,0.01
21.841601968779557,0.001909273298254,114.16261930080879,200.0,8.333333333333333e-05,0.61,0.15,0.17,0.02,0.88,0.05,0.01,0.01
21.996002507181554,0.0019221400097875,114.70187311032855,200.0,8.333333333333333e-05,0.61,0.15,0.17,0.02,0.88,0.05,0.01,0.01
22.144149024431055,0.001934485552891625,115.2532921629498,200.0,8.333333333333333e-05,0.61,0.15,0.17,0.02,0.88,0.05,0.01,0.01
22.292295541680556,0.00194683109599575,115.8047112155699,200.0,8.333333333333333e-05,0.61,0.15,0.17,0.02,0.88,0.05,0.01,0.01
22.440442058930056,0.001959176639099875,116.3561302681912,200.0,8.333333333333333e-05,0.61,0.15,0.17,0.02,0.88,0.05,0.01,0.01
22.588588576179557,0.001971522182204,116.90754932081322,200.0,8.333333333333333e-05,0.61,0.15,0.17,0.02,0.88,0.05,0.01,0.01
22.745858650606756,0.0019846280217396,117.46531832439746,200.0,8.333333333333333e-05,0.61,0.15,0.17,0.02,0.88,0.05,0.01,0.01
22.90312872503396,0.0019977338612752003,118.02308732798204,200.0,8.333333333333333e-05,0.61,0.15,0.17,0.02,0.88,0.05,0.01,0.01
23.06039879946116,0.0020108397008108004,118.58085633156647,200.0,8.333333333333333e-05,0.61,0.15,0.17,0.02,0.88,0.05,0.01,0.01
23.21766887388836,0.0020239455403464,119.13862533515106,200.0,8.333333333333333e-05,0.61,0.15,0.17,0.02,0.88,0.05,0.01,0.01
23.35422324892826,0.0020353250715997254,119.67188206391633,200.0,8.333333333333333e-05,0.61,0.15,0.17,0.02,0.88,0.05,0.01,0.01
23.49077762396816,0.0020467046028530504,120.20513879268171,200.0,8.333333333333333e-05,0.61,0.15,0.17,0.02,0.88,0.05,0.01,0.01
23.62733199900806,0.0020580841341063753,120.7383955214467,200.0,8.333333333333333e-05,0.61,0.15,0.17,0.02,0.88,0.05,0.01,0.01
23.76388637404796,0.0020694636653597,121.27165225021074,200.0,8.333333333333333e-05,0.61,0.15,0.17,0.02,0.88,0.05,0.01,0.01
23.905984911881358,0.00208130521017915,121.81275379883073,200.0,8.333333333333333e-05,0.61,0.15,0.17,0.02,0.88,0.05,0.01,0.01
24.048083449714756,0.0020931467549986,122.35385534745186,200.0,8.333333333333333e-05,0.61,0.15,0.17,0.02,0.88,0.05,0.01,0.01
24.190181987548154,0.00210498829981805,122.89495689607193,200.0,8.333333333333333e-05,0.61,0.15,0.17,0.02,0.88,0.05,0.01,0.01
24.332280525381552,0.0021168298446375,123.43605844469064,200.0,8.333333333333333e-05,0.61,0.15,0.17,0.02,0.88,0.05,0.01,0.01
24.490321614082454,0.002129999935362575,123.98103046754468,200.0,8.333333333333333e-05,0.61,0.15,0.17,0.02,0.88,0.05,0.01,0.01
24.648362702783352,0.00214317002608765,124.52600249039813,200.0,8.333333333333333e-05,0.61,0.15,0.17,0.02,0.88,0.05,0.01,0.01
24.80640379148425,0.002156340116812725,125.0709745132518,200.0,8.333333333333333e-05,0.61,0.15,0.17,0.02,0.88,0.05,0.01,0.01
24.96444488018515,0.0021695102075378,125.61594653610639,200.0,8.333333333333333e-05,0.61,0.15,0.17,0.02,0.88,0.05,0.01,0.01
25.11012515106055,0.0021816502301107497,126.1386115078724,200.0,8.333333333333333e-05,0.61,0.15,0.17,0.02,0.88,0.05,0.01,0.01
25.255805421935953,0.0021937902526836996,126.66127647963793,200.0,8.333333333333333e-05,0.61,0.15,0.17,0.02,0.88,0.05,0.01,0.01
25.401485692811356,0.00220593027525665,127.18394145140462,200.0,8.333333333333333e-05,0.61,0.15,0.17,0.02,0.88,0.05,0.01,0.01
25.547165963686755,0.0022180702978296,127.70660642317173,200.0,8.333333333333333e-05,0.61,0.15,0.17,0.02,0.88,0.05,0.01,0.01
25.701259548118458,0.002230911429865575,128.23955500250074,200.0,8.333333333333333e-05,0.61,0.15,0.17,0.02,0.88,0.05,0.01,0.01
25.855353132550157,0.00224375256190155,128.7725035818317,200.0,8.333333333333333e-05,0.61,0.15,0.17,0.02,0.88,0.05,0.01,0.01
26.009446716981856,0.002256593693937525,129.30545216116053,200.0,8.333333333333333e-05,0.61,0.15,0.17,0.02,0.88,0.05,0.01,0.01
26.163540301413555,0.0022694348259735,129.83840074048717,200.0,8.333333333333333e-05,0.61,0.15,0.17,0.02,0.88,0.05,0.01,0.01
26.338370113007056,0.0022840039769396253,130.37920914826915,200.0,8.333333333333333e-05,0.61,0.15,0.17,0.02,0.88,0.05,0.01,0.01
26.513199924600556,0.00229857312790575,130.92001755605233,200.0,8.333333333333333e-05,0.61,0.15,0.17,0.02,0.88,0.05,0.01,0.01
26.688029736194053,0.002313142278871875,131.46082596383445,200.0,8.333333333333333e-05,0.61,0.15,0.17,0.02,0.88,0.05,0.01,0.01
26.862859547787554,0.002327711429838,132.00163437161535,200.0,8.333333333333333e-05,0.61,0.15,0.17,0.02,0.88,0.05,0.01,0.01
27.020575752668055,0.002340854446911375,132.53004501642886,200.0,8.333333333333333e-05,0.61,0.15,0.17,0.02,0.88,0.05,0.01,0.01
27.178291957548556,0.00235399746398475,133.05845566124273,200.0,8.333333333333333e-05,0.61,0.15,0.17,0.02,0.88,0.05,0.01,0.01
27.336008162429057,0.002367140481058125,133.58686630605615,200.0,8.333333333333333e-05,0.61,0.15,0.17,0.02,0.88,0.05,0.01,0.01
27.493724367309557,0.0023802834981315,134.11527695086892,200.0,8.333333333333333e-05,0.61,0.15,0.17,0.02,0.88,0.05,0.01,0.01
27.62961342984776,0.00239160758667635,134.63855814720716,200.0,8.333333333333333e-05,0.61,0.15,0.17,0.02,0.88,0.05,0.01,0.01
27.765502492385956,0.0024029316752211998,135.1618393435466,200.0,8.333333333333333e-05,0.61,0.15,0.17,0.02,0.88,0.05,0.01,0.01
27.901391554924157,0.00241425576376605,135.68512053988462,200.0,8.333333333333333e-05,0.61,0.15,0.17,0.02,0.88,0.05,0.01,0.01
28.037280617462358,0.0024255798523109,136.2084017362227,200.0,8.333333333333333e-05,0.61,0.15,0.17,0.02,0.88,0.05,0.01,0.01
28.188264364721658,0.002438161831249175,136.71616763191446,200.0,8.333333333333333e-05,0.61,0.15,0.17,0.02,0.88,0.05,0.01,0.01
28.339248111980957,0.00245074381018745,137.22393352760656,200.0,8.333333333333333e-05,0.61,0.15,0.17,0.02,0.88,0.05,0.01,0.01
28.490231859240257,0.002463325789125725,137.7316994232986,200.0,8.333333333333333e-05,0.61,0.15,0.17,0.02,0.88,0.05,0.01,0.01
28.641215606499557,0.002475907768064,138.2394653189894,200.0,8.333333333333333e-05,0.61,0.15,0.17,0.02,0.88,0.05,0.01,0.01
28.807229629580057,0.002489742269987375,138.7426852127504,200.0,8.333333333333333e-05,0.61,0.15,0.17,0.02,0.88,0.05,0.01,0.01
28.973243652660557,0.00250357677191075,139.24590510651194,200.0,8.333333333333333e-05,0.61,0.15,0.17,0.02,0.88,0.05,0.01,0.01
29.139257675741057,0.0025174112738341253,139.74912500027278,200.0,8.333333333333333e-05,0.61,0.15,0.17,0.02,0.88,0.05,0.01,0.01
29.30527169882156,0.0025312457757575,140.2523448940342,200.0,8.333333333333333e-05,0.61,0.15,0.17,0.02,0.88,0.05,0.01,0.01
29.454762223352063,0.002543703319468375,140.76041335493096,200.0,8.333333333333333e-05,0.61,0.15,0.17,0.02,0.88,0.05,0.01,0.01
29.604252747882562,0.0025561608631792503,141.26848181582653,200.0,8.333333333333333e-05,0.61,0.15,0.17,0.02,0.88,0.05,0.01,0.01
29.75374327241306,0.0025686184068901253,141.77655027672307,200.0,8.333333333333333e-05,0.61,0.15,0.17,0.02,0.88,0.05,0.01,0.01
29.90323379694356,0.002581075950601,142.28461873761913,200.0,8.333333333333333e-05,0.61,0.15,0.17,0.02,0.88,0.05,0.01,0.01
30.07865278512746,0.002595694199616325,142.77445529076337,200.0,8.333333333333333e-05,0.61,0.15,0.17,0.02,0.88,0.05,0.01,0.01
30.25407177331136,0.00261031244863165,143.26429184390895,200.0,8.333333333333333e-05,0.61,0.15,0.17,0.02,0.88,0.05,0.01,0.01
30.42949076149526,0.002624930697646975,143.75412839705325,200.0,8.333333333333333e-05,0.61,0.15,0.17,0.02,0.88,0.05,0.01,0.01
30.604909749679155,0.0026395489466623,144.24396495019872,200.0,8.333333333333333e-05,0.61,0.15,0.17,0.02,0.88,0.05,0.01,0.01
30.747748126136656,0.002651452144700425,144.71124486685372,200.0,8.333333333333333e-05,0.61,0.15,0.17,0.02,0.88,0.05,0.01,0.01
30.890586502594157,0.0026633553427385503,145.17852478350648,200.0,8.333333333333333e-05,0.61,0.15,0.17,0.02,0.88,0.05,0.01,0.01
31.03342487905166,0.002675258540776675,145.64580470016188,200.0,8.333333333333333e-05,0.61,0.15,0.17,0.02,0.88,0.05,0.01,0.01
31.17626325550916,0.0026871617388148,146.11308461681776,200.0,8.333333333333333e-05,0.61,0.15,0.17,0.02,0.88,0.05,0.01,0.01
31.324185643589658,0.002699488604488175,146.594719178319,200.0,8.333333333333333e-05,0.61,0.15,0.17,0.02,0.88,0.05,0.01,0.01
31.47210803167016,0.00271181547016155,147.07635373981918,200.0,8.333333333333333e-05,0.61,0.15,0.17,0.02,0.88,0.05,0.01,0.01
31.62003041975066,0.002724142335834925,147.55798830132005,200.0,8.333333333333333e-05,0.61,0.15,0.17,0.02,0.88,0.05,0.01,0.01
31.767952807831158,0.0027364692015083,148.0396228628224,200.0,8.333333333333333e-05,0.61,0.15,0.17,0.02,0.88,0.05,0.01,0.01
31.91295222845996,0.0027485524865607,148.52048640940689,200.0,8.333333333333333e-05,0.61,0.15,0.17,0.02,0.88,0.05,0.01,0.01
32.057951649088764,0.0027606357716131,149.0013499559921,200.0,8.333333333333333e-05,0.61,0.15,0.17,0.02,0.88,0.05,0.01,0.01
32.202951069717564,0.0027727190566655,149.48221350257668,200.0,8.333333333333333e-05,0.61,0.15,0.17,0.02,0.88,0.05,0.01,0.01
32.34795049034636,0.0027848023417179,149.96307704916126,200.0,8.333333333333333e-05,0.61,0.15,0.17,0.02,0.88,0.05,0.01,0.01
32.49543026973116,0.0027970923233333,150.43960469463724,200.0,8.333333333333333e-05,0.61,0.15,0.17,0.02,0.88,0.05,0.01,0.01
32.64291004911596,0.0028093823049487,150.9161323401132,200.0,8.333333333333333e-05,0.61,0.15,0.17,0.02,0.88,0.05,0.01,0.01
32.790389828500764,0.0028216722865641,151.39265998558875,200.0,8.333333333333333e-05,0.61,0.15,0.17,0.02,0.88,0.05,0.01,0.01
32.93786960788556,0.0028339622681795,151.86918763106195,200.0,8.333333333333333e-05,0.61,0.15,0.17,0.02,0.88,0.05,0.01,0.01
33.061391908001056,0.002844255793189125,152.3360478544417,200.0,8.333333333333333e-05,0.61,0.15,0.17,0.02,0.88,0.05,0.01,0.01
33.18491420811656,0.00285454931819875,152.80290807782185,200.0,8.333333333333333e-05,0.61,0.15,0.17,0.02,0.88,0.05,0.01,0.01
33.30843650823206,0.002864842843208375,153.26976830120174,200.0,8.333333333333333e-05,0.61,0.15,0.17,0.02,0.88,0.05,0.01,0.01
33.43195880834756,0.002875136368218,153.73662852458207,200.0,8.333333333333333e-05,0.61,0.15,0.17,0.02,0.88,0.05,0.01,0.01
33.565686592085655,0.0028862803501961748,154.20949470951982,200.0,8.333333333333333e-05,0.61,0.15,0.17,0.02,0.88,0.05,0.01,0.01
33.69941437582376,0.0028974243321743497,154.6823608944594,200.0,8.333333333333333e-05,0.61,0.15,0.17,0.02,0.88,0.05,0.01,0.01
33.83314215956186,0.0029085683141525246,155.15522707939763,200.0,8.333333333333333e-05,0.61,0.15,0.17,0.02,0.88,0.05,0.01,0.01
33.966869943299955,0.0029197122961307,155.6280932643336,200.0,8.333333333333333e-05,0.61,0.15,0.17,0.02,0.88,0.05,0.01,0.01
34.08213566107315,0.0029293177726118,156.1007522969861,200.0,8.333333333333333e-05,0.61,0.15,0.17,0.02,0.88,0.05,0.01,0.01
34.19740137884636,0.0029389232490929,156.57341132963973,200.0,8.333333333333333e-05,0.61,0.15,0.17,0.02,0.88,0.05,0.01,0.01
34.31266709661956,0.002948528725574,157.0460703622919,200.0,8.333333333333333e-05,0.61,0.15,0.17,0.02,0.88,0.05,0.01,0.01
34.42793281439276,0.0029581342020551,157.51872939494308,200.0,8.333333333333333e-05,0.61,0.15,0.17,0.02,0.88,0.05,0.01,0.01
34.56464029717736,0.00296952649228715,158.0054930216878,200.0,8.333333333333333e-05,0.61,0.15,0.17,0.02,0.88,0.05,0.01,0.01
34.701347779961964,0.0029809187825192,158.49225664843462,200.0,8.333333333333333e-05,0.61,0.15,0.17,0.02,0.88,0.05,0.01,0.01
34.838055262746565,0.00299231107275125,158.979020275179,200.0,8.333333333333333e-05,0.61,0.15,0.17,0.02,0.88,0.05,0.01,0.01
34.97476274553116,0.0030037033629833,159.46578390192195,200.0,8.333333333333333e-05,0.61,0.15,0.17,0.02,0.88,0.05,0.01,0.01
35.085154748104756,0.0030129026965310998,159.93339601774719,200.0,8.333333333333333e-05,0.61,0.15,0.17,0.02,0.88,0.05,0.01,0.01
35.19554675067836,0.0030221020300789,160.40100813357154,200.0,8.333333333333333e-05,0.61,0.15,0.17,0.02,0.88,0.05,0.01,0.01
35.30593875325196,0.0030313013636267,160.8686202493973,200.0,8.333333333333333e-05,0.61,0.15,0.17,0.02,0.88,0.05,0.01,0.01
35.416330755825555,0.0030405006971745,161.33623236522396,200.0,8.333333333333333e-05,0.61,0.15,0.17,0.02,0.88,0.05,0.01,0.01
35.58948745515776,0.00305493042211885,161.81377991103346,200.0,8.333333333333333e-05,0.61,0.15,0.17,0.02,0.88,0.05,0.01,0.01
35.76264415448996,0.0030693601470632,162.29132745684188,200.0,8.333333333333333e-05,0.61,0.15,0.17,0.02,0.88,0.05,0.01,0.01
35.93580085382216,0.00308378987200755,162.76887500265147,200.0,8.333333333333333e-05,0.61,0.15,0.17,0.02,0.88,0.05,0.01,0.01
36.10895755315436,0.0030982195969519,163.24642254846214,200.0,8.333333333333333e-05,0.61,0.15,0.17,0.02,0.88,0.05,0.01,0.01
36.28175961296216,0.00311261976860255,163.72398169289139,200.0,8.333333333333333e-05,0.61,0.15,0.17,0.02,0.88,0.05,0.01,0.01
36.45456167276996,0.0031270199402532,164.20154083732294,200.0,8.333333333333333e-05,0.61,0.15,0.17,0.02,0.88,0.05,0.01,0.01
36.62736373257776,0.0031414201119038497,164.67909998175222,200.0,8.333333333333333e-05,0.61,0.15,0.17,0.02,0.88,0.05,0.01,0.01
36.80016579238556,0.0031558202835545,165.156659126177,200.0,8.333333333333333e-05,0.61,0.15,0.17,0.02,0.88,0.05,0.01,0.01
36.98029217670086,0.003170830815580775,165.63778792372926,200.0,8.333333333333333e-05,0.61,0.15,0.17,0.02,0.88,0.05,0.01,0.01
37.16041856101616,0.00318584134760705,166.1189167212836,200.0,8.333333333333333e-05,0.61,0.15,0.17,0.02,0.88,0.05,0.01,0.01
37.34054494533146,0.0032008518796333247,166.60004551883526,200.0,8.333333333333333e-05,0.61,0.15,0.17,0.02,0.88,0.05,0.01,0.01
37.52067132964676,0.0032158624116596,167.0811743163874,200.0,8.333333333333333e-05,0.61,0.15,0.17,0.02,0.88,0.05,0.01,0.01
37.68948840265796,0.0032299305010772003,167.54127225904892,200.0,8.333333333333333e-05,0.61,0.15,0.17,0.02,0.88,0.05,0.01,0.01
37.858305475669155,0.0032439985904948003,168.00137020171033,200.0,8.333333333333333e-05,0.61,0.15,0.17,0.02,0.88,0.05,0.01,0.01
38.02712254868035,0.0032580666799124003,168.4614681443719,200.0,8.333333333333333e-05,0.61,0.15,0.17,0.02,0.88,0.05,0.01,0.01
38.19593962169156,0.00327213476933,168.92156608703476,200.0,8.333333333333333e-05,0.61,0.15,0.17,0.02,0.88,0.05,0.01,0.01
38.33746108370636,0.0032839282244979,169.395664408275,200.0,8.333333333333333e-05,0.61,0.15,0.17,0.02,0.88,0.05,0.01,0.01
38.47898254572116,0.0032957216796658,169.8697627295108,200.0,8.333333333333333e-05,0.61,0.15,0.17,0.02,0.88,0.05,0.01,0.01
38.62050400773596,0.0033075151348337,170.34386105075137,200.0,8.333333333333333e-05,0.61,0.15,0.17,0.02,0.88,0.05,0.01,0.01
38.76202546975076,0.0033193085900016,170.81795937199695,200.0,8.333333333333333e-05,0.61,0.15,0.17,0.02,0.88,0.05,0.01,0.01
38.94165414781316,0.0033342776465068004,171.27680113253274,200.0,8.333333333333333e-05,0.61,0.15,0.17,0.02,0.88,0.05,0.01,0.01
39.12128282587556,0.0033492467030120003,171.73564289306563,200.0,8.333333333333333e-05,0.61,0.15,0.17,0.02,0.88,0.05,0.01,0.01
39.30091150393796,0.0033642157595172003,172.19448465360097,200.0,8.333333333333333e-05,0.61,0.15,0.17,0.02,0.88,0.05,0.01,0.01
39.48054018200036,0.0033791848160224,172.6533264141366,200.0,8.333333333333333e-05,0.61,0.15,0.17,0.02,0.88,0.05,0.01,0.01
39.65604607473476,0.0033938103070836,173.11279137953306,200.0,8.333333333333333e-05,0.61,0.15,0.17,0.02,0.88,0.05,0.01,0.01
39.83155196746916,0.0034084357981448,173.5722563449288,200.0,8.333333333333333e-05,0.61,0.15,0.17,0.02,0.88,0.05,0.01,0.01
40.00705786020356,0.003423061289206,174.03172131032613,200.0,8.333333333333333e-05,0.61,0.15,0.17,0.02,0.88,0.05,0.01,0.01
40.18256375293796,0.0034376867802672,174.49118627572358,200.0,8.333333333333333e-05,0.61,0.15,0.17,0.02,0.88,0.05,0.01,0.01
40.32559605961286,0.0034496061391567747,174.93678781697758,200.0,8.333333333333333e-05,0.61,0.15,0.17,0.02,0.88,0.05,0.01,0.01
40.46862836628776,0.00346152549804635,175.38238935823065,200.0,8.333333333333333e-05,0.61,0.15,0.17,0.02,0.88,0.05,0.01,0.01
40.61166067296266,0.003473444856935925,175.82799089948386,200.0,8.333333333333333e-05,0.61,0.15,0.17,0.02,0.88,0.05,0.01,0.01
40.75469297963756,0.0034853642158255,176.27359244073807,200.0,8.333333333333333e-05,0.61,0.15,0.17,0.02,0.88,0.05,0.01,0.01
40.870038351961156,0.0034949763301858,176.72565683765708,200.0,8.333333333333333e-05,0.61,0.15,0.17,0.02,0.88,0.05,0.01,0.01
40.98538372428476,0.0035045884445461,177.17772123457598,200.0,8.333333333333333e-05,0.61,0.15,0.17,0.02,0.88,0.05,0.01,0.01
41.10072909660836,0.0035142005589063998,177.6297856314946,200.0,8.333333333333333e-05,0.61,0.15,0.17,0.02,0.88,0.05,0.01,0.01
41.21607446893196,0.0035238126732667,178.0818500284115,200.0,8.333333333333333e-05,0.61,0.15,0.17,0.02,0.88,0.05,0.01,0.01
41.363711997591864,0.003536115800655025,178.53764302568703,200.0,8.333333333333333e-05,0.61,0.15,0.17,0.02,0.88,0.05,0.01,0.01
41.51134952625176,0.00354841892804335,178.9934360229636,200.0,8.333333333333333e-05,0.61,0.15,0.17,0.02,0.88,0.05,0.01,0.01
41.65898705491166,0.003560722055431675,179.4492290202402,200.0,8.333333333333333e-05,0.61,0.15,0.17,0.02,0.88,0.05,0.01,0.01
41.80662458357156,0.00357302518282,179.9050220175184,200.0,8.333333333333333e-05,0.61,0.15,0.17,0.02,0.88,0.05,0.01,0.01
41.971446042572666,0.003586760304403425,180.35665259634317,200.0,8.333333333333333e-05,0.61,0.15,0.17,0.02,0.88,0.05,0.01,0.01
42.13626750157376,0.00360049542598685,180.8082831751686,200.0,8.333333333333333e-05,0.61,0.15,0.17,0.02,0.88,0.05,0.01,0.01
42.30108896057486,0.003614230547570275,181.25991375399315,200.0,8.333333333333333e-05,0.61,0.15,0.17,0.02,0.88,0.05,0.01,0.01
42.46591041957596,0.0036279656691537,181.7115443328147,200.0,8.333333333333333e-05,0.61,0.15,0.17,0.02,0.88,0.05,0.01,0.01
42.63450498687596,0.0036420152164287,182.14173805031393,200.0,8.333333333333333e-05,0.61,0.15,0.17,0.02,0.88,0.05,0.01,0.01
42.80309955417596,0.0036560647637036998,182.57193176781726,200.0,8.333333333333333e-05,0.61,0.15,0.17,0.02,0.88,0.05,0.01,0.01
42.97169412147596,0.0036701143109786998,183.00212548531653,200.0,8.333333333333333e-05,0.61,0.15,0.17,0.02,0.88,0.05,0.01,0.01
43.14028868877596,0.0036841638582537,183.43231920281315,200.0,8.333333333333333e-05,0.61,0.15,0.17,0.02,0.88,0.05,0.01,0.01
43.26656309203136,0.0036946867251916498,183.85339582260713,200.0,8.333333333333333e-05,0.61,0.15,0.17,0.02,0.88,0.05,0.01,0.01
43.392837495286756,0.0037052095921296,184.2744724424026,200.0,8.333333333333333e-05,0.61,0.15,0.17,0.02,0.88,0.05,0.01,0.01
43.51911189854216,0.00371573245906755,184.69554906219662,200.0,8.333333333333333e-05,0.61,0.15,0.17,0.02,0.88,0.05,0.01,0.01
43.64538630179756,0.0037262553260055,185.11662568199148,200.0,8.333333333333333e-05,0.61,0.15,0.17,0.02,0.88,0.05,0.01,0.01
43.81501571285636,0.0037403911102604,185.54068556373795,200.0,8.333333333333333e-05,0.61,0.15,0.17,0.02,0.88,0.05,0.01,0.01
43.98464512391516,0.0037545268945152997,185.9647454454859,200.0,8.333333333333333e-05,0.61,0.15,0.17,0.02,0.88,0.05,0.01,0.01
44.15427453497396,0.0037686626787701996,186.38880532723311,200.0,8.333333333333333e-05,0.61,0.15,0.17,0.02,0.88,0.05,0.01,0.01
44.32390394603276,0.0037827984630251,186.81286520897746,200.0,8.333333333333333e-05,0.61,0.15,0.17,0.02,0.88,0.05,0.01,0.01
44.44427030306366,0.003792828992777675,187.2238963644112,200.0,8.333333333333333e-05,0.61,0.15,0.17,0.02,0.88,0.05,0.01,0.01
44.564636660094564,0.00380285952253025,187.63492751984072,200.0,8.333333333333333e-05,0.61,0.15,0.17,0.02,0.88,0.05,0.01,0.01
44.68500301712547,0.003812890052282825,188.04595867527433,200.0,8.333333333333333e-05,0.61,0.15,0.17,0.02,0.88,0.05,0.01,0.01
44.80536937415636,0.0038229205820354,188.45698983071173,200.0,8.333333333333333e-05,0.61,0.15,0.17,0.02,0.88,0.05,0.01,0.01
45.00142732293536,0.00383925874443365,188.867561104396,200.0,8.333333333333333e-05,0.61,0.15,0.17,0.02,0.88,0.05,0.01,0.01
45.19748527171436,0.0038555969068318997,189.27813237807976,200.0,8.333333333333333e-05,0.61,0.15,0.17,0.02,0.88,0.05,0.01,0.01
45.39354322049336,0.00387193506923015,189.68870365176332,200.0,8.333333333333333e-05,0.61,0.15,0.17,0.02,0.88,0.05,0.01,0.01
45.58960116927236,0.0038882732316284,190.09927492544875,200.0,8.333333333333333e-05,0.61,0.15,0.17,0.02,0.88,0.05,0.01,0.01
45.77376556902597,0.0039036202649412,190.49480998091752,200.0,8.333333333333333e-05,0.61,0.15,0.17,0.02,0.88,0.05,0.01,0.01
45.95792996877957,0.003918967298254,190.890345036388,200.0,8.333333333333333e-05,0.61,0.15,0.17,0.02,0.88,0.05,0.01,0.01
46.142094368533165,0.0039343143315668,191.2858800918566,200.0,8.333333333333333e-05,0.61,0.15,0.17,0.02,0.88,0.05,0.01,0.01
46.32625876828676,0.0039496613648796,191.6814151473226,200.0,8.333333333333333e-05,0.61,0.15,0.17,0.02,0.88,0.05,0.01,0.01
46.50586892483546,0.003964628877925325,192.07336755499085,200.0,8.333333333333333e-05,0.61,0.15,0.17,0.02,0.88,0.05,0.01,0.01
46.68547908138416,0.00397959639097105,192.46531996265975,200.0,8.333333333333333e-05,0.61,0.15,0.17,0.02,0.88,0.05,0.01,0.01
46.865089237932864,0.003994563904016775,192.8572723703281,200.0,8.333333333333333e-05,0.61,0.15,0.17,0.02,0.88,0.05,0.01,0.01
47.04469939448156,0.0040095314170625,193.249224777995,200.0,8.333333333333333e-05,0.61,0.15,0.17,0.02,0.88,0.05,0.01,0.01
47.24670082436727,0.004026364869552976,193.6302476843685,200.0,8.333333333333333e-05,0.61,0.15,0.17,0.02,0.88,0.05,0.01,0.01
47.448702254252964,0.0040431983220434505,194.01127059074537,200.0,8.333333333333333e-05,0.61,0.15,0.17,0.02,0.88,0.05,0.01,0.01
47.65070368413866,0.004060031774533925,194.3922934971187,200.0,8.333333333333333e-05,0.61,0.15,0.17,0.02,0.88,0.05,0.01,0.01
47.85270511402436,0.0040768652270244,194.7733164034894,200.0,8.333333333333333e-05,0.61,0.15,0.17,0.02,0.88,0.05,0.01,0.01
48.08219816554076,0.0040959896479841,195.13042937333864,200.0,8.333333333333333e-05,0.61,0.15,0.17,0.02,0.88,0.05,0.01,0.01
48.31169121705716,0.0041151140689438,195.48754234318616,200.0,8.333333333333333e-05,0.61,0.15,0.17,0.02,0.88,0.05,0.01,0.01
48.54118426857356,0.0041342384899035,195.84465531303525,200.0,8.333333333333333e-05,0.61,0.15,0.17,0.02,0.88,0.05,0.01,0.01
48.77067732008996,0.0041533629108632,196.20176828288476,200.0,8.333333333333333e-05,0.61,0.15,0.17,0.02,0.88,0.05,0.01,0.01
49.01839893007496,0.00417400637836195,196.53168777670976,200.0,8.333333333333333e-05,0.61,0.15,0.17,0.02,0.88,0.05,0.01,0.01
49.26612054005996,0.0041946498458607,196.86160727053752,200.0,8.333333333333333e-05,0.61,0.15,0.17,0.02,0.88,0.05,0.01,0.01
49.513842150044965,0.00421529331335945,197.19152676436312,200.0,8.333333333333333e-05,0.61,0.15,0.17,0.02,0.88,0.05,0.01,0.01
49.761563760029965,0.0042359367808582,197.5214462581867,200.0,8.333333333333333e-05,0.61,0.15,0.17,0.02,0.88,0.05,0.01,0.01
50.05612437879266,0.004260483499088425,197.83310382706293,200.0,8.333333333333333e-05,0.61,0.15,0.17,0.02,0.88,0.05,0.01,0.01
50.35068499755536,0.00428503021731865,198.1447613959417,200.0,8.333333333333333e-05,0.61,0.15,0.17,0.02,0.88,0.05,0.01,0.01
50.645245616318064,0.004309576935548875,198.45641896481763,200.0,8.333333333333333e-05,0.61,0.15,0.17,0.02,0.88,0.05,0.01,0.01
50.93980623508076,0.0043341236537791,198.76807653368974,200.0,8.333333333333333e-05,0.61,0.15,0.17,0.02,0.88,0.05,0.01,0.01
51.198855275716156,0.00435571107383205,199.048879482756,200.0,8.333333333333333e-05,0.61,0.15,0.17,0.02,0.88,0.05,0.01,0.01
51.45790431635156,0.0043772984938850006,199.32968243182387,200.0,8.333333333333333e-05,0.61,0.15,0.17,0.02,0.88,0.05,0.01,0.01
51.71695335698696,0.0043988859139379504,199.61048538088988,200.0,8.333333333333333e-05,0.61,0.15,0.17,0.02,0.88,0.05,0.01,0.01
51.976002397622366,0.0044204733339909,199.8912883299549,200.0,8.333333333333333e-05,0.61,0.15,0.17,0.02,0.88,0.05,0.01,0.01
52.24666064532177,0.00444302818796585,200.13404044308317,200.0,8.333333333333333e-05,0.61,0.15,0.17,0.02,0.88,0.05,0.01,0.01
52.51731889302116,0.0044655830419408,200.37679255621356,200.0,8.333333333333333e-05,0.61,0.15,0.17,0.02,0.88,0.05,0.01,0.01
52.78797714072056,0.00448813789591575,200.61954466934247,200.0,8.333333333333333e-05,0.61,0.15,0.17,0.02,0.88,0.05,0.01,0.01
53.05863538841996,0.0045106927498907,200.86229678247008,200.0,8.333333333333333e-05,0.61,0.15,0.17,0.02,0.88,0.05,0.01,0.01
53.37494559206816,0.00453705193352805,201.07589078703435,200.0,8.333333333333333e-05,0.61,0.15,0.17,0.02,0.88,0.05,0.01,0.01
53.69125579571636,0.0045634111171654005,201.28948479159902,200.0,8.333333333333333e-05,0.61,0.15,0.17,0.02,0.88,0.05,0.01,0.01
54.00756599936456,0.004589770300802751,201.50307879616292,200.0,8.333333333333333e-05,0.61,0.15,0.17,0.02,0.88,0.05,0.01,0.01
54.32387620301276,0.0046161294844401,201.7166728007268,200.0,8.333333333333333e-05,0.61,0.15,0.17,0.02,0.88,0.05,0.01,0.01
54.68061106107476,0.0046458573892786004,201.8965239414858,200.0,8.333333333333333e-05,0.61,0.15,0.17,0.02,0.88,0.05,0.01,0.01
55.037345919136754,0.0046755852941171,202.07637508224516,200.0,8.333333333333333e-05,0.61,0.15,0.17,0.02,0.88,0.05,0.01,0.01
55.39408077719875,0.004705313198955599,202.25622622300418,200.0,8.333333333333333e-05,0.61,0.15,0.17,0.02,0.88,0.05,0.01,0.01
55.75081563526076,0.0047350411037941,202.43607736376174,200.0,8.333333333333333e-05,0.61,0.15,0.17,0.02,0.88,0.05,0.01,0.01
56.129053934043256,0.004766560962025975,202.60338956374824,200.0,8.333333333333333e-05,0.61,0.15,0.17,0.02,0.88,0.05,0.01,0.01
56.50729223282576,0.00479808082025785,202.7707017637365,200.0,8.333333333333333e-05,0.61,0.15,0.17,0.02,0.88,0.05,0.01,0.01
56.88553053160827,0.004829600678489725,202.9380139637225,200.0,8.333333333333333e-05,0.61,0.15,0.17,0.02,0.88,0.05,0.01,0.01
57.26376883039077,0.0048611205367216,203.10532616370782,200.0,8.333333333333333e-05,0.61,0.15,0.17,0.02,0.88,0.05,0.01,0.01
57.633470937226164,0.004891929045624551,203.2287791807108,200.0,8.333333333333333e-05,0.61,0.15,0.17,0.02,0.88,0.05,0.01,0.01
58.00317304406157,0.0049227375545275,203.3522321977138,200.0,8.333333333333333e-05,0.61,0.15,0.17,0.02,0.88,0.05,0.01,0.01
58.372875150896974,0.00495354606343045,203.47568521471712,200.0,8.333333333333333e-05,0.61,0.15,0.17,0.02,0.88,0.05,0.01,0.01
58.74257725773237,0.0049843545723334,203.59913823172207,200.0,8.333333333333333e-05,0.61,0.15,0.17,0.02,0.88,0.05,0.01,0.01
59.15814095965557,0.0050189848808270005,203.69560116306056,200.0,8.333333333333333e-05,0.61,0.15,0.17,0.02,0.88,0.05,0.01,0.01
59.573704661578766,0.0050536151893206,203.79206409439792,200.0,8.333333333333333e-05,0.61,0.15,0.17,0.02,0.88,0.05,0.01,0.01
59.989268363501964,0.0050882454978141995,203.88852702573692,200.0,8.333333333333333e-05,0.61,0.15,0.17,0.02,0.88,0.05,0.01,0.01
60.40483206542516,0.0051228758063078,203.9849899570742,200.0,8.333333333333333e-05,0.61,0.15,0.17,0.02,0.88,0.05,0.01,0.01
60.831699429010456,0.005158448086606576,204.04736185093918,200.0,8.333333333333333e-05,0.61,0.15,0.17,0.02,0.88,0.05,0.01,0.01
61.25856679259576,0.00519402036690535,204.10973374480366,200.0,8.333333333333333e-05,0.61,0.15,0.17,0.02,0.88,0.05,0.01,0.01
61.68543415618106,0.005229592647204125,204.17210563866848,200.0,8.333333333333333e-05,0.61,0.15,0.17,0.02,0.88,0.05,0.01,0.01
62.11230151976636,0.0052651649275029,204.23447753253512,200.0,8.333333333333333e-05,0.61,0.15,0.17,0.02,0.88,0.05,0.01,0.01
62.56639425027356,0.0053030059883785,204.27625231139362,200.0,8.333333333333333e-05,0.61,0.15,0.17,0.02,0.88,0.05,0.01,0.01
63.02048698078076,0.0053408470492541,204.3180270902532,200.0,8.333333333333333e-05,0.61,0.15,0.17,0.02,0.88,0.05,0.01,0.01
63.47457971128796,0.0053786881101297,204.35980186911172,200.0,8.333333333333333e-05,0.61,0.15,0.17,0.02,0.88,0.05,0.01,0.01
63.92867244179516,0.0054165291710053,204.40157664796888,200.0,8.333333333333333e-05,0.61,0.15,0.17,0.02,0.88,0.05,0.01,0.01
64.37966196443546,0.005454111631225325,204.43412584331412,200.0,8.333333333333333e-05,0.61,0.15,0.17,0.02,0.88,0.05,0.01,0.01
64.83065148707576,0.00549169409144535,204.4666750386569,200.0,8.333333333333333e-05,0.61,0.15,0.17,0.02,0.88,0.05,0.01,0.01
65.28164100971605,0.0055292765516653745,204.49922423400238,200.0,8.333333333333333e-05,0.61,0.15,0.17,0.02,0.88,0.05,0.01,0.01
65.73263053235637,0.0055668590118854,204.5317734293525,200.0,8.333333333333333e-05,0.61,0.15,0.17,0.02,0.88,0.05,0.01,0.01
66.19662664733487,0.005605525354800275,204.55507563887699,200.0,8.333333333333333e-05,0.61,0.15,0.17,0.02,0.88,0.05,0.01,0.01
66.66062276231337,0.00564419169771515,204.57837784840004,200.0,8.333333333333333e-05,0.61,0.15,0.17,0.02,0.88,0.05,0.01,0.01
67.12461887729187,0.005682858040630025,204.60168005792414,200.0,8.333333333333333e-05,0.61,0.15,0.17,0.02,0.88,0.05,0.01,0.01
67.58861499227037,0.0057215243835449,204.62498226744776,200.0,8.333333333333333e-05,0.61,0.15,0.17,0.02,0.88,0.05,0.01,0.01
68.06245663500385,0.005761011187106025,204.63138721604653,200.0,8.333333333333333e-05,0.61,0.15,0.17,0.02,0.88,0.05,0.01,0.01
68.53629827773736,0.005800497990667151,204.6377921646446,200.0,8.333333333333333e-05,0.61,0.15,0.17,0.02,0.88,0.05,0.01,0.01
69.01013992047086,0.0058399847942282755,204.6441971132439,200.0,8.333333333333333e-05,0.61,0.15,0.17,0.02,0.88,0.05,0.01,0.01
69.48398156320437,0.0058794715977894,204.65060206184398,200.0,8.333333333333333e-05,0.61,0.15,0.17,0.02,0.88,0.05,0.01,0.01
69.96698169596156,0.005919721608852501,204.65206799284422,200.0,8.333333333333333e-05,0.61,0.15,0.17,0.02,0.88,0.05,0.01,0.01
70.44998182871876,0.0059599716199156,204.6535339238449,200.0,8.333333333333333e-05,0.61,0.15,0.17,0.02,0.88,0.05,0.01,0.01
70.93298196147596,0.0060002216309787,204.65499985484448,200.0,8.333333333333333e-05,0.61,0.15,0.17,0.02,0.88,0.05,0.01,0.01
71.41598209423316,0.0060404716420418,204.65646578584534,200.0,8.333333333333333e-05,0.61,0.15,0.17,0.02,0.88,0.05,0.01,0.01
71.89625187673916,0.0060804941239173006,204.6567206465461,200.0,8.333333333333333e-05,0.61,0.15,0.17,0.02,0.88,0.05,0.01,0.01
72.37652165924516,0.006120516605792801,204.65697550724462,200.0,8.333333333333333e-05,0.61,0.15,0.17,0.02,0.88,0.05,0.01,0.01
72.85679144175117,0.006160539087668301,204.65723036794554,200.0,8.333333333333333e-05,0.61,0.15,0.17,0.02,0.88,0.05,0.01,0.01
73.33706122425717,0.0062005615695438,204.657485228647,200.0,8.333333333333333e-05,0.61,0.15,0.17,0.02,0.88,0.05,0.01,0.01