File: datasets/al_6061_comp/csv/T_250_I_1.csv
Time,Strain(%),Stress(MPa),Temp(C),SR(%/s),Si(%),Fe(%),Cu(%),Mn(%),Mg(%),Cr(%),Zn(%),Ti(%)
0.0,0.0001125260207799,21.182935084135202,250.0,8.333333333333333e-05,0.68,0.23,0.2,0.04,0.87,0.05,0.02,0.02
0.13411353841679996,0.0001237021489813,21.71243071216383,250.0,8.333333333333333e-05,0.68,0.23,0.2,0.04,0.87,0.05,0.02,0.02
0.2682270768335999,0.0001348782771827,22.241926340192453,250.0,8.333333333333333e-05,0.68,0.23,0.2,0.04,0.87,0.05,0.02,0.02
0.4023406152503999,0.0001460544053841,22.77142196822108,250.0,8.333333333333333e-05,0.68,0.23,0.2,0.04,0.87,0.05,0.02,0.02
0.5364541536671998,0.0001572305335855,23.300917596249697,250.0,8.333333333333333e-05,0.68,0.23,0.2,0.04,0.87,0.05,0.02,0.02
0.6600231099077999,0.00016752794660555,23.85190062132917,250.0,8.333333333333333e-05,0.68,0.23,0.2,0.04,0.87,0.05,0.02,0.02
0.7835920661483999,0.0001778253596256,24.40288364640862,250.0,8.333333333333333e-05,0.68,0.23,0.2,0.04,0.87,0.05,0.02,0.02
0.907161022389,0.00018812277264565,24.953866671488104,250.0,8.333333333333333e-05,0.68,0.23,0.2,0.04,0.87,0.05,0.02,0.02
1.0307299786296,0.0001984201856657,25.504849696567586,250.0,8.333333333333333e-05,0.68,0.23,0.2,0.04,0.87,0.05,0.02,0.02
1.1596531405017,0.000209163782488375,26.063872555515037,250.0,8.333333333333333e-05,0.68,0.23,0.2,0.04,0.87,0.05,0.02,0.02
1.2885763023738002,0.00021990737931105,26.622895414462498,250.0,8.333333333333333e-05,0.68,0.23,0.2,0.04,0.87,0.05,0.02,0.02
1.4174994642459002,0.000230650976133725,27.181918273409945,250.0,8.333333333333333e-05,0.68,0.23,0.2,0.04,0.87,0.05,0.02,0.02
1.546422626118,0.0002413945729564,27.740941132357406,250.0,8.333333333333333e-05,0.68,0.23,0.2,0.04,0.87,0.05,0.02,0.02
1.6218839660925002,0.000247683017954275,28.301431169762957,250.0,8.333333333333333e-05,0.68,0.23,0.2,0.04,0.87,0.05,0.02,0.02
1.697345306067,0.00025397146295215,28.86192120716857,250.0,8.333333333333333e-05,0.68,0.23,0.2,0.04,0.87,0.05,0.02,0.02
1.7728066460415,0.000260259907950025,29.42241124457412,250.0,8.333333333333333e-05,0.68,0.23,0.2,0.04,0.87,0.05,0.02,0.02
1.848267986016,0.0002665483529479,29.982901281979604,250.0,8.333333333333333e-05,0.68,0.23,0.2,0.04,0.87,0.05,0.02,0.02
2.0669655220152,0.0002847731476145,30.543234081051654,250.0,8.333333333333333e-05,0.68,0.23,0.2,0.04,0.87,0.05,0.02,0.02
2.2856630580144,0.0003029979422811,31.103566880123687,250.0,8.333333333333333e-05,0.68,0.23,0.2,0.04,0.87,0.05,0.02,0.02
2.5043605940136002,0.0003212227369477,31.663899679195723,250.0,8.333333333333333e-05,0.68,0.23,0.2,0.04,0.87,0.05,0.02,0.02
2.7230581300128,0.0003394475316143,32.224232478267766,250.0,8.333333333333333e-05,0.68,0.23,0.2,0.04,0.87,0.05,0.02,0.02
2.8932840330222,0.00035363302353175,32.77039199486117,250.0,8.333333333333333e-05,0.68,0.23,0.2,0.04,0.87,0.05,0.02,0.02
3.0635099360316,0.0003678185154492,33.316551511454534,250.0,8.333333333333333e-05,0.68,0.23,0.2,0.04,0.87,0.05,0.02,0.02
3.233735839041,0.00038200400736664996,33.86271102804794,250.0,8.333333333333333e-05,0.68,0.23,0.2,0.04,0.87,0.05,0.02,0.02
3.4039617420504,0.0003961894992841,34.408870544641424,250.0,8.333333333333333e-05,0.68,0.23,0.2,0.04,0.87,0.05,0.02,0.02
3.5346400029432,0.0004070793543585,34.9679114780393,250.0,8.333333333333333e-05,0.68,0.23,0.2,0.04,0.87,0.05,0.02,0.02
3.6653182638360002,0.0004179692094329,35.526952411437144,250.0,8.333333333333333e-05,0.68,0.23,0.2,0.04,0.87,0.05,0.02,0.02
3.7959965247288,0.00042885906450729997,36.085993344835046,250.0,8.333333333333333e-05,0.68,0.23,0.2,0.04,0.87,0.05,0.02,0.02
3.9266747856216,0.0004397489195817,36.64503427823293,250.0,8.333333333333333e-05,0.68,0.23,0.2,0.04,0.87,0.05,0.02,0.02
4.0576416331386,0.00045066282354145,37.185375472029826,250.0,8.333333333333333e-05,0.68,0.23,0.2,0.04,0.87,0.05,0.02,0.02
4.1886084806556,0.0004615767275012,37.72571666582682,250.0,8.333333333333333e-05,0.68,0.23,0.2,0.04,0.87,0.05,0.02,0.02
4.319575328172601,0.00047249063146095004,38.266057859623686,250.0,8.333333333333333e-05,0.68,0.23,0.2,0.04,0.87,0.05,0.02,0.02
4.4505421756896,0.0004834045354207,38.80639905342034,250.0,8.333333333333333e-05,0.68,0.23,0.2,0.04,0.87,0.05,0.02,0.02
4.5746908121013,0.000493750255121675,39.340871705447945,250.0,8.333333333333333e-05,0.68,0.23,0.2,0.04,0.87,0.05,0.02,0.02
4.6988394485130005,0.00050409597482265,39.875344357475804,250.0,8.333333333333333e-05,0.68,0.23,0.2,0.04,0.87,0.05,0.02,0.02
4.822988084924701,0.0005144416945236251,40.40981700950342,250.0,8.333333333333333e-05,0.68,0.23,0.2,0.04,0.87,0.05,0.02,0.02
4.947136721336401,0.0005247874142246,40.94428966153092,250.0,8.333333333333333e-05,0.68,0.23,0.2,0.04,0.87,0.05,0.02,0.02
5.119439091846901,0.000539145945100475,41.48321111545869,250.0,8.333333333333333e-05,0.68,0.23,0.2,0.04,0.87,0.05,0.02,0.02
5.2917414623574,0.0005535044759763499,42.02213256938653,250.0,8.333333333333333e-05,0.68,0.23,0.2,0.04,0.87,0.05,0.02,0.02
5.4640438328679,0.000567863006852225,42.5610540233143,250.0,8.333333333333333e-05,0.68,0.23,0.2,0.04,0.87,0.05,0.02,0.02
5.6363462033784,0.0005822215377281,43.09997547724198,250.0,8.333333333333333e-05,0.68,0.23,0.2,0.04,0.87,0.05,0.02,0.02
5.8053992899550995,0.0005963092949428249,43.625773687447364,250.0,8.333333333333333e-05,0.68,0.23,0.2,0.04,0.87,0.05,0.02,0.02
5.9744523765318,0.0006103970521575499,44.151571897652744,250.0,8.333333333333333e-05,0.68,0.23,0.2,0.04,0.87,0.05,0.02,0.02
6.1435054631085,0.000624484809372275,44.677370107858096,250.0,8.333333333333333e-05,0.68,0.23,0.2,0.04,0.87,0.05,0.02,0.02
6.3125585496852,0.000638572566587,45.203168318063234,250.0,8.333333333333333e-05,0.68,0.23,0.2,0.04,0.87,0.05,0.02,0.02
6.3491685994593,0.000641623404068175,45.73282750383511,250.0,8.333333333333333e-05,0.68,0.23,0.2,0.04,0.87,0.05,0.02,0.02
6.3857786492334,0.00064467424154935,46.26248668960733,250.0,8.333333333333333e-05,0.68,0.23,0.2,0.04,0.87,0.05,0.02,0.02
6.4223886990075005,0.000647725079030525,46.792145875379305,250.0,8.333333333333333e-05,0.68,0.23,0.2,0.04,0.87,0.05,0.02,0.02
6.4589987487816005,0.0006507759165117,47.32180506115127,250.0,8.333333333333333e-05,0.68,0.23,0.2,0.04,0.87,0.05,0.02,0.02
6.585349666553101,0.000661305159659325,47.84620762032664,250.0,8.333333333333333e-05,0.68,0.23,0.2,0.04,0.87,0.05,0.02,0.02
6.711700584324601,0.00067183440280695,48.37061017950201,250.0,8.333333333333333e-05,0.68,0.23,0.2,0.04,0.87,0.05,0.02,0.02
6.838051502096101,0.000682363645954575,48.89501273867734,250.0,8.333333333333333e-05,0.68,0.23,0.2,0.04,0.87,0.05,0.02,0.02
6.964402419867601,0.0006928928891022,49.41941529785272,250.0,8.333333333333333e-05,0.68,0.23,0.2,0.04,0.87,0.05,0.02,0.02
7.096575605665801,0.0007039073212520501,49.91622307111074,250.0,8.333333333333333e-05,0.68,0.23,0.2,0.04,0.87,0.05,0.02,0.02
7.2287487914640005,0.0007149217534019,50.413030844368514,250.0,8.333333333333333e-05,0.68,0.23,0.2,0.04,0.87,0.05,0.02,0.02
7.3609219772622,0.00072593618555175,50.90983861762654,250.0,8.333333333333333e-05,0.68,0.23,0.2,0.04,0.87,0.05,0.02,0.02
7.4930951630604,0.0007369506177016,51.4066463908849,250.0,8.333333333333333e-05,0.68,0.23,0.2,0.04,0.87,0.05,0.02,0.02
7.6366448521359,0.000748913091791225,51.9151729894364,250.0,8.333333333333333e-05,0.68,0.23,0.2,0.04,0.87,0.05,0.02,0.02
7.780194541211401,0.00076087556588085,52.4236995879877,250.0,8.333333333333333e-05,0.68,0.23,0.2,0.04,0.87,0.05,0.02,0.02
7.923744230286902,0.000772838039970475,52.93222618653918,250.0,8.333333333333333e-05,0.68,0.23,0.2,0.04,0.87,0.05,0.02,0.02
8.067293919362402,0.0007848005140601,53.44075278509041,250.0,8.333333333333333e-05,0.68,0.23,0.2,0.04,0.87,0.05,0.02,0.02
8.258344337640303,0.000800721382249925,53.946514485452404,250.0,8.333333333333333e-05,0.68,0.23,0.2,0.04,0.87,0.05,0.02,0.02
8.4493947559182,0.00081664225043975,54.452276185814625,250.0,8.333333333333333e-05,0.68,0.23,0.2,0.04,0.87,0.05,0.02,0.02
8.640445174196099,0.000832563118629575,54.95803788617664,250.0,8.333333333333333e-05,0.68,0.23,0.2,0.04,0.87,0.05,0.02,0.02
8.831495592473999,0.0008484839868194,55.463799586538705,250.0,8.333333333333333e-05,0.68,0.23,0.2,0.04,0.87,0.05,0.02,0.02
8.7428393280951,0.000841095964787825,55.962847258160735,250.0,8.333333333333333e-05,0.68,0.23,0.2,0.04,0.87,0.05,0.02,0.02
8.6541830637162,0.00083370794275625,56.461894929782595,250.0,8.333333333333333e-05,0.68,0.23,0.2,0.04,0.87,0.05,0.02,0.02
8.5655267993373,0.0008263199207246749,56.960942601404575,250.0,8.333333333333333e-05,0.68,0.23,0.2,0.04,0.87,0.05,0.02,0.02
8.476870534958401,0.0008189318986931,57.459990273026484,250.0,8.333333333333333e-05,0.68,0.23,0.2,0.04,0.87,0.05,0.02,0.02
8.5909586611881,0.000828439242545575,57.95816786829133,250.0,8.333333333333333e-05,0.68,0.23,0.2,0.04,0.87,0.05,0.02,0.02
8.705046787417801,0.00083794658639805,58.456345463556346,250.0,8.333333333333333e-05,0.68,0.23,0.2,0.04,0.87,0.05,0.02,0.02
8.819134913647503,0.000847453930250525,58.95452305882123,250.0,8.333333333333333e-05,0.68,0.23,0.2,0.04,0.87,0.05,0.02,0.02
8.933223039877202,0.000856961274103,59.452700654086115,250.0,8.333333333333333e-05,0.68,0.23,0.2,0.04,0.87,0.05,0.02,0.02
9.095924919039001,0.00087051976403315,59.94534496478292,250.0,8.333333333333333e-05,0.68,0.23,0.2,0.04,0.87,0.05,0.02,0.02
9.258626798200801,0.0008840782539633,60.437989275479616,250.0,8.333333333333333e-05,0.68,0.23,0.2,0.04,0.87,0.05,0.02,0.02
9.4213286773626,0.0008976367438934499,60.930633586176434,250.0,8.333333333333333e-05,0.68,0.23,0.2,0.04,0.87,0.05,0.02,0.02
9.5840305565244,0.0009111952338236,61.42327789687316,250.0,8.333333333333333e-05,0.68,0.23,0.2,0.04,0.87,0.05,0.02,0.02
9.710455986326402,0.0009217306863071001,61.90298672383523,250.0,8.333333333333333e-05,0.68,0.23,0.2,0.04,0.87,0.05,0.02,0.02
9.836881416128401,0.0009322661387906001,62.38269555079745,250.0,8.333333333333333e-05,0.68,0.23,0.2,0.04,0.87,0.05,0.02,0.02
9.9633068459304,0.0009428015912741,62.86240437775953,250.0,8.333333333333333e-05,0.68,0.23,0.2,0.04,0.87,0.05,0.02,0.02
10.089732275732402,0.0009533370437576,63.34211320472151,250.0,8.333333333333333e-05,0.68,0.23,0.2,0.04,0.87,0.05,0.02,0.02
10.262549344848,0.0009677384661839001,63.82678955310476,250.0,8.333333333333333e-05,0.68,0.23,0.2,0.04,0.87,0.05,0.02,0.02
10.435366413963601,0.0009821398886102,64.31146590148778,250.0,8.333333333333333e-05,0.68,0.23,0.2,0.04,0.87,0.05,0.02,0.02
10.608183483079202,0.0009965413110365,64.79614224987107,250.0,8.333333333333333e-05,0.68,0.23,0.2,0.04,0.87,0.05,0.02,0.02
10.7810005521948,0.0010109427334628,65.28081859825443,250.0,8.333333333333333e-05,0.68,0.23,0.2,0.04,0.87,0.05,0.02,0.02
10.9199325659382,0.00102252040127475,65.77545124318796,250.0,8.333333333333333e-05,0.68,0.23,0.2,0.04,0.87,0.05,0.02,0.02
11.0588645796816,0.0010340980690867001,66.27008388812186,250.0,8.333333333333333e-05,0.68,0.23,0.2,0.04,0.87,0.05,0.02,0.02
11.197796593425,0.00104567573689865,66.7647165330552,250.0,8.333333333333333e-05,0.68,0.23,0.2,0.04,0.87,0.05,0.02,0.02
11.3367286071684,0.0010572534047106,67.25934917798813,250.0,8.333333333333333e-05,0.68,0.23,0.2,0.04,0.87,0.05,0.02,0.02
11.4385947957864,0.0010657422537621,67.73169749981002,250.0,8.333333333333333e-05,0.68,0.23,0.2,0.04,0.87,0.05,0.02,0.02
11.540460984404401,0.0010742311028136,68.20404582163235,250.0,8.333333333333333e-05,0.68,0.23,0.2,0.04,0.87,0.05,0.02,0.02
11.642327173022402,0.0010827199518651,68.67639414345429,250.0,8.333333333333333e-05,0.68,0.23,0.2,0.04,0.87,0.05,0.02,0.02
11.7441933616404,0.0010912088009166,69.14874246527606,250.0,8.333333333333333e-05,0.68,0.23,0.2,0.04,0.87,0.05,0.02,0.02
12.0927685326069,0.001120256731830475,69.60248305043842,250.0,8.333333333333333e-05,0.68,0.23,0.2,0.04,0.87,0.05,0.02,0.02
12.441343703573398,0.00114930466274435,70.05622363560103,250.0,8.333333333333333e-05,0.68,0.23,0.2,0.04,0.87,0.05,0.02,0.02
12.789918874539898,0.001178352593658225,70.50996422076335,250.0,8.333333333333333e-05,0.68,0.23,0.2,0.04,0.87,0.05,0.02,0.02
13.138494045506398,0.0012074005245721,70.96370480592488,250.0,8.333333333333333e-05,0.68,0.23,0.2,0.04,0.87,0.05,0.02,0.02
13.211969590754398,0.0012135234866760998,71.41141332676939,250.0,8.333333333333333e-05,0.68,0.23,0.2,0.04,0.87,0.05,0.02,0.02
13.285445136002398,0.0012196464487801,71.8591218476152,250.0,8.333333333333333e-05,0.68,0.23,0.2,0.04,0.87,0.05,0.02,0.02
13.3589206812504,0.0012257694108841,72.30683036845979,250.0,8.333333333333333e-05,0.68,0.23,0.2,0.04,0.87,0.05,0.02,0.02
13.4323962264984,0.0012318923729881,72.75453888930349,250.0,8.333333333333333e-05,0.68,0.23,0.2,0.04,0.87,0.05,0.02,0.02
13.583440359453,0.00124447938406765,73.20642021886601,250.0,8.333333333333333e-05,0.68,0.23,0.2,0.04,0.87,0.05,0.02,0.02
13.7344844924076,0.0012570663951472,73.65830154842916,250.0,8.333333333333333e-05,0.68,0.23,0.2,0.04,0.87,0.05,0.02,0.02
13.885528625362198,0.00126965340622675,74.11018287799165,250.0,8.333333333333333e-05,0.68,0.23,0.2,0.04,0.87,0.05,0.02,0.02
14.0365727583168,0.0012822404173063,74.5620642075539,250.0,8.333333333333333e-05,0.68,0.23,0.2,0.04,0.87,0.05,0.02,0.02
14.2205190594564,0.0012975692757346,75.0092166985504,250.0,8.333333333333333e-05,0.68,0.23,0.2,0.04,0.87,0.05,0.02,0.02
14.404465360596,0.0013128981341629,75.4563691895469,250.0,8.333333333333333e-05,0.68,0.23,0.2,0.04,0.87,0.05,0.02,0.02
14.588411661735599,0.0013282269925912,75.90352168054343,250.0,8.333333333333333e-05,0.68,0.23,0.2,0.04,0.87,0.05,0.02,0.02
14.7723579628752,0.0013435558510195,76.35067417153995,250.0,8.333333333333333e-05,0.68,0.23,0.2,0.04,0.87,0.05,0.02,0.02
14.901427382513099,0.001354311635989325,76.79379852372188,250.0,8.333333333333333e-05,0.68,0.23,0.2,0.04,0.87,0.05,0.02,0.02
15.030496802150997,0.00136506742095915,77.2369228759033,250.0,8.333333333333333e-05,0.68,0.23,0.2,0.04,0.87,0.05,0.02,0.02
15.159566221788896,0.001375823205928975,77.68004722808527,250.0,8.333333333333333e-05,0.68,0.23,0.2,0.04,0.87,0.05,0.02,0.02
15.288635641426795,0.0013865789908988,78.12317158026762,250.0,8.333333333333333e-05,0.68,0.23,0.2,0.04,0.87,0.05,0.02,0.02
15.441643135875896,0.001399329615436225,78.55426430419419,250.0,8.333333333333333e-05,0.68,0.23,0.2,0.04,0.87,0.05,0.02,0.02
15.594650630324999,0.00141208023997365,78.98535702812087,250.0,8.333333333333333e-05,0.68,0.23,0.2,0.04,0.87,0.05,0.02,0.02
15.7476581247741,0.001424830864511075,79.41644975204731,250.0,8.333333333333333e-05,0.68,0.23,0.2,0.04,0.87,0.05,0.02,0.02
15.9006656192232,0.0014375814890485,79.84754247597368,250.0,8.333333333333333e-05,0.68,0.23,0.2,0.04,0.87,0.05,0.02,0.02
16.0827977697378,0.00145275916825805,80.29072768375873,250.0,8.333333333333333e-05,0.68,0.23,0.2,0.04,0.87,0.05,0.02,0.02
16.2649299202524,0.0014679368474676,80.73391289154371,250.0,8.333333333333333e-05,0.68,0.23,0.2,0.04,0.87,0.05,0.02,0.02
16.447062070767,0.00148311452667715,81.17709809932899,250.0,8.333333333333333e-05,0.68,0.23,0.2,0.04,0.87,0.05,0.02,0.02
16.6291942212816,0.0014982922058867,81.62028330711422,250.0,8.333333333333333e-05,0.68,0.23,0.2,0.04,0.87,0.05,0.02,0.02
16.808065770814203,0.0015131981683477501,82.0675058825548,250.0,8.333333333333333e-05,0.68,0.23,0.2,0.04,0.87,0.05,0.02,0.02
16.9869373203468,0.0015281041308088002,82.51472845799516,250.0,8.333333333333333e-05,0.68,0.23,0.2,0.04,0.87,0.05,0.02,0.02
17.1658088698794,0.0015430100932698502,82.96195103343544,250.0,8.333333333333333e-05,0.68,0.23,0.2,0.04,0.87,0.05,0.02,0.02
17.344680419412,0.0015579160557309,83.40917360887568,250.0,8.333333333333333e-05,0.68,0.23,0.2,0.04,0.87,0.05,0.02,0.02
17.5658186562759,0.001576344242136225,83.85985382824768,250.0,8.333333333333333e-05,0.68,0.23,0.2,0.04,0.87,0.05,0.02,0.02
17.786956893139802,0.00159477242854155,84.31053404762025,250.0,8.333333333333333e-05,0.68,0.23,0.2,0.04,0.87,0.05,0.02,0.02
18.008095130003703,0.001613200614946875,84.76121426699243,250.0,8.333333333333333e-05,0.68,0.23,0.2,0.04,0.87,0.05,0.02,0.02
18.2292333668676,0.0016316288013522,85.2118944863644,250.0,8.333333333333333e-05,0.68,0.23,0.2,0.04,0.87,0.05,0.02,0.02
18.3728550742494,0.0016435972769673502,85.64736639309962,250.0,8.333333333333333e-05,0.68,0.23,0.2,0.04,0.87,0.05,0.02,0.02
18.516476781631198,0.0016555657525825001,86.08283829983482,250.0,8.333333333333333e-05,0.68,0.23,0.2,0.04,0.87,0.05,0.02,0.02
18.660098489013,0.00166753422819765,86.51831020656978,250.0,8.333333333333333e-05,0.68,0.23,0.2,0.04,0.87,0.05,0.02,0.02
18.8037201963948,0.0016795027038128,86.95378211330387,250.0,8.333333333333333e-05,0.68,0.23,0.2,0.04,0.87,0.05,0.02,0.02
18.9175683706665,0.001688990051668775,87.38546286300092,250.0,8.333333333333333e-05,0.68,0.23,0.2,0.04,0.87,0.05,0.02,0.02
19.0314165449382,0.00169847739952475,87.81714361269913,250.0,8.333333333333333e-05,0.68,0.23,0.2,0.04,0.87,0.05,0.02,0.02
19.145264719209898,0.001707964747380725,88.2488243623963,250.0,8.333333333333333e-05,0.68,0.23,0.2,0.04,0.87,0.05,0.02,0.02
19.2591128934816,0.0017174520952367,88.680505112093,250.0,8.333333333333333e-05,0.68,0.23,0.2,0.04,0.87,0.05,0.02,0.02
19.4056725760161,0.001729665402114575,89.1167243007635,250.0,8.333333333333333e-05,0.68,0.23,0.2,0.04,0.87,0.05,0.02,0.02
19.5522322585506,0.00174187870899245,89.55294348943409,250.0,8.333333333333333e-05,0.68,0.23,0.2,0.04,0.87,0.05,0.02,0.02
19.698791941085098,0.001754092015870325,89.98916267810486,250.0,8.333333333333333e-05,0.68,0.23,0.2,0.04,0.87,0.05,0.02,0.02
19.8453516236196,0.0017663053227482,90.42538186677497,250.0,8.333333333333333e-05,0.68,0.23,0.2,0.04,0.87,0.05,0.02,0.02
19.9930727684256,0.0017786154181487,90.84522953343455,250.0,8.333333333333333e-05,0.68,0.23,0.2,0.04,0.87,0.05,0.02,0.02
20.140793913231597,0.0017909255135492,91.26507720009423,250.0,8.333333333333333e-05,0.68,0.23,0.2,0.04,0.87,0.05,0.02,0.02
20.288515058037596,0.0018032356089497,91.68492486675396,250.0,8.333333333333333e-05,0.68,0.23,0.2,0.04,0.87,0.05,0.02,0.02
20.4362362028436,0.0018155457043502,92.10477253341332,250.0,8.333333333333333e-05,0.68,0.23,0.2,0.04,0.87,0.05,0.02,0.02
20.5562529020535,0.0018255470959510248,92.5137495326393,250.0,8.333333333333333e-05,0.68,0.23,0.2,0.04,0.87,0.05,0.02,0.02
20.6762696012634,0.0018355484875518498,92.92272653186609,250.0,8.333333333333333e-05,0.68,0.23,0.2,0.04,0.87,0.05,0.02,0.02
20.796286300473298,0.0018455498791526749,93.33170353109202,250.0,8.333333333333333e-05,0.68,0.23,0.2,0.04,0.87,0.05,0.02,0.02
20.9163029996832,0.0018555512707535,93.74068053031903,250.0,8.333333333333333e-05,0.68,0.23,0.2,0.04,0.87,0.05,0.02,0.02
21.0282176011026,0.00186487748753845,94.15885568854023,250.0,8.333333333333333e-05,0.68,0.23,0.2,0.04,0.87,0.05,0.02,0.02
21.140132202522,0.0018742037043234,94.57703084676055,250.0,8.333333333333333e-05,0.68,0.23,0.2,0.04,0.87,0.05,0.02,0.02
21.2520468039414,0.0018835299211083499,94.99520600498148,250.0,8.333333333333333e-05,0.68,0.23,0.2,0.04,0.87,0.05,0.02,0.02
21.3639614053608,0.0018928561378933,95.41338116320188,250.0,8.333333333333333e-05,0.68,0.23,0.2,0.04,0.87,0.05,0.02,0.02
21.533100934542603,0.00190695109865845,95.82202057846371,250.0,8.333333333333333e-05,0.68,0.23,0.2,0.04,0.87,0.05,0.02,0.02
21.7022404637244,0.0019210460594236,96.23065999372646,250.0,8.333333333333333e-05,0.68,0.23,0.2,0.04,0.87,0.05,0.02,0.02
21.8713799929062,0.00193514102018875,96.63929940898831,250.0,8.333333333333333e-05,0.68,0.23,0.2,0.04,0.87,0.05,0.02,0.02
22.040519522088,0.0019492359809539,97.047938824249,250.0,8.333333333333333e-05,0.68,0.23,0.2,0.04,0.87,0.05,0.02,0.02
22.1871728900271,0.001961457094948825,97.44488757391393,250.0,8.333333333333333e-05,0.68,0.23,0.2,0.04,0.87,0.05,0.02,0.02
22.3338262579662,0.00197367820894375,97.84183632357912,250.0,8.333333333333333e-05,0.68,0.23,0.2,0.04,0.87,0.05,0.02,0.02
22.4804796259053,0.001985899322938675,98.23878507324406,250.0,8.333333333333333e-05,0.68,0.23,0.2,0.04,0.87,0.05,0.02,0.02
22.6271329938444,0.0019981204369336,98.63573382290942,250.0,8.333333333333333e-05,0.68,0.23,0.2,0.04,0.87,0.05,0.02,0.02
22.8053239032561,0.002012969679384575,99.04387325397957,250.0,8.333333333333333e-05,0.68,0.23,0.2,0.04,0.87,0.05,0.02,0.02
22.9835148126678,0.00202781892183555,99.452012685049,250.0,8.333333333333333e-05,0.68,0.23,0.2,0.04,0.87,0.05,0.02,0.02
23.1617057220795,0.002042668164286525,99.8601521161192,250.0,8.333333333333333e-05,0.68,0.23,0.2,0.04,0.87,0.05,0.02,0.02
23.3398966314912,0.0020575174067375,100.2682915471909,250.0,8.333333333333333e-05,0.68,0.23,0.2,0.04,0.87,0.05,0.02,0.02
23.4954190106211,0.002070477604998325,100.66645237998189,250.0,8.333333333333333e-05,0.68,0.23,0.2,0.04,0.87,0.05,0.02,0.02
23.650941389751,0.0020834378032591498,101.0646132127714,250.0,8.333333333333333e-05,0.68,0.23,0.2,0.04,0.87,0.05,0.02,0.02
23.806463768880903,0.002096398001519975,101.46277404556253,250.0,8.333333333333333e-05,0.68,0.23,0.2,0.04,0.87,0.05,0.02,0.02
23.9619861480108,0.0021093581997808,101.86093487835404,250.0,8.333333333333333e-05,0.68,0.23,0.2,0.04,0.87,0.05,0.02,0.02
24.117145556829602,0.0021222881505157,102.28752147207155,250.0,8.333333333333333e-05,0.68,0.23,0.2,0.04,0.87,0.05,0.02,0.02
24.272304965648402,0.0021352181012506003,102.71410806578969,250.0,8.333333333333333e-05,0.68,0.23,0.2,0.04,0.87,0.05,0.02,0.02
24.427464374467203,0.0021481480519855,103.14069465950718,250.0,8.333333333333333e-05,0.68,0.23,0.2,0.04,0.87,0.05,0.02,0.02
24.582623783286003,0.0021610780027204,103.56728125322383,250.0,8.333333333333333e-05,0.68,0.23,0.2,0.04,0.87,0.05,0.02,0.02
24.7473698576037,0.002174806842246875,103.97483781650708,250.0,8.333333333333333e-05,0.68,0.23,0.2,0.04,0.87,0.05,0.02,0.02
24.912115931921402,0.00218853568177335,104.38239437979128,250.0,8.333333333333333e-05,0.68,0.23,0.2,0.04,0.87,0.05,0.02,0.02
25.076862006239104,0.002202264521299825,104.78995094307442,250.0,8.333333333333333e-05,0.68,0.23,0.2,0.04,0.87,0.05,0.02,0.02
25.2416080805568,0.0022159933608263,105.1975075063568,250.0,8.333333333333333e-05,0.68,0.23,0.2,0.04,0.87,0.05,0.02,0.02
25.3788510375429,0.0022274302739084748,105.5878332956073,250.0,8.333333333333333e-05,0.68,0.23,0.2,0.04,0.87,0.05,0.02,0.02
25.516093994529,0.00223886718699065,105.97815908485774,250.0,8.333333333333333e-05,0.68,0.23,0.2,0.04,0.87,0.05,0.02,0.02
25.6533369515151,0.002250304100072825,106.3684848741083,250.0,8.333333333333333e-05,0.68,0.23,0.2,0.04,0.87,0.05,0.02,0.02
25.7905799085012,0.002261741013155,106.75881066335809,250.0,8.333333333333333e-05,0.68,0.23,0.2,0.04,0.87,0.05,0.02,0.02
25.9124884928343,0.002271900061849425,107.1557305924476,250.0,8.333333333333333e-05,0.68,0.23,0.2,0.04,0.87,0.05,0.02,0.02
26.0343970771674,0.00228205911054385,107.55265052153825,250.0,8.333333333333333e-05,0.68,0.23,0.2,0.04,0.87,0.05,0.02,0.02
26.156305661500504,0.002292218159238275,107.94957045062779,250.0,8.333333333333333e-05,0.68,0.23,0.2,0.04,0.87,0.05,0.02,0.02
26.278214245833603,0.0023023772079327,108.34649037971671,250.0,8.333333333333333e-05,0.68,0.23,0.2,0.04,0.87,0.05,0.02,0.02
26.435641915299602,0.0023154961803882003,108.75185366592522,250.0,8.333333333333333e-05,0.68,0.23,0.2,0.04,0.87,0.05,0.02,0.02
26.5930695847656,0.0023286151528437,109.1572169521327,250.0,8.333333333333333e-05,0.68,0.23,0.2,0.04,0.87,0.05,0.02,0.02
26.7504972542316,0.0023417341252991997,109.56258023834096,250.0,8.333333333333333e-05,0.68,0.23,0.2,0.04,0.87,0.05,0.02,0.02
26.9079249236976,0.0023548530977547,109.96794352455012,250.0,8.333333333333333e-05,0.68,0.23,0.2,0.04,0.87,0.05,0.02,0.02
27.0496807812324,0.0023666660858826,110.35546357407938,250.0,8.333333333333333e-05,0.68,0.23,0.2,0.04,0.87,0.05,0.02,0.02
27.1914366387672,0.0023784790740105,110.74298362361033,250.0,8.333333333333333e-05,0.68,0.23,0.2,0.04,0.87,0.05,0.02,0.02
27.333192496302,0.0023902920621384,111.13050367313899,250.0,8.333333333333333e-05,0.68,0.23,0.2,0.04,0.87,0.05,0.02,0.02
27.4749483538368,0.0024021050502663,111.51802372266566,250.0,8.333333333333333e-05,0.68,0.23,0.2,0.04,0.87,0.05,0.02,0.02
27.5891753966583,0.0024116239705014248,111.89327845873639,250.0,8.333333333333333e-05,0.68,0.23,0.2,0.04,0.87,0.05,0.02,0.02
27.703402439479802,0.00242114289073655,112.26853319480954,250.0,8.333333333333333e-05,0.68,0.23,0.2,0.04,0.87,0.05,0.02,0.02
27.8176294823013,0.002430661810971675,112.64378793088103,250.0,8.333333333333333e-05,0.68,0.23,0.2,0.04,0.87,0.05,0.02,0.02
27.9318565251228,0.0024401807312068,113.01904266695229,250.0,8.333333333333333e-05,0.68,0.23,0.2,0.04,0.87,0.05,0.02,0.02
28.0676246627457,0.002451494742675375,113.40253686532478,250.0,8.333333333333333e-05,0.68,0.23,0.2,0.04,0.87,0.05,0.02,0.02
28.2033928003686,0.00246280875414395,113.78603106369607,250.0,8.333333333333333e-05,0.68,0.23,0.2,0.04,0.87,0.05,0.02,0.02
28.3391609379915,0.0024741227656125252,114.16952526206876,250.0,8.333333333333333e-05,0.68,0.23,0.2,0.04,0.87,0.05,0.02,0.02
28.4749290756144,0.0024854367770811,114.55301946044301,250.0,8.333333333333333e-05,0.68,0.23,0.2,0.04,0.87,0.05,0.02,0.02
28.5940412394159,0.0024953627907312254,114.93954737828253,250.0,8.333333333333333e-05,0.68,0.23,0.2,0.04,0.87,0.05,0.02,0.02
28.7131534032174,0.00250528880438135,115.3260752961203,250.0,8.333333333333333e-05,0.68,0.23,0.2,0.04,0.87,0.05,0.02,0.02
28.8322655670189,0.002515214818031475,115.7126032139592,250.0,8.333333333333333e-05,0.68,0.23,0.2,0.04,0.87,0.05,0.02,0.02
28.9513777308204,0.0025251408316816,116.09913113179842,250.0,8.333333333333333e-05,0.68,0.23,0.2,0.04,0.87,0.05,0.02,0.02
29.145240467168698,0.0025412960597106246,116.48044554832066,250.0,8.333333333333333e-05,0.68,0.23,0.2,0.04,0.87,0.05,0.02,0.02
29.339103203517,0.00255745128773965,116.86175996484306,250.0,8.333333333333333e-05,0.68,0.23,0.2,0.04,0.87,0.05,0.02,0.02
29.5329659398653,0.002573606515768675,117.24307438136566,250.0,8.333333333333333e-05,0.68,0.23,0.2,0.04,0.87,0.05,0.02,0.02
29.7268286762136,0.0025897617437977,117.62438879788894,250.0,8.333333333333333e-05,0.68,0.23,0.2,0.04,0.87,0.05,0.02,0.02
29.9125924754979,0.002605242060404725,117.99019590687894,250.0,8.333333333333333e-05,0.68,0.23,0.2,0.04,0.87,0.05,0.02,0.02
30.098356274782198,0.0026207223770117498,118.35600301586744,250.0,8.333333333333333e-05,0.68,0.23,0.2,0.04,0.87,0.05,0.02,0.02
30.2841200740665,0.002636202693618775,118.7218101248576,250.0,8.333333333333333e-05,0.68,0.23,0.2,0.04,0.87,0.05,0.02,0.02
30.4698838733508,0.0026516830102258,119.08761723384876,250.0,8.333333333333333e-05,0.68,0.23,0.2,0.04,0.87,0.05,0.02,0.02
30.615317890556398,0.0026638025116596,119.467412579235,250.0,8.333333333333333e-05,0.68,0.23,0.2,0.04,0.87,0.05,0.02,0.02
30.760751907762,0.0026759220130934,119.84720792462116,250.0,8.333333333333333e-05,0.68,0.23,0.2,0.04,0.87,0.05,0.02,0.02
30.906185924967602,0.0026880415145272,120.227003270007,250.0,8.333333333333333e-05,0.68,0.23,0.2,0.04,0.87,0.05,0.02,0.02
31.0516199421732,0.002700161015961,120.60679861539364,250.0,8.333333333333333e-05,0.68,0.23,0.2,0.04,0.87,0.05,0.02,0.02
31.2111615478509,0.002713456149767475,120.98384989396138,250.0,8.333333333333333e-05,0.68,0.23,0.2,0.04,0.87,0.05,0.02,0.02
31.370703153528602,0.00272675128357395,121.36090117252803,250.0,8.333333333333333e-05,0.68,0.23,0.2,0.04,0.87,0.05,0.02,0.02
31.5302447592063,0.002740046417380425,121.73795245109588,250.0,8.333333333333333e-05,0.68,0.23,0.2,0.04,0.87,0.05,0.02,0.02
31.689786364884,0.0027533415511869,122.11500372966442,250.0,8.333333333333333e-05,0.68,0.23,0.2,0.04,0.87,0.05,0.02,0.02
31.876253813221503,0.002768880505215025,122.48415619965768,250.0,8.333333333333333e-05,0.68,0.23,0.2,0.04,0.87,0.05,0.02,0.02
32.062721261559005,0.00278441945924315,122.8533086696489,250.0,8.333333333333333e-05,0.68,0.23,0.2,0.04,0.87,0.05,0.02,0.02
32.2491887098965,0.002799958413271275,123.22246113964212,250.0,8.333333333333333e-05,0.68,0.23,0.2,0.04,0.87,0.05,0.02,0.02
32.435656158234,0.0028154973672994,123.59161360963843,250.0,8.333333333333333e-05,0.68,0.23,0.2,0.04,0.87,0.05,0.02,0.02
32.609466713408096,0.002829981580230575,123.90877677264893,250.0,8.333333333333333e-05,0.68,0.23,0.2,0.04,0.87,0.05,0.02,0.02
32.7832772685822,0.00284446579316175,124.22593993565627,250.0,8.333333333333333e-05,0.68,0.23,0.2,0.04,0.87,0.05,0.02,0.02
32.9570878237563,0.0028589500060929246,124.54310309866666,250.0,8.333333333333333e-05,0.68,0.23,0.2,0.04,0.87,0.05,0.02,0.02
33.1308983789304,0.0028734342190241,124.86026626167944,250.0,8.333333333333333e-05,0.68,0.23,0.2,0.04,0.87,0.05,0.02,0.02
33.3198810324252,0.002889182773482,125.18764899348218,250.0,8.333333333333333e-05,0.68,0.23,0.2,0.04,0.87,0.05,0.02,0.02
33.50886368592,0.0029049313279399,125.51503172528396,250.0,8.333333333333333e-05,0.68,0.23,0.2,0.04,0.87,0.05,0.02,0.02
33.697846339414795,0.0029206798823978,125.84241445708678,250.0,8.333333333333333e-05,0.68,0.23,0.2,0.04,0.87,0.05,0.02,0.02
33.8868289929096,0.0029364284368557,126.16979718888945,250.0,8.333333333333333e-05,0.68,0.23,0.2,0.04,0.87,0.05,0.02,0.02
34.0463887166892,0.0029497250805040004,126.50614184091071,250.0,8.333333333333333e-05,0.68,0.23,0.2,0.04,0.87,0.05,0.02,0.02
34.2059484404688,0.0029630217241523003,126.84248649293187,250.0,8.333333333333333e-05,0.68,0.23,0.2,0.04,0.87,0.05,0.02,0.02
34.3655081642484,0.0029763183678006002,127.17883114495311,250.0,8.333333333333333e-05,0.68,0.23,0.2,0.04,0.87,0.05,0.02,0.02
34.525067888028005,0.0029896150114489,127.51517579697409,250.0,8.333333333333333e-05,0.68,0.23,0.2,0.04,0.87,0.05,0.02,0.02
34.6812494290359,0.003002630139866225,127.85829967793283,250.0,8.333333333333333e-05,0.68,0.23,0.2,0.04,0.87,0.05,0.02,0.02
34.8374309700438,0.00301564526828355,128.20142355889266,250.0,8.333333333333333e-05,0.68,0.23,0.2,0.04,0.87,0.05,0.02,0.02
34.993612511051694,0.003028660396700875,128.54454743985175,250.0,8.333333333333333e-05,0.68,0.23,0.2,0.04,0.87,0.05,0.02,0.02
35.1497940520596,0.0030416755251182,128.88767132080986,250.0,8.333333333333333e-05,0.68,0.23,0.2,0.04,0.87,0.05,0.02,0.02
35.3294176212855,0.0030566441558870254,129.19657733812113,250.0,8.333333333333333e-05,0.68,0.23,0.2,0.04,0.87,0.05,0.02,0.02
35.5090411905114,0.0030716127866558503,129.5054833554313,250.0,8.333333333333333e-05,0.68,0.23,0.2,0.04,0.87,0.05,0.02,0.02
35.6886647597373,0.0030865814174246753,129.81438937274245,250.0,8.333333333333333e-05,0.68,0.23,0.2,0.04,0.87,0.05,0.02,0.02
35.8682883289632,0.0031015500481935,130.12329539005458,250.0,8.333333333333333e-05,0.68,0.23,0.2,0.04,0.87,0.05,0.02,0.02
36.0591307439241,0.003117453582773575,130.42980430977357,250.0,8.333333333333333e-05,0.68,0.23,0.2,0.04,0.87,0.05,0.02,0.02
36.249973158885,0.00313335711735365,130.73631322949353,250.0,8.333333333333333e-05,0.68,0.23,0.2,0.04,0.87,0.05,0.02,0.02
36.440815573845896,0.003149260651933725,131.0428221492124,250.0,8.333333333333333e-05,0.68,0.23,0.2,0.04,0.87,0.05,0.02,0.02
36.6316579888068,0.0031651641865138,131.349331068932,250.0,8.333333333333333e-05,0.68,0.23,0.2,0.04,0.87,0.05,0.02,0.02
36.8257150845111,0.003181335611155825,131.66056731384373,250.0,8.333333333333333e-05,0.68,0.23,0.2,0.04,0.87,0.05,0.02,0.02
37.0197721802154,0.00319750703579785,131.97180355875471,250.0,8.333333333333333e-05,0.68,0.23,0.2,0.04,0.87,0.05,0.02,0.02
37.2138292759197,0.003213678460439875,132.28303980366667,250.0,8.333333333333333e-05,0.68,0.23,0.2,0.04,0.87,0.05,0.02,0.02
37.407886371624,0.0032298498850819,132.59427604857726,250.0,8.333333333333333e-05,0.68,0.23,0.2,0.04,0.87,0.05,0.02,0.02
37.5857837297697,0.003244674664927375,132.9011768186275,250.0,8.333333333333333e-05,0.68,0.23,0.2,0.04,0.87,0.05,0.02,0.02
37.7636810879154,0.00325949944477285,133.20807758867778,250.0,8.333333333333333e-05,0.68,0.23,0.2,0.04,0.87,0.05,0.02,0.02
37.9415784460611,0.003274324224618325,133.51497835872811,250.0,8.333333333333333e-05,0.68,0.23,0.2,0.04,0.87,0.05,0.02,0.02
38.1194758042068,0.0032891490044638,133.82187912877905,250.0,8.333333333333333e-05,0.68,0.23,0.2,0.04,0.87,0.05,0.02,0.02
38.3195589002184,0.0033058225957981,134.12166106809656,250.0,8.333333333333333e-05,0.68,0.23,0.2,0.04,0.87,0.05,0.02,0.02
38.51964199623,0.0033224961871324,134.4214430074138,250.0,8.333333333333333e-05,0.68,0.23,0.2,0.04,0.87,0.05,0.02,0.02
38.7197250922416,0.0033391697784667003,134.7212249467311,250.0,8.333333333333333e-05,0.68,0.23,0.2,0.04,0.87,0.05,0.02,0.02
38.9198081882532,0.003355843369801,135.0210068860487,250.0,8.333333333333333e-05,0.68,0.23,0.2,0.04,0.87,0.05,0.02,0.02
39.1290485441847,0.0033732800661286253,135.29963897317447,250.0,8.333333333333333e-05,0.68,0.23,0.2,0.04,0.87,0.05,0.02,0.02
39.3382889001162,0.0033907167624562503,135.57827106029998,250.0,8.333333333333333e-05,0.68,0.23,0.2,0.04,0.87,0.05,0.02,0.02
39.547529256047696,0.003408153458783875,135.85690314742567,250.0,8.333333333333333e-05,0.68,0.23,0.2,0.04,0.87,0.05,0.02,0.02
39.7567696119792,0.0034255901551115,136.13553523455272,250.0,8.333333333333333e-05,0.68,0.23,0.2,0.04,0.87,0.05,0.02,0.02
40.0203869657763,0.003447558267927925,136.4112024470182,250.0,8.333333333333333e-05,0.68,0.23,0.2,0.04,0.87,0.05,0.02,0.02
40.2840043195734,0.00346952638074435,136.68686965948234,250.0,8.333333333333333e-05,0.68,0.23,0.2,0.04,0.87,0.05,0.02,0.02
40.5476216733705,0.003491494493560775,136.96253687194798,250.0,8.333333333333333e-05,0.68,0.23,0.2,0.04,0.87,0.05,0.02,0.02
40.8112390271676,0.0035134626063772,137.23820408441452,250.0,8.333333333333333e-05,0.68,0.23,0.2,0.04,0.87,0.05,0.02,0.02
41.0692418106045,0.003534962838330275,137.49430129321703,250.0,8.333333333333333e-05,0.68,0.23,0.2,0.04,0.87,0.05,0.02,0.02
41.3272445940414,0.00355646307028335,137.75039850201986,250.0,8.333333333333333e-05,0.68,0.23,0.2,0.04,0.87,0.05,0.02,0.02
41.5852473774783,0.003577963302236425,138.0064957108227,250.0,8.333333333333333e-05,0.68,0.23,0.2,0.04,0.87,0.05,0.02,0.02
41.8432501609152,0.0035994635341895,138.26259291962478,250.0,8.333333333333333e-05,0.68,0.23,0.2,0.04,0.87,0.05,0.02,0.02
42.097612958084994,0.0036206604339536503,138.5070784671838,250.0,8.333333333333333e-05,0.68,0.23,0.2,0.04,0.87,0.05,0.02,0.02
42.3519757552548,0.0036418573337178,138.75156401474123,250.0,8.333333333333333e-05,0.68,0.23,0.2,0.04,0.87,0.05,0.02,0.02
42.6063385524246,0.0036630542334819497,138.99604956229962,250.0,8.333333333333333e-05,0.68,0.23,0.2,0.04,0.87,0.05,0.02,0.02
42.8607013495944,0.0036842511332461,139.24053510986073,250.0,8.333333333333333e-05,0.68,0.23,0.2,0.04,0.87,0.05,0.02,0.02
43.1514863461992,0.0037084832162965,139.47179277193624,250.0,8.333333333333333e-05,0.68,0.23,0.2,0.04,0.87,0.05,0.02,0.02
43.442271342804,0.0037327152993469,139.70305043401203,250.0,8.333333333333333e-05,0.68,0.23,0.2,0.04,0.87,0.05,0.02,0.02
43.7330563394088,0.0037569473823972997,139.93430809608748,250.0,8.333333333333333e-05,0.68,0.23,0.2,0.04,0.87,0.05,0.02,0.02
44.0238413360136,0.0037811794654477,140.16556575816188,250.0,8.333333333333333e-05,0.68,0.23,0.2,0.04,0.87,0.05,0.02,0.02
44.3816405194887,0.003810996064070625,140.38451703452637,250.0,8.333333333333333e-05,0.68,0.23,0.2,0.04,0.87,0.05,0.02,0.02
44.7394397029638,0.00384081266269355,140.60346831088947,250.0,8.333333333333333e-05,0.68,0.23,0.2,0.04,0.87,0.05,0.02,0.02
45.0972388864389,0.003870629261316475,140.82241958725422,250.0,8.333333333333333e-05,0.68,0.23,0.2,0.04,0.87,0.05,0.02,0.02
45.455038069914,0.0039004458599394,141.04137086361877,250.0,8.333333333333333e-05,0.68,0.23,0.2,0.04,0.87,0.05,0.02,0.02
45.77577375988051,0.003927173834103275,141.23079820563754,250.0,8.333333333333333e-05,0.68,0.23,0.2,0.04,0.87,0.05,0.02,0.02
46.096509449847005,0.00395390180826715,141.42022554765717,250.0,8.333333333333333e-05,0.68,0.23,0.2,0.04,0.87,0.05,0.02,0.02
46.4172451398135,0.003980629782431026,141.6096528896763,250.0,8.333333333333333e-05,0.68,0.23,0.2,0.04,0.87,0.05,0.02,0.02
46.73798082978,0.0040073577565949,141.79908023169565,250.0,8.333333333333333e-05,0.68,0.23,0.2,0.04,0.87,0.05,0.02,0.02
47.0939973364749,0.0040370257988194755,141.9745114615194,250.0,8.333333333333333e-05,0.68,0.23,0.2,0.04,0.87,0.05,0.02,0.02
47.4500138431698,0.00406669384104405,142.14994269134272,250.0,8.333333333333333e-05,0.68,0.23,0.2,0.04,0.87,0.05,0.02,0.02
47.8060303498647,0.004096361883268625,142.32537392116603,250.0,8.333333333333333e-05,0.68,0.23,0.2,0.04,0.87,0.05,0.02,0.02
48.162046856559606,0.0041260299254932,142.50080515098887,250.0,8.333333333333333e-05,0.68,0.23,0.2,0.04,0.87,0.05,0.02,0.02
48.5326247931696,0.0041569114202107006,142.6437495114281,250.0,8.333333333333333e-05,0.68,0.23,0.2,0.04,0.87,0.05,0.02,0.02
48.90320272977961,0.0041877929149282,142.786693871868,250.0,8.333333333333333e-05,0.68,0.23,0.2,0.04,0.87,0.05,0.02,0.02
49.273780666389605,0.0042186744096457,142.92963823230752,250.0,8.333333333333333e-05,0.68,0.23,0.2,0.04,0.87,0.05,0.02,0.02
49.6443586029996,0.0042495559043632,143.0725825927472,250.0,8.333333333333333e-05,0.68,0.23,0.2,0.04,0.87,0.05,0.02,0.02
50.0270607436524,0.0042814477494176,143.21112663007494,250.0,8.333333333333333e-05,0.68,0.23,0.2,0.04,0.87,0.05,0.02,0.02
50.4097628843052,0.0043133395944720005,143.34967066740316,250.0,8.333333333333333e-05,0.68,0.23,0.2,0.04,0.87,0.05,0.02,0.02
50.792465024958005,0.0043452314395264,143.48821470473106,250.0,8.333333333333333e-05,0.68,0.23,0.2,0.04,0.87,0.05,0.02,0.02
51.1751671656108,0.0043771232845808,143.62675874205945,250.0,8.333333333333333e-05,0.68,0.23,0.2,0.04,0.87,0.05,0.02,0.02
51.5842550846844,0.0044112139445036,143.74400659531847,250.0,8.333333333333333e-05,0.68,0.23,0.2,0.04,0.87,0.05,0.02,0.02
51.993343003758,0.0044453046044264,143.86125444857635,250.0,8.333333333333333e-05,0.68,0.23,0.2,0.04,0.87,0.05,0.02,0.02
52.4024309228316,0.0044793952643492,143.97850230183485,250.0,8.333333333333333e-05,0.68,0.23,0.2,0.04,0.87,0.05,0.02,0.02
52.811518841905205,0.004513485924272,144.09575015509273,250.0,8.333333333333333e-05,0.68,0.23,0.2,0.04,0.87,0.05,0.02,0.02
53.2035318566532,0.0045461536755010004,144.1838497073867,250.0,8.333333333333333e-05,0.68,0.23,0.2,0.04,0.87,0.05,0.02,0.02
53.5955448714012,0.004578821426730001,144.27194925968172,250.0,8.333333333333333e-05,0.68,0.23,0.2,0.04,0.87,0.05,0.02,0.02
53.987557886149204,0.004611489177959,144.36004881197556,250.0,8.333333333333333e-05,0.68,0.23,0.2,0.04,0.87,0.05,0.02,0.02
54.3795709008972,0.004644156929188,144.4481483642694,250.0,8.333333333333333e-05,0.68,0.23,0.2,0.04,0.87,0.05,0.02,0.02
54.845590358589305,0.0046829918839956745,144.52130959054116,250.0,8.333333333333333e-05,0.68,0.23,0.2,0.04,0.87,0.05,0.02,0.02
55.311609816281404,0.00472182683880335,144.59447081681384,250.0,8.333333333333333e-05,0.68,0.23,0.2,0.04,0.87,0.05,0.02,0.02
55.7776292739735,0.004760661793611025,144.66763204308597,250.0,8.333333333333333e-05,0.68,0.23,0.2,0.04,0.87,0.05,0.02,0.02
56.2436487316656,0.0047994967484187,144.7407932693571,250.0,8.333333333333333e-05,0.68,0.23,0.2,0.04,0.87,0.05,0.02,0.02
56.7624651276021,0.004842731448080074,144.8137038270121,250.0,8.333333333333333e-05,0.68,0.23,0.2,0.04,0.87,0.05,0.02,0.02
57.281281523538595,0.0048859661477414496,144.88661438466627,250.0,8.333333333333333e-05,0.68,0.23,0.2,0.04,0.87,0.05,0.02,0.02
57.80009791947509,0.004929200847402825,144.9595249423211,250.0,8.333333333333333e-05,0.68,0.23,0.2,0.04,0.87,0.05,0.02,0.02
58.3189143154116,0.0049724355470642,145.0324354999758,250.0,8.333333333333333e-05,0.68,0.23,0.2,0.04,0.87,0.05,0.02,0.02
58.7252429432355,0.005006296266049525,145.0835937928438,250.0,8.333333333333333e-05,0.68,0.23,0.2,0.04,0.87,0.05,0.02,0.02
59.131571571059396,0.00504015698503485,145.13475208571322,250.0,8.333333333333333e-05,0.68,0.23,0.2,0.04,0.87,0.05,0.02,0.02
59.5379001988833,0.005074017704020176,145.18591037858127,250.0,8.333333333333333e-05,0.68,0.23,0.2,0.04,0.87,0.05,0.02,0.02
59.9442288267072,0.0051078784230055,145.2370686714479,250.0,8.333333333333333e-05,0.68,0.23,0.2,0.04,0.87,0.05,0.02,0.02
60.434579139507605,0.0051487409490722,145.28080242431489,250.0,8.333333333333333e-05,0.68,0.23,0.2,0.04,0.87,0.05,0.02,0.02
60.92492945230801,0.0051896034751389,145.324536177183,250.0,8.333333333333333e-05,0.68,0.23,0.2,0.04,0.87,0.05,0.02,0.02
61.41527976510841,0.0052304660012055994,145.3682699300501,250.0,8.333333333333333e-05,0.68,0.23,0.2,0.04,0.87,0.05,0.02,0.02
61.9056300779088,0.0052713285272723,145.41200368291763,250.0,8.333333333333333e-05,0.68,0.23,0.2,0.04,0.87,0.05,0.02,0.02
62.4020922375273,0.005312700373907174,145.44163101938736,250.0,8.333333333333333e-05,0.68,0.23,0.2,0.04,0.87,0.05,0.02,0.02
62.8985543971458,0.0053540722205420496,145.47125835585746,250.0,8.333333333333333e-05,0.68,0.23,0.2,0.04,0.87,0.05,0.02,0.02
63.395016556764304,0.005395444067176925,145.5008856923271,250.0,8.333333333333333e-05,0.68,0.23,0.2,0.04,0.87,0.05,0.02,0.02
63.8914787163828,0.0054368159138118,145.53051302879553,250.0,8.333333333333333e-05,0.68,0.23,0.2,0.04,0.87,0.05,0.02,0.02
64.4551815757161,0.005483791152089575,145.55249490401778,250.0,8.333333333333333e-05,0.68,0.23,0.2,0.04,0.87,0.05,0.02,0.02
65.0188844350494,0.00553076639036735,145.5744767792405,250.0,8.333333333333333e-05,0.68,0.23,0.2,0.04,0.87,0.05,0.02,0.02
65.5825872943827,0.0055777416286451244,145.59645865446277,250.0,8.333333333333333e-05,0.68,0.23,0.2,0.04,0.87,0.05,0.02,0.02
66.14629015371601,0.0056247168669229,145.61844052968493,250.0,8.333333333333333e-05,0.68,0.23,0.2,0.04,0.87,0.05,0.02,0.02
66.7078805698506,0.00567151606826745,145.63333095567617,250.0,8.333333333333333e-05,0.68,0.23,0.2,0.04,0.87,0.05,0.02,0.02
67.26947098598521,0.005718315269612,145.64822138166747,250.0,8.333333333333333e-05,0.68,0.23,0.2,0.04,0.87,0.05,0.02,0.02
67.83106140211981,0.00576511447095655,145.6631118076589,250.0,8.333333333333333e-05,0.68,0.23,0.2,0.04,0.87,0.05,0.02,0.02
68.39265181825441,0.0058119136723011,145.67800223365032,250.0,8.333333333333333e-05,0.68,0.23,0.2,0.04,0.87,0.05,0.02,0.02
68.9007052399059,0.005854251457438725,145.68232238707157,250.0,8.333333333333333e-05,0.68,0.23,0.2,0.04,0.87,0.05,0.02,0.02
69.40875866155741,0.00589658924257635,145.68664254049202,250.0,8.333333333333333e-05,0.68,0.23,0.2,0.04,0.87,0.05,0.02,0.02
69.91681208320891,0.005938927027713975,145.69096269391312,250.0,8.333333333333333e-05,0.68,0.23,0.2,0.04,0.87,0.05,0.02,0.02
70.4248655048604,0.0059812648128516,145.695282847335,250.0,8.333333333333333e-05,0.68,0.23,0.2,0.04,0.87,0.05,0.02,0.02