File: datasets/al_6061_comp/csv/T_250_D_2.csv
Time,Strain(%),Stress(MPa),Temp(C),SR(%/s),Si(%),Fe(%),Cu(%),Mn(%),Mg(%),Cr(%),Zn(%),Ti(%)
0.0,9.75063995877519e-05,41.93735770856001,250.0,8.333333333333333e-05,0.67,0.28,0.23,0.05,0.9,0.05,0.03,0.02
0.13781097821834432,0.00010899064777261392,42.43740407788916,250.0,8.333333333333333e-05,0.67,0.28,0.23,0.05,0.9,0.05,0.03,0.02
0.27562195643668863,0.00012047489595747596,42.93745044721826,250.0,8.333333333333333e-05,0.67,0.28,0.23,0.05,0.9,0.05,0.03,0.02
0.41343293465503295,0.000131959144142338,43.437496816547416,250.0,8.333333333333333e-05,0.67,0.28,0.23,0.05,0.9,0.05,0.03,0.02
0.5512439128733773,0.0001434433923272,43.9375431858766,250.0,8.333333333333333e-05,0.67,0.28,0.23,0.05,0.9,0.05,0.03,0.02
0.6649734726239772,0.00015292085563975002,44.43667486084213,250.0,8.333333333333333e-05,0.67,0.28,0.23,0.05,0.9,0.05,0.03,0.02
0.7787030323745772,0.00016239831895230002,44.93580653580766,250.0,8.333333333333333e-05,0.67,0.28,0.23,0.05,0.9,0.05,0.03,0.02
0.8924325921251771,0.00017187578226485,45.43493821077318,250.0,8.333333333333333e-05,0.67,0.28,0.23,0.05,0.9,0.05,0.03,0.02
1.006162151875777,0.0001813532455774,45.93406988573874,250.0,8.333333333333333e-05,0.67,0.28,0.23,0.05,0.9,0.05,0.03,0.02
1.141402584639577,0.00019262328164105,46.42694834069554,250.0,8.333333333333333e-05,0.67,0.28,0.23,0.05,0.9,0.05,0.03,0.02
1.2766430174033772,0.0002038933177047,46.919826795652284,250.0,8.333333333333333e-05,0.67,0.28,0.23,0.05,0.9,0.05,0.03,0.02
1.4118834501671773,0.00021516335376835,47.41270525060908,250.0,8.333333333333333e-05,0.67,0.28,0.23,0.05,0.9,0.05,0.03,0.02
1.5471238829309772,0.000226433389832,47.905583705565874,250.0,8.333333333333333e-05,0.67,0.28,0.23,0.05,0.9,0.05,0.03,0.02
1.6857519577508773,0.000237985729400325,48.384827664122085,250.0,8.333333333333333e-05,0.67,0.28,0.23,0.05,0.9,0.05,0.03,0.02
1.8243800325707773,0.00024953806896865,48.86407162267833,250.0,8.333333333333333e-05,0.67,0.28,0.23,0.05,0.9,0.05,0.03,0.02
1.9630081073906773,0.00026109040853697504,49.34331558123452,250.0,8.333333333333333e-05,0.67,0.28,0.23,0.05,0.9,0.05,0.03,0.02
2.1016361822105774,0.0002726427481053,49.8225595397907,250.0,8.333333333333333e-05,0.67,0.28,0.23,0.05,0.9,0.05,0.03,0.02
2.234401401355777,0.0002837065163674,50.294414281521625,250.0,8.333333333333333e-05,0.67,0.28,0.23,0.05,0.9,0.05,0.03,0.02
2.3671666205009774,0.0002947702846295,50.76626902325262,250.0,8.333333333333333e-05,0.67,0.28,0.23,0.05,0.9,0.05,0.03,0.02
2.4999318396461776,0.0003058340528916,51.238123764983555,250.0,8.333333333333333e-05,0.67,0.28,0.23,0.05,0.9,0.05,0.03,0.02
2.6326970587913774,0.0003168978211537,51.709978506714386,250.0,8.333333333333333e-05,0.67,0.28,0.23,0.05,0.9,0.05,0.03,0.02
2.776649385472177,0.00032889384837710004,52.188401721481235,250.0,8.333333333333333e-05,0.67,0.28,0.23,0.05,0.9,0.05,0.03,0.02
2.920601712152977,0.0003408898756005,52.66682493624809,250.0,8.333333333333333e-05,0.67,0.28,0.23,0.05,0.9,0.05,0.03,0.02
3.0645540388337773,0.0003528859028239,53.145248151014925,250.0,8.333333333333333e-05,0.67,0.28,0.23,0.05,0.9,0.05,0.03,0.02
3.208506365514577,0.0003648819300473,53.623671365781846,250.0,8.333333333333333e-05,0.67,0.28,0.23,0.05,0.9,0.05,0.03,0.02
3.338366047519177,0.00037570357021435,54.09730514478355,250.0,8.333333333333333e-05,0.67,0.28,0.23,0.05,0.9,0.05,0.03,0.02
3.4682257295237773,0.0003865252103814,54.57093892378529,250.0,8.333333333333333e-05,0.67,0.28,0.23,0.05,0.9,0.05,0.03,0.02
3.5980854115283774,0.00039734685054845,55.044572702786986,250.0,8.333333333333333e-05,0.67,0.28,0.23,0.05,0.9,0.05,0.03,0.02
3.7279450935329774,0.0004081684907155,55.518206481788596,250.0,8.333333333333333e-05,0.67,0.28,0.23,0.05,0.9,0.05,0.03,0.02
3.872986768039177,0.00042025529692435004,55.98705683282437,250.0,8.333333333333333e-05,0.67,0.28,0.23,0.05,0.9,0.05,0.03,0.02
4.018028442545377,0.0004323421031332,56.45590718386009,250.0,8.333333333333333e-05,0.67,0.28,0.23,0.05,0.9,0.05,0.03,0.02
4.163070117051578,0.00044442890934205,56.924757534895875,250.0,8.333333333333333e-05,0.67,0.28,0.23,0.05,0.9,0.05,0.03,0.02
4.308111791557778,0.0004565157155509,57.3936078859317,250.0,8.333333333333333e-05,0.67,0.28,0.23,0.05,0.9,0.05,0.03,0.02
4.449603527551178,0.00046830669355035,57.84899200646915,250.0,8.333333333333333e-05,0.67,0.28,0.23,0.05,0.9,0.05,0.03,0.02
4.591095263544577,0.0004800976715498,58.30437612700646,250.0,8.333333333333333e-05,0.67,0.28,0.23,0.05,0.9,0.05,0.03,0.02
4.732586999537977,0.00049188864954925,58.75976024754391,250.0,8.333333333333333e-05,0.67,0.28,0.23,0.05,0.9,0.05,0.03,0.02
4.874078735531377,0.0005036796275487,59.215144368081546,250.0,8.333333333333333e-05,0.67,0.28,0.23,0.05,0.9,0.05,0.03,0.02
5.016931631765978,0.00051558403556825,59.664708760829214,250.0,8.333333333333333e-05,0.67,0.28,0.23,0.05,0.9,0.05,0.03,0.02
5.159784528000578,0.0005274884435878,60.11427315357679,250.0,8.333333333333333e-05,0.67,0.28,0.23,0.05,0.9,0.05,0.03,0.02
5.3026374242351775,0.00053939285160735,60.563837546324464,250.0,8.333333333333333e-05,0.67,0.28,0.23,0.05,0.9,0.05,0.03,0.02
5.445490320469778,0.0005512972596269,61.013401939072324,250.0,8.333333333333333e-05,0.67,0.28,0.23,0.05,0.9,0.05,0.03,0.02
5.571834321671378,0.0005618259263937,61.45146237844918,250.0,8.333333333333333e-05,0.67,0.28,0.23,0.05,0.9,0.05,0.03,0.02
5.698178322872978,0.0005723545931605001,61.88952281782574,250.0,8.333333333333333e-05,0.67,0.28,0.23,0.05,0.9,0.05,0.03,0.02
5.824522324074577,0.0005828832599273,62.327583257202605,250.0,8.333333333333333e-05,0.67,0.28,0.23,0.05,0.9,0.05,0.03,0.02
5.950866325276177,0.0005934119266941,62.76564369657967,250.0,8.333333333333333e-05,0.67,0.28,0.23,0.05,0.9,0.05,0.03,0.02
6.086181440422777,0.00060468818628965,63.18873740512582,250.0,8.333333333333333e-05,0.67,0.28,0.23,0.05,0.9,0.05,0.03,0.02
6.221496555569377,0.0006159644458852,63.61183111367173,250.0,8.333333333333333e-05,0.67,0.28,0.23,0.05,0.9,0.05,0.03,0.02
6.356811670715977,0.00062724070548075,64.03492482221783,250.0,8.333333333333333e-05,0.67,0.28,0.23,0.05,0.9,0.05,0.03,0.02
6.4921267858625775,0.0006385169650763,64.45801853076394,250.0,8.333333333333333e-05,0.67,0.28,0.23,0.05,0.9,0.05,0.03,0.02
6.626129979736177,0.0006496838978991,64.88537992721635,250.0,8.333333333333333e-05,0.67,0.28,0.23,0.05,0.9,0.05,0.03,0.02
6.760133173609778,0.0006608508307219001,65.31274132366879,250.0,8.333333333333333e-05,0.67,0.28,0.23,0.05,0.9,0.05,0.03,0.02
6.894136367483378,0.0006720177635447,65.74010272012124,250.0,8.333333333333333e-05,0.67,0.28,0.23,0.05,0.9,0.05,0.03,0.02
7.028139561356978,0.0006831846963675,66.1674641165737,250.0,8.333333333333333e-05,0.67,0.28,0.23,0.05,0.9,0.05,0.03,0.02
7.162238263309778,0.0006943595881969,66.6013523116577,250.0,8.333333333333333e-05,0.67,0.28,0.23,0.05,0.9,0.05,0.03,0.02
7.2963369652625785,0.0007055344800263,67.03524050674167,250.0,8.333333333333333e-05,0.67,0.28,0.23,0.05,0.9,0.05,0.03,0.02
7.430435667215379,0.0007167093718557,67.46912870182562,250.0,8.333333333333333e-05,0.67,0.28,0.23,0.05,0.9,0.05,0.03,0.02
7.564534369168179,0.0007278842636851,67.90301689690969,250.0,8.333333333333333e-05,0.67,0.28,0.23,0.05,0.9,0.05,0.03,0.02
7.690471617830679,0.000738379034406975,68.32705133889655,250.0,8.333333333333333e-05,0.67,0.28,0.23,0.05,0.9,0.05,0.03,0.02
7.816408866493179,0.00074887380512885,68.75108578088371,250.0,8.333333333333333e-05,0.67,0.28,0.23,0.05,0.9,0.05,0.03,0.02
7.9423461151556785,0.000759368575850725,69.17512022287066,250.0,8.333333333333333e-05,0.67,0.28,0.23,0.05,0.9,0.05,0.03,0.02
8.068283363818178,0.0007698633465726,69.59915466485754,250.0,8.333333333333333e-05,0.67,0.28,0.23,0.05,0.9,0.05,0.03,0.02
8.207525836920578,0.0007814668859978001,70.01927147522159,250.0,8.333333333333333e-05,0.67,0.28,0.23,0.05,0.9,0.05,0.03,0.02
8.346768310022977,0.000793070425423,70.43938828558545,250.0,8.333333333333333e-05,0.67,0.28,0.23,0.05,0.9,0.05,0.03,0.02
8.486010783125376,0.0008046739648481999,70.85950509594949,250.0,8.333333333333333e-05,0.67,0.28,0.23,0.05,0.9,0.05,0.03,0.02
8.625253256227777,0.0008162775042734,71.27962190631354,250.0,8.333333333333333e-05,0.67,0.28,0.23,0.05,0.9,0.05,0.03,0.02
8.759372437515577,0.00082745410271405,71.69559290749343,250.0,8.333333333333333e-05,0.67,0.28,0.23,0.05,0.9,0.05,0.03,0.02
8.893491618803377,0.0008386307011547,72.1115639086736,250.0,8.333333333333333e-05,0.67,0.28,0.23,0.05,0.9,0.05,0.03,0.02
9.027610800091177,0.00084980729959535,72.52753490985343,250.0,8.333333333333333e-05,0.67,0.28,0.23,0.05,0.9,0.05,0.03,0.02
9.161729981378976,0.000860983898036,72.94350591103333,250.0,8.333333333333333e-05,0.67,0.28,0.23,0.05,0.9,0.05,0.03,0.02
9.314262027355475,0.000873694901867375,73.37594305032907,250.0,8.333333333333333e-05,0.67,0.28,0.23,0.05,0.9,0.05,0.03,0.02
9.466794073331975,0.00088640590569875,73.80838018962493,250.0,8.333333333333333e-05,0.67,0.28,0.23,0.05,0.9,0.05,0.03,0.02
9.619326119308475,0.000899116909530125,74.24081732892066,250.0,8.333333333333333e-05,0.67,0.28,0.23,0.05,0.9,0.05,0.03,0.02
9.771858165284977,0.0009118279133615,74.67325446821576,250.0,8.333333333333333e-05,0.67,0.28,0.23,0.05,0.9,0.05,0.03,0.02
9.911247794614479,0.000923443715805625,75.10497609723647,250.0,8.333333333333333e-05,0.67,0.28,0.23,0.05,0.9,0.05,0.03,0.02
10.050637423943979,0.00093505951824975,75.53669772625739,250.0,8.333333333333333e-05,0.67,0.28,0.23,0.05,0.9,0.05,0.03,0.02
10.190027053273479,0.000946675320693875,75.96841935527823,250.0,8.333333333333333e-05,0.67,0.28,0.23,0.05,0.9,0.05,0.03,0.02
10.32941668260298,0.000958291123138,76.40014098429921,250.0,8.333333333333333e-05,0.67,0.28,0.23,0.05,0.9,0.05,0.03,0.02
10.464308322760179,0.0009695320931511,76.80911497457944,250.0,8.333333333333333e-05,0.67,0.28,0.23,0.05,0.9,0.05,0.03,0.02
10.599199962917378,0.0009807730631641999,77.21808896486019,250.0,8.333333333333333e-05,0.67,0.28,0.23,0.05,0.9,0.05,0.03,0.02
10.734091603074578,0.0009920140331773,77.62706295514042,250.0,8.333333333333333e-05,0.67,0.28,0.23,0.05,0.9,0.05,0.03,0.02
10.868983243231778,0.0010032550031904,78.03603694542008,250.0,8.333333333333333e-05,0.67,0.28,0.23,0.05,0.9,0.05,0.03,0.02
11.01518032009048,0.0010154380929286249,78.43399903573976,250.0,8.333333333333333e-05,0.67,0.28,0.23,0.05,0.9,0.05,0.03,0.02
11.16137739694918,0.00102762118266685,78.83196112605941,250.0,8.333333333333333e-05,0.67,0.28,0.23,0.05,0.9,0.05,0.03,0.02
11.307574473807879,0.0010398042724050751,79.22992321637908,250.0,8.333333333333333e-05,0.67,0.28,0.23,0.05,0.9,0.05,0.03,0.02
11.45377155066658,0.0010519873621433,79.62788530669906,250.0,8.333333333333333e-05,0.67,0.28,0.23,0.05,0.9,0.05,0.03,0.02
11.60707910215738,0.0010647629914342,80.02456088443581,250.0,8.333333333333333e-05,0.67,0.28,0.23,0.05,0.9,0.05,0.03,0.02
11.76038665364818,0.0010775386207251,80.42123646217229,250.0,8.333333333333333e-05,0.67,0.28,0.23,0.05,0.9,0.05,0.03,0.02
11.913694205138981,0.001090314250016,80.817912039909,250.0,8.333333333333333e-05,0.67,0.28,0.23,0.05,0.9,0.05,0.03,0.02
12.06700175662978,0.0011030898793069,81.21458761764544,250.0,8.333333333333333e-05,0.67,0.28,0.23,0.05,0.9,0.05,0.03,0.02
12.20778047441398,0.00111482143912225,81.60693866902207,250.0,8.333333333333333e-05,0.67,0.28,0.23,0.05,0.9,0.05,0.03,0.02
12.348559192198179,0.0011265529989376,81.9992897203991,250.0,8.333333333333333e-05,0.67,0.28,0.23,0.05,0.9,0.05,0.03,0.02
12.489337909982378,0.00113828455875295,82.39164077177568,250.0,8.333333333333333e-05,0.67,0.28,0.23,0.05,0.9,0.05,0.03,0.02
12.630116627766578,0.0011500161185683,82.78399182315192,250.0,8.333333333333333e-05,0.67,0.28,0.23,0.05,0.9,0.05,0.03,0.02
12.771163055432977,0.0011617699875405,83.16781742722813,250.0,8.333333333333333e-05,0.67,0.28,0.23,0.05,0.9,0.05,0.03,0.02
12.912209483099376,0.0011735238565126998,83.55164303130437,250.0,8.333333333333333e-05,0.67,0.28,0.23,0.05,0.9,0.05,0.03,0.02
13.053255910765776,0.0011852777254848998,83.9354686353805,250.0,8.333333333333333e-05,0.67,0.28,0.23,0.05,0.9,0.05,0.03,0.02
13.194302338432175,0.0011970315944571,84.3192942394569,250.0,8.333333333333333e-05,0.67,0.28,0.23,0.05,0.9,0.05,0.03,0.02
13.323474706202376,0.0012077959584379499,84.68200531630316,250.0,8.333333333333333e-05,0.67,0.28,0.23,0.05,0.9,0.05,0.03,0.02
13.452647073972575,0.0012185603224188,85.04471639314943,250.0,8.333333333333333e-05,0.67,0.28,0.23,0.05,0.9,0.05,0.03,0.02
13.581819441742775,0.00122932468639965,85.40742746999588,250.0,8.333333333333333e-05,0.67,0.28,0.23,0.05,0.9,0.05,0.03,0.02
13.710991809512976,0.0012400890503805,85.77013854684208,250.0,8.333333333333333e-05,0.67,0.28,0.23,0.05,0.9,0.05,0.03,0.02
13.831437805469676,0.001250126216710225,86.14898911890842,250.0,8.333333333333333e-05,0.67,0.28,0.23,0.05,0.9,0.05,0.03,0.02
13.951883801426376,0.00126016338303995,86.52783969097545,250.0,8.333333333333333e-05,0.67,0.28,0.23,0.05,0.9,0.05,0.03,0.02
14.072329797383077,0.001270200549369675,86.9066902630418,250.0,8.333333333333333e-05,0.67,0.28,0.23,0.05,0.9,0.05,0.03,0.02
14.192775793339775,0.0012802377156994,87.28554083510764,250.0,8.333333333333333e-05,0.67,0.28,0.23,0.05,0.9,0.05,0.03,0.02
14.334110249560478,0.001292015587051125,87.66151231691384,250.0,8.333333333333333e-05,0.67,0.28,0.23,0.05,0.9,0.05,0.03,0.02
14.475444705781179,0.00130379345840285,88.03748379871965,250.0,8.333333333333333e-05,0.67,0.28,0.23,0.05,0.9,0.05,0.03,0.02
14.61677916200188,0.001315571329754575,88.41345528052574,250.0,8.333333333333333e-05,0.67,0.28,0.23,0.05,0.9,0.05,0.03,0.02
14.75811361822258,0.0013273492011063,88.78942676233194,250.0,8.333333333333333e-05,0.67,0.28,0.23,0.05,0.9,0.05,0.03,0.02
14.89353589598068,0.0013386343909194752,89.17768793606601,250.0,8.333333333333333e-05,0.67,0.28,0.23,0.05,0.9,0.05,0.03,0.02
15.02895817373878,0.00134991958073265,89.56594910980073,250.0,8.333333333333333e-05,0.67,0.28,0.23,0.05,0.9,0.05,0.03,0.02
15.164380451496879,0.001361204770545825,89.9542102835347,250.0,8.333333333333333e-05,0.67,0.28,0.23,0.05,0.9,0.05,0.03,0.02
15.299802729254976,0.001372489960359,90.34247145726854,250.0,8.333333333333333e-05,0.67,0.28,0.23,0.05,0.9,0.05,0.03,0.02
15.440299386954575,0.0013841980151673,90.72220510453629,250.0,8.333333333333333e-05,0.67,0.28,0.23,0.05,0.9,0.05,0.03,0.02
15.580796044654175,0.0013959060699756001,91.10193875180455,250.0,8.333333333333333e-05,0.67,0.28,0.23,0.05,0.9,0.05,0.03,0.02
15.721292702353775,0.0014076141247839,91.48167239907251,250.0,8.333333333333333e-05,0.67,0.28,0.23,0.05,0.9,0.05,0.03,0.02
15.861789360053375,0.0014193221795922,91.86140604633977,250.0,8.333333333333333e-05,0.67,0.28,0.23,0.05,0.9,0.05,0.03,0.02
16.014905354495077,0.001432081845795675,92.24378597273673,250.0,8.333333333333333e-05,0.67,0.28,0.23,0.05,0.9,0.05,0.03,0.02
16.168021348936776,0.00144484151199915,92.62616589913375,250.0,8.333333333333333e-05,0.67,0.28,0.23,0.05,0.9,0.05,0.03,0.02
16.321137343378474,0.001457601178202625,93.00854582553066,250.0,8.333333333333333e-05,0.67,0.28,0.23,0.05,0.9,0.05,0.03,0.02
16.474253337820176,0.0014703608444061,93.39092575192774,250.0,8.333333333333333e-05,0.67,0.28,0.23,0.05,0.9,0.05,0.03,0.02
16.622334995817575,0.0014827009825725498,93.77216658058079,250.0,8.333333333333333e-05,0.67,0.28,0.23,0.05,0.9,0.05,0.03,0.02
16.770416653814976,0.0014950411207389999,94.1534074092333,250.0,8.333333333333333e-05,0.67,0.28,0.23,0.05,0.9,0.05,0.03,0.02
16.918498311812378,0.00150738125890545,94.53464823788647,250.0,8.333333333333333e-05,0.67,0.28,0.23,0.05,0.9,0.05,0.03,0.02
17.066579969809776,0.0015197213970719,94.91588906654056,250.0,8.333333333333333e-05,0.67,0.28,0.23,0.05,0.9,0.05,0.03,0.02
17.220487025174677,0.0015325469850189749,95.29894546637863,250.0,8.333333333333333e-05,0.67,0.28,0.23,0.05,0.9,0.05,0.03,0.02
17.374394080539574,0.00154537257296605,95.68200186621544,250.0,8.333333333333333e-05,0.67,0.28,0.23,0.05,0.9,0.05,0.03,0.02
17.528301135904474,0.001558198160913125,96.06505826605348,250.0,8.333333333333333e-05,0.67,0.28,0.23,0.05,0.9,0.05,0.03,0.02
17.682208191269375,0.0015710237488602,96.44811466589151,250.0,8.333333333333333e-05,0.67,0.28,0.23,0.05,0.9,0.05,0.03,0.02
17.852782247506774,0.00158523825354665,96.82695117487609,250.0,8.333333333333333e-05,0.67,0.28,0.23,0.05,0.9,0.05,0.03,0.02
18.023356303744176,0.0015994527582331,97.2057876838615,250.0,8.333333333333333e-05,0.67,0.28,0.23,0.05,0.9,0.05,0.03,0.02
18.19393035998158,0.00161366726291955,97.58462419284594,250.0,8.333333333333333e-05,0.67,0.28,0.23,0.05,0.9,0.05,0.03,0.02
18.364504416218978,0.001627881767606,97.96346070183014,250.0,8.333333333333333e-05,0.67,0.28,0.23,0.05,0.9,0.05,0.03,0.02
18.51193705664548,0.001640167820974875,98.33924454386863,250.0,8.333333333333333e-05,0.67,0.28,0.23,0.05,0.9,0.05,0.03,0.02
18.659369697071977,0.00165245387434375,98.71502838590732,250.0,8.333333333333333e-05,0.67,0.28,0.23,0.05,0.9,0.05,0.03,0.02
18.806802337498475,0.0016647399277126252,99.09081222794609,250.0,8.333333333333333e-05,0.67,0.28,0.23,0.05,0.9,0.05,0.03,0.02
18.954234977924976,0.0016770259810815,99.46659606998449,250.0,8.333333333333333e-05,0.67,0.28,0.23,0.05,0.9,0.05,0.03,0.02
19.102240816478975,0.0016893598009609999,99.8187164779512,250.0,8.333333333333333e-05,0.67,0.28,0.23,0.05,0.9,0.05,0.03,0.02
19.250246655032974,0.0017016936208404999,100.17083688591875,250.0,8.333333333333333e-05,0.67,0.28,0.23,0.05,0.9,0.05,0.03,0.02
19.398252493586973,0.00171402744072,100.52295729388514,250.0,8.333333333333333e-05,0.67,0.28,0.23,0.05,0.9,0.05,0.03,0.02
19.546258332140976,0.0017263612605995,100.87507770185044,250.0,8.333333333333333e-05,0.67,0.28,0.23,0.05,0.9,0.05,0.03,0.02
19.692829633448675,0.001738575535708475,101.24171572102219,250.0,8.333333333333333e-05,0.67,0.28,0.23,0.05,0.9,0.05,0.03,0.02
19.839400934756377,0.00175078981081745,101.60835374019493,250.0,8.333333333333333e-05,0.67,0.28,0.23,0.05,0.9,0.05,0.03,0.02
19.98597223606408,0.0017630040859264251,101.97499175936674,250.0,8.333333333333333e-05,0.67,0.28,0.23,0.05,0.9,0.05,0.03,0.02
20.132543537371777,0.0017752183610354,102.34162977853867,250.0,8.333333333333333e-05,0.67,0.28,0.23,0.05,0.9,0.05,0.03,0.02
20.295688243629577,0.0017888137532235501,102.69755677879067,250.0,8.333333333333333e-05,0.67,0.28,0.23,0.05,0.9,0.05,0.03,0.02
20.458832949887377,0.0018024091454117,103.05348377904247,250.0,8.333333333333333e-05,0.67,0.28,0.23,0.05,0.9,0.05,0.03,0.02
20.621977656145177,0.00181600453759985,103.40941077929446,250.0,8.333333333333333e-05,0.67,0.28,0.23,0.05,0.9,0.05,0.03,0.02
20.785122362402976,0.001829599929788,103.76533777954602,250.0,8.333333333333333e-05,0.67,0.28,0.23,0.05,0.9,0.05,0.03,0.02
20.935416398868874,0.001842124432826825,104.11439302973002,250.0,8.333333333333333e-05,0.67,0.28,0.23,0.05,0.9,0.05,0.03,0.02
21.085710435334775,0.0018546489358656501,104.46344827991439,250.0,8.333333333333333e-05,0.67,0.28,0.23,0.05,0.9,0.05,0.03,0.02
21.236004471800676,0.001867173438904475,104.81250353009818,250.0,8.333333333333333e-05,0.67,0.28,0.23,0.05,0.9,0.05,0.03,0.02
21.386298508266577,0.0018796979419433,105.16155878028172,250.0,8.333333333333333e-05,0.67,0.28,0.23,0.05,0.9,0.05,0.03,0.02
21.541925189672078,0.0018926668320604252,105.51465323190621,250.0,8.333333333333333e-05,0.67,0.28,0.23,0.05,0.9,0.05,0.03,0.02
21.69755187107758,0.00190563572217755,105.86774768353047,250.0,8.333333333333333e-05,0.67,0.28,0.23,0.05,0.9,0.05,0.03,0.02
21.85317855248308,0.001918604612294675,106.22084213515498,250.0,8.333333333333333e-05,0.67,0.28,0.23,0.05,0.9,0.05,0.03,0.02
22.008805233888577,0.0019315735024118,106.57393658678002,250.0,8.333333333333333e-05,0.67,0.28,0.23,0.05,0.9,0.05,0.03,0.02
22.156399373340278,0.0019438730140327748,106.90957333223278,250.0,8.333333333333333e-05,0.67,0.28,0.23,0.05,0.9,0.05,0.03,0.02
22.303993512791976,0.0019561725256537496,107.24521007768482,250.0,8.333333333333333e-05,0.67,0.28,0.23,0.05,0.9,0.05,0.03,0.02
22.451587652243674,0.0019684720372747247,107.58084682313779,250.0,8.333333333333333e-05,0.67,0.28,0.23,0.05,0.9,0.05,0.03,0.02
22.599181791695376,0.0019807715488957,107.91648356859073,250.0,8.333333333333333e-05,0.67,0.28,0.23,0.05,0.9,0.05,0.03,0.02
22.759829893074574,0.0019941588906773,108.26905918318849,250.0,8.333333333333333e-05,0.67,0.28,0.23,0.05,0.9,0.05,0.03,0.02
22.920477994453776,0.0020075462324589,108.62163479778667,250.0,8.333333333333333e-05,0.67,0.28,0.23,0.05,0.9,0.05,0.03,0.02
23.081126095832975,0.0020209335742404997,108.97421041238434,250.0,8.333333333333333e-05,0.67,0.28,0.23,0.05,0.9,0.05,0.03,0.02
23.241774197212173,0.0020343209160221,109.32678602698272,250.0,8.333333333333333e-05,0.67,0.28,0.23,0.05,0.9,0.05,0.03,0.02
23.393199568441176,0.00204693969695785,109.67274127652497,250.0,8.333333333333333e-05,0.67,0.28,0.23,0.05,0.9,0.05,0.03,0.02
23.544624939670175,0.0020595584778936,110.01869652606646,250.0,8.333333333333333e-05,0.67,0.28,0.23,0.05,0.9,0.05,0.03,0.02
23.696050310899174,0.00207217725882935,110.36465177560854,250.0,8.333333333333333e-05,0.67,0.28,0.23,0.05,0.9,0.05,0.03,0.02
23.847475682128177,0.0020847960397651,110.71060702515054,250.0,8.333333333333333e-05,0.67,0.28,0.23,0.05,0.9,0.05,0.03,0.02
24.003744240572676,0.002097818419635475,111.03723491922254,250.0,8.333333333333333e-05,0.67,0.28,0.23,0.05,0.9,0.05,0.03,0.02
24.160012799017174,0.0021108407995058497,111.36386281329452,250.0,8.333333333333333e-05,0.67,0.28,0.23,0.05,0.9,0.05,0.03,0.02
24.316281357461673,0.002123863179376225,111.69049070736685,250.0,8.333333333333333e-05,0.67,0.28,0.23,0.05,0.9,0.05,0.03,0.02
24.47254991590617,0.0021368855592466,112.0171186014398,250.0,8.333333333333333e-05,0.67,0.28,0.23,0.05,0.9,0.05,0.03,0.02
24.61473661195887,0.002148734450584325,112.33698311552855,250.0,8.333333333333333e-05,0.67,0.28,0.23,0.05,0.9,0.05,0.03,0.02
24.756923308011572,0.00216058334192205,112.65684762961683,250.0,8.333333333333333e-05,0.67,0.28,0.23,0.05,0.9,0.05,0.03,0.02
24.899110004064276,0.002172432233259775,112.97671214370536,250.0,8.333333333333333e-05,0.67,0.28,0.23,0.05,0.9,0.05,0.03,0.02
25.041296700116977,0.0021842811245975,113.29657665779371,250.0,8.333333333333333e-05,0.67,0.28,0.23,0.05,0.9,0.05,0.03,0.02
25.187129976833376,0.0021964338976571997,113.61976105718419,250.0,8.333333333333333e-05,0.67,0.28,0.23,0.05,0.9,0.05,0.03,0.02
25.332963253549778,0.0022085866707169,113.94294545657434,250.0,8.333333333333333e-05,0.67,0.28,0.23,0.05,0.9,0.05,0.03,0.02
25.478796530266177,0.0022207394437766,114.2661298559648,250.0,8.333333333333333e-05,0.67,0.28,0.23,0.05,0.9,0.05,0.03,0.02
25.624629806982576,0.0022328922168363,114.58931425535766,250.0,8.333333333333333e-05,0.67,0.28,0.23,0.05,0.9,0.05,0.03,0.02
25.769705925055774,0.0022449818933424,114.89730889476667,250.0,8.333333333333333e-05,0.67,0.28,0.23,0.05,0.9,0.05,0.03,0.02
25.914782043128977,0.0022570715698485002,115.20530353417317,250.0,8.333333333333333e-05,0.67,0.28,0.23,0.05,0.9,0.05,0.03,0.02
26.05985816120218,0.0022691612463546004,115.51329817358217,250.0,8.333333333333333e-05,0.67,0.28,0.23,0.05,0.9,0.05,0.03,0.02
26.204934279275378,0.0022812509228607,115.82129281299027,250.0,8.333333333333333e-05,0.67,0.28,0.23,0.05,0.9,0.05,0.03,0.02
26.361065027288376,0.00229426181852845,116.12884779792877,250.0,8.333333333333333e-05,0.67,0.28,0.23,0.05,0.9,0.05,0.03,0.02
26.517195775301374,0.0023072727141962,116.43640278286962,250.0,8.333333333333333e-05,0.67,0.28,0.23,0.05,0.9,0.05,0.03,0.02
26.673326523314373,0.00232028360986395,116.7439577678079,250.0,8.333333333333333e-05,0.67,0.28,0.23,0.05,0.9,0.05,0.03,0.02
26.82945727132737,0.0023332945055317,117.051512752746,250.0,8.333333333333333e-05,0.67,0.28,0.23,0.05,0.9,0.05,0.03,0.02
26.980846510961072,0.002345910275501175,117.34331188222676,250.0,8.333333333333333e-05,0.67,0.28,0.23,0.05,0.9,0.05,0.03,0.02
27.132235750594774,0.00235852604547065,117.63511101170863,250.0,8.333333333333333e-05,0.67,0.28,0.23,0.05,0.9,0.05,0.03,0.02
27.283624990228475,0.002371141815440125,117.92691014118958,250.0,8.333333333333333e-05,0.67,0.28,0.23,0.05,0.9,0.05,0.03,0.02
27.435014229862176,0.0023837575854096,118.21870927066875,250.0,8.333333333333333e-05,0.67,0.28,0.23,0.05,0.9,0.05,0.03,0.02
27.610756566295176,0.0023984027801123497,118.5228275172245,250.0,8.333333333333333e-05,0.67,0.28,0.23,0.05,0.9,0.05,0.03,0.02
27.786498902728177,0.0024130479748151,118.82694576378076,250.0,8.333333333333333e-05,0.67,0.28,0.23,0.05,0.9,0.05,0.03,0.02
27.962241239161177,0.00242769316951785,119.13106401033637,250.0,8.333333333333333e-05,0.67,0.28,0.23,0.05,0.9,0.05,0.03,0.02
28.137983575594177,0.0024423383642206,119.43518225689176,250.0,8.333333333333333e-05,0.67,0.28,0.23,0.05,0.9,0.05,0.03,0.02
28.301439746568576,0.0024559597118018,119.73022538410052,250.0,8.333333333333333e-05,0.67,0.28,0.23,0.05,0.9,0.05,0.03,0.02
28.464895917542975,0.002469581059383,120.02526851130784,250.0,8.333333333333333e-05,0.67,0.28,0.23,0.05,0.9,0.05,0.03,0.02
28.628352088517374,0.0024832024069642,120.32031163851687,250.0,8.333333333333333e-05,0.67,0.28,0.23,0.05,0.9,0.05,0.03,0.02
28.791808259491777,0.0024968237545454,120.61535476572675,250.0,8.333333333333333e-05,0.67,0.28,0.23,0.05,0.9,0.05,0.03,0.02
28.959101847956077,0.0025107648869174253,120.90545361673924,250.0,8.333333333333333e-05,0.67,0.28,0.23,0.05,0.9,0.05,0.03,0.02
29.126395436420378,0.00252470601928945,121.19555246775074,250.0,8.333333333333333e-05,0.67,0.28,0.23,0.05,0.9,0.05,0.03,0.02
29.293689024884678,0.002538647151661475,121.48565131876295,250.0,8.333333333333333e-05,0.67,0.28,0.23,0.05,0.9,0.05,0.03,0.02
29.46098261334898,0.0025525882840335,121.77575016977652,250.0,8.333333333333333e-05,0.67,0.28,0.23,0.05,0.9,0.05,0.03,0.02
29.63798103954838,0.00256733815288345,122.05241645693602,250.0,8.333333333333333e-05,0.67,0.28,0.23,0.05,0.9,0.05,0.03,0.02
29.814979465747776,0.0025820880217334,122.3290827440967,250.0,8.333333333333333e-05,0.67,0.28,0.23,0.05,0.9,0.05,0.03,0.02
29.991977891947176,0.00259683789058335,122.60574903125624,250.0,8.333333333333333e-05,0.67,0.28,0.23,0.05,0.9,0.05,0.03,0.02
30.168976318146576,0.0026115877594333,122.88241531841457,250.0,8.333333333333333e-05,0.67,0.28,0.23,0.05,0.9,0.05,0.03,0.02
30.346238615894073,0.0026263596175789246,123.15622698214582,250.0,8.333333333333333e-05,0.67,0.28,0.23,0.05,0.9,0.05,0.03,0.02
30.523500913641573,0.0026411314757245497,123.43003864587627,250.0,8.333333333333333e-05,0.67,0.28,0.23,0.05,0.9,0.05,0.03,0.02
30.700763211389074,0.002655903333870175,123.70385030960793,250.0,8.333333333333333e-05,0.67,0.28,0.23,0.05,0.9,0.05,0.03,0.02
30.87802550913657,0.0026706751920158,123.97766197334043,250.0,8.333333333333333e-05,0.67,0.28,0.23,0.05,0.9,0.05,0.03,0.02
31.07990185531857,0.0026874982208643,124.25049157773418,250.0,8.333333333333333e-05,0.67,0.28,0.23,0.05,0.9,0.05,0.03,0.02
31.281778201500572,0.0027043212497128,124.5233211821278,250.0,8.333333333333333e-05,0.67,0.28,0.23,0.05,0.9,0.05,0.03,0.02
31.483654547682576,0.0027211442785613,124.79615078652172,250.0,8.333333333333333e-05,0.67,0.28,0.23,0.05,0.9,0.05,0.03,0.02
31.685530893864577,0.0027379673074098,125.06898039091658,250.0,8.333333333333333e-05,0.67,0.28,0.23,0.05,0.9,0.05,0.03,0.02
31.887488952807878,0.002754797145655075,125.32627540270258,250.0,8.333333333333333e-05,0.67,0.28,0.23,0.05,0.9,0.05,0.03,0.02
32.089447011751176,0.00277162698390035,125.58357041448815,250.0,8.333333333333333e-05,0.67,0.28,0.23,0.05,0.9,0.05,0.03,0.02
32.29140507069448,0.002788456822145625,125.84086542627367,250.0,8.333333333333333e-05,0.67,0.28,0.23,0.05,0.9,0.05,0.03,0.02
32.49336312963778,0.0028052866603909,126.09816043805878,250.0,8.333333333333333e-05,0.67,0.28,0.23,0.05,0.9,0.05,0.03,0.02
32.69296399195168,0.0028219200655837254,126.34834449273555,250.0,8.333333333333333e-05,0.67,0.28,0.23,0.05,0.9,0.05,0.03,0.02
32.89256485426558,0.0028385534707765503,126.59852854741197,250.0,8.333333333333333e-05,0.67,0.28,0.23,0.05,0.9,0.05,0.03,0.02
33.09216571657948,0.002855186875969375,126.84871260208863,250.0,8.333333333333333e-05,0.67,0.28,0.23,0.05,0.9,0.05,0.03,0.02
33.29176657889338,0.0028718202811622,127.09889665676502,250.0,8.333333333333333e-05,0.67,0.28,0.23,0.05,0.9,0.05,0.03,0.02
33.509729072603974,0.00288998382230475,127.34890265563877,250.0,8.333333333333333e-05,0.67,0.28,0.23,0.05,0.9,0.05,0.03,0.02
33.727691566314576,0.0029081473634473,127.59890865451207,250.0,8.333333333333333e-05,0.67,0.28,0.23,0.05,0.9,0.05,0.03,0.02
33.94565406002518,0.0029263109045898497,127.84891465338619,250.0,8.333333333333333e-05,0.67,0.28,0.23,0.05,0.9,0.05,0.03,0.02
34.16361655373578,0.0029444744457324,128.0989206522613,250.0,8.333333333333333e-05,0.67,0.28,0.23,0.05,0.9,0.05,0.03,0.02
34.40165029969798,0.00296431059122925,128.3311937148888,250.0,8.333333333333333e-05,0.67,0.28,0.23,0.05,0.9,0.05,0.03,0.02
34.639684045660175,0.0029841467367261003,128.5634667775154,250.0,8.333333333333333e-05,0.67,0.28,0.23,0.05,0.9,0.05,0.03,0.02
34.87771779162237,0.00300398288222295,128.79573984014283,250.0,8.333333333333333e-05,0.67,0.28,0.23,0.05,0.9,0.05,0.03,0.02
35.11575153758458,0.0030238190277198,129.0280129027716,250.0,8.333333333333333e-05,0.67,0.28,0.23,0.05,0.9,0.05,0.03,0.02
35.33747764595488,0.003042296203417325,129.25487567882985,250.0,8.333333333333333e-05,0.67,0.28,0.23,0.05,0.9,0.05,0.03,0.02
35.55920375432518,0.00306077337911485,129.48173845488648,250.0,8.333333333333333e-05,0.67,0.28,0.23,0.05,0.9,0.05,0.03,0.02
35.78092986269549,0.0030792505548123753,129.7086012309445,250.0,8.333333333333333e-05,0.67,0.28,0.23,0.05,0.9,0.05,0.03,0.02
36.002655971065785,0.0030977277305099,129.9354640070048,250.0,8.333333333333333e-05,0.67,0.28,0.23,0.05,0.9,0.05,0.03,0.02
36.249102646053885,0.0031182649534255754,130.14691282167732,250.0,8.333333333333333e-05,0.67,0.28,0.23,0.05,0.9,0.05,0.03,0.02
36.49554932104198,0.00313880217634125,130.3583616363494,250.0,8.333333333333333e-05,0.67,0.28,0.23,0.05,0.9,0.05,0.03,0.02
36.74199599603008,0.003159339399256925,130.56981045102205,250.0,8.333333333333333e-05,0.67,0.28,0.23,0.05,0.9,0.05,0.03,0.02
36.98844267101818,0.0031798766221726,130.78125926569388,250.0,8.333333333333333e-05,0.67,0.28,0.23,0.05,0.9,0.05,0.03,0.02
37.26116980904338,0.0032026038836747003,130.97158290780737,250.0,8.333333333333333e-05,0.67,0.28,0.23,0.05,0.9,0.05,0.03,0.02
37.53389694706858,0.0032253311451768,131.16190654992104,250.0,8.333333333333333e-05,0.67,0.28,0.23,0.05,0.9,0.05,0.03,0.02
37.80662408509377,0.0032480584066789,131.35223019203443,250.0,8.333333333333333e-05,0.67,0.28,0.23,0.05,0.9,0.05,0.03,0.02
38.07935122311898,0.003270785668181,131.54255383414846,250.0,8.333333333333333e-05,0.67,0.28,0.23,0.05,0.9,0.05,0.03,0.02
38.35909538393878,0.00329409768158265,131.72774359994145,250.0,8.333333333333333e-05,0.67,0.28,0.23,0.05,0.9,0.05,0.03,0.02
38.63883954475858,0.0033174096949843,131.91293336573443,250.0,8.333333333333333e-05,0.67,0.28,0.23,0.05,0.9,0.05,0.03,0.02
38.918583705578385,0.00334072170838595,132.0981231315276,250.0,8.333333333333333e-05,0.67,0.28,0.23,0.05,0.9,0.05,0.03,0.02
39.19832786639818,0.0033640337217876,132.28331289732074,250.0,8.333333333333333e-05,0.67,0.28,0.23,0.05,0.9,0.05,0.03,0.02
39.48958373842228,0.003388305044456275,132.43634056535774,250.0,8.333333333333333e-05,0.67,0.28,0.23,0.05,0.9,0.05,0.03,0.02
39.78083961044638,0.00341257636712495,132.58936823339408,250.0,8.333333333333333e-05,0.67,0.28,0.23,0.05,0.9,0.05,0.03,0.02
40.07209548247048,0.003436847689793625,132.74239590143122,250.0,8.333333333333333e-05,0.67,0.28,0.23,0.05,0.9,0.05,0.03,0.02
40.36335135449458,0.0034611190124623,132.8954235694684,250.0,8.333333333333333e-05,0.67,0.28,0.23,0.05,0.9,0.05,0.03,0.02
40.671441118377885,0.0034867931594525755,133.0335349809009,250.0,8.333333333333333e-05,0.67,0.28,0.23,0.05,0.9,0.05,0.03,0.02
40.97953088226118,0.0035124673064428503,133.1716463923339,250.0,8.333333333333333e-05,0.67,0.28,0.23,0.05,0.9,0.05,0.03,0.02
41.287620646144475,0.003538141453433125,133.30975780376625,250.0,8.333333333333333e-05,0.67,0.28,0.23,0.05,0.9,0.05,0.03,0.02
41.59571041002778,0.0035638156004234,133.447869215198,250.0,8.333333333333333e-05,0.67,0.28,0.23,0.05,0.9,0.05,0.03,0.02
41.901876618113675,0.003589329451097225,133.57986005740327,250.0,8.333333333333333e-05,0.67,0.28,0.23,0.05,0.9,0.05,0.03,0.02
42.20804282619957,0.00361484330177105,133.7118508996079,250.0,8.333333333333333e-05,0.67,0.28,0.23,0.05,0.9,0.05,0.03,0.02
42.51420903428547,0.0036403571524448747,133.84384174181284,250.0,8.333333333333333e-05,0.67,0.28,0.23,0.05,0.9,0.05,0.03,0.02
42.82037524237138,0.0036658710031187,133.97583258401843,250.0,8.333333333333333e-05,0.67,0.28,0.23,0.05,0.9,0.05,0.03,0.02
43.18102934118838,0.00369592551135345,134.0895107274507,250.0,8.333333333333333e-05,0.67,0.28,0.23,0.05,0.9,0.05,0.03,0.02
43.54168344000538,0.0037259800195882002,134.20318887088297,250.0,8.333333333333333e-05,0.67,0.28,0.23,0.05,0.9,0.05,0.03,0.02
43.90233753882238,0.0037560345278229504,134.3168670143154,250.0,8.333333333333333e-05,0.67,0.28,0.23,0.05,0.9,0.05,0.03,0.02
44.26299163763938,0.0037860890360577,134.4305451577482,250.0,8.333333333333333e-05,0.67,0.28,0.23,0.05,0.9,0.05,0.03,0.02
44.62536569972248,0.003816286874564625,134.53353454715696,250.0,8.333333333333333e-05,0.67,0.28,0.23,0.05,0.9,0.05,0.03,0.02
44.987739761805585,0.0038464847130715504,134.63652393656446,250.0,8.333333333333333e-05,0.67,0.28,0.23,0.05,0.9,0.05,0.03,0.02
45.350113823888684,0.0038766825515784754,134.7395133259734,250.0,8.333333333333333e-05,0.67,0.28,0.23,0.05,0.9,0.05,0.03,0.02
45.71248788597178,0.0039068803900854,134.84250271538212,250.0,8.333333333333333e-05,0.67,0.28,0.23,0.05,0.9,0.05,0.03,0.02
46.052971230072885,0.003935254002093826,134.93989277254136,250.0,8.333333333333333e-05,0.67,0.28,0.23,0.05,0.9,0.05,0.03,0.02
46.39345457417398,0.003963627614102251,135.03728282970087,250.0,8.333333333333333e-05,0.67,0.28,0.23,0.05,0.9,0.05,0.03,0.02
46.733937918275075,0.0039920012261106756,135.13467288686022,250.0,8.333333333333333e-05,0.67,0.28,0.23,0.05,0.9,0.05,0.03,0.02
47.07442126237618,0.0040203748381191,135.23206294402024,250.0,8.333333333333333e-05,0.67,0.28,0.23,0.05,0.9,0.05,0.03,0.02
47.44977698661058,0.0040516544818053005,135.31628282013673,250.0,8.333333333333333e-05,0.67,0.28,0.23,0.05,0.9,0.05,0.03,0.02
47.82513271084498,0.004082934125491501,135.40050269625303,250.0,8.333333333333333e-05,0.67,0.28,0.23,0.05,0.9,0.05,0.03,0.02
48.20048843507938,0.004114213769177701,135.4847225723695,250.0,8.333333333333333e-05,0.67,0.28,0.23,0.05,0.9,0.05,0.03,0.02
48.57584415931378,0.0041454934128639,135.56894244848627,250.0,8.333333333333333e-05,0.67,0.28,0.23,0.05,0.9,0.05,0.03,0.02
48.96831714352378,0.0041781994948814,135.63935500001577,250.0,8.333333333333333e-05,0.67,0.28,0.23,0.05,0.9,0.05,0.03,0.02
49.36079012773378,0.0042109055768989,135.7097675515456,250.0,8.333333333333333e-05,0.67,0.28,0.23,0.05,0.9,0.05,0.03,0.02
49.75326311194378,0.0042436116589164,135.7801801030748,250.0,8.333333333333333e-05,0.67,0.28,0.23,0.05,0.9,0.05,0.03,0.02
50.14573609615378,0.0042763177409339,135.85059265460202,250.0,8.333333333333333e-05,0.67,0.28,0.23,0.05,0.9,0.05,0.03,0.02
50.54218229295028,0.004309354924000275,135.9105415643848,250.0,8.333333333333333e-05,0.67,0.28,0.23,0.05,0.9,0.05,0.03,0.02
50.938628489746776,0.004342392107066649,135.97049047416877,250.0,8.333333333333333e-05,0.67,0.28,0.23,0.05,0.9,0.05,0.03,0.02
51.33507468654328,0.0043754292901330245,136.0304393839519,250.0,8.333333333333333e-05,0.67,0.28,0.23,0.05,0.9,0.05,0.03,0.02
51.731520883339776,0.0044084664731994,136.09038829373432,250.0,8.333333333333333e-05,0.67,0.28,0.23,0.05,0.9,0.05,0.03,0.02
52.11858678610018,0.0044407219650961,136.14343481248483,250.0,8.333333333333333e-05,0.67,0.28,0.23,0.05,0.9,0.05,0.03,0.02
52.50565268886058,0.0044729774569928,136.19648133123752,250.0,8.333333333333333e-05,0.67,0.28,0.23,0.05,0.9,0.05,0.03,0.02
52.89271859162098,0.0045052329488895,136.24952784998794,250.0,8.333333333333333e-05,0.67,0.28,0.23,0.05,0.9,0.05,0.03,0.02
53.27978449438138,0.0045374884407862,136.30257436873862,250.0,8.333333333333333e-05,0.67,0.28,0.23,0.05,0.9,0.05,0.03,0.02
53.69004657390448,0.004571676947413126,136.35495490888536,250.0,8.333333333333333e-05,0.67,0.28,0.23,0.05,0.9,0.05,0.03,0.02
54.10030865342758,0.00460586545404005,136.40733544903,250.0,8.333333333333333e-05,0.67,0.28,0.23,0.05,0.9,0.05,0.03,0.02
54.51057073295068,0.004640053960666975,136.4597159891764,250.0,8.333333333333333e-05,0.67,0.28,0.23,0.05,0.9,0.05,0.03,0.02
54.92083281247378,0.0046742424672939,136.51209652932434,250.0,8.333333333333333e-05,0.67,0.28,0.23,0.05,0.9,0.05,0.03,0.02
55.34684012932769,0.004709743077031725,136.55407262256608,250.0,8.333333333333333e-05,0.67,0.28,0.23,0.05,0.9,0.05,0.03,0.02
55.772847446181586,0.004745243686769551,136.59604871580729,250.0,8.333333333333333e-05,0.67,0.28,0.23,0.05,0.9,0.05,0.03,0.02
56.198854763035484,0.004780744296507376,136.6380248090494,250.0,8.333333333333333e-05,0.67,0.28,0.23,0.05,0.9,0.05,0.03,0.02
56.62486207988938,0.0048162449062452,136.68000090229214,250.0,8.333333333333333e-05,0.67,0.28,0.23,0.05,0.9,0.05,0.03,0.02
57.06587891026438,0.004852996308776451,136.7160104746744,250.0,8.333333333333333e-05,0.67,0.28,0.23,0.05,0.9,0.05,0.03,0.02
57.50689574063938,0.0048897477113077,136.7520200470555,250.0,8.333333333333333e-05,0.67,0.28,0.23,0.05,0.9,0.05,0.03,0.02
57.94791257101438,0.0049264991138389495,136.78802961943768,250.0,8.333333333333333e-05,0.67,0.28,0.23,0.05,0.9,0.05,0.03,0.02
58.388929401389376,0.0049632505163702,136.8240391918198,250.0,8.333333333333333e-05,0.67,0.28,0.23,0.05,0.9,0.05,0.03,0.02
58.836230765721275,0.005000525630064525,136.84534763987855,250.0,8.333333333333333e-05,0.67,0.28,0.23,0.05,0.9,0.05,0.03,0.02
59.283532130053175,0.00503780074375885,136.86665608793766,250.0,8.333333333333333e-05,0.67,0.28,0.23,0.05,0.9,0.05,0.03,0.02
59.73083349438508,0.0050750758574531745,136.88796453599622,250.0,8.333333333333333e-05,0.67,0.28,0.23,0.05,0.9,0.05,0.03,0.02
60.17813485871698,0.0051123509711475,136.90927298405535,250.0,8.333333333333333e-05,0.67,0.28,0.23,0.05,0.9,0.05,0.03,0.02
60.63187872866398,0.00515016296030975,136.9346830481331,250.0,8.333333333333333e-05,0.67,0.28,0.23,0.05,0.9,0.05,0.03,0.02
61.08562259861098,0.005187974949472,136.9600931122107,250.0,8.333333333333333e-05,0.67,0.28,0.23,0.05,0.9,0.05,0.03,0.02
61.53936646855798,0.00522578693863425,136.98550317628874,250.0,8.333333333333333e-05,0.67,0.28,0.23,0.05,0.9,0.05,0.03,0.02
61.99311033850498,0.0052635989277965,137.01091324036648,250.0,8.333333333333333e-05,0.67,0.28,0.23,0.05,0.9,0.05,0.03,0.02
62.46756479083828,0.005303136798824275,137.0334737937835,250.0,8.333333333333333e-05,0.67,0.28,0.23,0.05,0.9,0.05,0.03,0.02
62.94201924317158,0.00534267466985205,137.05603434720013,250.0,8.333333333333333e-05,0.67,0.28,0.23,0.05,0.9,0.05,0.03,0.02
63.41647369550488,0.005382212540879825,137.0785949006169,250.0,8.333333333333333e-05,0.67,0.28,0.23,0.05,0.9,0.05,0.03,0.02
63.89092814783818,0.0054217504119076,137.1011554540331,250.0,8.333333333333333e-05,0.67,0.28,0.23,0.05,0.9,0.05,0.03,0.02
64.40054379591298,0.0054642183825805,137.11220451363758,250.0,8.333333333333333e-05,0.67,0.28,0.23,0.05,0.9,0.05,0.03,0.02
64.91015944398778,0.005506686353253401,137.1232535732429,250.0,8.333333333333333e-05,0.67,0.28,0.23,0.05,0.9,0.05,0.03,0.02
65.41977509206258,0.0055491543239263,137.13430263284732,250.0,8.333333333333333e-05,0.67,0.28,0.23,0.05,0.9,0.05,0.03,0.02
65.92939074013738,0.0055916222945992,137.14535169245204,250.0,8.333333333333333e-05,0.67,0.28,0.23,0.05,0.9,0.05,0.03,0.02
66.43648289171938,0.0056338799738977,137.15056039894176,250.0,8.333333333333333e-05,0.67,0.28,0.23,0.05,0.9,0.05,0.03,0.02
66.94357504330138,0.0056761376531962,137.15576910543123,250.0,8.333333333333333e-05,0.67,0.28,0.23,0.05,0.9,0.05,0.03,0.02
67.45066719488338,0.0057183953324946996,137.16097781192116,250.0,8.333333333333333e-05,0.67,0.28,0.23,0.05,0.9,0.05,0.03,0.02
67.95775934646538,0.0057606530117932,137.1661865184106,250.0,8.333333333333333e-05,0.67,0.28,0.23,0.05,0.9,0.05,0.03,0.02
68.47017344259208,0.005803354186470425,137.16957015291734,250.0,8.333333333333333e-05,0.67,0.28,0.23,0.05,0.9,0.05,0.03,0.02
68.98258753871878,0.00584605536114765,137.17295378742403,250.0,8.333333333333333e-05,0.67,0.28,0.23,0.05,0.9,0.05,0.03,0.02
69.49500163484548,0.005888756535824875,137.17633742193092,250.0,8.333333333333333e-05,0.67,0.28,0.23,0.05,0.9,0.05,0.03,0.02
70.00741573097218,0.0059314577105021,137.17972105643855,250.0,8.333333333333333e-05,0.67,0.28,0.23,0.05,0.9,0.05,0.03,0.02
70.51656437979358,0.00597388676457055,137.17974607771455,250.0,8.333333333333333e-05,0.67,0.28,0.23,0.05,0.9,0.05,0.03,0.02
71.02571302861497,0.006016315818639,137.17977109899016,250.0,8.333333333333333e-05,0.67,0.28,0.23,0.05,0.9,0.05,0.03,0.02
71.53486167743637,0.006058744872707449,137.17979612026605,250.0,8.333333333333333e-05,0.67,0.28,0.23,0.05,0.9,0.05,0.03,0.02
72.04401032625778,0.0061011739267759,137.179821141542,250.0,8.333333333333333e-05,0.67,0.28,0.23,0.05,0.9,0.05,0.03,0.02