File: datasets/al_6061_comp/csv/T_300_A_1.csv
Time,Strain(%),Stress(MPa),Temp(C),SR(%/s),Si(%),Fe(%),Cu(%),Mn(%),Mg(%),Cr(%),Zn(%),Ti(%)
0.0,9.32996804869509e-05,1.3355073416374,300.0,8.333333333333333e-05,0.56,0.23,0.18,0.07,0.86,0.06,0.02,0.01
0.06315694907722366,9.856275957671954e-05,1.5506168353119398,300.0,8.333333333333333e-05,0.56,0.23,0.18,0.07,0.86,0.06,0.02,0.01
0.12631389815444732,0.00010382583866648819,1.7657263289864815,300.0,8.333333333333333e-05,0.56,0.23,0.18,0.07,0.86,0.06,0.02,0.01
0.18947084723167099,0.00010908891775625682,1.9808358226610219,300.0,8.333333333333333e-05,0.56,0.23,0.18,0.07,0.86,0.06,0.02,0.01
0.25262779630889465,0.00011435199684602546,2.1959453163355613,300.0,8.333333333333333e-05,0.56,0.23,0.18,0.07,0.86,0.06,0.02,0.01
0.31578474538611834,0.0001196150759357941,2.411054810010101,300.0,8.333333333333333e-05,0.56,0.23,0.18,0.07,0.86,0.06,0.02,0.01
0.37894169446334197,0.00012487815502556273,2.6261643036846403,300.0,8.333333333333333e-05,0.56,0.23,0.18,0.07,0.86,0.06,0.02,0.01
0.4420986435405656,0.00013014123411533136,2.841273797359179,300.0,8.333333333333333e-05,0.56,0.23,0.18,0.07,0.86,0.06,0.02,0.01
0.5052555926177893,0.0001354043132051,3.056383291033719,300.0,8.333333333333333e-05,0.56,0.23,0.18,0.07,0.86,0.06,0.02,0.01
0.5617960458116893,0.000140116017637925,3.261638690064463,300.0,8.333333333333333e-05,0.56,0.23,0.18,0.07,0.86,0.06,0.02,0.01
0.6183364990055893,0.00014482772207075002,3.466894089095208,300.0,8.333333333333333e-05,0.56,0.23,0.18,0.07,0.86,0.06,0.02,0.01
0.6748769521994893,0.00014953942650357502,3.6721494881259527,300.0,8.333333333333333e-05,0.56,0.23,0.18,0.07,0.86,0.06,0.02,0.01
0.7314174053933893,0.0001542511309364,3.877404887156698,300.0,8.333333333333333e-05,0.56,0.23,0.18,0.07,0.86,0.06,0.02,0.01
0.7879578585872893,0.000158962835369225,4.082660286187442,300.0,8.333333333333333e-05,0.56,0.23,0.18,0.07,0.86,0.06,0.02,0.01
0.8444983117811893,0.00016367453980205,4.287915685218189,300.0,8.333333333333333e-05,0.56,0.23,0.18,0.07,0.86,0.06,0.02,0.01
0.9010387649750893,0.000168386244234875,4.493171084248931,300.0,8.333333333333333e-05,0.56,0.23,0.18,0.07,0.86,0.06,0.02,0.01
0.9575792181689892,0.0001730979486677,4.69842648327966,300.0,8.333333333333333e-05,0.56,0.23,0.18,0.07,0.86,0.06,0.02,0.01
1.0021734637586892,0.000176814135800175,4.905292161211151,300.0,8.333333333333333e-05,0.56,0.23,0.18,0.07,0.86,0.06,0.02,0.01
1.0467677093483891,0.00018053032293265,5.112157839142662,300.0,8.333333333333333e-05,0.56,0.23,0.18,0.07,0.86,0.06,0.02,0.01
1.091361954938089,0.000184246510065125,5.31902351707416,300.0,8.333333333333333e-05,0.56,0.23,0.18,0.07,0.86,0.06,0.02,0.01
1.1359562005277892,0.00018796269719760001,5.525889195005629,300.0,8.333333333333333e-05,0.56,0.23,0.18,0.07,0.86,0.06,0.02,0.01
1.1805504461174892,0.00019167888433007502,5.732754872937123,300.0,8.333333333333333e-05,0.56,0.23,0.18,0.07,0.86,0.06,0.02,0.01
1.225144691707189,0.00019539507146255002,5.939620550868652,300.0,8.333333333333333e-05,0.56,0.23,0.18,0.07,0.86,0.06,0.02,0.01
1.2697389372968892,0.00019911125859502503,6.146486228800137,300.0,8.333333333333333e-05,0.56,0.23,0.18,0.07,0.86,0.06,0.02,0.01
1.3143331828865892,0.0002028274457275,6.353351906731604,300.0,8.333333333333333e-05,0.56,0.23,0.18,0.07,0.86,0.06,0.02,0.01
1.4377907104676892,0.000213115573025925,6.739157482575296,300.0,8.333333333333333e-05,0.56,0.23,0.18,0.07,0.86,0.06,0.02,0.01
1.561248238048789,0.00022340370032435,7.124963058418987,300.0,8.333333333333333e-05,0.56,0.23,0.18,0.07,0.86,0.06,0.02,0.01
1.6847057656298892,0.000233691827622775,7.510768634262679,300.0,8.333333333333333e-05,0.56,0.23,0.18,0.07,0.86,0.06,0.02,0.01
1.8081632932109892,0.00024397995492120002,7.896574210106371,300.0,8.333333333333333e-05,0.56,0.23,0.18,0.07,0.86,0.06,0.02,0.01
1.931620820792089,0.00025426808221962503,8.282379785950061,300.0,8.333333333333333e-05,0.56,0.23,0.18,0.07,0.86,0.06,0.02,0.01
2.055078348373189,0.00026455620951805004,8.668185361793766,300.0,8.333333333333333e-05,0.56,0.23,0.18,0.07,0.86,0.06,0.02,0.01
2.1785358759542888,0.000274844336816475,9.053990937637462,300.0,8.333333333333333e-05,0.56,0.23,0.18,0.07,0.86,0.06,0.02,0.01
2.301993403535389,0.0002851324641149,9.439796513481163,300.0,8.333333333333333e-05,0.56,0.23,0.18,0.07,0.86,0.06,0.02,0.01
2.4122140665776888,0.000294317519368425,9.877365715859947,300.0,8.333333333333333e-05,0.56,0.23,0.18,0.07,0.86,0.06,0.02,0.01
2.522434729619989,0.00030350257462195005,10.314934918238716,300.0,8.333333333333333e-05,0.56,0.23,0.18,0.07,0.86,0.06,0.02,0.01
2.632655392662289,0.00031268762987547504,10.752504120617491,300.0,8.333333333333333e-05,0.56,0.23,0.18,0.07,0.86,0.06,0.02,0.01
2.7428760557045893,0.00032187268512900004,11.190073322996284,300.0,8.333333333333333e-05,0.56,0.23,0.18,0.07,0.86,0.06,0.02,0.01
2.8530967187468894,0.00033105774038252504,11.627642525375066,300.0,8.333333333333333e-05,0.56,0.23,0.18,0.07,0.86,0.06,0.02,0.01
2.9633173817891896,0.00034024279563605003,12.065211727753823,300.0,8.333333333333333e-05,0.56,0.23,0.18,0.07,0.86,0.06,0.02,0.01
3.0735380448314897,0.000349427850889575,12.502780930132602,300.0,8.333333333333333e-05,0.56,0.23,0.18,0.07,0.86,0.06,0.02,0.01
3.18375870787379,0.0003586129061431,12.940350132511382,300.0,8.333333333333333e-05,0.56,0.23,0.18,0.07,0.86,0.06,0.02,0.01
3.2781187008377897,0.0003664762388901,13.383098864130941,300.0,8.333333333333333e-05,0.56,0.23,0.18,0.07,0.86,0.06,0.02,0.01
3.37247869380179,0.0003743395716371,13.825847595750513,300.0,8.333333333333333e-05,0.56,0.23,0.18,0.07,0.86,0.06,0.02,0.01
3.46683868676579,0.00038220290438410005,14.268596327370084,300.0,8.333333333333333e-05,0.56,0.23,0.18,0.07,0.86,0.06,0.02,0.01
3.56119867972979,0.0003900662371311,14.711345058989643,300.0,8.333333333333333e-05,0.56,0.23,0.18,0.07,0.86,0.06,0.02,0.01
3.6555586726937896,0.0003979295698781,15.154093790609199,300.0,8.333333333333333e-05,0.56,0.23,0.18,0.07,0.86,0.06,0.02,0.01
3.74991866565779,0.0004057929026251,15.596842522228776,300.0,8.333333333333333e-05,0.56,0.23,0.18,0.07,0.86,0.06,0.02,0.01
3.84427865862179,0.00041365623537210005,16.039591253848332,300.0,8.333333333333333e-05,0.56,0.23,0.18,0.07,0.86,0.06,0.02,0.01
3.93863865158579,0.0004215195681191,16.48233998546789,300.0,8.333333333333333e-05,0.56,0.23,0.18,0.07,0.86,0.06,0.02,0.01
4.05737282274869,0.00043141408238267504,16.899268836140912,300.0,8.333333333333333e-05,0.56,0.23,0.18,0.07,0.86,0.06,0.02,0.01
4.17610699391159,0.00044130859664625005,17.31619768681392,300.0,8.333333333333333e-05,0.56,0.23,0.18,0.07,0.86,0.06,0.02,0.01
4.29484116507449,0.000451203110909825,17.73312653748693,300.0,8.333333333333333e-05,0.56,0.23,0.18,0.07,0.86,0.06,0.02,0.01
4.41357533623739,0.0004610976251734,18.150055388159902,300.0,8.333333333333333e-05,0.56,0.23,0.18,0.07,0.86,0.06,0.02,0.01
4.5323095074002895,0.00047099213943697503,18.56698423883293,300.0,8.333333333333333e-05,0.56,0.23,0.18,0.07,0.86,0.06,0.02,0.01
4.651043678563189,0.00048088665370055,18.983913089505986,300.0,8.333333333333333e-05,0.56,0.23,0.18,0.07,0.86,0.06,0.02,0.01
4.76977784972609,0.0004907811679641251,19.400841940179024,300.0,8.333333333333333e-05,0.56,0.23,0.18,0.07,0.86,0.06,0.02,0.01
4.88851202088899,0.0005006756822277,19.817770790852144,300.0,8.333333333333333e-05,0.56,0.23,0.18,0.07,0.86,0.06,0.02,0.01
4.99278476139329,0.000509365077269725,20.228742425456282,300.0,8.333333333333333e-05,0.56,0.23,0.18,0.07,0.86,0.06,0.02,0.01
5.09705750189759,0.00051805447231175,20.639714060060392,300.0,8.333333333333333e-05,0.56,0.23,0.18,0.07,0.86,0.06,0.02,0.01
5.201330242401889,0.000526743867353775,21.050685694664523,300.0,8.333333333333333e-05,0.56,0.23,0.18,0.07,0.86,0.06,0.02,0.01
5.30560298290619,0.0005354332623958001,21.461657329268668,300.0,8.333333333333333e-05,0.56,0.23,0.18,0.07,0.86,0.06,0.02,0.01
5.40987572341049,0.0005441226574378251,21.8726289638728,300.0,8.333333333333333e-05,0.56,0.23,0.18,0.07,0.86,0.06,0.02,0.01
5.51414846391479,0.0005528120524798501,22.283600598476987,300.0,8.333333333333333e-05,0.56,0.23,0.18,0.07,0.86,0.06,0.02,0.01
5.618421204419089,0.0005615014475218751,22.694572233081125,300.0,8.333333333333333e-05,0.56,0.23,0.18,0.07,0.86,0.06,0.02,0.01
5.72269394492339,0.0005701908425639,23.105543867685164,300.0,8.333333333333333e-05,0.56,0.23,0.18,0.07,0.86,0.06,0.02,0.01
5.82990629330099,0.0005791252049287,23.51375523361955,300.0,8.333333333333333e-05,0.56,0.23,0.18,0.07,0.86,0.06,0.02,0.01
5.937118641678589,0.0005880595672935,23.92196659955394,300.0,8.333333333333333e-05,0.56,0.23,0.18,0.07,0.86,0.06,0.02,0.01
6.0443309900561895,0.0005969939296583,24.330177965488325,300.0,8.333333333333333e-05,0.56,0.23,0.18,0.07,0.86,0.06,0.02,0.01
6.15154333843379,0.0006059282920231,24.738389331422717,300.0,8.333333333333333e-05,0.56,0.23,0.18,0.07,0.86,0.06,0.02,0.01
6.25875568681139,0.0006148626543879,25.1466006973571,300.0,8.333333333333333e-05,0.56,0.23,0.18,0.07,0.86,0.06,0.02,0.01
6.36596803518899,0.0006237970167527,25.554812063291394,300.0,8.333333333333333e-05,0.56,0.23,0.18,0.07,0.86,0.06,0.02,0.01
6.473180383566589,0.0006327313791175,25.96302342922578,300.0,8.333333333333333e-05,0.56,0.23,0.18,0.07,0.86,0.06,0.02,0.01
6.5803927319441895,0.0006416657414823,26.37123479516036,300.0,8.333333333333333e-05,0.56,0.23,0.18,0.07,0.86,0.06,0.02,0.01
6.717636167974339,0.0006531026944848126,26.775250329211925,300.0,8.333333333333333e-05,0.56,0.23,0.18,0.07,0.86,0.06,0.02,0.01
6.8548796040044895,0.0006645396474873251,27.179265863263463,300.0,8.333333333333333e-05,0.56,0.23,0.18,0.07,0.86,0.06,0.02,0.01
6.99212304003464,0.0006759766004898375,27.583281397315027,300.0,8.333333333333333e-05,0.56,0.23,0.18,0.07,0.86,0.06,0.02,0.01
7.1293664760647895,0.00068741355349235,27.987296931366544,300.0,8.333333333333333e-05,0.56,0.23,0.18,0.07,0.86,0.06,0.02,0.01
7.266609912094939,0.0006988505064948625,28.39131246541811,300.0,8.333333333333333e-05,0.56,0.23,0.18,0.07,0.86,0.06,0.02,0.01
7.403853348125089,0.000710287459497375,28.79532799946962,300.0,8.333333333333333e-05,0.56,0.23,0.18,0.07,0.86,0.06,0.02,0.01
7.54109678415524,0.0007217244124998875,29.199343533521212,300.0,8.333333333333333e-05,0.56,0.23,0.18,0.07,0.86,0.06,0.02,0.01
7.678340220185389,0.0007331613655024,29.60335906757284,300.0,8.333333333333333e-05,0.56,0.23,0.18,0.07,0.86,0.06,0.02,0.01
7.8049395608813885,0.0007437113105604001,29.992410932350566,300.0,8.333333333333333e-05,0.56,0.23,0.18,0.07,0.86,0.06,0.02,0.01
7.9315389015773885,0.0007542612556184,30.381462797128393,300.0,8.333333333333333e-05,0.56,0.23,0.18,0.07,0.86,0.06,0.02,0.01
8.058138242273388,0.0007648112006764,30.77051466190609,300.0,8.333333333333333e-05,0.56,0.23,0.18,0.07,0.86,0.06,0.02,0.01
8.184737582969388,0.0007753611457344,31.159566526683633,300.0,8.333333333333333e-05,0.56,0.23,0.18,0.07,0.86,0.06,0.02,0.01
8.311336923665388,0.0007859110907924,31.548618391461364,300.0,8.333333333333333e-05,0.56,0.23,0.18,0.07,0.86,0.06,0.02,0.01
8.437936264361388,0.0007964610358504,31.93767025623907,300.0,8.333333333333333e-05,0.56,0.23,0.18,0.07,0.86,0.06,0.02,0.01
8.564535605057388,0.0008070109809084,32.32672212101685,300.0,8.333333333333333e-05,0.56,0.23,0.18,0.07,0.86,0.06,0.02,0.01
8.691134945753388,0.0008175609259664,32.71577398579484,300.0,8.333333333333333e-05,0.56,0.23,0.18,0.07,0.86,0.06,0.02,0.01
8.815283348069539,0.0008279066261594125,33.095987416910454,300.0,8.333333333333333e-05,0.56,0.23,0.18,0.07,0.86,0.06,0.02,0.01
8.939431750385689,0.000838252326352425,33.476200848025854,300.0,8.333333333333333e-05,0.56,0.23,0.18,0.07,0.86,0.06,0.02,0.01
9.063580152701839,0.0008485980265454375,33.85641427914143,300.0,8.333333333333333e-05,0.56,0.23,0.18,0.07,0.86,0.06,0.02,0.01
9.187728555017989,0.00085894372673845,34.23662771025699,300.0,8.333333333333333e-05,0.56,0.23,0.18,0.07,0.86,0.06,0.02,0.01
9.311876957334139,0.0008692894269314625,34.616841141372596,300.0,8.333333333333333e-05,0.56,0.23,0.18,0.07,0.86,0.06,0.02,0.01
9.436025359650289,0.000879635127124475,34.997054572488096,300.0,8.333333333333333e-05,0.56,0.23,0.18,0.07,0.86,0.06,0.02,0.01
9.560173761966439,0.0008899808273174876,35.37726800360368,300.0,8.333333333333333e-05,0.56,0.23,0.18,0.07,0.86,0.06,0.02,0.01
9.68432216428259,0.0009003265275105,35.75748143471946,300.0,8.333333333333333e-05,0.56,0.23,0.18,0.07,0.86,0.06,0.02,0.01
9.818612887580688,0.000911517421118675,36.127407213241206,300.0,8.333333333333333e-05,0.56,0.23,0.18,0.07,0.86,0.06,0.02,0.01
9.952903610878788,0.00092270831472685,36.49733299176297,300.0,8.333333333333333e-05,0.56,0.23,0.18,0.07,0.86,0.06,0.02,0.01
10.087194334176889,0.000933899208335025,36.86725877028478,300.0,8.333333333333333e-05,0.56,0.23,0.18,0.07,0.86,0.06,0.02,0.01
10.22148505747499,0.0009450901019432,37.237184548806404,300.0,8.333333333333333e-05,0.56,0.23,0.18,0.07,0.86,0.06,0.02,0.01
10.35577578077309,0.000956280995551375,37.607110327328165,300.0,8.333333333333333e-05,0.56,0.23,0.18,0.07,0.86,0.06,0.02,0.01
10.490066504071189,0.0009674718891595499,37.97703610585024,300.0,8.333333333333333e-05,0.56,0.23,0.18,0.07,0.86,0.06,0.02,0.01
10.624357227369288,0.000978662782767725,38.34696188437201,300.0,8.333333333333333e-05,0.56,0.23,0.18,0.07,0.86,0.06,0.02,0.01
10.758647950667388,0.0009898536763759,38.71688766289344,300.0,8.333333333333333e-05,0.56,0.23,0.18,0.07,0.86,0.06,0.02,0.01
10.876389461852987,0.0009996654689747,39.070450323941536,300.0,8.333333333333333e-05,0.56,0.23,0.18,0.07,0.86,0.06,0.02,0.01
10.994130973038589,0.0010094772615735,39.42401298498972,300.0,8.333333333333333e-05,0.56,0.23,0.18,0.07,0.86,0.06,0.02,0.01
11.11187248422419,0.0010192890541723,39.77757564603773,300.0,8.333333333333333e-05,0.56,0.23,0.18,0.07,0.86,0.06,0.02,0.01
11.229613995409789,0.0010291008467711,40.13113830708587,300.0,8.333333333333333e-05,0.56,0.23,0.18,0.07,0.86,0.06,0.02,0.01
11.347355506595388,0.0010389126393699,40.48470096813395,300.0,8.333333333333333e-05,0.56,0.23,0.18,0.07,0.86,0.06,0.02,0.01
11.46509701778099,0.0010487244319687,40.838263629181945,300.0,8.333333333333333e-05,0.56,0.23,0.18,0.07,0.86,0.06,0.02,0.01
11.58283852896659,0.0010585362245675001,41.19182629023008,300.0,8.333333333333333e-05,0.56,0.23,0.18,0.07,0.86,0.06,0.02,0.01
11.70058004015219,0.0010683480171663,41.54538895127806,300.0,8.333333333333333e-05,0.56,0.23,0.18,0.07,0.86,0.06,0.02,0.01
11.83068305259329,0.001079189934869725,41.8866429113615,300.0,8.333333333333333e-05,0.56,0.23,0.18,0.07,0.86,0.06,0.02,0.01
11.96078606503439,0.00109003185257315,42.22789687144489,300.0,8.333333333333333e-05,0.56,0.23,0.18,0.07,0.86,0.06,0.02,0.01
12.090889077475488,0.001100873770276575,42.56915083152832,300.0,8.333333333333333e-05,0.56,0.23,0.18,0.07,0.86,0.06,0.02,0.01
12.220992089916589,0.0011117156879799999,42.91040479161223,300.0,8.333333333333333e-05,0.56,0.23,0.18,0.07,0.86,0.06,0.02,0.01
12.35109510235769,0.001122557605683425,43.25165875169566,300.0,8.333333333333333e-05,0.56,0.23,0.18,0.07,0.86,0.06,0.02,0.01
12.481198114798788,0.00113339952338685,43.592912711778915,300.0,8.333333333333333e-05,0.56,0.23,0.18,0.07,0.86,0.06,0.02,0.01
12.611301127239887,0.0011442414410902748,43.93416667186232,300.0,8.333333333333333e-05,0.56,0.23,0.18,0.07,0.86,0.06,0.02,0.01
12.741404139680988,0.0011550833587937,44.27542063194579,300.0,8.333333333333333e-05,0.56,0.23,0.18,0.07,0.86,0.06,0.02,0.01
12.877979289743388,0.0011664646212989,44.60571609444999,300.0,8.333333333333333e-05,0.56,0.23,0.18,0.07,0.86,0.06,0.02,0.01
13.014554439805789,0.0011778458838041,44.93601155695398,300.0,8.333333333333333e-05,0.56,0.23,0.18,0.07,0.86,0.06,0.02,0.01
13.151129589868189,0.0011892271463093,45.26630701945823,300.0,8.333333333333333e-05,0.56,0.23,0.18,0.07,0.86,0.06,0.02,0.01
13.28770473993059,0.0012006084088145,45.59660248196262,300.0,8.333333333333333e-05,0.56,0.23,0.18,0.07,0.86,0.06,0.02,0.01
13.42427988999299,0.0012119896713197,45.926897944466816,300.0,8.333333333333333e-05,0.56,0.23,0.18,0.07,0.86,0.06,0.02,0.01
13.56085504005539,0.0012233709338248999,46.25719340697069,300.0,8.333333333333333e-05,0.56,0.23,0.18,0.07,0.86,0.06,0.02,0.01
13.697430190117789,0.0012347521963301,46.58748886947482,300.0,8.333333333333333e-05,0.56,0.23,0.18,0.07,0.86,0.06,0.02,0.01
13.83400534018019,0.0012461334588353,46.91778433197922,300.0,8.333333333333333e-05,0.56,0.23,0.18,0.07,0.86,0.06,0.02,0.01
13.966961952107841,0.0012572131764959375,47.22773778506762,300.0,8.333333333333333e-05,0.56,0.23,0.18,0.07,0.86,0.06,0.02,0.01
14.099918564035491,0.001268292894156575,47.537691238156086,300.0,8.333333333333333e-05,0.56,0.23,0.18,0.07,0.86,0.06,0.02,0.01
14.232875175963141,0.0012793726118172125,47.847644691244554,300.0,8.333333333333333e-05,0.56,0.23,0.18,0.07,0.86,0.06,0.02,0.01
14.36583178789079,0.00129045232947785,48.15759814433278,300.0,8.333333333333333e-05,0.56,0.23,0.18,0.07,0.86,0.06,0.02,0.01
14.49878839981844,0.0013015320471384876,48.46755159742118,300.0,8.333333333333333e-05,0.56,0.23,0.18,0.07,0.86,0.06,0.02,0.01
14.63174501174609,0.001312611764799125,48.77750505050953,300.0,8.333333333333333e-05,0.56,0.23,0.18,0.07,0.86,0.06,0.02,0.01
14.76470162367374,0.0013236914824597626,49.08745850359789,300.0,8.333333333333333e-05,0.56,0.23,0.18,0.07,0.86,0.06,0.02,0.01
14.89765823560139,0.0013347712001204,49.39741195668632,300.0,8.333333333333333e-05,0.56,0.23,0.18,0.07,0.86,0.06,0.02,0.01
15.04462898703149,0.001347018762739575,49.69599967275318,300.0,8.333333333333333e-05,0.56,0.23,0.18,0.07,0.86,0.06,0.02,0.01
15.19159973846159,0.00135926632535875,49.99458738882019,300.0,8.333333333333333e-05,0.56,0.23,0.18,0.07,0.86,0.06,0.02,0.01
15.33857048989169,0.0013715138879779251,50.29317510488702,300.0,8.333333333333333e-05,0.56,0.23,0.18,0.07,0.86,0.06,0.02,0.01
15.48554124132179,0.0013837614505971,50.591762820953264,300.0,8.333333333333333e-05,0.56,0.23,0.18,0.07,0.86,0.06,0.02,0.01
15.63251199275189,0.001396009013216275,50.89035053702011,300.0,8.333333333333333e-05,0.56,0.23,0.18,0.07,0.86,0.06,0.02,0.01
15.77948274418199,0.0014082565758354502,51.18893825308746,300.0,8.333333333333333e-05,0.56,0.23,0.18,0.07,0.86,0.06,0.02,0.01
15.92645349561209,0.001420504138454625,51.48752596915426,300.0,8.333333333333333e-05,0.56,0.23,0.18,0.07,0.86,0.06,0.02,0.01
16.07342424704219,0.0014327517010738,51.78611368522109,300.0,8.333333333333333e-05,0.56,0.23,0.18,0.07,0.86,0.06,0.02,0.01
16.22799692495144,0.0014456327575662377,52.05758951042714,300.0,8.333333333333333e-05,0.56,0.23,0.18,0.07,0.86,0.06,0.02,0.01
16.38256960286069,0.0014585138140586751,52.329065335633295,300.0,8.333333333333333e-05,0.56,0.23,0.18,0.07,0.86,0.06,0.02,0.01
16.53714228076994,0.0014713948705511125,52.60054116083941,300.0,8.333333333333333e-05,0.56,0.23,0.18,0.07,0.86,0.06,0.02,0.01
16.691714958679192,0.0014842759270435502,52.872016986045715,300.0,8.333333333333333e-05,0.56,0.23,0.18,0.07,0.86,0.06,0.02,0.01
16.846287636588443,0.0014971569835359876,53.14349281125175,300.0,8.333333333333333e-05,0.56,0.23,0.18,0.07,0.86,0.06,0.02,0.01
17.000860314497693,0.001510038040028425,53.414968636457715,300.0,8.333333333333333e-05,0.56,0.23,0.18,0.07,0.86,0.06,0.02,0.01
17.155432992406944,0.0015229190965208627,53.68644446166363,300.0,8.333333333333333e-05,0.56,0.23,0.18,0.07,0.86,0.06,0.02,0.01
17.31000567031619,0.0015358001530133,53.957920286869516,300.0,8.333333333333333e-05,0.56,0.23,0.18,0.07,0.86,0.06,0.02,0.01
17.48222573456234,0.0015501518250338126,54.19747620328481,300.0,8.333333333333333e-05,0.56,0.23,0.18,0.07,0.86,0.06,0.02,0.01
17.65444579880849,0.001564503497054325,54.43703211970011,300.0,8.333333333333333e-05,0.56,0.23,0.18,0.07,0.86,0.06,0.02,0.01
17.82666586305464,0.0015788551690748376,54.67658803611555,300.0,8.333333333333333e-05,0.56,0.23,0.18,0.07,0.86,0.06,0.02,0.01
17.99888592730079,0.00159320684109535,54.9161439525308,300.0,8.333333333333333e-05,0.56,0.23,0.18,0.07,0.86,0.06,0.02,0.01
18.17110599154694,0.0016075585131158626,55.1556998689461,300.0,8.333333333333333e-05,0.56,0.23,0.18,0.07,0.86,0.06,0.02,0.01
18.343326055793092,0.001621910185136375,55.3952557853612,300.0,8.333333333333333e-05,0.56,0.23,0.18,0.07,0.86,0.06,0.02,0.01
18.51554612003924,0.0016362618571568875,55.6348117017764,300.0,8.333333333333333e-05,0.56,0.23,0.18,0.07,0.86,0.06,0.02,0.01
18.68776618428539,0.0016506135291774,55.87436761819174,300.0,8.333333333333333e-05,0.56,0.23,0.18,0.07,0.86,0.06,0.02,0.01
18.88011936474269,0.001666642960882175,56.097938976947034,300.0,8.333333333333333e-05,0.56,0.23,0.18,0.07,0.86,0.06,0.02,0.01
19.07247254519999,0.00168267239258695,56.3215103357023,300.0,8.333333333333333e-05,0.56,0.23,0.18,0.07,0.86,0.06,0.02,0.01
19.26482572565729,0.001698701824291725,56.54508169445767,300.0,8.333333333333333e-05,0.56,0.23,0.18,0.07,0.86,0.06,0.02,0.01
19.45717890611459,0.0017147312559965,56.7686530532129,300.0,8.333333333333333e-05,0.56,0.23,0.18,0.07,0.86,0.06,0.02,0.01
19.649532086571888,0.0017307606877012749,56.992224411968195,300.0,8.333333333333333e-05,0.56,0.23,0.18,0.07,0.86,0.06,0.02,0.01
19.841885267029188,0.00174679011940605,57.215795770723844,300.0,8.333333333333333e-05,0.56,0.23,0.18,0.07,0.86,0.06,0.02,0.01
20.034238447486487,0.001762819551110825,57.43936712947917,300.0,8.333333333333333e-05,0.56,0.23,0.18,0.07,0.86,0.06,0.02,0.01
20.226591627943787,0.0017788489828156,57.66293848823436,300.0,8.333333333333333e-05,0.56,0.23,0.18,0.07,0.86,0.06,0.02,0.01
20.442990349076837,0.0017968822095766872,57.85908820485571,300.0,8.333333333333333e-05,0.56,0.23,0.18,0.07,0.86,0.06,0.02,0.01
20.65938907020989,0.0018149154363377748,58.055237921477215,300.0,8.333333333333333e-05,0.56,0.23,0.18,0.07,0.86,0.06,0.02,0.01
20.87578779134294,0.0018329486630988623,58.25138763809855,300.0,8.333333333333333e-05,0.56,0.23,0.18,0.07,0.86,0.06,0.02,0.01
21.09218651247599,0.0018509818898599499,58.4475373547199,300.0,8.333333333333333e-05,0.56,0.23,0.18,0.07,0.86,0.06,0.02,0.01
21.30858523360904,0.0018690151166210374,58.64368707134123,300.0,8.333333333333333e-05,0.56,0.23,0.18,0.07,0.86,0.06,0.02,0.01
21.52498395474209,0.001887048343382125,58.839836787962554,300.0,8.333333333333333e-05,0.56,0.23,0.18,0.07,0.86,0.06,0.02,0.01
21.74138267587514,0.0019050815701432125,59.0359865045839,300.0,8.333333333333333e-05,0.56,0.23,0.18,0.07,0.86,0.06,0.02,0.01
21.95778139700819,0.0019231147969043,59.23213622120534,300.0,8.333333333333333e-05,0.56,0.23,0.18,0.07,0.86,0.06,0.02,0.01
22.17256346147609,0.001941013302276625,59.39973536854827,300.0,8.333333333333333e-05,0.56,0.23,0.18,0.07,0.86,0.06,0.02,0.01
22.387345525943992,0.00195891180764895,59.56733451589112,300.0,8.333333333333333e-05,0.56,0.23,0.18,0.07,0.86,0.06,0.02,0.01
22.60212759041189,0.001976810313021275,59.734933663233974,300.0,8.333333333333333e-05,0.56,0.23,0.18,0.07,0.86,0.06,0.02,0.01
22.81690965487979,0.0019947088183936,59.90253281057669,300.0,8.333333333333333e-05,0.56,0.23,0.18,0.07,0.86,0.06,0.02,0.01
23.03169171934769,0.002012607323765925,60.07013195791963,300.0,8.333333333333333e-05,0.56,0.23,0.18,0.07,0.86,0.06,0.02,0.01
23.24647378381559,0.00203050582913825,60.2377311052626,300.0,8.333333333333333e-05,0.56,0.23,0.18,0.07,0.86,0.06,0.02,0.01
23.46125584828349,0.002048404334510575,60.40533025260554,300.0,8.333333333333333e-05,0.56,0.23,0.18,0.07,0.86,0.06,0.02,0.01
23.67603791275139,0.0020663028398829,60.572929399948855,300.0,8.333333333333333e-05,0.56,0.23,0.18,0.07,0.86,0.06,0.02,0.01
23.96507280097514,0.0020903890805682125,60.715948954998616,300.0,8.333333333333333e-05,0.56,0.23,0.18,0.07,0.86,0.06,0.02,0.01
24.25410768919889,0.002114475321253525,60.858968510047994,300.0,8.333333333333333e-05,0.56,0.23,0.18,0.07,0.86,0.06,0.02,0.01
24.54314257742264,0.0021385615619388372,61.00198806509782,300.0,8.333333333333333e-05,0.56,0.23,0.18,0.07,0.86,0.06,0.02,0.01
24.83217746564639,0.00216264780262415,61.14500762014792,300.0,8.333333333333333e-05,0.56,0.23,0.18,0.07,0.86,0.06,0.02,0.01
25.12121235387014,0.002186734043309463,61.28802717519771,300.0,8.333333333333333e-05,0.56,0.23,0.18,0.07,0.86,0.06,0.02,0.01
25.410247242093888,0.0022108202839947752,61.43104673024704,300.0,8.333333333333333e-05,0.56,0.23,0.18,0.07,0.86,0.06,0.02,0.01
25.69928213031764,0.0022349065246800876,61.57406628529687,300.0,8.333333333333333e-05,0.56,0.23,0.18,0.07,0.86,0.06,0.02,0.01
25.98831701854139,0.0022589927653654,61.71708584034712,300.0,8.333333333333333e-05,0.56,0.23,0.18,0.07,0.86,0.06,0.02,0.01
26.326956174856193,0.0022872126950583003,61.82568114830872,300.0,8.333333333333333e-05,0.56,0.23,0.18,0.07,0.86,0.06,0.02,0.01
26.66559533117099,0.0023154326247512,61.934276456269664,300.0,8.333333333333333e-05,0.56,0.23,0.18,0.07,0.86,0.06,0.02,0.01
27.00423448748579,0.0023436525544441,62.04287176423123,300.0,8.333333333333333e-05,0.56,0.23,0.18,0.07,0.86,0.06,0.02,0.01
27.342873643800587,0.002371872484137,62.151467072193206,300.0,8.333333333333333e-05,0.56,0.23,0.18,0.07,0.86,0.06,0.02,0.01
27.681512800115385,0.0024000924138299,62.26006238015481,300.0,8.333333333333333e-05,0.56,0.23,0.18,0.07,0.86,0.06,0.02,0.01
28.020151956430187,0.0024283123435228,62.368657688116315,300.0,8.333333333333333e-05,0.56,0.23,0.18,0.07,0.86,0.06,0.02,0.01
28.35879111274499,0.0024565322732157,62.47725299607787,300.0,8.333333333333333e-05,0.56,0.23,0.18,0.07,0.86,0.06,0.02,0.01
28.697430269059787,0.0024847522029086,62.58584830403985,300.0,8.333333333333333e-05,0.56,0.23,0.18,0.07,0.86,0.06,0.02,0.01
29.053258308001638,0.0025144045394870874,62.67679637740526,300.0,8.333333333333333e-05,0.56,0.23,0.18,0.07,0.86,0.06,0.02,0.01
29.40908634694349,0.002544056876065575,62.76774445077043,300.0,8.333333333333333e-05,0.56,0.23,0.18,0.07,0.86,0.06,0.02,0.01
29.76491438588534,0.0025737092126440625,62.858692524135805,300.0,8.333333333333333e-05,0.56,0.23,0.18,0.07,0.86,0.06,0.02,0.01
30.12074242482719,0.00260336154922255,62.94964059750118,300.0,8.333333333333333e-05,0.56,0.23,0.18,0.07,0.86,0.06,0.02,0.01
30.476570463769036,0.0026330138858010376,63.0405886708666,300.0,8.333333333333333e-05,0.56,0.23,0.18,0.07,0.86,0.06,0.02,0.01
30.832398502710888,0.002662666222379525,63.13153674423201,300.0,8.333333333333333e-05,0.56,0.23,0.18,0.07,0.86,0.06,0.02,0.01
31.18822654165274,0.0026923185589580127,63.222484817597504,300.0,8.333333333333333e-05,0.56,0.23,0.18,0.07,0.86,0.06,0.02,0.01
31.54405458059459,0.0027219708955365,63.31343289096266,300.0,8.333333333333333e-05,0.56,0.23,0.18,0.07,0.86,0.06,0.02,0.01
31.94590311523769,0.002755458273423425,63.386816071075486,300.0,8.333333333333333e-05,0.56,0.23,0.18,0.07,0.86,0.06,0.02,0.01
32.34775164988079,0.0027889456513103504,63.46019925118838,300.0,8.333333333333333e-05,0.56,0.23,0.18,0.07,0.86,0.06,0.02,0.01
32.74960018452389,0.0028224330291972753,63.53358243130106,300.0,8.333333333333333e-05,0.56,0.23,0.18,0.07,0.86,0.06,0.02,0.01
33.15144871916699,0.0028559204070842,63.60696561141411,300.0,8.333333333333333e-05,0.56,0.23,0.18,0.07,0.86,0.06,0.02,0.01
33.55329725381009,0.002889407784971125,63.680348791526924,300.0,8.333333333333333e-05,0.56,0.23,0.18,0.07,0.86,0.06,0.02,0.01
33.955145788453194,0.00292289516285805,63.75373197163918,300.0,8.333333333333333e-05,0.56,0.23,0.18,0.07,0.86,0.06,0.02,0.01
34.35699432309629,0.0029563825407449753,63.827115151752125,300.0,8.333333333333333e-05,0.56,0.23,0.18,0.07,0.86,0.06,0.02,0.01
34.75884285773939,0.0029898699186319,63.900498331865464,300.0,8.333333333333333e-05,0.56,0.23,0.18,0.07,0.86,0.06,0.02,0.01
35.19912917252368,0.0030265604448639254,63.947787813421094,300.0,8.333333333333333e-05,0.56,0.23,0.18,0.07,0.86,0.06,0.02,0.01
35.639415487307986,0.00306325097109595,63.99507729497651,300.0,8.333333333333333e-05,0.56,0.23,0.18,0.07,0.86,0.06,0.02,0.01
36.07970180209229,0.003099941497327975,64.04236677653208,300.0,8.333333333333333e-05,0.56,0.23,0.18,0.07,0.86,0.06,0.02,0.01
36.51998811687659,0.00313663202356,64.08965625808767,300.0,8.333333333333333e-05,0.56,0.23,0.18,0.07,0.86,0.06,0.02,0.01
36.96027443166089,0.0031733225497920254,64.1369457396433,300.0,8.333333333333333e-05,0.56,0.23,0.18,0.07,0.86,0.06,0.02,0.01
37.400560746445194,0.00321001307602405,64.18423522119906,300.0,8.333333333333333e-05,0.56,0.23,0.18,0.07,0.86,0.06,0.02,0.01
37.840847061229496,0.003246703602256075,64.23152470275477,300.0,8.333333333333333e-05,0.56,0.23,0.18,0.07,0.86,0.06,0.02,0.01
38.28113337601379,0.0032833941284881,64.27881418431048,300.0,8.333333333333333e-05,0.56,0.23,0.18,0.07,0.86,0.06,0.02,0.01
38.770664114284344,0.0033241883566773123,64.31113318183056,300.0,8.333333333333333e-05,0.56,0.23,0.18,0.07,0.86,0.06,0.02,0.01
39.26019485255489,0.003364982584866525,64.34345217935068,300.0,8.333333333333333e-05,0.56,0.23,0.18,0.07,0.86,0.06,0.02,0.01
39.74972559082544,0.0034057768130557374,64.37577117687073,300.0,8.333333333333333e-05,0.56,0.23,0.18,0.07,0.86,0.06,0.02,0.01
40.239256329095994,0.00344657104124495,64.40809017439096,300.0,8.333333333333333e-05,0.56,0.23,0.18,0.07,0.86,0.06,0.02,0.01
40.72878706736654,0.0034873652694341626,64.44040917191103,300.0,8.333333333333333e-05,0.56,0.23,0.18,0.07,0.86,0.06,0.02,0.01
41.21831780563709,0.003528159497623375,64.47272816943116,300.0,8.333333333333333e-05,0.56,0.23,0.18,0.07,0.86,0.06,0.02,0.01
41.707848543907645,0.0035689537258125877,64.50504716695121,300.0,8.333333333333333e-05,0.56,0.23,0.18,0.07,0.86,0.06,0.02,0.01
42.19737928217819,0.0036097479540018,64.53736616447122,300.0,8.333333333333333e-05,0.56,0.23,0.18,0.07,0.86,0.06,0.02,0.01
42.72121828952399,0.0036534012046139496,64.56463425885977,300.0,8.333333333333333e-05,0.56,0.23,0.18,0.07,0.86,0.06,0.02,0.01
43.24505729686979,0.0036970544552261,64.59190235324827,300.0,8.333333333333333e-05,0.56,0.23,0.18,0.07,0.86,0.06,0.02,0.01
43.76889630421559,0.00374070770583825,64.61917044763682,300.0,8.333333333333333e-05,0.56,0.23,0.18,0.07,0.86,0.06,0.02,0.01
44.29273531156139,0.0037843609564504003,64.64643854202541,300.0,8.333333333333333e-05,0.56,0.23,0.18,0.07,0.86,0.06,0.02,0.01
44.816574318907186,0.0038280142070625505,64.67370663641395,300.0,8.333333333333333e-05,0.56,0.23,0.18,0.07,0.86,0.06,0.02,0.01
45.340413326252985,0.0038716674576747003,64.70097473080253,300.0,8.333333333333333e-05,0.56,0.23,0.18,0.07,0.86,0.06,0.02,0.01
45.864252333598785,0.00391532070828685,64.72824282519103,300.0,8.333333333333333e-05,0.56,0.23,0.18,0.07,0.86,0.06,0.02,0.01
46.38809134094459,0.003958973958899,64.75551091957966,300.0,8.333333333333333e-05,0.56,0.23,0.18,0.07,0.86,0.06,0.02,0.01
46.914283876188435,0.004002823336835987,64.76460432849969,300.0,8.333333333333333e-05,0.56,0.23,0.18,0.07,0.86,0.06,0.02,0.01
47.440476411432286,0.004046672714772975,64.77369773741928,300.0,8.333333333333333e-05,0.56,0.23,0.18,0.07,0.86,0.06,0.02,0.01
47.96666894667614,0.004090522092709962,64.78279114633916,300.0,8.333333333333333e-05,0.56,0.23,0.18,0.07,0.86,0.06,0.02,0.01
48.49286148191999,0.00413437147064695,64.7918845552592,300.0,8.333333333333333e-05,0.56,0.23,0.18,0.07,0.86,0.06,0.02,0.01
49.01905401716384,0.004178220848583937,64.80097796417924,300.0,8.333333333333333e-05,0.56,0.23,0.18,0.07,0.86,0.06,0.02,0.01
49.54524655240769,0.004222070226520925,64.8100713730995,300.0,8.333333333333333e-05,0.56,0.23,0.18,0.07,0.86,0.06,0.02,0.01
50.07143908765154,0.0042659196044579125,64.81916478201967,300.0,8.333333333333333e-05,0.56,0.23,0.18,0.07,0.86,0.06,0.02,0.01
50.59763162289539,0.0043097689823949,64.82825819093955,300.0,8.333333333333333e-05,0.56,0.23,0.18,0.07,0.86,0.06,0.02,0.01
51.12610298340989,0.004353808262437775,64.83421868341372,300.0,8.333333333333333e-05,0.56,0.23,0.18,0.07,0.86,0.06,0.02,0.01
51.654574343924395,0.0043978475424806505,64.84017917588793,300.0,8.333333333333333e-05,0.56,0.23,0.18,0.07,0.86,0.06,0.02,0.01
52.1830457044389,0.004441886822523526,64.8461396683621,300.0,8.333333333333333e-05,0.56,0.23,0.18,0.07,0.86,0.06,0.02,0.01
52.71151706495339,0.0044859261025664,64.85210016083627,300.0,8.333333333333333e-05,0.56,0.23,0.18,0.07,0.86,0.06,0.02,0.01
53.239988425467885,0.0045299653826092745,64.85806065331045,300.0,8.333333333333333e-05,0.56,0.23,0.18,0.07,0.86,0.06,0.02,0.01
53.76845978598239,0.00457400466265215,64.86402114578408,300.0,8.333333333333333e-05,0.56,0.23,0.18,0.07,0.86,0.06,0.02,0.01
54.29693114649689,0.004618043942695025,64.86998163825827,300.0,8.333333333333333e-05,0.56,0.23,0.18,0.07,0.86,0.06,0.02,0.01
54.82540250701139,0.0046620832227379,64.87594213073267,300.0,8.333333333333333e-05,0.56,0.23,0.18,0.07,0.86,0.06,0.02,0.01
55.39499922504014,0.004709549615906963,64.87901353095693,300.0,8.333333333333333e-05,0.56,0.23,0.18,0.07,0.86,0.06,0.02,0.01
55.964595943068886,0.004757016009076025,64.88208493118174,300.0,8.333333333333333e-05,0.56,0.23,0.18,0.07,0.86,0.06,0.02,0.01
56.534192661097634,0.004804482402245087,64.88515633140605,300.0,8.333333333333333e-05,0.56,0.23,0.18,0.07,0.86,0.06,0.02,0.01
57.10378937912639,0.0048519487954141495,64.88822773162981,300.0,8.333333333333333e-05,0.56,0.23,0.18,0.07,0.86,0.06,0.02,0.01
57.673386097155145,0.004899415188583212,64.89129913185407,300.0,8.333333333333333e-05,0.56,0.23,0.18,0.07,0.86,0.06,0.02,0.01
58.24298281518389,0.004946881581752275,64.8943705320787,300.0,8.333333333333333e-05,0.56,0.23,0.18,0.07,0.86,0.06,0.02,0.01
58.81257953321264,0.004994347974921338,64.89744193230288,300.0,8.333333333333333e-05,0.56,0.23,0.18,0.07,0.86,0.06,0.02,0.01
59.38217625124139,0.0050418143680904,64.900513332527,300.0,8.333333333333333e-05,0.56,0.23,0.18,0.07,0.86,0.06,0.02,0.01