File: datasets/al_6061_comp/csv/T_300_G_1.csv
Time,Strain(%),Stress(MPa),Temp(C),SR(%/s),Si(%),Fe(%),Cu(%),Mn(%),Mg(%),Cr(%),Zn(%),Ti(%)
0.0,0.0001050058471442,29.276734993435003,300.0,8.333333333333333e-05,0.61,0.15,0.17,0.02,0.88,0.05,0.01,0.01
0.13785309574770002,0.00011649360512317501,29.668999830954444,300.0,8.333333333333333e-05,0.61,0.15,0.17,0.02,0.88,0.05,0.01,0.01
0.27570619149540004,0.00012798136310215,30.06126466847386,300.0,8.333333333333333e-05,0.61,0.15,0.17,0.02,0.88,0.05,0.01,0.01
0.4135592872431001,0.000139469121081125,30.4535295059933,300.0,8.333333333333333e-05,0.61,0.15,0.17,0.02,0.88,0.05,0.01,0.01
0.5514123829908001,0.0001509568790601,30.845794343512736,300.0,8.333333333333333e-05,0.61,0.15,0.17,0.02,0.88,0.05,0.01,0.01
0.6892654787385002,0.000162444637039075,31.238059181032177,300.0,8.333333333333333e-05,0.61,0.15,0.17,0.02,0.88,0.05,0.01,0.01
0.8271185744862002,0.00017393239501805,31.630324018551597,300.0,8.333333333333333e-05,0.61,0.15,0.17,0.02,0.88,0.05,0.01,0.01
0.9649716702339002,0.00018542015299702499,32.02258885607103,300.0,8.333333333333333e-05,0.61,0.15,0.17,0.02,0.88,0.05,0.01,0.01
1.1028247659816002,0.000196907910976,32.41485369359049,300.0,8.333333333333333e-05,0.61,0.15,0.17,0.02,0.88,0.05,0.01,0.01
1.24693483429995,0.0002089170833358625,32.801405360549055,300.0,8.333333333333333e-05,0.61,0.15,0.17,0.02,0.88,0.05,0.01,0.01
1.3910449026183,0.000220926255695725,33.18795702750766,300.0,8.333333333333333e-05,0.61,0.15,0.17,0.02,0.88,0.05,0.01,0.01
1.53515497093665,0.00023293542805558748,33.57450869446622,300.0,8.333333333333333e-05,0.61,0.15,0.17,0.02,0.88,0.05,0.01,0.01
1.6792650392550001,0.00024494460041545,33.96106036142474,300.0,8.333333333333333e-05,0.61,0.15,0.17,0.02,0.88,0.05,0.01,0.01
1.8233751075733502,0.00025695377277531247,34.3476120283833,300.0,8.333333333333333e-05,0.61,0.15,0.17,0.02,0.88,0.05,0.01,0.01
1.9674851758917002,0.00026896294513517496,34.734163695341856,300.0,8.333333333333333e-05,0.61,0.15,0.17,0.02,0.88,0.05,0.01,0.01
2.1115952442100503,0.00028097211749503746,35.120715362300416,300.0,8.333333333333333e-05,0.61,0.15,0.17,0.02,0.88,0.05,0.01,0.01
2.2557053125284003,0.0002929812898549,35.50726702925899,300.0,8.333333333333333e-05,0.61,0.15,0.17,0.02,0.88,0.05,0.01,0.01
2.4040121815686004,0.00030534019560825,35.87582584387026,300.0,8.333333333333333e-05,0.61,0.15,0.17,0.02,0.88,0.05,0.01,0.01
2.5523190506088005,0.0003176991013616,36.24438465848147,300.0,8.333333333333333e-05,0.61,0.15,0.17,0.02,0.88,0.05,0.01,0.01
2.700625919649,0.00033005800711495,36.61294347309274,300.0,8.333333333333333e-05,0.61,0.15,0.17,0.02,0.88,0.05,0.01,0.01
2.8489327886892,0.0003424169128683,36.98150228770407,300.0,8.333333333333333e-05,0.61,0.15,0.17,0.02,0.88,0.05,0.01,0.01
2.9972396577294003,0.00035477581862165,37.35006110231532,300.0,8.333333333333333e-05,0.61,0.15,0.17,0.02,0.88,0.05,0.01,0.01
3.1455465267696,0.000367134724375,37.718619916926585,300.0,8.333333333333333e-05,0.61,0.15,0.17,0.02,0.88,0.05,0.01,0.01
3.2938533958098,0.00037949363012835,38.08717873153782,300.0,8.333333333333333e-05,0.61,0.15,0.17,0.02,0.88,0.05,0.01,0.01
3.44216026485,0.0003918525358817,38.45573754614912,300.0,8.333333333333333e-05,0.61,0.15,0.17,0.02,0.88,0.05,0.01,0.01
3.5743156350111,0.000402865483395125,38.817697866752795,300.0,8.333333333333333e-05,0.61,0.15,0.17,0.02,0.88,0.05,0.01,0.01
3.7064710051722,0.00041387843090855,39.17965818735638,300.0,8.333333333333333e-05,0.61,0.15,0.17,0.02,0.88,0.05,0.01,0.01
3.8386263753333,0.000424891378421975,39.54161850796007,300.0,8.333333333333333e-05,0.61,0.15,0.17,0.02,0.88,0.05,0.01,0.01
3.9707817454944,0.0004359043259354,39.903578828563774,300.0,8.333333333333333e-05,0.61,0.15,0.17,0.02,0.88,0.05,0.01,0.01
4.1029371156555,0.000446917273448825,40.26553914916746,300.0,8.333333333333333e-05,0.61,0.15,0.17,0.02,0.88,0.05,0.01,0.01
4.2350924858166,0.00045793022096225,40.62749946977112,300.0,8.333333333333333e-05,0.61,0.15,0.17,0.02,0.88,0.05,0.01,0.01
4.3672478559777,0.000468943168475675,40.98945979037481,300.0,8.333333333333333e-05,0.61,0.15,0.17,0.02,0.88,0.05,0.01,0.01
4.4994032261388,0.0004799561159891,41.35142011097849,300.0,8.333333333333333e-05,0.61,0.15,0.17,0.02,0.88,0.05,0.01,0.01
4.63813566442845,0.0004915171525132375,41.696683125836664,300.0,8.333333333333333e-05,0.61,0.15,0.17,0.02,0.88,0.05,0.01,0.01
4.776868102718101,0.0005030781890373751,42.04194614069491,300.0,8.333333333333333e-05,0.61,0.15,0.17,0.02,0.88,0.05,0.01,0.01
4.915600541007751,0.0005146392255615125,42.387209155553066,300.0,8.333333333333333e-05,0.61,0.15,0.17,0.02,0.88,0.05,0.01,0.01
5.054332979297401,0.00052620026208565,42.73247217041112,300.0,8.333333333333333e-05,0.61,0.15,0.17,0.02,0.88,0.05,0.01,0.01
5.193065417587051,0.0005377612986097876,43.07773518526929,300.0,8.333333333333333e-05,0.61,0.15,0.17,0.02,0.88,0.05,0.01,0.01
5.331797855876701,0.000549322335133925,43.42299820012761,300.0,8.333333333333333e-05,0.61,0.15,0.17,0.02,0.88,0.05,0.01,0.01
5.470530294166351,0.0005608833716580625,43.76826121498577,300.0,8.333333333333333e-05,0.61,0.15,0.17,0.02,0.88,0.05,0.01,0.01
5.609262732456001,0.0005724444081822,44.11352422984386,300.0,8.333333333333333e-05,0.61,0.15,0.17,0.02,0.88,0.05,0.01,0.01
5.745410874387151,0.0005837900866764625,44.45132883660109,300.0,8.333333333333333e-05,0.61,0.15,0.17,0.02,0.88,0.05,0.01,0.01
5.881559016318301,0.0005951357651707251,44.78913344335831,300.0,8.333333333333333e-05,0.61,0.15,0.17,0.02,0.88,0.05,0.01,0.01
6.017707158249451,0.0006064814436649875,45.126938050115555,300.0,8.333333333333333e-05,0.61,0.15,0.17,0.02,0.88,0.05,0.01,0.01
6.1538553001806005,0.00061782712215925,45.4647426568729,300.0,8.333333333333333e-05,0.61,0.15,0.17,0.02,0.88,0.05,0.01,0.01
6.29000344211175,0.0006291728006535125,45.802547263630125,300.0,8.333333333333333e-05,0.61,0.15,0.17,0.02,0.88,0.05,0.01,0.01
6.4261515840429,0.0006405184791477749,46.140351870387235,300.0,8.333333333333333e-05,0.61,0.15,0.17,0.02,0.88,0.05,0.01,0.01
6.56229972597405,0.0006518641576420375,46.47815647714445,300.0,8.333333333333333e-05,0.61,0.15,0.17,0.02,0.88,0.05,0.01,0.01
6.6984478679052,0.0006632098361363,46.8159610839018,300.0,8.333333333333333e-05,0.61,0.15,0.17,0.02,0.88,0.05,0.01,0.01
6.8619289567137,0.000676833260203675,47.1425479694054,300.0,8.333333333333333e-05,0.61,0.15,0.17,0.02,0.88,0.05,0.01,0.01
7.0254100455222,0.00069045668427105,47.46913485490903,300.0,8.333333333333333e-05,0.61,0.15,0.17,0.02,0.88,0.05,0.01,0.01
7.188891134330699,0.000704080108338425,47.795721740412574,300.0,8.333333333333333e-05,0.61,0.15,0.17,0.02,0.88,0.05,0.01,0.01
7.3523722231391995,0.0007177035324058,48.122308625916084,300.0,8.333333333333333e-05,0.61,0.15,0.17,0.02,0.88,0.05,0.01,0.01
7.5158533119477,0.000731326956473175,48.44889551141968,300.0,8.333333333333333e-05,0.61,0.15,0.17,0.02,0.88,0.05,0.01,0.01
7.679334400756199,0.00074495038054055,48.77548239692325,300.0,8.333333333333333e-05,0.61,0.15,0.17,0.02,0.88,0.05,0.01,0.01
7.842815489564699,0.000758573804607925,49.102069282426896,300.0,8.333333333333333e-05,0.61,0.15,0.17,0.02,0.88,0.05,0.01,0.01
8.006296578373199,0.0007721972286753,49.42865616793053,300.0,8.333333333333333e-05,0.61,0.15,0.17,0.02,0.88,0.05,0.01,0.01
8.14519397648415,0.0007837720118512126,49.741687294600936,300.0,8.333333333333333e-05,0.61,0.15,0.17,0.02,0.88,0.05,0.01,0.01
8.2840913745951,0.000795346795027125,50.05471842127132,300.0,8.333333333333333e-05,0.61,0.15,0.17,0.02,0.88,0.05,0.01,0.01
8.422988772706049,0.0008069215782030375,50.36774954794171,300.0,8.333333333333333e-05,0.61,0.15,0.17,0.02,0.88,0.05,0.01,0.01
8.561886170816999,0.00081849636137895,50.68078067461227,300.0,8.333333333333333e-05,0.61,0.15,0.17,0.02,0.88,0.05,0.01,0.01
8.70078356892795,0.0008300711445548626,50.993811801282696,300.0,8.333333333333333e-05,0.61,0.15,0.17,0.02,0.88,0.05,0.01,0.01
8.839680967038898,0.000841645927730775,51.306842927952985,300.0,8.333333333333333e-05,0.61,0.15,0.17,0.02,0.88,0.05,0.01,0.01
8.978578365149849,0.0008532207109066875,51.619874054623395,300.0,8.333333333333333e-05,0.61,0.15,0.17,0.02,0.88,0.05,0.01,0.01
9.1174757632608,0.0008647954940826,51.93290518129358,300.0,8.333333333333333e-05,0.61,0.15,0.17,0.02,0.88,0.05,0.01,0.01
9.26074992117675,0.0008767350072422626,52.24055669517651,300.0,8.333333333333333e-05,0.61,0.15,0.17,0.02,0.88,0.05,0.01,0.01
9.4040240790927,0.000888674520401925,52.54820820905954,300.0,8.333333333333333e-05,0.61,0.15,0.17,0.02,0.88,0.05,0.01,0.01
9.54729823700865,0.0009006140335615875,52.85585972294254,300.0,8.333333333333333e-05,0.61,0.15,0.17,0.02,0.88,0.05,0.01,0.01
9.6905723949246,0.0009125535467212501,53.1635112368256,300.0,8.333333333333333e-05,0.61,0.15,0.17,0.02,0.88,0.05,0.01,0.01
9.833846552840548,0.0009244930598809125,53.471162750708515,300.0,8.333333333333333e-05,0.61,0.15,0.17,0.02,0.88,0.05,0.01,0.01
9.977120710756498,0.000936432573040575,53.77881426459147,300.0,8.333333333333333e-05,0.61,0.15,0.17,0.02,0.88,0.05,0.01,0.01
10.120394868672449,0.0009483720862002375,54.086465778474306,300.0,8.333333333333333e-05,0.61,0.15,0.17,0.02,0.88,0.05,0.01,0.01
10.2636690265884,0.0009603115993599,54.394117292357336,300.0,8.333333333333333e-05,0.61,0.15,0.17,0.02,0.88,0.05,0.01,0.01
10.39215417357975,0.0009710186949425125,54.691663090652966,300.0,8.333333333333333e-05,0.61,0.15,0.17,0.02,0.88,0.05,0.01,0.01
10.5206393205711,0.000981725790525125,54.989208888948525,300.0,8.333333333333333e-05,0.61,0.15,0.17,0.02,0.88,0.05,0.01,0.01
10.64912446756245,0.0009924328861077377,55.286754687244226,300.0,8.333333333333333e-05,0.61,0.15,0.17,0.02,0.88,0.05,0.01,0.01
10.7776096145538,0.00100313998169035,55.584300485539735,300.0,8.333333333333333e-05,0.61,0.15,0.17,0.02,0.88,0.05,0.01,0.01
10.90609476154515,0.0010138470772729623,55.88184628383535,300.0,8.333333333333333e-05,0.61,0.15,0.17,0.02,0.88,0.05,0.01,0.01
11.0345799085365,0.001024554172855575,56.179392082131045,300.0,8.333333333333333e-05,0.61,0.15,0.17,0.02,0.88,0.05,0.01,0.01
11.16306505552785,0.0010352612684381875,56.47693788042659,300.0,8.333333333333333e-05,0.61,0.15,0.17,0.02,0.88,0.05,0.01,0.01
11.2915502025192,0.0010459683640208,56.77448367872195,300.0,8.333333333333333e-05,0.61,0.15,0.17,0.02,0.88,0.05,0.01,0.01
11.4299208328782,0.00105749924988405,57.06134156206497,300.0,8.333333333333333e-05,0.61,0.15,0.17,0.02,0.88,0.05,0.01,0.01
11.5682914632372,0.0010690301357473,57.34819944540821,300.0,8.333333333333333e-05,0.61,0.15,0.17,0.02,0.88,0.05,0.01,0.01
11.7066620935962,0.00108056102161055,57.635057328751216,300.0,8.333333333333333e-05,0.61,0.15,0.17,0.02,0.88,0.05,0.01,0.01
11.8450327239552,0.0010920919074738,57.921915212094135,300.0,8.333333333333333e-05,0.61,0.15,0.17,0.02,0.88,0.05,0.01,0.01
11.9834033543142,0.00110362279333705,58.20877309543717,300.0,8.333333333333333e-05,0.61,0.15,0.17,0.02,0.88,0.05,0.01,0.01
12.1217739846732,0.0011151536792003,58.49563097878044,300.0,8.333333333333333e-05,0.61,0.15,0.17,0.02,0.88,0.05,0.01,0.01
12.2601446150322,0.00112668456506355,58.78248886212351,300.0,8.333333333333333e-05,0.61,0.15,0.17,0.02,0.88,0.05,0.01,0.01
12.3985152453912,0.0011382154509268,59.069346745466326,300.0,8.333333333333333e-05,0.61,0.15,0.17,0.02,0.88,0.05,0.01,0.01
12.55577537540475,0.0011513204617612624,59.35159261056595,300.0,8.333333333333333e-05,0.61,0.15,0.17,0.02,0.88,0.05,0.01,0.01
12.7130355054183,0.0011644254725957249,59.63383847566514,300.0,8.333333333333333e-05,0.61,0.15,0.17,0.02,0.88,0.05,0.01,0.01
12.87029563543185,0.0011775304834301874,59.91608434076478,300.0,8.333333333333333e-05,0.61,0.15,0.17,0.02,0.88,0.05,0.01,0.01
13.027555765445399,0.0011906354942646498,60.19833020586512,300.0,8.333333333333333e-05,0.61,0.15,0.17,0.02,0.88,0.05,0.01,0.01
13.18481589545895,0.0012037405050991123,60.48057607096473,300.0,8.333333333333333e-05,0.61,0.15,0.17,0.02,0.88,0.05,0.01,0.01
13.3420760254725,0.0012168455159335748,60.76282193606397,300.0,8.333333333333333e-05,0.61,0.15,0.17,0.02,0.88,0.05,0.01,0.01
13.499336155486048,0.0012299505267680372,61.04506780116361,300.0,8.333333333333333e-05,0.61,0.15,0.17,0.02,0.88,0.05,0.01,0.01
13.6565962854996,0.0012430555376025,61.327313666263294,300.0,8.333333333333333e-05,0.61,0.15,0.17,0.02,0.88,0.05,0.01,0.01
13.7926116713931,0.0012543901530936248,61.60104853307209,300.0,8.333333333333333e-05,0.61,0.15,0.17,0.02,0.88,0.05,0.01,0.01
13.9286270572866,0.0012657247685847499,61.87478339988147,300.0,8.333333333333333e-05,0.61,0.15,0.17,0.02,0.88,0.05,0.01,0.01
14.064642443180102,0.001277059384075875,62.14851826669022,300.0,8.333333333333333e-05,0.61,0.15,0.17,0.02,0.88,0.05,0.01,0.01
14.2006578290736,0.001288393999567,62.42225313349849,300.0,8.333333333333333e-05,0.61,0.15,0.17,0.02,0.88,0.05,0.01,0.01
14.3366732149671,0.001299728615058125,62.69598800030729,300.0,8.333333333333333e-05,0.61,0.15,0.17,0.02,0.88,0.05,0.01,0.01
14.4726886008606,0.0013110632305492502,62.96972286711626,300.0,8.333333333333333e-05,0.61,0.15,0.17,0.02,0.88,0.05,0.01,0.01
14.6087039867541,0.0013223978460403752,63.24345773392504,300.0,8.333333333333333e-05,0.61,0.15,0.17,0.02,0.88,0.05,0.01,0.01
14.744719372647602,0.0013337324615315,63.517192600733736,300.0,8.333333333333333e-05,0.61,0.15,0.17,0.02,0.88,0.05,0.01,0.01
14.864244081959852,0.0013436928539741874,63.78223279031698,300.0,8.333333333333333e-05,0.61,0.15,0.17,0.02,0.88,0.05,0.01,0.01
14.983768791272102,0.001353653246416875,64.04727297990047,300.0,8.333333333333333e-05,0.61,0.15,0.17,0.02,0.88,0.05,0.01,0.01
15.103293500584352,0.0013636136388595625,64.31231316948382,300.0,8.333333333333333e-05,0.61,0.15,0.17,0.02,0.88,0.05,0.01,0.01
15.222818209896602,0.00137357403130225,64.57735335906725,300.0,8.333333333333333e-05,0.61,0.15,0.17,0.02,0.88,0.05,0.01,0.01
15.342342919208852,0.0013835344237449376,64.8423935486505,300.0,8.333333333333333e-05,0.61,0.15,0.17,0.02,0.88,0.05,0.01,0.01
15.461867628521102,0.0013934948161876252,65.10743373823348,300.0,8.333333333333333e-05,0.61,0.15,0.17,0.02,0.88,0.05,0.01,0.01
15.581392337833352,0.0014034552086303127,65.37247392781674,300.0,8.333333333333333e-05,0.61,0.15,0.17,0.02,0.88,0.05,0.01,0.01
15.700917047145602,0.001413415601073,65.6375141174,300.0,8.333333333333333e-05,0.61,0.15,0.17,0.02,0.88,0.05,0.01,0.01
15.841787424478351,0.0014251547991840628,65.89898385453964,300.0,8.333333333333333e-05,0.61,0.15,0.17,0.02,0.88,0.05,0.01,0.01
15.9826578018111,0.0014368939972951252,66.16045359167947,300.0,8.333333333333333e-05,0.61,0.15,0.17,0.02,0.88,0.05,0.01,0.01
16.12352817914385,0.0014486331954061877,66.42192332881905,300.0,8.333333333333333e-05,0.61,0.15,0.17,0.02,0.88,0.05,0.01,0.01
16.2643985564766,0.0014603723935172502,66.6833930659586,300.0,8.333333333333333e-05,0.61,0.15,0.17,0.02,0.88,0.05,0.01,0.01
16.40526893380935,0.0014721115916283127,66.94486280309823,300.0,8.333333333333333e-05,0.61,0.15,0.17,0.02,0.88,0.05,0.01,0.01
16.5461393111421,0.0014838507897393751,67.20633254023768,300.0,8.333333333333333e-05,0.61,0.15,0.17,0.02,0.88,0.05,0.01,0.01
16.687009688474852,0.0014955899878504376,67.46780227737739,300.0,8.333333333333333e-05,0.61,0.15,0.17,0.02,0.88,0.05,0.01,0.01
16.8278800658076,0.0015073291859615,67.72927201451697,300.0,8.333333333333333e-05,0.61,0.15,0.17,0.02,0.88,0.05,0.01,0.01
16.949016516572854,0.0015174238901919375,67.97873208968272,300.0,8.333333333333333e-05,0.61,0.15,0.17,0.02,0.88,0.05,0.01,0.01
17.070152967338103,0.001527518594422375,68.22819216484865,300.0,8.333333333333333e-05,0.61,0.15,0.17,0.02,0.88,0.05,0.01,0.01
17.191289418103352,0.0015376132986528127,68.47765224001434,300.0,8.333333333333333e-05,0.61,0.15,0.17,0.02,0.88,0.05,0.01,0.01
17.3124258688686,0.0015477080028832501,68.72711231517968,300.0,8.333333333333333e-05,0.61,0.15,0.17,0.02,0.88,0.05,0.01,0.01
17.43356231963385,0.0015578027071136875,68.97657239034544,300.0,8.333333333333333e-05,0.61,0.15,0.17,0.02,0.88,0.05,0.01,0.01
17.5546987703991,0.001567897411344125,69.22603246551157,300.0,8.333333333333333e-05,0.61,0.15,0.17,0.02,0.88,0.05,0.01,0.01
17.67583522116435,0.0015779921155745624,69.47549254067737,300.0,8.333333333333333e-05,0.61,0.15,0.17,0.02,0.88,0.05,0.01,0.01
17.7969716719296,0.001588086819805,69.72495261584321,300.0,8.333333333333333e-05,0.61,0.15,0.17,0.02,0.88,0.05,0.01,0.01
17.94679856519445,0.0016005723942437377,69.97161945223971,300.0,8.333333333333333e-05,0.61,0.15,0.17,0.02,0.88,0.05,0.01,0.01
18.0966254584593,0.0016130579686824752,70.21828628863574,300.0,8.333333333333333e-05,0.61,0.15,0.17,0.02,0.88,0.05,0.01,0.01
18.24645235172415,0.0016255435431212126,70.46495312503222,300.0,8.333333333333333e-05,0.61,0.15,0.17,0.02,0.88,0.05,0.01,0.01
18.396279244989003,0.00163802911755995,70.71161996142874,300.0,8.333333333333333e-05,0.61,0.15,0.17,0.02,0.88,0.05,0.01,0.01
18.546106138253855,0.0016505146919986876,70.95828679782525,300.0,8.333333333333333e-05,0.61,0.15,0.17,0.02,0.88,0.05,0.01,0.01
18.695933031518702,0.001663000266437425,71.20495363422233,300.0,8.333333333333333e-05,0.61,0.15,0.17,0.02,0.88,0.05,0.01,0.01
18.84575992478355,0.0016754858408761625,71.45162047061893,300.0,8.333333333333333e-05,0.61,0.15,0.17,0.02,0.88,0.05,0.01,0.01
18.9955868180484,0.0016879714153149,71.69828730701515,300.0,8.333333333333333e-05,0.61,0.15,0.17,0.02,0.88,0.05,0.01,0.01
19.15385306424255,0.0017011602691644125,71.93582651202917,300.0,8.333333333333333e-05,0.61,0.15,0.17,0.02,0.88,0.05,0.01,0.01
19.3121193104367,0.001714349123013925,72.17336571704377,300.0,8.333333333333333e-05,0.61,0.15,0.17,0.02,0.88,0.05,0.01,0.01
19.470385556630852,0.0017275379768634375,72.41090492205788,300.0,8.333333333333333e-05,0.61,0.15,0.17,0.02,0.88,0.05,0.01,0.01
19.628651802825,0.00174072683071295,72.64844412707092,300.0,8.333333333333333e-05,0.61,0.15,0.17,0.02,0.88,0.05,0.01,0.01
19.78691804901915,0.0017539156845624625,72.88598333208492,300.0,8.333333333333333e-05,0.61,0.15,0.17,0.02,0.88,0.05,0.01,0.01
19.945184295213302,0.001767104538411975,73.12352253709928,300.0,8.333333333333333e-05,0.61,0.15,0.17,0.02,0.88,0.05,0.01,0.01
20.10345054140745,0.0017802933922614875,73.36106174211318,300.0,8.333333333333333e-05,0.61,0.15,0.17,0.02,0.88,0.05,0.01,0.01
20.2617167876016,0.001793482246111,73.59860094712725,300.0,8.333333333333333e-05,0.61,0.15,0.17,0.02,0.88,0.05,0.01,0.01
20.421345866772,0.0018067846693751999,73.82467887777477,300.0,8.333333333333333e-05,0.61,0.15,0.17,0.02,0.88,0.05,0.01,0.01
20.5809749459424,0.0018200870926394,74.0507568084228,300.0,8.333333333333333e-05,0.61,0.15,0.17,0.02,0.88,0.05,0.01,0.01
20.740604025112802,0.0018333895159036002,74.27683473907047,300.0,8.333333333333333e-05,0.61,0.15,0.17,0.02,0.88,0.05,0.01,0.01
20.9002331042832,0.0018466919391678,74.50291266971792,300.0,8.333333333333333e-05,0.61,0.15,0.17,0.02,0.88,0.05,0.01,0.01
21.059862183453596,0.001859994362432,74.72899060036542,300.0,8.333333333333333e-05,0.61,0.15,0.17,0.02,0.88,0.05,0.01,0.01
21.219491262623997,0.0018732967856962,74.95506853101215,300.0,8.333333333333333e-05,0.61,0.15,0.17,0.02,0.88,0.05,0.01,0.01
21.379120341794398,0.0018865992089603999,75.18114646165951,300.0,8.333333333333333e-05,0.61,0.15,0.17,0.02,0.88,0.05,0.01,0.01
21.5387494209648,0.0018999016322246,75.40722439230669,300.0,8.333333333333333e-05,0.61,0.15,0.17,0.02,0.88,0.05,0.01,0.01
21.732701343421347,0.0019160642924293124,75.6326829745817,300.0,8.333333333333333e-05,0.61,0.15,0.17,0.02,0.88,0.05,0.01,0.01
21.9266532658779,0.001932226952634025,75.85814155685739,300.0,8.333333333333333e-05,0.61,0.15,0.17,0.02,0.88,0.05,0.01,0.01
22.12060518833445,0.0019483896128387375,76.08360013913224,300.0,8.333333333333333e-05,0.61,0.15,0.17,0.02,0.88,0.05,0.01,0.01
22.314557110791,0.00196455227304345,76.30905872140721,300.0,8.333333333333333e-05,0.61,0.15,0.17,0.02,0.88,0.05,0.01,0.01
22.50850903324755,0.0019807149332481625,76.53451730368218,300.0,8.333333333333333e-05,0.61,0.15,0.17,0.02,0.88,0.05,0.01,0.01
22.702460955704098,0.0019968775934528747,76.75997588595692,300.0,8.333333333333333e-05,0.61,0.15,0.17,0.02,0.88,0.05,0.01,0.01
22.896412878160646,0.0020130402536575874,76.98543446823187,300.0,8.333333333333333e-05,0.61,0.15,0.17,0.02,0.88,0.05,0.01,0.01
23.0903648006172,0.0020292029138623,77.21089305050688,300.0,8.333333333333333e-05,0.61,0.15,0.17,0.02,0.88,0.05,0.01,0.01
23.29039017543075,0.0020458716950967626,77.42124366430603,300.0,8.333333333333333e-05,0.61,0.15,0.17,0.02,0.88,0.05,0.01,0.01
23.4904155502443,0.002062540476331225,77.63159427810604,300.0,8.333333333333333e-05,0.61,0.15,0.17,0.02,0.88,0.05,0.01,0.01
23.69044092505785,0.002079209257565688,77.84194489190543,300.0,8.333333333333333e-05,0.61,0.15,0.17,0.02,0.88,0.05,0.01,0.01
23.8904662998714,0.00209587803880015,78.05229550570374,300.0,8.333333333333333e-05,0.61,0.15,0.17,0.02,0.88,0.05,0.01,0.01
24.090491674684948,0.002112546820034612,78.2626461195029,300.0,8.333333333333333e-05,0.61,0.15,0.17,0.02,0.88,0.05,0.01,0.01
24.290517049498497,0.0021292156012690747,78.47299673330212,300.0,8.333333333333333e-05,0.61,0.15,0.17,0.02,0.88,0.05,0.01,0.01
24.490542424312046,0.0021458843825035373,78.68334734710115,300.0,8.333333333333333e-05,0.61,0.15,0.17,0.02,0.88,0.05,0.01,0.01
24.6905677991256,0.002162553163738,78.8936979609005,300.0,8.333333333333333e-05,0.61,0.15,0.17,0.02,0.88,0.05,0.01,0.01
24.896722097414248,0.0021797326885953875,79.0827188345976,300.0,8.333333333333333e-05,0.61,0.15,0.17,0.02,0.88,0.05,0.01,0.01
25.1028763957029,0.002196912213452775,79.27173970829449,300.0,8.333333333333333e-05,0.61,0.15,0.17,0.02,0.88,0.05,0.01,0.01
25.30903069399155,0.0022140917383101626,79.4607605819917,300.0,8.333333333333333e-05,0.61,0.15,0.17,0.02,0.88,0.05,0.01,0.01
25.515184992280197,0.00223127126316755,79.64978145568902,300.0,8.333333333333333e-05,0.61,0.15,0.17,0.02,0.88,0.05,0.01,0.01
25.72133929056885,0.0022484507880249378,79.83880232938614,300.0,8.333333333333333e-05,0.61,0.15,0.17,0.02,0.88,0.05,0.01,0.01
25.927493588857498,0.0022656303128823253,80.0278232030827,300.0,8.333333333333333e-05,0.61,0.15,0.17,0.02,0.88,0.05,0.01,0.01
26.133647887146147,0.002282809837739713,80.21684407677974,300.0,8.333333333333333e-05,0.61,0.15,0.17,0.02,0.88,0.05,0.01,0.01
26.3398021854348,0.0022999893625971,80.40586495047737,300.0,8.333333333333333e-05,0.61,0.15,0.17,0.02,0.88,0.05,0.01,0.01
26.5930924415343,0.002321096883938725,80.57772234727136,300.0,8.333333333333333e-05,0.61,0.15,0.17,0.02,0.88,0.05,0.01,0.01
26.8463826976338,0.0023422044052803497,80.74957974406584,300.0,8.333333333333333e-05,0.61,0.15,0.17,0.02,0.88,0.05,0.01,0.01
27.0996729537333,0.0023633119266219748,80.92143714085987,300.0,8.333333333333333e-05,0.61,0.15,0.17,0.02,0.88,0.05,0.01,0.01
27.3529632098328,0.0023844194479636,81.09329453765339,300.0,8.333333333333333e-05,0.61,0.15,0.17,0.02,0.88,0.05,0.01,0.01
27.6062534659323,0.002405526969305225,81.26515193444737,300.0,8.333333333333333e-05,0.61,0.15,0.17,0.02,0.88,0.05,0.01,0.01
27.859543722031802,0.00242663449064685,81.43700933124111,300.0,8.333333333333333e-05,0.61,0.15,0.17,0.02,0.88,0.05,0.01,0.01
28.112833978131302,0.002447742011988475,81.60886672803517,300.0,8.333333333333333e-05,0.61,0.15,0.17,0.02,0.88,0.05,0.01,0.01
28.366124234230803,0.0024688495333301,81.78072412482916,300.0,8.333333333333333e-05,0.61,0.15,0.17,0.02,0.88,0.05,0.01,0.01
28.65276871179315,0.0024927365731269623,81.9369735702318,300.0,8.333333333333333e-05,0.61,0.15,0.17,0.02,0.88,0.05,0.01,0.01
28.939413189355502,0.002516623612923825,82.09322301563492,300.0,8.333333333333333e-05,0.61,0.15,0.17,0.02,0.88,0.05,0.01,0.01
29.226057666917853,0.0025405106527206876,82.24947246103744,300.0,8.333333333333333e-05,0.61,0.15,0.17,0.02,0.88,0.05,0.01,0.01
29.5127021444802,0.0025643976925175498,82.40572190643952,300.0,8.333333333333333e-05,0.61,0.15,0.17,0.02,0.88,0.05,0.01,0.01
29.79934662204255,0.0025882847323144124,82.56197135184222,300.0,8.333333333333333e-05,0.61,0.15,0.17,0.02,0.88,0.05,0.01,0.01
30.0859910996049,0.002612171772111275,82.71822079724527,300.0,8.333333333333333e-05,0.61,0.15,0.17,0.02,0.88,0.05,0.01,0.01
30.37263557716725,0.0026360588119081372,82.87447024264796,300.0,8.333333333333333e-05,0.61,0.15,0.17,0.02,0.88,0.05,0.01,0.01
30.6592800547296,0.002659945851705,83.03071968805074,300.0,8.333333333333333e-05,0.61,0.15,0.17,0.02,0.88,0.05,0.01,0.01
30.9586047681501,0.0026848895778233753,83.1650540316653,300.0,8.333333333333333e-05,0.61,0.15,0.17,0.02,0.88,0.05,0.01,0.01
31.2579294815706,0.0027098333039417503,83.2993883752796,300.0,8.333333333333333e-05,0.61,0.15,0.17,0.02,0.88,0.05,0.01,0.01
31.557254194991103,0.0027347770300601253,83.43372271889407,300.0,8.333333333333333e-05,0.61,0.15,0.17,0.02,0.88,0.05,0.01,0.01
31.856578908411603,0.0027597207561785003,83.56805706250876,300.0,8.333333333333333e-05,0.61,0.15,0.17,0.02,0.88,0.05,0.01,0.01
32.1559036218321,0.0027846644822968752,83.70239140612331,300.0,8.333333333333333e-05,0.61,0.15,0.17,0.02,0.88,0.05,0.01,0.01
32.455228335252606,0.0028096082084152502,83.83672574973792,300.0,8.333333333333333e-05,0.61,0.15,0.17,0.02,0.88,0.05,0.01,0.01
32.7545530486731,0.0028345519345336252,83.97106009335265,300.0,8.333333333333333e-05,0.61,0.15,0.17,0.02,0.88,0.05,0.01,0.01
33.053877762093606,0.002859495660652,84.10539443696707,300.0,8.333333333333333e-05,0.61,0.15,0.17,0.02,0.88,0.05,0.01,0.01
33.39042456506566,0.0028875412275663377,84.22209487398098,300.0,8.333333333333333e-05,0.61,0.15,0.17,0.02,0.88,0.05,0.01,0.01
33.7269713680377,0.0029155867944806752,84.33879531099495,300.0,8.333333333333333e-05,0.61,0.15,0.17,0.02,0.88,0.05,0.01,0.01
34.06351817100975,0.0029436323613950127,84.45549574800872,300.0,8.333333333333333e-05,0.61,0.15,0.17,0.02,0.88,0.05,0.01,0.01
34.4000649739818,0.0029716779283093502,84.57219618502172,300.0,8.333333333333333e-05,0.61,0.15,0.17,0.02,0.88,0.05,0.01,0.01
34.73661177695385,0.0029997234952236877,84.68889662203564,300.0,8.333333333333333e-05,0.61,0.15,0.17,0.02,0.88,0.05,0.01,0.01
35.0731585799259,0.0030277690621380252,84.80559705905029,300.0,8.333333333333333e-05,0.61,0.15,0.17,0.02,0.88,0.05,0.01,0.01
35.409705382897954,0.0030558146290523627,84.9222974960643,300.0,8.333333333333333e-05,0.61,0.15,0.17,0.02,0.88,0.05,0.01,0.01
35.74625218587,0.0030838601959667,85.03899793307839,300.0,8.333333333333333e-05,0.61,0.15,0.17,0.02,0.88,0.05,0.01,0.01
36.11440228245405,0.0031145393706820375,85.12889997464958,300.0,8.333333333333333e-05,0.61,0.15,0.17,0.02,0.88,0.05,0.01,0.01
36.4825523790381,0.003145218545397375,85.21880201622037,300.0,8.333333333333333e-05,0.61,0.15,0.17,0.02,0.88,0.05,0.01,0.01
36.85070247562215,0.003175897720112712,85.3087040577915,300.0,8.333333333333333e-05,0.61,0.15,0.17,0.02,0.88,0.05,0.01,0.01
37.2188525722062,0.00320657689482805,85.39860609936339,300.0,8.333333333333333e-05,0.61,0.15,0.17,0.02,0.88,0.05,0.01,0.01
37.58700266879025,0.0032372560695433875,85.48850814093461,300.0,8.333333333333333e-05,0.61,0.15,0.17,0.02,0.88,0.05,0.01,0.01
37.9551527653743,0.003267935244258725,85.57841018250514,300.0,8.333333333333333e-05,0.61,0.15,0.17,0.02,0.88,0.05,0.01,0.01
38.323302861958354,0.003298614418974062,85.66831222407652,300.0,8.333333333333333e-05,0.61,0.15,0.17,0.02,0.88,0.05,0.01,0.01
38.6914529585424,0.0033292935936894,85.75821426564879,300.0,8.333333333333333e-05,0.61,0.15,0.17,0.02,0.88,0.05,0.01,0.01
39.111288681042,0.0033642799038977,85.83123787066663,300.0,8.333333333333333e-05,0.61,0.15,0.17,0.02,0.88,0.05,0.01,0.01
39.5311244035416,0.003399266214106,85.90426147568331,300.0,8.333333333333333e-05,0.61,0.15,0.17,0.02,0.88,0.05,0.01,0.01
39.950960126041196,0.0034342525243143,85.97728508070117,300.0,8.333333333333333e-05,0.61,0.15,0.17,0.02,0.88,0.05,0.01,0.01
40.370795848540794,0.0034692388345226,86.0503086857199,300.0,8.333333333333333e-05,0.61,0.15,0.17,0.02,0.88,0.05,0.01,0.01
40.79063157104039,0.0035042251447308997,86.12333229073768,300.0,8.333333333333333e-05,0.61,0.15,0.17,0.02,0.88,0.05,0.01,0.01
41.21046729353999,0.0035392114549391996,86.19635589575567,300.0,8.333333333333333e-05,0.61,0.15,0.17,0.02,0.88,0.05,0.01,0.01
41.63030301603959,0.0035741977651474995,86.26937950077338,300.0,8.333333333333333e-05,0.61,0.15,0.17,0.02,0.88,0.05,0.01,0.01
42.0501387385392,0.0036091840753558,86.34240310579008,300.0,8.333333333333333e-05,0.61,0.15,0.17,0.02,0.88,0.05,0.01,0.01
42.50154392524905,0.0036468011742482875,86.40018915715659,300.0,8.333333333333333e-05,0.61,0.15,0.17,0.02,0.88,0.05,0.01,0.01
42.9529491119589,0.003684418273140775,86.45797520852402,300.0,8.333333333333333e-05,0.61,0.15,0.17,0.02,0.88,0.05,0.01,0.01
43.40435429866875,0.0037220353720332625,86.51576125989041,300.0,8.333333333333333e-05,0.61,0.15,0.17,0.02,0.88,0.05,0.01,0.01
43.8557594853786,0.0037596524709257503,86.57354731125605,300.0,8.333333333333333e-05,0.61,0.15,0.17,0.02,0.88,0.05,0.01,0.01
44.30716467208845,0.0037972695698182376,86.63133336262258,300.0,8.333333333333333e-05,0.61,0.15,0.17,0.02,0.88,0.05,0.01,0.01
44.7585698587983,0.0038348866687107253,86.68911941398976,300.0,8.333333333333333e-05,0.61,0.15,0.17,0.02,0.88,0.05,0.01,0.01
45.20997504550816,0.003872503767603213,86.74690546535635,300.0,8.333333333333333e-05,0.61,0.15,0.17,0.02,0.88,0.05,0.01,0.01
45.66138023221801,0.0039101208664957,86.80469151672287,300.0,8.333333333333333e-05,0.61,0.15,0.17,0.02,0.88,0.05,0.01,0.01
46.14618874875751,0.003950521576207325,86.85015177511964,300.0,8.333333333333333e-05,0.61,0.15,0.17,0.02,0.88,0.05,0.01,0.01
46.63099726529701,0.003990922285918951,86.89561203351678,300.0,8.333333333333333e-05,0.61,0.15,0.17,0.02,0.88,0.05,0.01,0.01
47.115805781836514,0.004031322995630576,86.9410722919136,300.0,8.333333333333333e-05,0.61,0.15,0.17,0.02,0.88,0.05,0.01,0.01
47.60061429837601,0.004071723705342201,86.9865325503102,300.0,8.333333333333333e-05,0.61,0.15,0.17,0.02,0.88,0.05,0.01,0.01
48.0854228149155,0.0041121244150538255,87.03199280870697,300.0,8.333333333333333e-05,0.61,0.15,0.17,0.02,0.88,0.05,0.01,0.01
48.570231331455005,0.00415252512476545,87.07745306710387,300.0,8.333333333333333e-05,0.61,0.15,0.17,0.02,0.88,0.05,0.01,0.01
49.05503984799451,0.004192925834477075,87.12291332550068,300.0,8.333333333333333e-05,0.61,0.15,0.17,0.02,0.88,0.05,0.01,0.01
49.53984836453401,0.0042333265441887,87.16837358389662,300.0,8.333333333333333e-05,0.61,0.15,0.17,0.02,0.88,0.05,0.01,0.01
50.03697032189386,0.004274753373968688,87.19737707894488,300.0,8.333333333333333e-05,0.61,0.15,0.17,0.02,0.88,0.05,0.01,0.01
50.534092279253706,0.004316180203748675,87.22638057399399,300.0,8.333333333333333e-05,0.61,0.15,0.17,0.02,0.88,0.05,0.01,0.01
51.03121423661355,0.004357607033528663,87.25538406904207,300.0,8.333333333333333e-05,0.61,0.15,0.17,0.02,0.88,0.05,0.01,0.01
51.5283361939734,0.00439903386330865,87.28438756408983,300.0,8.333333333333333e-05,0.61,0.15,0.17,0.02,0.88,0.05,0.01,0.01
52.025458151333254,0.004440460693088638,87.3133910591381,300.0,8.333333333333333e-05,0.61,0.15,0.17,0.02,0.88,0.05,0.01,0.01
52.522580108693106,0.0044818875228686255,87.34239455418619,300.0,8.333333333333333e-05,0.61,0.15,0.17,0.02,0.88,0.05,0.01,0.01
53.01970206605296,0.004523314352648612,87.37139804923457,300.0,8.333333333333333e-05,0.61,0.15,0.17,0.02,0.88,0.05,0.01,0.01
53.5168240234128,0.0045647411824286,87.40040154428304,300.0,8.333333333333333e-05,0.61,0.15,0.17,0.02,0.88,0.05,0.01,0.01
54.0474457306743,0.004608959658033724,87.41928565793177,300.0,8.333333333333333e-05,0.61,0.15,0.17,0.02,0.88,0.05,0.01,0.01
54.5780674379358,0.004653178133638849,87.4381697715804,300.0,8.333333333333333e-05,0.61,0.15,0.17,0.02,0.88,0.05,0.01,0.01
55.1086891451973,0.004697396609243974,87.4570538852291,300.0,8.333333333333333e-05,0.61,0.15,0.17,0.02,0.88,0.05,0.01,0.01
55.639310852458806,0.004741615084849099,87.47593799887805,300.0,8.333333333333333e-05,0.61,0.15,0.17,0.02,0.88,0.05,0.01,0.01
56.16993255972031,0.0047858335604542245,87.49482211252676,300.0,8.333333333333333e-05,0.61,0.15,0.17,0.02,0.88,0.05,0.01,0.01
56.700554266981804,0.0048300520360593496,87.5137062261756,300.0,8.333333333333333e-05,0.61,0.15,0.17,0.02,0.88,0.05,0.01,0.01
57.2311759742433,0.004874270511664475,87.53259033982448,300.0,8.333333333333333e-05,0.61,0.15,0.17,0.02,0.88,0.05,0.01,0.01
57.7617976815048,0.0049184889872696,87.55147445347306,300.0,8.333333333333333e-05,0.61,0.15,0.17,0.02,0.88,0.05,0.01,0.01
58.301533786569905,0.004963466996025024,87.56316908261405,300.0,8.333333333333333e-05,0.61,0.15,0.17,0.02,0.88,0.05,0.01,0.01
58.841269891635,0.00500844500478045,87.57486371175504,300.0,8.333333333333333e-05,0.61,0.15,0.17,0.02,0.88,0.05,0.01,0.01
59.3810059967001,0.005053423013535875,87.58655834089598,300.0,8.333333333333333e-05,0.61,0.15,0.17,0.02,0.88,0.05,0.01,0.01
59.9207421017652,0.0050984010222913,87.59825297003682,300.0,8.333333333333333e-05,0.61,0.15,0.17,0.02,0.88,0.05,0.01,0.01
60.4604782068303,0.005143379031046724,87.6099475991778,300.0,8.333333333333333e-05,0.61,0.15,0.17,0.02,0.88,0.05,0.01,0.01
61.0002143118954,0.00518835703980215,87.62164222831858,300.0,8.333333333333333e-05,0.61,0.15,0.17,0.02,0.88,0.05,0.01,0.01
61.539950416960494,0.005233335048557575,87.63333685745958,300.0,8.333333333333333e-05,0.61,0.15,0.17,0.02,0.88,0.05,0.01,0.01
62.0796865220256,0.005278313057313,87.64503148660079,300.0,8.333333333333333e-05,0.61,0.15,0.17,0.02,0.88,0.05,0.01,0.01
62.62931713676325,0.005324115608541137,87.65190364476712,300.0,8.333333333333333e-05,0.61,0.15,0.17,0.02,0.88,0.05,0.01,0.01
63.1789477515009,0.005369918159769275,87.6587758029335,300.0,8.333333333333333e-05,0.61,0.15,0.17,0.02,0.88,0.05,0.01,0.01
63.72857836623855,0.005415720710997413,87.6656479610998,300.0,8.333333333333333e-05,0.61,0.15,0.17,0.02,0.88,0.05,0.01,0.01
64.2782089809762,0.00546152326222555,87.67252011926558,300.0,8.333333333333333e-05,0.61,0.15,0.17,0.02,0.88,0.05,0.01,0.01
64.82783959571385,0.005507325813453687,87.67939227743193,300.0,8.333333333333333e-05,0.61,0.15,0.17,0.02,0.88,0.05,0.01,0.01
65.3774702104515,0.005553128364681825,87.68626443559896,300.0,8.333333333333333e-05,0.61,0.15,0.17,0.02,0.88,0.05,0.01,0.01
65.92710082518916,0.005598930915909963,87.69313659376535,300.0,8.333333333333333e-05,0.61,0.15,0.17,0.02,0.88,0.05,0.01,0.01
66.47673143992681,0.0056447334671381,87.70000875193178,300.0,8.333333333333333e-05,0.61,0.15,0.17,0.02,0.88,0.05,0.01,0.01
67.02879949055327,0.005690739138023638,87.7026608019273,300.0,8.333333333333333e-05,0.61,0.15,0.17,0.02,0.88,0.05,0.01,0.01
67.58086754117971,0.005736744808909175,87.70531285192301,300.0,8.333333333333333e-05,0.61,0.15,0.17,0.02,0.88,0.05,0.01,0.01
68.13293559180616,0.005782750479794712,87.70796490191867,300.0,8.333333333333333e-05,0.61,0.15,0.17,0.02,0.88,0.05,0.01,0.01
68.6850036424326,0.0058287561506802504,87.71061695191375,300.0,8.333333333333333e-05,0.61,0.15,0.17,0.02,0.88,0.05,0.01,0.01
69.23707169305905,0.005874761821565788,87.71326900190924,300.0,8.333333333333333e-05,0.61,0.15,0.17,0.02,0.88,0.05,0.01,0.01
69.7891397436855,0.005920767492451325,87.71592105190517,300.0,8.333333333333333e-05,0.61,0.15,0.17,0.02,0.88,0.05,0.01,0.01
70.34120779431194,0.005966773163336863,87.71857310190049,300.0,8.333333333333333e-05,0.61,0.15,0.17,0.02,0.88,0.05,0.01,0.01
70.8932758449384,0.0060127788342224,87.7212251518954,300.0,8.333333333333333e-05,0.61,0.15,0.17,0.02,0.88,0.05,0.01,0.01