File: datasets/al_6061_comp/csv/T_300_I_1.csv
Time,Strain(%),Stress(MPa),Temp(C),SR(%/s),Si(%),Fe(%),Cu(%),Mn(%),Mg(%),Cr(%),Zn(%),Ti(%)
0.0,9.99193291076019e-05,18.6208524175723,300.0,8.333333333333333e-05,0.68,0.23,0.2,0.04,0.87,0.05,0.02,0.02
0.10154499657119424,0.00010838141215520144,19.09980946299195,300.0,8.333333333333333e-05,0.68,0.23,0.2,0.04,0.87,0.05,0.02,0.02
0.2030899931423885,0.00011684349520280096,19.578766508411583,300.0,8.333333333333333e-05,0.68,0.23,0.2,0.04,0.87,0.05,0.02,0.02
0.3046349897135827,0.00012530557825040048,20.057723553831238,300.0,8.333333333333333e-05,0.68,0.23,0.2,0.04,0.87,0.05,0.02,0.02
0.406179986284777,0.000133767661298,20.536680599250907,300.0,8.333333333333333e-05,0.68,0.23,0.2,0.04,0.87,0.05,0.02,0.02
0.5477970911516771,0.000145569086703575,21.01329837624776,300.0,8.333333333333333e-05,0.68,0.23,0.2,0.04,0.87,0.05,0.02,0.02
0.6894141960185771,0.00015737051210915,21.4899161532446,300.0,8.333333333333333e-05,0.68,0.23,0.2,0.04,0.87,0.05,0.02,0.02
0.8310313008854772,0.000169171937514725,21.966533930241447,300.0,8.333333333333333e-05,0.68,0.23,0.2,0.04,0.87,0.05,0.02,0.02
0.9726484057523772,0.0001809733629203,22.443151707238293,300.0,8.333333333333333e-05,0.68,0.23,0.2,0.04,0.87,0.05,0.02,0.02
1.095833948298277,0.000191238824799125,22.92197322248512,300.0,8.333333333333333e-05,0.68,0.23,0.2,0.04,0.87,0.05,0.02,0.02
1.2190194908441772,0.00020150428667795002,23.40079473773195,300.0,8.333333333333333e-05,0.68,0.23,0.2,0.04,0.87,0.05,0.02,0.02
1.3422050333900772,0.000211769748556775,23.87961625297877,300.0,8.333333333333333e-05,0.68,0.23,0.2,0.04,0.87,0.05,0.02,0.02
1.465390575935977,0.0002220352104356,24.3584377682256,300.0,8.333333333333333e-05,0.68,0.23,0.2,0.04,0.87,0.05,0.02,0.02
1.6192651005449772,0.00023485808748634999,24.839852035457252,300.0,8.333333333333333e-05,0.68,0.23,0.2,0.04,0.87,0.05,0.02,0.02
1.7731396251539775,0.0002476809645371,25.32126630268891,300.0,8.333333333333333e-05,0.68,0.23,0.2,0.04,0.87,0.05,0.02,0.02
1.9270141497629776,0.00026050384158785,25.80268056992056,300.0,8.333333333333333e-05,0.68,0.23,0.2,0.04,0.87,0.05,0.02,0.02
2.0808886743719777,0.0002733267186386,26.2840948371522,300.0,8.333333333333333e-05,0.68,0.23,0.2,0.04,0.87,0.05,0.02,0.02
2.2326928060952778,0.00028597706294887504,26.747984557168998,300.0,8.333333333333333e-05,0.68,0.23,0.2,0.04,0.87,0.05,0.02,0.02
2.3844969378185774,0.00029862740725915,27.211874277185807,300.0,8.333333333333333e-05,0.68,0.23,0.2,0.04,0.87,0.05,0.02,0.02
2.536301069541877,0.00031127775156942496,27.6757639972026,300.0,8.333333333333333e-05,0.68,0.23,0.2,0.04,0.87,0.05,0.02,0.02
2.688105201265177,0.0003239280958797,28.139653717219304,300.0,8.333333333333333e-05,0.68,0.23,0.2,0.04,0.87,0.05,0.02,0.02
2.8100424725264768,0.000334089535151475,28.590735097003126,300.0,8.333333333333333e-05,0.68,0.23,0.2,0.04,0.87,0.05,0.02,0.02
2.931979743787777,0.00034425097442325,29.041816476787044,300.0,8.333333333333333e-05,0.68,0.23,0.2,0.04,0.87,0.05,0.02,0.02
3.053917015049077,0.000354412413695025,29.492897856570874,300.0,8.333333333333333e-05,0.68,0.23,0.2,0.04,0.87,0.05,0.02,0.02
3.1758542863103765,0.0003645738529668,29.943979236354615,300.0,8.333333333333333e-05,0.68,0.23,0.2,0.04,0.87,0.05,0.02,0.02
3.2684522046269766,0.00037229034615984997,30.406324519983833,300.0,8.333333333333333e-05,0.68,0.23,0.2,0.04,0.87,0.05,0.02,0.02
3.3610501229435767,0.0003800068393529,30.868669803613074,300.0,8.333333333333333e-05,0.68,0.23,0.2,0.04,0.87,0.05,0.02,0.02
3.453648041260177,0.00038772333254595,31.331015087242307,300.0,8.333333333333333e-05,0.68,0.23,0.2,0.04,0.87,0.05,0.02,0.02
3.546245959576777,0.000395439825739,31.793360370871525,300.0,8.333333333333333e-05,0.68,0.23,0.2,0.04,0.87,0.05,0.02,0.02
3.679278927645277,0.000406525906411375,32.24392719854551,300.0,8.333333333333333e-05,0.68,0.23,0.2,0.04,0.87,0.05,0.02,0.02
3.812311895713777,0.00041761198708375,32.69449402621949,300.0,8.333333333333333e-05,0.68,0.23,0.2,0.04,0.87,0.05,0.02,0.02
3.9453448637822772,0.00042869806775612496,33.14506085389345,300.0,8.333333333333333e-05,0.68,0.23,0.2,0.04,0.87,0.05,0.02,0.02
4.078377831850777,0.0004397841484285,33.59562768156747,300.0,8.333333333333333e-05,0.68,0.23,0.2,0.04,0.87,0.05,0.02,0.02
4.230097148784278,0.000452427424839625,34.03342979345657,300.0,8.333333333333333e-05,0.68,0.23,0.2,0.04,0.87,0.05,0.02,0.02
4.381816465717778,0.00046507070125075,34.47123190534563,300.0,8.333333333333333e-05,0.68,0.23,0.2,0.04,0.87,0.05,0.02,0.02
4.533535782651278,0.000477713977661875,34.909034017234745,300.0,8.333333333333333e-05,0.68,0.23,0.2,0.04,0.87,0.05,0.02,0.02
4.6852550995847775,0.000490357254073,35.34683612912389,300.0,8.333333333333333e-05,0.68,0.23,0.2,0.04,0.87,0.05,0.02,0.02
4.864107577160377,0.0005052616272043,35.78144850948591,300.0,8.333333333333333e-05,0.68,0.23,0.2,0.04,0.87,0.05,0.02,0.02
5.042960054735977,0.0005201660003356,36.21606088984795,300.0,8.333333333333333e-05,0.68,0.23,0.2,0.04,0.87,0.05,0.02,0.02
5.221812532311578,0.0005350703734669,36.65067327020992,300.0,8.333333333333333e-05,0.68,0.23,0.2,0.04,0.87,0.05,0.02,0.02
5.400665009887177,0.0005499747465982,37.08528565057185,300.0,8.333333333333333e-05,0.68,0.23,0.2,0.04,0.87,0.05,0.02,0.02
5.467348983473977,0.0005555317443970999,37.50608293768999,300.0,8.333333333333333e-05,0.68,0.23,0.2,0.04,0.87,0.05,0.02,0.02
5.534032957060777,0.0005610887421959999,37.92688022480808,300.0,8.333333333333333e-05,0.68,0.23,0.2,0.04,0.87,0.05,0.02,0.02
5.600716930647577,0.0005666457399948999,38.34767751192629,300.0,8.333333333333333e-05,0.68,0.23,0.2,0.04,0.87,0.05,0.02,0.02
5.667400904234377,0.0005722027377938,38.768474799044604,300.0,8.333333333333333e-05,0.68,0.23,0.2,0.04,0.87,0.05,0.02,0.02
5.761485595127677,0.0005800431287015749,39.18779774523575,300.0,8.333333333333333e-05,0.68,0.23,0.2,0.04,0.87,0.05,0.02,0.02
5.855570286020978,0.00058788351960935,39.60712069142703,300.0,8.333333333333333e-05,0.68,0.23,0.2,0.04,0.87,0.05,0.02,0.02
5.949654976914278,0.0005957239105171251,40.02644363761816,300.0,8.333333333333333e-05,0.68,0.23,0.2,0.04,0.87,0.05,0.02,0.02
6.043739667807578,0.0006035643014249,40.44576658380916,300.0,8.333333333333333e-05,0.68,0.23,0.2,0.04,0.87,0.05,0.02,0.02
6.171119248196378,0.0006141792664573,40.845946593766215,300.0,8.333333333333333e-05,0.68,0.23,0.2,0.04,0.87,0.05,0.02,0.02
6.298498828585178,0.0006247942314896999,41.24612660372321,300.0,8.333333333333333e-05,0.68,0.23,0.2,0.04,0.87,0.05,0.02,0.02
6.425878408973977,0.0006354091965221,41.64630661368028,300.0,8.333333333333333e-05,0.68,0.23,0.2,0.04,0.87,0.05,0.02,0.02
6.553257989362777,0.0006460241615545,42.04648662363739,300.0,8.333333333333333e-05,0.68,0.23,0.2,0.04,0.87,0.05,0.02,0.02
6.686215363257277,0.000657103942712375,42.441813489199475,300.0,8.333333333333333e-05,0.68,0.23,0.2,0.04,0.87,0.05,0.02,0.02
6.819172737151777,0.0006681837238702499,42.83714035476163,300.0,8.333333333333333e-05,0.68,0.23,0.2,0.04,0.87,0.05,0.02,0.02
6.9521301110462765,0.0006792635050281249,43.23246722032369,300.0,8.333333333333333e-05,0.68,0.23,0.2,0.04,0.87,0.05,0.02,0.02
7.085087484940777,0.000690343286186,43.627794085885704,300.0,8.333333333333333e-05,0.68,0.23,0.2,0.04,0.87,0.05,0.02,0.02
7.229004172946677,0.000702336343519825,44.01290735058353,300.0,8.333333333333333e-05,0.68,0.23,0.2,0.04,0.87,0.05,0.02,0.02
7.372920860952577,0.0007143294008536501,44.39802061528137,300.0,8.333333333333333e-05,0.68,0.23,0.2,0.04,0.87,0.05,0.02,0.02
7.5168375489584776,0.0007263224581874751,44.78313387997923,300.0,8.333333333333333e-05,0.68,0.23,0.2,0.04,0.87,0.05,0.02,0.02
7.660754236964378,0.0007383155155213,45.168247144677096,300.0,8.333333333333333e-05,0.68,0.23,0.2,0.04,0.87,0.05,0.02,0.02
7.785262954606178,0.00074869124199145,45.55257996725335,300.0,8.333333333333333e-05,0.68,0.23,0.2,0.04,0.87,0.05,0.02,0.02
7.909771672247977,0.0007590669684616001,45.93691278982969,300.0,8.333333333333333e-05,0.68,0.23,0.2,0.04,0.87,0.05,0.02,0.02
8.034280389889776,0.00076944269493175,46.32124561240598,300.0,8.333333333333333e-05,0.68,0.23,0.2,0.04,0.87,0.05,0.02,0.02
8.158789107531577,0.0007798184214019,46.70557843498245,300.0,8.333333333333333e-05,0.68,0.23,0.2,0.04,0.87,0.05,0.02,0.02
8.229466855334078,0.000785708233718775,47.085940852636604,300.0,8.333333333333333e-05,0.68,0.23,0.2,0.04,0.87,0.05,0.02,0.02
8.300144603136577,0.00079159804603565,47.46630327029022,300.0,8.333333333333333e-05,0.68,0.23,0.2,0.04,0.87,0.05,0.02,0.02
8.370822350939076,0.0007974878583525251,47.84666568794429,300.0,8.333333333333333e-05,0.68,0.23,0.2,0.04,0.87,0.05,0.02,0.02
8.441500098741576,0.0008033776706694,48.22702810559856,300.0,8.333333333333333e-05,0.68,0.23,0.2,0.04,0.87,0.05,0.02,0.02
8.601517117332275,0.0008167124222186249,48.60495973325432,300.0,8.333333333333333e-05,0.68,0.23,0.2,0.04,0.87,0.05,0.02,0.02
8.761534135922975,0.0008300471737678499,48.98289136091013,300.0,8.333333333333333e-05,0.68,0.23,0.2,0.04,0.87,0.05,0.02,0.02
8.921551154513676,0.000843381925317075,49.36082298856587,300.0,8.333333333333333e-05,0.68,0.23,0.2,0.04,0.87,0.05,0.02,0.02
9.081568173104376,0.0008567166768663,49.73875461622135,300.0,8.333333333333333e-05,0.68,0.23,0.2,0.04,0.87,0.05,0.02,0.02
9.239586835667676,0.000869884898746575,50.10855647968862,300.0,8.333333333333333e-05,0.68,0.23,0.2,0.04,0.87,0.05,0.02,0.02
9.397605498230977,0.00088305312062685,50.478358343156,300.0,8.333333333333333e-05,0.68,0.23,0.2,0.04,0.87,0.05,0.02,0.02
9.555624160794277,0.0008962213425071251,50.84816020662336,300.0,8.333333333333333e-05,0.68,0.23,0.2,0.04,0.87,0.05,0.02,0.02
9.713642823357578,0.0009093895643874,51.21796207009085,300.0,8.333333333333333e-05,0.68,0.23,0.2,0.04,0.87,0.05,0.02,0.02
9.813031957234777,0.0009176719922105001,51.5940957307583,300.0,8.333333333333333e-05,0.68,0.23,0.2,0.04,0.87,0.05,0.02,0.02
9.912421091111977,0.0009259544200336,51.97022939142566,300.0,8.333333333333333e-05,0.68,0.23,0.2,0.04,0.87,0.05,0.02,0.02
10.011810224989176,0.0009342368478567,52.346363052093054,300.0,8.333333333333333e-05,0.68,0.23,0.2,0.04,0.87,0.05,0.02,0.02
10.111199358866378,0.0009425192756798,52.72249671276051,300.0,8.333333333333333e-05,0.68,0.23,0.2,0.04,0.87,0.05,0.02,0.02
10.285331711940579,0.00095703030510265,53.08587215289971,300.0,8.333333333333333e-05,0.68,0.23,0.2,0.04,0.87,0.05,0.02,0.02
10.459464065014778,0.0009715413345255,53.44924759303896,300.0,8.333333333333333e-05,0.68,0.23,0.2,0.04,0.87,0.05,0.02,0.02
10.63359641808898,0.00098605236394835,53.81262303317815,300.0,8.333333333333333e-05,0.68,0.23,0.2,0.04,0.87,0.05,0.02,0.02
10.80772877116318,0.0010005633933712,54.17599847331755,300.0,8.333333333333333e-05,0.68,0.23,0.2,0.04,0.87,0.05,0.02,0.02
10.898316280912479,0.001008112352516975,54.54115582065852,300.0,8.333333333333333e-05,0.68,0.23,0.2,0.04,0.87,0.05,0.02,0.02
10.988903790661778,0.00101566131166275,54.90631316799898,300.0,8.333333333333333e-05,0.68,0.23,0.2,0.04,0.87,0.05,0.02,0.02
11.079491300411078,0.001023210270808525,55.27147051533995,300.0,8.333333333333333e-05,0.68,0.23,0.2,0.04,0.87,0.05,0.02,0.02
11.170078810160376,0.0010307592299543,55.63662786268105,300.0,8.333333333333333e-05,0.68,0.23,0.2,0.04,0.87,0.05,0.02,0.02
11.303289471974077,0.001041860118438775,56.00642564554359,300.0,8.333333333333333e-05,0.68,0.23,0.2,0.04,0.87,0.05,0.02,0.02
11.436500133787778,0.00105296100692325,56.37622342840625,300.0,8.333333333333333e-05,0.68,0.23,0.2,0.04,0.87,0.05,0.02,0.02
11.569710795601477,0.001064061895407725,56.7460212112688,300.0,8.333333333333333e-05,0.68,0.23,0.2,0.04,0.87,0.05,0.02,0.02
11.702921457415178,0.0010751627838922,57.11581899413131,300.0,8.333333333333333e-05,0.68,0.23,0.2,0.04,0.87,0.05,0.02,0.02
11.826293953499677,0.001085443825232575,57.47670182761771,300.0,8.333333333333333e-05,0.68,0.23,0.2,0.04,0.87,0.05,0.02,0.02
11.949666449584177,0.0010957248665729499,57.837584661104415,300.0,8.333333333333333e-05,0.68,0.23,0.2,0.04,0.87,0.05,0.02,0.02
12.073038945668676,0.001106005907913325,58.19846749459086,300.0,8.333333333333333e-05,0.68,0.23,0.2,0.04,0.87,0.05,0.02,0.02
12.196411441753176,0.0011162869492537,58.55935032807707,300.0,8.333333333333333e-05,0.68,0.23,0.2,0.04,0.87,0.05,0.02,0.02
12.347152656760777,0.001128848717171,58.917549354469905,300.0,8.333333333333333e-05,0.68,0.23,0.2,0.04,0.87,0.05,0.02,0.02
12.497893871768376,0.0011414104850883,59.27574838086226,300.0,8.333333333333333e-05,0.68,0.23,0.2,0.04,0.87,0.05,0.02,0.02
12.648635086775977,0.0011539722530056,59.63394740725503,300.0,8.333333333333333e-05,0.68,0.23,0.2,0.04,0.87,0.05,0.02,0.02
12.799376301783578,0.0011665340209229,59.99214643364863,300.0,8.333333333333333e-05,0.68,0.23,0.2,0.04,0.87,0.05,0.02,0.02
12.906540826500878,0.001175464397982675,60.36030569102048,300.0,8.333333333333333e-05,0.68,0.23,0.2,0.04,0.87,0.05,0.02,0.02
13.013705351218178,0.00118439477504245,60.728464948391604,300.0,8.333333333333333e-05,0.68,0.23,0.2,0.04,0.87,0.05,0.02,0.02
13.120869875935478,0.001193325152102225,61.09662420576339,300.0,8.333333333333333e-05,0.68,0.23,0.2,0.04,0.87,0.05,0.02,0.02
13.228034400652778,0.001202255529162,61.46478346313551,300.0,8.333333333333333e-05,0.68,0.23,0.2,0.04,0.87,0.05,0.02,0.02
13.386152789086777,0.0012154320615315,61.819783118993435,300.0,8.333333333333333e-05,0.68,0.23,0.2,0.04,0.87,0.05,0.02,0.02
13.544271177520777,0.001228608593901,62.174782774851465,300.0,8.333333333333333e-05,0.68,0.23,0.2,0.04,0.87,0.05,0.02,0.02
13.702389565954777,0.0012417851262705,62.52978243070946,300.0,8.333333333333333e-05,0.68,0.23,0.2,0.04,0.87,0.05,0.02,0.02
13.860507954388776,0.00125496165864,62.88478208656781,300.0,8.333333333333333e-05,0.68,0.23,0.2,0.04,0.87,0.05,0.02,0.02
13.979039742970176,0.00126483930768845,63.24104971686019,300.0,8.333333333333333e-05,0.68,0.23,0.2,0.04,0.87,0.05,0.02,0.02
14.097571531551576,0.0012747169567369,63.59731734715268,300.0,8.333333333333333e-05,0.68,0.23,0.2,0.04,0.87,0.05,0.02,0.02
14.216103320132977,0.0012845946057853498,63.95358497744501,300.0,8.333333333333333e-05,0.68,0.23,0.2,0.04,0.87,0.05,0.02,0.02
14.334635108714377,0.0012944722548338,64.30985260773707,300.0,8.333333333333333e-05,0.68,0.23,0.2,0.04,0.87,0.05,0.02,0.02
14.480275899090577,0.00130660898736515,64.66065643759842,300.0,8.333333333333333e-05,0.68,0.23,0.2,0.04,0.87,0.05,0.02,0.02
14.625916689466777,0.0013187457198965001,65.01146026745957,300.0,8.333333333333333e-05,0.68,0.23,0.2,0.04,0.87,0.05,0.02,0.02
14.77155747984298,0.0013308824524278502,65.36226409732092,300.0,8.333333333333333e-05,0.68,0.23,0.2,0.04,0.87,0.05,0.02,0.02
14.91719827021918,0.0013430191849592,65.7130679271823,300.0,8.333333333333333e-05,0.68,0.23,0.2,0.04,0.87,0.05,0.02,0.02
15.03961817927998,0.0013532208440476,66.06015343628307,300.0,8.333333333333333e-05,0.68,0.23,0.2,0.04,0.87,0.05,0.02,0.02
15.162038088340779,0.001363422503136,66.4072389453836,300.0,8.333333333333333e-05,0.68,0.23,0.2,0.04,0.87,0.05,0.02,0.02
15.28445799740158,0.0013736241622244,66.7543244544843,300.0,8.333333333333333e-05,0.68,0.23,0.2,0.04,0.87,0.05,0.02,0.02
15.40687790646238,0.0013838258213128,67.1014099635854,300.0,8.333333333333333e-05,0.68,0.23,0.2,0.04,0.87,0.05,0.02,0.02
15.56167115772058,0.00139672525891765,67.44826783687422,300.0,8.333333333333333e-05,0.68,0.23,0.2,0.04,0.87,0.05,0.02,0.02
15.71646440897878,0.0014096246965225,67.79512571016292,300.0,8.333333333333333e-05,0.68,0.23,0.2,0.04,0.87,0.05,0.02,0.02
15.87125766023698,0.00142252413412735,68.14198358345178,300.0,8.333333333333333e-05,0.68,0.23,0.2,0.04,0.87,0.05,0.02,0.02
16.02605091149518,0.0014354235717322,68.48884145674086,300.0,8.333333333333333e-05,0.68,0.23,0.2,0.04,0.87,0.05,0.02,0.02
16.18844700761248,0.0014489565797419749,68.83689177211701,300.0,8.333333333333333e-05,0.68,0.23,0.2,0.04,0.87,0.05,0.02,0.02
16.35084310372978,0.00146248958775175,69.18494208749269,300.0,8.333333333333333e-05,0.68,0.23,0.2,0.04,0.87,0.05,0.02,0.02
16.513239199847078,0.001476022595761525,69.53299240286901,300.0,8.333333333333333e-05,0.68,0.23,0.2,0.04,0.87,0.05,0.02,0.02
16.67563529596438,0.0014895556037713,69.88104271824533,300.0,8.333333333333333e-05,0.68,0.23,0.2,0.04,0.87,0.05,0.02,0.02
16.823877831276278,0.001501909148380625,70.21108751990839,300.0,8.333333333333333e-05,0.68,0.23,0.2,0.04,0.87,0.05,0.02,0.02
16.97212036658818,0.0015142626929899499,70.5411323215714,300.0,8.333333333333333e-05,0.68,0.23,0.2,0.04,0.87,0.05,0.02,0.02
17.12036290190008,0.001526616237599275,70.87117712323433,300.0,8.333333333333333e-05,0.68,0.23,0.2,0.04,0.87,0.05,0.02,0.02
17.26860543721198,0.0015389697822086,71.20122192489758,300.0,8.333333333333333e-05,0.68,0.23,0.2,0.04,0.87,0.05,0.02,0.02
17.399055204785682,0.0015498405961730751,71.53508682724713,300.0,8.333333333333333e-05,0.68,0.23,0.2,0.04,0.87,0.05,0.02,0.02
17.52950497235938,0.00156071141013755,71.8689517295964,300.0,8.333333333333333e-05,0.68,0.23,0.2,0.04,0.87,0.05,0.02,0.02
17.659954739933077,0.0015715822241020249,72.20281663194609,300.0,8.333333333333333e-05,0.68,0.23,0.2,0.04,0.87,0.05,0.02,0.02
17.79040450750678,0.0015824530380665,72.5366815342959,300.0,8.333333333333333e-05,0.68,0.23,0.2,0.04,0.87,0.05,0.02,0.02
17.920853401343678,0.001593323779219575,72.85648843178099,300.0,8.333333333333333e-05,0.68,0.23,0.2,0.04,0.87,0.05,0.02,0.02
18.051302295180577,0.0016041945203726501,73.17629532926605,300.0,8.333333333333333e-05,0.68,0.23,0.2,0.04,0.87,0.05,0.02,0.02
18.181751189017476,0.001615065261525725,73.49610222675112,300.0,8.333333333333333e-05,0.68,0.23,0.2,0.04,0.87,0.05,0.02,0.02
18.31220008285438,0.0016259360026788,73.81590912423634,300.0,8.333333333333333e-05,0.68,0.23,0.2,0.04,0.87,0.05,0.02,0.02
18.42852913986178,0.00163563009076275,74.13122985736355,300.0,8.333333333333333e-05,0.68,0.23,0.2,0.04,0.87,0.05,0.02,0.02
18.54485819686918,0.0016453241788467001,74.44655059049056,300.0,8.333333333333333e-05,0.68,0.23,0.2,0.04,0.87,0.05,0.02,0.02
18.661187253876577,0.0016550182669306502,74.76187132361761,300.0,8.333333333333333e-05,0.68,0.23,0.2,0.04,0.87,0.05,0.02,0.02
18.77751631088398,0.0016647123550146,75.07719205674448,300.0,8.333333333333333e-05,0.68,0.23,0.2,0.04,0.87,0.05,0.02,0.02
18.93816657533548,0.0016780998770522249,75.38838935639083,300.0,8.333333333333333e-05,0.68,0.23,0.2,0.04,0.87,0.05,0.02,0.02
19.098816839786977,0.00169148739908985,75.6995866560372,300.0,8.333333333333333e-05,0.68,0.23,0.2,0.04,0.87,0.05,0.02,0.02
19.259467104238478,0.001704874921127475,76.01078395568346,300.0,8.333333333333333e-05,0.68,0.23,0.2,0.04,0.87,0.05,0.02,0.02
19.42011736868998,0.0017182624431651,76.32198125533,300.0,8.333333333333333e-05,0.68,0.23,0.2,0.04,0.87,0.05,0.02,0.02
19.571789256029078,0.001730901767110025,76.62274727873893,300.0,8.333333333333333e-05,0.68,0.23,0.2,0.04,0.87,0.05,0.02,0.02
19.723461143368176,0.00174354109105495,76.92351330214873,300.0,8.333333333333333e-05,0.68,0.23,0.2,0.04,0.87,0.05,0.02,0.02
19.875133030707275,0.001756180414999875,77.22427932555814,300.0,8.333333333333333e-05,0.68,0.23,0.2,0.04,0.87,0.05,0.02,0.02
20.026804918046377,0.0017688197389448,77.52504534896666,300.0,8.333333333333333e-05,0.68,0.23,0.2,0.04,0.87,0.05,0.02,0.02
20.143544110930776,0.0017785480050185,77.81869329633864,300.0,8.333333333333333e-05,0.68,0.23,0.2,0.04,0.87,0.05,0.02,0.02
20.26028330381518,0.0017882762710922,78.11234124371066,300.0,8.333333333333333e-05,0.68,0.23,0.2,0.04,0.87,0.05,0.02,0.02
20.37702249669958,0.0017980045371659,78.40598919108237,300.0,8.333333333333333e-05,0.68,0.23,0.2,0.04,0.87,0.05,0.02,0.02
20.49376168958398,0.0018077328032396,78.69963713845404,300.0,8.333333333333333e-05,0.68,0.23,0.2,0.04,0.87,0.05,0.02,0.02
20.64639463288978,0.0018204522151817502,78.98633597661774,300.0,8.333333333333333e-05,0.68,0.23,0.2,0.04,0.87,0.05,0.02,0.02
20.79902757619558,0.0018331716271239,79.27303481478177,300.0,8.333333333333333e-05,0.68,0.23,0.2,0.04,0.87,0.05,0.02,0.02
20.95166051950138,0.00184589103906605,79.55973365294531,300.0,8.333333333333333e-05,0.68,0.23,0.2,0.04,0.87,0.05,0.02,0.02
21.10429346280718,0.0018586104510082,79.84643249110854,300.0,8.333333333333333e-05,0.68,0.23,0.2,0.04,0.87,0.05,0.02,0.02
21.26831183007358,0.0018722786482804,80.12263244278401,300.0,8.333333333333333e-05,0.68,0.23,0.2,0.04,0.87,0.05,0.02,0.02
21.43233019733998,0.0018859468455526,80.39883239445953,300.0,8.333333333333333e-05,0.68,0.23,0.2,0.04,0.87,0.05,0.02,0.02
21.59634856460638,0.0018996150428248,80.67503234613497,300.0,8.333333333333333e-05,0.68,0.23,0.2,0.04,0.87,0.05,0.02,0.02
21.76036693187278,0.001913283240097,80.9512322978098,300.0,8.333333333333333e-05,0.68,0.23,0.2,0.04,0.87,0.05,0.02,0.02
21.91884795956578,0.00192648999240475,81.21846193951244,300.0,8.333333333333333e-05,0.68,0.23,0.2,0.04,0.87,0.05,0.02,0.02
22.07732898725878,0.0019396967447125,81.48569158121596,300.0,8.333333333333333e-05,0.68,0.23,0.2,0.04,0.87,0.05,0.02,0.02
22.23581001495178,0.0019529034970202502,81.75292122291879,300.0,8.333333333333333e-05,0.68,0.23,0.2,0.04,0.87,0.05,0.02,0.02
22.39429104264478,0.001966110249328,82.02015086462124,300.0,8.333333333333333e-05,0.68,0.23,0.2,0.04,0.87,0.05,0.02,0.02
22.65361078601248,0.0019877202279419753,82.27706084109472,300.0,8.333333333333333e-05,0.68,0.23,0.2,0.04,0.87,0.05,0.02,0.02
22.91293052938018,0.00200933020655595,82.53397081756816,300.0,8.333333333333333e-05,0.68,0.23,0.2,0.04,0.87,0.05,0.02,0.02
23.17225027274788,0.0020309401851699247,82.79088079404161,300.0,8.333333333333333e-05,0.68,0.23,0.2,0.04,0.87,0.05,0.02,0.02
23.43157001611558,0.0020525501637839,83.04779077051512,300.0,8.333333333333333e-05,0.68,0.23,0.2,0.04,0.87,0.05,0.02,0.02
23.61626402509168,0.002067941331198575,83.30026306382165,300.0,8.333333333333333e-05,0.68,0.23,0.2,0.04,0.87,0.05,0.02,0.02
23.80095803406778,0.00208333249861325,83.55273535712828,300.0,8.333333333333333e-05,0.68,0.23,0.2,0.04,0.87,0.05,0.02,0.02
23.985652043043878,0.002098723666027925,83.80520765043494,300.0,8.333333333333333e-05,0.68,0.23,0.2,0.04,0.87,0.05,0.02,0.02
24.17034605201998,0.0021141148334426,84.05767994374122,300.0,8.333333333333333e-05,0.68,0.23,0.2,0.04,0.87,0.05,0.02,0.02
24.38471263342288,0.002131978715226175,84.29799238370258,300.0,8.333333333333333e-05,0.68,0.23,0.2,0.04,0.87,0.05,0.02,0.02
24.599079214825778,0.0021498425970097497,84.53830482366405,300.0,8.333333333333333e-05,0.68,0.23,0.2,0.04,0.87,0.05,0.02,0.02
24.813445796228677,0.0021677064787933246,84.77861726362522,300.0,8.333333333333333e-05,0.68,0.23,0.2,0.04,0.87,0.05,0.02,0.02
25.027812377631577,0.0021855703605769,85.01892970358608,300.0,8.333333333333333e-05,0.68,0.23,0.2,0.04,0.87,0.05,0.02,0.02
25.252559416125877,0.002204299280451425,85.24164905314814,300.0,8.333333333333333e-05,0.68,0.23,0.2,0.04,0.87,0.05,0.02,0.02
25.477306454620177,0.00222302820032595,85.46436840271065,300.0,8.333333333333333e-05,0.68,0.23,0.2,0.04,0.87,0.05,0.02,0.02
25.702053493114477,0.002241757120200475,85.68708775227283,300.0,8.333333333333333e-05,0.68,0.23,0.2,0.04,0.87,0.05,0.02,0.02
25.92680053160878,0.002260486040075,85.90980710183483,300.0,8.333333333333333e-05,0.68,0.23,0.2,0.04,0.87,0.05,0.02,0.02
26.20702647735868,0.002283838202220825,86.12171031650722,300.0,8.333333333333333e-05,0.68,0.23,0.2,0.04,0.87,0.05,0.02,0.02
26.48725242310858,0.0023071903643666503,86.33361353118009,300.0,8.333333333333333e-05,0.68,0.23,0.2,0.04,0.87,0.05,0.02,0.02
26.76747836885848,0.0023305425265124752,86.5455167458524,300.0,8.333333333333333e-05,0.68,0.23,0.2,0.04,0.87,0.05,0.02,0.02
27.04770431460838,0.0023538946886583,86.75741996052399,300.0,8.333333333333333e-05,0.68,0.23,0.2,0.04,0.87,0.05,0.02,0.02
27.27511896881068,0.0023728459098418253,86.95985071172359,300.0,8.333333333333333e-05,0.68,0.23,0.2,0.04,0.87,0.05,0.02,0.02
27.50253362301298,0.00239179713102535,87.16228146292303,300.0,8.333333333333333e-05,0.68,0.23,0.2,0.04,0.87,0.05,0.02,0.02
27.72994827721528,0.002410748352208875,87.36471221412262,300.0,8.333333333333333e-05,0.68,0.23,0.2,0.04,0.87,0.05,0.02,0.02
27.957362931417578,0.0024296995733924,87.56714296532245,300.0,8.333333333333333e-05,0.68,0.23,0.2,0.04,0.87,0.05,0.02,0.02
28.236924082952378,0.0024529963360203,87.75691657033957,300.0,8.333333333333333e-05,0.68,0.23,0.2,0.04,0.87,0.05,0.02,0.02
28.516485234487178,0.0024762930986482,87.94669017535728,300.0,8.333333333333333e-05,0.68,0.23,0.2,0.04,0.87,0.05,0.02,0.02
28.796046386021978,0.0024995898612761,88.13646378037447,300.0,8.333333333333333e-05,0.68,0.23,0.2,0.04,0.87,0.05,0.02,0.02
29.075607537556778,0.002522886623904,88.32623738539152,300.0,8.333333333333333e-05,0.68,0.23,0.2,0.04,0.87,0.05,0.02,0.02
29.354455928533476,0.0025461239898187248,88.50224003119851,300.0,8.333333333333333e-05,0.68,0.23,0.2,0.04,0.87,0.05,0.02,0.02
29.633304319510177,0.0025693613557334497,88.67824267700502,300.0,8.333333333333333e-05,0.68,0.23,0.2,0.04,0.87,0.05,0.02,0.02
29.91215271048688,0.002592598721648175,88.85424532281193,300.0,8.333333333333333e-05,0.68,0.23,0.2,0.04,0.87,0.05,0.02,0.02
30.191001101463577,0.0026158360875629,89.03024796861898,300.0,8.333333333333333e-05,0.68,0.23,0.2,0.04,0.87,0.05,0.02,0.02
30.507359954048077,0.0026421993252782753,89.18115369560277,300.0,8.333333333333333e-05,0.68,0.23,0.2,0.04,0.87,0.05,0.02,0.02
30.823718806632577,0.00266856256299365,89.3320594225864,300.0,8.333333333333333e-05,0.68,0.23,0.2,0.04,0.87,0.05,0.02,0.02
31.140077659217077,0.002694925800709025,89.48296514957039,300.0,8.333333333333333e-05,0.68,0.23,0.2,0.04,0.87,0.05,0.02,0.02
31.45643651180158,0.0027212890384244,89.63387087655526,300.0,8.333333333333333e-05,0.68,0.23,0.2,0.04,0.87,0.05,0.02,0.02
31.737441015071383,0.00274470608036355,89.77406765802257,300.0,8.333333333333333e-05,0.68,0.23,0.2,0.04,0.87,0.05,0.02,0.02
32.01844551834118,0.0027681231223027,89.91426443948879,300.0,8.333333333333333e-05,0.68,0.23,0.2,0.04,0.87,0.05,0.02,0.02
32.29945002161098,0.00279154016424185,90.0544612209559,300.0,8.333333333333333e-05,0.68,0.23,0.2,0.04,0.87,0.05,0.02,0.02
32.58045452488078,0.002814957206181,90.1946580024237,300.0,8.333333333333333e-05,0.68,0.23,0.2,0.04,0.87,0.05,0.02,0.02
32.93931101435848,0.0028448619136374753,90.32629257359409,300.0,8.333333333333333e-05,0.68,0.23,0.2,0.04,0.87,0.05,0.02,0.02
33.29816750383618,0.00287476662109395,90.45792714476492,300.0,8.333333333333333e-05,0.68,0.23,0.2,0.04,0.87,0.05,0.02,0.02
33.657023993313885,0.002904671328550425,90.58956171593533,300.0,8.333333333333333e-05,0.68,0.23,0.2,0.04,0.87,0.05,0.02,0.02
34.01588048279158,0.0029345760360069,90.72119628710581,300.0,8.333333333333333e-05,0.68,0.23,0.2,0.04,0.87,0.05,0.02,0.02
34.368703623797984,0.0029639779644241,90.8372984732859,300.0,8.333333333333333e-05,0.68,0.23,0.2,0.04,0.87,0.05,0.02,0.02
34.72152676480438,0.0029933798928413,90.95340065946502,300.0,8.333333333333333e-05,0.68,0.23,0.2,0.04,0.87,0.05,0.02,0.02
35.07434990581078,0.0030227818212585,91.06950284564522,300.0,8.333333333333333e-05,0.68,0.23,0.2,0.04,0.87,0.05,0.02,0.02
35.427173046817174,0.0030521837496757,91.1856050318262,300.0,8.333333333333333e-05,0.68,0.23,0.2,0.04,0.87,0.05,0.02,0.02
35.88016522460097,0.0030899330978243498,91.28074302672151,300.0,8.333333333333333e-05,0.68,0.23,0.2,0.04,0.87,0.05,0.02,0.02
36.33315740238477,0.003127682445973,91.37588102161651,300.0,8.333333333333333e-05,0.68,0.23,0.2,0.04,0.87,0.05,0.02,0.02
36.78614958016857,0.00316543179412165,91.47101901651179,300.0,8.333333333333333e-05,0.68,0.23,0.2,0.04,0.87,0.05,0.02,0.02
37.239141757952375,0.0032031811422703,91.56615701140721,300.0,8.333333333333333e-05,0.68,0.23,0.2,0.04,0.87,0.05,0.02,0.02
37.68005853287367,0.003239924206847075,91.65007076781706,300.0,8.333333333333333e-05,0.68,0.23,0.2,0.04,0.87,0.05,0.02,0.02
38.12097530779498,0.00327666727142385,91.73398452422707,300.0,8.333333333333333e-05,0.68,0.23,0.2,0.04,0.87,0.05,0.02,0.02
38.56189208271628,0.003313410336000625,91.81789828063677,300.0,8.333333333333333e-05,0.68,0.23,0.2,0.04,0.87,0.05,0.02,0.02
39.002808857637575,0.0033501534005774,91.90181203704661,300.0,8.333333333333333e-05,0.68,0.23,0.2,0.04,0.87,0.05,0.02,0.02
39.426116457941376,0.00338542903393605,91.97320266044966,300.0,8.333333333333333e-05,0.68,0.23,0.2,0.04,0.87,0.05,0.02,0.02
39.84942405824518,0.0034207046672947,92.04459328385184,300.0,8.333333333333333e-05,0.68,0.23,0.2,0.04,0.87,0.05,0.02,0.02
40.27273165854898,0.0034559803006533503,92.11598390725494,300.0,8.333333333333333e-05,0.68,0.23,0.2,0.04,0.87,0.05,0.02,0.02
40.69603925885278,0.003491255934012,92.1873745306591,300.0,8.333333333333333e-05,0.68,0.23,0.2,0.04,0.87,0.05,0.02,0.02
41.164117372519776,0.00353026244348425,92.24736048307182,300.0,8.333333333333333e-05,0.68,0.23,0.2,0.04,0.87,0.05,0.02,0.02
41.632195486186774,0.0035692689529564997,92.30734643548382,300.0,8.333333333333333e-05,0.68,0.23,0.2,0.04,0.87,0.05,0.02,0.02
42.10027359985378,0.00360827546242875,92.36733238789648,300.0,8.333333333333333e-05,0.68,0.23,0.2,0.04,0.87,0.05,0.02,0.02
42.56835171352078,0.003647281971901,92.42731834030917,300.0,8.333333333333333e-05,0.68,0.23,0.2,0.04,0.87,0.05,0.02,0.02
43.06522870546017,0.0036886883878959496,92.47806754395289,300.0,8.333333333333333e-05,0.68,0.23,0.2,0.04,0.87,0.05,0.02,0.02
43.56210569739957,0.0037300948038909,92.5288167475964,300.0,8.333333333333333e-05,0.68,0.23,0.2,0.04,0.87,0.05,0.02,0.02
44.058982689338976,0.00377150121988585,92.57956595124021,300.0,8.333333333333333e-05,0.68,0.23,0.2,0.04,0.87,0.05,0.02,0.02
44.55585968127838,0.0038129076358808,92.63031515488439,300.0,8.333333333333333e-05,0.68,0.23,0.2,0.04,0.87,0.05,0.02,0.02
45.02706666456358,0.0038521748844879003,92.66798395053787,300.0,8.333333333333333e-05,0.68,0.23,0.2,0.04,0.87,0.05,0.02,0.02
45.49827364784878,0.003891442133095,92.70565274619145,300.0,8.333333333333333e-05,0.68,0.23,0.2,0.04,0.87,0.05,0.02,0.02
45.969480631133976,0.0039307093817021,92.74332154184475,300.0,8.333333333333333e-05,0.68,0.23,0.2,0.04,0.87,0.05,0.02,0.02
46.440687614419176,0.0039699766303092,92.78099033749811,300.0,8.333333333333333e-05,0.68,0.23,0.2,0.04,0.87,0.05,0.02,0.02
46.915824050280875,0.004009571333297674,92.80738792655244,300.0,8.333333333333333e-05,0.68,0.23,0.2,0.04,0.87,0.05,0.02,0.02
47.390960486142575,0.004049166036286149,92.83378551560646,300.0,8.333333333333333e-05,0.68,0.23,0.2,0.04,0.87,0.05,0.02,0.02
47.866096922004274,0.0040887607392746245,92.86018310466099,300.0,8.333333333333333e-05,0.68,0.23,0.2,0.04,0.87,0.05,0.02,0.02
48.34123335786597,0.0041283554422631,92.88658069371566,300.0,8.333333333333333e-05,0.68,0.23,0.2,0.04,0.87,0.05,0.02,0.02
48.846743346958164,0.00417048127468745,92.91377042576116,300.0,8.333333333333333e-05,0.68,0.23,0.2,0.04,0.87,0.05,0.02,0.02
49.35225333605037,0.0042126071071118,92.94096015780681,300.0,8.333333333333333e-05,0.68,0.23,0.2,0.04,0.87,0.05,0.02,0.02
49.85776332514257,0.004254732939536149,92.96814988985234,300.0,8.333333333333333e-05,0.68,0.23,0.2,0.04,0.87,0.05,0.02,0.02
50.363273314234775,0.0042968587719605,92.99533962189786,300.0,8.333333333333333e-05,0.68,0.23,0.2,0.04,0.87,0.05,0.02,0.02
50.876378266266876,0.0043396175179631746,93.01871395320416,300.0,8.333333333333333e-05,0.68,0.23,0.2,0.04,0.87,0.05,0.02,0.02
51.38948321829898,0.0043823762639658495,93.04208828451026,300.0,8.333333333333333e-05,0.68,0.23,0.2,0.04,0.87,0.05,0.02,0.02
51.90258817033108,0.0044251350099685244,93.0654626158165,300.0,8.333333333333333e-05,0.68,0.23,0.2,0.04,0.87,0.05,0.02,0.02
52.41569312236318,0.0044678937559712,93.0888369471228,300.0,8.333333333333333e-05,0.68,0.23,0.2,0.04,0.87,0.05,0.02,0.02
52.96613514635368,0.004513763924637076,93.1102117311331,300.0,8.333333333333333e-05,0.68,0.23,0.2,0.04,0.87,0.05,0.02,0.02
53.51657717034418,0.00455963409330295,93.1315865151434,300.0,8.333333333333333e-05,0.68,0.23,0.2,0.04,0.87,0.05,0.02,0.02
54.06701919433468,0.004605504261968825,93.1529612991536,300.0,8.333333333333333e-05,0.68,0.23,0.2,0.04,0.87,0.05,0.02,0.02
54.61746121832518,0.0046513744306347,93.17433608316414,300.0,8.333333333333333e-05,0.68,0.23,0.2,0.04,0.87,0.05,0.02,0.02
55.159103738702385,0.0046965113073328,93.19212224379145,300.0,8.333333333333333e-05,0.68,0.23,0.2,0.04,0.87,0.05,0.02,0.02
55.70074625907958,0.0047416481840309,93.20990840441848,300.0,8.333333333333333e-05,0.68,0.23,0.2,0.04,0.87,0.05,0.02,0.02
56.242388779456775,0.004786785060729,93.22769456504578,300.0,8.333333333333333e-05,0.68,0.23,0.2,0.04,0.87,0.05,0.02,0.02
56.78403129983398,0.0048319219374271,93.24548072567265,300.0,8.333333333333333e-05,0.68,0.23,0.2,0.04,0.87,0.05,0.02,0.02
57.35677273990048,0.004879650390765974,93.25937373063641,300.0,8.333333333333333e-05,0.68,0.23,0.2,0.04,0.87,0.05,0.02,0.02
57.92951417996697,0.00492737884410485,93.27326673560054,300.0,8.333333333333333e-05,0.68,0.23,0.2,0.04,0.87,0.05,0.02,0.02
58.50225562003347,0.004975107297443725,93.28715974056438,300.0,8.333333333333333e-05,0.68,0.23,0.2,0.04,0.87,0.05,0.02,0.02
59.074997060099975,0.0050228357507826,93.30105274552848,300.0,8.333333333333333e-05,0.68,0.23,0.2,0.04,0.87,0.05,0.02,0.02
59.627617588282774,0.0050688874614645,93.31093934138684,300.0,8.333333333333333e-05,0.68,0.23,0.2,0.04,0.87,0.05,0.02,0.02
60.180238116465574,0.0051149391721464,93.32082593724505,300.0,8.333333333333333e-05,0.68,0.23,0.2,0.04,0.87,0.05,0.02,0.02
60.732858644648374,0.0051609908828283,93.33071253310331,300.0,8.333333333333333e-05,0.68,0.23,0.2,0.04,0.87,0.05,0.02,0.02
61.28547917283117,0.0052070425935102,93.34059912896112,300.0,8.333333333333333e-05,0.68,0.23,0.2,0.04,0.87,0.05,0.02,0.02
61.759333970061576,0.005246530493279399,93.34959296218966,300.0,8.333333333333333e-05,0.68,0.23,0.2,0.04,0.87,0.05,0.02,0.02
62.23318876729198,0.0052860183930486,93.35858679541893,300.0,8.333333333333333e-05,0.68,0.23,0.2,0.04,0.87,0.05,0.02,0.02
62.70704356452238,0.0053255062928178,93.36758062864747,300.0,8.333333333333333e-05,0.68,0.23,0.2,0.04,0.87,0.05,0.02,0.02
63.18089836175278,0.005364994192587,93.37657446187585,300.0,8.333333333333333e-05,0.68,0.23,0.2,0.04,0.87,0.05,0.02,0.02
63.755968420192175,0.00541291669745695,93.38104309648875,300.0,8.333333333333333e-05,0.68,0.23,0.2,0.04,0.87,0.05,0.02,0.02
64.33103847863157,0.0054608392023269,93.38551173110119,300.0,8.333333333333333e-05,0.68,0.23,0.2,0.04,0.87,0.05,0.02,0.02
64.90610853707096,0.005508761707196851,93.38998036571428,300.0,8.333333333333333e-05,0.68,0.23,0.2,0.04,0.87,0.05,0.02,0.02
65.48117859551037,0.0055566842120668,93.39444900032825,300.0,8.333333333333333e-05,0.68,0.23,0.2,0.04,0.87,0.05,0.02,0.02
66.04614022528946,0.005603764347881725,93.39450611311547,300.0,8.333333333333333e-05,0.68,0.23,0.2,0.04,0.87,0.05,0.02,0.02
66.61110185506857,0.00565084448369665,93.39456322590274,300.0,8.333333333333333e-05,0.68,0.23,0.2,0.04,0.87,0.05,0.02,0.02
67.17606348484767,0.005697924619511575,93.39462033868989,300.0,8.333333333333333e-05,0.68,0.23,0.2,0.04,0.87,0.05,0.02,0.02
67.74102511462678,0.0057450047553265,93.3946774514764,300.0,8.333333333333333e-05,0.68,0.23,0.2,0.04,0.87,0.05,0.02,0.02