File: datasets/al_6061_comp/csv/T_300_A_3.csv
Time,Strain(%),Stress(MPa),Temp(C),SR(%/s),Si(%),Fe(%),Cu(%),Mn(%),Mg(%),Cr(%),Zn(%),Ti(%)
0.0,8.37134481112684e-05,-2.3246870444728627,300.0,8.333333333333333e-05,0.56,0.23,0.18,0.07,0.86,0.06,0.02,0.01
0.024954999403097387,8.579303139485985e-05,-2.2270106092200406,300.0,8.333333333333333e-05,0.56,0.23,0.18,0.07,0.86,0.06,0.02,0.01
0.049909998806194775,8.78726146784513e-05,-2.129334173967214,300.0,8.333333333333333e-05,0.56,0.23,0.18,0.07,0.86,0.06,0.02,0.01
0.07486499820929216,8.995219796204275e-05,-2.03165773871439,300.0,8.333333333333333e-05,0.56,0.23,0.18,0.07,0.86,0.06,0.02,0.01
0.09981999761238955,9.20317812456342e-05,-1.9339813034615663,300.0,8.333333333333333e-05,0.56,0.23,0.18,0.07,0.86,0.06,0.02,0.01
0.12477499701548693,9.411136452922565e-05,-1.8363048682087442,300.0,8.333333333333333e-05,0.56,0.23,0.18,0.07,0.86,0.06,0.02,0.01
0.1497299964185843,9.61909478128171e-05,-1.7386284329559265,300.0,8.333333333333333e-05,0.56,0.23,0.18,0.07,0.86,0.06,0.02,0.01
0.1746849958216817,9.827053109640854e-05,-1.6409519977031044,300.0,8.333333333333333e-05,0.56,0.23,0.18,0.07,0.86,0.06,0.02,0.01
0.1996399952247791,0.00010035011438,-1.5432755624502792,300.0,8.333333333333333e-05,0.56,0.23,0.18,0.07,0.86,0.06,0.02,0.01
0.2727647109530291,0.00010644384069068751,-1.3900014193089278,300.0,8.333333333333333e-05,0.56,0.23,0.18,0.07,0.86,0.06,0.02,0.01
0.3458894266812791,0.000112537567001375,-1.2367272761675774,300.0,8.333333333333333e-05,0.56,0.23,0.18,0.07,0.86,0.06,0.02,0.01
0.41901414240952906,0.0001186312933120625,-1.083453133026227,300.0,8.333333333333333e-05,0.56,0.23,0.18,0.07,0.86,0.06,0.02,0.01
0.4921388581377791,0.00012472501962275,-0.9301789898848765,300.0,8.333333333333333e-05,0.56,0.23,0.18,0.07,0.86,0.06,0.02,0.01
0.5652635738660291,0.0001308187459334375,-0.7769048467435256,300.0,8.333333333333333e-05,0.56,0.23,0.18,0.07,0.86,0.06,0.02,0.01
0.6383882895942791,0.00013691247224412498,-0.6236307036021747,300.0,8.333333333333333e-05,0.56,0.23,0.18,0.07,0.86,0.06,0.02,0.01
0.7115130053225291,0.0001430061985548125,-0.4703565604608224,300.0,8.333333333333333e-05,0.56,0.23,0.18,0.07,0.86,0.06,0.02,0.01
0.7846377210507791,0.0001490999248655,-0.31708241731946885,300.0,8.333333333333333e-05,0.56,0.23,0.18,0.07,0.86,0.06,0.02,0.01
0.8213914699091291,0.0001521627372703625,-0.0893718752835948,300.0,8.333333333333333e-05,0.56,0.23,0.18,0.07,0.86,0.06,0.02,0.01
0.8581452187674792,0.00015522554967522498,0.13833866675227569,300.0,8.333333333333333e-05,0.56,0.23,0.18,0.07,0.86,0.06,0.02,0.01
0.8948989676258292,0.00015828836208008748,0.3660492087881515,300.0,8.333333333333333e-05,0.56,0.23,0.18,0.07,0.86,0.06,0.02,0.01
0.9316527164841791,0.00016135117448495,0.5937597508240273,300.0,8.333333333333333e-05,0.56,0.23,0.18,0.07,0.86,0.06,0.02,0.01
0.968406465342529,0.0001644139868898125,0.8214702928599031,300.0,8.333333333333333e-05,0.56,0.23,0.18,0.07,0.86,0.06,0.02,0.01
1.005160214200879,0.000167476799294675,1.0491808348957825,300.0,8.333333333333333e-05,0.56,0.23,0.18,0.07,0.86,0.06,0.02,0.01
1.0419139630592291,0.0001705396116995375,1.2768913769316566,300.0,8.333333333333333e-05,0.56,0.23,0.18,0.07,0.86,0.06,0.02,0.01
1.0786677119175792,0.0001736024241044,1.5046019189675262,300.0,8.333333333333333e-05,0.56,0.23,0.18,0.07,0.86,0.06,0.02,0.01
1.1433750953898794,0.000178994706060425,1.793530691307054,300.0,8.333333333333333e-05,0.56,0.23,0.18,0.07,0.86,0.06,0.02,0.01
1.2080824788621793,0.00018438698801645,2.0824594636465816,300.0,8.333333333333333e-05,0.56,0.23,0.18,0.07,0.86,0.06,0.02,0.01
1.2727898623344793,0.00018977926997247499,2.3713882359861094,300.0,8.333333333333333e-05,0.56,0.23,0.18,0.07,0.86,0.06,0.02,0.01
1.3374972458067793,0.0001951715519285,2.660317008325645,300.0,8.333333333333333e-05,0.56,0.23,0.18,0.07,0.86,0.06,0.02,0.01
1.4022046292790793,0.00020056383388452503,2.949245780665173,300.0,8.333333333333333e-05,0.56,0.23,0.18,0.07,0.86,0.06,0.02,0.01
1.4669120127513795,0.00020595611584055002,3.2381745530046944,300.0,8.333333333333333e-05,0.56,0.23,0.18,0.07,0.86,0.06,0.02,0.01
1.5316193962236797,0.00021134839779657501,3.527103325344222,300.0,8.333333333333333e-05,0.56,0.23,0.18,0.07,0.86,0.06,0.02,0.01
1.5963267796959797,0.0002167406797526,3.816032097683757,300.0,8.333333333333333e-05,0.56,0.23,0.18,0.07,0.86,0.06,0.02,0.01
1.6882454358225796,0.00022440056776315,4.169096914991182,300.0,8.333333333333333e-05,0.56,0.23,0.18,0.07,0.86,0.06,0.02,0.01
1.7801640919491795,0.0002320604557737,4.5221617322986,300.0,8.333333333333333e-05,0.56,0.23,0.18,0.07,0.86,0.06,0.02,0.01
1.8720827480757793,0.00023972034378425,4.875226549606025,300.0,8.333333333333333e-05,0.56,0.23,0.18,0.07,0.86,0.06,0.02,0.01
1.9640014042023795,0.0002473802317948,5.2282913669134645,300.0,8.333333333333333e-05,0.56,0.23,0.18,0.07,0.86,0.06,0.02,0.01
2.0559200603289796,0.00025504011980535,5.58135618422089,300.0,8.333333333333333e-05,0.56,0.23,0.18,0.07,0.86,0.06,0.02,0.01
2.1478387164555794,0.0002627000078159,5.934421001528313,300.0,8.333333333333333e-05,0.56,0.23,0.18,0.07,0.86,0.06,0.02,0.01
2.2397573725821793,0.00027035989582645,6.287485818835738,300.0,8.333333333333333e-05,0.56,0.23,0.18,0.07,0.86,0.06,0.02,0.01
2.331676028708779,0.000278019783837,6.640550636143145,300.0,8.333333333333333e-05,0.56,0.23,0.18,0.07,0.86,0.06,0.02,0.01
2.425651831876279,0.000285851100767625,7.0733114651998505,300.0,8.333333333333333e-05,0.56,0.23,0.18,0.07,0.86,0.06,0.02,0.01
2.519627635043779,0.00029368241769825,7.506072294256546,300.0,8.333333333333333e-05,0.56,0.23,0.18,0.07,0.86,0.06,0.02,0.01
2.613603438211279,0.000301513734628875,7.93883312331325,300.0,8.333333333333333e-05,0.56,0.23,0.18,0.07,0.86,0.06,0.02,0.01
2.707579241378779,0.0003093450515595,8.371593952369995,300.0,8.333333333333333e-05,0.56,0.23,0.18,0.07,0.86,0.06,0.02,0.01
2.801555044546279,0.000317176368490125,8.8043547814267,300.0,8.333333333333333e-05,0.56,0.23,0.18,0.07,0.86,0.06,0.02,0.01
2.895530847713779,0.00032500768542075,9.23711561048337,300.0,8.333333333333333e-05,0.56,0.23,0.18,0.07,0.86,0.06,0.02,0.01
2.989506650881279,0.000332839002351375,9.669876439540078,300.0,8.333333333333333e-05,0.56,0.23,0.18,0.07,0.86,0.06,0.02,0.01
3.083482454048779,0.000340670319282,10.102637268596807,300.0,8.333333333333333e-05,0.56,0.23,0.18,0.07,0.86,0.06,0.02,0.01
3.179178359484979,0.00034864497806835,10.584753753001921,300.0,8.333333333333333e-05,0.56,0.23,0.18,0.07,0.86,0.06,0.02,0.01
3.2748742649211793,0.0003566196368547,11.066870237407011,300.0,8.333333333333333e-05,0.56,0.23,0.18,0.07,0.86,0.06,0.02,0.01
3.3705701703573796,0.00036459429564105004,11.548986721812115,300.0,8.333333333333333e-05,0.56,0.23,0.18,0.07,0.86,0.06,0.02,0.01
3.4662660757935795,0.0003725689544274,12.031103206217216,300.0,8.333333333333333e-05,0.56,0.23,0.18,0.07,0.86,0.06,0.02,0.01
3.5619619812297794,0.00038054361321374997,12.513219690622327,300.0,8.333333333333333e-05,0.56,0.23,0.18,0.07,0.86,0.06,0.02,0.01
3.6576578866659797,0.0003885182720001,12.995336175027449,300.0,8.333333333333333e-05,0.56,0.23,0.18,0.07,0.86,0.06,0.02,0.01
3.75335379210218,0.00039649293078645,13.477452659432567,300.0,8.333333333333333e-05,0.56,0.23,0.18,0.07,0.86,0.06,0.02,0.01
3.84904969753838,0.0004044675895728,13.959569143837657,300.0,8.333333333333333e-05,0.56,0.23,0.18,0.07,0.86,0.06,0.02,0.01
3.95561639900603,0.0004133481480284375,14.443455555312555,300.0,8.333333333333333e-05,0.56,0.23,0.18,0.07,0.86,0.06,0.02,0.01
4.06218310047368,0.000422228706484075,14.92734196678748,300.0,8.333333333333333e-05,0.56,0.23,0.18,0.07,0.86,0.06,0.02,0.01
4.168749801941329,0.00043110926493971247,15.411228378262383,300.0,8.333333333333333e-05,0.56,0.23,0.18,0.07,0.86,0.06,0.02,0.01
4.2753165034089795,0.00043998982339535,15.895114789737315,300.0,8.333333333333333e-05,0.56,0.23,0.18,0.07,0.86,0.06,0.02,0.01
4.38188320487663,0.00044887038185098755,16.37900120121222,300.0,8.333333333333333e-05,0.56,0.23,0.18,0.07,0.86,0.06,0.02,0.01
4.488449906344279,0.00045775094030662503,16.86288761268709,300.0,8.333333333333333e-05,0.56,0.23,0.18,0.07,0.86,0.06,0.02,0.01
4.595016607811929,0.0004666314987622625,17.34677402416199,300.0,8.333333333333333e-05,0.56,0.23,0.18,0.07,0.86,0.06,0.02,0.01
4.701583309279579,0.0004755120572179,17.830660435637,300.0,8.333333333333333e-05,0.56,0.23,0.18,0.07,0.86,0.06,0.02,0.01
4.76206808137418,0.00048055245489244996,18.30442647246307,300.0,8.333333333333333e-05,0.56,0.23,0.18,0.07,0.86,0.06,0.02,0.01
4.822552853468779,0.000485592852567,18.77819250928915,300.0,8.333333333333333e-05,0.56,0.23,0.18,0.07,0.86,0.06,0.02,0.01
4.883037625563379,0.00049063325024155,19.251958546115226,300.0,8.333333333333333e-05,0.56,0.23,0.18,0.07,0.86,0.06,0.02,0.01
4.943522397657979,0.0004956736479161,19.725724582941226,300.0,8.333333333333333e-05,0.56,0.23,0.18,0.07,0.86,0.06,0.02,0.01
5.00400716975258,0.0005007140455906499,20.199490619767296,300.0,8.333333333333333e-05,0.56,0.23,0.18,0.07,0.86,0.06,0.02,0.01
5.064491941847179,0.0005057544432651999,20.673256656593338,300.0,8.333333333333333e-05,0.56,0.23,0.18,0.07,0.86,0.06,0.02,0.01
5.124976713941779,0.0005107948409397499,21.14702269341941,300.0,8.333333333333333e-05,0.56,0.23,0.18,0.07,0.86,0.06,0.02,0.01
5.185461486036379,0.0005158352386143,21.620788730245522,300.0,8.333333333333333e-05,0.56,0.23,0.18,0.07,0.86,0.06,0.02,0.01
5.3264554774185795,0.00052758473789615,22.105605264726623,300.0,8.333333333333333e-05,0.56,0.23,0.18,0.07,0.86,0.06,0.02,0.01
5.46744946880078,0.0005393342371779999,22.59042179920766,300.0,8.333333333333333e-05,0.56,0.23,0.18,0.07,0.86,0.06,0.02,0.01
5.60844346018298,0.00055108373645985,23.07523833368877,300.0,8.333333333333333e-05,0.56,0.23,0.18,0.07,0.86,0.06,0.02,0.01
5.74943745156518,0.0005628332357417,23.56005486816993,300.0,8.333333333333333e-05,0.56,0.23,0.18,0.07,0.86,0.06,0.02,0.01
5.8904314429473805,0.00057458273502355,24.04487140265103,300.0,8.333333333333333e-05,0.56,0.23,0.18,0.07,0.86,0.06,0.02,0.01
6.031425434329581,0.0005863322343054,24.52968793713215,300.0,8.333333333333333e-05,0.56,0.23,0.18,0.07,0.86,0.06,0.02,0.01
6.17241942571178,0.0005980817335872501,25.0145044716132,300.0,8.333333333333333e-05,0.56,0.23,0.18,0.07,0.86,0.06,0.02,0.01
6.31341341709398,0.0006098312328691,25.499321006094284,300.0,8.333333333333333e-05,0.56,0.23,0.18,0.07,0.86,0.06,0.02,0.01
6.435658004049531,0.0006200182817820625,25.987087327268537,300.0,8.333333333333333e-05,0.56,0.23,0.18,0.07,0.86,0.06,0.02,0.01
6.55790259100508,0.000630205330695025,26.474853648442718,300.0,8.333333333333333e-05,0.56,0.23,0.18,0.07,0.86,0.06,0.02,0.01
6.68014717796063,0.0006403923796079874,26.962619969616977,300.0,8.333333333333333e-05,0.56,0.23,0.18,0.07,0.86,0.06,0.02,0.01
6.80239176491618,0.0006505794285209499,27.450386290791343,300.0,8.333333333333333e-05,0.56,0.23,0.18,0.07,0.86,0.06,0.02,0.01
6.92463635187173,0.0006607664774339124,27.938152611965588,300.0,8.333333333333333e-05,0.56,0.23,0.18,0.07,0.86,0.06,0.02,0.01
7.046880938827281,0.0006709535263468749,28.425918933139783,300.0,8.333333333333333e-05,0.56,0.23,0.18,0.07,0.86,0.06,0.02,0.01
7.16912552578283,0.0006811405752598374,28.913685254314082,300.0,8.333333333333333e-05,0.56,0.23,0.18,0.07,0.86,0.06,0.02,0.01
7.29137011273838,0.0006913276241728,29.40145157548843,300.0,8.333333333333333e-05,0.56,0.23,0.18,0.07,0.86,0.06,0.02,0.01
7.39305400825898,0.00069980128213285,29.89405504849993,300.0,8.333333333333333e-05,0.56,0.23,0.18,0.07,0.86,0.06,0.02,0.01
7.49473790377958,0.0007082749400929001,30.386658521511457,300.0,8.333333333333333e-05,0.56,0.23,0.18,0.07,0.86,0.06,0.02,0.01
7.59642179930018,0.0007167485980529501,30.879261994522913,300.0,8.333333333333333e-05,0.56,0.23,0.18,0.07,0.86,0.06,0.02,0.01
7.69810569482078,0.0007252222560130001,31.37186546753427,300.0,8.333333333333333e-05,0.56,0.23,0.18,0.07,0.86,0.06,0.02,0.01
7.79978959034138,0.00073369591397305,31.86446894054579,300.0,8.333333333333333e-05,0.56,0.23,0.18,0.07,0.86,0.06,0.02,0.01
7.90147348586198,0.0007421695719331,32.35707241355722,300.0,8.333333333333333e-05,0.56,0.23,0.18,0.07,0.86,0.06,0.02,0.01
8.00315738138258,0.00075064322989315,32.8496758865688,300.0,8.333333333333333e-05,0.56,0.23,0.18,0.07,0.86,0.06,0.02,0.01
8.10484127690318,0.0007591168878532,33.34227935958043,300.0,8.333333333333333e-05,0.56,0.23,0.18,0.07,0.86,0.06,0.02,0.01
8.18456160113183,0.0007657602482055875,33.81893469520184,300.0,8.333333333333333e-05,0.56,0.23,0.18,0.07,0.86,0.06,0.02,0.01
8.26428192536048,0.000772403608557975,34.29559003082322,300.0,8.333333333333333e-05,0.56,0.23,0.18,0.07,0.86,0.06,0.02,0.01
8.344002249589131,0.0007790469689103626,34.77224536644458,300.0,8.333333333333333e-05,0.56,0.23,0.18,0.07,0.86,0.06,0.02,0.01
8.42372257381778,0.00078569032926275,35.24890070206581,300.0,8.333333333333333e-05,0.56,0.23,0.18,0.07,0.86,0.06,0.02,0.01
8.50344289804643,0.0007923336896151374,35.7255560376872,300.0,8.333333333333333e-05,0.56,0.23,0.18,0.07,0.86,0.06,0.02,0.01
8.583163222275079,0.000798977049967525,36.2022113733089,300.0,8.333333333333333e-05,0.56,0.23,0.18,0.07,0.86,0.06,0.02,0.01
8.662883546503728,0.0008056204103199125,36.67886670893027,300.0,8.333333333333333e-05,0.56,0.23,0.18,0.07,0.86,0.06,0.02,0.01
8.74260387073238,0.0008122637706723,37.15552204455148,300.0,8.333333333333333e-05,0.56,0.23,0.18,0.07,0.86,0.06,0.02,0.01
8.846560417745028,0.0008209268162566875,37.61139593452176,300.0,8.333333333333333e-05,0.56,0.23,0.18,0.07,0.86,0.06,0.02,0.01
8.950516964757679,0.000829589861841075,38.06726982449228,300.0,8.333333333333333e-05,0.56,0.23,0.18,0.07,0.86,0.06,0.02,0.01
9.054473511770329,0.0008382529074254625,38.52314371446261,300.0,8.333333333333333e-05,0.56,0.23,0.18,0.07,0.86,0.06,0.02,0.01
9.15843005878298,0.00084691595300985,38.979017604433,300.0,8.333333333333333e-05,0.56,0.23,0.18,0.07,0.86,0.06,0.02,0.01
9.26238660579563,0.0008555789985942375,39.434891494403274,300.0,8.333333333333333e-05,0.56,0.23,0.18,0.07,0.86,0.06,0.02,0.01
9.366343152808279,0.000864242044178625,39.89076538437323,300.0,8.333333333333333e-05,0.56,0.23,0.18,0.07,0.86,0.06,0.02,0.01
9.470299699820927,0.0008729050897630126,40.346639274343495,300.0,8.333333333333333e-05,0.56,0.23,0.18,0.07,0.86,0.06,0.02,0.01
9.574256246833578,0.0008815681353474,40.80251316431417,300.0,8.333333333333333e-05,0.56,0.23,0.18,0.07,0.86,0.06,0.02,0.01
9.684366779817978,0.0008907440130960999,41.24100177011661,300.0,8.333333333333333e-05,0.56,0.23,0.18,0.07,0.86,0.06,0.02,0.01
9.794477312802378,0.0008999198908448,41.67949037591882,300.0,8.333333333333333e-05,0.56,0.23,0.18,0.07,0.86,0.06,0.02,0.01
9.904587845786779,0.0009090957685935,42.117978981721265,300.0,8.333333333333333e-05,0.56,0.23,0.18,0.07,0.86,0.06,0.02,0.01
10.014698378771179,0.0009182716463422,42.556467587523606,300.0,8.333333333333333e-05,0.56,0.23,0.18,0.07,0.86,0.06,0.02,0.01
10.12480891175558,0.0009274475240909001,42.994956193326054,300.0,8.333333333333333e-05,0.56,0.23,0.18,0.07,0.86,0.06,0.02,0.01
10.23491944473998,0.0009366234018396,43.4334447991287,300.0,8.333333333333333e-05,0.56,0.23,0.18,0.07,0.86,0.06,0.02,0.01
10.34502997772438,0.0009457992795883,43.87193340493118,300.0,8.333333333333333e-05,0.56,0.23,0.18,0.07,0.86,0.06,0.02,0.01
10.455140510708778,0.000954975157337,44.31042201073346,300.0,8.333333333333333e-05,0.56,0.23,0.18,0.07,0.86,0.06,0.02,0.01
10.582084509631727,0.0009655538239139125,44.731564646952876,300.0,8.333333333333333e-05,0.56,0.23,0.18,0.07,0.86,0.06,0.02,0.01
10.709028508554677,0.000976132490490825,45.15270728317229,300.0,8.333333333333333e-05,0.56,0.23,0.18,0.07,0.86,0.06,0.02,0.01
10.835972507477628,0.0009867111570677376,45.57384991939162,300.0,8.333333333333333e-05,0.56,0.23,0.18,0.07,0.86,0.06,0.02,0.01
10.962916506400578,0.00099728982364465,45.99499255561078,300.0,8.333333333333333e-05,0.56,0.23,0.18,0.07,0.86,0.06,0.02,0.01
11.089860505323529,0.0010078684902215624,46.41613519183018,300.0,8.333333333333333e-05,0.56,0.23,0.18,0.07,0.86,0.06,0.02,0.01
11.216804504246479,0.001018447156798475,46.83727782804982,300.0,8.333333333333333e-05,0.56,0.23,0.18,0.07,0.86,0.06,0.02,0.01
11.34374850316943,0.0010290258233753877,47.2584204642693,300.0,8.333333333333333e-05,0.56,0.23,0.18,0.07,0.86,0.06,0.02,0.01
11.47069250209238,0.0010396044899523,47.6795631004885,300.0,8.333333333333333e-05,0.56,0.23,0.18,0.07,0.86,0.06,0.02,0.01
11.57657176517213,0.0010484277618756125,48.08164488985335,300.0,8.333333333333333e-05,0.56,0.23,0.18,0.07,0.86,0.06,0.02,0.01
11.68245102825188,0.001057251033798925,48.48372667921847,300.0,8.333333333333333e-05,0.56,0.23,0.18,0.07,0.86,0.06,0.02,0.01
11.78833029133163,0.0010660743057222374,48.885808468583264,300.0,8.333333333333333e-05,0.56,0.23,0.18,0.07,0.86,0.06,0.02,0.01
11.894209554411379,0.0010748975776455499,49.28789025794786,300.0,8.333333333333333e-05,0.56,0.23,0.18,0.07,0.86,0.06,0.02,0.01
12.000088817491129,0.0010837208495688623,49.68997204731271,300.0,8.333333333333333e-05,0.56,0.23,0.18,0.07,0.86,0.06,0.02,0.01
12.105968080570879,0.0010925441214921748,50.092053836677714,300.0,8.333333333333333e-05,0.56,0.23,0.18,0.07,0.86,0.06,0.02,0.01
12.211847343650629,0.0011013673934154875,50.49413562604265,300.0,8.333333333333333e-05,0.56,0.23,0.18,0.07,0.86,0.06,0.02,0.01
12.317726606730378,0.0011101906653388,50.89621741540735,300.0,8.333333333333333e-05,0.56,0.23,0.18,0.07,0.86,0.06,0.02,0.01
12.433076960258779,0.0011198031947994998,51.2804764461909,300.0,8.333333333333333e-05,0.56,0.23,0.18,0.07,0.86,0.06,0.02,0.01
12.54842731378718,0.0011294157242602,51.66473547697468,300.0,8.333333333333333e-05,0.56,0.23,0.18,0.07,0.86,0.06,0.02,0.01
12.663777667315578,0.0011390282537209,52.04899450775814,300.0,8.333333333333333e-05,0.56,0.23,0.18,0.07,0.86,0.06,0.02,0.01
12.779128020843979,0.0011486407831816001,52.43325353854155,300.0,8.333333333333333e-05,0.56,0.23,0.18,0.07,0.86,0.06,0.02,0.01
12.89447837437238,0.0011582533126423002,52.8175125693251,300.0,8.333333333333333e-05,0.56,0.23,0.18,0.07,0.86,0.06,0.02,0.01
13.009828727900778,0.001167865842103,53.2017716001082,300.0,8.333333333333333e-05,0.56,0.23,0.18,0.07,0.86,0.06,0.02,0.01
13.125179081429179,0.0011774783715637,53.58603063089176,300.0,8.333333333333333e-05,0.56,0.23,0.18,0.07,0.86,0.06,0.02,0.01
13.24052943495758,0.0011870909010244,53.97028966167545,300.0,8.333333333333333e-05,0.56,0.23,0.18,0.07,0.86,0.06,0.02,0.01
13.37591324498123,0.0011983728851930374,54.34036079469547,300.0,8.333333333333333e-05,0.56,0.23,0.18,0.07,0.86,0.06,0.02,0.01
13.51129705500488,0.001209654869361675,54.71043192771561,300.0,8.333333333333333e-05,0.56,0.23,0.18,0.07,0.86,0.06,0.02,0.01
13.646680865028529,0.0012209368535303126,55.08050306073553,300.0,8.333333333333333e-05,0.56,0.23,0.18,0.07,0.86,0.06,0.02,0.01
13.78206467505218,0.00123221883769895,55.45057419375518,300.0,8.333333333333333e-05,0.56,0.23,0.18,0.07,0.86,0.06,0.02,0.01
13.917448485075829,0.0012435008218675875,55.820645326775214,300.0,8.333333333333333e-05,0.56,0.23,0.18,0.07,0.86,0.06,0.02,0.01
14.052832295099478,0.001254782806036225,56.19071645979596,300.0,8.333333333333333e-05,0.56,0.23,0.18,0.07,0.86,0.06,0.02,0.01
14.188216105123129,0.0012660647902048624,56.5607875928161,300.0,8.333333333333333e-05,0.56,0.23,0.18,0.07,0.86,0.06,0.02,0.01
14.323599915146778,0.0012773467743735,56.930858725835904,300.0,8.333333333333333e-05,0.56,0.23,0.18,0.07,0.86,0.06,0.02,0.01
14.483546018075028,0.0012906756162841876,57.286275927990374,300.0,8.333333333333333e-05,0.56,0.23,0.18,0.07,0.86,0.06,0.02,0.01
14.643492121003277,0.001304004458194875,57.64169313014448,300.0,8.333333333333333e-05,0.56,0.23,0.18,0.07,0.86,0.06,0.02,0.01
14.803438223931527,0.0013173333001055623,57.99711033229893,300.0,8.333333333333333e-05,0.56,0.23,0.18,0.07,0.86,0.06,0.02,0.01
14.963384326859778,0.00133066214201625,58.352527534454154,300.0,8.333333333333333e-05,0.56,0.23,0.18,0.07,0.86,0.06,0.02,0.01
15.123330429788027,0.0013439909839269375,58.707944736608646,300.0,8.333333333333333e-05,0.56,0.23,0.18,0.07,0.86,0.06,0.02,0.01
15.283276532716277,0.001357319825837625,59.0633619387625,300.0,8.333333333333333e-05,0.56,0.23,0.18,0.07,0.86,0.06,0.02,0.01
15.443222635644528,0.0013706486677483123,59.418779140916996,300.0,8.333333333333333e-05,0.56,0.23,0.18,0.07,0.86,0.06,0.02,0.01
15.603168738572776,0.001383977509659,59.77419634307188,300.0,8.333333333333333e-05,0.56,0.23,0.18,0.07,0.86,0.06,0.02,0.01
15.768636456245776,0.0013977664861317498,60.115365016832726,300.0,8.333333333333333e-05,0.56,0.23,0.18,0.07,0.86,0.06,0.02,0.01
15.934104173918776,0.0014115554626045,60.45653369059333,300.0,8.333333333333333e-05,0.56,0.23,0.18,0.07,0.86,0.06,0.02,0.01
16.099571891591776,0.0014253444390772499,60.79770236435424,300.0,8.333333333333333e-05,0.56,0.23,0.18,0.07,0.86,0.06,0.02,0.01
16.265039609264775,0.0014391334155499998,61.1388710381153,300.0,8.333333333333333e-05,0.56,0.23,0.18,0.07,0.86,0.06,0.02,0.01
16.430507326937775,0.00145292239202275,61.48003971187613,300.0,8.333333333333333e-05,0.56,0.23,0.18,0.07,0.86,0.06,0.02,0.01
16.595975044610775,0.0014667113684954998,61.82120838563695,300.0,8.333333333333333e-05,0.56,0.23,0.18,0.07,0.86,0.06,0.02,0.01
16.761442762283778,0.0014805003449682498,62.162377059397755,300.0,8.333333333333333e-05,0.56,0.23,0.18,0.07,0.86,0.06,0.02,0.01
16.926910479956778,0.001494289321441,62.503545733158475,300.0,8.333333333333333e-05,0.56,0.23,0.18,0.07,0.86,0.06,0.02,0.01
17.109281978380128,0.0015094869463096125,62.83515871376282,300.0,8.333333333333333e-05,0.56,0.23,0.18,0.07,0.86,0.06,0.02,0.01
17.29165347680348,0.001524684571178225,63.16677169436734,300.0,8.333333333333333e-05,0.56,0.23,0.18,0.07,0.86,0.06,0.02,0.01
17.47402497522683,0.0015398821960468374,63.49838467497173,300.0,8.333333333333333e-05,0.56,0.23,0.18,0.07,0.86,0.06,0.02,0.01
17.65639647365018,0.00155507982091545,63.82999765557617,300.0,8.333333333333333e-05,0.56,0.23,0.18,0.07,0.86,0.06,0.02,0.01
17.83876797207353,0.0015702774457840626,64.1616106361805,300.0,8.333333333333333e-05,0.56,0.23,0.18,0.07,0.86,0.06,0.02,0.01
18.02113947049688,0.001585475070652675,64.49322361678504,300.0,8.333333333333333e-05,0.56,0.23,0.18,0.07,0.86,0.06,0.02,0.01
18.20351096892023,0.0016006726955212875,64.82483659738939,300.0,8.333333333333333e-05,0.56,0.23,0.18,0.07,0.86,0.06,0.02,0.01
18.38588246734358,0.0016158703203899,65.15644957799344,300.0,8.333333333333333e-05,0.56,0.23,0.18,0.07,0.86,0.06,0.02,0.01
18.58812196504013,0.0016327236118646126,65.46814957153332,300.0,8.333333333333333e-05,0.56,0.23,0.18,0.07,0.86,0.06,0.02,0.01
18.790361462736684,0.001649576903339325,65.77984956507302,300.0,8.333333333333333e-05,0.56,0.23,0.18,0.07,0.86,0.06,0.02,0.01
18.992600960433233,0.0016664301948140375,66.09154955861277,300.0,8.333333333333333e-05,0.56,0.23,0.18,0.07,0.86,0.06,0.02,0.01
19.194840458129782,0.00168328348628875,66.40324955215294,300.0,8.333333333333333e-05,0.56,0.23,0.18,0.07,0.86,0.06,0.02,0.01
19.39707995582633,0.0017001367777634625,66.71494954569282,300.0,8.333333333333333e-05,0.56,0.23,0.18,0.07,0.86,0.06,0.02,0.01
19.59931945352288,0.001716990069238175,67.02664953923262,300.0,8.333333333333333e-05,0.56,0.23,0.18,0.07,0.86,0.06,0.02,0.01
19.80155895121943,0.0017338433607128876,67.33834953277258,300.0,8.333333333333333e-05,0.56,0.23,0.18,0.07,0.86,0.06,0.02,0.01
20.00379844891598,0.0017506966521876,67.65004952631253,300.0,8.333333333333333e-05,0.56,0.23,0.18,0.07,0.86,0.06,0.02,0.01
20.25504630498248,0.001771633973526475,67.94170045183986,300.0,8.333333333333333e-05,0.56,0.23,0.18,0.07,0.86,0.06,0.02,0.01
20.506294161048977,0.0017925712948653502,68.23335137736734,300.0,8.333333333333333e-05,0.56,0.23,0.18,0.07,0.86,0.06,0.02,0.01
20.757542017115476,0.0018135086162042251,68.52500230289473,300.0,8.333333333333333e-05,0.56,0.23,0.18,0.07,0.86,0.06,0.02,0.01
21.00878987318198,0.0018344459375431,68.81665322842186,300.0,8.333333333333333e-05,0.56,0.23,0.18,0.07,0.86,0.06,0.02,0.01
21.26003772924848,0.001855383258881975,69.10830415394919,300.0,8.333333333333333e-05,0.56,0.23,0.18,0.07,0.86,0.06,0.02,0.01
21.51128558531498,0.00187632058022085,69.39995507947617,300.0,8.333333333333333e-05,0.56,0.23,0.18,0.07,0.86,0.06,0.02,0.01
21.76253344138148,0.001897257901559725,69.69160600500342,300.0,8.333333333333333e-05,0.56,0.23,0.18,0.07,0.86,0.06,0.02,0.01
22.013781297447977,0.0019181952228986,69.98325693053107,300.0,8.333333333333333e-05,0.56,0.23,0.18,0.07,0.86,0.06,0.02,0.01
22.307889502765576,0.0019427042400083998,70.2530681301331,300.0,8.333333333333333e-05,0.56,0.23,0.18,0.07,0.86,0.06,0.02,0.01
22.601997708083175,0.0019672132571181998,70.52287932973513,300.0,8.333333333333333e-05,0.56,0.23,0.18,0.07,0.86,0.06,0.02,0.01
22.896105913400774,0.0019917222742279997,70.79269052933714,300.0,8.333333333333333e-05,0.56,0.23,0.18,0.07,0.86,0.06,0.02,0.01
23.190214118718377,0.0020162312913377996,71.06250172893918,300.0,8.333333333333333e-05,0.56,0.23,0.18,0.07,0.86,0.06,0.02,0.01
23.48432232403598,0.0020407403084475996,71.3323129285412,300.0,8.333333333333333e-05,0.56,0.23,0.18,0.07,0.86,0.06,0.02,0.01
23.778430529353578,0.0020652493255573995,71.60212412814334,300.0,8.333333333333333e-05,0.56,0.23,0.18,0.07,0.86,0.06,0.02,0.01
24.072538734671177,0.0020897583426672,71.8719353277454,300.0,8.333333333333333e-05,0.56,0.23,0.18,0.07,0.86,0.06,0.02,0.01
24.366646939988776,0.002114267359777,72.14174652734727,300.0,8.333333333333333e-05,0.56,0.23,0.18,0.07,0.86,0.06,0.02,0.01
24.726181802660925,0.0021442285983330122,72.37369991054746,300.0,8.333333333333333e-05,0.56,0.23,0.18,0.07,0.86,0.06,0.02,0.01
25.085716665333077,0.002174189836889025,72.60565329374786,300.0,8.333333333333333e-05,0.56,0.23,0.18,0.07,0.86,0.06,0.02,0.01
25.44525152800523,0.0022041510754450375,72.83760667694803,300.0,8.333333333333333e-05,0.56,0.23,0.18,0.07,0.86,0.06,0.02,0.01
25.80478639067738,0.00223411231400105,73.06956006014805,300.0,8.333333333333333e-05,0.56,0.23,0.18,0.07,0.86,0.06,0.02,0.01
26.164321253349527,0.0022640735525570623,73.3015134433483,300.0,8.333333333333333e-05,0.56,0.23,0.18,0.07,0.86,0.06,0.02,0.01
26.523856116021676,0.0022940347911130747,73.53346682654848,300.0,8.333333333333333e-05,0.56,0.23,0.18,0.07,0.86,0.06,0.02,0.01
26.883390978693825,0.0023239960296690875,73.76542020974871,300.0,8.333333333333333e-05,0.56,0.23,0.18,0.07,0.86,0.06,0.02,0.01
27.242925841365977,0.0023539572682251,73.99737359294899,300.0,8.333333333333333e-05,0.56,0.23,0.18,0.07,0.86,0.06,0.02,0.01
27.606319666715926,0.0023842400870042624,74.19209481850524,300.0,8.333333333333333e-05,0.56,0.23,0.18,0.07,0.86,0.06,0.02,0.01
27.96971349206588,0.002414522905783425,74.38681604406135,300.0,8.333333333333333e-05,0.56,0.23,0.18,0.07,0.86,0.06,0.02,0.01
28.333107317415827,0.0024448057245625874,74.58153726961763,300.0,8.333333333333333e-05,0.56,0.23,0.18,0.07,0.86,0.06,0.02,0.01
28.696501142765776,0.00247508854334175,74.7762584951742,300.0,8.333333333333333e-05,0.56,0.23,0.18,0.07,0.86,0.06,0.02,0.01
29.059894968115728,0.0025053713621209124,74.97097972073044,300.0,8.333333333333333e-05,0.56,0.23,0.18,0.07,0.86,0.06,0.02,0.01
29.423288793465677,0.002535654180900075,75.1657009462868,300.0,8.333333333333333e-05,0.56,0.23,0.18,0.07,0.86,0.06,0.02,0.01
29.786682618815625,0.0025659369996792374,75.36042217184306,300.0,8.333333333333333e-05,0.56,0.23,0.18,0.07,0.86,0.06,0.02,0.01
30.150076444165578,0.0025962198184584,75.55514339739887,300.0,8.333333333333333e-05,0.56,0.23,0.18,0.07,0.86,0.06,0.02,0.01
30.563932728483078,0.002630707842151525,75.7207200877237,300.0,8.333333333333333e-05,0.56,0.23,0.18,0.07,0.86,0.06,0.02,0.01
30.977789012800578,0.00266519586584465,75.8862967780488,300.0,8.333333333333333e-05,0.56,0.23,0.18,0.07,0.86,0.06,0.02,0.01
31.391645297118078,0.0026996838895377746,76.05187346837371,300.0,8.333333333333333e-05,0.56,0.23,0.18,0.07,0.86,0.06,0.02,0.01
31.80550158143558,0.0027341719132309,76.2174501586983,300.0,8.333333333333333e-05,0.56,0.23,0.18,0.07,0.86,0.06,0.02,0.01
32.21935786575308,0.002768659936924025,76.38302684902312,300.0,8.333333333333333e-05,0.56,0.23,0.18,0.07,0.86,0.06,0.02,0.01
32.63321415007058,0.00280314796061715,76.54860353934836,300.0,8.333333333333333e-05,0.56,0.23,0.18,0.07,0.86,0.06,0.02,0.01
33.047070434388075,0.0028376359843102746,76.71418022967319,300.0,8.333333333333333e-05,0.56,0.23,0.18,0.07,0.86,0.06,0.02,0.01
33.46092671870558,0.0028721240080034,76.87975691999802,300.0,8.333333333333333e-05,0.56,0.23,0.18,0.07,0.86,0.06,0.02,0.01
33.907662316639275,0.002909351974497875,77.00788558439083,300.0,8.333333333333333e-05,0.56,0.23,0.18,0.07,0.86,0.06,0.02,0.01
34.35439791457298,0.0029465799409923495,77.13601424878358,300.0,8.333333333333333e-05,0.56,0.23,0.18,0.07,0.86,0.06,0.02,0.01
34.80113351250668,0.0029838079074868246,77.2641429131764,300.0,8.333333333333333e-05,0.56,0.23,0.18,0.07,0.86,0.06,0.02,0.01
35.24786911044038,0.0030210358739812997,77.39227157756908,300.0,8.333333333333333e-05,0.56,0.23,0.18,0.07,0.86,0.06,0.02,0.01
35.69460470837408,0.0030582638404757748,77.52040024196191,300.0,8.333333333333333e-05,0.56,0.23,0.18,0.07,0.86,0.06,0.02,0.01
36.14134030630778,0.00309549180697025,77.6485289063549,300.0,8.333333333333333e-05,0.56,0.23,0.18,0.07,0.86,0.06,0.02,0.01
36.58807590424148,0.003132719773464725,77.77665757074763,300.0,8.333333333333333e-05,0.56,0.23,0.18,0.07,0.86,0.06,0.02,0.01
37.03481150217518,0.0031699477399592,77.90478623514038,300.0,8.333333333333333e-05,0.56,0.23,0.18,0.07,0.86,0.06,0.02,0.01
37.52622711716033,0.0032108990412079625,77.9992239479073,300.0,8.333333333333333e-05,0.56,0.23,0.18,0.07,0.86,0.06,0.02,0.01
38.017642732145475,0.003251850342456725,78.09366166067412,300.0,8.333333333333333e-05,0.56,0.23,0.18,0.07,0.86,0.06,0.02,0.01
38.509058347130626,0.0032928016437054875,78.18809937344122,300.0,8.333333333333333e-05,0.56,0.23,0.18,0.07,0.86,0.06,0.02,0.01
39.00047396211578,0.00333375294495425,78.28253708620866,300.0,8.333333333333333e-05,0.56,0.23,0.18,0.07,0.86,0.06,0.02,0.01
39.49188957710093,0.0033747042462030125,78.3769747989756,300.0,8.333333333333333e-05,0.56,0.23,0.18,0.07,0.86,0.06,0.02,0.01
39.98330519208608,0.003415655547451775,78.47141251174236,300.0,8.333333333333333e-05,0.56,0.23,0.18,0.07,0.86,0.06,0.02,0.01
40.47472080707123,0.0034566068487005375,78.56585022450925,300.0,8.333333333333333e-05,0.56,0.23,0.18,0.07,0.86,0.06,0.02,0.01
40.96613642205638,0.0034975581499493,78.66028793727592,300.0,8.333333333333333e-05,0.56,0.23,0.18,0.07,0.86,0.06,0.02,0.01
41.484670798975884,0.003540769348025925,78.72445781590937,300.0,8.333333333333333e-05,0.56,0.23,0.18,0.07,0.86,0.06,0.02,0.01
42.00320517589538,0.00358398054610255,78.78862769454254,300.0,8.333333333333333e-05,0.56,0.23,0.18,0.07,0.86,0.06,0.02,0.01
42.52173955281488,0.003627191744179175,78.85279757317585,300.0,8.333333333333333e-05,0.56,0.23,0.18,0.07,0.86,0.06,0.02,0.01
43.04027392973438,0.0036704029422558,78.91696745180911,300.0,8.333333333333333e-05,0.56,0.23,0.18,0.07,0.86,0.06,0.02,0.01
43.55880830665388,0.003713614140332425,78.98113733044256,300.0,8.333333333333333e-05,0.56,0.23,0.18,0.07,0.86,0.06,0.02,0.01
44.07734268357338,0.00375682533840905,79.0453072090764,300.0,8.333333333333333e-05,0.56,0.23,0.18,0.07,0.86,0.06,0.02,0.01
44.59587706049288,0.003800036536485675,79.10947708770992,300.0,8.333333333333333e-05,0.56,0.23,0.18,0.07,0.86,0.06,0.02,0.01
45.11441143741238,0.0038432477345623,79.17364696634361,300.0,8.333333333333333e-05,0.56,0.23,0.18,0.07,0.86,0.06,0.02,0.01
45.63747935579153,0.0038868367277605626,79.21934887331658,300.0,8.333333333333333e-05,0.56,0.23,0.18,0.07,0.86,0.06,0.02,0.01
46.16054727417068,0.003930425720958825,79.2650507802891,300.0,8.333333333333333e-05,0.56,0.23,0.18,0.07,0.86,0.06,0.02,0.01
46.68361519254983,0.003974014714157087,79.31075268726217,300.0,8.333333333333333e-05,0.56,0.23,0.18,0.07,0.86,0.06,0.02,0.01
47.20668311092898,0.0040176037073553494,79.35645459423543,300.0,8.333333333333333e-05,0.56,0.23,0.18,0.07,0.86,0.06,0.02,0.01
47.729751029308126,0.004061192700553612,79.40215650120838,300.0,8.333333333333333e-05,0.56,0.23,0.18,0.07,0.86,0.06,0.02,0.01
48.252818947687274,0.004104781693751875,79.44785840818143,300.0,8.333333333333333e-05,0.56,0.23,0.18,0.07,0.86,0.06,0.02,0.01
48.77588686606643,0.004148370686950138,79.49356031515426,300.0,8.333333333333333e-05,0.56,0.23,0.18,0.07,0.86,0.06,0.02,0.01
49.29895478444558,0.0041919596801484,79.53926222212695,300.0,8.333333333333333e-05,0.56,0.23,0.18,0.07,0.86,0.06,0.02,0.01
49.818214660863376,0.00423523133651655,79.5677700184981,300.0,8.333333333333333e-05,0.56,0.23,0.18,0.07,0.86,0.06,0.02,0.01
50.33747453728118,0.0042785029928847,79.5962778148691,300.0,8.333333333333333e-05,0.56,0.23,0.18,0.07,0.86,0.06,0.02,0.01
50.85673441369898,0.00432177464925285,79.62478561124023,300.0,8.333333333333333e-05,0.56,0.23,0.18,0.07,0.86,0.06,0.02,0.01
51.37599429011678,0.004365046305621,79.6532934076115,300.0,8.333333333333333e-05,0.56,0.23,0.18,0.07,0.86,0.06,0.02,0.01
51.89525416653458,0.00440831796198915,79.68180120398264,300.0,8.333333333333333e-05,0.56,0.23,0.18,0.07,0.86,0.06,0.02,0.01
52.414514042952376,0.0044515896183573,79.7103090003537,300.0,8.333333333333333e-05,0.56,0.23,0.18,0.07,0.86,0.06,0.02,0.01
52.93377391937018,0.00449486127472545,79.73881679672478,300.0,8.333333333333333e-05,0.56,0.23,0.18,0.07,0.86,0.06,0.02,0.01
53.45303379578798,0.0045381329310936,79.76732459309622,300.0,8.333333333333333e-05,0.56,0.23,0.18,0.07,0.86,0.06,0.02,0.01
54.01724235702699,0.00458515031119685,79.78664070030688,300.0,8.333333333333333e-05,0.56,0.23,0.18,0.07,0.86,0.06,0.02,0.01
54.581450918265986,0.0046321676913001,79.80595680751753,300.0,8.333333333333333e-05,0.56,0.23,0.18,0.07,0.86,0.06,0.02,0.01
55.145659479504985,0.00467918507140335,79.82527291472837,300.0,8.333333333333333e-05,0.56,0.23,0.18,0.07,0.86,0.06,0.02,0.01
55.709868040743984,0.0047262024515066,79.84458902193886,300.0,8.333333333333333e-05,0.56,0.23,0.18,0.07,0.86,0.06,0.02,0.01
56.27407660198298,0.00477321983160985,79.86390512914954,300.0,8.333333333333333e-05,0.56,0.23,0.18,0.07,0.86,0.06,0.02,0.01
56.83828516322198,0.0048202372117131,79.88322123636011,300.0,8.333333333333333e-05,0.56,0.23,0.18,0.07,0.86,0.06,0.02,0.01
57.40249372446098,0.00486725459181635,79.90253734357077,300.0,8.333333333333333e-05,0.56,0.23,0.18,0.07,0.86,0.06,0.02,0.01
57.96670228569998,0.0049142719719196,79.92185345078158,300.0,8.333333333333333e-05,0.56,0.23,0.18,0.07,0.86,0.06,0.02,0.01
58.51439679804143,0.004959913181281387,79.933124422899,300.0,8.333333333333333e-05,0.56,0.23,0.18,0.07,0.86,0.06,0.02,0.01
59.062091310382876,0.005005554390643175,79.94439539501607,300.0,8.333333333333333e-05,0.56,0.23,0.18,0.07,0.86,0.06,0.02,0.01
59.60978582272432,0.005051195600004962,79.95566636713349,300.0,8.333333333333333e-05,0.56,0.23,0.18,0.07,0.86,0.06,0.02,0.01
60.15748033506577,0.005096836809366749,79.96693733925132,300.0,8.333333333333333e-05,0.56,0.23,0.18,0.07,0.86,0.06,0.02,0.01
60.70517484740722,0.005142478018728537,79.97820831136872,300.0,8.333333333333333e-05,0.56,0.23,0.18,0.07,0.86,0.06,0.02,0.01
61.25286935974867,0.005188119228090324,79.98947928348602,300.0,8.333333333333333e-05,0.56,0.23,0.18,0.07,0.86,0.06,0.02,0.01
61.80056387209012,0.0052337604374521115,80.00075025560331,300.0,8.333333333333333e-05,0.56,0.23,0.18,0.07,0.86,0.06,0.02,0.01
62.34825838443157,0.0052794016468139,80.01202122772092,300.0,8.333333333333333e-05,0.56,0.23,0.18,0.07,0.86,0.06,0.02,0.01
62.922118151330466,0.005327223294055475,80.01823987094502,300.0,8.333333333333333e-05,0.56,0.23,0.18,0.07,0.86,0.06,0.02,0.01
63.49597791822937,0.00537504494129705,80.02445851416914,300.0,8.333333333333333e-05,0.56,0.23,0.18,0.07,0.86,0.06,0.02,0.01
64.06983768512828,0.005422866588538624,80.0306771573933,300.0,8.333333333333333e-05,0.56,0.23,0.18,0.07,0.86,0.06,0.02,0.01
64.64369745202717,0.0054706882357802,80.03689580061688,300.0,8.333333333333333e-05,0.56,0.23,0.18,0.07,0.86,0.06,0.02,0.01
65.21755721892607,0.005518509883021775,80.04311444384096,300.0,8.333333333333333e-05,0.56,0.23,0.18,0.07,0.86,0.06,0.02,0.01
65.79141698582498,0.00556633153026335,80.04933308706529,300.0,8.333333333333333e-05,0.56,0.23,0.18,0.07,0.86,0.06,0.02,0.01
66.36527675272387,0.005614153177504924,80.05555173028938,300.0,8.333333333333333e-05,0.56,0.23,0.18,0.07,0.86,0.06,0.02,0.01
66.93913651962278,0.0056619748247465,80.06177037351362,300.0,8.333333333333333e-05,0.56,0.23,0.18,0.07,0.86,0.06,0.02,0.01
67.50540344699812,0.005709163735361112,80.0661471159003,300.0,8.333333333333333e-05,0.56,0.23,0.18,0.07,0.86,0.06,0.02,0.01
68.07167037437347,0.005756352645975725,80.07052385828703,300.0,8.333333333333333e-05,0.56,0.23,0.18,0.07,0.86,0.06,0.02,0.01
68.63793730174882,0.005803541556590338,80.07490060067376,300.0,8.333333333333333e-05,0.56,0.23,0.18,0.07,0.86,0.06,0.02,0.01
69.20420422912417,0.00585073046720495,80.0792773430602,300.0,8.333333333333333e-05,0.56,0.23,0.18,0.07,0.86,0.06,0.02,0.01
69.77047115649953,0.005897919377819563,80.08365408544687,300.0,8.333333333333333e-05,0.56,0.23,0.18,0.07,0.86,0.06,0.02,0.01
70.33673808387488,0.005945108288434175,80.08803082783389,300.0,8.333333333333333e-05,0.56,0.23,0.18,0.07,0.86,0.06,0.02,0.01
70.90300501125023,0.005992297199048788,80.09240757022059,300.0,8.333333333333333e-05,0.56,0.23,0.18,0.07,0.86,0.06,0.02,0.01
71.46927193862558,0.0060394861096634,80.09678431260696,300.0,8.333333333333333e-05,0.56,0.23,0.18,0.07,0.86,0.06,0.02,0.01
72.04258272358044,0.006087262008409637,80.09927320455984,300.0,8.333333333333333e-05,0.56,0.23,0.18,0.07,0.86,0.06,0.02,0.01
72.61589350853528,0.006135037907155875,80.1017620965129,300.0,8.333333333333333e-05,0.56,0.23,0.18,0.07,0.86,0.06,0.02,0.01
73.18920429349012,0.006182813805902113,80.10425098846551,300.0,8.333333333333333e-05,0.56,0.23,0.18,0.07,0.86,0.06,0.02,0.01
73.76251507844498,0.00623058970464835,80.10673988041766,300.0,8.333333333333333e-05,0.56,0.23,0.18,0.07,0.86,0.06,0.02,0.01
74.33582586339983,0.006278365603394587,80.10922877237056,300.0,8.333333333333333e-05,0.56,0.23,0.18,0.07,0.86,0.06,0.02,0.01
74.90913664835469,0.006326141502140825,80.1117176643241,300.0,8.333333333333333e-05,0.56,0.23,0.18,0.07,0.86,0.06,0.02,0.01
75.48244743330955,0.006373917400887063,80.11420655627727,300.0,8.333333333333333e-05,0.56,0.23,0.18,0.07,0.86,0.06,0.02,0.01
76.05575821826439,0.0064216932996333,80.11669544823016,300.0,8.333333333333333e-05,0.56,0.23,0.18,0.07,0.86,0.06,0.02,0.01
76.6415013125623,0.006470505224158125,80.11634005914625,300.0,8.333333333333333e-05,0.56,0.23,0.18,0.07,0.86,0.06,0.02,0.01
77.2272444068602,0.00651931714868295,80.11598467006328,300.0,8.333333333333333e-05,0.56,0.23,0.18,0.07,0.86,0.06,0.02,0.01
77.81298750115809,0.006568129073207775,80.1156292809793,300.0,8.333333333333333e-05,0.56,0.23,0.18,0.07,0.86,0.06,0.02,0.01
78.39873059545599,0.0066169409977326,80.1152738918942,300.0,8.333333333333333e-05,0.56,0.23,0.18,0.07,0.86,0.06,0.02,0.01
78.98447368975388,0.0066657529222574246,80.11491850281033,300.0,8.333333333333333e-05,0.56,0.23,0.18,0.07,0.86,0.06,0.02,0.01
79.57021678405178,0.0067145648467822495,80.11456311372605,300.0,8.333333333333333e-05,0.56,0.23,0.18,0.07,0.86,0.06,0.02,0.01
80.15595987834968,0.006763376771307075,80.1142077246422,300.0,8.333333333333333e-05,0.56,0.23,0.18,0.07,0.86,0.06,0.02,0.01
80.74170297264759,0.0068121886958319,80.11385233555923,300.0,8.333333333333333e-05,0.56,0.23,0.18,0.07,0.86,0.06,0.02,0.01
81.30875069512135,0.006859442672704713,80.11685262296922,300.0,8.333333333333333e-05,0.56,0.23,0.18,0.07,0.86,0.06,0.02,0.01
81.87579841759509,0.006906696649577526,80.11985291037837,300.0,8.333333333333333e-05,0.56,0.23,0.18,0.07,0.86,0.06,0.02,0.01
82.44284614006884,0.006953950626450338,80.12285319778839,300.0,8.333333333333333e-05,0.56,0.23,0.18,0.07,0.86,0.06,0.02,0.01
83.00989386254258,0.007001204603323151,80.12585348519902,300.0,8.333333333333333e-05,0.56,0.23,0.18,0.07,0.86,0.06,0.02,0.01
83.57694158501633,0.007048458580195963,80.12885377260899,300.0,8.333333333333333e-05,0.56,0.23,0.18,0.07,0.86,0.06,0.02,0.01
84.14398930749007,0.007095712557068775,80.1318540600178,300.0,8.333333333333333e-05,0.56,0.23,0.18,0.07,0.86,0.06,0.02,0.01
84.71103702996382,0.007142966533941588,80.13485434742786,300.0,8.333333333333333e-05,0.56,0.23,0.18,0.07,0.86,0.06,0.02,0.01
85.27808475243758,0.0071902205108144,80.13785463483966,300.0,8.333333333333333e-05,0.56,0.23,0.18,0.07,0.86,0.06,0.02,0.01
85.86949888721213,0.007239505022045612,80.13883958335056,300.0,8.333333333333333e-05,0.56,0.23,0.18,0.07,0.86,0.06,0.02,0.01
86.46091302198667,0.007288789533276825,80.13982453186152,300.0,8.333333333333333e-05,0.56,0.23,0.18,0.07,0.86,0.06,0.02,0.01
87.05232715676122,0.007338074044508038,80.14080948037241,300.0,8.333333333333333e-05,0.56,0.23,0.18,0.07,0.86,0.06,0.02,0.01
87.64374129153578,0.00738735855573925,80.14179442888317,300.0,8.333333333333333e-05,0.56,0.23,0.18,0.07,0.86,0.06,0.02,0.01
88.23515542631033,0.007436643066970462,80.14277937739408,300.0,8.333333333333333e-05,0.56,0.23,0.18,0.07,0.86,0.06,0.02,0.01
88.82656956108488,0.007485927578201675,80.14376432590466,300.0,8.333333333333333e-05,0.56,0.23,0.18,0.07,0.86,0.06,0.02,0.01
89.41798369585942,0.007535212089432888,80.14474927441543,300.0,8.333333333333333e-05,0.56,0.23,0.18,0.07,0.86,0.06,0.02,0.01
90.00939783063397,0.0075844966006641,80.145734222926,300.0,8.333333333333333e-05,0.56,0.23,0.18,0.07,0.86,0.06,0.02,0.01