File: datasets/al_6061_comp/csv/T_300_D_3.csv
Time,Strain(%),Stress(MPa),Temp(C),SR(%/s),Si(%),Fe(%),Cu(%),Mn(%),Mg(%),Cr(%),Zn(%),Ti(%)
0.0,0.0001064762291361,0.5078022737020067,300.0,8.333333333333333e-05,0.67,0.28,0.23,0.05,0.9,0.05,0.03,0.02
0.06015696297030002,0.000111489309383625,0.48591415102310365,300.0,8.333333333333333e-05,0.67,0.28,0.23,0.05,0.9,0.05,0.03,0.02
0.12031392594060004,0.00011650238963115,0.46402602834420037,300.0,8.333333333333333e-05,0.67,0.28,0.23,0.05,0.9,0.05,0.03,0.02
0.18047088891090007,0.00012151546987867501,0.442137905665297,300.0,8.333333333333333e-05,0.67,0.28,0.23,0.05,0.9,0.05,0.03,0.02
0.2406278518812001,0.0001265285501262,0.4202497829863935,300.0,8.333333333333333e-05,0.67,0.28,0.23,0.05,0.9,0.05,0.03,0.02
0.30412344875760006,0.00013181984986590002,0.3970390557671477,300.0,8.333333333333333e-05,0.67,0.28,0.23,0.05,0.9,0.05,0.03,0.02
0.36761904563400005,0.00013711114960560003,0.37382832854790193,300.0,8.333333333333333e-05,0.67,0.28,0.23,0.05,0.9,0.05,0.03,0.02
0.4311146425104001,0.00014240244934530003,0.35061760132865627,300.0,8.333333333333333e-05,0.67,0.28,0.23,0.05,0.9,0.05,0.03,0.02
0.4946102393868001,0.000147693749085,0.32740687410941116,300.0,8.333333333333333e-05,0.67,0.28,0.23,0.05,0.9,0.05,0.03,0.02
0.5481103018104001,0.00015215208762030003,0.3038254669281224,300.0,8.333333333333333e-05,0.67,0.28,0.23,0.05,0.9,0.05,0.03,0.02
0.6016103642340002,0.00015661042615560002,0.28024405974683275,300.0,8.333333333333333e-05,0.67,0.28,0.23,0.05,0.9,0.05,0.03,0.02
0.6551104266576002,0.0001610687646909,0.2566626525655441,300.0,8.333333333333333e-05,0.67,0.28,0.23,0.05,0.9,0.05,0.03,0.02
0.7086104890812002,0.0001655271032262,0.2330812453842559,300.0,8.333333333333333e-05,0.67,0.28,0.23,0.05,0.9,0.05,0.03,0.02
0.7859065568880002,0.0001719684422101,0.20472316301339988,300.0,8.333333333333333e-05,0.67,0.28,0.23,0.05,0.9,0.05,0.03,0.02
0.8632026246948001,0.00017840978119399998,0.17636508064254397,300.0,8.333333333333333e-05,0.67,0.28,0.23,0.05,0.9,0.05,0.03,0.02
0.9404986925016001,0.0001848511201779,0.14800699827168784,300.0,8.333333333333333e-05,0.67,0.28,0.23,0.05,0.9,0.05,0.03,0.02
1.0177947603084,0.0001912924591618,0.11964891590083215,300.0,8.333333333333333e-05,0.67,0.28,0.23,0.05,0.9,0.05,0.03,0.02
1.0959593123439002,0.00019780617183142498,0.09106058402541728,300.0,8.333333333333333e-05,0.67,0.28,0.23,0.05,0.9,0.05,0.03,0.02
1.1741238643794,0.00020431988450105,0.06247225215000196,300.0,8.333333333333333e-05,0.67,0.28,0.23,0.05,0.9,0.05,0.03,0.02
1.2522884164149,0.000210833597170675,0.033883920274586865,300.0,8.333333333333333e-05,0.67,0.28,0.23,0.05,0.9,0.05,0.03,0.02
1.3304529684504,0.0002173473098403,0.005295588399172019,300.0,8.333333333333333e-05,0.67,0.28,0.23,0.05,0.9,0.05,0.03,0.02
1.4291656506045,0.00022557336668647498,-0.0033469700427690152,300.0,8.333333333333333e-05,0.67,0.28,0.23,0.05,0.9,0.05,0.03,0.02
1.5278783327586,0.00023379942353265,-0.011989528484710105,300.0,8.333333333333333e-05,0.67,0.28,0.23,0.05,0.9,0.05,0.03,0.02
1.6265910149127,0.000242025480378825,-0.020632086926651222,300.0,8.333333333333333e-05,0.67,0.28,0.23,0.05,0.9,0.05,0.03,0.02
1.7253036970668,0.000250251537225,-0.029274645368591923,300.0,8.333333333333333e-05,0.67,0.28,0.23,0.05,0.9,0.05,0.03,0.02
1.7817772263816,0.00025495766466790003,0.015534524959743834,300.0,8.333333333333333e-05,0.67,0.28,0.23,0.05,0.9,0.05,0.03,0.02
1.8382507556964,0.0002596637921108,0.06034369528807826,300.0,8.333333333333333e-05,0.67,0.28,0.23,0.05,0.9,0.05,0.03,0.02
1.8947242850112,0.0002643699195537,0.10515286561641402,300.0,8.333333333333333e-05,0.67,0.28,0.23,0.05,0.9,0.05,0.03,0.02
1.951197814326,0.0002690760469966,0.14996203594474977,300.0,8.333333333333333e-05,0.67,0.28,0.23,0.05,0.9,0.05,0.03,0.02
2.0279434317144,0.0002754715151123,0.23781468110033943,300.0,8.333333333333333e-05,0.67,0.28,0.23,0.05,0.9,0.05,0.03,0.02
2.1046890491028,0.00028186698322799997,0.32566732625592776,300.0,8.333333333333333e-05,0.67,0.28,0.23,0.05,0.9,0.05,0.03,0.02
2.1814346664912003,0.0002882624513437,0.4135199714115174,300.0,8.333333333333333e-05,0.67,0.28,0.23,0.05,0.9,0.05,0.03,0.02
2.2581802838796,0.0002946579194594,0.5013726165671071,300.0,8.333333333333333e-05,0.67,0.28,0.23,0.05,0.9,0.05,0.03,0.02
2.3595224457279,0.000303103099613425,0.6297862634710287,300.0,8.333333333333333e-05,0.67,0.28,0.23,0.05,0.9,0.05,0.03,0.02
2.4608646075762,0.00031154827976745,0.7581999103749477,300.0,8.333333333333333e-05,0.67,0.28,0.23,0.05,0.9,0.05,0.03,0.02
2.5622067694245,0.000319993459921475,0.8866135572788676,300.0,8.333333333333333e-05,0.67,0.28,0.23,0.05,0.9,0.05,0.03,0.02
2.6635489312728,0.0003284386400755,1.0150272041827888,300.0,8.333333333333333e-05,0.67,0.28,0.23,0.05,0.9,0.05,0.03,0.02
2.7696569993718,0.00033728097908374997,1.1961411087186056,300.0,8.333333333333333e-05,0.67,0.28,0.23,0.05,0.9,0.05,0.03,0.02
2.8757650674708,0.000346123318092,1.3772550132544241,300.0,8.333333333333333e-05,0.67,0.28,0.23,0.05,0.9,0.05,0.03,0.02
2.9818731355698,0.00035496565710025,1.5583689177902418,300.0,8.333333333333333e-05,0.67,0.28,0.23,0.05,0.9,0.05,0.03,0.02
3.0879812036688006,0.0003638079961085,1.7394828223260532,300.0,8.333333333333333e-05,0.67,0.28,0.23,0.05,0.9,0.05,0.03,0.02
3.1786882072353,0.000371366913072375,2.017098393256653,300.0,8.333333333333333e-05,0.67,0.28,0.23,0.05,0.9,0.05,0.03,0.02
3.2693952108018003,0.00037892583003625003,2.294713964187263,300.0,8.333333333333333e-05,0.67,0.28,0.23,0.05,0.9,0.05,0.03,0.02
3.3601022143683004,0.00038648474700012504,2.5723295351178646,300.0,8.333333333333333e-05,0.67,0.28,0.23,0.05,0.9,0.05,0.03,0.02
3.4508092179348,0.000394043663964,2.8499451060484517,300.0,8.333333333333333e-05,0.67,0.28,0.23,0.05,0.9,0.05,0.03,0.02
3.534830521035,0.00040104543922235,3.210100989754334,300.0,8.333333333333333e-05,0.67,0.28,0.23,0.05,0.9,0.05,0.03,0.02
3.6188518241352,0.0004080472144807,3.5702568734602202,300.0,8.333333333333333e-05,0.67,0.28,0.23,0.05,0.9,0.05,0.03,0.02
3.7028731272354,0.00041504898973905,3.930412757166099,300.0,8.333333333333333e-05,0.67,0.28,0.23,0.05,0.9,0.05,0.03,0.02
3.7868944303356,0.0004220507649974,4.290568640871978,300.0,8.333333333333333e-05,0.67,0.28,0.23,0.05,0.9,0.05,0.03,0.02
3.8585666384883,0.000428023449010125,4.685852132116242,300.0,8.333333333333333e-05,0.67,0.28,0.23,0.05,0.9,0.05,0.03,0.02
3.930238846641,0.00043399613302285,5.0811356233605345,300.0,8.333333333333333e-05,0.67,0.28,0.23,0.05,0.9,0.05,0.03,0.02
4.0019110547937,0.000439968817035575,5.4764191146047985,300.0,8.333333333333333e-05,0.67,0.28,0.23,0.05,0.9,0.05,0.03,0.02
4.0735832629464,0.0004459415010483,5.871702605849034,300.0,8.333333333333333e-05,0.67,0.28,0.23,0.05,0.9,0.05,0.03,0.02
4.1677776180564,0.0004537910306408,6.265017090291501,300.0,8.333333333333333e-05,0.67,0.28,0.23,0.05,0.9,0.05,0.03,0.02
4.2619719731664,0.0004616405602333,6.658331574733971,300.0,8.333333333333333e-05,0.67,0.28,0.23,0.05,0.9,0.05,0.03,0.02
4.3561663282764,0.0004694900898258,7.051646059176434,300.0,8.333333333333333e-05,0.67,0.28,0.23,0.05,0.9,0.05,0.03,0.02
4.4503606833864,0.0004773396194183,7.44496054361888,300.0,8.333333333333333e-05,0.67,0.28,0.23,0.05,0.9,0.05,0.03,0.02
4.5759113457117,0.000487802174612075,7.846031210895529,300.0,8.333333333333333e-05,0.67,0.28,0.23,0.05,0.9,0.05,0.03,0.02
4.701462008037,0.00049826472980585,8.247101878172222,300.0,8.333333333333333e-05,0.67,0.28,0.23,0.05,0.9,0.05,0.03,0.02
4.8270126703623,0.000508727284999625,8.648172545448874,300.0,8.333333333333333e-05,0.67,0.28,0.23,0.05,0.9,0.05,0.03,0.02
4.9525633326876,0.0005191898401934,9.0492432127255,300.0,8.333333333333333e-05,0.67,0.28,0.23,0.05,0.9,0.05,0.03,0.02
5.0728067743416,0.0005292101269979,9.466898101583027,300.0,8.333333333333333e-05,0.67,0.28,0.23,0.05,0.9,0.05,0.03,0.02
5.1930502159956,0.0005392304138024,9.884552990440529,300.0,8.333333333333333e-05,0.67,0.28,0.23,0.05,0.9,0.05,0.03,0.02
5.3132936576495995,0.0005492507006069,10.302207879298049,300.0,8.333333333333333e-05,0.67,0.28,0.23,0.05,0.9,0.05,0.03,0.02
5.433537099303599,0.0005592709874114,10.71986276815558,300.0,8.333333333333333e-05,0.67,0.28,0.23,0.05,0.9,0.05,0.03,0.02
5.5198911313188,0.000566467156746,11.142507019500407,300.0,8.333333333333333e-05,0.67,0.28,0.23,0.05,0.9,0.05,0.03,0.02
5.606245163334,0.0005736633260806,11.565151270845185,300.0,8.333333333333333e-05,0.67,0.28,0.23,0.05,0.9,0.05,0.03,0.02
5.6925991953492,0.0005808594954151999,11.98779552219002,300.0,8.333333333333333e-05,0.67,0.28,0.23,0.05,0.9,0.05,0.03,0.02
5.778953227364401,0.0005880556647498,12.410439773534925,300.0,8.333333333333333e-05,0.67,0.28,0.23,0.05,0.9,0.05,0.03,0.02
5.907269673831,0.00059874870195535,12.803755669120275,300.0,8.333333333333333e-05,0.67,0.28,0.23,0.05,0.9,0.05,0.03,0.02
6.0355861202976,0.0006094417391609,13.197071564705562,300.0,8.333333333333333e-05,0.67,0.28,0.23,0.05,0.9,0.05,0.03,0.02
6.163902566764199,0.0006201347763664499,13.590387460290918,300.0,8.333333333333333e-05,0.67,0.28,0.23,0.05,0.9,0.05,0.03,0.02
6.292219013230799,0.000630827813572,13.983703355876337,300.0,8.333333333333333e-05,0.67,0.28,0.23,0.05,0.9,0.05,0.03,0.02
6.418099656011099,0.0006413178671370249,14.350693606172435,300.0,8.333333333333333e-05,0.67,0.28,0.23,0.05,0.9,0.05,0.03,0.02
6.5439802987914,0.00065180792070205,14.71768385646851,300.0,8.333333333333333e-05,0.67,0.28,0.23,0.05,0.9,0.05,0.03,0.02
6.6698609415717005,0.0006622979742670751,15.08467410676459,300.0,8.333333333333333e-05,0.67,0.28,0.23,0.05,0.9,0.05,0.03,0.02
6.795741584352001,0.0006727880278321,15.451664357060642,300.0,8.333333333333333e-05,0.67,0.28,0.23,0.05,0.9,0.05,0.03,0.02
6.910622220474301,0.000682361414175625,15.835563913568619,300.0,8.333333333333333e-05,0.67,0.28,0.23,0.05,0.9,0.05,0.03,0.02
7.025502856596601,0.00069193480051915,16.219463470076672,300.0,8.333333333333333e-05,0.67,0.28,0.23,0.05,0.9,0.05,0.03,0.02
7.140383492718901,0.0007015081868626751,16.603363026584663,300.0,8.333333333333333e-05,0.67,0.28,0.23,0.05,0.9,0.05,0.03,0.02
7.255264128841201,0.0007110815732062,16.98726258309254,300.0,8.333333333333333e-05,0.67,0.28,0.23,0.05,0.9,0.05,0.03,0.02
7.404840672543301,0.000723546285181375,17.385695334169817,300.0,8.333333333333333e-05,0.67,0.28,0.23,0.05,0.9,0.05,0.03,0.02
7.554417216245401,0.00073601099715655,17.784128085247126,300.0,8.333333333333333e-05,0.67,0.28,0.23,0.05,0.9,0.05,0.03,0.02
7.703993759947501,0.000748475709131725,18.18256083632439,300.0,8.333333333333333e-05,0.67,0.28,0.23,0.05,0.9,0.05,0.03,0.02
7.853570303649601,0.0007609404211069,18.580993587401625,300.0,8.333333333333333e-05,0.67,0.28,0.23,0.05,0.9,0.05,0.03,0.02
7.9529678142903,0.000769223546993625,19.00885055313508,300.0,8.333333333333333e-05,0.67,0.28,0.23,0.05,0.9,0.05,0.03,0.02
8.052365324931,0.00077750667288035,19.436707518868456,300.0,8.333333333333333e-05,0.67,0.28,0.23,0.05,0.9,0.05,0.03,0.02
8.151762835571699,0.000785789798767075,19.864564484601903,300.0,8.333333333333333e-05,0.67,0.28,0.23,0.05,0.9,0.05,0.03,0.02
8.2511603462124,0.0007940729246538,20.292421450335446,300.0,8.333333333333333e-05,0.67,0.28,0.23,0.05,0.9,0.05,0.03,0.02
8.337242465586002,0.0008012464346016,20.737785513239096,300.0,8.333333333333333e-05,0.67,0.28,0.23,0.05,0.9,0.05,0.03,0.02
8.423324584959602,0.0008084199445494,21.183149576142768,300.0,8.333333333333333e-05,0.67,0.28,0.23,0.05,0.9,0.05,0.03,0.02
8.509406704333202,0.0008155934544972,21.628513639046396,300.0,8.333333333333333e-05,0.67,0.28,0.23,0.05,0.9,0.05,0.03,0.02
8.595488823706802,0.000822766964445,22.07387770195014,300.0,8.333333333333333e-05,0.67,0.28,0.23,0.05,0.9,0.05,0.03,0.02
8.721704556966001,0.0008332849422166,22.525987375695117,300.0,8.333333333333333e-05,0.67,0.28,0.23,0.05,0.9,0.05,0.03,0.02
8.8479202902252,0.0008438029199882,22.978097049440006,300.0,8.333333333333333e-05,0.67,0.28,0.23,0.05,0.9,0.05,0.03,0.02
8.9741360234844,0.0008543208977598001,23.43020672318499,300.0,8.333333333333333e-05,0.67,0.28,0.23,0.05,0.9,0.05,0.03,0.02
9.1003517567436,0.0008648388755314,23.88231639693007,300.0,8.333333333333333e-05,0.67,0.28,0.23,0.05,0.9,0.05,0.03,0.02
9.2074258300242,0.00087376171497145,24.350629378543342,300.0,8.333333333333333e-05,0.67,0.28,0.23,0.05,0.9,0.05,0.03,0.02
9.3144999033048,0.0008826845544115,24.81894236015645,300.0,8.333333333333333e-05,0.67,0.28,0.23,0.05,0.9,0.05,0.03,0.02
9.4215739765854,0.00089160739385155,25.287255341769736,300.0,8.333333333333333e-05,0.67,0.28,0.23,0.05,0.9,0.05,0.03,0.02
9.528648049866,0.0009005302332916,25.755568323383084,300.0,8.333333333333333e-05,0.67,0.28,0.23,0.05,0.9,0.05,0.03,0.02
9.642155950486199,0.0009099892250099501,26.24546281043804,300.0,8.333333333333333e-05,0.67,0.28,0.23,0.05,0.9,0.05,0.03,0.02
9.7556638511064,0.0009194482167283,26.735357297492882,300.0,8.333333333333333e-05,0.67,0.28,0.23,0.05,0.9,0.05,0.03,0.02
9.8691717517266,0.00092890720844665,27.22525178454785,300.0,8.333333333333333e-05,0.67,0.28,0.23,0.05,0.9,0.05,0.03,0.02
9.9826796523468,0.000938366200165,27.71514627160293,300.0,8.333333333333333e-05,0.67,0.28,0.23,0.05,0.9,0.05,0.03,0.02
10.103083548589499,0.000948399858185225,28.211604379500226,300.0,8.333333333333333e-05,0.67,0.28,0.23,0.05,0.9,0.05,0.03,0.02
10.2234874448322,0.00095843351620545,28.708062487397537,300.0,8.333333333333333e-05,0.67,0.28,0.23,0.05,0.9,0.05,0.03,0.02
10.343891341074901,0.000968467174225675,29.204520595294834,300.0,8.333333333333333e-05,0.67,0.28,0.23,0.05,0.9,0.05,0.03,0.02
10.4642952373176,0.0009785008322459,29.70097870319222,300.0,8.333333333333333e-05,0.67,0.28,0.23,0.05,0.9,0.05,0.03,0.02
10.5888849481827,0.000988883308151325,30.20030454594032,300.0,8.333333333333333e-05,0.67,0.28,0.23,0.05,0.9,0.05,0.03,0.02
10.713474659047801,0.0009992657840567501,30.699630388688472,300.0,8.333333333333333e-05,0.67,0.28,0.23,0.05,0.9,0.05,0.03,0.02
10.838064369912901,0.0010096482599621752,31.198956231436537,300.0,8.333333333333333e-05,0.67,0.28,0.23,0.05,0.9,0.05,0.03,0.02
10.962654080778002,0.0010200307358676,31.69828207418436,300.0,8.333333333333333e-05,0.67,0.28,0.23,0.05,0.9,0.05,0.03,0.02
11.095751403265501,0.001031122179408225,32.18116106635641,300.0,8.333333333333333e-05,0.67,0.28,0.23,0.05,0.9,0.05,0.03,0.02
11.228848725753,0.00104221362294885,32.664040058528556,300.0,8.333333333333333e-05,0.67,0.28,0.23,0.05,0.9,0.05,0.03,0.02
11.361946048240501,0.001053305066489475,33.1469190507006,300.0,8.333333333333333e-05,0.67,0.28,0.23,0.05,0.9,0.05,0.03,0.02
11.495043370728,0.0010643965100301,33.62979804287262,300.0,8.333333333333333e-05,0.67,0.28,0.23,0.05,0.9,0.05,0.03,0.02
11.664740088189301,0.001078537903151875,34.114993040696376,300.0,8.333333333333333e-05,0.67,0.28,0.23,0.05,0.9,0.05,0.03,0.02
11.8344368056506,0.00109267929627365,34.60018803852018,300.0,8.333333333333333e-05,0.67,0.28,0.23,0.05,0.9,0.05,0.03,0.02
12.0041335231119,0.001106820689395425,35.08538303634394,300.0,8.333333333333333e-05,0.67,0.28,0.23,0.05,0.9,0.05,0.03,0.02
12.1738302405732,0.0011209620825172,35.570578034167916,300.0,8.333333333333333e-05,0.67,0.28,0.23,0.05,0.9,0.05,0.03,0.02
12.3086940305925,0.001132200731685475,36.05235639813317,300.0,8.333333333333333e-05,0.67,0.28,0.23,0.05,0.9,0.05,0.03,0.02
12.443557820611801,0.00114343938085375,36.53413476209815,300.0,8.333333333333333e-05,0.67,0.28,0.23,0.05,0.9,0.05,0.03,0.02
12.5784216106311,0.001154678030022025,37.01591312606338,300.0,8.333333333333333e-05,0.67,0.28,0.23,0.05,0.9,0.05,0.03,0.02
12.7132854006504,0.0011659166791903,37.49769149002856,300.0,8.333333333333333e-05,0.67,0.28,0.23,0.05,0.9,0.05,0.03,0.02
12.8209574732352,0.0011748893519057,37.96873212783265,300.0,8.333333333333333e-05,0.67,0.28,0.23,0.05,0.9,0.05,0.03,0.02
12.928629545820002,0.0011838620246211,38.439772765636825,300.0,8.333333333333333e-05,0.67,0.28,0.23,0.05,0.9,0.05,0.03,0.02
13.036301618404801,0.0011928346973365,38.910813403440976,300.0,8.333333333333333e-05,0.67,0.28,0.23,0.05,0.9,0.05,0.03,0.02
13.1439736909896,0.0012018073700519,39.381854041245134,300.0,8.333333333333333e-05,0.67,0.28,0.23,0.05,0.9,0.05,0.03,0.02
13.252967755451401,0.00121089020875705,39.85613246141708,300.0,8.333333333333333e-05,0.67,0.28,0.23,0.05,0.9,0.05,0.03,0.02
13.361961819913201,0.0012199730474622,40.33041088158885,300.0,8.333333333333333e-05,0.67,0.28,0.23,0.05,0.9,0.05,0.03,0.02
13.470955884375002,0.0012290558861673502,40.80468930176079,300.0,8.333333333333333e-05,0.67,0.28,0.23,0.05,0.9,0.05,0.03,0.02
13.579949948836802,0.0012381387248725,41.27896772193286,300.0,8.333333333333333e-05,0.67,0.28,0.23,0.05,0.9,0.05,0.03,0.02
13.692196329528002,0.0012474925899301002,41.7309435505538,300.0,8.333333333333333e-05,0.67,0.28,0.23,0.05,0.9,0.05,0.03,0.02
13.8044427102192,0.0012568464549877001,42.18291937917472,300.0,8.333333333333333e-05,0.67,0.28,0.23,0.05,0.9,0.05,0.03,0.02
13.916689090910399,0.0012662003200453,42.63489520779573,300.0,8.333333333333333e-05,0.67,0.28,0.23,0.05,0.9,0.05,0.03,0.02
14.0289354716016,0.0012755541851029,43.08687103641685,300.0,8.333333333333333e-05,0.67,0.28,0.23,0.05,0.9,0.05,0.03,0.02
14.1457363690332,0.0012852875932222,43.5367254271348,300.0,8.333333333333333e-05,0.67,0.28,0.23,0.05,0.9,0.05,0.03,0.02
14.2625372664648,0.0012950210013415,43.98657981785259,300.0,8.333333333333333e-05,0.67,0.28,0.23,0.05,0.9,0.05,0.03,0.02
14.379338163896401,0.0013047544094607999,44.436434208570574,300.0,8.333333333333333e-05,0.67,0.28,0.23,0.05,0.9,0.05,0.03,0.02
14.496139061328002,0.0013144878175801,44.88628859928852,300.0,8.333333333333333e-05,0.67,0.28,0.23,0.05,0.9,0.05,0.03,0.02
14.619604344344102,0.001324776591164775,45.327162488536324,300.0,8.333333333333333e-05,0.67,0.28,0.23,0.05,0.9,0.05,0.03,0.02
14.743069627360203,0.0013350653647494501,45.76803637778426,300.0,8.333333333333333e-05,0.67,0.28,0.23,0.05,0.9,0.05,0.03,0.02
14.866534910376304,0.001345354138334125,46.20891026703213,300.0,8.333333333333333e-05,0.67,0.28,0.23,0.05,0.9,0.05,0.03,0.02
14.990000193392405,0.0013556429119188,46.64978415628004,300.0,8.333333333333333e-05,0.67,0.28,0.23,0.05,0.9,0.05,0.03,0.02
15.086775820052104,0.0013637075474737751,47.07617911078602,300.0,8.333333333333333e-05,0.67,0.28,0.23,0.05,0.9,0.05,0.03,0.02
15.183551446711803,0.00137177218302875,47.50257406529121,300.0,8.333333333333333e-05,0.67,0.28,0.23,0.05,0.9,0.05,0.03,0.02
15.280327073371502,0.0013798368185837248,47.92896901979685,300.0,8.333333333333333e-05,0.67,0.28,0.23,0.05,0.9,0.05,0.03,0.02
15.3771027000312,0.0013879014541387,48.355363974303266,300.0,8.333333333333333e-05,0.67,0.28,0.23,0.05,0.9,0.05,0.03,0.02
15.4955992227333,0.0013977761643638748,48.78993942294071,300.0,8.333333333333333e-05,0.67,0.28,0.23,0.05,0.9,0.05,0.03,0.02
15.6140957454354,0.00140765087458905,49.224514871578,300.0,8.333333333333333e-05,0.67,0.28,0.23,0.05,0.9,0.05,0.03,0.02
15.7325922681375,0.001417525584814225,49.65909032021563,300.0,8.333333333333333e-05,0.67,0.28,0.23,0.05,0.9,0.05,0.03,0.02
15.8510887908396,0.0014274002950394,50.09366576885322,300.0,8.333333333333333e-05,0.67,0.28,0.23,0.05,0.9,0.05,0.03,0.02
15.9976492824201,0.001439613669337775,50.5244149292475,300.0,8.333333333333333e-05,0.67,0.28,0.23,0.05,0.9,0.05,0.03,0.02
16.1442097740006,0.00145182704363615,50.95516408964227,300.0,8.333333333333333e-05,0.67,0.28,0.23,0.05,0.9,0.05,0.03,0.02
16.290770265581102,0.0014640404179345249,51.38591325003661,300.0,8.333333333333333e-05,0.67,0.28,0.23,0.05,0.9,0.05,0.03,0.02
16.4373307571616,0.0014762537922329,51.816662410431135,300.0,8.333333333333333e-05,0.67,0.28,0.23,0.05,0.9,0.05,0.03,0.02
16.5929802532224,0.0014892245835713002,52.22385412145096,300.0,8.333333333333333e-05,0.67,0.28,0.23,0.05,0.9,0.05,0.03,0.02
16.7486297492832,0.0015021953749097,52.63104583247028,300.0,8.333333333333333e-05,0.67,0.28,0.23,0.05,0.9,0.05,0.03,0.02
16.904279245344,0.0015151661662481,53.03823754348996,300.0,8.333333333333333e-05,0.67,0.28,0.23,0.05,0.9,0.05,0.03,0.02
17.0599287414048,0.0015281369575865,53.44542925450993,300.0,8.333333333333333e-05,0.67,0.28,0.23,0.05,0.9,0.05,0.03,0.02
17.207326586908202,0.00154042011137845,53.86786149052983,300.0,8.333333333333333e-05,0.67,0.28,0.23,0.05,0.9,0.05,0.03,0.02
17.3547244324116,0.0015527032651703999,54.29029372654934,300.0,8.333333333333333e-05,0.67,0.28,0.23,0.05,0.9,0.05,0.03,0.02
17.502122277915,0.00156498641896235,54.712725962569415,300.0,8.333333333333333e-05,0.67,0.28,0.23,0.05,0.9,0.05,0.03,0.02
17.649520123418398,0.0015772695727543,55.13515819858937,300.0,8.333333333333333e-05,0.67,0.28,0.23,0.05,0.9,0.05,0.03,0.02
17.773747420827,0.0015876218475383498,55.53670218374454,300.0,8.333333333333333e-05,0.67,0.28,0.23,0.05,0.9,0.05,0.03,0.02
17.8979747182356,0.0015979741223223999,55.93824616889998,300.0,8.333333333333333e-05,0.67,0.28,0.23,0.05,0.9,0.05,0.03,0.02
18.022202015644197,0.00160832639710645,56.33979015405514,300.0,8.333333333333333e-05,0.67,0.28,0.23,0.05,0.9,0.05,0.03,0.02
18.1464293130528,0.0016186786718905,56.741334139210004,300.0,8.333333333333333e-05,0.67,0.28,0.23,0.05,0.9,0.05,0.03,0.02
18.2759240165241,0.001629469897179775,57.153769261917226,300.0,8.333333333333333e-05,0.67,0.28,0.23,0.05,0.9,0.05,0.03,0.02
18.4054187199954,0.00164026112246905,57.56620438462471,300.0,8.333333333333333e-05,0.67,0.28,0.23,0.05,0.9,0.05,0.03,0.02
18.534913423466698,0.0016510523477583248,57.978639507331785,300.0,8.333333333333333e-05,0.67,0.28,0.23,0.05,0.9,0.05,0.03,0.02
18.664408126938,0.0016618435730476,58.39107463003861,300.0,8.333333333333333e-05,0.67,0.28,0.23,0.05,0.9,0.05,0.03,0.02
18.8305722180147,0.001675690580637325,58.786112701004086,300.0,8.333333333333333e-05,0.67,0.28,0.23,0.05,0.9,0.05,0.03,0.02
18.9967363090914,0.00168953758822705,59.18115077196961,300.0,8.333333333333333e-05,0.67,0.28,0.23,0.05,0.9,0.05,0.03,0.02
19.1629004001681,0.0017033845958167749,59.57618884293516,300.0,8.333333333333333e-05,0.67,0.28,0.23,0.05,0.9,0.05,0.03,0.02
19.3290644912448,0.0017172316034065,59.97122691390095,300.0,8.333333333333333e-05,0.67,0.28,0.23,0.05,0.9,0.05,0.03,0.02
19.4793691913499,0.001729756995081925,60.34797850201708,300.0,8.333333333333333e-05,0.67,0.28,0.23,0.05,0.9,0.05,0.03,0.02
19.629673891455,0.00174228238675735,60.724730090132894,300.0,8.333333333333333e-05,0.67,0.28,0.23,0.05,0.9,0.05,0.03,0.02
19.779978591560102,0.001754807778432775,61.10148167824893,300.0,8.333333333333333e-05,0.67,0.28,0.23,0.05,0.9,0.05,0.03,0.02
19.9302832916652,0.0017673331701082,61.47823326636494,300.0,8.333333333333333e-05,0.67,0.28,0.23,0.05,0.9,0.05,0.03,0.02
20.076150484179003,0.00177948876948435,61.846904923055966,300.0,8.333333333333333e-05,0.67,0.28,0.23,0.05,0.9,0.05,0.03,0.02
20.2220176766928,0.0017916443688605,62.21557657974732,300.0,8.333333333333333e-05,0.67,0.28,0.23,0.05,0.9,0.05,0.03,0.02
20.3678848692066,0.0018037999682366502,62.584248236438455,300.0,8.333333333333333e-05,0.67,0.28,0.23,0.05,0.9,0.05,0.03,0.02
20.5137520617204,0.0018159555676128,62.95291989312957,300.0,8.333333333333333e-05,0.67,0.28,0.23,0.05,0.9,0.05,0.03,0.02
20.6492500448073,0.001827247066203375,63.337249326450745,300.0,8.333333333333333e-05,0.67,0.28,0.23,0.05,0.9,0.05,0.03,0.02
20.7847480278942,0.0018385385647939501,63.72157875977174,300.0,8.333333333333333e-05,0.67,0.28,0.23,0.05,0.9,0.05,0.03,0.02
20.9202460109811,0.001849830063384525,64.10590819309287,300.0,8.333333333333333e-05,0.67,0.28,0.23,0.05,0.9,0.05,0.03,0.02
21.055743994068,0.0018611215619751,64.49023762641399,300.0,8.333333333333333e-05,0.67,0.28,0.23,0.05,0.9,0.05,0.03,0.02
21.2293005611496,0.0018755846092319,64.85510111045807,300.0,8.333333333333333e-05,0.67,0.28,0.23,0.05,0.9,0.05,0.03,0.02
21.402857128231197,0.0018900476564887,65.21996459450247,300.0,8.333333333333333e-05,0.67,0.28,0.23,0.05,0.9,0.05,0.03,0.02
21.576413695312798,0.0019045107037455001,65.58482807854647,300.0,8.333333333333333e-05,0.67,0.28,0.23,0.05,0.9,0.05,0.03,0.02
21.7499702623944,0.0019189737510023,65.94969156259012,300.0,8.333333333333333e-05,0.67,0.28,0.23,0.05,0.9,0.05,0.03,0.02
21.9361858871574,0.00193449171973255,66.3064794237406,300.0,8.333333333333333e-05,0.67,0.28,0.23,0.05,0.9,0.05,0.03,0.02
22.1224015119204,0.0019500096884628002,66.66326728489155,300.0,8.333333333333333e-05,0.67,0.28,0.23,0.05,0.9,0.05,0.03,0.02
22.308617136683402,0.00196552765719305,67.02005514604201,300.0,8.333333333333333e-05,0.67,0.28,0.23,0.05,0.9,0.05,0.03,0.02
22.4948327614464,0.0019810456259233,67.37684300719269,300.0,8.333333333333333e-05,0.67,0.28,0.23,0.05,0.9,0.05,0.03,0.02
22.680096784545903,0.0019964842945149252,67.71271027186992,300.0,8.333333333333333e-05,0.67,0.28,0.23,0.05,0.9,0.05,0.03,0.02
22.865360807645402,0.00201192296310655,68.04857753654606,300.0,8.333333333333333e-05,0.67,0.28,0.23,0.05,0.9,0.05,0.03,0.02
23.0506248307449,0.0020273616316981748,68.38444480122347,300.0,8.333333333333333e-05,0.67,0.28,0.23,0.05,0.9,0.05,0.03,0.02
23.2358888538444,0.0020428003002898,68.72031206590226,300.0,8.333333333333333e-05,0.67,0.28,0.23,0.05,0.9,0.05,0.03,0.02
23.437150567064702,0.002059572109724825,69.05748480376616,300.0,8.333333333333333e-05,0.67,0.28,0.23,0.05,0.9,0.05,0.03,0.02
23.638412280285003,0.0020763439191598503,69.39465754162936,300.0,8.333333333333333e-05,0.67,0.28,0.23,0.05,0.9,0.05,0.03,0.02
23.8396739935053,0.002093115728594875,69.73183027949324,300.0,8.333333333333333e-05,0.67,0.28,0.23,0.05,0.9,0.05,0.03,0.02
24.0409357067256,0.0021098875380299,70.06900301735715,300.0,8.333333333333333e-05,0.67,0.28,0.23,0.05,0.9,0.05,0.03,0.02
24.271203375536402,0.0021290765104307998,70.40042057299962,300.0,8.333333333333333e-05,0.67,0.28,0.23,0.05,0.9,0.05,0.03,0.02
24.5014710443472,0.0021482654828317,70.73183812864245,300.0,8.333333333333333e-05,0.67,0.28,0.23,0.05,0.9,0.05,0.03,0.02
24.731738713158,0.0021674544552326,71.06325568428468,300.0,8.333333333333333e-05,0.67,0.28,0.23,0.05,0.9,0.05,0.03,0.02
24.9620063819688,0.0021866434276335,71.3946732399265,300.0,8.333333333333333e-05,0.67,0.28,0.23,0.05,0.9,0.05,0.03,0.02
25.163609148733798,0.00220344365819725,71.7131612561885,300.0,8.333333333333333e-05,0.67,0.28,0.23,0.05,0.9,0.05,0.03,0.02
25.3652119154988,0.002220243888761,72.03164927245064,300.0,8.333333333333333e-05,0.67,0.28,0.23,0.05,0.9,0.05,0.03,0.02
25.566814682263804,0.0022370441193247503,72.3501372887128,300.0,8.333333333333333e-05,0.67,0.28,0.23,0.05,0.9,0.05,0.03,0.02
25.768417449028803,0.0022538443498885,72.66862530497514,300.0,8.333333333333333e-05,0.67,0.28,0.23,0.05,0.9,0.05,0.03,0.02
26.052337428654603,0.0022775043481906504,72.96706506799843,300.0,8.333333333333333e-05,0.67,0.28,0.23,0.05,0.9,0.05,0.03,0.02
26.336257408280403,0.0023011643464928002,73.26550483102176,300.0,8.333333333333333e-05,0.67,0.28,0.23,0.05,0.9,0.05,0.03,0.02
26.620177387906203,0.00232482434479495,73.5639445940451,300.0,8.333333333333333e-05,0.67,0.28,0.23,0.05,0.9,0.05,0.03,0.02
26.904097367532,0.0023484843430971,73.86238435706812,300.0,8.333333333333333e-05,0.67,0.28,0.23,0.05,0.9,0.05,0.03,0.02
27.185028416060703,0.002371895263807825,74.14968509572513,300.0,8.333333333333333e-05,0.67,0.28,0.23,0.05,0.9,0.05,0.03,0.02
27.465959464589403,0.00239530618451855,74.43698583438206,300.0,8.333333333333333e-05,0.67,0.28,0.23,0.05,0.9,0.05,0.03,0.02
27.746890513118103,0.002418717105229275,74.72428657303902,300.0,8.333333333333333e-05,0.67,0.28,0.23,0.05,0.9,0.05,0.03,0.02
28.027821561646803,0.00244212802594,75.01158731169613,300.0,8.333333333333333e-05,0.67,0.28,0.23,0.05,0.9,0.05,0.03,0.02
28.343402500081204,0.0024684264374762004,75.30532813887758,300.0,8.333333333333333e-05,0.67,0.28,0.23,0.05,0.9,0.05,0.03,0.02
28.6589834385156,0.0024947248490124,75.5990689660588,300.0,8.333333333333333e-05,0.67,0.28,0.23,0.05,0.9,0.05,0.03,0.02
28.97456437695,0.0025210232605486,75.89280979324026,300.0,8.333333333333333e-05,0.67,0.28,0.23,0.05,0.9,0.05,0.03,0.02
29.2901453153844,0.0025473216720848,76.18655062042214,300.0,8.333333333333333e-05,0.67,0.28,0.23,0.05,0.9,0.05,0.03,0.02
29.6356345823616,0.0025761124443329,76.47221492347589,300.0,8.333333333333333e-05,0.67,0.28,0.23,0.05,0.9,0.05,0.03,0.02
29.9811238493388,0.002604903216581,76.7578792265298,300.0,8.333333333333333e-05,0.67,0.28,0.23,0.05,0.9,0.05,0.03,0.02
30.326613116316,0.0026336939888291,77.04354352958347,300.0,8.333333333333333e-05,0.67,0.28,0.23,0.05,0.9,0.05,0.03,0.02
30.6721023832932,0.0026624847610772,77.32920783263668,300.0,8.333333333333333e-05,0.67,0.28,0.23,0.05,0.9,0.05,0.03,0.02
30.975584372463,0.00268777492684135,77.61477921766289,300.0,8.333333333333333e-05,0.67,0.28,0.23,0.05,0.9,0.05,0.03,0.02
31.2790663616328,0.0027130650926055003,77.90035060268931,300.0,8.333333333333333e-05,0.67,0.28,0.23,0.05,0.9,0.05,0.03,0.02
31.5825483508026,0.00273835525836965,78.1859219877155,300.0,8.333333333333333e-05,0.67,0.28,0.23,0.05,0.9,0.05,0.03,0.02
31.8860303399724,0.0027636454241338,78.47149337274156,300.0,8.333333333333333e-05,0.67,0.28,0.23,0.05,0.9,0.05,0.03,0.02
32.262716185493105,0.002795035911260525,78.74527889633411,300.0,8.333333333333333e-05,0.67,0.28,0.23,0.05,0.9,0.05,0.03,0.02
32.6394020310138,0.00282642639838725,79.01906441992662,300.0,8.333333333333333e-05,0.67,0.28,0.23,0.05,0.9,0.05,0.03,0.02
33.0160878765345,0.002857816885513975,79.29284994351914,300.0,8.333333333333333e-05,0.67,0.28,0.23,0.05,0.9,0.05,0.03,0.02
33.3927737220552,0.0028892073726407,79.56663546711182,300.0,8.333333333333333e-05,0.67,0.28,0.23,0.05,0.9,0.05,0.03,0.02
33.83380487945131,0.002925959969090375,79.83133840075432,300.0,8.333333333333333e-05,0.67,0.28,0.23,0.05,0.9,0.05,0.03,0.02
34.274836036847404,0.00296271256554005,80.0960413343967,300.0,8.333333333333333e-05,0.67,0.28,0.23,0.05,0.9,0.05,0.03,0.02
34.7158671942435,0.0029994651619897252,80.36074426803916,300.0,8.333333333333333e-05,0.67,0.28,0.23,0.05,0.9,0.05,0.03,0.02
35.156898351639605,0.0030362177584394,80.62544720168148,300.0,8.333333333333333e-05,0.67,0.28,0.23,0.05,0.9,0.05,0.03,0.02
35.540020040455204,0.0030681445658407,80.86521366336319,300.0,8.333333333333333e-05,0.67,0.28,0.23,0.05,0.9,0.05,0.03,0.02
35.9231417292708,0.003100071373242,81.10498012504513,300.0,8.333333333333333e-05,0.67,0.28,0.23,0.05,0.9,0.05,0.03,0.02
36.3062634180864,0.0031319981806433002,81.34474658672696,300.0,8.333333333333333e-05,0.67,0.28,0.23,0.05,0.9,0.05,0.03,0.02
36.689385106902,0.0031639249880446,81.58451304840858,300.0,8.333333333333333e-05,0.67,0.28,0.23,0.05,0.9,0.05,0.03,0.02
37.091418092115006,0.00319742773681235,81.81833222270282,300.0,8.333333333333333e-05,0.67,0.28,0.23,0.05,0.9,0.05,0.03,0.02
37.493451077328004,0.0032309304855801,82.05215139699695,300.0,8.333333333333333e-05,0.67,0.28,0.23,0.05,0.9,0.05,0.03,0.02
37.895484062541,0.00326443323434785,82.2859705712912,300.0,8.333333333333333e-05,0.67,0.28,0.23,0.05,0.9,0.05,0.03,0.02
38.297517047754,0.0032979359831156,82.51978974558527,300.0,8.333333333333333e-05,0.67,0.28,0.23,0.05,0.9,0.05,0.03,0.02
38.7001993132641,0.003331492838574775,82.73631988183672,300.0,8.333333333333333e-05,0.67,0.28,0.23,0.05,0.9,0.05,0.03,0.02
39.1028815787742,0.00336504969403395,82.95285001808897,300.0,8.333333333333333e-05,0.67,0.28,0.23,0.05,0.9,0.05,0.03,0.02
39.505563844284296,0.003398606549493125,83.16938015434037,300.0,8.333333333333333e-05,0.67,0.28,0.23,0.05,0.9,0.05,0.03,0.02
39.9082461097944,0.0034321634049523,83.38591029059187,300.0,8.333333333333333e-05,0.67,0.28,0.23,0.05,0.9,0.05,0.03,0.02
40.3335810901245,0.0034676079866464747,83.60015652568045,300.0,8.333333333333333e-05,0.67,0.28,0.23,0.05,0.9,0.05,0.03,0.02
40.7589160704546,0.00350305256834065,83.81440276076894,300.0,8.333333333333333e-05,0.67,0.28,0.23,0.05,0.9,0.05,0.03,0.02
41.1842510507847,0.003538497150034825,84.02864899585744,300.0,8.333333333333333e-05,0.67,0.28,0.23,0.05,0.9,0.05,0.03,0.02
41.6095860311148,0.003573941731729,84.24289523094558,300.0,8.333333333333333e-05,0.67,0.28,0.23,0.05,0.9,0.05,0.03,0.02
42.0695332523181,0.003612270666829275,84.43103325138006,300.0,8.333333333333333e-05,0.67,0.28,0.23,0.05,0.9,0.05,0.03,0.02
42.5294804735214,0.00365059960192955,84.61917127181495,300.0,8.333333333333333e-05,0.67,0.28,0.23,0.05,0.9,0.05,0.03,0.02
42.9894276947247,0.0036889285370298253,84.8073092922495,300.0,8.333333333333333e-05,0.67,0.28,0.23,0.05,0.9,0.05,0.03,0.02
43.449374915928,0.0037272574721301,84.99544731268395,300.0,8.333333333333333e-05,0.67,0.28,0.23,0.05,0.9,0.05,0.03,0.02
43.898136556557,0.00376465427551585,85.17664703209951,300.0,8.333333333333333e-05,0.67,0.28,0.23,0.05,0.9,0.05,0.03,0.02
44.346898197186,0.0038020510789016,85.35784675151459,300.0,8.333333333333333e-05,0.67,0.28,0.23,0.05,0.9,0.05,0.03,0.02
44.795659837815,0.00383944788228735,85.53904647093006,300.0,8.333333333333333e-05,0.67,0.28,0.23,0.05,0.9,0.05,0.03,0.02
45.244421478444,0.0038768446856731,85.72024619034529,300.0,8.333333333333333e-05,0.67,0.28,0.23,0.05,0.9,0.05,0.03,0.02
45.694706336090405,0.0039143684238103,85.88242030821432,300.0,8.333333333333333e-05,0.67,0.28,0.23,0.05,0.9,0.05,0.03,0.02
46.1449911937368,0.0039518921619475,86.04459442608352,300.0,8.333333333333333e-05,0.67,0.28,0.23,0.05,0.9,0.05,0.03,0.02
46.595276051383195,0.0039894159000847,86.20676854395269,300.0,8.333333333333333e-05,0.67,0.28,0.23,0.05,0.9,0.05,0.03,0.02
47.0455609090296,0.0040269396382219,86.36894266182229,300.0,8.333333333333333e-05,0.67,0.28,0.23,0.05,0.9,0.05,0.03,0.02
47.5315871731128,0.0040674418268955,86.51694136320626,300.0,8.333333333333333e-05,0.67,0.28,0.23,0.05,0.9,0.05,0.03,0.02
48.017613437196,0.0041079440155691,86.66494006459008,300.0,8.333333333333333e-05,0.67,0.28,0.23,0.05,0.9,0.05,0.03,0.02
48.5036397012792,0.0041484462042427,86.81293876597411,300.0,8.333333333333333e-05,0.67,0.28,0.23,0.05,0.9,0.05,0.03,0.02
48.9896659653624,0.0041889483929163,86.9609374673584,300.0,8.333333333333333e-05,0.67,0.28,0.23,0.05,0.9,0.05,0.03,0.02
49.4906979778509,0.004230701060623674,87.09058091935856,300.0,8.333333333333333e-05,0.67,0.28,0.23,0.05,0.9,0.05,0.03,0.02
49.9917299903394,0.00427245372833105,87.22022437135863,300.0,8.333333333333333e-05,0.67,0.28,0.23,0.05,0.9,0.05,0.03,0.02
50.4927620028279,0.004314206396038425,87.3498678233587,300.0,8.333333333333333e-05,0.67,0.28,0.23,0.05,0.9,0.05,0.03,0.02
50.9937940153164,0.0043559590637458,87.47951127535885,300.0,8.333333333333333e-05,0.67,0.28,0.23,0.05,0.9,0.05,0.03,0.02
51.4843703480322,0.00439684042480545,87.59346738787833,300.0,8.333333333333333e-05,0.67,0.28,0.23,0.05,0.9,0.05,0.03,0.02
51.974946680748005,0.0044377217858651,87.70742350039758,300.0,8.333333333333333e-05,0.67,0.28,0.23,0.05,0.9,0.05,0.03,0.02
52.46552301346381,0.0044786031469247495,87.82137961291708,300.0,8.333333333333333e-05,0.67,0.28,0.23,0.05,0.9,0.05,0.03,0.02
52.956099346179606,0.0045194845079844,87.93533572543632,300.0,8.333333333333333e-05,0.67,0.28,0.23,0.05,0.9,0.05,0.03,0.02
53.468486156269805,0.00456218340882525,88.02530008070038,300.0,8.333333333333333e-05,0.67,0.28,0.23,0.05,0.9,0.05,0.03,0.02
53.98087296636,0.004604882309666099,88.11526443596514,300.0,8.333333333333333e-05,0.67,0.28,0.23,0.05,0.9,0.05,0.03,0.02
54.4932597764502,0.00464758121050695,88.20522879122917,300.0,8.333333333333333e-05,0.67,0.28,0.23,0.05,0.9,0.05,0.03,0.02
55.0056465865404,0.0046902801113478,88.2951931464922,300.0,8.333333333333333e-05,0.67,0.28,0.23,0.05,0.9,0.05,0.03,0.02
55.5334389894402,0.00473426281158945,88.37617319771061,300.0,8.333333333333333e-05,0.67,0.28,0.23,0.05,0.9,0.05,0.03,0.02
56.061231392340005,0.0047782455118311005,88.45715324892922,300.0,8.333333333333333e-05,0.67,0.28,0.23,0.05,0.9,0.05,0.03,0.02
56.58902379523981,0.0048222282120727504,88.53813330014759,300.0,8.333333333333333e-05,0.67,0.28,0.23,0.05,0.9,0.05,0.03,0.02
57.11681619813961,0.0048662109123144,88.61911335136627,300.0,8.333333333333333e-05,0.67,0.28,0.23,0.05,0.9,0.05,0.03,0.02
57.62678423377441,0.0049087082486173,88.68113804986555,300.0,8.333333333333333e-05,0.67,0.28,0.23,0.05,0.9,0.05,0.03,0.02
58.13675226940921,0.0049512055849202,88.74316274836526,300.0,8.333333333333333e-05,0.67,0.28,0.23,0.05,0.9,0.05,0.03,0.02
58.646720305044006,0.0049937029212231004,88.80518744686471,300.0,8.333333333333333e-05,0.67,0.28,0.23,0.05,0.9,0.05,0.03,0.02
59.156688340678805,0.005036200257526,88.86721214536406,300.0,8.333333333333333e-05,0.67,0.28,0.23,0.05,0.9,0.05,0.03,0.02
59.70574863904021,0.0050819552823894495,88.92032933840353,300.0,8.333333333333333e-05,0.67,0.28,0.23,0.05,0.9,0.05,0.03,0.02
60.254808937401606,0.0051277103072529,88.97344653144297,300.0,8.333333333333333e-05,0.67,0.28,0.23,0.05,0.9,0.05,0.03,0.02
60.803869235763,0.00517346533211635,89.02656372448236,300.0,8.333333333333333e-05,0.67,0.28,0.23,0.05,0.9,0.05,0.03,0.02
61.35292953412441,0.0052192203569798,89.07968091752129,300.0,8.333333333333333e-05,0.67,0.28,0.23,0.05,0.9,0.05,0.03,0.02
61.8809961757602,0.00526322591044945,89.12479799764628,300.0,8.333333333333333e-05,0.67,0.28,0.23,0.05,0.9,0.05,0.03,0.02
62.409062817396006,0.0053072314639191,89.16991507777176,300.0,8.333333333333333e-05,0.67,0.28,0.23,0.05,0.9,0.05,0.03,0.02
62.93712945903181,0.00535123701738875,89.2150321578966,300.0,8.333333333333333e-05,0.67,0.28,0.23,0.05,0.9,0.05,0.03,0.02
63.465196100667605,0.0053952425708584,89.26014923802136,300.0,8.333333333333333e-05,0.67,0.28,0.23,0.05,0.9,0.05,0.03,0.02
63.997303846471496,0.005439584883008725,89.30079316121358,300.0,8.333333333333333e-05,0.67,0.28,0.23,0.05,0.9,0.05,0.03,0.02
64.5294115922754,0.00548392719515905,89.34143708440573,300.0,8.333333333333333e-05,0.67,0.28,0.23,0.05,0.9,0.05,0.03,0.02
65.0615193380793,0.005528269507309375,89.38208100759806,300.0,8.333333333333333e-05,0.67,0.28,0.23,0.05,0.9,0.05,0.03,0.02
65.59362708388319,0.0055726118194597,89.42272493078966,300.0,8.333333333333333e-05,0.67,0.28,0.23,0.05,0.9,0.05,0.03,0.02
66.10757103722639,0.0056154404822383,89.45706261058143,300.0,8.333333333333333e-05,0.67,0.28,0.23,0.05,0.9,0.05,0.03,0.02
66.6215149905696,0.0056582691450169,89.49140029037403,300.0,8.333333333333333e-05,0.67,0.28,0.23,0.05,0.9,0.05,0.03,0.02
67.1354589439128,0.0057010978077955,89.5257379701659,300.0,8.333333333333333e-05,0.67,0.28,0.23,0.05,0.9,0.05,0.03,0.02
67.649402897256,0.0057439264705741,89.56007564995822,300.0,8.333333333333333e-05,0.67,0.28,0.23,0.05,0.9,0.05,0.03,0.02
68.1707226660093,0.005787369784636875,89.58674617540665,300.0,8.333333333333333e-05,0.67,0.28,0.23,0.05,0.9,0.05,0.03,0.02
68.6920424347626,0.00583081309869965,89.6134167008553,300.0,8.333333333333333e-05,0.67,0.28,0.23,0.05,0.9,0.05,0.03,0.02
69.2133622035159,0.0058742564127624245,89.64008722630346,300.0,8.333333333333333e-05,0.67,0.28,0.23,0.05,0.9,0.05,0.03,0.02
69.7346819722692,0.0059176997268252,89.66675775175123,300.0,8.333333333333333e-05,0.67,0.28,0.23,0.05,0.9,0.05,0.03,0.02
70.2578335919925,0.005961295695135475,89.68908218241833,300.0,8.333333333333333e-05,0.67,0.28,0.23,0.05,0.9,0.05,0.03,0.02
70.7809852117158,0.00600489166344575,89.71140661308522,300.0,8.333333333333333e-05,0.67,0.28,0.23,0.05,0.9,0.05,0.03,0.02
71.30413683143911,0.006048487631756025,89.73373104375243,300.0,8.333333333333333e-05,0.67,0.28,0.23,0.05,0.9,0.05,0.03,0.02
71.8272884511624,0.0060920836000663,89.75605547441997,300.0,8.333333333333333e-05,0.67,0.28,0.23,0.05,0.9,0.05,0.03,0.02
72.40996010467501,0.00614063957119235,89.77552456220535,300.0,8.333333333333333e-05,0.67,0.28,0.23,0.05,0.9,0.05,0.03,0.02
72.9926317581876,0.0061891955423184,89.79499364999016,300.0,8.333333333333333e-05,0.67,0.28,0.23,0.05,0.9,0.05,0.03,0.02
73.57530341170019,0.00623775151344445,89.81446273777561,300.0,8.333333333333333e-05,0.67,0.28,0.23,0.05,0.9,0.05,0.03,0.02
74.1579750652128,0.0062863074845705,89.8339318255612,300.0,8.333333333333333e-05,0.67,0.28,0.23,0.05,0.9,0.05,0.03,0.02
74.6840824531233,0.006330149766896375,89.85313110836059,300.0,8.333333333333333e-05,0.67,0.28,0.23,0.05,0.9,0.05,0.03,0.02
75.2101898410338,0.00637399204922225,89.872330391159,300.0,8.333333333333333e-05,0.67,0.28,0.23,0.05,0.9,0.05,0.03,0.02
75.7362972289443,0.006417834331548125,89.89152967395857,300.0,8.333333333333333e-05,0.67,0.28,0.23,0.05,0.9,0.05,0.03,0.02
76.2624046168548,0.006461676613874,89.91072895675931,300.0,8.333333333333333e-05,0.67,0.28,0.23,0.05,0.9,0.05,0.03,0.02
76.8660008854824,0.0065119763029262995,89.92727271767188,300.0,8.333333333333333e-05,0.67,0.28,0.23,0.05,0.9,0.05,0.03,0.02
77.46959715411,0.006562275991978599,89.94381647858427,300.0,8.333333333333333e-05,0.67,0.28,0.23,0.05,0.9,0.05,0.03,0.02
78.0731934227376,0.006612575681030899,89.96036023949651,300.0,8.333333333333333e-05,0.67,0.28,0.23,0.05,0.9,0.05,0.03,0.02
78.6767896913652,0.0066628753700832,89.97690400040935,300.0,8.333333333333333e-05,0.67,0.28,0.23,0.05,0.9,0.05,0.03,0.02
79.2265218326109,0.006708686381853675,89.9855302496761,300.0,8.333333333333333e-05,0.67,0.28,0.23,0.05,0.9,0.05,0.03,0.02
79.7762539738566,0.00675449739362415,89.99415649894269,300.0,8.333333333333333e-05,0.67,0.28,0.23,0.05,0.9,0.05,0.03,0.02
80.3259861151023,0.006800308405394625,90.00278274820944,300.0,8.333333333333333e-05,0.67,0.28,0.23,0.05,0.9,0.05,0.03,0.02
80.875718256348,0.0068461194171651,90.0114089974756,300.0,8.333333333333333e-05,0.67,0.28,0.23,0.05,0.9,0.05,0.03,0.02
81.41532500711489,0.006891086646395674,90.02229115430876,300.0,8.333333333333333e-05,0.67,0.28,0.23,0.05,0.9,0.05,0.03,0.02
81.9549317578818,0.00693605387562625,90.03317331114243,300.0,8.333333333333333e-05,0.67,0.28,0.23,0.05,0.9,0.05,0.03,0.02
82.4945385086487,0.006981021104856825,90.0440554679757,300.0,8.333333333333333e-05,0.67,0.28,0.23,0.05,0.9,0.05,0.03,0.02
83.0341452594156,0.0070259883340874,90.05493762480772,300.0,8.333333333333333e-05,0.67,0.28,0.23,0.05,0.9,0.05,0.03,0.02
83.5900495999947,0.007072313695802324,90.06349617083816,300.0,8.333333333333333e-05,0.67,0.28,0.23,0.05,0.9,0.05,0.03,0.02
84.1459539405738,0.007118639057517249,90.07205471686966,300.0,8.333333333333333e-05,0.67,0.28,0.23,0.05,0.9,0.05,0.03,0.02
84.70185828115291,0.007164964419232174,90.08061326290021,300.0,8.333333333333333e-05,0.67,0.28,0.23,0.05,0.9,0.05,0.03,0.02
85.257762621732,0.0072112897809471,90.0891718089303,300.0,8.333333333333333e-05,0.67,0.28,0.23,0.05,0.9,0.05,0.03,0.02
85.8258322573395,0.007258628917247724,90.09224759841925,300.0,8.333333333333333e-05,0.67,0.28,0.23,0.05,0.9,0.05,0.03,0.02
86.393901892947,0.007305968053548349,90.09532338790807,300.0,8.333333333333333e-05,0.67,0.28,0.23,0.05,0.9,0.05,0.03,0.02
86.9619715285545,0.007353307189848975,90.09839917739696,300.0,8.333333333333333e-05,0.67,0.28,0.23,0.05,0.9,0.05,0.03,0.02
87.530041164162,0.0074006463261496,90.10147496688603,300.0,8.333333333333333e-05,0.67,0.28,0.23,0.05,0.9,0.05,0.03,0.02
88.08206981315399,0.007446648713565599,90.10296983363081,300.0,8.333333333333333e-05,0.67,0.28,0.23,0.05,0.9,0.05,0.03,0.02
88.634098462146,0.007492651100981599,90.10446470037624,300.0,8.333333333333333e-05,0.67,0.28,0.23,0.05,0.9,0.05,0.03,0.02
89.186127111138,0.0075386534883975995,90.10595956712096,300.0,8.333333333333333e-05,0.67,0.28,0.23,0.05,0.9,0.05,0.03,0.02
89.73815576013,0.0075846558758136,90.1074544338652,300.0,8.333333333333333e-05,0.67,0.28,0.23,0.05,0.9,0.05,0.03,0.02