File: datasets/al_6061_comp/csv/T_300_D_1.csv
Time,Strain(%),Stress(MPa),Temp(C),SR(%/s),Si(%),Fe(%),Cu(%),Mn(%),Mg(%),Cr(%),Zn(%),Ti(%)
0.0,9.11731942329135e-05,0.07542823165836188,300.0,8.333333333333333e-05,0.67,0.28,0.23,0.05,0.9,0.05,0.03,0.02
0.17753138287371895,0.00010596747613905675,0.15469019847607496,300.0,8.333333333333333e-05,0.67,0.28,0.23,0.05,0.9,0.05,0.03,0.02
0.3550627657474379,0.0001207617580452,0.2339521652937877,300.0,8.333333333333333e-05,0.67,0.28,0.23,0.05,0.9,0.05,0.03,0.02
0.5041371496216379,0.00013318462336805,0.4158226381277228,300.0,8.333333333333333e-05,0.67,0.28,0.23,0.05,0.9,0.05,0.03,0.02
0.6532115334958379,0.0001456074886909,0.5976931109616581,300.0,8.333333333333333e-05,0.67,0.28,0.23,0.05,0.9,0.05,0.03,0.02
0.9375766457482381,0.0001693045813786,0.8748088230105491,300.0,8.333333333333333e-05,0.67,0.28,0.23,0.05,0.9,0.05,0.03,0.02
1.2219417580006382,0.0001930016740663,1.1519245350594391,300.0,8.333333333333333e-05,0.67,0.28,0.23,0.05,0.9,0.05,0.03,0.02
1.4059524662590381,0.0002083358997545,1.5085009236688243,300.0,8.333333333333333e-05,0.67,0.28,0.23,0.05,0.9,0.05,0.03,0.02
1.589963174517438,0.0002236701254427,1.8650773122782098,300.0,8.333333333333333e-05,0.67,0.28,0.23,0.05,0.9,0.05,0.03,0.02
1.6248462987220382,0.00022657705245975,2.344203645460304,300.0,8.333333333333333e-05,0.67,0.28,0.23,0.05,0.9,0.05,0.03,0.02
1.6597294229266384,0.0002294839794768,2.823329978642402,300.0,8.333333333333333e-05,0.67,0.28,0.23,0.05,0.9,0.05,0.03,0.02
1.8755496184690381,0.000247468995772,3.479742331163523,300.0,8.333333333333333e-05,0.67,0.28,0.23,0.05,0.9,0.05,0.03,0.02
2.091369814011438,0.0002654540120672,4.136154683684643,300.0,8.333333333333333e-05,0.67,0.28,0.23,0.05,0.9,0.05,0.03,0.02
2.3896840867276383,0.00029031353479355,4.873697542136814,300.0,8.333333333333333e-05,0.67,0.28,0.23,0.05,0.9,0.05,0.03,0.02
2.6879983594438386,0.0003151730575199,5.611240400588979,300.0,8.333333333333333e-05,0.67,0.28,0.23,0.05,0.9,0.05,0.03,0.02
2.9473308562408382,0.00033678409891965,6.32924094853229,300.0,8.333333333333333e-05,0.67,0.28,0.23,0.05,0.9,0.05,0.03,0.02
3.206663353037838,0.0003583951403194,7.047241496475607,300.0,8.333333333333333e-05,0.67,0.28,0.23,0.05,0.9,0.05,0.03,0.02
3.502460438924838,0.00038304489747665,7.765558025094476,300.0,8.333333333333333e-05,0.67,0.28,0.23,0.05,0.9,0.05,0.03,0.02
3.798257524811838,0.0004076946546339,8.483874553713353,300.0,8.333333333333333e-05,0.67,0.28,0.23,0.05,0.9,0.05,0.03,0.02
3.9428447084974385,0.0004197435866077,9.214525406518678,300.0,8.333333333333333e-05,0.67,0.28,0.23,0.05,0.9,0.05,0.03,0.02
4.087431892183039,0.0004317925185815,9.94517625932399,300.0,8.333333333333333e-05,0.67,0.28,0.23,0.05,0.9,0.05,0.03,0.02
4.313337579474439,0.00045061799252245,10.712327751544898,300.0,8.333333333333333e-05,0.67,0.28,0.23,0.05,0.9,0.05,0.03,0.02
4.539243266765839,0.0004694434664634,11.479479243765791,300.0,8.333333333333333e-05,0.67,0.28,0.23,0.05,0.9,0.05,0.03,0.02
4.767746851887438,0.0004884854318902,12.241662674545243,300.0,8.333333333333333e-05,0.67,0.28,0.23,0.05,0.9,0.05,0.03,0.02
4.996250437009038,0.000507527397317,13.0038461053247,300.0,8.333333333333333e-05,0.67,0.28,0.23,0.05,0.9,0.05,0.03,0.02
5.306942394371839,0.0005334183937639,13.70984084980805,300.0,8.333333333333333e-05,0.67,0.28,0.23,0.05,0.9,0.05,0.03,0.02
5.617634351734639,0.0005593093902108,14.415835594291417,300.0,8.333333333333333e-05,0.67,0.28,0.23,0.05,0.9,0.05,0.03,0.02
5.808835484397439,0.0005752428179327,15.13933323012237,300.0,8.333333333333333e-05,0.67,0.28,0.23,0.05,0.9,0.05,0.03,0.02
6.000036617060238,0.0005911762456546,15.862830865953306,300.0,8.333333333333333e-05,0.67,0.28,0.23,0.05,0.9,0.05,0.03,0.02
6.168093234589638,0.0006051809637820499,16.67812246150035,300.0,8.333333333333333e-05,0.67,0.28,0.23,0.05,0.9,0.05,0.03,0.02
6.336149852119038,0.0006191856819095,17.49341405704743,300.0,8.333333333333333e-05,0.67,0.28,0.23,0.05,0.9,0.05,0.03,0.02
6.472200936968238,0.0006305232723136,18.30780428676463,300.0,8.333333333333333e-05,0.67,0.28,0.23,0.05,0.9,0.05,0.03,0.02
6.608252021817438,0.0006418608627177,19.122194516481763,300.0,8.333333333333333e-05,0.67,0.28,0.23,0.05,0.9,0.05,0.03,0.02
6.687562273924638,0.0006484700503932999,19.94395313073965,300.0,8.333333333333333e-05,0.67,0.28,0.23,0.05,0.9,0.05,0.03,0.02
6.766872526031839,0.0006550792380689,20.765711744997564,300.0,8.333333333333333e-05,0.67,0.28,0.23,0.05,0.9,0.05,0.03,0.02
7.020838619437638,0.0006762430791860501,21.621170752844165,300.0,8.333333333333333e-05,0.67,0.28,0.23,0.05,0.9,0.05,0.03,0.02
7.274804712843438,0.0006974069203032,22.476629760690805,300.0,8.333333333333333e-05,0.67,0.28,0.23,0.05,0.9,0.05,0.03,0.02
7.5727059586978385,0.0007222320241244,23.373769577442605,300.0,8.333333333333333e-05,0.67,0.28,0.23,0.05,0.9,0.05,0.03,0.02
7.870607204552239,0.0007470571279456,24.27090939419439,300.0,8.333333333333333e-05,0.67,0.28,0.23,0.05,0.9,0.05,0.03,0.02
7.966496011606639,0.0007550478618668,25.14553679969974,300.0,8.333333333333333e-05,0.67,0.28,0.23,0.05,0.9,0.05,0.03,0.02
8.06238481866104,0.000763038595788,26.020164205205155,300.0,8.333333333333333e-05,0.67,0.28,0.23,0.05,0.9,0.05,0.03,0.02
8.269546126139838,0.0007803020380779001,26.904418134198508,300.0,8.333333333333333e-05,0.67,0.28,0.23,0.05,0.9,0.05,0.03,0.02
8.476707433618637,0.0007975654803678,27.788672063191807,300.0,8.333333333333333e-05,0.67,0.28,0.23,0.05,0.9,0.05,0.03,0.02
8.688594712193837,0.0008152227535824,28.622854379299756,300.0,8.333333333333333e-05,0.67,0.28,0.23,0.05,0.9,0.05,0.03,0.02
8.900481990769038,0.000832880026797,29.45703669540777,300.0,8.333333333333333e-05,0.67,0.28,0.23,0.05,0.9,0.05,0.03,0.02
9.179634249269839,0.0008561427150054,30.287771665682968,300.0,8.333333333333333e-05,0.67,0.28,0.23,0.05,0.9,0.05,0.03,0.02
9.458786507770638,0.0008794054032138,31.11850663595811,300.0,8.333333333333333e-05,0.67,0.28,0.23,0.05,0.9,0.05,0.03,0.02
9.819473600835437,0.0009094626609691999,31.97750718306196,300.0,8.333333333333333e-05,0.67,0.28,0.23,0.05,0.9,0.05,0.03,0.02
10.180160693900238,0.0009395199187246,32.836507730165785,300.0,8.333333333333333e-05,0.67,0.28,0.23,0.05,0.9,0.05,0.03,0.02
10.375250723684236,0.0009557774212066,33.66966792881254,300.0,8.333333333333333e-05,0.67,0.28,0.23,0.05,0.9,0.05,0.03,0.02
10.570340753468235,0.0009720349236886,34.50282812745934,300.0,8.333333333333333e-05,0.67,0.28,0.23,0.05,0.9,0.05,0.03,0.02
10.741752912175038,0.0009863192702475,35.278592147337086,300.0,8.333333333333333e-05,0.67,0.28,0.23,0.05,0.9,0.05,0.03,0.02
10.913165070881838,0.0010006036168064,36.05435616721476,300.0,8.333333333333333e-05,0.67,0.28,0.23,0.05,0.9,0.05,0.03,0.02
11.17544610959444,0.0010224603700324502,36.83371823604707,300.0,8.333333333333333e-05,0.67,0.28,0.23,0.05,0.9,0.05,0.03,0.02
11.437727148307038,0.0010443171232585,37.61308030487953,300.0,8.333333333333333e-05,0.67,0.28,0.23,0.05,0.9,0.05,0.03,0.02
11.61210883954784,0.0010588489308619,38.385909460132424,300.0,8.333333333333333e-05,0.67,0.28,0.23,0.05,0.9,0.05,0.03,0.02
11.78649053078864,0.0010733807384653,39.158738615385076,300.0,8.333333333333333e-05,0.67,0.28,0.23,0.05,0.9,0.05,0.03,0.02
11.968710999029838,0.0010885657774854,39.91366510755198,300.0,8.333333333333333e-05,0.67,0.28,0.23,0.05,0.9,0.05,0.03,0.02
12.150931467271038,0.0011037508165055,40.668591599718994,300.0,8.333333333333333e-05,0.67,0.28,0.23,0.05,0.9,0.05,0.03,0.02
12.360492318076039,0.00112121422073925,41.40747751511128,300.0,8.333333333333333e-05,0.67,0.28,0.23,0.05,0.9,0.05,0.03,0.02
12.57005316888104,0.001138677624973,42.14636343050359,300.0,8.333333333333333e-05,0.67,0.28,0.23,0.05,0.9,0.05,0.03,0.02
12.77115146434964,0.00115543581626205,42.86265834874073,300.0,8.333333333333333e-05,0.67,0.28,0.23,0.05,0.9,0.05,0.03,0.02
12.972249759818238,0.0011721940075511,43.57895326697772,300.0,8.333333333333333e-05,0.67,0.28,0.23,0.05,0.9,0.05,0.03,0.02
13.052121927435437,0.0011788500215192,44.27475187721748,300.0,8.333333333333333e-05,0.67,0.28,0.23,0.05,0.9,0.05,0.03,0.02
13.131994095052637,0.0011855060354873,44.970550487457245,300.0,8.333333333333333e-05,0.67,0.28,0.23,0.05,0.9,0.05,0.03,0.02
13.309253292711436,0.0012002776352922,45.65986811645794,300.0,8.333333333333333e-05,0.67,0.28,0.23,0.05,0.9,0.05,0.03,0.02
13.486512490370236,0.0012150492350971,46.34918574545871,300.0,8.333333333333333e-05,0.67,0.28,0.23,0.05,0.9,0.05,0.03,0.02
13.716751654788439,0.00123423583213195,47.031942957003956,300.0,8.333333333333333e-05,0.67,0.28,0.23,0.05,0.9,0.05,0.03,0.02
13.94699081920664,0.0012534224291668,47.7147001685493,300.0,8.333333333333333e-05,0.67,0.28,0.23,0.05,0.9,0.05,0.03,0.02
14.118014514741438,0.0012676744037947,48.396037779573504,300.0,8.333333333333333e-05,0.67,0.28,0.23,0.05,0.9,0.05,0.03,0.02
14.289038210276235,0.0012819263784226,49.077375390597936,300.0,8.333333333333333e-05,0.67,0.28,0.23,0.05,0.9,0.05,0.03,0.02
14.485297170557835,0.0012982812917794,49.722356286707694,300.0,8.333333333333333e-05,0.67,0.28,0.23,0.05,0.9,0.05,0.03,0.02
14.681556130839438,0.0013146362051362,50.36733718281718,300.0,8.333333333333333e-05,0.67,0.28,0.23,0.05,0.9,0.05,0.03,0.02
14.843713431385638,0.0013281493135150501,51.00535773079703,300.0,8.333333333333333e-05,0.67,0.28,0.23,0.05,0.9,0.05,0.03,0.02
15.005870731931838,0.0013416624218939,51.64337827877682,300.0,8.333333333333333e-05,0.67,0.28,0.23,0.05,0.9,0.05,0.03,0.02
15.148135683697639,0.00135351783454105,52.268256471910576,300.0,8.333333333333333e-05,0.67,0.28,0.23,0.05,0.9,0.05,0.03,0.02
15.29040063546344,0.0013653732471882,52.89313466504434,300.0,8.333333333333333e-05,0.67,0.28,0.23,0.05,0.9,0.05,0.03,0.02
15.641121756925639,0.0013946000073100499,53.498277122548636,300.0,8.333333333333333e-05,0.67,0.28,0.23,0.05,0.9,0.05,0.03,0.02
15.991842878387835,0.0014238267674319,54.10341958005327,300.0,8.333333333333333e-05,0.67,0.28,0.23,0.05,0.9,0.05,0.03,0.02
16.201386754780636,0.0014412887571313,54.69388989980347,300.0,8.333333333333333e-05,0.67,0.28,0.23,0.05,0.9,0.05,0.03,0.02
16.41093063117344,0.0014587507468307,55.28436021955292,300.0,8.333333333333333e-05,0.67,0.28,0.23,0.05,0.9,0.05,0.03,0.02
16.54997663283524,0.00147033791363585,55.86336716059478,300.0,8.333333333333333e-05,0.67,0.28,0.23,0.05,0.9,0.05,0.03,0.02
16.68902263449704,0.001481925080441,56.4423741016372,300.0,8.333333333333333e-05,0.67,0.28,0.23,0.05,0.9,0.05,0.03,0.02
16.909592603421437,0.0015003059111847001,56.99890772969025,300.0,8.333333333333333e-05,0.67,0.28,0.23,0.05,0.9,0.05,0.03,0.02
17.13016257234584,0.0015186867419284,57.555441357743184,300.0,8.333333333333333e-05,0.67,0.28,0.23,0.05,0.9,0.05,0.03,0.02
17.37027944307284,0.00153869648115565,58.13715152212644,300.0,8.333333333333333e-05,0.67,0.28,0.23,0.05,0.9,0.05,0.03,0.02
17.61039631379984,0.0015587062203829,58.71886168650969,300.0,8.333333333333333e-05,0.67,0.28,0.23,0.05,0.9,0.05,0.03,0.02
17.834063463533838,0.0015773451495274,59.31617270736364,300.0,8.333333333333333e-05,0.67,0.28,0.23,0.05,0.9,0.05,0.03,0.02
18.05773061326784,0.0015959840786719,59.913483728217436,300.0,8.333333333333333e-05,0.67,0.28,0.23,0.05,0.9,0.05,0.03,0.02
18.31592756620124,0.00161750049141635,60.49043549159288,300.0,8.333333333333333e-05,0.67,0.28,0.23,0.05,0.9,0.05,0.03,0.02
18.57412451913464,0.0016390169041608,61.06738725496851,300.0,8.333333333333333e-05,0.67,0.28,0.23,0.05,0.9,0.05,0.03,0.02
18.77088942406304,0.0016554139795715,61.61043455886906,300.0,8.333333333333333e-05,0.67,0.28,0.23,0.05,0.9,0.05,0.03,0.02
18.96765432899144,0.0016718110549822,62.15348186276955,300.0,8.333333333333333e-05,0.67,0.28,0.23,0.05,0.9,0.05,0.03,0.02
19.19396908740884,0.0016906706181836501,62.69420246272931,300.0,8.333333333333333e-05,0.67,0.28,0.23,0.05,0.9,0.05,0.03,0.02
19.42028384582624,0.0017095301813851,63.23492306268889,300.0,8.333333333333333e-05,0.67,0.28,0.23,0.05,0.9,0.05,0.03,0.02
19.67794478010644,0.00173100192590845,63.750447887114845,300.0,8.333333333333333e-05,0.67,0.28,0.23,0.05,0.9,0.05,0.03,0.02
19.93560571438664,0.0017524736704318,64.26597271154094,300.0,8.333333333333333e-05,0.67,0.28,0.23,0.05,0.9,0.05,0.03,0.02
20.21200564708124,0.00177550699815635,64.74989591619135,300.0,8.333333333333333e-05,0.67,0.28,0.23,0.05,0.9,0.05,0.03,0.02
20.48840557977584,0.0017985403258809,65.23381912084183,300.0,8.333333333333333e-05,0.67,0.28,0.23,0.05,0.9,0.05,0.03,0.02
20.75573721936464,0.0018208179625133,65.70884643877524,300.0,8.333333333333333e-05,0.67,0.28,0.23,0.05,0.9,0.05,0.03,0.02
21.02306885895344,0.0018430955991457,66.18387375670858,300.0,8.333333333333333e-05,0.67,0.28,0.23,0.05,0.9,0.05,0.03,0.02
21.31292963495264,0.0018672506638122998,66.64649913113138,300.0,8.333333333333333e-05,0.67,0.28,0.23,0.05,0.9,0.05,0.03,0.02
21.60279041095184,0.0018914057284789,67.10912450555438,300.0,8.333333333333333e-05,0.67,0.28,0.23,0.05,0.9,0.05,0.03,0.02
21.96057169674344,0.0019212208356281998,67.54361577501356,300.0,8.333333333333333e-05,0.67,0.28,0.23,0.05,0.9,0.05,0.03,0.02
22.31835298253504,0.0019510359427775,67.97810704447255,300.0,8.333333333333333e-05,0.67,0.28,0.23,0.05,0.9,0.05,0.03,0.02
22.60596574622684,0.00197500367308515,68.4174324638405,300.0,8.333333333333333e-05,0.67,0.28,0.23,0.05,0.9,0.05,0.03,0.02
22.89357850991864,0.0019989714033928,68.85675788320827,300.0,8.333333333333333e-05,0.67,0.28,0.23,0.05,0.9,0.05,0.03,0.02
23.235912951415642,0.00202749927351755,69.28722832598741,300.0,8.333333333333333e-05,0.67,0.28,0.23,0.05,0.9,0.05,0.03,0.02
23.57824739291264,0.0020560271436423,69.71769876876701,300.0,8.333333333333333e-05,0.67,0.28,0.23,0.05,0.9,0.05,0.03,0.02
23.98252975953704,0.002089717340861,70.15856783820952,300.0,8.333333333333333e-05,0.67,0.28,0.23,0.05,0.9,0.05,0.03,0.02
24.38681212616144,0.0021234075380797,70.59943690765176,300.0,8.333333333333333e-05,0.67,0.28,0.23,0.05,0.9,0.05,0.03,0.02
24.802611661964242,0.0021580574993966,71.02287023620971,300.0,8.333333333333333e-05,0.67,0.28,0.23,0.05,0.9,0.05,0.03,0.02
25.21841119776704,0.0021927074607135,71.44630356476755,300.0,8.333333333333333e-05,0.67,0.28,0.23,0.05,0.9,0.05,0.03,0.02
25.576507112546842,0.00222254878694515,71.8415350101017,300.0,8.333333333333333e-05,0.67,0.28,0.23,0.05,0.9,0.05,0.03,0.02
25.93460302732664,0.0022523901131768,72.23676645543627,300.0,8.333333333333333e-05,0.67,0.28,0.23,0.05,0.9,0.05,0.03,0.02
26.28885796185284,0.00228191135772065,72.62833750916707,300.0,8.333333333333333e-05,0.67,0.28,0.23,0.05,0.9,0.05,0.03,0.02
26.64311289637904,0.0023114326022645,73.01990856289753,300.0,8.333333333333333e-05,0.67,0.28,0.23,0.05,0.9,0.05,0.03,0.02
27.03640214671184,0.0023442067064588998,73.41048776852978,300.0,8.333333333333333e-05,0.67,0.28,0.23,0.05,0.9,0.05,0.03,0.02
27.42969139704464,0.0023769808106533,73.80106697416198,300.0,8.333333333333333e-05,0.67,0.28,0.23,0.05,0.9,0.05,0.03,0.02
27.94585810260824,0.0024199947027836,74.17212601701789,300.0,8.333333333333333e-05,0.67,0.28,0.23,0.05,0.9,0.05,0.03,0.02
28.46202480817184,0.0024630085949139,74.54318505987376,300.0,8.333333333333333e-05,0.67,0.28,0.23,0.05,0.9,0.05,0.03,0.02
28.94849442426464,0.0025035477295883,74.87918039580681,300.0,8.333333333333333e-05,0.67,0.28,0.23,0.05,0.9,0.05,0.03,0.02
29.434964040357443,0.0025440868642627,75.21517573173992,300.0,8.333333333333333e-05,0.67,0.28,0.23,0.05,0.9,0.05,0.03,0.02
29.895131174077044,0.002582434125406,75.51893975933116,300.0,8.333333333333333e-05,0.67,0.28,0.23,0.05,0.9,0.05,0.03,0.02
30.35529830779664,0.0026207813865493,75.8227037869224,300.0,8.333333333333333e-05,0.67,0.28,0.23,0.05,0.9,0.05,0.03,0.02
30.83564481628364,0.0026608102622565502,76.12624522463587,300.0,8.333333333333333e-05,0.67,0.28,0.23,0.05,0.9,0.05,0.03,0.02
31.31599132477064,0.0027008391379638,76.42978666234926,300.0,8.333333333333333e-05,0.67,0.28,0.23,0.05,0.9,0.05,0.03,0.02
32.01688492623464,0.0027592469380858,76.70689346603496,300.0,8.333333333333333e-05,0.67,0.28,0.23,0.05,0.9,0.05,0.03,0.02
32.71777852769864,0.0028176547382078,76.98400026972072,300.0,8.333333333333333e-05,0.67,0.28,0.23,0.05,0.9,0.05,0.03,0.02
33.40003793445764,0.00287450968877105,77.20913704938508,300.0,8.333333333333333e-05,0.67,0.28,0.23,0.05,0.9,0.05,0.03,0.02
34.08229734121664,0.0029313646393343,77.43427382904947,300.0,8.333333333333333e-05,0.67,0.28,0.23,0.05,0.9,0.05,0.03,0.02
34.727676229462034,0.00298514621335475,77.63081817204002,300.0,8.333333333333333e-05,0.67,0.28,0.23,0.05,0.9,0.05,0.03,0.02
35.37305511770744,0.0030389277873752,77.82736251503083,300.0,8.333333333333333e-05,0.67,0.28,0.23,0.05,0.9,0.05,0.03,0.02
36.00994242836864,0.0030920017299303,78.01265384701188,300.0,8.333333333333333e-05,0.67,0.28,0.23,0.05,0.9,0.05,0.03,0.02
36.64682973902984,0.0031450756724854,78.19794517899257,300.0,8.333333333333333e-05,0.67,0.28,0.23,0.05,0.9,0.05,0.03,0.02
37.33750267918004,0.00320263175083125,78.36702631769232,300.0,8.333333333333333e-05,0.67,0.28,0.23,0.05,0.9,0.05,0.03,0.02
38.02817561933024,0.0032601878291771,78.53610745639226,300.0,8.333333333333333e-05,0.67,0.28,0.23,0.05,0.9,0.05,0.03,0.02
38.79623458371704,0.003324192742876,78.68504860572881,300.0,8.333333333333333e-05,0.67,0.28,0.23,0.05,0.9,0.05,0.03,0.02
39.56429354810384,0.0033881976565749,78.83398975506516,300.0,8.333333333333333e-05,0.67,0.28,0.23,0.05,0.9,0.05,0.03,0.02
40.37678571102824,0.0034559053368186,78.96766069839991,300.0,8.333333333333333e-05,0.67,0.28,0.23,0.05,0.9,0.05,0.03,0.02
41.18927787395264,0.0035236130170623,79.10133164173455,300.0,8.333333333333333e-05,0.67,0.28,0.23,0.05,0.9,0.05,0.03,0.02
41.85792345412544,0.0035793334820767003,79.21378405596245,300.0,8.333333333333333e-05,0.67,0.28,0.23,0.05,0.9,0.05,0.03,0.02
42.52656903429824,0.0036350539470911,79.32623647019045,300.0,8.333333333333333e-05,0.67,0.28,0.23,0.05,0.9,0.05,0.03,0.02
43.358044374333446,0.0037043435587606997,79.4234605183204,300.0,8.333333333333333e-05,0.67,0.28,0.23,0.05,0.9,0.05,0.03,0.02
44.18951971436864,0.0037736331704303,79.52068456645065,300.0,8.333333333333333e-05,0.67,0.28,0.23,0.05,0.9,0.05,0.03,0.02
45.05196519476564,0.0038455036271300503,79.60105360997206,300.0,8.333333333333333e-05,0.67,0.28,0.23,0.05,0.9,0.05,0.03,0.02
45.91441067516264,0.0039173740838298,79.68142265349331,300.0,8.333333333333333e-05,0.67,0.28,0.23,0.05,0.9,0.05,0.03,0.02
46.67901147197084,0.00398109081689715,79.75671045724266,300.0,8.333333333333333e-05,0.67,0.28,0.23,0.05,0.9,0.05,0.03,0.02
47.44361226877904,0.0040448075499645,79.83199826099177,300.0,8.333333333333333e-05,0.67,0.28,0.23,0.05,0.9,0.05,0.03,0.02
48.39331789673684,0.00412394968562765,79.90107905739097,300.0,8.333333333333333e-05,0.67,0.28,0.23,0.05,0.9,0.05,0.03,0.02
49.34302352469464,0.0042030918212908,79.97015985379059,300.0,8.333333333333333e-05,0.67,0.28,0.23,0.05,0.9,0.05,0.03,0.02
50.30840964354344,0.0042835406645282004,80.03522897822374,300.0,8.333333333333333e-05,0.67,0.28,0.23,0.05,0.9,0.05,0.03,0.02
51.27379576239224,0.0043639895077656,80.10029810265671,300.0,8.333333333333333e-05,0.67,0.28,0.23,0.05,0.9,0.05,0.03,0.02
52.224873360650236,0.0044432459742871,80.1691712173755,300.0,8.333333333333333e-05,0.67,0.28,0.23,0.05,0.9,0.05,0.03,0.02
53.17595095890824,0.0045225024408086,80.23804433209416,300.0,8.333333333333333e-05,0.67,0.28,0.23,0.05,0.9,0.05,0.03,0.02
54.21086215397264,0.0046087450403973,80.29035122892917,300.0,8.333333333333333e-05,0.67,0.28,0.23,0.05,0.9,0.05,0.03,0.02
55.24577334903704,0.004694987639986,80.34265812576412,300.0,8.333333333333333e-05,0.67,0.28,0.23,0.05,0.9,0.05,0.03,0.02
56.227432379015234,0.00477679255915085,80.38182345448622,300.0,8.333333333333333e-05,0.67,0.28,0.23,0.05,0.9,0.05,0.03,0.02
57.20909140899343,0.0048585974783157,80.42098878320834,300.0,8.333333333333333e-05,0.67,0.28,0.23,0.05,0.9,0.05,0.03,0.02
58.190982085872434,0.00494042170138895,80.46027225701124,300.0,8.333333333333333e-05,0.67,0.28,0.23,0.05,0.9,0.05,0.03,0.02
59.17287276275144,0.0050222459244622,80.49955573081415,300.0,8.333333333333333e-05,0.67,0.28,0.23,0.05,0.9,0.05,0.03,0.02
60.33417276176144,0.0051190209243797,80.53357203355716,300.0,8.333333333333333e-05,0.67,0.28,0.23,0.05,0.9,0.05,0.03,0.02
61.49547276077144,0.0052157959242972,80.56758833630037,300.0,8.333333333333333e-05,0.67,0.28,0.23,0.05,0.9,0.05,0.03,0.02
62.488849199458045,0.00529857729418775,80.59246347433361,300.0,8.333333333333333e-05,0.67,0.28,0.23,0.05,0.9,0.05,0.03,0.02
63.48222563814465,0.0053813586640783,80.61733861236684,300.0,8.333333333333333e-05,0.67,0.28,0.23,0.05,0.9,0.05,0.03,0.02
64.37039094866445,0.00545537243995495,80.63874788057579,300.0,8.333333333333333e-05,0.67,0.28,0.23,0.05,0.9,0.05,0.03,0.02
65.25855625918425,0.0055293862158316,80.66015714878472,300.0,8.333333333333333e-05,0.67,0.28,0.23,0.05,0.9,0.05,0.03,0.02
66.26178990152805,0.00561298901936025,80.64903994064642,300.0,8.333333333333333e-05,0.67,0.28,0.23,0.05,0.9,0.05,0.03,0.02
67.26502354387185,0.0056965918228889,80.63792273250787,300.0,8.333333333333333e-05,0.67,0.28,0.23,0.05,0.9,0.05,0.03,0.02
68.24774340950265,0.0057784851450248,80.64735300181448,300.0,8.333333333333333e-05,0.67,0.28,0.23,0.05,0.9,0.05,0.03,0.02
69.23046327513345,0.0058603784671607,80.65678327112155,300.0,8.333333333333333e-05,0.67,0.28,0.23,0.05,0.9,0.05,0.03,0.02
70.25115379890285,0.00594543601080815,80.66768491435352,300.0,8.333333333333333e-05,0.67,0.28,0.23,0.05,0.9,0.05,0.03,0.02
71.27184432267225,0.0060304935544556,80.67858655758495,300.0,8.333333333333333e-05,0.67,0.28,0.23,0.05,0.9,0.05,0.03,0.02
72.36899401536044,0.0061219226955129494,80.6864520462748,300.0,8.333333333333333e-05,0.67,0.28,0.23,0.05,0.9,0.05,0.03,0.02
73.46614370804865,0.0062133518365703,80.69431753496497,300.0,8.333333333333333e-05,0.67,0.28,0.23,0.05,0.9,0.05,0.03,0.02
74.29442956244685,0.00628237565777015,80.70107334040057,300.0,8.333333333333333e-05,0.67,0.28,0.23,0.05,0.9,0.05,0.03,0.02
75.12271541684504,0.00635139947897,80.70782914583623,300.0,8.333333333333333e-05,0.67,0.28,0.23,0.05,0.9,0.05,0.03,0.02
76.21689178875283,0.00644258084329565,80.71672715434893,300.0,8.333333333333333e-05,0.67,0.28,0.23,0.05,0.9,0.05,0.03,0.02
77.31106816066064,0.0065337622076213,80.72562516286148,300.0,8.333333333333333e-05,0.67,0.28,0.23,0.05,0.9,0.05,0.03,0.02
78.41693847592063,0.0066259180672263,80.72517968112737,300.0,8.333333333333333e-05,0.67,0.28,0.23,0.05,0.9,0.05,0.03,0.02
79.52280879118064,0.0067180739268313,80.72473419939338,300.0,8.333333333333333e-05,0.67,0.28,0.23,0.05,0.9,0.05,0.03,0.02
80.57659093665524,0.00680588910562085,80.73178100871108,300.0,8.333333333333333e-05,0.67,0.28,0.23,0.05,0.9,0.05,0.03,0.02
81.63037308212985,0.0068937042844104,80.73882781802847,300.0,8.333333333333333e-05,0.67,0.28,0.23,0.05,0.9,0.05,0.03,0.02
82.68746369584485,0.00698179516888665,80.73708175500212,300.0,8.333333333333333e-05,0.67,0.28,0.23,0.05,0.9,0.05,0.03,0.02
83.74455430955985,0.0070698860533629,80.73533569197562,300.0,8.333333333333333e-05,0.67,0.28,0.23,0.05,0.9,0.05,0.03,0.02
84.79138228042125,0.0071571217176013505,80.73187132409657,300.0,8.333333333333333e-05,0.67,0.28,0.23,0.05,0.9,0.05,0.03,0.02
85.83821025128265,0.0072443573818398,80.72840695621791,300.0,8.333333333333333e-05,0.67,0.28,0.23,0.05,0.9,0.05,0.03,0.02
86.89175012062485,0.00733215237095165,80.72867557396341,300.0,8.333333333333333e-05,0.67,0.28,0.23,0.05,0.9,0.05,0.03,0.02
87.94528998996705,0.0074199473600635,80.72894419170865,300.0,8.333333333333333e-05,0.67,0.28,0.23,0.05,0.9,0.05,0.03,0.02
89.18695468097265,0.0075234194176473,80.72706509129765,300.0,8.333333333333333e-05,0.67,0.28,0.23,0.05,0.9,0.05,0.03,0.02
90.42861937197824,0.0076268914752311,80.72518599088723,300.0,8.333333333333333e-05,0.67,0.28,0.23,0.05,0.9,0.05,0.03,0.02
91.47222024158205,0.00771385821436475,80.72353908803562,300.0,8.333333333333333e-05,0.67,0.28,0.23,0.05,0.9,0.05,0.03,0.02
92.51582111118584,0.0078008249534984,80.72189218518338,300.0,8.333333333333333e-05,0.67,0.28,0.23,0.05,0.9,0.05,0.03,0.02
93.67395713727166,0.00789733628900555,80.72678797047568,300.0,8.333333333333333e-05,0.67,0.28,0.23,0.05,0.9,0.05,0.03,0.02
94.83209316335746,0.0079938476245127,80.7316837557679,300.0,8.333333333333333e-05,0.67,0.28,0.23,0.05,0.9,0.05,0.03,0.02
95.95148693445344,0.0080871304387707,80.7392794505858,300.0,8.333333333333333e-05,0.67,0.28,0.23,0.05,0.9,0.05,0.03,0.02
97.07088070554944,0.0081804132530287,80.74687514540435,300.0,8.333333333333333e-05,0.67,0.28,0.23,0.05,0.9,0.05,0.03,0.02
98.19137914335944,0.0082737881228462,80.74569989310044,300.0,8.333333333333333e-05,0.67,0.28,0.23,0.05,0.9,0.05,0.03,0.02
99.31187758116944,0.0083671629926637,80.74452464079621,300.0,8.333333333333333e-05,0.67,0.28,0.23,0.05,0.9,0.05,0.03,0.02
100.45081236952004,0.008462074225026251,80.75201195715097,300.0,8.333333333333333e-05,0.67,0.28,0.23,0.05,0.9,0.05,0.03,0.02
101.58974715787063,0.0085569854573888,80.7594992735058,300.0,8.333333333333333e-05,0.67,0.28,0.23,0.05,0.9,0.05,0.03,0.02