File: datasets/am_bench_2022/raw_data/45-XY.02-2/specimen.dat
MTS793|MPT|ENU|1|2|.|/|:|1|0|0|A

Operator Information						Time:	34.750244	Sec	10/19/2021 10:42:00 AM
Operator	Newell Moser
Project	AM Bench 2022 mini-tensile challenge
Specimen ID	45-XY.02-2
Material	PBF-L Inconel 625
Specimen Width	2.54	mm
Specimen Thickness	1.51	mm
Notes
Operator Information End

Data Acquisition						Time:	1035.7441	Sec	10/19/2021 10:58:41 AM
Time	Axial Displacement	Axial Extensometer	Axial Force
Sec	mm	mm	N
34.864014	-0.0014385014	-0.00011286815	45.533527
35.86499	0.0016352216	-9.798487e-05	52.7285
36.865967	0.0045147082	4.3448526e-06	65.391876
37.866943	0.0082174977	6.9340364e-05	79.722794
38.86792	0.010272503	0.00016913661	91.850006
39.868896	0.011556964	0.00020916821	107.27151
40.869873	0.017260002	0.00025123131	123.08573
41.87085	0.020154087	0.00037509095	132.8002
42.871826	0.025542257	0.00033131498	150.06171
43.872803	0.025950195	0.00047311388	165.56728
44.873779	0.028109286	0.00054925034	182.65468
45.874756	0.031058025	0.00062820199	199.53702
46.875732	0.032270979	0.00063852849	221.27737
47.876709	0.035902057	0.00075638795	242.01291
48.877686	0.041044515	0.00088102312	263.97614
49.878662	0.042670324	0.00089607749	280.85745
50.879639	0.043795329	0.001010844	299.12994
51.880615	0.047386043	0.0011410061	324.91278
52.881592	0.049248092	0.0012840467	352.13846
53.882568	0.055920467	0.0013696614	371.56464
54.883545	0.05601861	0.0014590831	389.25064
55.884521	0.06134798	0.001558367	411.30225
56.885498	0.061622329	0.0016115732	442.20428
57.886475	0.06766405	0.0016969666	467.28949
58.887451	0.069999963	0.0019092561	492.87357
59.888428	0.071431123	0.0019489025	513.40442
60.889404	0.074442819	0.0020603365	536.99396
61.890381	0.077362664	0.0021754678	559.90814
62.891357	0.084213912	0.0023077393	591.54071
63.892334	0.087013133	0.0023865763	615.51154
64.893311	0.085886233	0.0025053916	640.63666
65.894287	0.090649076	0.0026243667	664.07306
66.895264	0.093477137	0.0026709454	690.729
67.89624	0.095754296	0.0027660262	719.69379
68.897217	0.097469382	0.0029075874	742.00269
69.898193	0.10122565	0.0030087789	760.68732
70.89917	0.10638496	0.0031327687	793.9845
71.900146	0.11054046	0.0032235465	817.23761
72.901123	0.10727803	0.0033935753	835.784
73.9021	0.11373901	0.0035171646	872.48584
74.903076	0.11677221	0.003573017	889.72949
75.904053	0.12228306	0.0037639937	929.53827
76.905029	0.11950234	0.0039297403	948.28326
77.906006	0.12924111	0.0040537268	979.19275
78.906982	0.12718114	0.0040894025	999.10919
79.907959	0.1313877	0.0042572133	1027.1017
80.908936	0.13505663	0.0043701041	1063.0087
81.909912	0.13533118	0.0045041335	1083.458
82.910889	0.13924332	0.0046146838	1115.5907
83.911865	0.14126354	0.0047616991	1141.8053
84.912842	0.14576249	0.0048530344	1170.6683
85.913818	0.1487852	0.0049745417	1201.8962
86.914795	0.15300426	0.0051459516	1235.5146
87.915771	0.15710433	0.0052554267	1255.1743
88.916748	0.15556437	0.0053869537	1280.7634
89.917725	0.16361219	0.0055080019	1316.79
90.918701	0.16350052	0.0056353109	1347.0209
91.919678	0.16763414	0.0057831798	1370.3846
92.920654	0.16876453	0.0058112368	1389.8523
93.921631	0.17307661	0.0060225469	1423.0536
94.922607	0.17583747	0.0061736642	1456.7325
95.923584	0.17925642	0.006187154	1474.2831
96.924561	0.18402301	0.0063743526	1506.6975
97.925537	0.18750523	0.0064760107	1535.8517
98.926514	0.1876841	0.0066391467	1560.8524
99.92749	0.19279507	0.0066461335	1583.0913
100.92847	0.19280387	0.0068211821	1610.486
101.92944	0.19643106	0.0070048813	1647.1235
102.93042	0.20036122	0.0071060634	1671.0195
103.9314	0.20132416	0.0072715152	1694.2307
104.93237	0.20768659	0.0073583466	1730.1627
105.93335	0.21279529	0.0074814721	1754.792
106.93433	0.211082	0.0075386856	1767.5315
107.9353	0.21628556	0.0075917114	1794.9226
108.93628	0.21968587	0.0077523347	1817.1134
109.93726	0.2210945	0.0078209359	1840.1787
110.93823	0.22408201	0.0079502119	1863.8497
111.93921	0.22880793	0.0080494564	1891.7758
112.94019	0.23189272	0.0081380913	1906.3938
113.94116	0.23184682	0.0083134389	1931.6599
114.94214	0.23474623	0.008365145	1951.4668
115.94312	0.23947383	0.0084598325	1975.6575
116.94409	0.24077919	0.0085491017	1995.089
117.94507	0.24600013	0.0086781979	2021.5482
118.94604	0.25254306	0.0087290928	2038.3053
119.94702	0.24793778	0.0088231973	2052.5002
120.948	0.25352368	0.0089508472	2074.8733
121.94897	0.25454852	0.0090673929	2100.1387
122.94995	0.26049128	0.0091531379	2117.6804
123.95093	0.26663899	0.009370029	2144.5771
124.9519	0.26672629	0.0093877604	2161.4736
125.95288	0.27262539	0.0093604485	2177.1418
126.95386	0.27067181	0.0094325775	2188.2646
127.95483	0.27607718	0.0095787859	2208.4902
128.95581	0.27894315	0.0096212346	2221.7734
129.95679	0.2811234	0.0095574036	2231.0752
130.95776	0.28471899	0.0098538166	2255.345
131.95874	0.28852293	0.009879645	2268.8997
132.95972	0.29200277	0.0098776938	2275.55
133.96069	0.29261968	0.009939624	2289.1099
134.96167	0.29846388	0.010095282	2307.5134
135.96265	0.29765871	0.010230483	2325.1914
136.96362	0.30491856	0.010244539	2331.8086
137.9646	0.30528855	0.01031891	2345.8374
138.96558	0.3064841	0.010474673	2350.2695
139.96655	0.31151268	0.010479145	2364.7915
140.96753	0.31510743	0.010575004	2379.968
141.96851	0.31900606	0.010710422	2401.1592
142.96948	0.32133669	0.010800927	2411.5752
143.97046	0.32544157	0.010851488	2423.2942
144.97144	0.32659531	0.010969959	2425.1553
145.97241	0.32841599	0.011030218	2430.0615
146.97339	0.33540431	0.011169082	2452.019
147.97437	0.3341451	0.011293741	2459.7922
148.97534	0.33814493	0.011411155	2473.8701
149.97632	0.3429381	0.011512733	2484.3196
150.97729	0.34494498	0.011548942	2488.4495
151.97827	0.34681538	0.011646735	2498.2944
152.97925	0.35057631	0.011839576	2510.3564
153.98022	0.35499701	0.011921147	2520.8799
154.9812	0.35835537	0.012017682	2527.1936
155.98218	0.35888168	0.012061482	2533.0432
156.98315	0.36670309	0.012274333	2554.436
157.98413	0.36556962	0.012263257	2552.447
158.98511	0.37014711	0.012480677	2563.5957
159.98608	0.37379634	0.012631102	2581.6467
160.98706	0.37778881	0.012759613	2589.0361
161.98804	0.37946025	0.012962842	2597.7012
162.98901	0.38118032	0.013048234	2606.2039
163.98999	0.38516462	0.013267769	2616.6616
164.99097	0.38555551	0.013408351	2620.5374
165.99194	0.38938078	0.013632459	2629.6387
166.99292	0.39514717	0.013726204	2642.4229
167.9939	0.39394897	0.013972852	2653.5271
168.99487	0.39860225	0.014234938	2659.1924
169.99585	0.40065193	0.014427967	2661.8362
170.99683	0.40579972	0.014654689	2669.6792
171.9978	0.40632054	0.014761509	2673.6707
172.99878	0.40832704	0.015116718	2687.0354
173.99976	0.41461959	0.015338013	2694.832
175.00073	0.41599804	0.01554506	2698.1587
176.00171	0.4197928	0.015912127	2709.4238
177.00269	0.4259952	0.016163783	2719.7781
178.00366	0.4268955	0.016532615	2724.1909
179.00464	0.43194333	0.016958464	2732.1194
180.00562	0.43448412	0.017142536	2739.0896
181.00659	0.43364182	0.017520294	2735.7446
182.00757	0.43822381	0.017902218	2746.3687
183.00854	0.44077507	0.018292805	2751.0317
184.00952	0.44431224	0.01882639	2766.4817
185.0105	0.44893208	0.019079946	2769.4446
186.01147	0.45302922	0.019643059	2770.822
187.01245	0.45331097	0.020008314	2781.1379
188.01343	0.45635885	0.020525198	2780.0264
189.0144	0.45836043	0.021041648	2788.4949
190.01538	0.46360049	0.021575924	2793.885
191.01636	0.4667531	0.022322591	2807.8438
192.01733	0.46815598	0.023080532	2810.1345
193.01831	0.47164336	0.023607185	2806.6038
194.01929	0.47776997	0.024295514	2816.9702
195.02026	0.47743765	0.024916282	2822.1084
196.02124	0.48074123	0.025619157	2821.9673
197.02222	0.48307019	0.026397763	2823.6738
198.02319	0.48822418	0.027067551	2831.6604
199.02417	0.48883843	0.027974514	2841.6633
200.02515	0.49413195	0.028853569	2844.0359
201.02612	0.49681926	0.029671796	2849.5527
202.0271	0.49901772	0.030243225	2850.9448
203.02808	0.50088835	0.031141661	2851.6782
204.02905	0.50437474	0.032161564	2858.6785
205.03003	0.508753	0.032921594	2859.698
206.03101	0.51186728	0.03377144	2873.1653
207.03198	0.51451176	0.03476084	2875.3323
208.03296	0.51994157	0.035747152	2877.6943
209.03394	0.51985162	0.036712125	2875.7834
210.03491	0.52395165	0.037622407	2880.0532
211.03589	0.52633756	0.038566276	2879.8176
212.03687	0.52959794	0.039425217	2886.4919
213.03784	0.53156775	0.040412705	2886.5676
214.03882	0.53612041	0.041506868	2892.4902
215.03979	0.54026014	0.042377684	2892.7117
216.04077	0.54117376	0.043268584	2893.0818
217.04175	0.5446198	0.044197243	2902.0649
218.04272	0.54841393	0.045438036	2911.3206
219.0437	0.54953283	0.046551403	2904.8132
220.04468	0.55242378	0.047709383	2908.4526
221.04565	0.55708748	0.048939962	2912.864
222.04663	0.56097215	0.050297242	2918.5391
223.04761	0.55866551	0.05140667	2906.9482
224.04858	0.56239861	0.052571177	2915.3501
225.04956	0.56914699	0.053671662	2920.2231
226.05054	0.57026446	0.054782461	2921.2546
227.05151	0.57410222	0.055708352	2919.7798
228.05249	0.57776767	0.056778811	2923.2705
229.05347	0.58044821	0.057606053	2919.8474
230.05444	0.5851478	0.058770325	2933.9463
231.05542	0.58749765	0.060123876	2941.1897
232.0564	0.58818382	0.061326373	2933.7598
233.05737	0.59383237	0.062397853	2939.4307
234.05835	0.59802443	0.063604906	2938.8213
235.05933	0.5989694	0.064585097	2942.7629
236.0603	0.60289502	0.065522037	2942.9612
237.06128	0.60482115	0.066531129	2942.5762
238.06226	0.60812664	0.067702115	2950.2249
239.06323	0.61123973	0.068822391	2952.3777
240.06421	0.61075228	0.070172317	2954.2368
241.06519	0.61642587	0.07151933	2960.4744
242.06616	0.6206736	0.072637536	2957.0242
243.06714	0.62081045	0.073855177	2957.1702
244.06812	0.62500644	0.07517869	2962.6484
245.06909	0.63030624	0.076383412	2964.002
246.07007	0.63158762	0.077633433	2965.5496
247.07104	0.63512313	0.078660876	2960.1853
248.07202	0.6358425	0.079605475	2962.282
249.073	0.64115548	0.080706432	2969.6519
250.07397	0.64114237	0.081753224	2969.7439
251.07495	0.64872754	0.082830794	2975.925
252.07593	0.64979219	0.083944149	2977.8789
253.0769	0.65241027	0.085095882	2985.1995
254.07788	0.65712494	0.08661925	2978.4082
255.07886	0.65684795	0.087911367	2980.5886
256.07983	0.66205823	0.088990949	2987.1567
257.08081	0.66622508	0.090233617	2986.0503
258.08179	0.66681886	0.091255628	2988.8977
259.08276	0.67037326	0.092375316	2988.3293
260.08374	0.6709885	0.093654528	2984.3379
261.08472	0.67885053	0.094693877	2997.2026
262.08569	0.67719913	0.095863745	2993.2515
263.08667	0.68497807	0.097026452	3001.9175
264.08765	0.68515879	0.098392218	3001.0447
265.08862	0.68768281	0.099447981	3000.6584
266.0896	0.69283539	0.1007553	3010.845
267.09058	0.69253892	0.1022289	3005.7324
268.09155	0.69821185	0.10332314	3005.5942
269.09253	0.69920969	0.10444963	3005.7158
270.09351	0.70476383	0.10554616	3002.8894
271.09448	0.70585239	0.10651988	3007.3049
272.09546	0.71095103	0.10767179	3010.7581
273.09644	0.71288866	0.10885913	3015.0017
274.09741	0.71521986	0.11007378	3016.1833
275.09839	0.71835983	0.11131264	3017.9319
276.09937	0.72239321	0.11256219	3020.8059
277.10034	0.72391003	0.11379348	3020.5798
278.10132	0.72535676	0.11504635	3018.6599
279.10229	0.72956514	0.11625436	3027.7583
280.10327	0.73203611	0.11728504	3027.5522
281.10425	0.73459888	0.11847128	3019.9353
282.10522	0.73868883	0.11967928	3027.2576
283.1062	0.74361807	0.12094973	3037.4255
284.10718	0.74490678	0.12202827	3030.2258
285.10815	0.74896955	0.12308215	3033.3196
286.10913	0.75130528	0.12437839	3038.876
287.11011	0.75346071	0.12550694	3042.2727
288.11108	0.75850588	0.12683903	3042.0962
289.11206	0.76092178	0.12811843	3044.5217
290.11304	0.76328468	0.12918633	3031.8613
291.11401	0.7662617	0.13020791	3043.3914
292.11499	0.76763451	0.13148795	3042.1333
293.11597	0.77114093	0.13261132	3038.7939
294.11694	0.77657503	0.1337525	3047.8435
295.11792	0.777713	0.13497761	3048.7805
296.1189	0.78402597	0.13604136	3052.615
297.11987	0.78282142	0.13721171	3049.3608
298.12085	0.78693849	0.1384951	3054.3181
299.12183	0.78878391	0.13963944	3052.6602
300.1228	0.79075885	0.14082807	3055.0305
301.12378	0.79820901	0.14219187	3063.3699
302.12476	0.79890501	0.14334723	3056.6311
303.12573	0.80313408	0.14453188	3070.4802
304.12671	0.80542207	0.14563927	3063.5247
305.12769	0.80587488	0.1468361	3063.5195
306.12866	0.81287372	0.14798605	3065.4648
307.12964	0.81530815	0.14919691	3071.1677
308.13062	0.81877345	0.15044276	3069.4412
309.13159	0.82052362	0.15181349	3075.4978
310.13257	0.82343936	0.15291707	3076.9497
311.13354	0.82487792	0.15438432	3076.749
312.13452	0.82971162	0.15558028	3078.635
313.1355	0.83073753	0.15655752	3070.9985
314.13647	0.83769369	0.15768223	3080.7778
315.13745	0.83654791	0.15886623	3080.9622
316.13843	0.84067774	0.16025077	3085.1558
317.1394	0.84507054	0.16145319	3078.009
318.14038	0.8447302	0.1624289	3078.7979
319.14136	0.85084754	0.16364929	3089.7725
320.14233	0.85169148	0.16466643	3083.6077
321.14331	0.85834342	0.16593207	3093.7175
322.14429	0.85993969	0.16688009	3090.7673
323.14526	0.8643052	0.16807067	3095.563
324.14624	0.86428046	0.16905911	3094.9351
325.14722	0.8693828	0.17031772	3092.9358
326.14819	0.87061727	0.17147607	3097.8547
327.14917	0.87402701	0.17273206	3095.3125
328.15015	0.87659711	0.17384768	3097.1526
329.15112	0.88045502	0.17518324	3105.2119
330.1521	0.88583183	0.17644989	3103.2903
331.15308	0.88714337	0.17752013	3103.4023
332.15405	0.89010972	0.17876998	3101.4761
333.15503	0.89192259	0.1800396	3105.1077
334.15601	0.89728594	0.18134826	3111.7615
335.15698	0.89812189	0.18255042	3114.9011
336.15796	0.89990997	0.18369402	3109.469
337.15894	0.903148	0.18481913	3113.9995
338.15991	0.90739274	0.18581389	3111.5845
339.16089	0.91472036	0.1868697	3118.4895
340.16187	0.91375488	0.18813452	3126.6912
341.16284	0.91876811	0.18918732	3118.8254
342.16382	0.91809422	0.19033605	3124.4646
343.16479	0.92227936	0.19151224	3115.2793
344.16577	0.92686015	0.19281685	3127.0181
345.16675	0.92858702	0.19403288	3127.7725
346.16772	0.92811799	0.19523408	3125.25
347.1687	0.93438333	0.19634753	3122.9827
348.16968	0.93938833	0.19740981	3128.7419
349.17065	0.94262147	0.19859524	3132.6353
350.17163	0.94375449	0.19962926	3131.1797
351.17261	0.9475835	0.20073308	3134.9436
352.17358	0.94949734	0.20202745	3138.8601
353.17456	0.95520306	0.20326325	3139.7188
354.17554	0.95580357	0.20444128	3133.8699
355.17651	0.95634323	0.20560326	3135.9077
356.17749	0.96217054	0.20659067	3139.4009
357.17847	0.96376061	0.20793383	3147.1238
358.17944	0.96881527	0.20906422	3142.9404
359.18042	0.96756768	0.21019225	3141.6716
360.1814	0.97194839	0.21126503	3141.207
361.18237	0.97531247	0.21254736	3146.866
362.18335	0.98113376	0.21368864	3148.3999
363.18433	0.97864723	0.21480584	3144.1653
364.1853	0.98719662	0.21609661	3150.718
365.18628	0.98828828	0.21688761	3146.9805
366.18726	0.99028713	0.2180559	3155.2688
367.18823	0.99302346	0.21935096	3152.1528
368.18921	0.99865174	0.22040594	3158.8679
369.19019	0.99990624	0.22163193	3150.405
370.19116	1.0033883	0.22268693	3157.2473
371.19214	1.0052985	0.22402081	3158.384
372.19312	1.0088863	0.2252586	3163.9998
373.19409	1.0134056	0.22649564	3158.4668
374.19507	1.0134715	0.22768809	3163.5642
375.19604	1.0199031	0.22883873	3166.5583
376.19702	1.0212407	0.22995442	3165.0737
377.198	1.0240949	0.23095194	3164.271
378.19897	1.0277478	0.23213106	3173.3767
379.19995	1.03014	0.23327549	3173.6216
380.20093	1.0323066	0.23437041	3168.165
381.2019	1.0382786	0.2355869	3173.0486
382.20288	1.0381153	0.23676518	3174.1018
383.20386	1.0413136	0.23794086	3177.1416
384.20483	1.0464181	0.23931935	3178.46
385.20581	1.0458208	0.24047346	3182.5134
386.20679	1.0511106	0.24174458	3179.3296
387.20776	1.0561113	0.24284032	3174.2087
388.20874	1.0561866	0.24385786	3178.4587
389.20972	1.0630642	0.2451617	3189.8574
390.21069	1.0636278	0.24636869	3187.5435
391.21167	1.0690005	0.24753371	3191.313
392.21265	1.0709444	0.24877517	3186.8616
393.21362	1.0728583	0.24985063	3191.8828
394.2146	1.0767823	0.25104186	3187.7571
395.21558	1.0765244	0.25198185	3184.8618
396.21655	1.0833097	0.25301635	3190.2185
397.21753	1.0851768	0.25411314	3197.8372
398.21851	1.0872115	0.25534266	3191.4128
399.21948	1.0923127	0.25674221	3203.3655
400.22046	1.0946558	0.25786242	3196.9258
401.22144	1.0993932	0.25894973	3197.7253
402.22241	1.0991262	0.2598545	3195.175
403.22339	1.1031017	0.26090834	3197.9187
404.22437	1.1090617	0.2620298	3210.2654
405.22534	1.1095794	0.26309606	3203.2185
406.22632	1.1118294	0.26411667	3207.4641
407.22729	1.1142409	0.26519936	3208.053
408.22827	1.1176071	0.26665413	3211.3467
409.22925	1.1208488	0.26811406	3215.3181
410.23022	1.1235969	0.26912868	3208.3228
411.2312	1.124808	0.27040815	3209.8391
412.23218	1.1281093	0.27166954	3213.9507
413.23315	1.1349441	0.27284461	3219.9026
414.23413	1.1341211	0.27412677	3219.3982
415.23511	1.1379491	0.27522162	3220.7705
416.23608	1.1427128	0.27648374	3218.0344
417.23706	1.1465465	0.27755365	3218.4304
418.23804	1.150416	0.2787233	3228.1523
419.23901	1.1526747	0.27986997	3221.7979
420.23999	1.1545527	0.28086272	3218.3457
421.24097	1.1555227	0.28179047	3224.1416
422.24194	1.1589084	0.28298169	3228.8035
423.24292	1.164062	0.28426951	3233.6558
424.2439	1.1652741	0.28541061	3225.5718
425.24487	1.1712757	0.28652024	3227.2771
426.24585	1.1718373	0.28759825	3226.8892
427.24683	1.1748328	0.28885749	3241.23
428.2478	1.1781696	0.28995138	3233.0784
429.24878	1.1817498	0.29089844	3230.5869
430.24976	1.1840175	0.29203486	3233.6042
431.25073	1.1869529	0.29309157	3238.3945
432.25171	1.1930782	0.29432419	3243.4785
433.25269	1.1935248	0.29545522	3237.833
434.25366	1.1961355	0.29673529	3248.4915
435.25464	1.1994301	0.29803121	3244.7063
436.25562	1.2014157	0.29906851	3243.5715
437.25659	1.2044833	0.30031648	3242.7925
438.25757	1.2073234	0.30150515	3249.1448
439.25854	1.2124274	0.30283406	3247.3132
440.25952	1.2099128	0.30392596	3244.5435
441.2605	1.2161261	0.30492771	3246.3352
442.26147	1.219627	0.30602467	3250.1433
443.26245	1.2257664	0.30719066	3248.1746
444.26343	1.2261305	0.30818227	3253.0376
445.2644	1.2271395	0.3095133	3252.3843
446.26538	1.2333095	0.31073472	3257.3997
447.26636	1.2357707	0.31191897	3258.7771
448.26733	1.2371556	0.31285584	3253.6929
449.26831	1.2388246	0.31391099	3251.9648
450.26929	1.243811	0.31513304	3262.0017
451.27026	1.2482376	0.31623074	3257.3469
452.27124	1.2504224	0.31742233	3267.4138
453.27222	1.2519028	0.31874466	3265.9211
454.27319	1.2564029	0.31992769	3260.939
455.27417	1.2565733	0.32081896	3255.4241
456.27515	1.2603043	0.32200092	3267.272
457.27612	1.2666788	0.32328156	3270.8694
458.2771	1.2657613	0.32433528	3264.4565
459.27808	1.2715132	0.3254638	3266.5728
460.27905	1.2752913	0.32663199	3275.123
461.28003	1.2798115	0.32790589	3275.5259
462.28101	1.2814506	0.32887203	3264.5801
463.28198	1.2789154	0.32987618	3270.9807
464.28296	1.2838725	0.33095533	3266.8672
465.28394	1.2879165	0.33182892	3268.291
466.28491	1.2896718	0.33304164	3275.8572
467.28589	1.2970153	0.33396181	3278.522
468.28687	1.2971745	0.33501536	3278.3633
469.28784	1.3020184	0.33607331	3281.7507
470.28882	1.3032311	0.33736271	3278.8132
471.28979	1.3067936	0.33859891	3286.3828
472.29077	1.3111473	0.33986792	3291.5366
473.29175	1.3163836	0.34113491	3291.8813
474.29272	1.3179059	0.34249276	3287.5898
475.2937	1.3162935	0.3437613	3287.6521
476.29468	1.3213	0.34475568	3289.0806
477.29565	1.3262115	0.34602669	3296.8777
478.29663	1.3264657	0.34738576	3294.7131
479.29761	1.3286632	0.34855542	3291.2549
480.29858	1.3328359	0.34982336	3298.8928
481.29956	1.3382155	0.35087058	3296.0562
482.30054	1.3412901	0.35199347	3293.3308
483.30151	1.3424149	0.35311267	3295.7402
484.30249	1.3471228	0.35428354	3298.5527
485.30347	1.3497448	0.35539156	3299.4648
486.30444	1.3519068	0.35638335	3299.1763
487.30542	1.3570316	0.35755128	3298.2886
488.3064	1.3594909	0.3586306	3311.8245
489.30737	1.3591222	0.35980645	3310.2825
490.30835	1.3618697	0.36116353	3303.8406
491.30933	1.3680654	0.36221707	3306.1782
492.3103	1.3714409	0.36326984	3309.0276
493.31128	1.3731576	0.36445224	3305.2385
494.31226	1.3766218	0.36548969	3310.0066
495.31323	1.3761877	0.36664078	3309.3704
496.31421	1.3847295	0.3678264	3314.8071
497.31519	1.3850299	0.36904564	3309.0139
498.31616	1.3879385	0.37022021	3313.6501
499.31714	1.3884908	0.37137583	3310.5957
500.31812	1.3973924	0.37248239	3317.5193
501.31909	1.3991705	0.37362254	3315.8865
502.32007	1.40238	0.37455636	3322.281
503.32104	1.4022098	0.37557346	3314.9724
504.32202	1.4051772	0.3765727	3318.1179
505.323	1.4079317	0.37764713	3316.4551
506.32397	1.4110827	0.37883222	3325.7998
507.32495	1.4147748	0.3800579	3317.6021
508.32593	1.4181585	0.38126168	3325.4297
509.3269	1.4242249	0.38245904	3323.4109
510.32788	1.4247828	0.38358182	3329.7778
511.32886	1.4283503	0.38488001	3335.5225
512.32983	1.4311897	0.38609672	3330.5466
513.33081	1.4343271	0.38719964	3327.7261
514.33179	1.4355353	0.38840339	3330.8027
515.33276	1.4384495	0.3893525	3323.6843
516.33374	1.4412228	0.39040095	3328.98
517.33472	1.4449281	0.39189887	3342.0813
518.33569	1.4460242	0.39303795	3338.6597
519.33667	1.4531715	0.39430043	3334.9792
520.33765	1.4537394	0.39549792	3334.3103
521.33862	1.4566694	0.39672366	3342.9514
522.3396	1.460045	0.3980419	3344.323
523.34058	1.4621321	0.39929834	3339.821
524.34155	1.4674504	0.40020451	3339.0449
525.34253	1.4662462	0.40148741	3345.0989
526.34351	1.4711728	0.40264592	3343.7969
527.34448	1.4759126	0.40392396	3347.927
528.34546	1.4756138	0.40508178	3342.6648
529.34644	1.4843867	0.40635195	3352.3645
530.34741	1.4819194	0.40751782	3349.844
531.34839	1.4879653	0.40880403	3350.5664
532.34937	1.48873	0.40985304	3344.748
533.35034	1.4948878	0.41089973	3351.9292
534.35132	1.4978178	0.41200024	3357.5115
535.35229	1.5001339	0.4132013	3353.9182
536.35327	1.5017838	0.4141157	3344.2805
537.35425	1.5085367	0.41522953	3357.48
538.35522	1.5104012	0.41632733	3363.4102
539.3562	1.5127296	0.41737309	3359.0327
540.35718	1.5147073	0.4182981	3358.0605
541.35815	1.5178368	0.41963258	3359.9788
542.35913	1.5197345	0.42071873	3353.002
543.36011	1.5223544	0.42178357	3357.54
544.36108	1.5271957	0.42278737	3355.8286
545.36206	1.5267217	0.42385685	3360.115
546.36304	1.5322034	0.42503154	3360.3699
547.36401	1.5366312	0.42625585	3364.2349
548.36499	1.5375506	0.42737445	3363.458
549.36597	1.5407934	0.42871371	3366.7566
550.36694	1.5468421	0.42983419	3369.8235
551.36792	1.5462985	0.4310357	3373.2048
552.3689	1.5494137	0.43226647	3369.5945
553.36987	1.5542748	0.43353677	3368.4172
554.37085	1.5583489	0.43500316	3370.196
555.37183	1.5596948	0.43610716	3376.4312
556.3728	1.5618277	0.43738651	3374.7141
557.37378	1.5669249	0.43853292	3372.3289
558.37476	1.5662203	0.43975326	3376.7063
559.37573	1.5720227	0.44101107	3382.0186
560.37671	1.5729017	0.44202408	3372.7305
561.37769	1.5784926	0.44307393	3377.2544
562.37866	1.5808284	0.4443399	3379.908
563.37964	1.584635	0.44556639	3381.3496
564.38062	1.5863796	0.44666362	3377.4604
565.38159	1.5885333	0.44777903	3383.6255
566.38257	1.5904756	0.44881594	3379.1104
567.38354	1.5934209	0.44981778	3381.0784
568.38452	1.5966165	0.4511995	3391.6487
569.3855	1.6041355	0.4522748	3390.5745
570.38647	1.6043639	0.45335659	3386.7249
571.38745	1.608096	0.45445195	3388.5256
572.38843	1.6101872	0.45539239	3392.9346
573.3894	1.6129085	0.45645985	3384.8286
574.39038	1.6192855	0.45737365	3395.1855
575.39136	1.6192174	0.45868397	3397.3206
576.39233	1.621348	0.45975116	3395.134
577.39331	1.629361	0.46084109	3394.1499
578.39429	1.6271142	0.46201983	3392.1702
579.39526	1.6323996	0.46340272	3398.1011
580.39624	1.6342965	0.46454269	3396.9373
581.39722	1.6373596	0.46592879	3406.1465
582.39819	1.6414545	0.46722102	3397.2803
583.39917	1.6471115	0.46831539	3401.1804
584.40015	1.6476876	0.46961066	3404.9438
585.40112	1.6506264	0.47059557	3404.4971
586.4021	1.6532731	0.47179943	3405.0566
587.40308	1.6559582	0.47284815	3402.7288
588.40405	1.6592911	0.4738327	3393.9729
589.40503	1.6570191	0.47499231	3408.0293
590.40601	1.6629994	0.47632718	3405.8696
591.40698	1.6708663	0.4775826	3415.426
592.40796	1.6692057	0.47873092	3408.939
593.40894	1.6745908	0.48001283	3417.5764
594.40991	1.6756824	0.48104846	3409.6267
595.41089	1.6797005	0.48209539	3405.6279
596.41187	1.6801916	0.48327425	3411.938
597.41284	1.6848065	0.48456812	3414.8669
598.41382	1.6884166	0.48602897	3413.426
599.41479	1.6923001	0.48716977	3415.9631
600.41577	1.6925036	0.48849949	3416.4548
601.41675	1.6969695	0.48977137	3417.615
602.41772	1.7001095	0.49135363	3419.5762
603.4187	1.7030492	0.49268082	3421.1733
604.41968	1.7066917	0.49374279	3414.3086
605.42065	1.710766	0.49467689	3420.2507
606.42163	1.7105702	0.49572724	3419.3955
607.42261	1.715423	0.49664405	3411.0022
608.42358	1.7180724	0.49770629	3420.3167
609.42456	1.7218764	0.49874446	3419.197
610.42554	1.7244797	0.49991751	3427.0376
611.42651	1.7286015	0.50084466	3423.5737
612.42749	1.7284929	0.50218636	3429.2271
613.42847	1.7322258	0.50346363	3430.9792
614.42944	1.7370939	0.50462955	3423.7454
615.43042	1.7389463	0.50572276	3432.6646
616.4314	1.7421112	0.50690901	3434.2166
617.43237	1.7472222	0.50813854	3434.2573
618.43335	1.7480612	0.50927866	3433.3745
619.43433	1.7509693	0.51036251	3432.9238
620.4353	1.7551448	0.51158857	3434.5979
621.43628	1.7556475	0.51264679	3428.8501
622.43726	1.7590923	0.51378953	3436.467
623.43823	1.7599951	0.51486456	3432.4724
624.43921	1.7639296	0.51615196	3436.7317
625.44019	1.7698848	0.51752937	3439.9321
626.44116	1.7722013	0.51884371	3437.3589
627.44214	1.774855	0.51999986	3437.7107
628.44312	1.7812268	0.52102131	3438.4619
629.44409	1.7793776	0.52234375	3444.6575
630.44507	1.7862099	0.523678	3441.8171
631.44604	1.787825	0.5247224	3436.2039
632.44702	1.7920405	0.52582854	3442.0034
633.448	1.7937853	0.52697992	3443.8879
634.44897	1.7950749	0.52834219	3448.78
635.44995	1.7958217	0.5294019	3438.8062
636.45093	1.7992944	0.53073412	3441.6909
637.4519	1.8056791	0.53203517	3447.5713
638.45288	1.8107479	0.53316146	3448.429
639.45386	1.8101689	0.53446329	3454.4993
640.45483	1.8144463	0.53573138	3449.6326
641.45581	1.8187058	0.53695685	3448.2451
642.45679	1.8197519	0.53807062	3452.0916
643.45776	1.8223094	0.53928113	3446.0278
644.45874	1.8258319	0.54035127	3450.4954
645.45972	1.8321128	0.54122287	3447.4087
646.46069	1.8328493	0.54249811	3456.2834
647.46167	1.8360128	0.54362327	3453.3191
648.46265	1.8394992	0.54475588	3457.2144
649.46362	1.8415574	0.54601139	3465.7156
650.4646	1.8437721	0.54734051	3456.333
651.46558	1.8467335	0.54840511	3456.7673
652.46655	1.8492117	0.54974276	3460.8044
653.46753	1.8564554	0.55100948	3462.1499
654.46851	1.8573116	0.5521028	3466.03
655.46948	1.8604444	0.55322886	3459.0923
656.47046	1.8623313	0.55431342	3466.2449
657.47144	1.863989	0.55554807	3464.4639
658.47241	1.8684845	0.55683136	3462.1577
659.47339	1.8719709	0.55813199	3465.1304
660.47437	1.8725681	0.55936676	3466.9768
661.47534	1.8786755	0.56062001	3469.0918
662.47632	1.8819141	0.56193608	3473.0576
663.47729	1.8847384	0.56319267	3470.7969
664.47827	1.8875728	0.56456345	3474.5042
665.47925	1.8897945	0.56580639	3468.9102
666.48022	1.8946973	0.56681007	3469.6797
667.4812	1.8957883	0.56803054	3473.1777
668.48218	1.9013925	0.56912595	3474.697
669.48315	1.9007155	0.57038724	3477.8494
670.48413	1.9037759	0.57158577	3475.8379
671.48511	1.9090672	0.57272506	3472.0825
672.48608	1.9104335	0.57367927	3473.1885
673.48706	1.9144826	0.57506877	3482.085
674.48804	1.917568	0.57656753	3481.4253
675.48901	1.919956	0.57800657	3474.6917
676.48999	1.9225554	0.57893974	3476.2712
677.49097	1.9254445	0.58025134	3481.4543
678.49194	1.9268941	0.58135158	3485.2048
679.49292	1.9314504	0.58264196	3484.3599
680.4939	1.9346778	0.58364928	3473.9014
681.49487	1.9401159	0.58488101	3489.9958
682.49585	1.939237	0.58609271	3488.8271
683.49683	1.9446679	0.58747655	3486.7185
684.4978	1.9465923	0.58858436	3482.9277
685.49878	1.9471043	0.58975911	3485.0112
686.49976	1.9528012	0.59094584	3488.1631
687.50073	1.9562471	0.5921399	3489.3325
688.50171	1.9612074	0.59350967	3487.8552
689.50269	1.9622473	0.59462655	3485.3643
690.50366	1.9645339	0.59591883	3489.9436
691.50464	1.9657586	0.59707797	3491.49
692.50562	1.9701976	0.5983457	3489.9504
693.50659	1.9701035	0.59978718	3493.5139
694.50757	1.9797617	0.60107642	3491.5923
695.50854	1.9794031	0.6021806	3488.0693
696.50952	1.980864	0.60339278	3495.6545
697.5105	1.9850341	0.60480821	3502.7749
698.51147	1.9896955	0.60610348	3494.5674
699.51245	1.9944537	0.60742235	3501.2312
700.51343	1.9937445	0.6085335	3492.1052
701.5144	1.9986477	0.60957581	3494.4241
702.51538	2.0014789	0.61096388	3500.343
703.51636	2.0064404	0.61210376	3498.7505
704.51733	2.0077119	0.61329252	3497.0063
705.51831	2.0088506	0.61447912	3500.6121
706.51929	2.0132494	0.61574978	3501.7627
707.52026	2.013927	0.61712766	3505.5745
708.52124	2.018404	0.61839235	3502.9531
709.52222	2.022156	0.61958647	3506.2358
710.52319	2.0256686	0.62090629	3505.8765
711.52417	2.026669	0.62205815	3503.3804
712.52515	2.0309694	0.62327081	3503.8186
713.52612	2.0339715	0.62451452	3512.2017
714.5271	2.0360868	0.62567335	3502.2561
715.52808	2.0406451	0.62674314	3504.1187
716.52905	2.044059	0.62802511	3511.2419
717.53003	2.0450494	0.62914962	3501.8237
718.53101	2.0489333	0.6305539	3515.2444
719.53198	2.053679	0.63172781	3512.7617
720.53296	2.0554972	0.63307559	3513.5557
721.53394	2.0586913	0.63417506	3513.3853
722.53491	2.0595484	0.63563979	3512.7173
723.53589	2.0623543	0.63676769	3509.7197
724.53687	2.0676248	0.63784581	3509.3792
725.53784	2.0714586	0.63888097	3514.1204
726.53882	2.0688612	0.64006847	3514.4741
727.53979	2.0778313	0.64154434	3525.6501
728.54077	2.0790055	0.64287722	3521.7874
729.54175	2.0811188	0.64420754	3523.4578
730.54272	2.087291	0.64561111	3520.656
731.5437	2.0854394	0.64692408	3517.3728
732.54468	2.0932884	0.64811325	3517.2888
733.54565	2.0921752	0.64933705	3518.4192
734.54663	2.0958884	0.65065789	3516.9697
735.54761	2.0996368	0.65164149	3514.8083
736.54858	2.1026661	0.65299243	3521.54
737.54956	2.1069317	0.65424544	3524.7385
738.55054	2.1072395	0.6554845	3521.3481
739.55151	2.1110795	0.65669918	3531.9644
740.55249	2.1160076	0.65812939	3524.55
741.55347	2.1184394	0.65959907	3528.7725
742.55444	2.1228161	0.66088736	3527.6794
743.55542	2.1257372	0.6624198	3526.3193
744.5564	2.1258883	0.66358095	3528.7837
745.55737	2.1293118	0.66475755	3521.978
746.55835	2.1340916	0.66612899	3533.7373
747.55933	2.1352587	0.66742301	3527.0815
748.5603	2.1357622	0.66870624	3521.8181
749.56128	2.1425118	0.67002141	3531.7668
750.56226	2.1460087	0.6712513	3532.2546
751.56323	2.1497321	0.67225242	3525.4526
752.56421	2.1494651	0.6732555	3528.0833
753.56519	2.1519375	0.6743654	3527.1233
754.56616	2.1574559	0.67547202	3528.4675
755.56714	2.1590629	0.67667276	3531.2241
756.56812	2.1597569	0.67810887	3535.6882
757.56909	2.1671216	0.67966235	3543.4939
758.57007	2.1662319	0.68098235	3539.8779
759.57104	2.1722701	0.6823101	3537.7764
760.57202	2.1753561	0.68353212	3533.1221
761.573	2.181905	0.68485093	3538.7942
762.57397	2.1842589	0.6859287	3535.2573
763.57495	2.1858325	0.68710494	3541.6438
764.57593	2.1877103	0.68864638	3542.6624
765.5769	2.1885366	0.68988711	3534.7639
766.57788	2.1930566	0.69118488	3542.6316
767.57886	2.1973286	0.69283289	3547.4045
768.57983	2.1963143	0.69430155	3537.8044
769.58081	2.2040286	0.69549185	3537.1821
770.58179	2.2038224	0.69694024	3541.3577
771.58276	2.2075367	0.69843584	3551.4438
772.58374	2.2119887	0.6998505	3546.2856
773.58472	2.213634	0.70078486	3535.1653
774.58569	2.2173212	0.70208663	3544.0435
775.58667	2.2201786	0.70352197	3546.1533
776.58765	2.2217295	0.70482695	3548.4885
777.58862	2.2258956	0.70612335	3548.0278
778.5896	2.2287278	0.7074495	3549.2324
779.59058	2.2327332	0.70875573	3548.6846
780.59155	2.2349398	0.7099207	3546.5469
781.59253	2.2391369	0.71111727	3546.8909
782.59351	2.2397444	0.71227425	3545.4148
783.59448	2.245863	0.7136395	3557.4136
784.59546	2.2450204	0.71502405	3552.9001
785.59644	2.2499375	0.71635503	3555.7241
786.59741	2.2534826	0.71775937	3552.585
787.59839	2.2553401	0.71913141	3550.542
788.59937	2.2604716	0.72039318	3548.6135
789.60034	2.264024	0.72165358	3550.4253
790.60132	2.2665803	0.72285092	3555.1643
791.60229	2.2669849	0.72394538	3553.0347
792.60327	2.2714019	0.72527277	3554.5437
793.60425	2.2744751	0.72679543	3554.3232
794.60522	2.2757015	0.72794855	3552.0615
795.6062	2.2793148	0.72922987	3554.8608
796.60718	2.284976	0.73034006	3553.1431
797.60815	2.2870693	0.73153478	3554.2524
798.60913	2.2902076	0.73300236	3561.7532
799.61011	2.2933006	0.73430932	3562.2961
800.61108	2.296957	0.73580086	3564.2966
801.61206	2.2989097	0.73711586	3558.3923
802.61304	2.301326	0.73856783	3559.2188
803.61401	2.3009765	0.73988295	3560.4895
804.61499	2.3077216	0.74135917	3562.2131
805.61597	2.3120956	0.74278748	3564.967
806.61694	2.3138812	0.74413824	3561.6548
807.61792	2.3176112	0.74548864	3563.3423
808.6189	2.3195531	0.74701571	3569.7
809.61987	2.3223398	0.74849248	3566.9429
810.62085	2.323535	0.74986774	3563.9036
811.62183	2.3273201	0.75107616	3563.9714
812.6228	2.3323979	0.75273812	3572.6526
813.62378	2.3330593	0.75420231	3569.1721
814.62476	2.3398323	0.75564975	3565.0071
815.62573	2.3399661	0.75691092	3565.7859
816.62671	2.3448591	0.75820929	3573.5364
817.62769	2.3461509	0.75945657	3564.113
818.62866	2.3481829	0.76097065	3574.094
819.62964	2.3517177	0.76247299	3568.0769
820.63062	2.3564267	0.76385027	3565.563
821.63159	2.3589733	0.76523411	3571.9172
822.63257	2.3612652	0.7665109	3563.8745
823.63354	2.3674228	0.7677384	3569.2568
824.63452	2.3677559	0.76894003	3569.4419
825.6355	2.3716936	0.77019942	3571.4854
826.63647	2.3723505	0.77150255	3574.3918
827.63745	2.3753123	0.77280641	3569.5857
828.63843	2.3776782	0.77407318	3569.5281
829.6394	2.3843312	0.77555442	3580.7568
830.64038	2.3833871	0.77682263	3569.7717
831.64136	2.3885581	0.77820987	3574.3049
832.64233	2.390456	0.77959692	3579.0391
833.64331	2.3950207	0.78096789	3571.8091
834.64429	2.3977251	0.7823382	3578.5886
835.64526	2.4007404	0.78369111	3573.3828
836.64624	2.4016783	0.78502661	3575.3242
837.64722	2.4083354	0.78638935	3584.0457
838.64819	2.4107354	0.78795642	3586.48
839.64917	2.414156	0.78932208	3580.2773
840.65015	2.4148951	0.79091209	3582.9414
841.65112	2.4180782	0.79226846	3576.3171
842.6521	2.4210696	0.79383415	3581.8528
843.65308	2.4241712	0.79512125	3579.2175
844.65405	2.4284818	0.79649103	3579.7258
845.65503	2.4308519	0.79784435	3587.5295
846.65601	2.4310179	0.7992723	3581.1646
847.65698	2.4338541	0.80062616	3578.0515
848.65796	2.4414768	0.80209392	3587.593
849.65894	2.4403017	0.8035534	3581.7786
850.65991	2.4454966	0.80494899	3586.5435
851.66089	2.4485302	0.80648559	3586.2256
852.66187	2.4524124	0.80807114	3585.8379
853.66284	2.4555922	0.80943334	3585.6328
854.66382	2.4588668	0.810978	3584.5461
855.66479	2.4580741	0.81232208	3580.6052
856.66577	2.4621611	0.81375986	3582.7468
857.66675	2.46403	0.81499332	3582.7515
858.66772	2.4705763	0.8164674	3587.7778
859.6687	2.4732807	0.81765139	3586.6929
860.66968	2.4775677	0.81898367	3588.0994
861.67065	2.4808941	0.82028437	3590.9929
862.67163	2.4824085	0.82176822	3585.655
863.67261	2.4851396	0.82342827	3595.5754
864.67358	2.489177	0.8250066	3588.9504
865.67456	2.4922085	0.82644892	3585.28
866.67554	2.4925947	0.82777983	3589.4065
867.67651	2.4952691	0.82922828	3589.9976
868.67749	2.4966614	0.83051437	3585.7327
869.67847	2.5013659	0.83196455	3589.1743
870.67944	2.5037584	0.83323377	3583.437
871.68042	2.5097132	0.83475733	3595.5818
872.6814	2.5121839	0.83604491	3588.1318
873.68237	2.5133586	0.83748806	3598.4465
874.68335	2.5179133	0.83917522	3591.7292
875.68433	2.5226245	0.84065717	3593.1292
876.6853	2.5229819	0.84219652	3598.707
877.68628	2.5273011	0.84391069	3598.405
878.68726	2.5284228	0.84528309	3590.4495
879.68823	2.5307765	0.84676224	3590.4343
880.68921	2.5383301	0.84831047	3595.561
881.69019	2.5385895	0.84990752	3600.4077
882.69116	2.5402303	0.85142255	3594.3452
883.69214	2.5448525	0.85296148	3597.6941
884.69312	2.5453045	0.85444564	3592.2664
885.69409	2.5470507	0.85598147	3600.9258
886.69507	2.5523577	0.85733485	3591.4795
887.69604	2.5582564	0.85881042	3599.9729
888.69702	2.5606871	0.86000687	3597.6118
889.698	2.5606263	0.86161083	3595.947
890.69897	2.563839	0.86305934	3599.4172
891.69995	2.5684345	0.86450022	3597.1592
892.70093	2.5714829	0.86578465	3594.8523
893.7019	2.5731528	0.86705792	3595.4851
894.70288	2.5777862	0.86847198	3600.1545
895.70386	2.5802777	0.87004316	3606.2009
896.70483	2.5829434	0.87160587	3599.4353
897.70581	2.5884013	0.8729043	3600.2585
898.70679	2.5904381	0.87410259	3602.6545
899.70776	2.5905662	0.87559676	3603.9084
900.70874	2.5987532	0.87736297	3606.9221
901.70972	2.5997369	0.87890315	3601.3933
902.71069	2.6028566	0.8803162	3601.8923
903.71167	2.6047072	0.8819322	3606.0649
904.71265	2.6082423	0.88367802	3607.6533
905.71362	2.6107337	0.88512176	3602.4695
906.7146	2.6128047	0.88680083	3605.7378
907.71558	2.6144741	0.88833344	3604.0225
908.71655	2.6194699	0.88984907	3607.1985
909.71753	2.6218491	0.89160395	3606.8306
910.71851	2.6250627	0.89334679	3608.1631
911.71948	2.6287	0.89508748	3602.9756
912.72046	2.6322234	0.89654064	3603.2007
913.72144	2.6351702	0.8979786	3606.1418
914.72241	2.6395586	0.89950877	3607.155
915.72339	2.6388006	0.90128922	3602.9382
916.72437	2.6439481	0.90260017	3601.7417
917.72534	2.6453228	0.90408081	3605.2478
918.72632	2.6499979	0.90559775	3608.0747
919.72729	2.6536181	0.9073053	3610.1265
920.72827	2.6555104	0.90896678	3611.1521
921.72925	2.6572578	0.91043246	3601.3958
922.73022	2.6641283	0.91168803	3602.1372
923.7312	2.6631267	0.91311949	3608.1108
924.73218	2.667846	0.91484058	3606.7791
925.73315	2.6692221	0.91653991	3608.667
926.73413	2.6725593	0.91820598	3610.0171
927.73511	2.676641	0.9198789	3606.313
928.73608	2.681175	0.9213779	3606.8176
929.73706	2.6796825	0.92267919	3606.4268
930.73804	2.6823695	0.92429042	3608.9233
931.73901	2.6894281	0.92594087	3610.9063
932.73999	2.6913683	0.9274925	3604.2571
933.74097	2.6951528	0.92888367	3606.4707
934.74194	2.6969581	0.93051016	3616.6089
935.74292	2.7015455	0.9320119	3609.3892
936.7439	2.7045336	0.93365258	3612.3098
937.74487	2.7074959	0.93536568	3617.4243
938.74585	2.7080705	0.93713284	3610.6206
939.74683	2.7121515	0.93867302	3611.2737
940.7478	2.7172086	0.94047213	3616.9355
941.74878	2.7165308	0.94214237	3607.3196
942.74976	2.7210093	0.94363427	3606.9558
943.75073	2.7249515	0.94521827	3612.9744
944.75171	2.7277608	0.94665569	3613.2117
945.75269	2.7331252	0.94828832	3616.7681
946.75366	2.7319703	0.94995695	3609.0481
947.75464	2.7339809	0.95166385	3621.905
948.75562	2.7415304	0.95362365	3616.875
949.75659	2.7405183	0.95539349	3617.5427
950.75757	2.7462564	0.95725733	3619.5642
951.75854	2.7461798	0.95873958	3609.0222
952.75952	2.7520866	0.9604581	3615.4905
953.7605	2.7578244	0.96242756	3620.0811
954.76147	2.7600009	0.96391124	3613.8628
955.76245	2.7605405	0.96553677	3614.4607
956.76343	2.7622604	0.96718097	3612.4104
957.7644	2.768101	0.96882355	3609.6033
958.76538	2.7724178	0.9703415	3619.4631
959.76636	2.7724326	0.97211093	3622.0627
960.76733	2.7767243	0.97383142	3617.1902
961.76831	2.7766886	0.97537345	3611.0498
962.76929	2.7805967	0.97665942	3611.1709
963.77026	2.7856355	0.97839761	3619.6414
964.77124	2.7872078	0.98022842	3612.8923
965.77222	2.7900369	0.98184496	3620.6755
966.77319	2.7944036	0.98347139	3613.7266
967.77417	2.7931118	0.98499984	3613.4604
968.77515	2.8012407	0.98678362	3616.6953
969.77612	2.8037636	0.9883455	3618.0278
970.7771	2.8074841	0.9900893	3620.5725
971.77808	2.8084679	0.99175382	3617.8628
972.77905	2.8140202	0.99345076	3621.6367
973.78003	2.8143611	0.99516857	3619.8547
974.78101	2.8160384	0.99689895	3618.1221
975.78198	2.8208034	0.99888813	3627.1653
976.78296	2.8262002	1.0008088	3621.9851
977.78394	2.8261158	1.0030733	3625.9436
978.78491	2.8288419	1.004993	3616.8501
979.78589	2.8329985	1.0069091	3621.8003
980.78687	2.8356841	1.0086401	3611.4771
981.78784	2.8396175	1.0101209	3618.0232
982.78882	2.8420608	1.0116138	3624.2888
983.78979	2.84462	1.0136374	3624.5095
984.79077	2.8481452	1.0158247	3623.1716
985.79175	2.8471057	1.0175359	3616.3586
986.79272	2.8531065	1.0194428	3621.2568
987.7937	2.856493	1.0211394	3618.3472
988.79468	2.8598464	1.0230372	3617.3782
989.79565	2.8651483	1.0247927	3616.7795
990.79663	2.8664916	1.0263273	3617.5686
991.79761	2.8706746	1.0282432	3627.3318
992.79858	2.8691804	1.0301639	3619.0034
993.79956	2.8733785	1.0320429	3615.8176
994.80054	2.880249	1.0335448	3621.7813
995.80151	2.8763874	1.0352392	3616.0576
996.80249	2.8848727	1.0370351	3624.8933
997.80347	2.8891733	1.0386207	3622.78
998.80444	2.8874149	1.0407298	3624.1592
999.80542	2.8931227	1.0425025	3613.873
1000.8064	2.8952584	1.0441728	3623.0608
1001.8074	2.900125	1.0457308	3616.6721
1002.8083	2.902055	1.0473888	3621.2119
1003.8093	2.9037912	1.0489715	3614.6826
1004.8103	2.9078128	1.0508589	3619.8943
1005.8113	2.9099417	1.0528243	3622.2268
1006.8123	2.9125595	1.0549614	3620.1675
1007.8132	2.9186721	1.0567912	3618.0186
1008.8142	2.9193501	1.0584315	3620.6897
1009.8152	2.9222474	1.060093	3619.1294
1010.8162	2.9259031	1.0619763	3622.2439
1011.8171	2.9292686	1.0636619	3619.552
1012.8181	2.9312577	1.0654614	3617.541
1013.8191	2.9350204	1.0672925	3622.6389
1014.8201	2.9399345	1.0691395	3620.6758
1015.821	2.9391301	1.0710504	3618.2146
1016.822	2.9426603	1.0727384	3618.7522
1017.823	2.9441457	1.0747229	3618.8831
1018.824	2.9501355	1.0767519	3626.1348
1019.825	2.9517987	1.0788757	3619.7568
1020.8259	2.9578271	1.0810093	3624.7051
1021.8269	2.9563351	1.0827848	3615.3599
1022.8279	2.9611676	1.0849059	3623.3569
1023.8289	2.9656785	1.0868021	3614.8838
1024.8298	2.9684663	1.0885644	3617.2996
1025.8308	2.9707878	1.090315	3621.9316
1026.8318	2.975101	1.0922815	3625.9399
1027.8328	2.9755251	1.0939633	3614.8721
1028.8337	2.9791017	1.0957762	3621.448
1029.8347	2.9849217	1.0978736	3627.1233
1030.8357	2.985472	1.0999117	3626.5625
1031.8367	2.9874125	1.102285	3625.2134
1032.8376	2.9940667	1.1046361	3623.3247
1033.8386	2.9961419	1.1063869	3619.5955
1034.8396	2.9964855	1.107926	3614.1367
1035.8406	2.9996052	1.1097249	3625.6279
1036.8416	3.0038013	1.111459	3620.2961
1037.8425	3.0076518	1.113441	3619.4658
1038.8435	3.0092514	1.1149606	3609.5181
1039.8445	3.0139556	1.1163388	3614.697
1040.8455	3.0143363	1.1181855	3622.3752
1041.8464	3.0169482	1.1202992	3618.5369
1042.8474	3.0232785	1.1225135	3627.9263
1043.8484	3.0258358	1.1249084	3624.835
1044.8494	3.0291579	1.1272372	3623.1382
1045.8503	3.0324743	1.129411	3616.7534
1046.8513	3.0333374	1.1315191	3618.0583
1047.8523	3.0346811	1.1330563	3609.4077
1048.8533	3.0386367	1.1345831	3610.4253
1049.8542	3.0434294	1.1361643	3615.1697
1050.8552	3.0484762	1.1374938	3614.6274
1051.8562	3.0489182	1.1391176	3613.6443
1052.8572	3.0507123	1.1408366	3614.1846
1053.8582	3.0544586	1.1425539	3618.1372
1054.8591	3.0590761	1.1444305	3623.0273
1055.8601	3.0615652	1.1463957	3621.4045
1056.8611	3.0645082	1.1486728	3625.6787
1057.8621	3.0649204	1.1508524	3619.5452
1058.863	3.0698228	1.1530645	3614.5005
1059.864	3.0752099	1.1549988	3614.752
1060.865	3.0760093	1.1572733	3624.8691
1061.866	3.0790565	1.1595509	3616.6941
1062.8669	3.0809171	1.1614884	3616.2957
1063.8679	3.0828471	1.1635149	3609.9768
1064.8689	3.0899482	1.1654999	3616.199
1065.8699	3.0910959	1.1676215	3621.1582
1066.8708	3.0950515	1.1701913	3622.8005
1067.8718	3.097059	1.1728778	3622.1404
1068.8728	3.0989237	1.1753298	3615.0715
1069.8738	3.1041362	1.1774467	3611.8577
1070.8748	3.1055503	1.1794368	3609.7979
1071.8757	3.1094384	1.1812479	3613.5676
1072.8767	3.1137092	1.1832141	3611.0991
1073.8777	3.1124344	1.1850613	3611.6694
1074.8787	3.1165717	1.1870958	3615.1763
1075.8796	3.1215248	1.1896347	3615.585
1076.8806	3.1220801	1.1915345	3604.7678
1077.8816	3.1273515	1.1934377	3612.4773
1078.8826	3.1297696	1.1958033	3613.0378
1079.8835	3.1331716	1.1978823	3611.3586
1080.8845	3.1377399	1.2000862	3617.1887
1081.8855	3.140902	1.2025261	3619.3535
1082.8865	3.1433268	1.2044908	3601.2546
1083.8875	3.1453669	1.206392	3608.3909
1084.8884	3.1514783	1.2082771	3611.7722
1085.8894	3.1513805	1.2104322	3611.8037
1086.8904	3.1537628	1.2123467	3602.5903
1087.8914	3.1574824	1.2144891	3607.5828
1088.8923	3.1605117	1.2168463	3612.6904
1089.8933	3.1635442	1.2191912	3606.9863
1090.8943	3.1686511	1.2213373	3609.6245
1091.8953	3.166857	1.2237014	3609.5845
1092.8962	3.1736569	1.2259482	3611.7861
1093.8972	3.1771789	1.2283016	3608.4453
1094.8982	3.1790571	1.2303952	3602.9265
1095.8992	3.1780899	1.2324065	3600.9602
1096.9001	3.1823804	1.2348812	3604.9814
1097.9011	3.1883798	1.2373517	3606.6353
1098.9021	3.191139	1.2398415	3606.8201
1099.9031	3.1938024	1.2419438	3603.9072
1100.9041	3.194211	1.2444209	3603.2524
1101.905	3.2007384	1.2468143	3610.3464
1102.906	3.2019634	1.2491984	3601.4551
1103.907	3.2086008	1.2515173	3603.4946
1104.908	3.2066443	1.2536485	3591.8838
1105.9089	3.2121909	1.2560272	3595.9958
1106.9099	3.2184124	1.258265	3603.7412
1107.9109	3.2190235	1.2608262	3600.2832
1108.9119	3.2207754	1.2634609	3598.7317
1109.9128	3.2242413	1.2659167	3595.0449
1110.9138	3.2280254	1.268026	3592.604
1111.9148	3.2279065	1.2701522	3592.9165
1112.9158	3.2324326	1.2723418	3598.3892
1113.9167	3.2354531	1.2743691	3593.9705
1114.9177	3.2375507	1.2764889	3591.0347
1115.9187	3.2438645	1.2786562	3595.0427
1116.9197	3.2445903	1.2810844	3592.2861
1117.9207	3.2480004	1.2831043	3585.3259
1118.9216	3.2515678	1.2854966	3589.9905
1119.9226	3.2547107	1.2879796	3594.593
1120.9236	3.2562413	1.2906278	3592.7026
1121.9246	3.2598078	1.2929463	3586.3884
1122.9255	3.2600133	1.2954396	3581.6548
1123.9265	3.2656918	1.2977831	3581.1382
1124.9275	3.263792	1.3006204	3586.4148
1125.9285	3.2702973	1.3030823	3577.1118
1126.9294	3.2750254	1.3053042	3579.979
1127.9304	3.2762163	1.3076125	3581.9382
1128.9314	3.2803507	1.3102051	3581.1565
1129.9324	3.2832367	1.312412	3580.7146
1130.9333	3.2876136	1.3146404	3576.3594
1131.9343	3.2892799	1.3171241	3583.4519
1132.9353	3.2921202	1.3195419	3574.4841
1133.9363	3.2945004	1.3222958	3574.7732
1134.9373	3.2969768	1.3247766	3568.0503
1135.9382	3.3001046	1.3273625	3573.5718
1136.9392	3.3052318	1.3303528	3579.3022
1137.9402	3.3075364	1.3329288	3567.5747
1138.9412	3.3097534	1.3352071	3570.0667
1139.9421	3.3143873	1.3376731	3570.6382
1140.9431	3.3153543	1.3402148	3567.77
1141.9441	3.3184516	1.3429674	3566.8589
1142.9451	3.3245389	1.3458322	3566.1428
1143.946	3.32358	1.3485466	3556.3247
1144.947	3.3267982	1.3507459	3550.981
1145.948	3.3315203	1.3529221	3558.0737
1146.949	3.3339469	1.354669	3556.4573
1147.95	3.3389895	1.3567944	3556.3018
1148.9509	3.341125	1.3594838	3558.4436
1149.9519	3.3425186	1.3622265	3553.8567
1150.9529	3.3456249	1.3645109	3555.5427
1151.9539	3.3486967	1.3671383	3554.6772
1152.9548	3.351825	1.369848	3550.708
1153.9558	3.3528061	1.3725344	3550.7373
1154.9568	3.3580461	1.3753541	3541.5842
1155.9578	3.3608863	1.3779526	3544.2141
1156.9587	3.36585	1.3803211	3543.4927
1157.9597	3.3671944	1.3827856	3539.8438
1158.9607	3.3698418	1.3852342	3540.323
1159.9617	3.3689387	1.3877755	3530.7351
1160.9626	3.3766859	1.3897762	3532.7075
1161.9636	3.3808658	1.392064	3536.9507
1162.9646	3.3827569	1.394675	3532.9902
1163.9656	3.3842227	1.3973522	3532.4229
1164.9666	3.3865633	1.400363	3536.2051
1165.9675	3.3915496	1.4032371	3523.9636
1166.9685	3.3940649	1.4058622	3528.2158
1167.9695	3.3962514	1.4085089	3524.6646
1168.9705	3.4009738	1.4109294	3524.7058
1169.9714	3.4037132	1.4130399	3514.8701
1170.9724	3.4053593	1.4150041	3516.3237
1171.9734	3.4080775	1.4182644	3525.8582
1172.9744	3.4124663	1.4215662	3510.6177
1173.9753	3.4156561	1.4238231	3506.6167
1174.9763	3.4202478	1.4260534	3512.9548
1175.9773	3.4210811	1.4287404	3507.6528
1176.9783	3.4246778	1.4314306	3505.8354
1177.9792	3.4286637	1.4342364	3505.8582
1178.9802	3.434149	1.4367977	3510.4897
1179.9812	3.4341362	1.4394917	3493.9353
1180.9822	3.4383147	1.4418044	3501.3411
1181.9832	3.4405313	1.4440695	3493.8701
1182.9841	3.4417756	1.446448	3488.6074
1183.9851	3.4450891	1.4486088	3487.6721
1184.9861	3.4459949	1.4509525	3489.6565
1185.9871	3.4522154	1.4542476	3492.1704
1186.988	3.4541161	1.456803	3485.8577
1187.989	3.4603126	1.4600685	3495.9102
1188.99	3.4600244	1.4630405	3477.3594
1189.991	3.4674079	1.4655256	3471.4915
1190.9919	3.4676313	1.4679538	3474.8179
1191.9929	3.4673088	1.4702405	3470.5308
1192.9939	3.472012	1.4729688	3472.4036
1193.9949	3.4776533	1.4758402	3469.05
1194.9958	3.4780397	1.479316	3466.1746
1195.9968	3.4826438	1.4822624	3465.6523
1196.9978	3.4838603	1.4852159	3459.2478
1197.9988	3.488126	1.488327	3457.4812
1198.9998	3.4902334	1.4910901	3456.4319
1200.0007	3.4924335	1.4944254	3456.469
1201.0017	3.4952636	1.4976763	3448.6025
1202.0027	3.5012705	1.5006487	3444.2676
1203.0037	3.5035665	1.5036941	3440.6111
1204.0046	3.5054364	1.5064775	3437.2134
1205.0056	3.5070865	1.5091728	3434.1687
1206.0066	3.51179	1.511638	3428.1726
1207.0076	3.5120924	1.5144129	3427.0466
1208.0085	3.519124	1.5168703	3427.5928
1209.0095	3.5213859	1.5194175	3417.6785
1210.0105	3.5226867	1.5218445	3414.8096
1211.0115	3.5281372	1.5242465	3424.4507
1212.0125	3.5288541	1.5274023	3418.8064
1213.0134	3.529479	1.5305073	3409.0745
1214.0144	3.5388618	1.5339314	3411.6624
1215.0154	3.5384338	1.537352	3402.856
1216.0164	3.5425858	1.5401598	3404.417
1217.0173	3.5470455	1.542962	3399.3789
1218.0183	3.5503514	1.5463531	3396.6394
1219.0193	3.5506942	1.5489281	3386.0137
1220.0203	3.5537887	1.551457	3391.3684
1221.0212	3.5539303	1.5543171	3381.9917
1222.0222	3.5622339	1.5577769	3381.6162
1223.0232	3.5655022	1.5612302	3381.6284
1224.0242	3.5659292	1.5641922	3371.4326
1225.0251	3.5711439	1.5667864	3367.897
1226.0261	3.5699575	1.56973	3364.3455
1227.0271	3.5737686	1.5730746	3365.4116
1228.0281	3.5801959	1.5761755	3355.1987
1229.0291	3.5805175	1.5791527	3348.178
1230.03	3.5837831	1.5818297	3347.5156
1231.031	3.5859768	1.5848739	3346.2502
1232.032	3.5886579	1.5883472	3342.9622
1233.033	3.5928235	1.5917269	3331.3362
1234.0339	3.5956511	1.5948994	3323.6616
1235.0349	3.5990372	1.5979891	3334.2043
1236.0359	3.6009202	1.6014061	3321.4207
1237.0369	3.6032126	1.6055555	3316.8518
1238.0378	3.6067781	1.6092395	3312.2451
1239.0388	3.611517	1.6127195	3305.0378
1240.0398	3.6136045	1.6165041	3299.1875
1241.0408	3.6166549	1.6195959	3290.7551
1242.0417	3.6189842	1.623324	3281.7639
1243.0427	3.6233263	1.6268682	3269.4016
1244.0437	3.6240764	1.6307017	3263.5679
1245.0447	3.6296477	1.6345319	3253.6094
1246.0457	3.6305344	1.6377472	3238.4746
1247.0466	3.6356633	1.6414524	3240.6721
1248.0476	3.6380696	1.6457485	3218.5889
1249.0486	3.6411152	1.650224	3203.7075
1250.0496	3.6430919	1.6556224	3172.2258
1250.3499	3.6489906	1.6682957	3054.5457