File: datasets/am_bench_2022/raw_data/60-XY.04-1/specimen.dat
MTS793|MPT|ENU|1|2|.|/|:|1|0|0|A

Operator Information						Time:	24.087402	Sec	10/15/2021 11:55:13 AM
Operator	Orion Kafka
Project	AM Bench 2022 mini-tensile challenge
Specimen ID	60-XY.04-1
Material	PBF-L Inconel 625
Specimen Width	2.56	mm
Specimen Thickness	1.52	mm
Notes
Operator Information End

Data Acquisition						Time:	1025.0811	Sec	10/15/2021 12:11:54 PM
Time	Axial Displacement	Axial Extensometer	Axial Force
Sec	mm	mm	N
24.200928	0.00047820975	-0.00026104652	69.49649
25.201904	0.001394431	-0.00016394151	81.14888
26.202881	0.0059017763	-3.521466e-05	97.54908
27.203857	0.0093160281	-0.00012177597	114.75932
28.204834	0.012482413	7.4846189e-06	124.11161
29.205811	0.013563623	4.803664e-05	139.0376
30.206787	0.017583532	0.00016869897	155.87683
31.207764	0.022870027	0.00016483474	168.15472
32.20874	0.027161058	0.00025944007	184.5538
33.209717	0.025892373	0.00029017782	200.52776
34.210693	0.028662652	0.00027654847	224.01651
35.21167	0.030961528	0.00037089974	235.47499
36.212646	0.035827179	0.00041555264	260.91626
37.213623	0.037848633	0.00066509959	284.36816
38.2146	0.044337068	0.00054016628	307.50339
39.215576	0.043890201	0.00075707311	326.5025
40.216553	0.046876639	0.00085126969	350.4339
41.217529	0.05231132	0.00072689779	370.10391
42.218506	0.055021774	0.00088311691	400.37994
43.219482	0.055497326	0.0010062789	413.6095
44.220459	0.060623646	0.0010083974	439.14243
45.221436	0.06324169	0.0011823899	461.39117
46.222412	0.065693006	0.0012382052	485.61292
47.223389	0.068093099	0.0013268155	515.59204
48.224365	0.071096547	0.0014590265	530.20886
49.225342	0.074748881	0.0015823647	556.20807
50.226318	0.077872388	0.0016846904	584.06256
51.227295	0.079769887	0.0017731612	603.9375
52.228271	0.083577737	0.0018333941	638.84875
53.229248	0.086810455	0.0019467673	663.16553
54.230225	0.089945234	0.002083153	686.77087
55.231201	0.092769653	0.0021607904	709.31604
56.232178	0.093623847	0.0022982864	737.77106
57.233154	0.095734991	0.0023169562	760.2663
58.234131	0.099904679	0.0025482432	784.02856
59.235107	0.10571656	0.0026469002	816.65228
60.236084	0.10437965	0.0027215912	838.8855
61.237061	0.11151677	0.0029280528	870.78503
62.238037	0.11424853	0.0030707091	903.12921
63.239014	0.11343511	0.0030492693	919.01385
64.23999	0.11960883	0.0032042181	958.12494
65.240967	0.12196713	0.0033787012	985.66589
66.241943	0.12470463	0.0033866714	1007.6235
67.24292	0.12604804	0.0035023519	1042.8613
68.243896	0.12873493	0.0036444622	1062.2811
69.244873	0.13488208	0.0037565611	1095.043
70.24585	0.13600421	0.0039480869	1121.7225
71.246826	0.13928221	0.0040227319	1150.118
72.247803	0.14246391	0.004177283	1171.5632
73.248779	0.14785008	0.0042222855	1197.5177
74.249756	0.15233853	0.0044313204	1219.6665
75.250732	0.15240902	0.0044541042	1249.1533
76.251709	0.15261944	0.0046098325	1276.8445
77.252686	0.15603532	0.0046810023	1305.5486
78.253662	0.15905829	0.0048647346	1337.8127
79.254639	0.16466303	0.0049971985	1362.4565
80.255615	0.16706429	0.0050429334	1401.3878
81.256592	0.17248014	0.0053337892	1431.8298
82.257568	0.17481568	0.0054741632	1459.5093
83.258545	0.17484498	0.0053876061	1476.516
84.259521	0.17731079	0.0056475233	1507.2605
85.260498	0.1801782	0.0057332488	1530.4816
86.261475	0.1829583	0.0059580696	1561.007
87.262451	0.18800436	0.0059465421	1588.4153
88.263428	0.18982169	0.0061031752	1618.053
89.264404	0.19510639	0.0062287971	1640.4342
90.265381	0.19501276	0.0063083796	1672.8485
91.266357	0.19929923	0.0065677809	1697.6134
92.267334	0.20534982	0.00659326	1722.1432
93.268311	0.2065037	0.0067521031	1753.5575
94.269287	0.20920561	0.0067952927	1780.964
95.270264	0.21365578	0.0069486313	1804.2252
96.27124	0.21492898	0.0070419302	1826.7095
97.272217	0.21834138	0.0071710302	1849.7778
98.273193	0.22217341	0.0073663509	1880.3364
99.27417	0.22463492	0.0074817105	1903.4904
100.27515	0.22563827	0.0075145257	1920.1635
101.27612	0.22827706	0.0076466426	1945.7406
102.2771	0.23061153	0.0078533916	1969.6106
103.27808	0.23376147	0.007858796	1989.3937
104.27905	0.23963319	0.0079684118	2023.3829
105.28003	0.24114919	0.0080742938	2040.5143
106.28101	0.24572784	0.0082348939	2062.4456
107.28198	0.24618351	0.0082754409	2081.0471
108.28296	0.24947749	0.0083933994	2106.1821
109.28394	0.25469458	0.0085446024	2119.3816
110.28491	0.2575005	0.008561084	2140.4368
111.28589	0.26277846	0.0086908694	2164.8291
112.28687	0.26381063	0.0088253003	2175.2517
113.28784	0.2649568	0.0089616375	2203.2244
114.28882	0.2685172	0.0089062611	2213.4561
115.28979	0.2717503	0.0090751247	2236.4036
116.29077	0.27370614	0.0092430692	2248.9854
117.29175	0.27636194	0.0092816446	2262.3337
118.29272	0.28104201	0.0092978561	2282.675
119.2937	0.28360105	0.0095573142	2294.5076
120.29468	0.28763306	0.0096235173	2318.269
121.29565	0.29264197	0.0097237583	2326.2021
122.29663	0.29288065	0.0097539667	2343.0078
123.29761	0.29660165	0.0099538928	2353.3228
124.29858	0.30157736	0.010032648	2373.9656
125.29956	0.29978728	0.009996674	2380.6563
126.30054	0.30510637	0.010318693	2403.2461
127.30151	0.30810452	0.01025076	2406.6545
128.30249	0.31531823	0.010388901	2428.8572
129.30347	0.31452325	0.010461225	2442.2241
130.30444	0.31750253	0.010520603	2444.8105
131.30542	0.31784242	0.010580705	2452.8374
132.3064	0.32206771	0.010708608	2467.9788
133.30737	0.32418683	0.010934223	2477.9336
134.30835	0.32905561	0.010873028	2487.989
135.30933	0.33413357	0.011066377	2509.7124
136.3103	0.33383873	0.011071532	2506.739
137.31128	0.33807707	0.011264635	2526.7083
138.31226	0.34331197	0.011394555	2540.4077
139.31323	0.34363973	0.01146677	2546.575
140.31421	0.34984198	0.011570677	2558.1768
141.31519	0.34940475	0.011797169	2561.2297
142.31616	0.35379896	0.011873852	2575.7104
143.31714	0.35489491	0.011914751	2578.6509
144.31812	0.35922727	0.012215524	2585.1531
145.31909	0.36136696	0.01222305	2598.5774
146.32007	0.36463329	0.012302236	2609.0698
147.32104	0.36609682	0.012619592	2614.5061
148.32202	0.37127903	0.012741522	2625.2883
149.323	0.37395245	0.012818101	2631.749
150.32397	0.37956086	0.012998292	2644.0017
151.32495	0.38343531	0.013164788	2660.2314
152.32593	0.38107312	0.013354355	2656.7451
153.3269	0.38650492	0.013497712	2670.2234
154.32788	0.39077747	0.013793678	2679.2708
155.32886	0.39485207	0.013956416	2686.8589
156.32983	0.39456955	0.014243527	2696.3337
157.33081	0.39821285	0.014399328	2702.2268
158.33179	0.40181094	0.014678039	2709.9346
159.33276	0.40560403	0.01488146	2720.9246
160.33374	0.40724257	0.015153774	2730.7358
161.33472	0.41101676	0.015536452	2735.7751
162.33569	0.41487506	0.015836466	2745.085
163.33667	0.41703317	0.016137833	2747.4126
164.33765	0.41996205	0.016437745	2752.7905
165.33862	0.42292574	0.016919885	2760.4575
166.3396	0.42371169	0.017215744	2766.1108
167.34058	0.42954817	0.01750451	2771
168.34155	0.4311983	0.017985065	2785.8875
169.34253	0.43478632	0.018341213	2789.0156
170.34351	0.43748063	0.018697781	2791.3208
171.34448	0.44301367	0.019194813	2809.6396
172.34546	0.44245574	0.019845448	2810.708
173.34644	0.44774365	0.020269163	2814.7539
174.34741	0.45014989	0.020668723	2817.502
175.34839	0.45348364	0.021316152	2822.5654
176.34937	0.45794776	0.021797275	2834.0212
177.35034	0.45631379	0.022241747	2831.9929
178.35132	0.46360639	0.022722326	2839.5894
179.35229	0.46259791	0.023252271	2837.4197
180.35327	0.46636826	0.023804106	2852.3872
181.35425	0.47137552	0.024485471	2851.2847
182.35522	0.47365966	0.025255872	2857.9951
183.3562	0.4773075	0.02581249	2864.3494
184.35718	0.4821572	0.026416862	2870.1174
185.35815	0.4847734	0.027067136	2878.1438
186.35913	0.48629043	0.027930588	2876.0332
187.36011	0.4919914	0.028703324	2878.5549
188.36108	0.49360165	0.029361812	2890.2058
189.36206	0.49381289	0.030212449	2884.2324
190.36304	0.49994195	0.030826937	2895.949
191.36401	0.50008392	0.031605024	2894.1062
192.36499	0.50538498	0.032760117	2895.9805
193.36597	0.50628263	0.033138547	2897.0654
194.36694	0.51096272	0.033932127	2907.499
195.36792	0.51318902	0.034773622	2912.1104
196.3689	0.51619899	0.035818707	2917.0837
197.36987	0.51843184	0.036496591	2915.6687
198.37085	0.52150792	0.03738812	2922.0242
199.37183	0.52550834	0.038131554	2927.1011
200.3728	0.52913302	0.039378535	2927.6143
201.37378	0.53201395	0.04015075	2935.3745
202.37476	0.53558213	0.041272271	2938.0405
203.37573	0.53759843	0.042262264	2939.3335
204.37671	0.54195333	0.043103486	2943.2495
205.37769	0.5442282	0.043993112	2940.1575
206.37866	0.5462324	0.044829916	2944.0037
207.37964	0.54728061	0.045737498	2948.2297
208.38062	0.5515604	0.046639275	2949.873
209.38159	0.5542106	0.047394786	2955.1941
210.38257	0.5582	0.048561506	2965.2139
211.38354	0.56014025	0.049453516	2958.2869
212.38452	0.56275177	0.050498676	2963.2661
213.3855	0.56903321	0.051723573	2968.4368
214.38647	0.56926703	0.0526549	2967.0515
215.38745	0.57251078	0.053579286	2967.4666
216.38843	0.57563621	0.054611396	2982.7688
217.3894	0.58007836	0.055774473	2982.7388
218.39038	0.58003885	0.056612182	2975.9053
219.39136	0.58455193	0.05735828	2976.4197
220.39233	0.58674628	0.05828115	2988.9319
221.39331	0.59041482	0.059361108	2986.0552
222.39429	0.59344488	0.060359541	2997.9529
223.39526	0.59785306	0.061304308	2993.6895
224.39624	0.60239118	0.062356316	3001.3354
225.39722	0.6011737	0.06339737	2996.8845
226.39819	0.60645962	0.064460076	3007.1545
227.39917	0.60709131	0.065422282	3001.189
228.40015	0.61152631	0.066444494	3012.4768
229.40112	0.6166389	0.067648567	3014.2048
230.4021	0.62008578	0.068792164	3019.1265
231.40308	0.6189189	0.06991601	3021.2366
232.40405	0.62651592	0.070922561	3016.074
233.40503	0.62814319	0.071845613	3020.0159
234.40601	0.62949157	0.0728966	3022.5618
235.40698	0.63228858	0.073757224	3019.6621
236.40796	0.63671881	0.074807622	3028.8533
237.40894	0.63793957	0.075826734	3028.4688
238.40991	0.63935858	0.077106684	3030.7166
239.41089	0.64396328	0.078120045	3032.1028
240.41187	0.64783096	0.07922364	3037.4849
241.41284	0.64973986	0.080327034	3037.3811
242.41382	0.65614307	0.081270017	3039.0981
243.41479	0.65578347	0.082402214	3043.6055
244.41577	0.65884006	0.083328001	3040.207
245.41675	0.66438389	0.084550887	3049.145
246.41772	0.66479534	0.08549618	3048.4131
247.4187	0.6689353	0.086569145	3048.3359
248.41968	0.67426997	0.087911293	3060.3623
249.42065	0.67463309	0.088987134	3051.4724
250.42163	0.67539793	0.089825779	3049.6868
251.42261	0.68278784	0.090766937	3061.137
252.42358	0.68522131	0.091829017	3063.1536
253.42456	0.68520325	0.092712969	3060.2361
254.42554	0.68910682	0.093876444	3072.4824
255.42651	0.69237888	0.09518905	3072.7349
256.42749	0.69535708	0.09637779	3076.1936
257.42847	0.70082378	0.09773659	3073.0244
258.42944	0.70376658	0.09886843	3082.905
259.43042	0.70488262	0.10006361	3079.5989
260.4314	0.70796531	0.10125413	3084.717
261.43237	0.71030009	0.10221332	3075.5198
262.43335	0.71291566	0.10320789	3081.1558
263.43433	0.71652806	0.10423641	3081.3435
264.4353	0.72262532	0.10515684	3088.4705
265.43628	0.72427243	0.10622886	3095.8806
266.43726	0.72819728	0.1073835	3092.7219
267.43823	0.73019063	0.10863597	3096.5383
268.43921	0.73179924	0.10971069	3097.8701
269.44019	0.73653769	0.11082528	3098.2207
270.44116	0.73857409	0.11195794	3102.1711
271.44214	0.7415204	0.11322646	3103.9138
272.44312	0.74628466	0.11407063	3110.5359
273.44409	0.75106245	0.11531977	3109.6838
274.44507	0.75209326	0.11638617	3115.7917
275.44604	0.75302082	0.11754774	3112.0742
276.44702	0.75638425	0.11868338	3104.3975
277.448	0.76110691	0.11974648	3111.2837
278.44897	0.76477379	0.12071306	3118.6284
279.44995	0.76682514	0.12178253	3122.8237
280.45093	0.7682184	0.1229746	3124.2722
281.4519	0.7720623	0.12417334	3127.0903
282.45288	0.7767567	0.12538102	3128.321
283.45386	0.77594286	0.12652238	3114.9028
284.45483	0.78348339	0.12752336	3130.0144
285.45581	0.78236473	0.12848674	3121.9126
286.45679	0.78642213	0.12948656	3129.6335
287.45776	0.78788728	0.13046555	3130.8572
288.45874	0.79153103	0.13178746	3142.4441
289.45972	0.79393351	0.13309833	3137.0129
290.46069	0.79905307	0.13416724	3136.8101
291.46167	0.80172956	0.13520437	3129.7239
292.46265	0.80423474	0.13625464	3139.0601
293.46362	0.80964154	0.13738729	3147.8323
294.4646	0.80916089	0.13850786	3140.4302
295.46558	0.81310397	0.13964492	3143.5483
296.46655	0.81807929	0.14090103	3153.5908
297.46753	0.82133245	0.142096	3149.2217
298.46851	0.82286197	0.14311798	3148.9819
299.46948	0.82697576	0.14410223	3154.1345
300.47046	0.8289904	0.14520401	3151.6343
301.47144	0.83223033	0.14645612	3158.9365
302.47241	0.83573288	0.1474373	3155.5405
303.47339	0.83802885	0.14861941	3163.197
304.47437	0.83849478	0.1496933	3162.2908
305.47534	0.8419432	0.15091568	3167.5469
306.47632	0.84886545	0.1521856	3168.1348
307.47729	0.85008126	0.15324093	3168.4011
308.47827	0.85076123	0.15440446	3172.375
309.47925	0.8547557	0.15551175	3171.282
310.48022	0.85892075	0.15647395	3167.5959
311.4812	0.86328834	0.15770113	3175.0171
312.48218	0.86329448	0.15887365	3177.02
313.48315	0.86838245	0.16013117	3185.8904
314.48413	0.87113315	0.16113307	3180.4834
315.48511	0.87501001	0.16228013	3182.8418
316.48608	0.87437856	0.1633684	3184.5649
317.48706	0.87674177	0.16440441	3180.1863
318.48804	0.8820045	0.16551946	3184.0217
319.48901	0.88623261	0.1666618	3190.1147
320.48999	0.88477296	0.16749167	3180.0261
321.49097	0.89048547	0.16826864	3185.4907
322.49194	0.89254028	0.16922982	3192.7358
323.49292	0.89780676	0.17040443	3193.0867
324.4939	0.90071988	0.17154825	3193.761
325.49487	0.90406734	0.17262273	3194.9641
326.49585	0.90667635	0.173796	3204.6636
327.49683	0.90908444	0.17484519	3201.7551
328.4978	0.91191864	0.17589444	3199.0623
329.49878	0.9190281	0.17703867	3201.8201
330.49976	0.91912705	0.17815545	3210.1606
331.50073	0.92239052	0.17935435	3211.7869
332.50171	0.92696983	0.18077125	3210.3335
333.50269	0.92764145	0.18195505	3213.3804
334.50366	0.93053913	0.18303877	3216.8862
335.50464	0.93556547	0.18397996	3214.9094
336.50562	0.93974358	0.18526827	3221.2454
337.50659	0.94024533	0.18612596	3218.511
338.50757	0.94245523	0.1872959	3223.8484
339.50854	0.9468624	0.18868758	3227.9119
340.50952	0.94916207	0.19000016	3235.4675
341.5105	0.95377231	0.19102561	3228.3687
342.51147	0.95463055	0.19215935	3227.1094
343.51245	0.95652765	0.19332746	3224.9524
344.51343	0.96039367	0.19441302	3231.4783
345.5144	0.96491534	0.19524588	3229.7756
346.51538	0.96675366	0.19640742	3232.3533
347.51636	0.96874964	0.19755222	3233.0637
348.51733	0.96827203	0.19862863	3232.5388
349.51831	0.97407079	0.19969071	3233.1738
350.51929	0.97880781	0.20100908	3241.9797
351.52026	0.97942907	0.20212212	3233.3682
352.52124	0.98396713	0.20327976	3234.2327
353.52222	0.98790693	0.20431593	3242.5547
354.52319	0.9920879	0.20539123	3244.6299
355.52417	0.99199569	0.20655745	3242.0276
356.52515	0.99547881	0.20750144	3242.2646
357.52612	1.0026491	0.20847763	3249.262
358.5271	1.0043664	0.20946845	3254.6362
359.52808	1.0060354	0.2106162	3256.5088
360.52905	1.0083913	0.21182618	3257.0762
361.53003	1.0113357	0.21313597	3259.6736
362.53101	1.0139658	0.21435376	3253.1465
363.53198	1.0207202	0.21522087	3256.4182
364.53296	1.0208206	0.21646607	3261.1648
365.53394	1.0232617	0.21759051	3256.4583
366.53491	1.0276055	0.21864906	3267.1611
367.53589	1.0294263	0.21987912	3269.7117
368.53687	1.0337297	0.22096491	3266.2217
369.53784	1.0331724	0.22208683	3265.7747
370.53882	1.036643	0.22307862	3262.2546
371.53979	1.0415993	0.22432308	3266.3557
372.54077	1.0446082	0.22526713	3268.7798
373.54175	1.0474738	0.22631526	3271.2129
374.54272	1.0540651	0.2276167	3281.709
375.5437	1.0518123	0.2287221	3270.5806
376.54468	1.0551564	0.2300265	3285.5723
377.54565	1.060317	0.23134215	3282.9758
378.54663	1.0647713	0.23247437	3279.9934
379.54761	1.0665034	0.2335974	3283.6011
380.54858	1.068293	0.23460978	3281.6416
381.54956	1.0705842	0.2358291	3288.762
382.55054	1.0736407	0.23692161	3285.7781
383.55151	1.0762473	0.23810524	3289.7373
384.55249	1.0814263	0.23909971	3290.2844
385.55347	1.084141	0.24034154	3288.4392
386.55444	1.0869868	0.24131024	3293.1255
387.55542	1.0870606	0.2425154	3300.5078
388.5564	1.0938282	0.24385849	3293.7234
389.55737	1.0927714	0.24487804	3288.5034
390.55835	1.1001972	0.2462187	3293.8953
391.55933	1.1026682	0.24708872	3289.1274
392.5603	1.1058975	0.24816005	3302.0176
393.56128	1.1051047	0.24926786	3303.0288
394.56226	1.1121567	0.25042865	3301.3589
395.56323	1.1149135	0.25146765	3301.4033
396.56421	1.1166968	0.2524412	3305.7883
397.56519	1.1192274	0.25362891	3307.6414
398.56616	1.1260548	0.25476274	3308.5176
399.56714	1.1268555	0.25585884	3305.9021
400.56812	1.1262928	0.25686747	3308.8125
401.56909	1.1329501	0.25791252	3315.9421
402.57007	1.1377262	0.25914356	3309.8896
403.57104	1.138991	0.26027191	3315.373
404.57202	1.1432788	0.26156923	3322.4209
405.573	1.1424352	0.2627176	3317.8633
406.57397	1.1475508	0.2637738	3318.4417
407.57495	1.1504403	0.26482701	3319.2
408.57593	1.1539608	0.26587629	3322.3054
409.5769	1.1557363	0.26721832	3324.3801
410.57788	1.1588566	0.26841873	3331.4131
411.57886	1.161724	0.2697663	3328.1497
412.57983	1.1636647	0.27085778	3326.1563
413.58081	1.1703672	0.2719366	3337.5747
414.58179	1.1704329	0.27315941	3332.303
415.58276	1.1748682	0.27428254	3331.4707
416.58374	1.1805336	0.27539533	3332.9338
417.58472	1.1805896	0.27639613	3335.7339
418.58569	1.1782278	0.2774266	3328.397
419.58667	1.1856989	0.27842954	3334.7495
420.58765	1.1915469	0.27960426	3343.6748
421.58862	1.189443	0.28083175	3339.3069
422.5896	1.1966	0.28186554	3346.0269
423.59058	1.1985345	0.28313404	3349.0413
424.59155	1.1996499	0.28421614	3345.8384
425.59253	1.2059873	0.28551555	3350.8853
426.59351	1.209378	0.28681123	3348.3794
427.59448	1.2083749	0.28801477	3342.9553
428.59546	1.2140338	0.28925419	3351.354
429.59644	1.2167414	0.29012069	3341.8057
430.59741	1.2206151	0.29123637	3358.1245
431.59839	1.2224981	0.29215255	3354.5493
432.59937	1.2228811	0.2933794	3355.2961
433.60034	1.2285382	0.2944707	3359.627
434.60132	1.2306172	0.29576984	3355.0403
435.60229	1.2355828	0.2968969	3356.4485
436.60327	1.2370523	0.29790801	3361.1152
437.60425	1.2384722	0.29918897	3363.1941
438.60522	1.2424419	0.30028921	3359.5525
439.6062	1.2465118	0.30143571	3358.6084
440.60718	1.2518568	0.30226958	3364.0322
441.60815	1.2519563	0.30321568	3368.0603
442.60913	1.2545913	0.30451602	3367.1523
443.61011	1.2594286	0.30548093	3368.3213
444.61108	1.2601726	0.30664957	3372.8789
445.61206	1.2655913	0.30792758	3371.8508
446.61304	1.2668411	0.309255	3373.8918
447.61401	1.2684317	0.31062731	3372.7537
448.61499	1.2735438	0.31179541	3368.8093
449.61597	1.2765627	0.31269768	3377.2751
450.61694	1.2791723	0.31384215	3380.6604
451.61792	1.2840267	0.31532109	3389.115
452.6189	1.2857299	0.31635109	3378.5789
453.61987	1.2900939	0.31748995	3378.8733
454.62085	1.2908946	0.31850147	3388.644
455.62183	1.2928613	0.31983113	3386.1819
456.6228	1.2974414	0.32064652	3379.5081
457.62378	1.3000879	0.32166731	3388.2502
458.62476	1.3031344	0.32279116	3392.1436
459.62573	1.3063823	0.32393187	3382.301
460.62671	1.3088151	0.3250086	3389.855
461.62769	1.3126103	0.32607484	3393.6221
462.62866	1.3167015	0.32756421	3399.979
463.62964	1.3181106	0.32877579	3391.5503
464.63062	1.3211675	0.32974085	3391.5906
465.63159	1.324887	0.33097246	3394.1797
466.63257	1.3276659	0.33209151	3397.509
467.63354	1.3320854	0.3332926	3400.9783
468.63452	1.3331572	0.33429947	3396.001
469.6355	1.3348765	0.33544704	3399.5464
470.63647	1.3383068	0.33640426	3399.4497
471.63745	1.3417209	0.33741552	3404.8879
472.63843	1.3467308	0.33867523	3409.5703
473.6394	1.3480353	0.33965713	3407.3203
474.64038	1.3527031	0.34079054	3410.3618
475.64136	1.3554155	0.3420454	3408.5249
476.64233	1.3572931	0.34311822	3408.373
477.64331	1.3582368	0.34419701	3409.3213
478.64429	1.3653448	0.3454957	3414.9219
479.64526	1.3666672	0.34682038	3417.1372
480.64624	1.3705432	0.34804153	3413.3586
481.64722	1.3725166	0.3492811	3407.6619
482.64819	1.3753769	0.34991002	3410.1536
483.64917	1.3793272	0.35107812	3417.5935
484.65015	1.3810356	0.35215026	3424.8181
485.65112	1.3843095	0.3532072	3424.6304
486.6521	1.3891006	0.35453823	3429.2112
487.65308	1.390204	0.3557761	3425.1416
488.65405	1.3957914	0.35686696	3420.3494
489.65503	1.3933586	0.35811457	3417.6777
490.65601	1.3992844	0.35924715	3421.6196
491.65698	1.4012525	0.36027372	3423.5583
492.65796	1.4064393	0.36133057	3427.1438
493.65894	1.407015	0.36261833	3433.6187
494.65991	1.4113982	0.36378315	3428.8022
495.66089	1.4158455	0.3649337	3431.0444
496.66187	1.4171695	0.36616373	3435.7119
497.66284	1.4217932	0.36733615	3432.6777
498.66382	1.4240159	0.36848849	3434.8491
499.66479	1.4256471	0.3695609	3435.9812
500.66577	1.4308382	0.37083322	3435.3669
501.66675	1.4321425	0.3718861	3439.9832
502.66772	1.4326824	0.372982	3436.2209
503.6687	1.4362993	0.37415364	3439.2847
504.66968	1.4396831	0.3754476	3443.6052
505.67065	1.4451034	0.37685651	3448.7217
506.67163	1.4483892	0.37783322	3437.8774
507.67261	1.4470035	0.37899622	3442.4844
508.67358	1.4512511	0.38011241	3443.3694
509.67456	1.4553181	0.38115248	3442.1316
510.67554	1.4577471	0.38226053	3444.1912
511.67651	1.4636686	0.38345847	3448.2278
512.67749	1.4641273	0.38456267	3443.9375
513.67847	1.4665242	0.38548386	3445.551
514.67944	1.4707745	0.38663781	3454.7849
515.68042	1.4722396	0.38777691	3451.4873
516.6814	1.4784715	0.3890138	3459.5525
517.68237	1.4789321	0.39019471	3455.4102
518.68335	1.4844691	0.39158511	3460.8591
519.68433	1.4824739	0.39284122	3461.9795
520.6853	1.491309	0.39408794	3456.4937
521.68628	1.4910687	0.3952837	3457.1887
522.68726	1.4937476	0.39645818	3460.937
523.68823	1.4966099	0.39768052	3461.6467
524.68921	1.5028031	0.39874145	3468.5066
525.69019	1.5046471	0.40003726	3463.3567
526.69116	1.5083386	0.4013083	3466.501
527.69214	1.5112023	0.40261653	3468.3721
528.69312	1.5123087	0.40363759	3459.0745
529.69409	1.5166441	0.40452772	3464.1472
530.69507	1.5173398	0.40562886	3465.8911
531.69604	1.5204602	0.40660992	3469.2717
532.69702	1.5233763	0.40785885	3472.8523
533.698	1.5292155	0.40927005	3477.0408
534.69897	1.5308132	0.41046494	3472.6274
535.69995	1.5321903	0.41166404	3465.2463
536.70093	1.5384086	0.41266346	3480.9949
537.7019	1.5410361	0.41375709	3476.6587
538.70288	1.5426122	0.41504502	3482.1267
539.70386	1.5492208	0.41641241	3479.6816
540.70483	1.5495284	0.41742215	3478.3572
541.70581	1.5512513	0.41851795	3476.5742
542.70679	1.5526828	0.41964975	3476.6462
543.70776	1.5560166	0.42078045	3478.0247
544.70874	1.5641091	0.42204604	3489.2205
545.70972	1.5663815	0.42328846	3483.4958
546.71069	1.5680261	0.42446098	3484.3521
547.71167	1.571605	0.42544633	3488.2813
548.71265	1.5717543	0.42662597	3487.6018
549.71362	1.578504	0.42794454	3494.4602
550.7146	1.5781597	0.42930636	3495.9336
551.71558	1.58217	0.43074098	3495.4539
552.71655	1.5860666	0.43179905	3486.9902
553.71753	1.5896549	0.43320745	3494.6118
554.71851	1.5900859	0.43445826	3495.8167
555.71948	1.5919579	0.43555573	3480.6213
556.72046	1.5999855	0.43682858	3502.3054
557.72144	1.5993202	0.43779108	3496.1531
558.72241	1.6009997	0.43909317	3497.3005
559.72339	1.606159	0.4401679	3499.7407
560.72437	1.6080259	0.44144979	3496.9255
561.72534	1.6123466	0.4425607	3504.3464
562.72632	1.6180183	0.44367304	3496.5457
563.72729	1.6193169	0.4449183	3505.4207
564.72827	1.6207389	0.44609979	3507.1133
565.72925	1.6257318	0.44721195	3510.2439
566.73022	1.6283637	0.44826627	3502.6719
567.7312	1.6283087	0.44956365	3505.8877
568.73218	1.6311673	0.45074227	3509.3057
569.73315	1.6369529	0.45201483	3512.5181
570.73413	1.6391222	0.45346361	3513.1479
571.73511	1.6436272	0.45470515	3505.5154
572.73608	1.6443201	0.45581689	3508.6238
573.73706	1.6467193	0.45684743	3502.063
574.73804	1.6519524	0.45796573	3510.8115
575.73901	1.6542369	0.4589484	3510.2327
576.73999	1.6564614	0.4601261	3515.6685
577.74097	1.6589446	0.46136931	3515.0317
578.74194	1.6629535	0.46266204	3519.8076
579.74292	1.6641314	0.46394652	3515.166
580.7439	1.6699357	0.46529254	3519.656
581.74487	1.6747267	0.46648225	3522.7534
582.74585	1.6732481	0.46759737	3519.3354
583.74683	1.6784183	0.46872324	3519.1245
584.7478	1.6829406	0.46989194	3526.2219
585.74878	1.6848022	0.4711847	3529.7205
586.74976	1.6867102	0.47251847	3525.5591
587.75073	1.6888274	0.47403699	3521.4871
588.75171	1.6939375	0.47481903	3523.7878
589.75269	1.6993396	0.47599319	3530.4595
590.75366	1.7020884	0.477341	3535.7273
591.75464	1.702078	0.4788084	3524.0828
592.75562	1.7069023	0.48010069	3529.4966
593.75659	1.7095741	0.48149088	3533.7617
594.75757	1.7108667	0.48278269	3533.1501
595.75854	1.7132847	0.48402524	3534.8584
596.75952	1.7182409	0.48519218	3537.8279
597.7605	1.7203739	0.48637706	3535.1179
598.76147	1.720956	0.48779875	3535.9346
599.76245	1.7266681	0.48886031	3534.8572
600.76343	1.7301166	0.49015328	3538.9526
601.7644	1.733326	0.4912374	3535.082
602.76538	1.7339643	0.49248517	3530.8647
603.76636	1.7375606	0.4934932	3533.5239
604.76733	1.7399763	0.49449751	3538.1204
605.76831	1.7440135	0.49570209	3538.0889
606.76929	1.7437499	0.4968937	3535.6111
607.77026	1.7495929	0.49821016	3540.0854
608.77124	1.7547311	0.49951047	3548.1697
609.77222	1.7563468	0.50088358	3543.564
610.77319	1.7595053	0.502267	3549.0903
611.77417	1.7645239	0.50361574	3547.9995
612.77515	1.7654955	0.50469387	3546.5493
613.77612	1.7683053	0.50570416	3546.1929
614.7771	1.771148	0.50695354	3546.9683
615.77808	1.7752199	0.50812519	3548.1294
616.77905	1.7806976	0.50944203	3552.1201
617.78003	1.7828319	0.51082057	3554.842
618.78101	1.7843641	0.51200819	3549.2466
619.78198	1.7842014	0.51323944	3551.2927
620.78296	1.7907941	0.51421118	3549.1411
621.78394	1.7934091	0.51538539	3556.9199
622.78491	1.7967812	0.51670259	3554.5366
623.78589	1.7987698	0.517847	3556.949
624.78687	1.803848	0.51923883	3563.0522
625.78784	1.8061041	0.52077109	3565.2629
626.78882	1.8070556	0.52218813	3561.561
627.78979	1.8097584	0.52337104	3562.0559
628.79077	1.815641	0.52472055	3564.8701
629.79175	1.8156402	0.52576661	3557.8723
630.79272	1.8210307	0.52710152	3563.3811
631.7937	1.8216327	0.52831382	3566.8555
632.79468	1.8275542	0.52948642	3567.124
633.79565	1.828833	0.53076965	3565.2217
634.79663	1.831401	0.5320276	3564.9988
635.79761	1.8331012	0.53331089	3565.9956
636.79858	1.8403749	0.534841	3572.6824
637.79956	1.8417569	0.5362975	3572.7869
638.80054	1.8434069	0.53740257	3557.5959
639.80151	1.8463147	0.53859895	3563.9758
640.80249	1.8500975	0.5396626	3562.1907
641.80347	1.8501093	0.54072249	3568.0413
642.80444	1.8601317	0.54191291	3575.9673
643.80542	1.8580722	0.54319966	3575.8259
644.8064	1.8606548	0.5443114	3567.751
645.80737	1.8684977	0.54543251	3576.9946
646.80835	1.867142	0.54663599	3578.1792
647.80933	1.8695421	0.54808307	3574.4998
648.8103	1.8748813	0.54931331	3576.2825
649.81128	1.8764751	0.55041122	3574.5659
650.81226	1.8795716	0.55178869	3579.6118
651.81323	1.8837347	0.5529992	3576.4749
652.81421	1.8853607	0.55410379	3572.5764
653.81519	1.8903153	0.55544901	3579.3948
654.81616	1.8941694	0.55670613	3587.5847
655.81714	1.8947632	0.55772007	3577.967
656.81812	1.8955758	0.55908334	3582.085
657.81909	1.8974326	0.56055695	3583.8264
658.82007	1.9032609	0.56178635	3573.5315
659.82104	1.9068676	0.56294358	3580.2246
660.82202	1.9096562	0.56421191	3583.9624
661.823	1.9105585	0.56569999	3583.3748
662.82397	1.9175434	0.56694776	3586.4829
663.82495	1.9194751	0.56829756	3591.2334
664.82593	1.9203283	0.56964177	3586.4065
665.8269	1.9243406	0.5711751	3587.2852
666.82788	1.9280093	0.57244295	3583.6912
667.82886	1.9292855	0.57391506	3595.4514
668.82983	1.9334798	0.5755018	3589.9482
669.83081	1.9361049	0.57678878	3591.5645
670.83179	1.9364669	0.57810968	3590.4236
671.83276	1.9431967	0.57922739	3584.615
672.83374	1.9460577	0.58027297	3592.3984
673.83472	1.9491839	0.58138955	3593.3618
674.83569	1.9512502	0.58258301	3593.1074
675.83667	1.9514043	0.58411002	3602.1521
676.83765	1.9593918	0.58521563	3592.5557
677.83862	1.9605944	0.58650917	3589.6086
678.8396	1.9642678	0.58788007	3598.4609
679.84058	1.9695121	0.58920467	3605.7871
680.84155	1.9709961	0.59056771	3598.3442
681.84253	1.9739066	0.59193569	3600.427
682.84351	1.9762491	0.59322089	3600.1045
683.84448	1.9788613	0.59445673	3602.7502
684.84546	1.9835654	0.59576279	3601.3455
685.84644	1.9843622	0.59706742	3601.2334
686.84741	1.9873592	0.59838593	3606.3894
687.84839	1.9908255	0.59976101	3605.9263
688.84937	1.9936664	0.60113156	3607.2654
689.85034	1.9996178	0.60247838	3607.3655
690.85132	1.9988586	0.60345703	3599.0688
691.85229	2.0021005	0.60473192	3606.7781
692.85327	2.0046053	0.60600996	3605.6621
693.85425	2.005605	0.60740954	3605.7837
694.85522	2.0130241	0.6086188	3611.5264
695.8562	2.01459	0.60992742	3612.1492
696.85718	2.016928	0.61133277	3604.6531
697.85815	2.0211012	0.6125477	3605.5042
698.85913	2.0232692	0.61390519	3611.5288
699.86011	2.0253739	0.61532086	3612.9817
700.86108	2.0286496	0.61672169	3614.0269
701.86206	2.0344048	0.61786193	3612.5928
702.86304	2.0341432	0.61920732	3610.4924
703.86401	2.0407639	0.62065262	3618.4009
704.86499	2.0419614	0.62188584	3617.2488
705.86597	2.0432494	0.62334293	3619.4365
706.86694	2.048413	0.6247735	3616.2634
707.86792	2.0498281	0.62593603	3612.1914
708.8689	2.0544984	0.62722701	3616.7351
709.86987	2.0555766	0.6285156	3617.688
710.87085	2.0599761	0.62983268	3619.791
711.87183	2.0635264	0.63112152	3620.1807
712.8728	2.0668075	0.63264036	3621.8098
713.87378	2.0704889	0.63409013	3616.2197
714.87476	2.0738101	0.6354019	3619.3093
715.87573	2.0742452	0.63650924	3617.1926
716.87671	2.0760159	0.63772523	3617.7061
717.87769	2.0824964	0.6390571	3627.0635
718.87866	2.0828505	0.64063984	3632.448
719.87964	2.0883067	0.64219868	3625.2468
720.88062	2.0931008	0.64372927	3624.4521
721.88159	2.0908785	0.64490819	3618.2976
722.88257	2.0958719	0.64639962	3630.9397
723.88354	2.0977995	0.64775914	3618.4795
724.88452	2.1019197	0.64904952	3623.1338
725.8855	2.1037297	0.65026063	3629.385
726.88647	2.1089213	0.65160239	3626.4272
727.88745	2.1108444	0.65304393	3629.603
728.88843	2.1120718	0.65435946	3619.4849
729.8894	2.1158698	0.65555143	3623.9319
730.89038	2.1182976	0.6568374	3633.8079
731.89136	2.1235363	0.65833068	3633.0586
732.89233	2.1269531	0.6597982	3632.5818
733.89331	2.1287613	0.66138011	3635.0459
734.89429	2.1302035	0.6629433	3627.2932
735.89526	2.1357892	0.66426551	3629.5403
736.89624	2.1384821	0.6657002	3633.1563
737.89722	2.1398337	0.66702014	3625.459
738.89819	2.1441205	0.66848844	3633.6277
739.89917	2.1478229	0.66985273	3637.1951
740.90015	2.1494064	0.67138809	3633.262
741.90112	2.1541522	0.6728946	3633.2656
742.9021	2.1576521	0.67437094	3638.7773
743.90308	2.1582019	0.67558604	3632.0378
744.90405	2.1635745	0.6768899	3635.9656
745.90503	2.1620636	0.67816329	3636.3608
746.90601	2.1676908	0.67945492	3637.3767
747.90698	2.171041	0.68086678	3636.5066
748.90796	2.1741426	0.68224847	3638.856
749.90894	2.1755185	0.68350559	3637.8652
750.90991	2.179776	0.68471408	3632.4434
751.91089	2.1818953	0.68589467	3635.2571
752.91187	2.1846688	0.68725038	3640.2886
753.91284	2.1866541	0.68863863	3640.6165
754.91382	2.1925287	0.6899609	3642.9138
755.91479	2.1950598	0.69132763	3643.8877
756.91577	2.1973598	0.69263208	3642.5474
757.91675	2.2016387	0.69415778	3643.9395
758.91772	2.2011237	0.69552189	3638.884
759.9187	2.2053335	0.69684285	3640.2148
760.91968	2.2102144	0.69825763	3645.5662
761.92065	2.2121711	0.69981176	3642.1631
762.92163	2.2182417	0.70129997	3647.3516
763.92261	2.2204278	0.70270604	3646.759
764.92358	2.2222934	0.70392317	3649.031
765.92456	2.2245414	0.70542264	3649.4724
766.92554	2.2294872	0.70696986	3650.1982
767.92651	2.2321126	0.70829123	3649.8872
768.92749	2.2369342	0.70990056	3652.5586
769.92847	2.2390242	0.71144843	3651.1885
770.92944	2.2393234	0.71291459	3647.9714
771.93042	2.2439008	0.71429861	3656.1143
772.9314	2.2472074	0.7157945	3653.0508
773.93237	2.2484064	0.71715152	3647.3997
774.93335	2.2521703	0.71857649	3645.8484
775.93433	2.2578716	0.72027856	3658.0352
776.9353	2.2576032	0.72169024	3649.4849
777.93628	2.2596278	0.72324687	3656.2988
778.93726	2.2658083	0.72451681	3651.1331
779.93823	2.2674913	0.7258873	3648.4739
780.93921	2.2712362	0.72722214	3649.8831
781.94019	2.2723255	0.72872871	3657.895
782.94116	2.274992	0.73002845	3649.4014
783.94214	2.2782512	0.7315262	3654.1855
784.94312	2.280014	0.73301727	3654.5725
785.94409	2.2843645	0.73430479	3652.6863
786.94507	2.2882018	0.73570007	3653.751
787.94604	2.292968	0.73734713	3658.1934
788.94702	2.2925298	0.73865247	3651.0759
789.948	2.2993257	0.73995376	3657.5164
790.94897	2.2973022	0.74156415	3660.9329
791.94995	2.3030279	0.74326998	3656.9517
792.95093	2.3077703	0.74461883	3661.3406
793.9519	2.308876	0.74637836	3663.4622
794.95288	2.3123987	0.74833119	3663.8301
795.95386	2.3164093	0.74986011	3654.9917
796.95483	2.3186879	0.7515173	3661.5605
797.95581	2.3236814	0.75313896	3658.5205
798.95679	2.3272345	0.75427657	3659.2124
799.95776	2.3262737	0.75540948	3657.3232
800.95874	2.3284695	0.75663108	3659.6011
801.95972	2.3326926	0.7581591	3659.8101
802.96069	2.3373749	0.75948107	3663.7336
803.96167	2.3387666	0.76136118	3666.2751
804.96265	2.3426917	0.76314813	3665.4014
805.96362	2.347641	0.7649067	3662.4941
806.9646	2.348114	0.76631314	3662.4814
807.96558	2.3513222	0.76776737	3661.2463
808.96655	2.3522818	0.76921582	3658.5142
809.96753	2.3595724	0.77085167	3671.554
810.96851	2.35906	0.77238548	3664.8157
811.96948	2.3625445	0.77410603	3665.4285
812.97046	2.3664837	0.77549392	3670.6638
813.97144	2.3702786	0.77686244	3662.7058
814.97241	2.372596	0.77817184	3664.8022
815.97339	2.3753819	0.77966207	3662.9185
816.97437	2.3781898	0.78104889	3667.2693
817.97534	2.3805053	0.7825287	3667.2742
818.97632	2.3837237	0.78403836	3666.0493
819.97729	2.3880615	0.78536755	3662.6702
820.97827	2.3922768	0.78681266	3667.1091
821.97925	2.391459	0.78810883	3664.1863
822.98022	2.3979754	0.78956062	3664.3987
823.9812	2.3987544	0.79095519	3668.5227
824.98218	2.400969	0.79249507	3669.1221
825.98315	2.4061818	0.79404068	3670.5908
826.98413	2.408361	0.79536647	3669.0981
827.98511	2.4113269	0.79701644	3669.6853
828.98608	2.4126019	0.79857332	3668.7004
829.98706	2.4198329	0.80025673	3677.1819
830.98804	2.4187114	0.80164379	3665.3391
831.98901	2.4213557	0.80338258	3672.0984
832.98999	2.4252744	0.80495554	3671.7727
833.99097	2.4288757	0.80642903	3671.6616
834.99194	2.4309886	0.80827111	3675.6262
835.99292	2.4353456	0.81017202	3674.104
836.9939	2.4363821	0.81170738	3667.0796
837.99487	2.4412143	0.81338596	3676.6523
838.99585	2.444948	0.81512254	3672.9285
839.99683	2.4471385	0.816845	3672.0288
840.9978	2.4498057	0.81844985	3673.7798
841.99878	2.4527445	0.81983769	3672.9863
842.99976	2.4563694	0.82159173	3681.5564
844.00073	2.462713	0.82322478	3671.356
845.00171	2.4624093	0.82450843	3672.3083
846.00269	2.4660645	0.82612824	3675.0049
847.00366	2.4664378	0.82767743	3673.6475
848.00464	2.4725025	0.82910353	3676.4521
849.00562	2.4734688	0.83086169	3675.6541
850.00659	2.4772618	0.83251327	3673.3704
851.00757	2.4817929	0.83436275	3678.2285
852.00854	2.4848201	0.83604819	3674.5708
853.00952	2.4885881	0.83743298	3673.2019
854.0105	2.4873116	0.8391003	3669.7429
855.01147	2.4937274	0.84060127	3675.9788
856.01245	2.4954691	0.84216195	3676.5801
857.01343	2.5001254	0.84368944	3675.4558
858.0144	2.5001819	0.8451001	3674.8328
859.01538	2.5010443	0.84649634	3675.7217
860.01636	2.5058718	0.84799039	3672.4199
861.01733	2.5108132	0.84995204	3679.1931
862.01831	2.5123909	0.85125571	3671.6394
863.01929	2.5176349	0.85274798	3680.2798
864.02026	2.5203409	0.85424024	3678.2354
865.02124	2.5231748	0.85615855	3683.2625
866.02222	2.5258617	0.8576436	3681.9363
867.02319	2.5313523	0.85955364	3684.5044
868.02417	2.5322566	0.86147618	3683.0286
869.02515	2.5346701	0.86306942	3674.3115
870.02612	2.5392747	0.8649103	3676.4526
871.0271	2.5388198	0.86665827	3676.8188
872.02808	2.5447829	0.86849284	3683.4917
873.02905	2.5470281	0.87033981	3683.3179
874.03003	2.5498278	0.87196952	3678.6484
875.03101	2.5525727	0.87345368	3673.6604
876.03198	2.5563538	0.87501395	3676.907
877.03296	2.5592737	0.87664515	3679.4434
878.03394	2.5649555	0.87828833	3689.5291
879.03491	2.5666568	0.88012356	3682.8843
880.03589	2.5691164	0.88175231	3683.3523
881.03687	2.5710888	0.88350546	3682.9287
882.03784	2.5724044	0.8852371	3684.635
883.03882	2.5756969	0.88697296	3677.7241
884.03979	2.579284	0.88854408	3671.3562
885.04077	2.5831988	0.89003724	3682.5159
886.04175	2.5864635	0.89157665	3677.7131
887.04272	2.5874774	0.89328676	3682.1636
888.0437	2.5884328	0.89540339	3680.3916
889.04468	2.5948958	0.89731598	3678.8467
890.04565	2.5995765	0.89877003	3678.637
891.04663	2.6000125	0.90055823	3683.7725
892.04761	2.604506	0.90239066	3687.0828
893.04858	2.6057949	0.90401655	3678.7732
894.04956	2.6072342	0.90546703	3679.084
895.05054	2.6122119	0.90700263	3684.5461
896.05151	2.6124325	0.90844351	3673.5132
897.05249	2.618777	0.90987873	3683.4045
898.05347	2.6249778	0.91162783	3683.7339
899.05444	2.6230373	0.91353244	3686.3826
900.05542	2.6286626	0.91529751	3683.4785
901.0564	2.6280584	0.91701752	3680.2393
902.05737	2.6362469	0.91888297	3687.238
903.05835	2.6376073	0.92079705	3683.3174
904.05933	2.6411085	0.92259771	3684.5981
905.0603	2.6424384	0.92438078	3682.8005
906.06128	2.6452405	0.92601246	3685.7178
907.06226	2.6476357	0.92815781	3688.7886
908.06323	2.6509175	0.9300167	3678.9009
909.06421	2.6527691	0.93155086	3676.8484
910.06519	2.6561301	0.93314725	3676.3364
911.06616	2.6628332	0.9346332	3680.8582
912.06714	2.6652074	0.93659651	3686.8237
913.06812	2.6670134	0.93821913	3682.3816
914.06909	2.6709447	0.94006121	3684.8928
915.07007	2.6719406	0.94181371	3679.5623
916.07104	2.6755126	0.94369	3683.126
917.07202	2.6786826	0.94542962	3683.6001
918.073	2.6795011	0.94725662	3687.0125
919.07397	2.6865129	0.94908106	3682.656
920.07495	2.6858957	0.95086026	3676.7437
921.07593	2.6918468	0.95272893	3679.9028
922.0769	2.6958809	0.95483965	3691.8694
923.07788	2.6962404	0.95706642	3681.8152
924.07886	2.7006319	0.95908362	3681.2224
925.07983	2.7030475	0.96065021	3685.3318
926.08081	2.7043059	0.96257937	3687.1138
927.08179	2.7091355	0.96452624	3679.3594
928.08276	2.7119193	0.96653563	3670.1465
929.08374	2.7165923	0.96791381	3675.7434
930.08472	2.7166023	0.96961951	3680.2317
931.08569	2.7193351	0.97149938	3681.8274
932.08667	2.7243462	0.97304398	3682.2786
933.08765	2.726898	0.97510117	3682.4976
934.08862	2.7329571	0.97690648	3682.4858
935.0896	2.7304354	0.97871751	3681.9155
936.09058	2.7356875	0.98060793	3682.9834
937.09155	2.7428102	0.98251474	3685.3752
938.09253	2.7404695	0.9845953	3683.2776
939.09351	2.7463121	0.98619056	3682.5264
940.09448	2.7483344	0.98822337	3686.1299
941.09546	2.7508829	0.99007922	3676.7705
942.09644	2.7532923	0.99184787	3677.2727
943.09741	2.754554	0.99359125	3677.7351
944.09839	2.758481	0.99519312	3675.8269
945.09937	2.7610347	0.9971227	3684.103
946.10034	2.7693806	0.99951845	3685.6531
947.10132	2.7688227	1.001913	3683.552
948.10229	2.7712946	1.0038589	3675.0437
949.10327	2.7737176	1.0060426	3678.332
950.10425	2.7767849	1.0079093	3680.9626
951.10522	2.7786977	1.0100702	3685.7637
952.1062	2.7858028	1.0120443	3680.2251
953.10718	2.7850118	1.0137305	3676.0093
954.10815	2.7914848	1.015622	3682.761
955.10913	2.7931223	1.0174251	3682.6594
956.11011	2.7939837	1.0192932	3677.5977
957.11108	2.7978544	1.0213363	3680.0452
958.11206	2.799649	1.023634	3688.0444
959.11304	2.8031166	1.025798	3672.8247
960.11401	2.8075187	1.027503	3680.6863
961.11499	2.8100214	1.0293767	3680.7949
962.11597	2.8122597	1.0312439	3681.9648
963.11694	2.8169672	1.0334539	3679.4939
964.11792	2.8196156	1.0353258	3680.0828
965.1189	2.8243597	1.03736	3684.4736
966.11987	2.8262818	1.0395488	3678.7993
967.12085	2.8272686	1.0417742	3680.6445
968.12183	2.8306401	1.0437188	3674.0957
969.1228	2.8343399	1.045368	3670.0588
970.12378	2.8376787	1.0471996	3679.7136
971.12476	2.8424609	1.049045	3680.8567
972.12573	2.8443053	1.0512065	3676.6865
973.12671	2.8470178	1.0534407	3678.9248
974.12769	2.8479161	1.0557679	3680.0442
975.12866	2.8510563	1.0581288	3670.0583
976.12964	2.8571522	1.059999	3675.0547
977.13062	2.857311	1.0621126	3678.4702
978.13159	2.8628042	1.0643412	3678.1333
979.13257	2.8645868	1.0662857	3676.4722
980.13354	2.8654287	1.0682783	3676.0818
981.13452	2.869195	1.0700576	3674.3474
982.1355	2.8746612	1.0722789	3679.7695
983.13647	2.8762259	1.0742322	3675.644
984.13745	2.8816292	1.0765896	3675.9446
985.13843	2.8826575	1.0788128	3679.9822
986.1394	2.8844037	1.0813658	3679.6914
987.14038	2.8888752	1.0835594	3670.5457
988.14136	2.8924291	1.0855972	3674.8342
989.14233	2.8932097	1.08772	3673.7458
990.14331	2.8984239	1.0901347	3671.7207
991.14429	2.9012895	1.091859	3674.7383
992.14526	2.9027319	1.0938575	3675.6816
993.14624	2.9078233	1.0960511	3672.282
994.14722	2.9089189	1.0981059	3673.1807
995.14819	2.9120646	1.1003939	3676.5815
996.14917	2.9157662	1.1026843	3673.0715
997.15015	2.9199605	1.1047429	3676.2236
998.15112	2.9256437	1.1076633	3677.0461
999.1521	2.9230292	1.1098838	3669.7727
1000.1531	2.9268913	1.1125246	3663.9866
1001.1541	2.9305968	1.1144521	3662.7915
1002.155	2.9342673	1.1162815	3665.1206
1003.156	2.9374573	1.1182535	3673.4719
1004.157	2.9418449	1.1203581	3674.3696
1005.158	2.9428988	1.1224661	3672.8276
1006.1589	2.9481723	1.1248498	3669.2361
1007.1599	2.9474218	1.1274129	3668.9709
1008.1609	2.9525323	1.1300974	3669.1252
1009.1619	2.9559402	1.1322461	3663.1226
1010.1628	2.9574506	1.1345787	3669.0349
1011.1638	2.9582934	1.1366817	3664.467
1012.1648	2.9639661	1.1390109	3670.3789
1013.1658	2.9676893	1.1411685	3668.4937
1014.1667	2.9709506	1.1438596	3670.9172
1015.1677	2.9726431	1.1464124	3671.9529
1016.1687	2.97649	1.1489636	3668.5725
1017.1697	2.9812915	1.151207	3660.4817
1018.1707	2.9809144	1.1534768	3665.4021
1019.1716	2.9846821	1.1558456	3664.6479
1020.1726	2.9884334	1.1580732	3666.7769
1021.1736	2.994451	1.1602844	3664.1121
1022.1746	2.9940627	1.1626127	3658.8708
1023.1755	2.9975648	1.1648599	3669.7229
1024.1765	3.0001211	1.1674775	3664.1631
1025.1775	3.0015426	1.1701052	3661.4761
1026.1785	3.0071163	1.1724634	3666.0281
1027.1794	3.0100982	1.1749413	3662.8237
1028.1804	3.0123668	1.1774658	3663.8186
1029.1814	3.0148857	1.1799301	3660.6956
1030.1824	3.0190904	1.1826969	3658.3525
1031.1833	3.0186708	1.1849854	3656.406
1032.1843	3.0222788	1.1870725	3657.5803
1033.1853	3.0287585	1.1897352	3665.4768
1034.1863	3.029937	1.1925726	3660.9858
1035.1873	3.0322387	1.1955193	3656.5806
1036.1882	3.0335894	1.1978135	3650.2913
1037.1892	3.0389621	1.1999807	3655.9897
1038.1902	3.0399437	1.2024916	3650.1428
1039.1912	3.0480654	1.2048358	3659.5276
1040.1921	3.049382	1.2077334	3658.4211
1041.1931	3.0528407	1.2098987	3646.7693
1042.1941	3.0543618	1.2120247	3649.4512
1043.1951	3.0574584	1.2143283	3656.8047
1044.196	3.0623443	1.2170963	3657.2703
1045.197	3.0613253	1.219884	3653.5261
1046.198	3.0657918	1.2223743	3645.3987
1047.199	3.0663807	1.2245535	3640.3645
1048.2	3.0675931	1.2265589	3643.6401
1049.2009	3.0726583	1.2284191	3640.9866
1050.2019	3.0763888	1.2304223	3644.0283
1051.2029	3.07917	1.2324071	3648.3357
1052.2039	3.0839517	1.2347065	3649.6785
1053.2048	3.0881553	1.2373369	3647.8171
1054.2058	3.0896702	1.2401344	3654.1948
1055.2068	3.0952654	1.243088	3648.5457
1056.2078	3.0972421	1.2459251	3645.8728
1057.2087	3.0994289	1.2487326	3647.2119
1058.2097	3.1040039	1.2514191	3652.1597
1059.2107	3.1063805	1.2544165	3645.4856
1060.2117	3.1078691	1.2572949	3639.7505
1061.2126	3.1091895	1.2598387	3639.3643
1062.2136	3.1147046	1.2624215	3645.23
1063.2146	3.1178188	1.2656065	3645.7971
1064.2156	3.1183701	1.2687083	3644.2766
1065.2166	3.1222279	1.2714822	3635.7415
1066.2175	3.1276536	1.2741148	3629.3879
1067.2185	3.1292219	1.2766122	3638.062
1068.2195	3.1325862	1.2793107	3638.9414
1069.2205	3.1337342	1.2822341	3637.1824
1070.2214	3.1383796	1.2847087	3634.2698
1071.2224	3.1425807	1.2870795	3628.9214
1072.2234	3.143676	1.2895334	3636.9075
1073.2244	3.1466393	1.2922819	3634.1926
1074.2253	3.1494441	1.2956418	3632.957
1075.2263	3.1545279	1.2984933	3630.0635
1076.2273	3.1536922	1.3010449	3621.9783
1077.2283	3.1577666	1.3039674	3628.0769
1078.2292	3.1639714	1.306723	3623.9326
1079.2302	3.1673479	1.3091049	3626.8259
1080.2312	3.1667154	1.3121127	3628.582
1081.2322	3.1735296	1.3150274	3629.2297
1082.2332	3.1757116	1.3179793	3626.2344
1083.2341	3.1790128	1.3208191	3623.8625
1084.2351	3.1801348	1.323681	3621.1963
1085.2361	3.1818168	1.326748	3621.709
1086.2371	3.1858878	1.3298726	3613.7898
1087.238	3.1934536	1.3334286	3621.1367
1088.239	3.1944931	1.3359888	3613.7959
1089.24	3.1972067	1.3383723	3614.4861
1090.241	3.1984935	1.3412015	3614.8967
1091.2419	3.2034454	1.3445846	3624.0796
1092.2429	3.2024994	1.3483816	3612.8538
1093.2439	3.2067888	1.3512758	3605.8418
1094.2449	3.2074323	1.3541443	3610.2244
1095.2458	3.2141278	1.35689	3610.1528
1096.2468	3.216805	1.3598629	3611.0269
1097.2478	3.2182508	1.3630736	3610.6829
1098.2488	3.2220063	1.3663696	3606.9031
1099.2498	3.2276289	1.370039	3606.7954
1100.2507	3.227031	1.3730354	3602.0349
1101.2517	3.2323346	1.3758981	3600.0024
1102.2527	3.2352741	1.3789575	3601.5044
1103.2537	3.236526	1.3820815	3594.4614
1104.2546	3.2393148	1.3849142	3596.7085
1105.2556	3.2414353	1.3880668	3593.6533
1106.2566	3.2473514	1.3913077	3596.0723
1107.2576	3.2476692	1.3945709	3588.709
1108.2585	3.2512448	1.3971666	3587.5344
1109.2595	3.2546716	1.399722	3587.0806
1110.2605	3.2602139	1.4027052	3591.2319
1111.2615	3.2615702	1.405618	3583.5393
1112.2625	3.2646971	1.4083148	3580.6472
1113.2634	3.2678163	1.4110204	3585.1597
1114.2644	3.269634	1.4146707	3583.6843
1115.2654	3.2718408	1.4182193	3579.0852
1116.2664	3.2747285	1.4216168	3573.7134
1117.2673	3.279489	1.424583	3570.7622
1118.2683	3.2845733	1.4276192	3573.9631
1119.2693	3.2879975	1.4308213	3569.9292
1120.2703	3.2881978	1.4338412	3566.7256
1121.2712	3.2916577	1.4365389	3568.8389
1122.2722	3.2920513	1.4397349	3566.0288
1123.2732	3.2978029	1.4427992	3561.1313
1124.2742	3.2992775	1.4456307	3556.4287
1125.2751	3.3022361	1.4483101	3558.7058
1126.2761	3.3067756	1.451205	3556.6018
1127.2771	3.3099082	1.4540534	3557.4976
1128.2781	3.3129237	1.4575276	3559.394
1129.2791	3.3169706	1.4611436	3556.2385
1130.28	3.3204541	1.4645736	3556.2217
1131.281	3.320226	1.4678211	3543.3257
1132.282	3.323647	1.4704648	3542.8967
1133.283	3.3268447	1.4731294	3536.1917
1134.2839	3.3297658	1.4761871	3543.3499
1135.2849	3.3295197	1.4795516	3538.1208
1136.2859	3.3372138	1.4832633	3537.4412
1137.2869	3.3372254	1.4865876	3532.2798
1138.2878	3.3410225	1.4897399	3532.408
1139.2888	3.3455992	1.4930061	3533.2222
1140.2898	3.3512344	1.4967982	3530.7048
1141.2908	3.3526354	1.5001439	3525.3857
1142.2917	3.3544126	1.5031037	3518.6848
1143.2927	3.3577211	1.5066725	3521.6382
1144.2937	3.3612714	1.5098975	3520.4631
1145.2947	3.3632491	1.5130067	3514.4951
1146.2957	3.3662627	1.516155	3508.074
1147.2966	3.3677888	1.5191741	3508.0034
1148.2976	3.3724611	1.5222882	3506.2229
1149.2986	3.3762894	1.525484	3509.6433
1150.2996	3.3783872	1.5287395	3503.8989
1151.3005	3.379482	1.5316228	3498.855
1152.3015	3.3856075	1.5343865	3494.8672
1153.3025	3.3867323	1.5375735	3494.0842
1154.3035	3.3902345	1.5404853	3487.3848
1155.3044	3.3931119	1.5436014	3485.5642
1156.3054	3.3939185	1.5465827	3479.2075
1157.3064	3.3984704	1.5495093	3484.3491
1158.3074	3.4022973	1.5525888	3483.4138
1159.3083	3.4066217	1.5561275	3482.02
1160.3093	3.4078093	1.5598289	3469.2852
1161.3103	3.4110088	1.5635632	3466.3108
1162.3113	3.4152107	1.5672195	3464.7649
1163.3123	3.4175944	1.5711238	3456.7344
1164.3132	3.4224949	1.5743545	3457.9487
1165.3142	3.4253893	1.5775638	3450.5605
1166.3152	3.425256	1.581013	3447.7107
1167.3162	3.4287343	1.5841262	3436.5967
1168.3171	3.4343462	1.5875499	3439.9463
1169.3181	3.4336028	1.5907091	3431.594
1170.3191	3.4354613	1.5944204	3425.4404
1171.3201	3.4407024	1.5976783	3417.1187
1172.321	3.4469604	1.6009313	3420.572
1173.322	3.4477055	1.6041316	3410.8079
1174.323	3.4466155	1.6075484	3411.7744
1175.324	3.452976	1.611289	3401.1558
1176.325	3.4593992	1.614549	3394.9805
1177.3259	3.4606299	1.6172835	3397.866
1178.3269	3.4649408	1.6206096	3391.6958
1179.3279	3.4664352	1.6247206	3384.738
1180.3289	3.4697738	1.6277955	3378.0305
1181.3298	3.4723058	1.6309528	3369.0486
1182.3308	3.4771199	1.6341741	3366.1792
1183.3318	3.4777336	1.6376774	3353.3784
1184.3328	3.4798663	1.6412824	3347.04
1185.3337	3.48399	1.6457356	3335.5681
1186.3347	3.4900212	1.6508826	3309.6926
1187.3357	3.4897571	1.6566381	3270.1792
1188.3367	3.4934783	1.6610175	3252.2534
1189.3376	3.4963179	1.6649127	3243.5
1190.3386	3.5006473	1.6687207	3227.0632
1191.3396	3.5021584	1.673242	3215.0071
1192.3406	3.5046866	1.6778954	3188.6558
1193.3416	3.5109205	1.6835144	3159.3245
1194.0422	3.5165148	1.697904	3025.1094