File: datasets/am_bench_2022/raw_data/TH2-I/specimen.dat
MTS793|MPT|ENU|1|2|.|/|:|1|0|0|A

Operator Information						Time:	12.746826	Sec	11/3/2021 12:43:15 PM
Operator	Nick Derimow
Project	AM Bench 2022 mini-tensile challenge
Specimen ID	TH2-I
Material	PBF-L Inconel 625
Specimen Width	2.56	mm
Specimen Thickness	1.52	mm
Notes
Operator Information End

Data Acquisition						Time:	1013.7415	Sec	11/3/2021 12:59:56 PM
Time	Axial Displacement	Axial Extensometer	Axial Force
Sec	mm	mm	N
12.861328	0.00096992205	3.8403225e-05	46.850838
13.862305	0.0062439693	9.1522234e-05	57.785564
14.863281	0.0080291843	0.00014364548	66.87561
15.864258	0.0071993759	0.00025481419	77.99205
16.865234	0.012494271	0.00024400823	88.228889
17.866211	0.012547337	0.00042341283	99.228867
18.867188	0.017471021	0.00050843332	111.45694
19.868164	0.021590559	0.00049064879	122.56192
20.869141	0.021052925	0.00059955247	131.56697
21.870117	0.02327594	0.00071630545	144.908
22.871094	0.029147603	0.00074318203	155.3456
23.87207	0.031496678	0.00088264619	170.31798
24.873047	0.034889262	0.00087585615	191.29562
25.874023	0.03520336	0.0010305508	205.93628
26.875	0.04264874	0.0011468296	224.96056
27.875977	0.042340789	0.0012312067	239.40694
28.876953	0.044452395	0.0014052155	259.43814
29.87793	0.050672218	0.0014891409	279.32428
30.878906	0.051582754	0.0016486065	297.43607
31.879883	0.056664564	0.0018313252	323.03625
32.880859	0.060145456	0.0019381922	343.33945
33.881836	0.060630433	0.002050827	360.82736
34.882813	0.06302084	0.0022074159	383.18533
35.883789	0.067745991	0.0023445229	409.49072
36.884766	0.07101538	0.002516744	432.72916
37.885742	0.072361723	0.0025166741	444.3656
38.886719	0.075285308	0.0027311642	471.3811
39.887695	0.078224622	0.0029183538	496.06931
40.888672	0.081067026	0.0030524416	522.58038
41.889648	0.088281594	0.0031868152	541.47485
42.890625	0.087514281	0.00324298	561.95599
43.891602	0.090891033	0.0033829184	583.43787
44.892578	0.091298565	0.0035929992	607.30548
45.893555	0.096779086	0.00382218	634.51062
46.894531	0.099285111	0.0039604837	662.89972
47.895508	0.10143339	0.0040669153	687.49353
48.896484	0.10261438	0.0041837133	708.38678
49.897461	0.10936559	0.0044712052	738.36255
50.898438	0.11101906	0.0046428153	767.80896
51.899414	0.11532321	0.0048548058	798.15961
52.900391	0.11996286	0.0049158991	821.07922
53.901367	0.11761855	0.0051056142	841.27667
54.902344	0.12427823	0.0053047454	872.17206
55.90332	0.12606835	0.0054098209	901.49994
56.904297	0.13060807	0.0056151389	924.09009
57.905273	0.13238837	0.0058877189	962.15979
58.90625	0.13380964	0.0059879748	985.82281
59.907227	0.13875587	0.0061705592	1013.199
60.908203	0.1432292	0.0063935393	1043.818
61.90918	0.14437783	0.0065273033	1073.7273
62.910156	0.1481871	0.0067746947	1104.3129
63.911133	0.14936277	0.0068678525	1127.1509
64.912109	0.14954308	0.00701709	1149.9121
65.913086	0.15549387	0.0072310832	1175.7526
66.914063	0.16063428	0.0074621807	1206.2483
67.915039	0.16090617	0.0076367427	1237.5569
68.916016	0.16514163	0.0077993833	1261.0657
69.916992	0.16824532	0.0079567786	1292.4246
70.917969	0.16884995	0.0081227962	1313.9575
71.918945	0.17612061	0.0082687819	1340.3018
72.919922	0.1767801	0.0084249899	1365.715
73.920898	0.18226463	0.0087380717	1402.1929
74.921875	0.1795533	0.0089278976	1425.6188
75.922852	0.18631937	0.0090516256	1445.0557
76.923828	0.18929453	0.0092413528	1482.3002
77.924805	0.19227728	0.0094002839	1504.3871
78.925781	0.19632429	0.0095429067	1530.5229
79.926758	0.19990101	0.0098926723	1572.6902
80.927734	0.20054719	0.0098914923	1593.0591
81.928711	0.20551042	0.010146951	1621.3167
82.929688	0.20814286	0.010365375	1654.0854
83.930664	0.20857047	0.010513661	1673.5321
84.931641	0.21318825	0.01067749	1699.7001
85.932617	0.21726486	0.010930511	1728.322
86.933594	0.22146328	0.011142568	1761.1504
87.93457	0.22411288	0.011225223	1775.681
88.935547	0.22475746	0.01146221	1798.3334
89.936523	0.22821331	0.011564212	1821.718
90.9375	0.23075186	0.011784409	1847.5854
91.938477	0.23298271	0.011923828	1873.5277
92.939453	0.23812255	0.012167305	1899.9854
93.94043	0.24395877	0.012241483	1923.2151
94.941406	0.2426717	0.01242953	1940.6764
95.942383	0.24536966	0.012572303	1967.6938
96.943359	0.25116822	0.01281386	2002.4324
97.944336	0.24941994	0.012944871	2016.2568
98.945313	0.25626156	0.013070585	2042.9115
99.946289	0.25862062	0.013267209	2067.9231
100.94727	0.26335114	0.013468578	2095.7185
101.94824	0.26219699	0.013583946	2109.9973
102.94922	0.2672081	0.013823223	2136.9277
103.9502	0.27150565	0.013889386	2150.0535
104.95117	0.27154273	0.014022261	2169.6746
105.95215	0.27741894	0.014112722	2190.0496
106.95313	0.27987048	0.014293336	2208.6445
107.9541	0.28123808	0.014417777	2226.665
108.95508	0.28425238	0.014530049	2245.0654
109.95605	0.28952792	0.014763781	2265.9941
110.95703	0.29219615	0.015019121	2288.2544
111.95801	0.29510576	0.015002029	2297.49
112.95898	0.29750621	0.015219138	2320.582
113.95996	0.30183923	0.015413971	2340.6179
114.96094	0.3055512	0.015645823	2364.8423
115.96191	0.30744195	0.015777763	2379.5186
116.96289	0.30934387	0.01594929	2392.6382
117.96387	0.31360453	0.016068155	2407.0298
118.96484	0.3167986	0.01642401	2431.1111
119.96582	0.3196789	0.016446246	2444.9126
120.9668	0.3222529	0.016607683	2453.6741
121.96777	0.32232687	0.016785201	2468.9214
122.96875	0.32662153	0.016801825	2479.5281
123.96973	0.33082384	0.017103475	2494.4951
124.9707	0.3335095	0.017178508	2499.238
125.97168	0.3386921	0.017482124	2528.4941
126.97266	0.34132272	0.017633704	2537.2986
127.97363	0.34483838	0.017690873	2543.4785
128.97461	0.34756875	0.017975111	2561.0146
129.97559	0.35037345	0.018093966	2575.011
130.97656	0.3528696	0.018344352	2578.26
131.97754	0.35717455	0.018500134	2588.6575
132.97852	0.35937011	0.018688681	2599.0583
133.97949	0.36282533	0.018980691	2617.1008
134.98047	0.36643752	0.019137166	2620.3867
135.98145	0.369524	0.019379849	2634.241
136.98242	0.37096417	0.019654678	2640.6504
137.9834	0.37409034	0.019857898	2653.5488
138.98438	0.37953073	0.02008084	2657.5989
139.98535	0.38071355	0.020363407	2674.8586
140.98633	0.38037241	0.020663654	2676.6409
141.9873	0.38910621	0.020877142	2692.4348
142.98828	0.38960469	0.021165758	2699.6619
143.98926	0.39347729	0.021408074	2711.0286
144.99023	0.39373565	0.021726249	2713.4092
145.99121	0.39535964	0.022183023	2727.0742
146.99219	0.40054515	0.022570865	2744.218
147.99316	0.40447655	0.022824062	2746.155
148.99414	0.40548724	0.023139682	2751.7126
149.99512	0.40964159	0.023576122	2769.4346
150.99609	0.41384837	0.023925917	2773.3518
151.99707	0.41549811	0.024353512	2777.645
152.99805	0.41942006	0.024687475	2786.2688
153.99902	0.42170992	0.025263568	2799.3733
155	0.42568231	0.02579096	2809.0664
156.00098	0.42706224	0.026308116	2815.2671
157.00195	0.43169597	0.02676042	2816.1172
158.00293	0.43525288	0.02730717	2826.615
159.00391	0.43538871	0.027692918	2830.0698
160.00488	0.44232887	0.028214108	2843.582
161.00586	0.44094244	0.028777724	2845.7969
162.00684	0.44498488	0.029427115	2853.7717
163.00781	0.45067814	0.029973814	2859.5569
164.00879	0.45306855	0.030636786	2867.208
165.00977	0.4551613	0.0313471	2875.3699
166.01074	0.45982328	0.031955831	2877.0608
167.01172	0.4599452	0.03259116	2876.5664
168.0127	0.46586037	0.033258427	2892.6553
169.01367	0.46677294	0.033840764	2890.4331
170.01465	0.47038636	0.034592371	2897.1863
171.01563	0.4749406	0.035348177	2909.3074
172.0166	0.47492054	0.036035519	2909.5254
173.01758	0.48199248	0.036766637	2916.7336
174.01855	0.48128337	0.037522808	2925.1907
175.01953	0.48335004	0.038396798	2925.9207
176.02051	0.48984116	0.039348677	2937.2073
177.02148	0.49177778	0.040045548	2936.092
178.02246	0.49339637	0.040853895	2939.6318
179.02344	0.49979213	0.041590307	2939.0029
180.02441	0.50035805	0.042272449	2944.7039
181.02539	0.50144994	0.043186273	2953.7151
182.02637	0.50809878	0.044033118	2962.6479
183.02734	0.51263046	0.044868793	2959.5974
184.02832	0.51412803	0.045911994	2973.8796
185.0293	0.51540202	0.046729919	2969.0957
186.03027	0.51992553	0.047630806	2974.6726
187.03125	0.52053386	0.048409581	2968.7524
188.03223	0.52585644	0.049221031	2978.4233
189.0332	0.52766806	0.050278194	2988.439
190.03418	0.5311498	0.051065192	2985.3555
191.03516	0.53436917	0.051946558	2990.3706
192.03613	0.53686345	0.053065259	2998.2639
193.03711	0.54214817	0.054136079	3002.8958
194.03809	0.54092127	0.055059899	3002.9265
195.03906	0.54650021	0.055904832	3000.9329
196.04004	0.55069119	0.056946665	3015.5662
197.04102	0.55239326	0.057880275	3011.5979
198.04199	0.5571987	0.058867715	3013.6528
199.04297	0.55889845	0.059807431	3015.1311
200.04395	0.56213486	0.060519498	3020.2471
201.04492	0.56169885	0.061431672	3020.1917
202.0459	0.56641042	0.062279947	3021.9604
203.04688	0.57172698	0.063253544	3037.1421
204.04785	0.57194066	0.064231485	3031.313
205.04883	0.57936662	0.065148517	3036.8618
206.0498	0.57594049	0.065974653	3036.2227
207.05078	0.58331215	0.066876806	3043.8643
208.05176	0.58658481	0.067934208	3047.5215
209.05273	0.588754	0.068992384	3051.1992
210.05371	0.59190536	0.070108473	3049.21
211.05469	0.59327316	0.070898317	3046.8857
212.05566	0.59733677	0.071942024	3055.4519
213.05664	0.60146385	0.073015578	3061.6379
214.05762	0.60242867	0.07400275	3067.8518
215.05859	0.60705298	0.074883603	3068.1233
216.05957	0.61022264	0.075838864	3070.8447
217.06055	0.61097497	0.07693205	3071.6155
218.06152	0.61409134	0.078082338	3075.9592
219.0625	0.61955613	0.079180136	3075.0437
220.06348	0.6242348	0.08019799	3082.6575
221.06445	0.62384772	0.08115685	3084.594
222.06543	0.62665409	0.082231	3086.2329
223.06641	0.63247538	0.083315395	3085.2119
224.06738	0.6359058	0.084444389	3097.198
225.06836	0.63850057	0.085346602	3088.4138
226.06934	0.63983494	0.086575441	3100.3103
227.07031	0.63994193	0.087664582	3096.5044
228.07129	0.64496869	0.088766836	3101.428
229.07227	0.64631069	0.089680567	3101.7927
230.07324	0.65029252	0.09071818	3104.5171
231.07422	0.65480351	0.091615193	3102.9182
232.0752	0.6596182	0.092641428	3110.752
233.07617	0.65807539	0.093670167	3110.5574
234.07715	0.6637283	0.094593197	3111.4309
235.07813	0.66572988	0.09540008	3118.7053
236.0791	0.66791517	0.096496724	3117.5173
237.08008	0.67131078	0.097747497	3124.335
238.08105	0.67291588	0.098760553	3121.6218
239.08203	0.67652911	0.100019	3127.3433
240.08301	0.68417549	0.10118706	3132.0986
241.08398	0.68435663	0.10209764	3127.5344
242.08496	0.68648261	0.10311705	3132.8088
243.08594	0.68876666	0.1041982	3136.4097
244.08691	0.69388807	0.10527481	3140.6101
245.08789	0.69853866	0.10611951	3138.3481
246.08887	0.70302957	0.10697697	3142.0652
247.08984	0.70399505	0.10781586	3146.1702
248.09082	0.70515883	0.10884164	3149.9832
249.0918	0.70841509	0.10995045	3151.6636
250.09277	0.7151891	0.11096062	3158.4333
251.09375	0.71506065	0.11200961	3155.4832
252.09473	0.71649426	0.11317399	3151.8293
253.0957	0.71983808	0.11417322	3158.9551
254.09668	0.72532415	0.11533282	3162.8538
255.09766	0.72824621	0.11633544	3161.853
256.09863	0.72734761	0.11716012	3157.7771
257.09961	0.732032	0.11837925	3165.6904
258.10059	0.73808253	0.11941487	3166.3442
259.10156	0.74044472	0.12035719	3172.7302
260.10254	0.74040991	0.12146898	3168.8867
261.10352	0.74620479	0.12242594	3172.9885
262.10449	0.74684238	0.12334776	3173.6216
263.10547	0.75092947	0.12444903	3177.4395
264.10645	0.75320417	0.12558122	3181.5996
265.10742	0.75702941	0.12667429	3181.5007
266.1084	0.75793296	0.12791725	3180.3406
267.10938	0.76204491	0.12884715	3179.998
268.11035	0.76401454	0.12988511	3186.8245
269.11133	0.7667014	0.13106282	3195.4473
270.1123	0.77002406	0.13216487	3192.3896
271.11328	0.77460229	0.13321294	3189.3284
272.11426	0.77748734	0.13412368	3189.7834
273.11523	0.78002203	0.13514496	3196.1189
274.11621	0.78349531	0.13615569	3199.2981
275.11719	0.78653014	0.13726895	3201.8782
276.11816	0.79081416	0.13836241	3197.1533
277.11914	0.79094976	0.13939062	3202.8948
278.12012	0.79712164	0.14050917	3209.1204
279.12109	0.79664135	0.14141028	3203.1992
280.12207	0.80029374	0.14222619	3200.3242
281.12305	0.80627853	0.14316098	3203.6069
282.12402	0.80696243	0.14408515	3215.5273
283.125	0.810709	0.14495799	3210.3264
284.12598	0.81492889	0.14594854	3217.0088
285.12695	0.81595522	0.14688061	3222.8347
286.12793	0.81893325	0.1479727	3218.3667
287.12891	0.82211369	0.14925538	3226.0662
288.12988	0.82347417	0.15028487	3223.3784
289.13086	0.83119559	0.15135701	3222.8896
290.13184	0.83123761	0.15244073	3224.1934
291.13281	0.83510405	0.15359323	3228.4111
292.13379	0.83701611	0.15465955	3231.6775
293.13477	0.84169245	0.15557714	3224.085
294.13574	0.84351438	0.15658939	3231.228
295.13672	0.8438223	0.15789881	3240.4121
296.1377	0.85069835	0.15908492	3238.4827
297.13867	0.85150152	0.16004688	3239.2776
298.13965	0.85554338	0.16126181	3243.7051
299.14063	0.85653234	0.16224267	3238.9827
300.1416	0.8608377	0.16328818	3246.9177
301.14258	0.8611024	0.16433316	3248.1985
302.14355	0.86573392	0.16530997	3242.1963
303.14453	0.87095529	0.16650955	3251.6211
304.14551	0.8710016	0.16744043	3247.0906
305.14648	0.87620842	0.16841626	3249.6187
306.14746	0.87985831	0.16960432	3260.5388
307.14844	0.88316011	0.17068078	3254.6494
308.14941	0.8845253	0.17168085	3254.333
309.15039	0.88799667	0.17272395	3257.2434
310.15137	0.89026052	0.17381644	3263.1887
311.15234	0.8938424	0.17459539	3255.3484
312.15332	0.89491051	0.17563394	3261.3013
313.1543	0.89953458	0.17644736	3263.9966
314.15527	0.90310824	0.17747232	3265.5852
315.15625	0.9092086	0.17866077	3275.4207
316.15723	0.90905041	0.17975082	3270.9688
317.1582	0.91425174	0.18085022	3279.7095
318.15918	0.92030108	0.18186793	3279.4355
319.16016	0.91890723	0.18284974	3273.5039
320.16113	0.91986018	0.18389569	3278.2112
321.16211	0.92585886	0.1849093	3276.7004
322.16309	0.92653745	0.18593097	3280.3264
323.16406	0.93044633	0.18694796	3280.106
324.16504	0.93464553	0.18784548	3280.8296
325.16602	0.93579763	0.18889436	3285.5959
326.16699	0.9394725	0.18990429	3287.0266
327.16797	0.94423658	0.19110271	3299.0481
328.16895	0.9456718	0.19236445	3289.1125
329.16992	0.9504652	0.19349338	3303.9949
330.1709	0.9523952	0.19453478	3298.8259
331.17188	0.95729285	0.19574532	3299.4719
332.17285	0.9596827	0.19681707	3292.2207
333.17383	0.96028185	0.1977108	3294.3406
334.1748	0.9646259	0.1986932	3296.9839
335.17578	0.9655292	0.19962646	3300.8174
336.17676	0.96968454	0.200663	3301.426
337.17773	0.97180456	0.20164108	3301.4138
338.17871	0.97552967	0.20254682	3302.7427
339.17969	0.98097885	0.20356548	3309.3462
340.18066	0.98366797	0.20475888	3315.8416
341.18164	0.985605	0.20596984	3310.1167
342.18262	0.9857415	0.20696527	3310.5134
343.18359	0.99223399	0.20818815	3314.8547
344.18457	0.99520284	0.20920722	3314.8455
345.18555	0.99421257	0.21011457	3312.6882
346.18652	0.99840254	0.21099058	3316.3708
347.1875	0.99868757	0.21191956	3316.2048
348.18848	1.0065459	0.21313693	3324.7671
349.18945	1.005864	0.21416199	3319.8496
350.19043	1.009249	0.21491565	3320.1824
351.19141	1.0156758	0.21589333	3324.9585
352.19238	1.0191851	0.21684715	3329.5552
353.19336	1.0186962	0.21776274	3323.4724
354.19434	1.0217035	0.21886218	3333.9446
355.19531	1.0243592	0.21991661	3328.1885
356.19629	1.0268766	0.22112627	3337.4277
357.19727	1.031104	0.22199106	3324.4402
358.19824	1.0316001	0.2230134	3333.6113
359.19922	1.0377828	0.22428733	3341.5481
360.2002	1.0424591	0.22540404	3333.8633
361.20117	1.0434799	0.22644605	3335.3748
362.20215	1.0505528	0.22734822	3340.4397
363.20313	1.052066	0.22841983	3343.4792
364.2041	1.0530429	0.22932948	3343.8896
365.20508	1.0567893	0.23037073	3345.821
366.20605	1.0605055	0.23140576	3348.7664
367.20703	1.0639235	0.23245214	3347.8381
368.20801	1.0645968	0.23340799	3353.6648
369.20898	1.0667034	0.23458508	3352.2019
370.20996	1.0729134	0.23569402	3355.0618
371.21094	1.0722172	0.23686528	3357.7017
372.21191	1.0792243	0.23802043	3356.7463
373.21289	1.0811362	0.23894218	3353.0452
374.21387	1.084304	0.24010846	3356.1858
375.21484	1.0870715	0.24109462	3356.4451
376.21582	1.0914735	0.24224451	3362.5386
377.2168	1.0950044	0.2431348	3362.3906
378.21777	1.0967	0.24406601	3360.6235
379.21875	1.0983108	0.24500318	3365.0588
380.21973	1.1042923	0.24598815	3367.0498
381.2207	1.1056447	0.24693203	3369.7664
382.22168	1.1094844	0.24809161	3373.6201
383.22266	1.1145871	0.24935699	3374.3926
384.22363	1.1138843	0.25020221	3371.3784
385.22461	1.1160189	0.25141495	3372.6467
386.22559	1.1174073	0.25235447	3370.6399
387.22656	1.1243603	0.25353253	3379.4543
388.22754	1.1273699	0.2547074	3381.5034
389.22852	1.1270669	0.25565025	3376.7097
390.22949	1.1323321	0.25675455	3381.2227
391.23047	1.1365949	0.25768155	3381.8022
392.23145	1.1380764	0.25873262	3381.9644
393.23242	1.1394776	0.25980857	3382.6995
394.2334	1.1448723	0.26064768	3384.3083
395.23438	1.1452401	0.26165569	3388.0898
396.23535	1.151458	0.26273406	3387.552
397.23633	1.1517351	0.26392215	3387.3896
398.2373	1.1576931	0.26513568	3398.5776
399.23828	1.1568669	0.26615191	3387.9695
400.23926	1.1618353	0.26715097	3391.1096
401.24023	1.1633724	0.26815686	3395.5601
402.24121	1.1679838	0.26918337	3392.5747
403.24219	1.1700757	0.27029276	3390.854
404.24316	1.1744785	0.27122822	3397.8569
405.24414	1.177609	0.27247724	3402.4473
406.24512	1.1766202	0.27358475	3399.2815
407.24609	1.180634	0.27464509	3395.8479
408.24707	1.1863831	0.27568701	3404.7607
409.24805	1.1842622	0.27651629	3394.9204
410.24902	1.1923804	0.27740553	3403.9275
411.25	1.1949409	0.27850512	3406.5906
412.25098	1.1965145	0.27964044	3407.7617
413.25195	1.2030796	0.28071901	3414.8279
414.25293	1.2046732	0.28184482	3415.1699
415.25391	1.2072009	0.28301063	3413.7473
416.25488	1.2105895	0.28409508	3417.8711
417.25586	1.2168112	0.28506315	3415.822
418.25684	1.2147727	0.28611973	3413.4307
419.25781	1.2187947	0.28696975	3415.5535
420.25879	1.2225181	0.28801501	3413.4089
421.25977	1.2244285	0.28901058	3418.4761
422.26074	1.2313024	0.29016313	3427.0293
423.26172	1.2311873	0.29097137	3415.7637
424.2627	1.231835	0.2917119	3409.8171
425.26367	1.236261	0.29261124	3422.5662
426.26465	1.2417279	0.29360899	3431.1306
427.26563	1.2410117	0.29465204	3421.552
428.2666	1.243016	0.29567805	3427.4136
429.26758	1.2501777	0.29671443	3432.4512
430.26855	1.2531534	0.29783601	3432.0203
431.26953	1.2541788	0.2989209	3431.5986
432.27051	1.2611613	0.3001256	3438.1357
433.27148	1.2597439	0.30116543	3430.3696
434.27246	1.2649074	0.30229428	3438.0005
435.27344	1.2652738	0.30327654	3431.3992
436.27441	1.2687966	0.30443808	3438.4275
437.27539	1.2707293	0.30535254	3436.5654
438.27637	1.2775548	0.30619782	3435.6794
439.27734	1.2779995	0.30718881	3437.3826
440.27832	1.2853618	0.30823272	3444.9387
441.2793	1.2815726	0.30940503	3444.219
442.28027	1.2858891	0.31038931	3439.8552
443.28125	1.2917314	0.31152412	3449.9741
444.28223	1.2957904	0.31269076	3454.1194
445.2832	1.2945625	0.3138977	3452.3503
446.28418	1.3015598	0.3149775	3447.9983
447.28516	1.3007367	0.316084	3448.6169
448.28613	1.3079761	0.31716311	3453.2183
449.28711	1.3080094	0.31796443	3446.606
450.28809	1.3106004	0.31906757	3456.2224
451.28906	1.3144491	0.3202664	3459.7725
452.29004	1.3190811	0.32145727	3460.7473
453.29102	1.3205723	0.32260722	3454.5889
454.29199	1.3243704	0.32365891	3459.4768
455.29297	1.3252562	0.32485306	3459.2173
456.29395	1.3292819	0.32576957	3449.2898
457.29492	1.3348522	0.32662508	3461.5813
458.2959	1.336066	0.32746685	3465.0847
459.29688	1.3403677	0.32858786	3468.2485
460.29785	1.3433588	0.32964361	3464.0044
461.29883	1.3435931	0.33077019	3462.7869
462.2998	1.3477383	0.33165026	3466.2966
463.30078	1.3537498	0.33277833	3472.1621
464.30176	1.3507725	0.33380741	3466.9016
465.30273	1.3551687	0.33497146	3471.6794
466.30371	1.359616	0.33589017	3473.3279
467.30469	1.362628	0.33682823	3472.8298
468.30566	1.367503	0.33791375	3476.8196
469.30664	1.3703547	0.33897284	3469.7188
470.30762	1.3716203	0.34009665	3480.8247
471.30859	1.375312	0.34121716	3486.5835
472.30957	1.3784304	0.34238201	3483.4478
473.31055	1.3805906	0.34359384	3487.939
474.31152	1.3859504	0.34477982	3483.5151
475.3125	1.3871316	0.34601599	3487.3872
476.31348	1.389588	0.34693855	3482.8987
477.31445	1.3944724	0.34792933	3483.7319
478.31543	1.3981649	0.34889463	3481.6973
479.31641	1.3974082	0.34980136	3480.5334
480.31738	1.40074	0.35088214	3487.2988
481.31836	1.4064991	0.35200003	3498.6843
482.31934	1.4070063	0.35307685	3492.9905
483.32031	1.407443	0.35434207	3494.5962
484.32129	1.4154831	0.35563743	3497.0852
485.32227	1.4162378	0.35671267	3493.8726
486.32324	1.420089	0.35773629	3499.6162
487.32422	1.4214529	0.35897854	3499.8215
488.3252	1.4256483	0.35990819	3494.5378
489.32617	1.4310122	0.36108428	3501.8672
490.32715	1.4318703	0.36183479	3492.6309
491.32813	1.4305539	0.36276019	3497.0154
492.3291	1.4399642	0.36369872	3498.2173
493.33008	1.4404252	0.3647328	3505.2798
494.33105	1.4428283	0.36568454	3500.4136
495.33203	1.446825	0.36673686	3503.7661
496.33301	1.4501022	0.36753923	3501.3708
497.33398	1.4541625	0.36850554	3505.2302
498.33496	1.4560019	0.36965114	3513.6064
499.33594	1.4569101	0.37088934	3517.0398
500.33691	1.4616138	0.37182179	3502.5164
501.33789	1.4647433	0.3730548	3509.6462
502.33887	1.4704407	0.37407169	3514.2803
503.33984	1.4699975	0.37530342	3517.3403
504.34082	1.4720653	0.37643102	3513.9834
505.3418	1.4767234	0.37758163	3516.9768
506.34277	1.4790584	0.37893805	3520.5889
507.34375	1.4836448	0.37981588	3512.3179
508.34473	1.4849114	0.380934	3520.1184
509.3457	1.4894814	0.38195336	3518.0559
510.34668	1.490183	0.3829293	3517.4778
511.34766	1.4942752	0.38399351	3521.5459
512.34863	1.4994919	0.38518161	3527.4236
513.34961	1.5025749	0.38611931	3522.5623
514.35059	1.5039639	0.38716614	3521.8181
515.35156	1.5054704	0.388459	3530.5195
516.35254	1.5100738	0.38984886	3526.5669
517.35352	1.5138056	0.39089414	3521.6553
518.35449	1.5183277	0.39174518	3526.2402
519.35547	1.5205116	0.39289123	3527.6514
520.35645	1.5206648	0.39400998	3530.8276
521.35742	1.5245659	0.39497247	3526.6257
522.3584	1.5266278	0.39599544	3526.4995
523.35938	1.5322872	0.39710441	3530.9783
524.36035	1.5350691	0.39809486	3534.8928
525.36133	1.5402459	0.39916614	3533.843
526.3623	1.5395018	0.40035298	3537.9368
527.36328	1.5412585	0.40132704	3533.0029
528.36426	1.5466913	0.4024384	3544.387
529.36523	1.5506119	0.40352169	3541.1899
530.36621	1.5502404	0.40489459	3546.2532
531.36719	1.5543605	0.40601689	3536.8152
532.36816	1.5572523	0.40704149	3541.2788
533.36914	1.5620104	0.40806019	3538.2266
534.37012	1.5635782	0.4089756	3541.7808
535.37109	1.5696304	0.41028833	3548.0085
536.37207	1.5708938	0.41143239	3541.9829
537.37305	1.574378	0.41262451	3547.2522
538.37402	1.5762589	0.41356158	3543.7563
539.375	1.5776505	0.41468155	3545.8528
540.37598	1.583621	0.41592324	3549.509
541.37695	1.5855407	0.41715381	3551.5581
542.37793	1.5881988	0.41821706	3544.9219
543.37891	1.5928972	0.41927493	3553.9529
544.37988	1.5956635	0.4204345	3551.5564
545.38086	1.5967814	0.42129779	3553.4346
546.38184	1.5991548	0.42247671	3558.0449
547.38281	1.6052573	0.4235546	3560.0244
548.38379	1.6051085	0.42457855	3557.718
549.38477	1.6090512	0.42581734	3557.8616
550.38574	1.6104003	0.4270359	3560.0442
551.38672	1.6108001	0.42805952	3558.2227
552.3877	1.6169283	0.42926762	3556.0874
553.38867	1.6228207	0.43055946	3562.7786
554.38965	1.625861	0.43183318	3565.0012
555.39063	1.629366	0.43286845	3565.7563
556.3916	1.6313905	0.43383914	3559.626
557.39258	1.63508	0.43485224	3562.3989
558.39355	1.6378149	0.43589896	3564.8699
559.39453	1.6404778	0.43698502	3567.8484
560.39551	1.6403033	0.43799692	3562.7593
561.39648	1.6473557	0.43919301	3569.6416
562.39746	1.6473781	0.44052172	3574.5945
563.39844	1.6508366	0.44186848	3572.5027
564.39941	1.6555654	0.44302234	3566.6494
565.40039	1.6558105	0.44381446	3565.0354
566.40137	1.660941	0.44471556	3565.5542
567.40234	1.6661274	0.44573122	3572.177
568.40332	1.6675698	0.44651026	3569.0791
569.4043	1.6686838	0.44761333	3577.2224
570.40527	1.6725281	0.44880044	3579.9285
571.40625	1.6770058	0.44994646	3579.9841
572.40723	1.6809497	0.45104161	3581.8145
573.4082	1.6812338	0.45233023	3582.5879
574.40918	1.6852714	0.45350111	3579.7949
575.41016	1.6906461	0.45476615	3587.4509
576.41113	1.6922542	0.45583895	3580.0508
577.41211	1.6926174	0.45697349	3580.1221
578.41309	1.6967736	0.45807976	3582.5579
579.41406	1.6979675	0.45896754	3575.9126
580.41504	1.7018194	0.46013457	3583.8015
581.41602	1.7047633	0.46121183	3585.0803
582.41699	1.7053432	0.46214017	3583.26
583.41797	1.7117419	0.4632293	3592.4619
584.41895	1.7157004	0.46461925	3592.0583
585.41992	1.7193419	0.46594027	3591.9658
586.4209	1.7189322	0.46701854	3590.8564
587.42188	1.723117	0.4682163	3587.8513
588.42285	1.7251487	0.46917185	3586.9626
589.42383	1.7277132	0.4702943	3584.2188
590.4248	1.7304758	0.47154954	3598.0244
591.42578	1.7364235	0.4728432	3593.9458
592.42676	1.7392962	0.4739764	3593.6431
593.42773	1.7420999	0.47524825	3597.6169
594.42871	1.7432224	0.47627917	3592.9485
595.42969	1.7459283	0.47760698	3600.874
596.43066	1.7539089	0.47881702	3598.5454
597.43164	1.7516882	0.47981128	3592.0815
598.43262	1.7582121	0.48096091	3602.7476
599.43359	1.7561458	0.48196003	3600.0596
600.43457	1.7614069	0.48319566	3602.9768
601.43555	1.7680737	0.48452324	3606.4023
602.43652	1.7683215	0.48568824	3602.533
603.4375	1.7735488	0.48659962	3598.8008
604.43848	1.7716197	0.48777631	3605.5952
605.43945	1.7779073	0.48911649	3608.8313
606.44043	1.7820605	0.49016514	3604.1729
607.44141	1.7828156	0.49128258	3602.1917
608.44238	1.7883354	0.49235281	3603.5203
609.44336	1.7904612	0.49340686	3603.6113
610.44434	1.7951192	0.49470749	3609.137
611.44531	1.7937238	0.49600703	3607.1914
612.44629	1.798241	0.49721068	3608.3931
613.44727	1.8000395	0.49835318	3607.9248
614.44824	1.8060534	0.49958441	3606.9536
615.44922	1.8057278	0.50067443	3613.4648
616.4502	1.8117075	0.50196654	3615.7849
617.45117	1.8128809	0.50284272	3606.2349
618.45215	1.817175	0.50394696	3609.3669
619.45313	1.819536	0.50507927	3611.9343
620.4541	1.8243945	0.50629413	3620.8677
621.45508	1.8251363	0.50760502	3618.4041
622.45605	1.827719	0.50880957	3610.5989
623.45703	1.8340509	0.50985098	3616.1145
624.45801	1.8339474	0.51110888	3619.7573
625.45898	1.8377625	0.51245463	3623.1851
626.45996	1.8437442	0.51374054	3623.0737
627.46094	1.8417941	0.51494491	3619.6472
628.46191	1.8465815	0.51588315	3619.2903
629.46289	1.849201	0.51694417	3623.2876
630.46387	1.8532596	0.51818687	3618.9731
631.46484	1.8561981	0.51934743	3623.0991
632.46582	1.8592923	0.52043045	3623.2417
633.4668	1.8601619	0.52155763	3628.2808
634.46777	1.8660342	0.52300608	3625.6411
635.46875	1.8675432	0.52417004	3624.6753
636.46973	1.8711224	0.52528739	3621.2207
637.4707	1.8721346	0.52657586	3627.2952
638.47168	1.8754928	0.52783662	3625.4614
639.47266	1.8815129	0.52904916	3628.9224
640.47363	1.883598	0.53027701	3626.283
641.47461	1.8850286	0.53143567	3627.8704
642.47559	1.889415	0.53271317	3631.3054
643.47656	1.8920627	0.53388989	3628.6677
644.47754	1.895952	0.5351553	3631.2312
645.47852	1.899094	0.53635061	3634.6367
646.47949	1.9024607	0.53747904	3633.3928
647.48047	1.9028586	0.53863537	3629.5103
648.48145	1.909649	0.53997773	3635.6882
649.48242	1.9104065	0.54119074	3633.8364
650.4834	1.9144484	0.54240549	3636.0361
651.48438	1.9152193	0.54352534	3631.2256
652.48535	1.9186742	0.54494059	3636.4163
653.48633	1.9204503	0.54626876	3639.3591
654.4873	1.9254314	0.5474025	3636.3557
655.48828	1.9287916	0.54863435	3637.7769
656.48926	1.9305843	0.54994911	3645.2148
657.49023	1.9336292	0.55130476	3642.2754
658.49121	1.9357109	0.55250353	3639.9929
659.49219	1.9404391	0.55378783	3645.5464
660.49316	1.9437941	0.55526787	3642.3262
661.49414	1.9440901	0.55658501	3643.0127
662.49512	1.949383	0.55777532	3642.2666
663.49609	1.9524685	0.55882251	3638.595
664.49707	1.9565675	0.55994129	3639.1426
665.49805	1.9613382	0.5611732	3643.3494
666.49902	1.9591429	0.56241065	3640.9973
667.5	1.9637614	0.56352633	3643.2925
668.50098	1.9652113	0.56513989	3651.8506
669.50195	1.9700503	0.56652445	3650.1875
670.50293	1.9726758	0.56772465	3645.6201
671.50391	1.9748505	0.56879193	3642.282
672.50488	1.9797969	0.56986165	3645.302
673.50586	1.9805431	0.57101375	3645.4629
674.50684	1.9844038	0.57228208	3651.1226
675.50781	1.9884307	0.57339138	3649.1638
676.50879	1.9919608	0.57456446	3648.8196
677.50977	1.9910377	0.57571161	3647.4409
678.51074	1.9973418	0.57710242	3654.9724
679.51172	1.9998478	0.57855749	3655.5764
680.5127	2.00193	0.58007264	3654.7739
681.51367	2.005192	0.58148199	3654.1665
682.51465	2.007535	0.58279228	3649.79
683.51563	2.010319	0.5840643	3652.1873
684.5166	2.014864	0.58511674	3651.1326
685.51758	2.0184307	0.58626014	3658.4063
686.51855	2.0179152	0.58756143	3652.7747
687.51953	2.0221703	0.58895051	3661.1611
688.52051	2.0266042	0.59029323	3655.2993
689.52148	2.0299695	0.59169793	3661.9014
690.52246	2.0331552	0.59296936	3654.6919
691.52344	2.0349598	0.5942173	3659.6953
692.52441	2.0382929	0.59575415	3663.1943
693.52539	2.0429449	0.59720063	3661.3777
694.52637	2.0454931	0.59843671	3657.6843
695.52734	2.0482006	0.59984064	3659.1101
696.52832	2.0501759	0.60108727	3660.5095
697.5293	2.0548239	0.60239625	3664.1365
698.53027	2.0581894	0.60370964	3659.3901
699.53125	2.0610058	0.60487145	3662.9551
700.53223	2.0645676	0.60606182	3657.8323
701.5332	2.0656211	0.60709274	3654.7646
702.53418	2.0682905	0.60827178	3662.1289
703.53516	2.0700083	0.609649	3670.3987
704.53613	2.076401	0.61119312	3668.8167
705.53711	2.0796888	0.61245	3666.4182
706.53809	2.0815215	0.61348492	3662.0872
707.53906	2.0835145	0.61489105	3666.9834
708.54004	2.0912166	0.61619407	3669.863
709.54102	2.0880752	0.61724448	3659.9126
710.54199	2.0920496	0.61839759	3661.772
711.54297	2.0955353	0.61956167	3668.4436
712.54395	2.0984209	0.62088418	3666.7087
713.54492	2.1012828	0.62218362	3666.3716
714.5459	2.1053073	0.62360346	3672.0688
715.54688	2.1099615	0.62488317	3671.5754
716.54785	2.1104271	0.62626165	3673.8574
717.54883	2.1111584	0.62756395	3666.9504
718.5498	2.1162229	0.62876701	3667.4316
719.55078	2.1185865	0.63003409	3667.4033
720.55176	2.1210325	0.63139421	3675.2576
721.55273	2.1251006	0.63297963	3674.2703
722.55371	2.1284904	0.63444304	3670.3752
723.55469	2.1303959	0.63574153	3672.4546
724.55566	2.1368597	0.63724124	3676.3784
725.55664	2.1373596	0.6384961	3677.0188
726.55762	2.138263	0.63978726	3672.5085
727.55859	2.1430781	0.64124322	3680.1255
728.55957	2.1473367	0.64280009	3671.239
729.56055	2.1493783	0.64421213	3671.0674
730.56152	2.1535954	0.6454317	3672.5906
731.5625	2.1554933	0.64669186	3670.4463
732.56348	2.1616213	0.64802676	3680.4729
733.56445	2.1641309	0.64946145	3678.0056
734.56543	2.1647501	0.65070468	3672.969
735.56641	2.1704183	0.65224487	3675.7817
736.56738	2.1705899	0.65358871	3680.3157
737.56836	2.1746578	0.65501183	3676.7419
738.56934	2.1752572	0.65632755	3675.4194
739.57031	2.1782019	0.65790421	3676.3865
740.57129	2.1832764	0.65936643	3674.4597
741.57227	2.1865547	0.66090655	3678.6306
742.57324	2.1908655	0.66205078	3678.0947
743.57422	2.1916521	0.66337591	3679.1968
744.5752	2.1945095	0.66487241	3678.6138
745.57617	2.1973226	0.66628236	3676.509
746.57715	2.202255	0.66763264	3684.6321
747.57813	2.2026942	0.66902101	3683.1616
748.5791	2.2062802	0.67051685	3679.8853
749.58008	2.2121339	0.672014	3684.761
750.58105	2.2120926	0.67335194	3682.4929
751.58203	2.2143083	0.67472249	3680.6599
752.58301	2.2184205	0.67621076	3679.4004
753.58398	2.2231567	0.67760158	3682.929
754.58496	2.225992	0.67902088	3682.551
755.58594	2.2301471	0.68052721	3684.395
756.58691	2.2333117	0.68197095	3689.3909
757.58789	2.2340169	0.68347532	3684.0955
758.58887	2.2337997	0.68509692	3680.323
759.58984	2.2397294	0.68652284	3679.0344
760.59082	2.240725	0.68771988	3676.4299
761.5918	2.2446373	0.68899429	3684.8704
762.59277	2.2471595	0.69064593	3691.5938
763.59375	2.2511318	0.69241172	3690.9094
764.59473	2.2555416	0.69412583	3694.7839
765.5957	2.2548058	0.69579929	3681.0613
766.59668	2.2598786	0.69720483	3682.2375
767.59766	2.2636466	0.69852102	3683.9968
768.59863	2.2703674	0.69989818	3685.606
769.59961	2.2682447	0.70155674	3689.6777
770.60059	2.2744789	0.70306927	3687.3313
771.60156	2.2769582	0.70444059	3691.1597
772.60254	2.2805958	0.70572829	3687.4092
773.60352	2.2837989	0.70717114	3687.5271
774.60449	2.2823095	0.70858884	3681.1626
775.60547	2.2881091	0.71003795	3688.5969
776.60645	2.2910655	0.71167129	3689.3586
777.60742	2.2959454	0.71313232	3692.4087
778.6084	2.2997286	0.71464527	3690.5679
779.60938	2.3007324	0.71600896	3693.9749
780.61035	2.3038125	0.71722728	3687.4575
781.61133	2.3095403	0.71885759	3691.8176
782.6123	2.3105359	0.72035277	3695.8159
783.61328	2.3109627	0.72175169	3686.9009
784.61426	2.3163824	0.72318965	3690.8752
785.61523	2.3179429	0.72457141	3686.0256
786.61621	2.3205564	0.72597963	3686.0676
787.61719	2.3236449	0.72740585	3687.425
788.61816	2.3283896	0.72878152	3690.1694
789.61914	2.3306456	0.73051274	3691.6357
790.62012	2.3345082	0.73208082	3693.7043
791.62109	2.3386893	0.7338925	3699.3298
792.62207	2.3404357	0.73553061	3690.7388
793.62305	2.3439357	0.73720974	3693.0723
794.62402	2.3436975	0.73868942	3688.4868
795.625	2.3485448	0.74017888	3691.707
796.62598	2.3512924	0.74170852	3692.8857
797.62695	2.3550913	0.74321836	3691.3005
798.62793	2.3569198	0.74497283	3698.9458
799.62891	2.3595324	0.74675012	3694.9009
800.62988	2.3631859	0.7486127	3691.2527
801.63086	2.3652623	0.75014305	3692.314
802.63184	2.369895	0.75177199	3688.6213
803.63281	2.371645	0.75330299	3689.8032
804.63379	2.3796608	0.75486284	3690.4155
805.63477	2.3786807	0.75645351	3696.9878
806.63574	2.3810275	0.75812054	3693.9922
807.63672	2.3848991	0.75959677	3687.2234
808.6377	2.3885946	0.76112723	3697.7153
809.63867	2.3897188	0.76279867	3695.6431
810.63965	2.3921874	0.76444173	3693.6667
811.64063	2.3966737	0.76598835	3689.9617
812.6416	2.3996322	0.76748675	3691.4341
813.64258	2.3999698	0.76919198	3700.4543
814.64355	2.4047141	0.77096611	3695.4678
815.64453	2.4100881	0.77283293	3689.9138
816.64551	2.4116011	0.77426666	3692.8899
817.64648	2.4143651	0.775617	3688.2192
818.64746	2.4168615	0.77708805	3689.1287
819.64844	2.4208868	0.77884316	3700.8008
820.64941	2.4225938	0.78058821	3698.8335
821.65039	2.4250472	0.78225386	3690.0449
822.65137	2.4290762	0.78384978	3695.6287
823.65234	2.4300485	0.7857511	3703.7676
824.65332	2.4353335	0.78761894	3694.5774
825.6543	2.4396596	0.78946793	3698.2036
826.65527	2.4430354	0.79109728	3696.2751
827.65625	2.4458711	0.79273337	3698.7341
828.65723	2.4463792	0.79445237	3698.4458
829.6582	2.4483824	0.79594737	3695.1509
830.65918	2.4566572	0.79753751	3695.6082
831.66016	2.455112	0.7990725	3688.8928
832.66113	2.4596303	0.80073631	3694.8298
833.66211	2.4631674	0.80239642	3693.6729
834.66309	2.4634788	0.80437052	3694.5674
835.66406	2.4684319	0.80638587	3695.4253
836.66504	2.47103	0.80828124	3691.3325
837.66602	2.4720361	0.80995482	3693.6521
838.66699	2.4792399	0.81189972	3699.5476
839.66797	2.4773583	0.8136754	3696.4907
840.66895	2.4831877	0.81541181	3694.8738
841.66992	2.4867215	0.81729627	3693.2622
842.6709	2.4896362	0.81917703	3696.877
843.67188	2.4920902	0.82105881	3694.4619
844.67285	2.4939461	0.82280946	3693.7729
845.67383	2.4968066	0.82471532	3691.4224
846.6748	2.5048988	0.82648951	3695.585
847.67578	2.5047095	0.82812935	3692.7136
848.67676	2.5070179	0.82981378	3694.9331
849.67773	2.5080781	0.83144069	3693.9395
850.67871	2.5127366	0.83355832	3690.5015
851.67969	2.5143497	0.83556587	3694.3738
852.68066	2.520551	0.83757412	3695.4968
853.68164	2.5224507	0.8391971	3688.6116
854.68262	2.5234804	0.84078258	3689.2957
855.68359	2.5260465	0.84264868	3691.8608
856.68457	2.5333114	0.844473	3697.637
857.68555	2.5343823	0.84622127	3692.189
858.68652	2.5379632	0.84784418	3692.9238
859.6875	2.5394185	0.84975761	3697.8081
860.68848	2.5432291	0.85169923	3692.5532
861.68945	2.5431733	0.85360694	3690.1074
862.69043	2.5502911	0.85537982	3691.9805
863.69141	2.5546117	0.85711479	3689.6831
864.69238	2.5560989	0.859137	3691.928
865.69336	2.5578678	0.86124897	3692.7339
866.69434	2.560149	0.86351722	3690.2139
867.69531	2.5657384	0.8656975	3690.5857
868.69629	2.5693235	0.8675372	3691.0703
869.69727	2.5714767	0.86966449	3697.6831
870.69824	2.5737839	0.87197179	3693.856
871.69922	2.5783348	0.87427318	3691.1838
872.7002	2.5804832	0.8762064	3689.0679
873.70117	2.5845191	0.87809563	3686.9575
874.70215	2.583786	0.87981087	3688.3909
875.70313	2.5872426	0.88183445	3684.2754
876.7041	2.5903409	0.88390386	3687.1497
877.70508	2.5947254	0.88613147	3685.5684
878.70605	2.596544	0.88831496	3687.1565
879.70703	2.6039462	0.89039075	3691.3003
880.70801	2.6020055	0.89267826	3693.4475
881.70898	2.6056113	0.89470965	3688.0627
882.70996	2.6073976	0.89658165	3680.885
883.71094	2.6107979	0.89865249	3686.0369
884.71191	2.6167152	0.90081066	3689.6028
885.71289	2.620178	0.90279895	3686.7048
886.71387	2.6232622	0.90480995	3681.6792
887.71484	2.6243525	0.90683705	3690.1028
888.71582	2.6262796	0.90887302	3687.7927
889.7168	2.6314046	0.91139108	3684.9844
890.71777	2.6340537	0.91388685	3688.2273
891.71875	2.6342466	0.91591656	3680.3679
892.71973	2.6400814	0.91808581	3682.9207
893.7207	2.6407552	0.92000961	3680.5576
894.72168	2.6432307	0.92201775	3685.468
895.72266	2.6487706	0.92415959	3684.925
896.72363	2.6522355	0.92651552	3686.6477
897.72461	2.6556315	0.92917311	3687.7717
898.72559	2.658242	0.93153238	3682.0967
899.72656	2.6592934	0.93387884	3683.3381
900.72754	2.6643732	0.93631679	3683.9814
901.72852	2.6665504	0.9388203	3681.0806
902.72949	2.6702459	0.94122553	3679.5767
903.73047	2.6743841	0.94330186	3673.957
904.73145	2.6769898	0.94547373	3680.8396
905.73242	2.6807909	0.94801319	3682.4316
906.7334	2.681459	0.95062393	3681.1855
907.73438	2.6845741	0.95324159	3678.6235
908.73535	2.6884573	0.9558596	3676.1606
909.73633	2.6887197	0.95826578	3675.417
910.7373	2.6914835	0.96036696	3668.6616
911.73828	2.6953685	0.96262598	3672.073
912.73926	2.699472	0.96494561	3674.8726
913.74023	2.7043109	0.96757817	3675.8525
914.74121	2.7050912	0.97037566	3673.5967
915.74219	2.7098682	0.97288841	3677.8596
916.74316	2.7112963	0.97532725	3672.1125
917.74414	2.7131329	0.97828579	3670.3462
918.74512	2.719136	0.98098767	3674.3696
919.74609	2.7208033	0.98333973	3664.5569
920.74707	2.7217684	0.98517811	3655.9009
921.74805	2.7260313	0.98757929	3671.7363
922.74902	2.7298484	0.99003011	3668.6223
923.75	2.7336226	0.9930445	3670.6086
924.75098	2.7372813	0.99596673	3674.0457
925.75195	2.738569	0.9983362	3663.5974
926.75293	2.7430024	1.0011365	3665.6118
927.75391	2.7455261	1.0033631	3657.1729
928.75488	2.747025	1.0056871	3665.179
929.75586	2.7510459	1.0086888	3666.5593
930.75684	2.7547503	1.0114272	3657.9033
931.75781	2.7571497	1.0137724	3658.6003
932.75879	2.760036	1.0167658	3664.3528
933.75977	2.7622612	1.0197874	3662.0876
934.76074	2.7688811	1.0224389	3657.8547
935.76172	2.7691915	1.0246531	3654.262
936.7627	2.7711484	1.027174	3659.7842
937.76367	2.7733655	1.0297937	3655.1882
938.76465	2.779948	1.0329825	3656.2031
939.76563	2.7807097	1.0359567	3654.9509
940.7666	2.7825809	1.03857	3651.1189
941.76758	2.786278	1.0413383	3649.5957
942.76855	2.7908418	1.0443591	3653.9758
943.76953	2.7914846	1.047837	3652.0996
944.77051	2.7973199	1.0508657	3646.5742
945.77148	2.7981331	1.0539156	3650.6348
946.77246	2.8024914	1.0571445	3647.1841
947.77344	2.8039248	1.0601454	3645.9963
948.77441	2.811595	1.0626154	3639.8826
949.77539	2.8117888	1.064755	3638.7832
950.77637	2.8115778	1.0674666	3643.8242
951.77734	2.8163249	1.0707237	3647.7354
952.77832	2.819593	1.0741034	3641.1143
953.7793	2.8219328	1.0769235	3637.2122
954.78027	2.8279219	1.0800099	3640.0828
955.78125	2.8281357	1.0834379	3638.3149
956.78223	2.8304594	1.0870904	3635.6516
957.7832	2.8354442	1.0902518	3626.3547
958.78418	2.8373387	1.0933094	3632.5759
959.78516	2.8423271	1.096032	3628.0073
960.78613	2.8426359	1.0986633	3623.728
961.78711	2.8466263	1.1013721	3625.5459
962.78809	2.8483953	1.1040237	3618.4717
963.78906	2.8513336	1.106415	3616.0962
964.79004	2.8557212	1.1090627	3619.7634
965.79102	2.8572171	1.1123146	3620.9998
966.79199	2.8604429	1.1157697	3618.502
967.79297	2.866859	1.1190547	3617.6174
968.79395	2.8654559	1.1219077	3605.6543
969.79492	2.8731503	1.1250142	3614.3838
970.7959	2.8744962	1.1279228	3610.2061
971.79688	2.8793085	1.130704	3610.0439
972.79785	2.8788202	1.1337721	3609.448
973.79883	2.8852997	1.1370785	3609.0132
974.7998	2.8861358	1.1404901	3602.4612
975.80078	2.8910813	1.1435653	3598.7227
976.80176	2.8904727	1.1466243	3596.6702
977.80273	2.8960061	1.1494429	3598.8311
978.80371	2.8968306	1.1522578	3591.5745
979.80469	2.9042635	1.1557841	3595.4397
980.80566	2.902926	1.1593599	3596.1333
981.80664	2.9069901	1.1630981	3588.4739
982.80762	2.9102464	1.1661012	3580.1846
983.80859	2.9134188	1.1690671	3581.1191
984.80957	2.9178143	1.1722542	3582.4146
985.81055	2.920372	1.1751297	3576.4314
986.81152	2.9225047	1.1780478	3578.5391
987.8125	2.9244068	1.1813639	3580.1946
988.81348	2.928535	1.1848658	3579.5068
989.81445	2.9320469	1.1881462	3573.8076
990.81543	2.9353518	1.1913245	3567.9138
991.81641	2.9372211	1.1945523	3567.0486
992.81738	2.938652	1.1974992	3558.9268
993.81836	2.9438913	1.2006923	3559.8552
994.81934	2.9478476	1.2038996	3553.4417
995.82031	2.9466953	1.2067587	3550.8743
996.82129	2.9515512	1.2094736	3545.8904
997.82227	2.9530451	1.2121511	3550.4907
998.82324	2.9597855	1.2150272	3546.9792
999.82422	2.9604373	1.2183803	3543.1995
1000.8252	2.9650192	1.2213352	3540.7141
1001.8262	2.9664471	1.2241876	3533.781
1002.8271	2.9710286	1.2272276	3536.3762
1003.8281	2.9721797	1.2307242	3533.761
1004.8291	2.9761643	1.2344407	3536.877
1005.8301	2.9774342	1.2378601	3527.6907
1006.8311	2.9842768	1.2410119	3520.2573
1007.832	2.9831967	1.2435291	3514.2896
1008.833	2.9880826	1.2456549	3516.0793
1009.834	2.9941344	1.2479131	3519.1089
1010.835	2.9938931	1.2508048	3516.0303
1011.8359	2.996892	1.2537762	3512.031
1012.8369	3.0014	1.2571305	3517.0444
1013.8379	3.0047467	1.2606773	3511.9131
1014.8389	3.0077386	1.2645382	3505.6006
1015.8398	3.0090184	1.2683543	3499.875
1016.8408	3.0123549	1.2718767	3490.8298
1017.8418	3.0154614	1.2754782	3496.0649
1018.8428	3.0198627	1.2786255	3487.8042
1019.8438	3.021333	1.2814189	3482.6299
1020.8447	3.0240912	1.2846618	3481.3499
1021.8457	3.0268455	1.2880502	3476.2979
1022.8467	3.0292921	1.291039	3474.825
1023.8477	3.031821	1.2945696	3470.5227
1024.8486	3.0369852	1.2973486	3461.8386
1025.8496	3.0382204	1.3001767	3464.7109
1026.8506	3.0425761	1.3042002	3469.1777
1027.8516	3.0456631	1.3076558	3455.0422
1028.8525	3.0480635	1.3108902	3450.2949
1029.8535	3.0501213	1.3141801	3452.2815
1030.8545	3.0536916	1.3178358	3441.6687
1031.8555	3.0576189	1.321115	3442.1985
1032.8564	3.0585954	1.3242203	3437.0408
1033.8574	3.0637736	1.3271112	3425.2351
1034.8584	3.0677297	1.3300555	3427.8096
1035.8594	3.0694788	1.3329045	3428.2148
1036.8604	3.0727327	1.3359537	3421.813
1037.8613	3.0742624	1.3391305	3423.5776
1038.8623	3.0774293	1.3425798	3414.0168
1039.8633	3.0803266	1.346024	3413.3347
1040.8643	3.087332	1.3497303	3411.3335
1041.8652	3.0856137	1.3532926	3402.0962
1042.8662	3.0935929	1.3569002	3394.2373
1043.8672	3.0930524	1.3602229	3389.2681
1044.8682	3.098321	1.363536	3387.2529
1045.8691	3.1007681	1.3668443	3389.072
1046.8701	3.1042755	1.3700812	3380.3232
1047.8711	3.1050482	1.3733706	3371.0452
1048.8721	3.1090136	1.3770382	3378.6296
1049.873	3.112437	1.3802691	3361.8018
1050.874	3.1147847	1.3835268	3363.9849
1051.875	3.1171939	1.3871638	3353.8672
1052.876	3.1198039	1.3906689	3360.7734
1053.877	3.1256342	1.3949118	3356.4297
1054.8779	3.124603	1.3988166	3337.7102
1055.8789	3.1298947	1.4024339	3336.3479
1056.8799	3.1344421	1.4060409	3330.8005
1057.8809	3.1348696	1.4089361	3323.2698
1058.8818	3.1390858	1.4122876	3324.3684
1059.8828	3.1422722	1.4162735	3321.7327
1060.8838	3.144388	1.4198368	3312.7847
1061.8848	3.1458669	1.4231387	3306.6111
1062.8857	3.1503286	1.4264122	3304.7979
1063.8867	3.1530039	1.4293723	3295.6919
1064.8877	3.1589308	1.4322236	3294.7283
1065.8887	3.1598492	1.4354552	3291.9353
1066.8896	3.1585557	1.439195	3285.1116
1067.8906	3.1657097	1.4424464	3276.2837
1068.8916	3.1692255	1.4462098	3271.6179
1069.8926	3.173851	1.4495684	3263.877
1070.8936	3.176321	1.4521923	3250.1951
1071.8945	3.1821694	1.4550344	3261.6501
1072.8955	3.1831698	1.4587542	3259.3838
1073.8965	3.1817532	1.4626873	3247.7688
1074.8975	3.1895275	1.4660459	3240.2927
1075.8984	3.1894319	1.4692972	3233.0613
1076.8994	3.1941159	1.4729691	3233.0942
1077.9004	3.1957917	1.4766978	3221.6597
1078.9014	3.1988547	1.4801359	3218.7302
1079.9023	3.2011476	1.4838858	3209.8557
1080.9033	3.2037749	1.4879303	3204.3123
1081.9043	3.2077417	1.4921197	3198.1877
1082.9053	3.2120607	1.4957446	3192.5264
1083.9063	3.2127326	1.4989791	3186.5002
1084.9072	3.2208712	1.5023795	3181.6401
1085.9082	3.2208483	1.5057771	3183.2317
1086.9092	3.2226686	1.5100498	3169.7561
1087.9102	3.2247739	1.5136242	3156.8792
1088.9111	3.2276666	1.5169086	3148.3999
1089.9121	3.2337515	1.5203642	3148.4985
1090.9131	3.2332752	1.5239358	3138.5154
1091.9141	3.2391446	1.5272602	3130.9724
1092.915	3.2400942	1.5305592	3122.103
1093.916	3.2420452	1.5338904	3120.4968
1094.917	3.2473516	1.5378093	3114.9409
1095.918	3.2485702	1.5413465	3106.0376
1096.9189	3.2526436	1.5453844	3102.9902
1097.9199	3.2561574	1.5490832	3091.7734
1098.9209	3.2599199	1.5528644	3082.8022
1099.9219	3.2624707	1.5564793	3077.7153
1100.9229	3.2632155	1.5601848	3066.2625
1101.9238	3.2693098	1.564093	3064.6501
1102.9248	3.2731674	1.5675174	3048.2839
1103.9258	3.2729516	1.5702909	3045.2656
1104.9268	3.2766762	1.5736568	3044.063
1105.9277	3.2759686	1.5775335	3034.6824
1106.9287	3.2858477	1.5808744	3032.229
1107.9297	3.2865589	1.5845833	3021.2417
1108.9307	3.2907467	1.5884656	3012.4949
1109.9316	3.2895989	1.5917993	3004.4031
1110.9326	3.2925959	1.5952557	2996.3713
1111.9336	3.2972698	1.5990611	2986.7944
1112.9346	3.3022254	1.6022391	2975.5923
1113.9355	3.3027945	1.605301	2973.7798
1114.9365	3.3073022	1.6096524	2967.7502
1115.9375	3.3075535	1.6136131	2955.9751
1116.9385	3.312701	1.6182362	2947.3215
1117.9395	3.3215222	1.6228698	2940.8984
1118.9404	3.3171976	1.6264569	2922.5076
1119.9414	3.3233321	1.6299261	2918.7156
1120.9424	3.3263223	1.6338923	2912.5408
1121.9434	3.326478	1.6379269	2900.561
1122.9443	3.3266447	1.642719	2888.052
1123.9453	3.3343182	1.6468152	2873.1147
1124.9463	3.3338525	1.6502354	2868.4329
1125.9473	3.3420012	1.6540929	2863.1016
1126.9482	3.3414831	1.6576601	2851.7798
1127.9492	3.3492033	1.6614482	2844.8093
1128.9502	3.3497338	1.6651618	2831.197
1129.9512	3.3513596	1.6693481	2820.0959
1130.9521	3.3551245	1.6731476	2804.9121
1131.9531	3.356833	1.6767011	2792.8735
1132.9541	3.3638513	1.6805729	2788.3552
1133.9551	3.3630037	1.6849207	2772.1558
1134.9561	3.3673434	1.6890556	2756.7271
1135.957	3.3687952	1.6926696	2745.4365
1136.958	3.3727288	1.6976112	2735.1042
1137.959	3.3757925	1.7021602	2717.7532
1138.96	3.3796532	1.7061813	2703.3193
1139.9609	3.3863397	1.710518	2684.9426
1140.9619	3.3822634	1.7149125	2659.4614
1141.9629	3.3892798	1.7197309	2640.2158
1142.4634	3.3903596	1.7247009	2598.5806