File: datasets/am_bench_2022/raw_data/60-X.12-4/specimen.dat
MTS793|MPT|ENU|1|2|.|/|:|1|0|0|A

Operator Information						Time:	18.929199	Sec	11/1/2021 10:18:43 AM
Operator	Nick Derimow
Project	AM Bench 2022 mini-tensile challenge
Specimen ID	60-X.12-4
Material	PBF-L Inconel 625
Specimen Width	2.54	mm
Specimen Thickness	1.51	mm
Notes
Operator Information End

Data Acquisition						Time:	1019.9255	Sec	11/1/2021 10:35:24 AM
Time	Axial Displacement	Axial Extensometer	Axial Force
Sec	mm	mm	N
19.045654	0.0024703133	6.8116487e-06	46.091084
20.046631	0.004451558	-2.3680224e-05	60.02853
21.047607	0.0044298396	4.4666278e-05	72.821152
22.048584	0.0091695823	0.00013446179	85.16748
23.049561	0.012909406	9.0996225e-05	102.90579
24.050537	0.013497597	0.00026141838	116.40028
25.051514	0.019818636	0.000358466	131.76035
26.05249	0.021157803	0.00037679967	142.86554
27.053467	0.023326114	0.00052005739	155.11169
28.054443	0.028641343	0.00056670286	167.91977
29.05542	0.032951582	0.00064391294	186.40288
30.056396	0.032053955	0.00073212566	200.987
31.057373	0.037066564	0.00064887537	217.51266
32.05835	0.037055295	0.00068355113	229.13866
33.059326	0.041197319	0.00087355578	258.59134
34.060303	0.043711074	0.0010644179	280.65012
35.061279	0.047485985	0.0011253924	293.93445
36.062256	0.049260546	0.0011838437	310.21259
37.063232	0.052570712	0.0012046811	337.45621
38.064209	0.056202151	0.0013771767	355.185
39.065186	0.060603157	0.0014207847	375.63602
40.066162	0.060762152	0.0015965668	396.45313
41.067139	0.062580146	0.001795559	413.96631
42.068115	0.06624949	0.0018375902	441.66681
43.069092	0.073924601	0.0018146302	467.73615
44.070068	0.075797714	0.0019431972	488.68567
45.071045	0.076310351	0.0019499381	504.23093
46.072021	0.082076907	0.0023081133	539.30811
47.072998	0.083631776	0.0024007547	555.76929
48.073975	0.088512689	0.0025405549	580.72729
49.074951	0.088185064	0.002611069	597.64142
50.075928	0.091106966	0.0026565425	621.63556
51.076904	0.094538018	0.00274902	649.38348
52.077881	0.097030722	0.0028340293	670.72052
53.078857	0.10125655	0.0029896011	699.55389
54.079834	0.1071616	0.0032061103	727.02582
55.080811	0.1052572	0.0033373174	753.98645
56.081787	0.11083546	0.0035397385	791.89258
57.082764	0.11450034	0.0036847428	815.69818
58.08374	0.11670845	0.0037698166	839.67212
59.084717	0.11567867	0.0038950655	869.45221
60.085693	0.12226807	0.0039964775	901.34753
61.08667	0.12311877	0.0040322626	921.50415
62.087646	0.13044746	0.0043503148	958.0813
63.088623	0.13052553	0.0044244402	977.61499
64.0896	0.13739415	0.0045136814	1004.3743
65.090576	0.13442205	0.0046312949	1027.9652
66.091553	0.13863352	0.0047357609	1046.0477
67.092529	0.14384513	0.0048604636	1078.8918
68.093506	0.14877962	0.0050404994	1117.9072
69.094482	0.14856224	0.0051637106	1139.0614
70.095459	0.1525508	0.0052791871	1172.2343
71.096436	0.1544864	0.0054039429	1195.2921
72.097412	0.15846942	0.0054997285	1219.7314
73.098389	0.16191953	0.0057966411	1258.0854
74.099365	0.16661333	0.0059744548	1288.0834
75.100342	0.16815247	0.0060684546	1308.6008
76.101318	0.17316508	0.0061632763	1338.4508
77.102295	0.17156979	0.0061633131	1354.9795
78.103271	0.17443699	0.0063790898	1390.2657
79.104248	0.17785965	0.0064662537	1413.0375
80.105225	0.18230066	0.0066191382	1438.7953
81.106201	0.18330708	0.006803045	1459.7683
82.107178	0.18686189	0.0069603459	1499.7885
83.108154	0.19005978	0.0071562659	1530.7567
84.109131	0.19577311	0.0072235428	1557.2789
85.110107	0.19479537	0.0073122461	1581.0646
86.111084	0.19858539	0.0073862243	1603.5253
87.112061	0.20320645	0.0074948934	1633.8657
88.113037	0.20454864	0.0075723031	1653.2863
89.114014	0.20979242	0.0076733963	1676.3718
90.11499	0.21126942	0.007793149	1708.3174
91.115967	0.21413872	0.008028497	1734.1371
92.116943	0.21847451	0.0081037842	1749.3251
93.11792	0.22069123	0.0081938459	1772.8732
94.118896	0.22459564	0.0083240438	1802.2902
95.119873	0.22631073	0.0085550807	1829.6372
96.12085	0.22730997	0.0086527998	1855.7755
97.121826	0.23327322	0.0086928559	1881.9102
98.122803	0.23727208	0.0088796485	1902.2231
99.123779	0.23622939	0.0088894879	1920.6348
100.12476	0.24366397	0.0091281338	1945.0313
101.12573	0.24421942	0.0090341642	1953.6833
102.12671	0.2475429	0.0092484402	1976.17
103.12769	0.25216705	0.0093480982	1993.0685
104.12866	0.25474867	0.0094969533	2012.7671
105.12964	0.25532478	0.0095104519	2028.3533
106.13062	0.2603974	0.0096364254	2043.7234
107.13159	0.26257622	0.0096914871	2059.447
108.13257	0.26647258	0.0098616388	2075.4768
109.13354	0.26908818	0.0098482715	2086.2273
110.13452	0.27290094	0.0099157495	2097.4065
111.1355	0.27725506	0.0099471267	2116.0723
112.13647	0.27901605	0.010052284	2123.6296
113.13745	0.28352606	0.010081219	2132.9143
114.13843	0.28543764	0.010274833	2146.8518
115.1394	0.28596279	0.010378745	2157.3823
116.14038	0.2877861	0.010373889	2170.1323
117.14136	0.29510537	0.010367599	2175.9338
118.14233	0.3005943	0.01044147	2198.5615
119.14331	0.30040807	0.010599419	2213.2324
120.14429	0.30087686	0.010689971	2216.7886
121.14526	0.30737081	0.010835089	2236.8994
122.14624	0.30920064	0.010764977	2238.0945
123.14722	0.31085268	0.010832942	2253.1995
124.14819	0.31635538	0.01098152	2267.5186
125.14917	0.319525	0.011083525	2272.0908
126.15015	0.32019684	0.011127035	2277.3528
127.15112	0.32413602	0.011259581	2290.3572
128.1521	0.32580686	0.011304149	2297.5107
129.15308	0.33099306	0.011408462	2314.8403
130.15405	0.33227786	0.011573795	2325.4255
131.15503	0.33666906	0.011587977	2342.0608
132.15601	0.34163287	0.011647091	2345.6592
133.15698	0.34091762	0.011690049	2354.8074
134.15796	0.34513733	0.011968554	2370.1345
135.15894	0.34958869	0.01187437	2370.4946
136.15991	0.34977391	0.011900781	2377.23
137.16089	0.35578722	0.012054571	2392.9392
138.16187	0.35687989	0.0122429	2406.9768
139.16284	0.35902321	0.012282554	2402.9907
140.16382	0.36399812	0.01239103	2422.7026
141.16479	0.36697021	0.012503248	2425.8628
142.16577	0.3701241	0.012469732	2430.7429
143.16675	0.37378913	0.012694589	2448.47
144.16772	0.3746464	0.012802274	2456.3259
145.1687	0.37822968	0.0128518	2461.8582
146.16968	0.38083872	0.013045412	2475.3796
147.17065	0.3841975	0.012999741	2470.1724
148.17163	0.38621214	0.013238564	2483.4053
149.17261	0.39302957	0.013356526	2493.4456
150.17358	0.3949537	0.013523584	2505.4478
151.17456	0.39645043	0.013644039	2505.0767
152.17554	0.39917672	0.013765857	2513.4958
153.17651	0.40346622	0.013865471	2521.8579
154.17749	0.40822086	0.014005569	2530.2856
155.17847	0.40865073	0.01420452	2544.2834
156.17944	0.40967211	0.014361698	2544.5559
157.18042	0.41693211	0.014463024	2553.4131
158.1814	0.41562128	0.014753997	2558.4971
159.18237	0.42246884	0.014832458	2569.2397
160.18335	0.42307141	0.01518992	2580.6304
161.18433	0.42771912	0.015340853	2586.7874
162.1853	0.4271706	0.015441924	2580.8408
163.18628	0.43381411	0.015627306	2601.3672
164.18726	0.43693417	0.015816277	2599.1187
165.18823	0.44087562	0.016137946	2616.9739
166.18921	0.44199103	0.016506463	2615.9404
167.19019	0.44564828	0.016785994	2623.6377
168.19116	0.44726667	0.016974231	2627.8284
169.19214	0.45247993	0.017271608	2637.5784
170.19312	0.45287269	0.017577834	2639.0862
171.19409	0.45802233	0.017950643	2646.3403
172.19507	0.46096534	0.01830015	2653.3071
173.19604	0.46291918	0.018679136	2661.8274
174.19702	0.46632856	0.018980538	2670.4165
175.198	0.46784818	0.019270243	2671.8728
176.19897	0.47161362	0.019680319	2686.9709
177.19995	0.47324449	0.020126658	2682.3506
178.20093	0.47856387	0.020580014	2692.886
179.2019	0.48189616	0.020996364	2699.4988
180.20288	0.48605314	0.021430483	2701.3103
181.20386	0.48455396	0.021935364	2706.2888
182.20483	0.4892785	0.022418108	2709.7842
183.20581	0.49583843	0.022847485	2721.5811
184.20679	0.49733472	0.023356259	2725.0593
185.20776	0.500274	0.023797266	2725.4441
186.20874	0.50108927	0.024356447	2734.8335
187.20972	0.50670552	0.024893448	2733.9492
188.21069	0.50900888	0.025428101	2736.5195
189.21167	0.51194674	0.026137749	2750.8542
190.21265	0.51310194	0.026574805	2747.9612
191.21362	0.51945025	0.027279917	2758.7751
192.2146	0.52297944	0.027961217	2762.8855
193.21558	0.52431422	0.028495332	2765.6738
194.21655	0.52784711	0.02911837	2769.4214
195.21753	0.52845746	0.029874725	2775.5081
196.21851	0.52987367	0.030314712	2769.5059
197.21948	0.53593922	0.031005014	2776.3364
198.22046	0.53587162	0.031879567	2787.4331
199.22144	0.54125726	0.032566935	2784.783
200.22241	0.54339594	0.033337682	2792.7217
201.22339	0.55032814	0.034219164	2804.4807
202.22437	0.54959649	0.03507068	2800.0823
203.22534	0.55143392	0.035625428	2794.698
204.22632	0.55190474	0.036413345	2805.3418
205.22729	0.55535591	0.037344217	2809.3027
206.22827	0.56330049	0.038364869	2820.4961
207.22925	0.5654518	0.039013252	2811.8391
208.23022	0.56828392	0.039655484	2818.4858
209.2312	0.57188797	0.040639617	2831.6895
210.23218	0.57596916	0.041356266	2820.2034
211.23315	0.579961	0.042080492	2826.3481
212.23413	0.57845032	0.042809937	2830.1411
213.23511	0.58263272	0.043628041	2832.5513
214.23608	0.58460683	0.04435825	2838.2786
215.23706	0.58874786	0.045360979	2840.123
216.23804	0.59404027	0.046173885	2845.7969
217.23901	0.59871507	0.046956986	2851.7209
218.23999	0.59714866	0.047980353	2849.5513
219.24097	0.60398257	0.048854433	2853.0386
220.24194	0.60626477	0.049583841	2854.553
221.24292	0.6083194	0.050374631	2859.8123
222.2439	0.60966098	0.051412921	2860.2061
223.24487	0.61614287	0.052298989	2865.8909
224.24585	0.61834764	0.053214237	2871.0415
225.24683	0.62049961	0.054320041	2873.9507
226.2478	0.62072748	0.055043232	2869.1768
227.24878	0.62559807	0.056033164	2876.9077
228.24976	0.62869579	0.057257194	2883.7727
229.25073	0.63232619	0.058163989	2879.5383
230.25171	0.63388932	0.05903079	2886.6292
231.25269	0.63983703	0.059969723	2890.0461
232.25366	0.64109093	0.060924146	2882.4314
233.25464	0.6433183	0.061932649	2890.9761
234.25562	0.64748508	0.062817261	2895.5122
235.25659	0.65183735	0.063900888	2897.5637
236.25757	0.65135115	0.064786516	2895.8401
237.25854	0.6543532	0.066182725	2909.238
238.25952	0.65913689	0.06729836	2906.0178
239.2605	0.66183549	0.068171009	2905.1953
240.26147	0.66426116	0.068957716	2902.6641
241.26245	0.668185	0.069896735	2907.325
242.26343	0.67308551	0.0709337	2910.7932
243.2644	0.67194712	0.072158858	2919.0229
244.26538	0.67794156	0.073313788	2921.0784
245.26636	0.68013698	0.074509889	2920.1655
246.26733	0.68380183	0.075541019	2921.1553
247.26831	0.6860019	0.076470576	2924.4241
248.26929	0.69102311	0.077547215	2929.7971
249.27026	0.69313002	0.078642771	2929.3298
250.27124	0.69487846	0.079711273	2936.8406
251.27222	0.69806165	0.080702148	2930.033
252.27319	0.69857836	0.08167804	2928.8623
253.27417	0.70444924	0.082666896	2936.458
254.27515	0.70627791	0.083645567	2939.4656
255.27612	0.71258801	0.084749177	2940.345
256.2771	0.70848596	0.085748494	2939.0981
257.27808	0.7181145	0.087038301	2943.7141
258.27905	0.71821511	0.088057235	2950.2595
259.28003	0.72074574	0.089104176	2945.5945
260.28101	0.72773528	0.090241641	2954.4424
261.28198	0.72878426	0.091466032	2962.1548
262.28296	0.733356	0.092781693	2959.8794
263.28394	0.73331481	0.093865193	2954.4541
264.28491	0.73725581	0.094875053	2955.7031
265.28589	0.74048668	0.095956072	2961.2021
266.28687	0.74101305	0.09689521	2963.511
267.28784	0.74574536	0.098226391	2969.47
268.28882	0.74863428	0.099288784	2964.5562
269.28979	0.75113213	0.1001868	2967.5686
270.29077	0.75371003	0.10114884	2968.353
271.29175	0.75569618	0.10217943	2971.3701
272.29272	0.76410812	0.10365688	2981.2278
273.2937	0.76188833	0.10500107	2979.8335
274.29468	0.7670868	0.10645818	2988.6401
275.29565	0.76819628	0.10785195	2977.658
276.29663	0.7722981	0.10887868	2983.3374
277.29761	0.77339411	0.10981682	2981.2222
278.29858	0.77983475	0.11082656	2993.2319
279.29956	0.78006667	0.1118663	2984.0713
280.30054	0.78431505	0.11294114	2992.4146
281.30151	0.78672659	0.11408681	2997.1733
282.30249	0.79047954	0.1151707	2990.521
283.30347	0.79252553	0.11621397	2998.2053
284.30444	0.79477423	0.11749831	2999.4409
285.30542	0.80063033	0.11871267	2999.0327
286.3064	0.80538666	0.11986481	3003.272
287.30737	0.80764121	0.12098082	3006.0076
288.30835	0.80878919	0.12202018	3003.6252
289.30933	0.81175005	0.12299698	3000.062
290.3103	0.8137899	0.12408657	3005.7537
291.31128	0.81671572	0.12503512	3002.8579
292.31226	0.82195389	0.12614197	3012.2532
293.31323	0.82499278	0.12727393	3014.6848
294.31421	0.82839686	0.12846364	3010.2664
295.31519	0.82991564	0.12936831	3006.9666
296.31616	0.83232021	0.1305279	3022.2778
297.31714	0.83547556	0.13161252	3013.7661
298.31812	0.83884859	0.13287786	3023.9248
299.31909	0.84208119	0.13384961	3017.9797
300.32007	0.84357131	0.13511364	3024.0608
301.32104	0.84940505	0.13623713	3024.2222
302.32202	0.85413516	0.13740975	3032.5774
303.323	0.85886157	0.13858245	3032.3213
304.32397	0.85793012	0.13984779	3036.196
305.32495	0.85862511	0.14110121	3026.6841
306.32593	0.86401463	0.14226463	3031.3091
307.3269	0.86383641	0.14334051	3030.1479
308.32788	0.86528212	0.14474298	3040.5916
309.32886	0.87211847	0.14597882	3042.615
310.32983	0.87367165	0.14692739	3029.6345
311.33081	0.87808597	0.14811757	3037.5808
312.33179	0.87808806	0.149312	3045.1719
313.33276	0.88474	0.15039437	3033.9255
314.33374	0.88463837	0.15139069	3037.5669
315.33472	0.89068395	0.15260768	3055.0745
316.33569	0.89523381	0.15392451	3049.8589
317.33667	0.8948248	0.15497179	3051.7104
318.33765	0.9004842	0.15630341	3054.5164
319.33862	0.90063685	0.15737538	3050.7854
320.3396	0.90413755	0.15850091	3051.2166
321.34058	0.90942234	0.15964116	3058.1326
322.34155	0.91357577	0.16083044	3055.7798
323.34253	0.91354358	0.16188152	3059.2158
324.34351	0.91708553	0.16286549	3058.4297
325.34448	0.91809827	0.16400816	3055.5081
326.34546	0.92102087	0.16503063	3057.4082
327.34644	0.92543989	0.16631418	3064.1089
328.34741	0.9280479	0.16723955	3059.2837
329.34839	0.93157625	0.16864493	3074.1223
330.34937	0.93540835	0.16974251	3068.2986
331.35034	0.93767518	0.17084615	3068.7407
332.35132	0.94094336	0.17185423	3066.8928
333.35229	0.94136709	0.17304309	3070.842
334.35327	0.94804913	0.17415254	3071.2078
335.35425	0.95004922	0.17551468	3077.688
336.35522	0.95401651	0.17665635	3082.0945
337.3562	0.95697689	0.17791197	3082.6865
338.35718	0.95952308	0.17865065	3074.179
339.35815	0.96319902	0.17988051	3086.0667
340.35913	0.96406466	0.18086836	3088.4827
341.36011	0.96832633	0.18208376	3084.551
342.36108	0.96927458	0.1831343	3085.969
343.36206	0.97295761	0.18423599	3088.2676
344.36304	0.97673494	0.18528828	3089.4758
345.36401	0.97813028	0.18658409	3093.542
346.36499	0.98114848	0.18796074	3096.4841
347.36597	0.98348808	0.18921673	3094.0754
348.36694	0.9893977	0.19038235	3098.0481
349.36792	0.99112594	0.19154418	3097.7026
350.3689	0.99243045	0.19278139	3096.9041
351.36987	0.99640018	0.19370559	3095.0374
352.37085	1.00131	0.19496004	3102.03
353.37183	1.0028099	0.19609906	3102.9668
354.3728	1.0077231	0.19725952	3111.7207
355.37378	1.0090313	0.19843677	3104.0959
356.37476	1.0151078	0.19960225	3112.3975
357.37573	1.0177435	0.20079902	3110.1619
358.37671	1.0159695	0.20198609	3107.5652
359.37769	1.0249422	0.20307527	3114.4973
360.37866	1.0235846	0.20407721	3107.6016
361.37964	1.0291679	0.2052139	3118.6621
362.38062	1.0312505	0.2064172	3117.5723
363.38159	1.031925	0.20765197	3113.05
364.38257	1.0374719	0.20862189	3119.0894
365.38354	1.0404242	0.20973237	3123.7664
366.38452	1.0422645	0.21096161	3120.3804
367.3855	1.0446422	0.21215065	3122.3347
368.38647	1.0494376	0.2132891	3128.2197
369.38745	1.0525774	0.21441522	3129.5125
370.38843	1.0543077	0.21550836	3125.1956
371.3894	1.058607	0.21652156	3124.0371
372.39038	1.0601754	0.21755448	3128.4529
373.39136	1.0657477	0.21880601	3135.3481
374.39233	1.0636034	0.22001901	3128.5959
375.39331	1.0743369	0.2212054	3138.5442
376.39429	1.0692785	0.22218356	3127.7275
377.39526	1.0760071	0.22322467	3135.051
378.39624	1.0808498	0.22433066	3137.5305
379.39722	1.0816152	0.22556035	3146.4343
380.39819	1.0853575	0.22698049	3139.8118
381.39917	1.0896759	0.22816318	3140.396
382.40015	1.0920006	0.22929955	3150.7527
383.40112	1.0951144	0.23040116	3144.8057
384.4021	1.0971104	0.23155829	3146.7566
385.40308	1.1001174	0.23270373	3146.415
386.40405	1.1016486	0.23392007	3151.7605
387.40503	1.105733	0.23516315	3144.6914
388.40601	1.1106809	0.23622297	3149.8667
389.40698	1.1100526	0.23710917	3152.1047
390.40796	1.1164678	0.23825181	3153.1943
391.40894	1.1180673	0.23910274	3148.6416
392.40991	1.1219594	0.24033742	3161.8088
393.41089	1.1236832	0.24136059	3163.6396
394.41187	1.1268715	0.24265611	3155.2852
395.41284	1.1314875	0.24366955	3160.4258
396.41382	1.1383374	0.2450792	3168.3853
397.41479	1.136567	0.24635653	3162.9626
398.41577	1.1400161	0.24765661	3166.2803
399.41675	1.1422058	0.24850486	3157.6323
400.41772	1.1443275	0.24946211	3154.5686
401.4187	1.1476756	0.25053269	3162.1233
402.41968	1.1507225	0.25161853	3166.9832
403.42065	1.1519617	0.25272366	3168.4668
404.42163	1.1568307	0.25376633	3175.7012
405.42261	1.1565841	0.25490603	3173.4255
406.42358	1.1648252	0.2562345	3181.0085
407.42456	1.1659412	0.25737441	3171.939
408.42554	1.169113	0.25860548	3170.396
409.42651	1.1739056	0.25953358	3169.8132
410.42749	1.1734551	0.26035181	3171.6917
411.42847	1.1810782	0.26145637	3187.7078
412.42944	1.1798701	0.26271415	3181.8684
413.43042	1.1861973	0.26387206	3182.2944
414.4314	1.1881982	0.26496491	3192.0933
415.43237	1.1901251	0.26613861	3187.9438
416.43335	1.1915566	0.26738814	3185.5522
417.43433	1.1988596	0.26845479	3186.8831
418.4353	1.2001117	0.26965037	3190.2258
419.43628	1.2011945	0.27060381	3188.6545
420.43726	1.2037666	0.27151519	3182.5317
421.43823	1.2112917	0.27271652	3195.0493
422.43921	1.2113541	0.27375579	3195.3625
423.44019	1.2144586	0.27491614	3197.7002
424.44116	1.2158015	0.27609721	3193.1963
425.44214	1.2200994	0.27723837	3198.9377
426.44312	1.2231377	0.27854162	3195.7158
427.44409	1.2274946	0.27948353	3196.2039
428.44507	1.2287103	0.28035384	3196.6682
429.44604	1.2331637	0.28149563	3206.1233
430.44702	1.2298251	0.28271666	3200.0032
431.448	1.239037	0.28374004	3206.6372
432.44897	1.2419128	0.28487453	3208.0981
433.44995	1.2456093	0.28610003	3209.8838
434.45093	1.2466224	0.28715926	3206.2371
435.4519	1.2522321	0.28824505	3210.4802
436.45288	1.2517955	0.28906968	3204.3516
437.45386	1.2550263	0.29004437	3208.0259
438.45483	1.2576541	0.29115647	3215.8862
439.45581	1.2626166	0.29241836	3220.4429
440.45679	1.2671666	0.29355109	3217.1038
441.45776	1.2677016	0.29464027	3211.4414
442.45874	1.2720869	0.2957758	3219.043
443.45972	1.2753266	0.2968477	3221.9485
444.46069	1.2791448	0.29791418	3220.0452
445.46167	1.2798007	0.29894161	3218.1848
446.46265	1.2817388	0.30017462	3224.4092
447.46362	1.2868096	0.3014012	3232.21
448.4646	1.2864017	0.30270901	3227.3796
449.46558	1.2927833	0.30387121	3225.7651
450.46655	1.2925345	0.30493447	3224.9138
451.46753	1.2973478	0.3059459	3229.0332
452.46851	1.2997781	0.30731505	3229.6985
453.46948	1.3061115	0.30844188	3232.8506
454.47046	1.3094749	0.30953133	3232.6006
455.47144	1.3126193	0.31062564	3231.3611
456.47241	1.3123984	0.31158775	3232.7476
457.47339	1.3152852	0.31246689	3230.9456
458.47437	1.3202877	0.31364805	3239.2083
459.47534	1.3223659	0.31471056	3239.3193
460.47632	1.3260524	0.31594279	3243.4045
461.47729	1.3291231	0.31719461	3244.4294
462.47827	1.331339	0.31835169	3245.4958
463.47925	1.3339871	0.31956756	3241.8811
464.48022	1.340243	0.32094103	3246.2097
465.4812	1.3419018	0.3219361	3247.979
466.48218	1.3422661	0.32304695	3245.3379
467.48315	1.3454708	0.32412586	3244.3125
468.48413	1.3514208	0.32519457	3247.9368
469.48511	1.3514904	0.32632759	3254.2615
470.48608	1.3560849	0.32763755	3251.5637
471.48706	1.3574654	0.32858953	3246.5967
472.48804	1.3599344	0.32965916	3253.8381
473.48901	1.3668411	0.33076957	3253.074
474.48999	1.3688295	0.33187309	3256.9336
475.49097	1.3701143	0.33271107	3253.7747
476.49194	1.3729973	0.33401826	3262.792
477.49292	1.3744451	0.33505589	3257.6377
478.4939	1.3785412	0.33611423	3259.0986
479.49487	1.3798147	0.33734453	3262.6104
480.49585	1.3830454	0.33859712	3260.5503
481.49683	1.3906639	0.33962324	3266.6631
482.4978	1.3886598	0.34054857	3259.3708
483.49878	1.3950559	0.34168941	3268.4583
484.49976	1.3953716	0.34303695	3262.9309
485.50073	1.401307	0.34397513	3266.5898
486.50171	1.4042927	0.34502837	3270.4937
487.50269	1.4056816	0.34604523	3272.5454
488.50366	1.4091948	0.34732661	3270.7075
489.50464	1.411966	0.34825164	3269.6316
490.50562	1.4138302	0.34935787	3272.7847
491.50659	1.4172857	0.35066709	3282.7095
492.50757	1.4231601	0.35177359	3281.1953
493.50854	1.4236343	0.35304764	3278.7952
494.50952	1.4283471	0.35413975	3269.7124
495.5105	1.4326564	0.35495597	3273.5171
496.51147	1.4357197	0.35608879	3282.4148
497.51245	1.4348428	0.35711852	3279.9072
498.51343	1.4431059	0.35822585	3288.0254
499.5144	1.4421225	0.35914722	3277.9995
500.51538	1.4488509	0.36052045	3296.168
501.51636	1.4505126	0.36181551	3289.49
502.51733	1.4515058	0.36313787	3287.0444
503.51831	1.4585468	0.36426854	3289.999
504.51929	1.4578851	0.36530286	3283.127
505.52026	1.4614105	0.36633787	3286.2786
506.52124	1.4635079	0.36712429	3286.9026
507.52222	1.4642849	0.36811167	3282.488
508.52319	1.4681402	0.36920604	3291.8193
509.52417	1.4735631	0.37014878	3293.3391
510.52515	1.4750782	0.37125266	3295.5378
511.52612	1.4814225	0.3726247	3300.1462
512.5271	1.48238	0.37381136	3296.4639
513.52808	1.4851806	0.37507024	3303.7876
514.52905	1.4877918	0.37639785	3300.1384
515.53003	1.4925054	0.37761623	3306.1753
516.53101	1.490746	0.37864324	3291.4993
517.53198	1.49484	0.37987739	3302.8816
518.53296	1.5012971	0.38108709	3305.8586
519.53394	1.5022179	0.38216382	3303.9006
520.53491	1.5076343	0.38326475	3311.2568
521.53589	1.5088842	0.3842904	3301.7148
522.53687	1.513881	0.38541344	3315.4314
523.53784	1.5124344	0.3864477	3306.0125
524.53882	1.5165377	0.38749167	3310.0632
525.53979	1.5195628	0.3885684	3309.4897
526.54077	1.5225995	0.38955685	3305.4272
527.54175	1.5241867	0.39068928	3310.2922
528.54272	1.5302422	0.39162746	3316.2273
529.5437	1.530183	0.39274627	3312.7793
530.54468	1.5353909	0.39398527	3321.0168
531.54565	1.5366911	0.39513245	3318.2478
532.54663	1.5423931	0.39624858	3313.7568
533.54761	1.5426902	0.39734358	3316.4858
534.54858	1.5442854	0.39855811	3316.1987
535.54956	1.5506788	0.39961639	3317.5649
536.55054	1.5539378	0.40076146	3319.3318
537.55151	1.5571622	0.40197521	3324.8125
538.55249	1.557636	0.40312961	3321.5488
539.55347	1.5639054	0.40439013	3327.9673
540.55444	1.5640699	0.40556595	3323.2896
541.55542	1.5704098	0.40674695	3327.457
542.5564	1.5720886	0.4077501	3325.7402
543.55737	1.57577	0.40885398	3327.3916
544.55835	1.5768056	0.40981066	3332.0884
545.55933	1.5818942	0.41088259	3325.4001
546.5603	1.5824155	0.41201562	3327.887
547.56128	1.5855916	0.41326046	3335.2915
548.56226	1.5931854	0.41461238	3337.0991
549.56323	1.5919214	0.41558927	3331.094
550.56421	1.5977526	0.41672179	3336.8806
551.56519	1.5985448	0.41778874	3337.1797
552.56616	1.6034266	0.41895187	3343.0291
553.56714	1.6078295	0.42014307	3340.6062
554.56812	1.6066233	0.42132759	3340.1836
555.56909	1.6102836	0.42246306	3339.4146
556.57007	1.6113108	0.42357671	3337.333
557.57104	1.6177429	0.42476353	3338.0081
558.57202	1.6221454	0.42602798	3350.6931
559.573	1.6245791	0.42735797	3345.041
560.57397	1.6236587	0.42858112	3343.0022
561.57495	1.626423	0.42962283	3336.3203
562.57593	1.6324435	0.43061975	3346.7283
563.5769	1.6341187	0.43160057	3342.6484
564.57788	1.6357225	0.43272808	3347.7573
565.57886	1.6406925	0.43385398	3347.3691
566.57983	1.6435546	0.43494186	3349.9502
567.58081	1.6457924	0.43592837	3350.49
568.58179	1.6479896	0.43705913	3348.9875
569.58276	1.652774	0.43842533	3356.929
570.58374	1.6582963	0.43952554	3354.5649
571.58472	1.6563448	0.4407331	3364.0752
572.58569	1.6607513	0.44201362	3354.8335
573.58667	1.6664923	0.44323796	3361.4609
574.58765	1.6667794	0.44432396	3356.0205
575.58862	1.6749803	0.4454695	3357.3213
576.5896	1.6714435	0.44638339	3351.7649
577.59058	1.6771432	0.44729468	3353.0344
578.59155	1.6785651	0.44836992	3364.6736
579.59253	1.6845454	0.44961986	3364.9336
580.59351	1.6842566	0.4506695	3359.4773
581.59448	1.6895497	0.45190763	3363.1165
582.59546	1.692121	0.45305324	3365.1724
583.59644	1.6939384	0.45406413	3359.9473
584.59741	1.6974977	0.45517513	3366.291
585.59839	1.7007972	0.45654121	3370.3694
586.59937	1.7018676	0.45769024	3367.5913
587.60034	1.7068168	0.45880446	3364.5522
588.60132	1.711744	0.45994374	3364.2124
589.60229	1.714299	0.46085995	3368.8123
590.60327	1.7167765	0.46195632	3369.0896
591.60425	1.7205968	0.46291593	3367.0342
592.60522	1.7236257	0.4639996	3375.042
593.6062	1.7234255	0.46510121	3370.9792
594.60718	1.725155	0.46631333	3372.1597
595.60815	1.7290431	0.46771887	3371.8931
596.60913	1.7346065	0.46908236	3380.259
597.61011	1.7378851	0.47053668	3384.0491
598.61108	1.7407944	0.47183725	3382.4324
599.61206	1.7405518	0.47285241	3373.28
600.61304	1.7453568	0.47393155	3374.2307
601.61401	1.7502292	0.47509214	3383.6472
602.61499	1.7528037	0.47639424	3383.0991
603.61597	1.7557451	0.47748977	3379.2441
604.61694	1.7585142	0.47860157	3375.6948
605.61792	1.7625602	0.47981611	3386.3289
606.6189	1.7646446	0.48101521	3389.2161
607.61987	1.7686464	0.48228645	3390.8081
608.62085	1.7703862	0.48336631	3390.5928
609.62183	1.7705536	0.48446459	3383.2324
610.6228	1.7768701	0.48572975	3386.5176
611.62378	1.778218	0.48682785	3386.7461
612.62476	1.7790157	0.48780933	3385.6787
613.62573	1.7858074	0.48906285	3394.6699
614.62671	1.7880082	0.49005798	3390.0264
615.62769	1.7926447	0.49122748	3395.2512
616.62866	1.7943612	0.49249277	3392.01
617.62964	1.7970176	0.49357525	3386.9543
618.63062	1.7985537	0.49473822	3390.8125
619.63159	1.803579	0.49570626	3395.5132
620.63257	1.8075426	0.49677649	3393.5969
621.63354	1.8087159	0.49787787	3401.6484
622.63452	1.8110883	0.49895424	3397.0994
623.6355	1.8140266	0.50034809	3399.4353
624.63647	1.8181629	0.50163424	3397.1833
625.63745	1.821767	0.50302649	3405.7871
626.63843	1.8232024	0.50406551	3395.5718
627.6394	1.8275425	0.50512373	3401.9985
628.64038	1.8282863	0.50642532	3399.6592
629.64136	1.8310267	0.50780135	3403.0916
630.64233	1.8352057	0.50901437	3402.6782
631.64331	1.8394415	0.51025504	3408.4233
632.64429	1.8427861	0.51121837	3397.7029
633.64526	1.8436021	0.51244301	3404.8411
634.64624	1.8492477	0.5136131	3404.9268
635.64722	1.8531567	0.51486963	3414.1323
636.64819	1.8541594	0.51608664	3410.2258
637.64917	1.8595507	0.51716	3408.4119
638.65015	1.8594199	0.51836175	3406.7449
639.65112	1.8645936	0.51970696	3417.8008
640.6521	1.8630073	0.52079755	3407.3862
641.65308	1.8682146	0.52207357	3411.511
642.65405	1.8754528	0.52305591	3415.915
643.65503	1.8753668	0.52421165	3411.499
644.65601	1.8779255	0.52528679	3416.5684
645.65698	1.8827932	0.526241	3414.218
646.65796	1.8844725	0.52749431	3421.155
647.65894	1.8903327	0.52845293	3419.9797
648.65991	1.8885151	0.52960277	3418.3003
649.66089	1.8937113	0.5308153	3419.0027
650.66187	1.8955166	0.53215432	3417.9104
651.66284	1.8976077	0.53315014	3418.4331
652.66382	1.9018946	0.534325	3420.3755
653.66479	1.9026607	0.53525001	3404.9412
654.66577	1.9070573	0.53623527	3419.9546
655.66675	1.9117996	0.5372979	3417.7131
656.66772	1.9129535	0.53839284	3419.6824
657.6687	1.9174514	0.53955799	3428.1208
658.66968	1.9188707	0.54073012	3426.1904
659.67065	1.9217472	0.54172939	3424.1499
660.67163	1.9247373	0.54279357	3420.9043
661.67261	1.9296763	0.54391927	3424.5139
662.67358	1.9298556	0.5450899	3424.2065
663.67456	1.9308525	0.54620469	3426.5979
664.67554	1.9401581	0.54737937	3433.426
665.67651	1.9414209	0.54868823	3427.1685
666.67749	1.9459265	0.54990304	3432.5505
667.67847	1.9493953	0.55120307	3432.5103
668.67944	1.9504831	0.5522306	3431.4141
669.68042	1.951427	0.55322403	3432.1638
670.6814	1.9548999	0.5543403	3436.4736
671.68237	1.957605	0.55555743	3432.6199
672.68335	1.9643099	0.55647177	3434.759
673.68433	1.965937	0.55764216	3434.7466
674.6853	1.9656699	0.55852509	3435.2542
675.68628	1.9727807	0.55976194	3439.7654
676.68726	1.9723411	0.5609026	3435.1816
677.68823	1.9744569	0.56200051	3433.7498
678.68921	1.9820993	0.56281388	3437.8359
679.69019	1.979723	0.56394339	3436.0491
680.69116	1.9853873	0.56512326	3434.9475
681.69214	1.9916604	0.56610161	3441.8259
682.69312	1.994745	0.56719232	3441.9448
683.69409	1.9950919	0.56820911	3443.1121
684.69507	1.9976494	0.56927192	3435.4731
685.69604	2.0025966	0.57012773	3440.2263
686.69702	2.0058436	0.5712021	3452.1997
687.698	2.002244	0.57272476	3446.0239
688.69897	2.0116482	0.57403928	3445.3606
689.69995	2.0131905	0.57523638	3446.1799
690.70093	2.0180001	0.57631671	3449.0938
691.7019	2.0200546	0.57736415	3442.6865
692.70288	2.0215712	0.57862169	3445.46
693.70386	2.0250866	0.57980502	3449.7585
694.70483	2.0271058	0.58068067	3446.6223
695.70581	2.0294166	0.58173561	3445.8098
696.70679	2.0348625	0.58258355	3447.6436
697.70776	2.0360472	0.58343977	3449.0381
698.70874	2.0422387	0.58446306	3448.8464
699.70972	2.0439284	0.5855298	3450.053
700.71069	2.0461881	0.58645236	3445.1245
701.71167	2.0488191	0.58723831	3454.7415
702.71265	2.0497961	0.58832306	3454.0125
703.71362	2.0575435	0.58939642	3458.6299
704.7146	2.0570807	0.59053993	3458.7913
705.71558	2.0624597	0.59134883	3448.6511
706.71655	2.06534	0.5922063	3452.5386
707.71753	2.0687506	0.59309554	3456.1558
708.71851	2.0665691	0.59407288	3455.2783
709.71948	2.0745838	0.59503567	3463.6995
710.72046	2.073329	0.59620041	3456.7871
711.72144	2.0791864	0.59715796	3457.5569
712.72241	2.0833588	0.59817857	3453.6257
713.72339	2.0887449	0.59909582	3465.948
714.72437	2.0868046	0.60005242	3457.2539
715.72534	2.0897286	0.60103971	3454.1089
716.72632	2.0927024	0.60179937	3462.502
717.72729	2.099858	0.60286659	3468.3037
718.72827	2.1007891	0.60369647	3461.2617
719.72925	2.1063063	0.60466284	3467.4006
720.73022	2.1063778	0.60562152	3462.5857
721.7312	2.1091192	0.60646063	3457.8142
722.73218	2.1129119	0.60722411	3469.9927
723.73315	2.11694	0.60834545	3469.8696
724.73413	2.1208801	0.60925084	3465.3809
725.73511	2.1204584	0.61033982	3459.0303
726.73608	2.1250687	0.61119944	3465.033
727.73706	2.1287308	0.61227834	3469.2932
728.73804	2.128453	0.6132592	3470.2666
729.73901	2.1329238	0.61426616	3469.6829
730.73999	2.1372669	0.61529887	3471.9688
731.74097	2.1383183	0.61633974	3470.2078
732.74194	2.1413343	0.61740786	3463.7607
733.74292	2.1431656	0.61831653	3466.0874
734.7439	2.1484842	0.61913985	3463.5227
735.74487	2.1533425	0.62006938	3471.2297
736.74585	2.1572866	0.62113953	3479.2168
737.74683	2.1569078	0.62238091	3472.7712
738.7478	2.1605306	0.62352687	3470.7634
739.74878	2.1631272	0.62446028	3473.8357
740.74976	2.1680124	0.62558728	3478.7473
741.75073	2.1700921	0.6267572	3479.5679
742.75171	2.1743655	0.62795496	3476.7725
743.75269	2.174093	0.62895453	3468.7441
744.75366	2.1753931	0.6298157	3472.0383
745.75464	2.1803122	0.63109726	3482.157
746.75562	2.1857088	0.63232392	3477.2388
747.75659	2.1886289	0.63337702	3472.1357
748.75757	2.1898608	0.63414812	3471.4827
749.75854	2.1928322	0.63513535	3476.9941
750.75952	2.1973095	0.63608843	3475.3555
751.7605	2.201596	0.63692069	3485.5562
752.76147	2.2023671	0.63797772	3477.8704
753.76245	2.2036936	0.63912344	3477.4128
754.76343	2.2048004	0.64013261	3471.3701
755.7644	2.2117929	0.64092219	3480.4604
756.76538	2.2138293	0.6421656	3480.9812
757.76636	2.215348	0.64337742	3485.8787
758.76733	2.2201784	0.64484876	3479.9038
759.76831	2.2250116	0.64595419	3485.4275
760.76929	2.2254241	0.64708513	3472.5378
761.77026	2.2276444	0.64810407	3486.2683
762.77124	2.2331846	0.64920479	3483.1631
763.77222	2.2330375	0.65046579	3487.6912
764.77319	2.2379174	0.65142798	3481.5208
765.77417	2.2415137	0.65244228	3482.834
766.77515	2.242259	0.65347224	3489.718
767.77612	2.2484481	0.65473413	3493.385
768.7771	2.2544997	0.6557861	3492.4873
769.77808	2.2497063	0.65691543	3482.7864
770.77905	2.2566307	0.65815371	3491.0347
771.78003	2.2595966	0.65920639	3482.0266
772.78101	2.2635911	0.66022891	3485.4084
773.78198	2.2644687	0.66140425	3489.7136
774.78296	2.2675376	0.66265374	3490.4309
775.78394	2.2714431	0.66390997	3483.917
776.78491	2.2740436	0.66501021	3486.2351
777.78589	2.2774897	0.66621727	3485.1509
778.78687	2.2772665	0.66721511	3491.4438
779.78784	2.2854896	0.66817236	3490.8481
780.78882	2.2860477	0.66917956	3490.9668
781.78979	2.2894692	0.67019022	3493.9336
782.79077	2.2937708	0.67137909	3494.3501
783.79175	2.2960553	0.67252582	3492.5076
784.79272	2.2964416	0.67344791	3487.5955
785.7937	2.3001251	0.67461258	3494.106
786.79468	2.3049226	0.67563736	3495.5881
787.79565	2.3084621	0.67676252	3497.5637
788.79663	2.3121457	0.67802423	3495.6448
789.79761	2.3142269	0.67930603	3499.2375
790.79858	2.3162332	0.68037009	3496.6421
791.79956	2.3184443	0.68136257	3488.05
792.80054	2.3235073	0.68229312	3493.4885
793.80151	2.3254466	0.6832689	3494.7341
794.80249	2.3276494	0.68434036	3496.4307
795.80347	2.3302739	0.68527842	3495.7937
796.80444	2.3347065	0.68621218	3495.8247
797.80542	2.3346338	0.68731672	3501.7839
798.8064	2.3418834	0.68834484	3498.3457
799.80737	2.3435059	0.68934202	3498.4092
800.80835	2.3443613	0.6905371	3499.479
801.80933	2.349417	0.69144428	3498.446
802.8103	2.3530049	0.69240999	3498.7253
803.81128	2.3541005	0.69336778	3498.5522
804.81226	2.3569458	0.69474036	3501.0745
805.81323	2.3614948	0.69590139	3503.8293
806.81421	2.3652802	0.69731241	3499.4307
807.81519	2.3678522	0.69846874	3501.3672
808.81616	2.3686426	0.69960511	3502.8843
809.81714	2.3755705	0.70087665	3507.2378
810.81812	2.3753142	0.70237148	3502.3459
811.81909	2.3782964	0.70372069	3504.5369
812.82007	2.380738	0.70503151	3497.5854
813.82104	2.383637	0.70608908	3500.0918
814.82202	2.3877649	0.70723957	3504.5681
815.823	2.3931026	0.70840842	3510.2949
816.82397	2.3934729	0.70968276	3499.7158
817.82495	2.3990614	0.71074438	3499.0066
818.82593	2.4005692	0.71199191	3497.6848
819.8269	2.4027357	0.71305102	3506.8296
820.82788	2.4069695	0.7140702	3502.2222
821.82886	2.4083781	0.715271	3501.2192
822.82983	2.4153974	0.7162745	3507.6396
823.83081	2.4174492	0.71756613	3506.9255
824.83179	2.4189448	0.71885014	3509.3916
825.83276	2.4183834	0.72019875	3504.2959
826.83374	2.4260008	0.72129834	3504.5896
827.83472	2.4299796	0.72257811	3508.2368
828.83569	2.4325035	0.72372705	3507.3071
829.83667	2.4333057	0.7249763	3512.7278
830.83765	2.4377403	0.72619647	3511.4944
831.83862	2.4388938	0.72766215	3507.8296
832.8396	2.4438317	0.72880608	3512.7651
833.84058	2.4473155	0.73021227	3511.3042
834.84155	2.4507625	0.73126459	3508.6692
835.84253	2.4542375	0.73260051	3516.7803
836.84351	2.4526234	0.73401004	3508.7175
837.84448	2.459188	0.7353369	3509.7991
838.84546	2.4600356	0.73658806	3512.9111
839.84644	2.4642911	0.73794526	3508.2285
840.84741	2.4642143	0.7391693	3514.4219
841.84839	2.4721127	0.74055129	3515.5447
842.84937	2.475071	0.7417379	3515.2017
843.85034	2.4760838	0.74310005	3509.4705
844.85132	2.4796412	0.74423271	3511.8005
845.85229	2.4823732	0.74543017	3509.0823
846.85327	2.4861155	0.74656135	3516.0176
847.85425	2.4875729	0.74806941	3515.7673
848.85522	2.4903119	0.74929506	3504.7197
849.8562	2.4960716	0.75073862	3518.4895
850.85718	2.5009558	0.75214785	3524.1624
851.85815	2.5003254	0.75363737	3511.1191
852.85913	2.5037949	0.75494987	3515.8425
853.86011	2.507462	0.75623387	3513.4287
854.86108	2.5087581	0.75743181	3508.5806
855.86206	2.5135005	0.75867796	3515.6628
856.86304	2.5123825	0.76004952	3508.4836
857.86401	2.518399	0.76100624	3507.5835
858.86499	2.51863	0.76221043	3512.4333
859.86597	2.5233476	0.76335984	3515.3125
860.86694	2.5275793	0.76475525	3517.1152
861.86792	2.529032	0.7660622	3516.0308
862.8689	2.532311	0.76751196	3516.5015
863.86987	2.5329394	0.76868558	3507.0417
864.87085	2.5398388	0.76996499	3515.7964
865.87183	2.5403759	0.77115607	3510.0823
866.8728	2.5464983	0.77228284	3514.8132
867.87378	2.5491333	0.77362674	3509.885
868.87476	2.5513687	0.77479619	3517.6426
869.87573	2.5527968	0.77625149	3518.376
870.87671	2.5551412	0.77784079	3511.5496
871.87769	2.55843	0.77947134	3519.4583
872.87866	2.5589263	0.781183	3507.7666
873.87964	2.5673578	0.78248638	3518.28
874.88062	2.5702062	0.78390944	3523.4321
875.88159	2.5735669	0.78543788	3518.8716
876.88257	2.5752237	0.78689528	3508.4443
877.88354	2.5775037	0.78835768	3519.812
878.88452	2.5823236	0.78970909	3507.4338
879.8855	2.5817437	0.79091525	3515.1099
880.88647	2.5865712	0.79222453	3518.791
881.88745	2.5879781	0.79382432	3518.4585
882.88843	2.5916326	0.79549354	3518.2043
883.8894	2.598706	0.79712582	3520.616
884.89038	2.5988753	0.7989679	3517.394
885.89136	2.5986283	0.8008039	3514.3538
886.89233	2.6066701	0.80221522	3520.6057
887.89331	2.6063657	0.80398798	3516.7666
888.89429	2.610152	0.80553383	3518.4224
889.89526	2.6141038	0.8072238	3522.782
890.89624	2.6155355	0.80882263	3519.5017
891.89722	2.6204655	0.81047571	3515.854
892.89819	2.6259069	0.81183952	3520.1191
893.89917	2.6280055	0.81348091	3520.8469
894.90015	2.6295044	0.81488991	3523.0906
895.90112	2.631567	0.8164714	3519.7244
896.9021	2.6339114	0.81806713	3521.5603
897.90308	2.6404641	0.81964445	3519.7278
898.90405	2.645205	0.82077324	3514.3333
899.90503	2.6452489	0.82200527	3513.062
900.90601	2.6459413	0.82325369	3516.2024
901.90698	2.6521888	0.82449979	3516.4431
902.90796	2.6530476	0.82577419	3515.8311
903.90894	2.6555574	0.82730275	3519.9126
904.90991	2.6593931	0.82884663	3522.5513
905.91089	2.6638336	0.83033413	3519.4248
906.91187	2.6643453	0.83196712	3519.667
907.91284	2.6654105	0.83354169	3520.2578
908.91382	2.6719143	0.83492035	3513.0251
909.91479	2.6718564	0.83654237	3521.8467
910.91577	2.6779199	0.83843893	3526.3406
911.91675	2.6811237	0.84014088	3520.5466
912.91772	2.6860471	0.84186041	3518.8474
913.9187	2.6854222	0.84313959	3515.7651
914.91968	2.6905413	0.84446126	3520.8684
915.92065	2.6914604	0.84592599	3519.363
916.92163	2.6936681	0.84755254	3516.4973
917.92261	2.7001257	0.84896374	3521.3752
918.92358	2.7002685	0.85082787	3521.9854
919.92456	2.7032795	0.8522656	3515.4966
920.92554	2.7070322	0.85374969	3516.2297
921.92651	2.71049	0.85529095	3513.7615
922.92749	2.7091291	0.85656762	3505.6418
923.92847	2.7176189	0.85789502	3519.3997
924.92944	2.7207048	0.85949993	3524.5222
925.93042	2.7229481	0.86130595	3521.6592
926.9314	2.7257562	0.86287123	3513.6475
927.93237	2.7295611	0.86430717	3525.4607
928.93335	2.7324276	0.86603045	3521.3586
929.93433	2.735882	0.86749882	3515.0369
930.9353	2.7358294	0.86891329	3519.2725
931.93628	2.7397268	0.87036932	3513.657
932.93726	2.742821	0.87171543	3509.7632
933.93823	2.7510169	0.8729986	3523.8147
934.93921	2.7500777	0.87483734	3519.7554
935.94019	2.7540586	0.87614751	3517.1184
936.94116	2.7532258	0.87775171	3512.6797
937.94214	2.7590756	0.8791967	3514.8748
938.94312	2.7606497	0.88105601	3518.7219
939.94409	2.7636535	0.88253903	3509.7358
940.94507	2.7685544	0.88403636	3521.2383
941.94604	2.7687647	0.88544345	3516.0723
942.94702	2.7731345	0.88701636	3517.1892
943.948	2.7747991	0.88872063	3519.5928
944.94897	2.7781825	0.89055037	3520.8418
945.94995	2.7811844	0.89234632	3521.9846
946.95093	2.7841146	0.89425021	3516.2813
947.9519	2.787308	0.89573181	3516.7905
948.95288	2.7911081	0.89726675	3514.8999
949.95386	2.7904904	0.89858758	3512.5889
950.95483	2.7976458	0.90011877	3512.4297
951.95581	2.8028097	0.90143549	3516.9922
952.95679	2.8051248	0.90314966	3515.5457
953.95776	2.8068023	0.90481657	3522.7795
954.95874	2.8067799	0.90681809	3513.5029
955.95972	2.8129251	0.90833497	3513.4651
956.96069	2.8150778	0.91016459	3512.5964
957.96167	2.8205078	0.91184473	3514.2478
958.96265	2.8206611	0.91362303	3515.5327
959.96362	2.8229582	0.91526598	3513.2563
960.9646	2.8261454	0.91727144	3516.7532
961.96558	2.8310163	0.91893548	3510.1174
962.96655	2.8342168	0.92058092	3517.312
963.96753	2.8385365	0.92208475	3514.3242
964.96851	2.8373172	0.92383713	3512.502
965.96948	2.8428466	0.92558861	3519.9846
966.97046	2.8440225	0.92735744	3508.1768
967.97144	2.8462243	0.92908812	3510.1724
968.97241	2.8534563	0.93090725	3513.0613
969.97339	2.8526745	0.93271959	3511.7449
970.97437	2.8556144	0.93440861	3507.9194
971.97534	2.8587067	0.9361968	3510.5361
972.97632	2.8632579	0.93804806	3514.7183
973.97729	2.866679	0.93986613	3511.084
974.97827	2.8725297	0.94155711	3517.4783
975.97925	2.8746336	0.94350493	3515.2056
976.98022	2.872436	0.94577038	3508.1025
977.9812	2.8763862	0.94728601	3503.6487
978.98218	2.8815219	0.94878006	3499.8467
979.98315	2.8819208	0.95052415	3509.6274
980.98413	2.8876884	0.95269686	3510.7773
981.98511	2.8926129	0.95447564	3507.124
982.98608	2.8939421	0.9563033	3509.7642
983.98706	2.8944829	0.95827162	3505.4417
984.98804	2.9007318	0.96012431	3506.4973
985.98901	2.9036794	0.96207625	3512.3833
986.98999	2.9032335	0.96422613	3505.9104
987.99097	2.9089177	0.96592182	3507.5842
988.99194	2.9115171	0.96810216	3509.4482
989.99292	2.9143388	0.97002172	3502.3357
990.9939	2.9186492	0.97181749	3511.249
991.99487	2.9211366	0.97369838	3501.1475
992.99585	2.9245443	0.97541142	3505.5981
993.99683	2.9236715	0.9773345	3506.405
994.9978	2.933486	0.97936696	3511.3704
995.99878	2.9304187	0.98130947	3501.4851
996.99976	2.9351997	0.98293096	3498.3083
998.00073	2.9363971	0.98477679	3501.8069
999.00171	2.9410775	0.98679507	3503.5073
1000.0027	2.9429083	0.98881632	3497.2041
1001.0037	2.950738	0.99069697	3500.4595
1002.0046	2.9503219	0.99269402	3499.9534
1003.0056	2.95609	0.99506271	3503.6653
1004.0066	2.9555511	0.99700832	3490.6814
1005.0076	2.9610026	0.99897873	3498.3262
1006.0085	2.9627678	1.0007775	3494.011
1007.0095	2.9655669	1.0029161	3497.8728
1008.0105	2.9679506	1.0046415	3486.7095
1009.0115	2.9698668	1.0065258	3498.3762
1010.0125	2.9726663	1.0084363	3494.031
1011.0134	2.9792745	1.0108501	3501.3911
1012.0144	2.9804721	1.0129467	3499.0696
1013.0154	2.9823451	1.0150442	3492.8413
1014.0164	2.9866879	1.0169939	3492.3328
1015.0173	2.9898818	1.0190848	3493.2444
1016.0183	2.9926357	1.0210887	3494.3877
1017.0193	2.9982262	1.0232886	3494.2947
1018.0203	2.9960268	1.0250671	3484.4343
1019.0212	2.9972162	1.0268966	3486.4304
1020.0222	3.0026689	1.0283381	3485.5176
1021.0232	3.0089307	1.0299547	3490.5923
1022.0242	3.0118299	1.0316061	3497.6768
1023.0251	3.012738	1.0338472	3492.0278
1024.0261	3.0166738	1.0363469	3491.8726
1025.0271	3.0184298	1.0385834	3485.3499
1026.0281	3.0210297	1.0406667	3485.7158
1027.0291	3.0255952	1.0429968	3485.3804
1028.03	3.0297678	1.0450797	3485.2332
1029.031	3.0329368	1.0474924	3486.0115
1030.032	3.0342107	1.0501337	3490.7336
1031.033	3.0374188	1.0526218	3484.7603
1032.0339	3.0425642	1.0549802	3482.5803
1033.0349	3.044513	1.0573264	3482.3259
1034.0359	3.0454001	1.0597101	3479.7632
1035.0369	3.0465631	1.0622026	3481.1221
1036.0378	3.0509419	1.0645878	3475.415
1037.0388	3.0549593	1.0667689	3476.5505
1038.0398	3.0599039	1.0688008	3478.8682
1039.0408	3.0597286	1.0713331	3476.5898
1040.0417	3.060977	1.0739011	3475.8618
1041.0427	3.0703027	1.0766307	3478.1069
1042.0437	3.0718317	1.0794227	3478.7405
1043.0447	3.0719202	1.0820016	3466.3098
1044.0457	3.0750093	1.0843284	3473.6128
1045.0466	3.0798898	1.0869519	3471.562
1046.0476	3.0818801	1.0893863	3463.4536
1047.0486	3.0845094	1.0917422	3471.7788
1048.0496	3.0876281	1.0942428	3470.7935
1049.0505	3.0945559	1.0968245	3468.3237
1050.0515	3.0927567	1.0993798	3464.3315
1051.0525	3.0998142	1.1019956	3463.6052
1052.0535	3.0969088	1.1042502	3461.0747
1053.0544	3.1035688	1.1068102	3463.4666
1054.0554	3.1063643	1.1093509	3460.7476
1055.0564	3.1085756	1.1123748	3461.1479
1056.0574	3.112592	1.1147789	3457.3342
1057.0583	3.1169615	1.1171881	3449.3311
1058.0593	3.1179397	1.1190399	3458.6741
1059.0603	3.121412	1.1211587	3448.2576
1060.0613	3.124691	1.1232884	3460.4216
1061.0623	3.1267793	1.1262947	3456.2507
1062.0632	3.1306865	1.1295236	3455.8572
1063.0642	3.1345217	1.132763	3446.0652
1064.0652	3.1372466	1.1356343	3447.155
1065.0662	3.136013	1.1382706	3445.1787
1066.0671	3.141392	1.1411612	3444.5793
1067.0681	3.1442251	1.1439333	3439.3032
1068.0691	3.1472921	1.1463395	3443.6365
1069.0701	3.1518204	1.1489604	3439.1816
1070.071	3.1564324	1.151686	3445.0112
1071.072	3.156513	1.1547382	3438.5889
1072.073	3.1583087	1.1573426	3430.7585
1073.074	3.1634276	1.1602355	3436.5208
1074.075	3.1665559	1.1633505	3430.4453
1075.0759	3.1717329	1.1660539	3428.5979
1076.0769	3.1713657	1.1686039	3429.5042
1077.0779	3.1754465	1.171414	3423.7629
1078.0789	3.1810739	1.1738179	3431.5981
1079.0798	3.1785522	1.1766877	3426.0791
1080.0808	3.1863275	1.1794649	3425.9897
1081.0818	3.1860163	1.1821779	3417.1443
1082.0828	3.1890566	1.1845225	3413.8337
1083.0837	3.1926839	1.1868522	3412.1289
1084.0847	3.1947119	1.1889443	3415.2859
1085.0857	3.1974447	1.1920178	3412.439
1086.0867	3.2025864	1.1952291	3410.626
1087.0876	3.2055593	1.1980494	3403.7256
1088.0886	3.208451	1.2005668	3406.7725
1089.0896	3.2123652	1.2033546	3413.0901
1090.0906	3.2148929	1.207466	3402.1663
1091.0916	3.2175901	1.2105491	3401.144
1092.0925	3.22137	1.2133921	3400.0994
1093.0935	3.2240036	1.2158073	3391.3699
1094.0945	3.2284682	1.2183063	3395.2568
1095.0955	3.2301455	1.2214262	3392.7146
1096.0964	3.2336159	1.2246221	3393.2063
1097.0974	3.2386153	1.2281511	3388.8267
1098.0984	3.2400193	1.2305158	3387.157
1099.0994	3.2428348	1.2334421	3387.5859
1100.1003	3.2448835	1.2368536	3383.8809
1101.1013	3.2469563	1.2401391	3382.2864
1102.1023	3.2513297	1.2430875	3373.9492
1103.1033	3.2549791	1.2461606	3369.9705
1104.1042	3.2552342	1.248574	3365.1812
1105.1052	3.2598417	1.2515199	3364.9998
1106.1062	3.2616959	1.2545692	3366.4216
1107.1072	3.266	1.2583464	3362.2219
1108.1082	3.2687833	1.2614591	3361.9031
1109.1091	3.27163	1.2644622	3351.7781
1110.1101	3.2740309	1.2674029	3349.0723
1111.1111	3.2758684	1.2703675	3347.6228
1112.1121	3.2795746	1.2734431	3351.8206
1113.113	3.285785	1.2769613	3344.8838
1114.114	3.2847774	1.2804219	3337.0786
1115.115	3.2889853	1.2833029	3325.6477
1116.116	3.2945144	1.2862058	3332.5344
1117.1169	3.2977626	1.2897651	3325.8787
1118.1179	3.2982495	1.2928048	3319.1841
1119.1189	3.3003073	1.2961369	3318.8225
1120.1199	3.3042269	1.2995561	3305.1384
1121.1208	3.3091526	1.3026681	3302.5571
1122.1218	3.310219	1.3056798	3297.468
1123.1228	3.3147256	1.3089426	3297.8105
1124.1238	3.3182817	1.3126831	3296.3372
1125.1248	3.3195672	1.31616	3277.354
1126.1257	3.3218896	1.319328	3278.0095
1127.1267	3.3262007	1.3229976	3276.1375
1128.1277	3.3300898	1.3273028	3253.2429
1129.1287	3.335562	1.3306116	3245.416
1130.1296	3.3374331	1.3342097	3236.5166
1131.1306	3.3378565	1.3388678	3218.9622
1132.1316	3.344384	1.343606	3210.4661
1133.1326	3.3446047	1.348886	3185.5408
1134.1335	3.3469465	1.3543569	3157.45
1135.1345	3.3516538	1.3585585	3143.7607
1136.1355	3.3569059	1.3631465	3136.2695
1137.1365	3.3563552	1.368862	3097.8472
1138.1375	3.3646641	1.3818002	2981.561
1138.4377	3.3659167	1.3860554	2943.9646