File: datasets/am_bench_2022/raw_data/0-X.20-3/specimen.dat
MTS793|MPT|ENU|1|2|.|/|:|1|0|0|A

Operator Information						Time:	19.557617	Sec	10/13/2021 11:07:50 AM
Operator	Jake Benzing
Project	AM Bench 2022 mini-tensile challenge
Specimen ID	O-X.20-3
Material	PBF-L Inconel 625
Specimen Width	2.55	mm
Specimen Thickness	1.54	mm
Notes
Operator Information End

Data Acquisition						Time:	1020.5515	Sec	10/13/2021 11:24:31 AM
Time	Axial Displacement	Axial Extensometer	Axial Force
Sec	mm	mm	N
19.671387	-0.0013371186	8.8721044e-06	45.179405
20.772461	0.00032531549	0.00012093005	57.761051
21.873535	0.0040221633	9.044227e-05	71.236359
22.974609	0.010369993	0.00027578458	85.244339
24.075684	0.010843701	0.0003360174	98.416962
25.176758	0.016524661	0.00037565152	116.18909
26.277832	0.017464701	0.00045247743	129.03726
27.378906	0.02355073	0.00054134888	150.34331
28.47998	0.021376632	0.00079067866	162.81187
29.581055	0.026930152	0.00069884345	179.90816
30.682129	0.032961067	0.00091857777	199.7308
31.783203	0.03177147	0.0010282467	213.69081
32.884277	0.038736634	0.0010571936	238.85846
33.985352	0.041358162	0.0012040739	258.67987
35.086426	0.043683879	0.0013087066	282.33096
36.1875	0.046854362	0.0014026716	311.16504
37.288574	0.048128325	0.0015815198	334.14093
38.389648	0.053660944	0.0015761722	349.7475
39.490723	0.055551421	0.0018067575	372.14145
40.591797	0.062198032	0.0018840127	391.15103
41.692871	0.06237014	0.0019094888	412.9921
42.793945	0.065687276	0.0020914914	438.9632
43.89502	0.066055052	0.0022057581	466.99292
44.996094	0.07077077	0.0022872749	489.793
46.097168	0.076479807	0.0024237877	517.37372
47.198242	0.081191167	0.0024968795	543.41748
48.299316	0.084979191	0.0027231181	570.3847
49.400391	0.086891443	0.0027188687	590.89642
50.501465	0.089197434	0.0029170658	625.14783
51.602539	0.089838542	0.0030586189	649.07373
52.703613	0.096334919	0.0032006605	677.87683
53.804688	0.10117459	0.0033467088	709.1048
54.905762	0.10232936	0.0034856966	738.72614
56.006836	0.1071379	0.0036592628	769.76306
57.10791	0.10967235	0.0036898439	800.2334
58.208984	0.11298728	0.0039041291	817.9267
59.310059	0.11482858	0.0039691031	850.87421
60.411133	0.11677197	0.0040860414	884.66998
61.512207	0.1229106	0.0042758589	910.44238
62.613281	0.12531951	0.0043700165	944.28986
63.714355	0.12704509	0.0045589195	966.40643
64.81543	0.13155977	0.0047581503	1005.1042
65.916504	0.13598189	0.0048941867	1040.2186
67.017578	0.13796891	0.0050644297	1067.6295
68.118652	0.14073761	0.0051449058	1101.9773
69.219727	0.14236192	0.0053505404	1132.1884
70.320801	0.14916871	0.0056298487	1171.3334
71.421875	0.1526619	0.0056319707	1202.0446
72.522949	0.15259716	0.0057490198	1220.5886
73.624023	0.16165933	0.0059158318	1262.9153
74.725098	0.16113403	0.0061261253	1293.0564
75.826172	0.16544469	0.0062193703	1308.4502
76.927246	0.16687667	0.0062465873	1335.5093
78.02832	0.16991393	0.0066983141	1374.1823
79.129395	0.17267007	0.0066970726	1396.4196
80.230469	0.17704158	0.0068197264	1434.8483
81.331543	0.18042043	0.0071456884	1470.6578
82.432617	0.18350747	0.0072181206	1505.8394
83.533691	0.18286882	0.0073254979	1520.6071
84.634766	0.18935372	0.0075223632	1564.2484
85.73584	0.19620708	0.007780028	1598.115
86.836914	0.19539079	0.0079451846	1623.4362
87.937988	0.20312203	0.0080030402	1653.1339
89.039063	0.20595978	0.0082423305	1683.9348
90.140137	0.206497	0.0084816441	1707.4669
91.241211	0.20957749	0.0085506011	1730.179
92.342285	0.21333042	0.0087122871	1755.2048
93.443359	0.21627671	0.0089157494	1781.5568
94.544434	0.21993566	0.0091594439	1823.8661
95.645508	0.22468272	0.0093166521	1857.1511
96.746582	0.22843252	0.0095311981	1882.9418
97.847656	0.23153417	0.0097271372	1910.6921
98.94873	0.23277417	0.0099282973	1934.2375
100.0498	0.2394156	0.010330038	1974.6412
101.15088	0.23951764	0.010582252	2000.109
102.25195	0.24512197	0.010704583	2020.2422
103.35303	0.24692625	0.010934125	2036.0577
104.4541	0.24919453	0.011119446	2060.4187
105.55518	0.25469437	0.011493064	2080.3772
106.65625	0.25676578	0.011601946	2108.2295
107.75732	0.2628932	0.011906587	2132.0447
108.8584	0.26348287	0.012342771	2149.825
109.95947	0.26467985	0.012481467	2166.3596
111.06055	0.26849321	0.012992914	2189.5779
112.16162	0.27254346	0.01322847	2212.3782
113.2627	0.27856475	0.013683992	2240.6304
114.36377	0.2820296	0.014097055	2254.1211
115.46484	0.28562292	0.014457348	2281.4167
116.56592	0.28633779	0.014933558	2283.0762
117.66699	0.28827092	0.015282516	2300.6956
118.76807	0.29207224	0.015658053	2328.7302
119.86914	0.29645351	0.016114278	2334.6401
120.97021	0.29931647	0.016578306	2349.7043
122.07129	0.30374756	0.017081741	2367.7209
123.17236	0.30704442	0.01754343	2375.29
124.27344	0.30924574	0.018122649	2392.8142
125.37451	0.31363755	0.018789915	2405.1448
126.47559	0.31872475	0.019444317	2417.8438
127.57666	0.31990713	0.020151542	2432.8325
128.67773	0.32544959	0.020931307	2451.7288
129.77881	0.32805559	0.021577867	2450.7837
130.87988	0.33303824	0.022416484	2473.2446
131.98096	0.33227056	0.02331429	2478.1343
133.08203	0.33871305	0.024320018	2485.0925
134.18311	0.34228328	0.024993418	2497.1428
135.28418	0.34449974	0.026068402	2509.6838
136.38525	0.34886241	0.027122255	2515.0823
137.48633	0.35086006	0.028039012	2512.4971
138.5874	0.35395575	0.029102171	2527.0222
139.68848	0.35717291	0.030307088	2536.3738
140.78955	0.36435053	0.031314872	2533.9578
141.89063	0.36345518	0.032412082	2545.6177
142.9917	0.3680318	0.033566788	2561.0662
144.09277	0.37224862	0.034741931	2557.1233
145.19385	0.37519225	0.036058854	2563.2661
146.29492	0.37660491	0.037110936	2557.8093
147.396	0.38448292	0.038575172	2576.645
148.49707	0.38373733	0.039537441	2577.1699
149.59814	0.3886354	0.041300416	2584.0662
150.69922	0.39217237	0.042659741	2588.0574
151.80029	0.39627936	0.043765884	2581.2673
152.90137	0.39825594	0.044940073	2592.2407
154.00244	0.40094674	0.04606818	2598.1826
155.10352	0.40332279	0.047967087	2603.8259
156.20459	0.40487382	0.049575094	2607.1951
157.30566	0.408308	0.050676975	2597.4858
158.40674	0.41348058	0.052209787	2606.4436
159.50781	0.41605443	0.053752862	2612.9353
160.60889	0.42456365	0.055336915	2621.4258
161.70996	0.42481771	0.056894306	2621.4265
162.81104	0.42398235	0.058462895	2613.9856
163.91211	0.43113521	0.060238224	2629.1262
165.01318	0.43502608	0.061899532	2629.2781
166.11426	0.43587455	0.063648872	2622.5063
167.21533	0.44190541	0.065350622	2631.3696
168.31641	0.44309214	0.066683955	2625.2632
169.41748	0.44589642	0.068336993	2634.6917
170.51855	0.45258299	0.070062131	2640.313
171.61963	0.45524386	0.072019204	2644.7463
172.7207	0.4545753	0.073589452	2636.2043
173.82178	0.46078447	0.075163171	2643.1365
174.92285	0.46426532	0.077227525	2643.7859
176.02393	0.46783406	0.078736961	2647.9854
177.125	0.47174966	0.080687955	2648.4561
178.22607	0.47635275	0.082272232	2651.9973
179.32715	0.47967479	0.083873414	2653.4602
180.42822	0.47702289	0.085628405	2650.2019
181.5293	0.48515266	0.087164387	2655.1533
182.63037	0.48658219	0.08903423	2659.6831
183.73145	0.48987868	0.090959504	2664.9556
184.83252	0.49227729	0.09263026	2658.9543
185.93359	0.49811864	0.094245188	2664.5195
187.03467	0.50233734	0.095817879	2667.886
188.13574	0.50282049	0.097601987	2662.2954
189.23682	0.50572127	0.099559739	2669.5054
190.33789	0.51185417	0.10174902	2675.0498
191.43896	0.50970119	0.10360416	2665.8906
192.54004	0.51880527	0.10535903	2674.2456
193.64111	0.51907116	0.10719599	2665.5674
194.74219	0.52123541	0.10880555	2667.8005
195.84326	0.52507687	0.11039978	2674.5779
196.94434	0.5286774	0.11247556	2672.5747
198.04541	0.53433186	0.11417644	2680.1875
199.14648	0.53673363	0.11606154	2684.1292
200.24756	0.53992778	0.11796568	2683.2395
201.34863	0.5449236	0.11982022	2682.8667
202.44971	0.54505128	0.12154386	2681.0281
203.55078	0.54953521	0.12311686	2676.1699
204.65186	0.5532763	0.12502517	2692.6709
205.75293	0.55429602	0.12694083	2689.2959
206.854	0.55955511	0.12902357	2692.9634
207.95508	0.56274217	0.13115381	2690.9929
209.05615	0.56412101	0.13331047	2688.9355
210.15723	0.57164538	0.13541	2693.9446
211.2583	0.57237172	0.13711812	2691.0686
212.35938	0.57606035	0.13920511	2698.344
213.46045	0.58064491	0.14129516	2696.1094
214.56152	0.57946128	0.14283592	2692.6287
215.6626	0.58730769	0.14473091	2694.9604
216.76367	0.59114277	0.14641117	2696.928
217.86475	0.59235388	0.14835109	2699.2715
218.96582	0.5933972	0.15017442	2693.3677
220.06689	0.60010093	0.15182695	2705.29
221.16797	0.60302305	0.15400924	2705.3391
222.26904	0.60364389	0.1561005	2698.1248
223.37012	0.60784084	0.15772329	2702.1287
224.47119	0.61132187	0.15992071	2709.1389
225.57227	0.61246103	0.16152053	2700.647
226.67334	0.61755294	0.16342743	2702.6003
227.77441	0.62347996	0.16529852	2713.2163
228.87549	0.62638384	0.16704006	2711.2896
229.97656	0.63029045	0.16899776	2713.7881
231.07764	0.635409	0.17086737	2717.0227
232.17871	0.63658464	0.17282365	2719.0315
233.27979	0.63949651	0.17476456	2714.6868
234.38086	0.64454949	0.17633945	2720.6882
235.48193	0.64602053	0.17851588	2716.3054
236.58301	0.65100515	0.18033284	2726.1958
237.68408	0.65345377	0.18205495	2718.2014
238.78516	0.65897155	0.18394858	2725.8228
239.88623	0.658966	0.1857428	2718.9607
240.9873	0.6618126	0.18768518	2721.072
242.08838	0.6665377	0.18965228	2728.9683
243.18945	0.66939139	0.19169094	2725.6406
244.29053	0.66954935	0.19348913	2715.1941
245.3916	0.67479146	0.19524951	2726.9275
246.49268	0.67403066	0.19718732	2729.6479
247.59375	0.68216169	0.19915374	2726.1199
248.69482	0.68896711	0.20149638	2738.803
249.7959	0.68940187	0.2034241	2734.2981
250.89697	0.69063532	0.20531343	2729.3196
251.99805	0.69316852	0.20732346	2729.3665
253.09912	0.70012921	0.20907374	2735.7449
254.2002	0.69802928	0.21120839	2736.2476
255.30127	0.70487428	0.21334575	2740.678
256.40234	0.71061414	0.21530277	2737.9336
257.50342	0.71080208	0.2170542	2727.7031
258.60449	0.71334386	0.21879926	2738.9236
259.70557	0.72049779	0.22071294	2742.5286
260.80664	0.72193098	0.22245248	2747.3352
261.90771	0.72626048	0.22446124	2737.4727
263.00879	0.72827703	0.2263633	2739.2085
264.10986	0.73018575	0.22811416	2746.8843
265.21094	0.73444927	0.23037215	2744.2058
266.31201	0.7391578	0.23258378	2750.4727
267.41309	0.74301243	0.23452805	2747.7158
268.51416	0.74714518	0.23640592	2754.4773
269.61523	0.7478568	0.23809271	2751.3997
270.71631	0.75063694	0.24004892	2754.9917
271.81738	0.75247926	0.2418106	2740.1804
272.91846	0.7550838	0.24361603	2752.2493
274.01953	0.76104283	0.24578115	2757.0525
275.12061	0.76430935	0.24756916	2754.7053
276.22168	0.76942581	0.24954394	2757.7297
277.32275	0.77050334	0.25150821	2761.3987
278.42383	0.77373666	0.25364646	2760.8643
279.5249	0.77959645	0.25589371	2770.7148
280.62598	0.78177547	0.25803316	2758.5298
281.72705	0.78465748	0.25993687	2760.6782
282.82813	0.7855854	0.26159337	2759.2346
283.9292	0.79158205	0.26347452	2763.2715
285.03027	0.79433924	0.26549721	2763.1699
286.13135	0.794397	0.26733759	2760.8611
287.23242	0.80076581	0.26928273	2767.0049
288.3335	0.80503261	0.27132845	2773.5955
289.43457	0.81177181	0.27335632	2775.8816
290.53564	0.810498	0.27522847	2765.7129
291.63672	0.81286281	0.27710485	2771.8069
292.73779	0.82204038	0.27910659	2777.4055
293.83887	0.82091469	0.28092942	2775.7793
294.93994	0.82506949	0.28286922	2774.2024
296.04102	0.82438743	0.28469372	2765.3875
297.14209	0.82828808	0.28616762	2768.408
298.24316	0.83155173	0.28805366	2774.6143
299.34424	0.83856696	0.28967568	2774.8894
300.44531	0.84358442	0.29152086	2779.8711
301.54639	0.8443892	0.29390201	2774.8977
302.64746	0.84839702	0.2958492	2784.7471
303.74854	0.85119277	0.29801062	2791.4163
304.84961	0.85649711	0.29978693	2784.2837
305.95068	0.85745806	0.30197862	2791.5718
307.05176	0.86455584	0.3041814	2787.1421
308.15283	0.86650062	0.30574098	2782.6997
309.25391	0.86526477	0.3079285	2781.5076
310.35498	0.87168533	0.31005129	2783.5344
311.45605	0.87594187	0.31185949	2789.3679
312.55713	0.88056618	0.31399044	2796.9702
313.6582	0.88354897	0.31601292	2795.2668
314.75928	0.8845908	0.3178564	2788.0229
315.86035	0.88799465	0.31975949	2795.1323
316.96143	0.88856196	0.32162297	2785.0415
318.0625	0.89181173	0.32356641	2789.2793
319.16357	0.89508015	0.32530478	2791.759
320.26465	0.89654624	0.32736394	2790.21
321.36572	0.90185249	0.32963577	2793.376
322.4668	0.90838414	0.33176896	2794.2747
323.56787	0.9085173	0.33364654	2790.9333
324.66895	0.91083294	0.33543858	2797.3804
325.77002	0.91832906	0.33756688	2806.6313
326.87109	0.92207932	0.33976865	2813.2678
327.97217	0.91921908	0.34200919	2798.8406
329.07324	0.92846668	0.34396034	2801.646
330.17432	0.93311262	0.34545133	2799.6372
331.27539	0.93284851	0.34701824	2803.3799
332.37646	0.9373312	0.3490344	2807.5984
333.47754	0.93857306	0.35107863	2801.2358
334.57861	0.94714004	0.35287684	2812.2351
335.67969	0.94549853	0.35465443	2802.2349
336.78076	0.94661003	0.35687882	2807.6448
337.88184	0.95565766	0.35911015	2815.2224
338.98291	0.95562571	0.36114731	2815.5894
340.08398	0.95951718	0.3635256	2814.2095
341.18506	0.96084177	0.3652193	2800.7131
342.28613	0.96449572	0.36688909	2801.2217
343.38721	0.96809399	0.3691355	2823.3486
344.48828	0.97223812	0.37102076	2811.6265
345.58936	0.97390074	0.37291622	2812.0066
346.69043	0.98077476	0.37533095	2825.0522
347.7915	0.98274028	0.37760371	2817.8003
348.89258	0.98945367	0.37944123	2814.1128
349.99365	0.9874652	0.38133234	2823.5525
351.09473	0.99294579	0.38339305	2821.5452
352.1958	0.99794036	0.38507795	2813.8044
353.29688	1.000011	0.38677329	2827.1394
354.39795	1.0021065	0.38868383	2828.7778
355.49902	1.0082792	0.39128262	2835.7683
356.6001	1.0075911	0.39324132	2823.5869
357.70117	1.0127234	0.39494365	2825.0911
358.80225	1.0199722	0.39723718	2833.5676
359.90332	1.0202831	0.39931172	2827.5686
361.00439	1.0217685	0.40103617	2824.5059
362.10547	1.0236324	0.40282327	2831.3108
363.20654	1.0290756	0.40475056	2827.0232
364.30762	1.0331171	0.40642232	2824.2061
365.40869	1.0337436	0.40817952	2827.1641
366.50977	1.0405134	0.41020966	2835.5803
367.61084	1.0434505	0.41226107	2844.0649
368.71191	1.0441823	0.41429806	2842.9788
369.81299	1.0494026	0.41643983	2838.5803
370.91406	1.0533257	0.41803795	2827.4585
372.01514	1.0574281	0.41988012	2841.8455
373.11621	1.0614573	0.42174536	2843.1814
374.21729	1.0589815	0.42391011	2841.3335
375.31836	1.0634819	0.4266381	2846.3206
376.41943	1.0687265	0.42862251	2841.4912
377.52051	1.0725517	0.43063739	2849.1792
378.62158	1.0759103	0.43273073	2842.2747
379.72266	1.0800202	0.43456137	2838.2773
380.82373	1.0830163	0.4366948	2849.8687
381.9248	1.0848856	0.43854162	2844.3213
383.02588	1.0866567	0.4404445	2845.4214
384.12695	1.0934057	0.44225249	2847.7334
385.22803	1.096846	0.44429734	2858.8948
386.3291	1.0964237	0.44670755	2848.9055
387.43018	1.1000946	0.44894111	2848.0823
388.53125	1.105343	0.45079488	2853.8484
389.63232	1.109025	0.4529472	2853.575
390.7334	1.114266	0.4549084	2855.801
391.83447	1.1134154	0.45663339	2856.3401
392.93555	1.1174361	0.45878083	2858.8235
394.03662	1.122728	0.46101061	2859.6157
395.1377	1.1259545	0.46315944	2862.9939
396.23877	1.1275023	0.46525884	2854.5808
397.33984	1.133405	0.46758735	2856.5896
398.44092	1.1319205	0.46945882	2850.51
399.54199	1.1364424	0.47105744	2852.0012
400.64307	1.1392285	0.47293672	2860.1545
401.74414	1.1432824	0.47475305	2859.4612
402.84521	1.1496184	0.47676456	2863.8472
403.94629	1.1511461	0.47845915	2867.2883
405.04736	1.1561514	0.48037106	2866.7859
406.14844	1.156358	0.48257762	2867.0471
407.24951	1.1637578	0.48464182	2864.8323
408.35059	1.1644791	0.48657149	2865.7295
409.45166	1.1665969	0.48850775	2857.5825
410.55273	1.1741163	0.49045825	2876.9087
411.65381	1.1746532	0.49249473	2863.843
412.75488	1.1770093	0.49440873	2872.0325
413.85596	1.1797286	0.49640536	2871.7793
414.95703	1.1838112	0.49828783	2871.5359
416.05811	1.1859369	0.50060034	2874.261
417.15918	1.1907401	0.50279641	2865.5679
418.26025	1.1964725	0.50444764	2870.8015
419.36133	1.1954851	0.5065369	2879.5503
420.4624	1.201553	0.50847679	2874.8618
421.56348	1.2042071	0.51038653	2873.1458
422.66455	1.2079682	0.51262295	2887.6116
423.76563	1.2103888	0.51467937	2883.4094
424.8667	1.2112418	0.51681596	2877.6904
425.96777	1.2166666	0.51921242	2876.7397
427.06885	1.2227634	0.52137423	2890.4333
428.16992	1.225418	0.52334279	2880.2585
429.271	1.2265061	0.52524686	2887.835
430.37207	1.2318287	0.52728939	2882.7896
431.47314	1.2301644	0.52915889	2882.2947
432.57422	1.2351594	0.53143722	2882.6489
433.67529	1.2397239	0.53323328	2877.6531
434.77637	1.2414894	0.53505296	2884.0469
435.87744	1.2492925	0.53709656	2889.4219
436.97852	1.2486773	0.53907073	2882.9521
438.07959	1.2488374	0.54118961	2883.3655
439.18066	1.2560328	0.54317373	2888.6208
440.28174	1.2625695	0.5448311	2890.5691
441.38281	1.261027	0.54650837	2884.3108
442.48389	1.2641935	0.54829264	2891.7429
443.58496	1.2698815	0.55038679	2894.261
444.68604	1.2749478	0.55290252	2902.72
445.78711	1.2786646	0.55496484	2904.2583
446.88818	1.2818633	0.55685633	2893.4368
447.98926	1.2826852	0.55890971	2893.51
449.09033	1.2915837	0.56118405	2904.1182
450.19141	1.2919375	0.56339258	2901.2302
451.29248	1.2923024	0.56532079	2896.771
452.39355	1.2970099	0.56738049	2896.6655
453.49463	1.3019027	0.56922424	2900.897
454.5957	1.3016871	0.57109827	2895.584
455.69678	1.3067589	0.57310349	2900.7007
456.79785	1.3130444	0.5751847	2907.9294
457.89893	1.3109196	0.57742631	2900.1169
459	1.3156122	0.57955474	2908.3857
460.10107	1.3180488	0.58179504	2902.9255
461.20215	1.3229797	0.58374786	2907.9397
462.30322	1.3275629	0.58578575	2903.8552
463.4043	1.3318338	0.58766067	2905.6052
464.50537	1.3310027	0.58953273	2903.2908
465.60645	1.3345371	0.59136468	2903.502
466.70752	1.3379971	0.59323192	2908.6287
467.80859	1.3447952	0.595204	2917.9646
468.90967	1.3457197	0.59706604	2911.8928
470.01074	1.3488129	0.59917754	2906.1958
471.11182	1.3534385	0.60112256	2915.0083
472.21289	1.3543431	0.60311753	2913.5864
473.31396	1.3587584	0.6050899	2911.073
474.41504	1.3622375	0.60742754	2913.72
475.51611	1.3666567	0.6093902	2909.9326
476.61719	1.3698982	0.61151177	2920.228
477.71826	1.3682052	0.61353058	2909.551
478.81934	1.3754032	0.61561424	2910.4929
479.92041	1.3770164	0.61749268	2910.9504
481.02148	1.3842531	0.61941099	2921.436
482.12256	1.3844277	0.62148845	2922.6887
483.22363	1.3874243	0.62344271	2919.2681
484.32471	1.3902522	0.6254738	2917.418
485.42578	1.3970438	0.62751013	2920.377
486.52686	1.396428	0.62925929	2917.8535
487.62793	1.4025424	0.63144159	2922.5342
488.729	1.4070455	0.633578	2920.2402
489.83008	1.4098881	0.63519824	2917.6667
490.93115	1.4122909	0.6370846	2926.8794
492.03223	1.4174325	0.63958865	2934.8848
493.1333	1.4228328	0.6415289	2934.7871
494.23438	1.4200745	0.64358145	2933.2051
495.33545	1.4258136	0.64580363	2932.4729
496.43652	1.4298954	0.64803332	2935.1143
497.5376	1.4333616	0.65009165	2930.655
498.63867	1.4328305	0.65231299	2928.8518
499.73975	1.4387172	0.65449727	2935.2102
500.84082	1.4385949	0.65604168	2931.2854
501.94189	1.4464028	0.6582213	2938.093
503.04297	1.4489709	0.66044533	2932.3586
504.14404	1.4516509	0.66228604	2931.7324
505.24512	1.4539508	0.66439813	2934.7156
506.34619	1.4563012	0.66649336	2933.3555
507.44727	1.4647858	0.66850644	2941.6011
508.54834	1.466873	0.67054117	2940.9075
509.64941	1.4689543	0.6722216	2933.1602
510.75049	1.4701873	0.67395973	2937.7559
511.85156	1.4746319	0.67611706	2935.2761
512.95264	1.4789686	0.67817819	2938.95
514.05371	1.4809505	0.68033272	2937.3293
515.15479	1.4867165	0.68238401	2942.0735
516.25586	1.489628	0.68437338	2943.1799
517.35693	1.4938878	0.68629313	2942.3218
518.45801	1.4947267	0.68832541	2947.9324
519.55908	1.4968481	0.69025987	2940.3645
520.66016	1.5001713	0.69249004	2943.2263
521.76123	1.5027053	0.6943574	2939.0288
522.8623	1.5086576	0.69624984	2949.1394
523.96338	1.5103192	0.69827414	2942.7627
525.06445	1.5128802	0.70038712	2941.9258
526.16553	1.518456	0.70253193	2950.5012
527.2666	1.5207952	0.70471913	2948.1023
528.36768	1.523679	0.70674336	2948.4451
529.46875	1.5270106	0.70891333	2947.207
530.56982	1.5320758	0.71107	2951.3486
531.6709	1.535012	0.71277332	2953.9377
532.77197	1.5355824	0.71515912	2951.2529
533.87305	1.5421126	0.71707398	2952.1843
534.97412	1.5449073	0.71941942	2958.2327
536.0752	1.548355	0.72133398	2960.4395
537.17627	1.5505682	0.72330403	2953.2056
538.27734	1.5564301	0.72546959	2963.7312
539.37842	1.5579773	0.72727603	2954.1848
540.47949	1.5636891	0.72925633	2957.6072
541.58057	1.5619627	0.73132545	2958.9487
542.68164	1.5685058	0.73332494	2962.8015
543.78271	1.5701392	0.73560315	2958.5647
544.88379	1.5750948	0.73744392	2965.7097
545.98486	1.5776836	0.73928738	2957.5571
547.08594	1.5816305	0.74142492	2968.2249
548.18701	1.5837969	0.74325943	2965.8225
549.28809	1.5858605	0.74531651	2965.7114
550.38916	1.5904487	0.7473352	2963.8591
551.49023	1.5955441	0.74943316	2968.0132
552.59131	1.5970894	0.75134236	2964.1731
553.69238	1.6011611	0.75323087	2963.3774
554.79346	1.6072559	0.75521469	2964.9897
555.89453	1.605261	0.75704747	2964.1987
556.99561	1.6100775	0.7589196	2967.0083
558.09668	1.6157727	0.76093298	2975.1394
559.19775	1.6189307	0.7630496	2975.3645
560.29883	1.6212271	0.76522028	2978.989
561.3999	1.6212525	0.76728922	2968.6072
562.50098	1.6278657	0.76973414	2978.4199
563.60205	1.6278958	0.771882	2964.2813
564.70313	1.6328846	0.77419257	2984.9353
565.8042	1.633467	0.77641076	2974.8938
566.90527	1.6434194	0.77824825	2967.4985
568.00635	1.6441238	0.78024143	2972.4375
569.10742	1.6444191	0.78215426	2969.6511
570.2085	1.6498916	0.78406435	2976.574
571.30957	1.6532176	0.78625566	2977.812
572.41064	1.6546139	0.78840977	2973.7698
573.51172	1.6603141	0.79026675	2972.5857
574.61279	1.6647218	0.79238194	2984.3242
575.71387	1.6669648	0.79416066	2978.8384
576.81494	1.6704807	0.79618323	2979.6069
577.91602	1.6762261	0.79802012	2979.1833
579.01709	1.6770477	0.799963	2986.6355
580.11816	1.6790991	0.80195832	2976.657
581.21924	1.6825107	0.80372876	2978.9568
582.32031	1.6865371	0.80577296	2980.7156
583.42139	1.6866049	0.80778408	2981.6829
584.52246	1.6942033	0.80942947	2982.1943
585.62354	1.699295	0.81111312	2978.0935
586.72461	1.6968527	0.81309533	2989.5166
587.82568	1.7026777	0.81522298	2983.1282
588.92676	1.7072645	0.81712711	2986.2952
590.02783	1.7080998	0.81929171	2990.4031
591.12891	1.7117393	0.82148039	2986.2271
592.22998	1.7168329	0.82364506	2985.2671
593.33105	1.7185861	0.82551336	2981.8777
594.43213	1.7242154	0.82724196	2989.6855
595.5332	1.7256242	0.82934135	2989.4441
596.63428	1.7286869	0.83150405	2994.7178
597.73535	1.7324964	0.83375317	2983.1719
598.83643	1.7359787	0.835895	2989.1113
599.9375	1.7390988	0.83814323	2994.0835
601.03857	1.7407899	0.84043521	2986.1565
602.13965	1.7451851	0.84245074	2988.7505
603.24072	1.7485887	0.8445828	2992.7583
604.3418	1.7550602	0.84681636	2997.0986
605.44287	1.7518668	0.84849441	2993.2009
606.54395	1.7593421	0.85081673	2998.2734
607.64502	1.7608962	0.85305828	2995.5625
608.74609	1.7655185	0.85509479	2993.9077
609.84717	1.7713737	0.85734147	3001.4856
610.94824	1.7711003	0.8595112	2998.1538
612.04932	1.7757219	0.86155498	3001.1472
613.15039	1.7778271	0.86331207	2988.551
614.25146	1.7817094	0.86528939	2991.4932
615.35254	1.783205	0.86711353	2992.2988
616.45361	1.7920378	0.86896002	3002.322
617.55469	1.7911199	0.87074649	2996.7466
618.65576	1.7944295	0.87293708	3000.6453
619.75684	1.8001535	0.87461638	2998.551
620.85791	1.8024876	0.87680376	3010.676
621.95898	1.8042859	0.87887126	3001.3176
623.06006	1.8088245	0.88084614	3002.4895
624.16113	1.8087443	0.88282126	2999.7683
625.26221	1.8145944	0.88492233	3010.2485
626.36328	1.8185976	0.88730705	3010.7092
627.46436	1.8195167	0.8896476	3007.0293
628.56543	1.8269099	0.89175838	3005.2368
629.6665	1.8280828	0.89393872	3007.3384
630.76758	1.8332747	0.89556336	3003.8364
631.86865	1.8330438	0.89752728	3003.4819
632.96973	1.8377726	0.89938629	3003.6255
634.0708	1.8430058	0.90155023	3012.229
635.17188	1.8479282	0.90353549	3008.499
636.27295	1.848821	0.90580845	3018.5496
637.37402	1.8526922	0.90848565	3010.0093
638.4751	1.853613	0.91063452	3013.1758
639.57617	1.862747	0.9125126	3008.4973
640.67725	1.8611403	0.91432494	3010.5715
641.77832	1.8662214	0.9161815	3004.8149
642.87939	1.8680146	0.91820621	3011.4016
643.98047	1.8699894	0.92016488	3009.8945
645.08154	1.8702643	0.92245543	3011.8835
646.18262	1.8797696	0.92459142	3014.6333
647.28369	1.8812852	0.92659974	3014.6685
648.38477	1.8852136	0.92860293	3012.3418
649.48584	1.8857054	0.93023598	3009.8242
650.58691	1.89125	0.93170887	3010.3035
651.68799	1.8947341	0.93403631	3016.3057
652.78906	1.8993465	0.93593735	3018.343
653.89014	1.9009868	0.9379732	3020.3357
654.99121	1.903477	0.94018108	3017.1406
656.09229	1.9074426	0.94228303	3022.0239
657.19336	1.9109195	0.94482744	3022.1121
658.29443	1.9158543	0.94677991	3017.5288
659.39551	1.9172251	0.94897151	3018.7781
660.49658	1.9233919	0.9509486	3021.1372
661.59766	1.9225996	0.95320487	3019.6694
662.69873	1.9258113	0.95516217	3019.4446
663.7998	1.9339895	0.95723373	3026.7063
664.90088	1.9313004	0.95931822	3015.2773
666.00195	1.9338158	0.96131033	3016.6177
667.10303	1.940038	0.96347231	3015.8899
668.2041	1.9428389	0.96536303	3017.1423
669.30518	1.9491587	0.96715635	3023.5132
670.40625	1.9496794	0.9694255	3027.1096
671.50732	1.9542191	0.97176105	3022.9424
672.6084	1.9532818	0.97441477	3026.0911
673.70947	1.9612225	0.97657365	3028.3984
674.81055	1.9634005	0.97849625	3023.8914
675.91162	1.9661071	0.98049277	3019.8884
677.0127	1.9698225	0.98249948	3025.7415
678.11377	1.9724902	0.98427069	3027.7947
679.21484	1.9763837	0.98610288	3018.6553
680.31592	1.9783492	0.98814422	3030.5005
681.41699	1.983048	0.9904182	3029.4351
682.51807	1.984944	0.99269986	3026.1462
683.61914	1.9919841	0.99520707	3030.4395
684.72021	1.9934587	0.99753284	3036.366
685.82129	1.9973129	0.99965346	3027.0872
686.92236	2.0018733	1.0015215	3026.936
688.02344	2.0040567	1.0033139	3023.0186
689.12451	2.006531	1.0054357	3034.2415
690.22559	2.0101054	1.0077119	3032.9875
691.32666	2.014209	1.0096608	3031.625
692.42773	2.0174987	1.011863	3037.7537
693.52881	2.0216486	1.0138493	3032.6702
694.62988	2.023777	1.0159618	3033.9558
695.73096	2.0249672	1.0179663	3031.405
696.83203	2.0294385	1.0199651	3031.8103
697.93311	2.0319707	1.0221044	3033.8945
699.03418	2.0355942	1.0243028	3035.863
700.13525	2.03759	1.0263042	3033.3174
701.23633	2.0443177	1.0286603	3037.0159
702.3374	2.0482905	1.0305758	3030.9756
703.43848	2.0492048	1.0325335	3036.5957
704.53955	2.0526488	1.0345538	3035.5942
705.64063	2.0583949	1.0365839	3039.7732
706.7417	2.0582459	1.0386919	3036.6487
707.84277	2.0641131	1.0409733	3040.1685
708.94385	2.0669024	1.0434372	3039.1802
710.04492	2.0715442	1.0455436	3035.6428
711.146	2.072402	1.0478667	3033.1296
712.24707	2.0753379	1.0497044	3035.8445
713.34814	2.07951	1.0519902	3040.4395
714.44922	2.0816543	1.0543622	3040.4417
715.55029	2.086266	1.0566425	3052.1653
716.65137	2.0875475	1.0589764	3042.3545
717.75244	2.0918717	1.0611137	3036.0664
718.85352	2.0981846	1.0631082	3045.1462
719.95459	2.0994117	1.0652094	3041.9045
721.05566	2.1051905	1.0672029	3046.8625
722.15674	2.1069829	1.0693381	3043.1309
723.25781	2.1070888	1.0713652	3041.7246
724.35889	2.1123092	1.0732746	3040.4895
725.45996	2.1110272	1.0753666	3042.9812
726.56104	2.1219983	1.0771732	3040.1379
727.66211	2.1238606	1.0787107	3037.1047
728.76318	2.1265833	1.0803375	3041.6958
729.86426	2.1263559	1.0821614	3041.4309
730.96533	2.1310635	1.0841552	3043.2051
732.06641	2.135843	1.0863856	3045.9365
733.16748	2.1391785	1.0889735	3057.4673
734.26855	2.1400442	1.091252	3041.5564
735.36963	2.1453168	1.0934156	3046.4395
736.4707	2.1499205	1.0957451	3050.3159
737.57178	2.1540513	1.097834	3050.0977
738.67285	2.1556008	1.1001091	3042.6848
739.77393	2.1611612	1.1023725	3047.0942
740.875	2.1622188	1.1042974	3045.2544
741.97607	2.1646416	1.1066602	3053.6929
743.07715	2.1708806	1.108732	3054.1147
744.17822	2.174274	1.1109892	3043.6614
745.2793	2.1752756	1.1133366	3048.655
746.38037	2.181273	1.1155436	3056.5901
747.48145	2.1845975	1.1178061	3054.8904
748.58252	2.1863515	1.1203463	3050.6343
749.68359	2.1885989	1.1226859	3053.5581
750.78467	2.195013	1.1246679	3048.2332
751.88574	2.1934664	1.126682	3047.8555
752.98682	2.1989069	1.1289481	3050.4109
754.08789	2.1996205	1.1310883	3051.2866
755.18896	2.2067966	1.1329105	3044.0137
756.29004	2.2095282	1.1346647	3045.9392
757.39111	2.2109618	1.1365716	3053.3564
758.49219	2.2140179	1.1388034	3052.6799
759.59326	2.2153156	1.1407408	3051.1438
760.69434	2.2202818	1.1434094	3054.5413
761.79541	2.2240043	1.1455714	3051.4575
762.89648	2.2280691	1.1474805	3049.783
763.99756	2.2300715	1.149695	3052.239
765.09863	2.2335911	1.1518224	3056.6423
766.19971	2.2370284	1.1536528	3050.3921
767.30078	2.2406511	1.1555897	3049.1809
768.40186	2.2446456	1.1579938	3056.4587
769.50293	2.2492623	1.1600498	3056.1775
770.604	2.2506857	1.1622396	3059.4263
771.70508	2.2527599	1.1645061	3051.8037
772.80615	2.2574186	1.1669335	3054.3162
773.90723	2.2627285	1.1692675	3056.8911
775.0083	2.2634234	1.1715149	3055.3123
776.10938	2.2673111	1.1739506	3061.2817
777.21045	2.2721806	1.1761782	3056.7651
778.31152	2.2730417	1.1782558	3060.0732
779.4126	2.2796001	1.1807874	3061.4998
780.51367	2.2791209	1.1831465	3058.1555
781.61475	2.2835009	1.1854476	3064.7693
782.71582	2.2870798	1.1877904	3060.7163
783.81689	2.2920403	1.1900787	3061.2686
784.91797	2.2914288	1.1920877	3058.686
786.01904	2.2987871	1.1944104	3058.6738
787.12012	2.3018579	1.1966394	3059.3523
788.22119	2.3037834	1.1990836	3064.3416
789.32227	2.3094974	1.2014893	3068.3701
790.42334	2.3110065	1.2038598	3062.8167
791.52441	2.3132091	1.2064683	3062.3528
792.62549	2.3163314	1.2083865	3054.7083
793.72656	2.3179097	1.2105681	3063.6963
794.82764	2.3220782	1.2124752	3056.8123
795.92871	2.3268523	1.2142763	3058.9412
797.02979	2.3291371	1.2163099	3059.9929
798.13086	2.3343043	1.2180589	3062.1816
799.23193	2.3360581	1.2199866	3058.2427
800.33301	2.3406186	1.2223222	3069.814
801.43408	2.3445382	1.2239876	3059.9312
802.53516	2.3467374	1.2261616	3066.9253
803.63623	2.3488252	1.2283136	3069.2349
804.7373	2.3530259	1.2306895	3063.1331
805.83838	2.3577571	1.233235	3066.5767
806.93945	2.357965	1.2354466	3059.7498
808.04053	2.3645232	1.2377151	3068.1233
809.1416	2.3647289	1.2400708	3065.7246
810.24268	2.3688855	1.2422172	3059.3313
811.34375	2.3722262	1.2446432	3071.5496
812.44482	2.374964	1.2470182	3065.0977
813.5459	2.382242	1.2492558	3069.6719
814.64697	2.3807781	1.2512569	3062.7859
815.74805	2.3868856	1.2537546	3068.9294
816.84912	2.3889065	1.2560199	3065.6667
817.9502	2.3918924	1.2584029	3066.4895
819.05127	2.3985705	1.2607279	3066.488
820.15234	2.3979173	1.262713	3065.042
821.25342	2.400444	1.2653937	3071.5945
822.35449	2.4047956	1.2675489	3065.1687
823.45557	2.4086678	1.2698181	3066.1052
824.55664	2.4138055	1.2719398	3066.3352
825.65771	2.4147179	1.2739464	3069.5671
826.75879	2.4188292	1.2764965	3068.3164
827.85986	2.4226024	1.2786316	3067.7495
828.96094	2.4264193	1.2807838	3068.4348
830.06201	2.4295592	1.2833205	3069.2954
831.16309	2.4316666	1.2855564	3064.8091
832.26416	2.4342232	1.2878206	3069.3438
833.36523	2.4411118	1.2901996	3074.8887
834.46631	2.4403865	1.2924356	3064.2173
835.56738	2.4461462	1.294849	3071.4653
836.66846	2.4513454	1.297352	3078.4438
837.76953	2.4510972	1.2997085	3069.6003
838.87061	2.4596388	1.3019112	3069.8931
839.97168	2.4573615	1.3040032	3066.8601
841.07275	2.4622788	1.3064765	3073.8596
842.17383	2.4647954	1.3087469	3073.3459
843.2749	2.4692309	1.3112086	3072.4272
844.37598	2.471585	1.3135868	3076.9399
845.47705	2.4779532	1.3160427	3073.9844
846.57813	2.4776897	1.3182353	3068.1282
847.6792	2.4826131	1.3202419	3071.394
848.78027	2.4857931	1.3223962	3072.4597
849.88135	2.4876914	1.3246477	3065.3931
850.98242	2.4916899	1.327078	3069.8469
852.0835	2.4950888	1.3296093	3068.7839
853.18457	2.4982464	1.3320192	3072.46
854.28564	2.5011945	1.3349457	3077.2188
855.38672	2.5055156	1.3378016	3081.3496
856.48779	2.5100243	1.3402556	3072.3555
857.58887	2.5112109	1.342586	3071.0261
858.68994	2.5157299	1.3447093	3067.1948
859.79102	2.5187337	1.3467507	3068.4512
860.89209	2.5215826	1.3490256	3074.1482
861.99316	2.5256231	1.3511249	3072.166
863.09424	2.5278368	1.353586	3075.9849
864.19531	2.5329566	1.3563536	3088.5713
865.29639	2.5365307	1.3591635	3074.969
866.39746	2.5397465	1.3612684	3068.2568
867.49854	2.544246	1.3629975	3067.3645
868.59961	2.5449424	1.3654583	3072.0681
869.70068	2.5495839	1.3678715	3076.7126
870.80176	2.5498126	1.370162	3066.8494
871.90283	2.5551338	1.3724906	3075.6765
873.00391	2.5581543	1.3749005	3073.5049
874.10498	2.5609283	1.3772144	3075.969
875.20605	2.566124	1.3795313	3078.8105
876.30713	2.569206	1.3819278	3073.021
877.4082	2.5723376	1.3843504	3073.4333
878.50928	2.5759912	1.3865539	3072.8352
879.61035	2.5777991	1.3887935	3075.4165
880.71143	2.5815377	1.3909959	3071.7173
881.8125	2.5834944	1.3932575	3074.1672
882.91357	2.5888007	1.3958768	3079.384
884.01465	2.5892797	1.3983557	3077.4082
885.11572	2.5952728	1.4009815	3078.0476
886.2168	2.5998769	1.4036108	3083.5728
887.31787	2.5995955	1.406266	3077.4878
888.41895	2.6056201	1.4092268	3084.7947
889.52002	2.608269	1.411624	3071.5173
890.62109	2.611572	1.4138609	3073.5637
891.72217	2.6139069	1.4159447	3071.8735
892.82324	2.6202505	1.4185777	3074.3206
893.92432	2.6220882	1.4208541	3079.3118
895.02539	2.6230454	1.4233618	3072.2202
896.12646	2.6268506	1.4259633	3071.6218
897.22754	2.6353672	1.4283845	3078.7949
898.32861	2.6355488	1.4308226	3078.9175
899.42969	2.6384676	1.4331301	3072.9905
900.53076	2.6387517	1.4357004	3078.4824
901.63184	2.6457932	1.4383337	3077.0117
902.73291	2.64657	1.4409156	3079.9597
903.83398	2.651974	1.4434025	3069.1897
904.93506	2.6561356	1.4456576	3078.0278
906.03613	2.6536644	1.4479557	3069.0066
907.13721	2.663559	1.4503756	3071.814
908.23828	2.6658278	1.4527998	3081.634
909.33936	2.6702061	1.4552603	3070.9272
910.44043	2.6695828	1.4574537	3077.408
911.5415	2.6740313	1.4600952	3077.9678
912.64258	2.6787937	1.4626511	3077.4116
913.74365	2.6794174	1.4645448	3072.2864
914.84473	2.6841891	1.4670134	3080.46
915.9458	2.6888454	1.4692801	3076.481
917.04688	2.6885166	1.4716022	3079.4724
918.14795	2.6932051	1.4743989	3075.5337
919.24902	2.699023	1.4767973	3074.6357
920.3501	2.7004538	1.4793651	3080.7632
921.45117	2.7064376	1.4822328	3081.5229
922.55225	2.7069046	1.4851756	3078.6865
923.65332	2.7101021	1.4885076	3078.9004
924.75439	2.7122285	1.4908706	3072.813
925.85547	2.716063	1.4931065	3074.5369
926.95654	2.7212107	1.4956434	3073.4355
928.05762	2.7246478	1.4981563	3073.6306
929.15869	2.7285562	1.5005409	3074.5776
930.25977	2.7311096	1.5029854	3084.9358
931.36084	2.7312434	1.5055813	3075.6785
932.46191	2.7363369	1.5081834	3078.6797
933.56299	2.7412086	1.5107074	3077.9651
934.66406	2.7437141	1.5128868	3072.2153
935.76514	2.7471793	1.515166	3078.4556
936.86621	2.7487874	1.518069	3079.2493
937.96729	2.7538011	1.5207615	3078.1277
939.06836	2.7546062	1.5234573	3073.8699
940.16943	2.7601757	1.5262609	3080.8223
941.27051	2.7644327	1.5286608	3070.8506
942.37158	2.7690232	1.5312152	3078.1782
943.47266	2.7709079	1.5336797	3071.8765
944.57373	2.774277	1.536182	3079.7185
945.6748	2.7773275	1.5391648	3086.0107
946.77588	2.7798779	1.5420876	3075.5271
947.87695	2.7829731	1.544735	3078.4082
948.97803	2.7876933	1.5477828	3080.1528
950.0791	2.7900171	1.5504578	3081.8301
951.18018	2.7909739	1.5529091	3068.2307
952.28125	2.7966454	1.5552326	3073.1362
953.38232	2.8002386	1.557669	3076.5352
954.4834	2.8004591	1.5606321	3071.3389
955.58447	2.8067205	1.5632476	3073.3975
956.68555	2.8084352	1.5658844	3072.5593
957.78662	2.8119216	1.5685847	3075.3167
958.8877	2.8155003	1.5711011	3073.6289
959.98877	2.8199263	1.5738351	3081.571
961.08984	2.8244054	1.5764836	3074.2952
962.19092	2.8238852	1.5792027	3073.2756
963.29199	2.8306561	1.5817829	3073.5051
964.39307	2.8341565	1.5847088	3076.439
965.49414	2.8355985	1.5877836	3076.3074
966.59521	2.8399091	1.5905831	3073.3394
967.69629	2.8420444	1.5933733	3075.9163
968.79736	2.8476241	1.5962228	3082.5339
969.89844	2.8503416	1.5988573	3073.8853
970.99951	2.8540032	1.600955	3068.9607
972.10059	2.85531	1.6033269	3071.2781
973.20166	2.8588111	1.6063858	3077.0735
974.30273	2.8637478	1.608997	3074.8052
975.40381	2.8661768	1.6115482	3073.7061
976.50488	2.8684039	1.6141601	3071.6272
977.60596	2.872957	1.6165369	3068.2134
978.70703	2.877667	1.6191133	3071.4668
979.80811	2.8787112	1.6215596	3075.6904
980.90918	2.8829942	1.6245685	3083.0371
982.01025	2.8868515	1.6274438	3074.0894
983.11133	2.8906715	1.63036	3070.0276
984.2124	2.89236	1.6328872	3072.001
985.31348	2.8946505	1.635916	3072.8606
986.41455	2.8983479	1.6389453	3068.8472
987.51563	2.9038012	1.6416146	3072.4082
988.6167	2.906069	1.6444572	3072.7517
989.71777	2.9071496	1.6473613	3070.8872
990.81885	2.9147532	1.6502104	3072.5847
991.91992	2.9172661	1.6529409	3070.8506
993.021	2.9188433	1.6560746	3074.0156
994.12207	2.9218047	1.6586902	3067.9138
995.22314	2.9264493	1.6616924	3070.2378
996.32422	2.9287786	1.6643301	3070.0237
997.42529	2.9288476	1.6667747	3061.8088
998.52637	2.9372799	1.6696053	3078.8435
999.62744	2.9391367	1.6724972	3068.2163
1000.7285	2.9412575	1.6756096	3070.0732
1001.8296	2.94541	1.678452	3067.5046
1002.9307	2.9494953	1.6808928	3067.4065
1004.0317	2.9526432	1.6838633	3070.5449
1005.1328	2.9560199	1.686637	3067.3984
1006.2339	2.9590526	1.6893955	3064.6499
1007.335	2.959444	1.6922059	3066.5759
1008.436	2.9651828	1.6955215	3069.0483
1009.5371	2.9657066	1.6984611	3064.5803
1010.6382	2.9729064	1.7014284	3069.2651
1011.7393	2.9728024	1.7034689	3055.4929
1012.8403	2.9796145	1.7056532	3061.0728
1013.9414	2.9814682	1.7084501	3072.4673
1015.0425	2.9856536	1.7114793	3066.6719
1016.1436	2.9861567	1.7144678	3062.6436
1017.2446	2.992346	1.7174759	3060.8665
1018.3457	2.9943035	1.7198622	3063.769
1019.4468	2.9980328	1.722882	3064.7615
1020.5479	3.0005286	1.7258484	3064.5059
1021.6489	3.0035069	1.7285049	3061.2939
1022.75	3.0077448	1.7311307	3061.2334
1023.8511	3.0117919	1.7334893	3054.5728
1024.9521	3.0134132	1.7359246	3068.0649
1026.0532	3.0183344	1.7383956	3064.281
1027.1543	3.0196891	1.7410361	3059.5708
1028.2554	3.0250635	1.7443759	3060.8169
1029.3564	3.0280437	1.7467443	3054.8191
1030.4575	3.0290964	1.7493057	3058.9141
1031.5586	3.0379117	1.7526183	3064.4199
1032.6597	3.0373414	1.7554188	3059.1978
1033.7607	3.0408046	1.7584989	3062.3735
1034.8618	3.0442624	1.7614912	3064.3674
1035.9629	3.0449162	1.764665	3060.5491
1037.064	3.0496008	1.7681373	3064.0154
1038.165	3.0537233	1.7716178	3063.5513
1039.2661	3.0562656	1.7747785	3055.4385
1040.3672	3.0594053	1.7776705	3050.0354
1041.4683	3.0653133	1.7801471	3052.2295
1042.5693	3.0666988	1.7827123	3057.0989
1043.6704	3.070467	1.7856698	3059.7729
1044.7715	3.0742924	1.7888943	3055.2488
1045.8726	3.0758419	1.7919561	3055.0125
1046.9736	3.0795996	1.7948673	3056.5884
1048.0747	3.0819304	1.7982143	3057.5437
1049.1758	3.0888984	1.8014964	3057.7278
1050.2769	3.0910599	1.8043365	3050.2751
1051.3779	3.0930247	1.8065493	3047.1953
1052.479	3.0995986	1.8095503	3056.6243
1053.5801	3.1000483	1.8128216	3055.4602
1054.6812	3.1020353	1.8164605	3047.6567
1055.7822	3.1057355	1.819881	3050.3982
1056.8833	3.1119101	1.8226172	3048.9272
1057.9844	3.1138134	1.8257891	3053.8987
1059.0854	3.1166019	1.8288323	3048.3633
1060.1865	3.1226861	1.8320341	3047.4512
1061.2876	3.122474	1.8351077	3049.0149
1062.3887	3.1240375	1.838321	3045.981
1063.4897	3.1283145	1.8413739	3045.4836
1064.5908	3.1304181	1.8445917	3045.9504
1065.6919	3.1365011	1.8472495	3046.0413
1066.793	3.1398821	1.8503497	3043.9639
1067.894	3.1431029	1.8538805	3042.9106
1068.9951	3.1443095	1.8572004	3043.7622
1070.0962	3.1492355	1.8603892	3039.7012
1071.1973	3.1528273	1.8630459	3043.9951
1072.2983	3.156172	1.8660738	3037.2915
1073.3994	3.1600647	1.8692262	3044.0347
1074.5005	3.1636488	1.8726059	3041.9246
1075.6016	3.1657221	1.8757365	3042.6006
1076.7026	3.1695416	1.8788518	3039.3022
1077.8037	3.1776326	1.8821297	3044.0818
1078.9048	3.1768489	1.885546	3039.4778
1080.0059	3.1823547	1.8884813	3034.01
1081.1069	3.1823642	1.8908478	3033.5134
1082.208	3.1858752	1.8938422	3033.7898
1083.3091	3.190645	1.8975412	3035.0393
1084.4102	3.1929228	1.9007275	3034.8792
1085.5112	3.1941915	1.9040748	3028.2603
1086.6123	3.1980145	1.9070623	3032.3755
1087.7134	3.2037125	1.9102036	3032.9314
1088.8145	3.2054913	1.913377	3030.7832
1089.9155	3.2087591	1.9164729	3032.1299
1091.0166	3.212332	1.9200428	3027.2461
1092.1177	3.2174494	1.9231359	3025.9038
1093.2188	3.2196047	1.9261695	3025.3713
1094.3198	3.2234159	1.9293609	3025.3894
1095.4209	3.2275355	1.9325517	3026.1313
1096.522	3.2285147	1.9357946	3024.8872
1097.623	3.2310543	1.9395564	3019.8582
1098.7241	3.2373984	1.9420993	3018.0688
1099.8252	3.2393477	1.9450984	3019.4209
1100.9263	3.2431993	1.9481425	3025.3457
1102.0273	3.2466846	1.9516006	3016.864
1103.1284	3.2482491	1.955243	3012.4941
1104.2295	3.2510421	1.9585949	3014.4951
1105.3306	3.2580092	1.9617434	3011.6179
1106.4316	3.2572923	1.9648479	3015.2622
1107.5327	3.2627518	1.9682546	3015.2085
1108.6338	3.2639344	1.971877	3008.6211
1109.7349	3.2685456	1.9752691	3006.4167
1110.8359	3.2728541	1.978544	3015.6416
1111.937	3.278085	1.9817085	3008.5388
1113.0381	3.2794735	1.9847149	3006.2317
1114.1392	3.2848804	1.9885328	3012.4214
1115.2402	3.2847974	1.9917457	3002.0049
1116.3413	3.2885416	1.99433	2997.5107
1117.4424	3.293256	1.9972774	3007.0161
1118.5435	3.295577	2.0012097	3005.8965
1119.6445	3.2980018	2.005064	3001.1685
1120.7456	3.3002944	2.0083342	2989.478
1121.8467	3.3043835	2.0113637	2993.4319
1122.9478	3.3067052	2.014436	2995.4607
1124.0488	3.3121395	2.0182185	2994.1006
1125.1499	3.3160985	2.0224426	2993.7405
1126.251	3.3177562	2.0253038	2986.4226
1127.3521	3.3213186	2.0281715	2988.4771
1128.4531	3.327529	2.0312696	2986.9265
1129.5542	3.3279967	2.0341032	2988.9531
1130.6553	3.3310652	2.0368545	2983.042
1131.7563	3.3355017	2.0392015	2980.3823
1132.8574	3.3381548	2.0416744	2979.8489
1133.9585	3.3436282	2.043484	2988.4666
1135.0596	3.345454	2.044853	2982.7307
1136.1606	3.3478763	2.0456514	2980.3816
1137.2617	3.3496201	2.0457592	2977.9475
1138.3628	3.3529158	2.0459428	2976.2356
1139.4639	3.3566461	2.0461769	2979.531
1140.5649	3.359926	2.0464504	2969.4153
1141.666	3.3625495	2.0465777	2970.2393
1142.7671	3.3676052	2.0465925	2967.7939
1143.8682	3.372144	2.0466266	2972.9934
1144.9692	3.3737764	2.0466518	2960.262
1146.0703	3.3768725	2.0465512	2966.1685
1147.1714	3.3779817	2.0468235	2961.083
1148.2725	3.3855395	2.0466282	2962.427
1149.3735	3.3852203	2.0465128	2958.4497
1150.4746	3.3924069	2.0465565	2956.9077
1151.5757	3.3928769	2.0465729	2958.3589
1152.6768	3.3995843	2.0465169	2958.5071
1153.7778	3.4005086	2.0465829	2947.3923
1154.8789	3.4047499	2.046602	2948.6995
1155.98	3.4042006	2.0465679	2946.2383
1157.0811	3.4101577	2.0466461	2940.1904
1158.1821	3.4160237	2.0466337	2945.0188
1159.2832	3.4209433	2.0467834	2944.041
1160.3843	3.4186695	2.0468163	2937.7507
1161.4854	3.4260228	2.046581	2938.8582
1162.5864	3.4260106	2.0469038	2932.6013
1163.6875	3.4287498	2.0466607	2936.0112
1164.7886	3.4380922	2.0465772	2933.0859
1165.8896	3.4372363	2.0468156	2929.3745
1166.9907	3.4410615	2.0466945	2927.0806
1168.0918	3.4439368	2.0465982	2922.5706
1169.1929	3.4493372	2.0466042	2917.8633
1170.2939	3.4486713	2.0465276	2922.0227
1171.395	3.4542058	2.0464454	2924.0598
1172.4961	3.4582729	2.0465217	2913.1736
1173.5972	3.4616241	2.0465093	2911.0669
1174.6982	3.4647238	2.0464931	2907.9541
1175.7993	3.4622877	2.0466452	2908.9817
1176.9004	3.4669912	2.0466907	2906.416
1178.0015	3.4750676	2.0463471	2909.4236
1179.1025	3.4772468	2.0464575	2898.5364
1180.2036	3.4803591	2.0465775	2897.5693
1181.3047	3.4829011	2.0463507	2898.4304
1182.4058	3.4874823	2.0465028	2899.9099
1183.5068	3.4924345	2.0464566	2893.5898
1184.6079	3.4924467	2.0463507	2885.4792
1185.709	3.4963973	2.0464258	2883.0793
1186.8101	3.5000336	2.0466342	2883.2
1187.9111	3.5044956	2.0465503	2886.8262
1189.0122	3.5072298	2.0465205	2879.8896
1190.1133	3.5093412	2.0465972	2874.3845
1191.2144	3.5133731	2.0464957	2871.9856
1192.3154	3.5180283	2.0464904	2875.5906
1193.4165	3.5221636	2.0468545	2874.8967
1194.5176	3.5208044	2.0466664	2861.5974
1195.6187	3.5278876	2.0465224	2868.968
1196.7197	3.5263877	2.0466969	2858.8477
1197.8208	3.5322716	2.0466094	2865.302
1198.9219	3.5358517	2.0467956	2857.0002
1200.0229	3.5382357	2.0466151	2846.9941
1201.124	3.542228	2.0469804	2850.6814
1202.2251	3.5504632	2.0468829	2854.1094
1203.3262	3.5495713	2.046767	2846.7439
1204.4272	3.5534251	2.0470641	2838.9663
1205.5283	3.5548589	2.0471087	2837.8293
1206.6294	3.5616786	2.0470195	2835.4846
1207.7305	3.5621231	2.0472829	2832.5999
1208.8315	3.5669303	2.0472002	2830.3586
1209.9326	3.571605	2.0472779	2828.0356
1211.0337	3.5749538	2.0472476	2824.4912
1212.1348	3.5734432	2.0474443	2814.1836
1213.2358	3.5771041	2.0477076	2814.4595
1214.3369	3.5817194	2.0475039	2816.0837
1215.438	3.5875571	2.0475118	2809.459
1216.5391	3.5884974	2.0475054	2804.1641
1217.6401	3.5923476	2.0473969	2795.6677
1218.7412	3.5967774	2.0475035	2799.6143
1219.8423	3.5975194	2.0474176	2789.7104
1220.9434	3.6031744	2.0475516	2795.9612
1222.0444	3.6044283	2.047375	2790.4856
1223.1455	3.6068716	2.0473497	2784.1484
1224.2466	3.6109879	2.0476549	2776.064
1225.3477	3.6146522	2.04743	2773.1406
1226.4487	3.6196899	2.0473299	2775.9641
1227.5498	3.6224322	2.0475178	2773.0115
1228.6509	3.6252692	2.0472741	2762.052
1229.752	3.6276388	2.0472226	2761.0066
1230.853	3.6329741	2.0472231	2764.1565
1231.9541	3.6351891	2.047194	2749.761
1233.0552	3.6387734	2.0470953	2750.283
1234.1563	3.6427948	2.0469413	2747.7673
1235.2573	3.6457813	2.0469518	2741.5925
1236.3584	3.6492708	2.0467942	2745.1262
1237.4595	3.6519516	2.0471518	2737.5278
1238.5605	3.6543543	2.047045	2732.8237
1239.6616	3.6606326	2.0471296	2722.4617
1240.7627	3.6628706	2.047158	2725.1089
1241.8638	3.664705	2.0470476	2719.5959
1242.9648	3.6702373	2.0469265	2708.2034
1244.0659	3.6719182	2.0470381	2707.9199
1245.167	3.6766772	2.0472124	2698.8789
1246.2681	3.6792197	2.0471694	2701.5127
1247.3691	3.6837101	2.0469313	2693.595
1248.4702	3.6869893	2.0472236	2689.3167
1249.5713	3.6870511	2.0471754	2675.4978
1250.6724	3.6919482	2.0471048	2681.3306
1251.7734	3.6943502	2.0472746	2670.4412
1252.8745	3.6989806	2.0472381	2664.3193
1253.9756	3.703851	2.0471451	2666.1836
1255.0767	3.7052774	2.0472529	2653.9326
1256.1777	3.709157	2.0472484	2646.8464
1257.2788	3.7107952	2.0474784	2641.3276
1258.3799	3.7150853	2.0471742	2643.5503
1259.481	3.7164052	2.0472739	2640.9539
1260.582	3.7221768	2.0472765	2629.7354
1261.6831	3.7240436	2.0471437	2621.9631
1262.7842	3.7304332	2.0470078	2617.7004
1263.8853	3.7324038	2.0472267	2611.7439
1264.9863	3.7334533	2.0472617	2604.2451
1266.0874	3.7359231	2.0471303	2600.8335
1267.1885	3.7424047	2.0471404	2593.3516
1268.2896	3.7436326	2.0472202	2578.5881
1269.3906	3.7467604	2.0471003	2563.4653
1270.4917	3.751056	2.0472617	2543.9656
1271.5928	3.756263	2.0471215	2531.605
1272.6938	3.7591074	2.0473809	2513.2007
1273.6948	3.7640102	2.0473347	2442.2349