File: datasets/am_bench_2022/raw_data/60-XY.09-2/specimen.dat
MTS793|MPT|ENU|1|2|.|/|:|1|0|0|A

Operator Information						Time:	11.25415	Sec	11/1/2021 2:32:12 PM
Operator	Nick Derimow
Project	AM Bench 2022 mini-tensile challenge
Specimen ID	60-XY.09-2
Material	PBF-L Inconel 625
Specimen Width	2.55	mm
Specimen Thickness	1.51	mm
Notes
Operator Information End

Data Acquisition						Time:	1012.248	Sec	11/1/2021 2:48:53 PM
Time	Axial Displacement	Axial Extensometer	Axial Force
Sec	mm	mm	N
11.36792	0.0034706702	7.4224597e-05	63.645481
12.368896	0.0053668851	0.00014061235	74.802528
13.369873	0.0074448381	0.00016723177	86.768982
14.37085	0.011321529	0.00011962024	98.99559
15.371826	0.012943446	0.0002547192	112.8127
16.372803	0.016646234	0.00028130072	126.02001
17.373779	0.020801168	0.00031084599	136.38297
18.374756	0.02204214	0.0003181565	147.83359
19.375732	0.027909348	0.00036737541	160.4212
20.376709	0.029350346	0.00047453545	175.36084
21.377686	0.031078344	0.0004855053	190.36847
22.378662	0.034718387	0.00053648936	211.67288
23.379639	0.037747238	0.00068212481	230.32074
24.380615	0.039900437	0.00061367999	245.40952
25.381592	0.041764535	0.00083369703	262.98392
26.382568	0.044860795	0.00082426384	282.41229
27.383545	0.050951336	0.00093452691	309.67105
28.384521	0.051092658	0.00092206238	321.43469
29.385498	0.054455739	0.001088693	342.05182
30.386475	0.059102613	0.0011788369	364.50146
31.387451	0.060778212	0.0011754357	387.13254
32.388428	0.06348969	0.0013981326	408.85458
33.389404	0.065064631	0.0013717632	431.62048
34.390381	0.071998909	0.0014446307	455.26022
35.391357	0.070632137	0.0015112847	470.03244
36.392334	0.076862156	0.001655526	495.51968
37.393311	0.080690287	0.0017513237	521.14923
38.394287	0.081701219	0.0018469535	541.90399
39.395264	0.084170766	0.0019499061	567.79926
40.39624	0.085830949	0.0020234978	591.05243
41.397217	0.08737091	0.0021061867	611.6145
42.398193	0.092476688	0.0022427987	639.10352
43.39917	0.096303031	0.0023806146	664.70081
44.400146	0.099527754	0.0025243035	695.33484
45.401123	0.1037669	0.0025492297	720.46906
46.4021	0.10564549	0.0026518626	748.23962
47.403076	0.10960992	0.0028713357	769.78479
48.404053	0.11053829	0.0029407137	794.94818
49.405029	0.11476002	0.0030862386	827.60809
50.406006	0.11650092	0.0030423847	850.94482
51.406982	0.11916609	0.0031571258	877.20471
52.407959	0.12459488	0.003331159	902.31451
53.408936	0.12599157	0.0034690078	928.27588
54.409912	0.12647901	0.003570149	953.22583
55.410889	0.13327186	0.0037376371	991.46295
56.411865	0.13422686	0.00378388	1013.8267
57.412842	0.14033358	0.0040015667	1054.8425
58.413818	0.14008546	0.0041777217	1081.0959
59.414795	0.1408122	0.004339227	1110.4565
60.415771	0.14836726	0.0043751812	1140.1942
61.416748	0.14899197	0.0045751557	1173.0541
62.417725	0.15476246	0.0046673566	1208.093
63.418701	0.15746124	0.0047599981	1227.1027
64.419678	0.16050525	0.0049182139	1260.0348
65.420654	0.1634772	0.0050407243	1287.3334
66.421631	0.16181533	0.0051054358	1307.3411
67.422607	0.16918044	0.0053309696	1338.8387
68.423584	0.16947466	0.0053231674	1366.7797
69.424561	0.17467351	0.0054922989	1397.2433
70.425537	0.17815769	0.0056509562	1437.4221
71.426514	0.17940275	0.0057519632	1457.0658
72.42749	0.18547358	0.0059231957	1489.9022
73.428467	0.188675	0.0059868102	1512.1333
74.429443	0.18773393	0.0061288266	1543.0043
75.43042	0.19125949	0.006250428	1569.5663
76.431396	0.19506508	0.0063504959	1595.2594
77.432373	0.19797592	0.0064894715	1613.231
78.43335	0.19942199	0.0065724924	1639.1758
79.434326	0.20354337	0.0066767232	1663.3162
80.435303	0.20636836	0.006823957	1697.5807
81.436279	0.21105929	0.0069102468	1724.2228
82.437256	0.21299791	0.0069205118	1745.5088
83.438232	0.21740982	0.0071048709	1772.0115
84.439209	0.21907656	0.0071989144	1793.62
85.440186	0.22297251	0.007505158	1833.1895
86.441162	0.22496323	0.0075001013	1850.1527
87.442139	0.22783862	0.0076047913	1889.1362
88.443115	0.23382077	0.0076961103	1916.0065
89.444092	0.23751634	0.0078658238	1943.1183
90.445068	0.23801525	0.0079691	1959.4867
91.446045	0.23999281	0.007958699	1979.6125
92.447021	0.24429367	0.0082282266	2012.3258
93.447998	0.24820499	0.0083184913	2034.8315
94.448975	0.24762331	0.0083267028	2047.7855
95.449951	0.25238389	0.0084730024	2075.2383
96.450928	0.25300181	0.0085803811	2098.3928
97.451904	0.25989509	0.0086365324	2113.9546
98.452881	0.26112404	0.0086969752	2133.7595
99.453857	0.26525703	0.0088680228	2155.3313
100.45483	0.27206203	0.0089187995	2171.3809
101.45581	0.2708413	0.0089715747	2191.9219
102.45679	0.27580658	0.0090250624	2200.3071
103.45776	0.27626118	0.0092508709	2217.7859
104.45874	0.28023478	0.0093506221	2242.5959
105.45972	0.28372979	0.0093236873	2252.9631
106.46069	0.28420269	0.0093824826	2270.8625
107.46167	0.28916734	0.0095029818	2293.1333
108.46265	0.29167026	0.0095688822	2305.488
109.46362	0.29538384	0.0096088471	2318.2036
110.4646	0.29921141	0.0097562158	2342.3408
111.46558	0.30201632	0.0097213313	2350.8188
112.46655	0.30487493	0.0098310253	2364.0798
113.46753	0.30781934	0.0099478438	2377.5867
114.46851	0.31106216	0.0099442126	2385.4202
115.46948	0.31461021	0.010073986	2404.624
116.47046	0.31725305	0.010083894	2419.2678
117.47144	0.3215178	0.010227132	2431.5286
118.47241	0.32148543	0.010344472	2447.2749
119.47339	0.3262938	0.010436548	2453.9128
120.47437	0.33017823	0.010548557	2469.7185
121.47534	0.33177024	0.010581749	2481.8435
122.47632	0.33357403	0.010652333	2489.3701
123.47729	0.33716947	0.010716455	2500.4373
124.47827	0.34214601	0.010758301	2518.6748
125.47925	0.34042555	0.010888188	2516.0518
126.48022	0.34859076	0.011055427	2535.3789
127.4812	0.34755853	0.011057882	2540.9658
128.48218	0.34922674	0.011251997	2558.1501
129.48315	0.35629031	0.011388863	2568.7937
130.48413	0.35995406	0.011456001	2583.2122
131.48511	0.36088878	0.01161301	2589.5461
132.48608	0.36479032	0.011680521	2602.4688
133.48706	0.36703688	0.011871305	2608.4094
134.48804	0.37060583	0.011920471	2618.8984
135.48901	0.37273404	0.012161875	2630.4683
136.48999	0.37362668	0.012278706	2629.3813
137.49097	0.38241237	0.012406004	2643.229
138.49194	0.38328314	0.01245823	2652.9995
139.49292	0.38915521	0.01264244	2656.5034
140.4939	0.3901301	0.012849087	2673.5945
141.49487	0.39097896	0.012915602	2673.3567
142.49585	0.3947399	0.013219133	2685.4451
143.49683	0.39911509	0.013465499	2699.791
144.4978	0.400547	0.0136914	2700.6882
145.49878	0.4059512	0.013955866	2711.8154
146.49976	0.40803286	0.014156313	2714.4546
147.50073	0.40663904	0.014565382	2725.9353
148.50171	0.4111701	0.014774343	2732.7527
149.50269	0.41718012	0.015097761	2738.2332
150.50366	0.41945726	0.015483951	2750.5483
151.50464	0.42114142	0.015764223	2756.645
152.50562	0.42713419	0.016206732	2762.5012
153.50659	0.43017864	0.016500089	2764.5244
154.50757	0.43149856	0.016922195	2769.6538
155.50854	0.43353108	0.017337143	2776.0632
156.50952	0.44092011	0.017856807	2785.3376
157.5105	0.44003522	0.018313851	2791.0391
158.51147	0.44458908	0.018820332	2797.7703
159.51245	0.44564795	0.019344052	2801.3494
160.51343	0.44869545	0.02001396	2806.5374
161.5144	0.4546077	0.020550892	2815.7292
162.51538	0.45425978	0.021128625	2816.5945
163.51636	0.45677891	0.021887805	2822.4189
164.51733	0.46131599	0.022519035	2830.4717
165.51831	0.4650726	0.023156283	2829.3923
166.51929	0.46565592	0.023747487	2837.0798
167.52026	0.47194931	0.024560291	2848.1189
168.52124	0.47188866	0.025330612	2850.1633
169.52222	0.47666585	0.026099082	2855.4451
170.52319	0.4795531	0.026861915	2855.3113
171.52417	0.48537114	0.027620643	2867.042
172.52515	0.48562974	0.028558055	2866.1162
173.52612	0.48914519	0.029287592	2868.2175
174.5271	0.49270451	0.030083809	2876.7566
175.52808	0.49610358	0.03092473	2881.0398
176.52905	0.49750936	0.031678669	2871.8123
177.53003	0.49924213	0.032304779	2879.2747
178.53101	0.50078291	0.033143722	2884.7861
179.53198	0.50522071	0.034109209	2890.2102
180.53296	0.5104624	0.035023347	2897.5271
181.53394	0.51312065	0.036200661	2900.6174
182.53491	0.51554489	0.037209731	2900.0891
183.53589	0.51924253	0.038435504	2910.0535
184.53687	0.52245885	0.03938273	2906.9163
185.53784	0.52505785	0.040381704	2909.1335
186.53882	0.52726763	0.041278448	2912.1643
187.53979	0.53256315	0.042161465	2919.8066
188.54077	0.53146017	0.043226425	2918.7759
189.54175	0.5371471	0.044341289	2924.1973
190.54272	0.54117507	0.045251038	2927.4688
191.5437	0.54444814	0.046274822	2933.5881
192.54468	0.54431617	0.047345713	2931.1458
193.54565	0.55158192	0.048510354	2939.5388
194.54663	0.55296165	0.04973191	2941.042
195.54761	0.55569017	0.050825849	2947.0459
196.54858	0.55821806	0.051831402	2938.8298
197.54956	0.5591265	0.052733913	2946.6255
198.55054	0.56638044	0.053873859	2952.3999
199.55151	0.56758583	0.055184536	2951.3196
200.55249	0.56941402	0.056418791	2956.4658
201.55347	0.57385457	0.057605326	2965.7378
202.55444	0.574	0.058804475	2963.2959
203.55542	0.57793385	0.059785787	2963.7866
204.5564	0.58179396	0.060979728	2967.4297
205.55737	0.58457083	0.062018123	2967.5193
206.55835	0.58536845	0.06328088	2975.563
207.55933	0.59197962	0.064732149	2973.8931
208.5603	0.59483254	0.065693736	2974.4568
209.56128	0.59643757	0.066737555	2977.4534
210.56226	0.60170442	0.067788675	2978.5916
211.56323	0.60610932	0.068855956	2981.4827
212.56421	0.60626996	0.069947079	2986.0293
213.56519	0.60590732	0.071237154	2988.4341
214.56616	0.61297596	0.07231091	2988.0217
215.56714	0.61350292	0.073403306	2986.2183
216.56812	0.61804163	0.074623697	2992.7432
217.56909	0.62083346	0.075732872	2993.7156
218.57007	0.62394714	0.076910995	2999.1367
219.57104	0.62533545	0.078107715	3000.0378
220.57202	0.62803161	0.079417624	2999.8821
221.573	0.63247055	0.080450177	3004.5002
222.57397	0.63383877	0.081673555	3007.4229
223.57495	0.63784313	0.082920089	3006.032
224.57593	0.64148396	0.084076531	3008.4839
225.5769	0.64296633	0.085227214	3011.9993
226.57788	0.64954489	0.086241648	3014.323
227.57886	0.65325397	0.087626085	3019.532
228.57983	0.65665245	0.088894174	3025.1519
229.58081	0.65731508	0.090201117	3019.2402
230.58179	0.6611746	0.091385625	3026.9636
231.58276	0.66161841	0.092357278	3021.7075
232.58374	0.66310936	0.093598023	3022.2742
233.58472	0.66760051	0.095113866	3033.7361
234.58569	0.67069227	0.096417889	3031.8342
235.58667	0.67524576	0.097628936	3032.7805
236.58765	0.67966312	0.098905325	3037.0229
237.58862	0.6799022	0.10001723	3035.7737
238.5896	0.68369305	0.10109059	3038.9414
239.59058	0.68585074	0.10230425	3036.2393
240.59155	0.68957812	0.10348526	3043.9385
241.59253	0.69293147	0.10477501	3044.7852
242.59351	0.69550407	0.10604226	3043.3533
243.59448	0.70040667	0.10720188	3050.0313
244.59546	0.70345336	0.10845976	3052.7437
245.59644	0.7057032	0.10977247	3052.4653
246.59741	0.70895606	0.11099011	3056.9697
247.59839	0.7109822	0.1123485	3061.3828
248.59937	0.7148245	0.11338855	3056.2598
249.60034	0.72005588	0.11466052	3066.1069
250.60132	0.72162575	0.11566475	3062.0608
251.60229	0.72155732	0.11709809	3061.3884
252.60327	0.72768557	0.11852677	3071.665
253.60425	0.72899604	0.11959871	3060.1392
254.60522	0.73347872	0.12100205	3078.0222
255.6062	0.73644185	0.12235229	3074.7427
256.60718	0.73819244	0.12352663	3068.6233
257.60815	0.74173003	0.12448442	3067.5183
258.60913	0.74653852	0.12557644	3079.4834
259.61011	0.74422371	0.12681469	3075.2344
260.61108	0.75175196	0.12806283	3079.8579
261.61206	0.75369102	0.12920831	3083.5056
262.61304	0.75914085	0.13056296	3089.8967
263.61401	0.75711781	0.13204692	3084.738
264.61499	0.76226503	0.13337745	3090.0322
265.61597	0.76473141	0.13479407	3087.2886
266.61694	0.76544201	0.13603678	3084.0762
267.61792	0.77179563	0.13738605	3095.7903
268.6189	0.77208328	0.13877217	3091.1296
269.61987	0.77873743	0.14004743	3096.8167
270.62085	0.7811166	0.1411667	3106.8525
271.62183	0.78420734	0.14244251	3095.8535
272.6228	0.7857942	0.14364202	3097.8562
273.62378	0.78938466	0.144823	3101.2097
274.62476	0.79316443	0.14607422	3102.0115
275.62573	0.79554838	0.14746341	3106.3247
276.62671	0.79953814	0.14852211	3102.0588
277.62769	0.80188984	0.14971042	3108.1301
278.62866	0.80336255	0.15096493	3112.2351
279.62964	0.80848646	0.15232447	3111.9023
280.63062	0.80882615	0.15334934	3110.429
281.63159	0.81179112	0.15449534	3107.9404
282.63257	0.81732202	0.15553796	3110.3472
283.63354	0.81931174	0.1566163	3117.4939
284.63452	0.82384408	0.15801261	3117.6306
285.6355	0.82344532	0.15905194	3119.1875
286.63647	0.82777095	0.16030443	3120.7961
287.63745	0.83012551	0.16155034	3122.3855
288.63843	0.83787608	0.16288923	3134.8262
289.6394	0.83658326	0.16407816	3123.0164
290.64038	0.84286058	0.16533524	3125.9585
291.64136	0.84368628	0.16636641	3127.9119
292.64233	0.84463799	0.16767456	3134.2444
293.64331	0.85018492	0.16915445	3135.9519
294.64429	0.85253239	0.170443	3140.1846
295.64526	0.85670823	0.17186159	3144.7244
296.64624	0.85623473	0.17311384	3134.4177
297.64722	0.85932648	0.174399	3136.2554
298.64819	0.86296064	0.17547013	3138.9507
299.64917	0.8700909	0.17678466	3142.8928
300.65015	0.86969489	0.17797543	3146.4998
301.65112	0.87269461	0.17923437	3146.2983
302.6521	0.87535	0.18063907	3148.8694
303.65308	0.87908798	0.18190192	3147.3452
304.65405	0.88362896	0.18314491	3153.4885
305.65503	0.88488263	0.18444461	3152.5327
306.65601	0.89020586	0.1855067	3154.1208
307.65698	0.89190662	0.18683037	3154.551
308.65796	0.89223588	0.18792896	3149.3191
309.65894	0.8985917	0.18911442	3151.4575
310.65991	0.90028328	0.19029555	3153.9436
311.66089	0.90557617	0.19158545	3160.6577
312.66187	0.90448701	0.1928535	3162.4951
313.66284	0.9070338	0.19424148	3164.1196
314.66382	0.90964693	0.19539508	3164.1875
315.66479	0.91293865	0.19670279	3164.2878
316.66577	0.91681987	0.19789177	3159.6968
317.66675	0.91952521	0.1990238	3161.7363
318.66772	0.92365247	0.20003514	3174.8889
319.6687	0.92834342	0.20128845	3168.0608
320.66968	0.92965102	0.20255907	3175.7554
321.67065	0.9330126	0.2037639	3172.6682
322.67163	0.93603921	0.2049337	3175.1211
323.67261	0.93894166	0.20633675	3178.5251
324.67358	0.9431116	0.20780711	3181.0559
325.67456	0.94813645	0.20898287	3179.24
326.67554	0.9495092	0.21001391	3177.8931
327.67651	0.95082068	0.21129633	3182.9202
328.67749	0.95489967	0.21255869	3191.5706
329.67847	0.95330846	0.21368684	3180.4028
330.67944	0.96123844	0.21494634	3193.6494
331.68042	0.96609086	0.21620345	3190.0679
332.6814	0.96676618	0.21747155	3193.3723
333.68237	0.96924245	0.21875621	3191.7019
334.68335	0.97273558	0.22012633	3196.144
335.68433	0.97439927	0.22135676	3198.0996
336.6853	0.97930473	0.22266483	3198.4731
337.68628	0.9817425	0.22394177	3196.7249
338.68726	0.98514467	0.22509302	3197.5559
339.68823	0.98804015	0.22620836	3198.0415
340.68921	0.99171484	0.22729313	3197.4827
341.69019	0.99582535	0.22842877	3206.7666
342.69116	0.99554569	0.22995615	3203.4397
343.69214	0.99763799	0.2312495	3203.0876
344.69312	1.0029902	0.23258604	3205.4636
345.69409	1.0035568	0.23382822	3205.3503
346.69507	1.0074484	0.23521982	3211.4167
347.69604	1.0105628	0.2365482	3203.0232
348.69702	1.0119394	0.23796658	3207.8098
349.698	1.0181942	0.23886259	3212.2954
350.69897	1.0235739	0.2400723	3214.8591
351.69995	1.0226545	0.24105427	3214.9697
352.70093	1.0254153	0.24214293	3219.4902
353.7019	1.0286044	0.24353626	3217.4736
354.70288	1.0311211	0.24491578	3223.3215
355.70386	1.0384536	0.24629234	3225.4697
356.70483	1.0405636	0.24750032	3222.167
357.70581	1.0410123	0.24862851	3226.0857
358.70679	1.0445369	0.24988759	3229.0159
359.70776	1.046698	0.25128213	3227.0007
360.70874	1.0490042	0.2522839	3221.5078
361.70972	1.0520597	0.25345388	3227.813
362.71069	1.055627	0.25448331	3230.3171
363.71167	1.0630088	0.25571305	3241.6348
364.71265	1.0625467	0.25705314	3238.9294
365.71362	1.0635748	0.25847903	3234.9583
366.7146	1.0677282	0.25977695	3237.5425
367.71558	1.0689322	0.26096094	3234.9785
368.71655	1.0747128	0.26216748	3238.5925
369.71753	1.0773329	0.26345655	3245.5759
370.71851	1.0806909	0.26482362	3244.6448
371.71948	1.0836676	0.26624551	3244.1355
372.72046	1.089615	0.26752868	3246.6938
373.72144	1.0913445	0.26858702	3240.0154
374.72241	1.0913686	0.2698032	3251.115
375.72339	1.0968992	0.27093765	3246.9316
376.72437	1.0986476	0.27230889	3254.9727
377.72534	1.0998006	0.27346462	3248.0098
378.72632	1.1036041	0.27474731	3255.2236
379.72729	1.1079975	0.27603123	3255.354
380.72827	1.1096559	0.27747709	3251.4966
381.72925	1.1119422	0.27855441	3249.6187
382.73022	1.1167444	0.27963758	3258.9197
383.7312	1.1192031	0.28082222	3260.7278
384.73218	1.1245964	0.28214258	3264.9783
385.73315	1.1266502	0.28364643	3268.2478
386.73413	1.1280317	0.28501689	3256.9146
387.73511	1.131394	0.28606924	3259.2227
388.73608	1.1343306	0.28727922	3263.5547
389.73706	1.1368729	0.28832686	3260.5955
390.73804	1.1411282	0.28937724	3261.5881
391.73901	1.143097	0.29070887	3268.8564
392.73999	1.1458746	0.29206035	3271.2554
393.74097	1.1501683	0.2933774	3269.3921
394.74194	1.1530954	0.29456681	3272.9421
395.74292	1.156709	0.29575676	3273.0757
396.7439	1.1594727	0.29700795	3276.1252
397.74487	1.1636869	0.29819411	3275.2083
398.74585	1.1663002	0.29957724	3281.2495
399.74683	1.1669136	0.30077606	3274.3628
400.7478	1.1707283	0.30202046	3280.1174
401.74878	1.1730843	0.30325988	3278.0911
402.74976	1.1770407	0.3041167	3280.731
403.75073	1.1809732	0.30543542	3287.3081
404.75171	1.1833752	0.30673918	3287.0552
405.75269	1.1860521	0.30819848	3287.7346
406.75366	1.1885104	0.30971321	3291.5032
407.75464	1.1929097	0.31071845	3283.6536
408.75562	1.1954727	0.31194928	3292.1345
409.75659	1.1986458	0.31332427	3295.7834
410.75757	1.2000821	0.31441969	3286.4902
411.75854	1.2024996	0.31571841	3288.8008
412.75952	1.2079252	0.31703755	3295.0107
413.7605	1.2100213	0.31840342	3296.2556
414.76147	1.2152221	0.31980225	3301.3953
415.76245	1.2164277	0.32111645	3295.8875
416.76343	1.2155716	0.32217285	3293.4265
417.7644	1.2194041	0.32320172	3288.6472
418.76538	1.2259595	0.32427713	3293.6353
419.76636	1.2281735	0.32538721	3301.9871
420.76733	1.2347584	0.32671818	3303.5984
421.76831	1.2307506	0.32778579	3295.9431
422.76929	1.2378222	0.3292326	3309.6326
423.77026	1.2371026	0.330448	3303.7925
424.77124	1.245392	0.33169967	3307.7185
425.77222	1.2458624	0.33285871	3306.4751
426.77319	1.2463739	0.33405849	3305.1821
427.77417	1.2508556	0.33534935	3313.572
428.77515	1.2532759	0.33685684	3313.5737
429.77612	1.2555573	0.33809558	3308.6809
430.7771	1.2617639	0.33922705	3314.499
431.77808	1.2641585	0.34045264	3319.0381
432.77905	1.2660884	0.3417463	3319.4695
433.78003	1.2700298	0.34287119	3310.989
434.78101	1.2725856	0.34411174	3319.7295
435.78198	1.2775695	0.34525099	3322.7012
436.78296	1.2784739	0.34654355	3319.7969
437.78394	1.2840112	0.3479344	3327.1289
438.78491	1.285403	0.34934434	3322.1064
439.78589	1.2859458	0.35059676	3322.7886
440.78687	1.2915999	0.35190606	3326.6431
441.78784	1.2927276	0.35312021	3321.7847
442.78882	1.2971839	0.35450467	3328.1948
443.78979	1.3011833	0.35568497	3327.4656
444.79077	1.3035023	0.35670656	3325.4946
445.79175	1.3068686	0.35776311	3335.4844
446.79272	1.3099176	0.35904872	3331.1882
447.7937	1.3115628	0.36050931	3339.4373
448.79468	1.3134357	0.36191902	3332.9451
449.79565	1.3149391	0.36315006	3332.3076
450.79663	1.3209348	0.36459216	3337.7622
451.79761	1.3218838	0.36553535	3329.7424
452.79858	1.3243126	0.36691099	3336.7168
453.79956	1.3296196	0.36817899	3343.0273
454.80054	1.331154	0.36959299	3339.6494
455.80151	1.3338037	0.37071905	3337.427
456.80249	1.3402293	0.37173375	3338.2598
457.80347	1.3399603	0.37285349	3341.8425
458.80444	1.3423598	0.37413698	3342.7156
459.80542	1.3470759	0.37541929	3352.7102
460.8064	1.3502017	0.3766644	3343.8335
461.80737	1.3536373	0.377967	3350.6304
462.80835	1.3596926	0.37915981	3354.2014
463.80933	1.3610134	0.38040242	3352.1724
464.8103	1.3601472	0.38165495	3348.4526
465.81128	1.3657395	0.38277623	3347.7227
466.81226	1.368552	0.38398498	3352.3474
467.81323	1.3704308	0.38519594	3357.6084
468.81421	1.3733317	0.38649586	3351.905
469.81519	1.3789463	0.38802773	3360.8032
470.81616	1.3815781	0.38931689	3356.7944
471.81714	1.3831398	0.39056945	3358.8633
472.81812	1.3880625	0.39199039	3361.4119
473.81909	1.3890625	0.39340773	3355.396
474.82007	1.3934646	0.39462116	3360.865
475.82104	1.3967782	0.39594951	3361.4253
476.82202	1.397252	0.39708173	3361.4561
477.823	1.4008485	0.39842069	3373.3369
478.82397	1.4031671	0.39989111	3360.8445
479.82495	1.4066767	0.4011701	3371.0898
480.82593	1.4079434	0.40235317	3364.1108
481.8269	1.4140443	0.40372461	3373.1262
482.82788	1.4167693	0.40503234	3372.082
483.82886	1.4195446	0.40643901	3372.4441
484.82983	1.4232923	0.40771559	3375.937
485.83081	1.4273779	0.40910274	3366.8821
486.83179	1.4294399	0.41020039	3375.6619
487.83276	1.4314231	0.41121197	3367.3618
488.83374	1.4371765	0.41229537	3371.1257
489.83472	1.4388294	0.41353926	3382.5491
490.83569	1.4377563	0.41470087	3376.9285
491.83667	1.4435854	0.41604212	3375.9434
492.83765	1.4467616	0.41748843	3382.1609
493.83862	1.450163	0.41889998	3385.1201
494.8396	1.4523937	0.4200584	3376.0332
495.84058	1.4579749	0.42110023	3374.7856
496.84155	1.4588757	0.42229244	3392.4172
497.84253	1.4597306	0.42338896	3377.189
498.84351	1.4652442	0.42476842	3393.4561
499.84448	1.4657977	0.42604548	3383.5176
500.84546	1.4743259	0.42727789	3389.1689
501.84644	1.474491	0.42835206	3387.0486
502.84741	1.4796185	0.42984614	3393.5352
503.84839	1.4802431	0.43102175	3386.5923
504.84937	1.4835625	0.43245858	3395.9268
505.85034	1.4856144	0.43370461	3390.345
506.85132	1.4916713	0.43488738	3394.2102
507.85229	1.4928046	0.43602282	3395.9063
508.85327	1.4941292	0.43734378	3395.4998
509.85425	1.4988127	0.43875575	3400.4429
510.85522	1.4985001	0.43997768	3392.8328
511.8562	1.5051172	0.44138595	3405.332
512.85718	1.5100478	0.44265056	3403.405
513.85815	1.5083661	0.44388404	3397.636
514.85913	1.5128218	0.44516373	3401.8223
515.86011	1.5180233	0.44638634	3401.8552
516.86108	1.5188402	0.44778222	3404.616
517.86206	1.5225512	0.44919133	3406.0085
518.86304	1.524945	0.45036143	3399.9268
519.86401	1.5271468	0.45167348	3408.7744
520.86499	1.5306201	0.45303851	3403.8289
521.86597	1.5345236	0.45419011	3409.9565
522.86694	1.5363641	0.45567852	3409.2468
523.86792	1.5385768	0.45684758	3402.0901
524.8689	1.5442257	0.45820665	3417.1277
525.86987	1.5448506	0.45974755	3414.063
526.87085	1.54906	0.46096298	3407.782
527.87183	1.552922	0.46241304	3411.1033
528.8728	1.5581778	0.4637692	3418.7712
529.87378	1.5600533	0.46495235	3408.2236
530.87476	1.5595782	0.46600971	3408.5984
531.87573	1.5673968	0.46704116	3417.6614
532.87671	1.5663697	0.46824428	3412.8865
533.87769	1.5695351	0.46948561	3413.9263
534.87866	1.5730964	0.47088766	3417.7219
535.87964	1.5772173	0.47201535	3421.4668
536.88062	1.5763158	0.47324982	3423.1108
537.88159	1.5823619	0.47458735	3412.4004
538.88257	1.5851507	0.47587124	3420.8303
539.88354	1.5862188	0.47728404	3426.6218
540.88452	1.591301	0.47842515	3423.301
541.8855	1.5940329	0.47990021	3425.1692
542.88647	1.5957365	0.48134866	3427.8745
543.88745	1.598816	0.48264164	3430.0342
544.88843	1.6001837	0.48401919	3427.7334
545.8894	1.6064557	0.48540145	3431.8091
546.89038	1.6083544	0.48658875	3421.8528
547.89136	1.6108087	0.48772886	3423.9526
548.89233	1.6163237	0.48919114	3431.5146
549.89331	1.6180891	0.49068776	3435.0742
550.89429	1.6200529	0.49214756	3432.6497
551.89526	1.6267061	0.49364412	3437.3333
552.89624	1.6295245	0.49488479	3433.4641
553.89722	1.6322082	0.49605986	3445.4055
554.89819	1.6340126	0.49734282	3433.6013
555.89917	1.6365911	0.49856862	3434.7993
556.90015	1.6392133	0.49978581	3435.8074
557.90112	1.64283	0.50101072	3440.8684
558.9021	1.6468185	0.50241476	3447.6392
559.90308	1.6469302	0.50374603	3438.7468
560.90405	1.6511692	0.50483876	3439.9219
561.90503	1.6542513	0.50623173	3442.0825
562.90601	1.6568751	0.50736159	3439.4346
563.90698	1.6602422	0.50869828	3444.0359
564.90796	1.6656474	0.51008391	3447.4973
565.90894	1.66864	0.51132476	3446.8311
566.90991	1.6670196	0.5125227	3441.5615
567.91089	1.6722031	0.51367152	3444.6289
568.91187	1.6753398	0.51493102	3445.7368
569.91284	1.6761295	0.51609981	3447.9722
570.91382	1.679451	0.51732814	3438.8711
571.91479	1.6850201	0.51864433	3450.4392
572.91577	1.6870792	0.51992559	3448.252
573.91675	1.6906301	0.52144074	3452.4343
574.91772	1.6901098	0.52282727	3450.1328
575.9187	1.696775	0.52420598	3451.3376
576.91968	1.7001637	0.52533746	3453.634
577.92065	1.7017552	0.52648646	3448.1096
578.92163	1.7073811	0.52774847	3454.9729
579.92261	1.7089008	0.52906382	3459.3582
580.92358	1.7123592	0.53043813	3459.0227
581.92456	1.7120482	0.53179789	3454.8286
582.92554	1.7182544	0.53317451	3460.3406
583.92651	1.7225733	0.53489435	3467.718
584.92749	1.723654	0.53636193	3461.1511
585.92847	1.7253065	0.53785706	3463.2651
586.92944	1.72873	0.53935397	3462.0837
587.93042	1.7329265	0.54050773	3454.2722
588.9314	1.7335414	0.5417968	3464.1655
589.93237	1.7386667	0.54314464	3459.2375
590.93335	1.7403566	0.54453182	3469.9758
591.93433	1.7437313	0.54613841	3466.5325
592.9353	1.7472937	0.54751205	3472.2595
593.93628	1.7483815	0.548706	3464.3733
594.93726	1.7519031	0.55007815	3468.4282
595.93823	1.7547531	0.55137289	3468.1216
596.93921	1.7600985	0.55260289	3472.7334
597.94019	1.7626821	0.55386919	3469.6238
598.94116	1.7649946	0.5552882	3472.9595
599.94214	1.7702789	0.5565117	3476.4236
600.94312	1.7711231	0.55790073	3471.0623
601.94409	1.7714649	0.55930239	3472.304
602.94507	1.7774998	0.56065798	3473.8044
603.94604	1.7815443	0.56209677	3478.1321
604.94702	1.7824024	0.56347948	3479.0398
605.948	1.7840796	0.5649212	3471.1558
606.94897	1.788735	0.56636953	3476.3296
607.94995	1.7923331	0.56778252	3482.4788
608.95093	1.7957577	0.56925774	3477.5752
609.9519	1.7977116	0.57058066	3477.488
610.95288	1.8005557	0.57185298	3479.4294
611.95386	1.8052021	0.57309538	3478.4109
612.95483	1.8075092	0.57444495	3476.1763
613.95581	1.809211	0.57581651	3481.762
614.95679	1.8152052	0.5771066	3481.8586
615.95776	1.8139443	0.57854176	3482.6528
616.95874	1.8184481	0.58000821	3487.7527
617.95972	1.8224343	0.58150142	3482.47
618.96069	1.8240962	0.58285868	3479.1448
619.96167	1.8273982	0.58403403	3485.9309
620.96265	1.8323774	0.58539766	3488.4465
621.96362	1.8360908	0.58699453	3485.8728
622.9646	1.8380624	0.58832341	3482.8782
623.96558	1.8399644	0.58962059	3485.554
624.96655	1.8445401	0.5911479	3490.9863
625.96753	1.8475338	0.5925433	3495.1851
626.96851	1.8502337	0.59394383	3493.6877
627.96948	1.8499595	0.5953871	3489.8643
628.97046	1.8548228	0.5967235	3490.4058
629.97144	1.8560648	0.59820771	3493.5193
630.97241	1.8642732	0.59964442	3494.8379
631.97339	1.8651665	0.60102761	3494.9382
632.97437	1.8667479	0.60258353	3494.926
633.97534	1.8720702	0.60389775	3497.2283
634.97632	1.8744856	0.60529763	3499.8423
635.97729	1.8767706	0.60658085	3495.2593
636.97827	1.8802658	0.60799539	3502.29
637.97925	1.8806208	0.60932881	3494.1536
638.98022	1.8827238	0.61066699	3495.8049
639.9812	1.8884904	0.61195457	3493.8667
640.98218	1.889913	0.61341387	3501.5464
641.98315	1.8922261	0.61459881	3497.4978
642.98413	1.900709	0.61609483	3504.4939
643.98511	1.900326	0.61744875	3501.7988
644.98608	1.9041812	0.61885303	3508.4192
645.98706	1.9072959	0.62047052	3499.9756
646.98804	1.9087669	0.62184078	3505.0613
647.98901	1.9149313	0.6231395	3507.0735
648.98999	1.9133859	0.62446082	3502.6851
649.99097	1.918723	0.62585551	3505.9116
650.99194	1.920784	0.62723672	3509.7993
651.99292	1.9217567	0.62879217	3505.3452
652.9939	1.9244436	0.63018519	3498.3113
653.99487	1.9301312	0.63160521	3512.1797
654.99585	1.9317876	0.63319868	3508.1514
655.99683	1.9373212	0.63460153	3510.5071
656.9978	1.9380739	0.63614374	3512.0984
657.99878	1.9390343	0.63795543	3515.8083
658.99976	1.9479425	0.63941413	3513.9138
660.00073	1.947567	0.64079982	3503.7288
661.00171	1.9509596	0.64206707	3506.3384
662.00269	1.9570165	0.64334452	3513.6128
663.00366	1.9562668	0.64481246	3514.2439
664.00464	1.9618635	0.64633882	3516.2283
665.00562	1.9626894	0.64780504	3519.9404
666.00659	1.9655701	0.64922792	3514.6201
667.00757	1.9705504	0.65073138	3520.5725
668.00854	1.9724087	0.65222687	3524.7842
669.00952	1.9760947	0.65399349	3523.2937
670.0105	1.9790301	0.65532798	3518.6748
671.01147	1.9842345	0.65650332	3514.7588
672.01245	1.985684	0.65787494	3520.3955
673.01343	1.9857647	0.65933019	3513.835
674.0144	1.9896073	0.66056448	3516.6436
675.01538	1.991194	0.66183382	3518.249
676.01636	1.9989994	0.66331732	3527.7837
677.01733	1.9985242	0.66463768	3524.1072
678.01831	2.0032637	0.66616213	3523.4353
679.01929	2.0043819	0.6674037	3524.8311
680.02026	2.0090878	0.66889036	3521.0234
681.02124	2.007715	0.67000359	3521.345
682.02222	2.015744	0.67143732	3523.9368
683.02319	2.0162225	0.67304611	3531.2629
684.02417	2.0196898	0.67460954	3524.9004
685.02515	2.0236053	0.67632818	3531.6785
686.02612	2.0274355	0.67799729	3526.7131
687.0271	2.030345	0.67948717	3527.0239
688.02808	2.0333388	0.68090612	3525.7219
689.02905	2.0361755	0.68239135	3525.7498
690.03003	2.038882	0.68407393	3531.2732
691.03101	2.0410624	0.68560237	3527.6968
692.03198	2.0462966	0.68711966	3532.3059
693.03296	2.0480199	0.68867773	3534.3201
694.03394	2.0509233	0.69012541	3528.5085
695.03491	2.053252	0.69166756	3530.7571
696.03589	2.0577126	0.69311577	3531.5139
697.03687	2.0588853	0.69461471	3537.3159
698.03784	2.0599306	0.69581431	3526.6274
699.03882	2.0635796	0.69735551	3535.0325
700.03979	2.0690792	0.69886929	3537.3367
701.04077	2.0719857	0.70034546	3534.9509
702.04175	2.0739286	0.70218968	3537.4756
703.04272	2.0767593	0.70386106	3535.3447
704.0437	2.0817809	0.70564634	3545.489
705.04468	2.0825949	0.70685184	3530.1975
706.04565	2.085779	0.70836592	3533.8843
707.04663	2.0886469	0.70982969	3536.0479
708.04761	2.0925336	0.7112605	3543.0317
709.04858	2.0973127	0.71273643	3540.6409
710.04956	2.0997131	0.71413028	3533.6445
711.05054	2.1028984	0.71575218	3545.561
712.05151	2.1043921	0.71718347	3535.0488
713.05249	2.1086087	0.71857387	3542.0811
714.05347	2.1082909	0.7201218	3539.5042
715.05444	2.1143868	0.72162181	3543.196
716.05542	2.1183519	0.72295064	3540.8042
717.0564	2.1180813	0.72441483	3547.3013
718.05737	2.122458	0.72589278	3544.7109
719.05835	2.1248598	0.72735244	3542.2378
720.05933	2.1308727	0.72888917	3541.8267
721.0603	2.131012	0.73025155	3548.8689
722.06128	2.1345575	0.73186356	3545.667
723.06226	2.1366773	0.73356509	3545.938
724.06323	2.1403279	0.73489702	3544.4204
725.06421	2.143101	0.73634839	3543.7319
726.06519	2.144356	0.73805779	3548.012
727.06616	2.1498575	0.73960018	3548.5627
728.06714	2.1537352	0.7412914	3549.304
729.06812	2.1568468	0.74267304	3546.6206
730.06909	2.155211	0.74425274	3541.74
731.07007	2.159956	0.74591464	3551.2234
732.07104	2.163161	0.74757576	3545.0356
733.07202	2.1668904	0.74924767	3551.6648
734.073	2.1734574	0.75102729	3558.8906
735.07397	2.1754687	0.75242925	3547.1982
736.07495	2.1751683	0.75412893	3553.4128
737.07593	2.1797922	0.75584108	3552.8201
738.0769	2.1816754	0.75726783	3549.4355
739.07788	2.1857638	0.75865912	3550.0308
740.07886	2.1892676	0.76012552	3551.4377
741.07983	2.1936281	0.76148778	3554.02
742.08081	2.1945469	0.76294911	3561.4082
743.08179	2.2002215	0.76460654	3553.4539
744.08276	2.1997209	0.76613635	3555.9338
745.08374	2.2034049	0.76789498	3557.1938
746.08472	2.2039709	0.76930302	3546.7048
747.08569	2.2096119	0.77056301	3549.7441
748.08667	2.2152565	0.77202266	3560.5439
749.08765	2.2136908	0.77370059	3561.5627
750.08862	2.2193458	0.77565736	3559.158
751.0896	2.2203765	0.77734178	3555.6196
752.09058	2.2251775	0.77897412	3559.4585
753.09155	2.225158	0.78031868	3554.948
754.09253	2.2313671	0.78198385	3559.6396
755.09351	2.2323854	0.78365999	3562.7488
756.09448	2.2372978	0.78521204	3557.9402
757.09546	2.2388558	0.78701144	3563.636
758.09644	2.2392511	0.78866887	3559.6235
759.09741	2.2471468	0.79036951	3563.5039
760.09839	2.2480185	0.79228449	3560.7524
761.09937	2.2545016	0.79416674	3567.8972
762.10034	2.2525425	0.79565531	3554.6477
763.10132	2.2560961	0.79695731	3560.3079
764.10229	2.2608798	0.79858547	3562.2246
765.10327	2.2632148	0.80040258	3566.4277
766.10425	2.2678602	0.80202407	3564.5571
767.10522	2.2707312	0.80373442	3561.9714
768.1062	2.2714434	0.80543131	3558.781
769.10718	2.2767706	0.80696654	3567.5459
770.10815	2.2778788	0.8086291	3562.8137
771.10913	2.2796524	0.81043851	3562.7734
772.11011	2.2839518	0.81214237	3562.5649
773.11108	2.2867022	0.81393701	3567.2764
774.11206	2.2902415	0.81555802	3553.4863
775.11304	2.2954443	0.81697035	3564.79
776.11401	2.2961912	0.81855911	3565.5393
777.11499	2.2968397	0.82004905	3560.3108
778.11597	2.302793	0.82171112	3572.7883
779.11694	2.3067446	0.823237	3562.9363
780.11792	2.3093002	0.82498062	3566.3467
781.1189	2.3129945	0.82676995	3569.855
782.11987	2.3165786	0.82837909	3566.0115
783.12085	2.3187962	0.82961136	3559.8696
784.12183	2.3224213	0.83135599	3569.3181
785.1228	2.3244665	0.83265126	3563.2659
786.12378	2.3243914	0.8340739	3566.2593
787.12476	2.3289361	0.83578336	3572.8643
788.12573	2.3329272	0.83738011	3567.8354
789.12671	2.3381534	0.83920038	3574.5874
790.12769	2.337549	0.84076989	3564.104
791.12866	2.3415194	0.84241652	3565.7898
792.12964	2.3448408	0.84437782	3572.2466
793.13062	2.3483136	0.84624231	3577.4543
794.13159	2.3499546	0.84808636	3572.7244
795.13257	2.3534403	0.84971964	3572.4597
796.13354	2.3548779	0.85154039	3570.3262
797.13452	2.3625479	0.85339016	3573.7727
798.1355	2.3598161	0.85488212	3566.9705
799.13647	2.3665814	0.85660708	3576.02
800.13745	2.369571	0.8584317	3575.1328
801.13843	2.3719013	0.85995328	3573.7666
802.1394	2.3755934	0.86168379	3574.8604
803.14038	2.3786025	0.86350262	3577.6316
804.14136	2.3805313	0.86512214	3571.8682
805.14233	2.3839471	0.86700881	3578.4619
806.14331	2.3875074	0.86871266	3570.4668
807.14429	2.392385	0.87027562	3575.5945
808.14526	2.3920443	0.87188309	3574.4023
809.14624	2.3947966	0.87360406	3573.6558
810.14722	2.3982975	0.87540329	3576.0742
811.14819	2.3999307	0.87702101	3576.0637
812.14917	2.4032972	0.878766	3570.4504
813.15015	2.4108844	0.88050264	3577.3328
814.15112	2.4118316	0.88220358	3570.3975
815.1521	2.4150314	0.88395828	3573.7676
816.15308	2.4147041	0.88587171	3574.592
817.15405	2.422086	0.88792807	3586.6616
818.15503	2.4240043	0.88956892	3571.0212
819.15601	2.4295382	0.8913945	3578.114
820.15698	2.4301627	0.89315403	3576.7512
821.15796	2.4313231	0.89478761	3573.1025
822.15894	2.436897	0.89638299	3575.5103
823.15991	2.4407201	0.89832258	3584.0913
824.16089	2.4425197	0.90043992	3577.3027
825.16187	2.4457273	0.90177929	3569.8533
826.16284	2.4477708	0.90330893	3579.4958
827.16382	2.4537096	0.90508085	3585.9856
828.16479	2.4521651	0.90701646	3578.4795
829.16577	2.456368	0.90898597	3578.9729
830.16675	2.4604208	0.91086656	3585.5837
831.16772	2.4622483	0.91284287	3578.9319
832.1687	2.4667456	0.91461885	3575.6377
833.16968	2.4647355	0.91646117	3586.5698
834.17065	2.4706035	0.91852731	3583.8887
835.17163	2.4757638	0.92037582	3578.0405
836.17261	2.4760129	0.92213398	3577.6477
837.17358	2.4814563	0.92393231	3576.8389
838.17456	2.4829452	0.92575943	3578.689
839.17554	2.4867325	0.92761344	3578.3232
840.17651	2.4875014	0.92938209	3575.7139
841.17749	2.4936047	0.93124628	3580.7534
842.17847	2.4950459	0.93306065	3583.3477
843.17944	2.4969049	0.934973	3579.8882
844.18042	2.5009596	0.93711227	3585.2581
845.1814	2.5024219	0.93936199	3584.938
846.18237	2.5086515	0.94153595	3588.4036
847.18335	2.5125449	0.94374061	3582.156
848.18433	2.5126891	0.94565225	3576.7009
849.1853	2.51456	0.94716752	3573.0159
850.18628	2.517951	0.94905943	3583.7749
851.18726	2.5247035	0.95054716	3575.2397
852.18823	2.5260332	0.95197093	3574.0784
853.18921	2.5295389	0.95384347	3591.6826
854.19019	2.5345316	0.9555698	3583.8547
855.19116	2.5341654	0.95708823	3574.4597
856.19214	2.5384111	0.9591915	3582.3516
857.19312	2.5418024	0.96114177	3587.0925
858.19409	2.5444844	0.9629885	3584.0798
859.19507	2.5471241	0.9648149	3582.9319
860.19604	2.5485926	0.96664304	3575.6001
861.19702	2.5528815	0.96845865	3586.709
862.198	2.5555792	0.97064191	3579.6077
863.19897	2.5609131	0.97257358	3583.248
864.19995	2.5619998	0.97440708	3577.4651
865.20093	2.5631864	0.97630417	3577.4941
866.2019	2.5719182	0.97812539	3582.8669
867.20288	2.569253	0.97994399	3585.2295
868.20386	2.5713665	0.98185283	3583.7627
869.20483	2.5730817	0.98405802	3583.7607
870.20581	2.5783811	0.98632509	3581.2852
871.20679	2.5816636	0.98837566	3582.9219
872.20776	2.5878029	0.99053174	3586.2966
873.20874	2.5898466	0.99231201	3581.2493
874.20972	2.5903943	0.99446458	3585.1028
875.21069	2.5920262	0.99659568	3584.2791
876.21167	2.5969665	0.99878716	3582.7998
877.21265	2.6003828	1.0007226	3582.7102
878.21362	2.603472	1.002386	3576.9663
879.2146	2.607024	1.0042837	3589.0442
880.21558	2.6071641	1.0061895	3580.6331
881.21655	2.6119227	1.0084196	3585.2964
882.21753	2.6152778	1.0102539	3583.3755
883.21851	2.6187284	1.0121462	3582.5938
884.21948	2.6228275	1.0142682	3582.1482
885.22046	2.6258526	1.0162021	3580.9639
886.22144	2.6269617	1.0180154	3588.0039
887.22241	2.6314294	1.0198339	3581.9385
888.22339	2.6328776	1.0215937	3580.0889
889.22437	2.6361973	1.0236287	3589.8269
890.22534	2.6386447	1.0259759	3586.1238
891.22632	2.6404979	1.0277826	3581.2473
892.22729	2.6421013	1.0299649	3583.0862
893.22827	2.6486554	1.0324204	3584.1033
894.22925	2.6498234	1.0348643	3587.572
895.23022	2.6525817	1.0371749	3580.9001
896.2312	2.6574421	1.0394461	3580.5669
897.23218	2.6572866	1.0414302	3576.126
898.23315	2.664423	1.0433954	3579.8774
899.23413	2.6636043	1.0453049	3579.2981
900.23511	2.6677382	1.0475773	3583.679
901.23608	2.6724741	1.0496749	3576.7231
902.23706	2.6764498	1.0515169	3581.5613
903.23804	2.6811025	1.0532924	3586.1655
904.23901	2.6802325	1.0550935	3583.9844
905.23999	2.6842227	1.0575159	3581.1755
906.24097	2.6894963	1.0597595	3581.3962
907.24194	2.6895065	1.0618434	3578.3245
908.24292	2.6930957	1.0639446	3585.2256
909.2439	2.6991739	1.0660424	3581.0342
910.24487	2.6986473	1.0681125	3580.6936
911.24585	2.7049539	1.0701144	3581.0059
912.24683	2.7036245	1.0721911	3580.437
913.2478	2.7099636	1.0747932	3586.9924
914.24878	2.7106731	1.0772223	3586.9497
915.24976	2.7154052	1.0797069	3586.9355
916.25073	2.7179592	1.0816885	3584.8591
917.25171	2.719121	1.0838302	3579.0801
918.25269	2.7215774	1.0861071	3583.2522
919.25366	2.7269721	1.0883681	3582.0168
920.25464	2.7304945	1.0906472	3583.9065
921.25562	2.7312217	1.0927207	3574.9841
922.25659	2.7358642	1.0947881	3576.6709
923.25757	2.7410617	1.0970526	3584.3149
924.25854	2.7396853	1.099076	3578.4663
925.25952	2.7430532	1.1011072	3578.8528
926.2605	2.746664	1.1031532	3577.8921
927.26147	2.7509611	1.1054213	3581.8154
928.26245	2.7533581	1.1073433	3577.8594
929.26343	2.7574852	1.109581	3582.7261
930.2644	2.7581482	1.1119785	3581.5715
931.26538	2.7644827	1.114396	3578.4861
932.26636	2.7654145	1.1166283	3580.4526
933.26733	2.7678788	1.1186718	3573.6565
934.26831	2.7678075	1.1206027	3578.2065
935.26929	2.7752395	1.1229228	3575.7744
936.27026	2.7803049	1.1253947	3578.3289
937.27124	2.7821319	1.1277086	3579.7278
938.27222	2.7837148	1.129876	3577.2778
939.27319	2.7862754	1.1323014	3577.6689
940.27417	2.7892227	1.1346955	3580.1926
941.27515	2.7929754	1.1369653	3578.5762
942.27612	2.7956562	1.139411	3578.5793
943.2771	2.7968228	1.1421106	3579.4534
944.27808	2.7998114	1.144877	3572.6719
945.27905	2.8074481	1.1473278	3578.6416
946.28003	2.8097224	1.1496499	3572.5913
947.28101	2.8119779	1.1516664	3572.1748
948.28198	2.8159034	1.1539564	3576.3708
949.28296	2.8187001	1.1561606	3576.1543
950.28394	2.821909	1.1584228	3575.4456
951.28491	2.8226247	1.1609161	3574.5007
952.28589	2.8247859	1.1634896	3576.366
953.28687	2.8280716	1.1658413	3573.8728
954.28784	2.8325698	1.1679815	3566.9111
955.28882	2.835083	1.1702503	3570.1453
956.28979	2.8371787	1.1723012	3574.4299
957.29077	2.8402734	1.1748893	3575.3169
958.29175	2.8451099	1.1777606	3580.7332
959.29272	2.8454859	1.1804467	3572.6284
960.2937	2.8502388	1.1826296	3569.8057
961.29468	2.8544719	1.1850432	3574.4238
962.29565	2.8555675	1.1876571	3574.5693
963.29663	2.8577635	1.1901506	3571.6355
964.29761	2.8618946	1.1925296	3571.3672
965.29858	2.8659425	1.1949297	3572.6719
966.29956	2.8637853	1.1972502	3567.7993
967.30054	2.868803	1.1995913	3564.9333
968.30151	2.8733997	1.2020121	3563.6021
969.30249	2.8781099	1.2042676	3566.7668
970.30347	2.8800182	1.2065418	3565.8811
971.30444	2.8819597	1.2088658	3570.2793
972.30542	2.8850694	1.2113572	3568.4988
973.3064	2.8905637	1.2140187	3571.2473
974.30737	2.8914573	1.2171422	3569.0225
975.30835	2.8930159	1.2196572	3569.9224
976.30933	2.897207	1.2223446	3564.8167
977.3103	2.8997924	1.225078	3565.5059
978.31128	2.904918	1.2276074	3564.48
979.31226	2.9045639	1.2299073	3560.668
980.31323	2.9082804	1.2323313	3559.2832
981.31421	2.9123578	1.2347902	3563.5149
982.31519	2.9180419	1.2371933	3569.0969
983.31616	2.9165931	1.2395537	3562.2163
984.31714	2.9194314	1.2418362	3558.3425
985.31812	2.9235425	1.2443813	3561.394
986.31909	2.9283271	1.2467575	3563.4741
987.32007	2.9286492	1.2494447	3559.1125
988.32104	2.9342887	1.2524637	3565.0959
989.32202	2.9376156	1.2551026	3552.6873
990.323	2.9394519	1.2573682	3554.2432
991.32397	2.9446638	1.2598689	3561.8296
992.32495	2.9484475	1.2626977	3560.1355
993.32593	2.9490383	1.2656571	3557.467
994.3269	2.9522026	1.2687824	3565.0718
995.32788	2.9563479	1.271108	3551.0896
996.32886	2.9555635	1.273286	3552.4253
997.32983	2.9623606	1.2754263	3548.5781
998.33081	2.9667842	1.2774554	3551.9827
999.33179	2.9667056	1.2796612	3553.2646
1000.3328	2.9699624	1.2824172	3555.2844
1001.3337	2.9721038	1.2852801	3554.509
1002.3347	2.9729505	1.2880203	3546.8623
1003.3357	2.9795213	1.2905538	3555.0767
1004.3367	2.9812181	1.2932909	3546.6072
1005.3376	2.9840243	1.2959412	3544.7639
1006.3386	2.9878943	1.298789	3545.823
1007.3396	2.9910064	1.3013706	3550.52
1008.3406	2.9918895	1.3039297	3534.8599
1009.3416	2.9989192	1.3059025	3537.7209
1010.3425	3.0012259	1.3076166	3538.0049
1011.3435	3.0040696	1.3094324	3543.5222
1012.3445	3.008945	1.311543	3547.8552
1013.3455	3.0090036	1.3139086	3545.856
1014.3464	3.0119357	1.3166671	3546.3511
1015.3474	3.0131397	1.3199041	3544.45
1016.3484	3.0172105	1.3229619	3540.4937
1017.3494	3.0220897	1.3259699	3547.2749
1018.3503	3.023212	1.3289386	3541.6589
1019.3513	3.026603	1.3317406	3537.0828
1020.3523	3.0320611	1.3341756	3534.2861
1021.3533	3.0328989	1.336439	3534.783
1022.3542	3.035475	1.3390501	3535.6802
1023.3552	3.0345428	1.3419794	3536.9741
1024.3562	3.0403161	1.3450947	3534.6411
1025.3572	3.0460014	1.3478744	3538.6577
1026.3582	3.0482125	1.3511243	3532.8657
1027.3591	3.0516744	1.3537542	3527.7065
1028.3601	3.0521247	1.3566896	3532.7493
1029.3611	3.0587704	1.3597014	3530.9993
1030.3621	3.0606551	1.362496	3523.7012
1031.363	3.0654879	1.3649989	3522.5361
1032.364	3.0685225	1.3670892	3526.7515
1033.365	3.0689473	1.3693964	3522.3467
1034.366	3.0712535	1.372232	3525.3091
1035.3669	3.0743418	1.3752677	3527.3521
1036.3679	3.0772765	1.3781694	3523.395
1037.3689	3.0801404	1.3810565	3519.2703
1038.3699	3.0842798	1.3841774	3520.8267
1039.3708	3.0896459	1.3871899	3518.605
1040.3718	3.0911665	1.389902	3515.2131
1041.3728	3.0941079	1.3924568	3517.4526
1042.3738	3.0943117	1.3948325	3511.9509
1043.3748	3.0982277	1.3978257	3515.553
1044.3757	3.1023405	1.4007022	3510.5425
1045.3767	3.1058152	1.4033384	3511.491
1046.3777	3.1088514	1.4058895	3510.572
1047.3787	3.1109629	1.4084402	3509.415
1048.3796	3.1144788	1.4112751	3508.4441
1049.3806	3.1173763	1.4141998	3501.4253
1050.3816	3.1187294	1.4167856	3501.7905
1051.3826	3.1243188	1.4195992	3508.1555
1052.3835	3.1264124	1.4226308	3504.8997
1053.3845	3.1271446	1.4253041	3495.0828
1054.3855	3.1299307	1.4280312	3498.1365
1055.3865	3.1335301	1.431101	3499.0901
1056.3875	3.1385238	1.4344735	3498.3093
1057.3884	3.1433444	1.4375039	3492.6873
1058.3894	3.1480083	1.4408417	3500.0837
1059.3904	3.1488495	1.44373	3492.6589
1060.3914	3.1508954	1.4465966	3489.9229
1061.3923	3.1523533	1.4495343	3489.3035
1062.3933	3.1560473	1.4524369	3478.8894
1063.3943	3.1597285	1.4550575	3479.5659
1064.3953	3.1600139	1.4578906	3481.521
1065.3962	3.1649268	1.4606586	3478.0305
1066.3972	3.1684535	1.4635471	3478.7673
1067.3982	3.1704431	1.4663514	3480.3528
1068.3992	3.1743903	1.4693719	3475.1104
1069.4001	3.1760409	1.472466	3471.0269
1070.4011	3.1808491	1.4749813	3471.219
1071.4021	3.1846869	1.4777532	3472.0217
1072.4031	3.1873031	1.4803325	3463.7964
1073.4041	3.1894846	1.4829053	3471.7751
1074.405	3.1940603	1.4858896	3475.2637
1075.406	3.1938283	1.4889187	3464.7983
1076.407	3.197052	1.4916052	3463.8293
1077.408	3.2013443	1.494897	3456.0759
1078.4089	3.2035127	1.4980365	3459.3669
1079.4099	3.2088954	1.5007262	3453.5447
1080.4109	3.211993	1.503311	3450.1375
1081.4119	3.2118359	1.5065109	3452.261
1082.4128	3.2178848	1.5096848	3451.6665
1083.4138	3.2166755	1.5128276	3446.1455
1084.4148	3.2231243	1.5158764	3447.0244
1085.4158	3.225014	1.5188885	3440.0764
1086.4167	3.2276149	1.5217352	3434.9846
1087.4177	3.2322576	1.5253234	3442.9976
1088.4187	3.2320726	1.529014	3432.1646
1089.4197	3.2377768	1.5319674	3426.9141
1090.4207	3.2396672	1.5346124	3427.0442
1091.4216	3.2430158	1.5379966	3430.8689
1092.4226	3.2483058	1.5412096	3428.1184
1093.4236	3.2525904	1.5440995	3424.8794
1094.4246	3.2516823	1.5472254	3415.0276
1095.4255	3.2539291	1.5500594	3416.1287
1096.4265	3.2563345	1.5532701	3411.9619
1097.4275	3.2625985	1.5563468	3417.2908
1098.4285	3.2661042	1.558933	3408.9761
1099.4294	3.2671812	1.5622321	3407.6809
1100.4304	3.2697861	1.5652078	3405.4568
1101.4314	3.2754521	1.568473	3404.761
1102.4324	3.2760737	1.5713626	3401.8479
1103.4333	3.2788928	1.5748068	3391.646
1104.4343	3.2809272	1.5776358	3391.6836
1105.4353	3.2868109	1.5807062	3389.1042
1106.4363	3.2879777	1.5836631	3387.3538
1107.4373	3.2923372	1.5866228	3382.0615
1108.4382	3.2938793	1.5889693	3377.333
1109.4392	3.2972877	1.5915985	3383.2605
1110.4402	3.3005302	1.5951977	3382.167
1111.4412	3.3036978	1.598875	3371.4041
1112.4421	3.3062866	1.602314	3368.3928
1113.4431	3.3100529	1.6056902	3364.9937
1114.4441	3.3121972	1.6088283	3363.4563
1115.4451	3.3163877	1.6116363	3355.5598
1116.446	3.3182671	1.614525	3350.9146
1117.447	3.323267	1.6182559	3358.8545
1118.448	3.324774	1.6219275	3348.6421
1119.449	3.3290355	1.6253153	3337.605
1120.45	3.3305266	1.6282098	3334.8889
1121.4509	3.3350587	1.6313454	3339.0093
1122.4519	3.335237	1.634956	3338.364
1123.4529	3.339251	1.638553	3323.0808
1124.4539	3.3412197	1.6416622	3326.9424
1125.4548	3.3470511	1.6446283	3316.2998
1126.4558	3.3494375	1.6478109	3321.6663
1127.4568	3.3523974	1.6512023	3316.4622
1128.4578	3.3527062	1.654112	3304.4084
1129.4587	3.3558407	1.6572201	3303.4771
1130.4597	3.3603067	1.6605849	3303.5825
1131.4607	3.3644664	1.6646322	3298.2681
1132.4617	3.3672326	1.6680276	3290.4226
1133.4626	3.3729312	1.6716001	3289.3784
1134.4636	3.3728242	1.6756985	3281.9153
1135.4646	3.3754654	1.6793334	3271.3918
1136.4656	3.3788762	1.6823186	3263.6262
1137.4666	3.381228	1.6855749	3267.2544
1138.4675	3.3819823	1.6886997	3254.3052
1139.4685	3.3862839	1.6916635	3247.2485
1140.4695	3.3906567	1.695004	3245.9653
1141.4705	3.3904409	1.6978593	3234.2402
1142.4714	3.3950441	1.7014626	3235.7563
1143.4724	3.4017634	1.7049034	3235.4402
1144.4734	3.4013457	1.708783	3223.8079
1145.4744	3.4058135	1.7120749	3210.2798
1146.4753	3.4097931	1.7154433	3211.5928
1147.4763	3.4120998	1.7194359	3203.5063
1148.4773	3.4144893	1.7231804	3187.6982
1149.4783	3.416878	1.7262728	3188.1189
1150.4792	3.4229217	1.7295666	3184.0254
1151.4802	3.4259305	1.7329589	3174.0251
1152.4812	3.4258201	1.7366374	3168.0713
1153.4822	3.4313209	1.7407106	3154.7769
1154.4832	3.4337671	1.7451746	3144.9373
1155.4841	3.4380896	1.7499621	3124.4673
1156.4851	3.438448	1.7551681	3099.4976
1157.4861	3.4416025	1.7617599	3057.9666
1158.4871	3.4479711	1.7735009	2967.2615
1158.6873	3.4506831	1.7768307	2942.1899