File: datasets/am_bench_2022/raw_data/90-X.19-1/specimen.dat
MTS793|MPT|ENU|1|2|.|/|:|1|0|0|A

Operator Information						Time:	10.710205	Sec	11/2/2021 1:17:24 PM
Operator	Nick Derimow
Project	AM Bench 2022 mini-tensile challenge
Specimen ID	90-X.19-1
Material	PBF-L Inconel 625
Specimen Width	2.54	mm
Specimen Thickness	1.51	mm
Notes
Operator Information End

Data Acquisition						Time:	1011.7043	Sec	11/2/2021 1:34:05 PM
Time	Axial Displacement	Axial Extensometer	Axial Force
Sec	mm	mm	N
10.824219	0.00063271716	1.9570377e-06	62.581039
11.825195	-0.0013380778	9.4430477e-05	71.330269
12.826172	0.0027902189	-4.0143957e-05	89.957596
13.827148	0.0087543391	0.00029450445	101.60175
14.828125	0.0097150216	0.00022037695	112.56853
15.829102	0.015883623	0.00031222342	126.78559
16.830078	0.018730378	0.00046695195	139.99208
17.831055	0.023020077	0.00037003035	153.94835
18.832031	0.022983607	0.00055078004	167.59894
19.833008	0.026142154	0.00076708855	182.68051
20.833984	0.029753357	0.00070331933	201.8755
21.834961	0.032036457	0.00086592691	217.61934
22.835938	0.034687489	0.0010898953	233.42654
23.836914	0.034825381	0.0010213398	248.92207
24.837891	0.04007725	0.0013202716	272.9278
25.838867	0.042279828	0.0014819039	294.10477
26.839844	0.046468362	0.0014274695	313.79111
27.84082	0.050164953	0.0016774908	333.56
28.841797	0.052350935	0.0018364596	348.61185
29.842773	0.053563431	0.0019553076	377.45599
30.84375	0.056991052	0.0020272767	390.5148
31.844727	0.06107837	0.0022736671	418.83081
32.845703	0.061776228	0.0023699086	438.81616
33.84668	0.065749012	0.0025301795	460.38297
34.847656	0.071523815	0.002750132	485.48483
35.848633	0.074074037	0.0028811872	515.89337
36.849609	0.07675273	0.0030539155	530.34546
37.850586	0.080022946	0.0032192534	554.66431
38.851563	0.082931168	0.0033637527	581.1745
39.852539	0.083958291	0.0034703729	603.21832
40.853516	0.087166212	0.0037053355	634.94958
41.854492	0.092290692	0.0038595786	654.58435
42.855469	0.094985567	0.0041376455	687.64551
43.856445	0.096026212	0.0042358004	715.94293
44.857422	0.10108943	0.0043846802	741.25134
45.858398	0.10342288	0.0046457453	769.51398
46.859375	0.10651442	0.0047443458	787.10486
47.860352	0.10747741	0.0048481794	808.79675
48.861328	0.11157667	0.0052204942	840.86481
49.862305	0.11424081	0.0052096634	856.30603
50.863281	0.11817877	0.0054495563	888.63367
51.864258	0.1213994	0.0056981184	916.82214
52.865234	0.1240722	0.0058183023	944.51514
53.866211	0.12705208	0.0060436139	971.86737
54.867188	0.13392074	0.0062370086	1000.4386
55.868164	0.13306886	0.0063743009	1029.7355
56.869141	0.13616103	0.0065672966	1055.3682
57.870117	0.1373453	0.0067034909	1083.9581
58.871094	0.14194606	0.0069123344	1110.8043
59.87207	0.14456207	0.0071276426	1141.2788
60.873047	0.14935708	0.0074021937	1172.0359
61.874023	0.1494167	0.0074091353	1185.6345
62.875	0.15239069	0.0076901852	1216.3308
63.875977	0.15727745	0.0078773964	1243.5632
64.876953	0.15989308	0.0080797486	1268.8683
65.87793	0.16331594	0.0083308266	1299.8412
66.878906	0.16595125	0.0084001487	1321.5616
67.879883	0.16635448	0.0086738225	1349.5328
68.880859	0.17225687	0.0087474305	1374.9818
69.881836	0.17410699	0.0089941779	1401.6145
70.882813	0.17788476	0.0090887221	1423.2803
71.883789	0.18107221	0.0092390403	1456.0129
72.884766	0.18445858	0.0095861964	1488.0411
73.885742	0.18663228	0.0097801834	1510.4141
74.886719	0.18769684	0.009963166	1534.7941
75.887695	0.19553837	0.010143379	1568.0282
76.888672	0.1954308	0.01025262	1590.0679
77.889648	0.1973848	0.010404972	1609.6345
78.890625	0.19984205	0.010606783	1639.8785
79.891602	0.2042992	0.010835008	1673.4292
80.892578	0.20736657	0.011063791	1696.2905
81.893555	0.21024202	0.011244585	1717.0624
82.894531	0.21277605	0.011407143	1748.4647
83.895508	0.2156117	0.011547558	1762.7618
84.896484	0.21973287	0.011762658	1795.5873
85.897461	0.22313094	0.011970587	1817.726
86.898438	0.22395271	0.012122311	1848.549
87.899414	0.22884402	0.012389723	1880.1437
88.900391	0.23117198	0.012508453	1902.437
89.901367	0.2320983	0.012726711	1922.7968
90.902344	0.23849653	0.01293914	1952.026
91.90332	0.24075499	0.013047166	1964.0541
92.904297	0.24111703	0.013157897	1991.8199
93.905273	0.24336572	0.01336719	2018.7175
94.90625	0.25162455	0.013582421	2042.9688
95.907227	0.25034383	0.013820096	2062.5483
96.908203	0.25630483	0.013939555	2086.5225
97.90918	0.25952798	0.014147902	2104.0801
98.910156	0.26460364	0.014322889	2124.4531
99.911133	0.26662263	0.014427952	2140.6636
100.91211	0.2663956	0.014674383	2157.9482
101.91309	0.27047536	0.014857328	2186.748
102.91406	0.27355915	0.0150025	2203.9326
103.91504	0.27773577	0.015204144	2229.0129
104.91602	0.27878851	0.015461967	2243.7224
105.91699	0.28205687	0.015632147	2258.7339
106.91797	0.28581724	0.015832419	2281.3914
107.91895	0.2874662	0.015962489	2296.0884
108.91992	0.29208821	0.016150057	2315.6587
109.9209	0.29681993	0.016408309	2334.1355
110.92188	0.29681316	0.016425496	2334.9736
111.92285	0.29927287	0.01687438	2367.4124
112.92383	0.3063204	0.017063048	2380.2058
113.9248	0.30720657	0.017157305	2395.5947
114.92578	0.3093468	0.017420419	2412.3901
115.92676	0.31316289	0.017622247	2425.2078
116.92773	0.3184582	0.017755769	2436.1309
117.92871	0.31657204	0.018030459	2446.8887
118.92969	0.32465202	0.018183798	2456.8982
119.93066	0.32413751	0.018453132	2469.9727
120.93164	0.32995883	0.018641707	2484.4536
121.93262	0.32984287	0.018785814	2496.915
122.93359	0.33396849	0.019142624	2505.2537
123.93457	0.33827609	0.01938883	2522.5718
124.93555	0.34069872	0.01958406	2525.4636
125.93652	0.34019262	0.019758264	2538.0137
126.9375	0.3462911	0.020205302	2562.0837
127.93848	0.34746614	0.020330368	2556.4866
128.93945	0.35329708	0.020627156	2579.0713
129.94043	0.3540431	0.0209643	2583.3718
130.94141	0.35790011	0.021218846	2595.9788
131.94238	0.36492306	0.021704437	2607.7683
132.94336	0.36480668	0.021814764	2614.0869
133.94434	0.36697689	0.022169774	2617.2561
134.94531	0.37015	0.022512013	2629.3152
135.94629	0.37523487	0.022786636	2635.3882
136.94727	0.37560776	0.023205649	2647.9055
137.94824	0.37992871	0.023673108	2654.8467
138.94922	0.38399944	0.024083948	2661.2842
139.9502	0.38418999	0.024403568	2661.4053
140.95117	0.39025876	0.025019258	2686.2031
141.95215	0.3930805	0.025473522	2686.3535
142.95313	0.39465427	0.025994882	2695.459
143.9541	0.39511794	0.026505796	2693.4229
144.95508	0.40097651	0.027129145	2703.6814
145.95605	0.40554079	0.027689092	2716.9294
146.95703	0.40750715	0.02828048	2716.4746
147.95801	0.41531318	0.02888602	2725.0127
148.95898	0.41129902	0.029612342	2732.6235
149.95996	0.41919991	0.030280873	2732.7466
150.96094	0.41844654	0.030920846	2743.7366
151.96191	0.42198029	0.031686008	2748.0266
152.96289	0.42458871	0.032417197	2748.9106
153.96387	0.42807385	0.03316091	2759.4517
154.96484	0.43106294	0.034114551	2770.4536
155.96582	0.43169215	0.034970261	2774.1089
156.9668	0.43873894	0.035905454	2783.4575
157.96777	0.44070297	0.036618233	2781.6375
158.96875	0.4450548	0.037583258	2785.3203
159.96973	0.44775629	0.038374443	2789.7183
160.9707	0.45069826	0.039189484	2797.8853
161.97168	0.45422727	0.039904274	2798.1079
162.97266	0.45537895	0.040769238	2805.7695
163.97363	0.46091402	0.041856747	2814.0747
164.97461	0.46153688	0.042715009	2819.1086
165.97559	0.46460426	0.043582387	2818.9558
166.97656	0.46718523	0.044365305	2818.136
167.97754	0.47066116	0.045171268	2821.4868
168.97852	0.4723132	0.046155278	2827.624
169.97949	0.47463131	0.047141548	2828.6086
170.98047	0.48369822	0.048078883	2838.3645
171.98145	0.48335931	0.049073141	2841.874
172.98242	0.48740959	0.050188441	2851.2224
173.9834	0.49025816	0.051191829	2848.9214
174.98438	0.49281597	0.052123681	2853.2759
175.98535	0.4920401	0.053044807	2856.9338
176.98633	0.49928001	0.05403655	2858.656
177.9873	0.50379127	0.054871477	2862.6458
178.98828	0.50744808	0.055917822	2869.1563
179.98926	0.50805885	0.056931768	2870.4363
180.99023	0.50993848	0.057962347	2873.5093
181.99121	0.51312023	0.058903001	2877.0176
182.99219	0.51707298	0.059904445	2879.8921
183.99316	0.52016836	0.061023161	2888.0063
184.99414	0.52245027	0.061926585	2885.4294
185.99512	0.52620399	0.063246742	2893.2664
186.99609	0.52985185	0.064178422	2892.698
187.99707	0.5300172	0.065406621	2904.8694
188.99805	0.53528732	0.066635102	2909.7063
189.99902	0.53509802	0.067733124	2907.061
191	0.54000944	0.068710916	2905.1565
192.00098	0.54187393	0.069658391	2907.0066
193.00195	0.5460887	0.070474647	2905.3293
194.00293	0.54874176	0.071370937	2914.1606
195.00391	0.55210561	0.07273864	2923.7654
196.00488	0.55479074	0.073923945	2921.5178
197.00586	0.55934823	0.074859582	2922.8347
198.00684	0.56314456	0.075986817	2931.3008
199.00781	0.5620833	0.076935701	2934.6992
200.00879	0.56562316	0.077916734	2933.3875
201.00977	0.57112235	0.079104111	2937.7129
202.01074	0.57205623	0.080296569	2941.678
203.01172	0.57658017	0.081320606	2944.4099
204.0127	0.57954305	0.082367852	2933.5051
205.01367	0.58357775	0.083312593	2939.5383
206.01465	0.58424652	0.083946519	2944.8433
207.01563	0.58607697	0.084942445	2948.0049
208.0166	0.59077483	0.086005241	2958.9695
209.01758	0.5965507	0.086965226	2954.8577
210.01855	0.59620833	0.087993979	2959.5947
211.01953	0.59902227	0.089013435	2968.5388
212.02051	0.60306942	0.090475939	2968.5911
213.02148	0.60431695	0.091556937	2967.2488
214.02246	0.60835576	0.092537731	2971.7747
215.02344	0.60956895	0.093516305	2968.0496
216.02441	0.61319196	0.094424233	2974.3748
217.02539	0.61890298	0.095641181	2983.6675
218.02637	0.62204599	0.096847735	2981.3721
219.02734	0.62415063	0.09782654	2978.4177
220.02832	0.62793344	0.098793373	2986.5784
221.0293	0.62949455	0.099954821	2986.3337
222.03027	0.63189578	0.10099228	2989.387
223.03125	0.63603008	0.10217351	2993.5986
224.03223	0.63949639	0.10338686	2997.2454
225.0332	0.64422822	0.10449583	2994.175
226.03418	0.64682442	0.10545573	3003.1694
227.03516	0.64665252	0.10666287	3003.9197
228.03613	0.65248322	0.10798366	3017.3494
229.03711	0.65608436	0.10892575	3009.9194
230.03809	0.65527689	0.10989728	3002.1741
231.03906	0.6627236	0.11112405	3017.7437
232.04004	0.66586679	0.11206441	3016.8188
233.04102	0.66722208	0.11319194	3021.0593
234.04199	0.67017025	0.11444873	3020.4036
235.04297	0.6725207	0.11539415	3016.8135
236.04395	0.67929596	0.11642639	3023.0027
237.04492	0.67991579	0.11744299	3030.0322
238.0459	0.68501663	0.1186191	3027.2124
239.04688	0.68409914	0.11956887	3033.6428
240.04785	0.68505043	0.12072541	3034.9763
241.04883	0.68876904	0.12175555	3033.7192
242.0498	0.69483656	0.12276293	3037.0671
243.05078	0.69786888	0.12394728	3039.2917
244.05176	0.7009818	0.12491404	3046.6021
245.05273	0.70315039	0.12606402	3047.0176
246.05371	0.70479906	0.1271802	3041.4651
247.05469	0.71000409	0.12815706	3048.8325
248.05566	0.71082318	0.12918894	3048.3608
249.05664	0.71482038	0.13045147	3058.8284
250.05762	0.71624768	0.13152894	3050.0527
251.05859	0.72383326	0.13256767	3059.9048
252.05957	0.72404426	0.13355088	3052.6086
253.06055	0.72641909	0.13447794	3060.8428
254.06152	0.72951114	0.13546257	3061.811
255.0625	0.73383629	0.13644773	3064.4705
256.06348	0.73447555	0.13762499	3067.0549
257.06445	0.73984671	0.13896444	3076.1042
258.06543	0.74235702	0.14022672	3075.2556
259.06641	0.74492407	0.14160807	3075.3481
260.06738	0.74751407	0.14257824	3075.4854
261.06836	0.75213653	0.1436038	3075.8018
262.06934	0.7534343	0.14469419	3077.7034
263.07031	0.75785971	0.14566605	3076.0974
264.07129	0.75871903	0.14672363	3081.2639
265.07227	0.76258504	0.14783826	3084.1665
266.07324	0.76382935	0.14898044	3084.4507
267.07422	0.76947832	0.15004435	3095.1731
268.0752	0.77179229	0.15092997	3084.9197
269.07617	0.77590871	0.15198882	3091.4292
270.07715	0.77965981	0.15294306	3097.7659
271.07813	0.78112417	0.15390685	3096.0986
272.0791	0.7842117	0.15506415	3101.269
273.08008	0.79006797	0.1560517	3104.4849
274.08105	0.788109	0.15717894	3103.5461
275.08203	0.79393154	0.15826416	3110.3884
276.08301	0.79705185	0.15931165	3103.8313
277.08398	0.79755324	0.16040933	3106.4475
278.08496	0.80140424	0.16139571	3110.3445
279.08594	0.80498731	0.16240087	3110.8535
280.08691	0.80627692	0.16334952	3112.7878
281.08789	0.80962336	0.16439658	3117.5386
282.08887	0.81207955	0.16534701	3114.4299
283.08984	0.8156485	0.16649458	3117.248
284.09082	0.81652749	0.16769351	3121.1409
285.0918	0.82442313	0.16880929	3123.5767
286.09277	0.82641399	0.1697267	3117.1399
287.09375	0.82958752	0.17067762	3126.447
288.09473	0.8325637	0.17163046	3130.1863
289.0957	0.83364409	0.1726218	3128.0884
290.09668	0.83652586	0.17378426	3133.2585
291.09766	0.83941561	0.17486952	3132.021
292.09863	0.84365845	0.17597781	3132.283
293.09961	0.84497386	0.17696664	3134.4673
294.10059	0.84695899	0.17812388	3146.5964
295.10156	0.85270262	0.17932296	3144.7229
296.10254	0.85660106	0.18030672	3145.1968
297.10352	0.85781443	0.18119033	3135.6223
298.10449	0.86334252	0.18235371	3153.2693
299.10547	0.86340338	0.18335615	3144.5889
300.10645	0.86552393	0.18468247	3149.8765
301.10742	0.87158865	0.18558455	3143.7244
302.1084	0.87373507	0.18660903	3156.3298
303.10938	0.88001716	0.18758136	3155.6782
304.11035	0.87763619	0.18865688	3152.106
305.11133	0.88038164	0.18971834	3156.4714
306.1123	0.88711733	0.19067807	3158.4773
307.11328	0.89252418	0.19189593	3167.5881
308.11426	0.89094514	0.19303013	3159.0208
309.11523	0.89374799	0.1938449	3159.6855
310.11621	0.90022492	0.19490699	3167.1206
311.11719	0.90000343	0.19580677	3165.3489
312.11816	0.90524679	0.19659734	3162.8
313.11914	0.90328759	0.19751795	3163.2578
314.12012	0.91136694	0.19844134	3175.5759
315.12109	0.91456687	0.19966625	3174.6086
316.12207	0.91538054	0.2007203	3181.3174
317.12305	0.91879994	0.20193611	3179.0457
318.12402	0.92300522	0.20295666	3175.3357
319.125	0.92258519	0.20413591	3178.0515
320.12598	0.92939514	0.2050823	3186.637
321.12695	0.93239468	0.2060556	3183.9541
322.12793	0.93273646	0.20698233	3184.4885
323.12891	0.93765908	0.20827661	3192.6794
324.12988	0.94016486	0.20936657	3189.0391
325.13086	0.9419564	0.21054997	3193.0532
326.13184	0.94559509	0.21157159	3197.9731
327.13281	0.94809163	0.21264812	3197.4888
328.13379	0.95231563	0.21375282	3198.7373
329.13477	0.95550674	0.21474178	3194.8269
330.13574	0.95681453	0.21565925	3197.4089
331.13672	0.95982969	0.21672294	3201.9163
332.1377	0.96594661	0.21786422	3208.6909
333.13867	0.96847188	0.21885324	3204.1729
334.13965	0.96730709	0.21978809	3207.2905
335.14063	0.97288233	0.22068843	3207.1399
336.1416	0.97632706	0.22171146	3207.4541
337.14258	0.97755933	0.2228334	3209.2302
338.14355	0.98056316	0.22370186	3207.3342
339.14453	0.98605466	0.22493568	3215.5046
340.14551	0.9889968	0.22603697	3212.9893
341.14648	0.98975384	0.22692057	3214.7878
342.14746	0.99183124	0.22794187	3221.4099
343.14844	0.99886221	0.22891988	3220.8503
344.14941	1.0003607	0.22989365	3216.2756
345.15039	1.0047787	0.2308652	3219.3096
346.15137	1.0046773	0.23190755	3221.0532
347.15234	1.0096107	0.2328019	3219.0806
348.15332	1.0130053	0.23377678	3228.7839
349.1543	1.0127113	0.23491985	3226.168
350.15527	1.0157065	0.23586158	3228.8816
351.15625	1.0216085	0.23697072	3231.6194
352.15723	1.0260682	0.23796242	3237.3875
353.1582	1.0264812	0.23911855	3241.6089
354.15918	1.0292522	0.24034375	3236.4231
355.16016	1.0322224	0.24140227	3230.9968
356.16113	1.0357898	0.24255851	3238.05
357.16211	1.0417675	0.24352454	3242.6262
358.16309	1.0448693	0.24456522	3241.1714
359.16406	1.0438551	0.24553175	3236.9426
360.16504	1.0480267	0.24661128	3245.4136
361.16602	1.0518923	0.247715	3248.126
362.16699	1.0512897	0.24873568	3244.8394
363.16797	1.0571727	0.24957916	3242.7673
364.16895	1.057882	0.25061259	3249.1643
365.16992	1.0596547	0.25143269	3249.0063
366.1709	1.0643405	0.25233015	3250.1113
367.17188	1.0683146	0.25343603	3253.4084
368.17285	1.0715085	0.25459993	3258.2026
369.17383	1.0745947	0.25558329	3256.8572
370.1748	1.079273	0.25659698	3261.7529
371.17578	1.0841407	0.25761002	3258.6289
372.17676	1.084128	0.25873381	3260.0645
373.17773	1.0873736	0.25974375	3264.9822
374.17871	1.0920886	0.26064131	3265.7673
375.17969	1.0911196	0.26172325	3263.1499
376.18066	1.0962332	0.26267248	3269.2429
377.18164	1.0981449	0.26365045	3268.678
378.18262	1.1027073	0.26467657	3271.8262
379.18359	1.1053272	0.2657423	3278.2131
380.18457	1.1053027	0.26672679	3275.0981
381.18555	1.1145792	0.26777694	3277.6802
382.18652	1.1140006	0.26907828	3281.2874
383.1875	1.1193048	0.27015808	3280.5837
384.18848	1.1182443	0.271153	3274.6189
385.18945	1.1234622	0.27228272	3279.3435
386.19043	1.1275855	0.27311498	3279.9583
387.19141	1.129782	0.27424151	3287.2524
388.19238	1.1334608	0.27536276	3288.3313
389.19336	1.1345294	0.27642336	3287.259
390.19434	1.1365838	0.27756086	3289.9043
391.19531	1.1406903	0.27855417	3291.2839
392.19629	1.1460389	0.27952072	3294.0212
393.19727	1.143074	0.28057534	3290.1438
394.19824	1.1493087	0.28158408	3291.3542
395.19922	1.1527418	0.28262269	3289.8774
396.2002	1.1557699	0.28334022	3290.7932
397.20117	1.1588731	0.28419015	3291.6587
398.20215	1.163229	0.28517458	3303.144
399.20313	1.1638137	0.28629768	3302.9526
400.2041	1.1699847	0.2872088	3296.5952
401.20508	1.1735433	0.28818876	3302.2021
402.20605	1.1720181	0.28930128	3301.7715
403.20703	1.177524	0.29041094	3311.0315
404.20801	1.1800649	0.29160094	3308.2322
405.20898	1.1842607	0.29274407	3314.6633
406.20996	1.1863986	0.29373619	3310.4958
407.21094	1.1910388	0.29468265	3302.3474
408.21191	1.193247	0.29578343	3314.4316
409.21289	1.1969135	0.29668826	3314.3579
410.21387	1.1971766	0.29766038	3310.4434
411.21484	1.2016853	0.29882902	3322.1179
412.21582	1.2028725	0.30006236	3318.5205
413.2168	1.2071179	0.30125508	3320.8987
414.21777	1.2113187	0.30223098	3315.8154
415.21875	1.2153387	0.30306336	3322.5686
416.21973	1.2152926	0.30411237	3321.2173
417.2207	1.2189206	0.30512157	3324.3872
418.22168	1.2234666	0.30603039	3319.6318
419.22266	1.224371	0.30697417	3321.5874
420.22363	1.2267731	0.30794072	3326.3655
421.22461	1.2323369	0.30874762	3322.0098
422.22559	1.2324649	0.30951184	3320.3748
423.22656	1.2362787	0.31052384	3329.0225
424.22754	1.2386718	0.31170556	3333.0815
425.22852	1.2422916	0.31285563	3341.9058
426.22949	1.2482235	0.31397036	3336.8594
427.23047	1.2464699	0.31508201	3335.6531
428.23145	1.249619	0.31615487	3336.894
429.23242	1.2574373	0.31744483	3343.7861
430.2334	1.2587814	0.3182008	3329.6968
431.23438	1.2600112	0.31931484	3337.0247
432.23535	1.2629292	0.32023916	3346.5313
433.23633	1.269447	0.32142371	3347.688
434.2373	1.2717013	0.32261959	3348.4763
435.23828	1.276861	0.32351652	3340.7813
436.23926	1.2759925	0.32445973	3343.571
437.24023	1.2783449	0.32542053	3345.1985
438.24121	1.2804362	0.32658818	3351.0293
439.24219	1.287693	0.32758459	3350.3394
440.24316	1.2888738	0.32865831	3356.98
441.24414	1.290053	0.32985315	3355.0698
442.24512	1.2952627	0.33095598	3354.002
443.24609	1.2947358	0.33202565	3356.4678
444.24707	1.300941	0.33306888	3353.1279
445.24805	1.3039684	0.33402371	3355.47
446.24902	1.3066764	0.33488467	3355.876
447.25	1.3107893	0.33599806	3365.7395
448.25098	1.3143311	0.33694595	3362.5146
449.25195	1.3134142	0.33822379	3363.5825
450.25293	1.3175554	0.33915749	3355.7859
451.25391	1.3218757	0.34028932	3365.9504
452.25488	1.3217378	0.34112355	3360.9651
453.25586	1.3271438	0.34215054	3369.3523
454.25684	1.3327446	0.34332088	3369.7278
455.25781	1.3351232	0.3441703	3370.8799
456.25879	1.338982	0.34513605	3370.2974
457.25977	1.3387246	0.34584078	3370.5293
458.26074	1.3433137	0.34703693	3375.2388
459.26172	1.3425314	0.34823537	3379.9944
460.2627	1.348345	0.34936684	3378.3508
461.26367	1.3545593	0.35044494	3382.9346
462.26465	1.3553447	0.3516703	3380.4192
463.26563	1.3593527	0.3527706	3385.7102
464.2666	1.3593465	0.35373336	3377.3242
465.26758	1.3612616	0.3548933	3382.4185
466.26855	1.3683069	0.35588348	3382.2205
467.26953	1.3705703	0.35678533	3382.574
468.27051	1.3701117	0.35771427	3383.6804
469.27148	1.3773671	0.35856017	3384.0798
470.27246	1.3770038	0.35932785	3381.6182
471.27344	1.3834723	0.36030266	3389.7939
472.27441	1.3828987	0.36122504	3391.1172
473.27539	1.3878212	0.36237034	3393.7231
474.27637	1.3881074	0.36338443	3389.6636
475.27734	1.3938291	0.36464733	3401.4868
476.27832	1.3945875	0.36578837	3392.1465
477.2793	1.3963404	0.36691713	3397.2061
478.28027	1.399034	0.36809045	3393.085
479.28125	1.4037573	0.36917695	3394.033
480.28223	1.4119169	0.37012598	3398.2393
481.2832	1.4093639	0.37124947	3402.4961
482.28418	1.4162921	0.37246507	3399.6621
483.28516	1.4193989	0.37356958	3406.0378
484.28613	1.4181112	0.37458906	3405.7102
485.28711	1.4235851	0.37576225	3403.4985
486.28809	1.4259144	0.37667763	3401.3652
487.28906	1.4293723	0.37770316	3407.7495
488.29004	1.4326571	0.3789137	3408.5837
489.29102	1.434267	0.3799808	3406.9739
490.29199	1.4402725	0.38100764	3409.3381
491.29297	1.440782	0.38189334	3403.4404
492.29395	1.4427886	0.38294137	3410.3242
493.29492	1.447045	0.38382262	3409.6501
494.2959	1.4484622	0.3846547	3404.9429
495.29688	1.452981	0.38557392	3416.5715
496.29785	1.4552304	0.3865808	3410.9153
497.29883	1.4577875	0.38767985	3413.0203
498.2998	1.463401	0.38866457	3417.9221
499.30078	1.4616306	0.38965413	3421.2021
500.30176	1.4677413	0.39081156	3422.1377
501.30273	1.4728969	0.39195749	3420.2764
502.30371	1.475457	0.39293966	3422.5481
503.30469	1.4770845	0.39412537	3424.8555
504.30566	1.4817232	0.39527482	3426.2451
505.30664	1.4827067	0.39631715	3420.498
506.30762	1.4845876	0.39729121	3417.7051
507.30859	1.4871724	0.39812285	3418.1377
508.30957	1.489954	0.39907053	3423.2556
509.31055	1.4963799	0.40027356	3435.0198
510.31152	1.4972708	0.4018552	3435.033
511.3125	1.5016148	0.40301323	3430.021
512.31348	1.5047623	0.40411341	3434.5872
513.31445	1.5072253	0.40518042	3433.8779
514.31543	1.5102758	0.40615812	3432.5315
515.31641	1.5116823	0.40696901	3427.5051
516.31738	1.5150127	0.4079839	3436.5044
517.31836	1.5170944	0.40897647	3435.551
518.31934	1.523927	0.41002989	3437.1787
519.32031	1.5251206	0.4111532	3446.1274
520.32129	1.5257925	0.41238767	3441.6372
521.32227	1.5316116	0.41379479	3443.7903
522.32324	1.5343271	0.41489601	3436.6497
523.32422	1.5379539	0.41581759	3440.1411
524.3252	1.5392209	0.41675526	3441.4275
525.32617	1.5408628	0.41790262	3448.259
526.32715	1.5468515	0.41915423	3451.2927
527.32813	1.5491494	0.42024377	3450.0725
528.3291	1.5527102	0.42164502	3455.9351
529.33008	1.5549461	0.42265549	3442.9744
530.33105	1.5571613	0.42361498	3446.2476
531.33203	1.5616783	0.42485878	3454.8555
532.33301	1.5662006	0.42603371	3454.8118
533.33398	1.5704254	0.42685348	3450.0737
534.33496	1.5719256	0.42789036	3452.2166
535.33594	1.5717674	0.42894933	3455.5505
536.33691	1.5807238	0.43004113	3459.0757
537.33789	1.5799454	0.43107358	3458.7632
538.33887	1.5817785	0.43216419	3460.6182
539.33984	1.5879657	0.43314463	3451.042
540.34082	1.5897102	0.43416429	3455.5334
541.3418	1.5888451	0.43520266	3460.333
542.34277	1.5947928	0.4361133	3454.5181
543.34375	1.5977063	0.43719944	3467.2607
544.34473	1.6001654	0.43828133	3464.1941
545.3457	1.6034518	0.43938467	3465.6978
546.34668	1.6069813	0.44065341	3469.5532
547.34766	1.6102808	0.44167811	3466.1475
548.34863	1.6133842	0.44277853	3468.3118
549.34961	1.6174164	0.44377473	3469.1802
550.35059	1.617095	0.44483742	3469.7617
551.35156	1.623561	0.44596577	3469.3152
552.35254	1.6248237	0.44698343	3480.2517
553.35352	1.6276743	0.44810852	3474.7437
554.35449	1.6318879	0.44945723	3475.4299
555.35547	1.6349348	0.45056558	3478.2219
556.35645	1.6386175	0.45190725	3485.5513
557.35742	1.6422199	0.45316142	3475.6663
558.3584	1.6418049	0.45419335	3475.3123
559.35938	1.6466428	0.4551506	3473.5977
560.36035	1.6499536	0.45617077	3470.644
561.36133	1.6512603	0.45738411	3480.7688
562.3623	1.6557856	0.4585593	3480.7808
563.36328	1.6587853	0.45973524	3483.3596
564.36426	1.6596307	0.46062315	3477.9387
565.36523	1.6632818	0.46168983	3486.1292
566.36621	1.6670521	0.46266657	3483.8684
567.36719	1.6693487	0.46376443	3480.6523
568.36816	1.672857	0.46466359	3482.9924
569.36914	1.6737621	0.46576038	3483.8579
570.37012	1.6774578	0.46678901	3483.5288
571.37109	1.6824026	0.4679794	3486.7695
572.37207	1.6845611	0.46920252	3490.1704
573.37305	1.6876857	0.47032315	3490.2466
574.37402	1.6915119	0.47160482	3491.4441
575.375	1.6917102	0.47282588	3496.2563
576.37598	1.6976478	0.47387022	3489.9954
577.37695	1.6976224	0.47500083	3494.2771
578.37793	1.7021275	0.47608972	3496.0879
579.37891	1.7044445	0.47715273	3494.5527
580.37988	1.7061937	0.47835284	3486.8347
581.38086	1.7115704	0.47939789	3494.6152
582.38184	1.7152382	0.48051912	3499.3938
583.38281	1.715901	0.48168275	3495.2861
584.38379	1.7228128	0.48276699	3499.9805
585.38477	1.7258778	0.48407397	3502.9417
586.38574	1.7255315	0.48523208	3497.5642
587.38672	1.7320291	0.48629218	3501.6741
588.3877	1.7308067	0.48746404	3499.394
589.38867	1.7384332	0.48856771	3507.1626
590.38965	1.739009	0.48981926	3511.1191
591.39063	1.7412434	0.49098259	3509.3787
592.3916	1.7452372	0.49229628	3509.7751
593.39258	1.745195	0.49347863	3503.6401
594.39355	1.7522043	0.49464598	3507.0232
595.39453	1.754246	0.49571654	3508.4023
596.39551	1.7568336	0.49660078	3506.0403
597.39648	1.7621309	0.49763221	3509.52
598.39746	1.7609092	0.49873322	3513.925
599.39844	1.7665223	0.4999471	3511.5764
600.39941	1.7679467	0.50116795	3513.6934
601.40039	1.7699521	0.50264508	3513.9375
602.40137	1.7724017	0.50372899	3505.5291
603.40234	1.7787532	0.50479132	3517.7419
604.40332	1.7813716	0.50600237	3512.9556
605.4043	1.7826947	0.5069409	3511.5576
606.40527	1.7873094	0.50808895	3519.7803
607.40625	1.7872001	0.50933659	3517.3289
608.40723	1.7946906	0.51069838	3518.9958
609.4082	1.7949398	0.51189661	3519.9988
610.40918	1.795053	0.51319683	3519.2209
611.41016	1.8024911	0.51437199	3521.0728
612.41113	1.8066024	0.51543128	3516.4707
613.41211	1.8075777	0.51647532	3514.0481
614.41309	1.8117908	0.5176844	3524.5811
615.41406	1.8150997	0.51864707	3521.499
616.41504	1.8177998	0.51974857	3526.3066
617.41602	1.8207936	0.52099347	3527.1545
618.41699	1.8234526	0.52225983	3527.0845
619.41797	1.8262075	0.52343458	3527.311
620.41895	1.8299943	0.52490485	3531.2566
621.41992	1.8337564	0.52619809	3530.3674
622.4209	1.8341241	0.52714604	3522.1201
623.42188	1.83708	0.52832025	3524.7803
624.42285	1.8391403	0.52944732	3523.5654
625.42383	1.8447455	0.53057462	3526.78
626.4248	1.8477222	0.53175914	3535.739
627.42578	1.8464038	0.53287679	3532.0051
628.42676	1.8525223	0.53416705	3531.3699
629.42773	1.8542014	0.53525329	3525.4895
630.42871	1.857265	0.53634804	3532.4563
631.42969	1.8603506	0.53734642	3532.9426
632.43066	1.8646066	0.53879869	3535.6426
633.43164	1.8695102	0.53997374	3536.1582
634.43262	1.8687755	0.54125804	3536.4209
635.43359	1.8720355	0.54257101	3531.7844
636.43457	1.8781518	0.54362673	3534.1208
637.43555	1.8766042	0.54493082	3540.0559
638.43652	1.8786255	0.54605448	3536.4141
639.4375	1.886937	0.54713571	3536.0491
640.43848	1.8892577	0.54823989	3537.7888
641.43945	1.8914386	0.549528	3546.418
642.44043	1.8971857	0.55077916	3541.9609
643.44141	1.8961363	0.55205435	3543.8796
644.44238	1.9029818	0.55350834	3544.9919
645.44336	1.906853	0.55467492	3545.5688
646.44434	1.9070965	0.55579168	3543.5735
647.44531	1.9119141	0.55703956	3542.334
648.44629	1.9142665	0.5582602	3547.0408
649.44727	1.9166411	0.559623	3545.5574
650.44824	1.9211071	0.56081426	3548.5518
651.44922	1.9233959	0.56209534	3546.7097
652.4502	1.9262133	0.56326902	3544.3096
653.45117	1.9267093	0.56443024	3542.5042
654.45215	1.9326059	0.5658316	3550.5481
655.45313	1.9358991	0.56715	3548.3037
656.4541	1.93671	0.56836504	3546.6765
657.45508	1.9387141	0.56989306	3553.5002
658.45605	1.943972	0.57128042	3551.2747
659.45703	1.9446895	0.57252932	3547.6543
660.45801	1.9497054	0.57382154	3550.3508
661.45898	1.9535811	0.57491112	3548.6814
662.45996	1.9560494	0.57604563	3551.4846
663.46094	1.9571886	0.57712162	3551.4204
664.46191	1.9629719	0.5783965	3551.7288
665.46289	1.9645848	0.57962507	3553.4775
666.46387	1.9650677	0.58079141	3547.7175
667.46484	1.9720446	0.58219355	3560.561
668.46582	1.9696311	0.58342278	3551.4763
669.4668	1.9751657	0.58482665	3554.603
670.46777	1.9776555	0.58599824	3550.6467
671.46875	1.9814273	0.58727008	3554.4294
672.46973	1.9873297	0.58859736	3560.9575
673.4707	1.9883668	0.5898791	3556.5505
674.47168	1.9906203	0.59126776	3567.1748
675.47266	1.9968736	0.59256262	3558.0286
676.47363	1.9995034	0.59370506	3557.2085
677.47461	1.9973422	0.59493202	3558.7358
678.47559	2.0045812	0.59629279	3563.5122
679.47656	2.006243	0.59760743	3558.0979
680.47754	2.00877	0.59894919	3564.0483
681.47852	2.0092847	0.60020894	3560.1111
682.47949	2.0170896	0.60143334	3567.7495
683.48047	2.016005	0.60258162	3563.2749
684.48145	2.0206528	0.6039111	3561.3745
685.48242	2.022615	0.60515189	3561.4292
686.4834	2.0280197	0.60632288	3564.6943
687.48438	2.0308776	0.60757864	3564.4626
688.48535	2.0329525	0.60872841	3560.6494
689.48633	2.0379906	0.61012471	3567.6462
690.4873	2.0421417	0.61161762	3574.1028
691.48828	2.0413706	0.61303353	3565.7358
692.48926	2.0446486	0.61431348	3566.1277
693.49023	2.0469713	0.61545014	3560.4915
694.49121	2.0492105	0.61674923	3565.4841
695.49219	2.0545282	0.61793035	3565.458
696.49316	2.058286	0.61938924	3574.1799
697.49414	2.0608163	0.62071067	3571.1045
698.49512	2.0634048	0.62218118	3572.6208
699.49609	2.0670834	0.62383002	3580.7961
700.49707	2.0681531	0.62533545	3569.5769
701.49805	2.0741963	0.62686068	3571.2629
702.49902	2.0777316	0.62808442	3567.8022
703.5	2.0754991	0.62925243	3562.6733
704.50098	2.0814261	0.630279	3570.3977
705.50195	2.0853114	0.63180518	3579.2397
706.50293	2.089381	0.63308358	3573.7615
707.50391	2.0897832	0.63459986	3577.929
708.50488	2.0914333	0.63586366	3572.0967
709.50586	2.0962608	0.63722825	3571.5217
710.50684	2.1006734	0.63851398	3578.9888
711.50781	2.1028187	0.63996047	3573.5142
712.50879	2.1046777	0.64119864	3573.6824
713.50977	2.1075363	0.64236861	3570.3652
714.51074	2.11096	0.64390099	3583.3374
715.51172	2.1130958	0.6450808	3574.2844
716.5127	2.1182809	0.64661443	3581.5989
717.51367	2.1199419	0.64775252	3570.4773
718.51465	2.121927	0.64903671	3578.9131
719.51563	2.1272571	0.6503222	3581.1965
720.5166	2.1271412	0.65211338	3584.5088
721.51758	2.1323473	0.65354037	3579.4922
722.51855	2.1391709	0.65493089	3584.885
723.51953	2.1382725	0.65649277	3583.9087
724.52051	2.1423244	0.65822101	3582.7351
725.52148	2.144068	0.65963447	3577.5859
726.52246	2.1449819	0.6611557	3577.6636
727.52344	2.1491768	0.66256779	3582.4075
728.52441	2.152524	0.6639713	3580.8533
729.52539	2.1579781	0.66527867	3581.4827
730.52637	2.1598539	0.66656083	3579.2837
731.52734	2.1609752	0.66778207	3582.7168
732.52832	2.1655619	0.66918349	3582.5007
733.5293	2.1679084	0.67080688	3585.6689
734.53027	2.1712809	0.67229944	3583.8792
735.53125	2.1743422	0.6736967	3577.636
736.53223	2.177007	0.67509943	3582.9629
737.5332	2.1812642	0.67649102	3580.7083
738.53418	2.1824722	0.67797637	3587.1941
739.53516	2.1859481	0.67931962	3583.0278
740.53613	2.1923099	0.68089372	3590.7043
741.53711	2.1940715	0.68258107	3593.1777
742.53809	2.1948473	0.68371242	3580.6545
743.53906	2.1949816	0.6852439	3583.103
744.54004	2.2004623	0.68646413	3580.1292
745.54102	2.203692	0.6876809	3585.6921
746.54199	2.206912	0.68909168	3590.5332
747.54297	2.2087262	0.69046426	3584.0796
748.54395	2.2132471	0.69196934	3590.9575
749.54492	2.2139597	0.69346231	3588.6934
750.5459	2.2208364	0.69505286	3589.9539
751.54688	2.2218211	0.69661635	3588.3474
752.54785	2.2257085	0.69840854	3591.1458
753.54883	2.2296393	0.69975728	3584.9138
754.5498	2.2276051	0.7013402	3586.2217
755.55078	2.233748	0.70281667	3585.3281
756.55176	2.2356176	0.70413065	3583.5964
757.55273	2.2407739	0.70557195	3584.1899
758.55371	2.243217	0.70684856	3585.2253
759.55469	2.2465205	0.70854306	3595.0813
760.55566	2.2479784	0.71037638	3591.5354
761.55664	2.2516632	0.71196675	3587.376
762.55762	2.2528217	0.71349704	3590.0242
763.55859	2.2596741	0.71504456	3591.2693
764.55957	2.2611549	0.71665692	3593.5295
765.56055	2.263911	0.71800274	3593.0032
766.56152	2.2697444	0.71975446	3595.9136
767.5625	2.2708094	0.72136956	3593.5234
768.56348	2.2738891	0.72306883	3594.0815
769.56445	2.2760966	0.7245177	3591.1426
770.56543	2.2786069	0.72624874	3589.4336
771.56641	2.2802401	0.72780925	3589.1577
772.56738	2.2889962	0.72947907	3595.9658
773.56836	2.2874298	0.73106897	3590.844
774.56934	2.2920439	0.73273116	3591.5806
775.57031	2.2929921	0.73429048	3589.8667
776.57129	2.2969813	0.73576212	3593.9209
777.57227	2.2999647	0.73726773	3589.0884
778.57324	2.3070827	0.73874736	3590.7551
779.57422	2.3069754	0.74031842	3593.1113
780.5752	2.3106339	0.74196595	3590.5459
781.57617	2.3100865	0.74345642	3594.6106
782.57715	2.315336	0.74528909	3596.7458
783.57813	2.3162766	0.74696457	3593.0715
784.5791	2.3208818	0.74850029	3596.0769
785.58008	2.3268032	0.74996233	3599.6355
786.58105	2.3280928	0.75182652	3595.3467
787.58203	2.3313568	0.75336879	3592.0911
788.58301	2.3328652	0.75510007	3591.3491
789.58398	2.336493	0.75680554	3595.0027
790.58496	2.339345	0.75864899	3596.2983
791.58594	2.3416088	0.76024443	3591.5178
792.58691	2.3469696	0.7620365	3598.821
793.58789	2.3504877	0.76356721	3592.9873
794.58887	2.3510051	0.76493138	3593.5085
795.58984	2.3536737	0.76665807	3596.6628
796.59082	2.3575351	0.76843011	3597.9187
797.5918	2.3589661	0.76996773	3593.3276
798.59277	2.3631577	0.7718206	3595.5815
799.59375	2.3661201	0.77360463	3594.2712
800.59473	2.3662336	0.77531952	3591.1401
801.5957	2.3777108	0.7767995	3593.1245
802.59668	2.3752346	0.77839178	3597.5935
803.59766	2.3794944	0.78004879	3602.7307
804.59863	2.3812711	0.7821635	3609.4277
805.59961	2.3841701	0.7843048	3600.8074
806.60059	2.389118	0.78600776	3588.5598
807.60156	2.388566	0.78749758	3592.6306
808.60254	2.3924239	0.78930265	3592.469
809.60352	2.3949785	0.79115939	3597.0239
810.60449	2.3950121	0.79277313	3589.6455
811.60547	2.4005661	0.7944743	3593.1328
812.60645	2.4048343	0.79615927	3594.5178
813.60742	2.4087665	0.79786706	3600.05
814.6084	2.4106679	0.79978818	3597.9358
815.60938	2.4136229	0.80158806	3593.8975
816.61035	2.4179487	0.80325401	3591.3052
817.61133	2.4243925	0.80501384	3597.1016
818.6123	2.4238997	0.80676353	3594.5845
819.61328	2.4253953	0.80853361	3595.3796
820.61426	2.4297085	0.81049103	3595.8345
821.61523	2.433054	0.81264615	3595.8479
822.61621	2.436542	0.81471246	3592.2874
823.61719	2.4358232	0.81662947	3589.717
824.61816	2.4431241	0.81833464	3589.7085
825.61914	2.4431486	0.82004672	3594.6121
826.62012	2.4448555	0.82175004	3596.6406
827.62109	2.4504192	0.82375252	3594.6335
828.62207	2.4559963	0.8260088	3597.5264
829.62305	2.4546421	0.82788354	3590.635
830.62402	2.4586055	0.82971954	3591.8347
831.625	2.4630923	0.83183646	3600.8899
832.62598	2.4652395	0.83412802	3596.3816
833.62695	2.469862	0.83630383	3593.7522
834.62793	2.4744012	0.83819908	3594.6614
835.62891	2.473217	0.84002662	3588.896
836.62988	2.478111	0.8421461	3598.4827
837.63086	2.4833744	0.84419531	3595.1804
838.63184	2.4823532	0.84629881	3593.658
839.63281	2.4881709	0.84827042	3593.0371
840.63379	2.489959	0.84975046	3590.0288
841.63477	2.493515	0.851569	3587.7222
842.63574	2.4933376	0.85349005	3594.0598
843.63672	2.4968963	0.85577929	3591.2197
844.6377	2.5034499	0.85775107	3597.4297
845.63867	2.5045447	0.86003178	3592.6372
846.63965	2.5077767	0.86223847	3590.0818
847.64063	2.5104823	0.86438012	3588.8577
848.6416	2.5125892	0.86605901	3586.7996
849.64258	2.5141582	0.86781609	3588.8667
850.64355	2.5209396	0.86970705	3587.5667
851.64453	2.5193546	0.87147677	3589.7559
852.64551	2.5239806	0.87357235	3589.2458
853.64648	2.5282753	0.87566429	3588.4646
854.64746	2.5315835	0.87785995	3591.4832
855.64844	2.5341871	0.87994742	3588.9204
856.64941	2.5380123	0.88248801	3587.8887
857.65039	2.5399368	0.88490397	3586.0701
858.65137	2.5433874	0.88696337	3582.7837
859.65234	2.5464747	0.88880724	3587.2275
860.65332	2.5481102	0.89089304	3583.3708
861.6543	2.5529518	0.89290726	3591.6521
862.65527	2.5567682	0.89491922	3581.6155
863.65625	2.5550418	0.8971858	3585.8384
864.65723	2.5616744	0.89960063	3583.8677
865.6582	2.5639849	0.90187877	3582.991
866.65918	2.5706482	0.9044984	3589.0381
867.66016	2.5688305	0.9069044	3582.0349
868.66113	2.575655	0.90989596	3585.5493
869.66211	2.5783062	0.91216141	3578.4885
870.66309	2.5797992	0.91444707	3582.5449
871.66406	2.5813007	0.91625553	3578.2432
872.66504	2.5885079	0.91831499	3583.8826
873.66602	2.5894771	0.9202522	3580.5632
874.66699	2.5907357	0.92269397	3586.2961
875.66797	2.593926	0.92549777	3578.9392
876.66895	2.5958893	0.92785913	3579.8831
877.66992	2.599777	0.93012369	3578.1838
878.6709	2.6046376	0.9327985	3585.8413
879.67188	2.6051488	0.93529922	3578.5176
880.67285	2.6090729	0.93800932	3576.4307
881.67383	2.6153595	0.94032764	3576.916
882.6748	2.6149216	0.94245088	3575.9929
883.67578	2.6191647	0.9445926	3578.0757
884.67676	2.6212018	0.94696826	3574.344
885.67773	2.6247857	0.94959909	3580.6118
886.67871	2.628813	0.95189255	3572.1438
887.67969	2.630188	0.9540751	3572.7627
888.68066	2.6334684	0.9565888	3578.4619
889.68164	2.6372125	0.95887649	3570.0054
890.68262	2.6392081	0.96141934	3573.9402
891.68359	2.6430681	0.9637332	3565.179
892.68457	2.6436946	0.96589673	3565.3752
893.68555	2.6502085	0.96825558	3576.1191
894.68652	2.6554224	0.97117704	3572.6333
895.6875	2.6541591	0.97386009	3566.9121
896.68848	2.6575627	0.97640604	3572.698
897.68945	2.6621449	0.97922063	3570.0774
898.69043	2.6608653	0.98175675	3563.9961
899.69141	2.6635408	0.9843573	3567.4697
900.69238	2.6686337	0.98729217	3567.7324
901.69336	2.6744828	0.98999357	3564.8708
902.69434	2.6761265	0.99256706	3564.7317
903.69531	2.681864	0.99564755	3571.7839
904.69629	2.6807976	0.99858111	3566.4041
905.69727	2.6867819	1.0014586	3567.0493
906.69824	2.6892893	1.0037876	3553.0505
907.69922	2.6913424	1.0065345	3563.3176
908.7002	2.6946783	1.0092323	3563.791
909.70117	2.6956367	1.0122681	3559.5181
910.70215	2.6992459	1.0148702	3551.6526
911.70313	2.7036235	1.0174503	3560.7383
912.7041	2.7092011	1.0202129	3554.2751
913.70508	2.7082098	1.0229517	3555.0991
914.70605	2.7123177	1.0256886	3553.4573
915.70703	2.7142444	1.0279903	3548.7427
916.70801	2.7173648	1.0304393	3554.4773
917.70898	2.7198117	1.0332705	3552.8867
918.70996	2.7256389	1.0359595	3551.1768
919.71094	2.7289169	1.0388929	3554.7979
920.71191	2.7296262	1.0414529	3549.2119
921.71289	2.7323709	1.0443387	3549.8164
922.71387	2.7351022	1.0471432	3545.4939
923.71484	2.7378325	1.0496057	3539.4429
924.71582	2.7420843	1.0523684	3547.1094
925.7168	2.7456942	1.0554739	3547.6843
926.71777	2.7483428	1.0586344	3541.5557
927.71875	2.7506325	1.0617594	3544.9495
928.71973	2.7517266	1.0645274	3537.8101
929.7207	2.7576516	1.0674708	3536.7834
930.72168	2.7596929	1.0707568	3535.7666
931.72266	2.7641029	1.0739851	3535.2229
932.72363	2.7668738	1.0775043	3531.7813
933.72461	2.7687526	1.0804371	3529.168
934.72559	2.769798	1.0831228	3529.2092
935.72656	2.7728896	1.0862265	3528.9541
936.72754	2.780941	1.0894825	3528.8889
937.72852	2.7807903	1.0923536	3522.7529
938.72949	2.7820549	1.0948859	3519.8428
939.73047	2.7850013	1.0981474	3526.6729
940.73145	2.7900686	1.1018244	3530.2544
941.73242	2.7935159	1.1051036	3516.9036
942.7334	2.7960992	1.1076387	3518.8564
943.73438	2.7968378	1.110299	3511.7219
944.73535	2.8007228	1.1127466	3512.2061
945.73633	2.8030896	1.1152602	3513.5415
946.7373	2.8062603	1.1186166	3513.6433
947.73828	2.8118367	1.1221161	3511.4211
948.73926	2.8139627	1.1254766	3511.5928
949.74023	2.8179944	1.1285961	3504.7688
950.74121	2.8229558	1.1314092	3501.0645
951.74219	2.8191183	1.1338667	3494.0388
952.74316	2.8256495	1.1364669	3497.9663
953.74414	2.8297806	1.1392843	3500.9187
954.74512	2.8304553	1.142398	3497.6975
955.74609	2.8376524	1.1457385	3495.6438
956.74707	2.8396409	1.1495935	3493.6956
957.74805	2.8427145	1.1528448	3490.0183
958.74902	2.8467398	1.1556029	3491.0056
959.75	2.8469341	1.1585525	3486.5173
960.75098	2.8497846	1.1613519	3486.3367
961.75195	2.8532863	1.1643677	3483.2341
962.75293	2.8556428	1.1669707	3475.1833
963.75391	2.8580704	1.1697425	3479.175
964.75488	2.86377	1.1726379	3478.9358
965.75586	2.8657844	1.1761019	3484.1482
966.75684	2.8708305	1.1798477	3476.3809
967.75781	2.8725653	1.1829355	3472.2224
968.75879	2.8726978	1.1861092	3468.8245
969.75977	2.8757286	1.1892123	3468.509
970.76074	2.8806117	1.1925355	3464.0461
971.76172	2.8812773	1.1960775	3463.3411
972.7627	2.8865337	1.1992898	3456.271
973.76367	2.8907342	1.2022984	3456.6475
974.76465	2.8914895	1.2052987	3454.5845
975.76563	2.8960867	1.2090213	3458.3022
976.7666	2.8957484	1.2126734	3447.6262
977.76758	2.9033475	1.2156281	3446.4773
978.76855	2.9059467	1.2186896	3447.4517
979.76953	2.9065886	1.222236	3441.8142
980.77051	2.9102814	1.2251673	3439.2224
981.77148	2.9123943	1.227989	3439.5735
982.77246	2.9148889	1.2313647	3440.4998
983.77344	2.9196849	1.234676	3434.0654
984.77441	2.9238944	1.2372088	3428.2119
985.77539	2.9258089	1.2404146	3429.1714
986.77637	2.9298851	1.2431759	3425.7463
987.77734	2.9303226	1.2462956	3425.71
988.77832	2.9333973	1.2495915	3420.9233
989.7793	2.9377735	1.2534202	3422.103
990.78027	2.9417322	1.2567438	3411.3967
991.78125	2.9444144	1.2596768	3412.9045
992.78223	2.9437294	1.2626615	3409.5264
993.7832	2.951242	1.2657822	3401.9653
994.78418	2.9524066	1.2687731	3404.3606
995.78516	2.9563828	1.2721317	3399.9187
996.78613	2.9603691	1.2752739	3399.5288
997.78711	2.9588988	1.2788179	3398.4536
998.78809	2.9647524	1.2821739	3390.6062
999.78906	2.9700081	1.2850729	3390.1516
1000.79	2.9689939	1.2883589	3388.6897
1001.791	2.9726737	1.29193	3386.9692
1002.792	2.9764047	1.294973	3381.2485
1003.793	2.9804239	1.2978146	3376.7568
1004.7939	2.9823906	1.3001432	3365.5688
1005.7949	2.9848282	1.3025839	3375.7583
1006.7959	2.9884229	1.3048652	3370.8984
1007.7969	2.9914987	1.3076953	3365.1599
1008.7979	2.9929638	1.3105773	3364.5046
1009.7988	2.9990485	1.3139144	3367.1438
1010.7998	2.998311	1.3174382	3358.7466
1011.8008	3.0044057	1.3210357	3357.5967
1012.8018	3.0084567	1.3242059	3351.8376
1013.8027	3.0104527	1.3273122	3353.6609
1014.8037	3.0136647	1.3307076	3349.4622
1015.8047	3.013011	1.3344181	3340.1191
1016.8057	3.0188665	1.3377534	3337.8406
1017.8066	3.0209687	1.3406452	3328.6536
1018.8076	3.0250893	1.34317	3330.3738
1019.8086	3.0257609	1.3465395	3332.9294
1020.8096	3.0308647	1.3503789	3329.4841
1021.8105	3.035841	1.3541253	3320.3743
1022.8115	3.0372036	1.3573831	3319.9194
1023.8125	3.038451	1.3611237	3316.7856
1024.8135	3.0409179	1.3644521	3305.9583
1025.8145	3.0441639	1.368031	3307.6909
1026.8154	3.0503139	1.3717017	3305.0017
1027.8164	3.0509548	1.3748022	3296.9268
1028.8174	3.0558271	1.3779018	3290.728
1029.8184	3.059015	1.3807102	3287.1609
1030.8193	3.0601003	1.3835225	3285.0408
1031.8203	3.063627	1.3868452	3284.3806
1032.8213	3.0650702	1.3901794	3279.2744
1033.8223	3.0718789	1.3935246	3283.6941
1034.8232	3.072607	1.396821	3269.8118
1035.8242	3.0731068	1.3998961	3267.1765
1036.8252	3.078263	1.4031551	3261.2297
1037.8262	3.0837781	1.4067693	3262.9719
1038.8271	3.0833609	1.4100896	3256.9985
1039.8281	3.0883625	1.4136316	3246.7341
1040.8291	3.0887032	1.4164135	3241.5093
1041.8301	3.094908	1.4196239	3242.209
1042.8311	3.0980761	1.4232321	3241.9358
1043.832	3.1022067	1.4274803	3237.8625
1044.833	3.1013663	1.4308825	3226.5571
1045.834	3.1086254	1.4344077	3227.0605
1046.835	3.1090627	1.4378587	3218.4194
1047.8359	3.114558	1.4413369	3218.8271
1048.8369	3.1141534	1.444317	3210.156
1049.8379	3.1163237	1.4470836	3201.1694
1050.8389	3.1214519	1.4499543	3202.4465
1051.8398	3.1210704	1.4530913	3202.1355
1052.8408	3.1284022	1.4568028	3197.0791
1053.8418	3.1293075	1.4599307	3189.0781
1054.8428	3.1356959	1.463469	3190.0889
1055.8438	3.1354778	1.4671649	3183.4854
1056.8447	3.138217	1.4711225	3178.4888
1057.8457	3.1433954	1.4746698	3167.5381
1058.8467	3.1426029	1.4773957	3157.7979
1059.8477	3.1481931	1.4805098	3162.342
1060.8486	3.1528325	1.4840701	3158.231
1061.8496	3.1529996	1.4878633	3153.9639
1062.8506	3.15661	1.4915587	3148.3945
1063.8516	3.1591458	1.4947864	3134.1948
1064.8525	3.1637046	1.498124	3135.5659
1065.8535	3.1673369	1.5008667	3130.5894
1066.8545	3.1685367	1.5044034	3126.8372
1067.8555	3.1702118	1.508112	3119.9868
1068.8564	3.1721463	1.5115908	3110.9885
1069.8574	3.1767108	1.5151289	3109.7585
1070.8584	3.1776872	1.5182959	3099.6511
1071.8594	3.1864932	1.521641	3101.4727
1072.8604	3.1856098	1.5253624	3094.7576
1073.8613	3.1879759	1.5291541	3088.8806
1074.8623	3.1943901	1.5330011	3082.0308
1075.8633	3.1945055	1.536456	3081.0012
1076.8643	3.197794	1.5391082	3065.8625
1077.8652	3.2022109	1.5425838	3062.4775
1078.8662	3.2053668	1.5463029	3060.4766
1079.8672	3.2071385	1.5497901	3052.1152
1080.8682	3.2114089	1.5533952	3042.0449
1081.8691	3.2120855	1.557016	3038.3503
1082.8701	3.2191272	1.5611477	3038.1182
1083.8711	3.219867	1.5652088	3027.7922
1084.8721	3.2244763	1.5688353	3018.498
1085.873	3.2277324	1.5716038	3011.6108
1086.874	3.2301393	1.5746359	3009.1226
1087.875	3.2295451	1.5781735	3002.0825
1088.876	3.2341509	1.5823644	2995.0698
1089.877	3.235893	1.5864573	2986.4141
1090.8779	3.2411387	1.5903118	2980.4478
1091.8789	3.2434263	1.5938232	2971.7559
1092.8799	3.2476251	1.5967826	2966.8765
1093.8809	3.2509007	1.5996517	2963.1636
1094.8818	3.2547367	1.6028398	2957.6785
1095.8828	3.2560289	1.6059922	2954.9468
1096.8838	3.2592444	1.609805	2947.0928
1097.8848	3.2608821	1.6130528	2934.7153
1098.8857	3.2650414	1.6163952	2932.5186
1099.8867	3.2649355	1.6198717	2926.8784
1100.8877	3.2720218	1.623621	2916.2522
1101.8887	3.2719851	1.6264111	2905.2524
1102.8896	3.2753727	1.6294575	2908.5793
1103.8906	3.277293	1.6339095	2902.7051
1104.8916	3.2821681	1.6384181	2889.6191
1105.8926	3.2847843	1.6418886	2879.4729
1106.8936	3.2877426	1.645312	2871.8694
1107.8945	3.2903786	1.6494641	2866.6484
1108.8955	3.2978356	1.6531242	2861.5835
1109.8965	3.2947376	1.6566726	2855.8684
1110.8975	3.3001091	1.6604687	2840.9937
1111.8984	3.3033853	1.6644654	2837.7014
1112.8994	3.3071086	1.6683362	2829.7295
1113.9004	3.310714	1.672348	2819.3025
1114.9014	3.3115203	1.6761329	2808.1118
1115.9023	3.3163521	1.6802628	2803.3018
1116.9033	3.3195386	1.684834	2789.8757
1117.9043	3.3215468	1.6885775	2781.012
1118.9053	3.3263566	1.6923699	2775.926
1119.9063	3.3296893	1.6961288	2769.2454
1120.9072	3.3327453	1.6995839	2751.0427
1121.9082	3.3336196	1.7036766	2746.3062
1122.9092	3.3368471	1.7076905	2736.584
1123.9102	3.3399858	1.7121001	2727.8992
1124.9111	3.3444026	1.7164772	2713.8274
1125.9121	3.3492413	1.7200441	2698.3672
1126.9131	3.3479106	1.7235191	2693.6709
1127.9141	3.352648	1.7271963	2684.1196
1128.915	3.3568213	1.7308342	2675.6985
1129.916	3.3612182	1.7348368	2669.311
1130.917	3.3603151	1.7378806	2658.7324
1131.918	3.3656614	1.7415112	2650.0347
1132.9189	3.3686185	1.7456753	2638.6563
1133.9199	3.370079	1.7496287	2634.5527
1134.9209	3.3734262	1.7543024	2613.9973
1135.9219	3.3812206	1.7582488	2602.8149
1136.9229	3.3757865	1.7615916	2586.1162
1137.9238	3.382827	1.7648568	2576.4829
1138.9248	3.3841288	1.7682104	2574.5574
1139.9258	3.3918352	1.7720923	2558.2124
1140.9268	3.3906407	1.7758073	2551.7549
1141.9277	3.3958507	1.780254	2540.3784
1142.9287	3.3972366	1.7849424	2512.7212
1143.9297	3.4001064	1.7894428	2499.5098
1144.9307	3.4691052	-0.038571514	-10.665533