File: datasets/am_bench_2022/raw_data/0-XY.20-2/specimen.dat
MTS793|MPT|ENU|1|2|.|/|:|1|0|0|A

Operator Information						Time:	12.744629	Sec	10/13/2021 4:13:27 PM
Operator	Jake Benzing
Project	AM Bench 2022 mini-tensile challenge
Specimen ID	0-XY.20-2
Material	PBF-L Inconel 625
Specimen Width	2.56	mm
Specimen Thickness	1.52	mm
Notes
Operator Information End

Data Acquisition						Time:	1013.738	Sec	10/13/2021 4:30:08 PM
Time	Axial Displacement	Axial Extensometer	Axial Force
Sec	mm	mm	N
12.85791	0.0024965254	0.005086483	75.088158
13.758789	0.0052285418	0.0052810661	87.932281
14.659668	0.0069383057	0.0051637301	103.07543
15.560547	0.0091220336	0.0053415732	114.38065
16.461426	0.010146437	0.0055117742	127.40997
17.362305	0.012554265	0.0054901345	140.64653
18.263184	0.01727864	0.0055631977	157.22922
19.164063	0.01973011	0.0057446552	170.4245
20.064941	0.019990116	0.0055605792	181.74593
20.96582	0.026689334	0.0057306737	198.84947
21.866699	0.026756743	0.0057456344	216.69536
22.767578	0.028211674	0.0059490432	234.18762
23.668457	0.032383457	0.0060239062	252.07442
24.569336	0.033365451	0.0061058411	266.24487
25.470215	0.035695061	0.0061201127	282.18393
26.371094	0.039977793	0.0062101861	307.56555
27.271973	0.040152155	0.0062931259	319.47586
28.172852	0.043155856	0.0064327568	342.72986
29.07373	0.047184166	0.0065273498	361.37595
29.974609	0.049862862	0.0066475207	383.92743
30.875488	0.049513113	0.0066658501	403.82657
31.776367	0.055422936	0.0069096233	426.14618
32.677246	0.058909565	0.0067928899	446.62131
33.578125	0.06211913	0.0069385529	460.83612
34.479004	0.063817829	0.0070001297	486.42386
35.379883	0.064016782	0.0071429294	504.56757
36.280762	0.072215438	0.007264731	525.29529
37.181641	0.073437564	0.0073354105	545.60217
38.08252	0.075181596	0.0074236272	567.4823
38.983398	0.074721821	0.0076551344	589.70972
39.884277	0.078939863	0.0076096701	613.65283
40.785156	0.084402405	0.0079654343	637.35834
41.686035	0.085585035	0.0079213679	661.06122
42.586914	0.089309081	0.0080833798	685.48309
43.487793	0.091195054	0.0081426343	705.00262
44.388672	0.095917329	0.0082573807	734.71637
45.289551	0.09501335	0.0083493255	753.01593
46.19043	0.098690324	0.0084865149	777.30145
47.091309	0.10142843	0.008590091	795.11127
47.992188	0.10355556	0.0088806758	828.10205
48.893066	0.10644657	0.0088390633	852.4079
49.793945	0.10884272	0.0090647349	882.75751
50.694824	0.11151921	0.0092063257	905.0835
51.595703	0.11389549	0.0092552584	932.04376
52.496582	0.11674854	0.0094158407	954.95691
53.397461	0.11763121	0.0094153155	974.7066
54.29834	0.12640603	0.0098011754	1011.5425
55.199219	0.12357464	0.0097065242	1026.9053
56.100098	0.12549201	0.0099535463	1053.8871
57.000977	0.12887163	0.0099521736	1077.568
57.901855	0.13522376	0.010124846	1107.3112
58.802734	0.13522294	0.010276377	1132.0348
59.703613	0.13608247	0.010409247	1163.578
60.604492	0.13955168	0.010475131	1184.5785
61.505371	0.14749166	0.010865523	1219.3535
62.40625	0.14639166	0.010750079	1243.0508
63.307129	0.15067731	0.01097272	1271.6083
64.208008	0.15201668	0.011021261	1289.3395
65.108887	0.15265389	0.01118621	1314.1479
66.009766	0.15722224	0.011275267	1341.9015
66.910645	0.1595287	0.011557623	1365.9753
67.811523	0.16592187	0.011704635	1402.853
68.712402	0.16910644	0.011721301	1424.0583
69.613281	0.16764125	0.011855945	1446.1342
70.51416	0.1673667	0.011967868	1467.4242
71.415039	0.1757704	0.012116834	1496.0879
72.315918	0.17566407	0.012418127	1520.1978
73.216797	0.1783006	0.012423954	1541.3462
74.117676	0.18324867	0.012750925	1573.9944
75.018555	0.18175706	0.012773572	1595.1647
75.919434	0.18569605	0.012811731	1619.9741
76.820313	0.19079368	0.013079512	1647.2614
77.721191	0.19127968	0.013181595	1672.1075
78.62207	0.19521436	0.013369031	1702.7622
79.522949	0.19805594	0.013448999	1723.0426
80.423828	0.20309047	0.013603039	1743.4703
81.324707	0.2039258	0.0138101	1770.8608
82.225586	0.20477304	0.013913777	1800.3214
83.126465	0.20768264	0.014018549	1822.5554
84.027344	0.20971434	0.014129139	1833.4653
84.928223	0.2120443	0.014249024	1855.9535
85.829102	0.21553744	0.014533667	1881.5049
86.72998	0.2219511	0.014609543	1903.511
87.630859	0.22401045	0.014893125	1932.9071
88.531738	0.22446956	0.014916424	1946.946
89.432617	0.22927502	0.015105377	1976.2673
90.333496	0.22897977	0.015296968	1994.1348
91.234375	0.23025849	0.015417611	2011.0493
92.135254	0.23519979	0.015609148	2038.2352
93.036133	0.23826471	0.015707467	2050.6067
93.937012	0.24018373	0.015732447	2074.8047
94.837891	0.24450277	0.01602138	2087.8857
95.73877	0.24933138	0.016171506	2115.6958
96.639648	0.24928898	0.016399989	2138.4951
97.540527	0.25439906	0.01655462	2155.4736
98.441406	0.25670859	0.016831985	2179.7808
99.342285	0.25519854	0.016999723	2188.595
100.24316	0.26085088	0.017147502	2208.23
101.14404	0.26511845	0.017207639	2225.4038
102.04492	0.26528585	0.017447639	2242.5659
102.9458	0.26748943	0.017568983	2263.999
103.84668	0.27334845	0.017888784	2280.2727
104.74756	0.27606955	0.018030424	2291.9365
105.64844	0.27944407	0.018295944	2307.8464
106.54932	0.28186399	0.018572519	2330.5718
107.4502	0.28354388	0.018524271	2336.7983
108.35107	0.28319186	0.018748252	2345.4514
109.25195	0.28664041	0.018877072	2357.1069
110.15283	0.29097092	0.019194704	2377.2815
111.05371	0.29088876	0.019339986	2385.7693
111.95459	0.29521778	0.019554	2402.6509
112.85547	0.29784858	0.019807084	2416.6699
113.75635	0.30087873	0.020107754	2434.8792
114.65723	0.30490801	0.020166969	2447.3276
115.55811	0.30804074	0.020549688	2459.6699
116.45898	0.31110859	0.020699233	2466.127
117.35986	0.31276983	0.021028822	2482.0034
118.26074	0.3136152	0.021256395	2497.114
119.16162	0.31819484	0.021520615	2503.7043
120.0625	0.31954098	0.021722604	2505.3748
120.96338	0.32369262	0.022007272	2523.4465
121.86426	0.32345045	0.022293385	2531.8247
122.76514	0.32995281	0.022534229	2547.5269
123.66602	0.33122435	0.022742715	2551.8555
124.56689	0.33493361	0.023267742	2568.4363
125.46777	0.33588368	0.023438575	2567.4258
126.36865	0.34110287	0.02376096	2584.147
127.26953	0.34431386	0.024030071	2587.9707
128.17041	0.34844786	0.024485592	2601.8069
129.07129	0.34936762	0.024822691	2610.5208
129.97217	0.35054451	0.025275741	2623.0774
130.87305	0.35313126	0.025764072	2629.4646
131.77393	0.35745564	0.026115546	2634.6333
132.6748	0.35816577	0.026453072	2636.7
133.57568	0.36251715	0.026942378	2654.7649
134.47656	0.36294967	0.027331805	2654.8174
135.37744	0.36445379	0.027894819	2664.5999
136.27832	0.36769515	0.028429747	2672.6687
137.1792	0.37301484	0.02897875	2675.4517
138.08008	0.37661985	0.029502302	2681.428
138.98096	0.37541488	0.030021088	2683.3267
139.88184	0.3817786	0.030533917	2692.2695
140.78271	0.38077646	0.030852858	2693.0593
141.68359	0.38838992	0.031476706	2704.1904
142.58447	0.39006341	0.032251772	2709.814
143.48535	0.39047933	0.032843444	2713.1907
144.38623	0.39454356	0.033617679	2728.8264
145.28711	0.39713803	0.034355238	2724.4963
146.18799	0.39763346	0.034973364	2726.178
147.08887	0.40244153	0.035711505	2729.803
147.98975	0.40576345	0.036252491	2737.9468
148.89063	0.40686658	0.037183393	2740.6973
149.7915	0.40938073	0.037917685	2745.2419
150.69238	0.41156304	0.038824167	2752.5205
151.59326	0.41737691	0.039542682	2760.0715
152.49414	0.41797274	0.040444918	2763.7371
153.39502	0.41845506	0.041407045	2766.97
154.2959	0.42501438	0.042246155	2768.8735
155.19678	0.42683703	0.042983226	2772.8638
156.09766	0.43081659	0.044054352	2783.6475
156.99854	0.43651351	0.044896845	2791.3284
157.89941	0.43632811	0.046066817	2791.6794
158.80029	0.43533894	0.046825603	2782.6501
159.70117	0.44142041	0.047806572	2791.9863
160.60205	0.44473344	0.048774779	2798.7283
161.50293	0.44525263	0.049827199	2803.751
162.40381	0.45079634	0.050850172	2808.8174
163.30469	0.44523501	0.051797818	2803.533
164.20557	0.45781374	0.052899286	2817.6089
165.10645	0.45456955	0.05417151	2809.9973
166.00732	0.45837596	0.054984692	2804.8496
166.9082	0.46173638	0.0558597	2808.2195
167.80908	0.46530369	0.056759231	2823.2512
168.70996	0.46732816	0.058009204	2823.4033
169.61084	0.47000992	0.059082527	2828.627
170.51172	0.47502258	0.060263038	2835.7942
171.4126	0.47665593	0.061405234	2837.293
172.31348	0.47628877	0.062509194	2827.7695
173.21436	0.47961777	0.063581422	2828.6577
174.11523	0.48641908	0.064449616	2839.2656
175.01611	0.48363993	0.065590397	2846.071
175.91699	0.48846349	0.066911787	2840.1648
176.81787	0.49151734	0.068062447	2851.0098
177.71875	0.49720931	0.069262743	2849.095
178.61963	0.4981854	0.070470616	2851.4282
179.52051	0.50212568	0.071519688	2848.6401
180.42139	0.50367481	0.072650425	2853.3203
181.32227	0.50229388	0.073830128	2853.8208
182.22314	0.50779694	0.075219862	2860.2886
183.12402	0.51116532	0.076541178	2864.4893
184.0249	0.51346314	0.077808693	2863.1018
184.92578	0.51782089	0.079051301	2870.7163
185.82666	0.51949525	0.080205061	2862.8406
186.72754	0.52580953	0.081370935	2874.8394
187.62842	0.52749616	0.082779393	2876.8923
188.5293	0.52667886	0.083563104	2873.2766
189.43018	0.52967286	0.085191436	2873.5354
190.33105	0.53035969	0.086439982	2878.8521
191.23193	0.53363317	0.087749436	2880.4946
192.13281	0.53915107	0.089009866	2890.2368
193.03369	0.54063118	0.090231799	2883.6106
193.93457	0.54462302	0.091788344	2890.0232
194.83545	0.54775184	0.092973709	2896.1013
195.73633	0.54733348	0.094493032	2893.4507
196.63721	0.54999006	0.095876038	2896.4897
197.53809	0.55472875	0.097338639	2895.335
198.43896	0.55908221	0.09865921	2900.0491
199.33984	0.55716652	0.099763252	2890.8704
200.24072	0.56218445	0.10105718	2898.5627
201.1416	0.56401366	0.10222609	2895.8569
202.04248	0.5677582	0.10346134	2904.1785
202.94336	0.56911832	0.10495146	2907.4106
203.84424	0.57137674	0.10629113	2900.4211
204.74512	0.57308429	0.10769921	2909.1494
205.646	0.57435989	0.10895933	2904.6506
206.54688	0.58070576	0.11013246	2907.8933
207.44775	0.58289766	0.11126757	2906.9954
208.34863	0.5894385	0.11250474	2919.6531
209.24951	0.5914712	0.11417516	2924.2249
210.15039	0.59242719	0.11577269	2922.2898
211.05127	0.59093028	0.11700093	2911.3352
211.95215	0.59473163	0.11853293	2914.9172
212.85303	0.60269952	0.11981321	2922.0889
213.75391	0.60312057	0.12140308	2924.3076
214.65479	0.60881752	0.12269212	2928.5063
215.55566	0.60701138	0.12388043	2917.8616
216.45654	0.60901564	0.12504932	2922.3923
217.35742	0.61054879	0.12628298	2922.259
218.2583	0.61187953	0.12758675	2928.54
219.15918	0.61740947	0.12924404	2937.6907
220.06006	0.62207931	0.13065007	2929.7913
220.96094	0.62482196	0.13247553	2941.0881
221.86182	0.62477869	0.13351424	2934.6526
222.7627	0.62947845	0.13504212	2933.283
223.66357	0.63248187	0.13653927	2939.8601
224.56445	0.63505554	0.13766491	2935.2131
225.46533	0.63790774	0.13888229	2939.9202
226.36621	0.64174819	0.14004147	2943.2637
227.26709	0.64537638	0.14183633	2953.0747
228.16797	0.64652598	0.14306529	2946.0652
229.06885	0.64789325	0.14431469	2944.592
229.96973	0.65243542	0.14577799	2948.4368
230.87061	0.65422118	0.14738344	2952.3667
231.77148	0.6530714	0.14913556	2951.3691
232.67236	0.65979153	0.15048547	2950.1152
233.57324	0.66518462	0.15165913	2959.0923
234.47412	0.66519344	0.15312739	2959.9304
235.375	0.66750616	0.15445603	2958.5925
236.27588	0.67166251	0.15597689	2959.6765
237.17676	0.6730513	0.15718152	2959.3328
238.07764	0.67365569	0.15862587	2964.739
238.97852	0.67928851	0.16021873	2965.8516
239.87939	0.68607444	0.16155341	2962.3706
240.78027	0.6837008	0.16290201	2965.1902
241.68115	0.68469733	0.16456558	2966.2261
242.58203	0.68764615	0.16585092	2961.1426
243.48291	0.69190246	0.16729692	2966.9297
244.38379	0.69315231	0.16829666	2968.6255
245.28467	0.69758093	0.16992229	2973.0105
246.18555	0.7006129	0.171523	2971.7651
247.08643	0.70131016	0.17266588	2968.0491
247.9873	0.70407826	0.1737977	2963.7207
248.88818	0.70487416	0.17486544	2963.4551
249.78906	0.70815343	0.17607594	2974.7056
250.68994	0.71205264	0.17751376	2974.5227
251.59082	0.71490961	0.1791345	2980.4568
252.4917	0.71819627	0.18049435	2981.1194
253.39258	0.7224108	0.18174925	2979.9846
254.29346	0.72325349	0.18336216	2982.3745
255.19434	0.72870314	0.18464762	2987.4263
256.09521	0.7312327	0.1861033	2989.0479
256.99609	0.73004049	0.18738055	2980.2839
257.89697	0.73574948	0.1887361	2987.8823
258.79785	0.73796284	0.1903546	2992.772
259.69873	0.74262863	0.19179088	2992.1587
260.59961	0.74403477	0.19325313	2996.2915
261.50049	0.74455023	0.19466777	2988.0833
262.40137	0.75096226	0.19594492	2993.7981
263.30225	0.75137627	0.19741669	2996.5413
264.20313	0.7524839	0.19868854	2994.1519
265.104	0.75636971	0.19977203	2992.9377
266.00488	0.75844169	0.20114525	2995.0164
266.90576	0.76282424	0.20244977	2996.4597
267.80664	0.7650401	0.20389338	3000.1055
268.70752	0.77008229	0.20520878	3002.2539
269.6084	0.77102065	0.20692587	3011.2903
270.50928	0.77525032	0.208528	3007.1453
271.41016	0.77344877	0.20967701	3003.7852
272.31104	0.77573329	0.21120028	3005.5718
273.21191	0.78008306	0.21260287	3003.6882
274.11279	0.7820074	0.21377535	3005.532
275.01367	0.78780556	0.21525562	3011.0088
275.91455	0.78989536	0.21665484	3018.3474
276.81543	0.79247284	0.21854141	3017.2612
277.71631	0.79632872	0.21997084	3010.0356
278.61719	0.79550523	0.22128247	3011.0344
279.51807	0.80040354	0.22276863	3017.4412
280.41895	0.80185431	0.22402436	3012.4009
281.31982	0.80284041	0.22524859	3008.1929
282.2207	0.80753529	0.2267154	3020.5845
283.12158	0.81242615	0.2279664	3022.3662
284.02246	0.81264806	0.22918412	3016.6702
284.92334	0.81710726	0.23035023	3022.7446
285.82422	0.81941736	0.2314622	3018.0356
286.7251	0.82405484	0.23270415	3027.5669
287.62598	0.82266569	0.2341612	3021.375
288.52686	0.82723433	0.2356832	3026.0835
289.42773	0.82834154	0.23721485	3027.2939
290.32861	0.83261096	0.23889361	3027.2817
291.22949	0.8358171	0.240328	3028.4565
292.13037	0.84110117	0.24185269	3035.4768
293.03125	0.83783013	0.24351986	3029.4434
293.93213	0.84308302	0.24466789	3028.5
294.83301	0.8456257	0.24586886	3030.2039
295.73389	0.85147041	0.24722593	3036.8225
296.63477	0.8508848	0.24866199	3037.7053
297.53564	0.85136855	0.25000235	3032.3062
298.43652	0.85554862	0.25125086	3036.8884
299.3374	0.8601771	0.25254452	3030.4316
300.23828	0.86307693	0.25374332	3037.6067
301.13916	0.86700666	0.25495696	3043.8823
302.04004	0.86831081	0.25680235	3047.2617
302.94092	0.87116653	0.25824881	3041.7744
303.8418	0.87301272	0.25965065	3043.2939
304.74268	0.87720871	0.26090947	3043.6038
305.64355	0.88037521	0.26214862	3049.9468
306.54443	0.88399005	0.26387581	3055.522
307.44531	0.88401651	0.26525444	3047.3376
308.34619	0.88778359	0.26693934	3057.1121
309.24707	0.89065981	0.26832315	3051.73
310.14795	0.89487785	0.26969299	3057.2224
311.04883	0.89390421	0.2710143	3055.813
311.94971	0.90075588	0.27231678	3055.1343
312.85059	0.89845276	0.27356339	3055.1926
313.75146	0.9047277	0.27512112	3062.0945
314.65234	0.90369016	0.27622539	3048.1677
315.55322	0.90809053	0.27759656	3058.1621
316.4541	0.90846038	0.27886871	3056.158
317.35498	0.9116931	0.28023127	3059.064
318.25586	0.91772151	0.28131607	3058.8914
319.15674	0.91902274	0.28268901	3062.0359
320.05762	0.92178178	0.28432593	3069.1826
320.9585	0.92540056	0.28569824	3058.7471
321.85938	0.92520487	0.28714108	3059.2993
322.76025	0.93238008	0.28851464	3069.7983
323.66113	0.92900532	0.28982466	3063.7043
324.56201	0.93811774	0.29143867	3074.8704
325.46289	0.93600535	0.29272225	3060.8779
326.36377	0.93980294	0.29394439	3067.0916
327.26465	0.94315702	0.2954098	3070.4485
328.16553	0.94606191	0.2967504	3067.6428
329.06641	0.94876111	0.29838145	3083.1484
329.96729	0.94824952	0.29959857	3073.7529
330.86816	0.95517039	0.30111116	3081.1526
331.76904	0.95348847	0.30230844	3064.7354
332.66992	0.95735782	0.30363187	3080.0825
333.5708	0.96035779	0.30515644	3079.5698
334.47168	0.9621346	0.30639288	3078.1475
335.37256	0.96831483	0.30787358	3078.4553
336.27344	0.97261715	0.30912372	3079.1694
337.17432	0.97152835	0.31030387	3078.8213
338.0752	0.97651446	0.31187105	3085.301
338.97607	0.97917128	0.31340235	3088.043
339.87695	0.98221123	0.31504944	3086.9268
340.77783	0.9849965	0.3164756	3089.1975
341.67871	0.98558801	0.3177847	3087.0239
342.57959	0.98708165	0.31916159	3084.1492
343.48047	0.99105459	0.32032564	3085.6702
344.38135	0.99491554	0.32164791	3093.0784
345.28223	0.9991461	0.32318813	3092.5029
346.18311	1.0019367	0.32443416	3096.7683
347.08398	1.0040345	0.32586613	3094.8547
347.98486	1.0030684	0.32717007	3097.9751
348.88574	1.0100429	0.32857928	3096.2729
349.78662	1.0086633	0.32991663	3096.2427
350.6875	1.0134912	0.33131766	3092.0544
351.58838	1.0173311	0.33257294	3098.5088
352.48926	1.0207984	0.33370188	3099.3354
353.39014	1.0249764	0.33505809	3097.3879
354.29102	1.0262076	0.33632237	3103.219
355.19189	1.0269063	0.33765	3098.1028
356.09277	1.0324042	0.33900821	3106.0601
356.99365	1.031354	0.34035286	3095.729
357.89453	1.0376713	0.34174317	3104.3594
358.79541	1.0388422	0.34315684	3105.0745
359.69629	1.0433565	0.34428605	3105.4553
360.59717	1.0459815	0.34575903	3113.2175
361.49805	1.0462614	0.34717402	3112.3403
362.39893	1.0485703	0.3485246	3110.4231
363.2998	1.0537131	0.34999892	3107.5164
364.20068	1.0568175	0.35125685	3113.5713
365.10156	1.0562243	0.35286146	3112.4758
366.00244	1.0619953	0.35434335	3116.7571
366.90332	1.0602202	0.35573062	3110.7139
367.8042	1.0634184	0.35699683	3108.1802
368.70508	1.0691545	0.35824206	3112.7878
369.60596	1.0729368	0.3598482	3121.4966
370.50684	1.0730613	0.3610377	3111.1765
371.40771	1.0774423	0.36250693	3122.5352
372.30859	1.0781214	0.36390924	3125.0781
373.20947	1.0822362	0.3653934	3119.583
374.11035	1.0838712	0.36686018	3117.9189
375.01123	1.0854326	0.36817807	3116.1372
375.91211	1.089506	0.36960417	3122.9133
376.81299	1.08999	0.37109542	3120.4834
377.71387	1.0976613	0.37250149	3124.9839
378.61475	1.1001062	0.37395167	3125.0762
379.51563	1.0996171	0.37510082	3121.5593
380.4165	1.1055309	0.3763518	3124.8552
381.31738	1.1071427	0.37736022	3126.7507
382.21826	1.1064725	0.37873816	3129.873
383.11914	1.1095039	0.3801744	3125.8049
384.02002	1.1143805	0.38165596	3129.1929
384.9209	1.1170263	0.38304931	3133.1284
385.82178	1.1194531	0.38440749	3135.7727
386.72266	1.1228099	0.38575783	3133.1758
387.62354	1.1243057	0.38729939	3132.8831
388.52441	1.1288847	0.38850951	3134.5776
389.42529	1.1272687	0.38977182	3136.8442
390.32617	1.1327493	0.39096427	3131.1069
391.22705	1.1361002	0.3923088	3140.5439
392.12793	1.1398631	0.3938275	3141.2607
393.02881	1.1437386	0.39525685	3140.6946
393.92969	1.1412984	0.3965832	3135.4666
394.83057	1.1455595	0.39784732	3137.4622
395.73145	1.1507801	0.39910784	3141.2441
396.63232	1.1514267	0.40025416	3145.4924
397.5332	1.1524038	0.40190715	3138.5808
398.43408	1.1587365	0.40333977	3144.4507
399.33496	1.1562834	0.40475416	3143.6672
400.23584	1.1604496	0.40635559	3141.0737
401.13672	1.1636821	0.40783471	3143.4678
402.0376	1.1641062	0.40906256	3144.8892
402.93848	1.1685255	0.41050696	3149.4517
403.83936	1.1713545	0.41176692	3151.6311
404.74023	1.1772605	0.41314945	3152.0962
405.64111	1.1782823	0.414345	3140.876
406.54199	1.1796198	0.41536894	3139.4504
407.44287	1.1867028	0.41665825	3151.2473
408.34375	1.1859689	0.41801772	3153.4658
409.24463	1.1874664	0.41952187	3155.5637
410.14551	1.1908809	0.42089573	3152.0791
411.04639	1.1951677	0.42231616	3157.6726
411.94727	1.1970361	0.42384249	3161.6501
412.84814	1.2005496	0.42533734	3154.4287
413.74902	1.2007959	0.42655495	3152.4473
414.6499	1.205336	0.42809939	3160.2444
415.55078	1.2080206	0.42958775	3156.5359
416.45166	1.2094524	0.43101886	3158.4287
417.35254	1.2145774	0.43224442	3162.499
418.25342	1.2162317	0.43344519	3159.3018
419.1543	1.2163799	0.434737	3155.738
420.05518	1.2210727	0.43593943	3161.3469
420.95605	1.2253146	0.43735793	3165.3145
421.85693	1.2273237	0.43876135	3161.6128
422.75781	1.2280165	0.44014508	3166.7271
423.65869	1.2312101	0.44167382	3167.1072
424.55957	1.2332307	0.44273072	3161.9878
425.46045	1.2405792	0.4443025	3175.7515
426.36133	1.2414318	0.44540146	3168.8345
427.26221	1.2423378	0.44679093	3159.6528
428.16309	1.247164	0.44801852	3170.9878
429.06396	1.2483984	0.44951066	3172.844
429.96484	1.2520578	0.45073619	3169.4099
430.86572	1.2556568	0.45212445	3172.7109
431.7666	1.2582566	0.45314768	3169.6345
432.66748	1.2581114	0.45436859	3169.4785
433.56836	1.2639062	0.45561063	3176.3286
434.46924	1.2661377	0.45733944	3182.1289
435.37012	1.2683117	0.45864841	3179.0571
436.271	1.2718569	0.46007374	3177.6987
437.17188	1.2728771	0.46134692	3173.3
438.07275	1.2761364	0.46251276	3181.051
438.97363	1.278155	0.46381584	3178.7092
439.87451	1.280038	0.46519959	3177.168
440.77539	1.2835116	0.46643096	3183.6387
441.67627	1.2837001	0.46797502	3180.3821
442.57715	1.2860301	0.469331	3175.646
443.47803	1.2936083	0.47088382	3187.3608
444.37891	1.2935444	0.47210202	3178.7292
445.27979	1.2977102	0.47369358	3192.0122
446.18066	1.3003293	0.47508362	3184.5916
447.08154	1.3028754	0.47649401	3185.8188
447.98242	1.3078264	0.4776518	3182.7456
448.8833	1.3070402	0.47897416	3189.1863
449.78418	1.3083478	0.48030898	3190.3591
450.68506	1.3151805	0.4820092	3190.4192
451.58594	1.3174849	0.48339397	3190.6563
452.48682	1.3179473	0.48477358	3184.7827
453.3877	1.3209211	0.48611701	3186.8027
454.28857	1.3242072	0.48729923	3187.2439
455.18945	1.3281175	0.48880664	3198.282
456.09033	1.3310127	0.49001944	3194.9504
456.99121	1.3312672	0.49147904	3188.4751
457.89209	1.3361465	0.49284181	3199.4895
458.79297	1.3366517	0.49416873	3193.4856
459.69385	1.3411492	0.4955135	3194.8149
460.59473	1.3433038	0.49698022	3202.7861
461.49561	1.3478358	0.49806628	3197.5962
462.39648	1.3504684	0.4993045	3198.8428
463.29736	1.3511645	0.50065738	3197.9082
464.19824	1.353529	0.50194931	3195.5564
465.09912	1.3571422	0.50321198	3199.1143
466	1.3614787	0.50467187	3204.7041
466.90088	1.3636321	0.50607389	3202.7598
467.80176	1.3677876	0.50731528	3208.0229
468.70264	1.3676105	0.50866795	3200.9731
469.60352	1.3692663	0.5099287	3204.0447
470.50439	1.3761184	0.51129651	3206.2275
471.40527	1.3726779	0.51268417	3209.2717
472.30615	1.3776227	0.51420969	3205.1724
473.20703	1.3821696	0.51573092	3209.9763
474.10791	1.3804891	0.51686931	3201.2515
475.00879	1.3833601	0.51833344	3202.1978
475.90967	1.3874162	0.51960379	3207.1995
476.81055	1.3935677	0.52097625	3210.6882
477.71143	1.3973788	0.52237314	3206.6646
478.6123	1.3996525	0.52345419	3205.302
479.51318	1.4005229	0.52477205	3214.8635
480.41406	1.4009048	0.52616018	3214.519
481.31494	1.4051647	0.52773529	3210.9043
482.21582	1.4085068	0.52924412	3214.8291
483.1167	1.410898	0.53079075	3213.2197
484.01758	1.4127557	0.5322482	3213.929
484.91846	1.416569	0.53362572	3216.2244
485.81934	1.4210794	0.53489792	3220.6394
486.72021	1.4212863	0.53618091	3212.697
487.62109	1.4262092	0.5373739	3222.2852
488.52197	1.4263036	0.5387699	3219.3518
489.42285	1.4289368	0.54017597	3222.2947
490.32373	1.4288672	0.54165763	3217.3003
491.22461	1.4325792	0.54311019	3217.1516
492.12549	1.4405035	0.54455715	3226.8625
493.02637	1.4424046	0.54587829	3228.843
493.92725	1.4440097	0.5475623	3223.0876
494.82813	1.445803	0.54873556	3223.4873
495.729	1.4502563	0.5502615	3222.1885
496.62988	1.4499987	0.55144775	3217.894
497.53076	1.4570308	0.55278724	3223.6272
498.43164	1.4555387	0.55400121	3225.5999
499.33252	1.458681	0.55532008	3229.2307
500.2334	1.4644504	0.55633646	3224.5862
501.13428	1.4654373	0.55726707	3219.1863
502.03516	1.4696859	0.55834764	3226.301
502.93604	1.4700627	0.55979002	3230.7871
503.83691	1.4732749	0.56119865	3232.124
504.73779	1.4774821	0.56272811	3230.6353
505.63867	1.4784404	0.56414968	3232.1729
506.53955	1.4786868	0.56556833	3232.6179
507.44043	1.4839848	0.56691378	3232.7402
508.34131	1.4887118	0.56850499	3236.0259
509.24219	1.4901038	0.57009143	3231.1196
510.14307	1.4918932	0.57142687	3233.2183
511.04395	1.4941081	0.57284588	3231.2576
511.94482	1.5003387	0.57406741	3241.6768
512.8457	1.5006913	0.5755657	3229.3945
513.74658	1.5042723	0.57687902	3238.6841
514.64746	1.5100826	0.57832772	3242.429
515.54834	1.5108018	0.57965976	3240.6494
516.44922	1.5096124	0.58128923	3241.2891
517.3501	1.5141248	0.5828895	3244.1924
518.25098	1.5162655	0.58439064	3238.0364
519.15186	1.5199728	0.58570182	3245.4797
520.05273	1.5221192	0.58724028	3242.5544
520.95361	1.525941	0.58847886	3236.9822
521.85449	1.5262959	0.59000373	3241.3672
522.75537	1.5286301	0.59125918	3241.7959
523.65625	1.5337921	0.59275746	3239.1704
524.55713	1.5369967	0.59385473	3238.5847
525.45801	1.5398667	0.594989	3242.543
526.35889	1.5373932	0.59624785	3243.6389
527.25977	1.5446811	0.597844	3249.5142
528.16064	1.5467732	0.59903795	3245.0349
529.06152	1.5476557	0.6007641	3248.2092
529.9624	1.5507923	0.60237366	3246.6882
530.86328	1.5553724	0.60368901	3244.2632
531.76416	1.5595833	0.60483897	3248.1943
532.66504	1.5592583	0.6063379	3252.8445
533.56592	1.5597847	0.60779011	3245.5808
534.4668	1.5646948	0.60909265	3246.6248
535.36768	1.5675137	0.61047679	3252.0693
536.26855	1.571921	0.61191183	3252.8723
537.16943	1.5721282	0.61327469	3249.3328
538.07031	1.5778401	0.61452097	3250.1738
538.97119	1.5805341	0.61570781	3249.8193
539.87207	1.5792942	0.6168344	3253.8152
540.77295	1.5828588	0.61838531	3258.4836
541.67383	1.5855801	0.61970872	3253.7808
542.57471	1.5888842	0.62104386	3254.3359
543.47559	1.5940285	0.62243068	3252.7986
544.37646	1.5968201	0.62379235	3258.2378
545.27734	1.5973991	0.62501061	3250.3459
546.17822	1.6008343	0.62618643	3255.2144
547.0791	1.6019061	0.62767518	3259.7654
547.97998	1.6053754	0.62916756	3257.0764
548.88086	1.6062667	0.63048559	3258.2107
549.78174	1.6144379	0.6323275	3263.5659
550.68262	1.6152929	0.63345766	3263.0273
551.5835	1.6154683	0.63508195	3264.9592
552.48438	1.618457	0.63674325	3266.2883
553.38525	1.6208444	0.63846189	3261.301
554.28613	1.622965	0.63989091	3262.9167
555.18701	1.626616	0.64120638	3260.3774
556.08789	1.6320699	0.64263934	3263.3604
556.98877	1.6343848	0.64402604	3265.1912
557.88965	1.636472	0.64527667	3263.9656
558.79053	1.6370598	0.64693266	3263.9548
559.69141	1.6397398	0.64827764	3266.9321
560.59229	1.6414858	0.64976513	3260.5464
561.49316	1.6456885	0.65095639	3263.6868
562.39404	1.6463633	0.65223628	3259.0605
563.29492	1.6530627	0.65382737	3267.6086
564.1958	1.6550202	0.6550321	3267.8274
565.09668	1.6558053	0.6565913	3271.4717
565.99756	1.6560096	0.65791261	3262.1592
566.89844	1.6635721	0.65918529	3266.3518
567.79932	1.6670817	0.66061401	3271.5942
568.7002	1.6677504	0.66190183	3269.2817
569.60107	1.668322	0.66308916	3262.365
570.50195	1.6704381	0.66465098	3275.6865
571.40283	1.6769867	0.6659537	3269.55
572.30371	1.6771994	0.66747761	3265.9529
573.20459	1.6844469	0.66883147	3276.3889
574.10547	1.6828486	0.67054677	3273.5256
575.00635	1.6858969	0.67194569	3278.8594
575.90723	1.6910986	0.67342854	3277.76
576.80811	1.6935736	0.67499405	3278.3596
577.70898	1.6930296	0.67627823	3275.5835
578.60986	1.6977588	0.67771149	3279.0374
579.51074	1.6990645	0.67902082	3272.2458
580.41162	1.7019296	0.6804049	3273.2451
581.3125	1.7059599	0.68169773	3276.8301
582.21338	1.7087135	0.68297172	3281.3477
583.11426	1.7122505	0.68459034	3282.7178
584.01514	1.715325	0.68595517	3280.5261
584.91602	1.7196312	0.68720329	3280.2195
585.81689	1.7186583	0.68858707	3279.3311
586.71777	1.7202989	0.69012737	3280.636
587.61865	1.7260766	0.69172609	3289.2314
588.51953	1.7255253	0.69329005	3279.7419
589.42041	1.7308618	0.69454777	3283.3789
590.32129	1.7331464	0.69597423	3287.0391
591.22217	1.7356297	0.69740033	3280.9026
592.12305	1.7374663	0.69883555	3282.0635
593.02393	1.7417161	0.70035213	3285.7781
593.9248	1.7424644	0.70209777	3291.4451
594.82568	1.7456499	0.7037589	3286.7759
595.72656	1.7504059	0.70520687	3284.3682
596.62744	1.7531238	0.70667791	3282.8843
597.52832	1.7535785	0.70800751	3287.564
598.4292	1.7547832	0.70945686	3286.2178
599.33008	1.7601354	0.71091241	3281.8643
600.23096	1.7639707	0.7122609	3289.6992
601.13184	1.7610961	0.71346605	3279.5164
602.03271	1.7664894	0.71491766	3290.083
602.93359	1.7729739	0.71628058	3293.9878
603.83447	1.7709193	0.71773779	3288.9055
604.73535	1.7724812	0.71921116	3290.0002
605.63623	1.7790827	0.72065431	3282.0276
606.53711	1.7802628	0.72209162	3291.584
607.43799	1.7828772	0.72330731	3288.9331
608.33887	1.7849545	0.72468871	3287.3098
609.23975	1.788891	0.72608221	3288.9585
610.14063	1.794506	0.72762918	3296.9287
611.0415	1.7951329	0.72909397	3295.7778
611.94238	1.7969226	0.73067373	3293.2463
612.84326	1.8000352	0.73217732	3297.5232
613.74414	1.8054693	0.73366565	3295.5002
614.64502	1.8059331	0.73508596	3291.2341
615.5459	1.8087759	0.73643208	3293.8293
616.44678	1.8103137	0.73803449	3296.0996
617.34766	1.8125561	0.7393505	3289.9922
618.24854	1.8167675	0.74106473	3302.2107
619.14941	1.8200041	0.74256611	3293.603
620.05029	1.8220034	0.74414045	3296.9629
620.95117	1.8239996	0.74561834	3302.4988
621.85205	1.8297738	0.74718618	3301.7498
622.75293	1.8310264	0.74864012	3298.333
623.65381	1.8339757	0.75088412	3313.5176
624.55469	1.8330954	0.75267571	3300.6597
625.45557	1.8405178	0.7543534	3297.6267
626.35645	1.8435142	0.75567073	3298.8367
627.25732	1.8445895	0.75689679	3303.0596
628.1582	1.8466681	0.75822413	3297.77
629.05908	1.8502747	0.7597031	3304.5464
629.95996	1.8502082	0.7613104	3301.9189
630.86084	1.8544682	0.76289594	3302.657
631.76172	1.8546371	0.76433641	3301.0754
632.6626	1.8611854	0.76590002	3308.9482
633.56348	1.8614607	0.76726091	3298.1665
634.46436	1.8649675	0.76859039	3299.8025
635.36523	1.8663501	0.76998466	3297.9275
636.26611	1.8689213	0.77147669	3304.0269
637.16699	1.8769743	0.77315891	3304.3333
638.06787	1.873011	0.77443117	3298.2737
638.96875	1.8796364	0.77578282	3297.7144
639.86963	1.8831776	0.77736574	3306.4619
640.77051	1.8832768	0.77867788	3305.7002
641.67139	1.886699	0.78047633	3310.9114
642.57227	1.8883147	0.78222716	3304.54
643.47314	1.8900465	0.78369963	3306.6802
644.37402	1.8931466	0.78520411	3303.9956
645.2749	1.8973897	0.78652656	3307.1665
646.17578	1.8992887	0.78819591	3310.627
647.07666	1.9056181	0.78971583	3315.0559
647.97754	1.9085627	0.79151332	3311.6526
648.87842	1.9096146	0.79323965	3311.1816
649.7793	1.9135667	0.79472101	3311.6709
650.68018	1.9140987	0.79614937	3299.7842
651.58105	1.9194243	0.79744834	3308.7136
652.48193	1.918663	0.79884577	3306.5696
653.38281	1.9229251	0.80023241	3309.6611
654.28369	1.9255779	0.80163336	3310.1409
655.18457	1.9269842	0.8030445	3309.759
656.08545	1.9276206	0.80446517	3312.4099
656.98633	1.9327241	0.80611366	3319.0237
657.88721	1.9390079	0.80800116	3314.4854
658.78809	1.9365953	0.80976725	3312.636
659.68896	1.9408804	0.81158823	3318.1494
660.58984	1.943356	0.81343323	3311.4773
661.49072	1.9468225	0.81489825	3309.1975
662.3916	1.9472454	0.81613696	3302.0151
663.29248	1.9525287	0.81751424	3315.4536
664.19336	1.9560995	0.81913131	3318.2007
665.09424	1.9559909	0.82073581	3314.4089
665.99512	1.9609674	0.82247388	3324.3599
666.896	1.9594871	0.82417816	3313.6924
667.79688	1.9672552	0.82576519	3316.887
668.69775	1.9694322	0.82745141	3317.6335
669.59863	1.9712969	0.82899779	3313.5715
670.49951	1.972196	0.83042634	3313.8115
671.40039	1.9753201	0.8320865	3317.0708
672.30127	1.9809084	0.83356071	3317.1609
673.20215	1.9812989	0.83527976	3315.7734
674.10303	1.9827209	0.83682811	3320.3293
675.00391	1.9916936	0.83854246	3327.3496
675.90479	1.9907591	0.84033287	3318.5972
676.80566	1.9938474	0.84189522	3319.2817
677.70654	1.9950275	0.84370947	3321.4612
678.60742	1.9964184	0.8451007	3310.9749
679.5083	2.0005639	0.84689796	3321.9907
680.40918	2.0036187	0.84840697	3317.3906
681.31006	2.0059142	0.84967285	3319.3984
682.21094	2.0100739	0.85134935	3324.7231
683.11182	2.0091596	0.85272878	3317.0051
684.0127	2.0082803	0.85410219	3308.511
684.91357	2.0154984	0.85590297	3322.1174
685.81445	2.0190203	0.85764658	3323.011
686.71533	2.0245287	0.85947365	3322.8611
687.61621	2.0240319	0.8608923	3312.9106
688.51709	2.0266385	0.86243439	3323.0522
689.41797	2.0287066	0.86398774	3321.4934
690.31885	2.0317748	0.8655172	3321.2271
691.21973	2.035569	0.86706018	3319.7971
692.12061	2.0404184	0.86869138	3325.6094
693.02148	2.0394478	0.87043256	3324.1655
693.92236	2.0416846	0.87214315	3324.0396
694.82324	2.045754	0.87391287	3320.9758
695.72412	2.0482333	0.8755703	3320.6213
696.625	2.0503168	0.8773284	3323.1252
697.52588	2.054559	0.87919617	3322.0776
698.42676	2.0585322	0.88095725	3323.4075
699.32764	2.0597017	0.88234049	3321.1868
700.22852	2.0619996	0.88426304	3323.5105
701.12939	2.0664589	0.88576245	3324.7058
702.03027	2.066895	0.88742018	3325.2031
702.93115	2.0705504	0.88901764	3327.8115
703.83203	2.0713058	0.89062178	3325.7209
704.73291	2.0752807	0.8924827	3324.5029
705.63379	2.0785718	0.89406329	3329.4553
706.53467	2.0818801	0.89569187	3334.095
707.43555	2.0867002	0.89731783	3326.4343
708.33643	2.0850506	0.89881444	3323.9324
709.2373	2.0882506	0.90077525	3333.0061
710.13818	2.0909457	0.90246254	3323.4668
711.03906	2.0958092	0.90426332	3328.3596
711.93994	2.0985162	0.90597653	3327.261
712.84082	2.0989375	0.90750867	3324.1125
713.7417	2.1054771	0.90902537	3323.469
714.64258	2.1054246	0.91018927	3321.1035
715.54346	2.1071374	0.91171777	3328.8628
716.44434	2.1119442	0.91368824	3335.9922
717.34521	2.1114435	0.91511154	3325.2576
718.24609	2.1174719	0.91710705	3328.6992
719.14697	2.1183524	0.91866696	3319.5696
720.04785	2.1228178	0.92009395	3322.7104
720.94873	2.1252244	0.92176563	3328.5537
721.84961	2.1272695	0.92346573	3330.4956
722.75049	2.1336179	0.92531335	3335.8025
723.65137	2.1331713	0.92703611	3332.25
724.55225	2.1354589	0.92906654	3334.5989
725.45313	2.1363232	0.93108135	3337.7217
726.354	2.1423774	0.93289858	3328.5757
727.25488	2.1457133	0.93456244	3328.2993
728.15576	2.1455505	0.9360922	3330.0146
729.05664	2.1481616	0.93733186	3325.7346
729.95752	2.1508842	0.93900025	3333.5547
730.8584	2.1568038	0.94075912	3336.3245
731.75928	2.1560428	0.9431107	3334.7444
732.66016	2.1611278	0.94499445	3333.0835
733.56104	2.1604702	0.94685477	3327.1533
734.46191	2.1646371	0.94872099	3330.6326
735.36279	2.1652474	0.95033956	3331.7346
736.26367	2.1709385	0.95230174	3332.8982
737.16455	2.1713991	0.95424032	3329.6189
738.06543	2.1737812	0.95629781	3329.6633
738.96631	2.1787496	0.95837152	3338.9309
739.86719	2.1791332	0.95998013	3324.9192
740.76807	2.1824672	0.9616552	3331.6428
741.66895	2.1875482	0.96345079	3331.2612
742.56982	2.1898634	0.96542358	3329.4226
743.4707	2.1943488	0.967143	3332.6091
744.37158	2.1957977	0.9686076	3328.2407
745.27246	2.1962922	0.97034043	3332.2261
746.17334	2.2013369	0.97196901	3335.7817
747.07422	2.2048266	0.97361577	3331.8499
747.9751	2.2061794	0.97533596	3327.0212
748.87598	2.2064183	0.976924	3326.2888
749.77686	2.214138	0.97855079	3330.3735
750.67773	2.2126594	0.98029035	3332.0139
751.57861	2.216543	0.98198366	3330.8276
752.47949	2.2175536	0.98424542	3341.426
753.38037	2.2214336	0.98616558	3327.3052
754.28125	2.22404	0.98803431	3331.9897
755.18213	2.2280359	0.98977596	3331.2649
756.08301	2.2284424	0.99160486	3326.8657
756.98389	2.2336493	0.99341923	3336.0308
757.88477	2.2362788	0.99518472	3332.9189
758.78564	2.2398539	0.99721164	3333.9546
759.68652	2.2431641	0.99918669	3336.291
760.5874	2.2442536	1.0007876	3327.4856
761.48828	2.2485266	1.0026761	3338.689
762.38916	2.2503691	1.0043448	3333.9397
763.29004	2.2526646	1.0064861	3337.5674
764.19092	2.2540948	1.0086359	3336.4148
765.0918	2.2583234	1.0105004	3327.6626
765.99268	2.260051	1.0122812	3331.6787
766.89355	2.2625599	1.0145087	3338.9268
767.79443	2.267072	1.0169585	3335.9207
768.69531	2.2678626	1.0188744	3333.1248
769.59619	2.270328	1.0208704	3334.0454
770.49707	2.2729111	1.0228294	3329.0249
771.39795	2.2762718	1.0247346	3327.4148
772.29883	2.2767034	1.0268683	3330.3535
773.19971	2.2818124	1.0284321	3329.2219
774.10059	2.2859879	1.0303056	3331.3503
775.00146	2.2883279	1.0321099	3333.5972
775.90234	2.2893779	1.0336747	3330.1682
776.80322	2.2916148	1.0358062	3334.0779
777.7041	2.296839	1.0378323	3336.4292
778.60498	2.2972195	1.0396755	3333.7124
779.50586	2.3003032	1.0415978	3333.7795
780.40674	2.3027129	1.0437951	3333.252
781.30762	2.3046358	1.0458541	3330.3794
782.2085	2.3065903	1.047804	3328.05
783.10938	2.310674	1.0495642	3337.7017
784.01025	2.3140559	1.0516374	3330.3909
784.91113	2.3169611	1.0532904	3328.5032
785.81201	2.322032	1.0550921	3333.9734
786.71289	2.3215964	1.0570738	3338.3035
787.61377	2.3248234	1.0593046	3331.6699
788.51465	2.3258312	1.0613496	3336.4912
789.41553	2.3286204	1.0633745	3327.7134
790.31641	2.3319461	1.0651746	3328.1572
791.21729	2.3342016	1.0670151	3330.76
792.11816	2.3373735	1.0690944	3335.9001
793.01904	2.3400745	1.0712527	3329.2
793.91992	2.3440359	1.0732371	3335.251
794.8208	2.345907	1.0756149	3329.7859
795.72168	2.3463535	1.0776938	3330.8445
796.62256	2.3532078	1.0796878	3331.104
797.52344	2.3545711	1.0817467	3334.7534
798.42432	2.3537045	1.0837588	3325.7104
799.3252	2.3603604	1.0860189	3333.3911
800.22607	2.362474	1.0877806	3324.6946
801.12695	2.3635845	1.0894957	3326.0776
802.02783	2.3662615	1.0915467	3326.8579
802.92871	2.3705697	1.0936544	3329.1697
803.82959	2.3708429	1.0957999	3326.9329
804.73047	2.3751156	1.0978986	3335.3752
805.63135	2.3793325	1.1001135	3329.3186
806.53223	2.3819854	1.1022525	3330.3193
807.43311	2.3845909	1.1046309	3333.2263
808.33398	2.3864126	1.1067293	3323.4856
809.23486	2.3895013	1.109054	3332.8115
810.13574	2.3920996	1.1109011	3330.6882
811.03662	2.394011	1.1132655	3329.2029
811.9375	2.3985438	1.1152812	3327.3503
812.83838	2.3989415	1.1174448	3331.2954
813.73926	2.4026482	1.1195976	3331.886
814.64014	2.4073472	1.1215584	3328.7786
815.54102	2.40888	1.1237371	3328.675
816.44189	2.4100108	1.1259266	3326.8416
817.34277	2.4146855	1.1282674	3330.1001
818.24365	2.4157746	1.1305398	3327.804
819.14453	2.4171185	1.1328406	3323.9985
820.04541	2.4248161	1.1349202	3324.5632
820.94629	2.4258392	1.1369971	3324.9443
821.84717	2.4298582	1.1393217	3330.5525
822.74805	2.4279757	1.1413755	3320.041
823.64893	2.4354663	1.1433753	3323.3906
824.5498	2.437542	1.1454537	3326.5359
825.45068	2.4345312	1.1475699	3326.4717
826.35156	2.441478	1.1499854	3326.3486
827.25244	2.4408391	1.1521626	3321.4846
828.15332	2.4455202	1.1544288	3324.5281
829.0542	2.4480915	1.1567123	3320.5208
829.95508	2.4548168	1.1589677	3326.8206
830.85596	2.4555311	1.1610234	3319.6506
831.75684	2.4564481	1.1632395	3323.8755
832.65771	2.4583986	1.1651393	3318.5356
833.55859	2.4634521	1.1672635	3320.0198
834.45947	2.4645662	1.1697321	3327.5322
835.36035	2.4640305	1.1719835	3316.0603
836.26123	2.4717088	1.1742449	3324.0735
837.16211	2.4737482	1.1766791	3315.6089
838.06299	2.4774709	1.1793456	3325.6675
838.96387	2.4778762	1.181555	3320.2441
839.86475	2.4814582	1.1839752	3317.5913
840.76563	2.4836547	1.1861485	3318.4265
841.6665	2.4849851	1.1885618	3318.0667
842.56738	2.489753	1.1909101	3314.3174
843.46826	2.492487	1.1935403	3319.6338
844.36914	2.4958873	1.1960758	3317.311
845.27002	2.4968476	1.1983927	3313.8821
846.1709	2.4994638	1.2010885	3320.6714
847.07178	2.505882	1.2038392	3322.397
847.97266	2.5061502	1.2056863	3311.9424
848.87354	2.5075715	1.2074926	3308.4258
849.77441	2.5102415	1.2094631	3311.5115
850.67529	2.5130334	1.2117263	3312.0674
851.57617	2.5158033	1.2141831	3312.0391
852.47705	2.5195501	1.2162625	3306.9233
853.37793	2.5225894	1.2184851	3307.5398
854.27881	2.5254145	1.2205908	3311.7102
855.17969	2.5294652	1.2232112	3317.3569
856.08057	2.5310552	1.2255439	3313.3401
856.98145	2.5326881	1.2280343	3315.4446
857.88232	2.5324597	1.2306466	3304.2229
858.7832	2.5395265	1.2328985	3309.7905
859.68408	2.5395596	1.2350374	3300.1433
860.58496	2.5426285	1.2371066	3308.9417
861.48584	2.5459199	1.2397879	3311.4709
862.38672	2.5485575	1.2425627	3310.5107
863.2876	2.548991	1.2451378	3305.9314
864.18848	2.5547538	1.2477523	3308.5298
865.08936	2.5573025	1.2503566	3303.0752
865.99023	2.5608902	1.252419	3301.6895
866.89111	2.5643458	1.2546494	3305.4854
867.79199	2.5649021	1.2567716	3298.218
868.69287	2.5660832	1.259137	3300.8342
869.59375	2.5721343	1.2615193	3305.5239
870.49463	2.5737729	1.2638713	3304.7334
871.39551	2.5757136	1.2664349	3307.6086
872.29639	2.5783355	1.2687098	3300.0015
873.19727	2.5822921	1.2713146	3303.4519
874.09814	2.5813475	1.2737101	3300.5002
874.99902	2.5868247	1.2762175	3302.7856
875.8999	2.5892525	1.2789495	3299.1018
876.80078	2.5923624	1.281785	3296.4739
877.70166	2.594259	1.284351	3298.0586
878.60254	2.5972161	1.2871162	3292.925
879.50342	2.599618	1.2892941	3290.2981
880.4043	2.603379	1.2914541	3290.4277
881.30518	2.609241	1.2935797	3300.4631
882.20605	2.6076026	1.2959329	3292.6257
883.10693	2.6137664	1.29863	3292.7056
884.00781	2.6107197	1.3016564	3295.3269
884.90869	2.618223	1.3045263	3289.468
885.80957	2.6194839	1.3068192	3284.229
886.71045	2.6233768	1.3092344	3291.0635
887.61133	2.622674	1.3118125	3293.541
888.51221	2.6278627	1.3147149	3288.8132
889.41309	2.6288934	1.3172181	3282.9978
890.31396	2.6309648	1.3195245	3277.4172
891.21484	2.635103	1.3218081	3280.6841
892.11572	2.6392756	1.3242767	3290.9983
893.0166	2.6433389	1.3269842	3286.9683
893.91748	2.6415696	1.3298274	3282.7769
894.81836	2.6459084	1.3326874	3282.6045
895.71924	2.6507308	1.3349901	3278.8596
896.62012	2.6522386	1.3373336	3279.031
897.521	2.6546226	1.3395152	3275.9629
898.42188	2.6570263	1.341557	3274.5107
899.32275	2.6612599	1.3440171	3280.3713
900.22363	2.6634831	1.3468115	3280.1157
901.12451	2.6650405	1.3493183	3273.8921
902.02539	2.6661043	1.3517684	3264.4739
902.92627	2.6748333	1.3542465	3273.5906
903.82715	2.6743095	1.3572425	3273.8567
904.72803	2.6743052	1.360297	3270.0049
905.62891	2.6808226	1.3629533	3267.502
906.52979	2.6827695	1.3652778	3266.8345
907.43066	2.6831007	1.3681115	3264.2241
908.33154	2.6850328	1.3708239	3265.3306
909.23242	2.6883292	1.373799	3266.4839
910.1333	2.6920743	1.3771617	3261.073
911.03418	2.6915047	1.3801368	3259.8762
911.93506	2.6996193	1.3830789	3260.2388
912.83594	2.6998026	1.3853467	3256.8772
913.73682	2.7036307	1.387988	3258.3049
914.6377	2.7066927	1.3905509	3257.5933
915.53857	2.7096574	1.3929712	3257.2878
916.43945	2.7117362	1.3957138	3251.4133
917.34033	2.7142677	1.3981907	3256.2849
918.24121	2.7167244	1.4009315	3251.666
919.14209	2.7199242	1.4036764	3249.967
920.04297	2.7227867	1.406251	3250.4929
920.94385	2.7223158	1.4086281	3245.0591
921.84473	2.7274354	1.4107168	3248.3679
922.74561	2.7309332	1.4134394	3247.2793
923.64648	2.733727	1.4159111	3241.9077
924.54736	2.7337945	1.4185115	3244.2156
925.44824	2.7384725	1.4216104	3243.9524
926.34912	2.7402713	1.4246298	3237.7969
927.25	2.7437255	1.4279621	3239.8604
928.15088	2.7435155	1.4305965	3236.7173
929.05176	2.7489009	1.4332986	3235.1826
929.95264	2.7538676	1.4363449	3235.2988
930.85352	2.7553349	1.4389309	3231.262
931.75439	2.7577803	1.4411874	3227.822
932.65527	2.7600451	1.4436483	3224.7122
933.55615	2.7658885	1.4462049	3231.5762
934.45703	2.7669871	1.4490662	3228.0688
935.35791	2.7657506	1.4514924	3223.6396
936.25879	2.7731366	1.4543282	3228.1528
937.15967	2.7734861	1.4570304	3223.7944
938.06055	2.7758911	1.4598416	3222.5122
938.96143	2.778007	1.4626982	3221.3755
939.8623	2.7810984	1.4656423	3219.9836
940.76318	2.7848618	1.468279	3222.2954
941.66406	2.785491	1.4712999	3214.0747
942.56494	2.7920012	1.4735749	3212.1826
943.46582	2.7918708	1.476588	3214.0627
944.3667	2.7946527	1.4790941	3208.613
945.26758	2.7975869	1.4818439	3208.5779
946.16846	2.8024533	1.4845306	3213.8975
947.06934	2.8029685	1.4870472	3200.3147
947.97021	2.8079634	1.4899639	3206.231
948.87109	2.812777	1.4929447	3203.8904
949.77197	2.8144984	1.4955332	3201.4526
950.67285	2.8126059	1.4981952	3195.1348
951.57373	2.8187675	1.5007517	3199.0623
952.47461	2.8177931	1.503691	3194.6277
953.37549	2.8225729	1.5067425	3191.78
954.27637	2.8268561	1.5095351	3188.3877
955.17725	2.8253298	1.5123417	3190.2151
956.07813	2.830605	1.5150753	3186.2234
956.979	2.8322356	1.5176091	3182.9568
957.87988	2.8369246	1.5204864	3187.6421
958.78076	2.8392913	1.5233409	3181.4148
959.68164	2.839355	1.5262024	3178.708
960.58252	2.8465736	1.5290198	3182.2981
961.4834	2.8453081	1.5321214	3181.009
962.38428	2.8490348	1.5352393	3179.6257
963.28516	2.8535612	1.5376579	3167.6265
964.18604	2.8546429	1.5401407	3163.3079
965.08691	2.8564529	1.5427334	3165.666
965.98779	2.8612936	1.5453075	3162.8105
966.88867	2.8635728	1.547586	3166.1187
967.78955	2.8637943	1.5505466	3165.2522
968.69043	2.8675809	1.5532924	3158.4688
969.59131	2.8723102	1.5563648	3160.1682
970.49219	2.8722413	1.559317	3154.8408
971.39307	2.8766079	1.5621893	3153.9146
972.29395	2.878876	1.5647392	3153.1213
973.19482	2.8820858	1.5672445	3150.2673
974.0957	2.8839443	1.5693488	3147.6008
974.99658	2.8868191	1.5726463	3151.7583
975.89746	2.8906028	1.5757279	3149.1965
976.79834	2.8907373	1.5786985	3144.0635
977.69922	2.8954093	1.58172	3137.4155
978.6001	2.8978186	1.584473	3137.5728
979.50098	2.9015508	1.5871359	3138.3794
980.40186	2.9020653	1.589875	3130.6755
981.30273	2.9072325	1.5925715	3127.8225
982.20361	2.9095354	1.5953636	3130.7498
983.10449	2.9110844	1.5985689	3131.439
984.00537	2.9136894	1.6021359	3120.0112
984.90625	2.9159768	1.6050173	3120.8237
985.80713	2.9211304	1.6078593	3119.98
986.70801	2.9250593	1.6108032	3125.1396
987.60889	2.9249017	1.6136196	3110.4807
988.50977	2.9266658	1.6164167	3104.9812
989.41064	2.929493	1.6191181	3111.0259
990.31152	2.9295683	1.6221335	3106.9338
991.2124	2.9339101	1.6260468	3104.8831
992.11328	2.9388044	1.6285993	3092.0398
993.01416	2.9418197	1.6313361	3097.1248
993.91504	2.9459651	1.6343999	3098.0696
994.81592	2.9479904	1.6372435	3094.3716
995.7168	2.951663	1.6402048	3092.158
996.61768	2.9524577	1.6432953	3089.1658
997.51855	2.9562073	1.646037	3082.5076
998.41943	2.9591677	1.6484209	3080.7454
999.32031	2.9585953	1.6505015	3073.6125
1000.2212	2.9626799	1.6525624	3071.8022
1001.1221	2.9638176	1.6549059	3075.3538
1002.0229	2.9659667	1.6576068	3071.843
1002.9238	2.9723418	1.6607507	3070.4709
1003.8247	2.9739521	1.6642065	3074.8286
1004.7256	2.9746993	1.6672871	3065.1223
1005.6265	2.9785144	1.6708372	3061.1426
1006.5273	2.9818995	1.673678	3056.7188
1007.4282	2.9862592	1.6766201	3057.5112
1008.3291	2.98632	1.6802531	3055.0625
1009.23	2.9907293	1.683141	3048.467
1010.1309	2.9928737	1.6855595	3041.6072
1011.0317	2.9943748	1.6873717	3031.1538
1011.9326	2.9985874	1.6893512	3043.7188
1012.8335	3.0001545	1.6912442	3038.124
1013.7344	3.0032282	1.6932839	3034.2471
1014.6353	3.002928	1.6956123	3038.7583
1015.5361	3.007776	1.6985612	3040.2776
1016.437	3.0152233	1.701571	3040.4868
1017.3379	3.0146325	1.7044034	3031.5569
1018.2388	3.0147476	1.7077217	3029.3215
1019.1396	3.0205469	1.711205	3024.3345
1020.0405	3.0231907	1.7144243	3015.9736
1020.9414	3.0210834	1.7170544	3015.8086
1021.8423	3.0288038	1.720775	3019.6978
1022.7432	3.0309718	1.7240834	3011.1194
1023.644	3.0318041	1.7267879	3003.3042
1024.5449	3.0380259	1.7299353	3006.4438
1025.4458	3.0383844	1.7326378	2998.4729
1026.3467	3.0407231	1.735221	2992.3367
1027.2476	3.0438807	1.7380618	2992.2571
1028.1484	3.0453131	1.7410791	2992.0254
1029.0493	3.0480921	1.7451044	2988.2083
1029.9502	3.0541422	1.7484258	2984.3767
1030.8511	3.0542119	1.7514677	2980.9358
1031.752	3.0563765	1.7541162	2972.9888
1032.6528	3.0586102	1.7569305	2969.2651
1033.5537	3.0630312	1.7596492	2967.1689
1034.4546	3.0635304	1.7622964	2960.4836
1035.3555	3.0659282	1.7652031	2967.054
1036.2563	3.0725243	1.7685196	2957.7935
1037.1572	3.0755904	1.7708362	2955.5449
1038.0581	3.0757732	1.7734004	2950.4795
1038.959	3.0808475	1.776397	2960.4746
1039.8599	3.0810218	1.7797678	2948.0981
1040.7607	3.0846112	1.7829429	2938.9905
1041.6616	3.089236	1.7856262	2934.3364
1042.5625	3.0904896	1.7881602	2934.9836
1043.4634	3.0929995	1.7908089	2933.6953
1044.3643	3.0937519	1.794312	2936.8877
1045.2651	3.0971835	1.7977242	2930.8323
1046.166	3.1002386	1.8008325	2924.9294
1047.0669	3.1044307	1.8040272	2917.3228
1047.9678	3.1067739	1.8068466	2912.5381
1048.8687	3.1079292	1.8100227	2907.7913
1049.7695	3.1140475	1.8131193	2906.0957
1050.6704	3.1150584	1.8159908	2896.5435
1051.5713	3.1162186	1.8189209	2894.6772
1052.4722	3.11759	1.8216206	2891.2405
1053.373	3.1214757	1.8250564	2892.324
1054.2739	3.1244111	1.8288834	2883.0505
1055.1748	3.1294394	1.83201	2882.2639
1056.0757	3.1322572	1.8350517	2875.991
1056.9766	3.1313875	1.8377663	2868.1819
1057.8774	3.1371202	1.8401617	2866.5837
1058.7783	3.1387863	1.8431499	2864.6316
1059.6792	3.1429868	1.8463579	2858.4688
1060.5801	3.1440623	1.8493952	2860.8992
1061.481	3.1456101	1.8524083	2850.4915
1062.3818	3.1477337	1.8558307	2848.8716
1063.2827	3.1516581	1.8588058	2840.6628
1064.1836	3.1556857	1.8616343	2837.6755
1065.0845	3.1569347	1.8646969	2836.3743
1065.9854	3.1622202	1.8681738	2838.3325
1066.8862	3.1645043	1.8711897	2827.2092
1067.7871	3.1661367	1.8745371	2823.0984
1068.688	3.1701853	1.8773173	2815.5327
1069.5889	3.1695619	1.8804531	2808.7961
1070.4897	3.1736507	1.8830075	2801.9585
1071.3906	3.1737578	1.8859098	2801.2329
1072.2915	3.1789706	1.889249	2804.3279
1073.1924	3.1831241	1.8930703	2794.9924
1074.0933	3.1858299	1.8963898	2788.0183
1074.9941	3.1886425	1.8992563	2785.7153
1075.895	3.1917875	1.9023527	2782.6748
1076.7959	3.1945846	1.906136	2780.9951
1077.6968	3.1942577	1.9093158	2764.4939
1078.5977	3.1989751	1.912855	2763.8708
1079.4985	3.20297	1.9154299	2754.9778
1080.3994	3.2039683	1.9179959	2756.1814
1081.3003	3.2070456	1.9209797	2750.2886
1082.2012	3.2088034	1.9238524	2744.7637
1083.1021	3.2110076	1.9267548	2737.1604
1084.0029	3.21205	1.9298642	2731.6716
1084.9038	3.2189291	1.9334737	2731.1162
1085.8047	3.2176709	1.9371487	2718.6125
1086.7056	3.2247493	1.9397686	2704.9219
1087.6064	3.2242596	1.9423674	2712.4277
1088.5073	3.226908	1.9453729	2705.8323
1089.4082	3.2322426	1.948975	2703.9656
1090.3091	3.2341075	1.953478	2692.7722
1091.21	3.238425	1.9569318	2684.4263
1092.1108	3.2359176	1.9601101	2676.9678
1093.0117	3.2446675	1.9634806	2674.686
1093.9126	3.2415025	1.967137	2668.8315
1094.8135	3.2482843	1.9701949	2660.3679
1095.7144	3.2507772	1.9733132	2660.0029
1096.6152	3.2529249	1.9769346	2649.5015
1097.5161	3.2543485	1.9805003	2633.4458
1098.417	3.2580144	1.9829121	2631.2517
1099.3179	3.2632129	1.985988	2629.4453
1100.2188	3.2636073	1.9884628	2619.105
1101.1196	3.2667775	1.9924175	2623.7246
1102.0205	3.2679355	1.9959366	2605.5073
1102.9214	3.2724338	1.9994497	2599.7319
1103.8223	3.2750638	2.0029294	2586.1704
1104.7231	3.2787559	2.0059803	2586.5747
1105.624	3.2803712	2.0095274	2583.6904
1106.5249	3.2817733	2.0124638	2571.0015
1107.4258	3.2854829	2.0159009	2557.4492
1108.3267	3.2896342	2.0198627	2551.9128
1109.2275	3.2922814	2.0242474	2541.2273
1109.9282	3.2943916	2.0280466	2514.7695