File: datasets/am_bench_2022/raw_data/45-XY.08-2/specimen.dat
MTS793|MPT|ENU|1|2|.|/|:|1|0|0|A

Operator Information						Time:	25.736084	Sec	10/19/2021 12:51:22 PM
Operator	Newell Moser
Project	AM Bench 2022 mini-tensile challenge
Specimen ID	45-XY.08-2
Material	PBF-L Inconel 625
Specimen Width	2.55	mm
Specimen Thickness	1.49	mm
Notes
Operator Information End

Data Acquisition						Time:	1026.7307	Sec	10/19/2021 1:08:03 PM
Time	Axial Displacement	Axial Extensometer	Axial Force
Sec	mm	mm	N
25.850586	-0.0028486468	-0.0057615885	76.741333
26.851563	0.0012632589	-0.0056890459	87.278343
27.852539	-0.0011608062	-0.0056820386	96.74794
28.853516	0.0059269359	-0.0055302605	116.41142
29.854492	0.0063426597	-0.0054887058	127.19578
30.855469	0.0078289388	-0.0054489085	140.9915
31.856445	0.012771626	-0.0054197814	152.2916
32.857422	0.017049083	-0.0053877896	168.64674
33.858398	0.018912157	-0.0052908566	186.7957
34.859375	0.019193267	-0.0052137165	206.3063
35.860352	0.024147479	-0.0051729074	226.2065
36.861328	0.027298857	-0.005010745	252.3401
37.862305	0.031795137	-0.0048842519	265.80713
38.863281	0.032930642	-0.0047938055	291.83728
39.864258	0.035839837	-0.0047179754	311.87854
40.865234	0.040141065	-0.0046001691	330.6142
41.866211	0.042863194	-0.0045689284	351.18811
42.867188	0.043923505	-0.0044380045	367.83273
43.868164	0.045246281	-0.0043557212	388.74951
44.869141	0.052533329	-0.004266066	411.05643
45.870117	0.055923201	-0.0041920841	435.63513
46.871094	0.057187174	-0.0040087095	458.89221
47.87207	0.059971437	-0.003926991	485.13098
48.873047	0.063944012	-0.0037939243	509.11801
49.874023	0.065964602	-0.003711428	523.95953
50.875	0.071341708	-0.0036198264	558.24219
51.875977	0.071742475	-0.0034865141	583.46771
52.876953	0.075590938	-0.0034182814	609.08051
53.87793	0.076753236	-0.0033945551	631.01727
54.878906	0.077935047	-0.0032612591	653.52399
55.879883	0.083193883	-0.0031254748	679.78015
56.880859	0.086180374	-0.0029697064	704.67468
57.881836	0.090436317	-0.0027706774	737.26855
58.882813	0.090353951	-0.0027477059	756.74963
59.883789	0.096929409	-0.0025776476	789.53699
60.884766	0.097641408	-0.0025276102	813.49152
61.885742	0.10018595	-0.002306924	841.45746
62.886719	0.10443288	-0.0022558416	870.30786
63.887695	0.10664606	-0.0022081153	901.33435
64.888672	0.11195842	-0.0020428514	925.67682
65.889648	0.11378482	-0.0019727591	958.091
66.890625	0.11612544	-0.0017124565	983.84552
67.891602	0.11743162	-0.0016537808	1009.9813
68.892578	0.12612689	-0.0014756056	1040.3009
69.893555	0.1253731	-0.0013706	1072.4242
70.894531	0.12885173	-0.0012299024	1104.8086
71.895508	0.13188939	-0.0010564161	1133.3671
72.896484	0.1337897	-0.00094002677	1160.6348
73.897461	0.13871154	-0.00078307412	1186.0569
74.898438	0.13878326	-0.00067949051	1208.5548
75.899414	0.14281777	-0.00056324457	1241.8958
76.900391	0.14488834	-0.00042039971	1267.5642
77.901367	0.14797927	-0.00034376845	1294.4435
78.902344	0.15183835	-0.00019507189	1329.5601
79.90332	0.1538682	-7.2762232e-05	1362.5685
80.904297	0.15951741	2.50353e-05	1386.6337
81.905273	0.16208996	0.0001728795	1411.2903
82.90625	0.16225059	0.00029826662	1443.7001
83.907227	0.16814916	0.00057419844	1474.4254
84.908203	0.16915968	0.00064032903	1503.5825
85.90918	0.17410564	0.00071365025	1530.3909
86.910156	0.17468365	0.00078933185	1551.426
87.911133	0.17719452	0.00096907245	1574.746
88.912109	0.1829159	0.001060924	1604.7109
89.913086	0.18603942	0.0012581787	1635.7709
90.914063	0.18916292	0.0014639118	1664.0686
91.915039	0.19160661	0.0014515405	1686.1487
92.916016	0.19281608	0.0015443295	1717.9207
93.916992	0.19775328	0.0017636878	1740.9226
94.917969	0.20170538	0.0017517427	1766.707
95.918945	0.20281486	0.0019600654	1794.2827
96.919922	0.20749268	0.0019974827	1815.316
97.920898	0.20700176	0.0021569012	1835.6266
98.921875	0.21182382	0.0022400583	1858.4388
99.922852	0.21456848	0.0024547563	1891.4623
100.92383	0.21694618	0.0024619151	1906.7046
101.9248	0.22419293	0.0026146634	1928.0023
102.92578	0.22382104	0.0027387363	1947.9952
103.92676	0.22946185	0.0028717299	1980.2635
104.92773	0.22938953	0.0029792874	2002.0461
105.92871	0.23235404	0.0030647803	2021.1246
106.92969	0.23660553	0.0032751756	2047.1675
107.93066	0.23855993	0.0032742496	2069.1833
108.93164	0.24127592	0.0033707602	2082.748
109.93262	0.24822433	0.0035247502	2093.3508
110.93359	0.25078502	0.0036293173	2118.4246
111.93457	0.25176254	0.0037579376	2138.8877
112.93555	0.25512168	0.0037983463	2150.8398
113.93652	0.26053053	0.0039722146	2172.8035
114.9375	0.26298288	0.0040642465	2179.825
115.93848	0.26521963	0.0041122977	2197.229
116.93945	0.26921046	0.0043024579	2221.4146
117.94043	0.27022362	0.0043662079	2229.3113
118.94141	0.27377003	0.0044740411	2249.5776
119.94238	0.27845931	0.0045621954	2261.3489
120.94336	0.27937007	0.0046941317	2270.6482
121.94434	0.28143573	0.0047750259	2285.2317
122.94531	0.28446108	0.0049105682	2298.1077
123.94629	0.28780389	0.0049405275	2312.5339
124.94727	0.29136035	0.0051501645	2325.7905
125.94824	0.29366803	0.005135064	2340.4275
126.94922	0.29715234	0.0052289851	2351.3398
127.9502	0.29991975	0.0054011079	2359.1697
128.95117	0.30327711	0.0054245885	2367.5474
129.95215	0.30741706	0.0056031859	2384.8428
130.95313	0.30690137	0.0056623532	2399.1494
131.9541	0.31419906	0.0059183571	2413.9541
132.95508	0.31692165	0.0059999614	2424.5686
133.95605	0.31998944	0.0060880715	2438.1777
134.95703	0.32225323	0.0062327101	2454.5222
135.95801	0.32446212	0.0063476078	2457.7273
136.95898	0.32803765	0.0064986595	2468.3447
137.95996	0.33023676	0.0064605256	2468.6287
138.96094	0.33359569	0.0067118499	2490.261
139.96191	0.33616701	0.0067592412	2497.8809
140.96289	0.34238869	0.0070495848	2513.6877
141.96387	0.34097677	0.0070866537	2521.8833
142.96484	0.34590027	0.0072213183	2527.9409
143.96582	0.34805238	0.0073517263	2531.2217
144.9668	0.35344118	0.0073834094	2539.3892
145.96777	0.3566471	0.0076202736	2557.45
146.96875	0.35606828	0.0077621341	2560.9785
147.96973	0.36197662	0.0080555258	2572.207
148.9707	0.36728078	0.008066155	2578.25
149.97168	0.36692366	0.0082964422	2585.176
150.97266	0.36818191	0.0085051628	2598.27
151.97363	0.37374115	0.0086461464	2609.1692
152.97461	0.37639138	0.0087942071	2611.2727
153.97559	0.37621927	0.009007439	2618.1846
154.97656	0.38342687	0.0092572672	2625.7178
155.97754	0.38597894	0.0094155483	2637.4719
156.97852	0.38716894	0.0096636387	2640.1741
157.97949	0.3922694	0.0099579329	2649.4275
158.98047	0.39204422	0.010088649	2653.0332
159.98145	0.40092024	0.010383107	2668.323
160.98242	0.4020676	0.010627567	2676.7502
161.9834	0.40538165	0.010944787	2676.0564
162.98438	0.4064233	0.011224465	2685.0117
163.98535	0.40867016	0.011636906	2691.8989
164.98633	0.41275254	0.011888324	2699.1904
165.9873	0.41580659	0.012256723	2708.7122
166.98828	0.41805959	0.012622157	2715.5867
167.98926	0.42325249	0.012919381	2720.3643
168.99023	0.42387474	0.013353745	2727.0964
169.99121	0.42616558	0.013866713	2740.3223
170.99219	0.43048096	0.014329868	2747.4338
171.99316	0.43278345	0.014832615	2749.7402
172.99414	0.43928623	0.015235037	2759.7107
173.99512	0.43972492	0.015644502	2757.771
174.99609	0.44351062	0.016163345	2763.2888
175.99707	0.44524804	0.01669522	2772.1797
176.99805	0.45126691	0.017292861	2778.3501
177.99902	0.450214	0.01782212	2778.2563
179	0.45341393	0.018380282	2783.856
180.00098	0.45621249	0.019099511	2793.3806
181.00195	0.45756006	0.019800782	2801.5417
182.00293	0.46260566	0.020488599	2799.239
183.00391	0.46641698	0.021148499	2801.7056
184.00488	0.47259578	0.021811474	2813.7461
185.00586	0.47419187	0.022476235	2818.0898
186.00684	0.47979867	0.023254111	2820.7822
187.00781	0.47872093	0.023883304	2822.6633
188.00879	0.48043853	0.024621181	2821.6643
189.00977	0.48325676	0.025403798	2828.0247
190.01074	0.48826915	0.026160527	2831.8555
191.01172	0.48988861	0.026989477	2830.6279
192.0127	0.49132428	0.027777785	2842.168
193.01367	0.49624833	0.028754346	2848.4692
194.01465	0.50195736	0.029660689	2848.3088
195.01563	0.50205445	0.030612284	2850.1648
196.0166	0.50637925	0.031586885	2859.0413
197.01758	0.50600451	0.032546487	2857.6233
198.01855	0.51282257	0.033496413	2863.7063
199.01953	0.51412916	0.034393415	2863.24
200.02051	0.51698023	0.035386659	2868.0552
201.02148	0.5191291	0.036373481	2868.5078
202.02246	0.52313221	0.037230287	2873.4451
203.02344	0.52451599	0.03814413	2873.0833
204.02441	0.52932662	0.038979419	2876.2178
205.02539	0.52962595	0.040006492	2884.3601
206.02637	0.53612417	0.041164078	2887.2412
207.02734	0.53765512	0.042134054	2884.7354
208.02832	0.54104662	0.043221474	2898.4773
209.0293	0.54304469	0.044425	2891.9353
210.03027	0.54908794	0.045448132	2898.7358
211.03125	0.54999471	0.046491701	2896.2759
212.03223	0.55436808	0.047623083	2908.3127
213.0332	0.55766785	0.048939329	2907.0913
214.03418	0.56069666	0.050143715	2910.6013
215.03516	0.56306618	0.05131283	2910.4636
216.03613	0.56726068	0.052541602	2917.7168
217.03711	0.56545115	0.053656496	2908.4578
218.03809	0.57186949	0.054647692	2914.7722
219.03906	0.57340509	0.055829443	2922.0872
220.04004	0.57833409	0.057133328	2922.7419
221.04102	0.58383232	0.058019694	2918.3157
222.04199	0.58356184	0.059245806	2921.196
223.04297	0.58752584	0.060378887	2925.5154
224.04395	0.58854312	0.061411723	2925.1704
225.04492	0.59179384	0.062468819	2928.1213
226.0459	0.59675974	0.063477814	2932.5149
227.04688	0.59679049	0.06462653	2936.7461
228.04785	0.60397732	0.065871425	2939.0549
229.04883	0.60290658	0.066983357	2939.6436
230.0498	0.61119908	0.068170078	2948.4678
231.05078	0.61204547	0.069448285	2942.4038
232.05176	0.61147833	0.070819192	2948.825
233.05273	0.61621433	0.071824677	2943.0623
234.05371	0.62175614	0.072970897	2956.4055
235.05469	0.62417239	0.074110657	2955.3396
236.05566	0.6271103	0.075623743	2958.98
237.05664	0.62709063	0.076817185	2954.1724
238.05762	0.63225812	0.078204073	2961.2798
239.05859	0.63480121	0.079348005	2962.7095
240.05957	0.63627088	0.080626152	2970.271
241.06055	0.64190227	0.082014911	2964.6274
242.06152	0.64155251	0.08340957	2965.2151
243.0625	0.64655232	0.084812403	2965.6182
244.06348	0.65233189	0.086011499	2972.6948
245.06445	0.65333581	0.087221466	2972.1003
246.06543	0.65823555	0.088214546	2972.4314
247.06641	0.66039157	0.089289598	2980.6882
248.06738	0.66050094	0.090626851	2981.3694
249.06836	0.66707057	0.091799133	2977.5759
250.06934	0.66759914	0.092949584	2982.7524
251.07031	0.67052352	0.09417367	2988.0608
252.07129	0.67306745	0.095359758	2986.1262
253.07227	0.67802536	0.096595526	2987.991
254.07324	0.68018728	0.097859502	2990.7087
255.07422	0.68540132	0.099305674	2992.6978
256.0752	0.68876743	0.10070188	2994.9988
257.07617	0.68871617	0.10164605	2993.8772
258.07715	0.68922943	0.10290395	2995.5181
259.07813	0.69387448	0.10403724	2995.1162
260.0791	0.69670016	0.10531916	2998.0095
261.08008	0.70277691	0.10643447	2999.6631
262.08105	0.7039243	0.10775284	3006.0251
263.08203	0.70657825	0.10896627	3003.113
264.08301	0.70711702	0.11012336	3003.509
265.08398	0.71278816	0.11133581	3010.9087
266.08496	0.71658391	0.11270612	3015.1492
267.08594	0.71930182	0.11388754	3009.7717
268.08691	0.72165352	0.11519492	3007.8418
269.08789	0.72486448	0.11633792	3013.6926
270.08887	0.72994739	0.11755814	3015.2532
271.08984	0.73131526	0.11885449	3015.1663
272.09082	0.73560458	0.12008857	3021.2078
273.0918	0.7361303	0.12132829	3013.9604
274.09277	0.74002278	0.1223071	3018.448
275.09375	0.74354541	0.12359742	3026.8176
276.09473	0.74644113	0.12502067	3030.8647
277.0957	0.74838984	0.1266789	3031.5784
278.09668	0.75327581	0.12797394	3029.6892
279.09766	0.75558835	0.1292883	3031.1499
280.09863	0.7578243	0.1304265	3029.8435
281.09961	0.75965196	0.13151719	3025.699
282.10059	0.76353991	0.13248125	3031.3118
283.10156	0.7672351	0.13376789	3035.9531
284.10254	0.77175862	0.13498463	3038.1365
285.10352	0.77212596	0.1361661	3043.3745
286.10449	0.77648926	0.13748662	3042.3379
287.10547	0.77855456	0.13893819	3047.0361
288.10645	0.78129327	0.14015837	3044.8381
289.10742	0.78574306	0.14130296	3045.1333
290.1084	0.78722751	0.14291343	3051.9282
291.10938	0.79280084	0.14436619	3052.2476
292.11035	0.79235029	0.1455081	3048.8582
293.11133	0.79599261	0.14662533	3054.2
294.1123	0.80056721	0.14779246	3052.3718
295.11328	0.80460572	0.14912757	3057.9983
296.11426	0.80922145	0.15007375	3053.4661
297.11523	0.81185615	0.15113965	3056.1667
298.11621	0.81044567	0.15231901	3056.9937
299.11719	0.81432074	0.15360127	3060.0618
300.11816	0.81735927	0.15506905	3060.6011
301.11914	0.82126826	0.15625557	3065.9912
302.12012	0.82607722	0.15741466	3061.5186
303.12109	0.82897127	0.15849674	3067.8689
304.12207	0.82973963	0.15961623	3060.8867
305.12305	0.8333649	0.16079563	3070.3962
306.12402	0.83812386	0.16204013	3070.3408
307.125	0.83773518	0.16329801	3072.6282
308.12598	0.84274596	0.16452833	3079.9592
309.12695	0.84435272	0.16584019	3082.834
310.12793	0.85110337	0.16722009	3077.8208
311.12891	0.84959579	0.16835375	3073.5059
312.12988	0.85124761	0.16965632	3078.5403
313.13086	0.85629523	0.17080964	3081.3721
314.13184	0.86019552	0.17215769	3082.1797
315.13281	0.86221278	0.17343263	3084.7029
316.13379	0.86555618	0.1745913	3085.2834
317.13477	0.87167561	0.17592239	3087.6033
318.13574	0.87255704	0.17711496	3083.2476
319.13672	0.87583172	0.17830746	3091.3376
320.1377	0.88038462	0.17948587	3093.2424
321.13867	0.88213187	0.18078585	3091.4778
322.13965	0.88562971	0.18216197	3096.0125
323.14063	0.88803083	0.18350604	3099.9102
324.1416	0.88812798	0.18475214	3092.5862
325.14258	0.89154077	0.18589979	3097.3525
326.14355	0.89700395	0.18717697	3096.9136
327.14453	0.90125638	0.18836732	3104.5374
328.14551	0.90533	0.18976632	3110.252
329.14648	0.90593463	0.19122441	3108.9138
330.14746	0.90810627	0.19242771	3104.6963
331.14844	0.91004694	0.19360602	3103.011
332.14941	0.91519535	0.19476883	3110.1277
333.15039	0.91692668	0.19585814	3109.9387
334.15137	0.92276108	0.19708753	3108.0693
335.15234	0.92464346	0.19818588	3111.1663
336.15332	0.92510813	0.19923957	3105.0015
337.1543	0.9295277	0.20015919	3111.7649
338.15527	0.93238145	0.20139267	3115.1538
339.15625	0.93536443	0.20256743	3114.7546
340.15723	0.9379915	0.2037593	3113.1353
341.1582	0.94278568	0.20525979	3122.8762
342.15918	0.9423933	0.20660408	3120.0447
343.16016	0.947115	0.20794593	3123.0076
344.16113	0.95020986	0.20933503	3126.7192
345.16211	0.95421088	0.21054201	3122.4878
346.16309	0.9555043	0.21182002	3133.5803
347.16406	0.95977771	0.21320273	3130.2495
348.16504	0.96324563	0.21436413	3133.6887
349.16602	0.9652257	0.21559671	3133.2295
350.16699	0.96981782	0.21701448	3128.9785
351.16797	0.97132993	0.21828145	3135.2583
352.16895	0.97339481	0.21944067	3130.624
353.16992	0.97666502	0.22041351	3129.3086
354.1709	0.98096544	0.22162232	3138.9961
355.17188	0.98581618	0.22289588	3142.429
356.17285	0.9876436	0.22410828	3133.9639
357.17383	0.98805749	0.22529112	3139.0608
358.1748	0.99208951	0.22651294	3142.9192
359.17578	0.99862236	0.22796069	3151.1714
360.17676	1.0004319	0.22921814	3146.4822
361.17773	1.000679	0.23051552	3143.8755
362.17871	1.0040791	0.23160873	3146.0708
363.17969	1.0074164	0.23283343	3148.2959
364.18066	1.0087963	0.23428351	3152.929
365.18164	1.0114539	0.23550737	3151.4385
366.18262	1.0149131	0.23693474	3148.3308
367.18359	1.0188003	0.23806812	3149.6477
368.18457	1.0206642	0.23933449	3151.3076
369.18555	1.0246196	0.24045858	3153.7371
370.18652	1.0269349	0.24170724	3157.4917
371.1875	1.0340736	0.24293619	3162.5237
372.18848	1.034081	0.2440313	3156.4429
373.18945	1.0373303	0.24522552	3157.4233
374.19043	1.0438337	0.24624529	3163.5911
375.19141	1.0418342	0.24742582	3162.3835
376.19238	1.0485061	0.24880792	3172.7422
377.19336	1.0488399	0.25007415	3166.6929
378.19434	1.0574491	0.25138336	3169.2825
379.19531	1.0578231	0.25254178	3168.0828
380.19629	1.0587641	0.2536554	3166.7656
381.19727	1.0603637	0.25484818	3164.7327
382.19824	1.0657791	0.2561456	3168.4648
383.19922	1.0681739	0.25717598	3181.0393
384.2002	1.0709286	0.2586273	3177.9648
385.20117	1.0724308	0.26001337	3174.2366
386.20215	1.0736775	0.26119787	3174.3333
387.20313	1.0803025	0.26233047	3175.3425
388.2041	1.0829191	0.26343375	3177.9934
389.20508	1.0856863	0.26451388	3178.303
390.20605	1.0909318	0.26575205	3187.3728
391.20703	1.089357	0.26707047	3187.9106
392.20801	1.0943171	0.26842302	3184.8591
393.20898	1.0947268	0.26955244	3180.6255
394.20996	1.0993273	0.27084938	3184.54
395.21094	1.1040258	0.27236474	3195.6946
396.21191	1.1059879	0.27367288	3193.8193
397.21289	1.1115779	0.27489606	3193.7046
398.21387	1.1125696	0.27627811	3194.0344
399.21484	1.1139015	0.27742699	3189.8059
400.21582	1.1176349	0.27856416	3191.8071
401.2168	1.123077	0.27970853	3197.3745
402.21777	1.1237826	0.28087738	3191.842
403.21875	1.1289819	0.2820704	3197.3901
404.21973	1.12875	0.28318447	3189.0662
405.2207	1.1336796	0.28423893	3195.376
406.22168	1.1355673	0.28543481	3194.876
407.22266	1.1411839	0.28670084	3204.6909
408.22363	1.1409183	0.28785557	3198.9299
409.22461	1.1434046	0.28903216	3201.998
410.22559	1.1469742	0.29024473	3205.1436
411.22656	1.1516899	0.29153699	3204.1345
412.22754	1.1539793	0.29275143	3206.5798
413.22852	1.1576042	0.29396805	3211.7056
414.22949	1.160303	0.2952674	3207.814
415.23047	1.163058	0.29668474	3211.0759
416.23145	1.1672724	0.29784384	3211.4211
417.23242	1.1689452	0.29907674	3207.2781
418.2334	1.1721855	0.30003947	3208.592
419.23438	1.1772828	0.30137822	3224.8228
420.23535	1.1783085	0.30280915	3219.7288
421.23633	1.1810458	0.30415657	3218.0256
422.2373	1.1867948	0.30526543	3215.7295
423.23828	1.1852994	0.30643573	3220.9192
424.23926	1.1893921	0.30761266	3221.084
425.24023	1.1944073	0.30906385	3220.3181
426.24121	1.1990588	0.3101559	3221.7676
427.24219	1.1982301	0.31135249	3222.4434
428.24316	1.2029551	0.3124505	3224.4338
429.24414	1.2056017	0.31382623	3226.9993
430.24512	1.2051673	0.31510305	3227.3296
431.24609	1.211853	0.31653231	3229.6453
432.24707	1.2140393	0.31777719	3228.0974
433.24805	1.2168179	0.31864011	3222.0378
434.24902	1.2225416	0.31965667	3234.4597
435.25	1.2244284	0.32082409	3237.0623
436.25098	1.225885	0.32191697	3230.062
437.25195	1.2319131	0.32315689	3240.1829
438.25293	1.232591	0.32424921	3231.6465
439.25391	1.2369435	0.32536221	3237.3738
440.25488	1.2381703	0.32642955	3231.739
441.25586	1.2420523	0.32765022	3238.7756
442.25684	1.2438815	0.32877895	3242.8362
443.25781	1.247981	0.32989466	3237.2332
444.25879	1.2511518	0.3309896	3243.0466
445.25977	1.2546387	0.33218935	3244.3481
446.26074	1.258791	0.33347458	3249.6331
447.26172	1.2603378	0.33474487	3252.1882
448.2627	1.2620945	0.33616087	3244.9846
449.26367	1.2656893	0.33737168	3243.4685
450.26465	1.2696801	0.3386327	3248.561
451.26563	1.2708882	0.33977845	3244.5313
452.2666	1.2732186	0.34101892	3250.0996
453.26758	1.2793169	0.34240529	3255.6843
454.26855	1.2792181	0.34379828	3257.6055
455.26953	1.2855639	0.34497771	3254.3333
456.27051	1.286193	0.3462674	3254.854
457.27148	1.2906699	0.34761181	3253.9143
458.27246	1.2917668	0.34889045	3260.5212
459.27344	1.2968744	0.35025495	3258.5527
460.27441	1.2994018	0.3514123	3259.323
461.27539	1.2998705	0.35272282	3258.7473
462.27637	1.306556	0.35387412	3260.8884
463.27734	1.3081939	0.35509285	3262.1877
464.27832	1.3108407	0.35624084	3265.5251
465.2793	1.3130579	0.3573367	3260.2385
466.28027	1.3163518	0.35846835	3262.4717
467.28125	1.3195664	0.35959721	3264.3245
468.28223	1.3219444	0.36079422	3265.532
469.2832	1.3254869	0.36204517	3271.4253
470.28418	1.327118	0.3632462	3269.5098
471.28516	1.332368	0.36463663	3275.3093
472.28613	1.3327227	0.36575866	3265.5752
473.28711	1.3365464	0.36704782	3274.0701
474.28809	1.3408759	0.36817542	3268.8162
475.28906	1.3444309	0.36929423	3271.3313
476.29004	1.3482095	0.37068123	3276.6421
477.29102	1.3510476	0.37176773	3277.6765
478.29199	1.3557072	0.37295309	3279.9106
479.29297	1.3542131	0.37419698	3281.853
480.29395	1.3561505	0.37567222	3281.9136
481.29492	1.3627398	0.37711388	3282.2581
482.2959	1.3649167	0.37822723	3277.4263
483.29688	1.3650464	0.37950334	3280.3831
484.29785	1.3709427	0.38060144	3276.4705
485.29883	1.3737738	0.38173923	3284.6201
486.2998	1.3760905	0.38281673	3287.8059
487.30078	1.3818964	0.38415757	3288.9346
488.30176	1.3825101	0.38513058	3285.9697
489.30273	1.3857682	0.38632411	3290.979
490.30371	1.3910581	0.38771835	3296.3672
491.30469	1.3935868	0.38922349	3292.8196
492.30566	1.3968416	0.3905575	3298.1072
493.30664	1.3966382	0.39173886	3293.0359
494.30762	1.4019829	0.39312735	3296.8386
495.30859	1.4035923	0.39428887	3295.0176
496.30957	1.4070953	0.39545313	3295.6348
497.31055	1.4095963	0.39676645	3300.9949
498.31152	1.4131694	0.39809743	3296.6616
499.3125	1.419277	0.39948013	3307.0659
500.31348	1.4194241	0.40061659	3300.6736
501.31445	1.4219005	0.40163416	3306.4048
502.31543	1.4261224	0.40290046	3303.9089
503.31641	1.4266828	0.40415013	3306.9265
504.31738	1.430338	0.40543166	3302.8579
505.31836	1.4353558	0.40652713	3305.4346
506.31934	1.4361845	0.40765825	3305.7983
507.32031	1.4409156	0.40902567	3309.9878
508.32129	1.4432255	0.4102239	3304.4834
509.32227	1.4442081	0.41127631	3307.2686
510.32324	1.4512106	0.41238698	3303.7095
511.32422	1.4506304	0.41347662	3310.4224
512.3252	1.4541965	0.41485986	3316.137
513.32617	1.4564753	0.41592097	3305.1819
514.32715	1.4587133	0.4169848	3312.2661
515.32813	1.463003	0.41811159	3310.4963
516.3291	1.4670372	0.41926935	3313.7747
517.33008	1.471682	0.42032307	3316.8125
518.33105	1.4717493	0.42176732	3322.4968
519.33203	1.4765841	0.42290536	3320.001
520.33301	1.4772518	0.42443347	3319.2393
521.33398	1.4812886	0.42563841	3317.3865
522.33496	1.4888766	0.42712998	3326.0623
523.33594	1.4880857	0.42840192	3322.5159
524.33691	1.4915477	0.42970553	3327.3464
525.33789	1.4970485	0.43094528	3324.6013
526.33887	1.4993693	0.4321602	3326.2852
527.33984	1.5005202	0.43333361	3321.2981
528.34082	1.5048023	0.43449757	3331.4612
529.3418	1.5053445	0.43593687	3328.5762
530.34277	1.5081166	0.43722901	3330.7771
531.34375	1.5129594	0.43862328	3329.4082
532.34473	1.5159619	0.43983436	3332.2617
533.3457	1.5177377	0.44092765	3329.5205
534.34668	1.5219368	0.44204792	3326.311
535.34766	1.5236338	0.4433009	3331.5386
536.34863	1.5296594	0.44456798	3343.7651
537.34961	1.5281587	0.44599396	3338.0242
538.35059	1.5330275	0.44734168	3331.9126
539.35156	1.5366369	0.44844854	3341.1548
540.35254	1.5391804	0.44966772	3334.1392
541.35352	1.5426627	0.45091957	3345.1448
542.35449	1.5449208	0.45222187	3339.9758
543.35547	1.5485258	0.45336422	3341.7917
544.35645	1.5528364	0.45474201	3339.0654
545.35742	1.5561186	0.45578712	3342.0308
546.3584	1.5595552	0.4570545	3341.3137
547.35938	1.5611403	0.45811531	3338.5693
548.36035	1.564329	0.45919615	3341.1768
549.36133	1.5648777	0.46073344	3350.3577
550.3623	1.5687131	0.462129	3351.0645
551.36328	1.5738338	0.46343976	3351.6267
552.36426	1.577832	0.46489769	3345.6179
553.36523	1.577351	0.46616817	3344.2749
554.36621	1.5797373	0.46753207	3349.7388
555.36719	1.5804843	0.46846819	3340.7961
556.36816	1.586719	0.46959615	3342.78
557.36914	1.589824	0.47073424	3356.363
558.37012	1.5950952	0.47189882	3353.8777
559.37109	1.5973016	0.47315693	3362.1804
560.37207	1.6002402	0.47457954	3355.8601
561.37305	1.6017807	0.47590038	3353.5969
562.37402	1.6043825	0.47708625	3355.636
563.375	1.6086879	0.47830835	3355.824
564.37598	1.610399	0.47950831	3351.8569
565.37695	1.6159731	0.48075116	3359.1865
566.37793	1.6147859	0.48201385	3358.6782
567.37891	1.6191614	0.48342544	3364.9771
568.37988	1.6235478	0.48469043	3364.7808
569.38086	1.6258692	0.48593214	3362.6511
570.38184	1.6290402	0.48726648	3364.1875
571.38281	1.6324821	0.48836139	3362.2642
572.38379	1.6389157	0.48945516	3364.4731
573.38477	1.6389788	0.49082097	3371.2878
574.38574	1.6435745	0.49206105	3368.4312
575.38672	1.6459041	0.49336869	3360.1113
576.3877	1.6462787	0.49437743	3365.5071
577.38867	1.6489327	0.49573013	3367.0728
578.38965	1.649098	0.49715593	3366.3992
579.39063	1.6579928	0.49862877	3370.8872
580.3916	1.661002	0.49969989	3369.0396
581.39258	1.6631913	0.50093746	3372.9263
582.39355	1.6661439	0.50198019	3366.2588
583.39453	1.6682059	0.50323933	3371.29
584.39551	1.67251	0.50449604	3377.3928
585.39648	1.6737788	0.50574028	3368.8665
586.39746	1.6783913	0.50721419	3380.0557
587.39844	1.6790007	0.50836271	3368.6406
588.39941	1.6839424	0.50961047	3379.1204
589.40039	1.6882277	0.5110448	3386.2476
590.40137	1.6918917	0.51216924	3367.6296
591.40234	1.6948388	0.51328647	3379.9233
592.40332	1.6966435	0.51441437	3380.1011
593.4043	1.7013825	0.51560771	3374.6504
594.40527	1.7008246	0.51700461	3385.2388
595.40625	1.7031782	0.51828557	3387.4656
596.40723	1.7118195	0.51977652	3386.3599
597.4082	1.7110698	0.52104324	3382.1714
598.40918	1.7131559	0.52223414	3385.762
599.41016	1.7175281	0.52345622	3385.6833
600.41113	1.719684	0.52468401	3391.1782
601.41211	1.7219185	0.52633661	3390.5942
602.41309	1.7282027	0.52762789	3383.8918
603.41406	1.7296859	0.52908355	3392.7939
604.41504	1.7303692	0.53023911	3387.467
605.41602	1.7325456	0.53141928	3390.9194
606.41699	1.7373607	0.53283733	3400.9546
607.41797	1.7398707	0.53407556	3389.4165
608.41895	1.7439705	0.53541118	3394.8191
609.41992	1.7465863	0.53676009	3390.5405
610.4209	1.7494092	0.53797549	3393.5706
611.42188	1.7530668	0.53936565	3400.3994
612.42285	1.7572696	0.54078257	3399.9561
613.42383	1.758729	0.54196203	3390.7173
614.4248	1.7615128	0.54313374	3392.2129
615.42578	1.7641284	0.54415768	3397.4912
616.42676	1.7664728	0.54539847	3396.8889
617.42773	1.7692243	0.54681611	3402.4482
618.42871	1.7754307	0.54818565	3402.0151
619.42969	1.7759024	0.54947639	3399.2688
620.43066	1.7815194	0.55074793	3404.3989
621.43164	1.7818735	0.55219167	3402.4192
622.43262	1.786926	0.55348307	3401.9773
623.43359	1.7891574	0.55456871	3399.6907
624.43457	1.7920659	0.55573422	3402.8738
625.43555	1.794142	0.5570842	3406.1145
626.43652	1.7966158	0.5586099	3410.5425
627.4375	1.801639	0.56016135	3404.384
628.43848	1.8045058	0.56155246	3407.6692
629.43945	1.8086739	0.56295782	3410.0278
630.44043	1.8082174	0.56413764	3406.9185
631.44141	1.8132136	0.56541109	3407.6934
632.44238	1.8169791	0.56657708	3405.7205
633.44336	1.8199641	0.56787622	3414.918
634.44434	1.8240356	0.56914258	3416.8179
635.44531	1.8260583	0.57048106	3412.2673
636.44629	1.8257179	0.5718078	3412.7942
637.44727	1.8295718	0.57313108	3414.1902
638.44824	1.8344415	0.57459736	3418.9487
639.44922	1.8338053	0.57598209	3413.5886
640.4502	1.8402094	0.57726723	3418.2524
641.45117	1.8418648	0.57862848	3420.7776
642.45215	1.8443974	0.58008951	3418.1555
643.45313	1.8485073	0.58155286	3420.1978
644.4541	1.8514403	0.58295822	3416.4038
645.45508	1.8505498	0.58430535	3418.3413
646.45605	1.8581238	0.58570319	3425.1958
647.45703	1.8593681	0.58690935	3419.8572
648.45801	1.8634104	0.58835667	3428.3396
649.45898	1.8656727	0.5897879	3428.3606
650.45996	1.8697718	0.59113908	3417.6338
651.46094	1.8738908	0.59222835	3411.3542
652.46191	1.8735654	0.59352535	3420.3442
653.46289	1.8785526	0.59495509	3432.8167
654.46387	1.8790853	0.59653443	3426.3948
655.46484	1.8843668	0.59791726	3427.6758
656.46582	1.8878592	0.59913081	3421.6162
657.4668	1.8891494	0.60032737	3419.1438
658.46777	1.8932924	0.60161197	3420.6445
659.46875	1.8979445	0.60268337	3424.0205
660.46973	1.8972136	0.60394144	3426.4695
661.4707	1.9014704	0.60523981	3433.9529
662.47168	1.906565	0.6065585	3431.5396
663.47266	1.9068435	0.607705	3428.5857
664.47363	1.9111042	0.6090318	3433.3589
665.47461	1.9156274	0.61042452	3431.5354
666.47559	1.9160105	0.61181754	3432.696
667.47656	1.9223262	0.6131708	3430.7087
668.47754	1.9254291	0.61445993	3431.7974
669.47852	1.9284372	0.61586779	3437.1685
670.47949	1.9313061	0.61754	3440.427
671.48047	1.9292967	0.61917692	3435.7781
672.48145	1.9345776	0.62063044	3438.2375
673.48242	1.9352738	0.62201506	3431.8047
674.4834	1.9420205	0.62311798	3430.7485
675.48438	1.9437404	0.62426811	3432.4958
676.48535	1.9478605	0.62553567	3439.2803
677.48633	1.9508617	0.62705702	3442.6125
678.4873	1.9544718	0.62845957	3440.446
679.48828	1.9583955	0.6297816	3440.8347
680.48926	1.9580381	0.63109863	3437.3782
681.49023	1.9618284	0.63247502	3440.343
682.49121	1.9650377	0.63393056	3439.9333
683.49219	1.9698976	0.63526607	3443.8237
684.49316	1.9687589	0.63673836	3442.9878
685.49414	1.9740736	0.63804823	3442.8513
686.49512	1.9764788	0.63958472	3446.8792
687.49609	1.9823637	0.64092815	3445
688.49707	1.9824338	0.64226025	3448.7727
689.49805	1.9868881	0.64355135	3442.4497
690.49902	1.9909506	0.64494962	3445.7898
691.5	1.9899628	0.64615566	3444.8416
692.50098	1.998191	0.64744824	3451.3103
693.50195	1.9980881	0.6488772	3451.6372
694.50293	2.0006366	0.65046459	3449.9338
695.50391	2.0058928	0.65216005	3452.4749
696.50488	2.0081639	0.65349799	3452.0125
697.50586	2.0122533	0.65503961	3454.2104
698.50684	2.0140438	0.65652108	3455.7727
699.50781	2.0142355	0.65763575	3444.6169
700.50879	2.0178075	0.65895295	3448.3699
701.50977	2.0246162	0.66028678	3455.0825
702.51074	2.026669	0.66160512	3453.1121
703.51172	2.030139	0.66313297	3458.3613
704.5127	2.0299087	0.66462213	3451.5396
705.51367	2.0324557	0.66609639	3459.7874
706.51465	2.0383496	0.66772091	3454.45
707.51563	2.0406032	0.66912752	3455.7888
708.5166	2.0445414	0.67042595	3451.8574
709.51758	2.0461705	0.67174238	3456.5828
710.51855	2.0486162	0.67308432	3460.562
711.51953	2.0544243	0.67462939	3464.0837
712.52051	2.0558109	0.67608279	3461.8008
713.52148	2.060076	0.67754471	3462.249
714.52246	2.0622747	0.6790179	3459.7144
715.52344	2.0673051	0.68049979	3462.198
716.52441	2.0681839	0.68173742	3457.0242
717.52539	2.0687845	0.68302965	3458.2979
718.52637	2.0730016	0.68460512	3463.699
719.52734	2.076118	0.6860885	3460.1702
720.52832	2.0788319	0.68751127	3462.2346
721.5293	2.081568	0.68873584	3455.9165
722.53027	2.0841224	0.68991786	3461.925
723.53125	2.0893962	0.69156134	3469.0208
724.53223	2.0929902	0.69304752	3465.8782
725.5332	2.0936265	0.6943112	3461.1055
726.53418	2.0972326	0.69563538	3468.2297
727.53516	2.1000268	0.69690955	3466.9792
728.53613	2.1046119	0.69817996	3467.085
729.53711	2.1079841	0.69959313	3467.9128
730.53809	2.1084833	0.70093477	3464.4216
731.53906	2.1136825	0.70226079	3466.0278
732.54004	2.1162763	0.70381683	3469.3784
733.54102	2.1185155	0.70503563	3466.4636
734.54199	2.1205518	0.70639271	3466.6899
735.54297	2.1228433	0.70768046	3467.6133
736.54395	2.128056	0.70930177	3469.4624
737.54492	2.1324503	0.71096051	3473.9246
738.5459	2.1314642	0.71250534	3478.0635
739.54688	2.1359141	0.7142114	3472.9404
740.54785	2.140934	0.71577734	3474.7502
741.54883	2.1378138	0.71725279	3467.8464
742.5498	2.1435471	0.71881807	3472.322
743.55078	2.1470938	0.72039026	3476.3999
744.55176	2.1512244	0.72187573	3470.4963
745.55273	2.1570544	0.72341877	3476.959
746.55371	2.1576667	0.7246986	3472.2412
747.55469	2.1607895	0.72610348	3475.2266
748.55566	2.1640682	0.72776616	3476.9758
749.55664	2.1674984	0.72928983	3476.2717
750.55762	2.1700377	0.73091602	3477.7935
751.55859	2.1734829	0.73243052	3481.4375
752.55957	2.172369	0.73387051	3474.4148
753.56055	2.1841769	0.73547822	3484.4636
754.56152	2.1838078	0.73684305	3480.2351
755.5625	2.1845136	0.7380634	3475.2693
756.56348	2.1868196	0.73951322	3481.2163
757.56445	2.1927516	0.74124664	3485.7322
758.56543	2.1901555	0.74281085	3479.3154
759.56641	2.2011225	0.74430698	3484.0464
760.56738	2.2027581	0.74560899	3477.5117
761.56836	2.2025034	0.74701995	3483.7974
762.56934	2.2037096	0.74854732	3484.9089
763.57031	2.2079499	0.7499398	3481.2473
764.57129	2.2101271	0.75158572	3485.761
765.57227	2.2161558	0.7530728	3488.9539
766.57324	2.2187059	0.75438088	3484.5547
767.57422	2.2197914	0.75586635	3486.5815
768.5752	2.2216258	0.75762069	3485.4258
769.57617	2.2269681	0.75911242	3486.6143
770.57715	2.2305787	0.76060605	3490.2107
771.57813	2.2331932	0.76211917	3487.7087
772.5791	2.2374024	0.76376015	3493.9739
773.58008	2.2372675	0.76521772	3486.0837
774.58105	2.2418673	0.76692325	3486.0435
775.58203	2.241962	0.76831824	3485.7578
776.58301	2.2474592	0.7699188	3494.3276
777.58398	2.2540109	0.77146661	3497.1714
778.58496	2.2549036	0.77321351	3491.8467
779.58594	2.2587075	0.7748937	3490.0381
780.58691	2.2586498	0.77626044	3490.2688
781.58789	2.2627637	0.77785134	3486.9558
782.58887	2.2649031	0.77929038	3487.5586
783.58984	2.2709253	0.78066486	3490.1602
784.59082	2.2703745	0.78214729	3486.8303
785.5918	2.2758222	0.7837525	3499.9312
786.59277	2.2759857	0.78551829	3496.9773
787.59375	2.2831502	0.78719795	3494.9229
788.59473	2.2830997	0.78881103	3497.6384
789.5957	2.2868483	0.79073626	3499.5574
790.59668	2.2891679	0.79242575	3489.6367
791.59766	2.2914479	0.79393667	3495.7854
792.59863	2.2980061	0.79532057	3491.5291
793.59961	2.2976093	0.79660189	3487.2253
794.60059	2.3021896	0.79810202	3497.928
795.60156	2.30671	0.79954988	3494.8997
796.60254	2.3098316	0.80104053	3496.4565
797.60352	2.3126655	0.80270994	3494.9324
798.60449	2.3136604	0.80432975	3499.71
799.60547	2.3186998	0.80585605	3498.2224
800.60645	2.3216701	0.80744362	3500.6467
801.60742	2.3228455	0.80895615	3502.2434
802.6084	2.3240919	0.81058747	3496.5203
803.60938	2.3293552	0.81239641	3503.4924
804.61035	2.3334157	0.81401998	3500.178
805.61133	2.335273	0.81555313	3501.2024
806.6123	2.3372748	0.81702763	3499.3599
807.61328	2.3423777	0.81845838	3498.4919
808.61426	2.342427	0.82005739	3498.1953
809.61523	2.3481658	0.82169747	3497.7043
810.61621	2.3501964	0.82302642	3501.5828
811.61719	2.3535798	0.82464397	3500.0159
812.61816	2.3532622	0.82607961	3497.28
813.61914	2.3601344	0.82793295	3505.543
814.62012	2.3641863	0.8298142	3504.4651
815.62109	2.3629324	0.83164984	3501.5381
816.62207	2.3674498	0.83353502	3501.9307
817.62305	2.3699856	0.83517498	3503.6777
818.62402	2.373116	0.83684158	3501.4985
819.625	2.3779409	0.83867425	3506.9351
820.62598	2.3816378	0.84072381	3508.7722
821.62695	2.383358	0.84220755	3506.4373
822.62793	2.3866467	0.84382862	3507.7014
823.62891	2.3887494	0.84554088	3506.0549
824.62988	2.3921835	0.84718204	3502.7292
825.63086	2.3959432	0.84891587	3505.3286
826.63184	2.3971117	0.85067642	3500.583
827.63281	2.4007161	0.85224694	3503.5176
828.63379	2.4035275	0.85383987	3507.0688
829.63477	2.407501	0.85534286	3508.7876
830.63574	2.4130232	0.85705829	3508.2502
831.63672	2.4117336	0.85869581	3504.1396
832.6377	2.4146366	0.86040765	3510.0767
833.63867	2.4204364	0.86185759	3500.6172
834.63965	2.4224172	0.86333591	3504.3413
835.64063	2.4233241	0.86483717	3503.9905
836.6416	2.4296582	0.86640292	3511.0535
837.64258	2.4304328	0.86807388	3511.8992
838.64355	2.4352872	0.8698498	3508.6875
839.64453	2.4388888	0.87160993	3512.7971
840.64551	2.4399457	0.87334663	3517.1279
841.64648	2.4421794	0.87534499	3506.7844
842.64746	2.4469795	0.87711298	3512.8752
843.64844	2.4520788	0.87891692	3513.5784
844.64941	2.4547689	0.8805545	3506.5986
845.65039	2.4551945	0.88203251	3511.6118
846.65137	2.4563246	0.88365608	3507.2361
847.65234	2.4595287	0.88572538	3512.6372
848.65332	2.4618516	0.88773924	3512.6086
849.6543	2.4692388	0.88974869	3515.5085
850.65527	2.4702246	0.89160132	3512.0808
851.65625	2.4746628	0.89357328	3514.5769
852.65723	2.4782097	0.89555222	3513.9431
853.6582	2.4821117	0.8974241	3511.0679
854.65918	2.4814727	0.89925706	3514.4661
855.66016	2.4850283	0.90106529	3510.8577
856.66113	2.4879534	0.90282607	3512.2842
857.66211	2.488553	0.9044615	3510.4414
858.66309	2.4923675	0.90625006	3512.0737
859.66406	2.4977067	0.90806949	3515.8574
860.66504	2.5007489	0.91005993	3515.5667
861.66602	2.5040574	0.91157305	3511.8577
862.66699	2.5083156	0.91303158	3509.1118
863.66797	2.507143	0.91444808	3505.7795
864.66895	2.5130491	0.91598564	3509.6162
865.66992	2.5159168	0.91791707	3521.5342
866.6709	2.518919	0.91989344	3514.5908
867.67188	2.5223224	0.92181456	3516.9465
868.67285	2.5256691	0.92344153	3515.1775
869.67383	2.5284626	0.92489731	3513.3872
870.6748	2.5329454	0.92650729	3520.0042
871.67578	2.5338891	0.92854106	3521.1516
872.67676	2.5376911	0.93036759	3517.6204
873.67773	2.5399082	0.93236572	3521.6462
874.67871	2.542321	0.93446892	3523.1467
875.67969	2.544311	0.93622655	3514.7903
876.68066	2.5487709	0.93805736	3515.7354
877.68164	2.5541456	0.94000047	3522.8528
878.68262	2.5532472	0.94180894	3516.0715
879.68359	2.5569685	0.94344109	3514.8762
880.68457	2.560612	0.9450956	3512.4871
881.68555	2.5632722	0.94670069	3512.7205
882.68652	2.5636036	0.94873989	3519.7495
883.6875	2.5697699	0.95067233	3516.7681
884.68848	2.5706244	0.95257121	3518.1919
885.68945	2.5732994	0.95484322	3520.9736
886.69043	2.5797467	0.95698518	3524.0879
887.69141	2.5781596	0.9589349	3513.5134
888.69238	2.583185	0.96088594	3522.2983
889.69336	2.5860999	0.96295995	3516.6907
890.69434	2.5890939	0.96483999	3514.9995
891.69531	2.5924404	0.96697193	3514.252
892.69629	2.5972493	0.96861273	3514.343
893.69727	2.5992041	0.97021741	3509.5449
894.69824	2.6029708	0.97197181	3524.9624
895.69922	2.6051211	0.97435004	3521.8884
896.7002	2.6052625	0.97647786	3516.9839
897.70117	2.6097431	0.97850823	3518.355
898.70215	2.6153862	0.98068005	3519.4185
899.70313	2.6160798	0.98248464	3513.6477
900.7041	2.618089	0.98415613	3510.231
901.70508	2.6233358	0.98589933	3520.0664
902.70605	2.6248136	0.98789692	3519.2505
903.70703	2.6308613	0.98968703	3518.5115
904.70801	2.6320944	0.99156946	3516.0955
905.70898	2.6355758	0.99361676	3516.7751
906.70996	2.6394258	0.99541193	3513.949
907.71094	2.6422174	0.99740028	3522.3899
908.71191	2.6427627	0.99928761	3516.6011
909.71289	2.6504521	1.0013196	3518.4924
910.71387	2.6467204	1.0033783	3521.99
911.71484	2.6484277	1.0055023	3513.3064
912.71582	2.654362	1.0076194	3515.9775
913.7168	2.6595702	1.0098839	3520.0911
914.71777	2.6641071	1.0119389	3520.092
915.71875	2.6674793	1.0139965	3522.531
916.71973	2.6680121	1.0162842	3524.2368
917.7207	2.6691039	1.0186856	3518.4768
918.72168	2.6745479	1.0206466	3514.8271
919.72266	2.6792362	1.022673	3520.7307
920.72363	2.6783028	1.0248544	3518.4963
921.72461	2.6817212	1.0271741	3520.2017
922.72559	2.6841588	1.0297295	3520.9336
923.72656	2.6891899	1.0319718	3518.8318
924.72754	2.6920505	1.0340494	3517.6758
925.72852	2.6924222	1.0358239	3511.9392
926.72949	2.6953599	1.0380577	3521.3643
927.73047	2.7016709	1.0402775	3522.1865
928.73145	2.704803	1.0426385	3520.3096
929.73242	2.7072923	1.0448526	3519.7881
930.7334	2.7088509	1.0472107	3518.7058
931.73438	2.7117054	1.0494969	3514.8711
932.73535	2.715106	1.0515859	3517.0735
933.73633	2.7193432	1.0535946	3508.4529
934.7373	2.7243943	1.0556206	3518.062
935.73828	2.7277439	1.0576011	3519.9277
936.73926	2.7287123	1.059489	3514.999
937.74023	2.7317524	1.0617995	3515.1238
938.74121	2.7339463	1.064045	3519.009
939.74219	2.7375615	1.0664581	3517.7961
940.74316	2.7420123	1.0688496	3517.155
941.74414	2.7432001	1.0712063	3517.9299
942.74512	2.7478797	1.073456	3509.0073
943.74609	2.7509091	1.0754609	3514.6545
944.74707	2.7539887	1.0773885	3517.7734
945.74805	2.7554989	1.0793592	3514.9524
946.74902	2.7586663	1.0814881	3515.0447
947.75	2.7583022	1.0839227	3516.6479
948.75098	2.7651877	1.0863895	3518.8843
949.75195	2.7704949	1.0883893	3515.0864
950.75293	2.7697382	1.0905622	3516.7249
951.75391	2.7734294	1.0932604	3521.7141
952.75488	2.778614	1.0958831	3512.8416
953.75586	2.7776866	1.0981009	3509.9629
954.75684	2.780998	1.100673	3516.0693
955.75781	2.7854717	1.1035371	3516.1914
956.75879	2.7874215	1.1059481	3510.9141
957.75977	2.7912786	1.1086274	3516.52
958.76074	2.7932065	1.1113209	3516.1702
959.76172	2.7966914	1.113663	3507.5991
960.7627	2.799911	1.1155069	3508.7598
961.76367	2.8017073	1.1181506	3514.5579
962.76465	2.8059311	1.1204526	3502.6206
963.76563	2.8101189	1.122841	3510.0437
964.7666	2.8116968	1.1250968	3511.0283
965.76758	2.8145735	1.127807	3512.719
966.76855	2.8136978	1.1301628	3507.2769
967.76953	2.8202815	1.1325107	3509.2192
968.77051	2.8268502	1.1352109	3512.6033
969.77148	2.8288941	1.1379247	3509.1902
970.77246	2.8308129	1.1405833	3506.668
971.77344	2.8350611	1.143708	3506.8167
972.77441	2.8380964	1.1461931	3507.6243
973.77539	2.8393469	1.1486424	3507.7693
974.77637	2.8439991	1.1512679	3511.0889
975.77734	2.8466475	1.1534761	3507.4482
976.77832	2.8496721	1.1562157	3510.0642
977.7793	2.8528674	1.1586477	3503.9373
978.78027	2.8541319	1.1609806	3504.5847
979.78125	2.8576407	1.1634853	3502.7666
980.78223	2.8637171	1.1659374	3505.9128
981.7832	2.8634279	1.1684079	3503.437
982.78418	2.867362	1.1713569	3506.8794
983.78516	2.8694291	1.1740561	3495.3201
984.78613	2.874444	1.1763898	3503.2932
985.78711	2.8749812	1.1788304	3504.7676
986.78809	2.8785322	1.1816869	3502.3042
987.78906	2.8815358	1.1840063	3496.167
988.79004	2.8855138	1.1865691	3499.9939
989.79102	2.8870671	1.1894575	3500.7256
990.79199	2.8908255	1.1922021	3502.7097
991.79297	2.893646	1.1951135	3497.3621
992.79395	2.8975329	1.1980593	3500.7188
993.79492	2.9009597	1.2009822	3493.6479
994.7959	2.9025028	1.2033197	3494.647
995.79688	2.9041102	1.2062675	3495.3035
996.79785	2.9082961	1.2091728	3496.356
997.79883	2.909178	1.2123036	3487.6204
998.7998	2.9118564	1.214849	3490.3984
999.80078	2.9199336	1.2174664	3494.2373
1000.8018	2.9206879	1.2202512	3498.6121
1001.8027	2.9245558	1.223022	3493.3169
1002.8037	2.9283025	1.2257069	3493.041
1003.8047	2.9302323	1.2286943	3493.1677
1004.8057	2.933768	1.2316093	3485.5754
1005.8066	2.9371974	1.2342654	3483.3303
1006.8076	2.940304	1.2371035	3490.783
1007.8086	2.9419339	1.2398163	3489.801
1008.8096	2.944288	1.2427109	3484.0195
1009.8105	2.9473102	1.245671	3484.2876
1010.8115	2.9509397	1.2486883	3478.8354
1011.8125	2.9533105	1.2513953	3475.2859
1012.8135	2.957545	1.2536473	3480.7395
1013.8145	2.9600646	1.2565333	3482.8591
1014.8154	2.9605398	1.2589438	3473.0977
1015.8164	2.9661722	1.2617327	3484.7217
1016.8174	2.9674997	1.2648069	3478.4705
1017.8184	2.9705482	1.2677799	3477.3398
1018.8193	2.9756889	1.2708418	3474.4241
1019.8203	2.9797549	1.2737159	3470.3452
1020.8213	2.9799042	1.2766106	3473.1592
1021.8223	2.9844272	1.2790431	3465.7837
1022.8232	2.9871399	1.2811099	3463.3662
1023.8242	2.9919589	1.2831773	3466.7537
1024.8252	2.9941502	1.2856735	3462.3577
1025.8262	2.9949877	1.2878717	3461.5559
1026.8271	2.9977796	1.2903466	3465.6826
1027.8281	3.0022607	1.2926456	3468.5168
1028.8291	3.0065634	1.2957784	3467.4258
1029.8301	3.006855	1.29887	3466.9702
1030.8311	3.0125453	1.3026294	3468.4824
1031.832	3.0155954	1.3059925	3460.4949
1032.833	3.0175922	1.3089709	3456.3667
1033.834	3.0215161	1.312194	3460.4751
1034.835	3.0224161	1.3148646	3452.0232
1035.8359	3.0263467	1.3180676	3453.9473
1036.8369	3.0295844	1.3208941	3451.8518
1037.8379	3.033432	1.3239609	3450.1042
1038.8389	3.0350816	1.3267262	3448.5137
1039.8398	3.0381479	1.3303603	3449.2651
1040.8408	3.042994	1.3341591	3446.5166
1041.8418	3.0419347	1.3371748	3444.2512
1042.8428	3.0485051	1.3404815	3440.856
1043.8438	3.0489359	1.3437845	3443.8599
1044.8447	3.0532062	1.3466258	3435.5427
1045.8457	3.0563364	1.3492316	3433.3154
1046.8467	3.057373	1.351832	3438.3394
1047.8477	3.0596304	1.3546904	3435.0752
1048.8486	3.0615137	1.3568101	3425.8345
1049.8496	3.0692205	1.3597128	3436.1008
1050.8506	3.0703838	1.3630029	3432.9436
1051.8516	3.0733371	1.3662819	3432.8164
1052.8525	3.0788949	1.3694566	3428.3472
1053.8535	3.0799446	1.3721719	3420.3887
1054.8545	3.0840621	1.3747829	3424.6074
1055.8555	3.0856287	1.3783802	3423.8201
1056.8564	3.090589	1.3817788	3420.3699
1057.8574	3.0904584	1.3846035	3408.2922
1058.8584	3.0947614	1.3875437	3408.6455
1059.8594	3.0983622	1.3909297	3419.5608
1060.8604	3.1008067	1.3940971	3409.4424
1061.8613	3.1040809	1.3972619	3409.4641
1062.8623	3.1078751	1.4008303	3410.6985
1063.8633	3.1117675	1.4042497	3400.894
1064.8643	3.1114275	1.40736	3396.5623
1065.8652	3.117178	1.4099478	3398.156
1066.8662	3.1199303	1.4128387	3396.7375
1067.8672	3.1238191	1.4159003	3403.4102
1068.8682	3.1251569	1.4195104	3398.5566
1069.8691	3.1289937	1.422953	3392.3848
1070.8701	3.1292298	1.4260001	3387.2815
1071.8711	3.1323757	1.4290981	3384.6184
1072.8721	3.137264	1.4320643	3379.0896
1073.873	3.139535	1.4352058	3388.3586
1074.874	3.1420426	1.4386625	3380.4756
1075.875	3.1471448	1.4417779	3372.1592
1076.876	3.1462224	1.4446294	3370.3291
1077.877	3.1529686	1.447494	3370.2822
1078.8779	3.154773	1.4505678	3372.748
1079.8789	3.1573269	1.4539707	3368.3845
1080.8799	3.1632776	1.4578099	3367.8843
1081.8809	3.1637299	1.4610381	3356.1682
1082.8818	3.1679759	1.4639401	3356.1082
1083.8828	3.1732998	1.4671112	3357.6187
1084.8838	3.175492	1.4701643	3354.9207
1085.8848	3.1741233	1.4732006	3351.6663
1086.8857	3.1776855	1.475916	3340.606
1087.8867	3.181736	1.478573	3350.0818
1088.8877	3.1861641	1.481667	3342.7717
1089.8887	3.1862156	1.4851178	3336.614
1090.8896	3.1897902	1.4884139	3331.5828
1091.8906	3.1918061	1.4915816	3329.9543
1092.8916	3.2011721	1.4946448	3337.8755
1093.8926	3.2008166	1.4980502	3330.3867
1094.8936	3.2035732	1.5015519	3325.1902
1095.8945	3.2059364	1.504968	3325.114
1096.8955	3.2072773	1.5080981	3315.4075
1097.8965	3.2111557	1.5106664	3304.1682
1098.8975	3.215965	1.513166	3313.9402
1099.8984	3.2163126	1.5163785	3309.582
1100.8994	3.2221508	1.5202175	3308.5056
1101.9004	3.225209	1.5236424	3299.1509
1102.9014	3.2293861	1.5270386	3299.1685
1103.9023	3.23053	1.5303296	3293.8582
1104.9033	3.2317655	1.5341357	3294.375
1105.9043	3.2371931	1.5375686	3288.1951
1106.9053	3.238817	1.5406927	3281.1179
1107.9063	3.2419581	1.5436465	3281.5706
1108.9072	3.2445178	1.5470015	3275.8931
1109.9082	3.2471821	1.5508306	3271.4446
1110.9092	3.250643	1.5545722	3265.5679
1111.9102	3.2538002	1.5578055	3260.5654
1112.9111	3.259064	1.5605814	3254.594
1113.9121	3.2599788	1.5637639	3262.4563
1114.9131	3.2629204	1.5682461	3250.0146
1115.9141	3.2666774	1.5721089	3234.2419
1116.915	3.2696066	1.5750719	3232.8418
1117.916	3.273303	1.5782393	3232.2625
1118.917	3.2779655	1.5811616	3225.4775
1119.918	3.2778797	1.58429	3213.6343
1120.9189	3.2806756	1.587557	3213.5999
1121.9199	3.2831497	1.5907453	3201.988
1122.9209	3.2898762	1.5940872	3205.209
1123.9219	3.2918818	1.5982798	3187.0256
1124.9229	3.2949746	1.6029122	3173.6609
1125.9238	3.2962711	1.6066394	3165.54
1126.9248	3.3006799	1.6106479	3158.0791
1127.9258	3.3014998	1.6146792	3146.2148
1128.9268	3.3086984	1.6183321	3137.1541
1129.9277	3.3092697	1.6218081	3129.8865
1130.9287	3.3103752	1.6268139	3101.1267
1131.9297	3.3163383	1.6328803	3074.5449
1132.9307	3.3191552	1.6379218	3048.5374
1133.9316	3.3242025	1.6447904	3009.8931
1134.0317	3.3236196	1.6467955	2988.9292