File: datasets/am_bench_2022/raw_data/90-X.13-3/specimen.dat
MTS793|MPT|ENU|1|2|.|/|:|1|0|0|A

Operator Information						Time:	11.600586	Sec	11/2/2021 12:34:35 PM
Operator	Nick Derimow
Project	AM Bench 2022 mini-tensile challenge
Specimen ID	90-X.13-3
Material	PBF-L Inconel 625
Specimen Width	2.54	mm
Specimen Thickness	1.52	mm
Notes
Operator Information End

Data Acquisition						Time:	1012.5942	Sec	11/2/2021 12:51:16 PM
Time	Axial Displacement	Axial Extensometer	Axial Force
Sec	mm	mm	N
11.714111	-0.0010279921	0.00013310784	35.180202
12.61499	-0.0016795454	7.8464436e-05	45.016773
13.515869	0.0046959957	0.00028800848	60.725338
14.416748	0.0069995848	0.00039294339	70.205681
15.317627	0.0092096925	0.00033932444	79.347237
16.218506	0.014045888	0.00036751232	88.637276
17.119385	0.015578421	0.00041250227	100.09505
18.020264	0.018768368	0.00049592054	109.51504
18.921143	0.018967522	0.00066946936	119.81791
19.822021	0.023494741	0.0008042251	132.07689
20.7229	0.026796304	0.00087816105	145.33549
21.623779	0.029314771	0.0008819761	150.83743
22.524658	0.030743681	0.00098782894	162.96503
23.425537	0.03493242	0.0012777753	180.59358
24.326416	0.036155824	0.0013433322	197.07402
25.227295	0.037605017	0.0015750281	209.67899
26.128174	0.042044494	0.0016931548	232.24876
27.029053	0.044117376	0.0017627511	246.77802
27.929932	0.050095018	0.0018912741	259.5787
28.830811	0.048214734	0.0018985396	278.64227
29.731689	0.052141417	0.0021100496	297.1813
30.632568	0.055637013	0.0021368165	314.91785
31.533447	0.061023392	0.0022882493	331.05969
32.434326	0.059947714	0.0023602224	348.12802
33.335205	0.061774675	0.002506407	373.58328
34.236084	0.067508295	0.0026226889	388.21939
35.136963	0.067806616	0.0027786416	408.10376
36.037842	0.07249365	0.0028644488	429.15088
36.938721	0.071498491	0.0030411417	442.52341
37.8396	0.075855449	0.0030237834	465.09192
38.740479	0.078524716	0.0032278036	483.07486
39.641357	0.078966253	0.0033778881	505.87784
40.542236	0.086144969	0.0034900855	534.31433
41.443115	0.086569913	0.0036000444	550.19812
42.343994	0.088676758	0.0037153969	572.36749
43.244873	0.09104161	0.0037980857	587.86725
44.145752	0.095383756	0.0039264192	610.18652
45.046631	0.098458759	0.0040864707	635.85004
45.94751	0.099613324	0.0042393091	661.43243
46.848389	0.10382788	0.004382736	691.02185
47.749268	0.10411923	0.0045462493	712.5882
48.650146	0.11041769	0.0046220045	733.58069
49.551025	0.10868451	0.0047194581	754.43781
50.451904	0.1108539	0.0048806192	777.46021
51.352783	0.11965264	0.0051694592	811.43671
52.253662	0.123055	0.0052499226	830.79767
53.154541	0.12156632	0.0053149252	846.21173
54.05542	0.12368668	0.0054379571	867.63934
54.956299	0.12484247	0.0056350646	902.21979
55.857178	0.12765583	0.0057472195	918.68329
56.758057	0.13466136	0.0059191757	952.8078
57.658936	0.1347677	0.0060520535	970.55914
58.559814	0.13748778	0.0061954064	992.78217
59.460693	0.14307961	0.0063052792	1017.3611
60.361572	0.14240818	0.0065052547	1038.6411
61.262451	0.14968868	0.0066881506	1071.4008
62.16333	0.14949301	0.0068278639	1101.3843
63.064209	0.15357341	0.0069564809	1120.2676
63.965088	0.15457983	0.0070393095	1140.162
64.865967	0.15813403	0.0071449447	1165.8916
65.766846	0.16217688	0.0073457854	1184.4937
66.667725	0.16230166	0.0074760127	1208.3505
67.568604	0.1651793	0.0076476848	1235.7366
68.469482	0.16899621	0.0078070192	1265.7546
69.370361	0.16963112	0.0079720272	1293.4767
70.27124	0.1699364	0.0081305336	1315.7238
71.172119	0.17625453	0.0082298834	1335.0842
72.072998	0.17638975	0.0085164569	1360.4923
72.973877	0.18208183	0.0084645841	1392.0944
73.874756	0.18360822	0.0086720549	1414.7189
74.775635	0.18845016	0.008843272	1447.8804
75.676514	0.19068423	0.0090483725	1470.3212
76.577393	0.19235635	0.0091143064	1489.958
77.478271	0.1951105	0.009254192	1505.2697
78.37915	0.19475521	0.0094475988	1527.8696
79.280029	0.20058979	0.0096065057	1559.9379
80.180908	0.20186278	0.0096740788	1578.08
81.081787	0.20424356	0.0098810121	1605.4072
81.982666	0.20722656	0.010007679	1633.1324
82.883545	0.21253935	0.010080176	1651.5559
83.784424	0.21219677	0.01032387	1678.3009
84.685303	0.21779059	0.010458631	1703.959
85.586182	0.21921131	0.010629614	1724.7501
86.487061	0.22100595	0.010821607	1749.0969
87.387939	0.2223568	0.010919686	1773.1591
88.288818	0.22451629	0.011070849	1786.0428
89.189697	0.22999251	0.01110686	1816.8641
90.090576	0.23058587	0.011310716	1836.8304
90.991455	0.23555899	0.011515261	1861.4469
91.892334	0.23988496	0.011572815	1888.9762
92.793213	0.24118888	0.011768843	1905.7882
93.694092	0.23979357	0.011861199	1922.2061
94.594971	0.24348772	0.012021688	1940.4518
95.49585	0.24808055	0.012163922	1964.1152
96.396729	0.25118601	0.012238703	1983.121
97.297607	0.2541196	0.012358403	2006.0067
98.198486	0.25760046	0.012585964	2030.1304
99.099365	0.25897464	0.012749325	2051.0786
100.00024	0.26086375	0.012815996	2065.3398
100.90112	0.26394403	0.013030413	2087.1143
101.802	0.26923037	0.013184546	2109.8853
102.70288	0.26930147	0.013251991	2120.9814
103.60376	0.27420178	0.013286736	2145.1343
104.50464	0.27578148	0.01343183	2161.583
105.40552	0.27746934	0.013618287	2176.877
106.3064	0.28101084	0.01373136	2204.8064
107.20728	0.28123683	0.013922935	2217.5654
108.10815	0.28566998	0.014067919	2234.949
109.00903	0.2917591	0.014190095	2253.2173
109.90991	0.29342604	0.014328483	2266.8352
110.81079	0.29713309	0.014444717	2283.6384
111.71167	0.29752216	0.014571752	2293.6511
112.61255	0.30183575	0.01462295	2313.989
113.51343	0.30391881	0.014807214	2325.3904
114.41431	0.30491152	0.014975965	2338.7151
115.31519	0.30673313	0.015074217	2352.2786
116.21606	0.31290522	0.0152507	2372.5698
117.11694	0.31539589	0.015428789	2382.6172
118.01782	0.31689993	0.015625626	2396.3694
118.9187	0.32001224	0.015685678	2408.3225
119.81958	0.32184494	0.015796278	2423.7051
120.72046	0.32820243	0.015927119	2428.4092
121.62134	0.33078831	0.016039927	2443.563
122.52222	0.33082828	0.016210632	2454.1443
123.4231	0.33379954	0.016363595	2467.0391
124.32397	0.33387783	0.016528213	2477.832
125.22485	0.33681861	0.016650513	2483.9524
126.12573	0.3425377	0.016856231	2499.2576
127.02661	0.3440983	0.016921453	2500.0115
127.92749	0.34496641	0.017002326	2509.6013
128.82837	0.34925842	0.017260009	2526.0132
129.72925	0.35301957	0.017396703	2534.178
130.63013	0.35701144	0.017601071	2549.6975
131.53101	0.35658568	0.01769164	2552.8462
132.43188	0.36115444	0.017873229	2561.5779
133.33276	0.36248419	0.018018607	2568.4897
134.23364	0.36525202	0.018264527	2583.7903
135.13452	0.37000424	0.018503483	2588.6484
136.0354	0.36981678	0.018700007	2598.668
136.93628	0.3752383	0.018908838	2608.9617
137.83716	0.37772232	0.019134913	2609.5962
138.73804	0.37997818	0.019304836	2617.2832
139.63892	0.3834013	0.01961416	2632.2576
140.53979	0.38345048	0.019939363	2638.6616
141.44067	0.38811922	0.020168383	2639.9148
142.34155	0.39126855	0.020414738	2650.6816
143.24243	0.39330906	0.020731548	2654.251
144.14331	0.39743203	0.021060944	2665.7131
145.04419	0.39821777	0.021406198	2676.3713
145.94507	0.40108517	0.021748185	2679.187
146.84595	0.40386966	0.022112163	2684.4355
147.74683	0.40499076	0.022542264	2695.5674
148.64771	0.40956965	0.022795584	2698.2578
149.54858	0.41529402	0.023400325	2708.4336
150.44946	0.41350248	0.023697602	2709.8396
151.35034	0.42058733	0.024327766	2720.8657
152.25122	0.42311466	0.024855683	2725.5911
153.1521	0.42115712	0.025212675	2727.4539
154.05298	0.42637399	0.025660042	2732.6506
154.95386	0.42839047	0.02640425	2746.6458
155.85474	0.43364364	0.026957294	2747.4001
156.75562	0.43166417	0.027448183	2747.104
157.65649	0.43940452	0.028146951	2758.7239
158.55737	0.44039762	0.028880179	2766.1465
159.45825	0.44139659	0.029373689	2765.4604
160.35913	0.44396389	0.030095931	2768.9001
161.26001	0.44890049	0.030712284	2771.7227
162.16089	0.4519904	0.031364981	2778.6519
163.06177	0.45464531	0.032138657	2786.3269
163.96265	0.45327178	0.032806266	2788.8469
164.86353	0.45992634	0.033627406	2794.2126
165.7644	0.46222335	0.034428813	2798.7207
166.66528	0.46639693	0.035184428	2806.4409
167.56616	0.46713638	0.035979737	2811.2463
168.46704	0.46983722	0.036712054	2811.0703
169.36792	0.47172728	0.037522636	2810.3796
170.2688	0.47628653	0.038347289	2819.2349
171.16968	0.47833475	0.038976658	2819.7615
172.07056	0.47876871	0.039819006	2824.3909
172.97144	0.48164719	0.040691946	2830.5703
173.87231	0.48551077	0.041632306	2833.1375
174.77319	0.48639321	0.042429253	2834.7727
175.67407	0.49103442	0.043363214	2839.1758
176.57495	0.49336788	0.044239312	2844.7131
177.47583	0.49302816	0.045263737	2849.4539
178.37671	0.50040352	0.046116158	2855.0789
179.27759	0.50244999	0.046824176	2853.467
180.17847	0.50613445	0.047687512	2854.4124
181.07935	0.50777727	0.048525427	2862.9058
181.98022	0.51264662	0.049250595	2862.3872
182.8811	0.51383376	0.050155856	2874.4758
183.78198	0.51312566	0.051100016	2874.3308
184.68286	0.5169239	0.052041631	2870.0303
185.58374	0.52021176	0.052898955	2879.0767
186.48462	0.52503461	0.05395776	2882.9001
187.3855	0.52746296	0.054801971	2883.147
188.28638	0.527825	0.055471789	2888.6057
189.18726	0.53289396	0.05647606	2890.5017
190.08813	0.53587896	0.05751003	2901.2153
190.98901	0.53837448	0.058606002	2901.6191
191.88989	0.53925896	0.059596941	2902.0356
192.79077	0.54188198	0.060476542	2898.2063
193.69165	0.54467589	0.061296631	2903.9526
194.59253	0.54610515	0.062193029	2905.3259
195.49341	0.54944831	0.063085996	2915.6384
196.39429	0.55292976	0.064026214	2914.0845
197.29517	0.55473447	0.065052636	2921.3799
198.19604	0.55710953	0.066233248	2920.7021
199.09692	0.56229544	0.066965014	2923.3848
199.9978	0.56308389	0.067980506	2923.293
200.89868	0.56718552	0.068854727	2928.7737
201.79956	0.56861526	0.069768578	2930.1516
202.70044	0.57276303	0.070585594	2929.679
203.60132	0.57320315	0.07153181	2934.5356
204.5022	0.57646698	0.072518282	2939.4534
205.40308	0.57961506	0.073543966	2944.0781
206.30396	0.58429193	0.074424684	2942.917
207.20483	0.58632767	0.075275727	2951.4626
208.10571	0.58641493	0.076114185	2951.8767
209.00659	0.59110999	0.077221788	2955.1094
209.90747	0.59357929	0.078142621	2954.3311
210.80835	0.59435642	0.079237498	2950.9436
211.70923	0.60096389	0.08022406	2966.2791
212.61011	0.60578859	0.081128426	2965.4185
213.51099	0.60487479	0.082004368	2968.6614
214.41187	0.6101132	0.082917996	2966.4004
215.31274	0.61097026	0.083906054	2970.585
216.21362	0.61240238	0.084844023	2967.2051
217.1145	0.61270684	0.085678712	2972.0188
218.01538	0.61740166	0.086532317	2976.3689
218.91626	0.62069052	0.087698832	2979.0249
219.81714	0.62314963	0.088678531	2981.2231
220.71802	0.62879801	0.089735992	2987.6658
221.6189	0.63135707	0.090614147	2984.7073
222.51978	0.63375014	0.091536544	2986.2927
223.42065	0.63420254	0.092684075	2996.0117
224.32153	0.63834971	0.093538985	2988.4709
225.22241	0.63838887	0.094479591	2989.3223
226.12329	0.64075595	0.09541373	2995.8335
227.02417	0.64500266	0.096351035	2998.606
227.92505	0.64814889	0.097352162	2999.9634
228.82593	0.65078521	0.098270088	3004.4951
229.72681	0.65384424	0.099267028	3005.593
230.62769	0.657951	0.10038258	3012.2058
231.52856	0.65797991	0.10155627	3012.6125
232.42944	0.66111732	0.10276157	3019.6343
233.33032	0.66519278	0.1040178	3020.3704
234.2312	0.66650569	0.10485522	3011.6555
235.13208	0.66706628	0.1057853	3017.3669
236.03296	0.67632008	0.10664428	3024.2373
236.93384	0.67446542	0.10757844	3027.0046
237.83472	0.67741871	0.1085933	3027.7205
238.7356	0.67949438	0.10984524	3032.6265
239.63647	0.68328977	0.11067268	3030.4392
240.53735	0.6845535	0.11153462	3030.2832
241.43823	0.69200557	0.11235144	3030.0103
242.33911	0.69050825	0.11300966	3027.4231
243.23999	0.69411916	0.1139974	3037.3015
244.14087	0.69692898	0.11501418	3041.6431
245.04175	0.69728017	0.11597446	3046.1934
245.94263	0.69891477	0.11703114	3050.0283
246.84351	0.70587158	0.1181387	3043.9761
247.74438	0.71085817	0.11934383	3051.1912
248.64526	0.71317971	0.12049317	3061.0151
249.54614	0.7121588	0.12147623	3051.3025
250.44702	0.71516305	0.12224816	3049.9868
251.3479	0.71692801	0.12321832	3055.5667
252.24878	0.71996075	0.12405696	3059.2529
253.14966	0.72417444	0.12494092	3060.6838
254.05054	0.72745043	0.12593934	3060.8638
254.95142	0.72662205	0.12693915	3067.3708
255.85229	0.73351061	0.12789507	3063.6565
256.75317	0.7351141	0.12870803	3064.47
257.65405	0.73666424	0.12960024	3071.4353
258.55493	0.7405563	0.13070153	3075.5349
259.45581	0.74379134	0.13182589	3076.5454
260.35669	0.74431831	0.13273104	3068.4583
261.25757	0.74721378	0.13389614	3083.0308
262.15845	0.75002116	0.13501157	3090.0818
263.05933	0.75308323	0.13598436	3079.3845
263.96021	0.75674051	0.13694593	3085.1665
264.86108	0.75802863	0.13800573	3088.9136
265.76196	0.76425457	0.13898854	3090.5642
266.66284	0.76561588	0.1399636	3090.8501
267.56372	0.76871932	0.1409647	3094.0198
268.4646	0.76970607	0.14189769	3095.3555
269.36548	0.77174616	0.14285587	3098.6887
270.26636	0.7751891	0.14403948	3099.0005
271.16724	0.77780998	0.14481387	3097.7366
272.06812	0.78011644	0.1459491	3105.9517
272.96899	0.78431094	0.14677215	3101.8386
273.86987	0.78446686	0.14779018	3102.7803
274.77075	0.79023463	0.14863388	3108.4607
275.67163	0.7918123	0.14956863	3106.8318
276.57251	0.79611069	0.15036824	3107.9893
277.47339	0.79963952	0.15121382	3113.4348
278.37427	0.80017918	0.15209702	3109.375
279.27515	0.80119497	0.15305576	3117.0408
280.17603	0.80649894	0.15400496	3120.29
281.0769	0.80936223	0.15515344	3126.02
281.97778	0.81392223	0.15595087	3117.8245
282.87866	0.81382	0.15665866	3119.0115
283.77954	0.81455392	0.15757947	3123.7478
284.68042	0.81697875	0.15850377	3127.9338
285.5813	0.82301891	0.15948729	3133.8774
286.48218	0.8265301	0.16037585	3128.5176
287.38306	0.82596952	0.16140394	3129.4722
288.28394	0.82930142	0.16236985	3135.2576
289.18481	0.83338177	0.16358702	3138.0222
290.08569	0.83380461	0.16442901	3132.3701
290.98657	0.83931661	0.16534199	3141.9109
291.88745	0.83885801	0.16626874	3141.2747
292.78833	0.84096056	0.16741231	3142.5188
293.68921	0.84702224	0.16851507	3149.0178
294.59009	0.84612846	0.1695385	3140.6926
295.49097	0.85122508	0.17040083	3144.2385
296.39185	0.85382473	0.17139758	3150.731
297.29272	0.85546303	0.17253076	3150.5256
298.1936	0.86004329	0.17352924	3157.9631
299.09448	0.86157811	0.17459531	3157.0261
299.99536	0.86305004	0.17563003	3157.9136
300.89624	0.86534011	0.17667453	3152.1914
301.79712	0.86849129	0.17746931	3159.0393
302.698	0.87125355	0.17834002	3155.0889
303.59888	0.87735313	0.1793471	3160.667
304.49976	0.87656939	0.18018354	3157.791
305.40063	0.88291705	0.18114468	3164.6868
306.30151	0.88474733	0.18202943	3167.0317
307.20239	0.88477844	0.18299039	3167.491
308.10327	0.89055204	0.18395133	3169.8975
309.00415	0.88913727	0.18484107	3171.0713
309.90503	0.89591312	0.18576932	3177.6499
310.80591	0.89867586	0.18683629	3174.4197
311.70679	0.89870065	0.18775909	3172.5144
312.60767	0.90214378	0.18864372	3166.998
313.50854	0.90570235	0.18946543	3182.9221
314.40942	0.90882295	0.19060536	3186.261
315.3103	0.91225672	0.19150347	3180.1401
316.21118	0.91199195	0.19215435	3174.553
317.11206	0.91926557	0.19309656	3181.187
318.01294	0.91608828	0.19402762	3183.7383
318.91382	0.92013693	0.19482082	3183.2161
319.8147	0.92325515	0.19578026	3194.5649
320.71558	0.92576194	0.19678229	3187.9485
321.61646	0.92916656	0.19766378	3194.802
322.51733	0.93086898	0.1985162	3197.0044
323.41821	0.93254727	0.19955972	3197.6465
324.31909	0.93651325	0.20050803	3198.2759
325.21997	0.93988061	0.20144039	3199.1897
326.12085	0.94066411	0.20235772	3204.0417
327.02173	0.94510978	0.20356596	3210.28
327.92261	0.94968802	0.20451322	3202.4646
328.82349	0.94933558	0.20555608	3205.6038
329.72437	0.95273119	0.20647693	3205.8264
330.62524	0.95639318	0.207376	3204.842
331.52612	0.95973516	0.20845088	3217.4426
332.427	0.96043158	0.20944352	3216.7432
333.32788	0.96521056	0.21045271	3215.9431
334.22876	0.96586454	0.21130078	3210.9312
335.12964	0.96844143	0.21207777	3213.5063
336.03052	0.97190142	0.21299767	3219.0786
336.9314	0.97493213	0.21403252	3220.2905
337.83228	0.97895223	0.21495293	3218.1775
338.73315	0.97910178	0.21579053	3217.2407
339.63403	0.98415869	0.21668273	3226.9961
340.53491	0.9835729	0.21781965	3229.729
341.43579	0.98623073	0.21861608	3220.3616
342.33667	0.99260664	0.21958499	3230.2129
343.23755	0.99330634	0.22061719	3231.2808
344.13843	0.99795139	0.22155415	3229.5925
345.03931	0.99980909	0.22263636	3235.7715
345.94019	1.001054	0.22345845	3235.5139
346.84106	1.0043435	0.22436713	3224.5466
347.74194	1.0059508	0.22518696	3230.8862
348.64282	1.0129544	0.22608766	3237.1128
349.5437	1.0132512	0.22694626	3241.7104
350.44458	1.0154501	0.22777444	3243.3682
351.34546	1.0205458	0.22877504	3245.6628
352.24634	1.0251921	0.22977053	3247.6755
353.14722	1.0230949	0.23073639	3252.8008
354.0481	1.0263122	0.23155428	3243.3601
354.94897	1.0295988	0.23238234	3242.4937
355.84985	1.0308328	0.23325802	3251.113
356.75073	1.03807	0.23438565	3252.8135
357.65161	1.0368134	0.23518591	3250.8562
358.55249	1.0391108	0.23621048	3252.939
359.45337	1.042098	0.23710649	3253.1707
360.35425	1.0455077	0.238084	3257.3032
361.25513	1.0482917	0.23889151	3257.5007
362.15601	1.0518585	0.23972102	3268.489
363.05688	1.0573027	0.24086338	3271.8557
363.95776	1.055884	0.2417731	3261.3279
364.85864	1.0641159	0.24268541	3267.0425
365.75952	1.0624107	0.24364407	3266.3247
366.6604	1.0633568	0.24450414	3261.8049
367.56128	1.0673668	0.24559349	3275.5464
368.46216	1.0693892	0.24673165	3273.251
369.36304	1.0720465	0.24769503	3271.8147
370.26392	1.0762428	0.24854848	3273.7393
371.16479	1.0758058	0.24947162	3270.9148
372.06567	1.0791956	0.25023085	3271.6033
372.96655	1.0820856	0.25108489	3271.3601
373.86743	1.0864455	0.25190362	3277.8218
374.76831	1.0881693	0.25294521	3283.2522
375.66919	1.0946959	0.25386685	3279.709
376.57007	1.0938458	0.25476727	3281.5718
377.47095	1.0980165	0.25565886	3284.2551
378.37183	1.097207	0.25656897	3281.9167
379.27271	1.1052786	0.25735831	3285.9858
380.17358	1.1044195	0.25841361	3288.0544
381.07446	1.108592	0.25943756	3293.5356
381.97534	1.1098017	0.26025292	3282.0618
382.87622	1.1124417	0.26116574	3289.4097
383.7771	1.1163137	0.26208794	3292.6711
384.67798	1.1180145	0.2631951	3292.5508
385.57886	1.1207844	0.26401487	3290.7117
386.47974	1.1261792	0.26500884	3299.8391
387.38062	1.1266769	0.26572701	3292.9333
388.28149	1.1324511	0.26659474	3301.2632
389.18237	1.1316172	0.26753041	3301.3508
390.08325	1.1352144	0.26834396	3303.843
390.98413	1.1388419	0.26939356	3308.8188
391.88501	1.1410687	0.27033263	3303.6707
392.78589	1.1431201	0.27115172	3305.7014
393.68677	1.1470511	0.27212909	3305.7927
394.58765	1.1488638	0.27315101	3310.8708
395.48853	1.14947	0.27413082	3310.834
396.3894	1.1521645	0.27511105	3313.5947
397.29028	1.1564741	0.27608016	3311.4106
398.19116	1.1607085	0.27684727	3308.283
399.09204	1.1615142	0.27752891	3309.6267
399.99292	1.1606777	0.27845305	3315.917
400.8938	1.1658953	0.27950805	3322.3726
401.79468	1.1697015	0.28047022	3316.9331
402.69556	1.1731492	0.28147757	3318.5198
403.59644	1.1748246	0.28228942	3316.1155
404.49731	1.1788334	0.28313565	3320.4773
405.39819	1.1810774	0.28398648	3322.0037
406.29907	1.1869886	0.28485665	3323.4194
407.19995	1.1841865	0.28587997	3324.7576
408.10083	1.1910352	0.28678757	3326.1001
409.00171	1.1919256	0.2877509	3329.2825
409.90259	1.1953309	0.2886478	3335.0161
410.80347	1.1965851	0.28963116	3327.3723
411.70435	1.1981421	0.29064173	3335.8257
412.60522	1.2017632	0.29137474	3330.3054
413.5061	1.204811	0.29239917	3330.498
414.40698	1.2065216	0.29319698	3331.8572
415.30786	1.2109662	0.29401579	3332.6047
416.20874	1.2152179	0.29498026	3342.9033
417.10962	1.215814	0.295867	3340.0117
418.0105	1.2188423	0.29695904	3332.1106
418.91138	1.2215006	0.29778486	3342.228
419.81226	1.2231852	0.29874048	3344.3899
420.71313	1.2256957	0.29947621	3340.1013
421.61401	1.2281886	0.30024835	3338.1973
422.51489	1.2302582	0.30116048	3345.0479
423.41577	1.2342025	0.30206162	3350.6858
424.31665	1.237216	0.30297458	3343.9653
425.21753	1.2404222	0.30374655	3344.863
426.11841	1.242981	0.30472574	3351.981
427.01929	1.2454357	0.30548811	3351.1895
427.92017	1.249149	0.30658841	3357.2888
428.82104	1.2529795	0.30753255	3358.0986
429.72192	1.2541617	0.30829331	3355.7852
430.6228	1.257086	0.30937257	3361.6682
431.52368	1.259773	0.31018892	3352.3284
432.42456	1.260957	0.31122848	3360.8801
433.32544	1.2668499	0.31219697	3357.8296
434.22632	1.2679942	0.31298462	3358.9465
435.1272	1.2692707	0.31394419	3363.5015
436.02808	1.2727648	0.3149797	3368.5081
436.92896	1.2749379	0.31589273	3361.699
437.82983	1.2777561	0.31669101	3365.4929
438.73071	1.2808931	0.31759405	3367.1733
439.63159	1.2829418	0.31855181	3372.0388
440.53247	1.2865206	0.31955537	3365.7749
441.43335	1.2892473	0.3204459	3371.1042
442.33423	1.2941955	0.32141611	3371.2195
443.23511	1.2944287	0.32238546	3371.0491
444.13599	1.2953321	0.32315674	3370.9204
445.03687	1.3013703	0.32413614	3378.0667
445.93774	1.3053792	0.32537475	3379.488
446.83862	1.3046135	0.32647112	3379.1902
447.7395	1.3091931	0.32727477	3375.3845
448.64038	1.3136151	0.32814369	3380.1367
449.54126	1.3117034	0.3290619	3378.8147
450.44214	1.3162524	0.32988492	3378.1567
451.34302	1.3188012	0.33076146	3381.5176
452.2439	1.3222854	0.33137614	3379.8828
453.14478	1.3241359	0.33228916	3379.7283
454.04565	1.327612	0.3331455	3387.1824
454.94653	1.3315409	0.33402964	3393.1255
455.84741	1.3302131	0.33501744	3391.8442
456.74829	1.3340238	0.33606803	3393.5676
457.64917	1.3356447	0.33708668	3384.2319
458.55005	1.3396206	0.33807778	3391.8645
459.45093	1.3414847	0.33896253	3391.6411
460.35181	1.3435106	0.33999315	3394.0796
461.25269	1.3485864	0.34099674	3398.7
462.15356	1.3500435	0.34196433	3395.5786
463.05444	1.3544977	0.34294468	3400.0356
463.95532	1.3557998	0.34394467	3396.458
464.8562	1.3570429	0.34473774	3394.6421
465.75708	1.3635713	0.34555572	3402.2017
466.65796	1.3649585	0.34664682	3408.9377
467.55884	1.3647479	0.34755963	3401.1978
468.45972	1.3725287	0.34853676	3407.9028
469.3606	1.3729445	0.34939826	3405.3999
470.26147	1.3756258	0.35030833	3406.7937
471.16235	1.3784255	0.35144886	3411.8501
472.06323	1.3791401	0.35219947	3401.417
472.96411	1.3830565	0.35316688	3404.6978
473.86499	1.3842845	0.3541733	3410.3206
474.76587	1.3893013	0.35508049	3408.2974
475.66675	1.3928478	0.3559503	3413.2166
476.56763	1.3952583	0.35700145	3416.6731
477.46851	1.3963323	0.35786784	3413.3787
478.36938	1.4011488	0.35886213	3422.7476
479.27026	1.4029438	0.36002105	3421.6875
480.17114	1.4015857	0.3611562	3421.8394
481.07202	1.4067388	0.36200744	3420.9561
481.9729	1.4136155	0.36290818	3424.0586
482.87378	1.4130684	0.36364019	3420.3188
483.77466	1.4151958	0.36444741	3422.3459
484.67554	1.4170138	0.3652983	3415.9277
485.57642	1.4205424	0.3661814	3425.354
486.47729	1.4238279	0.36728987	3427.6033
487.37817	1.4244479	0.36818203	3420.125
488.27905	1.4323589	0.36901596	3428.6284
489.17993	1.4317731	0.37003762	3429.7954
490.08081	1.4321102	0.370891	3424.0579
490.98169	1.4372942	0.37191442	3427.6328
491.88257	1.4403999	0.37270689	3422.908
492.78345	1.4410638	0.37355512	3432.8376
493.68433	1.4481897	0.37437519	3438.6543
494.58521	1.4492527	0.3751916	3431.0366
495.48608	1.4526109	0.37603804	3436.0046
496.38696	1.4533536	0.37688494	3439.3811
497.28784	1.4573555	0.37790284	3441.1375
498.18872	1.4597044	0.37881222	3438.4219
499.0896	1.4605101	0.37986481	3436.4775
499.99048	1.4641961	0.38075489	3436.1289
500.89136	1.4660003	0.3817037	3437.6655
501.79224	1.469658	0.38256305	3442.0054
502.69312	1.4735495	0.38381907	3444.1387
503.59399	1.4746307	0.38492432	3449.4382
504.49487	1.4777509	0.38576591	3437.0674
505.39575	1.4805129	0.38655752	3441.4248
506.29663	1.4820585	0.38754219	3447.4741
507.19751	1.4876307	0.38846573	3445.7031
508.09839	1.489347	0.38930589	3446.6504
508.99927	1.4918284	0.39024076	3447.5615
509.90015	1.4933876	0.39133215	3453.5298
510.80103	1.4958556	0.39234358	3448.7576
511.7019	1.4982516	0.39325634	3452.0332
512.60278	1.5028681	0.3941727	3457.1035
513.50366	1.5066988	0.39514619	3454.2971
514.40454	1.508427	0.39616337	3453.6147
515.30542	1.5114486	0.39703551	3455.729
516.2063	1.5128981	0.39811695	3460.729
517.10718	1.5188038	0.39899728	3457.6138
518.00806	1.5176786	0.40010604	3457.5815
518.90894	1.5204085	0.40099517	3456.0493
519.80981	1.5228916	0.40201318	3461.1516
520.71069	1.5282484	0.40293607	3465.1228
521.61157	1.5311126	0.40419853	3468.9922
522.51245	1.5333228	0.40510479	3461.1021
523.41333	1.5360087	0.40587527	3458.2656
524.31421	1.5382224	0.40676454	3465.4045
525.21509	1.5397445	0.4076829	3465.8337
526.11597	1.5427635	0.40854111	3463.8582
527.01685	1.5427902	0.40934542	3465.0613
527.91772	1.5477411	0.41043308	3474.1877
528.8186	1.5492818	0.41149804	3470.9509
529.71948	1.5532157	0.41261002	3473.9453
530.62036	1.5583818	0.41365927	3472.9839
531.52124	1.5607836	0.41444817	3466.8728
532.42212	1.5639826	0.41541269	3478.4304
533.323	1.5664513	0.41646361	3477.1223
534.22388	1.5697416	0.41732183	3477.4731
535.12476	1.5702231	0.41847405	3481.4082
536.02563	1.5721353	0.41942322	3480.4854
536.92651	1.574923	0.42032719	3477.5957
537.82739	1.5773631	0.42126882	3478.3049
538.72827	1.582994	0.42223933	3486.5063
539.62915	1.5840176	0.42337865	3486.3333
540.53003	1.5854424	0.42427903	3480.946
541.43091	1.5907549	0.42528707	3485.6687
542.33179	1.5926051	0.42622769	3482.5378
543.23267	1.5936515	0.42722297	3486.5537
544.13354	1.5939087	0.42817575	3483.7197
545.03442	1.5982759	0.42926514	3490.4846
545.9353	1.6008443	0.43043271	3494.0471
546.83618	1.6050355	0.43147478	3486.6145
547.73706	1.6065524	0.43240008	3486.4534
548.63794	1.6096746	0.4333522	3486.3633
549.53882	1.6122153	0.43436426	3490.9163
550.4397	1.6166517	0.43522203	3491.8555
551.34058	1.617638	0.43611678	3491.9121
552.24146	1.6246071	0.43714488	3499.4915
553.14233	1.6234366	0.43808937	3495.5569
554.04321	1.6247635	0.43899354	3496.1084
554.94409	1.6262425	0.43998975	3495.8545
555.84497	1.6306098	0.44091317	3490.5496
556.74585	1.6350474	0.44180188	3500.1833
557.64673	1.6360223	0.44276795	3497.6565
558.54761	1.6420888	0.44380912	3504.2637
559.44849	1.6434071	0.44501334	3499.9553
560.34937	1.6465738	0.44612253	3504.4417
561.25024	1.6468426	0.44696799	3495.3149
562.15112	1.6533947	0.44791263	3501.2686
563.052	1.6526281	0.44878581	3500.26
563.95288	1.6581239	0.44981796	3511.613
564.85376	1.6627822	0.45080459	3508.6426
565.75464	1.6614199	0.45181984	3503.1265
566.65552	1.663591	0.45267352	3503.158
567.5564	1.6700205	0.45356941	3507.4351
568.45728	1.671937	0.4545438	3510.7119
569.35815	1.672188	0.45556253	3510.0017
570.25903	1.6770016	0.4564074	3504.0164
571.15991	1.6784254	0.45740747	3507.666
572.06079	1.6812127	0.4585537	3519.7605
572.96167	1.6827551	0.45968354	3518.6748
573.86255	1.6849196	0.46070027	3509.7822
574.76343	1.6890597	0.46168679	3515.0356
575.66431	1.6909406	0.462892	3517.6304
576.56519	1.6967971	0.46394536	3518.2546
577.46606	1.6989884	0.46495038	3518.3777
578.36694	1.6978439	0.46592191	3512.9211
579.26782	1.7003263	0.4669148	3514.0117
580.1687	1.7068348	0.46806264	3525.3008
581.06958	1.7088106	0.46896499	3517.5854
581.97046	1.708861	0.46980634	3519.8503
582.87134	1.7142326	0.47093743	3524.0823
583.77222	1.7166425	0.47199845	3521.4204
584.6731	1.7182487	0.47305879	3519.4124
585.57397	1.7219349	0.47399992	3524.8784
586.47485	1.7265313	0.47480178	3519.8989
587.37573	1.7264786	0.47571543	3525.0444
588.27661	1.7318302	0.47695109	3530.5405
589.17749	1.7316667	0.47799274	3526.8784
590.07837	1.7368945	0.47899663	3527.7876
590.97925	1.7382805	0.47980678	3522.7866
591.88013	1.7411133	0.48097771	3531.5613
592.78101	1.7418696	0.4820829	3531.8218
593.68188	1.7456696	0.48321357	3533.8372
594.58276	1.74875	0.48448539	3536.4692
595.48364	1.7511654	0.48551494	3531.0098
596.38452	1.7533205	0.48646015	3529.6541
597.2854	1.7564577	0.48739246	3529.7144
598.18628	1.7596097	0.48829168	3531.7439
599.08716	1.7623988	0.48909745	3526.6616
599.98804	1.7628616	0.49004924	3530.1116
600.88892	1.7664144	0.49114501	3540.1135
601.78979	1.7690271	0.4923642	3545.2822
602.69067	1.7718664	0.49363986	3542.1162
603.59155	1.7748904	0.49460307	3537.2007
604.49243	1.782582	0.49568608	3539.9087
605.39331	1.7803153	0.49675885	3538.8088
606.29419	1.7837543	0.49790847	3545.3992
607.19507	1.7865933	0.49898401	3536.7571
608.09595	1.790899	0.49984139	3537.0637
608.99683	1.7936112	0.50082338	3543.6511
609.89771	1.7933176	0.50209141	3548.9048
610.79858	1.7968259	0.50328422	3543.5137
611.69946	1.8003151	0.50439674	3547.4368
612.60034	1.8027369	0.50537652	3541.0332
613.50122	1.8052959	0.50638103	3543.262
614.4021	1.8080488	0.5074724	3548.3916
615.30298	1.8109971	0.50844479	3545.082
616.20386	1.8118774	0.50935942	3538.8818
617.10474	1.8188468	0.51039761	3554.1592
618.00562	1.819654	0.51172942	3556.7839
618.90649	1.8229684	0.51285148	3552.3125
619.80737	1.8250297	0.51416522	3555.428
620.70825	1.8277422	0.51542532	3554.9934
621.60913	1.8291433	0.51661444	3558.2991
622.51001	1.8328358	0.51762444	3552.0168
623.41089	1.8351363	0.51876503	3553.7319
624.31177	1.8386645	0.51972449	3549.8508
625.21265	1.8385226	0.5206967	3550.2114
626.11353	1.8432776	0.52174467	3560.4436
627.0144	1.8457539	0.5227648	3555.1631
627.91528	1.8470379	0.52382404	3556.4282
628.81616	1.8527898	0.5248664	3559.4375
629.71704	1.8559849	0.52596146	3561.7251
630.61792	1.8590927	0.52704668	3566.7063
631.5188	1.8609943	0.5280636	3558.2002
632.41968	1.8605677	0.52911365	3559.4771
633.32056	1.8637373	0.53030866	3556.5076
634.22144	1.8676822	0.53127891	3559.4885
635.12231	1.8683079	0.53208643	3555.0247
636.02319	1.8738312	0.53311479	3557.8848
636.92407	1.8772123	0.53413796	3562.3167
637.82495	1.8789839	0.53524029	3564.5547
638.72583	1.8802751	0.53630465	3564.177
639.62671	1.8835734	0.53770459	3570.5264
640.52759	1.8861512	0.53874135	3560.8521
641.42847	1.88985	0.53963947	3559.2705
642.32935	1.8947417	0.54075778	3570.1699
643.23022	1.8920434	0.54199499	3567.4041
644.1311	1.8961189	0.54315448	3567.4939
645.03198	1.9003392	0.54438758	3567.8823
645.93286	1.9027153	0.54559284	3570.9526
646.83374	1.9037781	0.54683959	3564.7415
647.73462	1.90707	0.5478037	3566.2053
648.6355	1.9108238	0.54901171	3567.2493
649.53638	1.9167545	0.54994214	3570.6648
650.43726	1.915373	0.55086535	3568.7937
651.33813	1.9181216	0.55213112	3573.5945
652.23901	1.922242	0.55344111	3581.2715
653.13989	1.9228653	0.55471426	3575.9795
654.04077	1.925384	0.55589473	3567.5217
654.94165	1.9274998	0.55713731	3573.2065
655.84253	1.9311054	0.55825144	3573.7515
656.74341	1.9339099	0.55937469	3567.5332
657.64429	1.9354182	0.56070262	3579.4268
658.54517	1.9405204	0.56182903	3575.9304
659.44604	1.9448013	0.56288427	3574.0598
660.34692	1.942941	0.56396204	3573.6074
661.2478	1.9444085	0.56500357	3576.3918
662.14868	1.951986	0.56624103	3580.1797
663.04956	1.9534239	0.56747568	3582.166
663.95044	1.958105	0.56862491	3582.7129
664.85132	1.96067	0.56986362	3580.0232
665.7522	1.9631308	0.57111079	3590.3975
666.65308	1.9651289	0.57214499	3578.2703
667.55396	1.969844	0.57326317	3582.9365
668.45483	1.9680419	0.57448608	3577.7737
669.35571	1.968668	0.57549572	3580.4277
670.25659	1.9757735	0.57662827	3582.4353
671.15747	1.9764328	0.57769871	3585.2942
672.05835	1.9799643	0.57895994	3586.3315
672.95923	1.9825016	0.57997525	3578.6616
673.86011	1.9845148	0.58134508	3590.8506
674.76099	1.9891207	0.58257979	3589.864
675.66187	1.9890723	0.58378714	3583.0454
676.56274	1.9931432	0.58479851	3581.5601
677.46362	1.9971182	0.58587164	3587.7893
678.3645	2.0021858	0.58708805	3592.1995
679.26538	2.0028493	0.58819902	3591.1257
680.16626	2.0031426	0.58924562	3584.8093
681.06714	2.0082257	0.5904609	3590.0239
681.96802	2.0111604	0.59171134	3594.1807
682.8689	2.0136428	0.59291947	3595.6978
683.76978	2.0169947	0.59409148	3584.3118
684.67065	2.0193312	0.59525645	3588.6169
685.57153	2.0225325	0.59650189	3593.7961
686.47241	2.0225146	0.59763658	3589.9275
687.37329	2.0267658	0.59890431	3595.0508
688.27417	2.0285535	0.60012043	3594.127
689.17505	2.0317922	0.60161436	3594.7534
690.07593	2.0339575	0.60275692	3596.1069
690.97681	2.0370843	0.60405135	3591.7007
691.87769	2.0408995	0.6055547	3595.6987
692.77856	2.0440912	0.60686225	3590.4561
693.67944	2.0444307	0.60788202	3591.7283
694.58032	2.0466819	0.60896051	3586.2932
695.4812	2.0515783	0.61006147	3594.9119
696.38208	2.0548923	0.61135048	3592.7073
697.28296	2.0555327	0.61236697	3596.2358
698.18384	2.0566504	0.61361122	3590.8096
699.08472	2.0622683	0.61489284	3596.4182
699.9856	2.062083	0.61619985	3602.115
700.88647	2.0646923	0.61773324	3595.7771
701.78735	2.074101	0.61884862	3597.9727
702.68823	2.0745592	0.61996883	3595.4441
703.58911	2.0748241	0.62119359	3603.0337
704.48999	2.0775144	0.6225369	3599.7708
705.39087	2.0833724	0.62389934	3602.363
706.29175	2.0870202	0.6251412	3599.4043
707.19263	2.0859518	0.62625962	3595.6858
708.09351	2.0919561	0.62722409	3596.8596
708.99438	2.092031	0.62811691	3598.749
709.89526	2.091995	0.62905186	3598.1707
710.79614	2.0984669	0.63047147	3610.6572
711.69702	2.0983326	0.6317175	3606.6306
712.5979	2.1010075	0.63297457	3603.9868
713.49878	2.1047418	0.6342259	3605.3999
714.39966	2.1086125	0.63560164	3609.9919
715.30054	2.1087141	0.6371724	3615.7644
716.20142	2.1123712	0.63859642	3602.2751
717.10229	2.1159081	0.64004999	3604.949
718.00317	2.1175494	0.64126658	3602.5059
718.90405	2.1199169	0.64251769	3604.562
719.80493	2.123333	0.64367908	3604.0732
720.70581	2.126739	0.64458871	3597.7627
721.60669	2.1289787	0.64582705	3608.6191
722.50757	2.1322069	0.64720911	3611.8191
723.40845	2.1353154	0.64861691	3609.3352
724.30933	2.1386285	0.65012872	3609.6035
725.21021	2.1402066	0.65154648	3607.5889
726.11108	2.1435966	0.65288615	3610.8306
727.01196	2.1442177	0.65435487	3608.7332
727.91284	2.1470094	0.65560126	3606.1531
728.81372	2.1517084	0.65699559	3607.6821
729.7146	2.1506433	0.65829104	3607.3264
730.61548	2.1552994	0.65976197	3607.416
731.51636	2.1593018	0.66113091	3605.7529
732.41724	2.1620438	0.66259027	3611.4724
733.31812	2.1658854	0.6638512	3609.4302
734.21899	2.1673403	0.66532063	3615.5288
735.11987	2.1682909	0.66651851	3605.6172
736.02075	2.1714683	0.66759187	3604.9136
736.92163	2.1745322	0.66881007	3616.4727
737.82251	2.1781414	0.67039472	3618.1768
738.72339	2.1829073	0.67182899	3617.416
739.62427	2.1851666	0.67290175	3609.0122
740.52515	2.1871395	0.67420614	3613.8457
741.42603	2.1868331	0.67549556	3608.7878
742.3269	2.1923773	0.67693555	3617.1704
743.22778	2.1968207	0.67819321	3613.5293
744.12866	2.196038	0.67966235	3618.3333
745.02954	2.2014084	0.68094748	3615.8979
745.93042	2.2026474	0.68255091	3623.2102
746.8313	2.2063863	0.68378234	3612.0042
747.73218	2.2080133	0.68513536	3612.085
748.63306	2.210207	0.68649501	3616.0754
749.53394	2.2148423	0.68790323	3619.2659
750.43481	2.2156696	0.68928921	3615.9685
751.33569	2.218986	0.69078249	3619.8579
752.23657	2.2191508	0.69215381	3612.4673
753.13745	2.2235579	0.69360465	3620.1431
754.03833	2.2265804	0.69532746	3620.9158
754.93921	2.2305672	0.6968419	3621.4863
755.84009	2.233835	0.69844747	3618.7209
756.74097	2.2333374	0.69985837	3619.2415
757.64185	2.2379169	0.70124882	3607.0176
758.54272	2.2412426	0.70287228	3618.564
759.4436	2.2416372	0.70416135	3615.7258
760.34448	2.2461996	0.7055673	3623.1912
761.24536	2.2489107	0.70708746	3622.2207
762.14624	2.2498386	0.70862669	3613.9456
763.04712	2.2561126	0.70985246	3618.2969
763.948	2.2536922	0.71121216	3617.6858
764.84888	2.2594624	0.71291375	3625.915
765.74976	2.265388	0.71448755	3622.5308
766.65063	2.265095	0.7160297	3619.4553
767.55151	2.2685661	0.71732795	3618.4612
768.45239	2.2713349	0.71869171	3622.0815
769.35327	2.2739813	0.72030777	3624.9517
770.25415	2.2784228	0.7219187	3622.658
771.15503	2.2768929	0.72329849	3621.1121
772.05591	2.2829456	0.72483277	3622.3391
772.95679	2.2832983	0.72651225	3629.1008
773.85767	2.2831299	0.72792965	3619.2349
774.75854	2.2916074	0.72929353	3619.8848
775.65942	2.2923644	0.73077208	3622.9849
776.5603	2.2947881	0.73223042	3619.4255
777.46118	2.2971668	0.73376441	3625.478
778.36206	2.3018322	0.73555267	3627.1714
779.26294	2.3017991	0.73686111	3616.2327
780.16382	2.3048246	0.73826182	3618.8789
781.0647	2.3091221	0.73951912	3621.3347
781.96558	2.3109827	0.740978	3624.7166
782.86646	2.312566	0.74229842	3616.8623
783.76733	2.3157935	0.74376822	3621.2231
784.66821	2.3174798	0.74543434	3630.844
785.56909	2.3200343	0.74696267	3622.1064
786.46997	2.3243568	0.74855411	3621.1138
787.37085	2.3262389	0.7501663	3625.2493
788.27173	2.3271494	0.75195783	3619.594
789.17261	2.3332131	0.75341678	3620.5205
790.07349	2.3335371	0.7551592	3622.0652
790.97437	2.335731	0.75690687	3621.6646
791.87524	2.3402486	0.75850356	3624.9854
792.77612	2.3421483	0.76021409	3626.0232
793.677	2.3429296	0.7618888	3619.0544
794.57788	2.346966	0.76354665	3620.0608
795.47876	2.3503058	0.7650497	3619.3262
796.37964	2.3542678	0.76666903	3626.0969
797.28052	2.3561556	0.76845556	3627.4402
798.1814	2.3605592	0.77037144	3628.7278
799.08228	2.3630595	0.77216625	3621.427
799.98315	2.3624551	0.77357394	3616.9265
800.88403	2.3676074	0.77529484	3622.8044
801.78491	2.368191	0.77687585	3618.2036
802.68579	2.3716192	0.77885455	3627.1943
803.58667	2.3764813	0.78076059	3621.428
804.48755	2.3803544	0.78245336	3622.8787
805.38843	2.3806722	0.78425145	3620.8127
806.28931	2.3853374	0.78593063	3620.5762
807.19019	2.3843372	0.78736138	3618.7307
808.09106	2.3882372	0.78914493	3626.9963
808.99194	2.3917093	0.79118901	3620.6892
809.89282	2.3956652	0.7927826	3620.6118
810.7937	2.3959377	0.79426855	3621.1116
811.69458	2.4004002	0.79601789	3622.022
812.59546	2.4032178	0.79790831	3624.9248
813.49634	2.405442	0.79946339	3621.4316
814.39722	2.4091048	0.8011651	3623.2036
815.2981	2.4094324	0.80300391	3621.7703
816.19897	2.4127321	0.80467403	3618.4692
817.09985	2.4201157	0.80619222	3617.6777
818.00073	2.4187143	0.80790359	3626.8821
818.90161	2.4208372	0.80965179	3622.8318
819.80249	2.4228058	0.81143886	3620.9492
820.70337	2.4248483	0.81332618	3623.0667
821.60425	2.4287572	0.8151902	3624.1584
822.50513	2.4307127	0.81695038	3622.3621
823.40601	2.4369867	0.81875211	3619.8633
824.30688	2.4404922	0.82056749	3623.6475
825.20776	2.4399707	0.82241255	3615.8284
826.10864	2.4430387	0.82422888	3617.5149
827.00952	2.4453597	0.82606882	3622.3933
827.9104	2.4488242	0.82819641	3621.3147
828.81128	2.4526927	0.83007675	3617.9385
829.71216	2.4535098	0.83192313	3618.6665
830.61304	2.4592516	0.83361334	3617.6577
831.51392	2.4593678	0.83537275	3620.4187
832.41479	2.4627941	0.83745611	3617.9187
833.31567	2.464637	0.83939821	3619.8938
834.21655	2.4662178	0.84143126	3623.5691
835.11743	2.4702368	0.84364331	3618.0781
836.01831	2.4723217	0.84600681	3616.7756
836.91919	2.4774272	0.84808767	3620.8455
837.82007	2.4804056	0.84996188	3618.5798
838.72095	2.4839127	0.85183734	3624.2222
839.62183	2.4841337	0.8542102	3625.28
840.52271	2.4869993	0.85658342	3617.9629
841.42358	2.4885674	0.85860646	3615.1985
842.32446	2.4920194	0.86058247	3616.9966
843.22534	2.4945805	0.8626914	3613.0779
844.12622	2.4975402	0.8649146	3613.876
845.0271	2.5008798	0.86689228	3611.21
845.92798	2.5025072	0.86861116	3614.0676
846.82886	2.5041211	0.87030321	3613.9072
847.72974	2.5114284	0.87218291	3614.2764
848.63062	2.5105798	0.87415773	3623.8982
849.53149	2.5112529	0.87636846	3613.208
850.43237	2.5186474	0.87847179	3615.3367
851.33325	2.5228825	0.88039047	3614.9109
852.23413	2.5218282	0.8821187	3610.1812
853.13501	2.522927	0.8837167	3603.9907
854.03589	2.5285125	0.88543051	3610.8018
854.93677	2.5313683	0.88782394	3611.3911
855.83765	2.5301726	0.890104	3611.532
856.73853	2.5339525	0.89234644	3612.6667
857.6394	2.5358009	0.89403826	3604.4792
858.54028	2.5419829	0.89617276	3611.7786
859.44116	2.5423915	0.89839751	3609.8162
860.34204	2.5466695	0.90035921	3604.9546
861.24292	2.5446026	0.90255892	3607.3835
862.1438	2.5518126	0.90478945	3613.5967
863.04468	2.5542443	0.90712297	3604.7676
863.94556	2.5581019	0.90951991	3605.0166
864.84644	2.55884	0.91195291	3605.7412
865.74731	2.5649073	0.91411424	3603.8716
866.64819	2.5650332	0.91618848	3604.2878
867.54907	2.5685422	0.91822141	3603.5061
868.44995	2.5701184	0.9201737	3606.3157
869.35083	2.5717032	0.92243952	3605.5793
870.25171	2.5738232	0.92498916	3605.4922
871.15259	2.5779798	0.92760003	3602.4639
872.05347	2.579999	0.92983645	3597.731
872.95435	2.5814333	0.93218088	3596.6467
873.85522	2.5886464	0.93463618	3602.2644
874.7561	2.5901997	0.9370268	3604.2427
875.65698	2.5926795	0.93958902	3601.2354
876.55786	2.5931609	0.94192898	3598.4004
877.45874	2.5962155	0.94435143	3599.677
878.35962	2.5994887	0.94664359	3593.1125
879.2605	2.6025765	0.94895393	3595.7021
880.16138	2.6063082	0.95125139	3595.9692
881.06226	2.6080303	0.95348066	3589.5742
881.96313	2.6107581	0.95589113	3594.4299
882.86401	2.6153541	0.95861179	3599.1689
883.76489	2.6147652	0.96137023	3592.1445
884.66577	2.615088	0.9636628	3588.4255
885.56665	2.6231277	0.96575469	3586.1443
886.46753	2.6231768	0.96791977	3588.4192
887.36841	2.627975	0.9701665	3592.1619
888.26929	2.6292579	0.97247314	3587.6848
889.17017	2.6334455	0.97513402	3586.7954
890.07104	2.6344206	0.977763	3586.9629
890.97192	2.6365402	0.98017496	3584.2415
891.8728	2.6394064	0.98212713	3579.9514
892.77368	2.641	0.98426098	3580.0127
893.67456	2.6484346	0.98659295	3586.9167
894.57544	2.6502798	0.98889428	3579.6882
895.47632	2.6523359	0.99151212	3583.8982
896.3772	2.6539056	0.99403918	3580.6543
897.27808	2.6576879	0.99652004	3582.3892
898.17896	2.6564929	0.99934471	3581.9841
899.07983	2.6621606	1.0020684	3575.7644
899.98071	2.6639349	1.0046002	3573.3271
900.88159	2.6693103	1.0074102	3571.4988
901.78247	2.6734276	1.0098647	3574.8342
902.68335	2.6744046	1.0122943	3571.7949
903.58423	2.6757469	1.0148115	3573.6709
904.48511	2.6781464	1.0173758	3569.3796
905.38599	2.6790197	1.0201626	3572.0864
906.28687	2.6884692	1.0229417	3568.0867
907.18774	2.6877515	1.0258423	3572.2786
908.08862	2.6879632	1.028989	3567.7266
908.9895	2.6918383	1.0312636	3558.4041
909.89038	2.6962066	1.0337936	3562.9346
910.79126	2.6950402	1.0361756	3553.4929
911.69214	2.6986501	1.0383588	3553.0422
912.59302	2.7040179	1.0404166	3560.9292
913.4939	2.7089288	1.0428526	3557.6606
914.39478	2.7084367	1.0454665	3552.8406
915.29565	2.7111828	1.0486454	3562.0454
916.19653	2.7125905	1.0519034	3554.2661
917.09741	2.716522	1.0551047	3549.5098
917.99829	2.720453	1.0574872	3544.488
918.89917	2.7225611	1.0595419	3544.0916
919.80005	2.723155	1.0619032	3549.822
920.70093	2.7282526	1.0647273	3548.9788
921.60181	2.7293367	1.0675839	3544.7822
922.50269	2.7347419	1.0705314	3545.8137
923.40356	2.7342985	1.0729392	3540.8967
924.30444	2.7405167	1.0754035	3537.2324
925.20532	2.738337	1.0775286	3533.7361
926.1062	2.7418668	1.0799458	3536.6572
927.00708	2.7482064	1.0827706	3539.5142
927.90796	2.7478495	1.0859518	3539.719
928.80884	2.7488446	1.0887331	3524.9631
929.70972	2.7539742	1.0913054	3533.3315
930.6106	2.7590094	1.0944463	3532.4189
931.51147	2.761301	1.0973158	3527.9839
932.41235	2.7611618	1.1000975	3525.2036
933.31323	2.7634602	1.1028109	3521.0127
934.21411	2.7675467	1.1055309	3524.072
935.11499	2.7704332	1.1084965	3521.4595
936.01587	2.7723882	1.1116751	3520.4985
936.91675	2.7798462	1.1142728	3515.3994
937.81763	2.7776999	1.1167194	3511.3066
938.71851	2.7834494	1.1194553	3518.9375
939.61938	2.7826514	1.1224422	3509.9175
940.52026	2.7878194	1.1257677	3513.01
941.42114	2.7894216	1.1286914	3507.0942
942.32202	2.7919607	1.1313164	3503.7576
943.2229	2.7919841	1.1342919	3496.9695
944.12378	2.7970176	1.1365656	3495.7493
945.02466	2.8021286	1.1390299	3504.3916
945.92554	2.8017817	1.1420896	3497.0984
946.82642	2.8039665	1.1449927	3492.8188
947.72729	2.807025	1.1476226	3487.6921
948.62817	2.8127682	1.1501818	3496.7295
949.52905	2.8136725	1.1529516	3490.1316
950.42993	2.8180537	1.155479	3488.1189
951.33081	2.819761	1.1582372	3485.02
952.23169	2.8233433	1.1612048	3481.5796
953.13257	2.827872	1.1638702	3479.6052
954.03345	2.8272774	1.1668286	3480.1824
954.93433	2.8283079	1.1697789	3472.7346
955.83521	2.8316343	1.1726079	3472.085
956.73608	2.8359594	1.1755936	3472.3943
957.63696	2.8376312	1.1790568	3465.4189
958.53784	2.8411093	1.1818049	3464.9048
959.43872	2.8416786	1.1842357	3454.6948
960.3396	2.8444023	1.1866021	3455.1855
961.24048	2.8483748	1.189049	3458.7375
962.14136	2.8524616	1.1917529	3455.4663
963.04224	2.8534369	1.1946641	3458.5215
963.94312	2.8566153	1.1979322	3451.5278
964.84399	2.8628478	1.201143	3454.8188
965.74487	2.8638201	1.2043307	3453.6343
966.64575	2.8648014	1.2075073	3441.511
967.54663	2.8678784	1.2100621	3437.845
968.44751	2.8683884	1.2126153	3434.8372
969.34839	2.8727872	1.2157613	3438.958
970.24927	2.8756413	1.2187699	3432.406
971.15015	2.8798158	1.2216829	3434.1753
972.05103	2.8823328	1.2241998	3428.21
972.9519	2.88238	1.2267512	3424.3374
973.85278	2.8895864	1.229647	3426.3389
974.75366	2.8898153	1.232867	3422.7275
975.65454	2.8928428	1.2360715	3414.0452
976.55542	2.8942578	1.2391896	3415.9243
977.4563	2.8952634	1.2424343	3410.1978
978.35718	2.9015341	1.2455256	3405.7871
979.25806	2.9039619	1.2480912	3403.335
980.15894	2.9063761	1.250497	3401.5911
981.05981	2.9078059	1.2540767	3404.1414
981.96069	2.910933	1.2577034	3396.4709
982.86157	2.9158161	1.260347	3392.9192
983.76245	2.9171708	1.2629179	3395.3042
984.66333	2.9188819	1.266055	3390.7739
985.56421	2.92135	1.2695504	3382.144
986.46509	2.9261231	1.272419	3375.9917
987.36597	2.9264815	1.2752806	3375.7131
988.26685	2.9296181	1.2782634	3375.6804
989.16772	2.9337809	1.2809327	3375.0125
990.0686	2.9360728	1.284099	3370.4438
990.96948	2.9396379	1.2874572	3363.9221
991.87036	2.9418976	1.29041	3360.8459
992.77124	2.9446144	1.2928339	3359.0549
993.67212	2.9475784	1.2950748	3357.323
994.573	2.9512143	1.2976213	3355.564
995.47388	2.951581	1.2999154	3346.7512
996.37476	2.9583614	1.3026118	3355.8193
997.27563	2.9581151	1.3057437	3342.6357
998.17651	2.9609339	1.308539	3339.5508
999.07739	2.9591932	1.3108916	3334.8206
999.97827	2.9655561	1.3135802	3336.7954
1000.8792	2.9677141	1.3168536	3334.2593
1001.78	2.9729955	1.3205578	3332.4395
1002.6809	2.9730687	1.3237262	3328.6453
1003.5818	2.9740875	1.3266108	3316.6086
1004.4827	2.9771647	1.3290497	3313.5303
1005.3835	2.9871874	1.3312503	3312.3411
1006.2844	2.9827774	1.3337876	3307.4485
1007.1853	2.984947	1.3361757	3299.0417
1008.0862	2.9869566	1.3381419	3297.5591
1008.9871	2.9913108	1.3404171	3297.9851
1009.8879	2.9960759	1.3434259	3310.9536
1010.7888	2.9956601	1.3465725	3291.5825
1011.6897	3.0010228	1.3496864	3293.4597
1012.5906	3.003109	1.3530735	3290.3479
1013.4915	3.0054736	1.3563243	3285.0752
1014.3923	3.0093889	1.3596846	3284.3611
1015.2932	3.0108609	1.3627579	3274.9172
1016.1941	3.0138452	1.3660936	3276.9929
1017.095	3.0167654	1.3692129	3262.063
1017.9958	3.02266	1.372094	3265.1365
1018.8967	3.0229044	1.3747394	3257.5847
1019.7976	3.0265667	1.3773537	3256.2876
1020.6985	3.0272737	1.3803132	3252.3237
1021.5994	3.0300646	1.3837878	3246.282
1022.5002	3.034806	1.3873346	3245.3699
1023.4011	3.0361691	1.3906056	3240.1709
1024.302	3.0372016	1.3939058	3234.946
1025.2029	3.0404477	1.3967882	3224.7271
1026.1038	3.0427651	1.3993404	3224.5278
1027.0046	3.0475929	1.4024829	3226.0864
1027.9055	3.0465724	1.4055768	3220.2524
1028.8064	3.0519605	1.4086562	3213.1221
1029.7073	3.05495	1.4111601	3203.6008
1030.6082	3.0589447	1.4142218	3209.1584
1031.509	3.0599983	1.4169816	3203.3777
1032.4099	3.062181	1.4198551	3200.731
1033.3108	3.06409	1.4234848	3191.2029
1034.2117	3.0674837	1.4261959	3183.7573
1035.1125	3.0708733	1.4292296	3183.5361
1036.0134	3.0754871	1.4327044	3181.4011
1036.9143	3.0759106	1.4354228	3166.2053
1037.8152	3.0797195	1.4379852	3171.1816
1038.7161	3.0807755	1.4410418	3162.0544
1039.6169	3.0826092	1.4444749	3160.1775
1040.5178	3.089128	1.4477292	3150.145
1041.4187	3.0920005	1.4509504	3148.4968
1042.3196	3.0911424	1.4547306	3144.9709
1043.2205	3.095	1.4585334	3140.8901
1044.1213	3.0998037	1.462214	3130.6045
1045.0222	3.1017406	1.4647095	3119.7151
1045.9231	3.105551	1.4675349	3121.9312
1046.824	3.1077366	1.4706599	3114.5681
1047.7249	3.1101794	1.4741832	3112.0186
1048.6257	3.1126978	1.4775028	3105.6636
1049.5266	3.1136224	1.4812119	3096.4153
1050.4275	3.1171319	1.4848856	3099.1094
1051.3284	3.1213071	1.488115	3082.8491
1052.2292	3.122175	1.4904518	3071.5959
1053.1301	3.1252742	1.4934534	3079.8276
1054.031	3.1264536	1.4968324	3071.0083
1054.9319	3.1303191	1.4998219	3068.6716
1055.8328	3.1332898	1.5019664	3056.4456
1056.7336	3.1344874	1.5048786	3055.4302
1057.6345	3.138617	1.508214	3058.6387
1058.5354	3.1405032	1.5115538	3045.5315
1059.4363	3.1459346	1.5148034	3039.5403
1060.3372	3.1479747	1.5184252	3031.9641
1061.238	3.1445258	1.5221674	3025.2261
1062.1389	3.1514938	1.5251831	3013.1045
1063.0398	3.1555803	1.52839	3015.4714
1063.9407	3.1564558	1.5314007	3001.6218
1064.8416	3.1622589	1.53517	3001.1987
1065.7424	3.1619136	1.5385079	2986.9351
1066.6433	3.1657088	1.5414209	2981.5886
1067.5442	3.1680691	1.5447385	2979.6638
1068.4451	3.1720512	1.5475791	2976.9741
1069.3459	3.1729767	1.5508318	2963.511
1070.2468	3.1797245	1.5545728	2962.6938
1071.1477	3.1782279	1.5579284	2952.074
1072.0486	3.1837649	1.5611172	2946.9429
1072.9495	3.1840959	1.5643009	2934.4829
1073.8503	3.1855757	1.5671077	2927.6753
1074.7512	3.1883154	1.5696136	2924.281
1075.6521	3.1931562	1.5724384	2921.3833
1076.553	3.1993098	1.5758955	2919.1733
1077.4539	3.1985681	1.5792767	2909.2126
1078.3547	3.2015932	1.5831211	2894.5183
1079.2556	3.2061362	1.5881631	2890.1123
1080.1565	3.2056627	1.5921119	2872.0137
1081.0574	3.2101054	1.5956157	2862.9307
1081.9583	3.211591	1.5989856	2857.4055
1082.8591	3.2151179	1.6023235	2852.1868
1083.76	3.2175953	1.6056011	2836.6753
1084.6609	3.2193623	1.6088688	2830.6667
1085.5618	3.2226913	1.6129125	2818.8716
1086.4626	3.2252185	1.616942	2805.8123
1087.3635	3.231616	1.6200563	2797.5591
1088.2644	3.2319832	1.623858	2796.3491
1089.1653	3.2350895	1.627373	2774.6296
1090.0662	3.236655	1.630411	2767.8208
1090.967	3.239079	1.6337911	2761.8257
1091.8679	3.2424257	1.6373856	2749.5981
1092.7688	3.2441328	1.640967	2733.6487
1093.6697	3.2485256	1.6466119	2708.021
1094.5706	3.2531536	1.654092	2667.5327
1095.4714	3.2518346	1.6591229	2625.5725
1095.8718	3.2528811	1.6613483	2617.9976