File: datasets/am_bench_2022/raw_data/60-XY.15-2/specimen.dat
MTS793|MPT|ENU|1|2|.|/|:|1|0|0|A

Operator Information						Time:	17.394775	Sec	11/2/2021 9:35:08 AM
Operator	Nick Derimow
Project	AM Bench 2022 mini-tensile challenge
Specimen ID	60-XY.15-2
Material	PBF-L Inconel 625
Specimen Width	2.55	mm
Specimen Thickness	1.51	mm
Notes
Operator Information End

Data Acquisition						Time:	1018.3899	Sec	11/2/2021 9:51:49 AM
Time	Axial Displacement	Axial Extensometer	Axial Force
Sec	mm	mm	N
17.509766	-0.00097527372	3.0235062e-05	50.290565
18.510742	0.00082817656	4.8404792e-05	62.159458
19.511719	0.0050132284	6.1890714e-05	76.985909
20.512695	0.0046643503	0.00016857233	85.704559
21.513672	0.011209695	0.00016051294	102.51189
22.514648	0.013858884	0.00031570246	117.51438
23.515625	0.017434845	0.00033426558	129.14728
24.516602	0.019076791	0.0003363186	140.74841
25.517578	0.019382488	0.00030634305	153.55402
26.518555	0.024476025	0.00049021939	168.97281
27.519531	0.028622149	0.00056315953	188.99251
28.520508	0.030382367	0.00052298041	204.81665
29.521484	0.033507314	0.00065920729	223.06924
30.522461	0.038766351	0.00074051518	240.39323
31.523438	0.038984559	0.00069585408	254.83156
32.524414	0.04366222	0.00092287024	273.1474
33.525391	0.046180278	0.00085025688	297.0069
34.526367	0.049635511	0.0010454012	311.3501
35.527344	0.052065261	0.0010434547	333.0737
36.52832	0.053806834	0.0011867175	353.47192
37.529297	0.057774547	0.0010792204	369.54962
38.530273	0.060844991	0.0013185956	393.82718
39.53125	0.06656073	0.0013153378	419.04477
40.532227	0.069430023	0.0014421726	449.17529
41.533203	0.068104379	0.0015412649	467.83267
42.53418	0.071520939	0.001481905	488.05801
43.535156	0.077798694	0.0016838834	510.8717
44.536133	0.079276934	0.0016851701	530.21826
45.537109	0.08011084	0.001886789	561.09283
46.538086	0.083020493	0.0019102808	576.86365
47.539063	0.086054265	0.0020313878	603.44696
48.540039	0.088379569	0.0022474339	627.26935
49.541016	0.095403545	0.0022728159	650.05151
50.541992	0.096512005	0.0024222408	683.33905
51.542969	0.099903509	0.0024397427	705.03558
52.543945	0.10157112	0.002634268	732.93042
53.544922	0.10410372	0.0026925299	754.90161
54.545898	0.10755362	0.0028457136	783.96912
55.546875	0.11059892	0.0029254674	809.367
56.547852	0.113922	0.0031118107	835.80823
57.548828	0.11853855	0.0032357101	869.19507
58.549805	0.12120249	0.003341601	897.15936
59.550781	0.12046488	0.0034358087	913.15045
60.551758	0.12788065	0.0036036042	949.21283
61.552734	0.12954289	0.00366128	972.74908
62.553711	0.13283359	0.0037548486	988.97211
63.554688	0.13494457	0.0039923922	1035.1609
64.555664	0.1360891	0.0040396233	1053.692
65.556641	0.14150207	0.0041943141	1082.9082
66.557617	0.14341138	0.0042661643	1106.2239
67.558594	0.14679429	0.0043754727	1139.0322
68.55957	0.15226202	0.0045459974	1168.1292
69.560547	0.15525645	0.0047585899	1195.5308
70.561523	0.15492781	0.0048268707	1221.0598
71.5625	0.15942383	0.0049696337	1239.5867
72.563477	0.1604118	0.0049744775	1271.0254
73.564453	0.16490465	0.0051477179	1305.6046
74.56543	0.16584101	0.0052999961	1324.8955
75.566406	0.16783926	0.0054108603	1353.0771
76.567383	0.1736851	0.0054950458	1377.2528
77.568359	0.17748584	0.005641459	1410.8815
78.569336	0.17915857	0.0057969866	1440.0128
79.570313	0.18476018	0.0059697805	1472.1404
80.571289	0.18656071	0.0061186329	1498.0769
81.572266	0.18848935	0.0061673834	1517.2156
82.573242	0.1920774	0.0063719321	1548.2307
83.574219	0.19643635	0.0065307003	1588.359
84.575195	0.19983482	0.0066924556	1617.1254
85.576172	0.20163295	0.006847315	1647.4209
86.577148	0.20301269	0.0068795681	1663.0352
87.578125	0.20587419	0.0070500928	1688.3422
88.579102	0.20684205	0.0071603763	1714.9274
89.580078	0.21511872	0.0073007778	1746.7181
90.581055	0.21464399	0.0075418996	1766.7521
91.582031	0.21958104	0.00750111	1783.207
92.583008	0.22048783	0.0076673166	1813.5979
93.583984	0.2250921	0.0077227997	1832.9375
94.584961	0.22700717	0.0078283492	1849.2363
95.585938	0.23098533	0.0079812752	1884.3291
96.586914	0.23671992	0.008111313	1914.7771
97.587891	0.23473908	0.0082909632	1938.2483
98.588867	0.24026509	0.0083787749	1966.1771
99.589844	0.24302559	0.0085754273	1984.9946
100.59082	0.24736431	0.0087169725	2010.0381
101.5918	0.24792735	0.0087894006	2030.9723
102.59277	0.25155652	0.0088004973	2050.9199
103.59375	0.25679165	0.0090078451	2068.7065
104.59473	0.25733727	0.0091363592	2094.3208
105.5957	0.2622411	0.0093081826	2124.1331
106.59668	0.26541519	0.0094267726	2141.3799
107.59766	0.26815885	0.009398534	2162.5955
108.59863	0.27119061	0.0095670344	2178.0161
109.59961	0.27231526	0.0096952794	2196.8694
110.60059	0.27756262	0.0098287724	2218.9646
111.60156	0.28094554	0.0099219345	2237.8872
112.60254	0.28295571	0.010071275	2261.1062
113.60352	0.28328949	0.010192601	2270.0234
114.60449	0.28822443	0.010210914	2286.897
115.60547	0.29217529	0.01032732	2304.186
116.60645	0.29437473	0.010459968	2316.4844
117.60742	0.29574487	0.010611713	2328.9353
118.6084	0.30122072	0.010717882	2348.8369
119.60938	0.30304506	0.010828665	2356.3054
120.61035	0.30873355	0.010931491	2378.5061
121.61133	0.31054726	0.01105628	2395.4038
122.6123	0.3174403	0.011205935	2413.9028
123.61328	0.31352392	0.011323766	2412.7563
124.61426	0.32004467	0.011439406	2433.7214
125.61523	0.32109836	0.011462292	2440.5703
126.61621	0.32554859	0.011649977	2454.8064
127.61719	0.32844263	0.011885804	2472.8589
128.61816	0.33267644	0.011926569	2479.428
129.61914	0.33392608	0.012165657	2491.5288
130.62012	0.33725387	0.012192441	2500.498
131.62109	0.33991191	0.01234371	2513.05
132.62207	0.3437835	0.012460361	2528.3586
133.62305	0.34760049	0.012690263	2536.1958
134.62402	0.34961888	0.012804308	2535.9124
135.625	0.35082835	0.013020105	2559.7739
136.62598	0.35587865	0.013186524	2563.24
137.62695	0.35953489	0.013321136	2575.0081
138.62793	0.36192223	0.013429484	2582.6465
139.62891	0.36256045	0.013849581	2597.6672
140.62988	0.37062001	0.013971743	2609.8713
141.63086	0.37118319	0.014187753	2612.7488
142.63184	0.3731944	0.014314874	2619.4204
143.63281	0.3765218	0.014627255	2636.7563
144.63379	0.37956175	0.014971689	2641.0522
145.63477	0.38515127	0.015216121	2656.926
146.63574	0.38492343	0.015496454	2662.3403
147.63672	0.38817275	0.015714046	2669.3115
148.6377	0.39412731	0.015941279	2672.1411
149.63867	0.39658388	0.016324623	2684.3359
150.63965	0.39904785	0.016648117	2694.6824
151.64063	0.40332225	0.017040897	2700.9348
152.6416	0.40516195	0.0174272	2710.7214
153.64258	0.40842929	0.017739935	2719.8538
154.64355	0.40890568	0.018057808	2715.3364
155.64453	0.41402996	0.018482067	2734.1919
156.64551	0.41583151	0.018969029	2734.9412
157.64648	0.41914397	0.019295471	2741.7434
158.64746	0.42293277	0.019757826	2750.2759
159.64844	0.42447007	0.020194944	2753.8022
160.64941	0.429297	0.020803394	2765.3279
161.65039	0.43091828	0.021147491	2768.7644
162.65137	0.43281987	0.021709345	2771.0945
163.65234	0.43932343	0.022209434	2780.5359
164.65332	0.43932444	0.02275544	2780.4685
165.6543	0.44342017	0.023269502	2787.6362
166.65527	0.44674903	0.023806499	2792.1462
167.65625	0.45141393	0.024417747	2807.2441
168.65723	0.45017865	0.025181256	2808.3936
169.6582	0.4551402	0.025920713	2811.2935
170.65918	0.45687479	0.026504502	2813.6235
171.66016	0.46188924	0.027207999	2820.3806
172.66113	0.46192735	0.027946491	2829.7397
173.66211	0.46801707	0.028792799	2837.0974
174.66309	0.47193393	0.029605633	2848.0012
175.66406	0.47290635	0.03039277	2846.9309
176.66504	0.47584218	0.031197844	2847.8572
177.66602	0.47744954	0.031992115	2851.707
178.66699	0.48337653	0.032688841	2854.2229
179.66797	0.4854404	0.033514295	2858.9861
180.66895	0.48696786	0.034350015	2872.3369
181.66992	0.49313661	0.035323542	2877.8157
182.6709	0.49497938	0.036283549	2871.531
183.67188	0.49612612	0.037040353	2881.0579
184.67285	0.50142032	0.038070496	2891.1104
185.67383	0.50256109	0.039036222	2889.2446
186.6748	0.50704873	0.039907213	2889.6848
187.67578	0.50667727	0.040969953	2890.9849
188.67676	0.51056749	0.041958705	2897.688
189.67773	0.51297516	0.042882536	2897.9727
190.67871	0.51850039	0.04376917	2901.5237
191.67969	0.52099818	0.044642888	2904.4182
192.68066	0.52702236	0.04560693	2910.5786
193.68164	0.52853078	0.0464416	2910.0198
194.68262	0.52628225	0.047447633	2910.6892
195.68359	0.53019583	0.048428759	2916.71
196.68457	0.5402317	0.049583394	2924.9802
197.68555	0.53732842	0.050564028	2933.116
198.68652	0.54282826	0.051798489	2927.373
199.6875	0.54508269	0.052788045	2933.3347
200.68848	0.55039704	0.053768836	2936.7927
201.68945	0.55294096	0.054912943	2937.2732
202.69043	0.55397892	0.055787034	2933.603
203.69141	0.55655497	0.056685947	2936.8669
204.69238	0.5619911	0.057828072	2952.3367
205.69336	0.56366152	0.059013002	2950.4941
206.69434	0.56314987	0.059979852	2942.5137
207.69531	0.5678618	0.061061095	2952.4761
208.69629	0.57384282	0.062246855	2957.8054
209.69727	0.57597369	0.063391402	2952.2742
210.69824	0.57798654	0.064490661	2964.2168
211.69922	0.58198166	0.065656699	2955.3196
212.7002	0.58469296	0.066691428	2966.6411
213.70117	0.58768106	0.067885287	2970.1492
214.70215	0.58890301	0.068933301	2972.113
215.70313	0.59630358	0.069999993	2975.5215
216.7041	0.59568852	0.071233779	2980.0603
217.70508	0.60176098	0.072530232	2983.3718
218.70605	0.60433477	0.073703766	2974.415
219.70703	0.60677254	0.075030595	2984.6262
220.70801	0.60641915	0.076274619	2981.6099
221.70898	0.61287516	0.077352814	2984.9526
222.70996	0.61590689	0.078513607	2989.7671
223.71094	0.61887842	0.079453394	2989.8013
224.71191	0.62033433	0.080652431	2996.437
225.71289	0.62394202	0.082003251	3001.8501
226.71387	0.62486666	0.083201326	2998.0193
227.71484	0.62881428	0.084328003	2998.5398
228.71582	0.63128686	0.085334376	2996.3647
229.7168	0.63757205	0.086492717	3008.6003
230.71777	0.63675267	0.087632708	3008.2939
231.71875	0.63934129	0.088999465	3009.8767
232.71973	0.64600092	0.090194523	3011.0798
233.7207	0.64732677	0.091299661	3008.9954
234.72168	0.65156734	0.092232257	3010.2188
235.72266	0.65120822	0.093315415	3012.5168
236.72363	0.65506071	0.09443263	3017.6753
237.72461	0.6605128	0.095563866	3016.208
238.72559	0.66213167	0.096821688	3026.7473
239.72656	0.66215295	0.098090842	3019.178
240.72754	0.66809016	0.099230915	3026.9729
241.72852	0.67069328	0.10060059	3026.666
242.72949	0.67546928	0.10174997	3034.7952
243.73047	0.6793626	0.10309189	3034.7046
244.73145	0.67978179	0.10423575	3031.7349
245.73242	0.68326646	0.10546516	3036.1086
246.7334	0.68774372	0.10659796	3043.6147
247.73438	0.6899184	0.10793622	3038.1604
248.73535	0.69359553	0.10881598	3035.5876
249.73633	0.69604826	0.10979575	3038.4919
250.7373	0.69992375	0.11083622	3043.4163
251.73828	0.6993072	0.11222522	3042.2317
252.73926	0.70517421	0.11336021	3048.2668
253.74023	0.70734888	0.11461934	3055.2681
254.74121	0.70878661	0.11601101	3051.5513
255.74219	0.71322405	0.11754793	3058.5776
256.74316	0.7130233	0.11877844	3051.9939
257.74414	0.71712267	0.11994396	3050.4802
258.74512	0.72207505	0.12094688	3054.8687
259.74609	0.72400773	0.12224314	3062.8362
260.74707	0.72784144	0.12362336	3060.561
261.74805	0.73054743	0.12523662	3067.7114
262.74902	0.73504925	0.12655394	3063.1641
263.75	0.73804653	0.12758537	3073.8945
264.75098	0.74137539	0.12864296	3066.0693
265.75195	0.74382931	0.12991528	3071.1323
266.75293	0.74641156	0.13122982	3074.6282
267.75391	0.75147986	0.13257457	3080.4268
268.75488	0.75269896	0.13371669	3072.8616
269.75586	0.75355089	0.13474566	3066.7683
270.75684	0.75524431	0.13580002	3073.8232
271.75781	0.76326114	0.13697168	3081.644
272.75879	0.76591468	0.13808715	3080.209
273.75977	0.76561981	0.1391672	3084.0027
274.76074	0.77139562	0.14027028	3088.3994
275.76172	0.77317101	0.141427	3083.7483
276.7627	0.77486908	0.14237528	3085.5232
277.76367	0.78024417	0.14352541	3091.9043
278.76465	0.78317308	0.14469495	3092.1218
279.76563	0.78618163	0.14597376	3096.5603
280.7666	0.78920394	0.14741595	3094.0603
281.76758	0.79261065	0.14868455	3094.6062
282.76855	0.79669881	0.14987031	3098.4939
283.76953	0.79876918	0.15086979	3099.0298
284.77051	0.80101758	0.15222077	3103.0437
285.77148	0.80427021	0.15347005	3102.5674
286.77246	0.80731958	0.15469551	3103.2378
287.77344	0.81026489	0.15597256	3112.0713
288.77441	0.81359905	0.15749352	3112.6721
289.77539	0.81912851	0.15884386	3110.1367
290.77637	0.81760538	0.16008531	3100.4985
291.77734	0.82061011	0.16117173	3106.9995
292.77832	0.82491994	0.162393	3116.6404
293.7793	0.83018148	0.16339731	3112.1943
294.78027	0.83130199	0.16436353	3113.6563
295.78125	0.83402926	0.16558713	3121.9756
296.78223	0.83638757	0.16686179	3124.8318
297.7832	0.84298271	0.16826943	3127.925
298.78418	0.84478056	0.16946429	3123.1836
299.78516	0.84743494	0.17080981	3124.8655
300.78613	0.84903741	0.17189778	3124.2542
301.78711	0.85249346	0.17309158	3126.1892
302.78809	0.85253257	0.17429967	3122.1208
303.78906	0.85887671	0.17564572	3136.3621
304.79004	0.86110348	0.17681445	3131.6577
305.79102	0.86724049	0.17787622	3131.8176
306.79199	0.86534834	0.1789816	3133.1941
307.79297	0.87188363	0.18009825	3135.8872
308.79395	0.87262863	0.18120062	3134.4976
309.79492	0.87393463	0.18231857	3138.229
310.7959	0.87986141	0.18369097	3143.2517
311.79688	0.87978315	0.18503116	3142.8
312.79785	0.88381499	0.18616943	3141.8396
313.79883	0.88959879	0.18749593	3146.0986
314.7998	0.88975447	0.18879296	3145.678
315.80078	0.89710426	0.19008547	3149.8979
316.80176	0.89614677	0.19119509	3146.5762
317.80273	0.89811963	0.19232956	3147.9148
318.80371	0.90177858	0.19346499	3148.6963
319.80469	0.90449029	0.19466782	3146.6685
320.80566	0.90892243	0.19574809	3156.0332
321.80664	0.91182548	0.19682379	3152.4263
322.80762	0.91424257	0.1980097	3161.8015
323.80859	0.91760647	0.1993178	3158.0156
324.80957	0.92001241	0.20060876	3164.6401
325.81055	0.9253698	0.20211932	3164.7832
326.81152	0.92927015	0.20333734	3167.2773
327.8125	0.93349922	0.2045002	3162.8271
328.81348	0.93253565	0.20576818	3169.3899
329.81445	0.93340725	0.20689639	3161.2244
330.81543	0.93972105	0.20813911	3167.4929
331.81641	0.93957269	0.20903517	3168.6587
332.81738	0.94387114	0.21007629	3163.2061
333.81836	0.94721365	0.21157609	3169.4482
334.81934	0.94941086	0.21251775	3170.2981
335.82031	0.95493323	0.21385828	3182.0188
336.82129	0.95483613	0.2151072	3174.739
337.82227	0.96043181	0.21628958	3172.8105
338.82324	0.96163535	0.21741949	3180.8486
339.82422	0.96595645	0.21863273	3178.3438
340.8252	0.96850508	0.21986867	3183.1272
341.82617	0.9710744	0.22115515	3178.1499
342.82715	0.97649264	0.22214502	3180.4126
343.82813	0.97812891	0.22325276	3179.1047
344.8291	0.98353571	0.22452721	3187.0959
345.83008	0.98493981	0.2258402	3188.4175
346.83105	0.98711491	0.22708149	3192.6555
347.83203	0.98841268	0.22847499	3197.1125
348.83301	0.99414605	0.22982007	3193.7927
349.83398	0.99471951	0.23095027	3194.873
350.83496	0.9981705	0.23227152	3203.5972
351.83594	0.99939179	0.23348735	3198.1252
352.83691	1.0026145	0.23459616	3189.2314
353.83789	1.0065262	0.23580502	3204.9304
354.83887	1.0087444	0.23695973	3199.4619
355.83984	1.0134974	0.23820789	3202.5913
356.84082	1.0187135	0.23962644	3200.1956
357.8418	1.0206132	0.24078599	3206.2124
358.84277	1.0217376	0.24180461	3208.7109
359.84375	1.0258417	0.24300857	3207.6985
360.84473	1.0292193	0.24431929	3209.271
361.8457	1.0324557	0.24576218	3218.147
362.84668	1.0328341	0.24720262	3215.3013
363.84766	1.0377644	0.24839307	3214.0005
364.84863	1.0398055	0.24953352	3211.6592
365.84961	1.0454583	0.25061563	3217.7769
366.85059	1.0453182	0.25194287	3212.342
367.85156	1.0484159	0.2531077	3219.6165
368.85254	1.0534705	0.25424084	3217.9722
369.85352	1.0569323	0.25559318	3217.261
370.85449	1.0613526	0.25681323	3226.373
371.85547	1.0643823	0.25790009	3222.9924
372.85645	1.0676693	0.2591041	3228.1743
373.85742	1.0688241	0.26022729	3225.3315
374.8584	1.070037	0.26137227	3220.3333
375.85938	1.0750184	0.26244029	3224.106
376.86035	1.0772262	0.26344082	3224.4358
377.86133	1.0789297	0.26452917	3224.6609
378.8623	1.0824475	0.26560703	3234.8994
379.86328	1.0888531	0.26687044	3232.897
380.86426	1.0869457	0.26807743	3233.4846
381.86523	1.0931505	0.26931304	3234.8254
382.86621	1.0946915	0.27040887	3232.7263
383.86719	1.0998231	0.27155015	3232.8091
384.86816	1.1000515	0.27288231	3236.9888
385.86914	1.1037178	0.27430752	3243.248
386.87012	1.1082848	0.275619	3241.9521
387.87109	1.1110151	0.27697751	3246.4075
388.87207	1.113609	0.27817711	3238.4941
389.87305	1.1146681	0.27938023	3242.5493
390.87402	1.115378	0.28056797	3240.1658
391.875	1.1226376	0.28195992	3250.0056
392.87598	1.1274726	0.28309754	3250.1841
393.87695	1.1286526	0.28425196	3246.2024
394.87793	1.1305699	0.28538802	3250.2302
395.87891	1.1330749	0.28645694	3248.1931
396.87988	1.136742	0.28780821	3255.7939
397.88086	1.1411407	0.28922048	3257.7292
398.88184	1.1423779	0.29052323	3253.7495
399.88281	1.146827	0.29147997	3253.9429
400.88379	1.1465907	0.29270813	3249.4229
401.88477	1.1519834	0.29386029	3257.6414
402.88574	1.1525939	0.29501063	3255.7786
403.88672	1.1603875	0.29612634	3262.554
404.8877	1.1598847	0.2972247	3258.6641
405.88867	1.1617124	0.29818454	3259.105
406.88965	1.1673715	0.29962215	3267.7295
407.89063	1.1712047	0.30086696	3268.8447
408.8916	1.1734148	0.30220315	3269.3413
409.89258	1.1774102	0.30332217	3266.1389
410.89355	1.1767976	0.30443236	3267.7085
411.89453	1.1824034	0.30566087	3269.9426
412.89551	1.1846945	0.30690446	3267.8586
413.89648	1.1886556	0.30828118	3278.6035
414.89746	1.1886225	0.30937931	3262.7617
415.89844	1.1945355	0.31067297	3273.8699
416.89941	1.1960857	0.31190518	3273.7815
417.90039	1.199216	0.31319648	3270.0413
418.90137	1.2038869	0.31432146	3279.7874
419.90234	1.2065547	0.31553203	3279.3606
420.90332	1.210098	0.31689087	3281.3167
421.9043	1.2113637	0.31807107	3280.6521
422.90527	1.2156041	0.3192142	3283.511
423.90625	1.2189919	0.32000002	3274.6057
424.90723	1.2201536	0.32109827	3277.2324
425.9082	1.2231477	0.32233819	3287.8601
426.90918	1.2274619	0.32365549	3291.0378
427.91016	1.2312669	0.32510296	3295.2393
428.91113	1.2337979	0.32651913	3291.9961
429.91211	1.2376209	0.32784733	3292.7312
430.91309	1.2352821	0.32904747	3286.8152
431.91406	1.2438952	0.33047611	3291.4226
432.91504	1.2429324	0.33162031	3288.4729
433.91602	1.2486136	0.33285481	3293.2036
434.91699	1.2520802	0.33392537	3289.6643
435.91797	1.2550039	0.33502018	3294.8342
436.91895	1.2564014	0.33593467	3291.623
437.91992	1.2570598	0.33708793	3299.0752
438.9209	1.2620683	0.33827302	3297.969
439.92188	1.266362	0.33950627	3309.2761
440.92285	1.2698046	0.34085733	3302.905
441.92383	1.2729921	0.34212363	3311.9966
442.9248	1.2762383	0.3432962	3300.2927
443.92578	1.2804683	0.34463525	3308.428
444.92676	1.2812778	0.34596542	3303.1794
445.92773	1.2835087	0.34712267	3295.6521
446.92871	1.2861049	0.34838912	3309.9792
447.92969	1.2889296	0.34953076	3309.8547
448.93066	1.2938162	0.35080495	3311.1714
449.93164	1.2968961	0.35209537	3311.1194
450.93262	1.2999032	0.35299432	3304.4309
451.93359	1.3004293	0.35411358	3315.8521
452.93457	1.3053682	0.35517162	3313.9929
453.93555	1.3081403	0.35632667	3312.342
454.93652	1.3100088	0.35772556	3320.9619
455.9375	1.3155384	0.3590638	3318.5115
456.93848	1.3168157	0.36026368	3318.0361
457.93945	1.3199993	0.36170802	3324.3459
458.94043	1.3257829	0.36290586	3321.7012
459.94141	1.3285779	0.36402643	3318.6182
460.94238	1.3313054	0.36503038	3323.3813
461.94336	1.3319638	0.3662771	3327.2856
462.94434	1.3369517	0.3675482	3328.813
463.94531	1.3365002	0.3689473	3331.6472
464.94629	1.3426896	0.37011412	3322.5259
465.94727	1.3441312	0.37121335	3330.7888
466.94824	1.3450656	0.37258092	3332.6948
467.94922	1.3487195	0.37390289	3328.2759
468.9502	1.3546306	0.37532243	3332.0728
469.95117	1.3575283	0.37655997	3331.9336
470.95215	1.3589355	0.37783325	3336.887
471.95313	1.3619099	0.37927854	3335.8823
472.9541	1.3652675	0.38016629	3324.6099
473.95508	1.3689059	0.38117149	3331.0996
474.95605	1.3717896	0.38229263	3338.1746
475.95703	1.3728167	0.38351622	3341.5603
476.95801	1.3767434	0.38468248	3339.9189
477.95898	1.3793759	0.38604698	3337.2908
478.95996	1.3824761	0.38726696	3340.978
479.96094	1.3871243	0.38861006	3345.0713
480.96191	1.3880326	0.38968524	3336.6917
481.96289	1.3885602	0.39093882	3339.084
482.96387	1.395671	0.392104	3344.8379
483.96484	1.4001503	0.39331806	3349.676
484.96582	1.4029298	0.3943699	3341.647
485.9668	1.4057121	0.39536181	3344.5164
486.96777	1.407825	0.39682114	3352.9321
487.96875	1.4111332	0.39831841	3350.5376
488.96973	1.4141061	0.39965558	3355.511
489.9707	1.4186184	0.40099227	3358.0281
490.97168	1.4214126	0.40215373	3350.3923
491.97266	1.4235829	0.40323329	3355.2688
492.97363	1.4246912	0.40452936	3355.8167
493.97461	1.430506	0.40578675	3357.7322
494.97559	1.4325788	0.40695789	3351.896
495.97656	1.4328325	0.40819106	3358.0889
496.97754	1.4372303	0.40933904	3352.231
497.97852	1.4414446	0.41054961	3359.8076
498.97949	1.4438413	0.41186461	3359.5391
499.98047	1.4463868	0.4132708	3365.3569
500.98145	1.4471992	0.41444659	3357.9629
501.98242	1.4536748	0.41559911	3367.8506
502.9834	1.45609	0.41689861	3368.5039
503.98438	1.4586735	0.41827041	3363.3157
504.98535	1.4590186	0.41943198	3365.2827
505.98633	1.4639962	0.42065978	3366.7117
506.9873	1.4663436	0.42198822	3368.3894
507.98828	1.4704161	0.4233323	3375.2661
508.98926	1.4755329	0.42471752	3374.6528
509.99023	1.4776467	0.42606202	3376.5271
510.99121	1.4777229	0.4273721	3370.6589
511.99219	1.4846514	0.42858416	3368.9329
512.99316	1.4861195	0.42979839	3372.5076
513.99414	1.4901106	0.43098301	3374.8279
514.99512	1.4906433	0.43228191	3378.6621
515.99609	1.4931107	0.43346286	3371.4556
516.99707	1.4980823	0.43476269	3379.261
517.99805	1.500818	0.43622759	3387.0874
518.99902	1.5033463	0.43747464	3382.2073
520	1.5071659	0.43870062	3382.7217
521.00098	1.5088153	0.43990898	3378.842
522.00195	1.5136468	0.44101572	3371.4988
523.00293	1.5151998	0.44212431	3374.8931
524.00391	1.5179569	0.44327664	3389.3174
525.00488	1.5214126	0.44429889	3383.2197
526.00586	1.5234115	0.44563061	3390.1191
527.00684	1.5243603	0.44690639	3383.6711
528.00781	1.5317361	0.44809949	3383.4277
529.00879	1.5319117	0.44931045	3385.5322
530.00977	1.5359459	0.45028612	3380.9026
531.01074	1.5400378	0.4514671	3386.1731
532.01172	1.5444218	0.45273721	3392.6758
533.0127	1.5452278	0.45415235	3391.8213
534.01367	1.5506341	0.45533442	3393.1519
535.01465	1.5535184	0.45677176	3394.6055
536.01563	1.5567691	0.45803067	3393.3936
537.0166	1.559211	0.45936966	3399.6838
538.01758	1.5603564	0.46072173	3397.9233
539.01855	1.5623237	0.46225783	3397.3643
540.01953	1.566244	0.4636187	3398.9646
541.02051	1.5686654	0.4651475	3407.5142
542.02148	1.5734844	0.46653259	3396.8091
543.02246	1.5722375	0.46767533	3397.0715
544.02344	1.5791008	0.46874326	3395.3435
545.02441	1.5817152	0.46980688	3396.2991
546.02539	1.5831496	0.47116059	3403.5271
547.02637	1.5883625	0.47266167	3409.2441
548.02734	1.5902374	0.47376713	3395.9326
549.02832	1.5925932	0.4751032	3408.4756
550.0293	1.5944084	0.47641468	3405.636
551.03027	1.602971	0.47760189	3405.3738
552.03125	1.6040397	0.47873428	3405.8752
553.03223	1.6058398	0.48000848	3405.95
554.0332	1.6101685	0.48130688	3415.7793
555.03418	1.6096792	0.48262423	3411.1758
556.03516	1.614985	0.48398814	3416.1228
557.03613	1.6196598	0.48509371	3413.5083
558.03711	1.6201485	0.4862982	3414.7136
559.03809	1.6225511	0.48732227	3405.449
560.03906	1.6275066	0.48843935	3408.0244
561.04004	1.6289306	0.48958224	3413.8562
562.04102	1.6347822	0.49096647	3417.6467
563.04199	1.6351568	0.4923625	3416.9312
564.04297	1.6391966	0.49366051	3419.092
565.04395	1.6405443	0.49498811	3416.5396
566.04492	1.6460901	0.49634689	3420.7395
567.0459	1.6467038	0.49772164	3414.6824
568.04688	1.6492299	0.49901348	3422.7124
569.04785	1.6539862	0.50047541	3422.8145
570.04883	1.6564254	0.50179803	3423.4189
571.0498	1.6606832	0.50294507	3420.3652
572.05078	1.662076	0.50436741	3424.845
573.05176	1.6653709	0.50578982	3427.7229
574.05273	1.6704875	0.50717121	3425.8779
575.05371	1.6736168	0.50862139	3431.0498
576.05469	1.6753851	0.51017374	3428.229
577.05566	1.6790044	0.51152021	3425.6899
578.05664	1.682722	0.51293749	3428.7034
579.05762	1.6860703	0.51426649	3429.9883
580.05859	1.6882885	0.51527828	3426.8323
581.05957	1.6877942	0.51656491	3430.4109
582.06055	1.6912923	0.51761591	3426.5291
583.06152	1.6965158	0.51893574	3435.1211
584.0625	1.6973623	0.52021819	3435.4053
585.06348	1.6974621	0.52145529	3426.9546
586.06445	1.7052132	0.52286232	3438.738
587.06543	1.7076441	0.52434391	3433.635
588.06641	1.7112107	0.52558088	3437.1379
589.06738	1.7114881	0.52675569	3428.3149
590.06836	1.716628	0.52799612	3435.499
591.06934	1.719945	0.529149	3434.4458
592.07031	1.7236705	0.53032595	3437.2495
593.07129	1.7236727	0.53145605	3435.5444
594.07227	1.7300159	0.53272611	3440.2773
595.07324	1.7292237	0.53392208	3440.6162
596.07422	1.7349417	0.53521281	3442.7058
597.0752	1.7383442	0.53643394	3439.6643
598.07617	1.7390352	0.53770489	3443.2515
599.07715	1.7441845	0.53880525	3438.6418
600.07813	1.7465318	0.54010993	3445.2205
601.0791	1.7500578	0.54156482	3448.9404
602.08008	1.7521693	0.54311174	3446.5532
603.08105	1.7561363	0.54461014	3446.5693
604.08203	1.7584685	0.54607201	3452.7744
605.08301	1.7617254	0.54765785	3449.4802
606.08398	1.7649049	0.54878783	3440.9949
607.08496	1.7687478	0.55005008	3445.2588
608.08594	1.7719321	0.55115831	3446.5039
609.08691	1.7727793	0.55247962	3445.8494
610.08789	1.7743744	0.55400097	3450.74
611.08887	1.7795532	0.55569446	3450.416
612.08984	1.7822704	0.5570637	3451.3484
613.09082	1.7852515	0.55834401	3452.6211
614.0918	1.7887883	0.55956435	3450.3008
615.09277	1.7903795	0.5611127	3457.6782
616.09375	1.79575	0.56247735	3454.676
617.09473	1.7981788	0.56361365	3449.9294
618.0957	1.7992926	0.56477684	3448.4185
619.09668	1.8040398	0.56609595	3457.6118
620.09766	1.8057215	0.56741333	3458.4993
621.09863	1.8109328	0.56894225	3462.2944
622.09961	1.8138442	0.57028461	3460.6946
623.10059	1.8178809	0.57170838	3462.2993
624.10156	1.8194379	0.57308805	3465.2715
625.10254	1.8217584	0.57424396	3455.5608
626.10352	1.8269433	0.57572913	3464.1875
627.10449	1.8231258	0.57715619	3454.4011
628.10547	1.8323481	0.57844603	3459.2166
629.10645	1.8333849	0.57990438	3462.5393
630.10742	1.8371693	0.58130127	3470.1375
631.1084	1.8387854	0.58242929	3457.292
632.10938	1.8424604	0.58384013	3470.0435
633.11035	1.8428116	0.58509785	3466.8022
634.11133	1.8464329	0.5865218	3464.2124
635.1123	1.8529491	0.5878517	3473.1702
636.11328	1.8555226	0.5892939	3467.7517
637.11426	1.8549887	0.59076339	3468.4529
638.11523	1.8601602	0.5921939	3466.5669
639.11621	1.8622794	0.59361333	3473.0203
640.11719	1.8652676	0.59484661	3468.4563
641.11816	1.8708212	0.59633708	3473.7866
642.11914	1.8734111	0.59784466	3469.9915
643.12012	1.8768363	0.5991239	3470.2834
644.12109	1.8792542	0.60066563	3475.9539
645.12207	1.8809022	0.60219246	3476.9529
646.12305	1.8848612	0.60373408	3477.1563
647.12402	1.888235	0.60501271	3469.5293
648.125	1.8902608	0.60628521	3471.406
649.12598	1.8968875	0.60783613	3483.418
650.12695	1.8952429	0.60930729	3478.6521
651.12793	1.9008132	0.61075282	3474.4109
652.12891	1.8998853	0.61206204	3472.2556
653.12988	1.9061232	0.61340404	3480.2629
654.13086	1.9073524	0.61469507	3474.7847
655.13184	1.9114794	0.61599588	3479.9995
656.13281	1.9119817	0.61741865	3483.5107
657.13379	1.9164407	0.61889708	3477.8501
658.13477	1.9197271	0.6202687	3478.3818
659.13574	1.9226	0.62161732	3478.5527
660.13672	1.9271154	0.62298185	3483.6956
661.1377	1.9291835	0.6243636	3484.9185
662.13867	1.9301312	0.62581265	3485.9856
663.13965	1.9365413	0.62725967	3485.9827
664.14063	1.9379499	0.62878424	3484.0269
665.1416	1.9422442	0.63010806	3486.1907
666.14258	1.9440808	0.63137448	3482.1208
667.14355	1.9458854	0.63258749	3478.3801
668.14453	1.9506825	0.63422054	3494.4263
669.14551	1.9519715	0.63563043	3487.907
670.14648	1.9565949	0.63711751	3495.0059
671.14746	1.9584062	0.63849699	3484.7607
672.14844	1.9643859	0.63991225	3490.5227
673.14941	1.9646746	0.64146733	3491.3333
674.15039	1.9673477	0.64308006	3490.4094
675.15137	1.9727519	0.64431614	3486.8303
676.15234	1.9768651	0.64568704	3490.9712
677.15332	1.9763602	0.64712626	3493.428
678.1543	1.9795291	0.64856482	3488.332
679.15527	1.9818695	0.6498428	3492.0869
680.15625	1.9877334	0.65121156	3491.9209
681.15723	1.989464	0.65256292	3492.5334
682.1582	1.9918801	0.65396464	3503.2644
683.15918	1.9969985	0.65538228	3494.0669
684.16016	1.9975168	0.65688354	3494.9617
685.16113	2.0037298	0.6584549	3501.7471
686.16211	2.0075216	0.66000742	3493.0315
687.16309	2.0053756	0.66159707	3497.3604
688.16406	2.0100198	0.66307026	3495.6804
689.16504	2.0136592	0.66442043	3499.1067
690.16602	2.0164816	0.66578799	3499.0361
691.16699	2.0176909	0.66739571	3496.0266
692.16797	2.0212116	0.66870826	3495.3789
693.16895	2.0288322	0.67022282	3503.9063
694.16992	2.0293236	0.67154634	3503.4402
695.1709	2.030344	0.67295903	3497.561
696.17188	2.0343118	0.67446953	3498.3142
697.17285	2.035583	0.67586184	3499.7351
698.17383	2.0454493	0.6775263	3503.0798
699.1748	2.0426731	0.67888892	3506.6826
700.17578	2.0474246	0.68035084	3506.408
701.17676	2.0506818	0.68172222	3502.3484
702.17773	2.054821	0.68281925	3500.3987
703.17871	2.0541444	0.6843316	3508.5994
704.17969	2.0584428	0.685911	3507.0684
705.18066	2.0633891	0.68750507	3514.1179
706.18164	2.0667448	0.68924564	3515.5391
707.18262	2.0675178	0.69066304	3504.0583
708.18359	2.0755415	0.69214648	3508.0007
709.18457	2.0751135	0.69366956	3505.0054
710.18555	2.0773249	0.69517761	3508.5276
711.18652	2.0802541	0.69652903	3510.8459
712.1875	2.0822697	0.69807404	3517.1082
713.18848	2.0857925	0.69992226	3512.6787
714.18945	2.0868769	0.70138699	3507.7749
715.19043	2.0917058	0.70284766	3506.7571
716.19141	2.0953665	0.70412898	3508.5437
717.19238	2.1001098	0.70557213	3510.4792
718.19336	2.0990722	0.70719022	3516.6836
719.19434	2.1057603	0.70871311	3516.313
720.19531	2.1107461	0.71042085	3513.5305
721.19629	2.1102674	0.71208781	3516.2346
722.19727	2.1121354	0.71351445	3506.5037
723.19824	2.1159267	0.71467429	3507.8691
724.19922	2.1204162	0.71584201	3510.9019
725.2002	2.1225219	0.71722215	3515.4138
726.20117	2.1251123	0.71874094	3523.8418
727.20215	2.1251903	0.72029072	3515.0605
728.20313	2.1289861	0.72188866	3514.8794
729.2041	2.1364481	0.72324169	3511.7866
730.20508	2.1367254	0.72456896	3517.1233
731.20605	2.1388257	0.72632086	3521.1167
732.20703	2.1422853	0.72808117	3518.8923
733.20801	2.1435266	0.72955304	3516.5928
734.20898	2.1499929	0.73085535	3517.752
735.20996	2.1510119	0.73259401	3521.3894
736.21094	2.1539283	0.73409969	3515.1799
737.21191	2.1599455	0.73541397	3516.9595
738.21289	2.1619439	0.73692679	3518.4424
739.21387	2.167146	0.73847324	3524.2419
740.21484	2.1656556	0.74005061	3522.8621
741.21582	2.1690102	0.7417233	3522.5332
742.2168	2.1716197	0.74307966	3523.8018
743.21777	2.1759388	0.74457455	3520.6973
744.21875	2.1801047	0.74589652	3518.8645
745.21973	2.1824746	0.74732459	3522.7012
746.2207	2.1867921	0.74848384	3520.0598
747.22168	2.1880922	0.7499851	3525.863
748.22266	2.1929288	0.75190097	3535.2373
749.22363	2.1941044	0.75395316	3527.6099
750.22461	2.1951284	0.7554996	3520.9976
751.22559	2.2005503	0.75718796	3523.1509
752.22656	2.2056086	0.75892591	3530.5989
753.22754	2.2077236	0.76063687	3533.7576
754.22852	2.2115569	0.76238126	3530.2546
755.22949	2.2135327	0.76386058	3522.8645
756.23047	2.2158704	0.765347	3530.8071
757.23145	2.220001	0.76687777	3527.311
758.23242	2.2198634	0.76845318	3527.6355
759.2334	2.225338	0.77000487	3528.0569
760.23438	2.2277439	0.77164835	3528.9526
761.23535	2.229151	0.77322316	3533.1736
762.23633	2.2326889	0.77498168	3530.5662
763.2373	2.2368248	0.77664959	3526.2285
764.23828	2.238178	0.77813065	3528.6746
765.23926	2.2419481	0.77960658	3527.0024
766.24023	2.242012	0.7809996	3528.1643
767.24121	2.2477837	0.78265852	3529.9402
768.24219	2.2496557	0.78407693	3526.7454
769.24316	2.254581	0.78586453	3534.1235
770.24414	2.2565272	0.78740251	3527.1516
771.24512	2.25841	0.78880292	3527.9692
772.24609	2.2639105	0.79069477	3537.1436
773.24707	2.2669277	0.79228413	3530.4363
774.24805	2.2712567	0.79372752	3531.0845
775.24902	2.2714841	0.79555494	3537.5613
776.25	2.2753856	0.79718119	3534.0056
777.25098	2.2784848	0.79885143	3531.5906
778.25195	2.2805138	0.80067891	3536.4153
779.25293	2.285264	0.80238944	3541.6326
780.25391	2.2862117	0.80425709	3536.2019
781.25488	2.289722	0.80616367	3539.0645
782.25586	2.2924206	0.80814952	3531.9426
783.25684	2.2962739	0.80978519	3535.5002
784.25781	2.2993135	0.81123006	3528.8569
785.25879	2.3037701	0.81274647	3535.3855
786.25977	2.3070536	0.81421393	3537.9893
787.26074	2.3118076	0.81553459	3535.8125
788.26172	2.3113279	0.81699067	3536.429
789.2627	2.313406	0.81891942	3547.1687
790.26367	2.3192608	0.82054389	3541.0791
791.26465	2.3189504	0.82211232	3536.625
792.26563	2.3241577	0.82371908	3538.4954
793.2666	2.3232224	0.82543176	3540.1777
794.26758	2.3291287	0.82702214	3540.2351
795.26855	2.3332489	0.82874346	3534.2373
796.26953	2.3359511	0.83031249	3535.7112
797.27051	2.3358285	0.83193827	3536.677
798.27148	2.3410285	0.83367753	3545.395
799.27246	2.3452055	0.83539587	3537.481
800.27344	2.3463674	0.83718342	3539.6064
801.27441	2.3472261	0.83884555	3537.3569
802.27539	2.3548541	0.84050643	3545.8604
803.27637	2.3579555	0.84210521	3543.5339
804.27734	2.3585029	0.84396076	3541.6899
805.27832	2.3648493	0.84557855	3541.2188
806.2793	2.3650579	0.84727508	3544.6675
807.28027	2.3678527	0.8487578	3538.7549
808.28125	2.373018	0.85047764	3542.1563
809.28223	2.3738828	0.85218608	3542.8154
810.2832	2.3780811	0.85381007	3540.6917
811.28418	2.3810034	0.8554824	3539.478
812.28516	2.3833218	0.85708696	3543.3352
813.28613	2.3874302	0.85885656	3546.4685
814.28711	2.3888535	0.86071879	3546.1287
815.28809	2.3929579	0.86246741	3546.2026
816.28906	2.3975697	0.86443877	3544.7041
817.29004	2.3974607	0.86627668	3545.4827
818.29102	2.4036832	0.86815965	3549.0977
819.29199	2.4046984	0.86960661	3534.2373
820.29297	2.4110692	0.87115431	3541.1602
821.29395	2.4104576	0.87273824	3546.3569
822.29492	2.4128506	0.87441576	3547.9429
823.2959	2.4172249	0.87594861	3545.3469
824.29688	2.4201806	0.87786365	3554.5374
825.29785	2.4227223	0.87981921	3548.6523
826.29883	2.4268951	0.88184458	3549.7151
827.2998	2.4279778	0.88367832	3543.1331
828.30078	2.4303694	0.88530499	3541.9878
829.30176	2.4353576	0.88705653	3547.8477
830.30273	2.4368067	0.88902551	3547.3538
831.30371	2.439796	0.8909229	3538.2405
832.30469	2.4414752	0.89269829	3545.4453
833.30566	2.4447277	0.89474571	3546.4905
834.30664	2.4491613	0.8963384	3544.5627
835.30762	2.4533157	0.89823651	3553.1536
836.30859	2.4556482	0.90009719	3545.804
837.30957	2.4578631	0.90166807	3536.1284
838.31055	2.4593351	0.90334123	3538.5156
839.31152	2.4615057	0.90497082	3540.8069
840.3125	2.4700832	0.90665966	3550.7661
841.31348	2.4686422	0.9085803	3546.8862
842.31445	2.4740634	0.91045207	3552.1157
843.31543	2.4766803	0.91239458	3551.6509
844.31641	2.48084	0.9143908	3554.9509
845.31738	2.4804456	0.91650409	3547.991
846.31836	2.4873667	0.91834247	3549.9939
847.31934	2.4898171	0.92024922	3546.4834
848.32031	2.4914956	0.92185467	3543.9067
849.32129	2.4952819	0.92374378	3549.7737
850.32227	2.4935238	0.92550182	3546.8469
851.32324	2.501405	0.92741126	3550.5056
852.32422	2.5005226	0.92915702	3548.8596
853.3252	2.5064042	0.93096334	3548.8042
854.32617	2.51036	0.93292606	3550.1252
855.32715	2.5116889	0.93448961	3544.2693
856.32813	2.5173359	0.93641925	3549.8987
857.3291	2.5229979	0.93826103	3550.5037
858.33008	2.5212331	0.94016463	3549.1904
859.33105	2.5249643	0.94203115	3545.6829
860.33203	2.5259304	0.94394183	3551.4395
861.33301	2.5295036	0.94589406	3554.0698
862.33398	2.532764	0.9479574	3549.5581
863.33496	2.5356398	0.94998252	3551.2361
864.33594	2.5404198	0.95184976	3546.2805
865.33691	2.5419414	0.95385087	3552.5667
866.33789	2.5449154	0.95583773	3557.1345
867.33887	2.5465345	0.95767665	3545.6326
868.33984	2.5497749	0.95976466	3551.4441
869.34082	2.55422	0.96192223	3549.0366
870.3418	2.5562205	0.96381205	3548.3892
871.34277	2.5613022	0.96562117	3543.9519
872.34375	2.5628145	0.96747923	3549.2896
873.34473	2.565829	0.9693414	3550.1545
874.3457	2.5713453	0.97146326	3550.783
875.34668	2.5724647	0.97362143	3550.4731
876.34766	2.5776348	0.97537374	3548.5454
877.34863	2.5786273	0.97738612	3550.0872
878.34961	2.5789421	0.97922212	3545.2271
879.35059	2.5855343	0.98132503	3553.2429
880.35156	2.5868461	0.98328269	3552.0781
881.35254	2.5912337	0.98538589	3550.687
882.35352	2.5972416	0.98707408	3547.6567
883.35449	2.5955622	0.98855245	3543.2737
884.35547	2.5993168	0.99025744	3549.9407
885.35645	2.602062	0.99228883	3559.6401
886.35742	2.6057768	0.99441028	3551.6257
887.3584	2.6071188	0.99662983	3551.6169
888.35938	2.6090224	0.99896288	3554.635
889.36035	2.6160166	1.0011059	3547.5769
890.36133	2.6167407	1.0032732	3550.2471
891.3623	2.6199763	1.0050733	3546.1172
892.36328	2.6216068	1.0071772	3550.5422
893.36426	2.6281886	1.0094424	3555.5005
894.36523	2.6290016	1.0118099	3549.7693
895.36621	2.6285455	1.0136762	3546.8088
896.36719	2.6371307	1.0159972	3554.686
897.36816	2.6378436	1.0181329	3549.9043
898.36914	2.6392243	1.0203844	3549.0881
899.37012	2.6442392	1.0222762	3539.5591
900.37109	2.6482036	1.0241854	3545.5676
901.37207	2.6511536	1.0259086	3545.7886
902.37305	2.6524928	1.0278772	3549.6228
903.37402	2.6562638	1.0298144	3544.9702
904.375	2.6586461	1.0321168	3550.8752
905.37598	2.6644521	1.0347372	3550.4478
906.37695	2.665307	1.0372266	3549.4976
907.37793	2.6685176	1.0395318	3549.8015
908.37891	2.6702449	1.04151	3541.666
909.37988	2.671351	1.0435756	3548.4075
910.38086	2.6762018	1.0457056	3549.866
911.38184	2.6821504	1.0478438	3553.7148
912.38281	2.6819329	1.050191	3554.1619
913.38379	2.6871111	1.0526915	3547.7043
914.38477	2.6880031	1.0548571	3546.9998
915.38574	2.6947479	1.0569482	3544.4839
916.38672	2.6965022	1.0588095	3539.8206
917.3877	2.6974099	1.0606217	3543.7878
918.38867	2.7020957	1.062776	3549.1921
919.38965	2.7052143	1.0648772	3549.0417
920.39063	2.707334	1.0671359	3550.8591
921.3916	2.7094316	1.0693868	3548.3958
922.39258	2.7130094	1.0717183	3545.2278
923.39355	2.7173741	1.0738217	3544.0327
924.39453	2.7184939	1.075755	3546.7429
925.39551	2.7243273	1.0779893	3543.3325
926.39648	2.7263396	1.0800014	3547.4595
927.39746	2.730675	1.0822767	3550.4763
928.39844	2.7315266	1.0848255	3548.6375
929.39941	2.7376916	1.0874515	3546.5459
930.40039	2.7366426	1.0893607	3537.5962
931.40137	2.7412152	1.0914416	3541.5613
932.40234	2.7460837	1.0937216	3549.3132
933.40332	2.7467296	1.0962223	3546.6411
934.4043	2.7505817	1.0987896	3544.5366
935.40527	2.7518635	1.1013906	3547.7695
936.40625	2.7562387	1.1036414	3547.3269
937.40723	2.760221	1.106094	3546.2617
938.4082	2.760119	1.1082834	3534.9243
939.40918	2.7666204	1.110314	3536.5676
940.41016	2.7684896	1.1122944	3543.426
941.41113	2.7716191	1.1147038	3546.8574
942.41211	2.7740521	1.1169951	3544.6682
943.41309	2.7749372	1.1193984	3539.5818
944.41406	2.779779	1.1217213	3543.4009
945.41504	2.7816956	1.1241416	3545.6819
946.41602	2.7857368	1.126866	3543.1714
947.41699	2.7894778	1.1294236	3543.7314
948.41797	2.7908297	1.1315495	3533.8845
949.41895	2.7920594	1.1343362	3546.2317
950.41992	2.7980013	1.1370108	3538.0945
951.4209	2.7981997	1.1390021	3535.6624
952.42188	2.8025129	1.1411943	3535.8357
953.42285	2.8066328	1.1433631	3533.7563
954.42383	2.8127553	1.1454878	3540.5625
955.4248	2.8146703	1.147724	3540.4639
956.42578	2.8135417	1.1500988	3539.894
957.42676	2.8171573	1.1529584	3541.8164
958.42773	2.8203714	1.1557332	3539.8691
959.42871	2.8218284	1.1579922	3534.9312
960.42969	2.8280497	1.1605479	3538.9143
961.43066	2.8327022	1.1633483	3538.8789
962.43164	2.8333776	1.1658874	3535.6794
963.43262	2.8362162	1.1682924	3535.6162
964.43359	2.8388872	1.1708509	3536.8311
965.43457	2.8404124	1.1729889	3528.8188
966.43555	2.8439114	1.1754558	3534.0916
967.43652	2.8490756	1.1780776	3537.9868
968.4375	2.8523705	1.1808447	3536.3389
969.43848	2.8543172	1.1832612	3528.6956
970.43945	2.856828	1.1855726	3532.0107
971.44043	2.8600125	1.1875962	3532.3328
972.44141	2.8633716	1.1901418	3534.0349
973.44238	2.8662341	1.1930646	3536.6443
974.44336	2.8688092	1.1957594	3528.3672
975.44434	2.8720181	1.198622	3529.4543
976.44531	2.8764422	1.2013849	3532.8313
977.44629	2.8797271	1.2043922	3533.2979
978.44727	2.8809726	1.2072089	3523.7808
979.44824	2.8842213	1.2096773	3529.3704
980.44922	2.8868535	1.2123684	3526.5154
981.4502	2.8902133	1.2146211	3528.157
982.45117	2.8923767	1.2170215	3529.7507
983.45215	2.8939991	1.2195736	3522.1328
984.45313	2.897094	1.2219509	3526.1631
985.4541	2.9011588	1.2248857	3521.3865
986.45508	2.9090867	1.227779	3530.6523
987.45605	2.9103684	1.2305757	3524.4326
988.45703	2.9132645	1.2328758	3522.821
989.45801	2.9163682	1.2354604	3526.1736
990.45898	2.919317	1.2382125	3525.0723
991.45996	2.9196107	1.240977	3522.0984
992.46094	2.9214292	1.2440083	3524.4282
993.46191	2.9264827	1.2466769	3518.1758
994.46289	2.928859	1.2490758	3515.2402
995.46387	2.9327683	1.2516176	3518.7988
996.46484	2.9374335	1.2538772	3519.8232
997.46582	2.9390969	1.2566868	3522.697
998.4668	2.9425092	1.2594987	3521.2554
999.46777	2.9448733	1.2622184	3513.085
1000.4688	2.9468606	1.2646691	3515.7485
1001.4697	2.94892	1.2674296	3519.0056
1002.4707	2.9530566	1.2705019	3515.8315
1003.4717	2.9569314	1.2734977	3520.5854
1004.4727	2.9609683	1.2765404	3521.0991
1005.4736	2.9610066	1.279772	3514.2939
1006.4746	2.9664896	1.2825114	3509.4407
1007.4756	2.9692156	1.2848361	3508.625
1008.4766	2.9708726	1.2873052	3511.9438
1009.4775	2.9752216	1.2899231	3506.7483
1010.4785	2.9816113	1.2929444	3517.377
1011.4795	2.9811976	1.2959669	3511.2925
1012.4805	2.9850736	1.2988391	3503.8958
1013.4814	2.9900053	1.3014001	3501.8872
1014.4824	2.9915767	1.3040221	3499.3406
1015.4834	2.9930875	1.3064897	3501.2434
1016.4844	2.9959817	1.3091185	3504.9155
1017.4854	3.0003178	1.3122449	3504.0356
1018.4863	3.00226	1.3156278	3506.061
1019.4873	3.0043418	1.3192971	3499.4626
1020.4883	3.010473	1.3221191	3495.9265
1021.4893	3.0122018	1.3247439	3494.1248
1022.4902	3.0116627	1.327142	3497.4138
1023.4912	3.0175021	1.3300457	3498.1528
1024.4922	3.0183363	1.3326166	3491.645
1025.4932	3.0222359	1.3350041	3491.9211
1026.4941	3.0259755	1.3378028	3493.7654
1027.4951	3.0275908	1.3409903	3496.0698
1028.4961	3.0337572	1.3435982	3487.5955
1029.4971	3.0343161	1.3464396	3488.8796
1030.498	3.0394673	1.349	3493.6455
1031.499	3.039511	1.3517246	3490.0874
1032.5	3.0442083	1.3547893	3493.7683
1033.501	3.0411987	1.3576638	3484.8477
1034.502	3.050761	1.3599297	3479.6853
1035.5029	3.0557668	1.3619109	3482.5898
1036.5039	3.0551705	1.3637617	3475.6426
1037.5049	3.060056	1.3660394	3482.3113
1038.5059	3.0608521	1.3689349	3485.0535
1039.5068	3.0650733	1.3719437	3485.2737
1040.5078	3.0654159	1.375078	3483.4893
1041.5088	3.0698626	1.3789022	3477.7212
1042.5098	3.0745292	1.3822179	3474.8169
1043.5107	3.0797098	1.3854374	3474.5654
1044.5117	3.0784383	1.3883954	3469.1228
1045.5127	3.0803401	1.3911788	3467.582
1046.5137	3.0843604	1.3946337	3470.2256
1047.5146	3.0901237	1.3973483	3465.0032
1048.5156	3.0904891	1.3998431	3464.0115
1049.5166	3.0971653	1.402578	3466.5315
1050.5176	3.0981467	1.4053526	3461.5396
1051.5186	3.1018834	1.4078919	3461.3662
1052.5195	3.1028666	1.4107692	3466.1189
1053.5205	3.1043997	1.4145938	3464.1265
1054.5215	3.1093781	1.418138	3461.2446
1055.5225	3.1132078	1.4210762	3454.3711
1056.5234	3.1163762	1.4235952	3454.3118
1057.5244	3.1171076	1.4260715	3447.4902
1058.5254	3.1232362	1.4288617	3455.1553
1059.5264	3.1238673	1.4318944	3448.5891
1060.5273	3.1285899	1.4347873	3446.0496
1061.5283	3.1324761	1.4376922	3446.5078
1062.5293	3.1332474	1.4406393	3447.3262
1063.5303	3.1381221	1.4433239	3440.583
1064.5313	3.1408558	1.4465184	3447.9543
1065.5322	3.1439548	1.4504623	3447.4749
1066.5332	3.1472485	1.4535347	3433.8694
1067.5342	3.1509988	1.4567236	3439.363
1068.5352	3.1519873	1.4600873	3435.0457
1069.5361	3.1572368	1.4629747	3433.667
1070.5371	3.1577015	1.4658105	3425.7476
1071.5381	3.1611581	1.4687678	3425.0588
1072.5391	3.1646957	1.4717121	3428.3599
1073.54	3.1694663	1.475315	3428.1475
1074.541	3.1689804	1.4783072	3422.3391
1075.542	3.1748109	1.4815855	3424.261
1076.543	3.1758618	1.4851096	3417.2378
1077.5439	3.1778791	1.4886055	3420.7554
1078.5449	3.1834466	1.491675	3413.2739
1079.5459	3.1827135	1.4942603	3405.1531
1080.5469	3.1900635	1.4973863	3412.1646
1081.5479	3.190114	1.5006267	3407.9065
1082.5488	3.1947362	1.5034668	3407.4758
1083.5498	3.1970029	1.5068587	3402.7952
1084.5508	3.1994081	1.5100323	3402.738
1085.5518	3.2018094	1.5130059	3398.5962
1086.5527	3.2035353	1.5161928	3398.7078
1087.5537	3.2075727	1.519473	3390.0952
1088.5547	3.2096536	1.5220488	3385.3745
1089.5557	3.2149081	1.5244712	3391.2004
1090.5566	3.2206388	1.5271555	3388.2385
1091.5576	3.2227211	1.5304437	3386.3789
1092.5586	3.2270148	1.5336362	3387.9612
1093.5596	3.2301116	1.537395	3387.6262
1094.5605	3.2326181	1.5410426	3379.1182
1095.5615	3.2340839	1.5442462	3371.9639
1096.5625	3.2340338	1.5472319	3363.4463
1097.5635	3.2413435	1.5497657	3365.2126
1098.5645	3.2419977	1.5525845	3366.0071
1099.5654	3.2455387	1.5555732	3365.1787
1100.5664	3.2517056	1.5587151	3363.6802
1101.5674	3.2499032	1.5617014	3360.5991
1102.5684	3.2555652	1.5652869	3361.0356
1103.5693	3.2577567	1.5691175	3355.4771
1104.5703	3.2606001	1.5722322	3344.6936
1105.5713	3.2630136	1.5749823	3344.4368
1106.5723	3.2679331	1.5781931	3349.2332
1107.5732	3.2687392	1.5813246	3344.3218
1108.5742	3.2695832	1.5846741	3340.4941
1109.5752	3.2767885	1.5881764	3331.8821
1110.5762	3.2793641	1.5917687	3339.0581
1111.5771	3.2814894	1.5949937	3327.3413
1112.5781	3.2846589	1.5975425	3327.821
1113.5791	3.29055	1.6008544	3325.8669
1114.5801	3.2894554	1.6041405	3317.7271
1115.5811	3.2935128	1.6077677	3315.4163
1116.582	3.2990692	1.6105034	3315.0371
1117.583	3.2997408	1.6135337	3313.8765
1118.584	3.3035312	1.6171013	3306.4478
1119.585	3.3069541	1.6204764	3308.8284
1120.5859	3.3087635	1.6245447	3303.4539
1121.5869	3.3127208	1.6282502	3295.0696
1122.5879	3.3159523	1.631339	3291.7397
1123.5889	3.3182657	1.6345439	3287.3628
1124.5898	3.3225658	1.637362	3285.2615
1125.5908	3.3233662	1.6405665	3281.3484
1126.5918	3.3276722	1.6431904	3274.3586
1127.5928	3.3309677	1.645911	3274.397
1128.5938	3.3335185	1.6490234	3270.5947
1129.5947	3.3345582	1.6523173	3270.2539
1130.5957	3.3419435	1.656253	3268.5295
1131.5967	3.3432367	1.6600487	3255.2649
1132.5977	3.3460593	1.6629148	3253.4678
1133.5986	3.3475618	1.6662083	3244.1362
1134.5996	3.352005	1.6693047	3244.5042
1135.6006	3.3545146	1.672525	3237.3921
1136.6016	3.3560615	1.6763039	3228.9063
1137.6025	3.3609664	1.6799738	3229.8418
1138.6035	3.3606589	1.6836019	3218.5112
1139.6045	3.3653681	1.6873367	3213.53
1140.6055	3.3685951	1.6911505	3200.9565
1141.6064	3.3746853	1.6945035	3193.3823
1142.6074	3.3764458	1.6975162	3189.9475
1143.6084	3.3774385	1.7015084	3192.0684
1144.6094	3.3789747	1.7068027	3165.095
1145.6104	3.386261	1.7112181	3149.2092
1146.6113	3.3871384	1.7154051	3123.3091
1147.6123	3.3911896	1.7213488	3089.5598
1148.6133	3.3951705	1.7271125	3053.8735
1149.2139	3.3953135	1.7310377	3025.0947