File: datasets/am_bench_2022/raw_data/90-XY.07-4/specimen.dat
MTS793|MPT|ENU|1|2|.|/|:|1|0|0|A

Operator Information						Time:	11.740967	Sec	11/2/2021 3:18:43 PM
Operator	Nick Derimow
Project	AM Bench 2022 mini-tensile challenge
Specimen ID	90-XY.07-4
Material	PBF-L Inconel 625
Specimen Width	2.54	mm
Specimen Thickness	1.49	mm
Notes
Operator Information End

Data Acquisition						Time:	1001.0374	Sec	11/2/2021 3:35:12 PM
Time	Axial Displacement	Axial Extensometer	Axial Force
Sec	mm	mm	N
11.854492	0.00039413839	0.00018643992	55.803635
12.755371	0.0044263415	0.00031264764	67.928848
13.65625	0.0065637128	0.00034665136	75.291824
14.557129	0.0090855109	0.00055154745	85.836769
15.458008	0.014426762	0.00069191313	103.52277
16.358887	0.016095804	0.00075296138	113.8243
17.259766	0.017974192	0.00097634376	126.07146
18.160645	0.01910601	0.0009309809	132.05664
19.061523	0.024209332	0.0010914126	146.67575
19.962402	0.024260554	0.0011015711	156.41556
20.863281	0.027161606	0.001284135	172.21245
21.76416	0.03187548	0.0013632342	186.48347
22.665039	0.03147205	0.0015580303	200.43341
23.565918	0.036474414	0.0017660663	223.36917
24.466797	0.038458321	0.0017857153	232.32927
25.367676	0.043626849	0.0019905868	250.34377
26.268555	0.045211475	0.0019921318	262.92218
27.169434	0.047376506	0.0021870139	271.51553
28.070313	0.049387101	0.0022820167	291.48969
28.971191	0.051780589	0.0024367359	310.06369
29.87207	0.052184634	0.0024531845	319.64212
30.772949	0.055811409	0.0026274833	343.23721
31.673828	0.06002878	0.0028309503	368.63098
32.574707	0.061667293	0.0031083203	391.26776
33.475586	0.064333081	0.0030284589	406.52765
34.376465	0.06869562	0.0032939003	429.35623
35.277344	0.067692883	0.0034249998	446.00705
36.178223	0.07394769	0.0036633392	467.88608
37.079102	0.077478528	0.0035831542	488.4397
37.97998	0.078974642	0.0039316616	512.60284
38.880859	0.081590071	0.0041566985	534.1076
39.781738	0.083180845	0.0043260879	555.46106
40.682617	0.087036997	0.0044525699	573.42957
41.583496	0.088598676	0.004428233	590.75537
42.484375	0.0910317	0.0046456982	619.34729
43.385254	0.096617237	0.0048703747	646.29474
44.286133	0.097604759	0.0049874275	669.93011
45.187012	0.098773867	0.0051966277	691.75952
46.087891	0.10362666	0.0053023412	716.26642
46.98877	0.10482255	0.0054434445	737.33551
47.889648	0.10962377	0.0055935332	765.23914
48.790527	0.10836902	0.005803749	781.7099
49.691406	0.11351766	0.0059612673	808.4892
50.592285	0.11302183	0.0061316076	838.70038
51.493164	0.11728305	0.0062765954	859.35577
52.394043	0.12203407	0.0063529531	886.03632
53.294922	0.12592694	0.0065333536	908.35089
54.195801	0.12675695	0.0066428455	942.13177
55.09668	0.12793338	0.0067380979	958.56549
55.997559	0.12948503	0.0069876029	980.85876
56.898438	0.13382682	0.0070245778	1014.3459
57.799316	0.13671333	0.0071920287	1040.8762
58.700195	0.14003456	0.0072515118	1056.6942
59.601074	0.14381433	0.0074971691	1090.1818
60.501953	0.14578901	0.0075681843	1113.5759
61.402832	0.14651126	0.0077090939	1136.0706
62.303711	0.14926909	0.0076612895	1157.4736
63.20459	0.15381701	0.0079062749	1178.0254
64.105469	0.15724765	0.0080569247	1208.3657
65.006348	0.15698293	0.0082173822	1232.264
65.907227	0.16261594	0.0082968622	1258.3373
66.808105	0.16105919	0.0083501125	1274.8903
67.708984	0.16448675	0.0085441377	1309.6952
68.609863	0.17160273	0.0087249232	1343.8138
69.510742	0.17207213	0.0087712891	1360.1892
70.411621	0.17547762	0.0089115202	1386.9819
71.3125	0.17787376	0.0090469914	1412.4248
72.213379	0.17934939	0.0092248647	1427.6973
73.114258	0.18445332	0.0092605185	1457.163
74.015137	0.18729496	0.0095147034	1479.7167
74.916016	0.18630739	0.0095047923	1501.1105
75.816895	0.19180231	0.0096837943	1531.1559
76.717773	0.19575378	0.0098863719	1567.6837
77.618652	0.1992213	0.009967708	1584.9196
78.519531	0.1982829	0.010091773	1602.4991
79.42041	0.19992448	0.010256593	1625.4257
80.321289	0.20539933	0.010323272	1656.4359
81.222168	0.20749332	0.010572921	1691.0574
82.123047	0.20998576	0.010612251	1708.7192
83.023926	0.21352439	0.010885245	1744.3492
83.924805	0.21585953	0.010882131	1762.4386
84.825684	0.21745256	0.011050287	1786.5853
85.726563	0.22053181	0.011194692	1811.1333
86.627441	0.22302036	0.011261703	1832.2018
87.52832	0.22598407	0.011375999	1851.6875
88.429199	0.2279084	0.011474496	1871.0256
89.330078	0.23425362	0.011691969	1906.5302
90.230957	0.23366128	0.011727422	1920.8634
91.131836	0.23565154	0.011827326	1946.5076
92.032715	0.23901169	0.011912045	1969.7339
92.933594	0.24192156	0.012066734	1988.6393
93.834473	0.24821816	0.012230663	2014.2832
94.735352	0.24739271	0.012327821	2030.7557
95.63623	0.2522479	0.012423811	2046.9091
96.537109	0.25342378	0.01259354	2079.9717
97.437988	0.2573415	0.012671615	2091.0251
98.338867	0.26026666	0.012889223	2118.251
99.239746	0.25886747	0.01292573	2132.0288
100.14063	0.26245588	0.012951936	2149.6953
101.0415	0.26749963	0.013092337	2168.0959
101.94238	0.26868984	0.013211685	2190.3098
102.84326	0.2717984	0.013294919	2206.3174
103.74414	0.27746093	0.013430243	2221.3152
104.64502	0.27746421	0.013577404	2230.6057
105.5459	0.28253478	0.013668743	2251.1277
106.44678	0.28252742	0.013813607	2267.8047
107.34766	0.2859093	0.013983808	2289.583
108.24854	0.2880252	0.014084683	2309.7505
109.14941	0.29070881	0.01417678	2319.0737
110.05029	0.29688725	0.014225867	2337.4373
110.95117	0.29794142	0.014306078	2347.583
111.85205	0.29776499	0.014589107	2369.9138
112.75293	0.30215511	0.014658232	2384.6133
113.65381	0.3040233	0.014743946	2393.668
114.55469	0.31061643	0.014918883	2407.7126
115.45557	0.31044063	0.014991938	2423.136
116.35645	0.31307262	0.01508547	2436.6248
117.25732	0.31422019	0.015224412	2445.7651
118.1582	0.31766027	0.015319325	2460.2668
119.05908	0.32074445	0.015463526	2471.0071
119.95996	0.32354346	0.015652815	2486.9875
120.86084	0.32940671	0.015804071	2498.1296
121.76172	0.33154723	0.015886609	2509.0613
122.6626	0.33419394	0.016072102	2523.8579
123.56348	0.33405462	0.01613191	2530.8665
124.46436	0.33865258	0.016307794	2535.4639
125.36523	0.34037688	0.016357807	2553.2253
126.26611	0.34167406	0.016555399	2559.0999
127.16699	0.34828782	0.01664659	2571.5662
128.06787	0.34929588	0.016783422	2576.4263
128.96875	0.352319	0.016920956	2590.7292
129.86963	0.35351804	0.017176406	2605.2769
130.77051	0.35796043	0.017314667	2616.8313
131.67139	0.36027318	0.017405281	2616.5376
132.57227	0.36415628	0.017409882	2620.0156
133.47314	0.36379033	0.017613575	2626.4717
134.37402	0.36660776	0.01774876	2645.0679
135.2749	0.36977491	0.017897103	2646.1975
136.17578	0.37448797	0.018124545	2659.5681
137.07666	0.37727651	0.018126074	2665.9099
137.97754	0.37855586	0.018424241	2673.906
138.87842	0.38428533	0.018655067	2683.9297
139.7793	0.38391858	0.018742587	2692.1624
140.68018	0.38708654	0.01889723	2708.0813
141.58105	0.38736212	0.019254789	2710.8342
142.48193	0.39213118	0.019384926	2721.3955
143.38281	0.39519158	0.019602844	2728.5388
144.28369	0.40095752	0.019881669	2734.3972
145.18457	0.40000722	0.019984802	2739.0564
146.08545	0.40299496	0.020331876	2752.7122
146.98633	0.40393582	0.020439103	2750.9875
147.88721	0.40607092	0.020830965	2767.7502
148.78809	0.40995356	0.021023348	2767.217
149.68896	0.41210738	0.021320174	2776.2266
150.58984	0.41398475	0.021698048	2790.8606
151.49072	0.41995582	0.02192444	2798.5315
152.3916	0.42041069	0.022318693	2803.7896
153.29248	0.42519403	0.022595182	2807.8428
154.19336	0.42453569	0.022886638	2816.8789
155.09424	0.43067521	0.023267021	2824.5591
155.99512	0.43174821	0.023632525	2830.7307
156.896	0.43662083	0.024035268	2839.207
157.79688	0.44005457	0.024496833	2846.6299
158.69775	0.44260237	0.0248264	2845.3962
159.59863	0.44649893	0.02513879	2855.0244
160.49951	0.44720069	0.025496414	2861.7981
161.40039	0.45013919	0.025970759	2868.8352
162.30127	0.45250732	0.02650376	2880.8047
163.20215	0.45881075	0.026973965	2875.7966
164.10303	0.45850566	0.027520418	2880.946
165.00391	0.46038467	0.027993932	2894.3308
165.90479	0.46081287	0.028597087	2890.6245
166.80566	0.46775222	0.029033065	2895.5093
167.70654	0.47185886	0.029608307	2906.5327
168.60742	0.47112516	0.030209487	2909.7268
169.5083	0.47505367	0.030559454	2905.9607
170.40918	0.47719103	0.031263441	2919.7288
171.31006	0.47919548	0.031690232	2919.8286
172.21094	0.48303059	0.032226652	2923.5115
173.11182	0.48535344	0.032915156	2930.5073
174.0127	0.48663908	0.033574969	2942.1482
174.91357	0.49098885	0.034295741	2942.0293
175.81445	0.49153981	0.034826964	2942.7139
176.71533	0.49357516	0.03569011	2948.8721
177.61621	0.49765861	0.036284488	2952.385
178.51709	0.49959135	0.037013445	2945.8079
179.41797	0.50250977	0.037747707	2961.6587
180.31885	0.5080657	0.038553748	2971.3945
181.21973	0.50744653	0.039194237	2962.5012
182.12061	0.51250505	0.039932471	2973.7024
183.02148	0.51504159	0.040768374	2978.9961
183.92236	0.51835954	0.041407477	2971.9924
184.82324	0.52021557	0.042081237	2984.7468
185.72412	0.52391958	0.042990688	2989.4951
186.625	0.52746171	0.043814924	2997.9485
187.52588	0.52875906	0.044751171	2993.1367
188.42676	0.5267362	0.04546015	3001.3843
189.32764	0.53317463	0.046467476	3002.5613
190.22852	0.53602135	0.047462277	3011.8357
191.12939	0.54006386	0.048465811	3007.9392
192.03027	0.54227412	0.049165521	3007.7944
192.93115	0.54541612	0.049925197	3014.8672
193.83203	0.54600334	0.050696645	3011.4834
194.73291	0.55048853	0.051568199	3027.4614
195.63379	0.55371696	0.052562669	3027.3191
196.53467	0.55561996	0.053334836	3023.498
197.43555	0.55613446	0.054285463	3029.0742
198.33643	0.56291705	0.055272661	3032.9094
199.2373	0.56301928	0.056058813	3033.7673
200.13818	0.56568742	0.057050459	3036.4524
201.03906	0.56938314	0.057848357	3039.49
201.93994	0.57345796	0.058891647	3043.0005
202.84082	0.57806432	0.059780799	3048.4927
203.7417	0.57422179	0.060573634	3048.6758
204.64258	0.58142817	0.061390217	3046.5134
205.54346	0.58465207	0.062311601	3056.3098
206.44434	0.58318692	0.063299567	3055.5381
207.34521	0.58419245	0.064279608	3061.8252
208.24609	0.59343916	0.065173753	3060.7869
209.14697	0.59429389	0.065983362	3063.8445
210.04785	0.59840584	0.066652276	3066.4231
210.94873	0.59816712	0.067648813	3066.9348
211.84961	0.60174304	0.068353951	3068.2341
212.75049	0.60305476	0.069182664	3077.3823
213.65137	0.60536081	0.070115469	3076.4539
214.55225	0.60873079	0.071241677	3082.2761
215.45313	0.61383152	0.072359554	3082.4316
216.354	0.61540461	0.073069796	3079.7876
217.25488	0.61728245	0.074162863	3090.2815
218.15576	0.61996955	0.075340062	3091.9966
219.05664	0.62219363	0.076329634	3094.874
219.95752	0.62612027	0.077237815	3093.251
220.8584	0.62753952	0.078120634	3097.969
221.75928	0.62887293	0.079076082	3100.0471
222.66016	0.63227499	0.080050506	3100.2156
223.56104	0.63720769	0.081336305	3108.9014
224.46191	0.64014941	0.082188815	3103.9431
225.36279	0.6416797	0.083380692	3109.8716
226.26367	0.64485407	0.08452078	3115.7405
227.16455	0.64609283	0.085351653	3108.7864
228.06543	0.65089834	0.086182199	3109.8525
228.96631	0.65098721	0.086990491	3117.9844
229.86719	0.65397042	0.087880135	3115.4661
230.76807	0.66009861	0.088832907	3123.752
231.66895	0.65884429	0.089950643	3128.5859
232.56982	0.66371125	0.090850949	3126.1443
233.4707	0.66616559	0.091808565	3133.7842
234.37158	0.67084503	0.092892125	3135.0283
235.27246	0.67263538	0.0938337	3130.228
236.17334	0.67645752	0.09476465	3134.6768
237.07422	0.67616087	0.09587837	3139.5591
237.9751	0.67966795	0.097086951	3144.3662
238.87598	0.68279719	0.09808147	3140.4385
239.77686	0.68374461	0.098958313	3141.7825
240.67773	0.68962985	0.099944867	3142.5652
241.57861	0.68925631	0.10065062	3136.9646
242.47949	0.69502592	0.10145122	3145.9434
243.38037	0.69523168	0.10241609	3155.9365
244.28125	0.69972551	0.10352787	3159.0422
245.18213	0.70506322	0.10458714	3157.8179
246.08301	0.70548922	0.10543543	3155.1096
246.98389	0.7093913	0.1064306	3168.4497
247.88477	0.70908499	0.1074923	3158.813
248.78564	0.71500176	0.10846236	3165.0962
249.68652	0.71550971	0.10948399	3167.1987
250.5874	0.71725684	0.11056509	3169.9226
251.48828	0.72135502	0.11166652	3171.2192
252.38916	0.72369969	0.11266067	3174.7778
253.29004	0.72312027	0.11376681	3174.0283
254.19092	0.72799402	0.11449565	3170.5405
255.0918	0.73122531	0.11541507	3171.2722
255.99268	0.7345621	0.11626371	3179.9075
256.89355	0.73575228	0.11722989	3179.0935
257.79443	0.73924118	0.11830588	3187.5515
258.69531	0.74422181	0.11919803	3189.0278
259.59619	0.74238068	0.12034756	3186.5691
260.49707	0.74685419	0.1214264	3189.9946
261.39795	0.74855536	0.1223634	3189.0308
262.29883	0.75392491	0.12343384	3196.2175
263.19971	0.75703698	0.12458996	3198.281
264.10059	0.76070285	0.12575851	3204.2021
265.00146	0.76060325	0.12676176	3196.5076
265.90234	0.76392162	0.12771419	3200.303
266.80322	0.7658785	0.12875183	3205.8413
267.7041	0.76864922	0.12964025	3206.8806
268.60498	0.77417099	0.13081805	3211.7991
269.50586	0.77663845	0.13172014	3210.5105
270.40674	0.77780837	0.13262971	3206.1243
271.30762	0.78079379	0.13356972	3210.2405
272.2085	0.78527528	0.13436538	3210.6492
273.10938	0.78219253	0.13546133	3214.166
274.01025	0.78774035	0.13655342	3220.5522
274.91113	0.78898233	0.13756005	3213.021
275.81201	0.79430026	0.1385521	3217.5496
276.71289	0.79723203	0.1393733	3215.8281
277.61377	0.80048704	0.14021438	3226.1755
278.51465	0.80054033	0.14117074	3219.8096
279.41553	0.80341554	0.14219058	3224.8208
280.31641	0.80653048	0.14316382	3229.0825
281.21729	0.80768853	0.14410567	3228.9155
282.11816	0.81109601	0.14518093	3225.6699
283.01904	0.81442463	0.14610942	3223.906
283.91992	0.81643271	0.14717692	3236.7991
284.8208	0.82152158	0.1482192	3238.3491
285.72168	0.8248328	0.14924879	3239.7688
286.62256	0.82582051	0.1505681	3243.3948
287.52344	0.82828206	0.15161307	3236.208
288.42432	0.83171862	0.15256198	3242.3218
289.3252	0.83350265	0.15352471	3241.6157
290.22607	0.83557403	0.15452425	3252.1082
291.12695	0.83663309	0.15540218	3244.6235
292.02783	0.84007502	0.15636963	3249.3484
292.92871	0.84447664	0.1574209	3248.6875
293.82959	0.84827632	0.15830997	3253.5151
294.73047	0.8487429	0.15945172	3254.8838
295.63135	0.85352516	0.16054824	3256.1599
296.53223	0.85547262	0.16153754	3256.7117
297.43311	0.85939133	0.16254826	3259.8591
298.33398	0.86111981	0.16371776	3263.7612
299.23486	0.86535054	0.16480759	3265.53
300.13574	0.86688942	0.16599119	3264.4226
301.03662	0.86786324	0.16680488	3258.1682
301.9375	0.87475002	0.16768152	3262.8584
302.83838	0.87429166	0.16871229	3261.293
303.73926	0.87681383	0.16966912	3267.2114
304.64014	0.88336325	0.17052501	3269.7527
305.54102	0.88271725	0.17163594	3282.2173
306.44189	0.88593298	0.17291354	3276.9783
307.34277	0.88840193	0.17389224	3271.7661
308.24365	0.8905977	0.17483883	3278.3545
309.14453	0.89590943	0.17592943	3286.0735
310.04541	0.89748663	0.17679441	3276.4978
310.94629	0.89887971	0.1778612	3288.96
311.84717	0.90062374	0.17879716	3278.5173
312.74805	0.90618926	0.17987478	3284.3538
313.64893	0.90829206	0.18090251	3286.5476
314.5498	0.9107374	0.18181574	3289.8274
315.45068	0.91293669	0.18282185	3296.4211
316.35156	0.91334528	0.18398724	3287.5901
317.25244	0.9171201	0.18479705	3284.8149
318.15332	0.92087775	0.18562737	3289.5508
319.0542	0.92101854	0.18676944	3297.6787
319.95508	0.92621797	0.18775374	3294.2107
320.85596	0.92771941	0.18886976	3298.7046
321.75684	0.93456453	0.19011883	3308.031
322.65771	0.93297088	0.19116622	3297.3279
323.55859	0.9345004	0.19202754	3299.8723
324.45947	0.94158959	0.1930979	3302.6909
325.36035	0.94063848	0.1941283	3308.374
326.26123	0.94542038	0.19509923	3309.4785
327.16211	0.94496059	0.19604871	3303.624
328.06299	0.9480952	0.19688568	3310.7786
328.96387	0.95240319	0.19802979	3314.8223
329.86475	0.95170778	0.19915314	3320.9351
330.76563	0.95895636	0.20036592	3322.6765
331.6665	0.96381605	0.20138507	3316.9121
332.56738	0.96577585	0.20229609	3323.123
333.46826	0.96321326	0.20330204	3317.8193
334.36914	0.97107387	0.20438908	3322.6418
335.27002	0.97125947	0.20541646	3319.1099
336.1709	0.97483194	0.20638968	3324.2012
337.07178	0.97650158	0.20758812	3328.1802
337.97266	0.97929275	0.20861496	3327.3696
338.87354	0.98091751	0.20968172	3329.7534
339.77441	0.98445493	0.21065503	3333.5178
340.67529	0.98799992	0.2118237	3336.2837
341.57617	0.98768497	0.21283267	3332.835
342.47705	0.99612683	0.21393019	3333.3591
343.37793	0.99598074	0.21493213	3340.3105
344.27881	0.99757516	0.21604711	3340.4277
345.17969	1.0026081	0.21720333	3341.0278
346.08057	1.0030017	0.21810684	3335.2869
346.98145	1.0064734	0.21911824	3339.0115
347.88232	1.011425	0.21993954	3345.7085
348.7832	1.0109891	0.2209339	3340.7998
349.68408	1.01578	0.22164667	3341.9673
350.58496	1.0182581	0.22262448	3347.5769
351.48584	1.0184175	0.22358243	3341.2927
352.38672	1.021832	0.22460815	3347.2319
353.2876	1.0265838	0.2255874	3353.3906
354.18848	1.0275047	0.22665055	3353.7666
355.08936	1.0319598	0.22770116	3353.8765
355.99023	1.0334352	0.2285949	3346.5283
356.89111	1.0349607	0.22962375	3364.1206
357.79199	1.0426226	0.23044302	3360.3972
358.69287	1.0440776	0.2315717	3362.5828
359.59375	1.0449052	0.23269705	3366.4729
360.49463	1.0474217	0.23390052	3366.3943
361.39551	1.0503886	0.23484185	3358.3838
362.29639	1.0536325	0.23593096	3364.3101
363.19727	1.0549316	0.2367793	3363.3704
364.09814	1.0584397	0.23790893	3368.9802
364.99902	1.0604243	0.23896891	3366.8228
365.8999	1.0659586	0.24002792	3372.6821
366.80078	1.0653367	0.24133402	3379.543
367.70166	1.0683949	0.24253707	3377.9709
368.60254	1.0727631	0.24353914	3371.1733
369.50342	1.0751642	0.24451509	3374.4468
370.4043	1.075857	0.24543479	3371.4915
371.30518	1.0791409	0.24649899	3372.687
372.20605	1.0839283	0.2473754	3383.2056
373.10693	1.0854546	0.24861623	3385.9326
374.00781	1.0860578	0.24970675	3384.2722
374.90869	1.0903991	0.25068122	3380.5579
375.80957	1.094486	0.2516849	3382.3855
376.71045	1.096379	0.25262073	3387.0049
377.61133	1.0982394	0.25371587	3385.8389
378.51221	1.0990714	0.25474092	3388.8083
379.41309	1.1057209	0.25580427	3387.6194
380.31396	1.1082736	0.25685075	3391.2532
381.21484	1.1085701	0.25773811	3387.5298
382.11572	1.1178267	0.25868392	3394.7708
383.0166	1.1152958	0.25979891	3396.7683
383.91748	1.1191773	0.26088464	3397.6006
384.81836	1.119545	0.26191768	3402.1213
385.71924	1.1264033	0.26267612	3390.8083
386.62012	1.1314362	0.26356691	3399.9082
387.521	1.1293238	0.26469305	3398.437
388.42188	1.1330588	0.26575711	3404.6501
389.32275	1.1336597	0.26677531	3403.7761
390.22363	1.1363764	0.26786992	3405.877
391.12451	1.1372131	0.26885471	3406.7158
392.02539	1.1419723	0.26974425	3404.7822
392.92627	1.1440986	0.27075693	3403.1262
393.82715	1.1512375	0.27185494	3411.5852
394.72803	1.1500732	0.27309951	3416.79
395.62891	1.1533395	0.27415931	3411.4543
396.52979	1.1541018	0.27518389	3409.1504
397.43066	1.1578608	0.27626207	3417.5122
398.33154	1.1619411	0.27723435	3415.4446
399.23242	1.1657603	0.27808684	3415.4951
400.1333	1.1678923	0.27914327	3418.3835
401.03418	1.1689713	0.2803365	3421.5232
401.93506	1.1715627	0.28154364	3424.937
402.83594	1.1729922	0.28245783	3421.0256
403.73682	1.1781527	0.28379789	3433.0608
404.6377	1.1796969	0.28508866	3423.9048
405.53857	1.1840308	0.28612697	3425.2346
406.43945	1.1848509	0.28702885	3421.7632
407.34033	1.1880503	0.28779221	3419.1177
408.24121	1.1895332	0.2887601	3419.2048
409.14209	1.1917597	0.28969705	3428.9072
410.04297	1.1976006	0.29080233	3435.5518
410.94385	1.2005922	0.29183111	3437.5537
411.84473	1.2015082	0.29305777	3433.7642
412.74561	1.2043346	0.29410088	3433.0913
413.64648	1.2074467	0.2950474	3435.7075
414.54736	1.2096318	0.29596967	3425.8164
415.44824	1.2128679	0.29699981	3443.2747
416.34912	1.2174581	0.29804701	3441.9404
417.25	1.2178735	0.29918045	3445.8442
418.15088	1.2194798	0.30040076	3439.5952
419.05176	1.2253113	0.30121294	3441.3406
419.95264	1.2246008	0.30217296	3438.2749
420.85352	1.2274948	0.30304694	3446.6602
421.75439	1.2328366	0.30411878	3447.0046
422.65527	1.2369705	0.3049047	3445.5774
423.55615	1.2376459	0.30591431	3450.2913
424.45703	1.2383885	0.30691418	3450.3164
425.35791	1.2404622	0.30801964	3453.5288
426.25879	1.2446866	0.30905923	3446.3118
427.15967	1.2461858	0.30979306	3450.5735
428.06055	1.2499144	0.31098807	3453.9539
428.96143	1.2544396	0.31208819	3457.3149
429.8623	1.256013	0.3131851	3461.6775
430.76318	1.2577058	0.31439611	3460.5713
431.66406	1.2590157	0.31542909	3452.5833
432.56494	1.2642963	0.31642902	3461.635
433.46582	1.2676284	0.31750432	3451.041
434.3667	1.2699492	0.31852949	3463.8293
435.26758	1.271602	0.31965753	3463.7739
436.16846	1.2739476	0.32089627	3470.9011
437.06934	1.2772721	0.32202348	3469.8887
437.97021	1.2792269	0.32321113	3464.9644
438.87109	1.2843004	0.3242287	3464.9221
439.77197	1.2880517	0.32535481	3472.1111
440.67285	1.287249	0.326336	3466.6702
441.57373	1.2912982	0.32723013	3469.1394
442.47461	1.293746	0.32810509	3465.9651
443.37549	1.2953538	0.32925525	3481.4192
444.27637	1.3007933	0.33035454	3482.668
445.17725	1.3003705	0.33148035	3475.3845
446.07813	1.3020912	0.33265585	3481.5227
446.979	1.3074411	0.33385614	3477.3652
447.87988	1.3096285	0.33487034	3478.5005
448.78076	1.3128545	0.335886	3480.0662
449.68164	1.3159659	0.33672595	3473.9314
450.58252	1.3192669	0.33769664	3481.9241
451.4834	1.3204029	0.33868954	3479.7952
452.38428	1.3224648	0.3399457	3488.959
453.28516	1.327414	0.34110799	3490.1965
454.18604	1.3268367	0.34213084	3485.9958
455.08691	1.3318257	0.34323722	3482.0842
455.98779	1.3345493	0.34435278	3488.7324
456.88867	1.3385314	0.34527186	3482.6812
457.78955	1.3406503	0.34609884	3486.7573
458.69043	1.3423625	0.34714556	3491.4653
459.59131	1.3439568	0.34813699	3492.5229
460.49219	1.3483795	0.34925103	3496.4185
461.39307	1.3498535	0.35018179	3494.1199
462.29395	1.3543891	0.35116133	3493.762
463.19482	1.3560182	0.35226837	3500.8044
464.0957	1.3569846	0.35348779	3495.8237
464.99658	1.3593609	0.35479796	3498.6685
465.89746	1.3627441	0.35593218	3500.2427
466.79834	1.3661445	0.35696346	3501.855
467.69922	1.3703663	0.35783252	3496.9194
468.6001	1.3723804	0.35889927	3503.7207
469.50098	1.3770299	0.35997513	3501.6204
470.40186	1.3751509	0.36092132	3499.2124
471.30273	1.3809624	0.36173302	3504.571
472.20361	1.3815297	0.36281472	3503.4944
473.10449	1.3861952	0.36388943	3512.9351
474.00537	1.3911922	0.36520052	3517.1116
474.90625	1.3923877	0.36646417	3507.9121
475.80713	1.3952863	0.36764541	3519.2415
476.70801	1.3964167	0.36871961	3505.5549
477.60889	1.3997707	0.36962008	3512.1672
478.50977	1.4035312	0.37069488	3515.4978
479.41064	1.4038072	0.37188447	3514.2256
480.31152	1.4045227	0.37281531	3507.5066
481.2124	1.4086618	0.37385699	3515.2458
482.11328	1.4131255	0.37503251	3520.144
483.01416	1.4164819	0.37601954	3515.6765
483.91504	1.4200672	0.37696373	3520.645
484.81592	1.4188861	0.37789342	3512.3701
485.7168	1.4231744	0.37907881	3523.1008
486.61768	1.4238786	0.38011262	3523.1584
487.51855	1.4285831	0.3814249	3523.7043
488.41943	1.4297353	0.38264608	3526.1858
489.32031	1.4336779	0.38371938	3523.8765
490.22119	1.4396073	0.38465023	3524.7705
491.12207	1.43906	0.38566223	3527.8933
492.02295	1.4414994	0.38686562	3528.8103
492.92383	1.4476345	0.38778198	3531.5857
493.82471	1.4449373	0.38883296	3527.4531
494.72559	1.4504764	0.38979498	3529.5225
495.62646	1.4554236	0.39080036	3529.6404
496.52734	1.4568493	0.39174569	3536.0981
497.42822	1.4590428	0.39262629	3531.5659
498.3291	1.4623777	0.39376777	3539.1177
499.22998	1.4660196	0.3946549	3535.0381
500.13086	1.465507	0.39571914	3535.2224
501.03174	1.4690473	0.39682791	3535.7334
501.93262	1.4735467	0.39797467	3545.3672
502.8335	1.4754686	0.39920783	3536.4419
503.73438	1.4751742	0.40034857	3540.5679
504.63525	1.4803767	0.40154332	3538.2178
505.53613	1.4846832	0.40247488	3537.5444
506.43701	1.4845991	0.40341732	3537.448
507.33789	1.4878021	0.40446326	3544.9397
508.23877	1.4916414	0.40589541	3552.1006
509.13965	1.4950227	0.40709782	3548.1831
510.04053	1.4941653	0.40820584	3544.4211
510.94141	1.4974296	0.409192	3546.782
511.84229	1.50166	0.41049573	3545.7539
512.74316	1.5036877	0.41142339	3544.9519
513.64404	1.5065892	0.4125998	3546.5693
514.54492	1.5117059	0.4137778	3557.3721
515.4458	1.5115266	0.41486213	3558.9915
516.34668	1.5179423	0.41597003	3547.3252
517.24756	1.5198041	0.41685045	3550.1448
518.14844	1.5221435	0.41785356	3554.3079
519.04932	1.5224023	0.41893536	3560.9983
519.9502	1.5261989	0.42000476	3551.729
520.85107	1.5290883	0.42094329	3553.925
521.75195	1.5296531	0.42222777	3563.1223
522.65283	1.5325457	0.42339769	3556.7571
523.55371	1.5375751	0.42459255	3558.5066
524.45459	1.5391097	0.425632	3563.301
525.35547	1.5425266	0.42658406	3562.6973
526.25635	1.5451543	0.42773324	3567.6719
527.15723	1.5450331	0.42879835	3562.5601
528.05811	1.5519587	0.43000412	3566.5789
528.95898	1.5542995	0.43098658	3564.6487
529.85986	1.5558176	0.43202209	3563.366
530.76074	1.5601256	0.43306878	3568.6416
531.66162	1.5590485	0.43409699	3565.1646
532.5625	1.5637509	0.43507624	3564.0198
533.46338	1.5672981	0.43628383	3569.3083
534.36426	1.5699764	0.43730149	3567.2175
535.26514	1.5734018	0.43834224	3570.5696
536.16602	1.575894	0.43960363	3574.2061
537.06689	1.5747589	0.4407846	3567.1438
537.96777	1.5792224	0.44203016	3572.4197
538.86865	1.5842351	0.44294578	3570.5842
539.76953	1.5880859	0.44418496	3578.3994
540.67041	1.5885785	0.44527861	3572.4766
541.57129	1.5907447	0.44633734	3571.8521
542.47217	1.5935028	0.4475171	3585.8499
543.37305	1.5957355	0.44873291	3580.5029
544.27393	1.597932	0.45002773	3580.0315
545.1748	1.6025383	0.45114192	3579.6182
546.07568	1.6048942	0.45226774	3574.5608
546.97656	1.6061007	0.45340413	3585.1704
547.87744	1.61063	0.45459041	3585.978
548.77832	1.6135877	0.45572966	3580.176
549.6792	1.6157979	0.45678183	3588.8433
550.58008	1.6187638	0.4580242	3584.1138
551.48096	1.6221224	0.45922425	3591.3208
552.38184	1.6237012	0.46026748	3582.9653
553.28271	1.6246775	0.4612492	3580.3599
554.18359	1.6298515	0.46240935	3591.9773
555.08447	1.6317536	0.46340519	3587.563
555.98535	1.6335754	0.46454147	3594.0005
556.88623	1.634915	0.46581	3597.6016
557.78711	1.6391622	0.46692261	3590.053
558.68799	1.6429616	0.46823746	3596.5112
559.58887	1.6472305	0.46968541	3602.1187
560.48975	1.6487033	0.47071937	3591.9961
561.39063	1.6493187	0.47183374	3592.3596
562.2915	1.6519841	0.47275788	3586.7844
563.19238	1.6547595	0.47366133	3592.0386
564.09326	1.6565512	0.47472912	3596.2244
564.99414	1.6637065	0.47579658	3599.9417
565.89502	1.6636916	0.4767842	3590.4602
566.7959	1.6654738	0.47793564	3599.2502
567.69678	1.6684678	0.47902986	3599.4063
568.59766	1.671021	0.48009765	3596.6899
569.49854	1.6745831	0.48123026	3596.781
570.39941	1.6777371	0.48225743	3605.1575
571.30029	1.6808033	0.48319799	3604.845
572.20117	1.6807687	0.4845587	3606.0852
573.10205	1.6854157	0.48571703	3600.2681
574.00293	1.6889586	0.48676136	3603.1492
574.90381	1.6890603	0.4878822	3600.8755
575.80469	1.6948797	0.48914769	3610.1138
576.70557	1.6949356	0.49027681	3607.2744
577.60645	1.6978399	0.49147102	3607.3149
578.50732	1.7025889	0.49261642	3609.9558
579.4082	1.7044495	0.49367398	3609.8906
580.30908	1.7096361	0.4948217	3603.9272
581.20996	1.7085778	0.49592301	3612.2283
582.11084	1.7109941	0.49709621	3609.0369
583.01172	1.7156603	0.4982945	3609.3687
583.9126	1.7167826	0.49960718	3612.4775
584.81348	1.7184439	0.50083649	3609.7202
585.71436	1.7224545	0.50203913	3616.113
586.61523	1.7267303	0.50322074	3610.8516
587.51611	1.731015	0.50426579	3613.98
588.41699	1.7279108	0.50537527	3611.8745
589.31787	1.7343386	0.50663835	3618.9016
590.21875	1.739284	0.50778753	3618.7432
591.11963	1.7385223	0.50896174	3622.4136
592.02051	1.7415618	0.51007676	3617.1426
592.92139	1.7469504	0.51132035	3621.6523
593.82227	1.7479925	0.5125019	3625.4121
594.72314	1.7500329	0.51371086	3620.658
595.62402	1.7563671	0.51485705	3619.4089
596.5249	1.7542844	0.51591766	3618.7488
597.42578	1.7593158	0.51713693	3622.2896
598.32666	1.7611246	0.51828396	3629.856
599.22754	1.7661793	0.51941395	3622.2549
600.12842	1.7674056	0.52076507	3624.5232
601.0293	1.7679818	0.52180719	3621.6875
601.93018	1.7749115	0.52287221	3626.541
602.83105	1.771639	0.52409554	3620.446
603.73193	1.7772309	0.52527326	3629.5046
604.63281	1.7803538	0.5262965	3622.0361
605.53369	1.7827162	0.52740121	3623.9873
606.43457	1.7887973	0.52849436	3631.5571
607.33545	1.7911617	0.52958095	3631.1812
608.23633	1.7924314	0.53072137	3625.1855
609.13721	1.794059	0.53184921	3630.0637
610.03809	1.7961111	0.53310448	3628.9221
610.93896	1.7958018	0.53417736	3625.2368
611.83984	1.8023183	0.53540659	3636.77
612.74072	1.8040611	0.53667098	3633.7654
613.6416	1.8076017	0.53777707	3626.4443
614.54248	1.8072505	0.53888047	3632.0317
615.44336	1.810917	0.54003143	3630.2407
616.34424	1.8175462	0.54122549	3638.2478
617.24512	1.8155984	0.54247332	3635.1013
618.146	1.8211373	0.54371667	3635.6855
619.04688	1.8245778	0.54494774	3636.3799
619.94775	1.8274859	0.54634982	3641.4897
620.84863	1.8301495	0.54761916	3637.7227
621.74951	1.829441	0.54908866	3640.0156
622.65039	1.8325516	0.55037808	3636.9119
623.55127	1.836264	0.55160004	3635.052
624.45215	1.8404531	0.55248481	3634.2795
625.35303	1.8414583	0.55378419	3638.7463
626.25391	1.8440844	0.55478621	3638.3523
627.15479	1.8483655	0.55603677	3638.4758
628.05566	1.8517675	0.55726624	3646.1052
628.95654	1.8515825	0.55853617	3648.1294
629.85742	1.8575251	0.55968785	3642.8315
630.7583	1.8588456	0.56101954	3645.4958
631.65918	1.8595434	0.56215876	3645.8462
632.56006	1.8645167	0.5634824	3646.9177
633.46094	1.8670367	0.56480342	3645.1931
634.36182	1.8679553	0.56597728	3640.3718
635.2627	1.8719509	0.56719315	3648.3462
636.16357	1.8772775	0.56844991	3650.1064
637.06445	1.8785411	0.56970108	3646.4163
637.96533	1.8788273	0.57088947	3648.0461
638.86621	1.8868355	0.57222968	3654.4102
639.76709	1.8842975	0.57342649	3651.5669
640.66797	1.8894125	0.57486224	3649.9888
641.56885	1.8901874	0.57590395	3642.1672
642.46973	1.8943825	0.57681739	3644.0007
643.37061	1.8961738	0.57808727	3655.9285
644.27148	1.8995963	0.57945919	3651.2632
645.17236	1.9019259	0.58066136	3651.3164
646.07324	1.9049212	0.58198452	3648.8286
646.97412	1.906271	0.58316958	3651.4219
647.875	1.9100286	0.5842635	3656.126
648.77588	1.9122093	0.58542871	3653.8767
649.67676	1.9167014	0.58663797	3654.5356
650.57764	1.9149184	0.58800584	3653.3015
651.47852	1.9238237	0.58914769	3655.2834
652.37939	1.9205453	0.59056109	3653.1521
653.28027	1.9287841	0.59191656	3661.7852
654.18115	1.927436	0.59336942	3661.4858
655.08203	1.9301733	0.59456927	3659.7712
655.98291	1.9356261	0.59593791	3656.2002
656.88379	1.9372534	0.59714746	3656.9758
657.78467	1.9418302	0.59833121	3659.3972
658.68555	1.9416835	0.59942418	3657.1899
659.58643	1.9465984	0.60038382	3656.5049
660.4873	1.9474229	0.60183007	3663.7507
661.38818	1.9520607	0.60318762	3660.5479
662.28906	1.9541833	0.60467213	3669.1033
663.18994	1.9554579	0.6059559	3658.1011
664.09082	1.9602374	0.60741025	3664.1602
664.9917	1.9611998	0.60854763	3661.2644
665.89258	1.9645077	0.60964739	3657.2205
666.79346	1.9672167	0.61088663	3659.0134
667.69434	1.9712679	0.61214328	3663.5146
668.59521	1.9725592	0.61316353	3658.9634
669.49609	1.9740636	0.61442035	3664.5012
670.39697	1.9782881	0.61580789	3666.5911
671.29785	1.9808731	0.61698377	3661.9778
672.19873	1.9835945	0.61811656	3661.6021
673.09961	1.9856522	0.6194182	3666.5178
674.00049	1.9872364	0.62062562	3665.9905
674.90137	1.991413	0.62186432	3667.3611
675.80225	1.9954362	0.62347925	3674.8096
676.70313	1.9972566	0.62475216	3663.4675
677.604	1.997924	0.62586921	3666.5884
678.50488	2.0056226	0.6271981	3671.4297
679.40576	2.0016215	0.62836009	3667.4592
680.30664	2.0074663	0.62974006	3667.0881
681.20752	2.0106983	0.63083118	3666.5764
682.1084	2.011735	0.63219225	3667.2976
683.00928	2.0161855	0.63328153	3670.502
683.91016	2.0167961	0.6347959	3677.5156
684.81104	2.0204282	0.63618195	3675.0051
685.71191	2.0216219	0.63747507	3665.3818
686.61279	2.0231676	0.63888383	3674.2048
687.51367	2.0282869	0.64033651	3673.9553
688.41455	2.0311651	0.64162308	3671.2827
689.31543	2.0347495	0.64299667	3673.3186
690.21631	2.0368829	0.64426458	3667.1987
691.11719	2.0416687	0.64548141	3671.0569
692.01807	2.0431597	0.64674866	3674.1587
692.91895	2.0458136	0.64804119	3679.2239
693.81982	2.0463398	0.64938545	3676.4758
694.7207	2.0511279	0.65042269	3673.7637
695.62158	2.0527	0.65162337	3669.2649
696.52246	2.0535734	0.65281314	3673.0042
697.42334	2.0594578	0.65424562	3674.7791
698.32422	2.0591934	0.65557331	3675.8376
699.2251	2.0613585	0.65694946	3672.5317
700.12598	2.0673077	0.65820861	3672.9585
701.02686	2.068855	0.65965003	3674.3999
701.92773	2.0730226	0.66105461	3679.2385
702.82861	2.0741141	0.66230983	3675.6609
703.72949	2.0778258	0.66376036	3677.6025
704.63037	2.0810232	0.66525817	3683.0127
705.53125	2.0839398	0.66648698	3683.5276
706.43213	2.0836861	0.66792679	3680.5798
707.33301	2.0849657	0.66886199	3674.6396
708.23389	2.0899372	0.67037058	3680.4817
709.13477	2.094501	0.67173052	3679.4963
710.03564	2.0976875	0.67283469	3676.3184
710.93652	2.0981398	0.67392004	3675.2822
711.8374	2.1029384	0.67522657	3679.813
712.73828	2.1061649	0.67644697	3680.1318
713.63916	2.1070883	0.67769933	3682.9258
714.54004	2.1110981	0.67897546	3681.2529
715.44092	2.1118119	0.68045092	3681.8989
716.3418	2.1133614	0.68180537	3680.2737
717.24268	2.1161284	0.68340129	3684.2488
718.14355	2.1216824	0.68486291	3684.4348
719.04443	2.1212332	0.68632817	3684.2339
719.94531	2.1248841	0.68770725	3682.0208
720.84619	2.1306214	0.68903232	3683.9236
721.74707	2.1305759	0.69046766	3682.3059
722.64795	2.1352339	0.6918298	3683.4485
723.54883	2.1354244	0.69309729	3683.156
724.44971	2.1378551	0.69443351	3684.4873
725.35059	2.1444154	0.69613838	3689.9082
726.25146	2.1448288	0.69758147	3689.0552
727.15234	2.1488893	0.6989423	3683.3772
728.05322	2.1476433	0.7000894	3684.3621
728.9541	2.1532161	0.70161998	3687.6545
729.85498	2.1575694	0.70327103	3694.4822
730.75586	2.1577277	0.70459038	3682.2717
731.65674	2.1600318	0.70595318	3685.5415
732.55762	2.1649525	0.70738119	3686.5991
733.4585	2.1658425	0.70877939	3685.8367
734.35938	2.1677098	0.70995957	3681.3826
735.26025	2.1698873	0.71097434	3676.5166
736.16113	2.1746676	0.71233952	3689.3665
737.06201	2.1771858	0.71390957	3690.8203
737.96289	2.1762443	0.71545684	3682.9014
738.86377	2.1833742	0.71682304	3684.0229
739.76465	2.1856472	0.7180354	3681.1672
740.66553	2.1898043	0.71943504	3686.4272
741.56641	2.1925805	0.72092974	3687.8413
742.46729	2.1951728	0.72237909	3693.7314
743.36816	2.1937459	0.7236892	3687.5261
744.26904	2.1982632	0.72496098	3686.4932
745.16992	2.201812	0.72618622	3684.2332
746.0708	2.2042453	0.72754085	3689.6836
746.97168	2.2069678	0.72885531	3689.3965
747.87256	2.2088795	0.73029083	3687.8518
748.77344	2.213707	0.73178792	3696.4922
749.67432	2.2140706	0.733163	3686.7913
750.5752	2.219929	0.73461485	3690.7388
751.47607	2.2179112	0.73624456	3689.406
752.37695	2.2237267	0.73788643	3696.2693
753.27783	2.224828	0.73932534	3688.0391
754.17871	2.2287753	0.74070495	3688.5657
755.07959	2.2342281	0.74208653	3691.5361
755.98047	2.2346184	0.74342251	3686.1584
756.88135	2.2384348	0.74468696	3688.5898
757.78223	2.2374079	0.74600619	3692.7144
758.68311	2.2428753	0.74762815	3696.7205
759.58398	2.2455704	0.74915206	3690.7793
760.48486	2.2486365	0.75055104	3690.425
761.38574	2.2495985	0.75200349	3685.3391
762.28662	2.253021	0.7536698	3695.8064
763.1875	2.2562718	0.75530118	3696.5364
764.08838	2.2572176	0.75649476	3684.3662
764.98926	2.2622807	0.75795287	3694.0557
765.89014	2.2652242	0.7592628	3692.0522
766.79102	2.266314	0.76082265	3696.9316
767.69189	2.2685361	0.76209056	3688.1157
768.59277	2.2717206	0.76351047	3692.3982
769.49365	2.2722833	0.76515996	3696.6375
770.39453	2.2781777	0.76677334	3697.1711
771.29541	2.2786655	0.76839775	3695.1511
772.19629	2.2842822	0.77036226	3698.5139
773.09717	2.2847667	0.77190173	3686.1277
773.99805	2.2898886	0.77338701	3694.0303
774.89893	2.290833	0.77474487	3692.811
775.7998	2.2908113	0.77607745	3689.9109
776.70068	2.2948413	0.7775659	3690.1641
777.60156	2.2979925	0.77898318	3692.033
778.50244	2.3012917	0.78042614	3689.9883
779.40332	2.3060148	0.78168654	3693.7
780.3042	2.3084478	0.78308761	3692.0818
781.20508	2.3105044	0.78453398	3697.0266
782.10596	2.3152611	0.78596431	3692.803
783.00684	2.3157349	0.78757745	3698.7571
783.90771	2.3213668	0.78920919	3697.5825
784.80859	2.3187287	0.79061824	3690.7976
785.70947	2.3234284	0.79196572	3689.3743
786.61035	2.3268926	0.79349011	3697.0168
787.51123	2.3317635	0.79497224	3696.9673
788.41211	2.3330939	0.79649216	3695.074
789.31299	2.3344378	0.79826212	3701.021
790.21387	2.3352757	0.79989523	3698.0435
791.11475	2.3409548	0.80194122	3698.2466
792.01563	2.3413219	0.8035301	3689.1946
792.9165	2.3398936	0.80471379	3687.2327
793.81738	2.349973	0.80604523	3691.4702
794.71826	2.3523405	0.80725849	3689.4272
795.61914	2.3562696	0.80864358	3694.7607
796.52002	2.3529658	0.81027001	3689.3999
797.4209	2.3569551	0.81197643	3694.3337
798.32178	2.3610091	0.8135736	3698.2981
799.22266	2.3632245	0.81509697	3692.5603
800.12354	2.3673787	0.81668246	3690.4387
801.02441	2.3681707	0.81828219	3698.4441
801.92529	2.3722937	0.81991696	3693.0864
802.82617	2.3744242	0.82159394	3693.2129
803.72705	2.3752944	0.82318658	3692.8333
804.62793	2.382005	0.82498413	3698.5591
805.52881	2.3840549	0.82686734	3694.2217
806.42969	2.3865888	0.82843089	3685.5911
807.33057	2.3867471	0.82992494	3690.5996
808.23145	2.3909376	0.83145338	3692.415
809.13232	2.3955238	0.83289272	3694.928
810.0332	2.3965933	0.83451605	3688.4143
810.93408	2.4001257	0.83606714	3688.6729
811.83496	2.4021738	0.83796483	3702.7632
812.73584	2.4071262	0.839616	3692.1318
813.63672	2.4050577	0.84115654	3688.7515
814.5376	2.4127243	0.84273452	3689.97
815.43848	2.4142182	0.84433812	3689.2002
816.33936	2.4157569	0.84575123	3689.2917
817.24023	2.4185889	0.84720826	3689.8862
818.14111	2.4249911	0.84868997	3692.6831
819.04199	2.4241986	0.85047901	3694.7705
819.94287	2.4244828	0.85232919	3691.4077
820.84375	2.4278874	0.8540262	3686.2278
821.74463	2.4331765	0.85565716	3689.3323
822.64551	2.4345596	0.85703528	3686.7354
823.54639	2.4378352	0.85864002	3697.6631
824.44727	2.4383743	0.86031038	3691.5945
825.34814	2.4423537	0.86205333	3691.344
826.24902	2.4443054	0.86365819	3689.5671
827.1499	2.4477668	0.86564189	3695.7488
828.05078	2.4513764	0.86763459	3686.6304
828.95166	2.4561367	0.86950183	3691.7966
829.85254	2.4570334	0.8709349	3681.4102
830.75342	2.4615204	0.87246877	3689.1072
831.6543	2.4605167	0.87407649	3688.9565
832.55518	2.4647043	0.87596196	3690.2805
833.45605	2.4665363	0.87783033	3689.0632
834.35693	2.465802	0.87939036	3685.8496
835.25781	2.4727755	0.88144296	3692.2341
836.15869	2.4738083	0.8834607	3684.3455
837.05957	2.4802663	0.88512838	3688.8821
837.96045	2.4781673	0.88677418	3685.532
838.86133	2.4839289	0.88842046	3683.3025
839.76221	2.4846451	0.89033371	3689.9795
840.66309	2.4901583	0.89193565	3685.3572
841.56396	2.4892488	0.89359993	3684.1614
842.46484	2.4927478	0.89519161	3689.1741
843.36572	2.4970148	0.89667982	3685.2537
844.2666	2.5000777	0.89870441	3689.3567
845.16748	2.5012119	0.90066856	3683.5303
846.06836	2.502346	0.90276599	3687.8369
846.96924	2.5074713	0.90489566	3685.8896
847.87012	2.5087965	0.90673226	3678.5918
848.771	2.5121799	0.9082064	3674.7488
849.67188	2.5169163	0.90962428	3680.3135
850.57275	2.5156505	0.911147	3677.8088
851.47363	2.5190208	0.9128859	3681.804
852.37451	2.52459	0.91463691	3679.6541
853.27539	2.5266459	0.91633373	3673.8726
854.17627	2.5287671	0.91805887	3682.0344
855.07715	2.5335917	0.91974902	3680.3477
855.97803	2.5357363	0.92154336	3685.0688
856.87891	2.5394297	0.92338705	3676.4258
857.77979	2.5402813	0.92499334	3681.3782
858.68066	2.5420969	0.9269383	3678.3706
859.58154	2.5444021	0.92905867	3678.9885
860.48242	2.5482202	0.93098027	3666.6338
861.3833	2.5528178	0.93268454	3678.1575
862.28418	2.5540519	0.93448949	3668.4839
863.18506	2.5583336	0.9363789	3674.9412
864.08594	2.5611205	0.93820786	3672.9612
864.98682	2.5615721	0.94022703	3670.6658
865.8877	2.5619202	0.94204217	3666.4519
866.78857	2.5692751	0.94398463	3675.7603
867.68945	2.5687857	0.94619453	3675.0598
868.59033	2.5714419	0.94846338	3671.4292
869.49121	2.5755498	0.95061421	3666.4812
870.39209	2.5776455	0.95246512	3671.6472
871.29297	2.5806832	0.954804	3672.564
872.19385	2.5822511	0.95709139	3670.4788
873.09473	2.5863214	0.95904046	3664.3301
873.99561	2.588846	0.96091455	3661.9294
874.89648	2.5933449	0.96322417	3669.2827
875.79736	2.59268	0.96530747	3659.1162
876.69824	2.5985947	0.96747589	3664.9102
877.59912	2.6018047	0.96949524	3660.9932
878.5	2.602562	0.97154301	3662.8621
879.40088	2.604773	0.97334152	3650.1135
880.30176	2.6062894	0.97509784	3654.2893
881.20264	2.6067317	0.97695768	3657.0249
882.10352	2.6141963	0.9789499	3661.3496
883.00439	2.6124117	0.98136085	3652.9353
883.90527	2.6162784	0.98381853	3661.6775
884.80615	2.6232543	0.98575199	3649.1316
885.70703	2.620898	0.98765314	3648.9075
886.60791	2.6265256	0.98964775	3651.0361
887.50879	2.6307871	0.99185836	3650.0498
888.40967	2.6341264	0.99370062	3648.1646
889.31055	2.6346028	0.9958775	3651.634
890.21143	2.6396172	0.99799395	3645.3777
891.1123	2.6382601	1.0000572	3643.0427
892.01318	2.6442239	1.0022516	3642.5557
892.91406	2.6444435	1.0045024	3641.855
893.81494	2.6467476	1.0070087	3641.9749
894.71582	2.6509283	1.0093664	3640.6707
895.6167	2.6539867	1.0118316	3639.1814
896.51758	2.6578619	1.0142951	3637.8672
897.41846	2.6598821	1.0166086	3637.167
898.31934	2.6624286	1.0186659	3630.8921
899.22021	2.6655748	1.0207437	3631.1533
900.12109	2.6687024	1.022705	3628.2017
901.02197	2.6715896	1.0248249	3627.2368
901.92285	2.672188	1.0272795	3629.0803
902.82373	2.6752694	1.029793	3629.0752
903.72461	2.6789441	1.0321907	3622.9585
904.62549	2.6797502	1.0344578	3615.4751
905.52637	2.6808586	1.0364387	3613.0889
906.42725	2.6856811	1.0384463	3608.4727
907.32813	2.689867	1.0405929	3613.0669
908.229	2.691484	1.0429349	3614.5664
909.12988	2.6953523	1.0455852	3609.2722
910.03076	2.6974983	1.0478355	3606.376
910.93164	2.699482	1.0500984	3602.5012
911.83252	2.7018261	1.05273	3603.4612
912.7334	2.7044873	1.0551341	3602.1526
913.63428	2.7091367	1.0575635	3597.6631
914.53516	2.7099814	1.0598304	3595.9929
915.43604	2.7111294	1.0622172	3591.0056
916.33691	2.7146044	1.0644511	3589.8755
917.23779	2.7190461	1.0667194	3588.7065
918.13867	2.7217727	1.0692174	3583.8743
919.03955	2.7235503	1.0715449	3583.6482
919.94043	2.728236	1.0737107	3576.2681
920.84131	2.7295945	1.0757396	3578.1753
921.74219	2.7316716	1.0780739	3576.8989
922.64307	2.7367961	1.080814	3579.9146
923.54395	2.7387495	1.0834066	3567.9512
924.44482	2.7412395	1.085604	3564.5798
925.3457	2.7415304	1.0879132	3561.261
926.24658	2.7444952	1.089862	3559.7419
927.14746	2.7463195	1.0922383	3559.1917
928.04834	2.7478023	1.0950325	3557.2241
928.94922	2.7528481	1.0981587	3552.8625
929.8501	2.7547972	1.1007199	3548.0361
930.75098	2.7587309	1.1028488	3543.4419
931.65186	2.7622733	1.1051871	3543.0374
932.55273	2.7641673	1.1076183	3538.9238
933.45361	2.7691245	1.1096952	3540.2578
934.35449	2.7680273	1.1121124	3535.0715
935.25537	2.7759764	1.1145545	3537.8682
936.15625	2.7763834	1.1172034	3532.6248
937.05713	2.7804635	1.1200236	3532.0764
937.95801	2.7838295	1.1226125	3521.6472
938.85889	2.7829807	1.1250098	3516.1599
939.75977	2.7876556	1.1275922	3513.7305
940.66064	2.7888105	1.1301794	3516.5999
941.56152	2.7897184	1.1325629	3506.0447
942.4624	2.7963779	1.135159	3507.3232
943.36328	2.7938869	1.1376785	3501.001
944.26416	2.79845	1.1405109	3497.3857
945.16504	2.8035109	1.1430051	3493.6472
946.06592	2.8062038	1.145453	3485.9221
946.9668	2.8061273	1.1475462	3489.3892
947.86768	2.8071017	1.1502659	3482.7112
948.76855	2.8142085	1.1529117	3483.3672
949.66943	2.8155937	1.1557823	3472.2637
950.57031	2.8191926	1.1588126	3473.3835
951.47119	2.8216434	1.1618869	3470.1118
952.37207	2.8223126	1.1649735	3462.3154
953.27295	2.829011	1.1679162	3458.3723
954.17383	2.828975	1.1700051	3446.998
955.07471	2.8333943	1.1721363	3452.707
955.97559	2.8358161	1.1744403	3443.5879
956.87646	2.8398156	1.1772493	3447.7358
957.77734	2.8441637	1.1799158	3435.2063
958.67822	2.8432651	1.1824511	3434.2815
959.5791	2.8472643	1.1847759	3436.6335
960.47998	2.8501194	1.1874988	3428.8457
961.38086	2.8515089	1.1899418	3413.4556
962.28174	2.8550379	1.1927885	3418.7412
963.18262	2.8560884	1.195153	3408.5625
964.0835	2.8600271	1.1977987	3406.8223
964.98438	2.8581924	1.20082	3408.7188
965.88525	2.862663	1.2036489	3392.8174
966.78613	2.8669531	1.2064942	3392.4883
967.68701	2.8675787	1.2094135	3389.9414
968.58789	2.8702745	1.2122003	3378.446
969.48877	2.8791029	1.2147547	3377.4724
970.38965	2.8777511	1.2176442	3372.7107
971.29053	2.8784955	1.2205751	3368.8503
972.19141	2.8852906	1.2237489	3361.0361
973.09229	2.8876634	1.2272799	3350.8923
973.99316	2.8890016	1.2307546	3347.1758
974.89404	2.8913381	1.234292	3338.4209
975.79492	2.8934782	1.2373633	3333.4563
976.6958	2.9002597	1.2406839	3330.4534
977.59668	2.8987937	1.2432773	3312.5034
978.49756	2.9027283	1.245748	3310.0989
979.39844	2.9045806	1.248087	3302.6753
980.29932	2.9097388	1.2507031	3305.8093
981.2002	2.9107985	1.2541131	3294.9163
982.10107	2.9129374	1.2568371	3288.4888
983.00195	2.9169183	1.2598529	3285.1953
983.90283	2.9194684	1.263025	3280.6091
984.80371	2.9222236	1.2663159	3271.1851
985.70459	2.9237666	1.2693653	3262.5498
986.60547	2.9268043	1.2725379	3250.3101
987.50635	2.93027	1.2756685	3250.1733
988.40723	2.9332991	1.2785038	3235.2139
989.30811	2.9336038	1.281263	3227.7883
990.20898	2.937501	1.2837676	3227.2898
991.10986	2.941067	1.2871256	3222.8843
992.01074	2.942502	1.290512	3204.2004
992.91162	2.9459424	1.2929879	3196.8489
993.8125	2.9501164	1.2956778	3189.3618
994.71338	2.9526119	1.2991219	3184.3157
995.61426	2.9532397	1.3020539	3171.6709
996.51514	2.954808	1.3057735	3165.4136
997.41602	2.959476	1.3093716	3155.5388
998.31689	2.962528	1.3137413	3142.4895
999.21777	2.9660408	1.3179016	3117.6177
1000.1187	2.9663143	1.3225416	3094.9631
1001.0195	3.16013	-0.0035652304	-22.015856